Workbook

Sheet Model_Info
A1: BRG.AX -- Breville Group Limited -- Owner-FCF DCF model
A2: Version 1.0, 2026-09-22. Fresh build; supersedes nothing (first valuation of this ticker).
A3: Built by the dcf-analyst agent (Claude Fable 5.1) at the request of Stephen Williams, research-stock workflow.
A5: DATA VINTAGE (all figures go stale -- refresh after each print)
A6: Price A$29.40 -- Yahoo Finance ASX close, regularMarketTime 2026-09-21T06:10:31Z. 52-week range A$25.41-35.48.
A7: Balance sheet 30 June 2026 -- BRG.AX_Annual_FY2026: cash 193.358m, borrowings 88.922m, lease liabilities 64.499m, value-chain (IEEPA refund) provision 55.163m.
A8: Share count 147.122m fully diluted = 144.839m issued (Note 14) + 2.283m potential ordinary shares (Note 13). Held flat.
A9: Guidance: none quantitative. FY26 EBIT A$207.0m was 'in line with guidance given at the half year'; FY27 outlook is qualitative ('challenging macro', 'continue our growth trajectory').
A10: Currency AUD throughout; quote currency AUD. Units A$ millions except per-share.
A12: METHODOLOGY
A13: Model: owner-FCF DCF, 10-year component build, three probability-weighted scenarios (dcf-methods/references/owner-fcf.md incl. section 7).
A14: Owner FCF = reported FCF - SBC - interest income - lease-asset renewal. SBC charged ONCE (expensed, count flat).
... A28: CELL COLOURS: blue font = hardcoded input; yellow fill = key driver row; black = formula; green font = cross-sheet link.

Sheet Actuals
A1: Reported history, A$ millions (source: BRG.AX metrics_normalized / annual reports FY2016-FY2026; each value is the filing's own, rescaled from thousands)
A3: FY (June year end) | B3: FY2016 | C3: FY2017 | D3: FY2018 | E3: FY2019 | F3: FY2020 | G3: FY2021 | H3: FY2022 | I3: FY2023 | J3: FY2024 | K3: FY2025 | L3: FY2026
A4: Revenue | B4: 576.573 | C4: 605.733 | D4: 652.348 | E4: 759.967 | F4: 952.244 | G4: 1187.659 | H4: 1418.437 | I4: 1478.554 | J4: 1529.993 | K4: 1696.551 | L4: 1810.896
A5: EBITDA (reported, after SBC, post-AASB16 from FY20) | B5: 83.412 | C5: 89.789 | D5: 100.211 | E5: 113.961 | F5: 126.521 | G5: 163.298 | H5: 186.825 | I5: 218.163 | J5: 245.498 | K5: 271.894 | L5: 284.124
A6: Share-based payments expense | B6: 0.646 | C6: 0.228 | D6: 1.231 | E6: 2.176 | F6: 2.94 | G6: 6.288 | H6: 8.307 | I6: 11.92 | J6: 14.966 | K6: 18.688 | L6: 21.924
A7: NPAT | B7: 50.172 | C7: 53.834 | D7: 58.519 | E7: 67.385 | F7: 66.201 | G7: 90.968 | H7: 105.717 | I7: 110.208 | J7: 118.507 | K7: 135.854 | L7: 138.127
A8: Operating cash flow | B8: 52.289 | C8: 62.672 | D8: 88.652 | E8: 30.341 | F8: 132.295 | G8: 124.267 | H8: -42.153 | I8: 90.254 | J8: 302.615 | K8: 171.474 | L8: 220.66
A9: Capex (PP&E + development/intangibles) | B9: 13.789 | C9: 19.322 | D9: 19.465 | E9: 28.476 | F9: 38.376 | G9: 31.115 | H9: 42.692 | I9: 53.243 | J9: 62.119 | K9: 100.404 | L9: 90.506
A10: Reported FCF (OCF - capex) | B10: 38.5 | C10: 43.35 | D10: 69.187 | E10: 1.865 | F10: 93.919 | G10: 93.152 | H10: -84.845 | I10: 37.011 | J10: 240.496 | K10: 71.07 | L10: 130.154
A11: Interest income | B11: 0.336 | C11: 0.624 | D11: 1.044 | E11: 0.449 | F11: 0.192 | G11: 0.13 | H11: 0.317 | I11: 0.669 | J11: 2.431 | K11: 1.845 | L11: 2.172
A12: Lease principal repaid (lease-asset renewal proxy) | B12: 0 | C12: 0 | D12: 0 | E12: 0 | F12: 7.325 | G12: 7.479 | H12: 7.674 | I12: 18.303 | J12: 20.547 | K12: 22.802 | L12: 22.136
A13: Shareholders' equity | B13: 246.005 | C13: 259.609 | D13: 283.235 | E13: 310.335 | F13: 426.4 | G13: 506.485 | H13: 614.417 | I13: 769.659 | J13: 848.214 | K13: 973.709 | L13: 1058.305
A14: EPS basic (A$) | B14: 0.386 | C14: 0.414 | D14: 0.45 | E14: 0.518 | F14: 0.505 | G14: 0.658 | H14: 0.759 | I14: 0.772 | J14: 0.827 | K14: 0.944 | L14: 0.955
A15: D&A (total, incl ROU from FY20) | B15: 9.68 | C15: 10.769 | D15: 13.302 | E15: 16.616 | F15: 25.582 | G15: 26.868 | H15: 30.464 | I15: 46.142 | J15: 59.785 | K15: 67.328 | L15: 77.105
... A17: Profit before tax | B17: 71.519 | C17: 77.223 | D17: 84.373 | E17: 94.311 | F17: 92.763 | G17: 127.403 | H17: 147.834 | I17: 150.991 | J17: 165.687 | K17: 189.898 | L17: 193.178
A20: Balance-sheet snapshot 30 June 2026 (A$m)
A21: Cash and cash equivalents | B21: 193.358
A22: Borrowings current | B22: 3.378
A23: Borrowings non-current | B23: 85.544
A24: Lease liabilities current | B24: 20.424
A25: Lease liabilities non-current | B25: 44.075
A26: Value-chain provision (IEEPA Phase 1 refunds owed onward, Note 6) | B26: 55.163
A27: Inventory | B27: 465.8
A28: Receivables | B28: 310.6
A29: Trade and other payables | B29: 321.1
A30: Company-stated net cash (ex-lease, ex-provision) | B30: 104.436
A33: Share count (Notes 13-14)
A34: Ordinary shares on issue 30 June 2026 (m) | B34: 144.83856
A35: Potential ordinary shares (diluted WANOS 146.963 - basic 144.680) | B35: 2.283
A36: Fully diluted (used) | B36: =B34+B35
A37: Shares issued to employee share trust FY26 (m) | B37: 0.892
A38: Buybacks FY16-FY26 | B38: 0
A40: Guidance: no quantitative FY27 guidance in the FY2026 annual report. FY26 EBIT A$207.0m met the half-year guidance. Board: 'challenging macro environment, again'; dividend payout target ~40% of EPS.

Sheet Assumptions
A1: Global inputs (blue) -- every DCF tab links here
A4: Current price (A$) | B4: 29.4 | C4: Yahoo ASX close 2026-09-21T06:10:31Z
A5: Fully diluted shares (m) | B5: 147.122 | C5: 144.839m issued + 2.283m potential; held flat (SBC expensed)
A6: Net debt (A$m; negative = net cash) | B6: 15.226 | C6: borrowings 88.922 + leases 64.499 - cash 193.358 + IEEPA provision 55.163
A7: WACC | B7: 0.1 | C7: AUD: ACGB ~4.3% + 5.5% ERP x ~1.05 beta; same for all scenarios
A8: D&A % of revenue | B8: 0.043 | C8: FY26 77.1m / 1810.9m = 4.26%, incl ROU depreciation 21.95m
A9: Hurdle rate (entry price IRR) | B9: 0.15 | C9: house standard
A10: Revenue FY2026 (A$m) | B10: 1810.896 | C10: annual report FY2026
A11: Cash (A$m, memo) | B11: 193.358 | C11: 30 June 2026
A12: Horizon (years) | B12: 10 | C12: margins and WC drag still maturing at year 5
A14: Per-scenario inputs | B14: Bear | C14: Base | D14: Bull
A15: Terminal growth | B15: 0.02 | C15: 0.03 | D15: 0.035
A16: Probability weight | B16: 0.2 | C16: 0.5 | D16: 0.3
A17: Terminal cap (x owner FCF_10) | B17: 15 | C17: 18 | D17: 18
A18: WC capture on revenue change | B18: -0.3 | C18: -0.25 | D18: -0.2
A19: Weights check (must be 100%) | B19: =SUM(B16:D16)
A21: Scenario narratives
A22: Bear | B22: The tariff regime and a soft US consumer bite. Americas (49% of revenue) stalls, tariff cost cannot be fully priced through, and Chinese espresso-machine competition compresses gross margin: revenue grows 2-3% p.a. and adjusted EBITDA slides to 14.7% (reported ~13.4%) by FY36. Working capital stays heavy at 30% of growth (inventory pre-build for peak seasons, longer supply chains from diversified manufacturing), SBC drifts up to 1.3% of revenue, and cash tax stays at 30%. No balance-sheet stress: the business remains profitable and net cash, so this is a de-rating, not a solvency, scenario.
A23: Base | B23: Breville keeps compounding at roughly its FY23-26 pace: revenue +7% in FY27 (FY26 was +6.7% reported, +9.7% constant currency) decelerating to 3% by FY36 as the coffee category matures and the new direct markets (China, Korea, Middle East, Mexico) scale from a small base. Adjusted EBITDA margin (pre-SBC, post-AASB16) recovers from the tariff-depressed 16.9% toward 17.7% as the diversified 120V sourcing (85% of GP ex-China) removes cost volatility. Working capital stays a 25% drag on growth (inventory + receivables - payables = 25% of revenue), development capex runs ahead of amortisation, and SBC is held at 1.25% of revenue. Cash tax 29-30%.
A24: Bull | B24: The last decade repeats. Revenue CAGR of ~12% (FY16-26 actual: 12.1%) for the first three years on China (7.1x the prior distributor in year one), Middle East (6.6x), Korea and the Best Buy store-in-store roll-out, then a normal deceleration. Premium coffee (Oracle Jet/Dual Boiler, Lelit, Baratza) keeps taking share, gross margin recovers above 37% once tariff pass-through is complete, and operating leverage lifts adjusted EBITDA to 19.5% by FY36. Better inventory turns cut the WC drag to 20% of revenue growth.
A26: Weights rationale | B26: 20/50/30 versus the house 15/50/35. Bear raised to 20% because the two bear axes -- US tariff policy (restructured four times in FY26 and still unresolved) and a US discretionary-spending slowdown (Americas 49% of revenue) -- are exogenous, correlated and unhedgeable. Bull trimmed to 30% because it needs new-market scaling AND gross-margin recovery AND continued coffee-category share gain together. No going-concern or covenant risk (net cash ex-lease, $364m undrawn facilities), so the bear is a de-rating case, which is why it is not higher.

Sheet DCF_Bear
A1: DCF_Bear -- owner-FCF component build, A$m. Drivers (yellow) on rows 5, 7, 9, 14, 22.
A3: Year | B3: 2026A | C3: 2027E | D3: 2028E | E3: 2029E | F3: 2030E | G3: 2031E | H3: 2032E | I3: 2033E | J3: 2034E | K3: 2035E | L3: 2036E
A4: Index | B4: 0 | C4: 1 | D4: 2 | E4: 3 | F4: 4 | G4: 5 | H4: 6 | I4: 7 | J4: 8 | K4: 9 | L4: 10
A5: Revenue growth YoY | C5: 0.02 | D5: 0.03 | E5: 0.03 | F5: 0.03 | G5: 0.03 | H5: 0.03 | I5: 0.03 | J5: 0.03 | K5: 0.025 | L5: 0.025
A6: Revenue | B6: =Assumptions!$B$10 | C6: =B6*(1+C5) | D6: =C6*(1+D5) | E6: =D6*(1+E5) | F6: =E6*(1+F5) | G6: =F6*(1+G5) | H6: =G6*(1+H5) | I6: =H6*(1+I5) | J6: =I6*(1+J5) | ... L6: =K6*(1+L5)
A7: Adj EBITDA margin (pre-SBC) | B7: 0.169 | C7: 0.162 | D7: 0.160333 | E7: 0.158667 | F7: 0.157 | G7: 0.155333 | H7: 0.153667 | I7: 0.152 | J7: 0.150333 | K7: 0.148667 | L7: 0.147
A8: Adjusted EBITDA | B8: =B6*B7 | C8: =C6*C7 | D8: =D6*D7 | E8: =E6*E7 | F8: =F6*F7 | G8: =G6*G7 | H8: =H6*H7 | I8: =I6*I7 | ... L8: =L6*L7
A9: SBC % of revenue | B9: 0.0121 | C9: 0.013 | D9: 0.013 | E9: 0.013 | F9: 0.013 | G9: 0.013 | H9: 0.013 | I9: 0.013 | J9: 0.013 | K9: 0.013 | L9: 0.013
A10: SBC (negative) | B10: =-B6*B9 | C10: =-C6*C9 | D10: =-D6*D9 | E10: =-E6*E9 | F10: =-F6*F9 | G10: =-G6*G9 | H10: =-H6*H9 | I10: =-I6*I9 | ... L10: =-L6*L9
A11: Owner EBITDA | B11: =B8+B10 | C11: =C8+C10 | D11: =D8+D10 | E11: =E8+E10 | F11: =F8+F10 | G11: =G8+G10 | H11: =H8+H10 | I11: =I8+I10 | ... L11: =L8+L10
A12: D&A (negative) | B12: -77.105 | C12: =-C6*Assumptions!$B$8 | D12: =-D6*Assumptions!$B$8 | E12: =-E6*Assumptions!$B$8 | F12: =-F6*Assumptions!$B$8 | G12: =-G6*Assumptions!$B$8 | H12: =-H6*Assumptions!$B$8 | I12: =-I6*Assumptions!$B$8 | J12: =-J6*Assumptions!$B$8 | ... L12: =-L6*Assumptions!$B$8
A13: EBIT, SBC expensed | B13: =B11+B12 | C13: =C11+C12 | D13: =D11+D12 | E13: =E11+E12 | F13: =F11+F12 | G13: =G11+G12 | H13: =H11+H12 | I13: =I11+I12 | ... L13: =L11+L12
A14: Cash tax rate | B14: 0.3225 | C14: 0.3 | D14: 0.3 | E14: 0.3 | F14: 0.3 | G14: 0.3 | H14: 0.3 | I14: 0.3 | J14: 0.3 | K14: 0.3 | L14: 0.3
A15: NOPAT | C15: =C13-MAX(0,C13)*C14 | D15: =D13-MAX(0,D13)*D14 | E15: =E13-MAX(0,E13)*E14 | F15: =F13-MAX(0,F13)*F14 | G15: =G13-MAX(0,G13)*G14 | H15: =H13-MAX(0,H13)*H14 | I15: =I13-MAX(0,I13)*I14 | J15: =J13-MAX(0,J13)*J14 | ... L15: =L13-MAX(0,L13)*L14
A16: add back D&A | C16: =-C12 | D16: =-D12 | E16: =-E12 | F16: =-F12 | G16: =-G12 | H16: =-H12 | I16: =-I12 | J16: =-J12 | ... L16: =-L12
A17: less capex | B17: -112.642 | C17: =-C6*C22 | D17: =-D6*D22 | E17: =-E6*E22 | F17: =-F6*F22 | G17: =-G6*G22 | H17: =-H6*H22 | I17: =-I6*I22 | J17: =-J6*J22 | ... L17: =-L6*L22
A18: add working capital (negative = build) | C18: =Assumptions!$B$18*(C6-B6) | D18: =Assumptions!$B$18*(D6-C6) | E18: =Assumptions!$B$18*(E6-D6) | F18: =Assumptions!$B$18*(F6-E6) | G18: =Assumptions!$B$18*(G6-F6) | H18: =Assumptions!$B$18*(H6-G6) | I18: =Assumptions!$B$18*(I6-H6) | J18: =Assumptions!$B$18*(J6-I6) | ... L18: =Assumptions!$B$18*(L6-K6)
A19: Unlevered owner FCF | B19: 83.922 | C19: =C15+C16+C17+C18 | D19: =D15+D16+D17+D18 | E19: =E15+E16+E17+E18 | F19: =F15+F16+F17+F18 | G19: =G15+G16+G17+G18 | H19: =H15+H16+H17+H18 | I19: =I15+I16+I17+I18 | J19: =J15+J16+J17+J18 | ... L19: =L15+L16+L17+L18
A20: Discount factor | C20: =1/(1+Assumptions!$B$7)^C4 | D20: =1/(1+Assumptions!$B$7)^D4 | E20: =1/(1+Assumptions!$B$7)^E4 | F20: =1/(1+Assumptions!$B$7)^F4 | G20: =1/(1+Assumptions!$B$7)^G4 | H20: =1/(1+Assumptions!$B$7)^H4 | I20: =1/(1+Assumptions!$B$7)^I4 | J20: =1/(1+Assumptions!$B$7)^J4 | ... L20: =1/(1+Assumptions!$B$7)^L4
A21: PV of FCF | C21: =C19*C20 | D21: =D19*D20 | E21: =E19*E20 | F21: =F19*F20 | G21: =G19*G20 | H21: =H19*H20 | I21: =I19*I20 | J21: =J19*J20 | ... L21: =L19*L20
A22: Capex % of revenue (incl ~1.2% lease renewal) | B22: 0.0622 | C22: 0.06 | D22: 0.058889 | E22: 0.057778 | F22: 0.056667 | G22: 0.055556 | H22: 0.054444 | I22: 0.053333 | J22: 0.052222 | K22: 0.051111 | L22: 0.05
A23: Memo: FCF before SBC (company-style) | C23: =C19-C10 | D23: =D19-D10 | E23: =E19-E10 | F23: =F19-F10 | G23: =G19-G10 | H23: =H19-H10 | I23: =I19-I10 | J23: =J19-J10 | ... L23: =L19-L10
A24: Memo: owner-FCF margin | B24: =B19/B6 | C24: =C19/C6 | D24: =D19/D6 | E24: =E19/E6 | F24: =F19/F6 | G24: =G19/G6 | H24: =H19/H6 | I24: =I19/I6 | ... L24: =L19/L6
A26: Sum of PV (years 1-10) | B26: =SUM(C21:L21)
A27: Terminal growth | B27: =Assumptions!$B$15
A28: Terminal-year FCF x (1+g) | B28: =L19*(1+B27)
A29: Gordon terminal value | B29: =IF(Assumptions!$B$7>B27,B28/(Assumptions!$B$7-B27),0)
A30: Cap terminal value | B30: =Assumptions!$B$17*L19
A31: Terminal value used = MAX(0,MIN(Gordon,cap)) | B31: =MAX(0,MIN(B29,B30))
A32: Implied exit multiple (x FCF_10) | B32: =IF(L19<>0,B31/L19,0)
A33: PV of terminal value | B33: =B31*L20
A34: Enterprise value | B34: =B26+B33
A35: less net debt (add net cash) | B35: =-Assumptions!$B$6
A36: Equity value | B36: =B34+B35
A37: Diluted shares (m) | B37: =Assumptions!$B$5
A38: VALUE PER SHARE (A$) | B38: =B36/B37
A39: Upside vs price | B39: =B38/Assumptions!$B$4-1
A41: Street memo: PV of explicit-period SBC | B41: =SUMPRODUCT(-C10:L10/(1+Assumptions!$B$7)^C4:L4)
A42: Street memo: PV of terminal SBC | B42: =IF(Assumptions!$B$7>B27,(-L10*(1+B27)/(Assumptions!$B$7-B27))*L20,0)
A43: Street value per share (SBC as non-cash) | B43: =(B36+B41+B42)/B37
...

Sheet DCF_Base
A1: DCF_Base -- owner-FCF component build, A$m. Drivers (yellow) on rows 5, 7, 9, 14, 22.
A3: Year | B3: 2026A | C3: 2027E | D3: 2028E | E3: 2029E | F3: 2030E | G3: 2031E | H3: 2032E | I3: 2033E | J3: 2034E | K3: 2035E | L3: 2036E
A4: Index | B4: 0 | C4: 1 | D4: 2 | E4: 3 | F4: 4 | G4: 5 | H4: 6 | I4: 7 | J4: 8 | K4: 9 | L4: 10
A5: Revenue growth YoY | C5: 0.07 | D5: 0.07 | E5: 0.065 | F5: 0.06 | G5: 0.055 | H5: 0.05 | I5: 0.045 | J5: 0.04 | K5: 0.035 | L5: 0.03
A6: Revenue | B6: =Assumptions!$B$10 | C6: =B6*(1+C5) | D6: =C6*(1+D5) | E6: =D6*(1+E5) | F6: =E6*(1+F5) | G6: =F6*(1+G5) | H6: =G6*(1+H5) | I6: =H6*(1+I5) | J6: =I6*(1+J5) | ... L6: =K6*(1+L5)
A7: Adj EBITDA margin (pre-SBC) | B7: 0.169 | C7: 0.169 | D7: 0.169889 | E7: 0.170778 | F7: 0.171667 | G7: 0.172556 | H7: 0.173444 | I7: 0.174333 | J7: 0.175222 | K7: 0.176111 | L7: 0.177
A8: Adjusted EBITDA | B8: =B6*B7 | C8: =C6*C7 | D8: =D6*D7 | E8: =E6*E7 | F8: =F6*F7 | G8: =G6*G7 | H8: =H6*H7 | I8: =I6*I7 | ... L8: =L6*L7
A9: SBC % of revenue | B9: 0.0121 | C9: 0.0125 | D9: 0.0125 | E9: 0.0125 | F9: 0.0125 | G9: 0.0125 | H9: 0.0125 | I9: 0.0125 | J9: 0.0125 | K9: 0.0125 | L9: 0.0125
A10: SBC (negative) | B10: =-B6*B9 | C10: =-C6*C9 | D10: =-D6*D9 | E10: =-E6*E9 | F10: =-F6*F9 | G10: =-G6*G9 | H10: =-H6*H9 | I10: =-I6*I9 | ... L10: =-L6*L9
A11: Owner EBITDA | B11: =B8+B10 | C11: =C8+C10 | D11: =D8+D10 | E11: =E8+E10 | F11: =F8+F10 | G11: =G8+G10 | H11: =H8+H10 | I11: =I8+I10 | ... L11: =L8+L10
A12: D&A (negative) | B12: -77.105 | C12: =-C6*Assumptions!$B$8 | D12: =-D6*Assumptions!$B$8 | E12: =-E6*Assumptions!$B$8 | F12: =-F6*Assumptions!$B$8 | G12: =-G6*Assumptions!$B$8 | H12: =-H6*Assumptions!$B$8 | I12: =-I6*Assumptions!$B$8 | J12: =-J6*Assumptions!$B$8 | ... L12: =-L6*Assumptions!$B$8
A13: EBIT, SBC expensed | B13: =B11+B12 | C13: =C11+C12 | D13: =D11+D12 | E13: =E11+E12 | F13: =F11+F12 | G13: =G11+G12 | H13: =H11+H12 | I13: =I11+I12 | ... L13: =L11+L12
A14: Cash tax rate | B14: 0.3225 | C14: 0.3 | D14: 0.29 | E14: 0.29 | F14: 0.29 | G14: 0.29 | H14: 0.29 | I14: 0.29 | J14: 0.29 | K14: 0.29 | L14: 0.29
A15: NOPAT | C15: =C13-MAX(0,C13)*C14 | D15: =D13-MAX(0,D13)*D14 | E15: =E13-MAX(0,E13)*E14 | F15: =F13-MAX(0,F13)*F14 | G15: =G13-MAX(0,G13)*G14 | H15: =H13-MAX(0,H13)*H14 | I15: =I13-MAX(0,I13)*I14 | J15: =J13-MAX(0,J13)*J14 | ... L15: =L13-MAX(0,L13)*L14
A16: add back D&A | C16: =-C12 | D16: =-D12 | E16: =-E12 | F16: =-F12 | G16: =-G12 | H16: =-H12 | I16: =-I12 | J16: =-J12 | ... L16: =-L12
A17: less capex | B17: -112.642 | C17: =-C6*C22 | D17: =-D6*D22 | E17: =-E6*E22 | F17: =-F6*F22 | G17: =-G6*G22 | H17: =-H6*H22 | I17: =-I6*I22 | J17: =-J6*J22 | ... L17: =-L6*L22
A18: add working capital (negative = build) | C18: =Assumptions!$C$18*(C6-B6) | D18: =Assumptions!$C$18*(D6-C6) | E18: =Assumptions!$C$18*(E6-D6) | F18: =Assumptions!$C$18*(F6-E6) | G18: =Assumptions!$C$18*(G6-F6) | H18: =Assumptions!$C$18*(H6-G6) | I18: =Assumptions!$C$18*(I6-H6) | J18: =Assumptions!$C$18*(J6-I6) | ... L18: =Assumptions!$C$18*(L6-K6)
A19: Unlevered owner FCF | B19: 83.922 | C19: =C15+C16+C17+C18 | D19: =D15+D16+D17+D18 | E19: =E15+E16+E17+E18 | F19: =F15+F16+F17+F18 | G19: =G15+G16+G17+G18 | H19: =H15+H16+H17+H18 | I19: =I15+I16+I17+I18 | J19: =J15+J16+J17+J18 | ... L19: =L15+L16+L17+L18
A20: Discount factor | C20: =1/(1+Assumptions!$B$7)^C4 | D20: =1/(1+Assumptions!$B$7)^D4 | E20: =1/(1+Assumptions!$B$7)^E4 | F20: =1/(1+Assumptions!$B$7)^F4 | G20: =1/(1+Assumptions!$B$7)^G4 | H20: =1/(1+Assumptions!$B$7)^H4 | I20: =1/(1+Assumptions!$B$7)^I4 | J20: =1/(1+Assumptions!$B$7)^J4 | ... L20: =1/(1+Assumptions!$B$7)^L4
A21: PV of FCF | C21: =C19*C20 | D21: =D19*D20 | E21: =E19*E20 | F21: =F19*F20 | G21: =G19*G20 | H21: =H19*H20 | I21: =I19*I20 | J21: =J19*J20 | ... L21: =L19*L20
A22: Capex % of revenue (incl ~1.2% lease renewal) | B22: 0.0622 | C22: 0.062 | D22: 0.060889 | E22: 0.059778 | F22: 0.058667 | G22: 0.057556 | H22: 0.056444 | I22: 0.055333 | J22: 0.054222 | K22: 0.053111 | L22: 0.052
A23: Memo: FCF before SBC (company-style) | C23: =C19-C10 | D23: =D19-D10 | E23: =E19-E10 | F23: =F19-F10 | G23: =G19-G10 | H23: =H19-H10 | I23: =I19-I10 | J23: =J19-J10 | ... L23: =L19-L10
A24: Memo: owner-FCF margin | B24: =B19/B6 | C24: =C19/C6 | D24: =D19/D6 | E24: =E19/E6 | F24: =F19/F6 | G24: =G19/G6 | H24: =H19/H6 | I24: =I19/I6 | ... L24: =L19/L6
A26: Sum of PV (years 1-10) | B26: =SUM(C21:L21)
A27: Terminal growth | B27: =Assumptions!$C$15
A28: Terminal-year FCF x (1+g) | B28: =L19*(1+B27)
A29: Gordon terminal value | B29: =IF(Assumptions!$B$7>B27,B28/(Assumptions!$B$7-B27),0)
A30: Cap terminal value | B30: =Assumptions!$C$17*L19
A31: Terminal value used = MAX(0,MIN(Gordon,cap)) | B31: =MAX(0,MIN(B29,B30))
A32: Implied exit multiple (x FCF_10) | B32: =IF(L19<>0,B31/L19,0)
A33: PV of terminal value | B33: =B31*L20
A34: Enterprise value | B34: =B26+B33
A35: less net debt (add net cash) | B35: =-Assumptions!$B$6
A36: Equity value | B36: =B34+B35
A37: Diluted shares (m) | B37: =Assumptions!$B$5
A38: VALUE PER SHARE (A$) | B38: =B36/B37
A39: Upside vs price | B39: =B38/Assumptions!$B$4-1
A41: Street memo: PV of explicit-period SBC | B41: =SUMPRODUCT(-C10:L10/(1+Assumptions!$B$7)^C4:L4)
A42: Street memo: PV of terminal SBC | B42: =IF(Assumptions!$B$7>B27,(-L10*(1+B27)/(Assumptions!$B$7-B27))*L20,0)
A43: Street value per share (SBC as non-cash) | B43: =(B36+B41+B42)/B37
...

Sheet DCF_Bull
A1: DCF_Bull -- owner-FCF component build, A$m. Drivers (yellow) on rows 5, 7, 9, 14, 22.
A3: Year | B3: 2026A | C3: 2027E | D3: 2028E | E3: 2029E | F3: 2030E | G3: 2031E | H3: 2032E | I3: 2033E | J3: 2034E | K3: 2035E | L3: 2036E
A4: Index | B4: 0 | C4: 1 | D4: 2 | E4: 3 | F4: 4 | G4: 5 | H4: 6 | I4: 7 | J4: 8 | K4: 9 | L4: 10
A5: Revenue growth YoY | C5: 0.12 | D5: 0.11 | E5: 0.1 | F5: 0.09 | G5: 0.08 | H5: 0.07 | I5: 0.06 | J5: 0.05 | K5: 0.04 | L5: 0.035
A6: Revenue | B6: =Assumptions!$B$10 | C6: =B6*(1+C5) | D6: =C6*(1+D5) | E6: =D6*(1+E5) | F6: =E6*(1+F5) | G6: =F6*(1+G5) | H6: =G6*(1+H5) | I6: =H6*(1+I5) | J6: =I6*(1+J5) | ... L6: =K6*(1+L5)
A7: Adj EBITDA margin (pre-SBC) | B7: 0.169 | C7: 0.172 | D7: 0.174556 | E7: 0.177111 | F7: 0.179667 | G7: 0.182222 | H7: 0.184778 | I7: 0.187333 | J7: 0.189889 | K7: 0.192444 | L7: 0.195
A8: Adjusted EBITDA | B8: =B6*B7 | C8: =C6*C7 | D8: =D6*D7 | E8: =E6*E7 | F8: =F6*F7 | G8: =G6*G7 | H8: =H6*H7 | I8: =I6*I7 | ... L8: =L6*L7
A9: SBC % of revenue | B9: 0.0121 | C9: 0.012 | D9: 0.012 | E9: 0.012 | F9: 0.012 | G9: 0.012 | H9: 0.012 | I9: 0.012 | J9: 0.012 | K9: 0.012 | L9: 0.012
A10: SBC (negative) | B10: =-B6*B9 | C10: =-C6*C9 | D10: =-D6*D9 | E10: =-E6*E9 | F10: =-F6*F9 | G10: =-G6*G9 | H10: =-H6*H9 | I10: =-I6*I9 | ... L10: =-L6*L9
A11: Owner EBITDA | B11: =B8+B10 | C11: =C8+C10 | D11: =D8+D10 | E11: =E8+E10 | F11: =F8+F10 | G11: =G8+G10 | H11: =H8+H10 | I11: =I8+I10 | ... L11: =L8+L10
A12: D&A (negative) | B12: -77.105 | C12: =-C6*Assumptions!$B$8 | D12: =-D6*Assumptions!$B$8 | E12: =-E6*Assumptions!$B$8 | F12: =-F6*Assumptions!$B$8 | G12: =-G6*Assumptions!$B$8 | H12: =-H6*Assumptions!$B$8 | I12: =-I6*Assumptions!$B$8 | J12: =-J6*Assumptions!$B$8 | ... L12: =-L6*Assumptions!$B$8
A13: EBIT, SBC expensed | B13: =B11+B12 | C13: =C11+C12 | D13: =D11+D12 | E13: =E11+E12 | F13: =F11+F12 | G13: =G11+G12 | H13: =H11+H12 | I13: =I11+I12 | ... L13: =L11+L12
A14: Cash tax rate | B14: 0.3225 | C14: 0.3 | D14: 0.29 | E14: 0.29 | F14: 0.29 | G14: 0.29 | H14: 0.29 | I14: 0.29 | J14: 0.29 | K14: 0.29 | L14: 0.29
A15: NOPAT | C15: =C13-MAX(0,C13)*C14 | D15: =D13-MAX(0,D13)*D14 | E15: =E13-MAX(0,E13)*E14 | F15: =F13-MAX(0,F13)*F14 | G15: =G13-MAX(0,G13)*G14 | H15: =H13-MAX(0,H13)*H14 | I15: =I13-MAX(0,I13)*I14 | J15: =J13-MAX(0,J13)*J14 | ... L15: =L13-MAX(0,L13)*L14
A16: add back D&A | C16: =-C12 | D16: =-D12 | E16: =-E12 | F16: =-F12 | G16: =-G12 | H16: =-H12 | I16: =-I12 | J16: =-J12 | ... L16: =-L12
A17: less capex | B17: -112.642 | C17: =-C6*C22 | D17: =-D6*D22 | E17: =-E6*E22 | F17: =-F6*F22 | G17: =-G6*G22 | H17: =-H6*H22 | I17: =-I6*I22 | J17: =-J6*J22 | ... L17: =-L6*L22
A18: add working capital (negative = build) | C18: =Assumptions!$D$18*(C6-B6) | D18: =Assumptions!$D$18*(D6-C6) | E18: =Assumptions!$D$18*(E6-D6) | F18: =Assumptions!$D$18*(F6-E6) | G18: =Assumptions!$D$18*(G6-F6) | H18: =Assumptions!$D$18*(H6-G6) | I18: =Assumptions!$D$18*(I6-H6) | J18: =Assumptions!$D$18*(J6-I6) | ... L18: =Assumptions!$D$18*(L6-K6)
A19: Unlevered owner FCF | B19: 83.922 | C19: =C15+C16+C17+C18 | D19: =D15+D16+D17+D18 | E19: =E15+E16+E17+E18 | F19: =F15+F16+F17+F18 | G19: =G15+G16+G17+G18 | H19: =H15+H16+H17+H18 | I19: =I15+I16+I17+I18 | J19: =J15+J16+J17+J18 | ... L19: =L15+L16+L17+L18
A20: Discount factor | C20: =1/(1+Assumptions!$B$7)^C4 | D20: =1/(1+Assumptions!$B$7)^D4 | E20: =1/(1+Assumptions!$B$7)^E4 | F20: =1/(1+Assumptions!$B$7)^F4 | G20: =1/(1+Assumptions!$B$7)^G4 | H20: =1/(1+Assumptions!$B$7)^H4 | I20: =1/(1+Assumptions!$B$7)^I4 | J20: =1/(1+Assumptions!$B$7)^J4 | ... L20: =1/(1+Assumptions!$B$7)^L4
A21: PV of FCF | C21: =C19*C20 | D21: =D19*D20 | E21: =E19*E20 | F21: =F19*F20 | G21: =G19*G20 | H21: =H19*H20 | I21: =I19*I20 | J21: =J19*J20 | ... L21: =L19*L20
A22: Capex % of revenue (incl ~1.2% lease renewal) | B22: 0.0622 | C22: 0.062 | D22: 0.061222 | E22: 0.060444 | F22: 0.059667 | G22: 0.058889 | H22: 0.058111 | I22: 0.057333 | J22: 0.056556 | K22: 0.055778 | L22: 0.055
A23: Memo: FCF before SBC (company-style) | C23: =C19-C10 | D23: =D19-D10 | E23: =E19-E10 | F23: =F19-F10 | G23: =G19-G10 | H23: =H19-H10 | I23: =I19-I10 | J23: =J19-J10 | ... L23: =L19-L10
A24: Memo: owner-FCF margin | B24: =B19/B6 | C24: =C19/C6 | D24: =D19/D6 | E24: =E19/E6 | F24: =F19/F6 | G24: =G19/G6 | H24: =H19/H6 | I24: =I19/I6 | ... L24: =L19/L6
A26: Sum of PV (years 1-10) | B26: =SUM(C21:L21)
A27: Terminal growth | B27: =Assumptions!$D$15
A28: Terminal-year FCF x (1+g) | B28: =L19*(1+B27)
A29: Gordon terminal value | B29: =IF(Assumptions!$B$7>B27,B28/(Assumptions!$B$7-B27),0)
A30: Cap terminal value | B30: =Assumptions!$D$17*L19
A31: Terminal value used = MAX(0,MIN(Gordon,cap)) | B31: =MAX(0,MIN(B29,B30))
A32: Implied exit multiple (x FCF_10) | B32: =IF(L19<>0,B31/L19,0)
A33: PV of terminal value | B33: =B31*L20
A34: Enterprise value | B34: =B26+B33
A35: less net debt (add net cash) | B35: =-Assumptions!$B$6
A36: Equity value | B36: =B34+B35
A37: Diluted shares (m) | B37: =Assumptions!$B$5
A38: VALUE PER SHARE (A$) | B38: =B36/B37
A39: Upside vs price | B39: =B38/Assumptions!$B$4-1
A41: Street memo: PV of explicit-period SBC | B41: =SUMPRODUCT(-C10:L10/(1+Assumptions!$B$7)^C4:L4)
A42: Street memo: PV of terminal SBC | B42: =IF(Assumptions!$B$7>B27,(-L10*(1+B27)/(Assumptions!$B$7-B27))*L20,0)
A43: Street value per share (SBC as non-cash) | B43: =(B36+B41+B42)/B37
...

Sheet FCF_Quality
A1: Reported FCF reconciled to owner FCF, A$m (links to Actuals)
A3: FY | B3: FY2016 | C3: FY2017 | D3: FY2018 | E3: FY2019 | F3: FY2020 | G3: FY2021 | H3: FY2022 | I3: FY2023 | J3: FY2024 | K3: FY2025 | L3: FY2026
A4: Free cash flow (company definition: OCF - PP&E - development capex) | B4: =Actuals!B10 | C4: =Actuals!C10 | D4: =Actuals!D10 | E4: =Actuals!E10 | F4: =Actuals!F10 | G4: =Actuals!G10 | H4: =Actuals!H10 | I4: =Actuals!I10 | ... L4: =Actuals!L10
A5: less: share-based payments (no separate equity-award tax line) | B5: =-Actuals!B6 | C5: =-Actuals!C6 | D5: =-Actuals!D6 | E5: =-Actuals!E6 | F5: =-Actuals!F6 | G5: =-Actuals!G6 | H5: =-Actuals!H6 | I5: =-Actuals!I6 | ... L5: =-Actuals!L6
A6: less: interest income | B6: =-Actuals!B11 | C6: =-Actuals!C11 | D6: =-Actuals!D11 | E6: =-Actuals!E11 | F6: =-Actuals!F11 | G6: =-Actuals!G11 | H6: =-Actuals!H11 | I6: =-Actuals!I11 | ... L6: =-Actuals!L11
A7: less: lease-asset renewal (lease principal repaid; nil pre-AASB16) | B7: =-Actuals!B12 | C7: =-Actuals!C12 | D7: =-Actuals!D12 | E7: =-Actuals!E12 | F7: =-Actuals!F12 | G7: =-Actuals!G12 | H7: =-Actuals!H12 | I7: =-Actuals!I12 | ... L7: =-Actuals!L12
A8: Owner FCF (sum of the four lines above) | B8: =SUM(B4:B7) | C8: =SUM(C4:C7) | D8: =SUM(D4:D7) | E8: =SUM(E4:E7) | F8: =SUM(F4:F7) | G8: =SUM(G4:G7) | H8: =SUM(H4:H7) | I8: =SUM(I4:I7) | ... L8: =SUM(L4:L7)
A9: Reported FCF margin | B9: =B4/Actuals!B4 | C9: =C4/Actuals!C4 | D9: =D4/Actuals!D4 | E9: =E4/Actuals!E4 | F9: =F4/Actuals!F4 | G9: =G4/Actuals!G4 | H9: =H4/Actuals!H4 | I9: =I4/Actuals!I4 | ... L9: =L4/Actuals!L4
A10: Owner FCF margin | B10: =B8/Actuals!B4 | C10: =C8/Actuals!C4 | D10: =D8/Actuals!D4 | E10: =E8/Actuals!E4 | F10: =F8/Actuals!F4 | G10: =G8/Actuals!G4 | H10: =H8/Actuals!H4 | I10: =I8/Actuals!I4 | ... L10: =L8/Actuals!L4
A11: Memo: cash tax rate (tax paid / PBT) | B11: =Actuals!B16/Actuals!B17 | C11: =Actuals!C16/Actuals!C17 | D11: =Actuals!D16/Actuals!D17 | E11: =Actuals!E16/Actuals!E17 | F11: =Actuals!F16/Actuals!F17 | G11: =Actuals!G16/Actuals!G17 | H11: =Actuals!H16/Actuals!H17 | I11: =Actuals!I16/Actuals!I17 | ... L11: =Actuals!L16/Actuals!L17
A12: Memo: SBC % of revenue | B12: =Actuals!B6/Actuals!B4 | C12: =Actuals!C6/Actuals!C4 | D12: =Actuals!D6/Actuals!D4 | E12: =Actuals!E6/Actuals!E4 | F12: =Actuals!F6/Actuals!F4 | G12: =Actuals!G6/Actuals!G4 | H12: =Actuals!H6/Actuals!H4 | I12: =Actuals!I6/Actuals!I4 | ... L12: =Actuals!L6/Actuals!L4
A14: Memo FY2026: OCF includes ~55.2m of IEEPA Phase 1 tariff-refund cash booked as a current 'value chain' provision (paid onward within 12 months). Underlying FY26 owner FCF: | M14: =L8-Actuals!B26
A15: Memo: FY2024 OCF 302.6m was an inventory unwind (+75.8m/yr rebuilt FY25-26); FY2022 OCF was negative on inventory build. Median owner FCF FY20-26 shown at M15: | M15: =MEDIAN(F8:L8)

Sheet Valuation
A1: Valuation summary (all cells are formulas; drivers live on Assumptions and the DCF_* tabs)
A3: Scenario | B3: Value per share | C3: Upside vs price | D3: Probability | E3: Street value per share | F3: Entry price @15% (TV at hurdle) | G3: Street entry price @15% | H3: Terminal % of EV
A4: Bear | B4: =DCF_Bear!$B$38 | C4: =B4/Assumptions!$B$4-1 | D4: =Assumptions!$B$16 | E4: =DCF_Bear!$B$43 | F4: =(SUMPRODUCT(DCF_Bear!$C$19:$L$19/(1+Assumptions!$B$9)^DCF_Bear!$C$4:$L$4)+MAX(0,MIN(IF(Assumptions!$B$9>Assumptions!$B$15,DCF_Bear!$L$19*(1+Assumptions!$B$15)/(Assumptions!$B$9-Assumptions!$B$15),0),Assumptions!$B$17*DCF_Bear!$L$19))/(1+Assumptions!$B$9)^Assumptions!$B$12-Assumptions!$B$6)/Assumptions!$B$5 | G4: =F4+(SUMPRODUCT(-DCF_Bear!$C$10:$L$10/(1+Assumptions!$B$9)^DCF_Bear!$C$4:$L$4)+IF(Assumptions!$B$9>Assumptions!$B$15,(-DCF_Bear!$L$10*(1+Assumptions!$B$15)/(Assumptions!$B$9-Assumptions!$B$15))/(1+Assumptions!$B$9)^Assumptions!$B$12,0))/Assumptions!$B$5 | H4: =DCF_Bear!$B$44
A5: Base | B5: =DCF_Base!$B$38 | C5: =B5/Assumptions!$B$4-1 | D5: =Assumptions!$C$16 | E5: =DCF_Base!$B$43 | F5: =(SUMPRODUCT(DCF_Base!$C$19:$L$19/(1+Assumptions!$B$9)^DCF_Base!$C$4:$L$4)+MAX(0,MIN(IF(Assumptions!$B$9>Assumptions!$C$15,DCF_Base!$L$19*(1+Assumptions!$C$15)/(Assumptions!$B$9-Assumptions!$C$15),0),Assumptions!$C$17*DCF_Base!$L$19))/(1+Assumptions!$B$9)^Assumptions!$B$12-Assumptions!$B$6)/Assumptions!$B$5 | G5: =F5+(SUMPRODUCT(-DCF_Base!$C$10:$L$10/(1+Assumptions!$B$9)^DCF_Base!$C$4:$L$4)+IF(Assumptions!$B$9>Assumptions!$C$15,(-DCF_Base!$L$10*(1+Assumptions!$C$15)/(Assumptions!$B$9-Assumptions!$C$15))/(1+Assumptions!$B$9)^Assumptions!$B$12,0))/Assumptions!$B$5 | H5: =DCF_Base!$B$44
A6: Bull | B6: =DCF_Bull!$B$38 | C6: =B6/Assumptions!$B$4-1 | D6: =Assumptions!$D$16 | E6: =DCF_Bull!$B$43 | F6: =(SUMPRODUCT(DCF_Bull!$C$19:$L$19/(1+Assumptions!$B$9)^DCF_Bull!$C$4:$L$4)+MAX(0,MIN(IF(Assumptions!$B$9>Assumptions!$D$15,DCF_Bull!$L$19*(1+Assumptions!$D$15)/(Assumptions!$B$9-Assumptions!$D$15),0),Assumptions!$D$17*DCF_Bull!$L$19))/(1+Assumptions!$B$9)^Assumptions!$B$12-Assumptions!$B$6)/Assumptions!$B$5 | G6: =F6+(SUMPRODUCT(-DCF_Bull!$C$10:$L$10/(1+Assumptions!$B$9)^DCF_Bull!$C$4:$L$4)+IF(Assumptions!$B$9>Assumptions!$D$15,(-DCF_Bull!$L$10*(1+Assumptions!$D$15)/(Assumptions!$B$9-Assumptions!$D$15))/(1+Assumptions!$B$9)^Assumptions!$B$12,0))/Assumptions!$B$5 | H6: =DCF_Bull!$B$44
A8: Probability-weighted value per share | B8: =SUMPRODUCT(B4:B6,D4:D6)
A9: Current price | B9: =Assumptions!$B$4
A10: Margin of safety (1 - price/weighted) | B10: =1-B9/B8
A11: Street weighted value per share | B11: =SUMPRODUCT(E4:E6,D4:D6)
A12: Band position (price - house)/(street - house); 0% = house, 100% = street | B12: =IF(B11<>B8,(B9-B8)/(B11-B8),"n/a")
A13: Weighted entry price @15% hurdle (buy-below) | B13: =SUMPRODUCT(F4:F6,D4:D6)
A14: Weighted street entry price @15% | B14: =SUMPRODUCT(G4:G6,D4:D6)
A17: Required-return table (base case; TV rebuilt at each rate)
A18: Required return | B18: Value per share
A19: 0.09 | B19: =(SUMPRODUCT(DCF_Base!$C$19:$L$19/(1+$A$19)^DCF_Base!$C$4:$L$4)+MAX(0,MIN(IF($A$19>Assumptions!$C$15,DCF_Base!$L$19*(1+Assumptions!$C$15)/($A$19-Assumptions!$C$15),0),Assumptions!$C$17*DCF_Base!$L$19))/(1+$A$19)^Assumptions!$B$12-Assumptions!$B$6)/Assumptions!$B$5
A20: 0.1 | B20: =(SUMPRODUCT(DCF_Base!$C$19:$L$19/(1+$A$20)^DCF_Base!$C$4:$L$4)+MAX(0,MIN(IF($A$20>Assumptions!$C$15,DCF_Base!$L$19*(1+Assumptions!$C$15)/($A$20-Assumptions!$C$15),0),Assumptions!$C$17*DCF_Base!$L$19))/(1+$A$20)^Assumptions!$B$12-Assumptions!$B$6)/Assumptions!$B$5
A21: 0.11 | B21: =(SUMPRODUCT(DCF_Base!$C$19:$L$19/(1+$A$21)^DCF_Base!$C$4:$L$4)+MAX(0,MIN(IF($A$21>Assumptions!$C$15,DCF_Base!$L$19*(1+Assumptions!$C$15)/($A$21-Assumptions!$C$15),0),Assumptions!$C$17*DCF_Base!$L$19))/(1+$A$21)^Assumptions!$B$12-Assumptions!$B$6)/Assumptions!$B$5
A22: 0.12 | B22: =(SUMPRODUCT(DCF_Base!$C$19:$L$19/(1+$A$22)^DCF_Base!$C$4:$L$4)+MAX(0,MIN(IF($A$22>Assumptions!$C$15,DCF_Base!$L$19*(1+Assumptions!$C$15)/($A$22-Assumptions!$C$15),0),Assumptions!$C$17*DCF_Base!$L$19))/(1+$A$22)^Assumptions!$B$12-Assumptions!$B$6)/Assumptions!$B$5
A23: 0.15 | B23: =(SUMPRODUCT(DCF_Base!$C$19:$L$19/(1+$A$23)^DCF_Base!$C$4:$L$4)+MAX(0,MIN(IF($A$23>Assumptions!$C$15,DCF_Base!$L$19*(1+Assumptions!$C$15)/($A$23-Assumptions!$C$15),0),Assumptions!$C$17*DCF_Base!$L$19))/(1+$A$23)^Assumptions!$B$12-Assumptions!$B$6)/Assumptions!$B$5 | C23: 15% row -- must equal base entry price F5
A24: =Assumptions!$B$7 | B24: =(SUMPRODUCT(DCF_Base!$C$19:$L$19/(1+$A$24)^DCF_Base!$C$4:$L$4)+MAX(0,MIN(IF($A$24>Assumptions!$C$15,DCF_Base!$L$19*(1+Assumptions!$C$15)/($A$24-Assumptions!$C$15),0),Assumptions!$C$17*DCF_Base!$L$19))/(1+$A$24)^Assumptions!$B$12-Assumptions!$B$6)/Assumptions!$B$5 | C24: model WACC row -- must equal DCF_Base!B38
A27: Sensitivity: base-case value per share, WACC (rows) x terminal growth (columns)
B28: 0.02 | C28: 0.025 | D28: 0.03 | E28: 0.035 | F28: 0.04
A29: 0.08 | B29: =IF($A$29>B$28,(SUMPRODUCT(DCF_Base!$C$19:$L$19/(1+$A$29)^DCF_Base!$C$4:$L$4)+MAX(0,MIN(IF($A$29>B$28,DCF_Base!$L$19*(1+B$28)/($A$29-B$28),0),Assumptions!$C$17*DCF_Base!$L$19))/(1+$A$29)^Assumptions!$B$12-Assumptions!$B$6)/Assumptions!$B$5,"n/a") | C29: =IF($A$29>C$28,(SUMPRODUCT(DCF_Base!$C$19:$L$19/(1+$A$29)^DCF_Base!$C$4:$L$4)+MAX(0,MIN(IF($A$29>C$28,DCF_Base!$L$19*(1+C$28)/($A$29-C$28),0),Assumptions!$C$17*DCF_Base!$L$19))/(1+$A$29)^Assumptions!$B$12-Assumptions!$B$6)/Assumptions!$B$5,"n/a") | D29: =IF($A$29>D$28,(SUMPRODUCT(DCF_Base!$C$19:$L$19/(1+$A$29)^DCF_Base!$C$4:$L$4)+MAX(0,MIN(IF($A$29>D$28,DCF_Base!$L$19*(1+D$28)/($A$29-D$28),0),Assumptions!$C$17*DCF_Base!$L$19))/(1+$A$29)^Assumptions!$B$12-Assumptions!$B$6)/Assumptions!$B$5,"n/a") | E29: =IF($A$29>E$28,(SUMPRODUCT(DCF_Base!$C$19:$L$19/(1+$A$29)^DCF_Base!$C$4:$L$4)+MAX(0,MIN(IF($A$29>E$28,DCF_Base!$L$19*(1+E$28)/($A$29-E$28),0),Assumptions!$C$17*DCF_Base!$L$19))/(1+$A$29)^Assumptions!$B$12-Assumptions!$B$6)/Assumptions!$B$5,"n/a") | F29: =IF($A$29>F$28,(SUMPRODUCT(DCF_Base!$C$19:$L$19/(1+$A$29)^DCF_Base!$C$4:$L$4)+MAX(0,MIN(IF($A$29>F$28,DCF_Base!$L$19*(1+F$28)/($A$29-F$28),0),Assumptions!$C$17*DCF_Base!$L$19))/(1+$A$29)^Assumptions!$B$12-Assumptions!$B$6)/Assumptions!$B$5,"n/a")
A30: 0.09 | B30: =IF($A$30>B$28,(SUMPRODUCT(DCF_Base!$C$19:$L$19/(1+$A$30)^DCF_Base!$C$4:$L$4)+MAX(0,MIN(IF($A$30>B$28,DCF_Base!$L$19*(1+B$28)/($A$30-B$28),0),Assumptions!$C$17*DCF_Base!$L$19))/(1+$A$30)^Assumptions!$B$12-Assumptions!$B$6)/Assumptions!$B$5,"n/a") | C30: =IF($A$30>C$28,(SUMPRODUCT(DCF_Base!$C$19:$L$19/(1+$A$30)^DCF_Base!$C$4:$L$4)+MAX(0,MIN(IF($A$30>C$28,DCF_Base!$L$19*(1+C$28)/($A$30-C$28),0),Assumptions!$C$17*DCF_Base!$L$19))/(1+$A$30)^Assumptions!$B$12-Assumptions!$B$6)/Assumptions!$B$5,"n/a") | D30: =IF($A$30>D$28,(SUMPRODUCT(DCF_Base!$C$19:$L$19/(1+$A$30)^DCF_Base!$C$4:$L$4)+MAX(0,MIN(IF($A$30>D$28,DCF_Base!$L$19*(1+D$28)/($A$30-D$28),0),Assumptions!$C$17*DCF_Base!$L$19))/(1+$A$30)^Assumptions!$B$12-Assumptions!$B$6)/Assumptions!$B$5,"n/a") | E30: =IF($A$30>E$28,(SUMPRODUCT(DCF_Base!$C$19:$L$19/(1+$A$30)^DCF_Base!$C$4:$L$4)+MAX(0,MIN(IF($A$30>E$28,DCF_Base!$L$19*(1+E$28)/($A$30-E$28),0),Assumptions!$C$17*DCF_Base!$L$19))/(1+$A$30)^Assumptions!$B$12-Assumptions!$B$6)/Assumptions!$B$5,"n/a") | F30: =IF($A$30>F$28,(SUMPRODUCT(DCF_Base!$C$19:$L$19/(1+$A$30)^DCF_Base!$C$4:$L$4)+MAX(0,MIN(IF($A$30>F$28,DCF_Base!$L$19*(1+F$28)/($A$30-F$28),0),Assumptions!$C$17*DCF_Base!$L$19))/(1+$A$30)^Assumptions!$B$12-Assumptions!$B$6)/Assumptions!$B$5,"n/a")
A31: 0.1 | B31: =IF($A$31>B$28,(SUMPRODUCT(DCF_Base!$C$19:$L$19/(1+$A$31)^DCF_Base!$C$4:$L$4)+MAX(0,MIN(IF($A$31>B$28,DCF_Base!$L$19*(1+B$28)/($A$31-B$28),0),Assumptions!$C$17*DCF_Base!$L$19))/(1+$A$31)^Assumptions!$B$12-Assumptions!$B$6)/Assumptions!$B$5,"n/a") | C31: =IF($A$31>C$28,(SUMPRODUCT(DCF_Base!$C$19:$L$19/(1+$A$31)^DCF_Base!$C$4:$L$4)+MAX(0,MIN(IF($A$31>C$28,DCF_Base!$L$19*(1+C$28)/($A$31-C$28),0),Assumptions!$C$17*DCF_Base!$L$19))/(1+$A$31)^Assumptions!$B$12-Assumptions!$B$6)/Assumptions!$B$5,"n/a") | D31: =IF($A$31>D$28,(SUMPRODUCT(DCF_Base!$C$19:$L$19/(1+$A$31)^DCF_Base!$C$4:$L$4)+MAX(0,MIN(IF($A$31>D$28,DCF_Base!$L$19*(1+D$28)/($A$31-D$28),0),Assumptions!$C$17*DCF_Base!$L$19))/(1+$A$31)^Assumptions!$B$12-Assumptions!$B$6)/Assumptions!$B$5,"n/a") | E31: =IF($A$31>E$28,(SUMPRODUCT(DCF_Base!$C$19:$L$19/(1+$A$31)^DCF_Base!$C$4:$L$4)+MAX(0,MIN(IF($A$31>E$28,DCF_Base!$L$19*(1+E$28)/($A$31-E$28),0),Assumptions!$C$17*DCF_Base!$L$19))/(1+$A$31)^Assumptions!$B$12-Assumptions!$B$6)/Assumptions!$B$5,"n/a") | F31: =IF($A$31>F$28,(SUMPRODUCT(DCF_Base!$C$19:$L$19/(1+$A$31)^DCF_Base!$C$4:$L$4)+MAX(0,MIN(IF($A$31>F$28,DCF_Base!$L$19*(1+F$28)/($A$31-F$28),0),Assumptions!$C$17*DCF_Base!$L$19))/(1+$A$31)^Assumptions!$B$12-Assumptions!$B$6)/Assumptions!$B$5,"n/a")
A32: 0.11 | B32: =IF($A$32>B$28,(SUMPRODUCT(DCF_Base!$C$19:$L$19/(1+$A$32)^DCF_Base!$C$4:$L$4)+MAX(0,MIN(IF($A$32>B$28,DCF_Base!$L$19*(1+B$28)/($A$32-B$28),0),Assumptions!$C$17*DCF_Base!$L$19))/(1+$A$32)^Assumptions!$B$12-Assumptions!$B$6)/Assumptions!$B$5,"n/a") | C32: =IF($A$32>C$28,(SUMPRODUCT(DCF_Base!$C$19:$L$19/(1+$A$32)^DCF_Base!$C$4:$L$4)+MAX(0,MIN(IF($A$32>C$28,DCF_Base!$L$19*(1+C$28)/($A$32-C$28),0),Assumptions!$C$17*DCF_Base!$L$19))/(1+$A$32)^Assumptions!$B$12-Assumptions!$B$6)/Assumptions!$B$5,"n/a") | D32: =IF($A$32>D$28,(SUMPRODUCT(DCF_Base!$C$19:$L$19/(1+$A$32)^DCF_Base!$C$4:$L$4)+MAX(0,MIN(IF($A$32>D$28,DCF_Base!$L$19*(1+D$28)/($A$32-D$28),0),Assumptions!$C$17*DCF_Base!$L$19))/(1+$A$32)^Assumptions!$B$12-Assumptions!$B$6)/Assumptions!$B$5,"n/a") | E32: =IF($A$32>E$28,(SUMPRODUCT(DCF_Base!$C$19:$L$19/(1+$A$32)^DCF_Base!$C$4:$L$4)+MAX(0,MIN(IF($A$32>E$28,DCF_Base!$L$19*(1+E$28)/($A$32-E$28),0),Assumptions!$C$17*DCF_Base!$L$19))/(1+$A$32)^Assumptions!$B$12-Assumptions!$B$6)/Assumptions!$B$5,"n/a") | F32: =IF($A$32>F$28,(SUMPRODUCT(DCF_Base!$C$19:$L$19/(1+$A$32)^DCF_Base!$C$4:$L$4)+MAX(0,MIN(IF($A$32>F$28,DCF_Base!$L$19*(1+F$28)/($A$32-F$28),0),Assumptions!$C$17*DCF_Base!$L$19))/(1+$A$32)^Assumptions!$B$12-Assumptions!$B$6)/Assumptions!$B$5,"n/a")
A33: 0.12 | B33: =IF($A$33>B$28,(SUMPRODUCT(DCF_Base!$C$19:$L$19/(1+$A$33)^DCF_Base!$C$4:$L$4)+MAX(0,MIN(IF($A$33>B$28,DCF_Base!$L$19*(1+B$28)/($A$33-B$28),0),Assumptions!$C$17*DCF_Base!$L$19))/(1+$A$33)^Assumptions!$B$12-Assumptions!$B$6)/Assumptions!$B$5,"n/a") | C33: =IF($A$33>C$28,(SUMPRODUCT(DCF_Base!$C$19:$L$19/(1+$A$33)^DCF_Base!$C$4:$L$4)+MAX(0,MIN(IF($A$33>C$28,DCF_Base!$L$19*(1+C$28)/($A$33-C$28),0),Assumptions!$C$17*DCF_Base!$L$19))/(1+$A$33)^Assumptions!$B$12-Assumptions!$B$6)/Assumptions!$B$5,"n/a") | D33: =IF($A$33>D$28,(SUMPRODUCT(DCF_Base!$C$19:$L$19/(1+$A$33)^DCF_Base!$C$4:$L$4)+MAX(0,MIN(IF($A$33>D$28,DCF_Base!$L$19*(1+D$28)/($A$33-D$28),0),Assumptions!$C$17*DCF_Base!$L$19))/(1+$A$33)^Assumptions!$B$12-Assumptions!$B$6)/Assumptions!$B$5,"n/a") | E33: =IF($A$33>E$28,(SUMPRODUCT(DCF_Base!$C$19:$L$19/(1+$A$33)^DCF_Base!$C$4:$L$4)+MAX(0,MIN(IF($A$33>E$28,DCF_Base!$L$19*(1+E$28)/($A$33-E$28),0),Assumptions!$C$17*DCF_Base!$L$19))/(1+$A$33)^Assumptions!$B$12-Assumptions!$B$6)/Assumptions!$B$5,"n/a") | F33: =IF($A$33>F$28,(SUMPRODUCT(DCF_Base!$C$19:$L$19/(1+$A$33)^DCF_Base!$C$4:$L$4)+MAX(0,MIN(IF($A$33>F$28,DCF_Base!$L$19*(1+F$28)/($A$33-F$28),0),Assumptions!$C$17*DCF_Base!$L$19))/(1+$A$33)^Assumptions!$B$12-Assumptions!$B$6)/Assumptions!$B$5,"n/a")
A35: Sanity check by hand: the 10%/3% cell (D31) equals DCF_Base!B38; the 15% row of the required-return table equals the base entry price.
