Workbook

Sheet Model_Info
A1: RECORDATI (REC.MI) — DCF MODEL
A3: Version | B3: v1.0 — first build for this ticker. Supersedes nothing.
A4: Built by | B4: dcf-analyst agent (Claude Opus 5), 2026-08-29, at the user request in the Stocks/Research project.
A5: Model type | B5: Deal-state weighted (live take-private) with a standalone owner-FCF DCF as the no-deal anchor.
A6: Routing | B6: SKILL.md routing table -> "Live takeover, scheme, strategic review" -> deal-completes vs deal-breaks weighting, NOT three growth scenarios.
A8: THE CENTRAL FACT | B8: REC.MI is DEAL-PINNED. CVC Fund IX + Groupe Bruxelles Lambert, via Respighi BidCo, launched a voluntary all-cash tender offer on 22-May-2026 at EUR 51.29 ex-dividend (EUR 52.00 cum-dividend). Acceptance period 31-Aug to 15-Oct-2026. The market price of EUR 52.65 is ABOVE the offer.
A9: Conclusion | B9: AVOID at EUR 52.65. Weighted IV EUR 50.47 = -4.1%. Risk/reward 4.6:1 AGAINST (make EUR 2.05, risk EUR 9.54).
A11: Price anchor | B11: EUR 52.65, Yahoo regularMarketTime 2026-08-28T15:39:07Z, Euronext Milan regular close. 52-week range 43.76 - 55.15.
A12: Balance sheet anchor | B12: H1-2026, 30-Jun-2026: total debt EUR 2,309.9m less cash EUR 391.4m = net debt EUR 1,918.5m (company NFP EUR 1,917.1m).
A13: Share count anchor | B13: 204.813m = 209.125m issued less 4.312m treasury, H1-2026. Held FLAT.
A14: Guidance anchor | B14: FY2026: revenue EUR 2.73-2.80bn, EBITDA EUR 995m-1.03bn, adj net income EUR 655-685m (reiterated at H1-2026). FY2027 plan: revenue EUR 3.0-3.2bn.
A16: Method: capex | B16: PP&E capex 1.5% of revenue (observed 1.29-1.57%, genuinely stable = maintenance) PLUS a product-rights replenishment charge of 6.5% of revenue set at the observed intangible amortisation rate. FY2025 capex of EUR 85.1m (3.3%) is NOT a run-rate: FY2021-25 total capex averaged 14.35% of revenue.
A17: Method: SBC | B17: SBC EUR 16.5m is ALREADY INSIDE reported EBITDA as an operating expense, so it is NOT deducted again. Deducting it twice is a real error the FY2025 calibration caught. Share count held flat (charge once).
... A27: Colour legend | B27: BLUE = hardcoded input. YELLOW fill = key lever. BLACK = formula. GREEN = cross-sheet link. Green fill = headline output.

Sheet Actuals
A1: REPORTED HISTORY (EUR millions)
A3: Line | B3: FY2019 | C3: FY2020 | D3: FY2021 | E3: FY2022 | F3: FY2023 | G3: FY2024 | H3: FY2025 | I3: H1-2026
A4: Revenue | B4: 1481.8 | C4: 1448.9 | D4: 1580.1 | E4: 1853.3 | F4: 2082.3 | G4: 2341.6 | H4: 2618.4 | I4: 1410.8 | J4: Metrics.csv / filings
A5: EBITDA (company definition) | B5: 544 | C5: 569.3 | D5: 602.3 | E5: 672.8 | F5: 769.6 | G5: 865.8 | H5: 991.1 | I5: 540.2 | J5: before non-recurring + IFRS-3 step-up
A6: EBITDA margin % | B6: 36.7 | C6: 39.3 | D6: 38.1 | E6: 36.3 | F6: 37 | G6: 37 | H6: 37.8 | I6: 38.3 | J6: derived
A7: Operating income | B7: 465.3 | C7: 469 | D7: 490.2 | E7: 437.3 | F7: 558 | G7: 638.9 | H7: 670.8 | I7: 419.2 | J7: income statement
A8: Net income | B8: 368.8 | C8: 355 | D8: 291.3 | E8: 271.8 | F8: 365.1 | G8: 416.5 | H8: 443.6 | I8: 269.7 | J8: attributable; NCI = 0
A9: Operating cash flow | B9: 318.7 | C9: 403.6 | D9: 491.6 | E9: 461.7 | F9: 485.3 | G9: 569.9 | H9: 596.9 | I9: 320 | J9: cash flow statement
A10: Capex (total, reported) | B10: -443.3 | C10: -131.7 | D10: -87.4 | E10: -96.3 | F10: -383.3 | G10: -851.2 | H10: -85.1 | I10: -78.8 | J10: PP&E + intangibles
A11: of which PP&E | D11: -21.9 | E11: -23.9 | F11: -29.7 | G11: -36.6 | H11: -39.4 | J11: stable 1.29-1.57% of revenue
A12: of which intangibles | D12: -65.5 | E12: -72.5 | F12: -353.6 | G12: -814.5 | H12: -45.7 | J12: lumpy 1.74%-34.79% of revenue
A13: Reported free cash flow | B13: -124.6 | C13: 271.9 | D13: 404.3 | E13: 365.4 | F13: 102.1 | G13: -281.2 | H13: 511.8 | I13: 241.2 | J13: OCF + capex
A14: SBC (equity-settled) | B14: 7 | C14: 4.9 | D14: 5.1 | E14: 8.3 | F14: 10.9 | G14: 16.5 | H14: 16.5 | I14: 23.6 | J14: inside EBITDA already
A15: Shareholders equity | B15: 1198.8 | C15: 1276.3 | D15: 1381.6 | E15: 1546.2 | F15: 1686.4 | G15: 1876.8 | H15: 1919.8 | I15: 2130.6 | J15: balance sheet
A16: Total debt | B16: 1100.6 | C16: 1061.1 | D16: 992.2 | E16: 1716.5 | F16: 1808.9 | G16: 2484.4 | H16: 2467.5 | I16: 2309.9 | J16: balance sheet
A17: Cash | B17: 187.9 | C17: 188.2 | D17: 244.6 | E17: 284.7 | F17: 221.8 | G17: 322.4 | H17: 428.8 | I17: 391.4 | J17: balance sheet
A18: Net debt | B18: 912.7 | C18: 872.9 | D18: 747.6 | E18: 1431.8 | F18: 1587.1 | G18: 2162 | H18: 2038.7 | I18: 1918.5 | J18: debt less cash
A20: CAPEX SPLIT — the key modelling judgment
A21: PP&E capex, FY2021-25 aggregate % of revenue | B21: 1.45 | D21: genuine maintenance; remarkably stable
A22: Intangible capex, FY2021-25 aggregate % of revenue | B22: 12.9 | D22: product rights / licences; lumpy and M&A-driven
A23: Total capex, FY2021-25 aggregate % of revenue | B23: 14.35 | D23: FY2025 alone was only 3.25%
A24: Intangible AMORTISATION, FY2025 % of revenue | B24: 6.49 | D24: the economic replenishment rate used in the model
A25: FY2019-25 aggregate operating cash flow (EURm) | B25: 3327.8 | D25: versus owner FCF of only 1180.3
A26: FY2019-25 aggregate owner FCF (EURm) | B26: 1180.3 | D26: the gap IS the acquisition spend
A28: GUIDANCE (reiterated at H1-2026)
A29: FY2026 revenue low (EURm) | B29: 2730
A30: FY2026 revenue high (EURm) | B30: 2800
A31: FY2026 EBITDA low (EURm) | B31: 995
A32: FY2026 EBITDA high (EURm) | B32: 1030
A33: FY2026 adj net income low (EURm) | B33: 655
A34: FY2026 adj net income high (EURm) | B34: 685
A35: FY2027 plan revenue low (EURm) | B35: 3000
A36: FY2027 plan revenue high (EURm) | B36: 3200
A38: DEAL TERMS
A39: Offer price ex-dividend (EUR) | B39: 51.29
A40: Offer price cum-dividend equivalent (EUR) | B40: 52
A41: Bidder | B41: Respighi BidCo (CVC Fund IX + Groupe Bruxelles Lambert)
A42: Rossini S.a r.l. irrevocable stake % | B42: 46.82
A43: Minimum acceptance threshold % | B43: 66.67
A44: Acceptance period | B44: 31-Aug-2026 to 15-Oct-2026
...

Sheet Assumptions
A1: GLOBAL ASSUMPTIONS
A3: Driver | B3: Value | E3: Note
A4: WACC (EUR-denominated) | B4: 0.078 | E4: CoE 8.75% x 82.9% + post-tax Kd 2.95% x 17.1% = 7.76%, applied as 7.8%
A5: risk-free (10y BTP) | B5: 0.035 | E5: EUR risk-free matching EUR flows
A6: beta | B6: 0.75 | E6: defensive pharma
A7: equity risk premium | B7: 0.05 | E7: EUR ERP
A8: premium: EM/FX | B8: 0.006 | E8: Turkiye IAS 29 hyperinflation; Russia/CIS ~7.2% of revenue
A9: premium: acquisition-dependence | B9: 0.005 | E9: growth algorithm requires continuous bolt-ons
A10: premium: drug pricing / AIFA payback | B10: 0.004 | E10: EUR 12.8m Urorec settlement Q3-2025
A11: cost of equity | B11: 0.0875 | E11: sum of the above
A12: pre-tax cost of debt | B12: 0.0386 | E12: FY2025 interest paid 95.6 / avg gross debt 2476
A13: effective tax rate | B13: 0.237 | E13: FY2025 reported
A14: PP&E capex % of revenue | B14: 0.015 | E14: maintenance; observed 1.29-1.57%
A15: Product-rights replenishment % of revenue | B15: 0.065 | E15: KEY LEVER — set at observed intangible amortisation 6.49%
... A21: FY2025 revenue base (EURm) | B21: 2618.4 | E21: FY0 for the standalone projection
A23: SCENARIOS (deal states)
A24: Item | B24: Bear | C24: Base | D24: Bull
A25: Standalone terminal growth | B25: 0.013 | C25: 0.018 | D25: 0.022
A26: Deal-state probability weight | B26: 0.1 | C26: 0.78 | D26: 0.12
A27: Weights check (must be 100%) | B27: =SUM(B26:D26)
A29: DEAL-STATE CONSIDERATION
A30: Item | B30: Bear (break) | C30: Base (completes) | D30: Bull (bump)
A31: Consideration / reversion price (EUR) | B31: 43.65 | C31: 51.29 | D31: 55.5
A32: Years to settlement | B32: 0.15 | C32: 0.3 | D32: 0.42
A33: Discount rate | B33: 0.0875 | C33: 0.035 | D33: 0.035
A34: PV of deal-state payoff (EUR/share) | B34: =B31/(1+B33)^B32 | C34: =C31/(1+C33)^C32 | D34: =D31/(1+D33)^D32
A36: SCENARIO NARRATIVES
A37: Base (78%) — deal completes | B37: Respighi BidCo acquires Recordati at EUR 51.29 ex-dividend, settling Q4-2026. Rossini S.a r.l. holds a 46.82% IRREVOCABLE commitment, taking the consortium most of the way to the 66.67% minimum before a single minority share is tendered. Luxinva (ADIA), CPP Investments and Andrea Recordati are reinvesting rather than selling. CONSOB approved the offer document 8-Jul-2026; six of ten directors judged it fair. A buyer at EUR 52.65 pays 52.65 to receive 51.29 — a NEGATIVE outcome, stated plainly.
A38: Bull (12%) — bumped | B38: The consortium fails to reach 66.67% on the initial terms, or the four dissenting independent directors mobilise enough minority resistance, or a competing bidder emerges; the offer is raised to ~EUR 55.50. Anchored on the dissent, on the standalone bull DCF of EUR 55.85, and on the EUR 55.15 52-week high the market actually paid within the last year. Deliberately set BELOW the standalone bull IV so the bump is supportable by fundamentals.
A39: Bear (10%) — deal breaks | B39: Antitrust or Italian golden-power/FDI clearance is refused on a nationally-sensitive pharmaceutical asset, financing fails, or acceptances fall short of 66.67% with no bump forthcoming. The price reverts toward a blend of the EUR 45.40 undisturbed pre-announcement level and the EUR 41.52 standalone DCF, landing near EUR 43.65. Note the standalone value sits BELOW the undisturbed price: the market was already paying more than these fundamentals support before the bid.
A40: Standalone axes (no-deal branch) | B40: Bull: Isturisa delivers on the doubled >EUR 1.2bn peak-sales guidance across the expanded non-overt Cushing s label, Enjaymo keeps compounding, and the FY2027 plan (revenue EUR 3.0-3.2bn) is met. Bear: the Specialty & Primary Care half (~57-59% of revenue) keeps eroding — Cardicor licence loss, lercanidipine, Seloken -12.8% in H1-2026 — Isturisa uptake disappoints or draws payer pushback, and the company must spend MORE on product rights just to stand still.

Sheet DCF_Bear
A1: STANDALONE OWNER-FCF DCF — BEAR (EUR m)
A2: This is the NO-DEAL anchor, not the headline value. See Valuation.
A3: Year | B3: 2025A | C3: 2026E | D3: 2027E | E3: 2028E | F3: 2029E | G3: 2030E | H3: 2031E | I3: 2032E | J3: 2033E | K3: 2034E | L3: 2035E
A4: Year index | B4: 0 | C4: 1 | D4: 2 | E4: 3 | F4: 4 | G4: 5 | H4: 6 | I4: 7 | J4: 8 | K4: 9 | L4: 10
A5: Revenue growth YoY | C5: 0.043 | D5: 0.035 | E5: 0.025 | F5: 0.02 | G5: 0.018 | H5: 0.015 | I5: 0.015 | J5: 0.012 | K5: 0.01 | L5: 0.01
A6: Revenue | B6: =Assumptions!$B$21 | C6: =B6*(1+C5) | D6: =C6*(1+D5) | E6: =D6*(1+E5) | F6: =E6*(1+F5) | G6: =F6*(1+G5) | H6: =G6*(1+H5) | I6: =H6*(1+I5) | J6: =I6*(1+J5) | ... L6: =K6*(1+L5)
A7: EBITDA margin | C7: 0.36 | D7: 0.356 | E7: 0.352 | F7: 0.35 | G7: 0.348 | H7: 0.347 | I7: 0.346 | J7: 0.345 | K7: 0.345 | L7: 0.345
A8: Adjusted EBITDA (net of SBC) | C8: =C6*C7 | D8: =D6*D7 | E8: =E6*E7 | F8: =F6*F7 | G8: =G6*G7 | H8: =H6*H7 | I8: =I6*I7 | J8: =J6*J7 | ... L8: =L6*L7
A9: SBC % of revenue (memo — inside EBITDA) | C9: 0.0075 | D9: 0.0072 | E9: 0.007 | F9: 0.0068 | G9: 0.0066 | H9: 0.0064 | I9: 0.0062 | J9: 0.006 | K9: 0.006 | L9: 0.006
A10: SBC (memo, not deducted again) | C10: =C6*C9 | D10: =D6*D9 | E10: =E6*E9 | F10: =F6*F9 | G10: =G6*G9 | H10: =H6*H9 | I10: =I6*I9 | J10: =J6*J9 | ... L10: =L6*L9
A11: D&A % of revenue | C11: 0.083 | D11: 0.082 | E11: 0.081 | F11: 0.08 | G11: 0.08 | H11: 0.079 | I11: 0.079 | J11: 0.078 | K11: 0.078 | L11: 0.078
A12: D&A | C12: =-C6*C11 | D12: =-D6*D11 | E12: =-E6*E11 | F12: =-F6*F11 | G12: =-G6*G11 | H12: =-H6*H11 | I12: =-I6*I11 | J12: =-J6*J11 | ... L12: =-L6*L11
A13: Non-recurring % of revenue | C13: 0.02 | D13: 0.02 | E13: 0.02 | F13: 0.02 | G13: 0.02 | H13: 0.02 | I13: 0.02 | J13: 0.02 | K13: 0.02 | L13: 0.02
A14: Non-recurring charges | C14: =-C6*C13 | D14: =-D6*D13 | E14: =-E6*E13 | F14: =-F6*F13 | G14: =-G6*G13 | H14: =-H6*H13 | I14: =-I6*I13 | J14: =-J6*J13 | ... L14: =-L6*L13
A15: EBIT after D&A and non-recurring | C15: =C8+C12+C14 | D15: =D8+D12+D14 | E15: =E8+E12+E14 | F15: =F8+F12+F14 | G15: =G8+G12+G14 | H15: =H8+H12+H14 | I15: =I8+I12+I14 | J15: =J8+J12+J14 | ... L15: =L8+L12+L14
A16: Cash tax rate | C16: 0.245 | D16: 0.245 | E16: 0.245 | F16: 0.245 | G16: 0.245 | H16: 0.245 | I16: 0.245 | J16: 0.245 | K16: 0.245 | L16: 0.245
A17: NOPAT | C17: =C15*(1-C16) | D17: =D15*(1-D16) | E17: =E15*(1-E16) | F17: =F15*(1-F16) | G17: =G15*(1-G16) | H17: =H15*(1-H16) | I17: =I15*(1-I16) | J17: =J15*(1-J16) | ... L17: =L15*(1-L16)
A18: add back D&A | C18: =-C12 | D18: =-D12 | E18: =-E12 | F18: =-F12 | G18: =-G12 | H18: =-H12 | I18: =-I12 | J18: =-J12 | ... L18: =-L12
A19: less PP&E capex | C19: =-C6*C28 | D19: =-D6*D28 | E19: =-E6*E28 | F19: =-F6*F28 | G19: =-G6*G28 | H19: =-H6*H28 | I19: =-I6*I28 | J19: =-J6*J28 | ... L19: =-L6*L28
A20: less product-rights replenishment | C20: =-C6*C29 | D20: =-D6*D29 | E20: =-E6*E29 | F20: =-F6*F29 | G20: =-G6*G29 | H20: =-H6*H29 | I20: =-I6*I29 | J20: =-J6*J29 | ... L20: =-L6*L29
A21: less lease principal | C21: =-C6*Assumptions!$B$16 | D21: =-D6*Assumptions!$B$16 | E21: =-E6*Assumptions!$B$16 | F21: =-F6*Assumptions!$B$16 | G21: =-G6*Assumptions!$B$16 | H21: =-H6*Assumptions!$B$16 | I21: =-I6*Assumptions!$B$16 | J21: =-J6*Assumptions!$B$16 | ... L21: =-L6*Assumptions!$B$16
A22: add working capital | C22: =-0.35*(C6-B6) | D22: =-0.35*(D6-C6) | E22: =-0.35*(E6-D6) | F22: =-0.35*(F6-E6) | G22: =-0.35*(G6-F6) | H22: =-0.35*(H6-G6) | I22: =-0.35*(I6-H6) | J22: =-0.35*(J6-I6) | ... L22: =-0.35*(L6-K6)
A23: OWNER FREE CASH FLOW | C23: =C17+C18+C19+C20+C21+C22 | D23: =D17+D18+D19+D20+D21+D22 | E23: =E17+E18+E19+E20+E21+E22 | F23: =F17+F18+F19+F20+F21+F22 | G23: =G17+G18+G19+G20+G21+G22 | H23: =H17+H18+H19+H20+H21+H22 | I23: =I17+I18+I19+I20+I21+I22 | J23: =J17+J18+J19+J20+J21+J22 | ... L23: =L17+L18+L19+L20+L21+L22
A24: Discount factor | C24: =1/(1+Assumptions!$B$4)^C4 | D24: =1/(1+Assumptions!$B$4)^D4 | E24: =1/(1+Assumptions!$B$4)^E4 | F24: =1/(1+Assumptions!$B$4)^F4 | G24: =1/(1+Assumptions!$B$4)^G4 | H24: =1/(1+Assumptions!$B$4)^H4 | I24: =1/(1+Assumptions!$B$4)^I4 | J24: =1/(1+Assumptions!$B$4)^J4 | ... L24: =1/(1+Assumptions!$B$4)^L4
A25: PV of FCF | C25: =C23*C24 | D25: =D23*D24 | E25: =E23*E24 | F25: =F23*F24 | G25: =G23*G24 | H25: =H23*H24 | I25: =I23*I24 | J25: =J23*J24 | ... L25: =L23*L24
A27: Memo: owner FCF margin | C27: =C23/C6 | D27: =D23/D6 | E27: =E23/E6 | F27: =F23/F6 | G27: =G23/G6 | H27: =H23/H6 | I27: =I23/I6 | J27: =J23/J6 | ... L27: =L23/L6
A28: PP&E capex % of revenue (driver) | C28: 0.015 | D28: 0.015 | E28: 0.015 | F28: 0.015 | G28: 0.015 | H28: 0.015 | I28: 0.015 | J28: 0.015 | K28: 0.015 | L28: 0.015
A29: Product-rights replenishment % of revenue (driver) | C29: 0.07 | D29: 0.07 | E29: 0.07 | F29: 0.07 | G29: 0.07 | H29: 0.07 | I29: 0.07 | J29: 0.07 | K29: 0.07 | L29: 0.07
A30: Sum of PV of FCF | B30: =SUM(C25:L25)
A31: Terminal growth | B31: =Assumptions!$B$25
A32: Terminal-year FCF grown | B32: =L23*(1+B31)
A33: Gordon terminal value | B33: =B32/(Assumptions!$B$4-B31)
A34: Cap terminal value (18x) | B34: =Assumptions!$B$20*L23
A35: Terminal value used | B35: =MAX(0,MIN(B33,B34))
A36: Implied exit multiple | B36: =B35/L23
A37: PV of terminal value | B37: =B35*L24
A38: Enterprise value | B38: =B30+B37
A39: less net debt | B39: =-Assumptions!$B$17
A40: Equity value | B40: =B38+B39
A41: Diluted shares (m) | B41: =Assumptions!$B$18
...

Sheet DCF_Base
A1: STANDALONE OWNER-FCF DCF — BASE (EUR m)
A2: This is the NO-DEAL anchor, not the headline value. See Valuation.
A3: Year | B3: 2025A | C3: 2026E | D3: 2027E | E3: 2028E | F3: 2029E | G3: 2030E | H3: 2031E | I3: 2032E | J3: 2033E | K3: 2034E | L3: 2035E
A4: Year index | B4: 0 | C4: 1 | D4: 2 | E4: 3 | F4: 4 | G4: 5 | H4: 6 | I4: 7 | J4: 8 | K4: 9 | L4: 10
A5: Revenue growth YoY | C5: 0.056 | D5: 0.07 | E5: 0.05 | F5: 0.042 | G5: 0.038 | H5: 0.034 | I5: 0.03 | J5: 0.027 | K5: 0.024 | L5: 0.022
A6: Revenue | B6: =Assumptions!$B$21 | C6: =B6*(1+C5) | D6: =C6*(1+D5) | E6: =D6*(1+E5) | F6: =E6*(1+F5) | G6: =F6*(1+G5) | H6: =G6*(1+H5) | I6: =H6*(1+I5) | J6: =I6*(1+J5) | ... L6: =K6*(1+L5)
A7: EBITDA margin | C7: 0.366 | D7: 0.37 | E7: 0.373 | F7: 0.375 | G7: 0.376 | H7: 0.376 | I7: 0.376 | J7: 0.375 | K7: 0.374 | L7: 0.373
A8: Adjusted EBITDA (net of SBC) | C8: =C6*C7 | D8: =D6*D7 | E8: =E6*E7 | F8: =F6*F7 | G8: =G6*G7 | H8: =H6*H7 | I8: =I6*I7 | J8: =J6*J7 | ... L8: =L6*L7
A9: SBC % of revenue (memo — inside EBITDA) | C9: 0.0075 | D9: 0.0072 | E9: 0.007 | F9: 0.0068 | G9: 0.0066 | H9: 0.0064 | I9: 0.0062 | J9: 0.006 | K9: 0.006 | L9: 0.006
A10: SBC (memo, not deducted again) | C10: =C6*C9 | D10: =D6*D9 | E10: =E6*E9 | F10: =F6*F9 | G10: =G6*G9 | H10: =H6*H9 | I10: =I6*I9 | J10: =J6*J9 | ... L10: =L6*L9
A11: D&A % of revenue | C11: 0.082 | D11: 0.081 | E11: 0.08 | F11: 0.079 | G11: 0.078 | H11: 0.077 | I11: 0.076 | J11: 0.075 | K11: 0.075 | L11: 0.075
A12: D&A | C12: =-C6*C11 | D12: =-D6*D11 | E12: =-E6*E11 | F12: =-F6*F11 | G12: =-G6*G11 | H12: =-H6*H11 | I12: =-I6*I11 | J12: =-J6*J11 | ... L12: =-L6*L11
A13: Non-recurring % of revenue | C13: 0.015 | D13: 0.015 | E13: 0.015 | F13: 0.015 | G13: 0.015 | H13: 0.015 | I13: 0.015 | J13: 0.015 | K13: 0.015 | L13: 0.015
A14: Non-recurring charges | C14: =-C6*C13 | D14: =-D6*D13 | E14: =-E6*E13 | F14: =-F6*F13 | G14: =-G6*G13 | H14: =-H6*H13 | I14: =-I6*I13 | J14: =-J6*J13 | ... L14: =-L6*L13
A15: EBIT after D&A and non-recurring | C15: =C8+C12+C14 | D15: =D8+D12+D14 | E15: =E8+E12+E14 | F15: =F8+F12+F14 | G15: =G8+G12+G14 | H15: =H8+H12+H14 | I15: =I8+I12+I14 | J15: =J8+J12+J14 | ... L15: =L8+L12+L14
A16: Cash tax rate | C16: 0.24 | D16: 0.24 | E16: 0.24 | F16: 0.24 | G16: 0.24 | H16: 0.24 | I16: 0.24 | J16: 0.24 | K16: 0.24 | L16: 0.24
A17: NOPAT | C17: =C15*(1-C16) | D17: =D15*(1-D16) | E17: =E15*(1-E16) | F17: =F15*(1-F16) | G17: =G15*(1-G16) | H17: =H15*(1-H16) | I17: =I15*(1-I16) | J17: =J15*(1-J16) | ... L17: =L15*(1-L16)
A18: add back D&A | C18: =-C12 | D18: =-D12 | E18: =-E12 | F18: =-F12 | G18: =-G12 | H18: =-H12 | I18: =-I12 | J18: =-J12 | ... L18: =-L12
A19: less PP&E capex | C19: =-C6*C28 | D19: =-D6*D28 | E19: =-E6*E28 | F19: =-F6*F28 | G19: =-G6*G28 | H19: =-H6*H28 | I19: =-I6*I28 | J19: =-J6*J28 | ... L19: =-L6*L28
A20: less product-rights replenishment | C20: =-C6*C29 | D20: =-D6*D29 | E20: =-E6*E29 | F20: =-F6*F29 | G20: =-G6*G29 | H20: =-H6*H29 | I20: =-I6*I29 | J20: =-J6*J29 | ... L20: =-L6*L29
A21: less lease principal | C21: =-C6*Assumptions!$B$16 | D21: =-D6*Assumptions!$B$16 | E21: =-E6*Assumptions!$B$16 | F21: =-F6*Assumptions!$B$16 | G21: =-G6*Assumptions!$B$16 | H21: =-H6*Assumptions!$B$16 | I21: =-I6*Assumptions!$B$16 | J21: =-J6*Assumptions!$B$16 | ... L21: =-L6*Assumptions!$B$16
A22: add working capital | C22: =-0.35*(C6-B6) | D22: =-0.35*(D6-C6) | E22: =-0.35*(E6-D6) | F22: =-0.35*(F6-E6) | G22: =-0.35*(G6-F6) | H22: =-0.35*(H6-G6) | I22: =-0.35*(I6-H6) | J22: =-0.35*(J6-I6) | ... L22: =-0.35*(L6-K6)
A23: OWNER FREE CASH FLOW | C23: =C17+C18+C19+C20+C21+C22 | D23: =D17+D18+D19+D20+D21+D22 | E23: =E17+E18+E19+E20+E21+E22 | F23: =F17+F18+F19+F20+F21+F22 | G23: =G17+G18+G19+G20+G21+G22 | H23: =H17+H18+H19+H20+H21+H22 | I23: =I17+I18+I19+I20+I21+I22 | J23: =J17+J18+J19+J20+J21+J22 | ... L23: =L17+L18+L19+L20+L21+L22
A24: Discount factor | C24: =1/(1+Assumptions!$B$4)^C4 | D24: =1/(1+Assumptions!$B$4)^D4 | E24: =1/(1+Assumptions!$B$4)^E4 | F24: =1/(1+Assumptions!$B$4)^F4 | G24: =1/(1+Assumptions!$B$4)^G4 | H24: =1/(1+Assumptions!$B$4)^H4 | I24: =1/(1+Assumptions!$B$4)^I4 | J24: =1/(1+Assumptions!$B$4)^J4 | ... L24: =1/(1+Assumptions!$B$4)^L4
A25: PV of FCF | C25: =C23*C24 | D25: =D23*D24 | E25: =E23*E24 | F25: =F23*F24 | G25: =G23*G24 | H25: =H23*H24 | I25: =I23*I24 | J25: =J23*J24 | ... L25: =L23*L24
A27: Memo: owner FCF margin | C27: =C23/C6 | D27: =D23/D6 | E27: =E23/E6 | F27: =F23/F6 | G27: =G23/G6 | H27: =H23/H6 | I27: =I23/I6 | J27: =J23/J6 | ... L27: =L23/L6
A28: PP&E capex % of revenue (driver) | C28: 0.015 | D28: 0.015 | E28: 0.015 | F28: 0.015 | G28: 0.015 | H28: 0.015 | I28: 0.015 | J28: 0.015 | K28: 0.015 | L28: 0.015
A29: Product-rights replenishment % of revenue (driver) | C29: 0.065 | D29: 0.065 | E29: 0.065 | F29: 0.065 | G29: 0.065 | H29: 0.065 | I29: 0.065 | J29: 0.065 | K29: 0.065 | L29: 0.065
A30: Sum of PV of FCF | B30: =SUM(C25:L25)
A31: Terminal growth | B31: =Assumptions!$C$25
A32: Terminal-year FCF grown | B32: =L23*(1+B31)
A33: Gordon terminal value | B33: =B32/(Assumptions!$B$4-B31)
A34: Cap terminal value (18x) | B34: =Assumptions!$B$20*L23
A35: Terminal value used | B35: =MAX(0,MIN(B33,B34))
A36: Implied exit multiple | B36: =B35/L23
A37: PV of terminal value | B37: =B35*L24
A38: Enterprise value | B38: =B30+B37
A39: less net debt | B39: =-Assumptions!$B$17
A40: Equity value | B40: =B38+B39
A41: Diluted shares (m) | B41: =Assumptions!$B$18
...

Sheet DCF_Bull
A1: STANDALONE OWNER-FCF DCF — BULL (EUR m)
A2: This is the NO-DEAL anchor, not the headline value. See Valuation.
A3: Year | B3: 2025A | C3: 2026E | D3: 2027E | E3: 2028E | F3: 2029E | G3: 2030E | H3: 2031E | I3: 2032E | J3: 2033E | K3: 2034E | L3: 2035E
A4: Year index | B4: 0 | C4: 1 | D4: 2 | E4: 3 | F4: 4 | G4: 5 | H4: 6 | I4: 7 | J4: 8 | K4: 9 | L4: 10
A5: Revenue growth YoY | C5: 0.069 | D5: 0.095 | E5: 0.075 | F5: 0.06 | G5: 0.05 | H5: 0.045 | I5: 0.04 | J5: 0.035 | K5: 0.03 | L5: 0.025
A6: Revenue | B6: =Assumptions!$B$21 | C6: =B6*(1+C5) | D6: =C6*(1+D5) | E6: =D6*(1+E5) | F6: =E6*(1+F5) | G6: =F6*(1+G5) | H6: =G6*(1+H5) | I6: =H6*(1+I5) | J6: =I6*(1+J5) | ... L6: =K6*(1+L5)
A7: EBITDA margin | C7: 0.373 | D7: 0.382 | E7: 0.388 | F7: 0.392 | G7: 0.395 | H7: 0.395 | I7: 0.395 | J7: 0.394 | K7: 0.393 | L7: 0.392
A8: Adjusted EBITDA (net of SBC) | C8: =C6*C7 | D8: =D6*D7 | E8: =E6*E7 | F8: =F6*F7 | G8: =G6*G7 | H8: =H6*H7 | I8: =I6*I7 | J8: =J6*J7 | ... L8: =L6*L7
A9: SBC % of revenue (memo — inside EBITDA) | C9: 0.0075 | D9: 0.0072 | E9: 0.007 | F9: 0.0068 | G9: 0.0066 | H9: 0.0064 | I9: 0.0062 | J9: 0.006 | K9: 0.006 | L9: 0.006
A10: SBC (memo, not deducted again) | C10: =C6*C9 | D10: =D6*D9 | E10: =E6*E9 | F10: =F6*F9 | G10: =G6*G9 | H10: =H6*H9 | I10: =I6*I9 | J10: =J6*J9 | ... L10: =L6*L9
A11: D&A % of revenue | C11: 0.082 | D11: 0.081 | E11: 0.08 | F11: 0.079 | G11: 0.078 | H11: 0.077 | I11: 0.076 | J11: 0.075 | K11: 0.075 | L11: 0.075
A12: D&A | C12: =-C6*C11 | D12: =-D6*D11 | E12: =-E6*E11 | F12: =-F6*F11 | G12: =-G6*G11 | H12: =-H6*H11 | I12: =-I6*I11 | J12: =-J6*J11 | ... L12: =-L6*L11
A13: Non-recurring % of revenue | C13: 0.012 | D13: 0.012 | E13: 0.012 | F13: 0.012 | G13: 0.012 | H13: 0.012 | I13: 0.012 | J13: 0.012 | K13: 0.012 | L13: 0.012
A14: Non-recurring charges | C14: =-C6*C13 | D14: =-D6*D13 | E14: =-E6*E13 | F14: =-F6*F13 | G14: =-G6*G13 | H14: =-H6*H13 | I14: =-I6*I13 | J14: =-J6*J13 | ... L14: =-L6*L13
A15: EBIT after D&A and non-recurring | C15: =C8+C12+C14 | D15: =D8+D12+D14 | E15: =E8+E12+E14 | F15: =F8+F12+F14 | G15: =G8+G12+G14 | H15: =H8+H12+H14 | I15: =I8+I12+I14 | J15: =J8+J12+J14 | ... L15: =L8+L12+L14
A16: Cash tax rate | C16: 0.235 | D16: 0.235 | E16: 0.235 | F16: 0.235 | G16: 0.235 | H16: 0.235 | I16: 0.235 | J16: 0.235 | K16: 0.235 | L16: 0.235
A17: NOPAT | C17: =C15*(1-C16) | D17: =D15*(1-D16) | E17: =E15*(1-E16) | F17: =F15*(1-F16) | G17: =G15*(1-G16) | H17: =H15*(1-H16) | I17: =I15*(1-I16) | J17: =J15*(1-J16) | ... L17: =L15*(1-L16)
A18: add back D&A | C18: =-C12 | D18: =-D12 | E18: =-E12 | F18: =-F12 | G18: =-G12 | H18: =-H12 | I18: =-I12 | J18: =-J12 | ... L18: =-L12
A19: less PP&E capex | C19: =-C6*C28 | D19: =-D6*D28 | E19: =-E6*E28 | F19: =-F6*F28 | G19: =-G6*G28 | H19: =-H6*H28 | I19: =-I6*I28 | J19: =-J6*J28 | ... L19: =-L6*L28
A20: less product-rights replenishment | C20: =-C6*C29 | D20: =-D6*D29 | E20: =-E6*E29 | F20: =-F6*F29 | G20: =-G6*G29 | H20: =-H6*H29 | I20: =-I6*I29 | J20: =-J6*J29 | ... L20: =-L6*L29
A21: less lease principal | C21: =-C6*Assumptions!$B$16 | D21: =-D6*Assumptions!$B$16 | E21: =-E6*Assumptions!$B$16 | F21: =-F6*Assumptions!$B$16 | G21: =-G6*Assumptions!$B$16 | H21: =-H6*Assumptions!$B$16 | I21: =-I6*Assumptions!$B$16 | J21: =-J6*Assumptions!$B$16 | ... L21: =-L6*Assumptions!$B$16
A22: add working capital | C22: =-0.3*(C6-B6) | D22: =-0.3*(D6-C6) | E22: =-0.3*(E6-D6) | F22: =-0.3*(F6-E6) | G22: =-0.3*(G6-F6) | H22: =-0.3*(H6-G6) | I22: =-0.3*(I6-H6) | J22: =-0.3*(J6-I6) | ... L22: =-0.3*(L6-K6)
A23: OWNER FREE CASH FLOW | C23: =C17+C18+C19+C20+C21+C22 | D23: =D17+D18+D19+D20+D21+D22 | E23: =E17+E18+E19+E20+E21+E22 | F23: =F17+F18+F19+F20+F21+F22 | G23: =G17+G18+G19+G20+G21+G22 | H23: =H17+H18+H19+H20+H21+H22 | I23: =I17+I18+I19+I20+I21+I22 | J23: =J17+J18+J19+J20+J21+J22 | ... L23: =L17+L18+L19+L20+L21+L22
A24: Discount factor | C24: =1/(1+Assumptions!$B$4)^C4 | D24: =1/(1+Assumptions!$B$4)^D4 | E24: =1/(1+Assumptions!$B$4)^E4 | F24: =1/(1+Assumptions!$B$4)^F4 | G24: =1/(1+Assumptions!$B$4)^G4 | H24: =1/(1+Assumptions!$B$4)^H4 | I24: =1/(1+Assumptions!$B$4)^I4 | J24: =1/(1+Assumptions!$B$4)^J4 | ... L24: =1/(1+Assumptions!$B$4)^L4
A25: PV of FCF | C25: =C23*C24 | D25: =D23*D24 | E25: =E23*E24 | F25: =F23*F24 | G25: =G23*G24 | H25: =H23*H24 | I25: =I23*I24 | J25: =J23*J24 | ... L25: =L23*L24
A27: Memo: owner FCF margin | C27: =C23/C6 | D27: =D23/D6 | E27: =E23/E6 | F27: =F23/F6 | G27: =G23/G6 | H27: =H23/H6 | I27: =I23/I6 | J27: =J23/J6 | ... L27: =L23/L6
A28: PP&E capex % of revenue (driver) | C28: 0.015 | D28: 0.015 | E28: 0.015 | F28: 0.015 | G28: 0.015 | H28: 0.015 | I28: 0.015 | J28: 0.015 | K28: 0.015 | L28: 0.015
A29: Product-rights replenishment % of revenue (driver) | C29: 0.06 | D29: 0.06 | E29: 0.06 | F29: 0.06 | G29: 0.06 | H29: 0.06 | I29: 0.06 | J29: 0.06 | K29: 0.06 | L29: 0.06
A30: Sum of PV of FCF | B30: =SUM(C25:L25)
A31: Terminal growth | B31: =Assumptions!$D$25
A32: Terminal-year FCF grown | B32: =L23*(1+B31)
A33: Gordon terminal value | B33: =B32/(Assumptions!$B$4-B31)
A34: Cap terminal value (18x) | B34: =Assumptions!$B$20*L23
A35: Terminal value used | B35: =MAX(0,MIN(B33,B34))
A36: Implied exit multiple | B36: =B35/L23
A37: PV of terminal value | B37: =B35*L24
A38: Enterprise value | B38: =B30+B37
A39: less net debt | B39: =-Assumptions!$B$17
A40: Equity value | B40: =B38+B39
A41: Diluted shares (m) | B41: =Assumptions!$B$18
...

Sheet FCF_Quality
A1: REPORTED FCF RECONCILED TO OWNER FCF (EUR m)
A3: Line | B3: FY2019 | C3: FY2020 | D3: FY2021 | E3: FY2022 | F3: FY2023 | G3: FY2024 | H3: FY2025
A4: Operating cash flow | B4: 318.7 | C4: 403.6 | D4: 491.6 | E4: 461.7 | F4: 485.3 | G4: 569.9 | H4: 596.9
A5: less total capex (as reported) | B5: -443.3 | C5: -131.7 | D5: -87.4 | E5: -96.3 | F5: -383.3 | G5: -851.2 | H5: -85.1
A6: Equals free cash flow (company definition) | B6: =B4+B5 | C6: =C4+C5 | D6: =D4+D5 | E6: =E4+E5 | F6: =F4+F5 | G6: =G4+G5 | H6: =H4+H5
A7: less SBC (memo — already inside EBITDA) | B7: -7 | C7: -4.9 | D7: -5.1 | E7: -8.3 | F7: -10.9 | G7: -16.5 | H7: -16.5
A8: less interest income | D8: -0.3 | E8: -1.9 | F8: -5.1 | G8: -4.8 | H8: -5.7
A9: Equals owner FCF (as-reported capex basis) | B9: =B6+B7+B8 | C9: =C6+C7+C8 | D9: =D6+D7+D8 | E9: =E6+E7+E8 | F9: =F6+F7+F8 | G9: =G6+G7+G8 | H9: =H6+H7+H8
A10: Revenue | B10: 1481.8 | C10: 1448.9 | D10: 1580.1 | E10: 1853.3 | F10: 2082.3 | G10: 2341.6 | H10: 2618.4
A11: Reported FCF margin % | B11: =B6/B10 | C11: =C6/C10 | D11: =D6/D10 | E11: =E6/E10 | F11: =F6/F10 | G11: =G6/G10 | H11: =H6/H10
A12: Owner FCF margin % | B12: =B9/B10 | C12: =C9/C10 | D12: =D9/D10 | E12: =E9/E10 | F12: =F9/F10 | G12: =G9/G10 | H12: =H9/H10
A14: THE REAL ADJUSTMENT: capex normalisation
A15: FY2019-25 aggregate operating cash flow | B15: 3327.8 | D15: seven years of cash generation
A16: FY2019-25 aggregate owner FCF | B16: 1180.3 | D16: only 35% of OCF survived capex
A17: FY2019-25 aggregate capex % of revenue | B17: 15.5 | D17: versus FY2025 alone at 3.25%
A18: FY2025 reported FCF | B18: 511.8 | D18: a quiet M&A year — NOT a run-rate
A19: FY2025 component-built sustainable owner FCF | B19: 359.2 | D19: charging 6.5% product-rights replenishment
A20: Difference (annual overstatement) | B20: 152.6 | D20: the cost of the growth Recordati did not pay for in FY2025
A22: Memo — cash tax rate: FY2025 income taxes paid EUR 174.3m on pre-tax income EUR 581.3m = 30.0% cash rate versus a 23.7% effective book rate. The model uses 24% (base), close to the book rate, because the FY2025 cash rate was inflated by timing of prior-year settlements. Not abnormal enough to require a ramp.
A23: Memo — working capital: FY2025 absorbed EUR 148.2m on a EUR 276.8m revenue increase (inventories -134.8, receivables -63.1, payables +49.8), a 53.5% outflow capture. The model uses a 35% OUTFLOW on the revenue change — working capital is a USE of cash as this business grows, the opposite sign to a prepaid-subscription model.
A24: Memo — SBC: EUR 16.5m is 0.63% of revenue and sits INSIDE reported EBITDA as an operating expense. It is not deducted a second time in the component build. H1-2026 SBC of EUR 23.6m is inflated by takeover-accelerated performance-share vesting and is treated as one-off.

Sheet Valuation
A1: VALUATION SUMMARY — DEAL-STATE WEIGHTED
A2: REC.MI is deal-pinned. The headline scenarios are DEAL STATES, not growth cases.
A4: Deal state | B4: Bear (break) | C4: Base (completes) | D4: Bull (bump) | E4: Weighted
A5: Consideration / reversion (EUR) | B5: =Assumptions!B$31 | C5: =Assumptions!C$31 | D5: =Assumptions!D$31
A6: PV of payoff (EUR/share) | B6: =Assumptions!B$34 | C6: =Assumptions!C$34 | D6: =Assumptions!D$34 | E6: =SUMPRODUCT(B6:D6,B7:D7)
A7: Probability weight | B7: =Assumptions!B$26 | C7: =Assumptions!C$26 | D7: =Assumptions!D$26 | E7: =SUM(B7:D7)
A8: Upside vs current price | B8: =B6/Assumptions!$B$19-1 | C8: =C6/Assumptions!$B$19-1 | D8: =D6/Assumptions!$B$19-1 | E8: =E6/Assumptions!$B$19-1
A9: Standalone DCF anchor (EUR) | B9: =DCF_Bear!$B$42 | C9: =DCF_Base!$B$42 | D9: =DCF_Bull!$B$42 | E9: =SUMPRODUCT(B9:D9,B7:D7)
A11: Current price (EUR) | B11: =Assumptions!$B$19
A12: Margin of safety (negative = overpriced) | B12: =1-Assumptions!$B$19/E6
A13: Band position (house vs street) | B13: n/a — collapses to a point under a fixed cash offer
A15: RISK / REWARD AT THE CURRENT PRICE
A16: Max gain if bumped (EUR/share) | B16: =D6-Assumptions!$B$19
A17: Loss if the deal breaks (EUR/share) | B17: =B6-Assumptions!$B$19
A18: Loss if the deal simply completes (EUR/share) | B18: =C6-Assumptions!$B$19
A19: Ratio against (risk : reward) | B19: =(Assumptions!$B$19-B6)/(D6-Assumptions!$B$19)
A20: Implied IRR at the current price | B20: =(SUMPRODUCT(B5:D5,B7:D7)/Assumptions!$B$19)^(1/0.299)-1
A22: BREAKEVEN ANALYSIS — what must be believed to justify EUR 52.65
A23: Required P(bump) if P(break)=0% | B23: =(Assumptions!$B$19-C6)/(D6-C6)
A24: Required P(bump) if P(break)=5% | B24: =(Assumptions!$B$19-0.05*B6-0.95*C6)/(D6-C6)
A25: Required P(bump) if P(break)=10% | B25: =(Assumptions!$B$19-0.1*B6-0.9*C6)/(D6-C6)
A26: Deal entry price for a 15% IRR (EUR) | B26: =SUMPRODUCT(B5:D5,B7:D7)/(1.15)^0.299
A28: STANDALONE REQUIRED-RETURN TABLE (no-deal branch, base case)
A29: Required return | B29: 7.8% | C29: 9% | D29: 10% | E29: 11% | F29: 12% | G29: 15%
A30: Standalone value per share (EUR) | B30: =(SUMPRODUCT(DCF_Base!C23:L23,1/(1+0.078)^DCF_Base!C4:L4)+DCF_Base!B35/(1+0.078)^10-Assumptions!$B$17)/Assumptions!$B$18 | C30: =(SUMPRODUCT(DCF_Base!C23:L23,1/(1+0.09)^DCF_Base!C4:L4)+DCF_Base!B35/(1+0.09)^10-Assumptions!$B$17)/Assumptions!$B$18 | D30: =(SUMPRODUCT(DCF_Base!C23:L23,1/(1+0.1)^DCF_Base!C4:L4)+DCF_Base!B35/(1+0.1)^10-Assumptions!$B$17)/Assumptions!$B$18 | E30: =(SUMPRODUCT(DCF_Base!C23:L23,1/(1+0.11)^DCF_Base!C4:L4)+DCF_Base!B35/(1+0.11)^10-Assumptions!$B$17)/Assumptions!$B$18 | F30: =(SUMPRODUCT(DCF_Base!C23:L23,1/(1+0.12)^DCF_Base!C4:L4)+DCF_Base!B35/(1+0.12)^10-Assumptions!$B$17)/Assumptions!$B$18 | G30: =(SUMPRODUCT(DCF_Base!C23:L23,1/(1+0.15)^DCF_Base!C4:L4)+DCF_Base!B35/(1+0.15)^10-Assumptions!$B$17)/Assumptions!$B$18
A32: STANDALONE SENSITIVITY — WACC x terminal growth (base case)
A33: WACC \ g | B33: 0.8% | C33: 1.3% | D33: 1.8% | E33: 2.3% | F33: 2.8%
A34: 5.8% | B34: =IF(0.057999999999999996<=0.008,"n/a",(SUMPRODUCT(DCF_Base!C23:L23,1/(1+0.057999999999999996)^DCF_Base!C4:L4)+MAX(0,MIN(DCF_Base!L23*(1+0.008)/(0.057999999999999996-0.008),Assumptions!$B$20*DCF_Base!L23))/(1+0.057999999999999996)^10-Assumptions!$B$17)/Assumptions!$B$18) | C34: =IF(0.057999999999999996<=0.013000000000000001,"n/a",(SUMPRODUCT(DCF_Base!C23:L23,1/(1+0.057999999999999996)^DCF_Base!C4:L4)+MAX(0,MIN(DCF_Base!L23*(1+0.013000000000000001)/(0.057999999999999996-0.013000000000000001),Assumptions!$B$20*DCF_Base!L23))/(1+0.057999999999999996)^10-Assumptions!$B$17)/Assumptions!$B$18) | D34: =IF(0.057999999999999996<=0.018000000000000002,"n/a",(SUMPRODUCT(DCF_Base!C23:L23,1/(1+0.057999999999999996)^DCF_Base!C4:L4)+MAX(0,MIN(DCF_Base!L23*(1+0.018000000000000002)/(0.057999999999999996-0.018000000000000002),Assumptions!$B$20*DCF_Base!L23))/(1+0.057999999999999996)^10-Assumptions!$B$17)/Assumptions!$B$18) | E34: =IF(0.057999999999999996<=0.023,"n/a",(SUMPRODUCT(DCF_Base!C23:L23,1/(1+0.057999999999999996)^DCF_Base!C4:L4)+MAX(0,MIN(DCF_Base!L23*(1+0.023)/(0.057999999999999996-0.023),Assumptions!$B$20*DCF_Base!L23))/(1+0.057999999999999996)^10-Assumptions!$B$17)/Assumptions!$B$18) | F34: =IF(0.057999999999999996<=0.027999999999999997,"n/a",(SUMPRODUCT(DCF_Base!C23:L23,1/(1+0.057999999999999996)^DCF_Base!C4:L4)+MAX(0,MIN(DCF_Base!L23*(1+0.027999999999999997)/(0.057999999999999996-0.027999999999999997),Assumptions!$B$20*DCF_Base!L23))/(1+0.057999999999999996)^10-Assumptions!$B$17)/Assumptions!$B$18)
A35: 6.8% | B35: =IF(0.068<=0.008,"n/a",(SUMPRODUCT(DCF_Base!C23:L23,1/(1+0.068)^DCF_Base!C4:L4)+MAX(0,MIN(DCF_Base!L23*(1+0.008)/(0.068-0.008),Assumptions!$B$20*DCF_Base!L23))/(1+0.068)^10-Assumptions!$B$17)/Assumptions!$B$18) | C35: =IF(0.068<=0.013000000000000001,"n/a",(SUMPRODUCT(DCF_Base!C23:L23,1/(1+0.068)^DCF_Base!C4:L4)+MAX(0,MIN(DCF_Base!L23*(1+0.013000000000000001)/(0.068-0.013000000000000001),Assumptions!$B$20*DCF_Base!L23))/(1+0.068)^10-Assumptions!$B$17)/Assumptions!$B$18) | D35: =IF(0.068<=0.018000000000000002,"n/a",(SUMPRODUCT(DCF_Base!C23:L23,1/(1+0.068)^DCF_Base!C4:L4)+MAX(0,MIN(DCF_Base!L23*(1+0.018000000000000002)/(0.068-0.018000000000000002),Assumptions!$B$20*DCF_Base!L23))/(1+0.068)^10-Assumptions!$B$17)/Assumptions!$B$18) | E35: =IF(0.068<=0.023,"n/a",(SUMPRODUCT(DCF_Base!C23:L23,1/(1+0.068)^DCF_Base!C4:L4)+MAX(0,MIN(DCF_Base!L23*(1+0.023)/(0.068-0.023),Assumptions!$B$20*DCF_Base!L23))/(1+0.068)^10-Assumptions!$B$17)/Assumptions!$B$18) | F35: =IF(0.068<=0.027999999999999997,"n/a",(SUMPRODUCT(DCF_Base!C23:L23,1/(1+0.068)^DCF_Base!C4:L4)+MAX(0,MIN(DCF_Base!L23*(1+0.027999999999999997)/(0.068-0.027999999999999997),Assumptions!$B$20*DCF_Base!L23))/(1+0.068)^10-Assumptions!$B$17)/Assumptions!$B$18)
A36: 7.8% | B36: =IF(0.078<=0.008,"n/a",(SUMPRODUCT(DCF_Base!C23:L23,1/(1+0.078)^DCF_Base!C4:L4)+MAX(0,MIN(DCF_Base!L23*(1+0.008)/(0.078-0.008),Assumptions!$B$20*DCF_Base!L23))/(1+0.078)^10-Assumptions!$B$17)/Assumptions!$B$18) | C36: =IF(0.078<=0.013000000000000001,"n/a",(SUMPRODUCT(DCF_Base!C23:L23,1/(1+0.078)^DCF_Base!C4:L4)+MAX(0,MIN(DCF_Base!L23*(1+0.013000000000000001)/(0.078-0.013000000000000001),Assumptions!$B$20*DCF_Base!L23))/(1+0.078)^10-Assumptions!$B$17)/Assumptions!$B$18) | D36: =IF(0.078<=0.018000000000000002,"n/a",(SUMPRODUCT(DCF_Base!C23:L23,1/(1+0.078)^DCF_Base!C4:L4)+MAX(0,MIN(DCF_Base!L23*(1+0.018000000000000002)/(0.078-0.018000000000000002),Assumptions!$B$20*DCF_Base!L23))/(1+0.078)^10-Assumptions!$B$17)/Assumptions!$B$18) | E36: =IF(0.078<=0.023,"n/a",(SUMPRODUCT(DCF_Base!C23:L23,1/(1+0.078)^DCF_Base!C4:L4)+MAX(0,MIN(DCF_Base!L23*(1+0.023)/(0.078-0.023),Assumptions!$B$20*DCF_Base!L23))/(1+0.078)^10-Assumptions!$B$17)/Assumptions!$B$18) | F36: =IF(0.078<=0.027999999999999997,"n/a",(SUMPRODUCT(DCF_Base!C23:L23,1/(1+0.078)^DCF_Base!C4:L4)+MAX(0,MIN(DCF_Base!L23*(1+0.027999999999999997)/(0.078-0.027999999999999997),Assumptions!$B$20*DCF_Base!L23))/(1+0.078)^10-Assumptions!$B$17)/Assumptions!$B$18)
A37: 8.8% | B37: =IF(0.08800000000000001<=0.008,"n/a",(SUMPRODUCT(DCF_Base!C23:L23,1/(1+0.08800000000000001)^DCF_Base!C4:L4)+MAX(0,MIN(DCF_Base!L23*(1+0.008)/(0.08800000000000001-0.008),Assumptions!$B$20*DCF_Base!L23))/(1+0.08800000000000001)^10-Assumptions!$B$17)/Assumptions!$B$18) | C37: =IF(0.08800000000000001<=0.013000000000000001,"n/a",(SUMPRODUCT(DCF_Base!C23:L23,1/(1+0.08800000000000001)^DCF_Base!C4:L4)+MAX(0,MIN(DCF_Base!L23*(1+0.013000000000000001)/(0.08800000000000001-0.013000000000000001),Assumptions!$B$20*DCF_Base!L23))/(1+0.08800000000000001)^10-Assumptions!$B$17)/Assumptions!$B$18) | D37: =IF(0.08800000000000001<=0.018000000000000002,"n/a",(SUMPRODUCT(DCF_Base!C23:L23,1/(1+0.08800000000000001)^DCF_Base!C4:L4)+MAX(0,MIN(DCF_Base!L23*(1+0.018000000000000002)/(0.08800000000000001-0.018000000000000002),Assumptions!$B$20*DCF_Base!L23))/(1+0.08800000000000001)^10-Assumptions!$B$17)/Assumptions!$B$18) | E37: =IF(0.08800000000000001<=0.023,"n/a",(SUMPRODUCT(DCF_Base!C23:L23,1/(1+0.08800000000000001)^DCF_Base!C4:L4)+MAX(0,MIN(DCF_Base!L23*(1+0.023)/(0.08800000000000001-0.023),Assumptions!$B$20*DCF_Base!L23))/(1+0.08800000000000001)^10-Assumptions!$B$17)/Assumptions!$B$18) | F37: =IF(0.08800000000000001<=0.027999999999999997,"n/a",(SUMPRODUCT(DCF_Base!C23:L23,1/(1+0.08800000000000001)^DCF_Base!C4:L4)+MAX(0,MIN(DCF_Base!L23*(1+0.027999999999999997)/(0.08800000000000001-0.027999999999999997),Assumptions!$B$20*DCF_Base!L23))/(1+0.08800000000000001)^10-Assumptions!$B$17)/Assumptions!$B$18)
A38: 9.8% | B38: =IF(0.098<=0.008,"n/a",(SUMPRODUCT(DCF_Base!C23:L23,1/(1+0.098)^DCF_Base!C4:L4)+MAX(0,MIN(DCF_Base!L23*(1+0.008)/(0.098-0.008),Assumptions!$B$20*DCF_Base!L23))/(1+0.098)^10-Assumptions!$B$17)/Assumptions!$B$18) | C38: =IF(0.098<=0.013000000000000001,"n/a",(SUMPRODUCT(DCF_Base!C23:L23,1/(1+0.098)^DCF_Base!C4:L4)+MAX(0,MIN(DCF_Base!L23*(1+0.013000000000000001)/(0.098-0.013000000000000001),Assumptions!$B$20*DCF_Base!L23))/(1+0.098)^10-Assumptions!$B$17)/Assumptions!$B$18) | D38: =IF(0.098<=0.018000000000000002,"n/a",(SUMPRODUCT(DCF_Base!C23:L23,1/(1+0.098)^DCF_Base!C4:L4)+MAX(0,MIN(DCF_Base!L23*(1+0.018000000000000002)/(0.098-0.018000000000000002),Assumptions!$B$20*DCF_Base!L23))/(1+0.098)^10-Assumptions!$B$17)/Assumptions!$B$18) | E38: =IF(0.098<=0.023,"n/a",(SUMPRODUCT(DCF_Base!C23:L23,1/(1+0.098)^DCF_Base!C4:L4)+MAX(0,MIN(DCF_Base!L23*(1+0.023)/(0.098-0.023),Assumptions!$B$20*DCF_Base!L23))/(1+0.098)^10-Assumptions!$B$17)/Assumptions!$B$18) | F38: =IF(0.098<=0.027999999999999997,"n/a",(SUMPRODUCT(DCF_Base!C23:L23,1/(1+0.098)^DCF_Base!C4:L4)+MAX(0,MIN(DCF_Base!L23*(1+0.027999999999999997)/(0.098-0.027999999999999997),Assumptions!$B$20*DCF_Base!L23))/(1+0.098)^10-Assumptions!$B$17)/Assumptions!$B$18)
A40: Reading the grid: even the most generous corner (5.8% WACC, 2.8% terminal growth) yields roughly EUR 52, barely at the EUR 51.29 offer. No plausible discount-rate / terminal-growth pair makes the standalone business worth materially more than the consortium is paying. Flat rows are the 18x terminal cap binding, which is intended.
A42: CONCLUSION: AVOID at EUR 52.65. The weighted value is below the price under EVERY plausible weighting; a buyer needs a ~48% chance of a bump merely to break even even if the deal cannot break, and 67% at a realistic 10% break risk. Risk/reward is 4.6:1 against.
