Workbook

Sheet Model_Info
A1: TOKAI RIKA (6995.T) - DCF MODEL
A3: Lineage | B3: v1.1, built 14-Aug-2026 by Claude (Fable 5) with Stephen via claude.ai. SUPERSEDES v1.0 (same date). Full stress-test rebuild against the FY2026 tanshin plus the FY2017-FY2026 filing archive (both uploaded this session). UNLIKE Boshoku v1.3, this audit moved the valuation UP: both prior models materially understated the asset side of the bridge.
A5: DATA VINTAGE
A6: FY0 anchors + data integrity | B6: Tanshin 15-May-26 (J-GAAP, English). Restatement quantified against original filings: FY23/FY24 OP identical, FY25 OP -0.5% (35,439->35,270), net trimmed -0.2% to -6.3% (FY25 27,808->26,047). User CSV verified as post-restatement. NCI profit share 6.9% FY26 / 6.4% FY25.
A7: FY1 guidance | B7: FY Mar-27 guide: sales 650,000 (+0.8%), OP 30,000 (-15.8%), net 20,000 (-32%); dividend Y120 under an explicit DOE 3% policy. Q1 (30-Jul): OP margin 4.6%, guidance MAINTAINED, progress 26.9% vs 5-yr avg 29.8%.
A8: Balance sheet / shares / price | B8: All bridge items from the tanshin BS. ONE judgment estimate remains (pension-surplus 50% realizability haircut, yellow). Confirm marketable-securities composition in the yuho filed 9-Jun-26.
A10: METHODOLOGY
A11: Owner-FCF basis | B11: SBC (incl. equity-award taxes) fully expensed, projected explicitly per scenario-year as % of revenue; INTEREST INCOME EXCLUDED from flows (cash pile added separately - including both double-counts); combined leakage held flat at 35.8% (= 31% Japan cash tax x 6.9% NCI share; flows attributable-only, NCI stock NOT deducted again); D&A and capex as % of revenue; working capital = 0% of the YoY revenue increase (set for this business model); diluted shares held FLAT (SBC expensing substitutes for grant dilution; never do both). TV = Gordon capped at 20x terminal owner FCF. End-of-year discounting. WACC 9.0%. Street-convention values (SBC as non-cash) shown as memos - the house/street pair is the accounting-regime price band.
A12: Scenario drivers | B12: Margin and growth paths carried from v1.0 (year 1 independently validated by guidance and Q1 actuals). Three evidence-driven changes: (1) leakage 31% -> 35.8% (= 31% cash tax x 6.9% NCI; v1.0 wrongly assumed NCI nil); (2) capex 4.8% -> 4.3% (10-yr filing history: range 2.8-5.5%, mean ~4.2%; FY26's 5.5% is a cyclical peak - adopts the third-party model's taper evidence as a flat equivalent); (3) weights 20/50/30 vs default 15/50/35 for the governance overhang - PROPOSED, restore via yellow cells. Takeover premium EXCLUDED. A no-re-rate memo value (TV capped at the 10-yr avg EV/EBITDA of 2.66x, the third-party model's discipline) sits below the sensitivity grid.
A14: UPDATE INSTRUCTIONS
A15: Each quarter | B15: Refresh price, net cash (+date), diluted shares, buyback pace, and the guidance-year driver columns; reassess blue rows 5/7/9/14 per scenario only where new evidence exists; add/extend the Reconciliation tab; increment the version above.
A16: Conventions | B16: Blue = hardcoded input. Yellow = key levers. Black = formula. Green = cross-sheet link. Prefilled values are working examples of the expected format.

Sheet Reconciliation
A1: RECONCILIATION - prior versions vs this file
A3: Model | B3: Bear | C3: Base | D3: Bull | E3: Weighted | F3: Notes
A4: v1.0 house engine (14-Aug, at Y3,025) | B4: 1536 | C4: 3683 | D4: 5038 | E4: 3836 | F4: bridge understated (missed 36.9bn marketable sec, 18.1bn investment sec, pension surplus); NCI wrongly nil; capex over-punitive
A5: User 6995_T_DCF_Model.xlsx (14-Aug, at Y3,040) | B5: 3493 | C5: 3493 | D5: 3493 | E5: 3493 | F5: single scenario shown in all columns; own pitfall-15 (stripped div income, bridged cash only); year-10 share division +5%; corrected ~3,323
A6: This file (live) | B6: =DCF_Bear!$B$38 -> 2475.8137 | C6: =DCF_Base!$B$38 -> 4558.4619 | D6: =DCF_Bull!$B$38 -> 5866.4822 | E6: =Valuation!$B$10 -> 4534.3384
A8: Bridge (approximate ¥/share; live cells are authoritative)
A9: v1.0 weighted per share | B9: 3836 | F9: prior version same day
A10: Bridge rebuilt from tanshin BS (+marketable sec, +investment sec, +pension credit) | B10: 658 | F10: +56,020/85.1m; pension credit is the yellow judgment
A11: Leakage 31% -> 35.8% (explicit NCI) | B11: -310 | F11: approximate
A12: Capex 4.8% -> 4.3% (10-yr evidence) | B12: 410 | F12: approximate
A13: Weights 15/50/35 -> 20/50/30 (governance) | B13: -170 | F13: proposed; restore via yellow cells
A14: Interaction effects (capex x growth x leakage) | B14: 110 | C14: residual to tie; live cells authoritative
A15: v1.1 weighted per share | B15: 4534 | F15: approximate - live Valuation tab authoritative; tied after build

Sheet Assumptions
A1: 6995.T - Global Assumptions & Scenario Parameters
A2: Blue = hardcoded input. Yellow = key levers. All ¥ in millions unless stated.
A4: Global inputs
A5: WACC / discount rate | B5: 0.09
A6: D&A (% of revenue) | B6: 0.036
A7: Capex + capitalized software (% of revenue) | B7: 0.043
A8: Working-capital capture (% of YoY revenue incr.) | B8: 0 | H8: Sign/size per business model
A9: Net cash (¥mm) | B9: 139777 | H9: ITEMIZED (tanshin BS 31-Mar-26): cash+deposits 80,905 + current marketable securities 36,881 (cash-like) + investment securities 18,051 (14.5bn cross-holdings SOLD in FY26) + pension surplus credit est 16,000 (net DB asset 46,574 gross, ~32,100 after tax, 50% realizability haircut - YELLOW judgment, range 0-32,100) - bonds 10,000 - lease liabilities 2,060. J-GAAP: no IFRS-16 adjustment
A10: Fully diluted shares (mm) | B10: 85.1 | H10: 89,234,171 issued - 4,126,002 treasury = 85.11m at 31-Mar-26 (tanshin); held flat
A11: Current share price | B11: 3040 | H11: 14-Aug-26 (user's third-party model, live Yahoo quote); refresh at next TSE close
A12: Terminal value cap (x terminal-year owner FCF) | B12: 20
A14: Scenario parameters | C14: Bear | D14: Base | E14: Bull
A15: Terminal growth rate | C15: 0 | D15: 0.005 | E15: 0.01
A16: Probability weight | C16: 0.2 | D16: 0.5 | E16: 0.3 | F16: =SUM(C16:E16) -> 1 | G16: must sum to 100%
A18: Scenario narratives
A19: Bear | B19: bZ-shock switch/HMI share loss compounds and decontenting outruns digital-key gains; margins round-trip toward the FY22-23 trough. Weight RAISED 15->20 for the ICFR material weakness / restatement overhang (house default 15 - restore via yellow cell if you disagree). Note the restatement itself did NOT touch operating profit - the raise prices control risk, not fake earnings.
A20: Base | B20: Year 1 = guided dip (OP 30bn / 4.6%; Q1 ran exactly 4.6% with guidance maintained 30-Jul), then recovery to FY25-26 margins and hold. Growth 2%/yr vs guided +0.8% (Q1 revenue +8.8%). DOE 3% dividend policy (Y120 FY27, 51% payout) and continuing cross-holding sales support the floor.
A21: Bull | B21: Content growth (digital key, e-latch, steering HMI, security) outruns decontenting; OP pushes past 7% toward the TRV2030 ambition; buybacks + DOE 3% + cross-holding sales keep shrinking the discount. Weight 30 (from default 35, offsetting the bear raise).

Sheet DCF_Bear
A1: 6995.T DCF - Bear - content loss; governance overhang persists
A2: Owner-FCF basis: SBC fully expensed, interest income excluded, share count flat. Blue rows = per-year drivers (edit).
B3: 2026A | C3: 2027E | D3: 2028E | E3: 2029E | F3: 2030E | G3: 2031E | H3: 2032E | I3: 2033E | J3: 2034E | K3: 2035E | L3: 2036E
A4: Year index (for discounting) | B4: 0 | C4: 1 | D4: 2 | E4: 3 | F4: 4 | G4: 5 | H4: 6 | I4: 7 | J4: 8 | K4: 9 | L4: 10
A5: Revenue growth YoY | C5: 0 | D5: -0.02 | E5: -0.02 | F5: -0.02 | G5: -0.015 | H5: -0.015 | I5: -0.01 | J5: -0.01 | K5: -0.01 | L5: -0.01
A6: Revenue | B6: 644701 | C6: =B6*(1+C5) -> 644701 | D6: =C6*(1+D5) -> 631806.98 | E6: =D6*(1+E5) -> 619170.84 | F6: =E6*(1+F5) -> 606787.42 | G6: =F6*(1+G5) -> 597685.61 | H6: =G6*(1+H5) -> 588720.33 | I6: =H6*(1+I5) -> 582833.12 | J6: =I6*(1+J5) -> 577004.79 | ... L6: =K6*(1+L5) -> 565522.4
A7: Adj EBITDA margin | B7: 0.0914 | C7: 0.078 | D7: 0.072 | E7: 0.068 | F7: 0.065 | G7: 0.063 | H7: 0.062 | I7: 0.06 | J7: 0.06 | K7: 0.06 | L7: 0.06
A8: Adjusted EBITDA | C8: =C6*C7 -> 50286.678 | D8: =D6*D7 -> 45490.103 | E8: =E6*E7 -> 42103.617 | F8: =F6*F7 -> 39441.183 | G8: =G6*G7 -> 37654.194 | H8: =H6*H7 -> 36500.66 | I8: =I6*I7 -> 34969.987 | J8: =J6*J7 -> 34620.288 | ... L8: =L6*L7 -> 33931.344
A9: SBC (% of revenue) | B9: 0 | C9: 0 | D9: 0 | E9: 0 | F9: 0 | G9: 0 | H9: 0 | I9: 0 | J9: 0 | K9: 0 | L9: 0
A10: SBC (incl. equity-award taxes) | C10: =-C6*C9 -> 0 | D10: =-D6*D9 -> 0 | E10: =-E6*E9 -> 0 | F10: =-F6*F9 -> 0 | G10: =-G6*G9 -> 0 | H10: =-H6*H9 -> 0 | I10: =-I6*I9 -> 0 | J10: =-J6*J9 -> 0 | ... L10: =-L6*L9 -> 0
A11: EBITDA less SBC ('owner EBITDA') | C11: =C8+C10 -> 50286.678 | D11: =D8+D10 -> 45490.103 | E11: =E8+E10 -> 42103.617 | F11: =F8+F10 -> 39441.183 | G11: =G8+G10 -> 37654.194 | H11: =H8+H10 -> 36500.66 | I11: =I8+I10 -> 34969.987 | J11: =J8+J10 -> 34620.288 | ... L11: =L8+L10 -> 33931.344
A12: D&A | C12: =-C6*Assumptions!$B$6 -> -23209.236 | D12: =-D6*Assumptions!$B$6 -> -22745.051 | E12: =-E6*Assumptions!$B$6 -> -22290.15 | F12: =-F6*Assumptions!$B$6 -> -21844.347 | G12: =-G6*Assumptions!$B$6 -> -21516.682 | H12: =-H6*Assumptions!$B$6 -> -21193.932 | I12: =-I6*Assumptions!$B$6 -> -20981.992 | J12: =-J6*Assumptions!$B$6 -> -20772.173 | ... L12: =-L6*Assumptions!$B$6 -> -20358.806
A13: EBIT (SBC expensed) | C13: =C11+C12 -> 27077.442 | D13: =D11+D12 -> 22745.051 | E13: =E11+E12 -> 19813.467 | F13: =F11+F12 -> 17596.835 | G13: =G11+G12 -> 16137.512 | H13: =H11+H12 -> 15306.729 | I13: =I11+I12 -> 13987.995 | J13: =J11+J12 -> 13848.115 | ... L13: =L11+L12 -> 13572.538
A14: Cash tax rate (neg = benefit) | C14: 0.358 | D14: 0.358 | E14: 0.358 | F14: 0.358 | G14: 0.358 | H14: 0.358 | I14: 0.358 | J14: 0.358 | K14: 0.358 | L14: 0.358
A15: NOPAT | C15: =C13*(1-C14) -> 17383.718 | D15: =D13*(1-D14) -> 14602.323 | E15: =E13*(1-E14) -> 12720.246 | F15: =F13*(1-F14) -> 11297.168 | G15: =G13*(1-G14) -> 10360.282 | H15: =H13*(1-H14) -> 9826.9197 | I15: =I13*(1-I14) -> 8980.2928 | J15: =J13*(1-J14) -> 8890.4899 | ... L15: =L13*(1-L14) -> 8713.5691
A16: add: D&A | C16: =-C12 -> 23209.236 | D16: =-D12 -> 22745.051 | E16: =-E12 -> 22290.15 | F16: =-F12 -> 21844.347 | G16: =-G12 -> 21516.682 | H16: =-H12 -> 21193.932 | I16: =-I12 -> 20981.992 | J16: =-J12 -> 20772.173 | ... L16: =-L12 -> 20358.806
A17: less: capex + capitalized software | C17: =-C6*Assumptions!$B$7 -> -27722.143 | D17: =-D6*Assumptions!$B$7 -> -27167.7 | E17: =-E6*Assumptions!$B$7 -> -26624.346 | F17: =-F6*Assumptions!$B$7 -> -26091.859 | G17: =-G6*Assumptions!$B$7 -> -25700.481 | H17: =-H6*Assumptions!$B$7 -> -25314.974 | I17: =-I6*Assumptions!$B$7 -> -25061.824 | J17: =-J6*Assumptions!$B$7 -> -24811.206 | ... L17: =-L6*Assumptions!$B$7 -> -24317.463
A18: add: working capital | C18: =Assumptions!$B$8*(C6-B6) -> 0 | D18: =Assumptions!$B$8*(D6-C6) -> 0 | E18: =Assumptions!$B$8*(E6-D6) -> 0 | F18: =Assumptions!$B$8*(F6-E6) -> 0 | G18: =Assumptions!$B$8*(G6-F6) -> 0 | H18: =Assumptions!$B$8*(H6-G6) -> 0 | I18: =Assumptions!$B$8*(I6-H6) -> 0 | J18: =Assumptions!$B$8*(J6-I6) -> 0 | ... L18: =Assumptions!$B$8*(L6-K6) -> 0
A19: Unlevered owner FCF | C19: =C15+C16+C17+C18 -> 12870.811 | D19: =D15+D16+D17+D18 -> 10179.674 | E19: =E15+E16+E17+E18 -> 8386.0499 | F19: =F15+F16+F17+F18 -> 7049.6563 | G19: =G15+G16+G17+G18 -> 6176.4831 | H19: =H15+H16+H17+H18 -> 5705.8774 | I19: =I15+I16+I17+I18 -> 4900.4609 | J19: =J15+J16+J17+J18 -> 4851.4563 | ... L19: =L15+L16+L17+L18 -> 4754.9123
A20: Discount factor | C20: =1/(1+Assumptions!$B$5)^C4 -> 0.91743119 | D20: =1/(1+Assumptions!$B$5)^D4 -> 0.84167999 | E20: =1/(1+Assumptions!$B$5)^E4 -> 0.77218348 | F20: =1/(1+Assumptions!$B$5)^F4 -> 0.70842521 | G20: =1/(1+Assumptions!$B$5)^G4 -> 0.64993139 | H20: =1/(1+Assumptions!$B$5)^H4 -> 0.59626733 | I20: =1/(1+Assumptions!$B$5)^I4 -> 0.54703424 | J20: =1/(1+Assumptions!$B$5)^J4 -> 0.50186628 | ... L20: =1/(1+Assumptions!$B$5)^L4 -> 0.42241081
A21: PV of FCF | C21: =C19*C20 -> 11808.083 | D21: =D19*D20 -> 8568.028 | E21: =E19*E20 -> 6475.5692 | F21: =F19*F20 -> 4994.1542 | G21: =G19*G20 -> 4014.2902 | H21: =H19*H20 -> 3402.2283 | I21: =I19*I20 -> 2680.7199 | J21: =J19*J20 -> 2434.7823 | ... L21: =L19*L20 -> 2008.5264
A23: Memo: FCF before SBC (company-style) | C23: =C19-C10 -> 12870.811 | D23: =D19-D10 -> 10179.674 | E23: =E19-E10 -> 8386.0499 | F23: =F19-F10 -> 7049.6563 | G23: =G19-G10 -> 6176.4831 | H23: =H19-H10 -> 5705.8774 | I23: =I19-I10 -> 4900.4609 | J23: =J19-J10 -> 4851.4563 | ... L23: =L19-L10 -> 4754.9123
A24: Memo: implied owner FCF margin | C24: =C19/C6 -> 0.019964 | D24: =D19/D6 -> 0.016112 | E24: =E19/E6 -> 0.013544 | F24: =F19/F6 -> 0.011618 | G24: =G19/G6 -> 0.010334 | H24: =H19/H6 -> 0.009692 | I24: =I19/I6 -> 0.008408 | J24: =J19/J6 -> 0.008408 | ... L24: =L19/L6 -> 0.008408
A25: Valuation
A26: PV of FCF, explicit years | B26: =SUM(C21:L21) -> 48597.79
A27: Terminal growth rate | B27: =Assumptions!$C$15 -> 0
A28: Terminal-year owner FCF x (1+g) | B28: =L19*(1+B27) -> 4754.9123
A29: Terminal value - Gordon | B29: =B28/(Assumptions!$B$5-B27) -> 52832.359
A30: Terminal value - cap | B30: =Assumptions!$B$12*L19 -> 95098.246
A31: Terminal value used (lower of the two, floored at 0) | B31: =MAX(0,MIN(B29,B30)) -> 52832.359
A32: Implied exit multiple | B32: =B31/L19 -> 11.111111
A33: PV of terminal value | B33: =B31*L20 -> 22316.959
A34: Enterprise value | B34: =B26+B33 -> 70914.749
A35: add: net cash | B35: =Assumptions!$B$9 -> 139777
A36: Equity value | B36: =B34+B35 -> 210691.75
A37: Fully diluted shares (mm) | B37: =Assumptions!$B$10 -> 85.1
A38: Value per share | B38: =B36/B37 -> 2475.8137
A39: Upside / (downside) vs current price | B39: =B38/Assumptions!$B$11-1 -> -0.18558759
A41: Memo: value if SBC treated as non-cash | B41: =SUMPRODUCT(-C10:L10/(1+Assumptions!$B$5)^C4:L4) -> 0
A42: plus PV of terminal SBC | B42: =(-L10*(1+B27)/(Assumptions!$B$5-B27))*L20 -> 0
...

Sheet DCF_Base
A1: 6995.T DCF - Base - guided FY27 dip then normalisation; DOE 3% floor
A2: Owner-FCF basis: SBC fully expensed, interest income excluded, share count flat. Blue rows = per-year drivers (edit).
B3: 2026A | C3: 2027E | D3: 2028E | E3: 2029E | F3: 2030E | G3: 2031E | H3: 2032E | I3: 2033E | J3: 2034E | K3: 2035E | L3: 2036E
A4: Year index (for discounting) | B4: 0 | C4: 1 | D4: 2 | E4: 3 | F4: 4 | G4: 5 | H4: 6 | I4: 7 | J4: 8 | K4: 9 | L4: 10
A5: Revenue growth YoY | C5: 0.02 | D5: 0.02 | E5: 0.02 | F5: 0.02 | G5: 0.015 | H5: 0.015 | I5: 0.015 | J5: 0.01 | K5: 0.01 | L5: 0.01
A6: Revenue | B6: 644701 | C6: =B6*(1+C5) -> 657595.02 | D6: =C6*(1+D5) -> 670746.92 | E6: =D6*(1+E5) -> 684161.86 | F6: =E6*(1+F5) -> 697845.1 | G6: =F6*(1+G5) -> 708312.77 | H6: =G6*(1+H5) -> 718937.46 | I6: =H6*(1+I5) -> 729721.53 | J6: =I6*(1+J5) -> 737018.74 | ... L6: =K6*(1+L5) -> 751832.82
A7: Adj EBITDA margin | B7: 0.0914 | C7: 0.082 | D7: 0.086 | E7: 0.09 | F7: 0.093 | G7: 0.095 | H7: 0.096 | I7: 0.096 | J7: 0.096 | K7: 0.096 | L7: 0.096
A8: Adjusted EBITDA | C8: =C6*C7 -> 53922.792 | D8: =D6*D7 -> 57684.235 | E8: =E6*E7 -> 61574.567 | F8: =F6*F7 -> 64899.594 | G8: =G6*G7 -> 67289.713 | H8: =H6*H7 -> 69017.997 | I8: =I6*I7 -> 70053.266 | J8: =J6*J7 -> 70753.799 | ... L8: =L6*L7 -> 72175.951
A9: SBC (% of revenue) | B9: 0 | C9: 0 | D9: 0 | E9: 0 | F9: 0 | G9: 0 | H9: 0 | I9: 0 | J9: 0 | K9: 0 | L9: 0
A10: SBC (incl. equity-award taxes) | C10: =-C6*C9 -> 0 | D10: =-D6*D9 -> 0 | E10: =-E6*E9 -> 0 | F10: =-F6*F9 -> 0 | G10: =-G6*G9 -> 0 | H10: =-H6*H9 -> 0 | I10: =-I6*I9 -> 0 | J10: =-J6*J9 -> 0 | ... L10: =-L6*L9 -> 0
A11: EBITDA less SBC ('owner EBITDA') | C11: =C8+C10 -> 53922.792 | D11: =D8+D10 -> 57684.235 | E11: =E8+E10 -> 61574.567 | F11: =F8+F10 -> 64899.594 | G11: =G8+G10 -> 67289.713 | H11: =H8+H10 -> 69017.997 | I11: =I8+I10 -> 70053.266 | J11: =J8+J10 -> 70753.799 | ... L11: =L8+L10 -> 72175.951
A12: D&A | C12: =-C6*Assumptions!$B$6 -> -23673.421 | D12: =-D6*Assumptions!$B$6 -> -24146.889 | E12: =-E6*Assumptions!$B$6 -> -24629.827 | F12: =-F6*Assumptions!$B$6 -> -25122.423 | G12: =-G6*Assumptions!$B$6 -> -25499.26 | H12: =-H6*Assumptions!$B$6 -> -25881.749 | I12: =-I6*Assumptions!$B$6 -> -26269.975 | J12: =-J6*Assumptions!$B$6 -> -26532.675 | ... L12: =-L6*Assumptions!$B$6 -> -27065.981
A13: EBIT (SBC expensed) | C13: =C11+C12 -> 30249.371 | D13: =D11+D12 -> 33537.346 | E13: =E11+E12 -> 36944.74 | F13: =F11+F12 -> 39777.17 | G13: =G11+G12 -> 41790.454 | H13: =H11+H12 -> 43136.248 | I13: =I11+I12 -> 43783.292 | J13: =J11+J12 -> 44221.124 | ... L13: =L11+L12 -> 45109.969
A14: Cash tax rate (neg = benefit) | C14: 0.358 | D14: 0.358 | E14: 0.358 | F14: 0.358 | G14: 0.358 | H14: 0.358 | I14: 0.358 | J14: 0.358 | K14: 0.358 | L14: 0.358
A15: NOPAT | C15: =C13*(1-C14) -> 19420.096 | D15: =D13*(1-D14) -> 21530.976 | E15: =E13*(1-E14) -> 23718.523 | F15: =F13*(1-F14) -> 25536.943 | G15: =G13*(1-G14) -> 26829.471 | H15: =H13*(1-H14) -> 27693.471 | I15: =I13*(1-I14) -> 28108.873 | J15: =J13*(1-J14) -> 28389.962 | ... L15: =L13*(1-L14) -> 28960.6
A16: add: D&A | C16: =-C12 -> 23673.421 | D16: =-D12 -> 24146.889 | E16: =-E12 -> 24629.827 | F16: =-F12 -> 25122.423 | G16: =-G12 -> 25499.26 | H16: =-H12 -> 25881.749 | I16: =-I12 -> 26269.975 | J16: =-J12 -> 26532.675 | ... L16: =-L12 -> 27065.981
A17: less: capex + capitalized software | C17: =-C6*Assumptions!$B$7 -> -28276.586 | D17: =-D6*Assumptions!$B$7 -> -28842.118 | E17: =-E6*Assumptions!$B$7 -> -29418.96 | F17: =-F6*Assumptions!$B$7 -> -30007.339 | G17: =-G6*Assumptions!$B$7 -> -30457.449 | H17: =-H6*Assumptions!$B$7 -> -30914.311 | I17: =-I6*Assumptions!$B$7 -> -31378.026 | J17: =-J6*Assumptions!$B$7 -> -31691.806 | ... L17: =-L6*Assumptions!$B$7 -> -32328.811
A18: add: working capital | C18: =Assumptions!$B$8*(C6-B6) -> 0 | D18: =Assumptions!$B$8*(D6-C6) -> 0 | E18: =Assumptions!$B$8*(E6-D6) -> 0 | F18: =Assumptions!$B$8*(F6-E6) -> 0 | G18: =Assumptions!$B$8*(G6-F6) -> 0 | H18: =Assumptions!$B$8*(H6-G6) -> 0 | I18: =Assumptions!$B$8*(I6-H6) -> 0 | J18: =Assumptions!$B$8*(J6-I6) -> 0 | ... L18: =Assumptions!$B$8*(L6-K6) -> 0
A19: Unlevered owner FCF | C19: =C15+C16+C17+C18 -> 14816.931 | D19: =D15+D16+D17+D18 -> 16835.748 | E19: =E15+E16+E17+E18 -> 18929.39 | F19: =F15+F16+F17+F18 -> 20652.028 | G19: =G15+G16+G17+G18 -> 21871.282 | H19: =H15+H16+H17+H18 -> 22660.909 | I19: =I15+I16+I17+I18 -> 23000.822 | J19: =J15+J16+J17+J18 -> 23230.831 | ... L19: =L15+L16+L17+L18 -> 23697.77
A20: Discount factor | C20: =1/(1+Assumptions!$B$5)^C4 -> 0.91743119 | D20: =1/(1+Assumptions!$B$5)^D4 -> 0.84167999 | E20: =1/(1+Assumptions!$B$5)^E4 -> 0.77218348 | F20: =1/(1+Assumptions!$B$5)^F4 -> 0.70842521 | G20: =1/(1+Assumptions!$B$5)^G4 -> 0.64993139 | H20: =1/(1+Assumptions!$B$5)^H4 -> 0.59626733 | I20: =1/(1+Assumptions!$B$5)^I4 -> 0.54703424 | J20: =1/(1+Assumptions!$B$5)^J4 -> 0.50186628 | ... L20: =1/(1+Assumptions!$B$5)^L4 -> 0.42241081
A21: PV of FCF | C21: =C19*C20 -> 13593.515 | D21: =D19*D20 -> 14170.312 | E21: =E19*E20 -> 14616.962 | F21: =F19*F20 -> 14630.417 | G21: =G19*G20 -> 14214.832 | H21: =H19*H20 -> 13511.96 | I21: =I19*I20 -> 12582.238 | J21: =J19*J20 -> 11658.771 | ... L21: =L19*L20 -> 10010.194
A23: Memo: FCF before SBC (company-style) | C23: =C19-C10 -> 14816.931 | D23: =D19-D10 -> 16835.748 | E23: =E19-E10 -> 18929.39 | F23: =F19-F10 -> 20652.028 | G23: =G19-G10 -> 21871.282 | H23: =H19-H10 -> 22660.909 | I23: =I19-I10 -> 23000.822 | J23: =J19-J10 -> 23230.831 | ... L23: =L19-L10 -> 23697.77
A24: Memo: implied owner FCF margin | C24: =C19/C6 -> 0.022532 | D24: =D19/D6 -> 0.0251 | E24: =E19/E6 -> 0.027668 | F24: =F19/F6 -> 0.029594 | G24: =G19/G6 -> 0.030878 | H24: =H19/H6 -> 0.03152 | I24: =I19/I6 -> 0.03152 | J24: =J19/J6 -> 0.03152 | ... L24: =L19/L6 -> 0.03152
A25: Valuation
A26: PV of FCF, explicit years | B26: =SUM(C21:L21) -> 129792.28
A27: Terminal growth rate | B27: =Assumptions!$D$15 -> 0.005
A28: Terminal-year owner FCF x (1+g) | B28: =L19*(1+B27) -> 23816.259
A29: Terminal value - Gordon | B29: =B28/(Assumptions!$B$5-B27) -> 280191.29
A30: Terminal value - cap | B30: =Assumptions!$B$12*L19 -> 473955.41
A31: Terminal value used (lower of the two, floored at 0) | B31: =MAX(0,MIN(B29,B30)) -> 280191.29
A32: Implied exit multiple | B32: =B31/L19 -> 11.823529
A33: PV of terminal value | B33: =B31*L20 -> 118355.83
A34: Enterprise value | B34: =B26+B33 -> 248148.11
A35: add: net cash | B35: =Assumptions!$B$9 -> 139777
A36: Equity value | B36: =B34+B35 -> 387925.11
A37: Fully diluted shares (mm) | B37: =Assumptions!$B$10 -> 85.1
A38: Value per share | B38: =B36/B37 -> 4558.4619
A39: Upside / (downside) vs current price | B39: =B38/Assumptions!$B$11-1 -> 0.49949405
A41: Memo: value if SBC treated as non-cash | B41: =SUMPRODUCT(-C10:L10/(1+Assumptions!$B$5)^C4:L4) -> 0
A42: plus PV of terminal SBC | B42: =(-L10*(1+B27)/(Assumptions!$B$5-B27))*L20 -> 0
...

Sheet DCF_Bull
A1: 6995.T DCF - Bull - digital-key/HMI content compounds toward TRV2030
A2: Owner-FCF basis: SBC fully expensed, interest income excluded, share count flat. Blue rows = per-year drivers (edit).
B3: 2026A | C3: 2027E | D3: 2028E | E3: 2029E | F3: 2030E | G3: 2031E | H3: 2032E | I3: 2033E | J3: 2034E | K3: 2035E | L3: 2036E
A4: Year index (for discounting) | B4: 0 | C4: 1 | D4: 2 | E4: 3 | F4: 4 | G4: 5 | H4: 6 | I4: 7 | J4: 8 | K4: 9 | L4: 10
A5: Revenue growth YoY | C5: 0.03 | D5: 0.04 | E5: 0.035 | F5: 0.03 | G5: 0.03 | H5: 0.025 | I5: 0.02 | J5: 0.02 | K5: 0.015 | L5: 0.015
A6: Revenue | B6: 644701 | C6: =B6*(1+C5) -> 664042.03 | D6: =C6*(1+D5) -> 690603.71 | E6: =D6*(1+E5) -> 714774.84 | F6: =E6*(1+F5) -> 736218.09 | G6: =F6*(1+G5) -> 758304.63 | H6: =G6*(1+H5) -> 777262.24 | I6: =H6*(1+I5) -> 792807.49 | J6: =I6*(1+J5) -> 808663.64 | ... L6: =K6*(1+L5) -> 833105.5
A7: Adj EBITDA margin | B7: 0.0914 | C7: 0.085 | D7: 0.093 | E7: 0.1 | F7: 0.105 | G7: 0.108 | H7: 0.11 | I7: 0.111 | J7: 0.112 | K7: 0.112 | L7: 0.112
A8: Adjusted EBITDA | C8: =C6*C7 -> 56443.573 | D8: =D6*D7 -> 64226.145 | E8: =E6*E7 -> 71477.484 | F8: =F6*F7 -> 77302.899 | G8: =G6*G7 -> 81896.9 | H8: =H6*H7 -> 85498.847 | I8: =I6*I7 -> 88001.631 | J8: =J6*J7 -> 90570.328 | ... L8: =L6*L7 -> 93307.816
A9: SBC (% of revenue) | B9: 0 | C9: 0 | D9: 0 | E9: 0 | F9: 0 | G9: 0 | H9: 0 | I9: 0 | J9: 0 | K9: 0 | L9: 0
A10: SBC (incl. equity-award taxes) | C10: =-C6*C9 -> 0 | D10: =-D6*D9 -> 0 | E10: =-E6*E9 -> 0 | F10: =-F6*F9 -> 0 | G10: =-G6*G9 -> 0 | H10: =-H6*H9 -> 0 | I10: =-I6*I9 -> 0 | J10: =-J6*J9 -> 0 | ... L10: =-L6*L9 -> 0
A11: EBITDA less SBC ('owner EBITDA') | C11: =C8+C10 -> 56443.573 | D11: =D8+D10 -> 64226.145 | E11: =E8+E10 -> 71477.484 | F11: =F8+F10 -> 77302.899 | G11: =G8+G10 -> 81896.9 | H11: =H8+H10 -> 85498.847 | I11: =I8+I10 -> 88001.631 | J11: =J8+J10 -> 90570.328 | ... L11: =L8+L10 -> 93307.816
A12: D&A | C12: =-C6*Assumptions!$B$6 -> -23905.513 | D12: =-D6*Assumptions!$B$6 -> -24861.734 | E12: =-E6*Assumptions!$B$6 -> -25731.894 | F12: =-F6*Assumptions!$B$6 -> -26503.851 | G12: =-G6*Assumptions!$B$6 -> -27298.967 | H12: =-H6*Assumptions!$B$6 -> -27981.441 | I12: =-I6*Assumptions!$B$6 -> -28541.07 | J12: =-J6*Assumptions!$B$6 -> -29111.891 | ... L12: =-L6*Assumptions!$B$6 -> -29991.798
A13: EBIT (SBC expensed) | C13: =C11+C12 -> 32538.059 | D13: =D11+D12 -> 39364.412 | E13: =E11+E12 -> 45745.59 | F13: =F11+F12 -> 50799.048 | G13: =G11+G12 -> 54597.933 | H13: =H11+H12 -> 57517.406 | I13: =I11+I12 -> 59460.562 | J13: =J11+J12 -> 61458.437 | ... L13: =L11+L12 -> 63316.018
A14: Cash tax rate (neg = benefit) | C14: 0.358 | D14: 0.358 | E14: 0.358 | F14: 0.358 | G14: 0.358 | H14: 0.358 | I14: 0.358 | J14: 0.358 | K14: 0.358 | L14: 0.358
A15: NOPAT | C15: =C13*(1-C14) -> 20889.434 | D15: =D13*(1-D14) -> 25271.952 | E15: =E13*(1-E14) -> 29368.669 | F15: =F13*(1-F14) -> 32612.989 | G15: =G13*(1-G14) -> 35051.873 | H15: =H13*(1-H14) -> 36926.175 | I15: =I13*(1-I14) -> 38173.681 | J15: =J13*(1-J14) -> 39456.316 | ... L15: =L13*(1-L14) -> 40648.883
A16: add: D&A | C16: =-C12 -> 23905.513 | D16: =-D12 -> 24861.734 | E16: =-E12 -> 25731.894 | F16: =-F12 -> 26503.851 | G16: =-G12 -> 27298.967 | H16: =-H12 -> 27981.441 | I16: =-I12 -> 28541.07 | J16: =-J12 -> 29111.891 | ... L16: =-L12 -> 29991.798
A17: less: capex + capitalized software | C17: =-C6*Assumptions!$B$7 -> -28553.807 | D17: =-D6*Assumptions!$B$7 -> -29695.96 | E17: =-E6*Assumptions!$B$7 -> -30735.318 | F17: =-F6*Assumptions!$B$7 -> -31657.378 | G17: =-G6*Assumptions!$B$7 -> -32607.099 | H17: =-H6*Assumptions!$B$7 -> -33422.277 | I17: =-I6*Assumptions!$B$7 -> -34090.722 | J17: =-J6*Assumptions!$B$7 -> -34772.536 | ... L17: =-L6*Assumptions!$B$7 -> -35823.536
A18: add: working capital | C18: =Assumptions!$B$8*(C6-B6) -> 0 | D18: =Assumptions!$B$8*(D6-C6) -> 0 | E18: =Assumptions!$B$8*(E6-D6) -> 0 | F18: =Assumptions!$B$8*(F6-E6) -> 0 | G18: =Assumptions!$B$8*(G6-F6) -> 0 | H18: =Assumptions!$B$8*(H6-G6) -> 0 | I18: =Assumptions!$B$8*(I6-H6) -> 0 | J18: =Assumptions!$B$8*(J6-I6) -> 0 | ... L18: =Assumptions!$B$8*(L6-K6) -> 0
A19: Unlevered owner FCF | C19: =C15+C16+C17+C18 -> 16241.14 | D19: =D15+D16+D17+D18 -> 20437.726 | E19: =E15+E16+E17+E18 -> 24365.245 | F19: =F15+F16+F17+F18 -> 27459.462 | G19: =G15+G16+G17+G18 -> 29743.741 | H19: =H15+H16+H17+H18 -> 31485.339 | I19: =I15+I16+I17+I18 -> 32624.028 | J19: =J15+J16+J17+J18 -> 33795.671 | ... L19: =L15+L16+L17+L18 -> 34817.145
A20: Discount factor | C20: =1/(1+Assumptions!$B$5)^C4 -> 0.91743119 | D20: =1/(1+Assumptions!$B$5)^D4 -> 0.84167999 | E20: =1/(1+Assumptions!$B$5)^E4 -> 0.77218348 | F20: =1/(1+Assumptions!$B$5)^F4 -> 0.70842521 | G20: =1/(1+Assumptions!$B$5)^G4 -> 0.64993139 | H20: =1/(1+Assumptions!$B$5)^H4 -> 0.59626733 | I20: =1/(1+Assumptions!$B$5)^I4 -> 0.54703424 | J20: =1/(1+Assumptions!$B$5)^J4 -> 0.50186628 | ... L20: =1/(1+Assumptions!$B$5)^L4 -> 0.42241081
A21: PV of FCF | C21: =C19*C20 -> 14900.128 | D21: =D19*D20 -> 17202.025 | E21: =E19*E20 -> 18814.44 | F21: =F19*F20 -> 19452.975 | G21: =G19*G20 -> 19331.391 | H21: =H19*H20 -> 18773.679 | I21: =I19*I20 -> 17846.461 | J21: =J19*J20 -> 16960.908 | ... L21: =L19*L20 -> 14707.138
A23: Memo: FCF before SBC (company-style) | C23: =C19-C10 -> 16241.14 | D23: =D19-D10 -> 20437.726 | E23: =E19-E10 -> 24365.245 | F23: =F19-F10 -> 27459.462 | G23: =G19-G10 -> 29743.741 | H23: =H19-H10 -> 31485.339 | I23: =I19-I10 -> 32624.028 | J23: =J19-J10 -> 33795.671 | ... L23: =L19-L10 -> 34817.145
A24: Memo: implied owner FCF margin | C24: =C19/C6 -> 0.024458 | D24: =D19/D6 -> 0.029594 | E24: =E19/E6 -> 0.034088 | F24: =F19/F6 -> 0.037298 | G24: =G19/G6 -> 0.039224 | H24: =H19/H6 -> 0.040508 | I24: =I19/I6 -> 0.04115 | J24: =J19/J6 -> 0.041792 | ... L24: =L19/L6 -> 0.041792
A25: Valuation
A26: PV of FCF, explicit years | B26: =SUM(C21:L21) -> 173783.02
A27: Terminal growth rate | B27: =Assumptions!$E$15 -> 0.01
A28: Terminal-year owner FCF x (1+g) | B28: =L19*(1+B27) -> 35165.316
A29: Terminal value - Gordon | B29: =B28/(Assumptions!$B$5-B27) -> 439566.46
A30: Terminal value - cap | B30: =Assumptions!$B$12*L19 -> 696342.9
A31: Terminal value used (lower of the two, floored at 0) | B31: =MAX(0,MIN(B29,B30)) -> 439566.46
A32: Implied exit multiple | B32: =B31/L19 -> 12.625
A33: PV of terminal value | B33: =B31*L20 -> 185677.62
A34: Enterprise value | B34: =B26+B33 -> 359460.64
A35: add: net cash | B35: =Assumptions!$B$9 -> 139777
A36: Equity value | B36: =B34+B35 -> 499237.64
A37: Fully diluted shares (mm) | B37: =Assumptions!$B$10 -> 85.1
A38: Value per share | B38: =B36/B37 -> 5866.4822
A39: Upside / (downside) vs current price | B39: =B38/Assumptions!$B$11-1 -> 0.92976389
A41: Memo: value if SBC treated as non-cash | B41: =SUMPRODUCT(-C10:L10/(1+Assumptions!$B$5)^C4:L4) -> 0
A42: plus PV of terminal SBC | B42: =(-L10*(1+B27)/(Assumptions!$B$5-B27))*L20 -> 0
...

Sheet Valuation
A1: 6995.T - Valuation Summary & Sensitivity
A2: Owner-FCF basis (SBC expensed) unless marked street. Green = links.
B4: Bear | C4: Base | D4: Bull
A5: Value per share | B5: =DCF_Bear!$B$38 -> 2475.8137 | C5: =DCF_Base!$B$38 -> 4558.4619 | D5: =DCF_Bull!$B$38 -> 5866.4822
A6: Upside / (downside) vs price | B6: =B5/Assumptions!$B$11-1 -> -0.18558759 | C6: =C5/Assumptions!$B$11-1 -> 0.49949405 | D6: =D5/Assumptions!$B$11-1 -> 0.92976389
A7: Probability | B7: =Assumptions!$C$16 -> 0.2 | C7: =Assumptions!$D$16 -> 0.5 | D7: =Assumptions!$E$16 -> 0.3
A8: Value per share, SBC as non-cash (street) | B8: =DCF_Bear!$B$43 -> 2475.8137 | C8: =DCF_Base!$B$43 -> 4558.4619 | D8: =DCF_Bull!$B$43 -> 5866.4822
A10: Probability-weighted value per share | B10: =SUMPRODUCT(B5:D5,B7:D7) -> 4534.3384
A11: Current price | B11: =Assumptions!$B$11 -> 3040
A12: Margin of safety vs weighted value | B12: =1-B11/B10 -> 0.3295604
A13: Weighted value, SBC as non-cash (street) | B13: =SUMPRODUCT(B8:D8,B7:D7) -> 4534.3384
A14: Band position (0%=house, 100%=street) | B14: =IF(ABS(B13-B10)<0.005,"n/a - SBC=0 so house=street",(Assumptions!$B$11-B10)/(B13-B10)) -> n/a - SBC=0 so house=street
A17: Base case - value per share at different required returns
A18: Required return | B18: Value / share
A19: 0.09 | B19: =(SUMPRODUCT(DCF_Base!$C$19:$L$19/(1+$A19)^DCF_Base!$C$4:$L$4)+MAX(0,MIN(DCF_Base!$L$19*(1+Assumptions!$D$15)/($A19-Assumptions!$D$15),Assumptions!$B$12*DCF_Base!$L$19))/(1+$A19)^10+Assumptions!$B$9)/Assumptions!$B$10 -> 4558.4619
A20: 0.1 | B20: =(SUMPRODUCT(DCF_Base!$C$19:$L$19/(1+$A20)^DCF_Base!$C$4:$L$4)+MAX(0,MIN(DCF_Base!$L$19*(1+Assumptions!$D$15)/($A20-Assumptions!$D$15),Assumptions!$B$12*DCF_Base!$L$19))/(1+$A20)^10+Assumptions!$B$9)/Assumptions!$B$10 -> 4233.1666
A21: 0.105 | B21: =(SUMPRODUCT(DCF_Base!$C$19:$L$19/(1+$A21)^DCF_Base!$C$4:$L$4)+MAX(0,MIN(DCF_Base!$L$19*(1+Assumptions!$D$15)/($A21-Assumptions!$D$15),Assumptions!$B$12*DCF_Base!$L$19))/(1+$A21)^10+Assumptions!$B$9)/Assumptions!$B$10 -> 4095.1851
A22: 0.11 | B22: =(SUMPRODUCT(DCF_Base!$C$19:$L$19/(1+$A22)^DCF_Base!$C$4:$L$4)+MAX(0,MIN(DCF_Base!$L$19*(1+Assumptions!$D$15)/($A22-Assumptions!$D$15),Assumptions!$B$12*DCF_Base!$L$19))/(1+$A22)^10+Assumptions!$B$9)/Assumptions!$B$10 -> 3970.5091
A23: 0.12 | B23: =(SUMPRODUCT(DCF_Base!$C$19:$L$19/(1+$A23)^DCF_Base!$C$4:$L$4)+MAX(0,MIN(DCF_Base!$L$19*(1+Assumptions!$D$15)/($A23-Assumptions!$D$15),Assumptions!$B$12*DCF_Base!$L$19))/(1+$A23)^10+Assumptions!$B$9)/Assumptions!$B$10 -> 3754.1146
A24: 0.15 | B24: =(SUMPRODUCT(DCF_Base!$C$19:$L$19/(1+$A24)^DCF_Base!$C$4:$L$4)+MAX(0,MIN(DCF_Base!$L$19*(1+Assumptions!$D$15)/($A24-Assumptions!$D$15),Assumptions!$B$12*DCF_Base!$L$19))/(1+$A24)^10+Assumptions!$B$9)/Assumptions!$B$10 -> 3286.5474
A25: 15%-hurdle entry per scenario + weighted | B25: =(SUMPRODUCT(DCF_Bear!$C$19:$L$19/(1+0.15)^DCF_Bear!$C$4:$L$4)+MAX(0,MIN(DCF_Bear!$L$19*(1+Assumptions!$C$15)/(0.15-Assumptions!$C$15),Assumptions!$B$12*DCF_Bear!$L$19))/(1+0.15)^10+Assumptions!$B$9)/Assumptions!$B$10 -> 2203.9131 | C25: =(SUMPRODUCT(DCF_Base!$C$19:$L$19/(1+0.15)^DCF_Base!$C$4:$L$4)+MAX(0,MIN(DCF_Base!$L$19*(1+Assumptions!$D$15)/(0.15-Assumptions!$D$15),Assumptions!$B$12*DCF_Base!$L$19))/(1+0.15)^10+Assumptions!$B$9)/Assumptions!$B$10 -> 3286.5474 | D25: =(SUMPRODUCT(DCF_Bull!$C$19:$L$19/(1+0.15)^DCF_Bull!$C$4:$L$4)+MAX(0,MIN(DCF_Bull!$L$19*(1+Assumptions!$E$15)/(0.15-Assumptions!$E$15),Assumptions!$B$12*DCF_Bull!$L$19))/(1+0.15)^10+Assumptions!$B$9)/Assumptions!$B$10 -> 3915.7668 | E25: =SUMPRODUCT(B25:D25,$B$7:$D$7) -> 3258.7864 | G25: model buy-below price at a 15% hurdle
A26: same, street basis | B26: =B25+(SUMPRODUCT(-DCF_Bear!$C$10:$L$10/(1+0.15)^DCF_Bear!$C$4:$L$4)+(-DCF_Bear!$L$10*(1+Assumptions!$C$15)/(0.15-Assumptions!$C$15))/(1+0.15)^10)/Assumptions!$B$10 -> 2203.9131 | C26: =C25+(SUMPRODUCT(-DCF_Base!$C$10:$L$10/(1+0.15)^DCF_Base!$C$4:$L$4)+(-DCF_Base!$L$10*(1+Assumptions!$D$15)/(0.15-Assumptions!$D$15))/(1+0.15)^10)/Assumptions!$B$10 -> 3286.5474 | D26: =D25+(SUMPRODUCT(-DCF_Bull!$C$10:$L$10/(1+0.15)^DCF_Bull!$C$4:$L$4)+(-DCF_Bull!$L$10*(1+Assumptions!$E$15)/(0.15-Assumptions!$E$15))/(1+0.15)^10)/Assumptions!$B$10 -> 3915.7668 | E26: =SUMPRODUCT(B26:D26,$B$7:$D$7) -> 3258.7864
A28: Base case - value per share: WACC x terminal growth
A29: WACC \ g | B29: 0 | C29: 0.005 | D29: 0.01 | E29: 0.015 | F29: 0.02
A30: 0.095 | B30: =IF($A30>B$29,(SUMPRODUCT(DCF_Base!$C$19:$L$19/(1+$A30)^DCF_Base!$C$4:$L$4)+MAX(0,MIN(DCF_Base!$L$19*(1+B$29)/($A30-B$29),Assumptions!$B$12*DCF_Base!$L$19))/(1+$A30)^10+Assumptions!$B$9)/Assumptions!$B$10,"n/a") -> 4314.7227 | C30: =IF($A30>C$29,(SUMPRODUCT(DCF_Base!$C$19:$L$19/(1+$A30)^DCF_Base!$C$4:$L$4)+MAX(0,MIN(DCF_Base!$L$19*(1+C$29)/($A30-C$29),Assumptions!$B$12*DCF_Base!$L$19))/(1+$A30)^10+Assumptions!$B$9)/Assumptions!$B$10,"n/a") -> 4386.6767 | D30: =IF($A30>D$29,(SUMPRODUCT(DCF_Base!$C$19:$L$19/(1+$A30)^DCF_Base!$C$4:$L$4)+MAX(0,MIN(DCF_Base!$L$19*(1+D$29)/($A30-D$29),Assumptions!$B$12*DCF_Base!$L$19))/(1+$A30)^10+Assumptions!$B$9)/Assumptions!$B$10,"n/a") -> 4467.0958 | E30: =IF($A30>E$29,(SUMPRODUCT(DCF_Base!$C$19:$L$19/(1+$A30)^DCF_Base!$C$4:$L$4)+MAX(0,MIN(DCF_Base!$L$19*(1+E$29)/($A30-E$29),Assumptions!$B$12*DCF_Base!$L$19))/(1+$A30)^10+Assumptions!$B$9)/Assumptions!$B$10,"n/a") -> 4557.5674 | F30: =IF($A30>F$29,(SUMPRODUCT(DCF_Base!$C$19:$L$19/(1+$A30)^DCF_Base!$C$4:$L$4)+MAX(0,MIN(DCF_Base!$L$19*(1+F$29)/($A30-F$29),Assumptions!$B$12*DCF_Base!$L$19))/(1+$A30)^10+Assumptions!$B$9)/Assumptions!$B$10,"n/a") -> 4660.1018
A31: 0.1 | B31: =IF($A31>B$29,(SUMPRODUCT(DCF_Base!$C$19:$L$19/(1+$A31)^DCF_Base!$C$4:$L$4)+MAX(0,MIN(DCF_Base!$L$19*(1+B$29)/($A31-B$29),Assumptions!$B$12*DCF_Base!$L$19))/(1+$A31)^10+Assumptions!$B$9)/Assumptions!$B$10,"n/a") -> 4171.0096 | C31: =IF($A31>C$29,(SUMPRODUCT(DCF_Base!$C$19:$L$19/(1+$A31)^DCF_Base!$C$4:$L$4)+MAX(0,MIN(DCF_Base!$L$19*(1+C$29)/($A31-C$29),Assumptions!$B$12*DCF_Base!$L$19))/(1+$A31)^10+Assumptions!$B$9)/Assumptions!$B$10,"n/a") -> 4233.1666 | D31: =IF($A31>D$29,(SUMPRODUCT(DCF_Base!$C$19:$L$19/(1+$A31)^DCF_Base!$C$4:$L$4)+MAX(0,MIN(DCF_Base!$L$19*(1+D$29)/($A31-D$29),Assumptions!$B$12*DCF_Base!$L$19))/(1+$A31)^10+Assumptions!$B$9)/Assumptions!$B$10,"n/a") -> 4302.2299 | E31: =IF($A31>E$29,(SUMPRODUCT(DCF_Base!$C$19:$L$19/(1+$A31)^DCF_Base!$C$4:$L$4)+MAX(0,MIN(DCF_Base!$L$19*(1+E$29)/($A31-E$29),Assumptions!$B$12*DCF_Base!$L$19))/(1+$A31)^10+Assumptions!$B$9)/Assumptions!$B$10,"n/a") -> 4379.4184 | F31: =IF($A31>F$29,(SUMPRODUCT(DCF_Base!$C$19:$L$19/(1+$A31)^DCF_Base!$C$4:$L$4)+MAX(0,MIN(DCF_Base!$L$19*(1+F$29)/($A31-F$29),Assumptions!$B$12*DCF_Base!$L$19))/(1+$A31)^10+Assumptions!$B$9)/Assumptions!$B$10,"n/a") -> 4466.2554
A32: 0.105 | B32: =IF($A32>B$29,(SUMPRODUCT(DCF_Base!$C$19:$L$19/(1+$A32)^DCF_Base!$C$4:$L$4)+MAX(0,MIN(DCF_Base!$L$19*(1+B$29)/($A32-B$29),Assumptions!$B$12*DCF_Base!$L$19))/(1+$A32)^10+Assumptions!$B$9)/Assumptions!$B$10,"n/a") -> 4041.197 | C32: =IF($A32>C$29,(SUMPRODUCT(DCF_Base!$C$19:$L$19/(1+$A32)^DCF_Base!$C$4:$L$4)+MAX(0,MIN(DCF_Base!$L$19*(1+C$29)/($A32-C$29),Assumptions!$B$12*DCF_Base!$L$19))/(1+$A32)^10+Assumptions!$B$9)/Assumptions!$B$10,"n/a") -> 4095.1851 | D32: =IF($A32>D$29,(SUMPRODUCT(DCF_Base!$C$19:$L$19/(1+$A32)^DCF_Base!$C$4:$L$4)+MAX(0,MIN(DCF_Base!$L$19*(1+D$29)/($A32-D$29),Assumptions!$B$12*DCF_Base!$L$19))/(1+$A32)^10+Assumptions!$B$9)/Assumptions!$B$10,"n/a") -> 4154.8562 | E32: =IF($A32>E$29,(SUMPRODUCT(DCF_Base!$C$19:$L$19/(1+$A32)^DCF_Base!$C$4:$L$4)+MAX(0,MIN(DCF_Base!$L$19*(1+E$29)/($A32-E$29),Assumptions!$B$12*DCF_Base!$L$19))/(1+$A32)^10+Assumptions!$B$9)/Assumptions!$B$10,"n/a") -> 4221.1574 | F32: =IF($A32>F$29,(SUMPRODUCT(DCF_Base!$C$19:$L$19/(1+$A32)^DCF_Base!$C$4:$L$4)+MAX(0,MIN(DCF_Base!$L$19*(1+F$29)/($A32-F$29),Assumptions!$B$12*DCF_Base!$L$19))/(1+$A32)^10+Assumptions!$B$9)/Assumptions!$B$10,"n/a") -> 4295.2587
A33: 0.11 | B33: =IF($A33>B$29,(SUMPRODUCT(DCF_Base!$C$19:$L$19/(1+$A33)^DCF_Base!$C$4:$L$4)+MAX(0,MIN(DCF_Base!$L$19*(1+B$29)/($A33-B$29),Assumptions!$B$12*DCF_Base!$L$19))/(1+$A33)^10+Assumptions!$B$9)/Assumptions!$B$10,"n/a") -> 3923.3832 | C33: =IF($A33>C$29,(SUMPRODUCT(DCF_Base!$C$19:$L$19/(1+$A33)^DCF_Base!$C$4:$L$4)+MAX(0,MIN(DCF_Base!$L$19*(1+C$29)/($A33-C$29),Assumptions!$B$12*DCF_Base!$L$19))/(1+$A33)^10+Assumptions!$B$9)/Assumptions!$B$10,"n/a") -> 3970.5091 | D33: =IF($A33>D$29,(SUMPRODUCT(DCF_Base!$C$19:$L$19/(1+$A33)^DCF_Base!$C$4:$L$4)+MAX(0,MIN(DCF_Base!$L$19*(1+D$29)/($A33-D$29),Assumptions!$B$12*DCF_Base!$L$19))/(1+$A33)^10+Assumptions!$B$9)/Assumptions!$B$10,"n/a") -> 4022.3475 | E33: =IF($A33>E$29,(SUMPRODUCT(DCF_Base!$C$19:$L$19/(1+$A33)^DCF_Base!$C$4:$L$4)+MAX(0,MIN(DCF_Base!$L$19*(1+E$29)/($A33-E$29),Assumptions!$B$12*DCF_Base!$L$19))/(1+$A33)^10+Assumptions!$B$9)/Assumptions!$B$10,"n/a") -> 4079.6426 | F33: =IF($A33>F$29,(SUMPRODUCT(DCF_Base!$C$19:$L$19/(1+$A33)^DCF_Base!$C$4:$L$4)+MAX(0,MIN(DCF_Base!$L$19*(1+F$29)/($A33-F$29),Assumptions!$B$12*DCF_Base!$L$19))/(1+$A33)^10+Assumptions!$B$9)/Assumptions!$B$10,"n/a") -> 4143.3038
A34: 0.115 | B34: =IF($A34>B$29,(SUMPRODUCT(DCF_Base!$C$19:$L$19/(1+$A34)^DCF_Base!$C$4:$L$4)+MAX(0,MIN(DCF_Base!$L$19*(1+B$29)/($A34-B$29),Assumptions!$B$12*DCF_Base!$L$19))/(1+$A34)^10+Assumptions!$B$9)/Assumptions!$B$10,"n/a") -> 3815.9975 | C34: =IF($A34>C$29,(SUMPRODUCT(DCF_Base!$C$19:$L$19/(1+$A34)^DCF_Base!$C$4:$L$4)+MAX(0,MIN(DCF_Base!$L$19*(1+C$29)/($A34-C$29),Assumptions!$B$12*DCF_Base!$L$19))/(1+$A34)^10+Assumptions!$B$9)/Assumptions!$B$10,"n/a") -> 3857.3197 | D34: =IF($A34>D$29,(SUMPRODUCT(DCF_Base!$C$19:$L$19/(1+$A34)^DCF_Base!$C$4:$L$4)+MAX(0,MIN(DCF_Base!$L$19*(1+D$29)/($A34-D$29),Assumptions!$B$12*DCF_Base!$L$19))/(1+$A34)^10+Assumptions!$B$9)/Assumptions!$B$10,"n/a") -> 3902.5774 | E34: =IF($A34>E$29,(SUMPRODUCT(DCF_Base!$C$19:$L$19/(1+$A34)^DCF_Base!$C$4:$L$4)+MAX(0,MIN(DCF_Base!$L$19*(1+E$29)/($A34-E$29),Assumptions!$B$12*DCF_Base!$L$19))/(1+$A34)^10+Assumptions!$B$9)/Assumptions!$B$10,"n/a") -> 3952.3608 | F34: =IF($A34>F$29,(SUMPRODUCT(DCF_Base!$C$19:$L$19/(1+$A34)^DCF_Base!$C$4:$L$4)+MAX(0,MIN(DCF_Base!$L$19*(1+F$29)/($A34-F$29),Assumptions!$B$12*DCF_Base!$L$19))/(1+$A34)^10+Assumptions!$B$9)/Assumptions!$B$10,"n/a") -> 4007.3846
A36: Memo: base value with TV capped at 10-yr avg EV/EBITDA 2.66x (no-re-rate reference) | B36: =(DCF_Base!B26+2.66*DCF_Base!L8*DCF_Base!L20+Assumptions!$B$9)/Assumptions!$B$10 -> 4120.6475 | C36: Third-party model's discipline: the stock has never traded above ~3.1x EV/EBITDA in a decade; the gap to the house value is the price of the re-rating thesis
