Workbook

Sheet Model_Info
A1: TOKAI RIKA (6995.T) - DCF MODEL
A3: Lineage | B3: v1.0 (Japan-adapted), built 14-Aug-2026 by Claude (Fable 5) with Stephen via claude.ai (openpyxl; recalculated in LibreOffice; key outputs hand-checked). First model for this name - no prior file.
A5: DATA VINTAGE
A6: FY0 anchors | B6: FY Mar-2026 results from user-supplied metrics CSV (14-Aug-26): revenue 644,701; OP 35,623 (5.5%); EBITDA 58,956 (9.1%); capex 35,232; equity 347,776; DPS Y115.
A7: FY1 guidance | B7: Company guided FY Mar-27 net profit ~-32% (Nikkei, mid-May-26: Middle East situation, raw-material costs). Absolute guided figures not captured - refresh from the May tanshin. Q1 FY27 not yet reviewed.
A8: Balance sheet / shares / price | B8: Net cash Y83.8bn and 85.10m shares at 31-Mar-26 (user CSV). Price Y3,025, Yahoo Japan ~10/11-Aug-26 close.
A10: METHODOLOGY
A11: Owner-FCF basis | B11: SBC (incl. equity-award taxes) fully expensed, projected explicitly per scenario-year as % of revenue; INTEREST INCOME EXCLUDED from flows (cash pile added separately - including both double-counts); cash tax held flat at a normalized Japanese effective rate (Boshoku's rate also absorbs minority-interest leakage - see Model_Info driver notes); D&A and capex as % of revenue; working capital = 0% of the YoY revenue increase (set for this business model); diluted shares held FLAT (SBC expensing substitutes for grant dilution; never do both). TV = Gordon capped at 20x terminal owner FCF. End-of-year discounting. WACC 9.0%. Street-convention values (SBC as non-cash) shown as memos - the house/street pair is the accounting-regime price band.
A12: Scenario drivers | B12: Scenario paths are Claude's judgment, set 14-Aug-2026 in-session with Stephen; not yet user-ratified. JAPAN ADAPTATIONS (differ from tech house defaults, all discussed in-chat): SBC = 0% (cash-comp market; explicit row kept per house rule). Tax = 31% flat Japanese effective rate - conservative vs actual attributable-NI conversion of 74-86% of OP in FY24-26 (non-operating income excluded per the house interest-income rule; minorities negligible). WACC 9.0% (JPY parameters) vs 10.5% USD tech default. WC capture 0. Capex 4.8% held ABOVE D&A 3.6%, near the elevated FY26 actual (5.5%) - deliberately conservative and the single biggest value lever here. Takeover/buy-in premium deliberately EXCLUDED: this values the operating business + net cash only.
A14: UPDATE INSTRUCTIONS
A15: Each quarter | B15: Refresh price, net cash (+date), diluted shares, buyback pace, and the guidance-year driver columns; reassess blue rows 5/7/9/14 per scenario only where new evidence exists; add/extend the Reconciliation tab; increment the version above.
A16: Conventions | B16: Blue = hardcoded input. Yellow = key levers. Black = formula. Green = cross-sheet link. Prefilled values are working examples of the expected format.

Sheet Assumptions
A1: 6995.T - Global Assumptions & Scenario Parameters
A2: Blue = hardcoded input. Yellow = key levers. All ¥ in millions unless stated.
A4: Global inputs
A5: WACC / discount rate | B5: 0.09
A6: D&A (% of revenue) | B6: 0.036
A7: Capex + capitalized software (% of revenue) | B7: 0.048
A8: Working-capital capture (% of YoY revenue incr.) | B8: 0 | H8: Sign/size per business model
A9: Net cash (¥mm) | B9: 83757 | H9: cash 93,757 - debt 10,000, 31-Mar-26 (user CSV)
A10: Fully diluted shares (mm) | B10: 85.1 | H10: shares outstanding, Mar-26 (user CSV); ~7% retired FY24-25; held flat per house rule
A11: Current share price | B11: 3025 | H11: Yahoo Japan close ~10/11-Aug-26; refresh at next TSE close
A12: Terminal value cap (x terminal-year owner FCF) | B12: 20
A14: Scenario parameters | C14: Bear | D14: Base | E14: Bull
A15: Terminal growth rate | C15: 0 | D15: 0.005 | E15: 0.01
A16: Probability weight | C16: 0.15 | D16: 0.5 | E16: 0.35 | F16: =SUM(C16:E16) -> 1 | G16: must sum to 100%
A18: Scenario narratives
A19: Bear | B19: Keiretsu order leakage (bZ-shock) hits HMI/switch share; touchscreen consolidation decontents mechanical switches faster than digital-key/e-latch content replaces them. Margins round-trip toward the FY22-23 trough. FY27 guided decline proves the new normal, not a blip.
A20: Base | B20: FY27 absorbs the guided ~32% net-profit decline (Middle East logistics, raw materials), then margins recover to the FY25-26 zone and hold. Low-single-digit growth as digital key, e-shifter and security content offsets switch decontenting. Buyback/dividend cadence of FY24-26 persists.
A21: Bull | B21: Content-per-vehicle growth (digital key, e-latch, steering HMI, security) outruns decontenting; operating margin pushes past 7% (EBITDA ~11%) as the FY22->FY26 recovery extends. TSE-era capital policy keeps shrinking the share count against a third-of-market-cap cash pile.

Sheet DCF_Bear
A1: 6995.T DCF - Bear - content loss to Chinese suppliers; switch/lever decontenting
A2: Owner-FCF basis: SBC fully expensed, interest income excluded, share count flat. Blue rows = per-year drivers (edit).
B3: 2026A | C3: 2027E | D3: 2028E | E3: 2029E | F3: 2030E | G3: 2031E | H3: 2032E | I3: 2033E | J3: 2034E | K3: 2035E | L3: 2036E
A4: Year index (for discounting) | B4: 0 | C4: 1 | D4: 2 | E4: 3 | F4: 4 | G4: 5 | H4: 6 | I4: 7 | J4: 8 | K4: 9 | L4: 10
A5: Revenue growth YoY | C5: 0 | D5: -0.02 | E5: -0.02 | F5: -0.02 | G5: -0.015 | H5: -0.015 | I5: -0.01 | J5: -0.01 | K5: -0.01 | L5: -0.01
A6: Revenue | B6: 644701 | C6: =B6*(1+C5) -> 644701 | D6: =C6*(1+D5) -> 631806.98 | E6: =D6*(1+E5) -> 619170.84 | F6: =E6*(1+F5) -> 606787.42 | G6: =F6*(1+G5) -> 597685.61 | H6: =G6*(1+H5) -> 588720.33 | I6: =H6*(1+I5) -> 582833.12 | J6: =I6*(1+J5) -> 577004.79 | ... L6: =K6*(1+L5) -> 565522.4
A7: Adj EBITDA margin | B7: 0.0914 | C7: 0.078 | D7: 0.072 | E7: 0.068 | F7: 0.065 | G7: 0.063 | H7: 0.062 | I7: 0.06 | J7: 0.06 | K7: 0.06 | L7: 0.06
A8: Adjusted EBITDA | C8: =C6*C7 -> 50286.678 | D8: =D6*D7 -> 45490.103 | E8: =E6*E7 -> 42103.617 | F8: =F6*F7 -> 39441.183 | G8: =G6*G7 -> 37654.194 | H8: =H6*H7 -> 36500.66 | I8: =I6*I7 -> 34969.987 | J8: =J6*J7 -> 34620.288 | ... L8: =L6*L7 -> 33931.344
A9: SBC (% of revenue) | B9: 0 | C9: 0 | D9: 0 | E9: 0 | F9: 0 | G9: 0 | H9: 0 | I9: 0 | J9: 0 | K9: 0 | L9: 0
A10: SBC (incl. equity-award taxes) | C10: =-C6*C9 -> 0 | D10: =-D6*D9 -> 0 | E10: =-E6*E9 -> 0 | F10: =-F6*F9 -> 0 | G10: =-G6*G9 -> 0 | H10: =-H6*H9 -> 0 | I10: =-I6*I9 -> 0 | J10: =-J6*J9 -> 0 | ... L10: =-L6*L9 -> 0
A11: EBITDA less SBC ('owner EBITDA') | C11: =C8+C10 -> 50286.678 | D11: =D8+D10 -> 45490.103 | E11: =E8+E10 -> 42103.617 | F11: =F8+F10 -> 39441.183 | G11: =G8+G10 -> 37654.194 | H11: =H8+H10 -> 36500.66 | I11: =I8+I10 -> 34969.987 | J11: =J8+J10 -> 34620.288 | ... L11: =L8+L10 -> 33931.344
A12: D&A | C12: =-C6*Assumptions!$B$6 -> -23209.236 | D12: =-D6*Assumptions!$B$6 -> -22745.051 | E12: =-E6*Assumptions!$B$6 -> -22290.15 | F12: =-F6*Assumptions!$B$6 -> -21844.347 | G12: =-G6*Assumptions!$B$6 -> -21516.682 | H12: =-H6*Assumptions!$B$6 -> -21193.932 | I12: =-I6*Assumptions!$B$6 -> -20981.992 | J12: =-J6*Assumptions!$B$6 -> -20772.173 | ... L12: =-L6*Assumptions!$B$6 -> -20358.806
A13: EBIT (SBC expensed) | C13: =C11+C12 -> 27077.442 | D13: =D11+D12 -> 22745.051 | E13: =E11+E12 -> 19813.467 | F13: =F11+F12 -> 17596.835 | G13: =G11+G12 -> 16137.512 | H13: =H11+H12 -> 15306.729 | I13: =I11+I12 -> 13987.995 | J13: =J11+J12 -> 13848.115 | ... L13: =L11+L12 -> 13572.538
A14: Cash tax rate (neg = benefit) | C14: 0.31 | D14: 0.31 | E14: 0.31 | F14: 0.31 | G14: 0.31 | H14: 0.31 | I14: 0.31 | J14: 0.31 | K14: 0.31 | L14: 0.31
A15: NOPAT | C15: =C13*(1-C14) -> 18683.435 | D15: =D13*(1-D14) -> 15694.085 | E15: =E13*(1-E14) -> 13671.292 | F15: =F13*(1-F14) -> 12141.816 | G15: =G13*(1-G14) -> 11134.883 | H15: =H13*(1-H14) -> 10561.643 | I15: =I13*(1-I14) -> 9651.7165 | J15: =J13*(1-J14) -> 9555.1994 | ... L15: =L13*(1-L14) -> 9365.0509
A16: add: D&A | C16: =-C12 -> 23209.236 | D16: =-D12 -> 22745.051 | E16: =-E12 -> 22290.15 | F16: =-F12 -> 21844.347 | G16: =-G12 -> 21516.682 | H16: =-H12 -> 21193.932 | I16: =-I12 -> 20981.992 | J16: =-J12 -> 20772.173 | ... L16: =-L12 -> 20358.806
A17: less: capex + capitalized software | C17: =-C6*Assumptions!$B$7 -> -30945.648 | D17: =-D6*Assumptions!$B$7 -> -30326.735 | E17: =-E6*Assumptions!$B$7 -> -29720.2 | F17: =-F6*Assumptions!$B$7 -> -29125.796 | G17: =-G6*Assumptions!$B$7 -> -28688.909 | H17: =-H6*Assumptions!$B$7 -> -28258.576 | I17: =-I6*Assumptions!$B$7 -> -27975.99 | J17: =-J6*Assumptions!$B$7 -> -27696.23 | ... L17: =-L6*Assumptions!$B$7 -> -27145.075
A18: add: working capital | C18: =Assumptions!$B$8*(C6-B6) -> 0 | D18: =Assumptions!$B$8*(D6-C6) -> 0 | E18: =Assumptions!$B$8*(E6-D6) -> 0 | F18: =Assumptions!$B$8*(F6-E6) -> 0 | G18: =Assumptions!$B$8*(G6-F6) -> 0 | H18: =Assumptions!$B$8*(H6-G6) -> 0 | I18: =Assumptions!$B$8*(I6-H6) -> 0 | J18: =Assumptions!$B$8*(J6-I6) -> 0 | ... L18: =Assumptions!$B$8*(L6-K6) -> 0
A19: Unlevered owner FCF | C19: =C15+C16+C17+C18 -> 10947.023 | D19: =D15+D16+D17+D18 -> 8112.4016 | E19: =E15+E16+E17+E18 -> 6241.2421 | F19: =F15+F16+F17+F18 -> 4860.3673 | G19: =G15+G16+G17+G18 -> 3962.6556 | H19: =H15+H16+H17+H18 -> 3496.9987 | I19: =I15+I16+I17+I18 -> 2657.719 | J19: =J15+J16+J17+J18 -> 2631.1419 | ... L19: =L15+L16+L17+L18 -> 2578.7821
A20: Discount factor | C20: =1/(1+Assumptions!$B$5)^C4 -> 0.91743119 | D20: =1/(1+Assumptions!$B$5)^D4 -> 0.84167999 | E20: =1/(1+Assumptions!$B$5)^E4 -> 0.77218348 | F20: =1/(1+Assumptions!$B$5)^F4 -> 0.70842521 | G20: =1/(1+Assumptions!$B$5)^G4 -> 0.64993139 | H20: =1/(1+Assumptions!$B$5)^H4 -> 0.59626733 | I20: =1/(1+Assumptions!$B$5)^I4 -> 0.54703424 | J20: =1/(1+Assumptions!$B$5)^J4 -> 0.50186628 | ... L20: =1/(1+Assumptions!$B$5)^L4 -> 0.42241081
A21: PV of FCF | C21: =C19*C20 -> 10043.14 | D21: =D19*D20 -> 6828.0461 | E21: =E19*E20 -> 4819.384 | F21: =F19*F20 -> 3443.2067 | G21: =G19*G20 -> 2575.4543 | H21: =H19*H20 -> 2085.1461 | I21: =I19*I20 -> 1453.8633 | J21: =J19*J20 -> 1320.4814 | ... L21: =L19*L20 -> 1089.3054
A23: Memo: FCF before SBC (company-style) | C23: =C19-C10 -> 10947.023 | D23: =D19-D10 -> 8112.4016 | E23: =E19-E10 -> 6241.2421 | F23: =F19-F10 -> 4860.3673 | G23: =G19-G10 -> 3962.6556 | H23: =H19-H10 -> 3496.9987 | I23: =I19-I10 -> 2657.719 | J23: =J19-J10 -> 2631.1419 | ... L23: =L19-L10 -> 2578.7821
A24: Memo: implied owner FCF margin | C24: =C19/C6 -> 0.01698 | D24: =D19/D6 -> 0.01284 | E24: =E19/E6 -> 0.01008 | F24: =F19/F6 -> 0.00801 | G24: =G19/G6 -> 0.00663 | H24: =H19/H6 -> 0.00594 | I24: =I19/I6 -> 0.00456 | J24: =J19/J6 -> 0.00456 | ... L24: =L19/L6 -> 0.00456
A25: Valuation
A26: PV of FCF, explicit years | B26: =SUM(C21:L21) -> 34857.364
A27: Terminal growth rate | B27: =Assumptions!$C$15 -> 0
A28: Terminal-year owner FCF x (1+g) | B28: =L19*(1+B27) -> 2578.7821
A29: Terminal value - Gordon | B29: =B28/(Assumptions!$B$5-B27) -> 28653.135
A30: Terminal value - cap | B30: =Assumptions!$B$12*L19 -> 51575.643
A31: Terminal value used (lower of the two) | B31: =MIN(B29,B30) -> 28653.135
A32: Implied exit multiple | B32: =B31/L19 -> 11.111111
A33: PV of terminal value | B33: =B31*L20 -> 12103.394
A34: Enterprise value | B34: =B26+B33 -> 46960.758
A35: add: net cash | B35: =Assumptions!$B$9 -> 83757
A36: Equity value | B36: =B34+B35 -> 130717.76
A37: Fully diluted shares (mm) | B37: =Assumptions!$B$10 -> 85.1
A38: Value per share | B38: =B36/B37 -> 1536.0489
A39: Upside / (downside) vs current price | B39: =B38/Assumptions!$B$11-1 -> -0.49221525
A41: Memo: value if SBC treated as non-cash | B41: =SUMPRODUCT(-C10:L10/(1+Assumptions!$B$5)^C4:L4) -> 0
A42: plus PV of terminal SBC | B42: =(-L10*(1+B27)/(Assumptions!$B$5-B27))*L20 -> 0
...

Sheet DCF_Base
A1: 6995.T DCF - Base - FY27 dip then margin normalisation; capital returns continue
A2: Owner-FCF basis: SBC fully expensed, interest income excluded, share count flat. Blue rows = per-year drivers (edit).
B3: 2026A | C3: 2027E | D3: 2028E | E3: 2029E | F3: 2030E | G3: 2031E | H3: 2032E | I3: 2033E | J3: 2034E | K3: 2035E | L3: 2036E
A4: Year index (for discounting) | B4: 0 | C4: 1 | D4: 2 | E4: 3 | F4: 4 | G4: 5 | H4: 6 | I4: 7 | J4: 8 | K4: 9 | L4: 10
A5: Revenue growth YoY | C5: 0.02 | D5: 0.02 | E5: 0.02 | F5: 0.02 | G5: 0.015 | H5: 0.015 | I5: 0.015 | J5: 0.01 | K5: 0.01 | L5: 0.01
A6: Revenue | B6: 644701 | C6: =B6*(1+C5) -> 657595.02 | D6: =C6*(1+D5) -> 670746.92 | E6: =D6*(1+E5) -> 684161.86 | F6: =E6*(1+F5) -> 697845.1 | G6: =F6*(1+G5) -> 708312.77 | H6: =G6*(1+H5) -> 718937.46 | I6: =H6*(1+I5) -> 729721.53 | J6: =I6*(1+J5) -> 737018.74 | ... L6: =K6*(1+L5) -> 751832.82
A7: Adj EBITDA margin | B7: 0.0914 | C7: 0.082 | D7: 0.086 | E7: 0.09 | F7: 0.093 | G7: 0.095 | H7: 0.096 | I7: 0.096 | J7: 0.096 | K7: 0.096 | L7: 0.096
A8: Adjusted EBITDA | C8: =C6*C7 -> 53922.792 | D8: =D6*D7 -> 57684.235 | E8: =E6*E7 -> 61574.567 | F8: =F6*F7 -> 64899.594 | G8: =G6*G7 -> 67289.713 | H8: =H6*H7 -> 69017.997 | I8: =I6*I7 -> 70053.266 | J8: =J6*J7 -> 70753.799 | ... L8: =L6*L7 -> 72175.951
A9: SBC (% of revenue) | B9: 0 | C9: 0 | D9: 0 | E9: 0 | F9: 0 | G9: 0 | H9: 0 | I9: 0 | J9: 0 | K9: 0 | L9: 0
A10: SBC (incl. equity-award taxes) | C10: =-C6*C9 -> 0 | D10: =-D6*D9 -> 0 | E10: =-E6*E9 -> 0 | F10: =-F6*F9 -> 0 | G10: =-G6*G9 -> 0 | H10: =-H6*H9 -> 0 | I10: =-I6*I9 -> 0 | J10: =-J6*J9 -> 0 | ... L10: =-L6*L9 -> 0
A11: EBITDA less SBC ('owner EBITDA') | C11: =C8+C10 -> 53922.792 | D11: =D8+D10 -> 57684.235 | E11: =E8+E10 -> 61574.567 | F11: =F8+F10 -> 64899.594 | G11: =G8+G10 -> 67289.713 | H11: =H8+H10 -> 69017.997 | I11: =I8+I10 -> 70053.266 | J11: =J8+J10 -> 70753.799 | ... L11: =L8+L10 -> 72175.951
A12: D&A | C12: =-C6*Assumptions!$B$6 -> -23673.421 | D12: =-D6*Assumptions!$B$6 -> -24146.889 | E12: =-E6*Assumptions!$B$6 -> -24629.827 | F12: =-F6*Assumptions!$B$6 -> -25122.423 | G12: =-G6*Assumptions!$B$6 -> -25499.26 | H12: =-H6*Assumptions!$B$6 -> -25881.749 | I12: =-I6*Assumptions!$B$6 -> -26269.975 | J12: =-J6*Assumptions!$B$6 -> -26532.675 | ... L12: =-L6*Assumptions!$B$6 -> -27065.981
A13: EBIT (SBC expensed) | C13: =C11+C12 -> 30249.371 | D13: =D11+D12 -> 33537.346 | E13: =E11+E12 -> 36944.74 | F13: =F11+F12 -> 39777.17 | G13: =G11+G12 -> 41790.454 | H13: =H11+H12 -> 43136.248 | I13: =I11+I12 -> 43783.292 | J13: =J11+J12 -> 44221.124 | ... L13: =L11+L12 -> 45109.969
A14: Cash tax rate (neg = benefit) | C14: 0.31 | D14: 0.31 | E14: 0.31 | F14: 0.31 | G14: 0.31 | H14: 0.31 | I14: 0.31 | J14: 0.31 | K14: 0.31 | L14: 0.31
A15: NOPAT | C15: =C13*(1-C14) -> 20872.066 | D15: =D13*(1-D14) -> 23140.769 | E15: =E13*(1-E14) -> 25491.871 | F15: =F13*(1-F14) -> 27446.248 | G15: =G13*(1-G14) -> 28835.413 | H15: =H13*(1-H14) -> 29764.011 | I15: =I13*(1-I14) -> 30210.471 | J15: =J13*(1-J14) -> 30512.576 | ... L15: =L13*(1-L14) -> 31125.879
A16: add: D&A | C16: =-C12 -> 23673.421 | D16: =-D12 -> 24146.889 | E16: =-E12 -> 24629.827 | F16: =-F12 -> 25122.423 | G16: =-G12 -> 25499.26 | H16: =-H12 -> 25881.749 | I16: =-I12 -> 26269.975 | J16: =-J12 -> 26532.675 | ... L16: =-L12 -> 27065.981
A17: less: capex + capitalized software | C17: =-C6*Assumptions!$B$7 -> -31564.561 | D17: =-D6*Assumptions!$B$7 -> -32195.852 | E17: =-E6*Assumptions!$B$7 -> -32839.769 | F17: =-F6*Assumptions!$B$7 -> -33496.565 | G17: =-G6*Assumptions!$B$7 -> -33999.013 | H17: =-H6*Assumptions!$B$7 -> -34508.998 | I17: =-I6*Assumptions!$B$7 -> -35026.633 | J17: =-J6*Assumptions!$B$7 -> -35376.9 | ... L17: =-L6*Assumptions!$B$7 -> -36087.975
A18: add: working capital | C18: =Assumptions!$B$8*(C6-B6) -> 0 | D18: =Assumptions!$B$8*(D6-C6) -> 0 | E18: =Assumptions!$B$8*(E6-D6) -> 0 | F18: =Assumptions!$B$8*(F6-E6) -> 0 | G18: =Assumptions!$B$8*(G6-F6) -> 0 | H18: =Assumptions!$B$8*(H6-G6) -> 0 | I18: =Assumptions!$B$8*(I6-H6) -> 0 | J18: =Assumptions!$B$8*(J6-I6) -> 0 | ... L18: =Assumptions!$B$8*(L6-K6) -> 0
A19: Unlevered owner FCF | C19: =C15+C16+C17+C18 -> 12980.926 | D19: =D15+D16+D17+D18 -> 15091.806 | E19: =E15+E16+E17+E18 -> 17281.929 | F19: =F15+F16+F17+F18 -> 19072.106 | G19: =G15+G16+G17+G18 -> 20335.66 | H19: =H15+H16+H17+H18 -> 21136.761 | I19: =I15+I16+I17+I18 -> 21453.813 | J19: =J15+J16+J17+J18 -> 21668.351 | ... L19: =L15+L16+L17+L18 -> 22103.885
A20: Discount factor | C20: =1/(1+Assumptions!$B$5)^C4 -> 0.91743119 | D20: =1/(1+Assumptions!$B$5)^D4 -> 0.84167999 | E20: =1/(1+Assumptions!$B$5)^E4 -> 0.77218348 | F20: =1/(1+Assumptions!$B$5)^F4 -> 0.70842521 | G20: =1/(1+Assumptions!$B$5)^G4 -> 0.64993139 | H20: =1/(1+Assumptions!$B$5)^H4 -> 0.59626733 | I20: =1/(1+Assumptions!$B$5)^I4 -> 0.54703424 | J20: =1/(1+Assumptions!$B$5)^J4 -> 0.50186628 | ... L20: =1/(1+Assumptions!$B$5)^L4 -> 0.42241081
A21: PV of FCF | C21: =C19*C20 -> 11909.106 | D21: =D19*D20 -> 12702.471 | E21: =E19*E20 -> 13344.82 | F21: =F19*F20 -> 13511.161 | G21: =G19*G20 -> 13216.783 | H21: =H19*H20 -> 12603.16 | I21: =I19*I20 -> 11735.97 | J21: =J19*J20 -> 10874.615 | ... L21: =L19*L20 -> 9336.9198
A23: Memo: FCF before SBC (company-style) | C23: =C19-C10 -> 12980.926 | D23: =D19-D10 -> 15091.806 | E23: =E19-E10 -> 17281.929 | F23: =F19-F10 -> 19072.106 | G23: =G19-G10 -> 20335.66 | H23: =H19-H10 -> 21136.761 | I23: =I19-I10 -> 21453.813 | J23: =J19-J10 -> 21668.351 | ... L23: =L19-L10 -> 22103.885
A24: Memo: implied owner FCF margin | C24: =C19/C6 -> 0.01974 | D24: =D19/D6 -> 0.0225 | E24: =E19/E6 -> 0.02526 | F24: =F19/F6 -> 0.02733 | G24: =G19/G6 -> 0.02871 | H24: =H19/H6 -> 0.0294 | I24: =I19/I6 -> 0.0294 | J24: =J19/J6 -> 0.0294 | ... L24: =L19/L6 -> 0.0294
A25: Valuation
A26: PV of FCF, explicit years | B26: =SUM(C21:L21) -> 119311.48
A27: Terminal growth rate | B27: =Assumptions!$D$15 -> 0.005
A28: Terminal-year owner FCF x (1+g) | B28: =L19*(1+B27) -> 22214.404
A29: Terminal value - Gordon | B29: =B28/(Assumptions!$B$5-B27) -> 261345.93
A30: Terminal value - cap | B30: =Assumptions!$B$12*L19 -> 442077.7
A31: Terminal value used (lower of the two) | B31: =MIN(B29,B30) -> 261345.93
A32: Implied exit multiple | B32: =B31/L19 -> 11.823529
A33: PV of terminal value | B33: =B31*L20 -> 110395.35
A34: Enterprise value | B34: =B26+B33 -> 229706.83
A35: add: net cash | B35: =Assumptions!$B$9 -> 83757
A36: Equity value | B36: =B34+B35 -> 313463.83
A37: Fully diluted shares (mm) | B37: =Assumptions!$B$10 -> 85.1
A38: Value per share | B38: =B36/B37 -> 3683.4763
A39: Upside / (downside) vs current price | B39: =B38/Assumptions!$B$11-1 -> 0.21767811
A41: Memo: value if SBC treated as non-cash | B41: =SUMPRODUCT(-C10:L10/(1+Assumptions!$B$5)^C4:L4) -> 0
A42: plus PV of terminal SBC | B42: =(-L10*(1+B27)/(Assumptions!$B$5-B27))*L20 -> 0
...

Sheet DCF_Bull
A1: 6995.T DCF - Bull - HMI/digital-key content story compounds; ROE push sustained
A2: Owner-FCF basis: SBC fully expensed, interest income excluded, share count flat. Blue rows = per-year drivers (edit).
B3: 2026A | C3: 2027E | D3: 2028E | E3: 2029E | F3: 2030E | G3: 2031E | H3: 2032E | I3: 2033E | J3: 2034E | K3: 2035E | L3: 2036E
A4: Year index (for discounting) | B4: 0 | C4: 1 | D4: 2 | E4: 3 | F4: 4 | G4: 5 | H4: 6 | I4: 7 | J4: 8 | K4: 9 | L4: 10
A5: Revenue growth YoY | C5: 0.03 | D5: 0.04 | E5: 0.035 | F5: 0.03 | G5: 0.03 | H5: 0.025 | I5: 0.02 | J5: 0.02 | K5: 0.015 | L5: 0.015
A6: Revenue | B6: 644701 | C6: =B6*(1+C5) -> 664042.03 | D6: =C6*(1+D5) -> 690603.71 | E6: =D6*(1+E5) -> 714774.84 | F6: =E6*(1+F5) -> 736218.09 | G6: =F6*(1+G5) -> 758304.63 | H6: =G6*(1+H5) -> 777262.24 | I6: =H6*(1+I5) -> 792807.49 | J6: =I6*(1+J5) -> 808663.64 | ... L6: =K6*(1+L5) -> 833105.5
A7: Adj EBITDA margin | B7: 0.0914 | C7: 0.085 | D7: 0.093 | E7: 0.1 | F7: 0.105 | G7: 0.108 | H7: 0.11 | I7: 0.111 | J7: 0.112 | K7: 0.112 | L7: 0.112
A8: Adjusted EBITDA | C8: =C6*C7 -> 56443.573 | D8: =D6*D7 -> 64226.145 | E8: =E6*E7 -> 71477.484 | F8: =F6*F7 -> 77302.899 | G8: =G6*G7 -> 81896.9 | H8: =H6*H7 -> 85498.847 | I8: =I6*I7 -> 88001.631 | J8: =J6*J7 -> 90570.328 | ... L8: =L6*L7 -> 93307.816
A9: SBC (% of revenue) | B9: 0 | C9: 0 | D9: 0 | E9: 0 | F9: 0 | G9: 0 | H9: 0 | I9: 0 | J9: 0 | K9: 0 | L9: 0
A10: SBC (incl. equity-award taxes) | C10: =-C6*C9 -> 0 | D10: =-D6*D9 -> 0 | E10: =-E6*E9 -> 0 | F10: =-F6*F9 -> 0 | G10: =-G6*G9 -> 0 | H10: =-H6*H9 -> 0 | I10: =-I6*I9 -> 0 | J10: =-J6*J9 -> 0 | ... L10: =-L6*L9 -> 0
A11: EBITDA less SBC ('owner EBITDA') | C11: =C8+C10 -> 56443.573 | D11: =D8+D10 -> 64226.145 | E11: =E8+E10 -> 71477.484 | F11: =F8+F10 -> 77302.899 | G11: =G8+G10 -> 81896.9 | H11: =H8+H10 -> 85498.847 | I11: =I8+I10 -> 88001.631 | J11: =J8+J10 -> 90570.328 | ... L11: =L8+L10 -> 93307.816
A12: D&A | C12: =-C6*Assumptions!$B$6 -> -23905.513 | D12: =-D6*Assumptions!$B$6 -> -24861.734 | E12: =-E6*Assumptions!$B$6 -> -25731.894 | F12: =-F6*Assumptions!$B$6 -> -26503.851 | G12: =-G6*Assumptions!$B$6 -> -27298.967 | H12: =-H6*Assumptions!$B$6 -> -27981.441 | I12: =-I6*Assumptions!$B$6 -> -28541.07 | J12: =-J6*Assumptions!$B$6 -> -29111.891 | ... L12: =-L6*Assumptions!$B$6 -> -29991.798
A13: EBIT (SBC expensed) | C13: =C11+C12 -> 32538.059 | D13: =D11+D12 -> 39364.412 | E13: =E11+E12 -> 45745.59 | F13: =F11+F12 -> 50799.048 | G13: =G11+G12 -> 54597.933 | H13: =H11+H12 -> 57517.406 | I13: =I11+I12 -> 59460.562 | J13: =J11+J12 -> 61458.437 | ... L13: =L11+L12 -> 63316.018
A14: Cash tax rate (neg = benefit) | C14: 0.31 | D14: 0.31 | E14: 0.31 | F14: 0.31 | G14: 0.31 | H14: 0.31 | I14: 0.31 | J14: 0.31 | K14: 0.31 | L14: 0.31
A15: NOPAT | C15: =C13*(1-C14) -> 22451.261 | D15: =D13*(1-D14) -> 27161.444 | E15: =E13*(1-E14) -> 31564.457 | F15: =F13*(1-F14) -> 35051.343 | G15: =G13*(1-G14) -> 37672.574 | H15: =H13*(1-H14) -> 39687.01 | I15: =I13*(1-I14) -> 41027.788 | J15: =J13*(1-J14) -> 42406.321 | ... L15: =L13*(1-L14) -> 43688.052
A16: add: D&A | C16: =-C12 -> 23905.513 | D16: =-D12 -> 24861.734 | E16: =-E12 -> 25731.894 | F16: =-F12 -> 26503.851 | G16: =-G12 -> 27298.967 | H16: =-H12 -> 27981.441 | I16: =-I12 -> 28541.07 | J16: =-J12 -> 29111.891 | ... L16: =-L12 -> 29991.798
A17: less: capex + capitalized software | C17: =-C6*Assumptions!$B$7 -> -31874.017 | D17: =-D6*Assumptions!$B$7 -> -33148.978 | E17: =-E6*Assumptions!$B$7 -> -34309.192 | F17: =-F6*Assumptions!$B$7 -> -35338.468 | G17: =-G6*Assumptions!$B$7 -> -36398.622 | H17: =-H6*Assumptions!$B$7 -> -37308.588 | I17: =-I6*Assumptions!$B$7 -> -38054.759 | J17: =-J6*Assumptions!$B$7 -> -38815.855 | ... L17: =-L6*Assumptions!$B$7 -> -39989.064
A18: add: working capital | C18: =Assumptions!$B$8*(C6-B6) -> 0 | D18: =Assumptions!$B$8*(D6-C6) -> 0 | E18: =Assumptions!$B$8*(E6-D6) -> 0 | F18: =Assumptions!$B$8*(F6-E6) -> 0 | G18: =Assumptions!$B$8*(G6-F6) -> 0 | H18: =Assumptions!$B$8*(H6-G6) -> 0 | I18: =Assumptions!$B$8*(I6-H6) -> 0 | J18: =Assumptions!$B$8*(J6-I6) -> 0 | ... L18: =Assumptions!$B$8*(L6-K6) -> 0
A19: Unlevered owner FCF | C19: =C15+C16+C17+C18 -> 14482.757 | D19: =D15+D16+D17+D18 -> 18874.199 | E19: =E15+E16+E17+E18 -> 22987.159 | F19: =F15+F16+F17+F18 -> 26216.726 | G19: =G15+G16+G17+G18 -> 28572.918 | H19: =H15+H16+H17+H18 -> 30359.863 | I19: =I15+I16+I17+I18 -> 31514.098 | J19: =J15+J16+J17+J18 -> 32702.358 | ... L19: =L15+L16+L17+L18 -> 33690.786
A20: Discount factor | C20: =1/(1+Assumptions!$B$5)^C4 -> 0.91743119 | D20: =1/(1+Assumptions!$B$5)^D4 -> 0.84167999 | E20: =1/(1+Assumptions!$B$5)^E4 -> 0.77218348 | F20: =1/(1+Assumptions!$B$5)^F4 -> 0.70842521 | G20: =1/(1+Assumptions!$B$5)^G4 -> 0.64993139 | H20: =1/(1+Assumptions!$B$5)^H4 -> 0.59626733 | I20: =1/(1+Assumptions!$B$5)^I4 -> 0.54703424 | J20: =1/(1+Assumptions!$B$5)^J4 -> 0.50186628 | ... L20: =1/(1+Assumptions!$B$5)^L4 -> 0.42241081
A21: PV of FCF | C21: =C19*C20 -> 13286.933 | D21: =D19*D20 -> 15886.036 | E21: =E19*E20 -> 17750.304 | F21: =F19*F20 -> 18572.59 | G21: =G19*G20 -> 18570.436 | H21: =H19*H20 -> 18102.595 | I21: =I19*I20 -> 17239.291 | J21: =J19*J20 -> 16412.211 | ... L21: =L19*L20 -> 14231.352
A23: Memo: FCF before SBC (company-style) | C23: =C19-C10 -> 14482.757 | D23: =D19-D10 -> 18874.199 | E23: =E19-E10 -> 22987.159 | F23: =F19-F10 -> 26216.726 | G23: =G19-G10 -> 28572.918 | H23: =H19-H10 -> 30359.863 | I23: =I19-I10 -> 31514.098 | J23: =J19-J10 -> 32702.358 | ... L23: =L19-L10 -> 33690.786
A24: Memo: implied owner FCF margin | C24: =C19/C6 -> 0.02181 | D24: =D19/D6 -> 0.02733 | E24: =E19/E6 -> 0.03216 | F24: =F19/F6 -> 0.03561 | G24: =G19/G6 -> 0.03768 | H24: =H19/H6 -> 0.03906 | I24: =I19/I6 -> 0.03975 | J24: =J19/J6 -> 0.04044 | ... L24: =L19/L6 -> 0.04044
A25: Valuation
A26: PV of FCF, explicit years | B26: =SUM(C21:L21) -> 165334.68
A27: Terminal growth rate | B27: =Assumptions!$E$15 -> 0.01
A28: Terminal-year owner FCF x (1+g) | B28: =L19*(1+B27) -> 34027.694
A29: Terminal value - Gordon | B29: =B28/(Assumptions!$B$5-B27) -> 425346.18
A30: Terminal value - cap | B30: =Assumptions!$B$12*L19 -> 673815.73
A31: Terminal value used (lower of the two) | B31: =MIN(B29,B30) -> 425346.18
A32: Implied exit multiple | B32: =B31/L19 -> 12.625
A33: PV of terminal value | B33: =B31*L20 -> 179670.82
A34: Enterprise value | B34: =B26+B33 -> 345005.5
A35: add: net cash | B35: =Assumptions!$B$9 -> 83757
A36: Equity value | B36: =B34+B35 -> 428762.5
A37: Fully diluted shares (mm) | B37: =Assumptions!$B$10 -> 85.1
A38: Value per share | B38: =B36/B37 -> 5038.3372
A39: Upside / (downside) vs current price | B39: =B38/Assumptions!$B$11-1 -> 0.66556603
A41: Memo: value if SBC treated as non-cash | B41: =SUMPRODUCT(-C10:L10/(1+Assumptions!$B$5)^C4:L4) -> 0
A42: plus PV of terminal SBC | B42: =(-L10*(1+B27)/(Assumptions!$B$5-B27))*L20 -> 0
...

Sheet Valuation
A1: 6995.T - Valuation Summary & Sensitivity
A2: Owner-FCF basis (SBC expensed) unless marked street. Green = links.
B4: Bear | C4: Base | D4: Bull
A5: Value per share | B5: =DCF_Bear!$B$38 -> 1536.0489 | C5: =DCF_Base!$B$38 -> 3683.4763 | D5: =DCF_Bull!$B$38 -> 5038.3372
A6: Upside / (downside) vs price | B6: =B5/Assumptions!$B$11-1 -> -0.49221525 | C6: =C5/Assumptions!$B$11-1 -> 0.21767811 | D6: =D5/Assumptions!$B$11-1 -> 0.66556603
A7: Probability | B7: =Assumptions!$C$16 -> 0.15 | C7: =Assumptions!$D$16 -> 0.5 | D7: =Assumptions!$E$16 -> 0.35
A8: Value per share, SBC as non-cash (street) | B8: =DCF_Bear!$B$43 -> 1536.0489 | C8: =DCF_Base!$B$43 -> 3683.4763 | D8: =DCF_Bull!$B$43 -> 5038.3372
A10: Probability-weighted value per share | B10: =SUMPRODUCT(B5:D5,B7:D7) -> 3835.5635
A11: Current price | B11: =Assumptions!$B$11 -> 3025
A12: Margin of safety vs weighted value | B12: =1-B11/B10 -> 0.2113284
A13: Weighted value, SBC as non-cash (street) | B13: =SUMPRODUCT(B8:D8,B7:D7) -> 3835.5635
A14: Band position (0%=house, 100%=street) | B14: n/a | C14: SBC = 0 so house = street; the accounting-regime band collapses to a single value
A17: Base case - value per share at different required returns
A18: Required return | B18: Value / share
A19: 0.09 | B19: =(SUMPRODUCT(DCF_Base!$C$19:$L$19/(1+$A19)^DCF_Base!$C$4:$L$4)+MIN(DCF_Base!$L$19*(1+Assumptions!$D$15)/($A19-Assumptions!$D$15),Assumptions!$B$12*DCF_Base!$L$19)/(1+$A19)^10+Assumptions!$B$9)/Assumptions!$B$10 -> 3683.4763
A20: 0.1 | B20: =(SUMPRODUCT(DCF_Base!$C$19:$L$19/(1+$A20)^DCF_Base!$C$4:$L$4)+MIN(DCF_Base!$L$19*(1+Assumptions!$D$15)/($A20-Assumptions!$D$15),Assumptions!$B$12*DCF_Base!$L$19)/(1+$A20)^10+Assumptions!$B$9)/Assumptions!$B$10 -> 3380.4225
A21: 0.105 | B21: =(SUMPRODUCT(DCF_Base!$C$19:$L$19/(1+$A21)^DCF_Base!$C$4:$L$4)+MIN(DCF_Base!$L$19*(1+Assumptions!$D$15)/($A21-Assumptions!$D$15),Assumptions!$B$12*DCF_Base!$L$19)/(1+$A21)^10+Assumptions!$B$9)/Assumptions!$B$10 -> 3251.8985
A22: 0.11 | B22: =(SUMPRODUCT(DCF_Base!$C$19:$L$19/(1+$A22)^DCF_Base!$C$4:$L$4)+MIN(DCF_Base!$L$19*(1+Assumptions!$D$15)/($A22-Assumptions!$D$15),Assumptions!$B$12*DCF_Base!$L$19)/(1+$A22)^10+Assumptions!$B$9)/Assumptions!$B$10 -> 3135.7822
A23: 0.12 | B23: =(SUMPRODUCT(DCF_Base!$C$19:$L$19/(1+$A23)^DCF_Base!$C$4:$L$4)+MIN(DCF_Base!$L$19*(1+Assumptions!$D$15)/($A23-Assumptions!$D$15),Assumptions!$B$12*DCF_Base!$L$19)/(1+$A23)^10+Assumptions!$B$9)/Assumptions!$B$10 -> 2934.2824
A24: 0.15 | B24: =(SUMPRODUCT(DCF_Base!$C$19:$L$19/(1+$A24)^DCF_Base!$C$4:$L$4)+MIN(DCF_Base!$L$19*(1+Assumptions!$D$15)/($A24-Assumptions!$D$15),Assumptions!$B$12*DCF_Base!$L$19)/(1+$A24)^10+Assumptions!$B$9)/Assumptions!$B$10 -> 2499.123
A25: 15%-hurdle entry per scenario + weighted | B25: =(SUMPRODUCT(DCF_Bear!$C$19:$L$19/(1+0.15)^DCF_Bear!$C$4:$L$4)+MIN(DCF_Bear!$L$19*(1+Assumptions!$C$15)/(0.15-Assumptions!$C$15),Assumptions!$B$12*DCF_Bear!$L$19)/(1+0.15)^10+Assumptions!$B$9)/Assumptions!$B$10 -> 1377.9277 | C25: =(SUMPRODUCT(DCF_Base!$C$19:$L$19/(1+0.15)^DCF_Base!$C$4:$L$4)+MIN(DCF_Base!$L$19*(1+Assumptions!$D$15)/(0.15-Assumptions!$D$15),Assumptions!$B$12*DCF_Base!$L$19)/(1+0.15)^10+Assumptions!$B$9)/Assumptions!$B$10 -> 2499.123 | D25: =(SUMPRODUCT(DCF_Bull!$C$19:$L$19/(1+0.15)^DCF_Bull!$C$4:$L$4)+MIN(DCF_Bull!$L$19*(1+Assumptions!$E$15)/(0.15-Assumptions!$E$15),Assumptions!$B$12*DCF_Bull!$L$19)/(1+0.15)^10+Assumptions!$B$9)/Assumptions!$B$10 -> 3154.3833 | E25: =SUMPRODUCT(B25:D25,$B$7:$D$7) -> 2560.2848 | G25: model buy-below price at a 15% hurdle
A26: same, street basis | B26: =B25+(SUMPRODUCT(-DCF_Bear!$C$10:$L$10/(1+0.15)^DCF_Bear!$C$4:$L$4)+(-DCF_Bear!$L$10*(1+Assumptions!$C$15)/(0.15-Assumptions!$C$15))/(1+0.15)^10)/Assumptions!$B$10 -> 1377.9277 | C26: =C25+(SUMPRODUCT(-DCF_Base!$C$10:$L$10/(1+0.15)^DCF_Base!$C$4:$L$4)+(-DCF_Base!$L$10*(1+Assumptions!$D$15)/(0.15-Assumptions!$D$15))/(1+0.15)^10)/Assumptions!$B$10 -> 2499.123 | D26: =D25+(SUMPRODUCT(-DCF_Bull!$C$10:$L$10/(1+0.15)^DCF_Bull!$C$4:$L$4)+(-DCF_Bull!$L$10*(1+Assumptions!$E$15)/(0.15-Assumptions!$E$15))/(1+0.15)^10)/Assumptions!$B$10 -> 3154.3833 | E26: =SUMPRODUCT(B26:D26,$B$7:$D$7) -> 2560.2848
A28: Base case - value per share: WACC x terminal growth
A29: WACC \ g | B29: 0 | C29: 0.005 | D29: 0.01 | E29: 0.015 | F29: 0.02
A30: 0.095 | B30: =IF($A30>B$29,(SUMPRODUCT(DCF_Base!$C$19:$L$19/(1+$A30)^DCF_Base!$C$4:$L$4)+MIN(DCF_Base!$L$19*(1+B$29)/($A30-B$29),Assumptions!$B$12*DCF_Base!$L$19)/(1+$A30)^10+Assumptions!$B$9)/Assumptions!$B$10,"n/a") -> 3456.3134 | C30: =IF($A30>C$29,(SUMPRODUCT(DCF_Base!$C$19:$L$19/(1+$A30)^DCF_Base!$C$4:$L$4)+MIN(DCF_Base!$L$19*(1+C$29)/($A30-C$29),Assumptions!$B$12*DCF_Base!$L$19)/(1+$A30)^10+Assumptions!$B$9)/Assumptions!$B$10,"n/a") -> 3523.4279 | D30: =IF($A30>D$29,(SUMPRODUCT(DCF_Base!$C$19:$L$19/(1+$A30)^DCF_Base!$C$4:$L$4)+MIN(DCF_Base!$L$19*(1+D$29)/($A30-D$29),Assumptions!$B$12*DCF_Base!$L$19)/(1+$A30)^10+Assumptions!$B$9)/Assumptions!$B$10,"n/a") -> 3598.4381 | E30: =IF($A30>E$29,(SUMPRODUCT(DCF_Base!$C$19:$L$19/(1+$A30)^DCF_Base!$C$4:$L$4)+MIN(DCF_Base!$L$19*(1+E$29)/($A30-E$29),Assumptions!$B$12*DCF_Base!$L$19)/(1+$A30)^10+Assumptions!$B$9)/Assumptions!$B$10,"n/a") -> 3682.8246 | F30: =IF($A30>F$29,(SUMPRODUCT(DCF_Base!$C$19:$L$19/(1+$A30)^DCF_Base!$C$4:$L$4)+MIN(DCF_Base!$L$19*(1+F$29)/($A30-F$29),Assumptions!$B$12*DCF_Base!$L$19)/(1+$A30)^10+Assumptions!$B$9)/Assumptions!$B$10,"n/a") -> 3778.4627
A31: 0.1 | B31: =IF($A31>B$29,(SUMPRODUCT(DCF_Base!$C$19:$L$19/(1+$A31)^DCF_Base!$C$4:$L$4)+MIN(DCF_Base!$L$19*(1+B$29)/($A31-B$29),Assumptions!$B$12*DCF_Base!$L$19)/(1+$A31)^10+Assumptions!$B$9)/Assumptions!$B$10,"n/a") -> 3322.4461 | C31: =IF($A31>C$29,(SUMPRODUCT(DCF_Base!$C$19:$L$19/(1+$A31)^DCF_Base!$C$4:$L$4)+MIN(DCF_Base!$L$19*(1+C$29)/($A31-C$29),Assumptions!$B$12*DCF_Base!$L$19)/(1+$A31)^10+Assumptions!$B$9)/Assumptions!$B$10,"n/a") -> 3380.4225 | D31: =IF($A31>D$29,(SUMPRODUCT(DCF_Base!$C$19:$L$19/(1+$A31)^DCF_Base!$C$4:$L$4)+MIN(DCF_Base!$L$19*(1+D$29)/($A31-D$29),Assumptions!$B$12*DCF_Base!$L$19)/(1+$A31)^10+Assumptions!$B$9)/Assumptions!$B$10,"n/a") -> 3444.8407 | E31: =IF($A31>E$29,(SUMPRODUCT(DCF_Base!$C$19:$L$19/(1+$A31)^DCF_Base!$C$4:$L$4)+MIN(DCF_Base!$L$19*(1+E$29)/($A31-E$29),Assumptions!$B$12*DCF_Base!$L$19)/(1+$A31)^10+Assumptions!$B$9)/Assumptions!$B$10,"n/a") -> 3516.8376 | F31: =IF($A31>F$29,(SUMPRODUCT(DCF_Base!$C$19:$L$19/(1+$A31)^DCF_Base!$C$4:$L$4)+MIN(DCF_Base!$L$19*(1+F$29)/($A31-F$29),Assumptions!$B$12*DCF_Base!$L$19)/(1+$A31)^10+Assumptions!$B$9)/Assumptions!$B$10,"n/a") -> 3597.834
A32: 0.105 | B32: =IF($A32>B$29,(SUMPRODUCT(DCF_Base!$C$19:$L$19/(1+$A32)^DCF_Base!$C$4:$L$4)+MIN(DCF_Base!$L$19*(1+B$29)/($A32-B$29),Assumptions!$B$12*DCF_Base!$L$19)/(1+$A32)^10+Assumptions!$B$9)/Assumptions!$B$10,"n/a") -> 3201.5415 | C32: =IF($A32>C$29,(SUMPRODUCT(DCF_Base!$C$19:$L$19/(1+$A32)^DCF_Base!$C$4:$L$4)+MIN(DCF_Base!$L$19*(1+C$29)/($A32-C$29),Assumptions!$B$12*DCF_Base!$L$19)/(1+$A32)^10+Assumptions!$B$9)/Assumptions!$B$10,"n/a") -> 3251.8985 | D32: =IF($A32>D$29,(SUMPRODUCT(DCF_Base!$C$19:$L$19/(1+$A32)^DCF_Base!$C$4:$L$4)+MIN(DCF_Base!$L$19*(1+D$29)/($A32-D$29),Assumptions!$B$12*DCF_Base!$L$19)/(1+$A32)^10+Assumptions!$B$9)/Assumptions!$B$10,"n/a") -> 3307.5561 | E32: =IF($A32>E$29,(SUMPRODUCT(DCF_Base!$C$19:$L$19/(1+$A32)^DCF_Base!$C$4:$L$4)+MIN(DCF_Base!$L$19*(1+E$29)/($A32-E$29),Assumptions!$B$12*DCF_Base!$L$19)/(1+$A32)^10+Assumptions!$B$9)/Assumptions!$B$10,"n/a") -> 3369.398 | F32: =IF($A32>F$29,(SUMPRODUCT(DCF_Base!$C$19:$L$19/(1+$A32)^DCF_Base!$C$4:$L$4)+MIN(DCF_Base!$L$19*(1+F$29)/($A32-F$29),Assumptions!$B$12*DCF_Base!$L$19)/(1+$A32)^10+Assumptions!$B$9)/Assumptions!$B$10,"n/a") -> 3438.5153
A33: 0.11 | B33: =IF($A33>B$29,(SUMPRODUCT(DCF_Base!$C$19:$L$19/(1+$A33)^DCF_Base!$C$4:$L$4)+MIN(DCF_Base!$L$19*(1+B$29)/($A33-B$29),Assumptions!$B$12*DCF_Base!$L$19)/(1+$A33)^10+Assumptions!$B$9)/Assumptions!$B$10,"n/a") -> 3091.826 | C33: =IF($A33>C$29,(SUMPRODUCT(DCF_Base!$C$19:$L$19/(1+$A33)^DCF_Base!$C$4:$L$4)+MIN(DCF_Base!$L$19*(1+C$29)/($A33-C$29),Assumptions!$B$12*DCF_Base!$L$19)/(1+$A33)^10+Assumptions!$B$9)/Assumptions!$B$10,"n/a") -> 3135.7822 | D33: =IF($A33>D$29,(SUMPRODUCT(DCF_Base!$C$19:$L$19/(1+$A33)^DCF_Base!$C$4:$L$4)+MIN(DCF_Base!$L$19*(1+D$29)/($A33-D$29),Assumptions!$B$12*DCF_Base!$L$19)/(1+$A33)^10+Assumptions!$B$9)/Assumptions!$B$10,"n/a") -> 3184.134 | E33: =IF($A33>E$29,(SUMPRODUCT(DCF_Base!$C$19:$L$19/(1+$A33)^DCF_Base!$C$4:$L$4)+MIN(DCF_Base!$L$19*(1+E$29)/($A33-E$29),Assumptions!$B$12*DCF_Base!$L$19)/(1+$A33)^10+Assumptions!$B$9)/Assumptions!$B$10,"n/a") -> 3237.5755 | F33: =IF($A33>F$29,(SUMPRODUCT(DCF_Base!$C$19:$L$19/(1+$A33)^DCF_Base!$C$4:$L$4)+MIN(DCF_Base!$L$19*(1+F$29)/($A33-F$29),Assumptions!$B$12*DCF_Base!$L$19)/(1+$A33)^10+Assumptions!$B$9)/Assumptions!$B$10,"n/a") -> 3296.955
A34: 0.115 | B34: =IF($A34>B$29,(SUMPRODUCT(DCF_Base!$C$19:$L$19/(1+$A34)^DCF_Base!$C$4:$L$4)+MIN(DCF_Base!$L$19*(1+B$29)/($A34-B$29),Assumptions!$B$12*DCF_Base!$L$19)/(1+$A34)^10+Assumptions!$B$9)/Assumptions!$B$10,"n/a") -> 2991.8343 | C34: =IF($A34>C$29,(SUMPRODUCT(DCF_Base!$C$19:$L$19/(1+$A34)^DCF_Base!$C$4:$L$4)+MIN(DCF_Base!$L$19*(1+C$29)/($A34-C$29),Assumptions!$B$12*DCF_Base!$L$19)/(1+$A34)^10+Assumptions!$B$9)/Assumptions!$B$10,"n/a") -> 3030.3773 | D34: =IF($A34>D$29,(SUMPRODUCT(DCF_Base!$C$19:$L$19/(1+$A34)^DCF_Base!$C$4:$L$4)+MIN(DCF_Base!$L$19*(1+D$29)/($A34-D$29),Assumptions!$B$12*DCF_Base!$L$19)/(1+$A34)^10+Assumptions!$B$9)/Assumptions!$B$10,"n/a") -> 3072.5909 | E34: =IF($A34>E$29,(SUMPRODUCT(DCF_Base!$C$19:$L$19/(1+$A34)^DCF_Base!$C$4:$L$4)+MIN(DCF_Base!$L$19*(1+E$29)/($A34-E$29),Assumptions!$B$12*DCF_Base!$L$19)/(1+$A34)^10+Assumptions!$B$9)/Assumptions!$B$10,"n/a") -> 3119.026 | F34: =IF($A34>F$29,(SUMPRODUCT(DCF_Base!$C$19:$L$19/(1+$A34)^DCF_Base!$C$4:$L$4)+MIN(DCF_Base!$L$19*(1+F$29)/($A34-F$29),Assumptions!$B$12*DCF_Base!$L$19)/(1+$A34)^10+Assumptions!$B$9)/Assumptions!$B$10,"n/a") -> 3170.3489
