Workbook

Sheet Model_Info
A1: MOVe Logistics Group (MOV.NZ) -- DCF Model
A3: Version | B3: 1.0 -- fresh build (no prior MOV.NZ_DCF.json existed).
A4: Built by | B4: dcf-analyst agent (Claude, Sonnet 5), 2026-08-20, at the user's request.
A5: Methodology | B5: Owner-FCF DCF, .claude/skills/dcf-methods/references/owner-fcf.md, plus section 7 non-US/cyclical adaptations (currency, leases, SBC-zero market).
A6: Model routing | B6: Operating company (NZ domestic freight/logistics) -- not a bank/REIT/LIC/holdco -- routes to Owner-FCF DCF per SKILL.md. No prior MEMORY.md entry for MOV.NZ existed to constrain the choice.
A7: Price data vintage | B7: NZD 0.205, Yahoo Finance regularMarketTime 2026-08-20T03:42:36Z (regular NZX session, not after-hours).
A8: Balance sheet vintage | B8: 31-Dec-2025 (H1-2026 interim report) -- net debt (bank borrowings $21.418m less cash $8.14m) and share count refreshed to this date, NOT the older 30-Jun-2025 annual balance sheet.
A9: Share count | B9: 127,614,019 fully diluted weighted-average shares, unchanged since FY2023. Dilutive LTI awards currently anti-dilutive given losses -- excluded. Held FLAT across all 10 projection years (annual_share_growth_pct = 0%).
A10: Guidance basis | B10: FY2026 guidance per H1-2026 results (26-Feb-2026) and 24-Jul-2026 pre-results trading update: positive full-year Normalised EBT achieved; positive free cash flow restored; net debt reduced. FY26 audited results due 25-Aug-2026 (after this valuation date) -- REFRESH after that print.
A11: Lease treatment | B11: Section 7(b) treatment (B): 'leases as operating cost'. Lease principal repayments (IFRS 16, sit in financing per the cash flow statement) are DEDUCTED from owner FCF as a capex-like fleet-renewal cost -- consistent with MOV's largely-leased truck fleet and near-zero PPE capex ($0.186m FY2025). Lease liabilities ($146.98m at H1-2026) are EXCLUDED from net_debt, which is bank borrowings only ($21.418m).
A12: SBC treatment | B12: SBC is genuinely immaterial ($47k FY2025, $0 FY2024) -- SBC-zero market per section 7(e). Kept as an explicit 0% row rather than deleted. House and street bases coincide; band_position is null, not a degenerate 0%.
A13: WACC | B13: Single 16.5% WACC used across ALL THREE scenarios (bear/base/bull) per section 7(f) 'charge risk once' -- cyclicality, customer concentration and going-concern risk are priced in the scenario flows and the probability weights (30% bear), not doubled into a per-scenario discount rate.
A14: Terminal value | B14: max(0, min(Gordon, cap multiple x Year-10 FCF)). Base case: Gordon bound (7.03x implied exit multiple, below the 8x cap). Bear case: cap bound (6.0x) since terminal-year FCF is small and positive.
... A20: Staleness warning | B20: All figures in this workbook go stale. Do not treat the intrinsic values as current without checking price_as_of and balance_sheet_date above against today's date.

Sheet Actuals
A1: MOV.NZ -- Reported History (NZD millions, unless noted)
A3: Metric | B3: FY2019 | C3: FY2020 | D3: FY2021 | E3: FY2022 | F3: FY2023 | G3: FY2024 | H3: FY2025 | I3: H1-2026
A4: Revenue | B4: 355.139 | C4: 333.811 | D4: 353.247 | E4: 360.121 | F4: 343.873 | G4: 293.866 | H4: 286.256 | I4: 141.4
A5: EBITDA (reported) | B5: 25.401 | C5: 57.416 | D5: 61.314 | E5: 56.191 | F5: 47.348 | G5: 27.631 | H5: 42.067 | I5: 23.384
A6: Net income (attrib. owners) | B6: 4.004 | C6: 2.015 | D6: 0.869 | E6: -4.208 | F6: -7.19 | G6: -48.063 | H6: -15.576 | I6: -0.907
A7: Shareholders' equity | B7: 34.322 | C7: 36.926 | D7: 37.967 | E7: 72.993 | F7: 74.903 | G7: 27.163 | H7: 11.402 | I7: 10.58
A8: Reported FCF (CSV definition) | B8: -4.241 | C8: 25.238 | D8: 36.607 | E8: 29.233 | F8: 19.272 | G8: 16.818 | H8: 25.14 | I8: 16.34
A9: Lease principal repaid (IFRS16) | C9: 22.956 | D9: 28.099 | E9: 28.266 | F9: 27.318 | G9: 29.521 | H9: 30.964 | I9: 14.918
A10: Owner FCF (reported - lease principal) | C10: 2.282 | D10: 8.508 | E10: 0.967 | F10: -8.046 | G10: -12.703 | H10: -5.824 | I10: 1.422
A11: Shares outstanding (m) | B11: 84.329 | C11: 87.685 | D11: 87.685 | E11: 106.049 | F11: 127.614 | G11: 127.614 | H11: 127.614 | I11: 127.614
A12: Bank borrowings (total_debt) | F12: 24.323 | G12: 26.665 | H12: 23.21 | I12: 21.418
A13: Cash | B13: 6.389 | C13: 11.882 | D13: 13.214 | E13: 14.94 | F13: 8.744 | G13: 9.704 | H13: 6.482 | I13: 8.14
A14: Lease liabilities (memo, excl. from net debt) | G14: 184.625 | H14: 163.079 | I14: 146.976
A16: Source: MOV.NZ_Metrics.csv (core_metrics, NZD millions) for Revenue/EBITDA/NetIncome/Equity/ReportedFCF/Shares/TotalDebt/Cash.
A17: Note: Lease principal repaid: FY2020-25 Annual Report cash flow statements (financing activities, 'Repayment of lease liability (NZ IFRS 16)'); H1-2026 interim report.
A18: Note: Owner FCF = Reported FCF - Lease principal repaid (section 7(b) treatment B: leases as operating cost).
A19: Note: H1-2026 = six months to 31-Dec-2025, most recent filing at valuation date. Balance-sheet figures (borrowings/cash/lease liabilities) are AS AT the period-end column, not flow figures.
A20: Note: Bank borrowings pre-FY2023: not separately disclosed at the granularity captured in core_metrics; TotalDebt column starts FY2023.
A22: SBC / buyback status
A23: SBC FY2025: $47k (0.016% of revenue). FY2024: $0. SBC-zero market -- section 7(e). No buyback programme; buyback_cash = 0.

Sheet Assumptions
A1: Global Assumptions
A3: WACC (all scenarios) | B3: 0.165 | C3: Single rate, all 3 scenarios -- section 7(f) 'charge risk once'. NZ risk-free ~4.5% + ERP ~6.5% + micro-cap/going-concern premium ~5.5pp.
A4: Hurdle rate (entry price) | B4: 0.15 | C4: House standard 15% IRR hurdle.
A5: D&A -- see per-scenario path | C5: D&A is mostly ROU-asset depreciation (non-cash); modelled as % of revenue, declining path per scenario tab.
A6: Capex % of revenue (PPE only) | B6: 0.0015 | C6: FY2025 actual PPE purchases were only $0.186m (0.065% of revenue) -- fleet is mostly leased, not owned. Held near-flat at 0.15%.
A7: WC capture % (of revenue change) | B7: 0.1 | C7: Modest working-capital drag/tailwind scaling with revenue growth -- trade receivables/payables move loosely with volume in a freight business.
A8: Net debt (bank-only) | B8: 13.278 | C8: Equals Borrowings $21.418m minus Cash $8.140m, both at 31-Dec-2025 (H1-2026). Lease liabilities ($146.976m) EXCLUDED -- see Model_Info lease treatment.
A9: Diluted shares (m) | B9: 127.614 | C9: Weighted-average, FY2025 Annual Report / H1-2026 interim. Flat, no dilution (LTI awards anti-dilutive).
A10: Price (NZD) | B10: 0.205 | C10: Yahoo Finance, 2026-08-20T03:42:36Z, regular NZX session.
A11: Terminal cap multiple -- base | B11: 8 | C11: Below house 12-15x cyclical default: chronically low-multiple micro-cap, real going-concern history.
A12: Terminal cap multiple -- bull | B12: 9
A13: Terminal cap multiple -- bear | B13: 6
A15: Scenario terminal growth & probability weights
A16: Scenario | B16: Terminal growth | C16: Weight
A17: Bear | B17: 0.015 | C17: 0.3
A18: Base | B18: 0.02 | C18: 0.45
A19: Bull | B19: 0.025 | C19: 0.25
A20: SUM (must = 100%) | C20: =SUM(C17:C19)
A22: Scenario narratives
A23: Base | B23: The Accelerate programme's ~$27m annualised cost-out holds; three of four divisions stay profitable, Warehousing stabilises without a full turnaround; NZ demand recovers slowly. EBITDA margin matures at 16.0%, below the FY2021 COVID-freight-boom peak of 17.4%.
A24: Bull | B24: New Horizons roadmap delivers in full: Warehousing reset succeeds, Oceans shipping scales, Specialist pipeline ramps from FY27, Cook Strait ferry tailwind materialises. EBITDA margin matures at 19%, above the FY2021 peak.
A25: Bear | B25: Going-concern-relapse scenario: recession persists, Warehousing decline continues, competitor pricing spreads into Freight & Fuel, key customer relationship pressured. Revenue shrinks through Y1-4, margin falls toward the FY2024 9.4% trough before a partial recovery to only 13%.

Sheet DCF_Bear
A1: MOV.NZ -- Bear Case DCF (NZD millions except per-share)
A3: Year | B3: 2025A | C3: Y1E | D3: Y2E | E3: Y3E | F3: Y4E | G3: Y5E | H3: Y6E | I3: Y7E | J3: Y8E | K3: Y9E | L3: Y10E
A4: Year index | B4: 0 | C4: 1 | D4: 2 | E4: 3 | F4: 4 | G4: 5 | H4: 6 | I4: 7 | J4: 8 | K4: 9 | L4: 10
A5: Revenue growth YoY | C5: -0.04 | D5: -0.03 | E5: -0.02 | F5: -0.01 | G5: 0 | H5: 0.005 | I5: 0.01 | J5: 0.01 | K5: 0.01 | L5: 0.01
A6: Revenue | B6: 286.256 | C6: =B6*(1+C5) | D6: =C6*(1+D5) | E6: =D6*(1+E5) | F6: =E6*(1+F5) | G6: =F6*(1+G5) | H6: =G6*(1+H5) | I6: =H6*(1+I5) | J6: =I6*(1+J5) | ... L6: =K6*(1+L5)
A7: Adj EBITDA margin | C7: 0.13 | D7: 0.12 | E7: 0.115 | F7: 0.115 | G7: 0.12 | H7: 0.123 | I7: 0.125 | J7: 0.127 | K7: 0.13 | L7: 0.13
A8: Adjusted EBITDA | C8: =C6*C7 | D8: =D6*D7 | E8: =E6*E7 | F8: =F6*F7 | G8: =G6*G7 | H8: =H6*H7 | I8: =I6*I7 | J8: =J6*J7 | ... L8: =L6*L7
A9: SBC % of revenue | C9: 0 | D9: 0 | E9: 0 | F9: 0 | G9: 0 | H9: 0 | I9: 0 | J9: 0 | K9: 0 | L9: 0
A10: SBC $ (negative) | C10: =-C6*C9 | D10: =-D6*D9 | E10: =-E6*E9 | F10: =-F6*F9 | G10: =-G6*G9 | H10: =-H6*H9 | I10: =-I6*I9 | J10: =-J6*J9 | ... L10: =-L6*L9
A11: Owner EBITDA | C11: =C8+C10 | D11: =D8+D10 | E11: =E8+E10 | F11: =F8+F10 | G11: =G8+G10 | H11: =H8+H10 | I11: =I8+I10 | J11: =J8+J10 | ... L11: =L8+L10
A12: D&A % of revenue | C12: 0.145 | D12: 0.145 | E12: 0.143 | F12: 0.14 | G12: 0.138 | H12: 0.136 | I12: 0.134 | J12: 0.132 | K12: 0.13 | L12: 0.13
A13: D&A $ (negative) | C13: =-C6*C12 | D13: =-D6*D12 | E13: =-E6*E12 | F13: =-F6*F12 | G13: =-G6*G12 | H13: =-H6*H12 | I13: =-I6*I12 | J13: =-J6*J12 | ... L13: =-L6*L12
A14: EBIT (SBC expensed) | C14: =C11+C13 | D14: =D11+D13 | E14: =E11+E13 | F14: =F11+F13 | G14: =G11+G13 | H14: =H11+H13 | I14: =I11+I13 | J14: =J11+J13 | ... L14: =L11+L13
A15: Interest on bank debt % of rev | C15: 0.013 | D15: 0.015 | E15: 0.016 | F15: 0.015 | G15: 0.014 | H15: 0.013 | I15: 0.012 | J15: 0.011 | K15: 0.01 | L15: 0.01
A16: Interest $ (negative) | C16: =-C6*C15 | D16: =-D6*D15 | E16: =-E6*E15 | F16: =-F6*F15 | G16: =-G6*G15 | H16: =-H6*H15 | I16: =-I6*I15 | J16: =-J6*J15 | ... L16: =-L6*L15
A17: Pretax income | C17: =C14+C16 | D17: =D14+D16 | E17: =E14+E16 | F17: =F14+F16 | G17: =G14+G16 | H17: =H14+H16 | I17: =I14+I16 | J17: =J14+J16 | ... L17: =L14+L16
A18: Cash tax rate | C18: 0 | D18: 0 | E18: 0 | F18: 0 | G18: 0.05 | H18: 0.1 | I18: 0.15 | J18: 0.2 | K18: 0.25 | L18: 0.28
A19: NOPAT | C19: =C17*(1-C18) | D19: =D17*(1-D18) | E19: =E17*(1-E18) | F19: =F17*(1-F18) | G19: =G17*(1-G18) | H19: =H17*(1-H18) | I19: =I17*(1-I18) | J19: =J17*(1-J18) | ... L19: =L17*(1-L18)
A20: add back D&A | C20: =-C13 | D20: =-D13 | E20: =-E13 | F20: =-F13 | G20: =-G13 | H20: =-H13 | I20: =-I13 | J20: =-J13 | ... L20: =-L13
A21: Lease principal % of revenue | C21: 0.11 | D21: 0.112 | E21: 0.11 | F21: 0.108 | G21: 0.106 | H21: 0.104 | I21: 0.102 | J21: 0.1 | K21: 0.098 | L21: 0.097
A22: less lease principal | C22: =-C6*C21 | D22: =-D6*D21 | E22: =-E6*E21 | F22: =-F6*F21 | G22: =-G6*G21 | H22: =-H6*H21 | I22: =-I6*I21 | J22: =-J6*J21 | ... L22: =-L6*L21
A23: less PPE capex | C23: =-C6*Assumptions!$B$6 | D23: =-D6*Assumptions!$B$6 | E23: =-E6*Assumptions!$B$6 | F23: =-F6*Assumptions!$B$6 | G23: =-G6*Assumptions!$B$6 | H23: =-H6*Assumptions!$B$6 | I23: =-I6*Assumptions!$B$6 | J23: =-J6*Assumptions!$B$6 | ... L23: =-L6*Assumptions!$B$6
A24: add WC (capture x rev change) | C24: =Assumptions!$B$7*(C6-B6) | D24: =Assumptions!$B$7*(D6-C6) | E24: =Assumptions!$B$7*(E6-D6) | F24: =Assumptions!$B$7*(F6-E6) | G24: =Assumptions!$B$7*(G6-F6) | H24: =Assumptions!$B$7*(H6-G6) | I24: =Assumptions!$B$7*(I6-H6) | J24: =Assumptions!$B$7*(J6-I6) | ... L24: =Assumptions!$B$7*(L6-K6)
A25: less residual restructuring cash cost | C25: -3 | D25: -2 | E25: -1 | F25: -0.5 | G25: 0 | H25: 0 | I25: 0 | J25: 0 | K25: 0 | L25: 0
A26: Unlevered owner FCF | C26: =C19+C20+C22+C23+C24+C25 | D26: =D19+D20+D22+D23+D24+D25 | E26: =E19+E20+E22+E23+E24+E25 | F26: =F19+F20+F22+F23+F24+F25 | G26: =G19+G20+G22+G23+G24+G25 | H26: =H19+H20+H22+H23+H24+H25 | I26: =I19+I20+I22+I23+I24+I25 | J26: =J19+J20+J22+J23+J24+J25 | ... L26: =L19+L20+L22+L23+L24+L25
A27: Discount factor | C27: =1/(1+Assumptions!$B$3)^C4 | D27: =1/(1+Assumptions!$B$3)^D4 | E27: =1/(1+Assumptions!$B$3)^E4 | F27: =1/(1+Assumptions!$B$3)^F4 | G27: =1/(1+Assumptions!$B$3)^G4 | H27: =1/(1+Assumptions!$B$3)^H4 | I27: =1/(1+Assumptions!$B$3)^I4 | J27: =1/(1+Assumptions!$B$3)^J4 | ... L27: =1/(1+Assumptions!$B$3)^L4
A28: PV of FCF | C28: =C26*C27 | D28: =D26*D27 | E28: =E26*E27 | F28: =F26*F27 | G28: =G26*G27 | H28: =H26*H27 | I28: =I26*I27 | J28: =J26*J27 | ... L28: =L26*L27
A30: Memo: implied owner-FCF margin | C30: =C26/C6 | D30: =D26/D6 | E30: =E26/E6 | F30: =F26/F6 | G30: =G26/G6 | H30: =H26/H6 | I30: =I26/I6 | J30: =J26/J6 | ... L30: =L26/L6
A32: Sum PV of FCF (Y1-Y10) | B32: =SUM(C28:L28)
A33: Terminal growth | B33: =Assumptions!$B$17
A34: Terminal FCF (Y11) | B34: =L26*(1+B33)
A35: Gordon TV | B35: =IF(Assumptions!$B$3>B33, B34/(Assumptions!$B$3-B33), "n/a")
A36: Cap TV | B36: =Assumptions!$B$13*L26
A37: TV used = MAX(0,MIN(Gordon,Cap)) | B37: =IF(L26>0, MAX(0,MIN(IF(ISNUMBER(B35),B35,B36),B36)), 0)
A38: Implied exit multiple (TV/Y10 FCF) | B38: =IF(L26>0,B37/L26,"n/a")
A39: PV of TV | B39: =B37*L27
A40: Enterprise value | B40: =B32+B39
A41: less net debt (bank-only) | B41: =-Assumptions!$B$8
A42: Equity value | B42: =B40+B41
A43: Diluted shares (m) | B43: =Assumptions!$B$9
...

Sheet DCF_Base
A1: MOV.NZ -- Base Case DCF (NZD millions except per-share)
A3: Year | B3: 2025A | C3: Y1E | D3: Y2E | E3: Y3E | F3: Y4E | G3: Y5E | H3: Y6E | I3: Y7E | J3: Y8E | K3: Y9E | L3: Y10E
A4: Year index | B4: 0 | C4: 1 | D4: 2 | E4: 3 | F4: 4 | G4: 5 | H4: 6 | I4: 7 | J4: 8 | K4: 9 | L4: 10
A5: Revenue growth YoY | C5: -0.0101 | D5: 0.015 | E5: 0.025 | F5: 0.03 | G5: 0.03 | H5: 0.0275 | I5: 0.025 | J5: 0.025 | K5: 0.025 | L5: 0.025
A6: Revenue | B6: 286.256 | C6: =B6*(1+C5) | D6: =C6*(1+D5) | E6: =D6*(1+E5) | F6: =E6*(1+F5) | G6: =F6*(1+G5) | H6: =G6*(1+H5) | I6: =H6*(1+I5) | J6: =I6*(1+J5) | ... L6: =K6*(1+L5)
A7: Adj EBITDA margin | C7: 0.15 | D7: 0.152 | E7: 0.155 | F7: 0.158 | G7: 0.16 | H7: 0.16 | I7: 0.16 | J7: 0.16 | K7: 0.16 | L7: 0.16
A8: Adjusted EBITDA | C8: =C6*C7 | D8: =D6*D7 | E8: =E6*E7 | F8: =F6*F7 | G8: =G6*G7 | H8: =H6*H7 | I8: =I6*I7 | J8: =J6*J7 | ... L8: =L6*L7
A9: SBC % of revenue | C9: 0 | D9: 0 | E9: 0 | F9: 0 | G9: 0 | H9: 0 | I9: 0 | J9: 0 | K9: 0 | L9: 0
A10: SBC $ (negative) | C10: =-C6*C9 | D10: =-D6*D9 | E10: =-E6*E9 | F10: =-F6*F9 | G10: =-G6*G9 | H10: =-H6*H9 | I10: =-I6*I9 | J10: =-J6*J9 | ... L10: =-L6*L9
A11: Owner EBITDA | C11: =C8+C10 | D11: =D8+D10 | E11: =E8+E10 | F11: =F8+F10 | G11: =G8+G10 | H11: =H8+H10 | I11: =I8+I10 | J11: =J8+J10 | ... L11: =L8+L10
A12: D&A % of revenue | C12: 0.142 | D12: 0.139 | E12: 0.136 | F12: 0.133 | G12: 0.13 | H12: 0.128 | I12: 0.126 | J12: 0.124 | K12: 0.122 | L12: 0.12
A13: D&A $ (negative) | C13: =-C6*C12 | D13: =-D6*D12 | E13: =-E6*E12 | F13: =-F6*F12 | G13: =-G6*G12 | H13: =-H6*H12 | I13: =-I6*I12 | J13: =-J6*J12 | ... L13: =-L6*L12
A14: EBIT (SBC expensed) | C14: =C11+C13 | D14: =D11+D13 | E14: =E11+E13 | F14: =F11+F13 | G14: =G11+G13 | H14: =H11+H13 | I14: =I11+I13 | J14: =J11+J13 | ... L14: =L11+L13
A15: Interest on bank debt % of rev | C15: 0.0095 | D15: 0.0085 | E15: 0.0075 | F15: 0.0065 | G15: 0.006 | H15: 0.0055 | I15: 0.005 | J15: 0.005 | K15: 0.005 | L15: 0.005
A16: Interest $ (negative) | C16: =-C6*C15 | D16: =-D6*D15 | E16: =-E6*E15 | F16: =-F6*F15 | G16: =-G6*G15 | H16: =-H6*H15 | I16: =-I6*I15 | J16: =-J6*J15 | ... L16: =-L6*L15
A17: Pretax income | C17: =C14+C16 | D17: =D14+D16 | E17: =E14+E16 | F17: =F14+F16 | G17: =G14+G16 | H17: =H14+H16 | I17: =I14+I16 | J17: =J14+J16 | ... L17: =L14+L16
A18: Cash tax rate | C18: 0 | D18: 0 | E18: 0.05 | F18: 0.1 | G18: 0.15 | H18: 0.2 | I18: 0.25 | J18: 0.28 | K18: 0.28 | L18: 0.28
A19: NOPAT | C19: =C17*(1-C18) | D19: =D17*(1-D18) | E19: =E17*(1-E18) | F19: =F17*(1-F18) | G19: =G17*(1-G18) | H19: =H17*(1-H18) | I19: =I17*(1-I18) | J19: =J17*(1-J18) | ... L19: =L17*(1-L18)
A20: add back D&A | C20: =-C13 | D20: =-D13 | E20: =-E13 | F20: =-F13 | G20: =-G13 | H20: =-H13 | I20: =-I13 | J20: =-J13 | ... L20: =-L13
A21: Lease principal % of revenue | C21: 0.1075 | D21: 0.1065 | E21: 0.1055 | F21: 0.104 | G21: 0.1025 | H21: 0.101 | I21: 0.0995 | J21: 0.098 | K21: 0.0965 | L21: 0.095
A22: less lease principal | C22: =-C6*C21 | D22: =-D6*D21 | E22: =-E6*E21 | F22: =-F6*F21 | G22: =-G6*G21 | H22: =-H6*H21 | I22: =-I6*I21 | J22: =-J6*J21 | ... L22: =-L6*L21
A23: less PPE capex | C23: =-C6*Assumptions!$B$6 | D23: =-D6*Assumptions!$B$6 | E23: =-E6*Assumptions!$B$6 | F23: =-F6*Assumptions!$B$6 | G23: =-G6*Assumptions!$B$6 | H23: =-H6*Assumptions!$B$6 | I23: =-I6*Assumptions!$B$6 | J23: =-J6*Assumptions!$B$6 | ... L23: =-L6*Assumptions!$B$6
A24: add WC (capture x rev change) | C24: =Assumptions!$B$7*(C6-B6) | D24: =Assumptions!$B$7*(D6-C6) | E24: =Assumptions!$B$7*(E6-D6) | F24: =Assumptions!$B$7*(F6-E6) | G24: =Assumptions!$B$7*(G6-F6) | H24: =Assumptions!$B$7*(H6-G6) | I24: =Assumptions!$B$7*(I6-H6) | J24: =Assumptions!$B$7*(J6-I6) | ... L24: =Assumptions!$B$7*(L6-K6)
A25: less residual restructuring cash cost | C25: -2 | D25: -0.8 | E25: 0 | F25: 0 | G25: 0 | H25: 0 | I25: 0 | J25: 0 | K25: 0 | L25: 0
A26: Unlevered owner FCF | C26: =C19+C20+C22+C23+C24+C25 | D26: =D19+D20+D22+D23+D24+D25 | E26: =E19+E20+E22+E23+E24+E25 | F26: =F19+F20+F22+F23+F24+F25 | G26: =G19+G20+G22+G23+G24+G25 | H26: =H19+H20+H22+H23+H24+H25 | I26: =I19+I20+I22+I23+I24+I25 | J26: =J19+J20+J22+J23+J24+J25 | ... L26: =L19+L20+L22+L23+L24+L25
A27: Discount factor | C27: =1/(1+Assumptions!$B$3)^C4 | D27: =1/(1+Assumptions!$B$3)^D4 | E27: =1/(1+Assumptions!$B$3)^E4 | F27: =1/(1+Assumptions!$B$3)^F4 | G27: =1/(1+Assumptions!$B$3)^G4 | H27: =1/(1+Assumptions!$B$3)^H4 | I27: =1/(1+Assumptions!$B$3)^I4 | J27: =1/(1+Assumptions!$B$3)^J4 | ... L27: =1/(1+Assumptions!$B$3)^L4
A28: PV of FCF | C28: =C26*C27 | D28: =D26*D27 | E28: =E26*E27 | F28: =F26*F27 | G28: =G26*G27 | H28: =H26*H27 | I28: =I26*I27 | J28: =J26*J27 | ... L28: =L26*L27
A30: Memo: implied owner-FCF margin | C30: =C26/C6 | D30: =D26/D6 | E30: =E26/E6 | F30: =F26/F6 | G30: =G26/G6 | H30: =H26/H6 | I30: =I26/I6 | J30: =J26/J6 | ... L30: =L26/L6
A32: Sum PV of FCF (Y1-Y10) | B32: =SUM(C28:L28)
A33: Terminal growth | B33: =Assumptions!$B$18
A34: Terminal FCF (Y11) | B34: =L26*(1+B33)
A35: Gordon TV | B35: =IF(Assumptions!$B$3>B33, B34/(Assumptions!$B$3-B33), "n/a")
A36: Cap TV | B36: =Assumptions!$B$11*L26
A37: TV used = MAX(0,MIN(Gordon,Cap)) | B37: =IF(L26>0, MAX(0,MIN(IF(ISNUMBER(B35),B35,B36),B36)), 0)
A38: Implied exit multiple (TV/Y10 FCF) | B38: =IF(L26>0,B37/L26,"n/a")
A39: PV of TV | B39: =B37*L27
A40: Enterprise value | B40: =B32+B39
A41: less net debt (bank-only) | B41: =-Assumptions!$B$8
A42: Equity value | B42: =B40+B41
A43: Diluted shares (m) | B43: =Assumptions!$B$9
...

Sheet DCF_Bull
A1: MOV.NZ -- Bull Case DCF (NZD millions except per-share)
A3: Year | B3: 2025A | C3: Y1E | D3: Y2E | E3: Y3E | F3: Y4E | G3: Y5E | H3: Y6E | I3: Y7E | J3: Y8E | K3: Y9E | L3: Y10E
A4: Year index | B4: 0 | C4: 1 | D4: 2 | E4: 3 | F4: 4 | G4: 5 | H4: 6 | I4: 7 | J4: 8 | K4: 9 | L4: 10
A5: Revenue growth YoY | C5: 0.01 | D5: 0.04 | E5: 0.055 | F5: 0.06 | G5: 0.06 | H5: 0.05 | I5: 0.04 | J5: 0.035 | K5: 0.03 | L5: 0.03
A6: Revenue | B6: 286.256 | C6: =B6*(1+C5) | D6: =C6*(1+D5) | E6: =D6*(1+E5) | F6: =E6*(1+F5) | G6: =F6*(1+G5) | H6: =G6*(1+H5) | I6: =H6*(1+I5) | J6: =I6*(1+J5) | ... L6: =K6*(1+L5)
A7: Adj EBITDA margin | C7: 0.155 | D7: 0.163 | E7: 0.17 | F7: 0.175 | G7: 0.18 | H7: 0.183 | I7: 0.185 | J7: 0.187 | K7: 0.19 | L7: 0.19
A8: Adjusted EBITDA | C8: =C6*C7 | D8: =D6*D7 | E8: =E6*E7 | F8: =F6*F7 | G8: =G6*G7 | H8: =H6*H7 | I8: =I6*I7 | J8: =J6*J7 | ... L8: =L6*L7
A9: SBC % of revenue | C9: 0 | D9: 0 | E9: 0 | F9: 0 | G9: 0 | H9: 0 | I9: 0 | J9: 0 | K9: 0 | L9: 0
A10: SBC $ (negative) | C10: =-C6*C9 | D10: =-D6*D9 | E10: =-E6*E9 | F10: =-F6*F9 | G10: =-G6*G9 | H10: =-H6*H9 | I10: =-I6*I9 | J10: =-J6*J9 | ... L10: =-L6*L9
A11: Owner EBITDA | C11: =C8+C10 | D11: =D8+D10 | E11: =E8+E10 | F11: =F8+F10 | G11: =G8+G10 | H11: =H8+H10 | I11: =I8+I10 | J11: =J8+J10 | ... L11: =L8+L10
A12: D&A % of revenue | C12: 0.14 | D12: 0.135 | E12: 0.13 | F12: 0.126 | G12: 0.122 | H12: 0.12 | I12: 0.118 | J12: 0.116 | K12: 0.114 | L12: 0.112
A13: D&A $ (negative) | C13: =-C6*C12 | D13: =-D6*D12 | E13: =-E6*E12 | F13: =-F6*F12 | G13: =-G6*G12 | H13: =-H6*H12 | I13: =-I6*I12 | J13: =-J6*J12 | ... L13: =-L6*L12
A14: EBIT (SBC expensed) | C14: =C11+C13 | D14: =D11+D13 | E14: =E11+E13 | F14: =F11+F13 | G14: =G11+G13 | H14: =H11+H13 | I14: =I11+I13 | J14: =J11+J13 | ... L14: =L11+L13
A15: Interest on bank debt % of rev | C15: 0.009 | D15: 0.007 | E15: 0.0055 | F15: 0.0045 | G15: 0.004 | H15: 0.0035 | I15: 0.003 | J15: 0.003 | K15: 0.003 | L15: 0.003
A16: Interest $ (negative) | C16: =-C6*C15 | D16: =-D6*D15 | E16: =-E6*E15 | F16: =-F6*F15 | G16: =-G6*G15 | H16: =-H6*H15 | I16: =-I6*I15 | J16: =-J6*J15 | ... L16: =-L6*L15
A17: Pretax income | C17: =C14+C16 | D17: =D14+D16 | E17: =E14+E16 | F17: =F14+F16 | G17: =G14+G16 | H17: =H14+H16 | I17: =I14+I16 | J17: =J14+J16 | ... L17: =L14+L16
A18: Cash tax rate | C18: 0 | D18: 0 | E18: 0.08 | F18: 0.15 | G18: 0.2 | H18: 0.25 | I18: 0.28 | J18: 0.28 | K18: 0.28 | L18: 0.28
A19: NOPAT | C19: =C17*(1-C18) | D19: =D17*(1-D18) | E19: =E17*(1-E18) | F19: =F17*(1-F18) | G19: =G17*(1-G18) | H19: =H17*(1-H18) | I19: =I17*(1-I18) | J19: =J17*(1-J18) | ... L19: =L17*(1-L18)
A20: add back D&A | C20: =-C13 | D20: =-D13 | E20: =-E13 | F20: =-F13 | G20: =-G13 | H20: =-H13 | I20: =-I13 | J20: =-J13 | ... L20: =-L13
A21: Lease principal % of revenue | C21: 0.106 | D21: 0.103 | E21: 0.1 | F21: 0.097 | G21: 0.094 | H21: 0.092 | I21: 0.09 | J21: 0.088 | K21: 0.086 | L21: 0.085
A22: less lease principal | C22: =-C6*C21 | D22: =-D6*D21 | E22: =-E6*E21 | F22: =-F6*F21 | G22: =-G6*G21 | H22: =-H6*H21 | I22: =-I6*I21 | J22: =-J6*J21 | ... L22: =-L6*L21
A23: less PPE capex | C23: =-C6*Assumptions!$B$6 | D23: =-D6*Assumptions!$B$6 | E23: =-E6*Assumptions!$B$6 | F23: =-F6*Assumptions!$B$6 | G23: =-G6*Assumptions!$B$6 | H23: =-H6*Assumptions!$B$6 | I23: =-I6*Assumptions!$B$6 | J23: =-J6*Assumptions!$B$6 | ... L23: =-L6*Assumptions!$B$6
A24: add WC (capture x rev change) | C24: =Assumptions!$B$7*(C6-B6) | D24: =Assumptions!$B$7*(D6-C6) | E24: =Assumptions!$B$7*(E6-D6) | F24: =Assumptions!$B$7*(F6-E6) | G24: =Assumptions!$B$7*(G6-F6) | H24: =Assumptions!$B$7*(H6-G6) | I24: =Assumptions!$B$7*(I6-H6) | J24: =Assumptions!$B$7*(J6-I6) | ... L24: =Assumptions!$B$7*(L6-K6)
A25: less residual restructuring cash cost | C25: -1.5 | D25: -0.5 | E25: 0 | F25: 0 | G25: 0 | H25: 0 | I25: 0 | J25: 0 | K25: 0 | L25: 0
A26: Unlevered owner FCF | C26: =C19+C20+C22+C23+C24+C25 | D26: =D19+D20+D22+D23+D24+D25 | E26: =E19+E20+E22+E23+E24+E25 | F26: =F19+F20+F22+F23+F24+F25 | G26: =G19+G20+G22+G23+G24+G25 | H26: =H19+H20+H22+H23+H24+H25 | I26: =I19+I20+I22+I23+I24+I25 | J26: =J19+J20+J22+J23+J24+J25 | ... L26: =L19+L20+L22+L23+L24+L25
A27: Discount factor | C27: =1/(1+Assumptions!$B$3)^C4 | D27: =1/(1+Assumptions!$B$3)^D4 | E27: =1/(1+Assumptions!$B$3)^E4 | F27: =1/(1+Assumptions!$B$3)^F4 | G27: =1/(1+Assumptions!$B$3)^G4 | H27: =1/(1+Assumptions!$B$3)^H4 | I27: =1/(1+Assumptions!$B$3)^I4 | J27: =1/(1+Assumptions!$B$3)^J4 | ... L27: =1/(1+Assumptions!$B$3)^L4
A28: PV of FCF | C28: =C26*C27 | D28: =D26*D27 | E28: =E26*E27 | F28: =F26*F27 | G28: =G26*G27 | H28: =H26*H27 | I28: =I26*I27 | J28: =J26*J27 | ... L28: =L26*L27
A30: Memo: implied owner-FCF margin | C30: =C26/C6 | D30: =D26/D6 | E30: =E26/E6 | F30: =F26/F6 | G30: =G26/G6 | H30: =H26/H6 | I30: =I26/I6 | J30: =J26/J6 | ... L30: =L26/L6
A32: Sum PV of FCF (Y1-Y10) | B32: =SUM(C28:L28)
A33: Terminal growth | B33: =Assumptions!$B$19
A34: Terminal FCF (Y11) | B34: =L26*(1+B33)
A35: Gordon TV | B35: =IF(Assumptions!$B$3>B33, B34/(Assumptions!$B$3-B33), "n/a")
A36: Cap TV | B36: =Assumptions!$B$12*L26
A37: TV used = MAX(0,MIN(Gordon,Cap)) | B37: =IF(L26>0, MAX(0,MIN(IF(ISNUMBER(B35),B35,B36),B36)), 0)
A38: Implied exit multiple (TV/Y10 FCF) | B38: =IF(L26>0,B37/L26,"n/a")
A39: PV of TV | B39: =B37*L27
A40: Enterprise value | B40: =B32+B39
A41: less net debt (bank-only) | B41: =-Assumptions!$B$8
A42: Equity value | B42: =B40+B41
A43: Diluted shares (m) | B43: =Assumptions!$B$9
...

Sheet FCF_Quality
A1: FCF Quality: Reported -> Owner FCF Reconciliation
B3: FY2020 | C3: FY2021 | D3: FY2022 | E3: FY2023 | F3: FY2024 | G3: FY2025 | H3: H1-2026
A4: Reported FCF (company/CSV definition) | B4: 25.238 | C4: 36.607 | D4: 29.233 | E4: 19.272 | F4: 16.818 | G4: 25.14 | H4: 16.34
A5: less: SBC incl. equity-award taxes | B5: 0 | C5: 0 | D5: 0 | E5: 0 | F5: 0 | G5: -0.047 | H5: 0
A6: less: lease principal repaid (IFRS16) | B6: -22.956 | C6: -28.099 | D6: -28.266 | E6: -27.318 | F6: -29.521 | G6: -30.964 | H6: -14.918
A7: less: interest income | B7: -0.1 | C7: -0.1 | D7: -0.1 | E7: -0.1 | F7: -0.1 | G7: -0.269 | H7: -0.086
A8: Equals Owner FCF | B8: =SUM(B4:B7) | C8: =SUM(C4:C7) | D8: =SUM(D4:D7) | E8: =SUM(E4:E7) | F8: =SUM(F4:F7) | G8: =SUM(G4:G7) | H8: =SUM(H4:H7)
A10: Reported FCF margin
B11: =B4/333.811 | C11: =C4/353.247 | D11: =D4/360.121 | E11: =E4/343.873 | F11: =F4/293.866 | G11: =G4/286.256 | H11: =H4/141.4
A12: Owner FCF margin | B12: =B8/333.811 | C12: =C8/353.247 | D12: =D8/360.121 | E12: =E8/343.873 | F12: =F8/293.866 | G12: =G8/286.256 | H12: =H8/141.4
A14: Memo: interest income is trivial for MOV.NZ (net debt positive, not net cash) -- included for completeness only, not material.
A15: Memo: cash tax paid was minimal throughout ($0.6-1.9m/yr on losses) -- not flagged as abnormal since it reflects genuine loss-making years, ramped to 28% statutory in projections as profitability returns.

Sheet Valuation
A1: MOV.NZ -- Valuation Summary
A3: Scenario | B3: Value/share | C3: Upside vs price | D3: Probability | E3: Street value/share
A4: Bear | B4: =DCF_Bear!$B$44 | C4: =B4/Assumptions!$B$10-1 | D4: =Assumptions!$C$17 | E4: =DCF_Bear!$B$50
A5: Base | B5: =DCF_Base!$B$44 | C5: =B5/Assumptions!$B$10-1 | D5: =Assumptions!$C$18 | E5: =DCF_Base!$B$50
A6: Bull | B6: =DCF_Bull!$B$44 | C6: =B6/Assumptions!$B$10-1 | D6: =Assumptions!$C$19 | E6: =DCF_Bull!$B$50
A7: Probability-weighted IV | B7: =SUMPRODUCT(B4:B6,D4:D6)
A8: Margin of safety | B8: =1-Assumptions!$B$10/B7
A9: Street weighted value/share | B9: =SUMPRODUCT(E4:E6,D4:D6)
A10: Band position (house/street) | B10: n/a -- SBC-zero market, house = street
A12: Required-return table (Base case)
A13: Required return | B13: Value/share
A14: 0.09 | B14: =(SUMPRODUCT(DCF_Base!$C$26:$L$26,1/(1+A14)^DCF_Base!$C$4:$L$4)+MAX(0,MIN(IF(0.09>DCF_Base!$B$33,DCF_Base!$L$26*(1+DCF_Base!$B$33)/(A14-DCF_Base!$B$33),DCF_Base!$B$36),DCF_Base!$B$36))/(1+A14)^10-Assumptions!$B$8)/Assumptions!$B$9
A15: 0.1 | B15: =(SUMPRODUCT(DCF_Base!$C$26:$L$26,1/(1+A15)^DCF_Base!$C$4:$L$4)+MAX(0,MIN(IF(0.1>DCF_Base!$B$33,DCF_Base!$L$26*(1+DCF_Base!$B$33)/(A15-DCF_Base!$B$33),DCF_Base!$B$36),DCF_Base!$B$36))/(1+A15)^10-Assumptions!$B$8)/Assumptions!$B$9
A16: 0.11 | B16: =(SUMPRODUCT(DCF_Base!$C$26:$L$26,1/(1+A16)^DCF_Base!$C$4:$L$4)+MAX(0,MIN(IF(0.11>DCF_Base!$B$33,DCF_Base!$L$26*(1+DCF_Base!$B$33)/(A16-DCF_Base!$B$33),DCF_Base!$B$36),DCF_Base!$B$36))/(1+A16)^10-Assumptions!$B$8)/Assumptions!$B$9
A17: 0.12 | B17: =(SUMPRODUCT(DCF_Base!$C$26:$L$26,1/(1+A17)^DCF_Base!$C$4:$L$4)+MAX(0,MIN(IF(0.12>DCF_Base!$B$33,DCF_Base!$L$26*(1+DCF_Base!$B$33)/(A17-DCF_Base!$B$33),DCF_Base!$B$36),DCF_Base!$B$36))/(1+A17)^10-Assumptions!$B$8)/Assumptions!$B$9
A18: 0.15 | B18: =(SUMPRODUCT(DCF_Base!$C$26:$L$26,1/(1+A18)^DCF_Base!$C$4:$L$4)+MAX(0,MIN(IF(0.15>DCF_Base!$B$33,DCF_Base!$L$26*(1+DCF_Base!$B$33)/(A18-DCF_Base!$B$33),DCF_Base!$B$36),DCF_Base!$B$36))/(1+A18)^10-Assumptions!$B$8)/Assumptions!$B$9
A19: 0.165 | B19: =(SUMPRODUCT(DCF_Base!$C$26:$L$26,1/(1+A19)^DCF_Base!$C$4:$L$4)+MAX(0,MIN(IF(0.165>DCF_Base!$B$33,DCF_Base!$L$26*(1+DCF_Base!$B$33)/(A19-DCF_Base!$B$33),DCF_Base!$B$36),DCF_Base!$B$36))/(1+A19)^10-Assumptions!$B$8)/Assumptions!$B$9
A21: Entry price (15% hurdle IRR)
A22: Scenario | B22: Entry price | C22: Discount vs price
A23: Bear | B23: =(SUMPRODUCT(DCF_Bear!$C$26:$L$26,1/(1+Assumptions!$B$4)^DCF_Bear!$C$4:$L$4)+DCF_Bear!$B$37/(1+Assumptions!$B$4)^10-Assumptions!$B$8)/Assumptions!$B$9 | C23: =B23/Assumptions!$B$10-1
A24: Base | B24: =(SUMPRODUCT(DCF_Base!$C$26:$L$26,1/(1+Assumptions!$B$4)^DCF_Base!$C$4:$L$4)+DCF_Base!$B$37/(1+Assumptions!$B$4)^10-Assumptions!$B$8)/Assumptions!$B$9 | C24: =B24/Assumptions!$B$10-1
A25: Bull | B25: =(SUMPRODUCT(DCF_Bull!$C$26:$L$26,1/(1+Assumptions!$B$4)^DCF_Bull!$C$4:$L$4)+DCF_Bull!$B$37/(1+Assumptions!$B$4)^10-Assumptions!$B$8)/Assumptions!$B$9 | C25: =B25/Assumptions!$B$10-1
A26: Weighted entry price | B26: =SUMPRODUCT(B23:B25,D4:D6)
A28: Sensitivity: WACC x Terminal Growth (Base case)
A29: WACC \ g | B29: 0.01 | C29: 0.015 | D29: 0.02 | E29: 0.025 | F29: 0.03
A30: 0.145 | B30: =IF(0.145>B29,(SUMPRODUCT(DCF_Base!$C$26:$L$26,1/(1+0.145)^DCF_Base!$C$4:$L$4)+MAX(0,MIN(DCF_Base!$L$26*(1+B29)/(0.145-B29),DCF_Base!$B$36))/(1+0.145)^10-Assumptions!$B$8)/Assumptions!$B$9,"n/a") | C30: =IF(0.145>C29,(SUMPRODUCT(DCF_Base!$C$26:$L$26,1/(1+0.145)^DCF_Base!$C$4:$L$4)+MAX(0,MIN(DCF_Base!$L$26*(1+C29)/(0.145-C29),DCF_Base!$B$36))/(1+0.145)^10-Assumptions!$B$8)/Assumptions!$B$9,"n/a") | D30: =IF(0.145>D29,(SUMPRODUCT(DCF_Base!$C$26:$L$26,1/(1+0.145)^DCF_Base!$C$4:$L$4)+MAX(0,MIN(DCF_Base!$L$26*(1+D29)/(0.145-D29),DCF_Base!$B$36))/(1+0.145)^10-Assumptions!$B$8)/Assumptions!$B$9,"n/a") | E30: =IF(0.145>E29,(SUMPRODUCT(DCF_Base!$C$26:$L$26,1/(1+0.145)^DCF_Base!$C$4:$L$4)+MAX(0,MIN(DCF_Base!$L$26*(1+E29)/(0.145-E29),DCF_Base!$B$36))/(1+0.145)^10-Assumptions!$B$8)/Assumptions!$B$9,"n/a") | F30: =IF(0.145>F29,(SUMPRODUCT(DCF_Base!$C$26:$L$26,1/(1+0.145)^DCF_Base!$C$4:$L$4)+MAX(0,MIN(DCF_Base!$L$26*(1+F29)/(0.145-F29),DCF_Base!$B$36))/(1+0.145)^10-Assumptions!$B$8)/Assumptions!$B$9,"n/a")
A31: 0.155 | B31: =IF(0.155>B29,(SUMPRODUCT(DCF_Base!$C$26:$L$26,1/(1+0.155)^DCF_Base!$C$4:$L$4)+MAX(0,MIN(DCF_Base!$L$26*(1+B29)/(0.155-B29),DCF_Base!$B$36))/(1+0.155)^10-Assumptions!$B$8)/Assumptions!$B$9,"n/a") | C31: =IF(0.155>C29,(SUMPRODUCT(DCF_Base!$C$26:$L$26,1/(1+0.155)^DCF_Base!$C$4:$L$4)+MAX(0,MIN(DCF_Base!$L$26*(1+C29)/(0.155-C29),DCF_Base!$B$36))/(1+0.155)^10-Assumptions!$B$8)/Assumptions!$B$9,"n/a") | D31: =IF(0.155>D29,(SUMPRODUCT(DCF_Base!$C$26:$L$26,1/(1+0.155)^DCF_Base!$C$4:$L$4)+MAX(0,MIN(DCF_Base!$L$26*(1+D29)/(0.155-D29),DCF_Base!$B$36))/(1+0.155)^10-Assumptions!$B$8)/Assumptions!$B$9,"n/a") | E31: =IF(0.155>E29,(SUMPRODUCT(DCF_Base!$C$26:$L$26,1/(1+0.155)^DCF_Base!$C$4:$L$4)+MAX(0,MIN(DCF_Base!$L$26*(1+E29)/(0.155-E29),DCF_Base!$B$36))/(1+0.155)^10-Assumptions!$B$8)/Assumptions!$B$9,"n/a") | F31: =IF(0.155>F29,(SUMPRODUCT(DCF_Base!$C$26:$L$26,1/(1+0.155)^DCF_Base!$C$4:$L$4)+MAX(0,MIN(DCF_Base!$L$26*(1+F29)/(0.155-F29),DCF_Base!$B$36))/(1+0.155)^10-Assumptions!$B$8)/Assumptions!$B$9,"n/a")
A32: 0.165 | B32: =IF(0.165>B29,(SUMPRODUCT(DCF_Base!$C$26:$L$26,1/(1+0.165)^DCF_Base!$C$4:$L$4)+MAX(0,MIN(DCF_Base!$L$26*(1+B29)/(0.165-B29),DCF_Base!$B$36))/(1+0.165)^10-Assumptions!$B$8)/Assumptions!$B$9,"n/a") | C32: =IF(0.165>C29,(SUMPRODUCT(DCF_Base!$C$26:$L$26,1/(1+0.165)^DCF_Base!$C$4:$L$4)+MAX(0,MIN(DCF_Base!$L$26*(1+C29)/(0.165-C29),DCF_Base!$B$36))/(1+0.165)^10-Assumptions!$B$8)/Assumptions!$B$9,"n/a") | D32: =IF(0.165>D29,(SUMPRODUCT(DCF_Base!$C$26:$L$26,1/(1+0.165)^DCF_Base!$C$4:$L$4)+MAX(0,MIN(DCF_Base!$L$26*(1+D29)/(0.165-D29),DCF_Base!$B$36))/(1+0.165)^10-Assumptions!$B$8)/Assumptions!$B$9,"n/a") | E32: =IF(0.165>E29,(SUMPRODUCT(DCF_Base!$C$26:$L$26,1/(1+0.165)^DCF_Base!$C$4:$L$4)+MAX(0,MIN(DCF_Base!$L$26*(1+E29)/(0.165-E29),DCF_Base!$B$36))/(1+0.165)^10-Assumptions!$B$8)/Assumptions!$B$9,"n/a") | F32: =IF(0.165>F29,(SUMPRODUCT(DCF_Base!$C$26:$L$26,1/(1+0.165)^DCF_Base!$C$4:$L$4)+MAX(0,MIN(DCF_Base!$L$26*(1+F29)/(0.165-F29),DCF_Base!$B$36))/(1+0.165)^10-Assumptions!$B$8)/Assumptions!$B$9,"n/a")
A33: 0.175 | B33: =IF(0.175>B29,(SUMPRODUCT(DCF_Base!$C$26:$L$26,1/(1+0.175)^DCF_Base!$C$4:$L$4)+MAX(0,MIN(DCF_Base!$L$26*(1+B29)/(0.175-B29),DCF_Base!$B$36))/(1+0.175)^10-Assumptions!$B$8)/Assumptions!$B$9,"n/a") | C33: =IF(0.175>C29,(SUMPRODUCT(DCF_Base!$C$26:$L$26,1/(1+0.175)^DCF_Base!$C$4:$L$4)+MAX(0,MIN(DCF_Base!$L$26*(1+C29)/(0.175-C29),DCF_Base!$B$36))/(1+0.175)^10-Assumptions!$B$8)/Assumptions!$B$9,"n/a") | D33: =IF(0.175>D29,(SUMPRODUCT(DCF_Base!$C$26:$L$26,1/(1+0.175)^DCF_Base!$C$4:$L$4)+MAX(0,MIN(DCF_Base!$L$26*(1+D29)/(0.175-D29),DCF_Base!$B$36))/(1+0.175)^10-Assumptions!$B$8)/Assumptions!$B$9,"n/a") | E33: =IF(0.175>E29,(SUMPRODUCT(DCF_Base!$C$26:$L$26,1/(1+0.175)^DCF_Base!$C$4:$L$4)+MAX(0,MIN(DCF_Base!$L$26*(1+E29)/(0.175-E29),DCF_Base!$B$36))/(1+0.175)^10-Assumptions!$B$8)/Assumptions!$B$9,"n/a") | F33: =IF(0.175>F29,(SUMPRODUCT(DCF_Base!$C$26:$L$26,1/(1+0.175)^DCF_Base!$C$4:$L$4)+MAX(0,MIN(DCF_Base!$L$26*(1+F29)/(0.175-F29),DCF_Base!$B$36))/(1+0.175)^10-Assumptions!$B$8)/Assumptions!$B$9,"n/a")
A34: 0.185 | B34: =IF(0.185>B29,(SUMPRODUCT(DCF_Base!$C$26:$L$26,1/(1+0.185)^DCF_Base!$C$4:$L$4)+MAX(0,MIN(DCF_Base!$L$26*(1+B29)/(0.185-B29),DCF_Base!$B$36))/(1+0.185)^10-Assumptions!$B$8)/Assumptions!$B$9,"n/a") | C34: =IF(0.185>C29,(SUMPRODUCT(DCF_Base!$C$26:$L$26,1/(1+0.185)^DCF_Base!$C$4:$L$4)+MAX(0,MIN(DCF_Base!$L$26*(1+C29)/(0.185-C29),DCF_Base!$B$36))/(1+0.185)^10-Assumptions!$B$8)/Assumptions!$B$9,"n/a") | D34: =IF(0.185>D29,(SUMPRODUCT(DCF_Base!$C$26:$L$26,1/(1+0.185)^DCF_Base!$C$4:$L$4)+MAX(0,MIN(DCF_Base!$L$26*(1+D29)/(0.185-D29),DCF_Base!$B$36))/(1+0.185)^10-Assumptions!$B$8)/Assumptions!$B$9,"n/a") | E34: =IF(0.185>E29,(SUMPRODUCT(DCF_Base!$C$26:$L$26,1/(1+0.185)^DCF_Base!$C$4:$L$4)+MAX(0,MIN(DCF_Base!$L$26*(1+E29)/(0.185-E29),DCF_Base!$B$36))/(1+0.185)^10-Assumptions!$B$8)/Assumptions!$B$9,"n/a") | F34: =IF(0.185>F29,(SUMPRODUCT(DCF_Base!$C$26:$L$26,1/(1+0.185)^DCF_Base!$C$4:$L$4)+MAX(0,MIN(DCF_Base!$L$26*(1+F29)/(0.185-F29),DCF_Base!$B$36))/(1+0.185)^10-Assumptions!$B$8)/Assumptions!$B$9,"n/a")
