Workbook

Sheet Model_Info
A1: Ticker | B1: FME.DE
A2: Company | B2: Fresenius Medical Care AG
A3: Valuation date | B3: 2026-10-25
A4: Current price | B4: 40.46
A5: Price as of | B5: 2026-10-23T15:35:53Z (Xetra regular close, Friday)
A6: Balance sheet date | B6: 2026-06-30
A7: Model | B7: owner_fcf_dcf_component
A8: Currency (model) | B8: EUR
A9: Currency (quote) | B9: EUR
A10: Units | B10: millions
A11: Engine | B11: dcf_engine v1
A12: Built at | B12: 2026-10-24T22:20:53Z
A13: Drivers file | B13: FME.DE_Drivers.json
A14: Convention | B14: Percents stored as percents; formulas divide by 100. Blue = input, green = link, black = formula.
A15: Methodology | B15: summary: A dialysis duopolist priced like a utility whose regulator is also its largest customer. Value depends almost entirely on the margin path, not on volume: the base case gives credit for half of the Reignite margin aspiration and charges the real costs the company's adjusted figures leave out (IFRS-16 lease cash, recurring special items, minority partners' share of the US clinics). key_risks_to_valuation: US reimbursement policy (CMS ESRD PPS rate, ACA subsidy expiry, OBBBA Medicaid cuts, Marietta) moves the margin path more than any operating lever; NCI valuation: 11x LTM NCI earnings is a judgment; each 1x is ~EUR0.94/share; EUR/USD: ~70% of flows are USD; a 10% stronger euro cuts EUR value roughly pro rata; Leadership transition and 5008X rollout execution in 2026-27; Terminal value is cap-bound at 15x owner FCF in the base case, so most of the value sits beyond 2035
A16: Data sources | B16: price: Yahoo Finance chart API (FME.DE, Xetra) at inputs.price_as_of; 52-week range 34.57-47.54 financials: FME.DE_Metrics.csv (core_metrics, FY2015-H1 2026); FY2025 20-F cash-flow statement, balance sheet, lease note 24 and NCI lines; H1-2026 interim report balance sheet, buyback table and net-leverage reconciliation qualitative: FME.DE_Analysis.json (2026-10-25): FY2026 guidance as reaffirmed at Q2 2026, FME Reignite / FME25+ targets, the October 2026 CEO change and the September 2026 cyberattack
... A19: Scenario narrative: bull | B19: HVHDF becomes the US standard of care on the CONVINCE mortality data, lifting both product pull-through (Care Enablement to a mid-teens margin) and clinic economics. Interwell Health scales profitably and US payor mix holds despite the ACA subsidy expiry. Revenue runs at the middle of the 3-7% aspiration, and the group reaches roughly the mid-teens operating margin (reported EBITDA ~21.5%, about the FY2020-21 IFRS-16 level). External CEO Korangy speeds up portfolio pruning and capital returns.

Sheet Actuals
A1: Period | B1: Revenue | C1: CostOfRevenue | D1: GrossProfit | E1: GrossMargin | F1: OperatingIncome | G1: OperatingMargin | H1: EBITDA | I1: NetIncome | J1: NetMargin | K1: EPS | L1: OperatingCashFlow | M1: CapEx | N1: FreeCashFlow | O1: ShareholdersEquity | P1: TotalAssets | Q1: TotalLiabilities | R1: TotalDebt | S1: CashAndEquivalents | T1: SharesOutstanding | U1: StockBasedComp | V1: DividendPerShare | W1: EBITDABeforeSignificant | X1: RevenueContinuing | Y1: EBITDAContinuingBeforeSignificant | Z1: EBITContinuingBeforeSignificant | AA1: Units | AB1: Currency
A2: FY2015 | B2: 15454.858 | C2: 10277.692 | D2: 5177.166 | E2: 33.5 | F2: 2128.501 | G2: 13.8 | H2: 2776.668 | I2: 954.946 | J2: 6.2 | K2: 3.13 | L2: 1766.604 | M2: 858.894 | N2: 907.71 | T2: 304.44 | U2: 8.37 | AA2: millions | AB2: EUR
A3: FY2016 | B3: 16569.715 | C3: 10953.769 | D3: 5615.946 | E3: 33.9 | F3: 2408.902 | G3: 14.5 | H3: 3110.438 | I3: 1143.98 | J3: 6.9 | K3: 3.73 | L3: 1931.973 | M3: 930.52 | N3: 1001.453 | O3: 9977.657 | P3: 25503.54 | Q3: 14452.408 | R3: 8132.114 | S3: 708.882 | T3: 305.748 | U3: 27.433 | AA3: millions | AB3: EUR
A4: FY2017 | B4: 17783.572 | C4: 11779.852 | D4: 6003.72 | E4: 33.8 | F4: 2362.439 | G4: 13.3 | H4: 3097.918 | I4: 1279.788 | J4: 7.2 | K4: 4.16 | L4: 2191.811 | M4: 944.46 | N4: 1247.351 | O4: 9820.102 | P4: 24025.128 | Q4: 13196.942 | R4: 7447.686 | S4: 978.109 | T4: 306.563 | U4: 46.811 | AA4: millions | AB4: EUR
A5: FY2018 | B5: 16546.873 | C5: 11392.13 | D5: 5154.743 | E5: 31.2 | F5: 3037.798 | G5: 18.4 | H5: 3827.364 | I5: 1981.924 | J5: 12 | K5: 6.45 | L5: 2061.911 | M5: 1057.276 | N5: 1004.635 | O5: 11758.411 | P5: 26242.268 | Q5: 13340.31 | R5: 7546.228 | S5: 2145.632 | T5: 306.542 | U5: 10.745 | AA5: millions | AB5: EUR
A6: FY2019 | B6: 17476.555 | C6: 12080.704 | D6: 5395.851 | E6: 30.9 | F6: 2269.558 | G6: 13 | H6: 3862.718 | I6: 1199.619 | J6: 6.9 | K6: 3.96 | L6: 2566.951 | M6: 1124.791 | N6: 1442.16 | O6: 11957.913 | P6: 32934.735 | Q6: 19707.498 | R6: 9077.41 | S6: 1007.723 | T6: 302.691 | U6: 1.992 | AA6: millions | AB6: EUR
A7: FY2020 | B7: 17859.063 | C7: 12321.618 | D7: 5537.445 | E7: 31 | F7: 2304.409 | G7: 12.9 | H7: 4090.308 | I7: 1164.377 | J7: 6.5 | K7: 3.96 | L7: 4233.156 | M7: 1051.983 | N7: 3181.173 | O7: 11215.08 | P7: 31689.036 | Q7: 19357.726 | R7: 7887.73 | S7: 1081.539 | T7: 294.056 | U7: 0 | AA7: millions | AB7: EUR
A8: FY2021 | B8: 17618.685 | C8: 12541.656 | D8: 5077.029 | E8: 28.8 | F8: 1852.29 | G8: 10.5 | H8: 3475.966 | I8: 969.308 | J8: 5.5 | K8: 3.31 | L8: 2489.498 | M8: 854.36 | N8: 1635.138 | O8: 12698.783 | P8: 34366.558 | Q8: 20387.521 | R8: 8570.768 | S8: 1481.655 | T8: 292.945 | U8: 0 | AA8: millions | AB8: EUR
A9: FY2022 | B9: 19398.017 | C9: 14087.765 | D9: 5310.252 | E9: 27.4 | F9: 1511.755 | G9: 7.8 | H9: 3350.118 | I9: 673.405 | J9: 3.5 | K9: 2.3 | L9: 2167.379 | M9: 723.988 | N9: 1443.391 | O9: 13989.453 | P9: 35754.114 | Q9: 20304.935 | R9: 8533.809 | S9: 1273.787 | T9: 293.246 | U9: 0 | AA9: millions | AB9: EUR
A10: FY2023 | B10: 19453.617 | C10: 14528.612 | D10: 4925.005 | E10: 25.3 | F10: 1369.438 | G10: 7 | H10: 3121.409 | I10: 498.997 | J10: 2.6 | K10: 1.7 | L10: 2628.801 | M10: 684.596 | N10: 1944.205 | O10: 13620.261 | P10: 33929.808 | Q10: 19103.273 | R10: 7904.466 | S10: 1403.492 | T10: 293.413 | U10: 0 | AA10: millions | AB10: EUR
A11: FY2024 | B11: 19335.909 | C11: 14579.257 | D11: 4756.652 | E11: 24.6 | F11: 1392.395 | G11: 7.2 | H11: 3134.652 | I11: 537.913 | J11: 2.8 | K11: 1.83 | L11: 2386.144 | M11: 699.358 | N11: 1686.786 | O11: 14576.563 | P11: 33566.579 | Q11: 17798.066 | R11: 6838.207 | S11: 1180.187 | T11: 293.413 | U11: 0 | AA11: millions | AB11: EUR
A12: FY2025 | B12: 19627.602 | C12: 14598.673 | D12: 5028.929 | E12: 25.6 | F12: 1827.036 | G12: 9.3 | H12: 3327.445 | I12: 978.367 | J12: 5 | K12: 3.36 | L12: 2680.999 | M12: 915.369 | N12: 1765.63 | O12: 13309.832 | P12: 31002.333 | Q12: 16719.524 | R12: 7304.896 | S12: 1599.113 | T12: 291.191 | U12: 8.182 | AA12: millions | AB12: EUR

Sheet Assumptions
A1: Input | B1: Value
A2: Current price (quote currency) | B2: 40.46
A3: Shares, final projected (m) | B3: 266.11
A4: Net debt (m, model currency) | B4: 6504.6
A5: Equity bridge total (m, + adds) | B5: -3323.2
A6: Hurdle rate (%) | B6: 15
A7: Base revenue FY0 (m) | B7: 19627.602
A8: FY0 | B8: FY2025
A9: Currency / units | B9: EUR millions
A10: FX rate (model -> quote) | B10: 1
A12: BEAR | C12: FY2026 | D12: FY2027 | E12: FY2028 | F12: FY2029 | G12: FY2030 | H12: FY2031 | I12: FY2032 | J12: FY2033 | K12: FY2034 | L12: FY2035
A13: Revenue growth (%) | C13: -3.5 | D13: 1.5 | E13: 2 | F13: 2 | G13: 2 | H13: 2 | I13: 2 | J13: 2 | K13: 2 | L13: 2
A14: EBITDA margin (%) | C14: 17 | D14: 16.8 | E14: 16.6 | F14: 16.5 | G14: 16.4 | H14: 16.3 | I14: 16.2 | J14: 16.2 | K14: 16.2 | L14: 16.2
A15: SBC (% of revenue) | C15: 0 | D15: 0 | E15: 0 | F15: 0 | G15: 0 | H15: 0 | I15: 0 | J15: 0 | K15: 0 | L15: 0
A16: Lease cost (% of revenue) | C16: 4 | D16: 4 | E16: 4 | F16: 4 | G16: 4 | H16: 4 | I16: 4 | J16: 4 | K16: 4 | L16: 4
A17: D&A (% of revenue) | C17: 4.3 | D17: 4.3 | E17: 4.3 | F17: 4.3 | G17: 4.3 | H17: 4.3 | I17: 4.3 | J17: 4.3 | K17: 4.3 | L17: 4.3
A18: Capex (% of revenue) | C18: 5 | D18: 4.8 | E18: 4.6 | F18: 4.5 | G18: 4.4 | H18: 4.3 | I18: 4.3 | J18: 4.3 | K18: 4.3 | L18: 4.3
A19: Cash tax rate (%) | C19: 27 | D19: 27 | E19: 27 | F19: 27 | G19: 27 | H19: 27 | I19: 27 | J19: 27 | K19: 27 | L19: 27
A20: WACC (%) | B20: 7
A21: Terminal growth (%) | B21: 1.5
A22: Terminal cap multiple (x FCF) | B22: 12
A23: Working-capital capture (% of revenue change) | B23: -10
A24: Scenario weight | B24: 0.25
A26: BASE | C26: FY2026 | D26: FY2027 | E26: FY2028 | F26: FY2029 | G26: FY2030 | H26: FY2031 | I26: FY2032 | J26: FY2033 | K26: FY2034 | L26: FY2035
A27: Revenue growth (%) | C27: -2.7 | D27: 3.5 | E27: 4 | F27: 4 | G27: 3.5 | H27: 3 | I27: 3 | J27: 2.5 | K27: 2.5 | L27: 2.5
A28: EBITDA margin (%) | C28: 17.4 | D28: 17.9 | E28: 18.4 | F28: 18.8 | G28: 19.1 | H28: 19.3 | I28: 19.4 | J28: 19.5 | K28: 19.5 | L28: 19.5
A29: SBC (% of revenue) | C29: 0 | D29: 0 | E29: 0 | F29: 0 | G29: 0 | H29: 0 | I29: 0 | J29: 0 | K29: 0 | L29: 0
A30: Lease cost (% of revenue) | C30: 4 | D30: 4 | E30: 4 | F30: 4 | G30: 4 | H30: 4 | I30: 4 | J30: 4 | K30: 4 | L30: 4
A31: D&A (% of revenue) | C31: 4.3 | D31: 4.3 | E31: 4.3 | F31: 4.3 | G31: 4.3 | H31: 4.3 | I31: 4.3 | J31: 4.3 | K31: 4.3 | L31: 4.3
A32: Capex (% of revenue) | C32: 5 | D32: 4.8 | E32: 4.6 | F32: 4.5 | G32: 4.4 | H32: 4.3 | I32: 4.3 | J32: 4.3 | K32: 4.3 | L32: 4.3
A33: Cash tax rate (%) | C33: 26 | D33: 26 | E33: 26 | F33: 26 | G33: 26 | H33: 26 | I33: 26 | J33: 26 | K33: 26 | L33: 26
A34: WACC (%) | B34: 7
A35: Terminal growth (%) | B35: 2
A36: Terminal cap multiple (x FCF) | B36: 15
A37: Working-capital capture (% of revenue change) | B37: -10
A38: Scenario weight | B38: 0.5
A40: BULL | C40: FY2026 | D40: FY2027 | E40: FY2028 | F40: FY2029 | G40: FY2030 | H40: FY2031 | I40: FY2032 | J40: FY2033 | K40: FY2034 | L40: FY2035
A41: Revenue growth (%) | C41: -2 | D41: 5.5 | E41: 6 | F41: 6 | G41: 5.5 | H41: 4.5 | I41: 4 | J41: 3.5 | K41: 3 | L41: 3
A42: EBITDA margin (%) | C42: 17.6 | D42: 18.5 | E42: 19.4 | F42: 20.2 | G42: 20.8 | H42: 21.2 | I42: 21.4 | J42: 21.5 | K42: 21.5 | L42: 21.5
A43: SBC (% of revenue) | C43: 0 | D43: 0 | E43: 0 | F43: 0 | G43: 0 | H43: 0 | I43: 0 | J43: 0 | K43: 0 | L43: 0
...

Sheet DCF_Bear
A1: FME.DE owner-FCF component DCF: bear case (millions, EUR)
A3: Line | B3: FY2025 | C3: FY2026 | D3: FY2027 | E3: FY2028 | F3: FY2029 | G3: FY2030 | H3: FY2031 | I3: FY2032 | J3: FY2033 | K3: FY2034 | L3: FY2035
A4: Year index (discount exponent) | B4: 0 | C4: =B4+1 -> 1 | D4: =C4+1 -> 2 | E4: =D4+1 -> 3 | F4: =E4+1 -> 4 | G4: =F4+1 -> 5 | H4: =G4+1 -> 6 | I4: =H4+1 -> 7 | J4: =I4+1 -> 8 | ... L4: =K4+1 -> 10
A5: Revenue growth (%) | C5: =Assumptions!C13 -> -3.5 | D5: =Assumptions!D13 -> 1.5 | E5: =Assumptions!E13 -> 2 | F5: =Assumptions!F13 -> 2 | G5: =Assumptions!G13 -> 2 | H5: =Assumptions!H13 -> 2 | I5: =Assumptions!I13 -> 2 | J5: =Assumptions!J13 -> 2 | ... L5: =Assumptions!L13 -> 2
A6: Revenue | B6: 19627.602 | C6: =B6*(1+C5/100) -> 18940.636 | D6: =C6*(1+D5/100) -> 19224.745 | E6: =D6*(1+E5/100) -> 19609.24 | F6: =E6*(1+F5/100) -> 20001.425 | G6: =F6*(1+G5/100) -> 20401.454 | H6: =G6*(1+H5/100) -> 20809.483 | I6: =H6*(1+I5/100) -> 21225.672 | J6: =I6*(1+J5/100) -> 21650.186 | ... L6: =K6*(1+L5/100) -> 22524.853
A7: EBITDA margin (%) | C7: =Assumptions!C14 -> 17 | D7: =Assumptions!D14 -> 16.8 | E7: =Assumptions!E14 -> 16.6 | F7: =Assumptions!F14 -> 16.5 | G7: =Assumptions!G14 -> 16.4 | H7: =Assumptions!H14 -> 16.3 | I7: =Assumptions!I14 -> 16.2 | J7: =Assumptions!J14 -> 16.2 | ... L7: =Assumptions!L14 -> 16.2
A8: EBITDA | C8: =C6*C7/100 -> 3219.9081 | D8: =D6*D7/100 -> 3229.7572 | E8: =E6*E7/100 -> 3255.1339 | F8: =F6*F7/100 -> 3300.2352 | G8: =G6*G7/100 -> 3345.8384 | H8: =H6*H7/100 -> 3391.9457 | I8: =I6*I7/100 -> 3438.5589 | J8: =J6*J7/100 -> 3507.3301 | ... L8: =L6*L7/100 -> 3649.0262
A9: SBC (% of revenue) | C9: =Assumptions!C15 -> 0 | D9: =Assumptions!D15 -> 0 | E9: =Assumptions!E15 -> 0 | F9: =Assumptions!F15 -> 0 | G9: =Assumptions!G15 -> 0 | H9: =Assumptions!H15 -> 0 | I9: =Assumptions!I15 -> 0 | J9: =Assumptions!J15 -> 0 | ... L9: =Assumptions!L15 -> 0
A10: SBC charge | C10: =-C6*C9/100 -> 0 | D10: =-D6*D9/100 -> 0 | E10: =-E6*E9/100 -> 0 | F10: =-F6*F9/100 -> 0 | G10: =-G6*G9/100 -> 0 | H10: =-H6*H9/100 -> 0 | I10: =-I6*I9/100 -> 0 | J10: =-J6*J9/100 -> 0 | ... L10: =-L6*L9/100 -> 0
A11: Owner EBITDA (after SBC and leases) | C11: =C8+C10+C24 -> 2462.2827 | D11: =D8+D10+D24 -> 2460.7674 | E11: =E8+E10+E24 -> 2470.7643 | F11: =F8+F10+F24 -> 2500.1781 | G11: =G8+G10+G24 -> 2529.7803 | H11: =H8+H10+H24 -> 2559.5664 | I11: =I8+I10+I24 -> 2589.532 | J11: =J8+J10+J24 -> 2641.3227 | ... L11: =L8+L10+L24 -> 2748.0321
A12: D&A | C12: =-C6*Assumptions!C17/100 -> -814.44734 | D12: =-D6*Assumptions!D17/100 -> -826.66406 | E12: =-E6*Assumptions!E17/100 -> -843.19734 | F12: =-F6*Assumptions!F17/100 -> -860.06128 | G12: =-G6*Assumptions!G17/100 -> -877.26251 | H12: =-H6*Assumptions!H17/100 -> -894.80776 | I12: =-I6*Assumptions!I17/100 -> -912.70391 | J12: =-J6*Assumptions!J17/100 -> -930.95799 | ... L12: =-L6*Assumptions!L17/100 -> -968.5687
A13: EBIT | C13: =C11+C12 -> 1647.8353 | D13: =D11+D12 -> 1634.1034 | E13: =E11+E12 -> 1627.567 | F13: =F11+F12 -> 1640.1169 | G13: =G11+G12 -> 1652.5177 | H13: =H11+H12 -> 1664.7586 | I13: =I11+I12 -> 1676.8281 | J13: =J11+J12 -> 1710.3647 | ... L13: =L11+L12 -> 1779.4634
A14: Cash tax rate (%) | C14: =Assumptions!C19 -> 27 | D14: =Assumptions!D19 -> 27 | E14: =Assumptions!E19 -> 27 | F14: =Assumptions!F19 -> 27 | G14: =Assumptions!G19 -> 27 | H14: =Assumptions!H19 -> 27 | I14: =Assumptions!I19 -> 27 | J14: =Assumptions!J19 -> 27 | ... L14: =Assumptions!L19 -> 27
A15: NOPAT | C15: =C13-MAX(0,C13)*C14/100 -> 1202.9198 | D15: =D13-MAX(0,D13)*D14/100 -> 1192.8955 | E15: =E13-MAX(0,E13)*E14/100 -> 1188.1239 | F15: =F13-MAX(0,F13)*F14/100 -> 1197.2853 | G15: =G13-MAX(0,G13)*G14/100 -> 1206.338 | H15: =H13-MAX(0,H13)*H14/100 -> 1215.2738 | I15: =I13-MAX(0,I13)*I14/100 -> 1224.0845 | J15: =J13-MAX(0,J13)*J14/100 -> 1248.5662 | ... L15: =L13-MAX(0,L13)*L14/100 -> 1299.0083
A16: D&A add-back | C16: =-C12 -> 814.44734 | D16: =-D12 -> 826.66406 | E16: =-E12 -> 843.19734 | F16: =-F12 -> 860.06128 | G16: =-G12 -> 877.26251 | H16: =-H12 -> 894.80776 | I16: =-I12 -> 912.70391 | J16: =-J12 -> 930.95799 | ... L16: =-L12 -> 968.5687
A17: Capex | C17: =-C6*Assumptions!C18/100 -> -947.0318 | D17: =-D6*Assumptions!D18/100 -> -922.78778 | E17: =-E6*Assumptions!E18/100 -> -902.02506 | F17: =-F6*Assumptions!F18/100 -> -900.06413 | G17: =-G6*Assumptions!G18/100 -> -897.66396 | H17: =-H6*Assumptions!H18/100 -> -894.80776 | I17: =-I6*Assumptions!I18/100 -> -912.70391 | J17: =-J6*Assumptions!J18/100 -> -930.95799 | ... L17: =-L6*Assumptions!L18/100 -> -968.5687
A18: Working capital | C18: =(C6-B6)*Assumptions!$B$23/100 -> 68.696607 | D18: =(D6-C6)*Assumptions!$B$23/100 -> -28.410954 | E18: =(E6-D6)*Assumptions!$B$23/100 -> -38.449491 | F18: =(F6-E6)*Assumptions!$B$23/100 -> -39.218481 | G18: =(G6-F6)*Assumptions!$B$23/100 -> -40.00285 | H18: =(H6-G6)*Assumptions!$B$23/100 -> -40.802907 | I18: =(I6-H6)*Assumptions!$B$23/100 -> -41.618966 | J18: =(J6-I6)*Assumptions!$B$23/100 -> -42.451345 | ... L18: =(L6-K6)*Assumptions!$B$23/100 -> -44.166379
A19: Unlevered owner FCF | C19: =C15+C16+C17+C18 -> 1139.0319 | D19: =D15+D16+D17+D18 -> 1068.3608 | E19: =E15+E16+E17+E18 -> 1090.8467 | F19: =F15+F16+F17+F18 -> 1118.064 | G19: =G15+G16+G17+G18 -> 1145.9337 | H19: =H15+H16+H17+H18 -> 1174.4709 | I19: =I15+I16+I17+I18 -> 1182.4656 | J19: =J15+J16+J17+J18 -> 1206.1149 | ... L19: =L15+L16+L17+L18 -> 1254.8419
A20: Discount factor | C20: =1/(1+$B$27/100)^C4 -> 0.93457944 | D20: =1/(1+$B$27/100)^D4 -> 0.87343873 | E20: =1/(1+$B$27/100)^E4 -> 0.81629788 | F20: =1/(1+$B$27/100)^F4 -> 0.76289521 | G20: =1/(1+$B$27/100)^G4 -> 0.71298618 | H20: =1/(1+$B$27/100)^H4 -> 0.66634222 | I20: =1/(1+$B$27/100)^I4 -> 0.62274974 | J20: =1/(1+$B$27/100)^J4 -> 0.5820091 | ... L20: =1/(1+$B$27/100)^L4 -> 0.50834929
A21: PV of FCF | C21: =C19*C20 -> 1064.5158 | D21: =D19*D20 -> 933.14768 | E21: =E19*E20 -> 890.45581 | F21: =F19*F20 -> 852.96566 | G21: =G19*G20 -> 817.03486 | H21: =H19*H20 -> 782.59954 | I21: =I19*I20 -> 736.38012 | J21: =J19*J20 -> 701.96984 | ... L21: =L19*L20 -> 637.898
A23: Lease cost (% of revenue) | C23: =Assumptions!C16 -> 4 | D23: =Assumptions!D16 -> 4 | E23: =Assumptions!E16 -> 4 | F23: =Assumptions!F16 -> 4 | G23: =Assumptions!G16 -> 4 | H23: =Assumptions!H16 -> 4 | I23: =Assumptions!I16 -> 4 | J23: =Assumptions!J16 -> 4 | ... L23: =Assumptions!L16 -> 4
A24: Lease cost | C24: =-C6*C23/100 -> -757.62544 | D24: =-D6*D23/100 -> -768.98982 | E24: =-E6*E23/100 -> -784.36962 | F24: =-F6*F23/100 -> -800.05701 | G24: =-G6*G23/100 -> -816.05815 | H24: =-H6*H23/100 -> -832.37931 | I24: =-I6*I23/100 -> -849.0269 | J24: =-J6*J23/100 -> -866.00743 | ... L24: =-L6*L23/100 -> -900.99414
A26: Valuation
A27: WACC (%) | B27: =Assumptions!$B$20 -> 7
A28: Terminal growth (%) | B28: =Assumptions!$B$21 -> 1.5
A29: Terminal cap multiple (x FCF) | B29: =Assumptions!$B$22 -> 12
A30: Sum of PV of FCF | B30: =SUM(C21:L21) -> 8086.1349
A31: Terminal-year FCF | B31: =L19 -> 1254.8419
A32: Gordon terminal value | B32: =IF(B27>B28,B31*(1+B28/100)/((B27-B28)/100),B31*B29) -> 23157.537
A33: Cap terminal value | B33: =B31*B29 -> 15058.103
A34: Terminal value used: MAX(0,MIN(Gordon,cap)) | B34: =MAX(0,MIN(B32,B33)) -> 15058.103
A35: PV of terminal value | B35: =B34/(1+B27/100)^L4 -> 7654.776
A36: Enterprise value | B36: =B30+B35 -> 15740.911
A37: Equity value (EV + bridge - net debt) | B37: =B36+Assumptions!$B$5-Assumptions!$B$4 -> 5913.1108
A38: Value per share (quote currency) | B38: =B37/Assumptions!$B$3*Assumptions!$B$10 -> 22.220551
A39: Upside vs price | B39: =B38/Assumptions!$B$2-1 -> -0.450802
A41: Street memo: PV of explicit-period SBC | B41: =SUMPRODUCT(-C10:L10/(1+$B$27/100)^C4:L4) -> 0
A42: Street memo: PV of terminal SBC (Gordon) | B42: =IF(B27>B28,-L10*(1+B28/100)/((B27-B28)/100),-L10*20)/(1+B27/100)^L4 -> 0
A43: Street value per share | B43: =(B37+B41+B42)/Assumptions!$B$3*Assumptions!$B$10 -> 22.220551
A45: Hurdle rate (%) | B45: =Assumptions!$B$6 -> 15
...

Sheet DCF_Base
A1: FME.DE owner-FCF component DCF: base case (millions, EUR)
A3: Line | B3: FY2025 | C3: FY2026 | D3: FY2027 | E3: FY2028 | F3: FY2029 | G3: FY2030 | H3: FY2031 | I3: FY2032 | J3: FY2033 | K3: FY2034 | L3: FY2035
A4: Year index (discount exponent) | B4: 0 | C4: =B4+1 -> 1 | D4: =C4+1 -> 2 | E4: =D4+1 -> 3 | F4: =E4+1 -> 4 | G4: =F4+1 -> 5 | H4: =G4+1 -> 6 | I4: =H4+1 -> 7 | J4: =I4+1 -> 8 | ... L4: =K4+1 -> 10
A5: Revenue growth (%) | C5: =Assumptions!C27 -> -2.7 | D5: =Assumptions!D27 -> 3.5 | E5: =Assumptions!E27 -> 4 | F5: =Assumptions!F27 -> 4 | G5: =Assumptions!G27 -> 3.5 | H5: =Assumptions!H27 -> 3 | I5: =Assumptions!I27 -> 3 | J5: =Assumptions!J27 -> 2.5 | ... L5: =Assumptions!L27 -> 2.5
A6: Revenue | B6: 19627.602 | C6: =B6*(1+C5/100) -> 19097.657 | D6: =C6*(1+D5/100) -> 19766.075 | E6: =D6*(1+E5/100) -> 20556.718 | F6: =E6*(1+F5/100) -> 21378.986 | G6: =F6*(1+G5/100) -> 22127.251 | H6: =G6*(1+H5/100) -> 22791.068 | I6: =H6*(1+I5/100) -> 23474.801 | J6: =I6*(1+J5/100) -> 24061.671 | ... L6: =K6*(1+L5/100) -> 25279.793
A7: EBITDA margin (%) | C7: =Assumptions!C28 -> 17.4 | D7: =Assumptions!D28 -> 17.9 | E7: =Assumptions!E28 -> 18.4 | F7: =Assumptions!F28 -> 18.8 | G7: =Assumptions!G28 -> 19.1 | H7: =Assumptions!H28 -> 19.3 | I7: =Assumptions!I28 -> 19.4 | J7: =Assumptions!J28 -> 19.5 | ... L7: =Assumptions!L28 -> 19.5
A8: EBITDA | C8: =C6*C7/100 -> 3322.9923 | D8: =D6*D7/100 -> 3538.1274 | E8: =E6*E7/100 -> 3782.4361 | F8: =F6*F7/100 -> 4019.2494 | G8: =G6*G7/100 -> 4226.3049 | H8: =H6*H7/100 -> 4398.6762 | I8: =I6*I7/100 -> 4554.1113 | J8: =J6*J7/100 -> 4692.0258 | ... L8: =L6*L7/100 -> 4929.5596
A9: SBC (% of revenue) | C9: =Assumptions!C29 -> 0 | D9: =Assumptions!D29 -> 0 | E9: =Assumptions!E29 -> 0 | F9: =Assumptions!F29 -> 0 | G9: =Assumptions!G29 -> 0 | H9: =Assumptions!H29 -> 0 | I9: =Assumptions!I29 -> 0 | J9: =Assumptions!J29 -> 0 | ... L9: =Assumptions!L29 -> 0
A10: SBC charge | C10: =-C6*C9/100 -> 0 | D10: =-D6*D9/100 -> 0 | E10: =-E6*E9/100 -> 0 | F10: =-F6*F9/100 -> 0 | G10: =-G6*G9/100 -> 0 | H10: =-H6*H9/100 -> 0 | I10: =-I6*I9/100 -> 0 | J10: =-J6*J9/100 -> 0 | ... L10: =-L6*L9/100 -> 0
A11: Owner EBITDA (after SBC and leases) | C11: =C8+C10+C24 -> 2559.086 | D11: =D8+D10+D24 -> 2747.4844 | E11: =E8+E10+E24 -> 2960.1674 | F11: =F8+F10+F24 -> 3164.09 | G11: =G8+G10+G24 -> 3341.2149 | H11: =H8+H10+H24 -> 3487.0335 | I11: =I8+I10+I24 -> 3615.1193 | J11: =J8+J10+J24 -> 3729.5589 | ... L11: =L8+L10+L24 -> 3918.3679
A12: D&A | C12: =-C6*Assumptions!C31/100 -> -821.19924 | D12: =-D6*Assumptions!D31/100 -> -849.94121 | E12: =-E6*Assumptions!E31/100 -> -883.93886 | F12: =-F6*Assumptions!F31/100 -> -919.29642 | G12: =-G6*Assumptions!G31/100 -> -951.47179 | H12: =-H6*Assumptions!H31/100 -> -980.01594 | I12: =-I6*Assumptions!I31/100 -> -1009.4164 | J12: =-J6*Assumptions!J31/100 -> -1034.6518 | ... L12: =-L6*Assumptions!L31/100 -> -1087.0311
A13: EBIT | C13: =C11+C12 -> 1737.8868 | D13: =D11+D12 -> 1897.5432 | E13: =E11+E12 -> 2076.2285 | F13: =F11+F12 -> 2244.7936 | G13: =G11+G12 -> 2389.7431 | H13: =H11+H12 -> 2507.0175 | I13: =I11+I12 -> 2605.7029 | J13: =J11+J12 -> 2694.9071 | ... L13: =L11+L12 -> 2831.3368
A14: Cash tax rate (%) | C14: =Assumptions!C33 -> 26 | D14: =Assumptions!D33 -> 26 | E14: =Assumptions!E33 -> 26 | F14: =Assumptions!F33 -> 26 | G14: =Assumptions!G33 -> 26 | H14: =Assumptions!H33 -> 26 | I14: =Assumptions!I33 -> 26 | J14: =Assumptions!J33 -> 26 | ... L14: =Assumptions!L33 -> 26
A15: NOPAT | C15: =C13-MAX(0,C13)*C14/100 -> 1286.0362 | D15: =D13-MAX(0,D13)*D14/100 -> 1404.1819 | E15: =E13-MAX(0,E13)*E14/100 -> 1536.4091 | F15: =F13-MAX(0,F13)*F14/100 -> 1661.1472 | G15: =G13-MAX(0,G13)*G14/100 -> 1768.4099 | H15: =H13-MAX(0,H13)*H14/100 -> 1855.193 | I15: =I13-MAX(0,I13)*I14/100 -> 1928.2201 | J15: =J13-MAX(0,J13)*J14/100 -> 1994.2313 | ... L15: =L13-MAX(0,L13)*L14/100 -> 2095.1892
A16: D&A add-back | C16: =-C12 -> 821.19924 | D16: =-D12 -> 849.94121 | E16: =-E12 -> 883.93886 | F16: =-F12 -> 919.29642 | G16: =-G12 -> 951.47179 | H16: =-H12 -> 980.01594 | I16: =-I12 -> 1009.4164 | J16: =-J12 -> 1034.6518 | ... L16: =-L12 -> 1087.0311
A17: Capex | C17: =-C6*Assumptions!C32/100 -> -954.88284 | D17: =-D6*Assumptions!D32/100 -> -948.77159 | E17: =-E6*Assumptions!E32/100 -> -945.60902 | F17: =-F6*Assumptions!F32/100 -> -962.05439 | G17: =-G6*Assumptions!G32/100 -> -973.59904 | H17: =-H6*Assumptions!H32/100 -> -980.01594 | I17: =-I6*Assumptions!I32/100 -> -1009.4164 | J17: =-J6*Assumptions!J32/100 -> -1034.6518 | ... L17: =-L6*Assumptions!L32/100 -> -1087.0311
A18: Working capital | C18: =(C6-B6)*Assumptions!$B$37/100 -> 52.994525 | D18: =(D6-C6)*Assumptions!$B$37/100 -> -66.841799 | E18: =(E6-D6)*Assumptions!$B$37/100 -> -79.064299 | F18: =(F6-E6)*Assumptions!$B$37/100 -> -82.226871 | G18: =(G6-F6)*Assumptions!$B$37/100 -> -74.826453 | H18: =(H6-G6)*Assumptions!$B$37/100 -> -66.381753 | I18: =(I6-H6)*Assumptions!$B$37/100 -> -68.373205 | J18: =(J6-I6)*Assumptions!$B$37/100 -> -58.687001 | ... L18: =(L6-K6)*Assumptions!$B$37/100 -> -61.658031
A19: Unlevered owner FCF | C19: =C15+C16+C17+C18 -> 1205.3471 | D19: =D15+D16+D17+D18 -> 1238.5098 | E19: =E15+E16+E17+E18 -> 1395.6746 | F19: =F15+F16+F17+F18 -> 1536.1624 | G19: =G15+G16+G17+G18 -> 1671.4562 | H19: =H15+H16+H17+H18 -> 1788.8112 | I19: =I15+I16+I17+I18 -> 1859.8469 | J19: =J15+J16+J17+J18 -> 1935.5443 | ... L19: =L15+L16+L17+L18 -> 2033.5312
A20: Discount factor | C20: =1/(1+$B$27/100)^C4 -> 0.93457944 | D20: =1/(1+$B$27/100)^D4 -> 0.87343873 | E20: =1/(1+$B$27/100)^E4 -> 0.81629788 | F20: =1/(1+$B$27/100)^F4 -> 0.76289521 | G20: =1/(1+$B$27/100)^G4 -> 0.71298618 | H20: =1/(1+$B$27/100)^H4 -> 0.66634222 | I20: =1/(1+$B$27/100)^I4 -> 0.62274974 | J20: =1/(1+$B$27/100)^J4 -> 0.5820091 | ... L20: =1/(1+$B$27/100)^L4 -> 0.50834929
A21: PV of FCF | C21: =C19*C20 -> 1126.4926 | D21: =D19*D20 -> 1081.7624 | E21: =E19*E20 -> 1139.2862 | F21: =F19*F20 -> 1171.9309 | G21: =G19*G20 -> 1191.7252 | H21: =H19*H20 -> 1191.9604 | I21: =I19*I20 -> 1158.2192 | J21: =J19*J20 -> 1126.5044 | ... L21: =L19*L20 -> 1033.7441
A23: Lease cost (% of revenue) | C23: =Assumptions!C30 -> 4 | D23: =Assumptions!D30 -> 4 | E23: =Assumptions!E30 -> 4 | F23: =Assumptions!F30 -> 4 | G23: =Assumptions!G30 -> 4 | H23: =Assumptions!H30 -> 4 | I23: =Assumptions!I30 -> 4 | J23: =Assumptions!J30 -> 4 | ... L23: =Assumptions!L30 -> 4
A24: Lease cost | C24: =-C6*C23/100 -> -763.90627 | D24: =-D6*D23/100 -> -790.64299 | E24: =-E6*E23/100 -> -822.26871 | F24: =-F6*F23/100 -> -855.15946 | G24: =-G6*G23/100 -> -885.09004 | H24: =-H6*H23/100 -> -911.64274 | I24: =-I6*I23/100 -> -938.99202 | J24: =-J6*J23/100 -> -962.46682 | ... L24: =-L6*L23/100 -> -1011.1917
A26: Valuation
A27: WACC (%) | B27: =Assumptions!$B$34 -> 7
A28: Terminal growth (%) | B28: =Assumptions!$B$35 -> 2
A29: Terminal cap multiple (x FCF) | B29: =Assumptions!$B$36 -> 15
A30: Sum of PV of FCF | B30: =SUM(C21:L21) -> 11300.754
A31: Terminal-year FCF | B31: =L19 -> 2033.5312
A32: Gordon terminal value | B32: =IF(B27>B28,B31*(1+B28/100)/((B27-B28)/100),B31*B29) -> 41484.036
A33: Cap terminal value | B33: =B31*B29 -> 30502.968
A34: Terminal value used: MAX(0,MIN(Gordon,cap)) | B34: =MAX(0,MIN(B32,B33)) -> 30502.968
A35: PV of terminal value | B35: =B34/(1+B27/100)^L4 -> 15506.162
A36: Enterprise value | B36: =B30+B35 -> 26806.916
A37: Equity value (EV + bridge - net debt) | B37: =B36+Assumptions!$B$5-Assumptions!$B$4 -> 16979.116
A38: Value per share (quote currency) | B38: =B37/Assumptions!$B$3*Assumptions!$B$10 -> 63.804876
A39: Upside vs price | B39: =B38/Assumptions!$B$2-1 -> 0.57698656
A41: Street memo: PV of explicit-period SBC | B41: =SUMPRODUCT(-C10:L10/(1+$B$27/100)^C4:L4) -> 0
A42: Street memo: PV of terminal SBC (Gordon) | B42: =IF(B27>B28,-L10*(1+B28/100)/((B27-B28)/100),-L10*20)/(1+B27/100)^L4 -> 0
A43: Street value per share | B43: =(B37+B41+B42)/Assumptions!$B$3*Assumptions!$B$10 -> 63.804876
A45: Hurdle rate (%) | B45: =Assumptions!$B$6 -> 15
...

Sheet DCF_Bull
A1: FME.DE owner-FCF component DCF: bull case (millions, EUR)
A3: Line | B3: FY2025 | C3: FY2026 | D3: FY2027 | E3: FY2028 | F3: FY2029 | G3: FY2030 | H3: FY2031 | I3: FY2032 | J3: FY2033 | K3: FY2034 | L3: FY2035
A4: Year index (discount exponent) | B4: 0 | C4: =B4+1 -> 1 | D4: =C4+1 -> 2 | E4: =D4+1 -> 3 | F4: =E4+1 -> 4 | G4: =F4+1 -> 5 | H4: =G4+1 -> 6 | I4: =H4+1 -> 7 | J4: =I4+1 -> 8 | ... L4: =K4+1 -> 10
A5: Revenue growth (%) | C5: =Assumptions!C41 -> -2 | D5: =Assumptions!D41 -> 5.5 | E5: =Assumptions!E41 -> 6 | F5: =Assumptions!F41 -> 6 | G5: =Assumptions!G41 -> 5.5 | H5: =Assumptions!H41 -> 4.5 | I5: =Assumptions!I41 -> 4 | J5: =Assumptions!J41 -> 3.5 | ... L5: =Assumptions!L41 -> 3
A6: Revenue | B6: 19627.602 | C6: =B6*(1+C5/100) -> 19235.05 | D6: =C6*(1+D5/100) -> 20292.978 | E6: =D6*(1+E5/100) -> 21510.556 | F6: =E6*(1+F5/100) -> 22801.19 | G6: =F6*(1+G5/100) -> 24055.255 | H6: =G6*(1+H5/100) -> 25137.742 | I6: =H6*(1+I5/100) -> 26143.251 | J6: =I6*(1+J5/100) -> 27058.265 | ... L6: =K6*(1+L5/100) -> 28706.113
A7: EBITDA margin (%) | C7: =Assumptions!C42 -> 17.6 | D7: =Assumptions!D42 -> 18.5 | E7: =Assumptions!E42 -> 19.4 | F7: =Assumptions!F42 -> 20.2 | G7: =Assumptions!G42 -> 20.8 | H7: =Assumptions!H42 -> 21.2 | I7: =Assumptions!I42 -> 21.4 | J7: =Assumptions!J42 -> 21.5 | ... L7: =Assumptions!L42 -> 21.5
A8: EBITDA | C8: =C6*C7/100 -> 3385.3688 | D8: =D6*D7/100 -> 3754.2009 | E8: =E6*E7/100 -> 4173.0479 | F8: =F6*F7/100 -> 4605.8403 | G8: =G6*G7/100 -> 5003.4931 | H8: =H6*H7/100 -> 5329.2012 | I8: =I6*I7/100 -> 5594.6558 | J8: =J6*J7/100 -> 5817.527 | ... L8: =L6*L7/100 -> 6171.8144
A9: SBC (% of revenue) | C9: =Assumptions!C43 -> 0 | D9: =Assumptions!D43 -> 0 | E9: =Assumptions!E43 -> 0 | F9: =Assumptions!F43 -> 0 | G9: =Assumptions!G43 -> 0 | H9: =Assumptions!H43 -> 0 | I9: =Assumptions!I43 -> 0 | J9: =Assumptions!J43 -> 0 | ... L9: =Assumptions!L43 -> 0
A10: SBC charge | C10: =-C6*C9/100 -> 0 | D10: =-D6*D9/100 -> 0 | E10: =-E6*E9/100 -> 0 | F10: =-F6*F9/100 -> 0 | G10: =-G6*G9/100 -> 0 | H10: =-H6*H9/100 -> 0 | I10: =-I6*I9/100 -> 0 | J10: =-J6*J9/100 -> 0 | ... L10: =-L6*L9/100 -> 0
A11: Owner EBITDA (after SBC and leases) | C11: =C8+C10+C24 -> 2615.9668 | D11: =D8+D10+D24 -> 2942.4818 | E11: =E8+E10+E24 -> 3312.6257 | F11: =F8+F10+F24 -> 3693.7927 | G11: =G8+G10+G24 -> 4041.2829 | H11: =H8+H10+H24 -> 4323.6916 | I11: =I8+I10+I24 -> 4548.9257 | J11: =J8+J10+J24 -> 4735.1964 | ... L11: =L8+L10+L24 -> 5023.5699
A12: D&A | C12: =-C6*Assumptions!C45/100 -> -827.10715 | D12: =-D6*Assumptions!D45/100 -> -872.59804 | E12: =-E6*Assumptions!E45/100 -> -924.95392 | F12: =-F6*Assumptions!F45/100 -> -980.45116 | G12: =-G6*Assumptions!G45/100 -> -1034.376 | H12: =-H6*Assumptions!H45/100 -> -1080.9229 | I12: =-I6*Assumptions!I45/100 -> -1124.1598 | J12: =-J6*Assumptions!J45/100 -> -1163.5054 | ... L12: =-L6*Assumptions!L45/100 -> -1234.3629
A13: EBIT | C13: =C11+C12 -> 1788.8596 | D13: =D11+D12 -> 2069.8837 | E13: =E11+E12 -> 2387.6718 | F13: =F11+F12 -> 2713.3416 | G13: =G11+G12 -> 3006.9069 | H13: =H11+H12 -> 3242.7687 | I13: =I11+I12 -> 3424.7659 | J13: =J11+J12 -> 3571.691 | ... L13: =L11+L12 -> 3789.207
A14: Cash tax rate (%) | C14: =Assumptions!C47 -> 26 | D14: =Assumptions!D47 -> 26 | E14: =Assumptions!E47 -> 26 | F14: =Assumptions!F47 -> 26 | G14: =Assumptions!G47 -> 26 | H14: =Assumptions!H47 -> 26 | I14: =Assumptions!I47 -> 26 | J14: =Assumptions!J47 -> 26 | ... L14: =Assumptions!L47 -> 26
A15: NOPAT | C15: =C13-MAX(0,C13)*C14/100 -> 1323.7561 | D15: =D13-MAX(0,D13)*D14/100 -> 1531.714 | E15: =E13-MAX(0,E13)*E14/100 -> 1766.8771 | F15: =F13-MAX(0,F13)*F14/100 -> 2007.8728 | G15: =G13-MAX(0,G13)*G14/100 -> 2225.1111 | H15: =H13-MAX(0,H13)*H14/100 -> 2399.6488 | I15: =I13-MAX(0,I13)*I14/100 -> 2534.3268 | J15: =J13-MAX(0,J13)*J14/100 -> 2643.0513 | ... L15: =L13-MAX(0,L13)*L14/100 -> 2804.0132
A16: D&A add-back | C16: =-C12 -> 827.10715 | D16: =-D12 -> 872.59804 | E16: =-E12 -> 924.95392 | F16: =-F12 -> 980.45116 | G16: =-G12 -> 1034.376 | H16: =-H12 -> 1080.9229 | I16: =-I12 -> 1124.1598 | J16: =-J12 -> 1163.5054 | ... L16: =-L12 -> 1234.3629
A17: Capex | C17: =-C6*Assumptions!C46/100 -> -961.7525 | D17: =-D6*Assumptions!D46/100 -> -974.06293 | E17: =-E6*Assumptions!E46/100 -> -989.48559 | F17: =-F6*Assumptions!F46/100 -> -1026.0535 | G17: =-G6*Assumptions!G46/100 -> -1058.4312 | H17: =-H6*Assumptions!H46/100 -> -1080.9229 | I17: =-I6*Assumptions!I46/100 -> -1124.1598 | J17: =-J6*Assumptions!J46/100 -> -1163.5054 | ... L17: =-L6*Assumptions!L46/100 -> -1234.3629
A18: Working capital | C18: =(C6-B6)*Assumptions!$B$51/100 -> 39.255204 | D18: =(D6-C6)*Assumptions!$B$51/100 -> -105.79277 | E18: =(E6-D6)*Assumptions!$B$51/100 -> -121.75787 | F18: =(F6-E6)*Assumptions!$B$51/100 -> -129.06334 | G18: =(G6-F6)*Assumptions!$B$51/100 -> -125.40654 | H18: =(H6-G6)*Assumptions!$B$51/100 -> -108.24865 | I18: =(I6-H6)*Assumptions!$B$51/100 -> -100.55097 | J18: =(J6-I6)*Assumptions!$B$51/100 -> -91.50138 | ... L18: =(L6-K6)*Assumptions!$B$51/100 -> -83.610039
A19: Unlevered owner FCF | C19: =C15+C16+C17+C18 -> 1228.366 | D19: =D15+D16+D17+D18 -> 1324.4563 | E19: =E15+E16+E17+E18 -> 1580.5876 | F19: =F15+F16+F17+F18 -> 1833.2071 | G19: =G15+G16+G17+G18 -> 2075.6493 | H19: =H15+H16+H17+H18 -> 2291.4002 | I19: =I15+I16+I17+I18 -> 2433.7758 | J19: =J15+J16+J17+J18 -> 2551.55 | ... L19: =L15+L16+L17+L18 -> 2720.4031
A20: Discount factor | C20: =1/(1+$B$27/100)^C4 -> 0.93457944 | D20: =1/(1+$B$27/100)^D4 -> 0.87343873 | E20: =1/(1+$B$27/100)^E4 -> 0.81629788 | F20: =1/(1+$B$27/100)^F4 -> 0.76289521 | G20: =1/(1+$B$27/100)^G4 -> 0.71298618 | H20: =1/(1+$B$27/100)^H4 -> 0.66634222 | I20: =1/(1+$B$27/100)^I4 -> 0.62274974 | J20: =1/(1+$B$27/100)^J4 -> 0.5820091 | ... L20: =1/(1+$B$27/100)^L4 -> 0.50834929
A21: PV of FCF | C21: =C19*C20 -> 1148.0056 | D21: =D19*D20 -> 1156.8314 | E21: =E19*E20 -> 1290.2303 | F21: =F19*F20 -> 1398.5449 | G21: =G19*G20 -> 1479.9093 | H21: =H19*H20 -> 1526.8567 | I21: =I19*I20 -> 1515.6333 | J21: =J19*J20 -> 1485.0253 | ... L21: =L19*L20 -> 1382.915
A23: Lease cost (% of revenue) | C23: =Assumptions!C44 -> 4 | D23: =Assumptions!D44 -> 4 | E23: =Assumptions!E44 -> 4 | F23: =Assumptions!F44 -> 4 | G23: =Assumptions!G44 -> 4 | H23: =Assumptions!H44 -> 4 | I23: =Assumptions!I44 -> 4 | J23: =Assumptions!J44 -> 4 | ... L23: =Assumptions!L44 -> 4
A24: Lease cost | C24: =-C6*C23/100 -> -769.402 | D24: =-D6*D23/100 -> -811.71911 | E24: =-E6*E23/100 -> -860.42225 | F24: =-F6*F23/100 -> -912.04759 | G24: =-G6*G23/100 -> -962.21021 | H24: =-H6*H23/100 -> -1005.5097 | I24: =-I6*I23/100 -> -1045.7301 | J24: =-J6*J23/100 -> -1082.3306 | ... L24: =-L6*L23/100 -> -1148.2445
A26: Valuation
A27: WACC (%) | B27: =Assumptions!$B$48 -> 7
A28: Terminal growth (%) | B28: =Assumptions!$B$49 -> 2.5
A29: Terminal cap multiple (x FCF) | B29: =Assumptions!$B$50 -> 16
A30: Sum of PV of FCF | B30: =SUM(C21:L21) -> 13820.572
A31: Terminal-year FCF | B31: =L19 -> 2720.4031
A32: Gordon terminal value | B32: =IF(B27>B28,B31*(1+B28/100)/((B27-B28)/100),B31*B29) -> 61964.738
A33: Cap terminal value | B33: =B31*B29 -> 43526.45
A34: Terminal value used: MAX(0,MIN(Gordon,cap)) | B34: =MAX(0,MIN(B32,B33)) -> 43526.45
A35: PV of terminal value | B35: =B34/(1+B27/100)^L4 -> 22126.64
A36: Enterprise value | B36: =B30+B35 -> 35947.212
A37: Equity value (EV + bridge - net debt) | B37: =B36+Assumptions!$B$5-Assumptions!$B$4 -> 26119.412
A38: Value per share (quote currency) | B38: =B37/Assumptions!$B$3*Assumptions!$B$10 -> 98.152689
A39: Upside vs price | B39: =B38/Assumptions!$B$2-1 -> 1.4259192
A41: Street memo: PV of explicit-period SBC | B41: =SUMPRODUCT(-C10:L10/(1+$B$27/100)^C4:L4) -> 0
A42: Street memo: PV of terminal SBC (Gordon) | B42: =IF(B27>B28,-L10*(1+B28/100)/((B27-B28)/100),-L10*20)/(1+B27/100)^L4 -> 0
A43: Street value per share | B43: =(B37+B41+B42)/Assumptions!$B$3*Assumptions!$B$10 -> 98.152689
A45: Hurdle rate (%) | B45: =Assumptions!$B$6 -> 15
...

Sheet Valuation
A1: FME.DE valuation summary
A3: Scenario | B3: Value per share | C3: Upside vs price | D3: Weight | E3: Street value per share | F3: Hurdle entry price
A4: Bear | B4: =DCF_Bear!$B$38 -> 22.220551 | C4: =B4/Assumptions!$B$2-1 -> -0.450802 | D4: =Assumptions!$B$24 -> 0.25 | E4: =DCF_Bear!$B$43 -> 22.220551 | F4: =DCF_Bear!$B$47 -> -6.6315838
A5: Base | B5: =DCF_Base!$B$38 -> 63.804876 | C5: =B5/Assumptions!$B$2-1 -> 0.57698656 | D5: =Assumptions!$B$38 -> 0.5 | E5: =DCF_Base!$B$43 -> 63.804876 | F5: =DCF_Base!$B$47 -> 7.1385121
A6: Bull | B6: =DCF_Bull!$B$38 -> 98.152689 | C6: =B6/Assumptions!$B$2-1 -> 1.4259192 | D6: =Assumptions!$B$52 -> 0.25 | E6: =DCF_Bull!$B$43 -> 98.152689 | F6: =DCF_Bull!$B$47 -> 18.932517
A8: Probability-weighted value per share | B8: =SUMPRODUCT(B4:B6,D4:D6) -> 61.995748
A9: Street weighted value per share | B9: =SUMPRODUCT(E4:E6,D4:D6) -> 61.995748
A10: Margin of safety (1 - price/weighted) | B10: =1-Assumptions!$B$2/B8 -> 0.3473746
A11: Band position (%; 0 = house, 100 = street) | B11: =IF(ABS(B9-B8)>0.01*ABS(B8),(Assumptions!$B$2-B8)/(B9-B8)*100,"n/a") -> n/a
A12: Weighted 15% hurdle entry price | B12: =SUMPRODUCT(F4:F6,D4:D6) -> 6.6444893
A14: Required-return table (base case; each row rebuilds its own terminal value) | C14: Rate (%)
A15: Value per share at 7% (WACC) | B15: =(SUMPRODUCT(DCF_Base!$C$19:$L$19/(1+$C$15/100)^DCF_Base!$C$4:$L$4)+MAX(0,MIN(IF($C$15>DCF_Base!$B$28,DCF_Base!$L$19*(1+DCF_Base!$B$28/100)/(($C$15-DCF_Base!$B$28)/100),DCF_Base!$L$19*DCF_Base!$B$29),DCF_Base!$L$19*DCF_Base!$B$29))/(1+$C$15/100)^DCF_Base!$L$4+Assumptions!$B$5-Assumptions!$B$4)/Assumptions!$B$3*Assumptions!$B$10 -> 63.804876 | C15: 7
A16: Value per share at 9% | B16: =(SUMPRODUCT(DCF_Base!$C$19:$L$19/(1+$C$16/100)^DCF_Base!$C$4:$L$4)+MAX(0,MIN(IF($C$16>DCF_Base!$B$28,DCF_Base!$L$19*(1+DCF_Base!$B$28/100)/(($C$16-DCF_Base!$B$28)/100),DCF_Base!$L$19*DCF_Base!$B$29),DCF_Base!$L$19*DCF_Base!$B$29))/(1+$C$16/100)^DCF_Base!$L$4+Assumptions!$B$5-Assumptions!$B$4)/Assumptions!$B$3*Assumptions!$B$10 -> 48.540982 | C16: 9
A17: Value per share at 10% | B17: =(SUMPRODUCT(DCF_Base!$C$19:$L$19/(1+$C$17/100)^DCF_Base!$C$4:$L$4)+MAX(0,MIN(IF($C$17>DCF_Base!$B$28,DCF_Base!$L$19*(1+DCF_Base!$B$28/100)/(($C$17-DCF_Base!$B$28)/100),DCF_Base!$L$19*DCF_Base!$B$29),DCF_Base!$L$19*DCF_Base!$B$29))/(1+$C$17/100)^DCF_Base!$L$4+Assumptions!$B$5-Assumptions!$B$4)/Assumptions!$B$3*Assumptions!$B$10 -> 37.262191 | C17: 10
A18: Value per share at 11% | B18: =(SUMPRODUCT(DCF_Base!$C$19:$L$19/(1+$C$18/100)^DCF_Base!$C$4:$L$4)+MAX(0,MIN(IF($C$18>DCF_Base!$B$28,DCF_Base!$L$19*(1+DCF_Base!$B$28/100)/(($C$18-DCF_Base!$B$28)/100),DCF_Base!$L$19*DCF_Base!$B$29),DCF_Base!$L$19*DCF_Base!$B$29))/(1+$C$18/100)^DCF_Base!$L$4+Assumptions!$B$5-Assumptions!$B$4)/Assumptions!$B$3*Assumptions!$B$10 -> 28.515087 | C18: 11
A19: Value per share at 12% | B19: =(SUMPRODUCT(DCF_Base!$C$19:$L$19/(1+$C$19/100)^DCF_Base!$C$4:$L$4)+MAX(0,MIN(IF($C$19>DCF_Base!$B$28,DCF_Base!$L$19*(1+DCF_Base!$B$28/100)/(($C$19-DCF_Base!$B$28)/100),DCF_Base!$L$19*DCF_Base!$B$29),DCF_Base!$L$19*DCF_Base!$B$29))/(1+$C$19/100)^DCF_Base!$L$4+Assumptions!$B$5-Assumptions!$B$4)/Assumptions!$B$3*Assumptions!$B$10 -> 21.538769 | C19: 12
A20: Value per share at 15% | B20: =(SUMPRODUCT(DCF_Base!$C$19:$L$19/(1+$C$20/100)^DCF_Base!$C$4:$L$4)+MAX(0,MIN(IF($C$20>DCF_Base!$B$28,DCF_Base!$L$19*(1+DCF_Base!$B$28/100)/(($C$20-DCF_Base!$B$28)/100),DCF_Base!$L$19*DCF_Base!$B$29),DCF_Base!$L$19*DCF_Base!$B$29))/(1+$C$20/100)^DCF_Base!$L$4+Assumptions!$B$5-Assumptions!$B$4)/Assumptions!$B$3*Assumptions!$B$10 -> 7.1385121 | C20: 15
A22: Sensitivity: value per share, rows WACC (%) x columns terminal growth (%)
B23: 1 | C23: 1.5 | D23: 2 | E23: 2.5 | F23: 3
A24: 5 | B24: =(SUMPRODUCT(DCF_Base!$C$19:$L$19/(1+$A$24/100)^DCF_Base!$C$4:$L$4)+MAX(0,MIN(IF($A$24>$B$23,DCF_Base!$L$19*(1+$B$23/100)/(($A$24-$B$23)/100),DCF_Base!$L$19*DCF_Base!$B$29),DCF_Base!$L$19*DCF_Base!$B$29))/(1+$A$24/100)^DCF_Base!$L$4+Assumptions!$B$5-Assumptions!$B$4)/Assumptions!$B$3*Assumptions!$B$10 -> 80.578269 | C24: =(SUMPRODUCT(DCF_Base!$C$19:$L$19/(1+$A$24/100)^DCF_Base!$C$4:$L$4)+MAX(0,MIN(IF($A$24>$C$23,DCF_Base!$L$19*(1+$C$23/100)/(($A$24-$C$23)/100),DCF_Base!$L$19*DCF_Base!$B$29),DCF_Base!$L$19*DCF_Base!$B$29))/(1+$A$24/100)^DCF_Base!$L$4+Assumptions!$B$5-Assumptions!$B$4)/Assumptions!$B$3*Assumptions!$B$10 -> 80.578269 | D24: =(SUMPRODUCT(DCF_Base!$C$19:$L$19/(1+$A$24/100)^DCF_Base!$C$4:$L$4)+MAX(0,MIN(IF($A$24>$D$23,DCF_Base!$L$19*(1+$D$23/100)/(($A$24-$D$23)/100),DCF_Base!$L$19*DCF_Base!$B$29),DCF_Base!$L$19*DCF_Base!$B$29))/(1+$A$24/100)^DCF_Base!$L$4+Assumptions!$B$5-Assumptions!$B$4)/Assumptions!$B$3*Assumptions!$B$10 -> 80.578269 | E24: =(SUMPRODUCT(DCF_Base!$C$19:$L$19/(1+$A$24/100)^DCF_Base!$C$4:$L$4)+MAX(0,MIN(IF($A$24>$E$23,DCF_Base!$L$19*(1+$E$23/100)/(($A$24-$E$23)/100),DCF_Base!$L$19*DCF_Base!$B$29),DCF_Base!$L$19*DCF_Base!$B$29))/(1+$A$24/100)^DCF_Base!$L$4+Assumptions!$B$5-Assumptions!$B$4)/Assumptions!$B$3*Assumptions!$B$10 -> 80.578269 | F24: =(SUMPRODUCT(DCF_Base!$C$19:$L$19/(1+$A$24/100)^DCF_Base!$C$4:$L$4)+MAX(0,MIN(IF($A$24>$F$23,DCF_Base!$L$19*(1+$F$23/100)/(($A$24-$F$23)/100),DCF_Base!$L$19*DCF_Base!$B$29),DCF_Base!$L$19*DCF_Base!$B$29))/(1+$A$24/100)^DCF_Base!$L$4+Assumptions!$B$5-Assumptions!$B$4)/Assumptions!$B$3*Assumptions!$B$10 -> 80.578269
A25: 6 | B25: =(SUMPRODUCT(DCF_Base!$C$19:$L$19/(1+$A$25/100)^DCF_Base!$C$4:$L$4)+MAX(0,MIN(IF($A$25>$B$23,DCF_Base!$L$19*(1+$B$23/100)/(($A$25-$B$23)/100),DCF_Base!$L$19*DCF_Base!$B$29),DCF_Base!$L$19*DCF_Base!$B$29))/(1+$A$25/100)^DCF_Base!$L$4+Assumptions!$B$5-Assumptions!$B$4)/Assumptions!$B$3*Assumptions!$B$10 -> 71.790036 | C25: =(SUMPRODUCT(DCF_Base!$C$19:$L$19/(1+$A$25/100)^DCF_Base!$C$4:$L$4)+MAX(0,MIN(IF($A$25>$C$23,DCF_Base!$L$19*(1+$C$23/100)/(($A$25-$C$23)/100),DCF_Base!$L$19*DCF_Base!$B$29),DCF_Base!$L$19*DCF_Base!$B$29))/(1+$A$25/100)^DCF_Base!$L$4+Assumptions!$B$5-Assumptions!$B$4)/Assumptions!$B$3*Assumptions!$B$10 -> 71.790036 | D25: =(SUMPRODUCT(DCF_Base!$C$19:$L$19/(1+$A$25/100)^DCF_Base!$C$4:$L$4)+MAX(0,MIN(IF($A$25>$D$23,DCF_Base!$L$19*(1+$D$23/100)/(($A$25-$D$23)/100),DCF_Base!$L$19*DCF_Base!$B$29),DCF_Base!$L$19*DCF_Base!$B$29))/(1+$A$25/100)^DCF_Base!$L$4+Assumptions!$B$5-Assumptions!$B$4)/Assumptions!$B$3*Assumptions!$B$10 -> 71.790036 | E25: =(SUMPRODUCT(DCF_Base!$C$19:$L$19/(1+$A$25/100)^DCF_Base!$C$4:$L$4)+MAX(0,MIN(IF($A$25>$E$23,DCF_Base!$L$19*(1+$E$23/100)/(($A$25-$E$23)/100),DCF_Base!$L$19*DCF_Base!$B$29),DCF_Base!$L$19*DCF_Base!$B$29))/(1+$A$25/100)^DCF_Base!$L$4+Assumptions!$B$5-Assumptions!$B$4)/Assumptions!$B$3*Assumptions!$B$10 -> 71.790036 | F25: =(SUMPRODUCT(DCF_Base!$C$19:$L$19/(1+$A$25/100)^DCF_Base!$C$4:$L$4)+MAX(0,MIN(IF($A$25>$F$23,DCF_Base!$L$19*(1+$F$23/100)/(($A$25-$F$23)/100),DCF_Base!$L$19*DCF_Base!$B$29),DCF_Base!$L$19*DCF_Base!$B$29))/(1+$A$25/100)^DCF_Base!$L$4+Assumptions!$B$5-Assumptions!$B$4)/Assumptions!$B$3*Assumptions!$B$10 -> 71.790036
A26: 7 | B26: =(SUMPRODUCT(DCF_Base!$C$19:$L$19/(1+$A$26/100)^DCF_Base!$C$4:$L$4)+MAX(0,MIN(IF($A$26>$B$23,DCF_Base!$L$19*(1+$B$23/100)/(($A$26-$B$23)/100),DCF_Base!$L$19*DCF_Base!$B$29),DCF_Base!$L$19*DCF_Base!$B$29))/(1+$A$26/100)^DCF_Base!$L$4+Assumptions!$B$5-Assumptions!$B$4)/Assumptions!$B$3*Assumptions!$B$10 -> 63.804876 | C26: =(SUMPRODUCT(DCF_Base!$C$19:$L$19/(1+$A$26/100)^DCF_Base!$C$4:$L$4)+MAX(0,MIN(IF($A$26>$C$23,DCF_Base!$L$19*(1+$C$23/100)/(($A$26-$C$23)/100),DCF_Base!$L$19*DCF_Base!$B$29),DCF_Base!$L$19*DCF_Base!$B$29))/(1+$A$26/100)^DCF_Base!$L$4+Assumptions!$B$5-Assumptions!$B$4)/Assumptions!$B$3*Assumptions!$B$10 -> 63.804876 | D26: =(SUMPRODUCT(DCF_Base!$C$19:$L$19/(1+$A$26/100)^DCF_Base!$C$4:$L$4)+MAX(0,MIN(IF($A$26>$D$23,DCF_Base!$L$19*(1+$D$23/100)/(($A$26-$D$23)/100),DCF_Base!$L$19*DCF_Base!$B$29),DCF_Base!$L$19*DCF_Base!$B$29))/(1+$A$26/100)^DCF_Base!$L$4+Assumptions!$B$5-Assumptions!$B$4)/Assumptions!$B$3*Assumptions!$B$10 -> 63.804876 | E26: =(SUMPRODUCT(DCF_Base!$C$19:$L$19/(1+$A$26/100)^DCF_Base!$C$4:$L$4)+MAX(0,MIN(IF($A$26>$E$23,DCF_Base!$L$19*(1+$E$23/100)/(($A$26-$E$23)/100),DCF_Base!$L$19*DCF_Base!$B$29),DCF_Base!$L$19*DCF_Base!$B$29))/(1+$A$26/100)^DCF_Base!$L$4+Assumptions!$B$5-Assumptions!$B$4)/Assumptions!$B$3*Assumptions!$B$10 -> 63.804876 | F26: =(SUMPRODUCT(DCF_Base!$C$19:$L$19/(1+$A$26/100)^DCF_Base!$C$4:$L$4)+MAX(0,MIN(IF($A$26>$F$23,DCF_Base!$L$19*(1+$F$23/100)/(($A$26-$F$23)/100),DCF_Base!$L$19*DCF_Base!$B$29),DCF_Base!$L$19*DCF_Base!$B$29))/(1+$A$26/100)^DCF_Base!$L$4+Assumptions!$B$5-Assumptions!$B$4)/Assumptions!$B$3*Assumptions!$B$10 -> 63.804876
A27: 8 | B27: =(SUMPRODUCT(DCF_Base!$C$19:$L$19/(1+$A$27/100)^DCF_Base!$C$4:$L$4)+MAX(0,MIN(IF($A$27>$B$23,DCF_Base!$L$19*(1+$B$23/100)/(($A$27-$B$23)/100),DCF_Base!$L$19*DCF_Base!$B$29),DCF_Base!$L$19*DCF_Base!$B$29))/(1+$A$27/100)^DCF_Base!$L$4+Assumptions!$B$5-Assumptions!$B$4)/Assumptions!$B$3*Assumptions!$B$10 -> 54.518033 | C27: =(SUMPRODUCT(DCF_Base!$C$19:$L$19/(1+$A$27/100)^DCF_Base!$C$4:$L$4)+MAX(0,MIN(IF($A$27>$C$23,DCF_Base!$L$19*(1+$C$23/100)/(($A$27-$C$23)/100),DCF_Base!$L$19*DCF_Base!$B$29),DCF_Base!$L$19*DCF_Base!$B$29))/(1+$A$27/100)^DCF_Base!$L$4+Assumptions!$B$5-Assumptions!$B$4)/Assumptions!$B$3*Assumptions!$B$10 -> 56.540652 | D27: =(SUMPRODUCT(DCF_Base!$C$19:$L$19/(1+$A$27/100)^DCF_Base!$C$4:$L$4)+MAX(0,MIN(IF($A$27>$D$23,DCF_Base!$L$19*(1+$D$23/100)/(($A$27-$D$23)/100),DCF_Base!$L$19*DCF_Base!$B$29),DCF_Base!$L$19*DCF_Base!$B$29))/(1+$A$27/100)^DCF_Base!$L$4+Assumptions!$B$5-Assumptions!$B$4)/Assumptions!$B$3*Assumptions!$B$10 -> 56.540652 | E27: =(SUMPRODUCT(DCF_Base!$C$19:$L$19/(1+$A$27/100)^DCF_Base!$C$4:$L$4)+MAX(0,MIN(IF($A$27>$E$23,DCF_Base!$L$19*(1+$E$23/100)/(($A$27-$E$23)/100),DCF_Base!$L$19*DCF_Base!$B$29),DCF_Base!$L$19*DCF_Base!$B$29))/(1+$A$27/100)^DCF_Base!$L$4+Assumptions!$B$5-Assumptions!$B$4)/Assumptions!$B$3*Assumptions!$B$10 -> 56.540652 | F27: =(SUMPRODUCT(DCF_Base!$C$19:$L$19/(1+$A$27/100)^DCF_Base!$C$4:$L$4)+MAX(0,MIN(IF($A$27>$F$23,DCF_Base!$L$19*(1+$F$23/100)/(($A$27-$F$23)/100),DCF_Base!$L$19*DCF_Base!$B$29),DCF_Base!$L$19*DCF_Base!$B$29))/(1+$A$27/100)^DCF_Base!$L$4+Assumptions!$B$5-Assumptions!$B$4)/Assumptions!$B$3*Assumptions!$B$10 -> 56.540652
A28: 9 | B28: =(SUMPRODUCT(DCF_Base!$C$19:$L$19/(1+$A$28/100)^DCF_Base!$C$4:$L$4)+MAX(0,MIN(IF($A$28>$B$23,DCF_Base!$L$19*(1+$B$23/100)/(($A$28-$B$23)/100),DCF_Base!$L$19*DCF_Base!$B$29),DCF_Base!$L$19*DCF_Base!$B$29))/(1+$A$28/100)^DCF_Base!$L$4+Assumptions!$B$5-Assumptions!$B$4)/Assumptions!$B$3*Assumptions!$B$10 -> 42.258039 | C28: =(SUMPRODUCT(DCF_Base!$C$19:$L$19/(1+$A$28/100)^DCF_Base!$C$4:$L$4)+MAX(0,MIN(IF($A$28>$C$23,DCF_Base!$L$19*(1+$C$23/100)/(($A$28-$C$23)/100),DCF_Base!$L$19*DCF_Base!$B$29),DCF_Base!$L$19*DCF_Base!$B$29))/(1+$A$28/100)^DCF_Base!$L$4+Assumptions!$B$5-Assumptions!$B$4)/Assumptions!$B$3*Assumptions!$B$10 -> 45.190079 | D28: =(SUMPRODUCT(DCF_Base!$C$19:$L$19/(1+$A$28/100)^DCF_Base!$C$4:$L$4)+MAX(0,MIN(IF($A$28>$D$23,DCF_Base!$L$19*(1+$D$23/100)/(($A$28-$D$23)/100),DCF_Base!$L$19*DCF_Base!$B$29),DCF_Base!$L$19*DCF_Base!$B$29))/(1+$A$28/100)^DCF_Base!$L$4+Assumptions!$B$5-Assumptions!$B$4)/Assumptions!$B$3*Assumptions!$B$10 -> 48.540982 | E28: =(SUMPRODUCT(DCF_Base!$C$19:$L$19/(1+$A$28/100)^DCF_Base!$C$4:$L$4)+MAX(0,MIN(IF($A$28>$E$23,DCF_Base!$L$19*(1+$E$23/100)/(($A$28-$E$23)/100),DCF_Base!$L$19*DCF_Base!$B$29),DCF_Base!$L$19*DCF_Base!$B$29))/(1+$A$28/100)^DCF_Base!$L$4+Assumptions!$B$5-Assumptions!$B$4)/Assumptions!$B$3*Assumptions!$B$10 -> 49.924383 | F28: =(SUMPRODUCT(DCF_Base!$C$19:$L$19/(1+$A$28/100)^DCF_Base!$C$4:$L$4)+MAX(0,MIN(IF($A$28>$F$23,DCF_Base!$L$19*(1+$F$23/100)/(($A$28-$F$23)/100),DCF_Base!$L$19*DCF_Base!$B$29),DCF_Base!$L$19*DCF_Base!$B$29))/(1+$A$28/100)^DCF_Base!$L$4+Assumptions!$B$5-Assumptions!$B$4)/Assumptions!$B$3*Assumptions!$B$10 -> 49.924383
