Workbook

Sheet Model_Info
A1: T&G Global (TGG.NZ) DCF model
A2: Version | B2: v1 (fresh build) -- supersedes nothing; first TGG.NZ valuation in this folder
A3: Built by | B3: dcf-analyst agent (Claude, claude-fable-5-1) on 2026-09-05 at the request of the research orchestrator
A4: Price | B4: NZ$2.40, NZX regular close 2026-09-04 (Yahoo regularMarketTime 04:42Z). Goes stale; refresh before use.
A5: Balance sheet | B5: 31-Dec-2025 audited (borrowings 194.840, cash 47.618, term deposits 1.510) is the net-debt anchor; 30-Jun-2026 unaudited interim for book value, disposal group (net assets 76.058 at FVLCS) and lease split
A6: Share count | B6: 122,543,204, unchanged since FY2016, no dilutive securities (basic = diluted EPS)
A7: Guidance | B7: None numeric. H1-2026 report: continuing revenue 572.3 (+2.6%), operating profit 11.6 (+30.3%); T&G Fresh divestment (3 SPAs 31-Jul-2026) subject to Commerce Commission; El Nino risk flagged for 2026/27 crop
A8: Model | B8: Owner-FCF DCF on CONTINUING operations (FY2025 re-presented: revenue 1,144.6, EBITDA 70.9), 10-year component build, blended 50/50 with an asset leg (parent book/share 3.66 x exit P/B disciplined by TGG's own 10-year P/B range)
A9: Why blended | B9: Pure DCF gives ~0.9/share = 0.24x book, below the 10-year minimum 0.42x: an earnings model that ignores 232m of land and buildings at valuation. Sanity-check fix per the routing table's straddle rule.
A10: Leases | B10: Treatment B: lease cash (2.9% of revenue, ~33.5m continuing) charged in flows; lease liabilities excluded from net debt; D&A is owned-asset only (1.75%)
A11: NCI | B11: Charged once, in the flows: NCI profit share folded into the combined tax + leakage rate (row 15). Book NCI not deducted.
A12: WACC | B12: 10.5% NZD-built (rf 4.4 + 5.5 ERP x 1.1 beta + 2.5pp structural premium for BayWa distress/illiquidity/weather; Kd 6% pre-tax; E/D 70/30). Same rate in all scenarios; risk charged once.
A13: Terminal | B13: max(0, min(Gordon, cap x FCF10)); cap 12x (10x bear). Entry price rebuilds TV at the 15% hurdle.
... A18: Units | B18: NZ$ millions except per-share (NZ$) and percentages

Sheet Actuals
A1: WHOLE-COMPANY history (Metrics.csv / kpis; annual reports, NZ$m). Source: TGG.NZ_Metrics.csv, kpis table
A2: Period | B2: Revenue | C2: EBITDA | D2: OperatingProfit | E2: NetIncomeTotal | F2: NetIncomeAttributable | G2: OCF | H2: Capex | I2: ReportedFCF | J2: LeasePrincipal | K2: InterestIncome | L2: TotalEquity | M2: NCI | N2: Borrowings+Leases | O2: Cash | P2: EPS_c | Q2: NTA_company
A3: FY2019 | B3: 1216.409 | C3: 54.254 | D3: 16.501 | E3: 6.611 | F3: 0.901 | G3: 51.009 | H3: -39.528 | I3: 11.481 | J3: 21.242 | K3: 0.748 | L3: 474.403 | M3: 13.697 | N3: 153.015 | O3: 36.208 | P3: 0.7 | Q3: 3.56
A4: FY2020 | B4: 1412.59 | C4: 78.255 | D4: 32.376 | E4: 16.59 | F4: 11.056 | G4: 56.281 | H4: -46.777 | I4: 9.504 | J4: 21.658 | K4: 1.334 | L4: 519.754 | M4: 13.147 | N4: 224.868 | O4: 44.664 | P4: 9 | Q4: 3.61
A5: FY2021 | B5: 1365.413 | C5: 69.532 | D5: 16.887 | E5: 13.552 | F5: 8.876 | G5: 55.36 | H5: -53.2 | I5: 2.16 | J5: 30.413 | K5: 1.234 | L5: 573.604 | M5: 13.528 | N5: 199.299 | O5: 59.005 | P5: 7.2 | Q5: 4.06
A6: FY2022 | B6: 1304.936 | C6: 78.052 | D6: 20.409 | E6: -0.861 | F6: -5.471 | G6: -0.468 | H6: -106.673 | I6: -107.141 | J6: 33.455 | K6: 2.383 | L6: 580.168 | M6: 16.917 | N6: 305.418 | O6: 58.519 | P6: -4.4 | Q6: 4.11
A7: FY2023 | B7: 1334.338 | C7: 13.05 | D7: -45.579 | E7: -46.595 | F7: -51.155 | G7: 25.563 | H7: -76.07 | I7: -50.507 | J7: 37.383 | K7: 4.09 | L7: 521.888 | M7: 17.471 | N7: 371.305 | O7: 30.508 | P7: -41.7 | Q7: 3.61
A8: FY2024 | B8: 1360.891 | C8: 71.061 | D8: 12.664 | E8: -9.888 | F8: -16.034 | G8: 60.666 | H8: -48.055 | I8: 12.611 | J8: 37.544 | K8: 5.406 | L8: 490.651 | M8: 20.511 | N8: 413.504 | O8: 46.801 | P8: -13 | Q8: 3.36
A9: FY2025 | B9: 1558.723 | C9: 110.135 | D9: 46.906 | E9: 16.047 | F9: 10.213 | G9: 91.948 | H9: -32.622 | I9: 59.326 | J9: 41.912 | K9: 2.515 | L9: 510.019 | M9: 18.119 | N9: 405.524 | O9: 47.618 | P9: 8.3 | Q9: 3.53
A11: CONTINUING operations, re-presented (H1-2026 interim report, income statement + note 3)
A12: Period | B12: Revenue | C12: OperatingProfit | D12: D&A | E12: EBITDA | F12: NPAT continuing | G12: NCI (all in continuing)
A13: FY2025 | B13: 1144.643 | C13: 28.876 | D13: 42.003 | E13: 70.879 | F13: 5.26 | G13: 5.834
A14: H1 FY2025 | B14: 557.947 | C14: 8.893 | D14: 20.017 | E14: 28.91 | F14: -3.496 | G14: 2.791
A15: H1 FY2026 | B15: 572.302 | C15: 11.642 | D15: 23.034 | E15: 34.676 | F15: -0.948 | G15: 2.45
A16: Discontinued FY2025 (note 7): revenue 414.080, operating profit 18.030, NPAT 10.787, OCF 25.916
A18: Balance sheet anchors
A19: Borrowings Dec-25 | B19: 194.84
A20: Cash Dec-25 | B20: 47.618
A21: Term deposits Dec-25 | B21: 1.51
A22: Lease liabilities Dec-25 (excluded, treatment B) | B22: 210.684
A23: Borrowings Jun-26 (seasonal peak) | B23: 307.915
A24: Cash+TD Jun-26 | B24: 72.657
A25: Disposal group net assets at FVLCS Jun-26 (expected proceeds) | B25: 76.058
A26: Ettrick property held for sale Jun-26 | B26: 8.28
A27: Parent equity Jun-26 | B27: 448.611
A28: Intangibles Jun-26 incl. disposal group | B28: 44.191
A29: NCI equity Jun-26 | B29: 18.728
A30: Investments in unlisted entities + JV Jun-26 | B30: 18.877
... A33: Share-based payment any year | B33: 0

Sheet Assumptions
A1: Global assumptions
A3: Price (NZ$) | B3: 2.4 | C3: NZX close 2026-09-04
A4: Shares (m) | B4: 122.5432 | C4: flat; no dilutive securities
A5: Net debt pro forma (NZ$m) | B5: =B13-B14 | C5: Dec-25 net debt less expected disposal proceeds; leases excluded
A6: Non-operating assets (NZ$m) | B6: 27.157 | C6: unlisted entities 16.327 + JV 2.550 + Ettrick held-for-sale property 8.280, Jun-26; none in the flows
A7: Parent book value / share (NZ$) | B7: =448.611/B4 | C7: Jun-26 attributable equity 448.611
A8: WACC (%) | B8: 10.5 | C8: NZD-built; same in all scenarios
A9: Lease cash (% revenue) | B9: 2.9 | C9: treatment B; ~33.5m continuing on 1,144.6m
A10: Owned-asset D&A (% revenue) | B10: 1.75 | C10: continuing D&A 42.0 less ~22 ROU depreciation
A11: WC capture (% of revenue change) | B11: -8 | C11: produce business: receivables + inventory + biological assets ~8% of revenue
A12: Hurdle rate | B12: 0.15 | C12: entry-price IRR; TV rebuilt at this rate
A13: Net debt Dec-2025 (NZ$m) | B13: 145.712 | C13: 194.840 - 47.618 - 1.510
A14: Expected disposal proceeds (NZ$m) | B14: 76.058 | C14: disposal group 143.904 - 67.846 at fair value less costs to sell (note 6; its 84.338 includes the Ettrick property)
A15: Revenue FY2025 continuing (NZ$m) | B15: 1144.643 | C15: H1-2026 report re-presented
A17: Scenario | B17: Terminal growth % | C17: TV cap (x FCF10) | D17: Capex % revenue | E17: Exit P/B (asset leg) | F17: Asset weight | G17: Probability
A18: bear | B18: 2 | C18: 10 | D18: 3.3 | E18: 0.45 | F18: 0.5 | G18: 0.3
A19: base | B19: 2.5 | C19: 12 | D19: 3 | E19: 0.7 | F19: 0.5 | G19: 0.5
A20: bull | B20: 3 | C20: 12 | D20: 2.8 | E20: 0.95 | F20: 0.5 | G20: 0.2
A21: Weights check | G21: =SUM(G18:G20)
A23: Narratives
A24: base | B24: Turner/Bidfood/Unearthed sales complete and 84m of proceeds cut net debt to ~70m. Apples grows 6%/yr FY27-30 as ENVY plantings mature (NZ crop +24% in 2026), JOLI launches in Vietnam and the NZ-India FTA opens a new market, then decelerates to 3%. Group EBITDA margin (post-IFRS-16) climbs from 7.0% in FY2026 to 9.0% by FY2031 as stranded corporate cost in the 'Other' segment (-45m FY2025) is cut and VentureFruit reaches breakeven; capex normalises to 3% of revenue (~35m) between the suppressed FY2025 (32.6m) and the FY2024 48m. Cash tax ramps to 28% as the 37.5m deferred tax asset is used; NCI leakage fades from 20% to 10% of EBIT. Asset leg at 0.70x book, the 10-year average.
A25: bull | B25: Apples 2035 strategy delivers: 8% growth FY27-29 on ENVY US household penetration (12% -> 15%), China/Vietnam/Thailand volume (+26/+34/+10% H1-26) and India; VentureFruit's royalty model (California Giant berries, Chinese PVR wins) turns profitable; corporate cost-out takes the group EBITDA margin to 11.5% by FY2032. BayWa's stake is sold to a strategic buyer who, under the Takeovers Code, offers all holders ~0.95x book -- the asset leg at FY2017-18 multiples.
A26: bear | B26: El Nino delivers the weather event flagged in the H1-2026 outlook: FY2027 revenue -10% and EBITDA margin 3.5% (a milder Gabrielle), recovering to a 6.5% ceiling as UK/EU oversupply and retailer buying power cap pricing; capex stays at 3.3% because replanting cannot be deferred; NCI leakage stays high because the UK distributor's profit does not fall with the NZ crop. Terminal cap 10x, terminal growth 2%. The BayWa process drags with no offer and the stock stays at its FY2023-24 trough of 0.45x book on the asset leg.

Sheet DCF_Bear
A1: BEAR scenario -- owner FCF on continuing operations (NZ$m)
A3: Year | B3: 2025A | C3: 2026E | D3: 2027E | E3: 2028E | F3: 2029E | G3: 2030E | H3: 2031E | I3: 2032E | J3: 2033E | K3: 2034E | L3: 2035E
A4: Index | B4: 0 | C4: 1 | D4: 2 | E4: 3 | F4: 4 | G4: 5 | H4: 6 | I4: 7 | J4: 8 | K4: 9 | L4: 10
A5: Revenue growth % | C5: 1 | D5: -10 | E5: 8 | F5: 4 | G5: 4 | H5: 3.5 | I5: 3 | J5: 3 | K5: 2.5 | L5: 2.5
A6: Revenue | B6: =Assumptions!$B$15 | C6: =B6*(1+C5/100) | D6: =C6*(1+D5/100) | E6: =D6*(1+E5/100) | F6: =E6*(1+F5/100) | G6: =F6*(1+G5/100) | H6: =G6*(1+H5/100) | I6: =H6*(1+I5/100) | J6: =I6*(1+J5/100) | ... L6: =K6*(1+L5/100)
A7: Adj EBITDA margin % (post-IFRS16) | C7: 6.3 | D7: 3.5 | E7: 6 | F7: 6.5 | G7: 6.5 | H7: 6.5 | I7: 6.5 | J7: 6.5 | K7: 6.5 | L7: 6.5
A8: Adjusted EBITDA | C8: =C6*C7/100 | D8: =D6*D7/100 | E8: =E6*E7/100 | F8: =F6*F7/100 | G8: =G6*G7/100 | H8: =H6*H7/100 | I8: =I6*I7/100 | J8: =J6*J7/100 | ... L8: =L6*L7/100
A9: SBC % revenue | C9: 0 | D9: 0 | E9: 0 | F9: 0 | G9: 0 | H9: 0 | I9: 0 | J9: 0 | K9: 0 | L9: 0
A10: SBC $ | C10: =-C6*C9/100 | D10: =-D6*D9/100 | E10: =-E6*E9/100 | F10: =-F6*F9/100 | G10: =-G6*G9/100 | H10: =-H6*H9/100 | I10: =-I6*I9/100 | J10: =-J6*J9/100 | ... L10: =-L6*L9/100
A11: Lease cash (treatment B) | C11: =-C6*Assumptions!$B$9/100 | D11: =-D6*Assumptions!$B$9/100 | E11: =-E6*Assumptions!$B$9/100 | F11: =-F6*Assumptions!$B$9/100 | G11: =-G6*Assumptions!$B$9/100 | H11: =-H6*Assumptions!$B$9/100 | I11: =-I6*Assumptions!$B$9/100 | J11: =-J6*Assumptions!$B$9/100 | ... L11: =-L6*Assumptions!$B$9/100
A12: Owner EBITDA (after SBC, lease cash) | C12: =C8+C10+C11 | D12: =D8+D10+D11 | E12: =E8+E10+E11 | F12: =F8+F10+F11 | G12: =G8+G10+G11 | H12: =H8+H10+H11 | I12: =I8+I10+I11 | J12: =J8+J10+J11 | ... L12: =L8+L10+L11
A13: Owned-asset D&A | C13: =-C6*Assumptions!$B$10/100 | D13: =-D6*Assumptions!$B$10/100 | E13: =-E6*Assumptions!$B$10/100 | F13: =-F6*Assumptions!$B$10/100 | G13: =-G6*Assumptions!$B$10/100 | H13: =-H6*Assumptions!$B$10/100 | I13: =-I6*Assumptions!$B$10/100 | J13: =-J6*Assumptions!$B$10/100 | ... L13: =-L6*Assumptions!$B$10/100
A14: EBIT (pre-IFRS16, pre-interest) | C14: =C12+C13 | D14: =D12+D13 | E14: =E12+E13 | F14: =F12+F13 | G14: =G12+G13 | H14: =H12+H13 | I14: =I12+I13 | J14: =J12+J13 | ... L14: =L12+L13
A15: Cash tax + NCI leakage rate % | C15: 32 | D15: 35 | E15: 36 | F15: 38 | G15: 40 | H15: 42 | I15: 42 | J15: 42 | K15: 42 | L15: 42
A16: Tax + NCI leakage | C16: =-MAX(0,C14)*C15/100 | D16: =-MAX(0,D14)*D15/100 | E16: =-MAX(0,E14)*E15/100 | F16: =-MAX(0,F14)*F15/100 | G16: =-MAX(0,G14)*G15/100 | H16: =-MAX(0,H14)*H15/100 | I16: =-MAX(0,I14)*I15/100 | J16: =-MAX(0,J14)*J15/100 | ... L16: =-MAX(0,L14)*L15/100
A17: NOPAT (attributable) | C17: =C14+C16 | D17: =D14+D16 | E17: =E14+E16 | F17: =F14+F16 | G17: =G14+G16 | H17: =H14+H16 | I17: =I14+I16 | J17: =J14+J16 | ... L17: =L14+L16
A18: add back D&A | C18: =-C13 | D18: =-D13 | E18: =-E13 | F18: =-F13 | G18: =-G13 | H18: =-H13 | I18: =-I13 | J18: =-J13 | ... L18: =-L13
A19: less capex | C19: =-C6*Assumptions!$D$18/100 | D19: =-D6*Assumptions!$D$18/100 | E19: =-E6*Assumptions!$D$18/100 | F19: =-F6*Assumptions!$D$18/100 | G19: =-G6*Assumptions!$D$18/100 | H19: =-H6*Assumptions!$D$18/100 | I19: =-I6*Assumptions!$D$18/100 | J19: =-J6*Assumptions!$D$18/100 | ... L19: =-L6*Assumptions!$D$18/100
A20: Working capital (on change) | C20: =(C6-B6)*Assumptions!$B$11/100 | D20: =(D6-C6)*Assumptions!$B$11/100 | E20: =(E6-D6)*Assumptions!$B$11/100 | F20: =(F6-E6)*Assumptions!$B$11/100 | G20: =(G6-F6)*Assumptions!$B$11/100 | H20: =(H6-G6)*Assumptions!$B$11/100 | I20: =(I6-H6)*Assumptions!$B$11/100 | J20: =(J6-I6)*Assumptions!$B$11/100 | ... L20: =(L6-K6)*Assumptions!$B$11/100
A21: Unlevered owner FCF | C21: =C17+C18+C19+C20 | D21: =D17+D18+D19+D20 | E21: =E17+E18+E19+E20 | F21: =F17+F18+F19+F20 | G21: =G17+G18+G19+G20 | H21: =H17+H18+H19+H20 | I21: =I17+I18+I19+I20 | J21: =J17+J18+J19+J20 | ... L21: =L17+L18+L19+L20
A22: Discount factor | C22: =1/(1+Assumptions!$B$8/100)^C4 | D22: =1/(1+Assumptions!$B$8/100)^D4 | E22: =1/(1+Assumptions!$B$8/100)^E4 | F22: =1/(1+Assumptions!$B$8/100)^F4 | G22: =1/(1+Assumptions!$B$8/100)^G4 | H22: =1/(1+Assumptions!$B$8/100)^H4 | I22: =1/(1+Assumptions!$B$8/100)^I4 | J22: =1/(1+Assumptions!$B$8/100)^J4 | ... L22: =1/(1+Assumptions!$B$8/100)^L4
A23: PV of FCF | C23: =C21*C22 | D23: =D21*D22 | E23: =E21*E22 | F23: =F21*F22 | G23: =G21*G22 | H23: =H21*H22 | I23: =I21*I22 | J23: =J21*J22 | ... L23: =L21*L22
A25: Memo: owner FCF margin % | C25: =C21/C6*100 | D25: =D21/D6*100 | E25: =E21/E6*100 | F25: =F21/F6*100 | G25: =G21/G6*100 | H25: =H21/H6*100 | I25: =I21/I6*100 | J25: =J21/J6*100 | ... L25: =L21/L6*100
A26: Memo: FCF before lease & SBC | C26: =C21-C10-C11 | D26: =D21-D10-D11 | E26: =E21-E10-E11 | F26: =F21-F10-F11 | G26: =G21-G10-G11 | H26: =H21-H10-H11 | I26: =I21-I10-I11 | J26: =J21-J10-J11 | ... L26: =L21-L10-L11
A28: Sum of PV (FCF) | B28: =SUM(C23:L23)
A29: Terminal growth % | B29: =Assumptions!$B$18
A30: Terminal-year FCF x (1+g) | B30: =L21*(1+B29/100)
A31: Gordon TV | B31: =IF(Assumptions!$B$8>B29,B30/((Assumptions!$B$8-B29)/100),L21*B32)
A32: Cap multiple | B32: =Assumptions!$C$18
A33: Cap TV | B33: =B32*L21
A34: TV used = MAX(0,MIN(Gordon,cap)) | B34: =MAX(0,MIN(B31,B33))
A35: Implied exit multiple | B35: =IF(L21>0,B34/L21,"n/a")
A36: PV of TV | B36: =B34*L22
A37: Enterprise value | B37: =B28+B36
A38: less net debt (pro forma) | B38: =Assumptions!$B$5
A39: add non-operating assets | B39: =Assumptions!$B$6
A40: DCF equity value | B40: =B37-B38+B39
A41: DCF value per share | B41: =B40/Assumptions!$B$4
A42: Exit P/B (asset leg) | B42: =Assumptions!$E$18
A43: Asset-leg equity = BVPS x P/B x shares | B43: =Assumptions!$B$7*B42*Assumptions!$B$4
...

Sheet DCF_Base
A1: BASE scenario -- owner FCF on continuing operations (NZ$m)
A3: Year | B3: 2025A | C3: 2026E | D3: 2027E | E3: 2028E | F3: 2029E | G3: 2030E | H3: 2031E | I3: 2032E | J3: 2033E | K3: 2034E | L3: 2035E
A4: Index | B4: 0 | C4: 1 | D4: 2 | E4: 3 | F4: 4 | G4: 5 | H4: 6 | I4: 7 | J4: 8 | K4: 9 | L4: 10
A5: Revenue growth % | C5: 3 | D5: 6 | E5: 6 | F5: 6 | G5: 5.5 | H5: 5 | I5: 4.5 | J5: 4 | K5: 3.5 | L5: 3
A6: Revenue | B6: =Assumptions!$B$15 | C6: =B6*(1+C5/100) | D6: =C6*(1+D5/100) | E6: =D6*(1+E5/100) | F6: =E6*(1+F5/100) | G6: =F6*(1+G5/100) | H6: =G6*(1+H5/100) | I6: =H6*(1+I5/100) | J6: =I6*(1+J5/100) | ... L6: =K6*(1+L5/100)
A7: Adj EBITDA margin % (post-IFRS16) | C7: 7 | D7: 7.4 | E7: 7.8 | F7: 8.2 | G7: 8.6 | H7: 9 | I7: 9 | J7: 9 | K7: 9 | L7: 9
A8: Adjusted EBITDA | C8: =C6*C7/100 | D8: =D6*D7/100 | E8: =E6*E7/100 | F8: =F6*F7/100 | G8: =G6*G7/100 | H8: =H6*H7/100 | I8: =I6*I7/100 | J8: =J6*J7/100 | ... L8: =L6*L7/100
A9: SBC % revenue | C9: 0 | D9: 0 | E9: 0 | F9: 0 | G9: 0 | H9: 0 | I9: 0 | J9: 0 | K9: 0 | L9: 0
A10: SBC $ | C10: =-C6*C9/100 | D10: =-D6*D9/100 | E10: =-E6*E9/100 | F10: =-F6*F9/100 | G10: =-G6*G9/100 | H10: =-H6*H9/100 | I10: =-I6*I9/100 | J10: =-J6*J9/100 | ... L10: =-L6*L9/100
A11: Lease cash (treatment B) | C11: =-C6*Assumptions!$B$9/100 | D11: =-D6*Assumptions!$B$9/100 | E11: =-E6*Assumptions!$B$9/100 | F11: =-F6*Assumptions!$B$9/100 | G11: =-G6*Assumptions!$B$9/100 | H11: =-H6*Assumptions!$B$9/100 | I11: =-I6*Assumptions!$B$9/100 | J11: =-J6*Assumptions!$B$9/100 | ... L11: =-L6*Assumptions!$B$9/100
A12: Owner EBITDA (after SBC, lease cash) | C12: =C8+C10+C11 | D12: =D8+D10+D11 | E12: =E8+E10+E11 | F12: =F8+F10+F11 | G12: =G8+G10+G11 | H12: =H8+H10+H11 | I12: =I8+I10+I11 | J12: =J8+J10+J11 | ... L12: =L8+L10+L11
A13: Owned-asset D&A | C13: =-C6*Assumptions!$B$10/100 | D13: =-D6*Assumptions!$B$10/100 | E13: =-E6*Assumptions!$B$10/100 | F13: =-F6*Assumptions!$B$10/100 | G13: =-G6*Assumptions!$B$10/100 | H13: =-H6*Assumptions!$B$10/100 | I13: =-I6*Assumptions!$B$10/100 | J13: =-J6*Assumptions!$B$10/100 | ... L13: =-L6*Assumptions!$B$10/100
A14: EBIT (pre-IFRS16, pre-interest) | C14: =C12+C13 | D14: =D12+D13 | E14: =E12+E13 | F14: =F12+F13 | G14: =G12+G13 | H14: =H12+H13 | I14: =I12+I13 | J14: =J12+J13 | ... L14: =L12+L13
A15: Cash tax + NCI leakage rate % | C15: 30 | D15: 31 | E15: 33 | F15: 35 | G15: 38 | H15: 39 | I15: 39 | J15: 38 | K15: 38 | L15: 38
A16: Tax + NCI leakage | C16: =-MAX(0,C14)*C15/100 | D16: =-MAX(0,D14)*D15/100 | E16: =-MAX(0,E14)*E15/100 | F16: =-MAX(0,F14)*F15/100 | G16: =-MAX(0,G14)*G15/100 | H16: =-MAX(0,H14)*H15/100 | I16: =-MAX(0,I14)*I15/100 | J16: =-MAX(0,J14)*J15/100 | ... L16: =-MAX(0,L14)*L15/100
A17: NOPAT (attributable) | C17: =C14+C16 | D17: =D14+D16 | E17: =E14+E16 | F17: =F14+F16 | G17: =G14+G16 | H17: =H14+H16 | I17: =I14+I16 | J17: =J14+J16 | ... L17: =L14+L16
A18: add back D&A | C18: =-C13 | D18: =-D13 | E18: =-E13 | F18: =-F13 | G18: =-G13 | H18: =-H13 | I18: =-I13 | J18: =-J13 | ... L18: =-L13
A19: less capex | C19: =-C6*Assumptions!$D$19/100 | D19: =-D6*Assumptions!$D$19/100 | E19: =-E6*Assumptions!$D$19/100 | F19: =-F6*Assumptions!$D$19/100 | G19: =-G6*Assumptions!$D$19/100 | H19: =-H6*Assumptions!$D$19/100 | I19: =-I6*Assumptions!$D$19/100 | J19: =-J6*Assumptions!$D$19/100 | ... L19: =-L6*Assumptions!$D$19/100
A20: Working capital (on change) | C20: =(C6-B6)*Assumptions!$B$11/100 | D20: =(D6-C6)*Assumptions!$B$11/100 | E20: =(E6-D6)*Assumptions!$B$11/100 | F20: =(F6-E6)*Assumptions!$B$11/100 | G20: =(G6-F6)*Assumptions!$B$11/100 | H20: =(H6-G6)*Assumptions!$B$11/100 | I20: =(I6-H6)*Assumptions!$B$11/100 | J20: =(J6-I6)*Assumptions!$B$11/100 | ... L20: =(L6-K6)*Assumptions!$B$11/100
A21: Unlevered owner FCF | C21: =C17+C18+C19+C20 | D21: =D17+D18+D19+D20 | E21: =E17+E18+E19+E20 | F21: =F17+F18+F19+F20 | G21: =G17+G18+G19+G20 | H21: =H17+H18+H19+H20 | I21: =I17+I18+I19+I20 | J21: =J17+J18+J19+J20 | ... L21: =L17+L18+L19+L20
A22: Discount factor | C22: =1/(1+Assumptions!$B$8/100)^C4 | D22: =1/(1+Assumptions!$B$8/100)^D4 | E22: =1/(1+Assumptions!$B$8/100)^E4 | F22: =1/(1+Assumptions!$B$8/100)^F4 | G22: =1/(1+Assumptions!$B$8/100)^G4 | H22: =1/(1+Assumptions!$B$8/100)^H4 | I22: =1/(1+Assumptions!$B$8/100)^I4 | J22: =1/(1+Assumptions!$B$8/100)^J4 | ... L22: =1/(1+Assumptions!$B$8/100)^L4
A23: PV of FCF | C23: =C21*C22 | D23: =D21*D22 | E23: =E21*E22 | F23: =F21*F22 | G23: =G21*G22 | H23: =H21*H22 | I23: =I21*I22 | J23: =J21*J22 | ... L23: =L21*L22
A25: Memo: owner FCF margin % | C25: =C21/C6*100 | D25: =D21/D6*100 | E25: =E21/E6*100 | F25: =F21/F6*100 | G25: =G21/G6*100 | H25: =H21/H6*100 | I25: =I21/I6*100 | J25: =J21/J6*100 | ... L25: =L21/L6*100
A26: Memo: FCF before lease & SBC | C26: =C21-C10-C11 | D26: =D21-D10-D11 | E26: =E21-E10-E11 | F26: =F21-F10-F11 | G26: =G21-G10-G11 | H26: =H21-H10-H11 | I26: =I21-I10-I11 | J26: =J21-J10-J11 | ... L26: =L21-L10-L11
A28: Sum of PV (FCF) | B28: =SUM(C23:L23)
A29: Terminal growth % | B29: =Assumptions!$B$19
A30: Terminal-year FCF x (1+g) | B30: =L21*(1+B29/100)
A31: Gordon TV | B31: =IF(Assumptions!$B$8>B29,B30/((Assumptions!$B$8-B29)/100),L21*B32)
A32: Cap multiple | B32: =Assumptions!$C$19
A33: Cap TV | B33: =B32*L21
A34: TV used = MAX(0,MIN(Gordon,cap)) | B34: =MAX(0,MIN(B31,B33))
A35: Implied exit multiple | B35: =IF(L21>0,B34/L21,"n/a")
A36: PV of TV | B36: =B34*L22
A37: Enterprise value | B37: =B28+B36
A38: less net debt (pro forma) | B38: =Assumptions!$B$5
A39: add non-operating assets | B39: =Assumptions!$B$6
A40: DCF equity value | B40: =B37-B38+B39
A41: DCF value per share | B41: =B40/Assumptions!$B$4
A42: Exit P/B (asset leg) | B42: =Assumptions!$E$19
A43: Asset-leg equity = BVPS x P/B x shares | B43: =Assumptions!$B$7*B42*Assumptions!$B$4
...

Sheet DCF_Bull
A1: BULL scenario -- owner FCF on continuing operations (NZ$m)
A3: Year | B3: 2025A | C3: 2026E | D3: 2027E | E3: 2028E | F3: 2029E | G3: 2030E | H3: 2031E | I3: 2032E | J3: 2033E | K3: 2034E | L3: 2035E
A4: Index | B4: 0 | C4: 1 | D4: 2 | E4: 3 | F4: 4 | G4: 5 | H4: 6 | I4: 7 | J4: 8 | K4: 9 | L4: 10
A5: Revenue growth % | C5: 4 | D5: 8 | E5: 8 | F5: 8 | G5: 7 | H5: 6 | I5: 5 | J5: 4.5 | K5: 4 | L5: 3.5
A6: Revenue | B6: =Assumptions!$B$15 | C6: =B6*(1+C5/100) | D6: =C6*(1+D5/100) | E6: =D6*(1+E5/100) | F6: =E6*(1+F5/100) | G6: =F6*(1+G5/100) | H6: =G6*(1+H5/100) | I6: =H6*(1+I5/100) | J6: =I6*(1+J5/100) | ... L6: =K6*(1+L5/100)
A7: Adj EBITDA margin % (post-IFRS16) | C7: 7.3 | D7: 8 | E7: 8.8 | F7: 9.5 | G7: 10.2 | H7: 11 | I7: 11.5 | J7: 11.5 | K7: 11.5 | L7: 11.5
A8: Adjusted EBITDA | C8: =C6*C7/100 | D8: =D6*D7/100 | E8: =E6*E7/100 | F8: =F6*F7/100 | G8: =G6*G7/100 | H8: =H6*H7/100 | I8: =I6*I7/100 | J8: =J6*J7/100 | ... L8: =L6*L7/100
A9: SBC % revenue | C9: 0 | D9: 0 | E9: 0 | F9: 0 | G9: 0 | H9: 0 | I9: 0 | J9: 0 | K9: 0 | L9: 0
A10: SBC $ | C10: =-C6*C9/100 | D10: =-D6*D9/100 | E10: =-E6*E9/100 | F10: =-F6*F9/100 | G10: =-G6*G9/100 | H10: =-H6*H9/100 | I10: =-I6*I9/100 | J10: =-J6*J9/100 | ... L10: =-L6*L9/100
A11: Lease cash (treatment B) | C11: =-C6*Assumptions!$B$9/100 | D11: =-D6*Assumptions!$B$9/100 | E11: =-E6*Assumptions!$B$9/100 | F11: =-F6*Assumptions!$B$9/100 | G11: =-G6*Assumptions!$B$9/100 | H11: =-H6*Assumptions!$B$9/100 | I11: =-I6*Assumptions!$B$9/100 | J11: =-J6*Assumptions!$B$9/100 | ... L11: =-L6*Assumptions!$B$9/100
A12: Owner EBITDA (after SBC, lease cash) | C12: =C8+C10+C11 | D12: =D8+D10+D11 | E12: =E8+E10+E11 | F12: =F8+F10+F11 | G12: =G8+G10+G11 | H12: =H8+H10+H11 | I12: =I8+I10+I11 | J12: =J8+J10+J11 | ... L12: =L8+L10+L11
A13: Owned-asset D&A | C13: =-C6*Assumptions!$B$10/100 | D13: =-D6*Assumptions!$B$10/100 | E13: =-E6*Assumptions!$B$10/100 | F13: =-F6*Assumptions!$B$10/100 | G13: =-G6*Assumptions!$B$10/100 | H13: =-H6*Assumptions!$B$10/100 | I13: =-I6*Assumptions!$B$10/100 | J13: =-J6*Assumptions!$B$10/100 | ... L13: =-L6*Assumptions!$B$10/100
A14: EBIT (pre-IFRS16, pre-interest) | C14: =C12+C13 | D14: =D12+D13 | E14: =E12+E13 | F14: =F12+F13 | G14: =G12+G13 | H14: =H12+H13 | I14: =I12+I13 | J14: =J12+J13 | ... L14: =L12+L13
A15: Cash tax + NCI leakage rate % | C15: 29 | D15: 30 | E15: 32 | F15: 34 | G15: 36 | H15: 37 | I15: 37 | J15: 36 | K15: 36 | L15: 36
A16: Tax + NCI leakage | C16: =-MAX(0,C14)*C15/100 | D16: =-MAX(0,D14)*D15/100 | E16: =-MAX(0,E14)*E15/100 | F16: =-MAX(0,F14)*F15/100 | G16: =-MAX(0,G14)*G15/100 | H16: =-MAX(0,H14)*H15/100 | I16: =-MAX(0,I14)*I15/100 | J16: =-MAX(0,J14)*J15/100 | ... L16: =-MAX(0,L14)*L15/100
A17: NOPAT (attributable) | C17: =C14+C16 | D17: =D14+D16 | E17: =E14+E16 | F17: =F14+F16 | G17: =G14+G16 | H17: =H14+H16 | I17: =I14+I16 | J17: =J14+J16 | ... L17: =L14+L16
A18: add back D&A | C18: =-C13 | D18: =-D13 | E18: =-E13 | F18: =-F13 | G18: =-G13 | H18: =-H13 | I18: =-I13 | J18: =-J13 | ... L18: =-L13
A19: less capex | C19: =-C6*Assumptions!$D$20/100 | D19: =-D6*Assumptions!$D$20/100 | E19: =-E6*Assumptions!$D$20/100 | F19: =-F6*Assumptions!$D$20/100 | G19: =-G6*Assumptions!$D$20/100 | H19: =-H6*Assumptions!$D$20/100 | I19: =-I6*Assumptions!$D$20/100 | J19: =-J6*Assumptions!$D$20/100 | ... L19: =-L6*Assumptions!$D$20/100
A20: Working capital (on change) | C20: =(C6-B6)*Assumptions!$B$11/100 | D20: =(D6-C6)*Assumptions!$B$11/100 | E20: =(E6-D6)*Assumptions!$B$11/100 | F20: =(F6-E6)*Assumptions!$B$11/100 | G20: =(G6-F6)*Assumptions!$B$11/100 | H20: =(H6-G6)*Assumptions!$B$11/100 | I20: =(I6-H6)*Assumptions!$B$11/100 | J20: =(J6-I6)*Assumptions!$B$11/100 | ... L20: =(L6-K6)*Assumptions!$B$11/100
A21: Unlevered owner FCF | C21: =C17+C18+C19+C20 | D21: =D17+D18+D19+D20 | E21: =E17+E18+E19+E20 | F21: =F17+F18+F19+F20 | G21: =G17+G18+G19+G20 | H21: =H17+H18+H19+H20 | I21: =I17+I18+I19+I20 | J21: =J17+J18+J19+J20 | ... L21: =L17+L18+L19+L20
A22: Discount factor | C22: =1/(1+Assumptions!$B$8/100)^C4 | D22: =1/(1+Assumptions!$B$8/100)^D4 | E22: =1/(1+Assumptions!$B$8/100)^E4 | F22: =1/(1+Assumptions!$B$8/100)^F4 | G22: =1/(1+Assumptions!$B$8/100)^G4 | H22: =1/(1+Assumptions!$B$8/100)^H4 | I22: =1/(1+Assumptions!$B$8/100)^I4 | J22: =1/(1+Assumptions!$B$8/100)^J4 | ... L22: =1/(1+Assumptions!$B$8/100)^L4
A23: PV of FCF | C23: =C21*C22 | D23: =D21*D22 | E23: =E21*E22 | F23: =F21*F22 | G23: =G21*G22 | H23: =H21*H22 | I23: =I21*I22 | J23: =J21*J22 | ... L23: =L21*L22
A25: Memo: owner FCF margin % | C25: =C21/C6*100 | D25: =D21/D6*100 | E25: =E21/E6*100 | F25: =F21/F6*100 | G25: =G21/G6*100 | H25: =H21/H6*100 | I25: =I21/I6*100 | J25: =J21/J6*100 | ... L25: =L21/L6*100
A26: Memo: FCF before lease & SBC | C26: =C21-C10-C11 | D26: =D21-D10-D11 | E26: =E21-E10-E11 | F26: =F21-F10-F11 | G26: =G21-G10-G11 | H26: =H21-H10-H11 | I26: =I21-I10-I11 | J26: =J21-J10-J11 | ... L26: =L21-L10-L11
A28: Sum of PV (FCF) | B28: =SUM(C23:L23)
A29: Terminal growth % | B29: =Assumptions!$B$20
A30: Terminal-year FCF x (1+g) | B30: =L21*(1+B29/100)
A31: Gordon TV | B31: =IF(Assumptions!$B$8>B29,B30/((Assumptions!$B$8-B29)/100),L21*B32)
A32: Cap multiple | B32: =Assumptions!$C$20
A33: Cap TV | B33: =B32*L21
A34: TV used = MAX(0,MIN(Gordon,cap)) | B34: =MAX(0,MIN(B31,B33))
A35: Implied exit multiple | B35: =IF(L21>0,B34/L21,"n/a")
A36: PV of TV | B36: =B34*L22
A37: Enterprise value | B37: =B28+B36
A38: less net debt (pro forma) | B38: =Assumptions!$B$5
A39: add non-operating assets | B39: =Assumptions!$B$6
A40: DCF equity value | B40: =B37-B38+B39
A41: DCF value per share | B41: =B40/Assumptions!$B$4
A42: Exit P/B (asset leg) | B42: =Assumptions!$E$20
A43: Asset-leg equity = BVPS x P/B x shares | B43: =Assumptions!$B$7*B42*Assumptions!$B$4
...

Sheet FCF_Quality
A1: Reported FCF reconciled to owner FCF (WHOLE-COMPANY history, NZ$m). Treatment B: lease principal deducted; SBC = 0; interest income shown as memo, NOT deducted (net-debt company)
A2: Period | B2: Revenue | C2: Reported FCF | D2: less SBC | E2: less lease principal | F2: Owner FCF | G2: Reported FCF margin % | H2: Owner FCF margin % | I2: Memo: interest income | J2: Memo: cash tax paid | K2: Memo: NCI dividends
A3: FY2019 | B3: 1216.409 | C3: 11.481 | D3: 0 | E3: 21.242 | F3: =C3-D3-E3 | G3: =C3/B3*100 | H3: =F3/B3*100 | I3: 0.748 | J3: 6.47 | K3: 5.667
A4: FY2020 | B4: 1412.59 | C4: 9.504 | D4: 0 | E4: 21.658 | F4: =C4-D4-E4 | G4: =C4/B4*100 | H4: =F4/B4*100 | I4: 1.334 | J4: 0.272 | K4: 12.794
A5: FY2021 | B5: 1365.413 | C5: 2.16 | D5: 0 | E5: 30.413 | F5: =C5-D5-E5 | G5: =C5/B5*100 | H5: =F5/B5*100 | I5: 1.234 | J5: 2.4 | K5: 12.202
A6: FY2022 | B6: 1304.936 | C6: -107.141 | D6: 0 | E6: 33.455 | F6: =C6-D6-E6 | G6: =C6/B6*100 | H6: =F6/B6*100 | I6: 2.383 | J6: 3 | K6: 4.991
A7: FY2023 | B7: 1334.338 | C7: -50.507 | D7: 0 | E7: 37.383 | F7: =C7-D7-E7 | G7: =C7/B7*100 | H7: =F7/B7*100 | I7: 4.09 | J7: 0.06 | K7: 5.668
A8: FY2024 | B8: 1360.891 | C8: 12.611 | D8: 0 | E8: 37.544 | F8: =C8-D8-E8 | G8: =C8/B8*100 | H8: =F8/B8*100 | I8: 5.406 | J8: 0.44 | K8: 5.379
A9: FY2025 | B9: 1558.723 | C9: 59.326 | D9: 0 | E9: 41.912 | F9: =C9-D9-E9 | G9: =C9/B9*100 | H9: =F9/B9*100 | I9: 2.515 | J9: 1.558 | K9: 7.135
A11: FY2025 CONTINUING owner FCF (model base, inputs.last_fcf): continuing OCF 66.0 (91.948 group - 25.916 discontinued) - continuing capex ~30 - continuing lease cash ~33.5 = ~2.5
A12: FY2025 group reported FCF 59.3 is a PEAK: capex 32.6 vs 48-107 in FY2021-24, plus a 6.9 debtor release; not a base.

Sheet Valuation
A1: Valuation summary (NZ$ per share)
A2: Scenario | B2: DCF-only value | C2: Asset-leg value | D2: Blended value | E2: Upside vs price | F2: Probability | G2: Street value | H2: Entry price (15%)
A3: bear | B3: =DCF_Bear!$B$41 | C3: =DCF_Bear!$B$44 | D3: =DCF_Bear!$B$47 | E3: =DCF_Bear!$B$47/Assumptions!$B$3-1 | F3: =Assumptions!$G$18 | G3: =DCF_Bear!$B$53 | H3: =DCF_Bear!$B$60
A4: base | B4: =DCF_Base!$B$41 | C4: =DCF_Base!$B$44 | D4: =DCF_Base!$B$47 | E4: =DCF_Base!$B$47/Assumptions!$B$3-1 | F4: =Assumptions!$G$19 | G4: =DCF_Base!$B$53 | H4: =DCF_Base!$B$60
A5: bull | B5: =DCF_Bull!$B$41 | C5: =DCF_Bull!$B$44 | D5: =DCF_Bull!$B$47 | E5: =DCF_Bull!$B$47/Assumptions!$B$3-1 | F5: =Assumptions!$G$20 | G5: =DCF_Bull!$B$53 | H5: =DCF_Bull!$B$60
A7: Probability-weighted value | D7: =SUMPRODUCT(D3:D5,F3:F5)
A8: Margin of safety | D8: =1-Assumptions!$B$3/D7
A9: Weighted DCF-only | D9: =SUMPRODUCT(B3:B5,F3:F5)
A10: Weighted asset-leg | D10: =SUMPRODUCT(C3:C5,F3:F5)
A11: Weighted street value | D11: =SUMPRODUCT(G3:G5,F3:F5)
A12: Band position | D12: n/a -- SBC-zero filer, house = street
A13: Weighted entry price (buy-below) | D13: =SUMPRODUCT(H3:H5,F3:F5)
A16: Required-return table (base): value per share at r, TV rebuilt at r
A17: r | B17: Value / share
A18: 0.09 | B18: =(SUMPRODUCT(DCF_Base!$C$21:$L$21/(1+$A$18)^DCF_Base!$C$4:$L$4)+MAX(0,MIN(IF($A$18>DCF_Base!$B$29/100,DCF_Base!$L$21*(1+DCF_Base!$B$29/100)/($A$18-DCF_Base!$B$29/100),DCF_Base!$L$21*DCF_Base!$B$32),DCF_Base!$B$32*DCF_Base!$L$21))/(1+$A$18)^10+DCF_Base!$B$59-Assumptions!$B$5)/Assumptions!$B$4
A19: 0.1 | B19: =(SUMPRODUCT(DCF_Base!$C$21:$L$21/(1+$A$19)^DCF_Base!$C$4:$L$4)+MAX(0,MIN(IF($A$19>DCF_Base!$B$29/100,DCF_Base!$L$21*(1+DCF_Base!$B$29/100)/($A$19-DCF_Base!$B$29/100),DCF_Base!$L$21*DCF_Base!$B$32),DCF_Base!$B$32*DCF_Base!$L$21))/(1+$A$19)^10+DCF_Base!$B$59-Assumptions!$B$5)/Assumptions!$B$4
A20: 0.105 | B20: =(SUMPRODUCT(DCF_Base!$C$21:$L$21/(1+$A$20)^DCF_Base!$C$4:$L$4)+MAX(0,MIN(IF($A$20>DCF_Base!$B$29/100,DCF_Base!$L$21*(1+DCF_Base!$B$29/100)/($A$20-DCF_Base!$B$29/100),DCF_Base!$L$21*DCF_Base!$B$32),DCF_Base!$B$32*DCF_Base!$L$21))/(1+$A$20)^10+DCF_Base!$B$59-Assumptions!$B$5)/Assumptions!$B$4 | C20: house WACC row: must equal DCF_Base!B47
A21: 0.11 | B21: =(SUMPRODUCT(DCF_Base!$C$21:$L$21/(1+$A$21)^DCF_Base!$C$4:$L$4)+MAX(0,MIN(IF($A$21>DCF_Base!$B$29/100,DCF_Base!$L$21*(1+DCF_Base!$B$29/100)/($A$21-DCF_Base!$B$29/100),DCF_Base!$L$21*DCF_Base!$B$32),DCF_Base!$B$32*DCF_Base!$L$21))/(1+$A$21)^10+DCF_Base!$B$59-Assumptions!$B$5)/Assumptions!$B$4
A22: 0.12 | B22: =(SUMPRODUCT(DCF_Base!$C$21:$L$21/(1+$A$22)^DCF_Base!$C$4:$L$4)+MAX(0,MIN(IF($A$22>DCF_Base!$B$29/100,DCF_Base!$L$21*(1+DCF_Base!$B$29/100)/($A$22-DCF_Base!$B$29/100),DCF_Base!$L$21*DCF_Base!$B$32),DCF_Base!$B$32*DCF_Base!$L$21))/(1+$A$22)^10+DCF_Base!$B$59-Assumptions!$B$5)/Assumptions!$B$4
A23: 0.15 | B23: =(SUMPRODUCT(DCF_Base!$C$21:$L$21/(1+$A$23)^DCF_Base!$C$4:$L$4)+MAX(0,MIN(IF($A$23>DCF_Base!$B$29/100,DCF_Base!$L$21*(1+DCF_Base!$B$29/100)/($A$23-DCF_Base!$B$29/100),DCF_Base!$L$21*DCF_Base!$B$32),DCF_Base!$B$32*DCF_Base!$L$21))/(1+$A$23)^10+DCF_Base!$B$59-Assumptions!$B$5)/Assumptions!$B$4 | C23: hurdle row: must equal DCF_Base!B60
A26: Sensitivity (base): WACC (rows) x terminal growth % (columns), blended value per share
B27: 1.5 | C27: 2 | D27: 2.5 | E27: 3 | F27: 3.5
A28: 0.085 | B28: =(SUMPRODUCT(DCF_Base!$C$21:$L$21/(1+$A28)^DCF_Base!$C$4:$L$4)+MAX(0,MIN(IF($A28>B$27/100,DCF_Base!$L$21*(1+B$27/100)/($A28-B$27/100),DCF_Base!$L$21*DCF_Base!$B$32),DCF_Base!$B$32*DCF_Base!$L$21))/(1+$A28)^10+DCF_Base!$B$59-Assumptions!$B$5)/Assumptions!$B$4 | C28: =(SUMPRODUCT(DCF_Base!$C$21:$L$21/(1+$A28)^DCF_Base!$C$4:$L$4)+MAX(0,MIN(IF($A28>C$27/100,DCF_Base!$L$21*(1+C$27/100)/($A28-C$27/100),DCF_Base!$L$21*DCF_Base!$B$32),DCF_Base!$B$32*DCF_Base!$L$21))/(1+$A28)^10+DCF_Base!$B$59-Assumptions!$B$5)/Assumptions!$B$4 | D28: =(SUMPRODUCT(DCF_Base!$C$21:$L$21/(1+$A28)^DCF_Base!$C$4:$L$4)+MAX(0,MIN(IF($A28>D$27/100,DCF_Base!$L$21*(1+D$27/100)/($A28-D$27/100),DCF_Base!$L$21*DCF_Base!$B$32),DCF_Base!$B$32*DCF_Base!$L$21))/(1+$A28)^10+DCF_Base!$B$59-Assumptions!$B$5)/Assumptions!$B$4 | E28: =(SUMPRODUCT(DCF_Base!$C$21:$L$21/(1+$A28)^DCF_Base!$C$4:$L$4)+MAX(0,MIN(IF($A28>E$27/100,DCF_Base!$L$21*(1+E$27/100)/($A28-E$27/100),DCF_Base!$L$21*DCF_Base!$B$32),DCF_Base!$B$32*DCF_Base!$L$21))/(1+$A28)^10+DCF_Base!$B$59-Assumptions!$B$5)/Assumptions!$B$4 | F28: =(SUMPRODUCT(DCF_Base!$C$21:$L$21/(1+$A28)^DCF_Base!$C$4:$L$4)+MAX(0,MIN(IF($A28>F$27/100,DCF_Base!$L$21*(1+F$27/100)/($A28-F$27/100),DCF_Base!$L$21*DCF_Base!$B$32),DCF_Base!$B$32*DCF_Base!$L$21))/(1+$A28)^10+DCF_Base!$B$59-Assumptions!$B$5)/Assumptions!$B$4
A29: 0.095 | B29: =(SUMPRODUCT(DCF_Base!$C$21:$L$21/(1+$A29)^DCF_Base!$C$4:$L$4)+MAX(0,MIN(IF($A29>B$27/100,DCF_Base!$L$21*(1+B$27/100)/($A29-B$27/100),DCF_Base!$L$21*DCF_Base!$B$32),DCF_Base!$B$32*DCF_Base!$L$21))/(1+$A29)^10+DCF_Base!$B$59-Assumptions!$B$5)/Assumptions!$B$4 | C29: =(SUMPRODUCT(DCF_Base!$C$21:$L$21/(1+$A29)^DCF_Base!$C$4:$L$4)+MAX(0,MIN(IF($A29>C$27/100,DCF_Base!$L$21*(1+C$27/100)/($A29-C$27/100),DCF_Base!$L$21*DCF_Base!$B$32),DCF_Base!$B$32*DCF_Base!$L$21))/(1+$A29)^10+DCF_Base!$B$59-Assumptions!$B$5)/Assumptions!$B$4 | D29: =(SUMPRODUCT(DCF_Base!$C$21:$L$21/(1+$A29)^DCF_Base!$C$4:$L$4)+MAX(0,MIN(IF($A29>D$27/100,DCF_Base!$L$21*(1+D$27/100)/($A29-D$27/100),DCF_Base!$L$21*DCF_Base!$B$32),DCF_Base!$B$32*DCF_Base!$L$21))/(1+$A29)^10+DCF_Base!$B$59-Assumptions!$B$5)/Assumptions!$B$4 | E29: =(SUMPRODUCT(DCF_Base!$C$21:$L$21/(1+$A29)^DCF_Base!$C$4:$L$4)+MAX(0,MIN(IF($A29>E$27/100,DCF_Base!$L$21*(1+E$27/100)/($A29-E$27/100),DCF_Base!$L$21*DCF_Base!$B$32),DCF_Base!$B$32*DCF_Base!$L$21))/(1+$A29)^10+DCF_Base!$B$59-Assumptions!$B$5)/Assumptions!$B$4 | F29: =(SUMPRODUCT(DCF_Base!$C$21:$L$21/(1+$A29)^DCF_Base!$C$4:$L$4)+MAX(0,MIN(IF($A29>F$27/100,DCF_Base!$L$21*(1+F$27/100)/($A29-F$27/100),DCF_Base!$L$21*DCF_Base!$B$32),DCF_Base!$B$32*DCF_Base!$L$21))/(1+$A29)^10+DCF_Base!$B$59-Assumptions!$B$5)/Assumptions!$B$4
A30: 0.105 | B30: =(SUMPRODUCT(DCF_Base!$C$21:$L$21/(1+$A30)^DCF_Base!$C$4:$L$4)+MAX(0,MIN(IF($A30>B$27/100,DCF_Base!$L$21*(1+B$27/100)/($A30-B$27/100),DCF_Base!$L$21*DCF_Base!$B$32),DCF_Base!$B$32*DCF_Base!$L$21))/(1+$A30)^10+DCF_Base!$B$59-Assumptions!$B$5)/Assumptions!$B$4 | C30: =(SUMPRODUCT(DCF_Base!$C$21:$L$21/(1+$A30)^DCF_Base!$C$4:$L$4)+MAX(0,MIN(IF($A30>C$27/100,DCF_Base!$L$21*(1+C$27/100)/($A30-C$27/100),DCF_Base!$L$21*DCF_Base!$B$32),DCF_Base!$B$32*DCF_Base!$L$21))/(1+$A30)^10+DCF_Base!$B$59-Assumptions!$B$5)/Assumptions!$B$4 | D30: =(SUMPRODUCT(DCF_Base!$C$21:$L$21/(1+$A30)^DCF_Base!$C$4:$L$4)+MAX(0,MIN(IF($A30>D$27/100,DCF_Base!$L$21*(1+D$27/100)/($A30-D$27/100),DCF_Base!$L$21*DCF_Base!$B$32),DCF_Base!$B$32*DCF_Base!$L$21))/(1+$A30)^10+DCF_Base!$B$59-Assumptions!$B$5)/Assumptions!$B$4 | E30: =(SUMPRODUCT(DCF_Base!$C$21:$L$21/(1+$A30)^DCF_Base!$C$4:$L$4)+MAX(0,MIN(IF($A30>E$27/100,DCF_Base!$L$21*(1+E$27/100)/($A30-E$27/100),DCF_Base!$L$21*DCF_Base!$B$32),DCF_Base!$B$32*DCF_Base!$L$21))/(1+$A30)^10+DCF_Base!$B$59-Assumptions!$B$5)/Assumptions!$B$4 | F30: =(SUMPRODUCT(DCF_Base!$C$21:$L$21/(1+$A30)^DCF_Base!$C$4:$L$4)+MAX(0,MIN(IF($A30>F$27/100,DCF_Base!$L$21*(1+F$27/100)/($A30-F$27/100),DCF_Base!$L$21*DCF_Base!$B$32),DCF_Base!$B$32*DCF_Base!$L$21))/(1+$A30)^10+DCF_Base!$B$59-Assumptions!$B$5)/Assumptions!$B$4
A31: 0.115 | B31: =(SUMPRODUCT(DCF_Base!$C$21:$L$21/(1+$A31)^DCF_Base!$C$4:$L$4)+MAX(0,MIN(IF($A31>B$27/100,DCF_Base!$L$21*(1+B$27/100)/($A31-B$27/100),DCF_Base!$L$21*DCF_Base!$B$32),DCF_Base!$B$32*DCF_Base!$L$21))/(1+$A31)^10+DCF_Base!$B$59-Assumptions!$B$5)/Assumptions!$B$4 | C31: =(SUMPRODUCT(DCF_Base!$C$21:$L$21/(1+$A31)^DCF_Base!$C$4:$L$4)+MAX(0,MIN(IF($A31>C$27/100,DCF_Base!$L$21*(1+C$27/100)/($A31-C$27/100),DCF_Base!$L$21*DCF_Base!$B$32),DCF_Base!$B$32*DCF_Base!$L$21))/(1+$A31)^10+DCF_Base!$B$59-Assumptions!$B$5)/Assumptions!$B$4 | D31: =(SUMPRODUCT(DCF_Base!$C$21:$L$21/(1+$A31)^DCF_Base!$C$4:$L$4)+MAX(0,MIN(IF($A31>D$27/100,DCF_Base!$L$21*(1+D$27/100)/($A31-D$27/100),DCF_Base!$L$21*DCF_Base!$B$32),DCF_Base!$B$32*DCF_Base!$L$21))/(1+$A31)^10+DCF_Base!$B$59-Assumptions!$B$5)/Assumptions!$B$4 | E31: =(SUMPRODUCT(DCF_Base!$C$21:$L$21/(1+$A31)^DCF_Base!$C$4:$L$4)+MAX(0,MIN(IF($A31>E$27/100,DCF_Base!$L$21*(1+E$27/100)/($A31-E$27/100),DCF_Base!$L$21*DCF_Base!$B$32),DCF_Base!$B$32*DCF_Base!$L$21))/(1+$A31)^10+DCF_Base!$B$59-Assumptions!$B$5)/Assumptions!$B$4 | F31: =(SUMPRODUCT(DCF_Base!$C$21:$L$21/(1+$A31)^DCF_Base!$C$4:$L$4)+MAX(0,MIN(IF($A31>F$27/100,DCF_Base!$L$21*(1+F$27/100)/($A31-F$27/100),DCF_Base!$L$21*DCF_Base!$B$32),DCF_Base!$B$32*DCF_Base!$L$21))/(1+$A31)^10+DCF_Base!$B$59-Assumptions!$B$5)/Assumptions!$B$4
A32: 0.125 | B32: =(SUMPRODUCT(DCF_Base!$C$21:$L$21/(1+$A32)^DCF_Base!$C$4:$L$4)+MAX(0,MIN(IF($A32>B$27/100,DCF_Base!$L$21*(1+B$27/100)/($A32-B$27/100),DCF_Base!$L$21*DCF_Base!$B$32),DCF_Base!$B$32*DCF_Base!$L$21))/(1+$A32)^10+DCF_Base!$B$59-Assumptions!$B$5)/Assumptions!$B$4 | C32: =(SUMPRODUCT(DCF_Base!$C$21:$L$21/(1+$A32)^DCF_Base!$C$4:$L$4)+MAX(0,MIN(IF($A32>C$27/100,DCF_Base!$L$21*(1+C$27/100)/($A32-C$27/100),DCF_Base!$L$21*DCF_Base!$B$32),DCF_Base!$B$32*DCF_Base!$L$21))/(1+$A32)^10+DCF_Base!$B$59-Assumptions!$B$5)/Assumptions!$B$4 | D32: =(SUMPRODUCT(DCF_Base!$C$21:$L$21/(1+$A32)^DCF_Base!$C$4:$L$4)+MAX(0,MIN(IF($A32>D$27/100,DCF_Base!$L$21*(1+D$27/100)/($A32-D$27/100),DCF_Base!$L$21*DCF_Base!$B$32),DCF_Base!$B$32*DCF_Base!$L$21))/(1+$A32)^10+DCF_Base!$B$59-Assumptions!$B$5)/Assumptions!$B$4 | E32: =(SUMPRODUCT(DCF_Base!$C$21:$L$21/(1+$A32)^DCF_Base!$C$4:$L$4)+MAX(0,MIN(IF($A32>E$27/100,DCF_Base!$L$21*(1+E$27/100)/($A32-E$27/100),DCF_Base!$L$21*DCF_Base!$B$32),DCF_Base!$B$32*DCF_Base!$L$21))/(1+$A32)^10+DCF_Base!$B$59-Assumptions!$B$5)/Assumptions!$B$4 | F32: =(SUMPRODUCT(DCF_Base!$C$21:$L$21/(1+$A32)^DCF_Base!$C$4:$L$4)+MAX(0,MIN(IF($A32>F$27/100,DCF_Base!$L$21*(1+F$27/100)/($A32-F$27/100),DCF_Base!$L$21*DCF_Base!$B$32),DCF_Base!$B$32*DCF_Base!$L$21))/(1+$A32)^10+DCF_Base!$B$59-Assumptions!$B$5)/Assumptions!$B$4
A34: Note: with the 12x cap binding, low-WACC rows are flat across terminal growth -- that is the cap doing its job.
