Workbook

Sheet Model_Info
A1: NetEase (9999.HK / NTES) -- Owner-FCF DCF workbook
A2: Version | B2: 2026-08-29 full rebuild. Supersedes the 2026-06-25 model.
A3: Built by | B3: dcf-analyst agent (Claude Opus 5), at the user's request, 2026-08-29.
A4: What changed vs prior | B4: Net cash corrected from RMB39,859.7m (narrow cash only) to RMB167,496.0m stated / RMB150,089.1m after haircut -- the prior file omitted time deposits and short-term investments, understating net cash by ~RMB128bn (~HK$43/share). SBC now explicitly modelled (prior file omitted inputs.sbc). Horizon extended 5 -> 10 years. Single WACC across scenarios (prior used 10/11/13%, charging risk three times). Component margin build replaces a flat 43% FCF margin.
A5: PRICE anchor | B5: HK$192.20, 9999.HK HKEX regular close 2026-08-28 (regularMarketTime 2026-08-28T08:08:31Z). NTES ADS US$122.76, 2026-08-28T20:00:00Z close. Both regular-session, not after-hours.
A6: BALANCE SHEET anchor | B6: 2026-06-30 (Q2-2026 6-K). Net cash reconciles: cash 22,814.5 + time deposits 101,978.6 + restricted 4,447.5 + short-term investments 50,599.6 + non-current TD 260.0 - short-term loans 12,604.2 = 167,496.0.
A7: SHARE COUNT anchor | B7: 3,221.6m fully diluted ordinary, Q2-2026 6-K. NOT 3,210.6m, which is the H1-2025 six-month average (the 6-K share row has seven columns).
A8: GUIDANCE anchor | B8: Q2-2026 results 2026-08-20: FY2026 revenue mid-to-high single-digit growth; gaming gross margin mid-to-high 70s; effective tax rate elevated vs prior year (H1-2026 21.7% vs 15.0%).
A9: METHOD | B9: Owner-FCF DCF, three scenarios, probability-weighted. Routed via .claude/skills/dcf-methods/SKILL.md -- asset-light cash-generative operating company.
A10: Owner FCF definition | B10: reported FCF less SBC less net interest income. SBC expensed in the flows AND share count held FLAT -- charged exactly once, never both expensed and diluted.
A11: Why interest income is stripped | B11: Net cash is ~3.5x the owner-FCF base and is added separately in the bridge; leaving its income in the flows would count the treasury twice.
A12: NET CASH HAIRCUT (judgement) | B12: 10.4% total: restricted cash excluded entirely; short-term investments at 90% for mark-to-market risk (the Q2-2026 earnings drop was caused by exactly this book); 5% repatriation friction for PRC withholding tax on onshore dividends. Flex cell is on Assumptions.
A13: TAX | B13: Ramped to 24% base, NOT reverted to the 14-15% of prior years -- the H1-2026 step-up to 21.7% is treated as structural (expiring preferential software/HNTE rates).
... A21: Currency | B21: Modelled in RMB millions. Headline value in HKD at RMB:HKD 1.08 (HKD is the quote currency of the primary listing). USD per ADS at RMB:USD 7.20, 1 ADS = 5 ordinary.

Sheet Actuals
A1: Reported history -- all hardcoded, RMB millions
A3: FY | B3: 2019 | C3: 2020 | D3: 2021 | E3: 2022 | F3: 2023 | G3: 2024 | H3: 2025 | I3: TTM Q2-26
A4: Revenue | B4: 60925.1 | C4: 73631.2 | D4: 87987.6 | E4: 99423 | F4: 103437.7 | G4: 105377.6 | H4: 112625.8 | I4: 116582.5
A5: Operating cash flow | B5: 17216.5 | C5: 24888.2 | D5: 24926.7 | E5: 27709.2 | F5: 35331.3 | G5: 39676.8 | H5: 50739.8
A6: Capex | B6: 1209.5 | C6: 1055.6 | D6: 1601.8 | E6: 2100.3 | F6: 2301.6 | G6: 1275.4 | H6: 1065.4
A7: Reported FCF | B7: 16007 | C7: 23832.6 | D7: 23324.9 | E7: 25609 | F7: 33029.7 | G7: 38401.4 | H7: 49674.4 | I7: 50036.6
A8: less SBC | B8: 2404.1 | C8: 2663.5 | D8: 3041.5 | E8: 3174.2 | F8: 3242.8 | G8: 3882.9 | H8: 3647.7 | I8: 3199.2
A9: less net interest income | B9: 821.8 | C9: 1598.6 | D9: 1519.7 | E9: 2149.7 | F9: 4120.4 | G9: 4920.9 | H9: 3953.5 | I9: 3953.5
A10: Owner FCF | B10: 12781.1 | C10: 19570.5 | D10: 18763.7 | E10: 20285.1 | F10: 25666.5 | G10: 29597.6 | H10: 42073.3 | I10: 42883.9
A11: Net income attributable | B11: 10989.9 | C11: 12062.8 | D11: 16856.8 | E11: 20337.6 | F11: 29416.6 | G11: 29697.6 | H11: 33759.8 | I11: 32570.3
A12: Shareholders equity | B12: 102388.2 | C12: 118044.8 | D12: 128766.8 | E12: 120571.4 | F12: 124285.8 | G12: 138685.6 | H12: 160296.1 | I12: 167090.5
A13: Diluted ord shares (m) | C13: 3349.8 | D13: 3367.5 | E13: 3296 | F13: 3252 | G13: 3230.6 | H13: 3218.2 | I13: 3221.6
A14: EPS diluted RMB/ord | C14: 3.6 | D14: 5.01 | E14: 6.17 | F14: 9.05 | G14: 9.19 | H14: 10.48
A16: Source: FY2021/FY2023/FY2025 20-F (SBC line 733/765/788; interest income net line 598/608/625; OCF and capex from the cash flow statement). TTM = FY2025 + H1-2026 - H1-2025.
A18: FY2025 FCF QUALITY WARNING
A19: FY2025 OCF included an RMB8,400m working-capital inflow (contract liabilities +5,400, payables +1,900, taxes payable +1,100).
A20: That is 16.9% of reported FCF and ~116% of the FY2025 revenue increase -- NOT repeatable. It is why the forward model uses a 35% WC capture rate.
A22: Balance sheet at 2026-06-30 (RMB m)
A23: Cash and equivalents | B23: 22814.5
A24: Time deposits (current) | B24: 101978.6
A25: Restricted cash | B25: 4447.5
A26: Short-term investments | B26: 50599.6
A27: Time deposits (non-current) | B27: 260
A28: Short-term loans | B28: -12604.2
A29: Net cash, company stated | B29: 167496
A31: Buyback status
A32: FY2025 financing outflow RMB20,159.8m; ~24.8m ADSs repurchased under the US$5.0bn authorization extended to January 2029.
A33: Share count has actually FALLEN 3,349.8m (FY2020) -> 3,218.2m (FY2025), so the flat-count assumption is funded, not aspirational.
A34: Dividend: US$0.096/ordinary share (US$0.48/ADS) declared for Q2-2026.

Sheet Assumptions
A1: Global assumptions
A2: Base revenue TTM (RMB m) | B2: 116582.5 | C2: TTM = FY2025 + H1-2026 - H1-2025
A3: Diluted ordinary shares (m) | B3: 3221.6 | C3: Q2-2026 6-K; held FLAT because SBC is expensed
A4: Net cash STATED (RMB m) | B4: 167496 | C4: Company-stated at 2026-06-30; reconciles from the balance sheet
A5: Restricted cash EXCLUDED (RMB m) | B5: 4447.5 | C5: Not available to shareholders
A6: ST investments haircut | B6: 0.1 | C6: Mark-to-market risk; this book caused the Q2-2026 earnings drop
A7: ST investments balance (RMB m) | B7: 50599.6 | C7: Balance the haircut applies to
A8: Repatriation friction | B8: 0.05 | C8: PRC withholding tax on onshore dividends, partial-repatriation basis
A9: Net cash USED (RMB m) | B9: =(B4-B5-B7*B6)*(1-B8) | C9: Stated 167,496.0 less restricted 4,447.5 less 10% of ST investments (5,060.0), then times (1-5%) repatriation friction = 150,089.1
A10: Net debt for bridge (RMB m) | B10: =-B9 | C10: negative of net cash used
A11: WACC (all scenarios) | B11: 0.105 | C11: RMB-built. Risk charged once, in the flows
A12: Terminal cap multiple | B12: 18 | C12: 18x not 20x, for the China regulatory discount
A13: Price HK$ (2026-08-28 close) | B13: 192.2 | C13: regularMarketTime 2026-08-28T08:08:31Z
A14: RMB:HKD | B14: 1.08 | C14: Headline value reported in HKD, the quote currency
A15: RMB:USD | B15: 7.2 | C15: For the NTES ADS cross-check, 1 ADS = 5 ordinary
A17: Per-scenario drivers: terminal growth, weight, D&A %, capex %, WC capture %
A18: Scenario | B18: Terminal growth | C18: Weight | D18: D&A % rev | E18: Capex % rev | F18: WC capture %
A19: Bear | B19: 0.015 | C19: 0.25 | D19: 0.017 | E19: 0.012 | F19: 0.1
A20: Base | B20: 0.025 | C20: 0.5 | D20: 0.016 | E20: 0.01 | F20: 0.35
A21: Bull | B21: 0.03 | C21: 0.25 | D21: 0.016 | E21: 0.01 | F21: 0.45
A22: Weights check | C22: =SUM(C19:C21) | D22: =IF(ABS(C22-1)<0.0001,"OK sums to 100%","ERROR")
A24: Scenario narratives
A25: BEAR | B25: Bear case names the actual downside axes, not generic weakness: a December-2023-style regulatory reversal (that draft rule cut the stock 28% in a single session) or a China consumer-spending slump stalls domestic gaming; Marvel Rivals churns out against Overwatch 2 / Valorant as hero-shooters historically do; Sea of Remnants' rocky China launch (criticised learning curve) proves representative of the wider simultaneous pipeline; and the AI investment gap versus Tencent (~RMB85.8bn 2025 R&D) and miHoYo (RMB100bn over three years) erodes NetEase's relative development velocity. Revenue goes flat-to-slightly-negative from Y3, and critically the platform revenue-sharing margin gain REVERSES: adjusted EBITDA margin falls 39.0% -> 33.0%, back toward the FY2022-23 level. SBC rises as a share of a shrinking revenue base (3.0% -> 4.0%) because retention grants do not shrink with revenue. Tax stays at 25% statutory.
A26: BASE | B26: Base case follows management's own framing: mid-to-high single-digit revenue growth (H1-2026 actual +7.0%), decelerating to 3% by Y10 as the China gaming market matures and the international titles move from launch surge to steady live-service. Adjusted EBITDA margin starts at the TTM 41.0% and drifts DOWN to 40.0% -- the Q2-2026 gaming gross margin of 76.1% (from 70.2%) is a genuine structural gain from lower platform revenue-sharing, but assuming it compounds further would be extrapolating a one-time channel-mix shift. Cash tax ramps 22.0% -> 24.0%: the H1-2026 effective rate of 21.7% (vs 15.0% in H1-2025) is treated as STRUCTURAL, reflecting expiring preferential software/HNTE rates, not a timing blip. Working-capital capture cut to 35% of the revenue increase, far below the ~116% of the FY2025 revenue delta that the contract-liability/payables/tax-payable inflow actually represented -- that RMB8.4bn inflow was 16.9% of reported FCF and is not repeatable at that rate.
A27: BULL | B27: Bull case: Where Winds Meet (100m+ cumulative players, Xbox/Game Pass since June 2026) and Marvel Rivals (#2 on Steam globally) both convert into durable multi-year evergreen franchises, and the Ananta / Blood Message / Sea of Remnants pipeline lands at least one further global hit, holding revenue growth at 8-10% for five years. The platform revenue-sharing benefit proves to be a permanent step-change, letting adjusted EBITDA margin RISE from 42.0% to 43.5% as international self-published mix grows. Tax settles at 22% as preferential rates are partly renewed. NPPA approvals continue running ~19% ahead of prior year, removing the licensing bottleneck.
A29: Net cash haircut rationale | B29: Restricted cash RMB4,447.5m excluded entirely (not available to shareholders). Short-term investments RMB50,599.6m taken at 90% for mark-to-market risk -- the Q2-2026 net income fall to RMB7.0bn from RMB10.7bn was caused by declines in the fair value of equity securities and impairments in exactly this book. Then a 5% repatriation friction on the remainder for the 10% PRC withholding tax on onshore dividends under a partial-repatriation assumption. Total 10.4%. Set B5 to 0 to value on the full stated figure (worth about HK$5.83/share).

Sheet DCF_Bear
A1: BEAR scenario -- owner-FCF DCF, RMB millions
A3: Year | B3: 2025A | C3: 2026E | D3: 2027E | E3: 2028E | F3: 2029E | G3: 2030E | H3: 2031E | I3: 2032E | J3: 2033E | K3: 2034E | L3: 2035E
A4: Index | B4: 0 | C4: 1 | D4: 2 | E4: 3 | F4: 4 | G4: 5 | H4: 6 | I4: 7 | J4: 8 | K4: 9 | L4: 10
A5: Revenue growth % | C5: 0.03 | D5: 0.015 | E5: 0.005 | F5: 0 | G5: -0.01 | H5: -0.01 | I5: -0.005 | J5: 0 | K5: 0.005 | L5: 0.01
A6: Revenue | B6: 116582.5 | C6: =B6*(1+C5) | D6: =C6*(1+D5) | E6: =D6*(1+E5) | F6: =E6*(1+F5) | G6: =F6*(1+G5) | H6: =G6*(1+H5) | I6: =H6*(1+I5) | J6: =I6*(1+J5) | ... L6: =K6*(1+L5)
A7: Adj EBITDA margin % (pre-SBC) | C7: 0.39 | D7: 0.3833 | E7: 0.3767 | F7: 0.37 | G7: 0.3633 | H7: 0.3567 | I7: 0.35 | J7: 0.3433 | K7: 0.3367 | L7: 0.33
A8: Adjusted EBITDA | C8: =C6*C7 | D8: =D6*D7 | E8: =E6*E7 | F8: =F6*F7 | G8: =G6*G7 | H8: =H6*H7 | I8: =I6*I7 | J8: =J6*J7 | ... L8: =L6*L7
A9: SBC % of revenue | C9: 0.03 | D9: 0.032 | E9: 0.034 | F9: 0.036 | G9: 0.038 | H9: 0.04 | I9: 0.04 | J9: 0.04 | K9: 0.04 | L9: 0.04
A10: SBC (expense) | C10: =-C6*C9 | D10: =-D6*D9 | E10: =-E6*E9 | F10: =-F6*F9 | G10: =-G6*G9 | H10: =-H6*H9 | I10: =-I6*I9 | J10: =-J6*J9 | ... L10: =-L6*L9
A11: Owner EBITDA | C11: =C8+C10 | D11: =D8+D10 | E11: =E8+E10 | F11: =F8+F10 | G11: =G8+G10 | H11: =H8+H10 | I11: =I8+I10 | J11: =J8+J10 | ... L11: =L8+L10
A12: D&A | C12: =-C6*Assumptions!$D$19 | D12: =-D6*Assumptions!$D$19 | E12: =-E6*Assumptions!$D$19 | F12: =-F6*Assumptions!$D$19 | G12: =-G6*Assumptions!$D$19 | H12: =-H6*Assumptions!$D$19 | I12: =-I6*Assumptions!$D$19 | J12: =-J6*Assumptions!$D$19 | ... L12: =-L6*Assumptions!$D$19
A13: EBIT after SBC | C13: =C11+C12 | D13: =D11+D12 | E13: =E11+E12 | F13: =F11+F12 | G13: =G11+G12 | H13: =H11+H12 | I13: =I11+I12 | J13: =J11+J12 | ... L13: =L11+L12
A14: Cash tax rate | C14: 0.24 | D14: 0.25 | E14: 0.25 | F14: 0.25 | G14: 0.25 | H14: 0.25 | I14: 0.25 | J14: 0.25 | K14: 0.25 | L14: 0.25
A15: NOPAT | C15: =C13*(1-C14) | D15: =D13*(1-D14) | E15: =E13*(1-E14) | F15: =F13*(1-F14) | G15: =G13*(1-G14) | H15: =H13*(1-H14) | I15: =I13*(1-I14) | J15: =J13*(1-J14) | ... L15: =L13*(1-L14)
A16: add back D&A | C16: =-C12 | D16: =-D12 | E16: =-E12 | F16: =-F12 | G16: =-G12 | H16: =-H12 | I16: =-I12 | J16: =-J12 | ... L16: =-L12
A17: less capex | C17: =-C6*Assumptions!$E$19 | D17: =-D6*Assumptions!$E$19 | E17: =-E6*Assumptions!$E$19 | F17: =-F6*Assumptions!$E$19 | G17: =-G6*Assumptions!$E$19 | H17: =-H6*Assumptions!$E$19 | I17: =-I6*Assumptions!$E$19 | J17: =-J6*Assumptions!$E$19 | ... L17: =-L6*Assumptions!$E$19
A18: add working capital | C18: =Assumptions!$F$19*(C6-B6) | D18: =Assumptions!$F$19*(D6-C6) | E18: =Assumptions!$F$19*(E6-D6) | F18: =Assumptions!$F$19*(F6-E6) | G18: =Assumptions!$F$19*(G6-F6) | H18: =Assumptions!$F$19*(H6-G6) | I18: =Assumptions!$F$19*(I6-H6) | J18: =Assumptions!$F$19*(J6-I6) | ... L18: =Assumptions!$F$19*(L6-K6)
A19: UNLEVERED OWNER FCF | C19: =C15+C16+C17+C18 | D19: =D15+D16+D17+D18 | E19: =E15+E16+E17+E18 | F19: =F15+F16+F17+F18 | G19: =G15+G16+G17+G18 | H19: =H15+H16+H17+H18 | I19: =I15+I16+I17+I18 | J19: =J15+J16+J17+J18 | ... L19: =L15+L16+L17+L18
A20: Discount factor | C20: =1/(1+Assumptions!$B$11)^C4 | D20: =1/(1+Assumptions!$B$11)^D4 | E20: =1/(1+Assumptions!$B$11)^E4 | F20: =1/(1+Assumptions!$B$11)^F4 | G20: =1/(1+Assumptions!$B$11)^G4 | H20: =1/(1+Assumptions!$B$11)^H4 | I20: =1/(1+Assumptions!$B$11)^I4 | J20: =1/(1+Assumptions!$B$11)^J4 | ... L20: =1/(1+Assumptions!$B$11)^L4
A21: PV of FCF | C21: =C19*C20 | D21: =D19*D20 | E21: =E19*E20 | F21: =F19*F20 | G21: =G19*G20 | H21: =H19*H20 | I21: =I19*I20 | J21: =J19*J20 | ... L21: =L19*L20
A23: Memo: FCF before SBC | C23: =C19-C10 | D23: =D19-D10 | E23: =E19-E10 | F23: =F19-F10 | G23: =G19-G10 | H23: =H19-H10 | I23: =I19-I10 | J23: =J19-J10 | ... L23: =L19-L10
A24: Memo: owner-FCF margin | C24: =C19/C6 | D24: =D19/D6 | E24: =E19/E6 | F24: =F19/F6 | G24: =G19/G6 | H24: =H19/H6 | I24: =I19/I6 | J24: =J19/J6 | ... L24: =L19/L6
A26: Sum PV of explicit FCF | B26: =SUM(C21:L21)
A27: Terminal growth | B27: =Assumptions!$B$19
A28: Terminal-year FCF grown | B28: =L19*(1+B27)
A29: Gordon terminal value | B29: =B28/(Assumptions!$B$11-B27)
A30: Cap terminal value | B30: =Assumptions!$B$12*L19
A31: TERMINAL VALUE USED | B31: =MAX(0,MIN(B29,B30))
A32: Which bound | B32: =IF(B30<B29,"cap","gordon")
A33: Implied exit multiple | B33: =B31/L19
A34: PV of terminal value | B34: =B31*L20
A35: Enterprise value | B35: =B26+B34
A36: add net cash used | B36: =Assumptions!$B$9
A37: Equity value | B37: =B35+B36
A38: Diluted shares (m) | B38: =Assumptions!$B$3
A39: VALUE PER SHARE RMB | B39: =B37/B38
A40: VALUE PER SHARE HKD | B40: =B39*Assumptions!$B$14
A41: Upside vs price | B41: =B40/Assumptions!$B$13-1
A42: Terminal % of EV | B42: =B34/B35
A44: Street basis memo (SBC treated as non-cash)
...

Sheet DCF_Base
A1: BASE scenario -- owner-FCF DCF, RMB millions
A3: Year | B3: 2025A | C3: 2026E | D3: 2027E | E3: 2028E | F3: 2029E | G3: 2030E | H3: 2031E | I3: 2032E | J3: 2033E | K3: 2034E | L3: 2035E
A4: Index | B4: 0 | C4: 1 | D4: 2 | E4: 3 | F4: 4 | G4: 5 | H4: 6 | I4: 7 | J4: 8 | K4: 9 | L4: 10
A5: Revenue growth % | C5: 0.075 | D5: 0.07 | E5: 0.065 | F5: 0.06 | G5: 0.055 | H5: 0.05 | I5: 0.045 | J5: 0.04 | K5: 0.035 | L5: 0.03
A6: Revenue | B6: 116582.5 | C6: =B6*(1+C5) | D6: =C6*(1+D5) | E6: =D6*(1+E5) | F6: =E6*(1+F5) | G6: =F6*(1+G5) | H6: =G6*(1+H5) | I6: =H6*(1+I5) | J6: =I6*(1+J5) | ... L6: =K6*(1+L5)
A7: Adj EBITDA margin % (pre-SBC) | C7: 0.41 | D7: 0.4089 | E7: 0.4078 | F7: 0.4067 | G7: 0.4056 | H7: 0.4044 | I7: 0.4033 | J7: 0.4022 | K7: 0.4011 | L7: 0.4
A8: Adjusted EBITDA | C8: =C6*C7 | D8: =D6*D7 | E8: =E6*E7 | F8: =F6*F7 | G8: =G6*G7 | H8: =H6*H7 | I8: =I6*I7 | J8: =J6*J7 | ... L8: =L6*L7
A9: SBC % of revenue | C9: 0.028 | D9: 0.028 | E9: 0.029 | F9: 0.029 | G9: 0.03 | H9: 0.03 | I9: 0.03 | J9: 0.03 | K9: 0.03 | L9: 0.03
A10: SBC (expense) | C10: =-C6*C9 | D10: =-D6*D9 | E10: =-E6*E9 | F10: =-F6*F9 | G10: =-G6*G9 | H10: =-H6*H9 | I10: =-I6*I9 | J10: =-J6*J9 | ... L10: =-L6*L9
A11: Owner EBITDA | C11: =C8+C10 | D11: =D8+D10 | E11: =E8+E10 | F11: =F8+F10 | G11: =G8+G10 | H11: =H8+H10 | I11: =I8+I10 | J11: =J8+J10 | ... L11: =L8+L10
A12: D&A | C12: =-C6*Assumptions!$D$20 | D12: =-D6*Assumptions!$D$20 | E12: =-E6*Assumptions!$D$20 | F12: =-F6*Assumptions!$D$20 | G12: =-G6*Assumptions!$D$20 | H12: =-H6*Assumptions!$D$20 | I12: =-I6*Assumptions!$D$20 | J12: =-J6*Assumptions!$D$20 | ... L12: =-L6*Assumptions!$D$20
A13: EBIT after SBC | C13: =C11+C12 | D13: =D11+D12 | E13: =E11+E12 | F13: =F11+F12 | G13: =G11+G12 | H13: =H11+H12 | I13: =I11+I12 | J13: =J11+J12 | ... L13: =L11+L12
A14: Cash tax rate | C14: 0.22 | D14: 0.225 | E14: 0.23 | F14: 0.235 | G14: 0.24 | H14: 0.24 | I14: 0.24 | J14: 0.24 | K14: 0.24 | L14: 0.24
A15: NOPAT | C15: =C13*(1-C14) | D15: =D13*(1-D14) | E15: =E13*(1-E14) | F15: =F13*(1-F14) | G15: =G13*(1-G14) | H15: =H13*(1-H14) | I15: =I13*(1-I14) | J15: =J13*(1-J14) | ... L15: =L13*(1-L14)
A16: add back D&A | C16: =-C12 | D16: =-D12 | E16: =-E12 | F16: =-F12 | G16: =-G12 | H16: =-H12 | I16: =-I12 | J16: =-J12 | ... L16: =-L12
A17: less capex | C17: =-C6*Assumptions!$E$20 | D17: =-D6*Assumptions!$E$20 | E17: =-E6*Assumptions!$E$20 | F17: =-F6*Assumptions!$E$20 | G17: =-G6*Assumptions!$E$20 | H17: =-H6*Assumptions!$E$20 | I17: =-I6*Assumptions!$E$20 | J17: =-J6*Assumptions!$E$20 | ... L17: =-L6*Assumptions!$E$20
A18: add working capital | C18: =Assumptions!$F$20*(C6-B6) | D18: =Assumptions!$F$20*(D6-C6) | E18: =Assumptions!$F$20*(E6-D6) | F18: =Assumptions!$F$20*(F6-E6) | G18: =Assumptions!$F$20*(G6-F6) | H18: =Assumptions!$F$20*(H6-G6) | I18: =Assumptions!$F$20*(I6-H6) | J18: =Assumptions!$F$20*(J6-I6) | ... L18: =Assumptions!$F$20*(L6-K6)
A19: UNLEVERED OWNER FCF | C19: =C15+C16+C17+C18 | D19: =D15+D16+D17+D18 | E19: =E15+E16+E17+E18 | F19: =F15+F16+F17+F18 | G19: =G15+G16+G17+G18 | H19: =H15+H16+H17+H18 | I19: =I15+I16+I17+I18 | J19: =J15+J16+J17+J18 | ... L19: =L15+L16+L17+L18
A20: Discount factor | C20: =1/(1+Assumptions!$B$11)^C4 | D20: =1/(1+Assumptions!$B$11)^D4 | E20: =1/(1+Assumptions!$B$11)^E4 | F20: =1/(1+Assumptions!$B$11)^F4 | G20: =1/(1+Assumptions!$B$11)^G4 | H20: =1/(1+Assumptions!$B$11)^H4 | I20: =1/(1+Assumptions!$B$11)^I4 | J20: =1/(1+Assumptions!$B$11)^J4 | ... L20: =1/(1+Assumptions!$B$11)^L4
A21: PV of FCF | C21: =C19*C20 | D21: =D19*D20 | E21: =E19*E20 | F21: =F19*F20 | G21: =G19*G20 | H21: =H19*H20 | I21: =I19*I20 | J21: =J19*J20 | ... L21: =L19*L20
A23: Memo: FCF before SBC | C23: =C19-C10 | D23: =D19-D10 | E23: =E19-E10 | F23: =F19-F10 | G23: =G19-G10 | H23: =H19-H10 | I23: =I19-I10 | J23: =J19-J10 | ... L23: =L19-L10
A24: Memo: owner-FCF margin | C24: =C19/C6 | D24: =D19/D6 | E24: =E19/E6 | F24: =F19/F6 | G24: =G19/G6 | H24: =H19/H6 | I24: =I19/I6 | J24: =J19/J6 | ... L24: =L19/L6
A26: Sum PV of explicit FCF | B26: =SUM(C21:L21)
A27: Terminal growth | B27: =Assumptions!$B$20
A28: Terminal-year FCF grown | B28: =L19*(1+B27)
A29: Gordon terminal value | B29: =B28/(Assumptions!$B$11-B27)
A30: Cap terminal value | B30: =Assumptions!$B$12*L19
A31: TERMINAL VALUE USED | B31: =MAX(0,MIN(B29,B30))
A32: Which bound | B32: =IF(B30<B29,"cap","gordon")
A33: Implied exit multiple | B33: =B31/L19
A34: PV of terminal value | B34: =B31*L20
A35: Enterprise value | B35: =B26+B34
A36: add net cash used | B36: =Assumptions!$B$9
A37: Equity value | B37: =B35+B36
A38: Diluted shares (m) | B38: =Assumptions!$B$3
A39: VALUE PER SHARE RMB | B39: =B37/B38
A40: VALUE PER SHARE HKD | B40: =B39*Assumptions!$B$14
A41: Upside vs price | B41: =B40/Assumptions!$B$13-1
A42: Terminal % of EV | B42: =B34/B35
A44: Street basis memo (SBC treated as non-cash)
...

Sheet DCF_Bull
A1: BULL scenario -- owner-FCF DCF, RMB millions
A3: Year | B3: 2025A | C3: 2026E | D3: 2027E | E3: 2028E | F3: 2029E | G3: 2030E | H3: 2031E | I3: 2032E | J3: 2033E | K3: 2034E | L3: 2035E
A4: Index | B4: 0 | C4: 1 | D4: 2 | E4: 3 | F4: 4 | G4: 5 | H4: 6 | I4: 7 | J4: 8 | K4: 9 | L4: 10
A5: Revenue growth % | C5: 0.1 | D5: 0.095 | E5: 0.09 | F5: 0.085 | G5: 0.08 | H5: 0.07 | I5: 0.06 | J5: 0.055 | K5: 0.05 | L5: 0.045
A6: Revenue | B6: 116582.5 | C6: =B6*(1+C5) | D6: =C6*(1+D5) | E6: =D6*(1+E5) | F6: =E6*(1+F5) | G6: =F6*(1+G5) | H6: =G6*(1+H5) | I6: =H6*(1+I5) | J6: =I6*(1+J5) | ... L6: =K6*(1+L5)
A7: Adj EBITDA margin % (pre-SBC) | C7: 0.42 | D7: 0.4217 | E7: 0.4233 | F7: 0.425 | G7: 0.4267 | H7: 0.4283 | I7: 0.43 | J7: 0.4317 | K7: 0.4333 | L7: 0.435
A8: Adjusted EBITDA | C8: =C6*C7 | D8: =D6*D7 | E8: =E6*E7 | F8: =F6*F7 | G8: =G6*G7 | H8: =H6*H7 | I8: =I6*I7 | J8: =J6*J7 | ... L8: =L6*L7
A9: SBC % of revenue | C9: 0.028 | D9: 0.028 | E9: 0.028 | F9: 0.028 | G9: 0.028 | H9: 0.028 | I9: 0.028 | J9: 0.028 | K9: 0.028 | L9: 0.028
A10: SBC (expense) | C10: =-C6*C9 | D10: =-D6*D9 | E10: =-E6*E9 | F10: =-F6*F9 | G10: =-G6*G9 | H10: =-H6*H9 | I10: =-I6*I9 | J10: =-J6*J9 | ... L10: =-L6*L9
A11: Owner EBITDA | C11: =C8+C10 | D11: =D8+D10 | E11: =E8+E10 | F11: =F8+F10 | G11: =G8+G10 | H11: =H8+H10 | I11: =I8+I10 | J11: =J8+J10 | ... L11: =L8+L10
A12: D&A | C12: =-C6*Assumptions!$D$21 | D12: =-D6*Assumptions!$D$21 | E12: =-E6*Assumptions!$D$21 | F12: =-F6*Assumptions!$D$21 | G12: =-G6*Assumptions!$D$21 | H12: =-H6*Assumptions!$D$21 | I12: =-I6*Assumptions!$D$21 | J12: =-J6*Assumptions!$D$21 | ... L12: =-L6*Assumptions!$D$21
A13: EBIT after SBC | C13: =C11+C12 | D13: =D11+D12 | E13: =E11+E12 | F13: =F11+F12 | G13: =G11+G12 | H13: =H11+H12 | I13: =I11+I12 | J13: =J11+J12 | ... L13: =L11+L12
A14: Cash tax rate | C14: 0.215 | D14: 0.215 | E14: 0.22 | F14: 0.22 | G14: 0.22 | H14: 0.22 | I14: 0.22 | J14: 0.22 | K14: 0.22 | L14: 0.22
A15: NOPAT | C15: =C13*(1-C14) | D15: =D13*(1-D14) | E15: =E13*(1-E14) | F15: =F13*(1-F14) | G15: =G13*(1-G14) | H15: =H13*(1-H14) | I15: =I13*(1-I14) | J15: =J13*(1-J14) | ... L15: =L13*(1-L14)
A16: add back D&A | C16: =-C12 | D16: =-D12 | E16: =-E12 | F16: =-F12 | G16: =-G12 | H16: =-H12 | I16: =-I12 | J16: =-J12 | ... L16: =-L12
A17: less capex | C17: =-C6*Assumptions!$E$21 | D17: =-D6*Assumptions!$E$21 | E17: =-E6*Assumptions!$E$21 | F17: =-F6*Assumptions!$E$21 | G17: =-G6*Assumptions!$E$21 | H17: =-H6*Assumptions!$E$21 | I17: =-I6*Assumptions!$E$21 | J17: =-J6*Assumptions!$E$21 | ... L17: =-L6*Assumptions!$E$21
A18: add working capital | C18: =Assumptions!$F$21*(C6-B6) | D18: =Assumptions!$F$21*(D6-C6) | E18: =Assumptions!$F$21*(E6-D6) | F18: =Assumptions!$F$21*(F6-E6) | G18: =Assumptions!$F$21*(G6-F6) | H18: =Assumptions!$F$21*(H6-G6) | I18: =Assumptions!$F$21*(I6-H6) | J18: =Assumptions!$F$21*(J6-I6) | ... L18: =Assumptions!$F$21*(L6-K6)
A19: UNLEVERED OWNER FCF | C19: =C15+C16+C17+C18 | D19: =D15+D16+D17+D18 | E19: =E15+E16+E17+E18 | F19: =F15+F16+F17+F18 | G19: =G15+G16+G17+G18 | H19: =H15+H16+H17+H18 | I19: =I15+I16+I17+I18 | J19: =J15+J16+J17+J18 | ... L19: =L15+L16+L17+L18
A20: Discount factor | C20: =1/(1+Assumptions!$B$11)^C4 | D20: =1/(1+Assumptions!$B$11)^D4 | E20: =1/(1+Assumptions!$B$11)^E4 | F20: =1/(1+Assumptions!$B$11)^F4 | G20: =1/(1+Assumptions!$B$11)^G4 | H20: =1/(1+Assumptions!$B$11)^H4 | I20: =1/(1+Assumptions!$B$11)^I4 | J20: =1/(1+Assumptions!$B$11)^J4 | ... L20: =1/(1+Assumptions!$B$11)^L4
A21: PV of FCF | C21: =C19*C20 | D21: =D19*D20 | E21: =E19*E20 | F21: =F19*F20 | G21: =G19*G20 | H21: =H19*H20 | I21: =I19*I20 | J21: =J19*J20 | ... L21: =L19*L20
A23: Memo: FCF before SBC | C23: =C19-C10 | D23: =D19-D10 | E23: =E19-E10 | F23: =F19-F10 | G23: =G19-G10 | H23: =H19-H10 | I23: =I19-I10 | J23: =J19-J10 | ... L23: =L19-L10
A24: Memo: owner-FCF margin | C24: =C19/C6 | D24: =D19/D6 | E24: =E19/E6 | F24: =F19/F6 | G24: =G19/G6 | H24: =H19/H6 | I24: =I19/I6 | J24: =J19/J6 | ... L24: =L19/L6
A26: Sum PV of explicit FCF | B26: =SUM(C21:L21)
A27: Terminal growth | B27: =Assumptions!$B$21
A28: Terminal-year FCF grown | B28: =L19*(1+B27)
A29: Gordon terminal value | B29: =B28/(Assumptions!$B$11-B27)
A30: Cap terminal value | B30: =Assumptions!$B$12*L19
A31: TERMINAL VALUE USED | B31: =MAX(0,MIN(B29,B30))
A32: Which bound | B32: =IF(B30<B29,"cap","gordon")
A33: Implied exit multiple | B33: =B31/L19
A34: PV of terminal value | B34: =B31*L20
A35: Enterprise value | B35: =B26+B34
A36: add net cash used | B36: =Assumptions!$B$9
A37: Equity value | B37: =B35+B36
A38: Diluted shares (m) | B38: =Assumptions!$B$3
A39: VALUE PER SHARE RMB | B39: =B37/B38
A40: VALUE PER SHARE HKD | B40: =B39*Assumptions!$B$14
A41: Upside vs price | B41: =B40/Assumptions!$B$13-1
A42: Terminal % of EV | B42: =B34/B35
A44: Street basis memo (SBC treated as non-cash)
...

Sheet FCF_Quality
A1: Reported FCF reconciled to owner FCF -- RMB millions
A3: Year | B3: 2019 | C3: 2020 | D3: 2021 | E3: 2022 | F3: 2023 | G3: 2024 | H3: 2025 | I3: TTM
A4: Free cash flow (company definition) | B4: 16007 | C4: 23832.6 | D4: 23324.9 | E4: 25609 | F4: 33029.7 | G4: 38401.4 | H4: 49674.4 | I4: 50036.6
A5: less: SBC | B5: -2404.1 | C5: -2663.5 | D5: -3041.5 | E5: -3174.2 | F5: -3242.8 | G5: -3882.9 | H5: -3647.7 | I5: -3199.2
A6: less: net interest income | B6: -821.8 | C6: -1598.6 | D6: -1519.7 | E6: -2149.7 | F6: -4120.4 | G6: -4920.9 | H6: -3953.5 | I6: -3953.5
A7: Owner FCF | B7: =B4+B5+B6 | C7: =C4+C5+C6 | D7: =D4+D5+D6 | E7: =E4+E5+E6 | F7: =F4+F5+F6 | G7: =G4+G5+G6 | H7: =H4+H5+H6 | I7: =I4+I5+I6
A8: Revenue | B8: 60925.1 | C8: 73631.2 | D8: 87987.6 | E8: 99423 | F8: 103437.7 | G8: 105377.6 | H8: 112625.8 | I8: 116582.5
A9: Reported FCF margin | B9: =B4/B8 | C9: =C4/C8 | D9: =D4/D8 | E9: =E4/E8 | F9: =F4/F8 | G9: =G4/G8 | H9: =H4/H8 | I9: =I4/I8
A10: Owner FCF margin | B10: =B7/B8 | C10: =C7/C8 | D10: =D7/D8 | E10: =E7/E8 | F10: =F7/F8 | G10: =G7/G8 | H10: =H7/H8 | I10: =I7/I8
A12: Memo: working-capital inflow inside OCF, and why it matters
A13: FY2025 WC inflow (contract liab 5,400 + payables 1,900 + taxes payable 1,100) | B13: 8400
A14: as % of FY2025 reported FCF | B14: 0.169
A15: as % of the FY2025 revenue INCREASE | B15: 1.159
A16: FY2024 WC inflow | B16: 3306.8
A17: FY2024 as % of reported FCF | B17: 0.086
A18: Forward WC capture rate assumed in the model | B18: 0.35
A20: Memo: cash tax rate -- FLAGGED as structurally higher
A21: H1-2025 effective tax rate | B21: 0.15
A22: H1-2026 effective tax rate | B22: 0.217
A23: Q2-2026 alone | B23: 0.255
A24: Modelled base-case path | B24: 0.22
A25: ramping to | B25: 0.24
A27: The step-up is treated as permanent (expiring preferential software/HNTE rates), not a timing item. Reverting to 15% would materially overstate value.

Sheet Valuation
A1: Valuation summary -- NetEase 9999.HK
A3: Scenario | B3: Value/share HKD | C3: Upside | D3: Weight | E3: Street value HKD | F3: Entry HKD @15%
A4: Bear | B4: =DCF_Bear!$B$40 | C4: =B4/Assumptions!$B$13-1 | D4: =Assumptions!$C$19 | E4: =DCF_Bear!$B$47 | F4: =DCF_Bear!$B$52
A5: Base | B5: =DCF_Base!$B$40 | C5: =B5/Assumptions!$B$13-1 | D5: =Assumptions!$C$20 | E5: =DCF_Base!$B$47 | F5: =DCF_Base!$B$52
A6: Bull | B6: =DCF_Bull!$B$40 | C6: =B6/Assumptions!$B$13-1 | D6: =Assumptions!$C$21 | E6: =DCF_Bull!$B$47 | F6: =DCF_Bull!$B$52
A8: PROBABILITY-WEIGHTED | B8: =SUMPRODUCT(B4:B6,D4:D6) | C8: =B8/Assumptions!$B$13-1 | E8: =SUMPRODUCT(E4:E6,D4:D6) | F8: =SUMPRODUCT(F4:F6,D4:D6)
A9: Margin of safety vs price | B9: =1-Assumptions!$B$13/B8
A10: Band position (0%=house, 100%=street) | B10: =(Assumptions!$B$13-B8)/(E8-B8) | C10: Negative because the price sits BELOW the house IV. The band is only ~HK$18 wide (SBC is just 2.8% of revenue), so a HK$35 gap below the floor scales to a large negative. Not an error -- it means no part of the thesis depends on SBC treatment.
A12: Required-return table (base case), value per share HKD
A13: Required return | B13: Value/share HKD
A14: 0.09 | B14: =(SUMPRODUCT(DCF_Base!$C$19:$L$19,1/(1+$A14)^DCF_Base!$C$4:$L$4)+DCF_Base!$B$31/(1+$A14)^10+Assumptions!$B$9)/Assumptions!$B$3*Assumptions!$B$14 | D14: Today's HK$192.20 sits between the 12% and 15% rows -- the market is pricing roughly a 13-14% forward return on the base-case flows.
A15: 0.1 | B15: =(SUMPRODUCT(DCF_Base!$C$19:$L$19,1/(1+$A15)^DCF_Base!$C$4:$L$4)+DCF_Base!$B$31/(1+$A15)^10+Assumptions!$B$9)/Assumptions!$B$3*Assumptions!$B$14
A16: 0.105 | B16: =(SUMPRODUCT(DCF_Base!$C$19:$L$19,1/(1+$A16)^DCF_Base!$C$4:$L$4)+DCF_Base!$B$31/(1+$A16)^10+Assumptions!$B$9)/Assumptions!$B$3*Assumptions!$B$14
A17: 0.11 | B17: =(SUMPRODUCT(DCF_Base!$C$19:$L$19,1/(1+$A17)^DCF_Base!$C$4:$L$4)+DCF_Base!$B$31/(1+$A17)^10+Assumptions!$B$9)/Assumptions!$B$3*Assumptions!$B$14
A18: 0.12 | B18: =(SUMPRODUCT(DCF_Base!$C$19:$L$19,1/(1+$A18)^DCF_Base!$C$4:$L$4)+DCF_Base!$B$31/(1+$A18)^10+Assumptions!$B$9)/Assumptions!$B$3*Assumptions!$B$14
A19: 0.15 | B19: =(SUMPRODUCT(DCF_Base!$C$19:$L$19,1/(1+$A19)^DCF_Base!$C$4:$L$4)+DCF_Base!$B$31/(1+$A19)^10+Assumptions!$B$9)/Assumptions!$B$3*Assumptions!$B$14
A21: Sensitivity: WACC (rows) x terminal growth (cols), base case, value per share HKD
B22: 0.015 | C22: 0.02 | D22: 0.025 | E22: 0.03 | F22: 0.035
A23: 0.085 | B23: =IF($A23<=B$22,"n/a",(SUMPRODUCT(DCF_Base!$C$19:$L$19,1/(1+$A23)^DCF_Base!$C$4:$L$4)+MAX(0,MIN(DCF_Base!$L$19*(1+B$22)/($A23-B$22),Assumptions!$B$12*DCF_Base!$L$19))/(1+$A23)^10+Assumptions!$B$9)/Assumptions!$B$3*Assumptions!$B$14) | C23: =IF($A23<=C$22,"n/a",(SUMPRODUCT(DCF_Base!$C$19:$L$19,1/(1+$A23)^DCF_Base!$C$4:$L$4)+MAX(0,MIN(DCF_Base!$L$19*(1+C$22)/($A23-C$22),Assumptions!$B$12*DCF_Base!$L$19))/(1+$A23)^10+Assumptions!$B$9)/Assumptions!$B$3*Assumptions!$B$14) | D23: =IF($A23<=D$22,"n/a",(SUMPRODUCT(DCF_Base!$C$19:$L$19,1/(1+$A23)^DCF_Base!$C$4:$L$4)+MAX(0,MIN(DCF_Base!$L$19*(1+D$22)/($A23-D$22),Assumptions!$B$12*DCF_Base!$L$19))/(1+$A23)^10+Assumptions!$B$9)/Assumptions!$B$3*Assumptions!$B$14) | E23: =IF($A23<=E$22,"n/a",(SUMPRODUCT(DCF_Base!$C$19:$L$19,1/(1+$A23)^DCF_Base!$C$4:$L$4)+MAX(0,MIN(DCF_Base!$L$19*(1+E$22)/($A23-E$22),Assumptions!$B$12*DCF_Base!$L$19))/(1+$A23)^10+Assumptions!$B$9)/Assumptions!$B$3*Assumptions!$B$14) | F23: =IF($A23<=F$22,"n/a",(SUMPRODUCT(DCF_Base!$C$19:$L$19,1/(1+$A23)^DCF_Base!$C$4:$L$4)+MAX(0,MIN(DCF_Base!$L$19*(1+F$22)/($A23-F$22),Assumptions!$B$12*DCF_Base!$L$19))/(1+$A23)^10+Assumptions!$B$9)/Assumptions!$B$3*Assumptions!$B$14)
A24: 0.095 | B24: =IF($A24<=B$22,"n/a",(SUMPRODUCT(DCF_Base!$C$19:$L$19,1/(1+$A24)^DCF_Base!$C$4:$L$4)+MAX(0,MIN(DCF_Base!$L$19*(1+B$22)/($A24-B$22),Assumptions!$B$12*DCF_Base!$L$19))/(1+$A24)^10+Assumptions!$B$9)/Assumptions!$B$3*Assumptions!$B$14) | C24: =IF($A24<=C$22,"n/a",(SUMPRODUCT(DCF_Base!$C$19:$L$19,1/(1+$A24)^DCF_Base!$C$4:$L$4)+MAX(0,MIN(DCF_Base!$L$19*(1+C$22)/($A24-C$22),Assumptions!$B$12*DCF_Base!$L$19))/(1+$A24)^10+Assumptions!$B$9)/Assumptions!$B$3*Assumptions!$B$14) | D24: =IF($A24<=D$22,"n/a",(SUMPRODUCT(DCF_Base!$C$19:$L$19,1/(1+$A24)^DCF_Base!$C$4:$L$4)+MAX(0,MIN(DCF_Base!$L$19*(1+D$22)/($A24-D$22),Assumptions!$B$12*DCF_Base!$L$19))/(1+$A24)^10+Assumptions!$B$9)/Assumptions!$B$3*Assumptions!$B$14) | E24: =IF($A24<=E$22,"n/a",(SUMPRODUCT(DCF_Base!$C$19:$L$19,1/(1+$A24)^DCF_Base!$C$4:$L$4)+MAX(0,MIN(DCF_Base!$L$19*(1+E$22)/($A24-E$22),Assumptions!$B$12*DCF_Base!$L$19))/(1+$A24)^10+Assumptions!$B$9)/Assumptions!$B$3*Assumptions!$B$14) | F24: =IF($A24<=F$22,"n/a",(SUMPRODUCT(DCF_Base!$C$19:$L$19,1/(1+$A24)^DCF_Base!$C$4:$L$4)+MAX(0,MIN(DCF_Base!$L$19*(1+F$22)/($A24-F$22),Assumptions!$B$12*DCF_Base!$L$19))/(1+$A24)^10+Assumptions!$B$9)/Assumptions!$B$3*Assumptions!$B$14)
A25: 0.105 | B25: =IF($A25<=B$22,"n/a",(SUMPRODUCT(DCF_Base!$C$19:$L$19,1/(1+$A25)^DCF_Base!$C$4:$L$4)+MAX(0,MIN(DCF_Base!$L$19*(1+B$22)/($A25-B$22),Assumptions!$B$12*DCF_Base!$L$19))/(1+$A25)^10+Assumptions!$B$9)/Assumptions!$B$3*Assumptions!$B$14) | C25: =IF($A25<=C$22,"n/a",(SUMPRODUCT(DCF_Base!$C$19:$L$19,1/(1+$A25)^DCF_Base!$C$4:$L$4)+MAX(0,MIN(DCF_Base!$L$19*(1+C$22)/($A25-C$22),Assumptions!$B$12*DCF_Base!$L$19))/(1+$A25)^10+Assumptions!$B$9)/Assumptions!$B$3*Assumptions!$B$14) | D25: =IF($A25<=D$22,"n/a",(SUMPRODUCT(DCF_Base!$C$19:$L$19,1/(1+$A25)^DCF_Base!$C$4:$L$4)+MAX(0,MIN(DCF_Base!$L$19*(1+D$22)/($A25-D$22),Assumptions!$B$12*DCF_Base!$L$19))/(1+$A25)^10+Assumptions!$B$9)/Assumptions!$B$3*Assumptions!$B$14) | E25: =IF($A25<=E$22,"n/a",(SUMPRODUCT(DCF_Base!$C$19:$L$19,1/(1+$A25)^DCF_Base!$C$4:$L$4)+MAX(0,MIN(DCF_Base!$L$19*(1+E$22)/($A25-E$22),Assumptions!$B$12*DCF_Base!$L$19))/(1+$A25)^10+Assumptions!$B$9)/Assumptions!$B$3*Assumptions!$B$14) | F25: =IF($A25<=F$22,"n/a",(SUMPRODUCT(DCF_Base!$C$19:$L$19,1/(1+$A25)^DCF_Base!$C$4:$L$4)+MAX(0,MIN(DCF_Base!$L$19*(1+F$22)/($A25-F$22),Assumptions!$B$12*DCF_Base!$L$19))/(1+$A25)^10+Assumptions!$B$9)/Assumptions!$B$3*Assumptions!$B$14)
A26: 0.115 | B26: =IF($A26<=B$22,"n/a",(SUMPRODUCT(DCF_Base!$C$19:$L$19,1/(1+$A26)^DCF_Base!$C$4:$L$4)+MAX(0,MIN(DCF_Base!$L$19*(1+B$22)/($A26-B$22),Assumptions!$B$12*DCF_Base!$L$19))/(1+$A26)^10+Assumptions!$B$9)/Assumptions!$B$3*Assumptions!$B$14) | C26: =IF($A26<=C$22,"n/a",(SUMPRODUCT(DCF_Base!$C$19:$L$19,1/(1+$A26)^DCF_Base!$C$4:$L$4)+MAX(0,MIN(DCF_Base!$L$19*(1+C$22)/($A26-C$22),Assumptions!$B$12*DCF_Base!$L$19))/(1+$A26)^10+Assumptions!$B$9)/Assumptions!$B$3*Assumptions!$B$14) | D26: =IF($A26<=D$22,"n/a",(SUMPRODUCT(DCF_Base!$C$19:$L$19,1/(1+$A26)^DCF_Base!$C$4:$L$4)+MAX(0,MIN(DCF_Base!$L$19*(1+D$22)/($A26-D$22),Assumptions!$B$12*DCF_Base!$L$19))/(1+$A26)^10+Assumptions!$B$9)/Assumptions!$B$3*Assumptions!$B$14) | E26: =IF($A26<=E$22,"n/a",(SUMPRODUCT(DCF_Base!$C$19:$L$19,1/(1+$A26)^DCF_Base!$C$4:$L$4)+MAX(0,MIN(DCF_Base!$L$19*(1+E$22)/($A26-E$22),Assumptions!$B$12*DCF_Base!$L$19))/(1+$A26)^10+Assumptions!$B$9)/Assumptions!$B$3*Assumptions!$B$14) | F26: =IF($A26<=F$22,"n/a",(SUMPRODUCT(DCF_Base!$C$19:$L$19,1/(1+$A26)^DCF_Base!$C$4:$L$4)+MAX(0,MIN(DCF_Base!$L$19*(1+F$22)/($A26-F$22),Assumptions!$B$12*DCF_Base!$L$19))/(1+$A26)^10+Assumptions!$B$9)/Assumptions!$B$3*Assumptions!$B$14)
A27: 0.125 | B27: =IF($A27<=B$22,"n/a",(SUMPRODUCT(DCF_Base!$C$19:$L$19,1/(1+$A27)^DCF_Base!$C$4:$L$4)+MAX(0,MIN(DCF_Base!$L$19*(1+B$22)/($A27-B$22),Assumptions!$B$12*DCF_Base!$L$19))/(1+$A27)^10+Assumptions!$B$9)/Assumptions!$B$3*Assumptions!$B$14) | C27: =IF($A27<=C$22,"n/a",(SUMPRODUCT(DCF_Base!$C$19:$L$19,1/(1+$A27)^DCF_Base!$C$4:$L$4)+MAX(0,MIN(DCF_Base!$L$19*(1+C$22)/($A27-C$22),Assumptions!$B$12*DCF_Base!$L$19))/(1+$A27)^10+Assumptions!$B$9)/Assumptions!$B$3*Assumptions!$B$14) | D27: =IF($A27<=D$22,"n/a",(SUMPRODUCT(DCF_Base!$C$19:$L$19,1/(1+$A27)^DCF_Base!$C$4:$L$4)+MAX(0,MIN(DCF_Base!$L$19*(1+D$22)/($A27-D$22),Assumptions!$B$12*DCF_Base!$L$19))/(1+$A27)^10+Assumptions!$B$9)/Assumptions!$B$3*Assumptions!$B$14) | E27: =IF($A27<=E$22,"n/a",(SUMPRODUCT(DCF_Base!$C$19:$L$19,1/(1+$A27)^DCF_Base!$C$4:$L$4)+MAX(0,MIN(DCF_Base!$L$19*(1+E$22)/($A27-E$22),Assumptions!$B$12*DCF_Base!$L$19))/(1+$A27)^10+Assumptions!$B$9)/Assumptions!$B$3*Assumptions!$B$14) | F27: =IF($A27<=F$22,"n/a",(SUMPRODUCT(DCF_Base!$C$19:$L$19,1/(1+$A27)^DCF_Base!$C$4:$L$4)+MAX(0,MIN(DCF_Base!$L$19*(1+F$22)/($A27-F$22),Assumptions!$B$12*DCF_Base!$L$19))/(1+$A27)^10+Assumptions!$B$9)/Assumptions!$B$3*Assumptions!$B$14)
A29: House pair (WACC 10.5%, g 2.5%) highlighted.
