Workbook

Sheet Model_Info
A1: Ansell Limited (ANN.AX) owner-FCF DCF model
A2: Version | B2: 1.0, fresh build 2026-09-21; supersedes nothing (first valuation of this ticker)
A3: Built by | B3: dcf-analyst agent (Claude Fable 5.1) on 2026-09-21 at the orchestrator's request as part of /research-stock ANN.AX
A4: Currencies | B4: Statements and every flow in this workbook are USD millions. The ASX quote is AUD. Per-share values are computed in USD and converted at Assumptions!B10 (AUDUSD).
A5: Price | B5: A$42.71 -- 2026-09-21T06:10:32Z ASX regular close
A6: FX | B6: AUDUSD 0.7132 -- Yahoo AUDUSD=X 2026-09-21T11:08:08Z (no liquid dual listing for a parity check)
A7: Balance sheet | B7: 2026-06-30 FY26 Annual Report: cash 249.5, borrowings 657.2 (ex-lease), lease liabilities 99.4, NCI 30.9
A8: Share count | B8: 139.4m ordinary shares on issue at 30 June 2026 (FY26 five-year summary, after the $118.4m FY26 on-market buyback) plus 1.0m potential ordinary shares from the FY26 diluted-EPS note = 140.4m fully diluted. Held FLAT: SBC is fully expensed in the flows, and the on-market buyback plus treasury purchases are the cash mechanism that keeps it flat (charging both would double-count). The 143.8m in Metrics.csv is the FY26 weighted-average diluted denominator, not the year-end count.
A9: Guidance | B9: FY26 Annual Report (year ended 30-Jun-2026, published Aug-2026): FY27 outlook is qualitative only -- constant-currency sales growth from higher volumes and FY26 pricing actions, earnings growth from commercial excellence and productivity; no EPS range given in the report.
A10: Model | B10: Component-built owner FCF, 10-year horizon, end-year discounting, TV = MAX(0, MIN(Gordon, 15x FCF_10)), equity = EV - net debt - NCI.
A11: SBC | B11: Expensed in the flows at 0.55% of revenue; share count held flat (charge once). Street memo adds the PV of SBC back.
A12: Leases | B12: B: leases as operating cost. Lease principal ($23.4m, financing) and lease interest ($5.4m, financing) are deducted from the flows as lease_cost_pct 1.35% of revenue; lease liabilities ($99.4m) are EXCLUDED from net debt. D&A for the cash-tax EBIT is ex right-of-use depreciation (79.7 - ~23.4 = ~56.3, 2.6% of revenue; the ROU depreciation charge is not broken out in the extracted leases note, so it is taken as equal to the principal repayment).
A13: Interest income | B13: Stripped from the FY26 owner-FCF base ($4.4m) because the cash sits in the bridge. Forward flows are unlevered (built from EBITDA) so nothing further is needed.
... A21: Staleness | B21: Every figure here goes stale: the price moves daily, the FX rate is not refreshed by scripts/refresh_price.py, and the balance sheet is as at 30-Jun-2026.

Sheet Actuals
A1: Ansell reported history, USD millions (FY26 Annual Report cash-flow statements; June year-end)
A3: Line | B3: FY2016 | C3: FY2017 | D3: FY2018 | E3: FY2019 | F3: FY2020 | G3: FY2021 | H3: FY2022 | I3: FY2023 | J3: FY2024 | K3: FY2025 | L3: FY2026
A4: Revenue | B4: 1572.8 | C4: 1374.5 | D4: 1489.8 | E4: 1499 | F4: 1613.7 | G4: 2026.9 | H4: 1952.1 | I4: 1655.1 | J4: 1619.3 | K4: 2003.3 | L4: 2140.2
A5: Net cash from operating activities (pre-interest-paid: Ansell books interest paid in financing) | B5: 232.3 | C5: 216.2 | D5: 153.6 | E5: 188.9 | F5: 290.9 | G5: 172.8 | H5: 222 | I5: 180.5 | J5: 276.3 | K5: 239.3 | L5: 388.6
A6: Capex (PPE + intangibles) | B6: 67.2 | C6: 51 | D6: 45.7 | E6: 43.6 | F6: 64.8 | G6: 80.4 | H6: 67.5 | I6: 67.2 | J6: 62.8 | K6: 69.3 | L6: 49
A7: Share-based payments expense | B7: -2.2 | C7: 4.7 | D7: 10.4 | E7: 9.3 | F7: 10.3 | G7: 30.1 | H7: -2.6 | I7: -5.5 | J7: 6.2 | K7: 9.1 | L7: 11.6
A8: Interest received | B8: 4.1 | C8: 3.6 | D8: 7.6 | E8: 8.8 | F8: 5.3 | G8: 1.3 | H8: 0.2 | I8: 2.2 | J8: 4 | K8: 6.6 | L8: 4.4
A9: Lease principal repaid (financing, IFRS16 from FY20) | B9: 0 | C9: 0 | D9: 0 | E9: 0 | F9: 20.3 | G9: 20.8 | H9: 21.5 | I9: 20.5 | J9: 20.1 | K9: 20.1 | L9: 23.4
A10: Interest paid on lease liabilities | B10: 0 | C10: 0 | D10: 0 | E10: 0 | F10: 1.5 | G10: 1.7 | H10: 1.5 | I10: 1.8 | J10: 4 | K10: 4.8 | L10: 5.4
A11: Net profit after tax (reported) | B11: 161.9 | C11: 150.2 | D11: 486.2 | E11: 113.1 | F11: 160.1 | G11: 248.3 | H11: 159.8 | I11: 149.9 | J11: 77.5 | K11: 103.6 | L11: 209.6
A12: Income taxes paid | B12: 29.8 | C12: 35.8 | D12: 35.6 | E12: 25 | F12: 34.2 | G12: 67 | H12: 49.9 | I12: 39.8 | J12: 38.2 | K12: 45.4 | L12: 56.9
A14: Balance sheet 30-Jun-2026
A15: Cash and cash equivalents | B15: 249.5
A16: Interest-bearing liabilities (51.4 current + 605.8 non-current) | B16: 657.2
A17: Lease liabilities (20.9 + 78.5) -- excluded from net debt, charged in flows | B17: 99.4
A18: Non-controlling interests | B18: 30.9
A19: Shares on issue 30-Jun-2026 (m) | B19: 139.4
A20: Potential ordinary shares (diluted-EPS note) | B20: 1
A21: FY26 on-market buyback ($m) | B21: 118.4
A22: FY26 treasury share purchases for employee plans ($m) | B22: 17.4
A23: FY26 Adjusted EBIT | B23: 321.9
A24: FY26 D&A (75.5 dep + 4.2 amort) | B24: 79.7
A25: FY26 Adjusted effective tax rate | B25: 0.241
A26: FY26 dividends paid | B26: 78.8
A27: FY27 outlook | B27: Qualitative: constant-currency sales growth from volume and FY26 pricing; earnings growth from commercial excellence and productivity

Sheet Assumptions
A1: Global inputs (blue = hardcoded)
A3: WACC (USD, all scenarios) | B3: 0.085 | C3: rf 4.2% + 1.0 x 5.0% ERP = 9.2% CoE; Kd 3.95% after tax; E 87% / D 13%
A4: D&A ex-ROU % of revenue | B4: 0.026 | C4: FY26 79.7 less ~23.4 ROU depreciation = 56.3 / 2140.2
A5: Working-capital capture on revenue change | B5: -0.2 | C5: Negative: manufacturer, net WC 24% of sales; growth consumes cash
A6: Net debt (borrowings 657.2 - cash 249.5), USD m | B6: 407.7 | C6: 30-Jun-2026, ex-lease
A7: Non-controlling interests, USD m | B7: 30.9 | C7: 30-Jun-2026 balance sheet
A8: Fully diluted shares (m) | B8: 140.4 | C8: 139.4 on issue + 1.0 potential; held flat
A9: Share price, AUD | B9: 42.71 | C9: 2026-09-21T06:10:32Z ASX regular close
A10: AUDUSD | B10: 0.7132 | C10: Yahoo AUDUSD=X 2026-09-21T11:08Z; USD per-share / this = AUD
A11: Terminal value cap (x FCF_10) | B11: 15 | C11: Cyclical industrial: 15x, not 20x
A12: Hurdle rate for entry price | B12: 0.15 | C12: TV rebuilt at the hurdle
A13: Lease cost % of revenue (principal + interest) | B13: 0.0135 | C13: FY26 23.4 + 5.4 = 28.8 / 2140.2
A14: FY26 revenue, USD m | B14: 2140.2 | C14: FY26 Annual Report
A17: Per-scenario | C17: Bear | D17: Base | E17: Bull
A18: Terminal growth | C18: 0.02 | D18: 0.025 | E18: 0.03
A19: Probability weight | C19: 0.2 | D19: 0.5 | E19: 0.3
A20: Capex % of revenue | C20: 0.034 | D20: 0.032 | E20: 0.03
A21: Weights check (must be 100%) | C21: =SUM(C19:E19)
A23: Scenario narratives
A24: Base | B24: FY27 delivers the qualitative guide -- constant-currency sales growth from volume plus FY26 pricing actions -- at ~5% (FY26 organic CC was 5.0%, FY25 7.7%), fading to 3% as the KBU cross-sell and US channel gains mature and to 2.5% by Y9-10. Adjusted EBITDA margin drifts from 18.8% to 19.2% (Adj EBIT ~15.0% -> ~15.4%) as APIP footprint savings and the India surgical greenfield offset tariff and labour inflation; that is the top of Ansell's FY19-FY26 EBIT-margin range ex the COVID year, so no further re-rating is assumed. Capex normalises from FY26's 2.3% trough to 3.2% of sales; working capital absorbs 20c per dollar of growth (net WC is 24% of sales); cash tax 24% (adjusted ETR 24.1%). Count flat at 140.4m, funded by the ongoing buyback.
A25: Bull | B25: US share gains and KBU cross-selling into scientific, cleanroom (FY26 +10%) and life-sciences verticals hold growth at 8% in FY27 fading to 3.5%; tariff pass-through sticks and mix shifts toward differentiated Industrial/surgical product, taking Adj EBITDA margin to 21% (Adj EBIT ~17%, a level Ansell has only touched in FY21's COVID year). Capex 3.0%, cash tax 23.5%, terminal growth 3%. This case needs both above-market growth and record margins simultaneously, which is why its weight is below the house default.
A26: Bear | B26: A second destocking cycle or US recession repeats the FY23-24 pattern (revenue fell 20% from the FY21 peak to the FY24 trough, Adj EBIT margin 12%): FY27 revenue -2%, flat FY28, then 2-2.5% growth. US tariffs on Malaysian, Thai and Sri Lankan glove production are not fully passed through, and Chinese exam-glove price competition compresses Healthcare margins, so Adj EBITDA margin resets to 16.5% (Adj EBIT ~12.5-13%, the FY22-24 average) and stays there. Capex 3.4%, cash tax 25%, terminal growth 2%. The balance sheet (net debt/EBITDA ~1.0x) carries this case without a solvency question, which is why the bear weight is 20% and not higher.

Sheet DCF_Bear
A1: ANN.AX owner-FCF DCF -- BEAR scenario (USD millions)
A3: Year | B3: FY2026A | C3: FY2027E | D3: FY2028E | E3: FY2029E | F3: FY2030E | G3: FY2031E | H3: FY2032E | I3: FY2033E | J3: FY2034E | K3: FY2035E | L3: FY2036E
A4: Index | B4: 0 | C4: 1 | D4: 2 | E4: 3 | F4: 4 | G4: 5 | H4: 6 | I4: 7 | J4: 8 | K4: 9 | L4: 10
A5: Revenue growth YoY | C5: -0.02 | D5: 0 | E5: 0.02 | F5: 0.025 | G5: 0.025 | H5: 0.025 | I5: 0.025 | J5: 0.02 | K5: 0.02 | L5: 0.02
A6: Revenue | B6: =Assumptions!$B$14 | C6: =B6*(1+C5) | D6: =C6*(1+D5) | E6: =D6*(1+E5) | F6: =E6*(1+F5) | G6: =F6*(1+G5) | H6: =G6*(1+H5) | I6: =H6*(1+I5) | J6: =I6*(1+J5) | ... L6: =K6*(1+L5)
A7: Adj EBITDA margin (post-IFRS16) | C7: 0.175 | D7: 0.165 | E7: 0.165 | F7: 0.165 | G7: 0.165 | H7: 0.165 | I7: 0.165 | J7: 0.165 | K7: 0.165 | L7: 0.165
A8: Adjusted EBITDA | C8: =C6*C7 | D8: =D6*D7 | E8: =E6*E7 | F8: =F6*F7 | G8: =G6*G7 | H8: =H6*H7 | I8: =I6*I7 | J8: =J6*J7 | ... L8: =L6*L7
A9: SBC % of revenue | C9: 0.0055 | D9: 0.0055 | E9: 0.0055 | F9: 0.0055 | G9: 0.0055 | H9: 0.0055 | I9: 0.0055 | J9: 0.0055 | K9: 0.0055 | L9: 0.0055
A10: SBC (expensed) | C10: =-C6*C9 | D10: =-D6*D9 | E10: =-E6*E9 | F10: =-F6*F9 | G10: =-G6*G9 | H10: =-H6*H9 | I10: =-I6*I9 | J10: =-J6*J9 | ... L10: =-L6*L9
A11: Lease cost (principal + interest) | C11: =-C6*Assumptions!$B$13 | D11: =-D6*Assumptions!$B$13 | E11: =-E6*Assumptions!$B$13 | F11: =-F6*Assumptions!$B$13 | G11: =-G6*Assumptions!$B$13 | H11: =-H6*Assumptions!$B$13 | I11: =-I6*Assumptions!$B$13 | J11: =-J6*Assumptions!$B$13 | ... L11: =-L6*Assumptions!$B$13
A12: Owner EBITDA | C12: =C8+C10+C11 | D12: =D8+D10+D11 | E12: =E8+E10+E11 | F12: =F8+F10+F11 | G12: =G8+G10+G11 | H12: =H8+H10+H11 | I12: =I8+I10+I11 | J12: =J8+J10+J11 | ... L12: =L8+L10+L11
A13: D&A ex-ROU | C13: =-C6*Assumptions!$B$4 | D13: =-D6*Assumptions!$B$4 | E13: =-E6*Assumptions!$B$4 | F13: =-F6*Assumptions!$B$4 | G13: =-G6*Assumptions!$B$4 | H13: =-H6*Assumptions!$B$4 | I13: =-I6*Assumptions!$B$4 | J13: =-J6*Assumptions!$B$4 | ... L13: =-L6*Assumptions!$B$4
A14: EBIT (SBC and leases expensed) | C14: =C12+C13 | D14: =D12+D13 | E14: =E12+E13 | F14: =F12+F13 | G14: =G12+G13 | H14: =H12+H13 | I14: =I12+I13 | J14: =J12+J13 | ... L14: =L12+L13
A15: Cash tax rate | C15: 0.25 | D15: 0.25 | E15: 0.25 | F15: 0.25 | G15: 0.25 | H15: 0.25 | I15: 0.25 | J15: 0.25 | K15: 0.25 | L15: 0.25
A16: Cash tax on max(0, EBIT) | C16: =-MAX(0,C14)*C15 | D16: =-MAX(0,D14)*D15 | E16: =-MAX(0,E14)*E15 | F16: =-MAX(0,F14)*F15 | G16: =-MAX(0,G14)*G15 | H16: =-MAX(0,H14)*H15 | I16: =-MAX(0,I14)*I15 | J16: =-MAX(0,J14)*J15 | ... L16: =-MAX(0,L14)*L15
A17: NOPAT | C17: =C14+C16 | D17: =D14+D16 | E17: =E14+E16 | F17: =F14+F16 | G17: =G14+G16 | H17: =H14+H16 | I17: =I14+I16 | J17: =J14+J16 | ... L17: =L14+L16
A18: Add back D&A | C18: =-C13 | D18: =-D13 | E18: =-E13 | F18: =-F13 | G18: =-G13 | H18: =-H13 | I18: =-I13 | J18: =-J13 | ... L18: =-L13
A19: Less capex | C19: =-C6*Assumptions!$C$20 | D19: =-D6*Assumptions!$C$20 | E19: =-E6*Assumptions!$C$20 | F19: =-F6*Assumptions!$C$20 | G19: =-G6*Assumptions!$C$20 | H19: =-H6*Assumptions!$C$20 | I19: =-I6*Assumptions!$C$20 | J19: =-J6*Assumptions!$C$20 | ... L19: =-L6*Assumptions!$C$20
A20: Working capital (on revenue change) | C20: =Assumptions!$B$5*(C6-B6) | D20: =Assumptions!$B$5*(D6-C6) | E20: =Assumptions!$B$5*(E6-D6) | F20: =Assumptions!$B$5*(F6-E6) | G20: =Assumptions!$B$5*(G6-F6) | H20: =Assumptions!$B$5*(H6-G6) | I20: =Assumptions!$B$5*(I6-H6) | J20: =Assumptions!$B$5*(J6-I6) | ... L20: =Assumptions!$B$5*(L6-K6)
A21: Unlevered owner FCF | C21: =C17+C18+C19+C20 | D21: =D17+D18+D19+D20 | E21: =E17+E18+E19+E20 | F21: =F17+F18+F19+F20 | G21: =G17+G18+G19+G20 | H21: =H17+H18+H19+H20 | I21: =I17+I18+I19+I20 | J21: =J17+J18+J19+J20 | ... L21: =L17+L18+L19+L20
A22: Discount factor | C22: =1/(1+Assumptions!$B$3)^C4 | D22: =1/(1+Assumptions!$B$3)^D4 | E22: =1/(1+Assumptions!$B$3)^E4 | F22: =1/(1+Assumptions!$B$3)^F4 | G22: =1/(1+Assumptions!$B$3)^G4 | H22: =1/(1+Assumptions!$B$3)^H4 | I22: =1/(1+Assumptions!$B$3)^I4 | J22: =1/(1+Assumptions!$B$3)^J4 | ... L22: =1/(1+Assumptions!$B$3)^L4
A23: PV of FCF | C23: =C21*C22 | D23: =D21*D22 | E23: =E21*E22 | F23: =F21*F22 | G23: =G21*G22 | H23: =H21*H22 | I23: =I21*I22 | J23: =J21*J22 | ... L23: =L21*L22
A25: Memo: FCF before SBC (company-style) | C25: =C21-C10 | D25: =D21-D10 | E25: =E21-E10 | F25: =F21-F10 | G25: =G21-G10 | H25: =H21-H10 | I25: =I21-I10 | J25: =J21-J10 | ... L25: =L21-L10
A26: Memo: owner-FCF margin | C26: =C21/C6 | D26: =D21/D6 | E26: =E21/E6 | F26: =F21/F6 | G26: =G21/G6 | H26: =H21/H6 | I26: =I21/I6 | J26: =J21/J6 | ... L26: =L21/L6
A28: Sum of PV of FCF | B28: =SUM(C23:L23)
A29: Terminal growth | B29: =Assumptions!C18
A30: Terminal-year FCF x (1+g) | B30: =L21*(1+B29)
A31: Gordon TV | B31: =IF(Assumptions!B3>B29,B30/(Assumptions!B3-B29),"n/a")
A32: Cap TV (cap x FCF_10) | B32: =Assumptions!B11*L21
A33: TV used = MAX(0, MIN(Gordon, cap)) | B33: =MAX(0,MIN(B31,B32))
A34: Implied exit multiple (TV / FCF_10) | B34: =IF(L21<>0,B33/L21,"n/a")
A35: PV of TV | B35: =B33*L22
A36: Enterprise value | B36: =B28+B35
A37: Less net debt | B37: =-Assumptions!B6
A38: Less NCI | B38: =-Assumptions!B7
A39: Equity value | B39: =B36+B37+B38
A40: Fully diluted shares (m) | B40: =Assumptions!B8
A41: Value per share, USD | B41: =B39/B40
A42: Value per share, AUD | B42: =B41/Assumptions!B10
A43: Upside vs price | B43: =B42/Assumptions!B9-1
...

Sheet DCF_Base
A1: ANN.AX owner-FCF DCF -- BASE scenario (USD millions)
A3: Year | B3: FY2026A | C3: FY2027E | D3: FY2028E | E3: FY2029E | F3: FY2030E | G3: FY2031E | H3: FY2032E | I3: FY2033E | J3: FY2034E | K3: FY2035E | L3: FY2036E
A4: Index | B4: 0 | C4: 1 | D4: 2 | E4: 3 | F4: 4 | G4: 5 | H4: 6 | I4: 7 | J4: 8 | K4: 9 | L4: 10
A5: Revenue growth YoY | C5: 0.05 | D5: 0.045 | E5: 0.04 | F5: 0.035 | G5: 0.03 | H5: 0.03 | I5: 0.03 | J5: 0.03 | K5: 0.025 | L5: 0.025
A6: Revenue | B6: =Assumptions!$B$14 | C6: =B6*(1+C5) | D6: =C6*(1+D5) | E6: =D6*(1+E5) | F6: =E6*(1+F5) | G6: =F6*(1+G5) | H6: =G6*(1+H5) | I6: =H6*(1+I5) | J6: =I6*(1+J5) | ... L6: =K6*(1+L5)
A7: Adj EBITDA margin (post-IFRS16) | C7: 0.189 | D7: 0.19 | E7: 0.191 | F7: 0.192 | G7: 0.192 | H7: 0.192 | I7: 0.192 | J7: 0.192 | K7: 0.192 | L7: 0.192
A8: Adjusted EBITDA | C8: =C6*C7 | D8: =D6*D7 | E8: =E6*E7 | F8: =F6*F7 | G8: =G6*G7 | H8: =H6*H7 | I8: =I6*I7 | J8: =J6*J7 | ... L8: =L6*L7
A9: SBC % of revenue | C9: 0.0055 | D9: 0.0055 | E9: 0.0055 | F9: 0.0055 | G9: 0.0055 | H9: 0.0055 | I9: 0.0055 | J9: 0.0055 | K9: 0.0055 | L9: 0.0055
A10: SBC (expensed) | C10: =-C6*C9 | D10: =-D6*D9 | E10: =-E6*E9 | F10: =-F6*F9 | G10: =-G6*G9 | H10: =-H6*H9 | I10: =-I6*I9 | J10: =-J6*J9 | ... L10: =-L6*L9
A11: Lease cost (principal + interest) | C11: =-C6*Assumptions!$B$13 | D11: =-D6*Assumptions!$B$13 | E11: =-E6*Assumptions!$B$13 | F11: =-F6*Assumptions!$B$13 | G11: =-G6*Assumptions!$B$13 | H11: =-H6*Assumptions!$B$13 | I11: =-I6*Assumptions!$B$13 | J11: =-J6*Assumptions!$B$13 | ... L11: =-L6*Assumptions!$B$13
A12: Owner EBITDA | C12: =C8+C10+C11 | D12: =D8+D10+D11 | E12: =E8+E10+E11 | F12: =F8+F10+F11 | G12: =G8+G10+G11 | H12: =H8+H10+H11 | I12: =I8+I10+I11 | J12: =J8+J10+J11 | ... L12: =L8+L10+L11
A13: D&A ex-ROU | C13: =-C6*Assumptions!$B$4 | D13: =-D6*Assumptions!$B$4 | E13: =-E6*Assumptions!$B$4 | F13: =-F6*Assumptions!$B$4 | G13: =-G6*Assumptions!$B$4 | H13: =-H6*Assumptions!$B$4 | I13: =-I6*Assumptions!$B$4 | J13: =-J6*Assumptions!$B$4 | ... L13: =-L6*Assumptions!$B$4
A14: EBIT (SBC and leases expensed) | C14: =C12+C13 | D14: =D12+D13 | E14: =E12+E13 | F14: =F12+F13 | G14: =G12+G13 | H14: =H12+H13 | I14: =I12+I13 | J14: =J12+J13 | ... L14: =L12+L13
A15: Cash tax rate | C15: 0.24 | D15: 0.24 | E15: 0.24 | F15: 0.24 | G15: 0.24 | H15: 0.24 | I15: 0.24 | J15: 0.24 | K15: 0.24 | L15: 0.24
A16: Cash tax on max(0, EBIT) | C16: =-MAX(0,C14)*C15 | D16: =-MAX(0,D14)*D15 | E16: =-MAX(0,E14)*E15 | F16: =-MAX(0,F14)*F15 | G16: =-MAX(0,G14)*G15 | H16: =-MAX(0,H14)*H15 | I16: =-MAX(0,I14)*I15 | J16: =-MAX(0,J14)*J15 | ... L16: =-MAX(0,L14)*L15
A17: NOPAT | C17: =C14+C16 | D17: =D14+D16 | E17: =E14+E16 | F17: =F14+F16 | G17: =G14+G16 | H17: =H14+H16 | I17: =I14+I16 | J17: =J14+J16 | ... L17: =L14+L16
A18: Add back D&A | C18: =-C13 | D18: =-D13 | E18: =-E13 | F18: =-F13 | G18: =-G13 | H18: =-H13 | I18: =-I13 | J18: =-J13 | ... L18: =-L13
A19: Less capex | C19: =-C6*Assumptions!$D$20 | D19: =-D6*Assumptions!$D$20 | E19: =-E6*Assumptions!$D$20 | F19: =-F6*Assumptions!$D$20 | G19: =-G6*Assumptions!$D$20 | H19: =-H6*Assumptions!$D$20 | I19: =-I6*Assumptions!$D$20 | J19: =-J6*Assumptions!$D$20 | ... L19: =-L6*Assumptions!$D$20
A20: Working capital (on revenue change) | C20: =Assumptions!$B$5*(C6-B6) | D20: =Assumptions!$B$5*(D6-C6) | E20: =Assumptions!$B$5*(E6-D6) | F20: =Assumptions!$B$5*(F6-E6) | G20: =Assumptions!$B$5*(G6-F6) | H20: =Assumptions!$B$5*(H6-G6) | I20: =Assumptions!$B$5*(I6-H6) | J20: =Assumptions!$B$5*(J6-I6) | ... L20: =Assumptions!$B$5*(L6-K6)
A21: Unlevered owner FCF | C21: =C17+C18+C19+C20 | D21: =D17+D18+D19+D20 | E21: =E17+E18+E19+E20 | F21: =F17+F18+F19+F20 | G21: =G17+G18+G19+G20 | H21: =H17+H18+H19+H20 | I21: =I17+I18+I19+I20 | J21: =J17+J18+J19+J20 | ... L21: =L17+L18+L19+L20
A22: Discount factor | C22: =1/(1+Assumptions!$B$3)^C4 | D22: =1/(1+Assumptions!$B$3)^D4 | E22: =1/(1+Assumptions!$B$3)^E4 | F22: =1/(1+Assumptions!$B$3)^F4 | G22: =1/(1+Assumptions!$B$3)^G4 | H22: =1/(1+Assumptions!$B$3)^H4 | I22: =1/(1+Assumptions!$B$3)^I4 | J22: =1/(1+Assumptions!$B$3)^J4 | ... L22: =1/(1+Assumptions!$B$3)^L4
A23: PV of FCF | C23: =C21*C22 | D23: =D21*D22 | E23: =E21*E22 | F23: =F21*F22 | G23: =G21*G22 | H23: =H21*H22 | I23: =I21*I22 | J23: =J21*J22 | ... L23: =L21*L22
A25: Memo: FCF before SBC (company-style) | C25: =C21-C10 | D25: =D21-D10 | E25: =E21-E10 | F25: =F21-F10 | G25: =G21-G10 | H25: =H21-H10 | I25: =I21-I10 | J25: =J21-J10 | ... L25: =L21-L10
A26: Memo: owner-FCF margin | C26: =C21/C6 | D26: =D21/D6 | E26: =E21/E6 | F26: =F21/F6 | G26: =G21/G6 | H26: =H21/H6 | I26: =I21/I6 | J26: =J21/J6 | ... L26: =L21/L6
A28: Sum of PV of FCF | B28: =SUM(C23:L23)
A29: Terminal growth | B29: =Assumptions!D18
A30: Terminal-year FCF x (1+g) | B30: =L21*(1+B29)
A31: Gordon TV | B31: =IF(Assumptions!B3>B29,B30/(Assumptions!B3-B29),"n/a")
A32: Cap TV (cap x FCF_10) | B32: =Assumptions!B11*L21
A33: TV used = MAX(0, MIN(Gordon, cap)) | B33: =MAX(0,MIN(B31,B32))
A34: Implied exit multiple (TV / FCF_10) | B34: =IF(L21<>0,B33/L21,"n/a")
A35: PV of TV | B35: =B33*L22
A36: Enterprise value | B36: =B28+B35
A37: Less net debt | B37: =-Assumptions!B6
A38: Less NCI | B38: =-Assumptions!B7
A39: Equity value | B39: =B36+B37+B38
A40: Fully diluted shares (m) | B40: =Assumptions!B8
A41: Value per share, USD | B41: =B39/B40
A42: Value per share, AUD | B42: =B41/Assumptions!B10
A43: Upside vs price | B43: =B42/Assumptions!B9-1
...

Sheet DCF_Bull
A1: ANN.AX owner-FCF DCF -- BULL scenario (USD millions)
A3: Year | B3: FY2026A | C3: FY2027E | D3: FY2028E | E3: FY2029E | F3: FY2030E | G3: FY2031E | H3: FY2032E | I3: FY2033E | J3: FY2034E | K3: FY2035E | L3: FY2036E
A4: Index | B4: 0 | C4: 1 | D4: 2 | E4: 3 | F4: 4 | G4: 5 | H4: 6 | I4: 7 | J4: 8 | K4: 9 | L4: 10
A5: Revenue growth YoY | C5: 0.08 | D5: 0.07 | E5: 0.06 | F5: 0.055 | G5: 0.05 | H5: 0.045 | I5: 0.04 | J5: 0.04 | K5: 0.035 | L5: 0.035
A6: Revenue | B6: =Assumptions!$B$14 | C6: =B6*(1+C5) | D6: =C6*(1+D5) | E6: =D6*(1+E5) | F6: =E6*(1+F5) | G6: =F6*(1+G5) | H6: =G6*(1+H5) | I6: =H6*(1+I5) | J6: =I6*(1+J5) | ... L6: =K6*(1+L5)
A7: Adj EBITDA margin (post-IFRS16) | C7: 0.193 | D7: 0.198 | E7: 0.203 | F7: 0.207 | G7: 0.21 | H7: 0.21 | I7: 0.21 | J7: 0.21 | K7: 0.21 | L7: 0.21
A8: Adjusted EBITDA | C8: =C6*C7 | D8: =D6*D7 | E8: =E6*E7 | F8: =F6*F7 | G8: =G6*G7 | H8: =H6*H7 | I8: =I6*I7 | J8: =J6*J7 | ... L8: =L6*L7
A9: SBC % of revenue | C9: 0.0055 | D9: 0.0055 | E9: 0.0055 | F9: 0.0055 | G9: 0.0055 | H9: 0.0055 | I9: 0.0055 | J9: 0.0055 | K9: 0.0055 | L9: 0.0055
A10: SBC (expensed) | C10: =-C6*C9 | D10: =-D6*D9 | E10: =-E6*E9 | F10: =-F6*F9 | G10: =-G6*G9 | H10: =-H6*H9 | I10: =-I6*I9 | J10: =-J6*J9 | ... L10: =-L6*L9
A11: Lease cost (principal + interest) | C11: =-C6*Assumptions!$B$13 | D11: =-D6*Assumptions!$B$13 | E11: =-E6*Assumptions!$B$13 | F11: =-F6*Assumptions!$B$13 | G11: =-G6*Assumptions!$B$13 | H11: =-H6*Assumptions!$B$13 | I11: =-I6*Assumptions!$B$13 | J11: =-J6*Assumptions!$B$13 | ... L11: =-L6*Assumptions!$B$13
A12: Owner EBITDA | C12: =C8+C10+C11 | D12: =D8+D10+D11 | E12: =E8+E10+E11 | F12: =F8+F10+F11 | G12: =G8+G10+G11 | H12: =H8+H10+H11 | I12: =I8+I10+I11 | J12: =J8+J10+J11 | ... L12: =L8+L10+L11
A13: D&A ex-ROU | C13: =-C6*Assumptions!$B$4 | D13: =-D6*Assumptions!$B$4 | E13: =-E6*Assumptions!$B$4 | F13: =-F6*Assumptions!$B$4 | G13: =-G6*Assumptions!$B$4 | H13: =-H6*Assumptions!$B$4 | I13: =-I6*Assumptions!$B$4 | J13: =-J6*Assumptions!$B$4 | ... L13: =-L6*Assumptions!$B$4
A14: EBIT (SBC and leases expensed) | C14: =C12+C13 | D14: =D12+D13 | E14: =E12+E13 | F14: =F12+F13 | G14: =G12+G13 | H14: =H12+H13 | I14: =I12+I13 | J14: =J12+J13 | ... L14: =L12+L13
A15: Cash tax rate | C15: 0.235 | D15: 0.235 | E15: 0.235 | F15: 0.235 | G15: 0.235 | H15: 0.235 | I15: 0.235 | J15: 0.235 | K15: 0.235 | L15: 0.235
A16: Cash tax on max(0, EBIT) | C16: =-MAX(0,C14)*C15 | D16: =-MAX(0,D14)*D15 | E16: =-MAX(0,E14)*E15 | F16: =-MAX(0,F14)*F15 | G16: =-MAX(0,G14)*G15 | H16: =-MAX(0,H14)*H15 | I16: =-MAX(0,I14)*I15 | J16: =-MAX(0,J14)*J15 | ... L16: =-MAX(0,L14)*L15
A17: NOPAT | C17: =C14+C16 | D17: =D14+D16 | E17: =E14+E16 | F17: =F14+F16 | G17: =G14+G16 | H17: =H14+H16 | I17: =I14+I16 | J17: =J14+J16 | ... L17: =L14+L16
A18: Add back D&A | C18: =-C13 | D18: =-D13 | E18: =-E13 | F18: =-F13 | G18: =-G13 | H18: =-H13 | I18: =-I13 | J18: =-J13 | ... L18: =-L13
A19: Less capex | C19: =-C6*Assumptions!$E$20 | D19: =-D6*Assumptions!$E$20 | E19: =-E6*Assumptions!$E$20 | F19: =-F6*Assumptions!$E$20 | G19: =-G6*Assumptions!$E$20 | H19: =-H6*Assumptions!$E$20 | I19: =-I6*Assumptions!$E$20 | J19: =-J6*Assumptions!$E$20 | ... L19: =-L6*Assumptions!$E$20
A20: Working capital (on revenue change) | C20: =Assumptions!$B$5*(C6-B6) | D20: =Assumptions!$B$5*(D6-C6) | E20: =Assumptions!$B$5*(E6-D6) | F20: =Assumptions!$B$5*(F6-E6) | G20: =Assumptions!$B$5*(G6-F6) | H20: =Assumptions!$B$5*(H6-G6) | I20: =Assumptions!$B$5*(I6-H6) | J20: =Assumptions!$B$5*(J6-I6) | ... L20: =Assumptions!$B$5*(L6-K6)
A21: Unlevered owner FCF | C21: =C17+C18+C19+C20 | D21: =D17+D18+D19+D20 | E21: =E17+E18+E19+E20 | F21: =F17+F18+F19+F20 | G21: =G17+G18+G19+G20 | H21: =H17+H18+H19+H20 | I21: =I17+I18+I19+I20 | J21: =J17+J18+J19+J20 | ... L21: =L17+L18+L19+L20
A22: Discount factor | C22: =1/(1+Assumptions!$B$3)^C4 | D22: =1/(1+Assumptions!$B$3)^D4 | E22: =1/(1+Assumptions!$B$3)^E4 | F22: =1/(1+Assumptions!$B$3)^F4 | G22: =1/(1+Assumptions!$B$3)^G4 | H22: =1/(1+Assumptions!$B$3)^H4 | I22: =1/(1+Assumptions!$B$3)^I4 | J22: =1/(1+Assumptions!$B$3)^J4 | ... L22: =1/(1+Assumptions!$B$3)^L4
A23: PV of FCF | C23: =C21*C22 | D23: =D21*D22 | E23: =E21*E22 | F23: =F21*F22 | G23: =G21*G22 | H23: =H21*H22 | I23: =I21*I22 | J23: =J21*J22 | ... L23: =L21*L22
A25: Memo: FCF before SBC (company-style) | C25: =C21-C10 | D25: =D21-D10 | E25: =E21-E10 | F25: =F21-F10 | G25: =G21-G10 | H25: =H21-H10 | I25: =I21-I10 | J25: =J21-J10 | ... L25: =L21-L10
A26: Memo: owner-FCF margin | C26: =C21/C6 | D26: =D21/D6 | E26: =E21/E6 | F26: =F21/F6 | G26: =G21/G6 | H26: =H21/H6 | I26: =I21/I6 | J26: =J21/J6 | ... L26: =L21/L6
A28: Sum of PV of FCF | B28: =SUM(C23:L23)
A29: Terminal growth | B29: =Assumptions!E18
A30: Terminal-year FCF x (1+g) | B30: =L21*(1+B29)
A31: Gordon TV | B31: =IF(Assumptions!B3>B29,B30/(Assumptions!B3-B29),"n/a")
A32: Cap TV (cap x FCF_10) | B32: =Assumptions!B11*L21
A33: TV used = MAX(0, MIN(Gordon, cap)) | B33: =MAX(0,MIN(B31,B32))
A34: Implied exit multiple (TV / FCF_10) | B34: =IF(L21<>0,B33/L21,"n/a")
A35: PV of TV | B35: =B33*L22
A36: Enterprise value | B36: =B28+B35
A37: Less net debt | B37: =-Assumptions!B6
A38: Less NCI | B38: =-Assumptions!B7
A39: Equity value | B39: =B36+B37+B38
A40: Fully diluted shares (m) | B40: =Assumptions!B8
A41: Value per share, USD | B41: =B39/B40
A42: Value per share, AUD | B42: =B41/Assumptions!B10
A43: Upside vs price | B43: =B42/Assumptions!B9-1
...

Sheet FCF_Quality
A1: Reported FCF reconciled to owner FCF (USD millions; links to Actuals)
A3: Line | B3: FY2016 | C3: FY2017 | D3: FY2018 | E3: FY2019 | F3: FY2020 | G3: FY2021 | H3: FY2022 | I3: FY2023 | J3: FY2024 | K3: FY2025 | L3: FY2026
A4: Free cash flow, company definition (OCF - capex) | B4: =Actuals!B5-Actuals!B6 | C4: =Actuals!C5-Actuals!C6 | D4: =Actuals!D5-Actuals!D6 | E4: =Actuals!E5-Actuals!E6 | F4: =Actuals!F5-Actuals!F6 | G4: =Actuals!G5-Actuals!G6 | H4: =Actuals!H5-Actuals!H6 | I4: =Actuals!I5-Actuals!I6 | ... L4: =Actuals!L5-Actuals!L6
A5: less: SBC | B5: =-Actuals!B7 | C5: =-Actuals!C7 | D5: =-Actuals!D7 | E5: =-Actuals!E7 | F5: =-Actuals!F7 | G5: =-Actuals!G7 | H5: =-Actuals!H7 | I5: =-Actuals!I7 | ... L5: =-Actuals!L7
A6: less: interest received | B6: =-Actuals!B8 | C6: =-Actuals!C8 | D6: =-Actuals!D8 | E6: =-Actuals!E8 | F6: =-Actuals!F8 | G6: =-Actuals!G8 | H6: =-Actuals!H8 | I6: =-Actuals!I8 | ... L6: =-Actuals!L8
A7: less: lease principal | B7: =-Actuals!B9 | C7: =-Actuals!C9 | D7: =-Actuals!D9 | E7: =-Actuals!E9 | F7: =-Actuals!F9 | G7: =-Actuals!G9 | H7: =-Actuals!H9 | I7: =-Actuals!I9 | ... L7: =-Actuals!L9
A8: less: lease interest | B8: =-Actuals!B10 | C8: =-Actuals!C10 | D8: =-Actuals!D10 | E8: =-Actuals!E10 | F8: =-Actuals!F10 | G8: =-Actuals!G10 | H8: =-Actuals!H10 | I8: =-Actuals!I10 | ... L8: =-Actuals!L10
A9: Owner FCF (sum of the above) | B9: =SUM(B4:B8) | C9: =SUM(C4:C8) | D9: =SUM(D4:D8) | E9: =SUM(E4:E8) | F9: =SUM(F4:F8) | G9: =SUM(G4:G8) | H9: =SUM(H4:H8) | I9: =SUM(I4:I8) | ... L9: =SUM(L4:L8)
A10: Reported FCF margin | B10: =B4/Actuals!B4 | C10: =C4/Actuals!C4 | D10: =D4/Actuals!D4 | E10: =E4/Actuals!E4 | F10: =F4/Actuals!F4 | G10: =G4/Actuals!G4 | H10: =H4/Actuals!H4 | I10: =I4/Actuals!I4 | ... L10: =L4/Actuals!L4
A11: Owner FCF margin | B11: =B9/Actuals!B4 | C11: =C9/Actuals!C4 | D11: =D9/Actuals!D4 | E11: =E9/Actuals!E4 | F11: =F9/Actuals!F4 | G11: =G9/Actuals!G4 | H11: =H9/Actuals!H4 | I11: =I9/Actuals!I4 | ... L11: =L9/Actuals!L4
A12: Memo: cash tax paid / NPAT (flag when far from ~0.3) | B12: =Actuals!B12/Actuals!B11 | C12: =Actuals!C12/Actuals!C11 | D12: =Actuals!D12/Actuals!D11 | E12: =Actuals!E12/Actuals!E11 | F12: =Actuals!F12/Actuals!F11 | G12: =Actuals!G12/Actuals!G11 | H12: =Actuals!H12/Actuals!H11 | I12: =Actuals!I12/Actuals!I11 | ... L12: =Actuals!L12/Actuals!L11
A15: Notes
A16: FY2018 includes the part-year Sexual Wellness business (sold FY18); FY2021 SBC of 30.1 is the CEO-succession one-off; FY2024 is the destock-trough inventory release; FY2025 carries the KBU inventory build; FY2026 is a release year with capex at a decade-low 2.3% of sales.
A17: Owner FCF FY2026 = 294.8 ties to the JSON's inputs.last_fcf. The DCF's Y1 owner FCF (~211) is the component-built normalized figure, deliberately below the FY26 print.

Sheet Valuation
A1: ANN.AX valuation summary (per-share values in AUD unless stated)
A3: Scenario | B3: Value/share AUD | C3: Value/share USD | D3: Upside vs price | E3: Probability | F3: Street value AUD | G3: Terminal % of EV | H3: Exit multiple
A4: Bear | B4: =DCF_Bear!B42 | C4: =DCF_Bear!B41 | D4: =DCF_Bear!B43 | E4: =Assumptions!C19 | F4: =DCF_Bear!B47 | G4: =DCF_Bear!B48 | H4: =DCF_Bear!B34
A5: Base | B5: =DCF_Base!B42 | C5: =DCF_Base!B41 | D5: =DCF_Base!B43 | E5: =Assumptions!D19 | F5: =DCF_Base!B47 | G5: =DCF_Base!B48 | H5: =DCF_Base!B34
A6: Bull | B6: =DCF_Bull!B42 | C6: =DCF_Bull!B41 | D6: =DCF_Bull!B43 | E6: =Assumptions!E19 | F6: =DCF_Bull!B47 | G6: =DCF_Bull!B48 | H6: =DCF_Bull!B34
A8: Probability-weighted value, AUD | B8: =SUMPRODUCT(B4:B6,E4:E6)
A9: Probability-weighted value, USD | B9: =SUMPRODUCT(C4:C6,E4:E6)
A10: Street weighted value, AUD | B10: =SUMPRODUCT(F4:F6,E4:E6)
A11: Current price, AUD | B11: =Assumptions!B9
A12: Margin of safety (1 - price/weighted) | B12: =1-B11/B8
A13: Band position (price - house)/(street - house) | B13: =IF(B10<>B8,(B11-B8)/(B10-B8),"n/a")
A16: 15% hurdle entry prices, AUD (TV rebuilt at the hurdle)
A17: Scenario | B17: House entry AUD | C17: Street entry AUD | D17: Probability
A18: Bear | B18: =IF(Assumptions!$B$12>Assumptions!$C$18,(NPV(Assumptions!$B$12,DCF_Bear!$C$21:$L$21)+MAX(0,MIN(DCF_Bear!$L$21*(1+Assumptions!$C$18)/(Assumptions!$B$12-Assumptions!$C$18),Assumptions!$B$11*DCF_Bear!$L$21))/(1+Assumptions!$B$12)^10-Assumptions!$B$6-Assumptions!$B$7)/Assumptions!$B$8/Assumptions!$B$10,"n/a") | C18: =IF(Assumptions!$B$12>Assumptions!$C$18,(NPV(Assumptions!$B$12,DCF_Bear!$C$21:$L$21)+MAX(0,MIN(DCF_Bear!$L$21*(1+Assumptions!$C$18)/(Assumptions!$B$12-Assumptions!$C$18),Assumptions!$B$11*DCF_Bear!$L$21))/(1+Assumptions!$B$12)^10-Assumptions!$B$6-Assumptions!$B$7-NPV(Assumptions!$B$12,DCF_Bear!$C$10:$L$10)+(-DCF_Bear!$L$10*(1+Assumptions!$C$18)/(Assumptions!$B$12-Assumptions!$C$18))/(1+Assumptions!$B$12)^10)/Assumptions!$B$8/Assumptions!$B$10,"n/a") | D18: =Assumptions!C19
A19: Base | B19: =IF(Assumptions!$B$12>Assumptions!$D$18,(NPV(Assumptions!$B$12,DCF_Base!$C$21:$L$21)+MAX(0,MIN(DCF_Base!$L$21*(1+Assumptions!$D$18)/(Assumptions!$B$12-Assumptions!$D$18),Assumptions!$B$11*DCF_Base!$L$21))/(1+Assumptions!$B$12)^10-Assumptions!$B$6-Assumptions!$B$7)/Assumptions!$B$8/Assumptions!$B$10,"n/a") | C19: =IF(Assumptions!$B$12>Assumptions!$D$18,(NPV(Assumptions!$B$12,DCF_Base!$C$21:$L$21)+MAX(0,MIN(DCF_Base!$L$21*(1+Assumptions!$D$18)/(Assumptions!$B$12-Assumptions!$D$18),Assumptions!$B$11*DCF_Base!$L$21))/(1+Assumptions!$B$12)^10-Assumptions!$B$6-Assumptions!$B$7-NPV(Assumptions!$B$12,DCF_Base!$C$10:$L$10)+(-DCF_Base!$L$10*(1+Assumptions!$D$18)/(Assumptions!$B$12-Assumptions!$D$18))/(1+Assumptions!$B$12)^10)/Assumptions!$B$8/Assumptions!$B$10,"n/a") | D19: =Assumptions!D19
A20: Bull | B20: =IF(Assumptions!$B$12>Assumptions!$E$18,(NPV(Assumptions!$B$12,DCF_Bull!$C$21:$L$21)+MAX(0,MIN(DCF_Bull!$L$21*(1+Assumptions!$E$18)/(Assumptions!$B$12-Assumptions!$E$18),Assumptions!$B$11*DCF_Bull!$L$21))/(1+Assumptions!$B$12)^10-Assumptions!$B$6-Assumptions!$B$7)/Assumptions!$B$8/Assumptions!$B$10,"n/a") | C20: =IF(Assumptions!$B$12>Assumptions!$E$18,(NPV(Assumptions!$B$12,DCF_Bull!$C$21:$L$21)+MAX(0,MIN(DCF_Bull!$L$21*(1+Assumptions!$E$18)/(Assumptions!$B$12-Assumptions!$E$18),Assumptions!$B$11*DCF_Bull!$L$21))/(1+Assumptions!$B$12)^10-Assumptions!$B$6-Assumptions!$B$7-NPV(Assumptions!$B$12,DCF_Bull!$C$10:$L$10)+(-DCF_Bull!$L$10*(1+Assumptions!$E$18)/(Assumptions!$B$12-Assumptions!$E$18))/(1+Assumptions!$B$12)^10)/Assumptions!$B$8/Assumptions!$B$10,"n/a") | D20: =Assumptions!E19
A21: Weighted entry price (buy-below), AUD | B21: =SUMPRODUCT(B18:B20,D18:D20) | C21: =SUMPRODUCT(C18:C20,D18:D20)
A24: Required-return table, base case, AUD (TV rebuilt at each rate)
A25: Required return | B25: Value/share AUD
A26: =Assumptions!$B$3 | B26: =IF($A$26>Assumptions!$D$18,(NPV($A$26,DCF_Base!$C$21:$L$21)+MAX(0,MIN(DCF_Base!$L$21*(1+Assumptions!$D$18)/($A$26-Assumptions!$D$18),Assumptions!$B$11*DCF_Base!$L$21))/(1+$A$26)^10-Assumptions!$B$6-Assumptions!$B$7)/Assumptions!$B$8/Assumptions!$B$10,"n/a") | C26: model WACC; must equal DCF_Base!B42
A27: 0.09 | B27: =IF($A$27>Assumptions!$D$18,(NPV($A$27,DCF_Base!$C$21:$L$21)+MAX(0,MIN(DCF_Base!$L$21*(1+Assumptions!$D$18)/($A$27-Assumptions!$D$18),Assumptions!$B$11*DCF_Base!$L$21))/(1+$A$27)^10-Assumptions!$B$6-Assumptions!$B$7)/Assumptions!$B$8/Assumptions!$B$10,"n/a")
A28: 0.1 | B28: =IF($A$28>Assumptions!$D$18,(NPV($A$28,DCF_Base!$C$21:$L$21)+MAX(0,MIN(DCF_Base!$L$21*(1+Assumptions!$D$18)/($A$28-Assumptions!$D$18),Assumptions!$B$11*DCF_Base!$L$21))/(1+$A$28)^10-Assumptions!$B$6-Assumptions!$B$7)/Assumptions!$B$8/Assumptions!$B$10,"n/a")
A29: 0.11 | B29: =IF($A$29>Assumptions!$D$18,(NPV($A$29,DCF_Base!$C$21:$L$21)+MAX(0,MIN(DCF_Base!$L$21*(1+Assumptions!$D$18)/($A$29-Assumptions!$D$18),Assumptions!$B$11*DCF_Base!$L$21))/(1+$A$29)^10-Assumptions!$B$6-Assumptions!$B$7)/Assumptions!$B$8/Assumptions!$B$10,"n/a")
A30: 0.12 | B30: =IF($A$30>Assumptions!$D$18,(NPV($A$30,DCF_Base!$C$21:$L$21)+MAX(0,MIN(DCF_Base!$L$21*(1+Assumptions!$D$18)/($A$30-Assumptions!$D$18),Assumptions!$B$11*DCF_Base!$L$21))/(1+$A$30)^10-Assumptions!$B$6-Assumptions!$B$7)/Assumptions!$B$8/Assumptions!$B$10,"n/a")
A31: 0.15 | B31: =IF($A$31>Assumptions!$D$18,(NPV($A$31,DCF_Base!$C$21:$L$21)+MAX(0,MIN(DCF_Base!$L$21*(1+Assumptions!$D$18)/($A$31-Assumptions!$D$18),Assumptions!$B$11*DCF_Base!$L$21))/(1+$A$31)^10-Assumptions!$B$6-Assumptions!$B$7)/Assumptions!$B$8/Assumptions!$B$10,"n/a") | C31: must equal the base hurdle entry price in B19
A34: Sensitivity, base case, AUD: rows WACC, columns terminal growth (TV rebuilt per cell)
B35: 0.015 | C35: 0.02 | D35: 0.025 | E35: 0.03 | F35: 0.035
A36: 0.065 | B36: =IF($A36>B$35,(NPV($A36,DCF_Base!$C$21:$L$21)+MAX(0,MIN(DCF_Base!$L$21*(1+B$35)/($A36-B$35),Assumptions!$B$11*DCF_Base!$L$21))/(1+$A36)^10-Assumptions!$B$6-Assumptions!$B$7)/Assumptions!$B$8/Assumptions!$B$10,"n/a") | C36: =IF($A36>C$35,(NPV($A36,DCF_Base!$C$21:$L$21)+MAX(0,MIN(DCF_Base!$L$21*(1+C$35)/($A36-C$35),Assumptions!$B$11*DCF_Base!$L$21))/(1+$A36)^10-Assumptions!$B$6-Assumptions!$B$7)/Assumptions!$B$8/Assumptions!$B$10,"n/a") | D36: =IF($A36>D$35,(NPV($A36,DCF_Base!$C$21:$L$21)+MAX(0,MIN(DCF_Base!$L$21*(1+D$35)/($A36-D$35),Assumptions!$B$11*DCF_Base!$L$21))/(1+$A36)^10-Assumptions!$B$6-Assumptions!$B$7)/Assumptions!$B$8/Assumptions!$B$10,"n/a") | E36: =IF($A36>E$35,(NPV($A36,DCF_Base!$C$21:$L$21)+MAX(0,MIN(DCF_Base!$L$21*(1+E$35)/($A36-E$35),Assumptions!$B$11*DCF_Base!$L$21))/(1+$A36)^10-Assumptions!$B$6-Assumptions!$B$7)/Assumptions!$B$8/Assumptions!$B$10,"n/a") | F36: =IF($A36>F$35,(NPV($A36,DCF_Base!$C$21:$L$21)+MAX(0,MIN(DCF_Base!$L$21*(1+F$35)/($A36-F$35),Assumptions!$B$11*DCF_Base!$L$21))/(1+$A36)^10-Assumptions!$B$6-Assumptions!$B$7)/Assumptions!$B$8/Assumptions!$B$10,"n/a")
A37: 0.075 | B37: =IF($A37>B$35,(NPV($A37,DCF_Base!$C$21:$L$21)+MAX(0,MIN(DCF_Base!$L$21*(1+B$35)/($A37-B$35),Assumptions!$B$11*DCF_Base!$L$21))/(1+$A37)^10-Assumptions!$B$6-Assumptions!$B$7)/Assumptions!$B$8/Assumptions!$B$10,"n/a") | C37: =IF($A37>C$35,(NPV($A37,DCF_Base!$C$21:$L$21)+MAX(0,MIN(DCF_Base!$L$21*(1+C$35)/($A37-C$35),Assumptions!$B$11*DCF_Base!$L$21))/(1+$A37)^10-Assumptions!$B$6-Assumptions!$B$7)/Assumptions!$B$8/Assumptions!$B$10,"n/a") | D37: =IF($A37>D$35,(NPV($A37,DCF_Base!$C$21:$L$21)+MAX(0,MIN(DCF_Base!$L$21*(1+D$35)/($A37-D$35),Assumptions!$B$11*DCF_Base!$L$21))/(1+$A37)^10-Assumptions!$B$6-Assumptions!$B$7)/Assumptions!$B$8/Assumptions!$B$10,"n/a") | E37: =IF($A37>E$35,(NPV($A37,DCF_Base!$C$21:$L$21)+MAX(0,MIN(DCF_Base!$L$21*(1+E$35)/($A37-E$35),Assumptions!$B$11*DCF_Base!$L$21))/(1+$A37)^10-Assumptions!$B$6-Assumptions!$B$7)/Assumptions!$B$8/Assumptions!$B$10,"n/a") | F37: =IF($A37>F$35,(NPV($A37,DCF_Base!$C$21:$L$21)+MAX(0,MIN(DCF_Base!$L$21*(1+F$35)/($A37-F$35),Assumptions!$B$11*DCF_Base!$L$21))/(1+$A37)^10-Assumptions!$B$6-Assumptions!$B$7)/Assumptions!$B$8/Assumptions!$B$10,"n/a")
A38: 0.085 | B38: =IF($A38>B$35,(NPV($A38,DCF_Base!$C$21:$L$21)+MAX(0,MIN(DCF_Base!$L$21*(1+B$35)/($A38-B$35),Assumptions!$B$11*DCF_Base!$L$21))/(1+$A38)^10-Assumptions!$B$6-Assumptions!$B$7)/Assumptions!$B$8/Assumptions!$B$10,"n/a") | C38: =IF($A38>C$35,(NPV($A38,DCF_Base!$C$21:$L$21)+MAX(0,MIN(DCF_Base!$L$21*(1+C$35)/($A38-C$35),Assumptions!$B$11*DCF_Base!$L$21))/(1+$A38)^10-Assumptions!$B$6-Assumptions!$B$7)/Assumptions!$B$8/Assumptions!$B$10,"n/a") | D38: =IF($A38>D$35,(NPV($A38,DCF_Base!$C$21:$L$21)+MAX(0,MIN(DCF_Base!$L$21*(1+D$35)/($A38-D$35),Assumptions!$B$11*DCF_Base!$L$21))/(1+$A38)^10-Assumptions!$B$6-Assumptions!$B$7)/Assumptions!$B$8/Assumptions!$B$10,"n/a") | E38: =IF($A38>E$35,(NPV($A38,DCF_Base!$C$21:$L$21)+MAX(0,MIN(DCF_Base!$L$21*(1+E$35)/($A38-E$35),Assumptions!$B$11*DCF_Base!$L$21))/(1+$A38)^10-Assumptions!$B$6-Assumptions!$B$7)/Assumptions!$B$8/Assumptions!$B$10,"n/a") | F38: =IF($A38>F$35,(NPV($A38,DCF_Base!$C$21:$L$21)+MAX(0,MIN(DCF_Base!$L$21*(1+F$35)/($A38-F$35),Assumptions!$B$11*DCF_Base!$L$21))/(1+$A38)^10-Assumptions!$B$6-Assumptions!$B$7)/Assumptions!$B$8/Assumptions!$B$10,"n/a")
A39: 0.095 | B39: =IF($A39>B$35,(NPV($A39,DCF_Base!$C$21:$L$21)+MAX(0,MIN(DCF_Base!$L$21*(1+B$35)/($A39-B$35),Assumptions!$B$11*DCF_Base!$L$21))/(1+$A39)^10-Assumptions!$B$6-Assumptions!$B$7)/Assumptions!$B$8/Assumptions!$B$10,"n/a") | C39: =IF($A39>C$35,(NPV($A39,DCF_Base!$C$21:$L$21)+MAX(0,MIN(DCF_Base!$L$21*(1+C$35)/($A39-C$35),Assumptions!$B$11*DCF_Base!$L$21))/(1+$A39)^10-Assumptions!$B$6-Assumptions!$B$7)/Assumptions!$B$8/Assumptions!$B$10,"n/a") | D39: =IF($A39>D$35,(NPV($A39,DCF_Base!$C$21:$L$21)+MAX(0,MIN(DCF_Base!$L$21*(1+D$35)/($A39-D$35),Assumptions!$B$11*DCF_Base!$L$21))/(1+$A39)^10-Assumptions!$B$6-Assumptions!$B$7)/Assumptions!$B$8/Assumptions!$B$10,"n/a") | E39: =IF($A39>E$35,(NPV($A39,DCF_Base!$C$21:$L$21)+MAX(0,MIN(DCF_Base!$L$21*(1+E$35)/($A39-E$35),Assumptions!$B$11*DCF_Base!$L$21))/(1+$A39)^10-Assumptions!$B$6-Assumptions!$B$7)/Assumptions!$B$8/Assumptions!$B$10,"n/a") | F39: =IF($A39>F$35,(NPV($A39,DCF_Base!$C$21:$L$21)+MAX(0,MIN(DCF_Base!$L$21*(1+F$35)/($A39-F$35),Assumptions!$B$11*DCF_Base!$L$21))/(1+$A39)^10-Assumptions!$B$6-Assumptions!$B$7)/Assumptions!$B$8/Assumptions!$B$10,"n/a")
A40: 0.105 | B40: =IF($A40>B$35,(NPV($A40,DCF_Base!$C$21:$L$21)+MAX(0,MIN(DCF_Base!$L$21*(1+B$35)/($A40-B$35),Assumptions!$B$11*DCF_Base!$L$21))/(1+$A40)^10-Assumptions!$B$6-Assumptions!$B$7)/Assumptions!$B$8/Assumptions!$B$10,"n/a") | C40: =IF($A40>C$35,(NPV($A40,DCF_Base!$C$21:$L$21)+MAX(0,MIN(DCF_Base!$L$21*(1+C$35)/($A40-C$35),Assumptions!$B$11*DCF_Base!$L$21))/(1+$A40)^10-Assumptions!$B$6-Assumptions!$B$7)/Assumptions!$B$8/Assumptions!$B$10,"n/a") | D40: =IF($A40>D$35,(NPV($A40,DCF_Base!$C$21:$L$21)+MAX(0,MIN(DCF_Base!$L$21*(1+D$35)/($A40-D$35),Assumptions!$B$11*DCF_Base!$L$21))/(1+$A40)^10-Assumptions!$B$6-Assumptions!$B$7)/Assumptions!$B$8/Assumptions!$B$10,"n/a") | E40: =IF($A40>E$35,(NPV($A40,DCF_Base!$C$21:$L$21)+MAX(0,MIN(DCF_Base!$L$21*(1+E$35)/($A40-E$35),Assumptions!$B$11*DCF_Base!$L$21))/(1+$A40)^10-Assumptions!$B$6-Assumptions!$B$7)/Assumptions!$B$8/Assumptions!$B$10,"n/a") | F40: =IF($A40>F$35,(NPV($A40,DCF_Base!$C$21:$L$21)+MAX(0,MIN(DCF_Base!$L$21*(1+F$35)/($A40-F$35),Assumptions!$B$11*DCF_Base!$L$21))/(1+$A40)^10-Assumptions!$B$6-Assumptions!$B$7)/Assumptions!$B$8/Assumptions!$B$10,"n/a")
