Workbook

Sheet Model_Info
A1: SPN.NZ - South Port New Zealand - owner-FCF DCF model
A2: Version | B2: v1.0, 2026-09-03. Fresh build; supersedes nothing (first DCF for this ticker).
A3: Built by | B3: dcf-analyst agent (Claude, Fable 5.1) on 2026-09-03 at the request of the research-stock orchestrator for Stephen Williams.
A4: Data vintage - price | B4: NZ$8.92 NZX regular close 2026-09-02T21:59:47Z (Yahoo). 52w 7.55-9.28. Figures go stale: refresh price after each close and all anchors after the next print.
A5: Data vintage - balance sheet | B5: 30 June 2026 (FY2026 annual result, released 21-Aug-2026): cash 12.556, loans and borrowings 31.008 (28.008 non-current + 3.000 current; the Metrics.csv 28.008 omits the current tranche), net debt 18.452, IFRS-16 leases 0.205 (immaterial, excluded).
A6: Data vintage - shares | B6: 26,234,900 ordinary shares, unchanged FY2014-FY2026; ~36k unvested share rights immaterial. Held FLAT (SBC is expensed in the flows).
A7: Data vintage - guidance | B7: FY2027 (21-Aug-2026 result): trade volumes 'broadly in line with FY26'; downside risk from absence of wind-farm project cargo and higher people/infrastructure spend; no numeric guidance; update due at the Oct-2026 ASM; Port Planning Exercise Stages 1-2 due late Sept 2026.
A8: Method - model | B8: Owner-FCF DCF (dcf-methods routing: operating company, non-US/cyclical). 10-year component build: revenue x EBITDA margin - SBC - D&A -> 28% tax, + D&A - capex + WC capture on revenue change. Same model as SPN.NZ_DCF.json.
A9: Method - owner FCF | B9: Reported FCF (OCF - all capex) less SBC less interest income (not stripped: net-debt company). FY2026 owner FCF 14.011 = 14.159 - 0.148.
A10: Method - mid-cycle | B10: FY2026 is a declared record year; the base year is NOT carried forward. Year-1 FCF is rebuilt from mid-cycle drivers (40% EBITDA margin, 13% capex/revenue = 10y median, +1% revenue).
A11: Method - terminal value | B11: TV = MAX(0, MIN(Gordon growth, exit EV/EBITDA cap x terminal EBITDA)). Caps are the stock's own 10-year min/avg/max EV/EBITDA (8.12/9.92/11.41x). Gordon binds in every scenario.
A12: Method - discount rate | B12: 10.0% NZD WACC in all scenarios: CoE 10.9% (Rf 4.5% + 0.80 x 5.5% ERP + 1.5% illiquidity/66%-council float + 0.5% single-asset/region), Kd 3.9% after tax, 88/12 E/D. Tiwai concentration is charged once, in the bear flows and 25% bear weight, not in the rate.
A13: Method - entry price | B13: 15% hurdle IRR with the terminal value rebuilt at 15% (min(Gordon@15%, cap)), per the 2026-09-01 correction; never the WACC-built TV.
... A18: Verification | B18: Recalculated headless in LibreOffice with zero formula errors; scenario values per share and the weighted value agree with SPN.NZ_DCF.json to the cent.

Sheet Actuals
A1: Actuals - reported history (NZ$ millions, FY ends 30 June). Source: SPN annual reports FY2017-FY2026 via Metrics.csv; June closes from Yahoo.
A3: Line | B3: FY2017 | C3: FY2018 | D3: FY2019 | E3: FY2020 | F3: FY2021 | G3: FY2022 | H3: FY2023 | I3: FY2024 | J3: FY2025 | K3: FY2026
A4: Revenue | B4: 36.868 | C4: 40.705 | D4: 43.95 | E4: 44.573 | F4: 47.291 | G4: 48.584 | H4: 53.589 | I4: 56.128 | J4: 63.282 | K4: 71.852
A5: EBITDA | B5: 15.55 | C5: 17.158 | D5: 17.99 | E5: 17.714 | F5: 18.85 | G5: 21.152 | H5: 22.768 | I5: 21.305 | J5: 25.832 | K5: 29.887
A6: NPAT (reported) | B6: 8.448 | C6: 9.658 | D6: 9.787 | E6: 9.43 | F6: 10.714 | G6: 12.829 | H6: 11.712 | I6: 7.376 | J6: 13.318 | K6: 16.11
A7: Operating cash flow | B7: 12.068 | C7: 12.342 | D7: 13.554 | E7: 12.605 | F7: 15.827 | G7: 13.695 | H7: 16.448 | I7: 12.786 | J7: 23.672 | K7: 23.598
A8: Capex (all, purchase of PPE) | B8: 2.503 | C8: 4.385 | D8: 5.976 | E8: 5.498 | F8: 10.184 | G8: 24.406 | H8: 15.023 | I8: 9.045 | J8: 8.043 | K8: 9.439
A9: Free cash flow (OCF - capex) | B9: 9.565 | C9: 7.957 | D9: 7.578 | E9: 7.107 | F9: 5.643 | G9: -10.711 | H9: 1.425 | I9: 3.741 | J9: 15.629 | K9: 14.159
A10: Shareholders equity | B10: 37.223 | C10: 40.06 | D10: 43.026 | E10: 45.635 | F10: 49.528 | G10: 55.274 | H10: 59.903 | I10: 60.232 | J10: 66.573 | K10: 75.223
A11: Cash | B11: 1.675 | C11: 0.991 | D11: 1.426 | E11: 1.229 | F11: 1.627 | G11: 1.303 | H11: 1.035 | I11: 2.31 | J11: 6.075 | K11: 12.556
A12: Total debt (incl. current) | B12: 9.6 | C12: 7.2 | D12: 7 | E12: 6.5 | F12: 9 | G12: 25.5 | H12: 25 | I12: 35.75 | J12: 31.008 | K12: 31.008
A13: Diluted EPS (NZ$) | B13: 0.322 | C13: 0.368 | D13: 0.373 | E13: 0.359 | F13: 0.408 | G13: 0.489 | H13: 0.446 | I13: 0.281 | J13: 0.506 | K13: 0.611
A14: Depreciation & amortisation | B14: 3.291 | C14: 3.361 | D14: 3.61 | E14: 3.843 | F14: 4.144 | G14: 4.36 | H14: 4.802 | I14: 4.915 | J14: 5.212 | K14: 5.406
A15: Dividend per share (NZ$) | B15: 0.26 | C15: 0.26 | D15: 0.26 | E15: 0.26 | F15: 0.26 | G15: 0.27 | H15: 0.27 | I15: 0.27 | J15: 0.28 | K15: 0.29
A16: June close (Yahoo, NZ$) | B16: 5.74 | C16: 6.9 | D16: 7.02 | E16: 6.25 | F16: 7.92 | G16: 8.02 | H16: 7.43 | I16: 6.01 | J16: 7.67 | K16: 8.5
A18: Balance sheet snapshot 30-Jun-2026
A19: Cash | B19: 12.556
A20: Loans and borrowings non-current | B20: 28.008
A21: Loans and borrowings current | B21: 3
A22: Total debt | B22: 31.008
A23: Net debt | B23: 18.452
A24: Lease liabilities (excluded, immaterial) | B24: 0.205
A25: Shares outstanding (m), flat since FY2014 | B25: 26.2349
A26: Buybacks FY2024-26 | B26: 0
A27: SBC FY2026 (equity-settled accrual) | B27: 0.148
A29: FY2027 guidance (21-Aug-2026)
A30: Volumes broadly in line with FY26; downside from loss of wind-farm project cargo and higher people/infrastructure spend; no numeric guidance; Port Planning Exercise Stages 1-2 due late Sept 2026; tug + mobile harbour crane replacement flagged.

Sheet Assumptions
A1: Assumptions - globals and scenario drivers (NZ$ millions unless stated)
A4: Current price (NZ$) | B4: 8.92 | F4: Yahoo NZX close 2026-09-02T21:59:47Z
A5: Price timestamp | B5: 2026-09-02T21:59:47Z | F5: regular close, not after-hours
A6: Diluted shares (m) | B6: 26.2349 | F6: flat since FY2014; SBC expensed so count held flat
A7: Cash | B7: 12.556 | F7: 30-Jun-2026
A8: Total debt | B8: 31.008 | F8: 28.008 non-current + 3.000 current, 30-Jun-2026
A9: Net debt | B9: =B8-B7 | F9: positive = net debt; deducted from EV
A10: Balance sheet date | B10: 2026-06-30
A11: FY2026 revenue (FY0 base) | B11: 71.852 | F11: Statement of comprehensive income FY2026
A12: Hurdle rate for entry price | B12: 0.15 | F12: 15% IRR; TV rebuilt at this rate
A13: Cash tax rate | B13: 0.28 | F13: NZ statutory; no losses or credits
A15: Scenario block | C15: Bear | D15: Base | E15: Bull
A16: WACC | C16: 0.1 | D16: 0.1 | E16: 0.1 | F16: identical across scenarios: risk is charged in the flows, not the rate
A17: Terminal growth | C17: 0.015 | D17: 0.0225 | E17: 0.025 | F17: at or below long-run NZ nominal GDP
A18: Probability weight | C18: 0.25 | D18: 0.5 | E18: 0.25 | F18: must sum to 100%
A19: D&A % of revenue | C19: 0.078 | D19: 0.078 | E19: 0.078 | F19: FY2026 actual 7.5%; rising as the asset base grows
A20: Capex % of revenue | C20: 0.14 | D20: 0.13 | E20: 0.115 | F20: 10y median 13.4%; bear = new capex cycle, bull = post-deepening
A21: WC capture % of revenue change | C21: -0.05 | D21: -0.05 | E21: -0.05 | F21: growth absorbs ~5% of incremental revenue as receivables
A22: Exit EV/EBITDA cap (10y min/avg/max) | C22: 8.12 | D22: 9.92 | E22: 11.41 | F22: Step 8c.5(4): stock's own 10-year EV/EBITDA range
A23: Weight check (must be 100%) | C23: =SUM(C18:E18)
A25: Scenario narratives
A26: Bear | B26: A repeat Meridian demand-response call on NZAS (up to 185MW available under the 2024 agreements) in a dry FY27/28 cuts Tiwai tonnage by a third for a season, China log demand stays weak, and dairy payout cuts trim farm-input imports: FY27 revenue -6%, EBITDA margin 37% (below the FY2024 trough of 38%). The Port Planning Exercise then launches a transformation capex cycle (14% of revenue) whose volume payoff is slow, under a new CEO and Chair. Recovery to 2-2.5% growth from FY29; margin never exceeds 38.5%; terminal growth 1.5%. Not a solvency case - net debt/EBITDA stays under 2x and the dividend is cut, not suspended.
A27: Base | B27: FY2027 revenue +1%: volumes guided 'broadly in line with FY26' with the 16k-tonne wind-farm project cargo gone and log volumes normalising after the FY26 wind-throw surge, offset by tariff inflation and a full year of the MSC Eagle service and the Bluff Freight Centre. EBITDA margin eases to 40.0% (management: 'invest more in our people and infrastructure') then settles at 40.5%, the 10-year mean. Growth 4-4.5% in FY28-30 as the Southland wind pipeline (1,851MW consented/in development) delivers lumpy project cargo, Edendale dairy warehousing ramps and Tiwai runs at full three-potline output, fading to 2.5% by FY36. Capex 13% of revenue funds a moderate Port-Planning capex programme (tug, crane, landside). Tiwai stays open to 2044 with no curtailment beyond a normal dry-year nuisance.
A28: Bull | B28: Tiwai runs uninterrupted, the wind-farm pipeline converts into 5-8 years of recurring project cargo, container volumes keep compounding on the new MSC services, and Ballance coastal fertiliser shifts to Bluff after the Mt Maunganui closure. Revenue +6% FY28-29, fading to 3%. Operating leverage on a fixed-cost port takes EBITDA margin to 43.5% (the FY2022 peak). Channel deepening is complete so capex runs at 11.5% of revenue (landside productivity, not marine works). Terminal growth 2.5%. Requires three independent things to go right - Tiwai, project cargo AND margin - hence only 25% weight.

Sheet DCF_Bear
A1: DCF_Bear - owner-FCF component build (NZ$ millions). Drivers in yellow (rows 5, 7, 9, 14); everything else is formula.
B3: 2026A | C3: FY2027E | D3: FY2028E | E3: FY2029E | F3: FY2030E | G3: FY2031E | H3: FY2032E | I3: FY2033E | J3: FY2034E | K3: FY2035E | L3: FY2036E
B4: 0 | C4: 1 | D4: 2 | E4: 3 | F4: 4 | G4: 5 | H4: 6 | I4: 7 | J4: 8 | K4: 9 | L4: 10
A5: Revenue growth YoY | C5: -0.06 | D5: 0.01 | E5: 0.025 | F5: 0.025 | G5: 0.025 | H5: 0.02 | I5: 0.02 | J5: 0.02 | K5: 0.02 | L5: 0.02
A6: Revenue | B6: =Assumptions!B11 | C6: =B6*(1+C5) | D6: =C6*(1+D5) | E6: =D6*(1+E5) | F6: =E6*(1+F5) | G6: =F6*(1+G5) | H6: =G6*(1+H5) | I6: =H6*(1+I5) | J6: =I6*(1+J5) | ... L6: =K6*(1+L5)
A7: Adj. EBITDA margin | B7: 0.41595224 | C7: 0.37 | D7: 0.375 | E7: 0.38 | F7: 0.385 | G7: 0.385 | H7: 0.385 | I7: 0.385 | J7: 0.385 | K7: 0.385 | L7: 0.385
A8: Adjusted EBITDA | B8: 29.887 | C8: =C6*C7 | D8: =D6*D7 | E8: =E6*E7 | F8: =F6*F7 | G8: =G6*G7 | H8: =H6*H7 | I8: =I6*I7 | J8: =J6*J7 | ... L8: =L6*L7
A9: SBC % of revenue | B9: 0.0020597896 | C9: 0.002 | D9: 0.002 | E9: 0.002 | F9: 0.002 | G9: 0.002 | H9: 0.002 | I9: 0.002 | J9: 0.002 | K9: 0.002 | L9: 0.002
A10: SBC (negative) | B10: -0.148 | C10: =-C6*C9 | D10: =-D6*D9 | E10: =-E6*E9 | F10: =-F6*F9 | G10: =-G6*G9 | H10: =-H6*H9 | I10: =-I6*I9 | J10: =-J6*J9 | ... L10: =-L6*L9
A11: Owner EBITDA (EBITDA + SBC) | B11: =B8+B10 | C11: =C8+C10 | D11: =D8+D10 | E11: =E8+E10 | F11: =F8+F10 | G11: =G8+G10 | H11: =H8+H10 | I11: =I8+I10 | ... L11: =L8+L10
A12: D&A (negative) | B12: -5.406 | C12: =-C6*Assumptions!$C$19 | D12: =-D6*Assumptions!$C$19 | E12: =-E6*Assumptions!$C$19 | F12: =-F6*Assumptions!$C$19 | G12: =-G6*Assumptions!$C$19 | H12: =-H6*Assumptions!$C$19 | I12: =-I6*Assumptions!$C$19 | J12: =-J6*Assumptions!$C$19 | ... L12: =-L6*Assumptions!$C$19
A13: EBIT, SBC expensed | B13: =B11+B12 | C13: =C11+C12 | D13: =D11+D12 | E13: =E11+E12 | F13: =F11+F12 | G13: =G11+G12 | H13: =H11+H12 | I13: =I11+I12 | ... L13: =L11+L12
A14: Cash tax rate | C14: 0.28 | D14: 0.28 | E14: 0.28 | F14: 0.28 | G14: 0.28 | H14: 0.28 | I14: 0.28 | J14: 0.28 | K14: 0.28 | L14: 0.28
A15: NOPAT | C15: =C13-MAX(0,C13)*C14 | D15: =D13-MAX(0,D13)*D14 | E15: =E13-MAX(0,E13)*E14 | F15: =F13-MAX(0,F13)*F14 | G15: =G13-MAX(0,G13)*G14 | H15: =H13-MAX(0,H13)*H14 | I15: =I13-MAX(0,I13)*I14 | J15: =J13-MAX(0,J13)*J14 | ... L15: =L13-MAX(0,L13)*L14
A16: add back D&A | C16: =-C12 | D16: =-D12 | E16: =-E12 | F16: =-F12 | G16: =-G12 | H16: =-H12 | I16: =-I12 | J16: =-J12 | ... L16: =-L12
A17: less capex | B17: -9.439 | C17: =-C6*Assumptions!$C$20 | D17: =-D6*Assumptions!$C$20 | E17: =-E6*Assumptions!$C$20 | F17: =-F6*Assumptions!$C$20 | G17: =-G6*Assumptions!$C$20 | H17: =-H6*Assumptions!$C$20 | I17: =-I6*Assumptions!$C$20 | J17: =-J6*Assumptions!$C$20 | ... L17: =-L6*Assumptions!$C$20
A18: add working capital (on revenue change) | C18: =Assumptions!$C$21*(C6-B6) | D18: =Assumptions!$C$21*(D6-C6) | E18: =Assumptions!$C$21*(E6-D6) | F18: =Assumptions!$C$21*(F6-E6) | G18: =Assumptions!$C$21*(G6-F6) | H18: =Assumptions!$C$21*(H6-G6) | I18: =Assumptions!$C$21*(I6-H6) | J18: =Assumptions!$C$21*(J6-I6) | ... L18: =Assumptions!$C$21*(L6-K6)
A19: Unlevered owner FCF | B19: 14.011 | C19: =C15+C16+C17+C18 | D19: =D15+D16+D17+D18 | E19: =E15+E16+E17+E18 | F19: =F15+F16+F17+F18 | G19: =G15+G16+G17+G18 | H19: =H15+H16+H17+H18 | I19: =I15+I16+I17+I18 | J19: =J15+J16+J17+J18 | ... L19: =L15+L16+L17+L18
A20: Discount factor | C20: =1/(1+Assumptions!$C$16)^C4 | D20: =1/(1+Assumptions!$C$16)^D4 | E20: =1/(1+Assumptions!$C$16)^E4 | F20: =1/(1+Assumptions!$C$16)^F4 | G20: =1/(1+Assumptions!$C$16)^G4 | H20: =1/(1+Assumptions!$C$16)^H4 | I20: =1/(1+Assumptions!$C$16)^I4 | J20: =1/(1+Assumptions!$C$16)^J4 | ... L20: =1/(1+Assumptions!$C$16)^L4
A21: PV of FCF | C21: =C19*C20 | D21: =D19*D20 | E21: =E19*E20 | F21: =F19*F20 | G21: =G19*G20 | H21: =H19*H20 | I21: =I19*I20 | J21: =J19*J20 | ... L21: =L19*L20
A23: Memo: FCF before SBC (company-style) | C23: =C19-C10 | D23: =D19-D10 | E23: =E19-E10 | F23: =F19-F10 | G23: =G19-G10 | H23: =H19-H10 | I23: =I19-I10 | J23: =J19-J10 | ... L23: =L19-L10
A24: Memo: owner-FCF margin | B24: =B19/B6 | C24: =C19/C6 | D24: =D19/D6 | E24: =E19/E6 | F24: =F19/F6 | G24: =G19/G6 | H24: =H19/H6 | I24: =I19/I6 | ... L24: =L19/L6
A25: FY0 column: actuals (blue); row 19 FY0 is reported owner FCF 14.011 (OCF 23.598 - capex 9.439 - SBC 0.148), not a component build.
A26: Sum of PV of FCF | B26: =SUM(C21:L21)
A27: Terminal growth | B27: =Assumptions!C17
A28: Terminal-year FCF x (1+g) | B28: =L19*(1+B27)
A29: Gordon terminal value | B29: =B28/(Assumptions!C16-B27)
A30: Exit-multiple cap TV (cap x terminal EBITDA) | B30: =Assumptions!C22*L8
A31: Terminal value used = MAX(0,MIN(Gordon, cap)) | B31: =MAX(0,MIN(B29,B30))
A32: Implied exit multiple (TV / FCF_10) | B32: =B31/L19
A33: PV of terminal value | B33: =B31*L20
A34: Enterprise value | B34: =B26+B33
A35: less net debt | B35: =Assumptions!B9
A36: Equity value | B36: =B34-B35
A37: Diluted shares (m) | B37: =Assumptions!B6
A38: VALUE PER SHARE (NZ$) | B38: =B36/B37
A39: Upside vs current price | B39: =B38/Assumptions!B4-1
A40: Memo: implied EV/EBITDA at exit (TV / EBITDA_10) | B40: =B31/L8
A41: Street memo: PV of explicit-period SBC | B41: =SUMPRODUCT(-C10:L10/(1+Assumptions!C16)^C4:L4)
A42: Street memo: PV of terminal SBC | B42: =(-L10*(1+B27)/(Assumptions!C16-B27))*L20
...

Sheet DCF_Base
A1: DCF_Base - owner-FCF component build (NZ$ millions). Drivers in yellow (rows 5, 7, 9, 14); everything else is formula.
B3: 2026A | C3: FY2027E | D3: FY2028E | E3: FY2029E | F3: FY2030E | G3: FY2031E | H3: FY2032E | I3: FY2033E | J3: FY2034E | K3: FY2035E | L3: FY2036E
B4: 0 | C4: 1 | D4: 2 | E4: 3 | F4: 4 | G4: 5 | H4: 6 | I4: 7 | J4: 8 | K4: 9 | L4: 10
A5: Revenue growth YoY | C5: 0.01 | D5: 0.045 | E5: 0.045 | F5: 0.04 | G5: 0.04 | H5: 0.035 | I5: 0.03 | J5: 0.03 | K5: 0.025 | L5: 0.025
A6: Revenue | B6: =Assumptions!B11 | C6: =B6*(1+C5) | D6: =C6*(1+D5) | E6: =D6*(1+E5) | F6: =E6*(1+F5) | G6: =F6*(1+G5) | H6: =G6*(1+H5) | I6: =H6*(1+I5) | J6: =I6*(1+J5) | ... L6: =K6*(1+L5)
A7: Adj. EBITDA margin | B7: 0.41595224 | C7: 0.4 | D7: 0.405 | E7: 0.405 | F7: 0.405 | G7: 0.405 | H7: 0.405 | I7: 0.405 | J7: 0.405 | K7: 0.405 | L7: 0.405
A8: Adjusted EBITDA | B8: 29.887 | C8: =C6*C7 | D8: =D6*D7 | E8: =E6*E7 | F8: =F6*F7 | G8: =G6*G7 | H8: =H6*H7 | I8: =I6*I7 | J8: =J6*J7 | ... L8: =L6*L7
A9: SBC % of revenue | B9: 0.0020597896 | C9: 0.002 | D9: 0.002 | E9: 0.002 | F9: 0.002 | G9: 0.002 | H9: 0.002 | I9: 0.002 | J9: 0.002 | K9: 0.002 | L9: 0.002
A10: SBC (negative) | B10: -0.148 | C10: =-C6*C9 | D10: =-D6*D9 | E10: =-E6*E9 | F10: =-F6*F9 | G10: =-G6*G9 | H10: =-H6*H9 | I10: =-I6*I9 | J10: =-J6*J9 | ... L10: =-L6*L9
A11: Owner EBITDA (EBITDA + SBC) | B11: =B8+B10 | C11: =C8+C10 | D11: =D8+D10 | E11: =E8+E10 | F11: =F8+F10 | G11: =G8+G10 | H11: =H8+H10 | I11: =I8+I10 | ... L11: =L8+L10
A12: D&A (negative) | B12: -5.406 | C12: =-C6*Assumptions!$D$19 | D12: =-D6*Assumptions!$D$19 | E12: =-E6*Assumptions!$D$19 | F12: =-F6*Assumptions!$D$19 | G12: =-G6*Assumptions!$D$19 | H12: =-H6*Assumptions!$D$19 | I12: =-I6*Assumptions!$D$19 | J12: =-J6*Assumptions!$D$19 | ... L12: =-L6*Assumptions!$D$19
A13: EBIT, SBC expensed | B13: =B11+B12 | C13: =C11+C12 | D13: =D11+D12 | E13: =E11+E12 | F13: =F11+F12 | G13: =G11+G12 | H13: =H11+H12 | I13: =I11+I12 | ... L13: =L11+L12
A14: Cash tax rate | C14: 0.28 | D14: 0.28 | E14: 0.28 | F14: 0.28 | G14: 0.28 | H14: 0.28 | I14: 0.28 | J14: 0.28 | K14: 0.28 | L14: 0.28
A15: NOPAT | C15: =C13-MAX(0,C13)*C14 | D15: =D13-MAX(0,D13)*D14 | E15: =E13-MAX(0,E13)*E14 | F15: =F13-MAX(0,F13)*F14 | G15: =G13-MAX(0,G13)*G14 | H15: =H13-MAX(0,H13)*H14 | I15: =I13-MAX(0,I13)*I14 | J15: =J13-MAX(0,J13)*J14 | ... L15: =L13-MAX(0,L13)*L14
A16: add back D&A | C16: =-C12 | D16: =-D12 | E16: =-E12 | F16: =-F12 | G16: =-G12 | H16: =-H12 | I16: =-I12 | J16: =-J12 | ... L16: =-L12
A17: less capex | B17: -9.439 | C17: =-C6*Assumptions!$D$20 | D17: =-D6*Assumptions!$D$20 | E17: =-E6*Assumptions!$D$20 | F17: =-F6*Assumptions!$D$20 | G17: =-G6*Assumptions!$D$20 | H17: =-H6*Assumptions!$D$20 | I17: =-I6*Assumptions!$D$20 | J17: =-J6*Assumptions!$D$20 | ... L17: =-L6*Assumptions!$D$20
A18: add working capital (on revenue change) | C18: =Assumptions!$D$21*(C6-B6) | D18: =Assumptions!$D$21*(D6-C6) | E18: =Assumptions!$D$21*(E6-D6) | F18: =Assumptions!$D$21*(F6-E6) | G18: =Assumptions!$D$21*(G6-F6) | H18: =Assumptions!$D$21*(H6-G6) | I18: =Assumptions!$D$21*(I6-H6) | J18: =Assumptions!$D$21*(J6-I6) | ... L18: =Assumptions!$D$21*(L6-K6)
A19: Unlevered owner FCF | B19: 14.011 | C19: =C15+C16+C17+C18 | D19: =D15+D16+D17+D18 | E19: =E15+E16+E17+E18 | F19: =F15+F16+F17+F18 | G19: =G15+G16+G17+G18 | H19: =H15+H16+H17+H18 | I19: =I15+I16+I17+I18 | J19: =J15+J16+J17+J18 | ... L19: =L15+L16+L17+L18
A20: Discount factor | C20: =1/(1+Assumptions!$D$16)^C4 | D20: =1/(1+Assumptions!$D$16)^D4 | E20: =1/(1+Assumptions!$D$16)^E4 | F20: =1/(1+Assumptions!$D$16)^F4 | G20: =1/(1+Assumptions!$D$16)^G4 | H20: =1/(1+Assumptions!$D$16)^H4 | I20: =1/(1+Assumptions!$D$16)^I4 | J20: =1/(1+Assumptions!$D$16)^J4 | ... L20: =1/(1+Assumptions!$D$16)^L4
A21: PV of FCF | C21: =C19*C20 | D21: =D19*D20 | E21: =E19*E20 | F21: =F19*F20 | G21: =G19*G20 | H21: =H19*H20 | I21: =I19*I20 | J21: =J19*J20 | ... L21: =L19*L20
A23: Memo: FCF before SBC (company-style) | C23: =C19-C10 | D23: =D19-D10 | E23: =E19-E10 | F23: =F19-F10 | G23: =G19-G10 | H23: =H19-H10 | I23: =I19-I10 | J23: =J19-J10 | ... L23: =L19-L10
A24: Memo: owner-FCF margin | B24: =B19/B6 | C24: =C19/C6 | D24: =D19/D6 | E24: =E19/E6 | F24: =F19/F6 | G24: =G19/G6 | H24: =H19/H6 | I24: =I19/I6 | ... L24: =L19/L6
A25: FY0 column: actuals (blue); row 19 FY0 is reported owner FCF 14.011 (OCF 23.598 - capex 9.439 - SBC 0.148), not a component build.
A26: Sum of PV of FCF | B26: =SUM(C21:L21)
A27: Terminal growth | B27: =Assumptions!D17
A28: Terminal-year FCF x (1+g) | B28: =L19*(1+B27)
A29: Gordon terminal value | B29: =B28/(Assumptions!D16-B27)
A30: Exit-multiple cap TV (cap x terminal EBITDA) | B30: =Assumptions!D22*L8
A31: Terminal value used = MAX(0,MIN(Gordon, cap)) | B31: =MAX(0,MIN(B29,B30))
A32: Implied exit multiple (TV / FCF_10) | B32: =B31/L19
A33: PV of terminal value | B33: =B31*L20
A34: Enterprise value | B34: =B26+B33
A35: less net debt | B35: =Assumptions!B9
A36: Equity value | B36: =B34-B35
A37: Diluted shares (m) | B37: =Assumptions!B6
A38: VALUE PER SHARE (NZ$) | B38: =B36/B37
A39: Upside vs current price | B39: =B38/Assumptions!B4-1
A40: Memo: implied EV/EBITDA at exit (TV / EBITDA_10) | B40: =B31/L8
A41: Street memo: PV of explicit-period SBC | B41: =SUMPRODUCT(-C10:L10/(1+Assumptions!D16)^C4:L4)
A42: Street memo: PV of terminal SBC | B42: =(-L10*(1+B27)/(Assumptions!D16-B27))*L20
...

Sheet DCF_Bull
A1: DCF_Bull - owner-FCF component build (NZ$ millions). Drivers in yellow (rows 5, 7, 9, 14); everything else is formula.
B3: 2026A | C3: FY2027E | D3: FY2028E | E3: FY2029E | F3: FY2030E | G3: FY2031E | H3: FY2032E | I3: FY2033E | J3: FY2034E | K3: FY2035E | L3: FY2036E
B4: 0 | C4: 1 | D4: 2 | E4: 3 | F4: 4 | G4: 5 | H4: 6 | I4: 7 | J4: 8 | K4: 9 | L4: 10
A5: Revenue growth YoY | C5: 0.03 | D5: 0.06 | E5: 0.06 | F5: 0.05 | G5: 0.05 | H5: 0.04 | I5: 0.04 | J5: 0.035 | K5: 0.03 | L5: 0.03
A6: Revenue | B6: =Assumptions!B11 | C6: =B6*(1+C5) | D6: =C6*(1+D5) | E6: =D6*(1+E5) | F6: =E6*(1+F5) | G6: =F6*(1+G5) | H6: =G6*(1+H5) | I6: =H6*(1+I5) | J6: =I6*(1+J5) | ... L6: =K6*(1+L5)
A7: Adj. EBITDA margin | B7: 0.41595224 | C7: 0.415 | D7: 0.42 | E7: 0.425 | F7: 0.43 | G7: 0.435 | H7: 0.435 | I7: 0.435 | J7: 0.435 | K7: 0.435 | L7: 0.435
A8: Adjusted EBITDA | B8: 29.887 | C8: =C6*C7 | D8: =D6*D7 | E8: =E6*E7 | F8: =F6*F7 | G8: =G6*G7 | H8: =H6*H7 | I8: =I6*I7 | J8: =J6*J7 | ... L8: =L6*L7
A9: SBC % of revenue | B9: 0.0020597896 | C9: 0.002 | D9: 0.002 | E9: 0.002 | F9: 0.002 | G9: 0.002 | H9: 0.002 | I9: 0.002 | J9: 0.002 | K9: 0.002 | L9: 0.002
A10: SBC (negative) | B10: -0.148 | C10: =-C6*C9 | D10: =-D6*D9 | E10: =-E6*E9 | F10: =-F6*F9 | G10: =-G6*G9 | H10: =-H6*H9 | I10: =-I6*I9 | J10: =-J6*J9 | ... L10: =-L6*L9
A11: Owner EBITDA (EBITDA + SBC) | B11: =B8+B10 | C11: =C8+C10 | D11: =D8+D10 | E11: =E8+E10 | F11: =F8+F10 | G11: =G8+G10 | H11: =H8+H10 | I11: =I8+I10 | ... L11: =L8+L10
A12: D&A (negative) | B12: -5.406 | C12: =-C6*Assumptions!$E$19 | D12: =-D6*Assumptions!$E$19 | E12: =-E6*Assumptions!$E$19 | F12: =-F6*Assumptions!$E$19 | G12: =-G6*Assumptions!$E$19 | H12: =-H6*Assumptions!$E$19 | I12: =-I6*Assumptions!$E$19 | J12: =-J6*Assumptions!$E$19 | ... L12: =-L6*Assumptions!$E$19
A13: EBIT, SBC expensed | B13: =B11+B12 | C13: =C11+C12 | D13: =D11+D12 | E13: =E11+E12 | F13: =F11+F12 | G13: =G11+G12 | H13: =H11+H12 | I13: =I11+I12 | ... L13: =L11+L12
A14: Cash tax rate | C14: 0.28 | D14: 0.28 | E14: 0.28 | F14: 0.28 | G14: 0.28 | H14: 0.28 | I14: 0.28 | J14: 0.28 | K14: 0.28 | L14: 0.28
A15: NOPAT | C15: =C13-MAX(0,C13)*C14 | D15: =D13-MAX(0,D13)*D14 | E15: =E13-MAX(0,E13)*E14 | F15: =F13-MAX(0,F13)*F14 | G15: =G13-MAX(0,G13)*G14 | H15: =H13-MAX(0,H13)*H14 | I15: =I13-MAX(0,I13)*I14 | J15: =J13-MAX(0,J13)*J14 | ... L15: =L13-MAX(0,L13)*L14
A16: add back D&A | C16: =-C12 | D16: =-D12 | E16: =-E12 | F16: =-F12 | G16: =-G12 | H16: =-H12 | I16: =-I12 | J16: =-J12 | ... L16: =-L12
A17: less capex | B17: -9.439 | C17: =-C6*Assumptions!$E$20 | D17: =-D6*Assumptions!$E$20 | E17: =-E6*Assumptions!$E$20 | F17: =-F6*Assumptions!$E$20 | G17: =-G6*Assumptions!$E$20 | H17: =-H6*Assumptions!$E$20 | I17: =-I6*Assumptions!$E$20 | J17: =-J6*Assumptions!$E$20 | ... L17: =-L6*Assumptions!$E$20
A18: add working capital (on revenue change) | C18: =Assumptions!$E$21*(C6-B6) | D18: =Assumptions!$E$21*(D6-C6) | E18: =Assumptions!$E$21*(E6-D6) | F18: =Assumptions!$E$21*(F6-E6) | G18: =Assumptions!$E$21*(G6-F6) | H18: =Assumptions!$E$21*(H6-G6) | I18: =Assumptions!$E$21*(I6-H6) | J18: =Assumptions!$E$21*(J6-I6) | ... L18: =Assumptions!$E$21*(L6-K6)
A19: Unlevered owner FCF | B19: 14.011 | C19: =C15+C16+C17+C18 | D19: =D15+D16+D17+D18 | E19: =E15+E16+E17+E18 | F19: =F15+F16+F17+F18 | G19: =G15+G16+G17+G18 | H19: =H15+H16+H17+H18 | I19: =I15+I16+I17+I18 | J19: =J15+J16+J17+J18 | ... L19: =L15+L16+L17+L18
A20: Discount factor | C20: =1/(1+Assumptions!$E$16)^C4 | D20: =1/(1+Assumptions!$E$16)^D4 | E20: =1/(1+Assumptions!$E$16)^E4 | F20: =1/(1+Assumptions!$E$16)^F4 | G20: =1/(1+Assumptions!$E$16)^G4 | H20: =1/(1+Assumptions!$E$16)^H4 | I20: =1/(1+Assumptions!$E$16)^I4 | J20: =1/(1+Assumptions!$E$16)^J4 | ... L20: =1/(1+Assumptions!$E$16)^L4
A21: PV of FCF | C21: =C19*C20 | D21: =D19*D20 | E21: =E19*E20 | F21: =F19*F20 | G21: =G19*G20 | H21: =H19*H20 | I21: =I19*I20 | J21: =J19*J20 | ... L21: =L19*L20
A23: Memo: FCF before SBC (company-style) | C23: =C19-C10 | D23: =D19-D10 | E23: =E19-E10 | F23: =F19-F10 | G23: =G19-G10 | H23: =H19-H10 | I23: =I19-I10 | J23: =J19-J10 | ... L23: =L19-L10
A24: Memo: owner-FCF margin | B24: =B19/B6 | C24: =C19/C6 | D24: =D19/D6 | E24: =E19/E6 | F24: =F19/F6 | G24: =G19/G6 | H24: =H19/H6 | I24: =I19/I6 | ... L24: =L19/L6
A25: FY0 column: actuals (blue); row 19 FY0 is reported owner FCF 14.011 (OCF 23.598 - capex 9.439 - SBC 0.148), not a component build.
A26: Sum of PV of FCF | B26: =SUM(C21:L21)
A27: Terminal growth | B27: =Assumptions!E17
A28: Terminal-year FCF x (1+g) | B28: =L19*(1+B27)
A29: Gordon terminal value | B29: =B28/(Assumptions!E16-B27)
A30: Exit-multiple cap TV (cap x terminal EBITDA) | B30: =Assumptions!E22*L8
A31: Terminal value used = MAX(0,MIN(Gordon, cap)) | B31: =MAX(0,MIN(B29,B30))
A32: Implied exit multiple (TV / FCF_10) | B32: =B31/L19
A33: PV of terminal value | B33: =B31*L20
A34: Enterprise value | B34: =B26+B33
A35: less net debt | B35: =Assumptions!B9
A36: Equity value | B36: =B34-B35
A37: Diluted shares (m) | B37: =Assumptions!B6
A38: VALUE PER SHARE (NZ$) | B38: =B36/B37
A39: Upside vs current price | B39: =B38/Assumptions!B4-1
A40: Memo: implied EV/EBITDA at exit (TV / EBITDA_10) | B40: =B31/L8
A41: Street memo: PV of explicit-period SBC | B41: =SUMPRODUCT(-C10:L10/(1+Assumptions!E16)^C4:L4)
A42: Street memo: PV of terminal SBC | B42: =(-L10*(1+B27)/(Assumptions!E16-B27))*L20
...

Sheet FCF_Quality
A1: FCF_Quality - reported FCF reconciled to owner FCF, FY2017-FY2026 (NZ$ millions)
A3: Line | B3: FY2017 | C3: FY2018 | D3: FY2019 | E3: FY2020 | F3: FY2021 | G3: FY2022 | H3: FY2023 | I3: FY2024 | J3: FY2025 | K3: FY2026
A4: Free cash flow (company definition: OCF - all capex) | B4: =Actuals!B9 | C4: =Actuals!C9 | D4: =Actuals!D9 | E4: =Actuals!E9 | F4: =Actuals!F9 | G4: =Actuals!G9 | H4: =Actuals!H9 | I4: =Actuals!I9 | ... K4: =Actuals!K9
A5: less: SBC incl. equity-award taxes (nil taxes) | B5: 0 | C5: 0 | D5: 0 | E5: 0 | F5: 0 | G5: 0 | H5: 0 | I5: -0.036 | J5: -0.106 | K5: -0.148
A6: less: interest income (not stripped: net-debt company) | B6: 0 | C6: 0 | D6: 0 | E6: 0 | F6: 0 | G6: 0 | H6: 0 | I6: 0 | J6: 0 | K6: 0
A7: Owner FCF (reported FCF less SBC less interest income) | B7: =B4+B5+B6 | C7: =C4+C5+C6 | D7: =D4+D5+D6 | E7: =E4+E5+E6 | F7: =F4+F5+F6 | G7: =G4+G5+G6 | H7: =H4+H5+H6 | I7: =I4+I5+I6 | ... K7: =K4+K5+K6
A8: Reported FCF margin | B8: =B4/Actuals!B4 | C8: =C4/Actuals!C4 | D8: =D4/Actuals!D4 | E8: =E4/Actuals!E4 | F8: =F4/Actuals!F4 | G8: =G4/Actuals!G4 | H8: =H4/Actuals!H4 | I8: =I4/Actuals!I4 | ... K8: =K4/Actuals!K4
A9: Owner FCF margin | B9: =B7/Actuals!B4 | C9: =C7/Actuals!C4 | D9: =D7/Actuals!D4 | E9: =E7/Actuals!E4 | F9: =F7/Actuals!F4 | G9: =G7/Actuals!G4 | H9: =H7/Actuals!H4 | I9: =I7/Actuals!I4 | ... K9: =K7/Actuals!K4
A10: Memo: capex % of revenue (lumpy: 6.8% FY17 -> 50% FY22 channel deepening) | B10: =-Actuals!B8/Actuals!B4 | C10: =-Actuals!C8/Actuals!C4 | D10: =-Actuals!D8/Actuals!D4 | E10: =-Actuals!E8/Actuals!E4 | F10: =-Actuals!F8/Actuals!F4 | G10: =-Actuals!G8/Actuals!G4 | H10: =-Actuals!H8/Actuals!H4 | I10: =-Actuals!I8/Actuals!I4 | ... K10: =-Actuals!K8/Actuals!K4
A11: Memo: normalised-capex FCF (OCF - 13.37% of revenue, the 10y median capex ratio) | B11: =Actuals!B7-0.1337*Actuals!B4 | C11: =Actuals!C7-0.1337*Actuals!C4 | D11: =Actuals!D7-0.1337*Actuals!D4 | E11: =Actuals!E7-0.1337*Actuals!E4 | F11: =Actuals!F7-0.1337*Actuals!F4 | G11: =Actuals!G7-0.1337*Actuals!G4 | H11: =Actuals!H7-0.1337*Actuals!H4 | I11: =Actuals!I7-0.1337*Actuals!I4 | ... K11: =Actuals!K7-0.1337*Actuals!K4
A12: Memo: normalised-capex FCF margin (8y median 17.4%; FY2026 19.5%) | B12: =B11/Actuals!B4 | C12: =C11/Actuals!C4 | D12: =D11/Actuals!D4 | E12: =E11/Actuals!E4 | F12: =F11/Actuals!F4 | G12: =G11/Actuals!G4 | H12: =H11/Actuals!H4 | I12: =I11/Actuals!I4 | ... K12: =K11/Actuals!K4
A13: Memo: cash income tax paid | B13: 3.185 | C13: 3.564 | D13: 4.123 | E13: 4.752 | F13: 3.934 | G13: 4.377 | H13: 5.205 | I13: 4.954 | J13: 3.183 | K13: 5.358
A14: Memo: cash tax rate on (NPAT + tax paid) - FY2025 low on timing, FY2024 has 2.3m one-off deferred tax expense (non-cash) | B14: =B13/(Actuals!B6+B13) | C14: =C13/(Actuals!C6+C13) | D14: =D13/(Actuals!D6+D13) | E14: =E13/(Actuals!E6+E13) | F14: =F13/(Actuals!F6+F13) | G14: =G13/(Actuals!G6+G13) | H14: =H13/(Actuals!H6+H13) | I14: =I13/(Actuals!I6+I13) | ... K14: =K13/(Actuals!K6+K13)
A16: Reading: the raw FCF series is dominated by growth capex timing; on a normalised-capex basis FY2026 is 1.12x the 8-year median margin, and the DCF year-1 margin (17.8%) sits at that median rather than at the FY2026 record.

Sheet Valuation
A1: Valuation summary, hurdle entry prices, required-return table, sensitivity
A3: Scenario | B3: Value per share | C3: Upside vs price | D3: Probability | E3: Street value per share | F3: Entry price @15% hurdle
A4: Bear | B4: =DCF_Bear!$B$38 | C4: =B4/Assumptions!$B$4-1 | D4: =Assumptions!C18 | E4: =DCF_Bear!$B$43 | F4: =(SUMPRODUCT(DCF_Bear!$C$19:$L$19/(1+Assumptions!$B$12)^DCF_Bear!$C$4:$L$4)+MAX(0,MIN(DCF_Bear!$L$19*(1+Assumptions!$C$17)/(Assumptions!$B$12-Assumptions!$C$17),Assumptions!$C$22*DCF_Bear!$L$8))/(1+Assumptions!$B$12)^10-Assumptions!$B$9)/Assumptions!$B$6
A5: Base | B5: =DCF_Base!$B$38 | C5: =B5/Assumptions!$B$4-1 | D5: =Assumptions!D18 | E5: =DCF_Base!$B$43 | F5: =(SUMPRODUCT(DCF_Base!$C$19:$L$19/(1+Assumptions!$B$12)^DCF_Base!$C$4:$L$4)+MAX(0,MIN(DCF_Base!$L$19*(1+Assumptions!$D$17)/(Assumptions!$B$12-Assumptions!$D$17),Assumptions!$D$22*DCF_Base!$L$8))/(1+Assumptions!$B$12)^10-Assumptions!$B$9)/Assumptions!$B$6
A6: Bull | B6: =DCF_Bull!$B$38 | C6: =B6/Assumptions!$B$4-1 | D6: =Assumptions!E18 | E6: =DCF_Bull!$B$43 | F6: =(SUMPRODUCT(DCF_Bull!$C$19:$L$19/(1+Assumptions!$B$12)^DCF_Bull!$C$4:$L$4)+MAX(0,MIN(DCF_Bull!$L$19*(1+Assumptions!$E$17)/(Assumptions!$B$12-Assumptions!$E$17),Assumptions!$E$22*DCF_Bull!$L$8))/(1+Assumptions!$B$12)^10-Assumptions!$B$9)/Assumptions!$B$6
A8: Probability-weighted value per share | B8: =SUMPRODUCT(B4:B6,D4:D6)
A9: Margin of safety vs price | B9: =1-Assumptions!B4/B8
A10: Street weighted value per share | B10: =SUMPRODUCT(E4:E6,D4:D6)
A11: Band position (price - house)/(street - house) | B11: n/a - SBC is 0.2% of revenue so house and street coincide
A12: Probability-weighted entry price (buy-below at 15% IRR) | B12: =SUMPRODUCT(F4:F6,D4:D6)
A13: Current price | B13: =Assumptions!B4
A15: Required-return table (base case; TV rebuilt at each rate)
A16: Required return | B16: Value per share
A17: 0.08 | B17: =(SUMPRODUCT(DCF_Base!$C$19:$L$19/(1+$A$17)^DCF_Base!$C$4:$L$4)+MAX(0,MIN(DCF_Base!$L$19*(1+Assumptions!$D$17)/($A$17-Assumptions!$D$17),Assumptions!$D$22*DCF_Base!$L$8))/(1+$A$17)^10-Assumptions!$B$9)/Assumptions!$B$6
A18: 0.09 | B18: =(SUMPRODUCT(DCF_Base!$C$19:$L$19/(1+$A$18)^DCF_Base!$C$4:$L$4)+MAX(0,MIN(DCF_Base!$L$19*(1+Assumptions!$D$17)/($A$18-Assumptions!$D$17),Assumptions!$D$22*DCF_Base!$L$8))/(1+$A$18)^10-Assumptions!$B$9)/Assumptions!$B$6
A19: 0.1 | B19: =(SUMPRODUCT(DCF_Base!$C$19:$L$19/(1+$A$19)^DCF_Base!$C$4:$L$4)+MAX(0,MIN(DCF_Base!$L$19*(1+Assumptions!$D$17)/($A$19-Assumptions!$D$17),Assumptions!$D$22*DCF_Base!$L$8))/(1+$A$19)^10-Assumptions!$B$9)/Assumptions!$B$6
A20: 0.11 | B20: =(SUMPRODUCT(DCF_Base!$C$19:$L$19/(1+$A$20)^DCF_Base!$C$4:$L$4)+MAX(0,MIN(DCF_Base!$L$19*(1+Assumptions!$D$17)/($A$20-Assumptions!$D$17),Assumptions!$D$22*DCF_Base!$L$8))/(1+$A$20)^10-Assumptions!$B$9)/Assumptions!$B$6
A21: 0.12 | B21: =(SUMPRODUCT(DCF_Base!$C$19:$L$19/(1+$A$21)^DCF_Base!$C$4:$L$4)+MAX(0,MIN(DCF_Base!$L$19*(1+Assumptions!$D$17)/($A$21-Assumptions!$D$17),Assumptions!$D$22*DCF_Base!$L$8))/(1+$A$21)^10-Assumptions!$B$9)/Assumptions!$B$6
A22: 0.15 | B22: =(SUMPRODUCT(DCF_Base!$C$19:$L$19/(1+$A$22)^DCF_Base!$C$4:$L$4)+MAX(0,MIN(DCF_Base!$L$19*(1+Assumptions!$D$17)/($A$22-Assumptions!$D$17),Assumptions!$D$22*DCF_Base!$L$8))/(1+$A$22)^10-Assumptions!$B$9)/Assumptions!$B$6
A23: =Assumptions!D16 | B23: =(SUMPRODUCT(DCF_Base!$C$19:$L$19/(1+$A$23)^DCF_Base!$C$4:$L$4)+MAX(0,MIN(DCF_Base!$L$19*(1+Assumptions!$D$17)/($A$23-Assumptions!$D$17),Assumptions!$D$22*DCF_Base!$L$8))/(1+$A$23)^10-Assumptions!$B$9)/Assumptions!$B$6 | C23: ties to DCF_Base!B38
A25: Sensitivity: base value per share, WACC (rows) x terminal growth (columns)
B26: 0.0125 | C26: 0.0175 | D26: 0.0225 | E26: 0.0275 | F26: 0.0325
A27: 0.08 | B27: =IF($A$27>B$26,(SUMPRODUCT(DCF_Base!$C$19:$L$19/(1+$A$27)^DCF_Base!$C$4:$L$4)+MAX(0,MIN(DCF_Base!$L$19*(1+B$26)/($A$27-B$26),Assumptions!$D$22*DCF_Base!$L$8))/(1+$A$27)^10-Assumptions!$B$9)/Assumptions!$B$6,"n/a") | C27: =IF($A$27>C$26,(SUMPRODUCT(DCF_Base!$C$19:$L$19/(1+$A$27)^DCF_Base!$C$4:$L$4)+MAX(0,MIN(DCF_Base!$L$19*(1+C$26)/($A$27-C$26),Assumptions!$D$22*DCF_Base!$L$8))/(1+$A$27)^10-Assumptions!$B$9)/Assumptions!$B$6,"n/a") | D27: =IF($A$27>D$26,(SUMPRODUCT(DCF_Base!$C$19:$L$19/(1+$A$27)^DCF_Base!$C$4:$L$4)+MAX(0,MIN(DCF_Base!$L$19*(1+D$26)/($A$27-D$26),Assumptions!$D$22*DCF_Base!$L$8))/(1+$A$27)^10-Assumptions!$B$9)/Assumptions!$B$6,"n/a") | E27: =IF($A$27>E$26,(SUMPRODUCT(DCF_Base!$C$19:$L$19/(1+$A$27)^DCF_Base!$C$4:$L$4)+MAX(0,MIN(DCF_Base!$L$19*(1+E$26)/($A$27-E$26),Assumptions!$D$22*DCF_Base!$L$8))/(1+$A$27)^10-Assumptions!$B$9)/Assumptions!$B$6,"n/a") | F27: =IF($A$27>F$26,(SUMPRODUCT(DCF_Base!$C$19:$L$19/(1+$A$27)^DCF_Base!$C$4:$L$4)+MAX(0,MIN(DCF_Base!$L$19*(1+F$26)/($A$27-F$26),Assumptions!$D$22*DCF_Base!$L$8))/(1+$A$27)^10-Assumptions!$B$9)/Assumptions!$B$6,"n/a")
A28: 0.09 | B28: =IF($A$28>B$26,(SUMPRODUCT(DCF_Base!$C$19:$L$19/(1+$A$28)^DCF_Base!$C$4:$L$4)+MAX(0,MIN(DCF_Base!$L$19*(1+B$26)/($A$28-B$26),Assumptions!$D$22*DCF_Base!$L$8))/(1+$A$28)^10-Assumptions!$B$9)/Assumptions!$B$6,"n/a") | C28: =IF($A$28>C$26,(SUMPRODUCT(DCF_Base!$C$19:$L$19/(1+$A$28)^DCF_Base!$C$4:$L$4)+MAX(0,MIN(DCF_Base!$L$19*(1+C$26)/($A$28-C$26),Assumptions!$D$22*DCF_Base!$L$8))/(1+$A$28)^10-Assumptions!$B$9)/Assumptions!$B$6,"n/a") | D28: =IF($A$28>D$26,(SUMPRODUCT(DCF_Base!$C$19:$L$19/(1+$A$28)^DCF_Base!$C$4:$L$4)+MAX(0,MIN(DCF_Base!$L$19*(1+D$26)/($A$28-D$26),Assumptions!$D$22*DCF_Base!$L$8))/(1+$A$28)^10-Assumptions!$B$9)/Assumptions!$B$6,"n/a") | E28: =IF($A$28>E$26,(SUMPRODUCT(DCF_Base!$C$19:$L$19/(1+$A$28)^DCF_Base!$C$4:$L$4)+MAX(0,MIN(DCF_Base!$L$19*(1+E$26)/($A$28-E$26),Assumptions!$D$22*DCF_Base!$L$8))/(1+$A$28)^10-Assumptions!$B$9)/Assumptions!$B$6,"n/a") | F28: =IF($A$28>F$26,(SUMPRODUCT(DCF_Base!$C$19:$L$19/(1+$A$28)^DCF_Base!$C$4:$L$4)+MAX(0,MIN(DCF_Base!$L$19*(1+F$26)/($A$28-F$26),Assumptions!$D$22*DCF_Base!$L$8))/(1+$A$28)^10-Assumptions!$B$9)/Assumptions!$B$6,"n/a")
A29: 0.1 | B29: =IF($A$29>B$26,(SUMPRODUCT(DCF_Base!$C$19:$L$19/(1+$A$29)^DCF_Base!$C$4:$L$4)+MAX(0,MIN(DCF_Base!$L$19*(1+B$26)/($A$29-B$26),Assumptions!$D$22*DCF_Base!$L$8))/(1+$A$29)^10-Assumptions!$B$9)/Assumptions!$B$6,"n/a") | C29: =IF($A$29>C$26,(SUMPRODUCT(DCF_Base!$C$19:$L$19/(1+$A$29)^DCF_Base!$C$4:$L$4)+MAX(0,MIN(DCF_Base!$L$19*(1+C$26)/($A$29-C$26),Assumptions!$D$22*DCF_Base!$L$8))/(1+$A$29)^10-Assumptions!$B$9)/Assumptions!$B$6,"n/a") | D29: =IF($A$29>D$26,(SUMPRODUCT(DCF_Base!$C$19:$L$19/(1+$A$29)^DCF_Base!$C$4:$L$4)+MAX(0,MIN(DCF_Base!$L$19*(1+D$26)/($A$29-D$26),Assumptions!$D$22*DCF_Base!$L$8))/(1+$A$29)^10-Assumptions!$B$9)/Assumptions!$B$6,"n/a") | E29: =IF($A$29>E$26,(SUMPRODUCT(DCF_Base!$C$19:$L$19/(1+$A$29)^DCF_Base!$C$4:$L$4)+MAX(0,MIN(DCF_Base!$L$19*(1+E$26)/($A$29-E$26),Assumptions!$D$22*DCF_Base!$L$8))/(1+$A$29)^10-Assumptions!$B$9)/Assumptions!$B$6,"n/a") | F29: =IF($A$29>F$26,(SUMPRODUCT(DCF_Base!$C$19:$L$19/(1+$A$29)^DCF_Base!$C$4:$L$4)+MAX(0,MIN(DCF_Base!$L$19*(1+F$26)/($A$29-F$26),Assumptions!$D$22*DCF_Base!$L$8))/(1+$A$29)^10-Assumptions!$B$9)/Assumptions!$B$6,"n/a")
A30: 0.11 | B30: =IF($A$30>B$26,(SUMPRODUCT(DCF_Base!$C$19:$L$19/(1+$A$30)^DCF_Base!$C$4:$L$4)+MAX(0,MIN(DCF_Base!$L$19*(1+B$26)/($A$30-B$26),Assumptions!$D$22*DCF_Base!$L$8))/(1+$A$30)^10-Assumptions!$B$9)/Assumptions!$B$6,"n/a") | C30: =IF($A$30>C$26,(SUMPRODUCT(DCF_Base!$C$19:$L$19/(1+$A$30)^DCF_Base!$C$4:$L$4)+MAX(0,MIN(DCF_Base!$L$19*(1+C$26)/($A$30-C$26),Assumptions!$D$22*DCF_Base!$L$8))/(1+$A$30)^10-Assumptions!$B$9)/Assumptions!$B$6,"n/a") | D30: =IF($A$30>D$26,(SUMPRODUCT(DCF_Base!$C$19:$L$19/(1+$A$30)^DCF_Base!$C$4:$L$4)+MAX(0,MIN(DCF_Base!$L$19*(1+D$26)/($A$30-D$26),Assumptions!$D$22*DCF_Base!$L$8))/(1+$A$30)^10-Assumptions!$B$9)/Assumptions!$B$6,"n/a") | E30: =IF($A$30>E$26,(SUMPRODUCT(DCF_Base!$C$19:$L$19/(1+$A$30)^DCF_Base!$C$4:$L$4)+MAX(0,MIN(DCF_Base!$L$19*(1+E$26)/($A$30-E$26),Assumptions!$D$22*DCF_Base!$L$8))/(1+$A$30)^10-Assumptions!$B$9)/Assumptions!$B$6,"n/a") | F30: =IF($A$30>F$26,(SUMPRODUCT(DCF_Base!$C$19:$L$19/(1+$A$30)^DCF_Base!$C$4:$L$4)+MAX(0,MIN(DCF_Base!$L$19*(1+F$26)/($A$30-F$26),Assumptions!$D$22*DCF_Base!$L$8))/(1+$A$30)^10-Assumptions!$B$9)/Assumptions!$B$6,"n/a")
A31: 0.12 | B31: =IF($A$31>B$26,(SUMPRODUCT(DCF_Base!$C$19:$L$19/(1+$A$31)^DCF_Base!$C$4:$L$4)+MAX(0,MIN(DCF_Base!$L$19*(1+B$26)/($A$31-B$26),Assumptions!$D$22*DCF_Base!$L$8))/(1+$A$31)^10-Assumptions!$B$9)/Assumptions!$B$6,"n/a") | C31: =IF($A$31>C$26,(SUMPRODUCT(DCF_Base!$C$19:$L$19/(1+$A$31)^DCF_Base!$C$4:$L$4)+MAX(0,MIN(DCF_Base!$L$19*(1+C$26)/($A$31-C$26),Assumptions!$D$22*DCF_Base!$L$8))/(1+$A$31)^10-Assumptions!$B$9)/Assumptions!$B$6,"n/a") | D31: =IF($A$31>D$26,(SUMPRODUCT(DCF_Base!$C$19:$L$19/(1+$A$31)^DCF_Base!$C$4:$L$4)+MAX(0,MIN(DCF_Base!$L$19*(1+D$26)/($A$31-D$26),Assumptions!$D$22*DCF_Base!$L$8))/(1+$A$31)^10-Assumptions!$B$9)/Assumptions!$B$6,"n/a") | E31: =IF($A$31>E$26,(SUMPRODUCT(DCF_Base!$C$19:$L$19/(1+$A$31)^DCF_Base!$C$4:$L$4)+MAX(0,MIN(DCF_Base!$L$19*(1+E$26)/($A$31-E$26),Assumptions!$D$22*DCF_Base!$L$8))/(1+$A$31)^10-Assumptions!$B$9)/Assumptions!$B$6,"n/a") | F31: =IF($A$31>F$26,(SUMPRODUCT(DCF_Base!$C$19:$L$19/(1+$A$31)^DCF_Base!$C$4:$L$4)+MAX(0,MIN(DCF_Base!$L$19*(1+F$26)/($A$31-F$26),Assumptions!$D$22*DCF_Base!$L$8))/(1+$A$31)^10-Assumptions!$B$9)/Assumptions!$B$6,"n/a")
A33: Sanity check (Step 8c) memo
A34: Implied at base IV: P/E 10.4x, P/B 2.2x, EV/EBITDA 6.19x
A35: 10y history (ex-outlier FY2024 for P/E): P/E avg 17.2x max 19.4x; P/B max 4.52x; EV/EBITDA min 8.12x avg 9.92x max 11.41x
A36: Passed: no trip. Implied multiples sit below every level the market has paid in ten years; the price is the outlier, not the model.
