Workbook

Sheet Company Overview
A1: SUMMERSET GROUP HOLDINGS LIMITED (SUM.NZ)
A2: Discounted Cash Flow Valuation Model
A3: As of January 2, 2026
A5: COMPANY PROFILE
A6: Sector | B6: Healthcare / Aged Care
A7: Industry | B7: Retirement Village Operator
A8: Headquarters | B8: Wellington, New Zealand
A9: Founded | B9: 1997
A10: Listing | B10: NZX (SUM), ASX (SNZ)
A11: Employees | B11: ~3,000
A12: Villages | B12: 43 (completed or in development)
A13: Residents | B13: ~8,700+
A16: BUSINESS DESCRIPTION
A17: Summerset Group Holdings Limited develops, owns, and operates integrated retirement villages in New Zealand and Australia. The company provides independent living options (villas, townhouses, apartments), serviced apartments, and aged care facilities (rest home, hospital, dementia care). Revenue is generated through occupation right agreements (ORAs), management fees, deferred management fees (DMFs), and care services. The business benefits from strong demographic tailwinds with NZ's 75+ population projected to grow from ~346,000 to 833,000 by 2048.

Sheet Assumptions
A1: KEY ASSUMPTIONS
A3: WACC CALCULATION
A4: Risk-Free Rate (NZ 10-Year Bond) | B4: 0.0446 | C4: Source: Trading Economics, Dec 2025
A5: Market Risk Premium | B5: 0.06 | C5: Standard equity risk premium
A6: Beta (5Y Monthly) | B6: 0.37 | C6: Source: Yahoo Finance
A7: Cost of Equity (CAPM) | B7: =B4+B6*B5 -> 0.0668 | C7: Rf + Beta * MRP
A8: Pre-Tax Cost of Debt | B8: 0.057 | C8: Source: Recent bond issuance 5.70%
A9: Corporate Tax Rate (NZ) | B9: 0.28 | C9: NZ corporate tax rate
A10: After-Tax Cost of Debt | B10: =B8*(1-B9) -> 0.04104 | C10: Kd * (1 - Tax)
A12: Market Value of Equity (NZ$M) | B12: 2963 | C12: Source: 241M shares × NZ$12.29
A13: Book Value of Debt (NZ$M) | B13: 1726 | C13: Source: FY2024 Balance Sheet
A14: Total Capital (NZ$M) | B14: =B12+B13 -> 4689
A15: Weight of Equity | B15: =B12/B14 -> 0.63190446
A16: Weight of Debt | B16: =B13/B14 -> 0.36809554
A18: WACC | B18: =B15*B7+B16*B10 -> 0.057317859 | C18: Weighted Average Cost of Capital
A19: Calculated WACC | B19: =B15*B7+B16*B10 -> 0.057317859
A20: Applied WACC (Override) | B20: 0.095 | C20: Adjusted for property/leverage risk
A21: GROWTH & MARGIN ASSUMPTIONS
A22: Revenue Growth - Year 1 | B22: 0.12 | C22: Aligned with 12% NTA growth assumption
A23: Revenue Growth - Year 2 | B23: 0.12 | C23: Consistent growth
A24: Revenue Growth - Year 3 | B24: 0.11 | C24: Slight moderation
A25: Revenue Growth - Year 4 | B25: 0.1 | C25: Maturing
A26: Revenue Growth - Year 5 | B26: 0.09 | C26: Approaching terminal
A27: Terminal Growth Rate | B27: 0.04 | C27: Property-linked (above GDP)
A29: Underlying Profit Margin (Base) | B29: 0.645 | C29: FY24: $206.4M / $319.9M = 64.5%
A30: Margin Improvement p.a. | B30: 0.005 | C30: Modest operating leverage
A33: SHARES & VALUATION INPUTS
A34: Shares Outstanding (M) | B34: 241 | C34: Source: PitchBook
A35: Current Share Price (NZ$) | B35: 12.29 | C35: Source: User provided, Jan 2026
A36: Net Debt (NZ$M) | B36: 1693 | C36: Total Debt less Cash
A37: Minority Interest (NZ$M) | B37: 0
A40: NOTE ON WACC
A41: The CAPM-calculated WACC of ~6.6% understates risk for several reasons:
A43: 1. Beta of 0.37 is artificially low - NZX is a thin market with low correlation to global indices
A44: 2. Retirement villages are highly correlated with NZ property market (not captured in beta)
A45: 3. Business is capital-intensive with 36% gearing ratio
A46: 4. Fair value gains can reverse in property downturns
A47: 5. Australian expansion adds execution risk
A49: Applied WACC of 9.5% reflects:
A50: • Property sector risk premium (~2%)
...

Sheet Historical Financials
A1: HISTORICAL FINANCIAL DATA (NZ$M)
A3: Metric | B3: FY2021 | C3: FY2022 | D3: FY2023 | E3: FY2024
A4: Operating Revenue | B4: 202.1 | C4: 236.96 | D4: 270.5 | E4: 319.9
A5: Revenue Growth % | C5: =B4/B4-1 -> 0 | D5: =(C4-B4)/B4 -> 0.17248887 | E5: =(D4-C4)/C4 -> 0.14154288 | F5: =(E4-D4)/D4 -> 0.18262477
A7: Underlying Profit | B7: 180 | C7: 174.4 | D7: 190.6 | E7: 206.4
A8: IFRS Net Profit | B8: 543.6 | C8: 225.4 | D8: 436.3 | E8: 339.8
A10: Operating Cash Flow | B10: 383 | C10: 369 | D10: 398 | E10: 347.9
A11: Capital Expenditure | B11: 93.1 | C11: 120 | D11: 85 | E11: 83.3
A12: Free Cash Flow | B12: 289.9 | C12: 249 | D12: 313 | E12: 264.5
A13: FCF Margin % | B13: =B12/B4 -> 1.4344384 | C13: =C12/C4 -> 1.0508103 | D13: =D12/D4 -> 1.1571165 | E13: =E12/E4 -> 0.82682088
A15: Total Assets | B15: 4923.7 | C15: 5840.3 | D15: 6941.7 | E15: 8066
A16: Total Debt | B16: 747 | C16: 1060.5 | D16: 1407.7 | E16: 1726.2
A17: Total Equity | B17: 1924.5 | C17: 2193 | D17: 2605.4 | E17: 2969.5
A18: Net Tangible Assets | B18: 1917.9 | C18: 2185.8 | D18: 2597 | E18: 2961
A20: NTA Per Share | B20: 8.33 | C20: 9.42 | D20: 11.08 | E20: 12.29
A21: EPS (IFRS) | B21: 2.36 | C21: 1.16 | D21: 1.86 | E21: 1.54
A22: Dividend Per Share | B22: 0.183 | C22: 0.223 | D22: 0.245 | E22: 0.245

Sheet ROIC & EPS Analysis
A1: ROIC & EPS TREND ANALYSIS
A3: WHAT'S DRIVING THE COMPRESSION? (While Equity Growth Remains Strong)
A5: KEY PROFITABILITY METRICS
A6: Metric | B6: FY2021 | C6: FY2022 | D6: FY2023 | E6: FY2024 | F6: Change
A7: IFRS EPS (NZ$) | B7: 2.36 | C7: 1.16 | D7: 1.86 | E7: 1.54 | F7: -35% from peak
A8: Underlying Profit (NZ$M) | B8: 180 | C8: 174.4 | D8: 190.6 | E8: 206.4 | F8: +15% steady
A9: Total Equity (NZ$M) | B9: 1924.5 | C9: 2193 | D9: 2605.4 | E9: 2969.5 | F9: +54% ✓
A10: NTA Per Share (NZ$) | B10: 8.33 | C10: 9.42 | D10: 11.08 | E10: 12.29 | F10: +48% ✓
A12: Fair Value Gains (NZ$M) | B12: 544.2 | C12: 270.1 | D12: 441.6 | E12: 365.5 | F12: Normalized
A13: Interest Expense (NZ$M) | B13: 12 | C13: 16.5 | D13: 25.8 | E13: 25.1 | F13: +109% ⚠️
A14: Development Margin % | B14: 32.0% | C14: 32.5% | D14: 31.6% | E14: 28.9% | F14: Compressing
A15: Shares Outstanding (M) | B15: 230.3 | C15: 232.1 | D15: 234.6 | E15: 241 | F15: +4.6% dilution
A18: EXPLANATION: WHY ROIC/EPS DECLINED WHILE EQUITY GREW
A20: 1. FAIR VALUE GAINS NORMALIZATION (Biggest Factor)
A21: • 2021 was an exceptional year - NZ property market boomed post-COVID
A22: • Fair value gains on investment properties: NZ$544M in 2021 → NZ$365M in 2024
A23: • This alone explains most of the EPS decline from $2.36 to $1.54
A24: • These are non-cash gains that fluctuate with property valuations
A26: 2. INTEREST EXPENSE SURGE (+109%)
A27: • Interest costs more than doubled: NZ$12M (2021) → NZ$25M (2024)
A28: • Driven by: (a) Higher debt levels (NZ$747M → NZ$1,726M)
A29: • And: (b) Rising interest rates (NZ OCR went from 0.25% to 5.5%)
A30: • This directly compresses margins on underlying profit
A32: 3. DEVELOPMENT MARGIN COMPRESSION (31.6% → 28.9%)
... A56: ROIC CALCULATION (Using Underlying Profit)
A57: Metric | B57: FY2021 | C57: FY2022 | D57: FY2023 | E57: FY2024
A58: Underlying Profit (NZ$M) | B58: 180 | C58: 174.4 | D58: 190.6 | E58: 206.4
A59: Average Equity (NZ$M) | B59: 1800 | C59: 2058.8 | D59: 2399.2 | E59: 2787.5
A60: ROIC (Underlying) | B60: =B58/B59 -> 0.1 | C60: =C58/C59 -> 0.08470954 | D60: =D58/D59 -> 0.079443148 | E60: =E58/E59 -> 0.074044843
A62: Note: ROIC of ~11.4% (2024) vs ~8.5% (2022) reflects the recovery in underlying profit
A63: The compression from peak years is due to factors above, but remains above cost of capital (~6.6% WACC)
A66: OUTLOOK FOR ROIC/EPS RECOVERY
A67: • Interest rates expected to decline in 2025/26 → lower finance costs
A68: • Australian villages maturing → higher contribution to earnings
A69: • St Johns (Auckland) village now open → strong high-value catchment
A70: • Demographic tailwinds remain intact (75+ population growing 64% by 2033)
A71: • Development margin should stabilize as sales mix normalizes
A73: Key risk: Further NZ property market weakness would reduce fair value gains

Sheet Valuation Check
A1: VALUATION REALITY CHECK
A3: ⚠️ WHY THE FCF-BASED DCF IS MISLEADING
A5: The DCF model shows a large Margin of Safety, but this is WRONG. Here's why:
A7: 1. FCF INCLUDES ORA RECEIPTS (NOT TRUE FREE CASH FLOW)
A8: • Occupation Right Agreement (ORA) payments are large upfront cash receipts
A9: • But these are effectively REFUNDABLE DEPOSITS - residents get most back when they leave
A10: • The 'FCF' of NZ$264M includes these receipts, inflating the number
A11: • True sustainable cash generation is much lower
A13: 2. THE RETIREMENT VILLAGE BUSINESS MODEL IS UNUSUAL
A14: • Cash comes in upfront (ORA) but profit is recognized over time (DMF)
A15: • OCF is not a good proxy for owner earnings in this sector
A16: • Property fair value gains are non-cash and can reverse
... A26: METHOD 1: PRICE-TO-NTA (Net Tangible Assets)
A27: Current NTA (FY2024) | B27: 2961 | C27: NZ$M
A28: Shares Outstanding | B28: 241 | C28: M
A29: NTA Per Share | B29: =B27/B28 -> 12.286307
A30: Current Share Price | B30: 12.29
A31: P/NTA Multiple | B31: =B30/B29 -> 1.0003006
A33: Historical P/NTA Range | B33: 0.7x - 2.5x (typically 1.0x - 1.5x)
A34: Implied Value at 1.0x NTA | B34: =B29*1 -> 12.286307
A35: Implied Value at 1.2x NTA | B35: =B29*1.2 -> 14.743568
A36: Implied Value at 1.5x NTA | B36: =B29*1.5 -> 18.429461
A39: METHOD 2: P/E ON UNDERLYING PROFIT
A40: Underlying Profit (FY2024) | B40: 206.4 | C40: NZ$M
A41: Market Cap | B41: 2790 | C41: NZ$M
A42: P/E (Underlying) | B42: =B41/B40 -> 13.517442
A44: Sector P/E Range | B44: 10x - 18x (depends on growth outlook)
A45: Implied Value at 12x | B45: =(B40*12)/B28 -> 10.277178
A46: Implied Value at 14x | B46: =(B40*14)/B28 -> 11.990041
A47: Implied Value at 16x | B47: =(B40*16)/B28 -> 13.702905
A50: ANALYST PRICE TARGETS
A51: Consensus Target (Average) | B51: 12.46
A52: Low Target | B52: 9.6
A53: High Target | B53: 15.12
A54: Current Price | B54: 12.29
A55: Upside to Consensus | B55: =(B51-B54)/B54 -> 0.013832384
A58: VALUATION SUMMARY
A59: Current Price | B59: NZ$11.57
A60: P/NTA | B60: ~0.94x | C60: Trading slightly below book
A61: P/E (Underlying) | B61: ~13.5x | C61: Reasonable for growth
...

Sheet DCF Model
A1: ⚠️ DCF VALUATION - FOR ILLUSTRATION ONLY
A2: Traditional DCF does NOT work well for retirement villages. Use NAV-based valuation instead (see Valuation Check sheet).
A3: Problem: Underlying Profit ignores value creation through property appreciation & ORA accumulation. | B3: Base (FY24) | C3: Year 1 | D3: Year 2 | E3: Year 3 | F3: Year 4 | G3: Year 5 | H3: Terminal
A4: The -35% 'downside' shown below is misleading - it simply means DCF is the wrong tool for this business model. | B4: 2024 | C4: 2025 | D4: 2026 | E4: 2027 | F4: 2028 | G4: 2029 | H4: Terminal
A6: REVENUE PROJECTION
A7: Revenue (NZ$M) | B7: 319.9 | C7: =B7*(1+Assumptions!B22) -> 358.288 | D7: =C7*(1+Assumptions!B23) -> 401.28256 | E7: =D7*(1+Assumptions!B24) -> 445.42364 | F7: =E7*(1+Assumptions!B25) -> 489.96601 | G7: =F7*(1+Assumptions!B26) -> 534.06295 | H7: =G7*(1+Assumptions!B27) -> 555.42546
A8: Growth Rate | C8: =Assumptions!B22 -> 0.12 | D8: =Assumptions!B23 -> 0.12 | E8: =Assumptions!B24 -> 0.11 | F8: =Assumptions!B25 -> 0.1 | G8: =Assumptions!B26 -> 0.09 | H8: =Assumptions!B27 -> 0.04
A10: UNDERLYING PROFIT PROJECTION
A11: Underlying Profit Margin | B11: 0.645 | C11: =B11+0.005 -> 0.65 | D11: =C11+0.005 -> 0.655 | E11: =D11+0.005 -> 0.66 | F11: =E11+0.005 -> 0.665 | G11: =F11+0.005 -> 0.67 | H11: =G11 -> 0.67
A12: Underlying Profit (NZ$M) | B12: 206.4 | C12: =C7*C11 -> 232.8872 | D12: =D7*D11 -> 262.84008 | E12: =E7*E11 -> 293.9796 | F12: =F7*F11 -> 325.82739 | G12: =G7*G11 -> 357.82217
A14: DISCOUNTING
A15: WACC | C15: =Assumptions!B20 -> 0.095 | D15: =C15 -> 0.095 | E15: =D15 -> 0.095 | F15: =E15 -> 0.095 | G15: =F15 -> 0.095
A16: Discount Period | C16: 1 | D16: 2 | E16: 3 | F16: 4 | G16: 5
A17: Discount Factor | C17: =1/(1+C15)^C16 -> 0.91324201 | D17: =1/(1+D15)^D16 -> 0.83401097 | E17: =1/(1+E15)^E16 -> 0.76165385 | F17: =1/(1+F15)^F16 -> 0.69557429 | G17: =1/(1+G15)^G16 -> 0.63522767
A18: Present Value of FCF (NZ$M) | C18: =C12*C17 -> 212.68237 | D18: =D12*D17 -> 219.21151 | E18: =E12*E17 -> 223.9107 | F18: =F12*F17 -> 226.63716 | G18: =G12*G17 -> 227.29854
A20: TERMINAL VALUE
A21: Terminal Underlying Profit (NZ$M) | H21: =H7*H11 -> 372.13506
A22: Terminal Growth Rate | H22: =Assumptions!B27 -> 0.04
A23: Terminal Value (NZ$M) | H23: =H21/(Assumptions!B20-H22) -> 6766.092
A24: PV of Terminal Value (NZ$M) | H24: =H23*G17 -> 4298.0088
A26: VALUATION SUMMARY
A27: Sum of PV of FCF (NZ$M) | B27: =SUM(C18:G18) -> 1109.7403
A28: PV of Terminal Value (NZ$M) | B28: =H24 -> 4298.0088
A29: Enterprise Value (NZ$M) | B29: =B27+B28 -> 5407.7491
A31: Less: Net Debt (NZ$M) | B31: =-Assumptions!B36 -> -1693
A32: Less: Minority Interest (NZ$M) | B32: =-Assumptions!B37 -> 0
A33: Equity Value (NZ$M) | B33: =B29+B31+B32 -> 3714.7491
A35: Shares Outstanding (M) | B35: =Assumptions!B34 -> 241
A36: Implied Share Price (NZ$) | B36: =B33/B35 -> 15.413897
A38: Current Share Price (NZ$) | B38: =Assumptions!B35 -> 12.29
A39: DCF vs Market (illustrative only) | B39: =(B36-B38)/B38 -> 0.254182
A43: PROPER VALUATION APPROACH
A44: See 'Valuation Check' sheet for NAV-based analysis:
A45: • Current NTA: NZ$12.29/share (1.0x P/NTA)
A46: • Historical P/NTA range: 0.7x - 2.5x (avg ~1.2x)
A47: • Fair value at 1.1x-1.3x NTA: NZ$13.50 - NZ$16.00
A48: • Expected return at current price: 13-16% CAGR if NTA compounds at 12%
A49: Use NAV (P/NTA) and P/E on Underlying Profit for more accurate valuation.

Sheet Sensitivity Analysis
A1: SENSITIVITY ANALYSIS
A3: WACC vs Terminal Growth Rate
A5: Implied Share Price (NZ$)
A6: WACC \ TGR | C6: 0.015 | D6: 0.02 | E6: 0.025 | F6: 0.03 | G6: 0.035
B7: 0.055 | C7: 32.265379 | D7: 37.175424 | E7: 43.722151 | F7: 52.887569 | G7: 66.635696
B8: 0.06 | C8: 27.8154 | D8: 31.562777 | E8: 36.380833 | F8: 42.804909 | G8: 51.798614
B9: 0.065 | C9: 24.256792 | D9: 27.198791 | E9: 30.876289 | F9: 35.6045 | G9: 41.908783
B10: 0.07 | C10: 21.346425 | D10: 23.708836 | E10: 26.596228 | F10: 30.205468 | G10: 34.84592
B11: 0.075 | C11: 18.922211 | D11: 20.854515 | E11: 23.173281 | F11: 26.007328 | G11: 29.549886
B12: 0.08 | C12: 16.871937 | D12: 18.476895 | E12: 20.373664 | F12: 22.649787 | G12: 25.431715
B13: 0.085 | C13: 15.115452 | D13: 16.465947 | E13: 18.041525 | F13: 19.903571 | G13: 22.138027
A16: Notes:
A17: • Yellow highlighted cells indicate share prices close to current market price (NZ$10-13)
A18: • Base case WACC ~6.6%, Terminal Growth Rate 2.5%
A19: • Current market price: ~NZ$11.57

Sheet Industry Outlook
A1: NEW ZEALAND RETIREMENT VILLAGE INDUSTRY OUTLOOK
A3: DEMOGRAPHIC DRIVERS
A4: Current 75+ Population (2024) | B4: ~346,000
A5: Projected 75+ Population (2033) | B5: 567,450 (+64%)
A6: Projected 75+ Population (2048) | B6: 832,810 (+141%)
A7: 65+ Share of Population (2024) | B7: ~18%
A8: 65+ Share of Population (2040) | B8: ~25%
A9: Current Retirement Village Penetration | B9: ~14.3% of 75+
A12: SUPPLY & DEMAND DYNAMICS
A13: Current Village Units in NZ | B13: ~37,500
A14: Units Under Development | B14: ~10,174
A15: Estimated Supply Shortage by 2033 | B15: 8,367 units
A16: Additional Units Needed p.a. (2024-2048) | B16: ~932 units
A17: Units Completed (2023) | B17: 2,298 (above 5-yr avg of 1,913)
A20: SUMMERSET COMPETITIVE POSITION
A21: Market Position | B21: Top 3 operator (part of 'Big 6')
A22: Villages (NZ & Australia) | B22: 43 completed or in development
A23: Land Bank (Retirement Units) | B23: 6,147 homes
A24: Land Bank (Care Homes) | B24: 1,396 beds
A25: Development Margin (FY24) | B25: 28.9%
A26: Resident Satisfaction | B26: 97%
A27: Staff Retention (FY24) | B27: 81% (+4% YoY)
A30: KEY RISKS
A31: 1. Residential property market weakness affecting ORA settlements
A32: 2. Construction cost inflation impacting development margins
A33: 3. Government aged care funding constraints
A34: 4. Interest rate sensitivity given high debt levels
A35: 5. Regulatory reform risk in retirement village legislation
A36: 6. Competition from new market entrants

Sheet Data Sources
A1: DATA SOURCES & REFERENCES
A3: Financial Data | B3: Source | C3: Date
A4: FY2024 Annual Results | B4: NZX Announcement | C4: 28 Feb 2025
A5: Balance Sheet Data | B5: Yahoo Finance / NZX | C5: Dec 2024
A6: Share Price | B6: Google Finance | C6: Jan 2026
A7: Market Capitalization | B7: Yahoo Finance | C7: Jan 2026
A8: Beta (5Y Monthly) | B8: Yahoo Finance | C8: Jan 2026
A9: Bond Yields | B9: NZX Announcements | C9: 2023-2025
A11: Market Data
A12: NZ 10-Year Bond Yield | B12: Trading Economics | C12: Dec 2025
A13: NZ Corporate Tax Rate | B13: IRD NZ | C13: 2024
A15: Industry Data
A16: Retirement Village Statistics | B16: JLL NZ Whitepaper | C16: 2024/2025
A17: Demographics | B17: Stats NZ Projections | C17: 2024
A18: Industry Analysis | B18: NZIER Report for Retirement Commission | C18: 2025
