Workbook

Sheet Scenario Valuation
A1: AFC.NZ - Scenario / Asset Valuation Model
A2: NOT a growth DCF. Going-concern shell trading at the NZX minimum tick. Gray cells are inputs.
A4: KEY INPUTS
A5: Current Stock Price (NZ$) | B5: 0.001
A6: Shares Outstanding (millions) | B6: 3664.2532
A7: Shares Outstanding (absolute) | B7: =B6*1000000
A8: FY2026 Shareholders' Equity (NZ$) | B8: 206390
A9: FY2026 Cash (of which restricted NZ$37,345) | B9: 39437
A10: FY2026 Total Debt (NZ$) | B10: 169364
A11: Related-Party Payable to NZSG (NZ$) | B11: 1170427
A12: Note: net debt is already embedded in the equity figure above - do not subtract again.
A14: BEAR CASE - Insolvency / Wind-Up
A15: Narrative: shareholder support withdrawn; realizable assets < liabilities in a forced wind-up.
A16: Intrinsic Value / Share (NZ$) | B16: 0
A17: Upside/(Downside) vs Current Price | B17: =(B16-B5)/B5
A19: BASE CASE - Shell Persists on Life Support
A20: Narrative: NZSG continues discretionary funding/forgiveness; no RTO; sub-scale ops continue.
A21: Shell Scarcity Value Assumption (NZ$) | B21: 500000
A22: Base Case Equity Value (NZ$) | B22: =B8+B21
A23: Intrinsic Value / Share (NZ$) | B23: =B22/B7
A24: Upside/(Downside) vs Current Price | B24: =(B23-B5)/B5
A26: BULL CASE - RTO Completes (Speculative Option Value)
A27: Narrative: Fast Track Group (or other) RTO completes; existing holders retain minority stake.
A28: Upper-Precedent Shell Value (NZ$) | B28: 2500000
A29: Intrinsic Value / Share (NZ$) | B29: =B28/B7
A30: Upside/(Downside) vs Current Price | B30: =(B29-B5)/B5
A32: PROBABILITY-WEIGHTED VALUATION
A33: Weight - Bear | B33: 0.55
A34: Weight - Base | B34: 0.35
A35: Weight - Bull | B35: 0.1
A36: Weights sum check (should = 100%) | B36: =B33+B34+B35
A37: Weighted Intrinsic Value / Share (NZ$) | B37: =B16*B33+B23*B34+B29*B35
A38: Weighted Upside/(Downside) vs Current Price | B38: =(B37-B5)/B5
A40: ENTRY PRICE (15% IRR Hurdle, Base Case)
A41: Hurdle Rate | B41: 0.15
A42: Years to Exit | B42: 5
A43: Interim Distributions (dividends/buybacks) | B43: 0
A44: Exit Equity Value in Year 5 (= Base Case Equity Value) | B44: =B22
A45: PV of Exit Value at Hurdle Rate | B45: =B44/(1+B41)^B42
A46: Entry Price / Share (NZ$) | B46: =B45/B7
...

Sheet Sensitivity
A1: Sensitivity Analysis - Base Case Intrinsic Value
A2: Rows: equity haircut (uncertainty on realizability of FY2026 book equity). Columns: shell scarcity value assumption.
A4: Haircut \ Shell $ | B4: 0 | C4: 250000 | D4: 500000 | E4: 750000 | F4: 1000000
A5: 0 | B5: =('Scenario Valuation'!$B$8*(1-$A5)+B$4)/'Scenario Valuation'!$B$7 | C5: =('Scenario Valuation'!$B$8*(1-$A5)+C$4)/'Scenario Valuation'!$B$7 | D5: =('Scenario Valuation'!$B$8*(1-$A5)+D$4)/'Scenario Valuation'!$B$7 | E5: =('Scenario Valuation'!$B$8*(1-$A5)+E$4)/'Scenario Valuation'!$B$7 | F5: =('Scenario Valuation'!$B$8*(1-$A5)+F$4)/'Scenario Valuation'!$B$7
A6: 0.25 | B6: =('Scenario Valuation'!$B$8*(1-$A6)+B$4)/'Scenario Valuation'!$B$7 | C6: =('Scenario Valuation'!$B$8*(1-$A6)+C$4)/'Scenario Valuation'!$B$7 | D6: =('Scenario Valuation'!$B$8*(1-$A6)+D$4)/'Scenario Valuation'!$B$7 | E6: =('Scenario Valuation'!$B$8*(1-$A6)+E$4)/'Scenario Valuation'!$B$7 | F6: =('Scenario Valuation'!$B$8*(1-$A6)+F$4)/'Scenario Valuation'!$B$7
A7: 0.5 | B7: =('Scenario Valuation'!$B$8*(1-$A7)+B$4)/'Scenario Valuation'!$B$7 | C7: =('Scenario Valuation'!$B$8*(1-$A7)+C$4)/'Scenario Valuation'!$B$7 | D7: =('Scenario Valuation'!$B$8*(1-$A7)+D$4)/'Scenario Valuation'!$B$7 | E7: =('Scenario Valuation'!$B$8*(1-$A7)+E$4)/'Scenario Valuation'!$B$7 | F7: =('Scenario Valuation'!$B$8*(1-$A7)+F$4)/'Scenario Valuation'!$B$7
A8: 0.75 | B8: =('Scenario Valuation'!$B$8*(1-$A8)+B$4)/'Scenario Valuation'!$B$7 | C8: =('Scenario Valuation'!$B$8*(1-$A8)+C$4)/'Scenario Valuation'!$B$7 | D8: =('Scenario Valuation'!$B$8*(1-$A8)+D$4)/'Scenario Valuation'!$B$7 | E8: =('Scenario Valuation'!$B$8*(1-$A8)+E$4)/'Scenario Valuation'!$B$7 | F8: =('Scenario Valuation'!$B$8*(1-$A8)+F$4)/'Scenario Valuation'!$B$7
A9: 1 | B9: =('Scenario Valuation'!$B$8*(1-$A9)+B$4)/'Scenario Valuation'!$B$7 | C9: =('Scenario Valuation'!$B$8*(1-$A9)+C$4)/'Scenario Valuation'!$B$7 | D9: =('Scenario Valuation'!$B$8*(1-$A9)+D$4)/'Scenario Valuation'!$B$7 | E9: =('Scenario Valuation'!$B$8*(1-$A9)+E$4)/'Scenario Valuation'!$B$7 | F9: =('Scenario Valuation'!$B$8*(1-$A9)+F$4)/'Scenario Valuation'!$B$7
A11: Every cell in this grid remains far below the current NZ$0.001 price.

Sheet Burn Rate Projection
A1: Cash Burn Projections by Scenario (NZ$)
A2: Shown for disclosure/transparency. Base-case burn is assumed funded externally (NZSG loans/forgiveness) and is a wash against the tangible-equity valuation - not subtracted a second time.
A4: Scenario | B4: FY2027 | C4: FY2028 | D4: FY2029 | E4: FY2030 | F4: FY2031
A5: Base - Operating Cash Burn | B5: -480000 | C5: -400000 | D5: -340000 | E5: -300000 | F5: -280000
A6: Base - Revenue (de minimis) | B6: 140000 | C6: 125000 | D6: 115000 | E6: 105000 | F6: 100000
A7: Bull - FCF (FY27 transaction costs only; post-RTO not modelled) | B7: -350000 | C7: n/m (post-RTO, undisclosed) | D7: n/m (post-RTO, undisclosed) | E7: n/m (post-RTO, undisclosed) | F7: n/m (post-RTO, undisclosed)
A8: Bear - FCF (wind-up during/after FY27) | B8: -650000 | C8: 0 | D8: 0 | E8: 0 | F8: 0
A10: Funding history (context)
A11: FY2026 debt forgiven by NZSG (NZ$) | B11: 500000
A12: FY2026 interest waived by NZSG (NZ$) | B12: 281170
A13: Post year-end advances (Apr+May 2026, NZ$) | B13: 200000

Sheet Historical
A1: Historical Financials (NZD absolute $)
A3: Period | B3: Revenue | C3: Shareholders Equity | D3: Free Cash Flow
A4: FY2019 | B4: 2602043 | C4: 3733719 | D4: -420512
A5: FY2020 | B5: 1234931 | C5: 2563166 | D5: -290903
A6: FY2021 | B6: 646910 | C6: 1291315 | D6: -380450
A7: FY2022 | B7: 415023 | C7: 552890 | D7: -294999
A8: FY2023 | B8: 1075442 | C8: 374469 | D8: 18709
A9: FY2024 | B9: 1324402 | C9: 428380 | D9: -140788
A10: FY2025 | B10: 741088 | C10: 243574 | D10: -324569
A11: FY2026 | B11: 161285 | C11: 206390 | D11: -631437
A13: Revenue 3yr CAGR | B13: -0.4687
A14: Revenue 5yr CAGR | B14: -0.2426
A15: Equity 3yr CAGR | B15: -0.1801
A16: Equity 5yr CAGR | B16: -0.307
A17: FCF positive years since FY2020 | B17: 1 of 7 (FY2023, +$18,709, immaterial)
A19: Note: both revenue and equity CAGRs are deeply NEGATIVE - this is a shrinking, value-destroying business, not a growth story.

Sheet FCF Quality
A1: FCF Quality Reconciliation
A2: SBC is NIL throughout AFC's disclosed history - reported FCF = owner FCF. No SBC adjustment required.
A4: Period | B4: FY2020 | C4: FY2021 | D4: FY2022 | E4: FY2023 | F4: FY2024 | G4: FY2025 | H4: FY2026
A5: Reported FCF (company definition, post IFRS-16 lease principal) | B5: -290903 | C5: -380450 | D5: -294999 | E5: 18709 | F5: -140788 | G5: -324569 | H5: -631437
A6: Less: SBC incl. equity-award taxes | B6: 0 | C6: 0 | D6: 0 | E6: 0 | F6: 0 | G6: 0 | H6: 0
A7: Less: Interest Income | B7: 0 | C7: 0 | D7: 0 | E7: 0 | F7: 0 | G7: 0 | H7: 0
A8: =Owner FCF | B8: =B5-B6-B7 | C8: =C5-C6-C7 | D8: =D5-D6-D7 | E8: =E5-E6-E7 | F8: =F5-F6-F7 | G8: =G5-G6-G7 | H8: =H5-H6-H7
A9: Revenue | B9: 1234931 | C9: 646910 | D9: 415023 | E9: 1075442 | F9: 1324402 | G9: 741088 | H9: 161285
A10: Reported FCF Margin | B10: =B5/B9 | C10: =C5/C9 | D10: =D5/D9 | E10: =E5/E9 | F10: =F5/F9 | G10: =G5/G9 | H10: =H5/H9
A11: Owner FCF Margin | B11: =B8/B9 | C11: =C8/C9 | D11: =D8/D9 | E11: =E8/E9 | F11: =F8/F9 | G11: =G8/G9 | H11: =H8/H9
A13: Memo: cash tax rate | B13: N/A - company has generated tax losses (NZ$1.7M+ accumulated), no cash tax paid, no DTA recognized.
A14: Memo: deferred revenue / working capital timing | B14: Not a subscription/prepaid business model - no material deferred revenue balance disclosed.

Sheet Model_Info
A1: Model Provenance & Methodology Notes
A3: Ticker | B3: AFC.NZ (AFC Group Holdings Limited, NZX)
A4: Built by | B4: Claude dcf-analyst agent, per /Users/swilliams/Stocks/Research/.claude/agents/dcf-analyst.md
A5: Valuation date | B5: 2026-07-31
A6: Data vintage | B6: FY2026 annual report (year ended 31-Mar-2026), released 30-Jun-2026. Share price fetched live from Yahoo Finance on 2026-07-31 (NZ$0.001, the NZX minimum tick).
A7: Model type | B7: Asset/scenario-based valuation, NOT a growth perpetuity DCF. Selected because: (1) no repeatable positive owner FCF history exists (only 1 of 7 years since FY2020 was FCF-positive, and that by an immaterial working-capital blip), (2) explicit FY2026 going-concern material uncertainty audit paragraph, (3) revenue has collapsed 78% YoY and equity has fallen 94% since FY2019, (4) the company survives on non-binding, discretionary related-party shareholder support.
A8: Methodology - Bear | B8: Direct insolvency/wind-up: intrinsic value set to NZ$0.0000/share on the basis that a forced liquidation would leave realizable assets short of liabilities once related-party loans and liquidation costs are applied.
A9: Methodology - Base | B9: Tangible FY2026 shareholders' equity (NZ$206,390) plus a conservative NZ$500,000 listed-shell scarcity value (low end of a NZ$0.5-1.5M precedent range for NZX shells, discounted for AFC's below-average governance quality), divided by shares outstanding. Projected cash burn (FY2027-31) is disclosed for transparency but NOT subtracted from this valuation a second time, because it is assumed funded by continued shareholder loans/forgiveness (consistent with the FY2020-26 pattern) - a wash against the equity balance, not a further drag on it.
A10: Methodology - Bull | B10: Speculative reverse-takeover (RTO) completion. Shell valued at the upper end of NZX shell-value precedent (NZ$2.5M, within a NZ$2-3M range), divided by CURRENT shares outstanding as an approximation of existing holders' retained economic claim on the shell prior to new RTO consideration shares being issued. This is explicitly option value, not a cash-flow DCF - no specific transaction terms are disclosed beyond a non-binding MOU with 'Fast Track Group'.
A11: Probability weights | B11: Bear 55% / Base 35% / Bull 10% - weighted toward bear given the explicit going-concern audit qualification and the entirely discretionary, non-binding nature of the sole funding source (NZ Silveray Group).
A12: WACC / discount rate | B12: Base case 33% (additive build: 4.5% risk-free + 5.5% NZ equity risk premium + 12% illiquidity/micro-cap premium + 8% going-concern premium + 3% related-party concentration premium). NOT a conventional CAPM WACC - no meaningful beta exists for a stock pinned at the minimum tick for 4+ years. Used only for the entry-price 15%-hurdle comparison; the base/bear/bull scenario valuations themselves do not discount a perpetuity cash-flow stream (there isn't one).
A13: SBC treatment | B13: Nil throughout disclosed history (Metrics.csv StockBasedComp = 0 every period, FY2017-FY2026). No adjustment required; reported FCF = owner FCF.
A14: Units | B14: All dollar figures NZD absolute dollars (NOT thousands or millions) except shares_outstanding, which is in millions per the Metrics.csv convention (3,664.253194 = 3.664 billion shares).
... A18: Staleness warning | B18: This is a going-concern micro-cap shell - facts can change materially within weeks (as evidenced by the 30-Jul-2026 director resignation disclosed the day before this model was built). Do not rely on this file without checking for NZX announcements more recent than the valuation date above.
