Workbook

Sheet Model_Info
A1: WHS.NZ owner-FCF DCF model
A2: Version | B2: v1 (2026-09-21). Fresh build; supersedes nothing (first WHS.NZ valuation in this folder).
A3: Built by | B3: dcf-analyst agent (Claude Fable 5.1), 2026-09-21, at the request of the research-stock pipeline (step 8) for Stephen Williams.
A4: Company | B4: The Warehouse Group Limited (NZX: WHS). NZ general-merchandise retailer: The Warehouse, Warehouse Stationery, Noel Leeming. 52/53-week FY ending late Jul/early Aug.
A5: Currency / units | B5: NZD millions throughout (filings are NZ$000; divided by 1,000). Quote currency NZD.
A6: Price | B6: NZ$0.6 as of 2026-09-21T04:15:20Z NZX regular close (Yahoo regularMarketTime via make dcf-context). Figures go stale: refresh the price, and after the FY2026 result (due late Sep-2026) refresh EBITDA, capex, net debt and guidance.
A7: Balance sheet | B7: H1 FY2026 interim financial statements (26 weeks to 1-Feb-2026, released 27-Mar-2026): cash 43,264k, borrowings 136,570k, lease liabilities 708,861k, minority interest 1,108k (date 2026-02-01).
A8: Share count | B8: 345,354k ordinary shares net of treasury (FY2025 Annual Report EPS note, weighted average = period-end, unchanged since FY2022; H1 FY2026 basic = diluted EPS 4.6c). No dilutive instruments: FY25/FY26 LTI is cash-settled. Held FLAT; SBC is nil so there is nothing to double-count.
A9: Guidance | B9: None issued for FY2026 beyond 'cost reset to restore profitability' (Nov-2025) and the subsequent-event warning on Middle East freight costs (H1 FY26 note 2).
A10: Method | B10: owner-fcf.md (dcf-methods skill), lease treatment (B), 10-year horizon, end-of-year discounting, TV = max(0, min(Gordon, 12x FCF_10)), entry price with TV rebuilt at the 15% hurdle.
A11: Lease treatment | B11: Treatment (B): leases as operating cost. The FULL IFRS-16 lease cash (FY2025: principal $104.882m in financing + interest $36.847m in operating = $141.729m, 4.6% of revenue; H1 FY2026 $64.570m) is deducted inside the flow build as a dollar premises bill ($140m FY2026E escalating 2%/yr, expressed per scenario as lease_cost_pct_path), and lease liabilities ($708.9m at 1-Feb-2026) are EXCLUDED from net debt. net_debt = borrowings $136.570m less cash $43.264m = $93.306m, which ties to the company's own note 13 'Net cash/(debt)' (93,306). D&A for cash-tax EBIT is ex right-of-use depreciation (FY2025: $156.5m total less $93.3m ROU = $63.2m, 2.05% of revenue), so the lease is charged once. core_metrics.total_debt already excludes leases, so the CSV and the DCF are on the same basis.
A12: WACC | B12: NZD flows discounted at a NZD-built rate. Bottom-up: NZ 10y govt ~4.4% + beta 1.25 (NZX cyclical discretionary retailer, mkt cap ~NZ$207m) x 5.5% ERP = 11.3% cost of equity; after-tax cost of debt ~4.7% (BKBM + margin, 28% tax); 30% debt / 70% equity ex-lease => 9.3%. The company's own FY2025 impairment tests use 11.1-11.7% post-tax. House rate 10.0%, the midpoint, applied to ALL THREE scenarios: cyclicality, competitive erosion and covenant risk are charged in the scenario flows and the 30% bear weight, not stacked into the discount rate (owner-fcf.md s7f).
A13: SBC | B13: FY2025 Annual Report note 3.2 'Share based payment expense' nil (FY2024: $804k); FY25 LTI was cash-settled. SBC-zero market per owner-fcf.md s7(e): SBC rows kept explicit at 0%.
... A21: Refresh after next print | B21: FY2026 actuals (revenue, post-IFRS-16 EBITDA, lease cash, ex-ROU D&A, capex, cash tax, net debt at ~2-Aug-2026, share count), any FY2027 guidance, dividend decision, covenant status.

Sheet Actuals
A1: FY | B1: Revenue | C1: EBITDA post-IFRS16 | D1: Lease cash (P+I) | E1: Lease-adj EBITDA | F1: Lease-adj margin % | G1: Reported FCF | H1: Lease principal | I1: SBC | J1: Interest income | K1: Owner FCF | L1: Owner FCF margin % | M1: Capex | N1: Source
A2: FY2018 | B2: 2994.571 | C2: 116.937 | D2: 0 | E2: 116.937 | F2: 3.9 | G2: 37.685 | H2: 0 | I2: 0.353 | J2: 1.494 | K2: 35.838 | L2: 1.2 | M2: 70.229 | N2: WHS.NZ_Annual_FY2018.txt income statement / cash-flow statement (NZ$000 / 1000)
A3: FY2019 | B3: 3071.357 | C3: 163.556 | D3: 0 | E3: 163.556 | F3: 5.33 | G3: 136.667 | H3: 0 | I3: 0.42 | J3: 0.436 | K3: 135.811 | L3: 4.42 | M3: 61.326 | N3: WHS.NZ_Annual_FY2019.txt income statement / cash-flow statement (NZ$000 / 1000)
A4: FY2020 | B4: 3172.83 | C4: 259.334 | D4: 124.946 | E4: 134.388 | F4: 4.24 | G4: 343.493 | H4: 83.833 | I4: 0 | J4: 0.713 | K4: 258.947 | L4: 8.16 | M4: 64.513 | N4: WHS.NZ_Annual_FY2020.txt income statement / cash-flow statement (NZ$000 / 1000)
A5: FY2021 | B5: 3414.601 | C5: 343.462 | D5: 137.88 | E5: 205.582 | F5: 6.02 | G5: 164.081 | H5: 99.383 | I5: 0 | J5: 1.048 | K5: 63.65 | L5: 1.86 | M5: 83.18 | N5: WHS.NZ_Annual_FY2021.txt income statement / cash-flow statement (NZ$000 / 1000)
A6: FY2022 | B6: 3294.332 | C6: 304.892 | D6: 134.947 | E6: 169.945 | F6: 5.16 | G6: -2.046 | H6: 98.264 | I6: 0 | J6: 0.592 | K6: -100.902 | L6: -3.06 | M6: 107.469 | N6: WHS.NZ_Annual_FY2022.txt income statement / cash-flow statement (NZ$000 / 1000)
A7: FY2023 | B7: 3399.112 | C7: 250.811 | D7: 137.37 | E7: 113.441 | F7: 3.34 | G7: 99.095 | H7: 101.171 | I7: 0.804 | J7: 0.748 | K7: -3.628 | L7: -0.11 | M7: 115.088 | N7: WHS.NZ_Annual_FY2023.txt income statement / cash-flow statement (NZ$000 / 1000)
A8: FY2024 | B8: 3037.597 | C8: 217.496 | D8: 136.059 | E8: 81.437 | F8: 2.68 | G8: 146.586 | H8: 99.532 | I8: 0 | J8: 1.001 | K8: 46.053 | L8: 1.52 | M8: 39.284 | N8: WHS.NZ_Annual_FY2024.txt income statement / cash-flow statement (NZ$000 / 1000)
A9: FY2025 | B9: 3086.725 | C9: 197.04 | D9: 141.729 | E9: 55.311 | F9: 1.79 | G9: 59.719 | H9: 104.882 | I9: 0 | J9: 0.319 | K9: -45.482 | L9: -1.47 | M9: 12.604 | N9: WHS.NZ_Annual_FY2025.txt income statement / cash-flow statement (NZ$000 / 1000)
A11: Balance sheet snapshot (1-Feb-2026, H1 FY2026 interim)
A12: Cash | B12: 43.264
A13: Borrowings (ex-lease) | B13: 136.57
A14: Net debt | B14: 93.306
A15: Lease liabilities (excluded from net debt, treatment B) | B15: 708.861
A16: Minority interest (book) | B16: 1.108
A17: Shares (m, net of treasury; basic = diluted) | B17: 345.354
A18: Buybacks FY2023-26 | B18: 0
A19: Dividends | B19: None since FY2024 interim; policy >=70% adjusted NPAT
A20: H1 FY2026 lease-adj EBITDA | B20: 51.898
A21: H1 FY2025 lease-adj EBITDA | B21: 50.244
A22: TTM lease-adj EBITDA | B22: 56.965
A23: Carried-forward tax losses (DTA $34.0m at 28%) | B23: 121.4

Sheet Assumptions
A1: Global assumptions (blue = input)
A4: WACC (all scenarios) | B4: 0.1 | C4: NZD-built; see Model_Info
A5: Terminal cap multiple (x FCF_10) | B5: 12 | C5: 12x: cyclical retailer
A6: WC capture (share of revenue change) | B6: -0.05 | C6: negative: growth consumes cash
A7: Net debt (ex-lease), 1-Feb-2026 | B7: 93.306 | C7: borrowings 136.570 - cash 43.264
A8: Minority interest (book), 1-Feb-2026 | B8: 1.108 | C8: deducted once in bridge
A9: Diluted shares (m) | B9: 345.354 | C9: flat; SBC nil
A10: Current price (NZD) | B10: 0.6 | C10: 2026-09-21T04:15:20Z NZX regular close (Yahoo regularMarketTime via make dcf-context)
A11: Lease cash bill FY2026E (principal + interest) | B11: 140 | C11: FY25 actual 141.729; H1 FY26 64.570
A12: Lease bill escalator (p.a.) | B12: 0.02 | C12: CPI-linked rent, shrinking store count
A13: Hurdle rate for entry price | B13: 0.15 | C13: TV rebuilt at this rate
A14: Revenue FY2025A (base year) | B14: 3086.725 | C14: 53 weeks to 3-Aug-2025
A16: Scenario | B16: Terminal growth | C16: Probability
A17: Bear | B17: 0.01 | C17: 0.3
A18: Base | B18: 0.02 | C18: 0.5
A19: Bull | B19: 0.025 | C19: 0.2
A20: Weights check (must be 1.0) | C20: =SUM(C17:C19)
A22: Scenario narratives
A23: Bear | B23: NZ discretionary spending stays weak through FY2027 (fuel/freight shock from the Middle East conflict flagged as a subsequent event, weak consumer confidence), Kmart's store roll-out and Temu/Shein take general-merchandise share from The Warehouse, and Noel Leeming's margin stays ~1-2% under JB Hi-Fi/Harvey Norman pressure. Reported revenue falls 3% in FY26 (52 vs 53 weeks plus the Q3 run-rate), slips again in FY27, then grows ~1% nominal (negative real), the cost reset only offsets wage inflation, so the lease-adjusted EBITDA margin never recovers from ~2%. Capex still has to normalise to ~1.7% of sales to keep 217 stores trading, so owner FCF trends to ~zero: the terminal value hits the zero floor and equity is worth less than the $93m of bank debt -- i.e. the business is a going concern only because the banks keep amending the interest-cover covenant (already reset twice, to 6.5x/7.5x operating-profit-plus-depreciation for FY26/FY27).
A24: Base | B24: Partial mid-cycle recovery, not a return to the FY2019-22 margins. The Nov-2025 cost reset (TCS co-sourcing of technology, accounting, call centres and payroll; $4.8m redundancy; SSO costs already -7.8% in FY25) lifts the lease-adjusted EBITDA margin from 1.8% to 3.2% by FY2031 -- guided savings are only ~$17m annualised by FY2031, so the rest comes from the gross-margin recovery already visible in Q3 FY26 (+50bps) and modest operating leverage; 3.2% is below the 4.0% eight-year median and well below the company's own impairment-test terminal EBIT margins of 3.2-4.0% -- with FY2026 reported revenue ~2% lower (52 weeks vs 53, Q3 sales -1.4%) then ~2% nominal growth (zero real: store count still shrinking, 84 Warehouse stores vs 88 two years ago). Capex normalises from $12.6m to 2% of revenue, the $121m of tax losses shelter cash tax until FY2029, and working capital consumes 5c per dollar of growth. Owner FCF settles at ~$30m (0.8% margin) -- roughly the cost of capital on a $300m ex-lease EV, so the equity value is a modest premium to net assets.
A25: Bull | B25: The cost reset delivers in full and the consumer cycle turns: OCR cuts restore NZ discretionary spending in FY2027-28, The Warehouse's private-label/grocery mix and 1-hour click-and-collect hold share against Kmart and Temu, Noel Leeming's operating margin returns to ~3% and Warehouse Stationery holds ~7% (H1 FY26 already 7.0%). After the 52-week FY26 (-1.5%), revenue grows 3-3.5% for three years, the lease-adjusted EBITDA margin reaches 4.5% (post-IFRS-16 9.0%, still below FY2021-22's 9.3-10.1%), dividends resume under the 70% policy, and the market re-rates a $400m+ ex-lease EV. Requires several independent things to go right (macro, competition, execution), hence the 20% weight.
A27: Weights rationale | B27: Bear raised from the 15% house default to 30%: interest-cover covenants have been amended twice (FY25 and again for FY26/FY27), FY2025 adjusted NPAT was a loss, no dividend is being paid, the balance sheet has $93m of bank debt against a business whose lease-adjusted EBITDA is $57m, and the two structural threats (Kmart roll-out, Temu/Shein) are independent of the cycle. Bull cut to 20% because it needs macro recovery, competitive share-hold AND cost-reset execution simultaneously. Base 50%.

Sheet DCF_Bear
A1: DCF_Bear: owner-FCF build (NZD m), lease treatment B
A3: Year | B3: FY2025A | C3: FY2026E | D3: FY2027E | E3: FY2028E | F3: FY2029E | G3: FY2030E | H3: FY2031E | I3: FY2032E | J3: FY2033E | K3: FY2034E | L3: FY2035E
A4: Index | B4: 0 | C4: 1 | D4: 2 | E4: 3 | F4: 4 | G4: 5 | H4: 6 | I4: 7 | J4: 8 | K4: 9 | L4: 10
A5: Revenue growth YoY (driver) | C5: -0.03 | D5: -0.01 | E5: 0 | F5: 0.005 | G5: 0.01 | H5: 0.01 | I5: 0.01 | J5: 0.01 | K5: 0.01 | L5: 0.01
A6: Revenue | B6: =Assumptions!B14 | C6: =B6*(1+C5) | D6: =C6*(1+D5) | E6: =D6*(1+E5) | F6: =E6*(1+F5) | G6: =F6*(1+G5) | H6: =G6*(1+H5) | I6: =H6*(1+I5) | J6: =I6*(1+J5) | ... L6: =K6*(1+L5)
A7: Adj EBITDA margin, post-IFRS-16 (driver) | C7: 0.065 | D7: 0.065 | E7: 0.066 | F7: 0.067 | G7: 0.068 | H7: 0.068 | I7: 0.068 | J7: 0.068 | K7: 0.068 | L7: 0.068
A8: Adjusted EBITDA (post-IFRS-16) | C8: =C6*C7 | D8: =D6*D7 | E8: =E6*E7 | F8: =F6*F7 | G8: =G6*G7 | H8: =H6*H7 | I8: =I6*I7 | J8: =J6*J7 | ... L8: =L6*L7
A9: SBC % of revenue (driver) | C9: 0 | D9: 0 | E9: 0 | F9: 0 | G9: 0 | H9: 0 | I9: 0 | J9: 0 | K9: 0 | L9: 0
A10: SBC $ (negative) | C10: =-C6*C9 | D10: =-D6*D9 | E10: =-E6*E9 | F10: =-F6*F9 | G10: =-G6*G9 | H10: =-H6*H9 | I10: =-I6*I9 | J10: =-J6*J9 | ... L10: =-L6*L9
A11: Lease cash: principal + interest (negative; link) | C11: =-Assumptions!B11 | D11: =C11*(1+Assumptions!B12) | E11: =D11*(1+Assumptions!B12) | F11: =E11*(1+Assumptions!B12) | G11: =F11*(1+Assumptions!B12) | H11: =G11*(1+Assumptions!B12) | I11: =H11*(1+Assumptions!B12) | J11: =I11*(1+Assumptions!B12) | K11: =J11*(1+Assumptions!B12) | L11: =K11*(1+Assumptions!B12)
A12: Owner EBITDA (lease-adjusted, SBC expensed) | C12: =C8+C10+C11 | D12: =D8+D10+D11 | E12: =E8+E10+E11 | F12: =F8+F10+F11 | G12: =G8+G10+G11 | H12: =H8+H10+H11 | I12: =I8+I10+I11 | J12: =J8+J10+J11 | ... L12: =L8+L10+L11
A13: D&A % of revenue, ex-ROU (driver) | C13: 0.018 | D13: 0.017 | E13: 0.017 | F13: 0.017 | G13: 0.017 | H13: 0.017 | I13: 0.017 | J13: 0.017 | K13: 0.017 | L13: 0.017
A14: D&A ex-ROU (negative) | C14: =-C6*C13 | D14: =-D6*D13 | E14: =-E6*E13 | F14: =-F6*F13 | G14: =-G6*G13 | H14: =-H6*H13 | I14: =-I6*I13 | J14: =-J6*J13 | ... L14: =-L6*L13
A15: EBIT (for cash tax) | C15: =C12+C14 | D15: =D12+D14 | E15: =E12+E14 | F15: =F12+F14 | G15: =G12+G14 | H15: =H12+H14 | I15: =I12+I14 | J15: =J12+J14 | ... L15: =L12+L14
A16: Cash tax rate (driver) | C16: 0 | D16: 0 | E16: 0 | F16: 0 | G16: 0 | H16: 0 | I16: 0.05 | J16: 0.15 | K16: 0.28 | L16: 0.28
A17: Cash tax (negative; on MAX(0,EBIT)) | C17: =-MAX(0,C15)*C16 | D17: =-MAX(0,D15)*D16 | E17: =-MAX(0,E15)*E16 | F17: =-MAX(0,F15)*F16 | G17: =-MAX(0,G15)*G16 | H17: =-MAX(0,H15)*H16 | I17: =-MAX(0,I15)*I16 | J17: =-MAX(0,J15)*J16 | ... L17: =-MAX(0,L15)*L16
A18: NOPAT | C18: =C15+C17 | D18: =D15+D17 | E18: =E15+E17 | F18: =F15+F17 | G18: =G15+G17 | H18: =H15+H17 | I18: =I15+I17 | J18: =J15+J17 | ... L18: =L15+L17
A19: add back D&A | C19: =-C14 | D19: =-D14 | E19: =-E14 | F19: =-F14 | G19: =-G14 | H19: =-H14 | I19: =-I14 | J19: =-J14 | ... L19: =-L14
A20: Capex % of revenue (driver) | C20: 0.007 | D20: 0.011 | E20: 0.014 | F20: 0.016 | G20: 0.017 | H20: 0.017 | I20: 0.017 | J20: 0.017 | K20: 0.017 | L20: 0.017
A21: less capex | C21: =-C6*C20 | D21: =-D6*D20 | E21: =-E6*E20 | F21: =-F6*F20 | G21: =-G6*G20 | H21: =-H6*H20 | I21: =-I6*I20 | J21: =-J6*J20 | ... L21: =-L6*L20
A22: add working capital (on revenue change) | C22: =Assumptions!$B$6*(C6-B6) | D22: =Assumptions!$B$6*(D6-C6) | E22: =Assumptions!$B$6*(E6-D6) | F22: =Assumptions!$B$6*(F6-E6) | G22: =Assumptions!$B$6*(G6-F6) | H22: =Assumptions!$B$6*(H6-G6) | I22: =Assumptions!$B$6*(I6-H6) | J22: =Assumptions!$B$6*(J6-I6) | ... L22: =Assumptions!$B$6*(L6-K6)
A23: Unlevered owner FCF | C23: =C18+C19+C21+C22 | D23: =D18+D19+D21+D22 | E23: =E18+E19+E21+E22 | F23: =F18+F19+F21+F22 | G23: =G18+G19+G21+G22 | H23: =H18+H19+H21+H22 | I23: =I18+I19+I21+I22 | J23: =J18+J19+J21+J22 | ... L23: =L18+L19+L21+L22
A24: Discount factor | C24: =1/(1+Assumptions!$B$4)^C4 | D24: =1/(1+Assumptions!$B$4)^D4 | E24: =1/(1+Assumptions!$B$4)^E4 | F24: =1/(1+Assumptions!$B$4)^F4 | G24: =1/(1+Assumptions!$B$4)^G4 | H24: =1/(1+Assumptions!$B$4)^H4 | I24: =1/(1+Assumptions!$B$4)^I4 | J24: =1/(1+Assumptions!$B$4)^J4 | ... L24: =1/(1+Assumptions!$B$4)^L4
A25: PV of FCF | C25: =C23*C24 | D25: =D23*D24 | E25: =E23*E24 | F25: =F23*F24 | G25: =G23*G24 | H25: =H23*H24 | I25: =I23*I24 | J25: =J23*J24 | ... L25: =L23*L24
A27: Memo: FCF before SBC (company-style) | C27: =C23-C10 | D27: =D23-D10 | E27: =E23-E10 | F27: =F23-F10 | G27: =G23-G10 | H27: =H23-H10 | I27: =I23-I10 | J27: =J23-J10 | ... L27: =L23-L10
A28: Memo: owner FCF margin | C28: =C23/C6 | D28: =D23/D6 | E28: =E23/E6 | F28: =F23/F6 | G28: =G23/G6 | H28: =H23/H6 | I28: =I23/I6 | J28: =J23/J6 | ... L28: =L23/L6
A29: Memo: lease cash % of revenue | C29: =-C11/C6 | D29: =-D11/D6 | E29: =-E11/E6 | F29: =-F11/F6 | G29: =-G11/G6 | H29: =-H11/H6 | I29: =-I11/I6 | J29: =-J11/J6 | ... L29: =-L11/L6
A31: Sum of PV (explicit years) | B31: =SUM(C25:L25)
A32: Terminal growth | B32: =Assumptions!B17
A33: Terminal FCF (yr 10 x (1+g)) | B33: =L23*(1+B32)
A34: Gordon TV | B34: =IF(Assumptions!B4>B32,B33/(Assumptions!B4-B32),"n/a")
A35: Cap TV (cap x FCF_10) | B35: =Assumptions!B5*L23
A36: TV used = MAX(0, MIN(Gordon, cap)) | B36: =MAX(0,MIN(IF(ISNUMBER(B34),B34,1E+99),B35))
A37: Implied exit multiple (TV / FCF_10) | B37: =IF(L23>0,B36/L23,"n/a")
A38: PV of TV | B38: =B36*L24
A39: Enterprise value | B39: =B31+B38
A40: less net debt | B40: =-Assumptions!B7
A41: less minority interest | B41: =-Assumptions!B8
A42: Equity value | B42: =B39+B40+B41
A43: Diluted shares (m) | B43: =Assumptions!B9
...

Sheet DCF_Base
A1: DCF_Base: owner-FCF build (NZD m), lease treatment B
A3: Year | B3: FY2025A | C3: FY2026E | D3: FY2027E | E3: FY2028E | F3: FY2029E | G3: FY2030E | H3: FY2031E | I3: FY2032E | J3: FY2033E | K3: FY2034E | L3: FY2035E
A4: Index | B4: 0 | C4: 1 | D4: 2 | E4: 3 | F4: 4 | G4: 5 | H4: 6 | I4: 7 | J4: 8 | K4: 9 | L4: 10
A5: Revenue growth YoY (driver) | C5: -0.02 | D5: 0.015 | E5: 0.02 | F5: 0.02 | G5: 0.02 | H5: 0.02 | I5: 0.02 | J5: 0.02 | K5: 0.02 | L5: 0.02
A6: Revenue | B6: =Assumptions!B14 | C6: =B6*(1+C5) | D6: =C6*(1+D5) | E6: =D6*(1+E5) | F6: =E6*(1+F5) | G6: =F6*(1+G5) | H6: =G6*(1+H5) | I6: =H6*(1+I5) | J6: =I6*(1+J5) | ... L6: =K6*(1+L5)
A7: Adj EBITDA margin, post-IFRS-16 (driver) | C7: 0.066 | D7: 0.069 | E7: 0.072 | F7: 0.075 | G7: 0.076 | H7: 0.077 | I7: 0.077 | J7: 0.077 | K7: 0.077 | L7: 0.077
A8: Adjusted EBITDA (post-IFRS-16) | C8: =C6*C7 | D8: =D6*D7 | E8: =E6*E7 | F8: =F6*F7 | G8: =G6*G7 | H8: =H6*H7 | I8: =I6*I7 | J8: =J6*J7 | ... L8: =L6*L7
A9: SBC % of revenue (driver) | C9: 0 | D9: 0 | E9: 0 | F9: 0 | G9: 0 | H9: 0 | I9: 0 | J9: 0 | K9: 0 | L9: 0
A10: SBC $ (negative) | C10: =-C6*C9 | D10: =-D6*D9 | E10: =-E6*E9 | F10: =-F6*F9 | G10: =-G6*G9 | H10: =-H6*H9 | I10: =-I6*I9 | J10: =-J6*J9 | ... L10: =-L6*L9
A11: Lease cash: principal + interest (negative; link) | C11: =-Assumptions!B11 | D11: =C11*(1+Assumptions!B12) | E11: =D11*(1+Assumptions!B12) | F11: =E11*(1+Assumptions!B12) | G11: =F11*(1+Assumptions!B12) | H11: =G11*(1+Assumptions!B12) | I11: =H11*(1+Assumptions!B12) | J11: =I11*(1+Assumptions!B12) | K11: =J11*(1+Assumptions!B12) | L11: =K11*(1+Assumptions!B12)
A12: Owner EBITDA (lease-adjusted, SBC expensed) | C12: =C8+C10+C11 | D12: =D8+D10+D11 | E12: =E8+E10+E11 | F12: =F8+F10+F11 | G12: =G8+G10+G11 | H12: =H8+H10+H11 | I12: =I8+I10+I11 | J12: =J8+J10+J11 | ... L12: =L8+L10+L11
A13: D&A % of revenue, ex-ROU (driver) | C13: 0.018 | D13: 0.017 | E13: 0.017 | F13: 0.018 | G13: 0.019 | H13: 0.02 | I13: 0.02 | J13: 0.02 | K13: 0.02 | L13: 0.02
A14: D&A ex-ROU (negative) | C14: =-C6*C13 | D14: =-D6*D13 | E14: =-E6*E13 | F14: =-F6*F13 | G14: =-G6*G13 | H14: =-H6*H13 | I14: =-I6*I13 | J14: =-J6*J13 | ... L14: =-L6*L13
A15: EBIT (for cash tax) | C15: =C12+C14 | D15: =D12+D14 | E15: =E12+E14 | F15: =F12+F14 | G15: =G12+G14 | H15: =H12+H14 | I15: =I12+I14 | J15: =J12+J14 | ... L15: =L12+L14
A16: Cash tax rate (driver) | C16: 0 | D16: 0 | E16: 0 | F16: 0.1 | G16: 0.28 | H16: 0.28 | I16: 0.28 | J16: 0.28 | K16: 0.28 | L16: 0.28
A17: Cash tax (negative; on MAX(0,EBIT)) | C17: =-MAX(0,C15)*C16 | D17: =-MAX(0,D15)*D16 | E17: =-MAX(0,E15)*E16 | F17: =-MAX(0,F15)*F16 | G17: =-MAX(0,G15)*G16 | H17: =-MAX(0,H15)*H16 | I17: =-MAX(0,I15)*I16 | J17: =-MAX(0,J15)*J16 | ... L17: =-MAX(0,L15)*L16
A18: NOPAT | C18: =C15+C17 | D18: =D15+D17 | E18: =E15+E17 | F18: =F15+F17 | G18: =G15+G17 | H18: =H15+H17 | I18: =I15+I17 | J18: =J15+J17 | ... L18: =L15+L17
A19: add back D&A | C19: =-C14 | D19: =-D14 | E19: =-E14 | F19: =-F14 | G19: =-G14 | H19: =-H14 | I19: =-I14 | J19: =-J14 | ... L19: =-L14
A20: Capex % of revenue (driver) | C20: 0.007 | D20: 0.012 | E20: 0.016 | F20: 0.019 | G20: 0.02 | H20: 0.02 | I20: 0.02 | J20: 0.02 | K20: 0.02 | L20: 0.02
A21: less capex | C21: =-C6*C20 | D21: =-D6*D20 | E21: =-E6*E20 | F21: =-F6*F20 | G21: =-G6*G20 | H21: =-H6*H20 | I21: =-I6*I20 | J21: =-J6*J20 | ... L21: =-L6*L20
A22: add working capital (on revenue change) | C22: =Assumptions!$B$6*(C6-B6) | D22: =Assumptions!$B$6*(D6-C6) | E22: =Assumptions!$B$6*(E6-D6) | F22: =Assumptions!$B$6*(F6-E6) | G22: =Assumptions!$B$6*(G6-F6) | H22: =Assumptions!$B$6*(H6-G6) | I22: =Assumptions!$B$6*(I6-H6) | J22: =Assumptions!$B$6*(J6-I6) | ... L22: =Assumptions!$B$6*(L6-K6)
A23: Unlevered owner FCF | C23: =C18+C19+C21+C22 | D23: =D18+D19+D21+D22 | E23: =E18+E19+E21+E22 | F23: =F18+F19+F21+F22 | G23: =G18+G19+G21+G22 | H23: =H18+H19+H21+H22 | I23: =I18+I19+I21+I22 | J23: =J18+J19+J21+J22 | ... L23: =L18+L19+L21+L22
A24: Discount factor | C24: =1/(1+Assumptions!$B$4)^C4 | D24: =1/(1+Assumptions!$B$4)^D4 | E24: =1/(1+Assumptions!$B$4)^E4 | F24: =1/(1+Assumptions!$B$4)^F4 | G24: =1/(1+Assumptions!$B$4)^G4 | H24: =1/(1+Assumptions!$B$4)^H4 | I24: =1/(1+Assumptions!$B$4)^I4 | J24: =1/(1+Assumptions!$B$4)^J4 | ... L24: =1/(1+Assumptions!$B$4)^L4
A25: PV of FCF | C25: =C23*C24 | D25: =D23*D24 | E25: =E23*E24 | F25: =F23*F24 | G25: =G23*G24 | H25: =H23*H24 | I25: =I23*I24 | J25: =J23*J24 | ... L25: =L23*L24
A27: Memo: FCF before SBC (company-style) | C27: =C23-C10 | D27: =D23-D10 | E27: =E23-E10 | F27: =F23-F10 | G27: =G23-G10 | H27: =H23-H10 | I27: =I23-I10 | J27: =J23-J10 | ... L27: =L23-L10
A28: Memo: owner FCF margin | C28: =C23/C6 | D28: =D23/D6 | E28: =E23/E6 | F28: =F23/F6 | G28: =G23/G6 | H28: =H23/H6 | I28: =I23/I6 | J28: =J23/J6 | ... L28: =L23/L6
A29: Memo: lease cash % of revenue | C29: =-C11/C6 | D29: =-D11/D6 | E29: =-E11/E6 | F29: =-F11/F6 | G29: =-G11/G6 | H29: =-H11/H6 | I29: =-I11/I6 | J29: =-J11/J6 | ... L29: =-L11/L6
A31: Sum of PV (explicit years) | B31: =SUM(C25:L25)
A32: Terminal growth | B32: =Assumptions!B18
A33: Terminal FCF (yr 10 x (1+g)) | B33: =L23*(1+B32)
A34: Gordon TV | B34: =IF(Assumptions!B4>B32,B33/(Assumptions!B4-B32),"n/a")
A35: Cap TV (cap x FCF_10) | B35: =Assumptions!B5*L23
A36: TV used = MAX(0, MIN(Gordon, cap)) | B36: =MAX(0,MIN(IF(ISNUMBER(B34),B34,1E+99),B35))
A37: Implied exit multiple (TV / FCF_10) | B37: =IF(L23>0,B36/L23,"n/a")
A38: PV of TV | B38: =B36*L24
A39: Enterprise value | B39: =B31+B38
A40: less net debt | B40: =-Assumptions!B7
A41: less minority interest | B41: =-Assumptions!B8
A42: Equity value | B42: =B39+B40+B41
A43: Diluted shares (m) | B43: =Assumptions!B9
...

Sheet DCF_Bull
A1: DCF_Bull: owner-FCF build (NZD m), lease treatment B
A3: Year | B3: FY2025A | C3: FY2026E | D3: FY2027E | E3: FY2028E | F3: FY2029E | G3: FY2030E | H3: FY2031E | I3: FY2032E | J3: FY2033E | K3: FY2034E | L3: FY2035E
A4: Index | B4: 0 | C4: 1 | D4: 2 | E4: 3 | F4: 4 | G4: 5 | H4: 6 | I4: 7 | J4: 8 | K4: 9 | L4: 10
A5: Revenue growth YoY (driver) | C5: -0.015 | D5: 0.03 | E5: 0.035 | F5: 0.035 | G5: 0.03 | H5: 0.03 | I5: 0.025 | J5: 0.025 | K5: 0.025 | L5: 0.025
A6: Revenue | B6: =Assumptions!B14 | C6: =B6*(1+C5) | D6: =C6*(1+D5) | E6: =D6*(1+E5) | F6: =E6*(1+F5) | G6: =F6*(1+G5) | H6: =G6*(1+H5) | I6: =H6*(1+I5) | J6: =I6*(1+J5) | ... L6: =K6*(1+L5)
A7: Adj EBITDA margin, post-IFRS-16 (driver) | C7: 0.068 | D7: 0.076 | E7: 0.083 | F7: 0.088 | G7: 0.09 | H7: 0.09 | I7: 0.09 | J7: 0.09 | K7: 0.09 | L7: 0.09
A8: Adjusted EBITDA (post-IFRS-16) | C8: =C6*C7 | D8: =D6*D7 | E8: =E6*E7 | F8: =F6*F7 | G8: =G6*G7 | H8: =H6*H7 | I8: =I6*I7 | J8: =J6*J7 | ... L8: =L6*L7
A9: SBC % of revenue (driver) | C9: 0 | D9: 0 | E9: 0 | F9: 0 | G9: 0 | H9: 0 | I9: 0 | J9: 0 | K9: 0 | L9: 0
A10: SBC $ (negative) | C10: =-C6*C9 | D10: =-D6*D9 | E10: =-E6*E9 | F10: =-F6*F9 | G10: =-G6*G9 | H10: =-H6*H9 | I10: =-I6*I9 | J10: =-J6*J9 | ... L10: =-L6*L9
A11: Lease cash: principal + interest (negative; link) | C11: =-Assumptions!B11 | D11: =C11*(1+Assumptions!B12) | E11: =D11*(1+Assumptions!B12) | F11: =E11*(1+Assumptions!B12) | G11: =F11*(1+Assumptions!B12) | H11: =G11*(1+Assumptions!B12) | I11: =H11*(1+Assumptions!B12) | J11: =I11*(1+Assumptions!B12) | K11: =J11*(1+Assumptions!B12) | L11: =K11*(1+Assumptions!B12)
A12: Owner EBITDA (lease-adjusted, SBC expensed) | C12: =C8+C10+C11 | D12: =D8+D10+D11 | E12: =E8+E10+E11 | F12: =F8+F10+F11 | G12: =G8+G10+G11 | H12: =H8+H10+H11 | I12: =I8+I10+I11 | J12: =J8+J10+J11 | ... L12: =L8+L10+L11
A13: D&A % of revenue, ex-ROU (driver) | C13: 0.018 | D13: 0.017 | E13: 0.018 | F13: 0.019 | G13: 0.02 | H13: 0.02 | I13: 0.02 | J13: 0.02 | K13: 0.02 | L13: 0.02
A14: D&A ex-ROU (negative) | C14: =-C6*C13 | D14: =-D6*D13 | E14: =-E6*E13 | F14: =-F6*F13 | G14: =-G6*G13 | H14: =-H6*H13 | I14: =-I6*I13 | J14: =-J6*J13 | ... L14: =-L6*L13
A15: EBIT (for cash tax) | C15: =C12+C14 | D15: =D12+D14 | E15: =E12+E14 | F15: =F12+F14 | G15: =G12+G14 | H15: =H12+H14 | I15: =I12+I14 | J15: =J12+J14 | ... L15: =L12+L14
A16: Cash tax rate (driver) | C16: 0 | D16: 0.05 | E16: 0.2 | F16: 0.28 | G16: 0.28 | H16: 0.28 | I16: 0.28 | J16: 0.28 | K16: 0.28 | L16: 0.28
A17: Cash tax (negative; on MAX(0,EBIT)) | C17: =-MAX(0,C15)*C16 | D17: =-MAX(0,D15)*D16 | E17: =-MAX(0,E15)*E16 | F17: =-MAX(0,F15)*F16 | G17: =-MAX(0,G15)*G16 | H17: =-MAX(0,H15)*H16 | I17: =-MAX(0,I15)*I16 | J17: =-MAX(0,J15)*J16 | ... L17: =-MAX(0,L15)*L16
A18: NOPAT | C18: =C15+C17 | D18: =D15+D17 | E18: =E15+E17 | F18: =F15+F17 | G18: =G15+G17 | H18: =H15+H17 | I18: =I15+I17 | J18: =J15+J17 | ... L18: =L15+L17
A19: add back D&A | C19: =-C14 | D19: =-D14 | E19: =-E14 | F19: =-F14 | G19: =-G14 | H19: =-H14 | I19: =-I14 | J19: =-J14 | ... L19: =-L14
A20: Capex % of revenue (driver) | C20: 0.007 | D20: 0.013 | E20: 0.018 | F20: 0.02 | G20: 0.02 | H20: 0.02 | I20: 0.02 | J20: 0.02 | K20: 0.02 | L20: 0.02
A21: less capex | C21: =-C6*C20 | D21: =-D6*D20 | E21: =-E6*E20 | F21: =-F6*F20 | G21: =-G6*G20 | H21: =-H6*H20 | I21: =-I6*I20 | J21: =-J6*J20 | ... L21: =-L6*L20
A22: add working capital (on revenue change) | C22: =Assumptions!$B$6*(C6-B6) | D22: =Assumptions!$B$6*(D6-C6) | E22: =Assumptions!$B$6*(E6-D6) | F22: =Assumptions!$B$6*(F6-E6) | G22: =Assumptions!$B$6*(G6-F6) | H22: =Assumptions!$B$6*(H6-G6) | I22: =Assumptions!$B$6*(I6-H6) | J22: =Assumptions!$B$6*(J6-I6) | ... L22: =Assumptions!$B$6*(L6-K6)
A23: Unlevered owner FCF | C23: =C18+C19+C21+C22 | D23: =D18+D19+D21+D22 | E23: =E18+E19+E21+E22 | F23: =F18+F19+F21+F22 | G23: =G18+G19+G21+G22 | H23: =H18+H19+H21+H22 | I23: =I18+I19+I21+I22 | J23: =J18+J19+J21+J22 | ... L23: =L18+L19+L21+L22
A24: Discount factor | C24: =1/(1+Assumptions!$B$4)^C4 | D24: =1/(1+Assumptions!$B$4)^D4 | E24: =1/(1+Assumptions!$B$4)^E4 | F24: =1/(1+Assumptions!$B$4)^F4 | G24: =1/(1+Assumptions!$B$4)^G4 | H24: =1/(1+Assumptions!$B$4)^H4 | I24: =1/(1+Assumptions!$B$4)^I4 | J24: =1/(1+Assumptions!$B$4)^J4 | ... L24: =1/(1+Assumptions!$B$4)^L4
A25: PV of FCF | C25: =C23*C24 | D25: =D23*D24 | E25: =E23*E24 | F25: =F23*F24 | G25: =G23*G24 | H25: =H23*H24 | I25: =I23*I24 | J25: =J23*J24 | ... L25: =L23*L24
A27: Memo: FCF before SBC (company-style) | C27: =C23-C10 | D27: =D23-D10 | E27: =E23-E10 | F27: =F23-F10 | G27: =G23-G10 | H27: =H23-H10 | I27: =I23-I10 | J27: =J23-J10 | ... L27: =L23-L10
A28: Memo: owner FCF margin | C28: =C23/C6 | D28: =D23/D6 | E28: =E23/E6 | F28: =F23/F6 | G28: =G23/G6 | H28: =H23/H6 | I28: =I23/I6 | J28: =J23/J6 | ... L28: =L23/L6
A29: Memo: lease cash % of revenue | C29: =-C11/C6 | D29: =-D11/D6 | E29: =-E11/E6 | F29: =-F11/F6 | G29: =-G11/G6 | H29: =-H11/H6 | I29: =-I11/I6 | J29: =-J11/J6 | ... L29: =-L11/L6
A31: Sum of PV (explicit years) | B31: =SUM(C25:L25)
A32: Terminal growth | B32: =Assumptions!B19
A33: Terminal FCF (yr 10 x (1+g)) | B33: =L23*(1+B32)
A34: Gordon TV | B34: =IF(Assumptions!B4>B32,B33/(Assumptions!B4-B32),"n/a")
A35: Cap TV (cap x FCF_10) | B35: =Assumptions!B5*L23
A36: TV used = MAX(0, MIN(Gordon, cap)) | B36: =MAX(0,MIN(IF(ISNUMBER(B34),B34,1E+99),B35))
A37: Implied exit multiple (TV / FCF_10) | B37: =IF(L23>0,B36/L23,"n/a")
A38: PV of TV | B38: =B36*L24
A39: Enterprise value | B39: =B31+B38
A40: less net debt | B40: =-Assumptions!B7
A41: less minority interest | B41: =-Assumptions!B8
A42: Equity value | B42: =B39+B40+B41
A43: Diluted shares (m) | B43: =Assumptions!B9
...

Sheet FCF_Quality
A1: Reported FCF reconciled to owner FCF (treatment B), NZD m
B3: FY2018 | C3: FY2019 | D3: FY2020 | E3: FY2021 | F3: FY2022 | G3: FY2023 | H3: FY2024 | I3: FY2025
A4: Revenue | B4: 2994.571 | C4: 3071.357 | D4: 3172.83 | E4: 3414.601 | F4: 3294.332 | G4: 3399.112 | H4: 3037.597 | I4: 3086.725
A5: Free cash flow (company definition: OCF - capex) | B5: 37.685 | C5: 136.667 | D5: 343.493 | E5: 164.081 | F5: -2.046 | G5: 99.095 | H5: 146.586 | I5: 59.719
A6: less: lease principal (financing) | B6: 0 | C6: 0 | D6: 83.833 | E6: 99.383 | F6: 98.264 | G6: 101.171 | H6: 99.532 | I6: 104.882
A7: less: SBC incl. equity-award taxes | B7: 0.353 | C7: 0.42 | D7: 0 | E7: 0 | F7: 0 | G7: 0.804 | H7: 0 | I7: 0
A8: less: interest income | B8: 1.494 | C8: 0.436 | D8: 0.713 | E8: 1.048 | F8: 0.592 | G8: 0.748 | H8: 1.001 | I8: 0.319
A9: Owner FCF | B9: =B5-B6-B7-B8 | C9: =C5-C6-C7-C8 | D9: =D5-D6-D7-D8 | E9: =E5-E6-E7-E8 | F9: =F5-F6-F7-F8 | G9: =G5-G6-G7-G8 | H9: =H5-H6-H7-H8 | I9: =I5-I6-I7-I8
A10: Reported FCF margin | B10: =B5/B4 | C10: =C5/C4 | D10: =D5/D4 | E10: =E5/E4 | F10: =F5/F4 | G10: =G5/G4 | H10: =H5/H4 | I10: =I5/I4
A11: Owner FCF margin | B11: =B9/B4 | C11: =C9/C4 | D11: =D9/D4 | E11: =E9/E4 | F11: =F9/F4 | G11: =G9/G4 | H11: =H9/H4 | I11: =I9/I4
A12: Memo: EBITDA post-IFRS-16 | B12: 116.937 | C12: 163.556 | D12: 259.334 | E12: 343.462 | F12: 304.892 | G12: 250.811 | H12: 217.496 | I12: 197.04
A13: Memo: lease cash (principal + interest) | B13: 0 | C13: 0 | D13: 124.946 | E13: 137.88 | F13: 134.947 | G13: 137.37 | H13: 136.059 | I13: 141.729
A14: Memo: lease-adjusted EBITDA | B14: =B12-B13 | C14: =C12-C13 | D14: =D12-D13 | E14: =E12-E13 | F14: =F12-F13 | G14: =G12-G13 | H14: =H12-H13 | I14: =I12-I13
A15: Memo: lease-adjusted EBITDA margin | B15: =B14/B4 | C15: =C14/C4 | D15: =D14/D4 | E15: =E14/E4 | F15: =F14/F4 | G15: =G14/G4 | H15: =H14/H4 | I15: =I14/I4
A16: Memo: capex | B16: 70.229 | C16: 61.326 | D16: 64.513 | E16: 83.18 | F16: 107.469 | G16: 115.088 | H16: 39.284 | I16: 12.604
A17: Memo: capex % revenue | B17: =B16/B4 | C17: =C16/C4 | D17: =D16/D4 | E17: =E16/E4 | F17: =F16/F4 | G17: =G16/G4 | H17: =H16/H4 | I17: =I16/I4
A19: Notes
A20: FY2018-19 are pre-IFRS-16 (rent inside operating expenses, no lease principal to deduct). FY2020 owner FCF is a COVID artefact (wage subsidy $67.7m, deferred creditor payments); FY2022 reverses it. FY2025 owner FCF is dominated by an $84m payables outflow; the projection base is the component build on the DCF tabs, not this series. Cash tax was $0.7m in FY2025 and $0.35m in H1 FY2026 against NZ$121m of gross tax losses; abnormal and ramped to 28% on the DCF tabs.

Sheet Valuation
A1: Valuation summary (NZD per share)
A3: Scenario | B3: Value per share | C3: Upside vs price | D3: Probability | E3: Street value per share | F3: Entry price @ hurdle | G3: TV bound
A4: Bear | B4: =DCF_Bear!B44 | C4: =DCF_Bear!B45 | D4: =Assumptions!C17 | E4: =DCF_Bear!B49 | F4: =(SUMPRODUCT(DCF_Bear!$C$23:$L$23/(1+Assumptions!$B$13)^DCF_Bear!$C$4:$L$4)+MAX(0,MIN(IF(Assumptions!$B$13>Assumptions!$B$17,DCF_Bear!$L$23*(1+Assumptions!$B$17)/(Assumptions!$B$13-Assumptions!$B$17),1E+99),Assumptions!$B$5*DCF_Bear!$L$23))/(1+Assumptions!$B$13)^10-Assumptions!$B$7-Assumptions!$B$8)/Assumptions!$B$9 | G4: =IF(DCF_Bear!B36=0,"floor",IF(ISNUMBER(DCF_Bear!B34),IF(DCF_Bear!B34<=DCF_Bear!B35,"gordon","cap"),"cap"))
A5: Base | B5: =DCF_Base!B44 | C5: =DCF_Base!B45 | D5: =Assumptions!C18 | E5: =DCF_Base!B49 | F5: =(SUMPRODUCT(DCF_Base!$C$23:$L$23/(1+Assumptions!$B$13)^DCF_Base!$C$4:$L$4)+MAX(0,MIN(IF(Assumptions!$B$13>Assumptions!$B$18,DCF_Base!$L$23*(1+Assumptions!$B$18)/(Assumptions!$B$13-Assumptions!$B$18),1E+99),Assumptions!$B$5*DCF_Base!$L$23))/(1+Assumptions!$B$13)^10-Assumptions!$B$7-Assumptions!$B$8)/Assumptions!$B$9 | G5: =IF(DCF_Base!B36=0,"floor",IF(ISNUMBER(DCF_Base!B34),IF(DCF_Base!B34<=DCF_Base!B35,"gordon","cap"),"cap"))
A6: Bull | B6: =DCF_Bull!B44 | C6: =DCF_Bull!B45 | D6: =Assumptions!C19 | E6: =DCF_Bull!B49 | F6: =(SUMPRODUCT(DCF_Bull!$C$23:$L$23/(1+Assumptions!$B$13)^DCF_Bull!$C$4:$L$4)+MAX(0,MIN(IF(Assumptions!$B$13>Assumptions!$B$19,DCF_Bull!$L$23*(1+Assumptions!$B$19)/(Assumptions!$B$13-Assumptions!$B$19),1E+99),Assumptions!$B$5*DCF_Bull!$L$23))/(1+Assumptions!$B$13)^10-Assumptions!$B$7-Assumptions!$B$8)/Assumptions!$B$9 | G6: =IF(DCF_Bull!B36=0,"floor",IF(ISNUMBER(DCF_Bull!B34),IF(DCF_Bull!B34<=DCF_Bull!B35,"gordon","cap"),"cap"))
A8: Probability-weighted value per share | B8: =SUMPRODUCT(B4:B6,D4:D6)
A9: Current price | B9: =Assumptions!B10
A10: Margin of safety (1 - price/weighted) | B10: =1-B9/B8
A11: Street weighted value per share | B11: =SUMPRODUCT(E4:E6,D4:D6)
A12: Band position (price - house)/(street - house) | B12: =IF(ABS(B11-B8)<0.0001,"n/a (SBC-zero: house = street)",(B9-B8)/(B11-B8))
A13: Probability-weighted 15% hurdle entry price | B13: =SUMPRODUCT(F4:F6,D4:D6)
A14: Entry discount vs current price | B14: =B13/B9-1
A16: Required-return table (base case; TV rebuilt at each rate)
A17: Required return | B17: 0.09 | C17: 0.1 | D17: 0.11 | E17: 0.12 | F17: 0.15 | G17: =Assumptions!B4 | H17: (model WACC; must equal DCF_Base!B44)
A18: Value per share | B18: =(SUMPRODUCT(DCF_Base!$C$23:$L$23/(1+B$17)^DCF_Base!$C$4:$L$4)+MAX(0,MIN(IF(B$17>Assumptions!$B$18,DCF_Base!$L$23*(1+Assumptions!$B$18)/(B$17-Assumptions!$B$18),1E+99),Assumptions!$B$5*DCF_Base!$L$23))/(1+B$17)^10-Assumptions!$B$7-Assumptions!$B$8)/Assumptions!$B$9 | C18: =(SUMPRODUCT(DCF_Base!$C$23:$L$23/(1+C$17)^DCF_Base!$C$4:$L$4)+MAX(0,MIN(IF(C$17>Assumptions!$B$18,DCF_Base!$L$23*(1+Assumptions!$B$18)/(C$17-Assumptions!$B$18),1E+99),Assumptions!$B$5*DCF_Base!$L$23))/(1+C$17)^10-Assumptions!$B$7-Assumptions!$B$8)/Assumptions!$B$9 | D18: =(SUMPRODUCT(DCF_Base!$C$23:$L$23/(1+D$17)^DCF_Base!$C$4:$L$4)+MAX(0,MIN(IF(D$17>Assumptions!$B$18,DCF_Base!$L$23*(1+Assumptions!$B$18)/(D$17-Assumptions!$B$18),1E+99),Assumptions!$B$5*DCF_Base!$L$23))/(1+D$17)^10-Assumptions!$B$7-Assumptions!$B$8)/Assumptions!$B$9 | E18: =(SUMPRODUCT(DCF_Base!$C$23:$L$23/(1+E$17)^DCF_Base!$C$4:$L$4)+MAX(0,MIN(IF(E$17>Assumptions!$B$18,DCF_Base!$L$23*(1+Assumptions!$B$18)/(E$17-Assumptions!$B$18),1E+99),Assumptions!$B$5*DCF_Base!$L$23))/(1+E$17)^10-Assumptions!$B$7-Assumptions!$B$8)/Assumptions!$B$9 | F18: =(SUMPRODUCT(DCF_Base!$C$23:$L$23/(1+F$17)^DCF_Base!$C$4:$L$4)+MAX(0,MIN(IF(F$17>Assumptions!$B$18,DCF_Base!$L$23*(1+Assumptions!$B$18)/(F$17-Assumptions!$B$18),1E+99),Assumptions!$B$5*DCF_Base!$L$23))/(1+F$17)^10-Assumptions!$B$7-Assumptions!$B$8)/Assumptions!$B$9 | G18: =(SUMPRODUCT(DCF_Base!$C$23:$L$23/(1+G$17)^DCF_Base!$C$4:$L$4)+MAX(0,MIN(IF(G$17>Assumptions!$B$18,DCF_Base!$L$23*(1+Assumptions!$B$18)/(G$17-Assumptions!$B$18),1E+99),Assumptions!$B$5*DCF_Base!$L$23))/(1+G$17)^10-Assumptions!$B$7-Assumptions!$B$8)/Assumptions!$B$9
A20: Sensitivity: base-case value per share, WACC (rows) x terminal growth (columns)
B21: 0.01 | C21: 0.015 | D21: 0.02 | E21: 0.025 | F21: 0.03
A22: 0.08 | B22: =(SUMPRODUCT(DCF_Base!$C$23:$L$23/(1+$A22)^DCF_Base!$C$4:$L$4)+MAX(0,MIN(IF($A22>B$21,DCF_Base!$L$23*(1+B$21)/($A22-B$21),1E+99),Assumptions!$B$5*DCF_Base!$L$23))/(1+$A22)^10-Assumptions!$B$7-Assumptions!$B$8)/Assumptions!$B$9 | C22: =(SUMPRODUCT(DCF_Base!$C$23:$L$23/(1+$A22)^DCF_Base!$C$4:$L$4)+MAX(0,MIN(IF($A22>C$21,DCF_Base!$L$23*(1+C$21)/($A22-C$21),1E+99),Assumptions!$B$5*DCF_Base!$L$23))/(1+$A22)^10-Assumptions!$B$7-Assumptions!$B$8)/Assumptions!$B$9 | D22: =(SUMPRODUCT(DCF_Base!$C$23:$L$23/(1+$A22)^DCF_Base!$C$4:$L$4)+MAX(0,MIN(IF($A22>D$21,DCF_Base!$L$23*(1+D$21)/($A22-D$21),1E+99),Assumptions!$B$5*DCF_Base!$L$23))/(1+$A22)^10-Assumptions!$B$7-Assumptions!$B$8)/Assumptions!$B$9 | E22: =(SUMPRODUCT(DCF_Base!$C$23:$L$23/(1+$A22)^DCF_Base!$C$4:$L$4)+MAX(0,MIN(IF($A22>E$21,DCF_Base!$L$23*(1+E$21)/($A22-E$21),1E+99),Assumptions!$B$5*DCF_Base!$L$23))/(1+$A22)^10-Assumptions!$B$7-Assumptions!$B$8)/Assumptions!$B$9 | F22: =(SUMPRODUCT(DCF_Base!$C$23:$L$23/(1+$A22)^DCF_Base!$C$4:$L$4)+MAX(0,MIN(IF($A22>F$21,DCF_Base!$L$23*(1+F$21)/($A22-F$21),1E+99),Assumptions!$B$5*DCF_Base!$L$23))/(1+$A22)^10-Assumptions!$B$7-Assumptions!$B$8)/Assumptions!$B$9
A23: 0.09 | B23: =(SUMPRODUCT(DCF_Base!$C$23:$L$23/(1+$A23)^DCF_Base!$C$4:$L$4)+MAX(0,MIN(IF($A23>B$21,DCF_Base!$L$23*(1+B$21)/($A23-B$21),1E+99),Assumptions!$B$5*DCF_Base!$L$23))/(1+$A23)^10-Assumptions!$B$7-Assumptions!$B$8)/Assumptions!$B$9 | C23: =(SUMPRODUCT(DCF_Base!$C$23:$L$23/(1+$A23)^DCF_Base!$C$4:$L$4)+MAX(0,MIN(IF($A23>C$21,DCF_Base!$L$23*(1+C$21)/($A23-C$21),1E+99),Assumptions!$B$5*DCF_Base!$L$23))/(1+$A23)^10-Assumptions!$B$7-Assumptions!$B$8)/Assumptions!$B$9 | D23: =(SUMPRODUCT(DCF_Base!$C$23:$L$23/(1+$A23)^DCF_Base!$C$4:$L$4)+MAX(0,MIN(IF($A23>D$21,DCF_Base!$L$23*(1+D$21)/($A23-D$21),1E+99),Assumptions!$B$5*DCF_Base!$L$23))/(1+$A23)^10-Assumptions!$B$7-Assumptions!$B$8)/Assumptions!$B$9 | E23: =(SUMPRODUCT(DCF_Base!$C$23:$L$23/(1+$A23)^DCF_Base!$C$4:$L$4)+MAX(0,MIN(IF($A23>E$21,DCF_Base!$L$23*(1+E$21)/($A23-E$21),1E+99),Assumptions!$B$5*DCF_Base!$L$23))/(1+$A23)^10-Assumptions!$B$7-Assumptions!$B$8)/Assumptions!$B$9 | F23: =(SUMPRODUCT(DCF_Base!$C$23:$L$23/(1+$A23)^DCF_Base!$C$4:$L$4)+MAX(0,MIN(IF($A23>F$21,DCF_Base!$L$23*(1+F$21)/($A23-F$21),1E+99),Assumptions!$B$5*DCF_Base!$L$23))/(1+$A23)^10-Assumptions!$B$7-Assumptions!$B$8)/Assumptions!$B$9
A24: 0.1 | B24: =(SUMPRODUCT(DCF_Base!$C$23:$L$23/(1+$A24)^DCF_Base!$C$4:$L$4)+MAX(0,MIN(IF($A24>B$21,DCF_Base!$L$23*(1+B$21)/($A24-B$21),1E+99),Assumptions!$B$5*DCF_Base!$L$23))/(1+$A24)^10-Assumptions!$B$7-Assumptions!$B$8)/Assumptions!$B$9 | C24: =(SUMPRODUCT(DCF_Base!$C$23:$L$23/(1+$A24)^DCF_Base!$C$4:$L$4)+MAX(0,MIN(IF($A24>C$21,DCF_Base!$L$23*(1+C$21)/($A24-C$21),1E+99),Assumptions!$B$5*DCF_Base!$L$23))/(1+$A24)^10-Assumptions!$B$7-Assumptions!$B$8)/Assumptions!$B$9 | D24: =(SUMPRODUCT(DCF_Base!$C$23:$L$23/(1+$A24)^DCF_Base!$C$4:$L$4)+MAX(0,MIN(IF($A24>D$21,DCF_Base!$L$23*(1+D$21)/($A24-D$21),1E+99),Assumptions!$B$5*DCF_Base!$L$23))/(1+$A24)^10-Assumptions!$B$7-Assumptions!$B$8)/Assumptions!$B$9 | E24: =(SUMPRODUCT(DCF_Base!$C$23:$L$23/(1+$A24)^DCF_Base!$C$4:$L$4)+MAX(0,MIN(IF($A24>E$21,DCF_Base!$L$23*(1+E$21)/($A24-E$21),1E+99),Assumptions!$B$5*DCF_Base!$L$23))/(1+$A24)^10-Assumptions!$B$7-Assumptions!$B$8)/Assumptions!$B$9 | F24: =(SUMPRODUCT(DCF_Base!$C$23:$L$23/(1+$A24)^DCF_Base!$C$4:$L$4)+MAX(0,MIN(IF($A24>F$21,DCF_Base!$L$23*(1+F$21)/($A24-F$21),1E+99),Assumptions!$B$5*DCF_Base!$L$23))/(1+$A24)^10-Assumptions!$B$7-Assumptions!$B$8)/Assumptions!$B$9
A25: 0.11 | B25: =(SUMPRODUCT(DCF_Base!$C$23:$L$23/(1+$A25)^DCF_Base!$C$4:$L$4)+MAX(0,MIN(IF($A25>B$21,DCF_Base!$L$23*(1+B$21)/($A25-B$21),1E+99),Assumptions!$B$5*DCF_Base!$L$23))/(1+$A25)^10-Assumptions!$B$7-Assumptions!$B$8)/Assumptions!$B$9 | C25: =(SUMPRODUCT(DCF_Base!$C$23:$L$23/(1+$A25)^DCF_Base!$C$4:$L$4)+MAX(0,MIN(IF($A25>C$21,DCF_Base!$L$23*(1+C$21)/($A25-C$21),1E+99),Assumptions!$B$5*DCF_Base!$L$23))/(1+$A25)^10-Assumptions!$B$7-Assumptions!$B$8)/Assumptions!$B$9 | D25: =(SUMPRODUCT(DCF_Base!$C$23:$L$23/(1+$A25)^DCF_Base!$C$4:$L$4)+MAX(0,MIN(IF($A25>D$21,DCF_Base!$L$23*(1+D$21)/($A25-D$21),1E+99),Assumptions!$B$5*DCF_Base!$L$23))/(1+$A25)^10-Assumptions!$B$7-Assumptions!$B$8)/Assumptions!$B$9 | E25: =(SUMPRODUCT(DCF_Base!$C$23:$L$23/(1+$A25)^DCF_Base!$C$4:$L$4)+MAX(0,MIN(IF($A25>E$21,DCF_Base!$L$23*(1+E$21)/($A25-E$21),1E+99),Assumptions!$B$5*DCF_Base!$L$23))/(1+$A25)^10-Assumptions!$B$7-Assumptions!$B$8)/Assumptions!$B$9 | F25: =(SUMPRODUCT(DCF_Base!$C$23:$L$23/(1+$A25)^DCF_Base!$C$4:$L$4)+MAX(0,MIN(IF($A25>F$21,DCF_Base!$L$23*(1+F$21)/($A25-F$21),1E+99),Assumptions!$B$5*DCF_Base!$L$23))/(1+$A25)^10-Assumptions!$B$7-Assumptions!$B$8)/Assumptions!$B$9
A26: 0.12 | B26: =(SUMPRODUCT(DCF_Base!$C$23:$L$23/(1+$A26)^DCF_Base!$C$4:$L$4)+MAX(0,MIN(IF($A26>B$21,DCF_Base!$L$23*(1+B$21)/($A26-B$21),1E+99),Assumptions!$B$5*DCF_Base!$L$23))/(1+$A26)^10-Assumptions!$B$7-Assumptions!$B$8)/Assumptions!$B$9 | C26: =(SUMPRODUCT(DCF_Base!$C$23:$L$23/(1+$A26)^DCF_Base!$C$4:$L$4)+MAX(0,MIN(IF($A26>C$21,DCF_Base!$L$23*(1+C$21)/($A26-C$21),1E+99),Assumptions!$B$5*DCF_Base!$L$23))/(1+$A26)^10-Assumptions!$B$7-Assumptions!$B$8)/Assumptions!$B$9 | D26: =(SUMPRODUCT(DCF_Base!$C$23:$L$23/(1+$A26)^DCF_Base!$C$4:$L$4)+MAX(0,MIN(IF($A26>D$21,DCF_Base!$L$23*(1+D$21)/($A26-D$21),1E+99),Assumptions!$B$5*DCF_Base!$L$23))/(1+$A26)^10-Assumptions!$B$7-Assumptions!$B$8)/Assumptions!$B$9 | E26: =(SUMPRODUCT(DCF_Base!$C$23:$L$23/(1+$A26)^DCF_Base!$C$4:$L$4)+MAX(0,MIN(IF($A26>E$21,DCF_Base!$L$23*(1+E$21)/($A26-E$21),1E+99),Assumptions!$B$5*DCF_Base!$L$23))/(1+$A26)^10-Assumptions!$B$7-Assumptions!$B$8)/Assumptions!$B$9 | F26: =(SUMPRODUCT(DCF_Base!$C$23:$L$23/(1+$A26)^DCF_Base!$C$4:$L$4)+MAX(0,MIN(IF($A26>F$21,DCF_Base!$L$23*(1+F$21)/($A26-F$21),1E+99),Assumptions!$B$5*DCF_Base!$L$23))/(1+$A26)^10-Assumptions!$B$7-Assumptions!$B$8)/Assumptions!$B$9
A28: Sanity multiples (lease-consistent)
A29: Market cap | B29: =Assumptions!B10*Assumptions!B9
A30: EV ex-lease | B30: =B29+Assumptions!B7
A31: EV incl. lease liabilities | B31: =B30+708.861
A32: TTM lease-adjusted EBITDA | B32: 57
A33: TTM post-IFRS-16 EBITDA | B33: 197.6
A34: EV ex-lease / lease-adj EBITDA | B34: =B30/B32
A35: EV incl. lease / post-IFRS-16 EBITDA | B35: =B31/B33
A36: Price / book (equity 310.67) | B36: =B29/310.67
A37: Base terminal EV / yr-10 lease-adj EBITDA | B37: =DCF_Base!B36/DCF_Base!L12
