Workbook

Sheet Scenario Model
A1: IPR.NZ (Iperion Limited) - Asset / Scenario Valuation
A2: NOT a Gordon-growth FCF DCF - see Model_Info tab. Gray cells are INPUTS.
A3: Iperion has EARNED ZERO REVENUE in every year on record (FY2019-FY2026). All scenario values are probability-weighted net-asset / option-value constructions.
A5: KEY INPUTS
A6: Current Stock Price (STALE - last real trade 23-Oct-2025) | B6: 0.003
A7: Shares Outstanding | B7: 514894500
A8: FY2026 Shareholders Equity / Net Tangible Assets ($) | B8: 53803
A9: FY2026 Cash ($) | B9: 155492
A10: FY2026 Total Debt ($) | B10: 0
A11: Net Tangible Assets per Share | B11: =B8/B7 -> 0
A13: BEAR CASE: Insolvency / Wind-up
A14: Narrative: related-party support withdrawn before any commercial breakthrough; even an orderly wind-up consumes remaining net assets in liquidation costs.
A15: Recoverable value to ordinary equity ($) | B15: 0
A16: Bear Intrinsic Value / Share | B16: =B15/B7 -> 0
A18: BASE CASE: Persisting Shell + Listing Option Value
A19: Narrative: company persists as a going-concern shell on continued related-party support; no commercial sale occurs. Value = net tangible assets + NZX listing scarcity value (NOT the post-RTO entity value).
A20: FY2026 Net Tangible Assets ($) | B20: =B8 -> 0
A21: NZX Listing Scarcity Value ($) [ADJUSTABLE] | B21: 300000
A22: Base Case Equity Value ($) | B22: =B20+B21 -> 0
A23: Base Intrinsic Value / Share | B23: =B22/B7 -> 0
A25: BULL CASE: Pathoglaze Commercialises (Diluted)
A26: Narrative: first signed commercial contract; bottom-up revenue ramp to Year 5, valued on an exit revenue multiple, discounted at 30% WACC, net of a modelled dilutive capital raise.
A27: Year 5 Revenue ($) [ADJUSTABLE] | B27: 1500000
A28: Exit Revenue Multiple [ADJUSTABLE] | B28: 1.5
A29: Year 5 Exit Enterprise Value ($) | B29: =B27*B28 -> 0
A30: Bull WACC (discount rate) [ADJUSTABLE] | B30: 0.3
A31: Years to Exit | B31: 5
A32: PV of Exit Enterprise Value ($) | B32: =B29/(1+B30)^B31 -> 0
A33: Dilutive Capital Raise ($) [ADJUSTABLE] | B33: 750000
A34: Assumed Raise Price ($/share) [ADJUSTABLE] | B34: 0.006
A35: New Shares Issued | B35: =B33/B34 -> 0
A36: Total Shares Post-Raise | B36: =B7+B35 -> 0
A37: Bull Intrinsic Value / Share | B37: =B32/B36 -> 0
A39: PROBABILITY-WEIGHTED VALUATION
B40: Weight | C40: IV/Share | D40: Contribution
A41: Bear | B41: 0.65 | C41: =B16 -> 0 | D41: =B41*C41 -> 0
A42: Base | B42: 0.28 | C42: =B23 -> 0 | D42: =B42*C42 -> 0
A43: Bull | B43: 0.07 | C43: =B37 -> 0 | D43: =B43*C43 -> 0
A44: Weight Check (should = 100%) | B44: =SUM(B41:B43) -> 0
A45: WEIGHTED INTRINSIC VALUE / SHARE | B45: =SUM(D41:D43) -> 0
...

Sheet Sensitivity
A1: Sensitivity Analysis
A2: Weighted Intrinsic Value by Bear-Weight & Listing Scarcity Value
A4: Bear Wt \ Listing $ | B4: 0 | C4: 150000 | D4: 300000 | E4: 450000 | F4: 600000
A5: 0.5 | B5: ='Scenario Model'!$B$15*0.5+(('Scenario Model'!$B$8+0)/'Scenario Model'!$B$7)*((1-0.5)*0.8)+'Scenario Model'!$B$37*((1-0.5)*0.2) -> 0 | C5: ='Scenario Model'!$B$15*0.5+(('Scenario Model'!$B$8+150000)/'Scenario Model'!$B$7)*((1-0.5)*0.8)+'Scenario Model'!$B$37*((1-0.5)*0.2) -> 0 | D5: ='Scenario Model'!$B$15*0.5+(('Scenario Model'!$B$8+300000)/'Scenario Model'!$B$7)*((1-0.5)*0.8)+'Scenario Model'!$B$37*((1-0.5)*0.2) -> 0 | E5: ='Scenario Model'!$B$15*0.5+(('Scenario Model'!$B$8+450000)/'Scenario Model'!$B$7)*((1-0.5)*0.8)+'Scenario Model'!$B$37*((1-0.5)*0.2) -> 0 | F5: ='Scenario Model'!$B$15*0.5+(('Scenario Model'!$B$8+600000)/'Scenario Model'!$B$7)*((1-0.5)*0.8)+'Scenario Model'!$B$37*((1-0.5)*0.2) -> 0
A6: 0.6 | B6: ='Scenario Model'!$B$15*0.6+(('Scenario Model'!$B$8+0)/'Scenario Model'!$B$7)*((1-0.6)*0.8)+'Scenario Model'!$B$37*((1-0.6)*0.2) -> 0 | C6: ='Scenario Model'!$B$15*0.6+(('Scenario Model'!$B$8+150000)/'Scenario Model'!$B$7)*((1-0.6)*0.8)+'Scenario Model'!$B$37*((1-0.6)*0.2) -> 0 | D6: ='Scenario Model'!$B$15*0.6+(('Scenario Model'!$B$8+300000)/'Scenario Model'!$B$7)*((1-0.6)*0.8)+'Scenario Model'!$B$37*((1-0.6)*0.2) -> 0 | E6: ='Scenario Model'!$B$15*0.6+(('Scenario Model'!$B$8+450000)/'Scenario Model'!$B$7)*((1-0.6)*0.8)+'Scenario Model'!$B$37*((1-0.6)*0.2) -> 0 | F6: ='Scenario Model'!$B$15*0.6+(('Scenario Model'!$B$8+600000)/'Scenario Model'!$B$7)*((1-0.6)*0.8)+'Scenario Model'!$B$37*((1-0.6)*0.2) -> 0
A7: 0.65 | B7: ='Scenario Model'!$B$15*0.65+(('Scenario Model'!$B$8+0)/'Scenario Model'!$B$7)*((1-0.65)*0.8)+'Scenario Model'!$B$37*((1-0.65)*0.2) -> 0 | C7: ='Scenario Model'!$B$15*0.65+(('Scenario Model'!$B$8+150000)/'Scenario Model'!$B$7)*((1-0.65)*0.8)+'Scenario Model'!$B$37*((1-0.65)*0.2) -> 0 | D7: ='Scenario Model'!$B$15*0.65+(('Scenario Model'!$B$8+300000)/'Scenario Model'!$B$7)*((1-0.65)*0.8)+'Scenario Model'!$B$37*((1-0.65)*0.2) -> 0 | E7: ='Scenario Model'!$B$15*0.65+(('Scenario Model'!$B$8+450000)/'Scenario Model'!$B$7)*((1-0.65)*0.8)+'Scenario Model'!$B$37*((1-0.65)*0.2) -> 0 | F7: ='Scenario Model'!$B$15*0.65+(('Scenario Model'!$B$8+600000)/'Scenario Model'!$B$7)*((1-0.65)*0.8)+'Scenario Model'!$B$37*((1-0.65)*0.2) -> 0
A8: 0.7 | B8: ='Scenario Model'!$B$15*0.7+(('Scenario Model'!$B$8+0)/'Scenario Model'!$B$7)*((1-0.7)*0.8)+'Scenario Model'!$B$37*((1-0.7)*0.2) -> 0 | C8: ='Scenario Model'!$B$15*0.7+(('Scenario Model'!$B$8+150000)/'Scenario Model'!$B$7)*((1-0.7)*0.8)+'Scenario Model'!$B$37*((1-0.7)*0.2) -> 0 | D8: ='Scenario Model'!$B$15*0.7+(('Scenario Model'!$B$8+300000)/'Scenario Model'!$B$7)*((1-0.7)*0.8)+'Scenario Model'!$B$37*((1-0.7)*0.2) -> 0 | E8: ='Scenario Model'!$B$15*0.7+(('Scenario Model'!$B$8+450000)/'Scenario Model'!$B$7)*((1-0.7)*0.8)+'Scenario Model'!$B$37*((1-0.7)*0.2) -> 0 | F8: ='Scenario Model'!$B$15*0.7+(('Scenario Model'!$B$8+600000)/'Scenario Model'!$B$7)*((1-0.7)*0.8)+'Scenario Model'!$B$37*((1-0.7)*0.2) -> 0
A9: 0.8 | B9: ='Scenario Model'!$B$15*0.8+(('Scenario Model'!$B$8+0)/'Scenario Model'!$B$7)*((1-0.8)*0.8)+'Scenario Model'!$B$37*((1-0.8)*0.2) -> 0 | C9: ='Scenario Model'!$B$15*0.8+(('Scenario Model'!$B$8+150000)/'Scenario Model'!$B$7)*((1-0.8)*0.8)+'Scenario Model'!$B$37*((1-0.8)*0.2) -> 0 | D9: ='Scenario Model'!$B$15*0.8+(('Scenario Model'!$B$8+300000)/'Scenario Model'!$B$7)*((1-0.8)*0.8)+'Scenario Model'!$B$37*((1-0.8)*0.2) -> 0 | E9: ='Scenario Model'!$B$15*0.8+(('Scenario Model'!$B$8+450000)/'Scenario Model'!$B$7)*((1-0.8)*0.8)+'Scenario Model'!$B$37*((1-0.8)*0.2) -> 0 | F9: ='Scenario Model'!$B$15*0.8+(('Scenario Model'!$B$8+600000)/'Scenario Model'!$B$7)*((1-0.8)*0.8)+'Scenario Model'!$B$37*((1-0.8)*0.2) -> 0
A11: Row = probability weight on BEAR scenario (residual split 80% base / 20% bull)
A12: Column = NZX listing scarcity value assumption ($)
A13: Every cell should be far below the current stale $0.003 quote.

Sheet FCF Quality
A1: Cash Burn Quality (no FCF exists - company is pre-revenue)
A3: Period | B3: FY2019 | C3: FY2020 | D3: FY2024 | E3: FY2025 | F3: FY2026
A4: Revenue ($) | B4: 0 | C4: 0 | D4: 0 | E4: 0 | F4: 0
A5: Net Loss ($) | B5: -56142 | C5: -159877 | D5: -812259 | E5: -455683 | F5: -294595
A6: Operating/Free Cash Flow ($) | B6: -87718 | C6: -159880 | D6: -734204 | E6: -447900 | F6: -269849
A7: Shareholders Equity ($) | B7: 2405445 | C7: 2188713 | D7: 814081 | E7: 359648 | F7: 53803
A9: Memo: SBC | B9: NIL in every year - confirmed via Metrics.csv StockBasedComp column (always 0.0)
A10: Memo: Cash Tax Rate | B10: Not applicable - company has never had taxable income
A11: Memo: FY2026 improvement driver | B11: Net loss narrowed FY2025->FY2026 (-455,683 to -294,595) almost entirely because Three Summit Ventures waived its $400,000/yr fixed outsourcing fee - NOT an operating improvement

Sheet Historical
A1: Historical Growth & P/B Anchor
A3: No conventional FCF/EPS/Revenue CAGR applies (see Scenario Model tab). Historical Price/Book is the only meaningful multiple anchor.
A5: FY End | B5: Book Value/Share | C5: Approx. Price | D5: P/B
A6: FY2019 | B6: 0.004672 | C6: 0.001 | D6: =C6/B6 -> 0
A7: FY2020 | B7: 0.004251 | C7: 0.001 | D7: =C7/B7 -> 0
A8: FY2024 | B8: 0.001581 | C8: 0.003 | D8: =C8/B8 -> 0
A9: FY2025 | B9: 0.000698 | C9: 0.003 | D9: =C9/B9 -> 0
A10: FY2026 | B10: 0.000104 | C10: 0.003 | D10: =C10/B10 -> 0
A12: Current (stale) | B12: 0.0001045 | C12: 0.003 | D12: =C12/B12 -> 0
A13: Current 28.7x P/B is the historical OUTLIER (range 0.21x-4.3x in prior years) - mechanical artifact of a frozen/untraded price against a collapsing book value, not a re-rating.

Sheet Model_Info
A1: Model Provenance & Info
A3: Built by | B3: Claude (dcf-analyst agent), per .claude/agents/dcf-analyst.md, deviating on METHOD per explicit user instruction
A4: Valuation date | B4: 2026-08-12
A5: Share price date/source | B5: Yahoo Finance chart API regularMarketPrice, but STALE - last genuine trade 2025-10-23 (regularMarketTime); unchanged $0.003 print in every month Dec-2023 through Aug-2026
A6: Data vintage | B6: FY2026 Annual Report (year ended 31-Mar-2026, audited, signed 30-Jun-2026); H1 FY2026 interim (30-Sep-2025, unaudited); IPR.NZ_Analysis.json dated 2026-08-12
A7: Methodology | B7: ASSET/SCENARIO model, NOT a Gordon-growth FCF DCF. Iperion has zero revenue in every year on record and structurally negative FCF, so no growth rate exists to project and no terminal value can be meaningfully capitalised. Follows the AFC.NZ / BGI.NZ precedent in this repository: probability-weighted bear (wind-up, ~nil) / base (net tangible assets + NZX listing scarcity value) / bull (bottom-up Pathoglaze commercialisation, heavily diluted and discounted) scenarios.
A8: WACC / discount rate | B8: 30% stacked cost of equity used ONLY for entry-price and bull-case 5yr exit discounting (see wacc_rationale in the DCF JSON for the 5-component build-up: NZ small-cap base 10% + illiquidity 6% + going-concern 6% + single-product/binary tech 5% + controlling-holder governance 3%). NOT used to discount a perpetuity FCF stream - none exists.
A9: Key judgment calls | B9: (1) Base-case NZX listing scarcity value set at $300,000 (range considered $200k-$400k), below the AFC.NZ precedent given smaller scale and no disclosed RTO counterparty. (2) Bull case revenue ramp to $1.5m by Year 5 and 1.5x exit revenue multiple are illustrative "what does success look like" constructions, not projections with claimed precision. (3) Bull case models an explicit $750,000 dilutive raise at $0.006/share (~19.5% dilution) as the near-certain cost of scaling from $155k cash. (4) Probability weights 65% bear / 28% base / 7% bull, justified in probability_weighted.weights_rationale in the JSON.
A10: What to refresh after next earnings/announcement | B10: Watch for: (a) any signed commercial agreement with the chocolate manufacturer (would require rebuilding bull case from an actual contract, not an illustrative ramp); (b) shareholder/NZX approval outcome on expanding the Elitesoft Asia facility to US$1,000,000 (materially changes dilution and solvency risk); (c) any lapse/renewal of the Chang Ku Ee support letter (expires ~mid-2027); (d) any resumption of genuine trading volume (would make current_price a meaningful anchor again); (e) FY2027 half-year and annual results for updated cash burn, equity and going-concern language.
A11: Cell colour conventions | B11: Gray cells = adjustable inputs. Green result cells = key computed outputs (bull/base intrinsic value, weighted IV, entry price). Red result cell = bear-case value (zero). White cells with borders = formula-driven intermediate calculations.
A12: Staleness warning | B12: ALL figures in this model will go stale and MUST be re-checked against the next IPR.NZ announcement or annual/half-year report before being relied upon. The current market price in particular is not a reliable, currently-tradeable data point (see current_price_note in the DCF JSON).
