Workbook

Sheet Model_Info
A1: NETFLIX (NFLX) - OWNER-FCF DCF MODEL
A3: Lineage | B3: v1.0 - FRESH BUILD, 9-Aug-2026. No prior NFLX workbook existed in this workspace, so all ten forecast years are newly constructed (nothing to reconcile against). Built by Claude (Opus 5) via claude.ai chat at Stephen's request, using the house tech-dcf-workbook engine (openpyxl; recalculated in LibreOffice; per-share outputs hand-checked against an independent Python model before delivery). Supersedes nothing.
A5: DATA VINTAGE
A6: FY0 actuals (FY2025) | B6: Netflix Q4'25 shareholder letter, 20-Jan-2026 (ir.netflix.net): revenue $45,183.0m, operating income $13,326.6m (29.5%), net income $10,981.2m, OCF $10,149.3m, PP&E capex $688.2m, FCF $9,461.1m, SBC $368.4m, additions to content assets $17,096.6m, change in content liabilities -$610.8m, content amortisation $16,422.2m, tax provision $1,741.4m of which deferred -$442.1m.
A7: Latest print (Q2 FY2026) | B7: Netflix Q2'26 shareholder letter, 16-Jul-2026: revenue $12,559.9m (+13.4%), operating income $4,192.6m (33.4%), net income $3,401.4m, diluted EPS $0.80, FCF $1,525.2m, SBC $131.3m (H1'26 $271.7m), diluted shares 4,261.3m.
A8: FY1 guidance (FY2026E) | B8: Same letter: revenue $51.0-51.4bn (13-14% growth) - midpoint $51.2bn used; operating margin 31.5%; FCF ~$12.5bn; cash content spend / content amortisation ~1.1x; content amortisation +~10% y/y; ads revenue ~$3bn (roughly double 2025's $1.5bn). Q3'26 guide: revenue $12,860m (+11.7%), operating margin 33.2%.
A9: Balance sheet | B9: 30-Jun-2026 (Q2'26 letter): cash & equivalents $9,099.2m, short-term investments $28.7m, total debt $14,309.3m. Netflix's own non-GAAP reconciliation gives NET DEBT of $5,244.2m - used here as a NEGATIVE net-cash input. Total streaming content obligations $25,106.7m (incl. off-balance-sheet) - disclosed on Actuals_Data but deliberately NOT added to the bridge (see methodology).
A10: Share count | B10: 4,261.3m fully diluted, Q2'26 letter summary table (weighted average for the quarter). Period-end diluted is somewhat lower after the $4.7bn Q2 buyback, so this input is mildly conservative.
A11: Price | B11: $74.14 - last regular close, Friday 7-Aug-2026 (Macrotrends daily history; Robinhood quoted $74.16 over the same weekend). 52-week range $65.08-$126.71; all-time-high close $133.91 on 30-Jun-2025. Refresh at the next regular close before acting on any output.
A12: Split | B12: All share and per-share figures reflect the 10-for-1 forward split effected 14-Nov-2025.
A14: METHODOLOGY
A15: Owner-FCF basis | B15: SBC fully expensed and projected as its OWN driver row (row 9, % of revenue, per scenario-year) - never folded into a net margin. INTEREST EXCLUDED from flows: Netflix runs a net interest COST (~$0.6bn/yr), and the balance-sheet position is carried separately as net debt; including both would double-count. Cash taxes modelled explicitly and ramped (row 14). Diluted share count held FLAT - expensing SBC substitutes for modelling grant dilution; buybacks are treated as value-neutral. Terminal value = Gordon growth, capped at 20x terminal-year owner FCF. End-of-year discounting, 10-year explicit horizon, FY1 = 2026E. Street-convention values (SBC added back as non-cash) are carried as memos - the house/street pair is the accounting-regime band around the price.
A16: Content treatment (key) | B16: For Netflix the dominant investment flows are content amortisation (P&L) and content cash spend (cash), not PP&E. They are therefore mapped into the engine's D&A and capex lines: row 12 D&A = revenue x (content amortisation % + PP&E D&A %); row 17 capex = revenue x (content amortisation % x cash-spend/amortisation ratio + PP&E capex %). Those four inputs are per-year, per-scenario blue driver rows 46-49 on each DCF tab (a documented extension to the shipped engine, which carries single global D&A/capex percentages - too coarse here, because the CONVERGENCE of the cash/amortisation ratio toward 1.0x is the single biggest swing factor in the model). Rows 1-43 keep the published engine row map unchanged. By construction row 13 EBIT then equals reported GAAP operating income.
A17: FY2025 tie-out | B17: Applying this mapping to FY2025 actuals produces owner FCF of $9,503m against reported FCF of $9,461m - a $42m difference, being the net of excluding interest (+$0.6bn), expensing SBC (-$0.37bn) and excluding non-recurring/other non-cash items (-$0.2bn). See the bridge at the foot of Actuals_Data. The close tie is the main evidence that the content mapping is right.
A18: Warner Bros. termination fee | B18: EXCLUDED from every flow in this model. The $2.8bn fee Netflix received on the collapsed WBD deal sits in Q1'26 'interest and other income' - below operating income - so it never enters row 13 EBIT. It is worth roughly $2.1bn after tax (~17% of the $12.5bn FY26 FCF guide and ~$0.50 of 2026 EPS), and it is also why 2026-27 consensus EPS growth looks weak: ex-fee, 2026->2027 is ~+24%, not ~+7%. Any comparison of this model against guided FCF or reported EPS must strip it first.
A19: Cash tax | B19: FY0 cash tax rate 16.4% of EBIT (book provision $1,741.4m less the -$442.1m deferred component = $2,183.5m current tax). Netflix's low rate is structural (FDII, foreign mix, option exercises) rather than an expiring NOL, so it is more durable than DUOL's shelter was - but house rule is to normalise, and OECD Pillar Two plus digital-services taxes are live risks. Ramped to 21% by 2030 (Base/Bull) and 22% (Bear). Holding the Base terminal rate at 18% instead of 21% would add ~$2/share; this is a deliberate conservatism, not a forecast.
A20: Working capital | B20: Set NEGATIVE (per scenario: Bear -6%, Base -4%, Bull -2% of the YoY revenue increase). The prepaid-subscription deferred-revenue float is real but small (+$254.9m in FY25) and has been more than offset by other operating assets and liabilities (FY25 net working-capital movement -$456.3m on a $6,182m revenue increase, i.e. -7.4%). The ~$700m Brazilian tax-dispute deposit that slipped from 2025 into 2026 is treated as a one-off and is NOT in the run-rate. Note the content-spend wedge - the item that would sit in working capital for most businesses - is modelled inside capex instead (see above).
A21: Net debt, not net cash | B21: Deviation from the house default (cash + short-term investments), and deliberate: Netflix carries $14.3bn of real debt against $9.1bn of cash. The Assumptions net-cash cell is therefore NEGATIVE $5,244.2m, taken from Netflix's own non-GAAP net-debt reconciliation at 30-Jun-2026. The $25.1bn of total streaming content obligations (including amounts not yet on the balance sheet) are NOT treated as debt-like, per Stephen's sign-off on 9-Aug-2026: that spend is already fully modelled through the content capex line, so adding it to the bridge would double-count it.
A22: WACC | B22: House default 10.5% retained. Defensible on CAPM for a name with realised beta above 1 that has just drawn down ~45%, but it is the single most powerful input in the file: Base ranges from $77.85 at 8.5% to $44.82 at 12%. The required-return table and the WACC x terminal-growth grid on the Valuation tab exist precisely so this can be re-read at another hurdle rate. Terminal growth 1.5/3.0/3.5% (Bear/Base/Bull), house defaults.
A23: Scenario drivers | B23: All ten forecast years for all three scenarios are Claude's judgment, constructed 9-Aug-2026 from the deep dive of the same date and signed off at architecture level by Stephen ('go with your intuition'), who approved the Bear/Base/Bull axes and the house 15/50/35 weights. Year 1 (2026E) is company guidance in every scenario - the scenarios only diverge from 2027. The axes are: hours-per-member (falling: +2% total view hours in H1'26 on a faster-growing member base); whether the ~14-month price ladder keeps clearing at ~2% monthly churn (Antenna; peers 5-8%); advertising scaling from ~$3bn (2026E) toward the company's ~$9bn 2030 ambition; operating leverage on the ~31% non-content cost base; and the content cash-spend / amortisation ratio. Nothing here has been reconciled against a prior file because none exists - treat every 2027+ column as a first draft to be argued with.
A25: UPDATE INSTRUCTIONS
A26: Each quarter | B26: Next print is Q3'26, expected ~20-Oct-2026 (unconfirmed; Netflix normally announces the date in mid-September). Refresh: price, net debt + date, diluted shares, buyback usage and remaining authorisation, and the 2026E guidance columns. Then reassess blue rows 5/7/9/14 and 46-49 per scenario ONLY where the print gives evidence - leave later-year judgments alone and say so. Add a Reconciliation tab (prior per-share values hardcoded blue with their date and price, current version as green links, plus an approximate $/share bridge), and increment the version above.
A27: What to watch on the print | B27: UCAN growth with the March-2026 price rise fully flowed through (Q2 was only +10% on a partial quarter - it needs to reaccelerate); operating margin against the implied H2 step-up (33.2% guided for Q3 vs 28.2% a year earlier, driven by content amortisation growth slowing in H2); whether ads closed the ~$3bn year and what the US upfront settled at; the free-trial retest; any read on the 3-Aug publisher short-form launch; and the FY27 framework, which is the first year with no termination fee in the base. From 2027 Netflix reports view hours annually, not half-yearly - the engagement axis gets harder to track exactly when it is under most scrutiny.
A28: What would move the drivers | B28: Rows 46/48 (content): evidence that the cash-spend/amortisation ratio is converging (Bull) or stuck (Bear) - management guides this ratio explicitly each January. Row 5 (growth): UCAN reacceleration, ad-market expansion to the 15 new countries from 2027, aggregation deals of the TF1 type. Row 7 (margin): whether live-sports rights and aggregation revenue-shares dilute the mix. Row 14 (tax): Pillar Two and DST developments. Structural wildcard: if the Paramount-WBD deal is blocked on antitrust (it can run to June 2027), those assets return to play and Netflix's capital-allocation discipline gets retested.
A29: Conventions | B29: Blue = hardcoded input. Yellow fill = key lever. Black = formula. Green = cross-sheet link. All $ in millions unless stated. Percentages stored as fractions.
A31: NOT INVESTMENT ADVICE | B31: This is Stephen's own framework computed at the inputs above. Every 2027+ number is a judgment, and the output is only as good as those judgments.

Sheet Actuals_Data
A1: NFLX - Reported Actuals & Guidance (all hardcoded, blue)
A2: Every figure below is taken from a Netflix shareholder letter. $ in millions except per-share.
A4: Quarterly | B4: Q2'25A | C4: Q3'25A | D4: Q4'25A | E4: Q1'26A | F4: Q2'26A | G4: Q3'26G | H4: Source
A5: Revenue | B5: 11079 | C5: 11510 | D5: 12051 | E5: 12250 | F5: 12560 | G5: 12860 | H5: Q2'26 letter summary table (Q1'26 shown as reported $12,249.8m)
A6: Revenue growth y/y | B6: 0.159 | C6: 0.172 | D6: 0.176 | E6: 0.162 | F6: 0.134 | G6: 0.117 | H6: Third consecutive quarter of deceleration
A7: Operating income | B7: 3775 | C7: 3248 | D7: 2957 | E7: 3957 | F7: 4193 | G7: 4268 | H7: Q2'26 letter
A8: Operating margin | B8: 0.341 | C8: 0.282 | D8: 0.245 | E8: 0.323 | F8: 0.334 | G8: 0.332 | H8: Q4 is seasonally lowest (marketing + content timing)
A9: Net income | B9: 3125 | C9: 2547 | D9: 2419 | E9: 5283 | F9: 3401 | G9: 3452 | H9: Q1'26 includes the $2.8bn WBD termination fee in other income
A10: Diluted EPS | B10: 0.72 | C10: 0.59 | D10: 0.56 | E10: 1.23 | F10: 0.8 | G10: 0.82 | H10: Restated for the 10-for-1 split of 14-Nov-2025
A11: Free cash flow | B11: 2267 | C11: 2660 | D11: 1872 | E11: 5094 | F11: 1525 | H11: Q2'26 hit by cash taxes on the termination fee
A12: Diluted shares (mm) | B12: 4349 | C12: 4340 | D12: 4317 | E12: 4298 | F12: 4261 | H12: Falling ~2%/yr on buybacks
A14: Annual | B14: FY2024A | C14: FY2025A | D14: FY2026G | H14: Source / note
A15: Revenue | B15: 39001 | C15: 45183 | D15: 51200 | H15: FY26 = midpoint of the $51.0-51.4bn guide
A16: Revenue growth y/y | B16: 0.16 | C16: 0.159 | D16: 0.133 | H16: FY26 guide 13-14% reported, ~12% FX-neutral
A17: Operating income | B17: 10417.6 | C17: 13326.6 | D17: 16128 | H17: FY26 derived as 31.5% x guided revenue midpoint
A18: Operating margin | B18: 0.267 | C18: 0.295 | D18: 0.315 | H18: Guided; implies operating income growth of 20%+ in 2026
A19: Net income | B19: 8711.6 | C19: 10981.2 | H19: FY26 not guided; would include the termination fee
A20: Diluted EPS | B20: 1.98 | C20: 2.53 | H20: Consensus FY26 ~$3.59 incl. fee, ~$3.09 ex-fee
A21: Operating cash flow | B21: 7361.4 | C21: 10149.3 | H21: FY25 letter cash-flow statement
A22: Capex - property & equipment | B22: 439.5 | C22: 688.2 | D22: 900 | H22: FY26 estimated from H1'26 actual of $414.8m
A23: Free cash flow (reported) | B23: 6921.8 | C23: 9461.1 | D23: 12500 | H23: FY26 guided ~$12.5bn - INCLUDES the WBD fee
A24: less: WBD termination fee, after tax | B24: 0 | C24: 0 | D24: -2142 | H24: $2.8bn pre-tax at ~23.5%; strip before any comparison
A25: underlying FCF ex-fee | B25: 6921.8 | C25: 9461.1 | D25: 10358 | H25: The number to compare against this model
A26: Stock-based compensation | B26: 272.6 | C26: 368.4 | D26: 620 | H26: FY26 est. from H1'26 $271.7m; ~1.2% of revenue - very low for large-cap tech
A27: Additions to content assets | B27: 16223.6 | C27: 17096.6 | H27: Cash-flow statement
A28: Change in content liabilities | B28: -779.1 | C28: -610.8 | H28: Cash-flow statement
A29: Content cash spend (sum of the two) | B29: 17002.7 | C29: 17707.4 | D29: 19870 | H29: FY26 = 1.10x guided amortisation
A30: Content amortisation | B30: 15301.5 | C30: 16422.2 | D30: 18064.4 | H30: FY26 = +10% y/y as guided
A31: Content cash spend / amortisation | B31: 1.111 | C31: 1.078 | D31: 1.1 | H31: Management guides ~1.1x for 2026 - the model's key lever
A32: Tax provision (book) | B32: 1254 | C32: 1741.4 | H32: Effective rate 12.6% (FY24) and 13.7% (FY25) - well below statutory
A33: of which deferred | B33: -590.7 | C33: -442.1 | H33: Cash-flow statement
A34: Cash taxes paid (derived) | B34: 1844.7 | C34: 2183.5 | H34: Book provision less deferred component
A35: Cash tax rate on EBIT | B35: 0.177 | C35: 0.164 | D35: 0.17 | H35: FY26 estimate; model row 14 starts here and ramps
A37: Balance sheet, 30-Jun-2026
A38: Cash and cash equivalents | B38: 9099.2 | H38: Q2'26 letter
A39: Short-term investments | B39: 28.7 | H39: Q2'26 letter
A40: Total debt | B40: 14309.3 | H40: $1bn matures later in 2026 and will be refinanced
A41: NET DEBT (Netflix non-GAAP reconciliation) | B41: 5244.2 | H41: Enters the model as NEGATIVE net cash
A42: Content assets, net | B42: 33837.6 | H42: Q2'26 balance sheet
A43: Total streaming content obligations | B43: 25106.7 | H43: Incl. off-balance-sheet; deliberately NOT in the bridge
...

Sheet Assumptions
A1: NFLX - Global Assumptions & Scenario Parameters
A2: Blue = hardcoded input. Yellow = key lever. All $ in millions unless stated.
A4: Global inputs
A5: WACC / discount rate | B5: 0.105 | H5: House default for this risk class. The most powerful single input - see the required-return table on Valuation.
A6: D&A (% of revenue) - FY0 reference only | B6: 0.3709 | H6: NOT live. Live per-year drivers are rows 46-47 on each DCF tab. FY2025 = content amortisation 36.35% + PP&E D&A 0.74%.
A7: Capex (% of revenue) - FY0 reference only | B7: 0.407053 | H7: NOT live. Live per-year drivers are rows 46 x 48 plus 49. FY2025 = content cash spend 39.19% + PP&E 1.52%.
A8: Working-capital capture - default | B8: -0.04 | H8: NOT live. Live value is per scenario in the block below. Negative: the deferred-revenue float is outweighed by other operating assets and liabilities.
A9: Net cash / (net debt) ($mm) | B9: -5244.2 | H9: NEGATIVE - Netflix carries net debt of $5,244.2m at 30-Jun-2026 per its own non-GAAP reconciliation.
A10: Fully diluted shares (mm) | B10: 4261.3 | H10: Q2'26 letter, weighted average diluted. Held flat: SBC is expensed instead of modelling grant dilution.
A11: Current share price | B11: 74.14 | H11: Last regular close, Friday 7-Aug-2026. Refresh before acting.
A12: Terminal value cap (x terminal-year owner FCF) | B12: 20 | H12: House cap. Not binding in any scenario here - Gordon gives 11.3x/13.7x/14.8x.
A14: Scenario parameters | C14: Bear | D14: Base | E14: Bull
A15: Terminal growth rate | C15: 0.015 | D15: 0.03 | E15: 0.035
A16: Working-capital capture (% of YoY revenue incr.) | C16: -0.06 | D16: -0.04 | E16: -0.02 | H16: Negative in all cases; FY2025 actual was -7.4% of the revenue increase
A17: Probability weight | C17: 0.15 | D17: 0.5 | E17: 0.35 | F17: =SUM(C17:E17) -> 1 | G17: must sum to 100%
A19: Scenario narratives
A20: Bear | B20: Attention loss compounds and price becomes the only lever left. Hours per member keep falling, memberships plateau, and the March-2026 style rise starts to bite - churn steps from ~2% toward 3% and the ladder stops clearing. Advertising plateaus near $5-6bn as CPM deflation outruns impression growth, and YouTube's aggregation of rival services (Peacock inside YouTube Premium from early 2027) caps Netflix's share of TV time. Netflix has to buy engagement back - sports rights, aggregation revenue shares, publisher licences - so the 31.5% margin of 2026 turns out to be the peak and drifts back toward 29%, and content cash spend stays permanently above amortisation at ~1.1x. Revenue fades to 2-3%. Not a broken business: a mature, price-led one that was mistaken for a growth stock.
A21: Base | B21: Monetisation carries the business while volume flatlines. Hours per member keep drifting down, but the price ladder keeps clearing at ~2% churn, the ad tier scales to roughly $8bn by 2030 on the 15 new markets and programmatic, and the ~31% non-content cost base leverages steadily. Revenue compounds at ~7-8% after 2026, operating margin climbs from 31.5% toward ~35% by 2030 and ~37% by 2035, and the content cash-spend ratio grinds down from 1.10x to ~1.02x as the library matures and genAI takes real cost out of post-production. Ads and aggregation (TF1-style deals, publisher short-form, podcasts, games) do enough to hold share of TV time without ever winning the attention war outright. Cash taxes normalise to 21%.
A22: Bull | B22: The harness thesis works: Netflix converts from a place you watch shows into the default TV aggregation layer - third-party services, live channels, creators, publishers, podcasts and cloud games inside one interface - and takes distribution economics on content it does not have to fund. GenAI genuinely bends the content cost curve (already documented at twice the speed and half the cost on real footage), so a slowly growing budget buys a much larger slate and cash spend converges to amortisation by 2030. Advertising reaches the company's ~$9bn 2030 ambition and beyond, lifting blended margin toward 42% by 2035, revenue roughly doubles from 2024 by 2030 as management has aspired, and the $27bn buyback authorisation retires a high-single-digit share of the company at depressed prices.

Sheet DCF_Bear
A1: NFLX DCF - Bear - price-led maturity; engagement keeps eroding
A2: Owner-FCF basis: SBC fully expensed, interest excluded, share count flat. Blue rows 5/7/9/14 and 46-49 are per-year drivers (edit these).
B3: 2025A | C3: 2026E | D3: 2027E | E3: 2028E | F3: 2029E | G3: 2030E | H3: 2031E | I3: 2032E | J3: 2033E | K3: 2034E | L3: 2035E
A4: Year index (for discounting) | B4: 0 | C4: 1 | D4: 2 | E4: 3 | F4: 4 | G4: 5 | H4: 6 | I4: 7 | J4: 8 | K4: 9 | L4: 10
A5: Revenue growth YoY | C5: 0.133 | D5: 0.08 | E5: 0.06 | F5: 0.05 | G5: 0.04 | H5: 0.035 | I5: 0.03 | J5: 0.025 | K5: 0.025 | L5: 0.02
A6: Revenue | B6: 45183 | C6: =B6*(1+C5) -> 51192.339 | D6: =C6*(1+D5) -> 55287.726 | E6: =D6*(1+E5) -> 58604.99 | F6: =E6*(1+F5) -> 61535.239 | G6: =F6*(1+G5) -> 63996.649 | H6: =G6*(1+H5) -> 66236.531 | I6: =H6*(1+I5) -> 68223.627 | J6: =I6*(1+J5) -> 69929.218 | ... L6: =K6*(1+L5) -> 73110.997
A7: Adj EBITDA margin (pre-SBC, pre-content amort) | B7: 0.6739 | C7: 0.6878 | D7: 0.69 | E7: 0.69 | F7: 0.689 | G7: 0.687 | H7: 0.685 | I7: 0.683 | J7: 0.682 | K7: 0.681 | L7: 0.68
A8: Adjusted EBITDA | C8: =C6*C7 -> 35210.091 | D8: =D6*D7 -> 38148.531 | E8: =E6*E7 -> 40437.443 | F8: =F6*F7 -> 42397.78 | G8: =G6*G7 -> 43965.698 | H8: =H6*H7 -> 45372.024 | I8: =I6*I7 -> 46596.738 | J8: =J6*J7 -> 47691.727 | ... L8: =L6*L7 -> 49715.478
A9: SBC (% of revenue) | B9: 0.0082 | C9: 0.012 | D9: 0.014 | E9: 0.0155 | F9: 0.017 | G9: 0.018 | H9: 0.019 | I9: 0.02 | J9: 0.0205 | K9: 0.021 | L9: 0.0215
A10: SBC (incl. equity-award taxes) | C10: =-C6*C9 -> -614.30807 | D10: =-D6*D9 -> -774.02817 | E10: =-E6*E9 -> -908.37734 | F10: =-F6*F9 -> -1046.0991 | G10: =-G6*G9 -> -1151.9397 | H10: =-H6*H9 -> -1258.4941 | I10: =-I6*I9 -> -1364.4725 | J10: =-J6*J9 -> -1433.549 | ... L10: =-L6*L9 -> -1571.8864
A11: EBITDA less SBC ('owner EBITDA') | C11: =C8+C10 -> 34595.783 | D11: =D8+D10 -> 37374.503 | E11: =E8+E10 -> 39529.066 | F11: =F8+F10 -> 41351.681 | G11: =G8+G10 -> 42813.758 | H11: =H8+H10 -> 44113.53 | I11: =I8+I10 -> 45232.265 | J11: =J8+J10 -> 46258.178 | ... L11: =L8+L10 -> 48143.592
A12: D&A (content amortisation + PP&E) | C12: =-C6*(C46+C47) -> -18470.196 | D12: =-D6*(D46+D47) -> -19804.063 | E12: =-E6*(E46+E47) -> -21004.028 | F12: =-F6*(F46+F47) -> -22183.454 | G12: =-G6*(G46+G47) -> -23205.185 | H12: =-H6*(H46+H47) -> -24156.463 | I12: =-I6*(I46+I47) -> -25024.427 | J12: =-J6*(J46+J47) -> -25789.896 | ... L12: =-L6*(L46+L47) -> -27124.18
A13: EBIT (SBC expensed) = reported operating income | C13: =C11+C12 -> 16125.587 | D13: =D11+D12 -> 17570.439 | E13: =E11+E12 -> 18525.037 | F13: =F11+F12 -> 19168.227 | G13: =G11+G12 -> 19608.573 | H13: =H11+H12 -> 19957.067 | I13: =I11+I12 -> 20207.838 | J13: =J11+J12 -> 20468.282 | ... L13: =L11+L12 -> 21019.412
A14: Cash tax rate on EBIT | B14: 0.1638 | C14: 0.17 | D14: 0.185 | E14: 0.2 | F14: 0.215 | G14: 0.22 | H14: 0.22 | I14: 0.22 | J14: 0.22 | K14: 0.22 | L14: 0.22
A15: NOPAT | C15: =C13*(1-C14) -> 13384.237 | D15: =D13*(1-D14) -> 14319.908 | E15: =E13*(1-E14) -> 14820.03 | F15: =F13*(1-F14) -> 15047.058 | G15: =G13*(1-G14) -> 15294.687 | H15: =H13*(1-H14) -> 15566.512 | I15: =I13*(1-I14) -> 15762.114 | J15: =J13*(1-J14) -> 15965.26 | ... L15: =L13*(1-L14) -> 16395.141
A16: add: D&A | C16: =-C12 -> 18470.196 | D16: =-D12 -> 19804.063 | E16: =-E12 -> 21004.028 | F16: =-F12 -> 22183.454 | G16: =-G12 -> 23205.185 | H16: =-H12 -> 24156.463 | I16: =-I12 -> 25024.427 | J16: =-J12 -> 25789.896 | ... L16: =-L12 -> 27124.18
A17: less: capex (content cash spend + PP&E) | C17: =-C6*(C46*C48+C49) -> -20767.708 | D17: =-D6*(D46*D48+D49) -> -22214.608 | E17: =-E6*(E46*E48+E49) -> -23717.439 | F17: =-F6*(F46*F48+F49) -> -25015.305 | G17: =-G6*(G46*G48+G49) -> -26365.339 | H17: =-H6*(H46*H48+H49) -> -27416.625 | I17: =-I6*(I46*I48+I49) -> -28378.3 | J17: =-J6*(J46*J48+J49) -> -29244.399 | ... L17: =-L6*(L46*L48+L49) -> -30724.166
A18: add: working capital | C18: =Assumptions!$C$16*(C6-B6) -> -360.56034 | D18: =Assumptions!$C$16*(D6-C6) -> -245.72323 | E18: =Assumptions!$C$16*(E6-D6) -> -199.03581 | F18: =Assumptions!$C$16*(F6-E6) -> -175.81497 | G18: =Assumptions!$C$16*(G6-F6) -> -147.68457 | H18: =Assumptions!$C$16*(H6-G6) -> -134.39296 | I18: =Assumptions!$C$16*(I6-H6) -> -119.22576 | J18: =Assumptions!$C$16*(J6-I6) -> -102.33544 | ... L18: =Assumptions!$C$16*(L6-K6) -> -86.012938
A19: Unlevered owner FCF | C19: =C15+C16+C17+C18 -> 10726.165 | D19: =D15+D16+D17+D18 -> 11663.64 | E19: =E15+E16+E17+E18 -> 11907.583 | F19: =F15+F16+F17+F18 -> 12039.392 | G19: =G15+G16+G17+G18 -> 11986.848 | H19: =H15+H16+H17+H18 -> 12171.957 | I19: =I15+I16+I17+I18 -> 12289.015 | J19: =J15+J16+J17+J18 -> 12408.421 | ... L19: =L15+L16+L17+L18 -> 12709.143
A20: Discount factor | C20: =1/(1+Assumptions!$B$5)^C4 -> 0.90497738 | D20: =1/(1+Assumptions!$B$5)^D4 -> 0.81898405 | E20: =1/(1+Assumptions!$B$5)^E4 -> 0.74116204 | F20: =1/(1+Assumptions!$B$5)^F4 -> 0.67073487 | G20: =1/(1+Assumptions!$B$5)^G4 -> 0.60699989 | H20: =1/(1+Assumptions!$B$5)^H4 -> 0.54932116 | I20: =1/(1+Assumptions!$B$5)^I4 -> 0.49712323 | J20: =1/(1+Assumptions!$B$5)^J4 -> 0.44988527 | ... L20: =1/(1+Assumptions!$B$5)^L4 -> 0.36844886
A21: PV of FCF | C21: =C19*C20 -> 9706.9362 | D21: =D19*D20 -> 9552.3351 | E21: =E19*E20 -> 8825.4484 | F21: =F19*F20 -> 8075.2398 | G21: =G19*G20 -> 7276.0154 | H21: =H19*H20 -> 6686.3137 | I21: =I19*I20 -> 6109.1546 | J21: =J19*J20 -> 5582.366 | ... L21: =L19*L20 -> 4682.6692
A23: Memo: FCF before SBC (company-style) | C23: =C19-C10 -> 11340.473 | D23: =D19-D10 -> 12437.668 | E23: =E19-E10 -> 12815.96 | F23: =F19-F10 -> 13085.491 | G23: =G19-G10 -> 13138.788 | H23: =H19-H10 -> 13430.451 | I23: =I19-I10 -> 13653.487 | J23: =J19-J10 -> 13841.97 | ... L23: =L19-L10 -> 14281.029
A24: Memo: implied owner FCF margin | C24: =C19/C6 -> 0.20952675 | D24: =D19/D6 -> 0.21096256 | E24: =E19/E6 -> 0.20318377 | F24: =F19/F6 -> 0.19565036 | G24: =G19/G6 -> 0.18730431 | H24: =H19/H6 -> 0.18376501 | I24: =I19/I6 -> 0.18012843 | J24: =J19/J6 -> 0.17744259 | ... L24: =L19/L6 -> 0.17383353
A25: Valuation
A26: PV of FCF, explicit years | B26: =SUM(C21:L21) -> 71620.762
A27: Terminal growth rate | B27: =Assumptions!$C$15 -> 0.015
A28: Terminal-year owner FCF x (1+g) | B28: =L19*(1+B27) -> 12899.78
A29: Terminal value - Gordon | B29: =B28/(Assumptions!$B$5-B27) -> 143330.89
A30: Terminal value - cap | B30: =Assumptions!$B$12*L19 -> 254182.85
A31: Terminal value used (lower of the two) | B31: =MIN(B29,B30) -> 143330.89
A32: Implied exit multiple | B32: =B31/L19 -> 11.277778
A33: PV of terminal value | B33: =B31*L20 -> 52810.102
A34: Enterprise value | B34: =B26+B33 -> 124430.86
A35: add: net cash / (net debt) | B35: =Assumptions!$B$9 -> -5244.2
A36: Equity value | B36: =B34+B35 -> 119186.66
A37: Fully diluted shares (mm) | B37: =Assumptions!$B$10 -> 4261.3
A38: Value per share | B38: =B36/B37 -> 27.969555
A39: Upside / (downside) vs current price | B39: =B38/Assumptions!$B$11-1 -> -0.62274676
A41: Memo: PV of explicit-period SBC | B41: =SUMPRODUCT(-C10:L10/(1+Assumptions!$B$5)^C4:L4) -> 6470.5414
A42: plus PV of terminal SBC | B42: =(-L10*(1+B27)/(Assumptions!$B$5-B27))*L20 -> 6531.6352
...

Sheet DCF_Base
A1: NFLX DCF - Base - monetisation carries it while volume flatlines
A2: Owner-FCF basis: SBC fully expensed, interest excluded, share count flat. Blue rows 5/7/9/14 and 46-49 are per-year drivers (edit these).
B3: 2025A | C3: 2026E | D3: 2027E | E3: 2028E | F3: 2029E | G3: 2030E | H3: 2031E | I3: 2032E | J3: 2033E | K3: 2034E | L3: 2035E
A4: Year index (for discounting) | B4: 0 | C4: 1 | D4: 2 | E4: 3 | F4: 4 | G4: 5 | H4: 6 | I4: 7 | J4: 8 | K4: 9 | L4: 10
A5: Revenue growth YoY | C5: 0.133 | D5: 0.105 | E5: 0.095 | F5: 0.085 | G5: 0.075 | H5: 0.065 | I5: 0.06 | J5: 0.055 | K5: 0.05 | L5: 0.045
A6: Revenue | B6: 45183 | C6: =B6*(1+C5) -> 51192.339 | D6: =C6*(1+D5) -> 56567.535 | E6: =D6*(1+E5) -> 61941.45 | F6: =E6*(1+F5) -> 67206.474 | G6: =F6*(1+G5) -> 72246.959 | H6: =G6*(1+H5) -> 76943.012 | I6: =H6*(1+I5) -> 81559.592 | J6: =I6*(1+J5) -> 86045.37 | ... L6: =K6*(1+L5) -> 94413.282
A7: Adj EBITDA margin (pre-SBC, pre-content amort) | B7: 0.6739 | C7: 0.6878 | D7: 0.692 | E7: 0.696 | F7: 0.7 | G7: 0.703 | H7: 0.706 | I7: 0.709 | J7: 0.711 | K7: 0.713 | L7: 0.715
A8: Adjusted EBITDA | C8: =C6*C7 -> 35210.091 | D8: =D6*D7 -> 39144.734 | E8: =E6*E7 -> 43111.249 | F8: =F6*F7 -> 47044.532 | G8: =G6*G7 -> 50789.612 | H8: =H6*H7 -> 54321.766 | I8: =I6*I7 -> 57825.751 | J8: =J6*J7 -> 61178.258 | ... L8: =L6*L7 -> 67505.497
A9: SBC (% of revenue) | B9: 0.0082 | C9: 0.012 | D9: 0.013 | E9: 0.014 | F9: 0.0145 | G9: 0.015 | H9: 0.0155 | I9: 0.016 | J9: 0.016 | K9: 0.0165 | L9: 0.0165
A10: SBC (incl. equity-award taxes) | C10: =-C6*C9 -> -614.30807 | D10: =-D6*D9 -> -735.37795 | E10: =-E6*E9 -> -867.18031 | F10: =-F6*F9 -> -974.49387 | G10: =-G6*G9 -> -1083.7044 | H10: =-H6*H9 -> -1192.6167 | I10: =-I6*I9 -> -1304.9535 | J10: =-J6*J9 -> -1376.7259 | ... L10: =-L6*L9 -> -1557.8192
A11: EBITDA less SBC ('owner EBITDA') | C11: =C8+C10 -> 34595.783 | D11: =D8+D10 -> 38409.356 | E11: =E8+E10 -> 42244.069 | F11: =F8+F10 -> 46070.038 | G11: =G8+G10 -> 49705.908 | H11: =H8+H10 -> 53129.149 | I11: =I8+I10 -> 56520.797 | J11: =J8+J10 -> 59801.532 | ... L11: =L8+L10 -> 65947.677
A12: D&A (content amortisation + PP&E) | C12: =-C6*(C46+C47) -> -18470.196 | D12: =-D6*(D46+D47) -> -20036.221 | E12: =-E6*(E46+E47) -> -21580.401 | F12: =-F6*(F46+F47) -> -23085.424 | G12: =-G6*(G46+G47) -> -24462.82 | H12: =-H6*(H46+H47) -> -25752.826 | I12: =-I6*(I46+I47) -> -27061.473 | J12: =-J6*(J46+J47) -> -28291.718 | ... L12: =-L6*(L46+L47) -> -30684.317
A13: EBIT (SBC expensed) = reported operating income | C13: =C11+C12 -> 16125.587 | D13: =D11+D12 -> 18373.135 | E13: =E11+E12 -> 20663.668 | F13: =F11+F12 -> 22984.614 | G13: =G11+G12 -> 25243.088 | H13: =H11+H12 -> 27376.324 | I13: =I11+I12 -> 29459.325 | J13: =J11+J12 -> 31509.814 | ... L13: =L11+L12 -> 35263.361
A14: Cash tax rate on EBIT | B14: 0.1638 | C14: 0.17 | D14: 0.18 | E14: 0.19 | F14: 0.2 | G14: 0.21 | H14: 0.21 | I14: 0.21 | J14: 0.21 | K14: 0.21 | L14: 0.21
A15: NOPAT | C15: =C13*(1-C14) -> 13384.237 | D15: =D13*(1-D14) -> 15065.971 | E15: =E13*(1-E14) -> 16737.571 | F15: =F13*(1-F14) -> 18387.691 | G15: =G13*(1-G14) -> 19942.039 | H15: =H13*(1-H14) -> 21627.296 | I15: =I13*(1-I14) -> 23272.867 | J15: =J13*(1-J14) -> 24892.753 | ... L15: =L13*(1-L14) -> 27858.055
A16: add: D&A | C16: =-C12 -> 18470.196 | D16: =-D12 -> 20036.221 | E16: =-E12 -> 21580.401 | F16: =-F12 -> 23085.424 | G16: =-G12 -> 24462.82 | H16: =-H12 -> 25752.826 | I16: =-I12 -> 27061.473 | J16: =-J12 -> 28291.718 | ... L16: =-L12 -> 30684.317
A17: less: capex (content cash spend + PP&E) | C17: =-C6*(C46*C48+C49) -> -20767.708 | D17: =-D6*(D46*D48+D49) -> -22099.804 | E17: =-E6*(E46*E48+E49) -> -23345.733 | F17: =-F6*(F46*F48+F49) -> -24715.181 | G17: =-G6*(G46*G48+G49) -> -25936.658 | H17: =-H6*(H46*H48+H49) -> -27028.541 | I17: =-I6*(I46*I48+I49) -> -28398.234 | J17: =-J6*(J46*J48+J49) -> -29393.098 | ... L17: =-L6*(L46*L48+L49) -> -31847.488
A18: add: working capital | C18: =Assumptions!$D$16*(C6-B6) -> -240.37356 | D18: =Assumptions!$D$16*(D6-C6) -> -215.00782 | E18: =Assumptions!$D$16*(E6-D6) -> -214.95663 | F18: =Assumptions!$D$16*(F6-E6) -> -210.60093 | G18: =Assumptions!$D$16*(G6-F6) -> -201.61942 | H18: =Assumptions!$D$16*(H6-G6) -> -187.84209 | I18: =Assumptions!$D$16*(I6-H6) -> -184.66323 | J18: =Assumptions!$D$16*(J6-I6) -> -179.4311 | ... L18: =Assumptions!$D$16*(L6-K6) -> -162.62575
A19: Unlevered owner FCF | C19: =C15+C16+C17+C18 -> 10846.351 | D19: =D15+D16+D17+D18 -> 12787.379 | E19: =E15+E16+E17+E18 -> 14757.283 | F19: =F15+F16+F17+F18 -> 16547.333 | G19: =G15+G16+G17+G18 -> 18266.582 | H19: =H15+H16+H17+H18 -> 20163.738 | I19: =I15+I16+I17+I18 -> 21751.442 | J19: =J15+J16+J17+J18 -> 23611.942 | ... L19: =L15+L16+L17+L18 -> 26532.258
A20: Discount factor | C20: =1/(1+Assumptions!$B$5)^C4 -> 0.90497738 | D20: =1/(1+Assumptions!$B$5)^D4 -> 0.81898405 | E20: =1/(1+Assumptions!$B$5)^E4 -> 0.74116204 | F20: =1/(1+Assumptions!$B$5)^F4 -> 0.67073487 | G20: =1/(1+Assumptions!$B$5)^G4 -> 0.60699989 | H20: =1/(1+Assumptions!$B$5)^H4 -> 0.54932116 | I20: =1/(1+Assumptions!$B$5)^I4 -> 0.49712323 | J20: =1/(1+Assumptions!$B$5)^J4 -> 0.44988527 | ... L20: =1/(1+Assumptions!$B$5)^L4 -> 0.36844886
A21: PV of FCF | C21: =C19*C20 -> 9815.7025 | D21: =D19*D20 -> 10472.66 | E21: =E19*E20 -> 10937.538 | F21: =F19*F20 -> 11098.874 | G21: =G19*G20 -> 11087.813 | H21: =H19*H20 -> 11076.368 | I21: =I19*I20 -> 10813.147 | J21: =J19*J20 -> 10622.665 | ... L21: =L19*L20 -> 9775.7802
A23: Memo: FCF before SBC (company-style) | C23: =C19-C10 -> 11460.659 | D23: =D19-D10 -> 13522.757 | E23: =E19-E10 -> 15624.463 | F23: =F19-F10 -> 17521.827 | G23: =G19-G10 -> 19350.286 | H23: =H19-H10 -> 21356.355 | I23: =I19-I10 -> 23056.395 | J23: =J19-J10 -> 24988.667 | ... L23: =L19-L10 -> 28090.077
A24: Memo: implied owner FCF margin | C24: =C19/C6 -> 0.2118745 | D24: =D19/D6 -> 0.2260551 | E24: =E19/E6 -> 0.23824568 | F24: =F19/F6 -> 0.24621636 | G24: =G19/G6 -> 0.2528353 | H24: =H19/H6 -> 0.26206069 | I24: =I19/I6 -> 0.26669385 | J24: =J19/J6 -> 0.27441269 | ... L24: =L19/L6 -> 0.28102251
A25: Valuation
A26: PV of FCF, explicit years | B26: =SUM(C21:L21) -> 105912.43
A27: Terminal growth rate | B27: =Assumptions!$D$15 -> 0.03
A28: Terminal-year owner FCF x (1+g) | B28: =L19*(1+B27) -> 27328.225
A29: Terminal value - Gordon | B29: =B28/(Assumptions!$B$5-B27) -> 364376.34
A30: Terminal value - cap | B30: =Assumptions!$B$12*L19 -> 530645.15
A31: Terminal value used (lower of the two) | B31: =MIN(B29,B30) -> 364376.34
A32: Implied exit multiple | B32: =B31/L19 -> 13.733333
A33: PV of terminal value | B33: =B31*L20 -> 134254.05
A34: Enterprise value | B34: =B26+B33 -> 240166.48
A35: add: net cash / (net debt) | B35: =Assumptions!$B$9 -> -5244.2
A36: Equity value | B36: =B34+B35 -> 234922.28
A37: Fully diluted shares (mm) | B37: =Assumptions!$B$10 -> 4261.3
A38: Value per share | B38: =B36/B37 -> 55.129251
A39: Upside / (downside) vs current price | B39: =B38/Assumptions!$B$11-1 -> -0.2564169
A41: Memo: PV of explicit-period SBC | B41: =SUMPRODUCT(-C10:L10/(1+Assumptions!$B$5)^C4:L4) -> 6216.4843
A42: plus PV of terminal SBC | B42: =(-L10*(1+B27)/(Assumptions!$B$5-B27))*L20 -> 7882.6133
...

Sheet DCF_Bull
A1: NFLX DCF - Bull - Netflix becomes the aggregation layer
A2: Owner-FCF basis: SBC fully expensed, interest excluded, share count flat. Blue rows 5/7/9/14 and 46-49 are per-year drivers (edit these).
B3: 2025A | C3: 2026E | D3: 2027E | E3: 2028E | F3: 2029E | G3: 2030E | H3: 2031E | I3: 2032E | J3: 2033E | K3: 2034E | L3: 2035E
A4: Year index (for discounting) | B4: 0 | C4: 1 | D4: 2 | E4: 3 | F4: 4 | G4: 5 | H4: 6 | I4: 7 | J4: 8 | K4: 9 | L4: 10
A5: Revenue growth YoY | C5: 0.133 | D5: 0.125 | E5: 0.12 | F5: 0.11 | G5: 0.1 | H5: 0.09 | I5: 0.08 | J5: 0.07 | K5: 0.065 | L5: 0.06
A6: Revenue | B6: 45183 | C6: =B6*(1+C5) -> 51192.339 | D6: =C6*(1+D5) -> 57591.381 | E6: =D6*(1+E5) -> 64502.347 | F6: =E6*(1+F5) -> 71597.605 | G6: =F6*(1+G5) -> 78757.366 | H6: =G6*(1+H5) -> 85845.529 | I6: =H6*(1+I5) -> 92713.171 | J6: =I6*(1+J5) -> 99203.093 | ... L6: =K6*(1+L5) -> 111990.37
A7: Adj EBITDA margin (pre-SBC, pre-content amort) | B7: 0.6739 | C7: 0.6878 | D7: 0.695 | E7: 0.702 | F7: 0.709 | G7: 0.715 | H7: 0.72 | I7: 0.725 | J7: 0.729 | K7: 0.732 | L7: 0.735
A8: Adjusted EBITDA | C8: =C6*C7 -> 35210.091 | D8: =D6*D7 -> 40026.01 | E8: =E6*E7 -> 45280.648 | F8: =F6*F7 -> 50762.702 | G8: =G6*G7 -> 56311.517 | H8: =H6*H7 -> 61808.781 | I8: =I6*I7 -> 67217.049 | J8: =J6*J7 -> 72319.055 | ... L8: =L6*L7 -> 82312.923
A9: SBC (% of revenue) | B9: 0.0082 | C9: 0.012 | D9: 0.0125 | E9: 0.013 | F9: 0.013 | G9: 0.0135 | H9: 0.0135 | I9: 0.014 | J9: 0.014 | K9: 0.014 | L9: 0.014
A10: SBC (incl. equity-award taxes) | C10: =-C6*C9 -> -614.30807 | D10: =-D6*D9 -> -719.89227 | E10: =-E6*E9 -> -838.53051 | F10: =-F6*F9 -> -930.76887 | G10: =-G6*G9 -> -1063.2244 | H10: =-H6*H9 -> -1158.9146 | I10: =-I6*I9 -> -1297.9844 | J10: =-J6*J9 -> -1388.8433 | ... L10: =-L6*L9 -> -1567.8652
A11: EBITDA less SBC ('owner EBITDA') | C11: =C8+C10 -> 34595.783 | D11: =D8+D10 -> 39306.118 | E11: =E8+E10 -> 44442.117 | F11: =F8+F10 -> 49831.933 | G11: =G8+G10 -> 55248.292 | H11: =H8+H10 -> 60649.866 | I11: =I8+I10 -> 65919.065 | J11: =J8+J10 -> 70930.212 | ... L11: =L8+L10 -> 80745.058
A12: D&A (content amortisation + PP&E) | C12: =-C6*(C46+C47) -> -18470.196 | D12: =-D6*(D46+D47) -> -20168.502 | E12: =-E6*(E46+E47) -> -21956.599 | F12: =-F6*(F46+F47) -> -23734.606 | G12: =-G6*(G46+G47) -> -25485.884 | H12: =-H6*(H46+H47) -> -27187.279 | I12: =-I6*(I46+I47) -> -28815.254 | J12: =-J6*(J46+J47) -> -30336.306 | ... L12: =-L6*(L46+L47) -> -33485.121
A13: EBIT (SBC expensed) = reported operating income | C13: =C11+C12 -> 16125.587 | D13: =D11+D12 -> 19137.616 | E13: =E11+E12 -> 22485.518 | F13: =F11+F12 -> 26097.327 | G13: =G11+G12 -> 29762.409 | H13: =H11+H12 -> 33462.587 | I13: =I11+I12 -> 37103.811 | J13: =J11+J12 -> 40593.906 | ... L13: =L11+L12 -> 47259.937
A14: Cash tax rate on EBIT | B14: 0.1638 | C14: 0.17 | D14: 0.175 | E14: 0.185 | F14: 0.195 | G14: 0.205 | H14: 0.21 | I14: 0.21 | J14: 0.21 | K14: 0.21 | L14: 0.21
A15: NOPAT | C15: =C13*(1-C14) -> 13384.237 | D15: =D13*(1-D14) -> 15788.533 | E15: =E13*(1-E14) -> 18325.697 | F15: =F13*(1-F14) -> 21008.348 | G15: =G13*(1-G14) -> 23661.115 | H15: =H13*(1-H14) -> 26435.444 | I15: =I13*(1-I14) -> 29312.011 | J15: =J13*(1-J14) -> 32069.185 | ... L15: =L13*(1-L14) -> 37335.35
A16: add: D&A | C16: =-C12 -> 18470.196 | D16: =-D12 -> 20168.502 | E16: =-E12 -> 21956.599 | F16: =-F12 -> 23734.606 | G16: =-G12 -> 25485.884 | H16: =-H12 -> 27187.279 | I16: =-I12 -> 28815.254 | J16: =-J12 -> 30336.306 | ... L16: =-L12 -> 33485.121
A17: less: capex (content cash spend + PP&E) | C17: =-C6*(C46*C48+C49) -> -20767.708 | D17: =-D6*(D46*D48+D49) -> -22065.562 | E17: =-E6*(E46*E48+E49) -> -23355.01 | F17: =-F6*(F46*F48+F49) -> -24769.908 | G17: =-G6*(G46*G48+G49) -> -26084.44 | H17: =-H6*(H46*H48+H49) -> -27813.951 | I17: =-I6*(I46*I48+I49) -> -29464.246 | J17: =-J6*(J46*J48+J49) -> -31010.887 | ... L17: =-L6*(L46*L48+L49) -> -34213.059
A18: add: working capital | C18: =Assumptions!$E$16*(C6-B6) -> -120.18678 | D18: =Assumptions!$E$16*(D6-C6) -> -127.98085 | E18: =Assumptions!$E$16*(E6-D6) -> -138.21932 | F18: =Assumptions!$E$16*(F6-E6) -> -141.90516 | G18: =Assumptions!$E$16*(G6-F6) -> -143.19521 | H18: =Assumptions!$E$16*(H6-G6) -> -141.76326 | I18: =Assumptions!$E$16*(I6-H6) -> -137.35285 | J18: =Assumptions!$E$16*(J6-I6) -> -129.79844 | ... L18: =Assumptions!$E$16*(L6-K6) -> -126.78155
A19: Unlevered owner FCF | C19: =C15+C16+C17+C18 -> 10966.538 | D19: =D15+D16+D17+D18 -> 13763.492 | E19: =E15+E16+E17+E18 -> 16789.067 | F19: =F15+F16+F17+F18 -> 19831.142 | G19: =G15+G16+G17+G18 -> 22919.364 | H19: =H15+H16+H17+H18 -> 25667.008 | I19: =I15+I16+I17+I18 -> 28525.666 | J19: =J15+J16+J17+J18 -> 31264.806 | ... L19: =L15+L16+L17+L18 -> 36480.631
A20: Discount factor | C20: =1/(1+Assumptions!$B$5)^C4 -> 0.90497738 | D20: =1/(1+Assumptions!$B$5)^D4 -> 0.81898405 | E20: =1/(1+Assumptions!$B$5)^E4 -> 0.74116204 | F20: =1/(1+Assumptions!$B$5)^F4 -> 0.67073487 | G20: =1/(1+Assumptions!$B$5)^G4 -> 0.60699989 | H20: =1/(1+Assumptions!$B$5)^H4 -> 0.54932116 | I20: =1/(1+Assumptions!$B$5)^I4 -> 0.49712323 | J20: =1/(1+Assumptions!$B$5)^J4 -> 0.44988527 | ... L20: =1/(1+Assumptions!$B$5)^L4 -> 0.36844886
A21: PV of FCF | C21: =C19*C20 -> 9924.4688 | D21: =D19*D20 -> 11272.081 | E21: =E19*E20 -> 12443.419 | F21: =F19*F20 -> 13301.438 | G21: =G19*G20 -> 13912.051 | H21: =H19*H20 -> 14099.431 | I21: =I19*I20 -> 14180.771 | J21: =J19*J20 -> 14065.576 | ... L21: =L19*L20 -> 13441.247
A23: Memo: FCF before SBC (company-style) | C23: =C19-C10 -> 11580.846 | D23: =D19-D10 -> 14483.385 | E23: =E19-E10 -> 17627.598 | F23: =F19-F10 -> 20761.911 | G23: =G19-G10 -> 23982.588 | H23: =H19-H10 -> 26825.923 | I23: =I19-I10 -> 29823.65 | J23: =J19-J10 -> 32653.649 | ... L23: =L19-L10 -> 38048.496
A24: Memo: implied owner FCF margin | C24: =C19/C6 -> 0.21422225 | D24: =D19/D6 -> 0.23898528 | E24: =E19/E6 -> 0.26028614 | F24: =F19/F6 -> 0.27698052 | G24: =G19/G6 -> 0.29101232 | H24: =H19/H6 -> 0.29899062 | I24: =I19/I6 -> 0.30767652 | J24: =J19/J6 -> 0.31515959 | ... L24: =L19/L6 -> 0.32574792
A25: Valuation
A26: PV of FCF, explicit years | B26: =SUM(C21:L21) -> 130443.75
A27: Terminal growth rate | B27: =Assumptions!$E$15 -> 0.035
A28: Terminal-year owner FCF x (1+g) | B28: =L19*(1+B27) -> 37757.453
A29: Terminal value - Gordon | B29: =B28/(Assumptions!$B$5-B27) -> 539392.19
A30: Terminal value - cap | B30: =Assumptions!$B$12*L19 -> 729612.62
A31: Terminal value used (lower of the two) | B31: =MIN(B29,B30) -> 539392.19
A32: Implied exit multiple | B32: =B31/L19 -> 14.785714
A33: PV of terminal value | B33: =B31*L20 -> 198738.44
A34: Enterprise value | B34: =B26+B33 -> 329182.19
A35: add: net cash / (net debt) | B35: =Assumptions!$B$9 -> -5244.2
A36: Equity value | B36: =B34+B35 -> 323937.99
A37: Fully diluted shares (mm) | B37: =Assumptions!$B$10 -> 4261.3
A38: Value per share | B38: =B36/B37 -> 76.018582
A39: Upside / (downside) vs current price | B39: =B38/Assumptions!$B$11-1 -> 0.025338312
A41: Memo: PV of explicit-period SBC | B41: =SUMPRODUCT(-C10:L10/(1+Assumptions!$B$5)^C4:L4) -> 6123.2535
A42: plus PV of terminal SBC | B42: =(-L10*(1+B27)/(Assumptions!$B$5-B27))*L20 -> 8541.3841
...

Sheet Valuation
A1: NFLX - Valuation Summary & Sensitivity
A2: Owner-FCF basis (SBC expensed) unless marked street. Green = links.
B4: Bear | C4: Base | D4: Bull
A5: Value per share | B5: =DCF_Bear!$B$38 -> 27.969555 | C5: =DCF_Base!$B$38 -> 55.129251 | D5: =DCF_Bull!$B$38 -> 76.018582
A6: Upside / (downside) vs price | B6: =B5/Assumptions!$B$11-1 -> -0.62274676 | C6: =C5/Assumptions!$B$11-1 -> -0.2564169 | D6: =D5/Assumptions!$B$11-1 -> 0.025338312
A7: Probability | B7: =Assumptions!$C$17 -> 0.15 | C7: =Assumptions!$D$17 -> 0.5 | D7: =Assumptions!$E$17 -> 0.35
A8: Value per share, SBC as non-cash (street) | B8: =DCF_Bear!$B$43 -> 31.020778 | C8: =DCF_Base!$B$43 -> 58.437889 | D8: =DCF_Bull!$B$43 -> 79.459935
A10: Probability-weighted value per share | B10: =SUMPRODUCT(B5:D5,B7:D7) -> 58.366563
A11: Current price | B11: =Assumptions!$B$11 -> 74.14
A12: Margin of safety vs weighted value | B12: =1-B11/B10 -> -0.27024784 | G12: negative = price is ABOVE the weighted value
A13: Weighted value, SBC as non-cash (street) | B13: =SUMPRODUCT(B8:D8,B7:D7) -> 61.683038
A14: Band position (0%=house, 100%=street) | B14: =(Assumptions!$B$11-B10)/(B13-B10) -> 4.7560839 | G14: above 100% means the price exceeds even the street convention
A17: Base case - value per share at different required returns
A18: Required return | B18: Value / share | C18: vs price
A19: 0.085 | B19: =(SUMPRODUCT(DCF_Base!$C$19:$L$19/(1+$A19)^DCF_Base!$C$4:$L$4)+MIN(DCF_Base!$L$19*(1+Assumptions!$D$15)/($A19-Assumptions!$D$15),Assumptions!$B$12*DCF_Base!$L$19)/(1+$A19)^10+Assumptions!$B$9)/Assumptions!$B$10 -> 77.847249 | C19: =B19/Assumptions!$B$11-1 -> 0.050003361 | G19: The price implies a Base-case IRR of roughly 8.8%,
A20: 0.09 | B20: =(SUMPRODUCT(DCF_Base!$C$19:$L$19/(1+$A20)^DCF_Base!$C$4:$L$4)+MIN(DCF_Base!$L$19*(1+Assumptions!$D$15)/($A20-Assumptions!$D$15),Assumptions!$B$12*DCF_Base!$L$19)/(1+$A20)^10+Assumptions!$B$9)/Assumptions!$B$10 -> 70.725569 | C20: =B20/Assumptions!$B$11-1 -> -0.046053831 | G20: and a probability-weighted IRR of roughly 9.1%.
A21: 0.095 | B21: =(SUMPRODUCT(DCF_Base!$C$19:$L$19/(1+$A21)^DCF_Base!$C$4:$L$4)+MIN(DCF_Base!$L$19*(1+Assumptions!$D$15)/($A21-Assumptions!$D$15),Assumptions!$B$12*DCF_Base!$L$19)/(1+$A21)^10+Assumptions!$B$9)/Assumptions!$B$10 -> 64.713599 | C21: =B21/Assumptions!$B$11-1 -> -0.12714325 | G21: That is the cleanest way to read this model:
A22: 0.1 | B22: =(SUMPRODUCT(DCF_Base!$C$19:$L$19/(1+$A22)^DCF_Base!$C$4:$L$4)+MIN(DCF_Base!$L$19*(1+Assumptions!$D$15)/($A22-Assumptions!$D$15),Assumptions!$B$12*DCF_Base!$L$19)/(1+$A22)^10+Assumptions!$B$9)/Assumptions!$B$10 -> 59.573065 | C22: =B22/Assumptions!$B$11-1 -> -0.19647876 | G22: not 'wrong price' but 'this is the return on offer'.
A23: 0.105 | B23: =(SUMPRODUCT(DCF_Base!$C$19:$L$19/(1+$A23)^DCF_Base!$C$4:$L$4)+MIN(DCF_Base!$L$19*(1+Assumptions!$D$15)/($A23-Assumptions!$D$15),Assumptions!$B$12*DCF_Base!$L$19)/(1+$A23)^10+Assumptions!$B$9)/Assumptions!$B$10 -> 55.129251 | C23: =B23/Assumptions!$B$11-1 -> -0.2564169
A24: 0.11 | B24: =(SUMPRODUCT(DCF_Base!$C$19:$L$19/(1+$A24)^DCF_Base!$C$4:$L$4)+MIN(DCF_Base!$L$19*(1+Assumptions!$D$15)/($A24-Assumptions!$D$15),Assumptions!$B$12*DCF_Base!$L$19)/(1+$A24)^10+Assumptions!$B$9)/Assumptions!$B$10 -> 51.251139 | C24: =B24/Assumptions!$B$11-1 -> -0.30872486
A25: 0.12 | B25: =(SUMPRODUCT(DCF_Base!$C$19:$L$19/(1+$A25)^DCF_Base!$C$4:$L$4)+MIN(DCF_Base!$L$19*(1+Assumptions!$D$15)/($A25-Assumptions!$D$15),Assumptions!$B$12*DCF_Base!$L$19)/(1+$A25)^10+Assumptions!$B$9)/Assumptions!$B$10 -> 44.81359 | C25: =B25/Assumptions!$B$11-1 -> -0.39555449
A26: 0.15 | B26: =(SUMPRODUCT(DCF_Base!$C$19:$L$19/(1+$A26)^DCF_Base!$C$4:$L$4)+MIN(DCF_Base!$L$19*(1+Assumptions!$D$15)/($A26-Assumptions!$D$15),Assumptions!$B$12*DCF_Base!$L$19)/(1+$A26)^10+Assumptions!$B$9)/Assumptions!$B$10 -> 32.078623 | C26: =B26/Assumptions!$B$11-1 -> -0.56732367
A28: 15%-hurdle entry per scenario + weighted | B28: =(SUMPRODUCT(DCF_Bear!$C$19:$L$19/(1+0.15)^DCF_Bear!$C$4:$L$4)+MIN(DCF_Bear!$L$19*(1+Assumptions!$C$15)/(0.15-Assumptions!$C$15),Assumptions!$B$12*DCF_Bear!$L$19)/(1+0.15)^10+Assumptions!$B$9)/Assumptions!$B$10 -> 18.269569 | C28: =(SUMPRODUCT(DCF_Base!$C$19:$L$19/(1+0.15)^DCF_Base!$C$4:$L$4)+MIN(DCF_Base!$L$19*(1+Assumptions!$D$15)/(0.15-Assumptions!$D$15),Assumptions!$B$12*DCF_Base!$L$19)/(1+0.15)^10+Assumptions!$B$9)/Assumptions!$B$10 -> 32.078623 | D28: =(SUMPRODUCT(DCF_Bull!$C$19:$L$19/(1+0.15)^DCF_Bull!$C$4:$L$4)+MIN(DCF_Bull!$L$19*(1+Assumptions!$E$15)/(0.15-Assumptions!$E$15),Assumptions!$B$12*DCF_Bull!$L$19)/(1+0.15)^10+Assumptions!$B$9)/Assumptions!$B$10 -> 42.316802 | E28: =SUMPRODUCT(B28:D28,$B$7:$D$7) -> 33.590628 | G28: model buy-below price at a 15% hurdle
A29: same, street basis | B29: =B28+(SUMPRODUCT(-DCF_Bear!$C$10:$L$10/(1+0.15)^DCF_Bear!$C$4:$L$4)+(-DCF_Bear!$L$10*(1+Assumptions!$C$15)/(0.15-Assumptions!$C$15))/(1+0.15)^10)/Assumptions!$B$10 -> 20.182352 | C29: =C28+(SUMPRODUCT(-DCF_Base!$C$10:$L$10/(1+0.15)^DCF_Base!$C$4:$L$4)+(-DCF_Base!$L$10*(1+Assumptions!$D$15)/(0.15-Assumptions!$D$15))/(1+0.15)^10)/Assumptions!$B$10 -> 34.032633 | D29: =D28+(SUMPRODUCT(-DCF_Bull!$C$10:$L$10/(1+0.15)^DCF_Bull!$C$4:$L$4)+(-DCF_Bull!$L$10*(1+Assumptions!$E$15)/(0.15-Assumptions!$E$15))/(1+0.15)^10)/Assumptions!$B$10 -> 44.294987 | E29: =SUMPRODUCT(B29:D29,$B$7:$D$7) -> 35.546915
A31: Base case - value per share: WACC x terminal growth
A32: WACC \ g | B32: 0.02 | C32: 0.025 | D32: 0.03 | E32: 0.035 | F32: 0.04
A33: 0.085 | B33: =IF($A33>B$32,(SUMPRODUCT(DCF_Base!$C$19:$L$19/(1+$A33)^DCF_Base!$C$4:$L$4)+MIN(DCF_Base!$L$19*(1+B$32)/($A33-B$32),Assumptions!$B$12*DCF_Base!$L$19)/(1+$A33)^10+Assumptions!$B$9)/Assumptions!$B$10,"n/a") -> 69.489518 | C33: =IF($A33>C$32,(SUMPRODUCT(DCF_Base!$C$19:$L$19/(1+$A33)^DCF_Base!$C$4:$L$4)+MIN(DCF_Base!$L$19*(1+C$32)/($A33-C$32),Assumptions!$B$12*DCF_Base!$L$19)/(1+$A33)^10+Assumptions!$B$9)/Assumptions!$B$10,"n/a") -> 73.320145 | D33: =IF($A33>D$32,(SUMPRODUCT(DCF_Base!$C$19:$L$19/(1+$A33)^DCF_Base!$C$4:$L$4)+MIN(DCF_Base!$L$19*(1+D$32)/($A33-D$32),Assumptions!$B$12*DCF_Base!$L$19)/(1+$A33)^10+Assumptions!$B$9)/Assumptions!$B$10,"n/a") -> 77.847249 | E33: =IF($A33>E$32,(SUMPRODUCT(DCF_Base!$C$19:$L$19/(1+$A33)^DCF_Base!$C$4:$L$4)+MIN(DCF_Base!$L$19*(1+E$32)/($A33-E$32),Assumptions!$B$12*DCF_Base!$L$19)/(1+$A33)^10+Assumptions!$B$9)/Assumptions!$B$10,"n/a") -> 81.352104 | F33: =IF($A33>F$32,(SUMPRODUCT(DCF_Base!$C$19:$L$19/(1+$A33)^DCF_Base!$C$4:$L$4)+MIN(DCF_Base!$L$19*(1+F$32)/($A33-F$32),Assumptions!$B$12*DCF_Base!$L$19)/(1+$A33)^10+Assumptions!$B$9)/Assumptions!$B$10,"n/a") -> 81.352104
A34: 0.09 | B34: =IF($A34>B$32,(SUMPRODUCT(DCF_Base!$C$19:$L$19/(1+$A34)^DCF_Base!$C$4:$L$4)+MIN(DCF_Base!$L$19*(1+B$32)/($A34-B$32),Assumptions!$B$12*DCF_Base!$L$19)/(1+$A34)^10+Assumptions!$B$9)/Assumptions!$B$10,"n/a") -> 63.899914 | C34: =IF($A34>C$32,(SUMPRODUCT(DCF_Base!$C$19:$L$19/(1+$A34)^DCF_Base!$C$4:$L$4)+MIN(DCF_Base!$L$19*(1+C$32)/($A34-C$32),Assumptions!$B$12*DCF_Base!$L$19)/(1+$A34)^10+Assumptions!$B$9)/Assumptions!$B$10,"n/a") -> 67.050216 | D34: =IF($A34>D$32,(SUMPRODUCT(DCF_Base!$C$19:$L$19/(1+$A34)^DCF_Base!$C$4:$L$4)+MIN(DCF_Base!$L$19*(1+D$32)/($A34-D$32),Assumptions!$B$12*DCF_Base!$L$19)/(1+$A34)^10+Assumptions!$B$9)/Assumptions!$B$10,"n/a") -> 70.725569 | E34: =IF($A34>E$32,(SUMPRODUCT(DCF_Base!$C$19:$L$19/(1+$A34)^DCF_Base!$C$4:$L$4)+MIN(DCF_Base!$L$19*(1+E$32)/($A34-E$32),Assumptions!$B$12*DCF_Base!$L$19)/(1+$A34)^10+Assumptions!$B$9)/Assumptions!$B$10,"n/a") -> 75.069168 | F34: =IF($A34>F$32,(SUMPRODUCT(DCF_Base!$C$19:$L$19/(1+$A34)^DCF_Base!$C$4:$L$4)+MIN(DCF_Base!$L$19*(1+F$32)/($A34-F$32),Assumptions!$B$12*DCF_Base!$L$19)/(1+$A34)^10+Assumptions!$B$9)/Assumptions!$B$10,"n/a") -> 78.177431
A35: 0.095 | B35: =IF($A35>B$32,(SUMPRODUCT(DCF_Base!$C$19:$L$19/(1+$A35)^DCF_Base!$C$4:$L$4)+MIN(DCF_Base!$L$19*(1+B$32)/($A35-B$32),Assumptions!$B$12*DCF_Base!$L$19)/(1+$A35)^10+Assumptions!$B$9)/Assumptions!$B$10,"n/a") -> 59.070335 | C35: =IF($A35>C$32,(SUMPRODUCT(DCF_Base!$C$19:$L$19/(1+$A35)^DCF_Base!$C$4:$L$4)+MIN(DCF_Base!$L$19*(1+C$32)/($A35-C$32),Assumptions!$B$12*DCF_Base!$L$19)/(1+$A35)^10+Assumptions!$B$9)/Assumptions!$B$10,"n/a") -> 61.690422 | D35: =IF($A35>D$32,(SUMPRODUCT(DCF_Base!$C$19:$L$19/(1+$A35)^DCF_Base!$C$4:$L$4)+MIN(DCF_Base!$L$19*(1+D$32)/($A35-D$32),Assumptions!$B$12*DCF_Base!$L$19)/(1+$A35)^10+Assumptions!$B$9)/Assumptions!$B$10,"n/a") -> 64.713599 | E35: =IF($A35>E$32,(SUMPRODUCT(DCF_Base!$C$19:$L$19/(1+$A35)^DCF_Base!$C$4:$L$4)+MIN(DCF_Base!$L$19*(1+E$32)/($A35-E$32),Assumptions!$B$12*DCF_Base!$L$19)/(1+$A35)^10+Assumptions!$B$9)/Assumptions!$B$10,"n/a") -> 68.240639 | F35: =IF($A35>F$32,(SUMPRODUCT(DCF_Base!$C$19:$L$19/(1+$A35)^DCF_Base!$C$4:$L$4)+MIN(DCF_Base!$L$19*(1+F$32)/($A35-F$32),Assumptions!$B$12*DCF_Base!$L$19)/(1+$A35)^10+Assumptions!$B$9)/Assumptions!$B$10,"n/a") -> 72.40896
A36: 0.1 | B36: =IF($A36>B$32,(SUMPRODUCT(DCF_Base!$C$19:$L$19/(1+$A36)^DCF_Base!$C$4:$L$4)+MIN(DCF_Base!$L$19*(1+B$32)/($A36-B$32),Assumptions!$B$12*DCF_Base!$L$19)/(1+$A36)^10+Assumptions!$B$9)/Assumptions!$B$10,"n/a") -> 54.857759 | C36: =IF($A36>C$32,(SUMPRODUCT(DCF_Base!$C$19:$L$19/(1+$A36)^DCF_Base!$C$4:$L$4)+MIN(DCF_Base!$L$19*(1+C$32)/($A36-C$32),Assumptions!$B$12*DCF_Base!$L$19)/(1+$A36)^10+Assumptions!$B$9)/Assumptions!$B$10,"n/a") -> 57.058235 | D36: =IF($A36>D$32,(SUMPRODUCT(DCF_Base!$C$19:$L$19/(1+$A36)^DCF_Base!$C$4:$L$4)+MIN(DCF_Base!$L$19*(1+D$32)/($A36-D$32),Assumptions!$B$12*DCF_Base!$L$19)/(1+$A36)^10+Assumptions!$B$9)/Assumptions!$B$10,"n/a") -> 59.573065 | E36: =IF($A36>E$32,(SUMPRODUCT(DCF_Base!$C$19:$L$19/(1+$A36)^DCF_Base!$C$4:$L$4)+MIN(DCF_Base!$L$19*(1+E$32)/($A36-E$32),Assumptions!$B$12*DCF_Base!$L$19)/(1+$A36)^10+Assumptions!$B$9)/Assumptions!$B$10,"n/a") -> 62.474792 | F36: =IF($A36>F$32,(SUMPRODUCT(DCF_Base!$C$19:$L$19/(1+$A36)^DCF_Base!$C$4:$L$4)+MIN(DCF_Base!$L$19*(1+F$32)/($A36-F$32),Assumptions!$B$12*DCF_Base!$L$19)/(1+$A36)^10+Assumptions!$B$9)/Assumptions!$B$10,"n/a") -> 65.86014
A37: 0.105 | B37: =IF($A37>B$32,(SUMPRODUCT(DCF_Base!$C$19:$L$19/(1+$A37)^DCF_Base!$C$4:$L$4)+MIN(DCF_Base!$L$19*(1+B$32)/($A37-B$32),Assumptions!$B$12*DCF_Base!$L$19)/(1+$A37)^10+Assumptions!$B$9)/Assumptions!$B$10,"n/a") -> 51.152839 | C37: =IF($A37>C$32,(SUMPRODUCT(DCF_Base!$C$19:$L$19/(1+$A37)^DCF_Base!$C$4:$L$4)+MIN(DCF_Base!$L$19*(1+C$32)/($A37-C$32),Assumptions!$B$12*DCF_Base!$L$19)/(1+$A37)^10+Assumptions!$B$9)/Assumptions!$B$10,"n/a") -> 53.016782 | D37: =IF($A37>D$32,(SUMPRODUCT(DCF_Base!$C$19:$L$19/(1+$A37)^DCF_Base!$C$4:$L$4)+MIN(DCF_Base!$L$19*(1+D$32)/($A37-D$32),Assumptions!$B$12*DCF_Base!$L$19)/(1+$A37)^10+Assumptions!$B$9)/Assumptions!$B$10,"n/a") -> 55.129251 | E37: =IF($A37>E$32,(SUMPRODUCT(DCF_Base!$C$19:$L$19/(1+$A37)^DCF_Base!$C$4:$L$4)+MIN(DCF_Base!$L$19*(1+E$32)/($A37-E$32),Assumptions!$B$12*DCF_Base!$L$19)/(1+$A37)^10+Assumptions!$B$9)/Assumptions!$B$10,"n/a") -> 57.543501 | F37: =IF($A37>F$32,(SUMPRODUCT(DCF_Base!$C$19:$L$19/(1+$A37)^DCF_Base!$C$4:$L$4)+MIN(DCF_Base!$L$19*(1+F$32)/($A37-F$32),Assumptions!$B$12*DCF_Base!$L$19)/(1+$A37)^10+Assumptions!$B$9)/Assumptions!$B$10,"n/a") -> 60.329175
A38: 0.11 | B38: =IF($A38>B$32,(SUMPRODUCT(DCF_Base!$C$19:$L$19/(1+$A38)^DCF_Base!$C$4:$L$4)+MIN(DCF_Base!$L$19*(1+B$32)/($A38-B$32),Assumptions!$B$12*DCF_Base!$L$19)/(1+$A38)^10+Assumptions!$B$9)/Assumptions!$B$10,"n/a") -> 47.870546 | C38: =IF($A38>C$32,(SUMPRODUCT(DCF_Base!$C$19:$L$19/(1+$A38)^DCF_Base!$C$4:$L$4)+MIN(DCF_Base!$L$19*(1+C$32)/($A38-C$32),Assumptions!$B$12*DCF_Base!$L$19)/(1+$A38)^10+Assumptions!$B$9)/Assumptions!$B$10,"n/a") -> 49.461413 | D38: =IF($A38>D$32,(SUMPRODUCT(DCF_Base!$C$19:$L$19/(1+$A38)^DCF_Base!$C$4:$L$4)+MIN(DCF_Base!$L$19*(1+D$32)/($A38-D$32),Assumptions!$B$12*DCF_Base!$L$19)/(1+$A38)^10+Assumptions!$B$9)/Assumptions!$B$10,"n/a") -> 51.251139 | E38: =IF($A38>E$32,(SUMPRODUCT(DCF_Base!$C$19:$L$19/(1+$A38)^DCF_Base!$C$4:$L$4)+MIN(DCF_Base!$L$19*(1+E$32)/($A38-E$32),Assumptions!$B$12*DCF_Base!$L$19)/(1+$A38)^10+Assumptions!$B$9)/Assumptions!$B$10,"n/a") -> 53.279494 | F38: =IF($A38>F$32,(SUMPRODUCT(DCF_Base!$C$19:$L$19/(1+$A38)^DCF_Base!$C$4:$L$4)+MIN(DCF_Base!$L$19*(1+F$32)/($A38-F$32),Assumptions!$B$12*DCF_Base!$L$19)/(1+$A38)^10+Assumptions!$B$9)/Assumptions!$B$10,"n/a") -> 55.597614
A39: 0.115 | B39: =IF($A39>B$32,(SUMPRODUCT(DCF_Base!$C$19:$L$19/(1+$A39)^DCF_Base!$C$4:$L$4)+MIN(DCF_Base!$L$19*(1+B$32)/($A39-B$32),Assumptions!$B$12*DCF_Base!$L$19)/(1+$A39)^10+Assumptions!$B$9)/Assumptions!$B$10,"n/a") -> 44.943771 | C39: =IF($A39>C$32,(SUMPRODUCT(DCF_Base!$C$19:$L$19/(1+$A39)^DCF_Base!$C$4:$L$4)+MIN(DCF_Base!$L$19*(1+C$32)/($A39-C$32),Assumptions!$B$12*DCF_Base!$L$19)/(1+$A39)^10+Assumptions!$B$9)/Assumptions!$B$10,"n/a") -> 46.310751 | D39: =IF($A39>D$32,(SUMPRODUCT(DCF_Base!$C$19:$L$19/(1+$A39)^DCF_Base!$C$4:$L$4)+MIN(DCF_Base!$L$19*(1+D$32)/($A39-D$32),Assumptions!$B$12*DCF_Base!$L$19)/(1+$A39)^10+Assumptions!$B$9)/Assumptions!$B$10,"n/a") -> 47.838552 | E39: =IF($A39>E$32,(SUMPRODUCT(DCF_Base!$C$19:$L$19/(1+$A39)^DCF_Base!$C$4:$L$4)+MIN(DCF_Base!$L$19*(1+E$32)/($A39-E$32),Assumptions!$B$12*DCF_Base!$L$19)/(1+$A39)^10+Assumptions!$B$9)/Assumptions!$B$10,"n/a") -> 49.557328 | F39: =IF($A39>F$32,(SUMPRODUCT(DCF_Base!$C$19:$L$19/(1+$A39)^DCF_Base!$C$4:$L$4)+MIN(DCF_Base!$L$19*(1+F$32)/($A39-F$32),Assumptions!$B$12*DCF_Base!$L$19)/(1+$A39)^10+Assumptions!$B$9)/Assumptions!$B$10,"n/a") -> 51.505275
A41: Swing factors on the Base case (computed offline, for orientation)
A42: Base as built | B42: 55.13 | G42: content ratio fading 1.10x to 1.02x; cash tax to 21%
A43: if content cash spend stays at 1.10x forever | B43: 50.59 | G43: the Bear content assumption applied to Base operations
A44: if content cash spend converges to 1.00x by 2030 | B44: 56.47 | G44: the Bull content assumption applied to Base operations
A45: if cash tax normalises to 18% rather than 21% | B45: 57.12 | G45: Netflix's low rate is structural, not an expiring NOL
A46: The content wedge is worth about $6/share across its plausible range - real, but less than the discount rate, which moves the Base case from $77.85 at 8.5% to $44.82 at 12%.
