Workbook

Sheet Model_Info
A1: PINTEREST (PINS) - DCF MODEL
A3: Lineage | B3: PINS v1.0, built 8-Aug-2026 by Claude (Fable 5) with Stephen via claude.ai (openpyxl; recalculated in LibreOffice; key outputs hand-checked). Fresh build - no prior PINS workbook exists. First live run of the equity-deep-dive -> tech-dcf-workbook pipeline.
A5: DATA VINTAGE
A6: FY0 anchors | B6: FY25: revenue $4,222M (+16%), adj EBITDA $1,270M (30.1%), OCF $1,284M, FCF $1,252M - Q4/FY25 press release 12-Feb-26 (Business Wire/EDGAR). FY25 SBC estimated ~$870M + ~$33M equity-award payroll tax; exact figure to be trued up from the FY25 10-K on next update.
A7: Q2-26 print | B7: Revenue $1,179.7M +18% (+17% cc); MAU 640M +11% (12th consecutive record); ARPU UCAN $8.30 +14%, Europe $1.35, RoW $0.23; adj EBITDA $311.3M (26.4%); OCF $292.9M, FCF $269.9M; SBC $324.5M (+43% y/y, guided as the 2026 peak quarter); ad impressions +16%, pricing +1%. Press release + 10-Q, 4-Aug-26 (Business Wire / SEC EDGAR).
A8: FY1 guidance | B8: Q3-26 revenue $1,190-1,210M (+13-15%; FX headwind plus ~1.5pt one-off drag: Prime Day shift into Q2 and World Cup lapping); Q3-26 adj EBITDA $335-355M; FY26 adj EBITDA margin raised to ~30% (from 29%). Q2-26 earnings call, 4-Aug-26.
A9: Balance sheet / shares / price | B9: Net cash $274.9M = cash + marketable securities $1,274.9M (30-Jun-26 10-Q) less $1,000M face of 1.75% convertible senior notes due 1-Mar-2031, sold entirely to Elliott (related party; closed 5-Mar-26; conversion price $22.72 = 44.006M shares; capped calls strike $22.72 / cap $30.59, cost $99.2M). Undrawn $500M revolver. Diluted shares 577.6M (Q2-26 weighted: 562.9M basic + 14.7M dilutive). Price $23.33, regular close ~6-Aug-26 (aggregator) - refresh at next use. Buybacks: $2,024.9M in 1H26 at avg $18.17 (~111M shares retired); Nov-24 program canceled ($499.9M unused); March-26 program $3.5B authorized, roughly $1.9-2.0B remaining (approximate - confirm from 10-Q).
A10: Commitments / other | B10: AWS cloud commitment >=$4.0B through 2031 ($3,927.9M remaining per 10-Q); tvScientific acquired Q1-26 for $465.1M (goodwill + intangibles ~$558M now on B/S); restructuring <15% of workforce announced 27-Jan-26, total charges ~$69.6M through Q3-26 (one-off, excluded from run-rate); unrecognized SBC $1,443.8M (10-Q). Dual-class: Class B carries 20 votes/share - founders retain voting control.
A12: METHODOLOGY
A13: Owner-FCF basis | B13: SBC (incl. equity-award taxes) fully expensed, projected explicitly per scenario-year as % of revenue; INTEREST INCOME EXCLUDED from flows (cash pile added separately - including both double-counts); cash tax ramps from the current sheltered rate to a normalized ~21%; D&A and capex as % of revenue; working capital = -7% of the YoY revenue increase (set for this business model); diluted shares held FLAT (SBC expensing substitutes for grant dilution; never do both). TV = Gordon capped at 20x terminal owner FCF. End-of-year discounting. WACC 10.5%. Street-convention values (SBC as non-cash) shown as memos - the house/street pair is the accounting-regime price band.
A14: Scenario drivers | B14: Scenario axes, driver paths and 15/50/35 weights proposed by Claude from the 8-Aug-26 deep dive and signed off by Stephen the same day at the Stage-2 checkpoint (explicitly including Base SBC declining only to ~15% of revenue by 2030). Convertible treated as debt inside net cash in ALL scenarios; if-converted alternative for Bull (relevant above $22.72): +44.0M shares and add back $1,000M to net cash, worth roughly -$0.6/share on Bull BEFORE the capped-call offset (which neutralizes dilution up to $30.59) - immaterial at the weighted level, so the simpler debt treatment is used throughout. Cash-tax ramp to 21% by 2029 is deliberately faster than the $1.6B DTA would permit (house rule: never perpetuate a temporary shelter).
A16: UPDATE INSTRUCTIONS
A17: Each quarter | B17: Refresh price, net cash (+date), diluted shares, buyback pace, and the guidance-year driver columns; reassess blue rows 5/7/9/14 per scenario only where new evidence exists; add/extend the Reconciliation tab; increment the version above.
A18: Conventions | B18: Blue = hardcoded input. Yellow = key levers. Black = formula. Green = cross-sheet link. Prefilled values are working examples of the expected format.

Sheet Actuals_Data
A1: PINS - Reported Actuals & Current Guidance
A2: All cells hardcoded inputs (blue). Sources noted per row. Refresh each quarter.
A4: QUARTERLY REVENUE ($mm)
B5: Q1 | C5: Q2 | D5: Q3 | E5: Q4 | F5: FY
A6: 2025 | B6: 855 | C6: 998.2 | D6: 1049.8 | E6: 1319 | F6: 4222 | G6: Q4/FY25 press release 12-Feb-26. Q3-25 derived as FY less reported quarters.
A7: 2026 | B7: 1008 | C7: 1179.7 | G7: Q1-26 release 4-May-26 (+18% rep / +15% cc); Q2-26 release 4-Aug-26 (+18% rep / +17% cc).
A9: Q2-26 GEO DETAIL
B10: UCAN | C10: Europe | D10: RoW | E10: Global
A11: Revenue ($mm) | B11: 880 | C11: 213 | D11: 87 | E11: 1179.7 | G11: Press release 4-Aug-26. UCAN +18%, Europe +12% (+7% cc), RoW +38% (+32% cc).
A12: MAU (mm) | B12: 106 | C12: 157 | D12: 377 | E12: 640 | G12: UCAN +4%, Europe +8%, RoW +15%, global +11% y/y.
A13: ARPU ($/quarter) | B13: 8.3 | C13: 1.35 | D13: 0.23 | E13: 1.86 | G13: UCAN +14%, Europe +4%, RoW +21%, global +7% y/y. UCAN = 75% of revenue from 17% of users.
A15: PROFITABILITY & CASH FLOW ($mm)
A16: Adj EBITDA - FY25 / margin | B16: 1270 | C16: 0.3008 | G16: FY25 release. Q4-25 alone: $542M, 41% margin (seasonality).
A17: Adj EBITDA - Q1-26 / Q2-26 | B17: 207 | C17: 311.3 | G17: Q2-26 margin 26.4%, +130bps y/y. 1H26 $517.8M.
A18: OCF / FCF - FY25 | B18: 1284 | C18: 1252 | G18: FY25 capex only $32M (0.8% of revenue); FCF = 99% of adj EBITDA.
A19: OCF / FCF / capex - 1H26 | B19: 620.9 | C19: 581.6 | D19: 39.3 | G19: 10-Q 4-Aug-26. Capex run-rate ~1.8% of revenue on AI infrastructure.
A21: SBC TRAJECTORY ($mm, cash-flow-statement basis)
A22: FY22 / FY23 / FY24 | B22: 497 | C22: 648 | D22: 766 | G22: 10-K filings (via Macrotrends). 17.7% / 21.2% / 21.0% of revenue.
A23: FY25 (estimated) | B23: 870 | G23: Estimate: 1H25 reported $414.7M; ~21% of revenue + ~$33M equity-award payroll tax. True up from FY25 10-K.
A24: Q1-26 / Q2-26 | B24: 231.5 | C24: 324.5 | G24: 10-Q. Q2 +43% y/y = 27.5% of revenue; guided as the 2026 peak quarter. Unrecognized SBC $1,443.8M.
A26: BALANCE SHEET, 30-JUN-26 ($mm)
A27: Cash / marketable securities | B27: 422.5 | C27: 852.4 | G27: 10-Q. Total $1,274.9M. Undrawn $500M revolver.
A28: Convertible notes (face / carrying) | B28: 1000 | C28: 981.1 | G28: 1.75% due 1-Mar-2031; issued 5-Mar-26 to Elliott (related party). Conversion $22.72 (44.006M shares); capped calls to $30.59.
A29: AR / AP / accrued | B29: 932 | C29: 145.1 | D29: 464.7 | G29: Net working capital ~$322M = ~7% of revenue - basis for the negative WC capture in Assumptions.
A30: Deferred tax assets | B30: 1616.4 | G30: NOL/DTA shelter keeps cash taxes near zero for now; model ramps to 21% by 2029 regardless (house rule).
A31: Goodwill / intangibles | B31: 475.3 | C31: 83 | G31: Jump from Dec-25 reflects tvScientific ($465.1M, closed Q1-26).
A33: SHARES & BUYBACK
A34: Shares outstanding 30-Jun-26 (mm) | B34: 565.5 | G34: 490.7M Class A + 74.8M Class B (20 votes/sh). Down from 664.5M at 31-Dec-25: ~15% retired in six months.
A35: Diluted weighted Q2-26 (mm) | B35: 577.6 | G35: 562.9M basic + 14.7M dilutive securities (release table) - the valuation share count.
A36: 1H26 repurchases ($mm / avg price) | B36: 2024.9 | C36: 18.17 | G36: About 111M shares retired. Nov-24 program canceled ($499.9M unused); March-26 program $3.5B authorized, roughly $1.9-2.0B remaining (approximate).
A38: CURRENT GUIDANCE
A39: Q3-26 revenue ($mm, low / high) | B39: 1190 | C39: 1210 | G39: Guided 4-Aug-26: +13-15% y/y incl. FX headwind and ~1.5pt one-off drag (Prime Day shift, World Cup lapping).
A40: Q3-26 adj EBITDA ($mm, low / high) | B40: 335 | C40: 355 | G40: Q3 cost of revenue guided roughly flat sequentially on the AWS agreement.
A41: FY26 adj EBITDA margin (guide) | B41: 0.3 | G41: Raised from 29% on 4-Aug-26. Long-term Investor-Day range 30-34% reiterated as the frame for 2027+.

Sheet Assumptions
A1: PINS - Global Assumptions & Scenario Parameters
A2: Blue = hardcoded input. Yellow = key levers. All $ in millions unless stated.
A4: Global inputs
A5: WACC / discount rate | B5: 0.105
A6: D&A (% of revenue) | B6: 0.01
A7: Capex + capitalized software (% of revenue) | B7: 0.018
A8: Working-capital capture (% of YoY revenue incr.) | B8: -0.07 | H8: Sign/size per business model
A9: Net cash ($mm) | B9: 274.9 | H9: cash + marketable securities $1,274.9M (30-Jun-26 10-Q) LESS $1,000M face 1.75% converts due 2031 (Elliott); deviation from cash-only default documented in Model_Info
A10: Fully diluted shares (mm) | B10: 577.6 | H10: Q2-26 diluted weighted-avg: 562.9M basic + 14.7M dilutive (4-Aug-26 release); convert's 44.0M underlying shares excluded - notes carried as debt in net cash
A11: Current share price | B11: 23.33 | H11: regular close ~6-Aug-26 (aggregator quotes; 4-Aug post-print close $25.58, AH $23.22) - refresh with a live quote at next use
A12: Terminal value cap (x terminal-year owner FCF) | B12: 20
A14: Scenario parameters | C14: Bear | D14: Base | E14: Bull
A15: Terminal growth rate | C15: 0.015 | D15: 0.03 | E15: 0.035
A16: Probability weight | C16: 0.15 | D16: 0.5 | E16: 0.35 | F16: =SUM(C16:E16) -> 1 | G16: must sum to 100%
A18: Scenario narratives
A19: Bear | B19: Assistant-led shopping and AI Overviews erode discovery top-of-funnel; UCAN ARPU gains stall after the easy Performance+ harvest; Europe stagnant post cross-border-retailer crackdown. Revenue fades to ~2% (2030 ~$6.3B); adj EBITDA stuck ~28%; SBC sticky at 20-22% of revenue (AI talent war); converts stay debt.
A20: Base | B20: Clicks-to-revenue gap partially closes via Performance+ and advertiser measurement integrations. Revenue ~16% FY26 fading to ~7.5% by 2030 (~$7.2B); adj EBITDA to 32% (low end of the 30-34% Investor-Day range); SBC declines only to ~15% of revenue by 2030-31 (deliberate half-credit on comp discipline, per 8-Aug-26 checkpoint); cash tax ramps to 21% by 2029.
A21: Bull | B21: UCAN ARPU compounds mid-teens for longer as the Meta monetization gap closes; Pinterest Assistant, Performance+ defaults and tvScientific/CTV open incremental budgets; international re-accelerates in 2027. Revenue ~$8.3B by 2030; adj EBITDA to 35%; SBC disciplined to ~11-12%.

Sheet DCF_Bear
A1: PINS DCF - Bear - AI erosion reaches the KPIs; ARPU harvest stalls
A2: Owner-FCF basis: SBC fully expensed, interest income excluded, share count flat. Blue rows = per-year drivers (edit).
B3: 2025A | C3: 2026E | D3: 2027E | E3: 2028E | F3: 2029E | G3: 2030E | H3: 2031E | I3: 2032E | J3: 2033E | K3: 2034E | L3: 2035E
A4: Year index (for discounting) | B4: 0 | C4: 1 | D4: 2 | E4: 3 | F4: 4 | G4: 5 | H4: 6 | I4: 7 | J4: 8 | K4: 9 | L4: 10
A5: Revenue growth YoY | C5: 0.14 | D5: 0.1 | E5: 0.08 | F5: 0.06 | G5: 0.04 | H5: 0.03 | I5: 0.025 | J5: 0.02 | K5: 0.02 | L5: 0.015
A6: Revenue | B6: 4222 | C6: =B6*(1+C5) -> 4813.08 | D6: =C6*(1+D5) -> 5294.388 | E6: =D6*(1+E5) -> 5717.939 | F6: =E6*(1+F5) -> 6061.0154 | G6: =F6*(1+G5) -> 6303.456 | H6: =G6*(1+H5) -> 6492.5597 | I6: =H6*(1+I5) -> 6654.8737 | J6: =I6*(1+J5) -> 6787.9711 | ... L6: =K6*(1+L5) -> 7027.5865
A7: Adj EBITDA margin | B7: 0.3008 | C7: 0.29 | D7: 0.285 | E7: 0.28 | F7: 0.28 | G7: 0.28 | H7: 0.28 | I7: 0.28 | J7: 0.28 | K7: 0.28 | L7: 0.28
A8: Adjusted EBITDA | C8: =C6*C7 -> 1395.7932 | D8: =D6*D7 -> 1508.9006 | E8: =E6*E7 -> 1601.0229 | F8: =F6*F7 -> 1697.0843 | G8: =G6*G7 -> 1764.9677 | H8: =H6*H7 -> 1817.9167 | I8: =I6*I7 -> 1863.3646 | J8: =J6*J7 -> 1900.6319 | ... L8: =L6*L7 -> 1967.7242
A9: SBC (% of revenue) | B9: 0.214 | C9: 0.235 | D9: 0.225 | E9: 0.22 | F9: 0.215 | G9: 0.21 | H9: 0.21 | I9: 0.205 | J9: 0.205 | K9: 0.205 | L9: 0.205
A10: SBC (incl. equity-award taxes) | C10: =-C6*C9 -> -1131.0738 | D10: =-D6*D9 -> -1191.2373 | E10: =-E6*E9 -> -1257.9466 | F10: =-F6*F9 -> -1303.1183 | G10: =-G6*G9 -> -1323.7258 | H10: =-H6*H9 -> -1363.4375 | I10: =-I6*I9 -> -1364.2491 | J10: =-J6*J9 -> -1391.5341 | ... L10: =-L6*L9 -> -1440.6552
A11: EBITDA less SBC ('owner EBITDA') | C11: =C8+C10 -> 264.7194 | D11: =D8+D10 -> 317.66328 | E11: =E8+E10 -> 343.07634 | F11: =F8+F10 -> 393.966 | G11: =G8+G10 -> 441.24192 | H11: =H8+H10 -> 454.47918 | I11: =I8+I10 -> 499.11553 | J11: =J8+J10 -> 509.09784 | ... L11: =L8+L10 -> 527.06899
A12: D&A | C12: =-C6*Assumptions!$B$6 -> -48.1308 | D12: =-D6*Assumptions!$B$6 -> -52.94388 | E12: =-E6*Assumptions!$B$6 -> -57.17939 | F12: =-F6*Assumptions!$B$6 -> -60.610154 | G12: =-G6*Assumptions!$B$6 -> -63.03456 | H12: =-H6*Assumptions!$B$6 -> -64.925597 | I12: =-I6*Assumptions!$B$6 -> -66.548737 | J12: =-J6*Assumptions!$B$6 -> -67.879711 | ... L12: =-L6*Assumptions!$B$6 -> -70.275865
A13: EBIT (SBC expensed) | C13: =C11+C12 -> 216.5886 | D13: =D11+D12 -> 264.7194 | E13: =E11+E12 -> 285.89695 | F13: =F11+F12 -> 333.35585 | G13: =G11+G12 -> 378.20736 | H13: =H11+H12 -> 389.55358 | I13: =I11+I12 -> 432.56679 | J13: =J11+J12 -> 441.21812 | ... L13: =L11+L12 -> 456.79312
A14: Cash tax rate (neg = benefit) | C14: 0.02 | D14: 0.08 | E14: 0.14 | F14: 0.21 | G14: 0.21 | H14: 0.21 | I14: 0.21 | J14: 0.21 | K14: 0.21 | L14: 0.21
A15: NOPAT | C15: =C13*(1-C14) -> 212.25683 | D15: =D13*(1-D14) -> 243.54185 | E15: =E13*(1-E14) -> 245.87138 | F15: =F13*(1-F14) -> 263.35112 | G15: =G13*(1-G14) -> 298.78381 | H15: =H13*(1-H14) -> 307.74733 | I15: =I13*(1-I14) -> 341.72776 | J15: =J13*(1-J14) -> 348.56232 | ... L15: =L13*(1-L14) -> 360.86657
A16: add: D&A | C16: =-C12 -> 48.1308 | D16: =-D12 -> 52.94388 | E16: =-E12 -> 57.17939 | F16: =-F12 -> 60.610154 | G16: =-G12 -> 63.03456 | H16: =-H12 -> 64.925597 | I16: =-I12 -> 66.548737 | J16: =-J12 -> 67.879711 | ... L16: =-L12 -> 70.275865
A17: less: capex + capitalized software | C17: =-C6*Assumptions!$B$7 -> -86.63544 | D17: =-D6*Assumptions!$B$7 -> -95.298984 | E17: =-E6*Assumptions!$B$7 -> -102.9229 | F17: =-F6*Assumptions!$B$7 -> -109.09828 | G17: =-G6*Assumptions!$B$7 -> -113.46221 | H17: =-H6*Assumptions!$B$7 -> -116.86607 | I17: =-I6*Assumptions!$B$7 -> -119.78773 | J17: =-J6*Assumptions!$B$7 -> -122.18348 | ... L17: =-L6*Assumptions!$B$7 -> -126.49656
A18: add: working capital | C18: =Assumptions!$B$8*(C6-B6) -> -41.3756 | D18: =Assumptions!$B$8*(D6-C6) -> -33.69156 | E18: =Assumptions!$B$8*(E6-D6) -> -29.648573 | F18: =Assumptions!$B$8*(F6-E6) -> -24.015344 | G18: =Assumptions!$B$8*(G6-F6) -> -16.970843 | H18: =Assumptions!$B$8*(H6-G6) -> -13.237258 | I18: =Assumptions!$B$8*(I6-H6) -> -11.361979 | J18: =Assumptions!$B$8*(J6-I6) -> -9.3168231 | ... L18: =Assumptions!$B$8*(L6-K6) -> -7.2699171
A19: Unlevered owner FCF | C19: =C15+C16+C17+C18 -> 132.37659 | D19: =D15+D16+D17+D18 -> 167.49518 | E19: =E15+E16+E17+E18 -> 170.47929 | F19: =F15+F16+F17+F18 -> 190.84765 | G19: =G15+G16+G17+G18 -> 231.38532 | H19: =H15+H16+H17+H18 -> 242.56959 | I19: =I15+I16+I17+I18 -> 277.12679 | J19: =J15+J16+J17+J18 -> 284.94173 | ... L19: =L15+L16+L17+L18 -> 297.37596
A20: Discount factor | C20: =1/(1+Assumptions!$B$5)^C4 -> 0.90497738 | D20: =1/(1+Assumptions!$B$5)^D4 -> 0.81898405 | E20: =1/(1+Assumptions!$B$5)^E4 -> 0.74116204 | F20: =1/(1+Assumptions!$B$5)^F4 -> 0.67073487 | G20: =1/(1+Assumptions!$B$5)^G4 -> 0.60699989 | H20: =1/(1+Assumptions!$B$5)^H4 -> 0.54932116 | I20: =1/(1+Assumptions!$B$5)^I4 -> 0.49712323 | J20: =1/(1+Assumptions!$B$5)^J4 -> 0.44988527 | ... L20: =1/(1+Assumptions!$B$5)^L4 -> 0.36844886
A21: PV of FCF | C21: =C19*C20 -> 119.79782 | D21: =D19*D20 -> 137.17588 | E21: =E19*E20 -> 126.35278 | F21: =F19*F20 -> 128.00818 | G21: =G19*G20 -> 140.45086 | H21: =H19*H20 -> 133.24861 | I21: =I19*I20 -> 137.76617 | J21: =J19*J20 -> 128.19109 | ... L21: =L19*L20 -> 109.56783
A23: Memo: FCF before SBC (company-style) | C23: =C19-C10 -> 1263.4504 | D23: =D19-D10 -> 1358.7325 | E23: =E19-E10 -> 1428.4259 | F23: =F19-F10 -> 1493.966 | G23: =G19-G10 -> 1555.1111 | H23: =H19-H10 -> 1606.0071 | I23: =I19-I10 -> 1641.3759 | J23: =J19-J10 -> 1676.4758 | ... L23: =L19-L10 -> 1738.0312
A24: Memo: implied owner FCF margin | C24: =C19/C6 -> 0.027503509 | D24: =D19/D6 -> 0.031636364 | E24: =E19/E6 -> 0.029814815 | F24: =F19/F6 -> 0.031487736 | G24: =G19/G6 -> 0.036707692 | H24: =H19/H6 -> 0.037361165 | I24: =I19/I6 -> 0.041642683 | J24: =J19/J6 -> 0.041977451 | ... L24: =L19/L6 -> 0.042315517
A25: Valuation
A26: PV of FCF, explicit years | B26: =SUM(C21:L21) -> 1278.8895
A27: Terminal growth rate | B27: =Assumptions!$C$15 -> 0.015
A28: Terminal-year owner FCF x (1+g) | B28: =L19*(1+B27) -> 301.8366
A29: Terminal value - Gordon | B29: =B28/(Assumptions!$B$5-B27) -> 3353.74
A30: Terminal value - cap | B30: =Assumptions!$B$12*L19 -> 5947.5192
A31: Terminal value used (lower of the two) | B31: =MIN(B29,B30) -> 3353.74
A32: Implied exit multiple | B32: =B31/L19 -> 11.277778
A33: PV of terminal value | B33: =B31*L20 -> 1235.6817
A34: Enterprise value | B34: =B26+B33 -> 2514.5711
A35: add: net cash | B35: =Assumptions!$B$9 -> 274.9
A36: Equity value | B36: =B34+B35 -> 2789.4711
A37: Fully diluted shares (mm) | B37: =Assumptions!$B$10 -> 577.6
A38: Value per share | B38: =B36/B37 -> 4.8294168
A39: Upside / (downside) vs current price | B39: =B38/Assumptions!$B$11-1 -> -0.79299542
A41: Memo: value if SBC treated as non-cash | B41: =SUMPRODUCT(-C10:L10/(1+Assumptions!$B$5)^C4:L4) -> 7770.969
A42: plus PV of terminal SBC | B42: =(-L10*(1+B27)/(Assumptions!$B$5-B27))*L20 -> 5986.3322
...

Sheet DCF_Base
A1: PINS DCF - Base - monetization gap partially closes; graceful fade
A2: Owner-FCF basis: SBC fully expensed, interest income excluded, share count flat. Blue rows = per-year drivers (edit).
B3: 2025A | C3: 2026E | D3: 2027E | E3: 2028E | F3: 2029E | G3: 2030E | H3: 2031E | I3: 2032E | J3: 2033E | K3: 2034E | L3: 2035E
A4: Year index (for discounting) | B4: 0 | C4: 1 | D4: 2 | E4: 3 | F4: 4 | G4: 5 | H4: 6 | I4: 7 | J4: 8 | K4: 9 | L4: 10
A5: Revenue growth YoY | C5: 0.16 | D5: 0.13 | E5: 0.11 | F5: 0.09 | G5: 0.075 | H5: 0.065 | I5: 0.055 | J5: 0.05 | K5: 0.045 | L5: 0.04
A6: Revenue | B6: 4222 | C6: =B6*(1+C5) -> 4897.52 | D6: =C6*(1+D5) -> 5534.1976 | E6: =D6*(1+E5) -> 6142.9593 | F6: =E6*(1+F5) -> 6695.8257 | G6: =F6*(1+G5) -> 7198.0126 | H6: =G6*(1+H5) -> 7665.8834 | I6: =H6*(1+I5) -> 8087.507 | J6: =I6*(1+J5) -> 8491.8824 | ... L6: =K6*(1+L5) -> 9228.9777
A7: Adj EBITDA margin | B7: 0.3008 | C7: 0.3 | D7: 0.305 | E7: 0.31 | F7: 0.315 | G7: 0.32 | H7: 0.32 | I7: 0.32 | J7: 0.32 | K7: 0.32 | L7: 0.32
A8: Adjusted EBITDA | C8: =C6*C7 -> 1469.256 | D8: =D6*D7 -> 1687.9303 | E8: =E6*E7 -> 1904.3174 | F8: =F6*F7 -> 2109.1851 | G8: =G6*G7 -> 2303.364 | H8: =H6*H7 -> 2453.0827 | I8: =I6*I7 -> 2588.0022 | J8: =J6*J7 -> 2717.4024 | ... L8: =L6*L7 -> 2953.2729
A9: SBC (% of revenue) | B9: 0.214 | C9: 0.235 | D9: 0.21 | E9: 0.19 | F9: 0.17 | G9: 0.155 | H9: 0.15 | I9: 0.145 | J9: 0.14 | K9: 0.14 | L9: 0.14
A10: SBC (incl. equity-award taxes) | C10: =-C6*C9 -> -1150.9172 | D10: =-D6*D9 -> -1162.1815 | E10: =-E6*E9 -> -1167.1623 | F10: =-F6*F9 -> -1138.2904 | G10: =-G6*G9 -> -1115.692 | H10: =-H6*H9 -> -1149.8825 | I10: =-I6*I9 -> -1172.6885 | J10: =-J6*J9 -> -1188.8635 | ... L10: =-L6*L9 -> -1292.0569
A11: EBITDA less SBC ('owner EBITDA') | C11: =C8+C10 -> 318.3388 | D11: =D8+D10 -> 525.74877 | E11: =E8+E10 -> 737.15512 | F11: =F8+F10 -> 970.89472 | G11: =G8+G10 -> 1187.6721 | H11: =H8+H10 -> 1303.2002 | I11: =I8+I10 -> 1415.3137 | J11: =J8+J10 -> 1528.5388 | ... L11: =L8+L10 -> 1661.216
A12: D&A | C12: =-C6*Assumptions!$B$6 -> -48.9752 | D12: =-D6*Assumptions!$B$6 -> -55.341976 | E12: =-E6*Assumptions!$B$6 -> -61.429593 | F12: =-F6*Assumptions!$B$6 -> -66.958257 | G12: =-G6*Assumptions!$B$6 -> -71.980126 | H12: =-H6*Assumptions!$B$6 -> -76.658834 | I12: =-I6*Assumptions!$B$6 -> -80.87507 | J12: =-J6*Assumptions!$B$6 -> -84.918824 | ... L12: =-L6*Assumptions!$B$6 -> -92.289777
A13: EBIT (SBC expensed) | C13: =C11+C12 -> 269.3636 | D13: =D11+D12 -> 470.4068 | E13: =E11+E12 -> 675.72553 | F13: =F11+F12 -> 903.93647 | G13: =G11+G12 -> 1115.692 | H13: =H11+H12 -> 1226.5413 | I13: =I11+I12 -> 1334.4387 | J13: =J11+J12 -> 1443.62 | ... L13: =L11+L12 -> 1568.9262
A14: Cash tax rate (neg = benefit) | C14: 0.02 | D14: 0.08 | E14: 0.14 | F14: 0.21 | G14: 0.21 | H14: 0.21 | I14: 0.21 | J14: 0.21 | K14: 0.21 | L14: 0.21
A15: NOPAT | C15: =C13*(1-C14) -> 263.97633 | D15: =D13*(1-D14) -> 432.77425 | E15: =E13*(1-E14) -> 581.12395 | F15: =F13*(1-F14) -> 714.10981 | G15: =G13*(1-G14) -> 881.39664 | H15: =H13*(1-H14) -> 968.96766 | I15: =I13*(1-I14) -> 1054.2065 | J15: =J13*(1-J14) -> 1140.4598 | ... L15: =L13*(1-L14) -> 1239.4517
A16: add: D&A | C16: =-C12 -> 48.9752 | D16: =-D12 -> 55.341976 | E16: =-E12 -> 61.429593 | F16: =-F12 -> 66.958257 | G16: =-G12 -> 71.980126 | H16: =-H12 -> 76.658834 | I16: =-I12 -> 80.87507 | J16: =-J12 -> 84.918824 | ... L16: =-L12 -> 92.289777
A17: less: capex + capitalized software | C17: =-C6*Assumptions!$B$7 -> -88.15536 | D17: =-D6*Assumptions!$B$7 -> -99.615557 | E17: =-E6*Assumptions!$B$7 -> -110.57327 | F17: =-F6*Assumptions!$B$7 -> -120.52486 | G17: =-G6*Assumptions!$B$7 -> -129.56423 | H17: =-H6*Assumptions!$B$7 -> -137.9859 | I17: =-I6*Assumptions!$B$7 -> -145.57513 | J17: =-J6*Assumptions!$B$7 -> -152.85388 | ... L17: =-L6*Assumptions!$B$7 -> -166.1216
A18: add: working capital | C18: =Assumptions!$B$8*(C6-B6) -> -47.2864 | D18: =Assumptions!$B$8*(D6-C6) -> -44.567432 | E18: =Assumptions!$B$8*(E6-D6) -> -42.613322 | F18: =Assumptions!$B$8*(F6-E6) -> -38.700644 | G18: =Assumptions!$B$8*(G6-F6) -> -35.153085 | H18: =Assumptions!$B$8*(H6-G6) -> -32.750957 | I18: =Assumptions!$B$8*(I6-H6) -> -29.513651 | J18: =Assumptions!$B$8*(J6-I6) -> -28.306275 | ... L18: =Assumptions!$B$8*(L6-K6) -> -24.847248
A19: Unlevered owner FCF | C19: =C15+C16+C17+C18 -> 177.50977 | D19: =D15+D16+D17+D18 -> 343.93324 | E19: =E15+E16+E17+E18 -> 489.36696 | F19: =F15+F16+F17+F18 -> 621.84256 | G19: =G15+G16+G17+G18 -> 788.65946 | H19: =H15+H16+H17+H18 -> 874.88964 | I19: =I15+I16+I17+I18 -> 959.99283 | J19: =J15+J16+J17+J18 -> 1044.2185 | ... L19: =L15+L16+L17+L18 -> 1140.7726
A20: Discount factor | C20: =1/(1+Assumptions!$B$5)^C4 -> 0.90497738 | D20: =1/(1+Assumptions!$B$5)^D4 -> 0.81898405 | E20: =1/(1+Assumptions!$B$5)^E4 -> 0.74116204 | F20: =1/(1+Assumptions!$B$5)^F4 -> 0.67073487 | G20: =1/(1+Assumptions!$B$5)^G4 -> 0.60699989 | H20: =1/(1+Assumptions!$B$5)^H4 -> 0.54932116 | I20: =1/(1+Assumptions!$B$5)^I4 -> 0.49712323 | J20: =1/(1+Assumptions!$B$5)^J4 -> 0.44988527 | ... L20: =1/(1+Assumptions!$B$5)^L4 -> 0.36844886
A21: PV of FCF | C21: =C19*C20 -> 160.64232 | D21: =D19*D20 -> 281.67584 | E21: =E19*E20 -> 362.70021 | F21: =F19*F20 -> 417.09149 | G21: =G19*G20 -> 478.7162 | H21: =H19*H20 -> 480.5954 | I21: =I19*I20 -> 477.23473 | J21: =J19*J20 -> 469.77851 | ... L21: =L19*L20 -> 420.31638
A23: Memo: FCF before SBC (company-style) | C23: =C19-C10 -> 1328.427 | D23: =D19-D10 -> 1506.1147 | E23: =E19-E10 -> 1656.5292 | F23: =F19-F10 -> 1760.1329 | G23: =G19-G10 -> 1904.3514 | H23: =H19-H10 -> 2024.7722 | I23: =I19-I10 -> 2132.6813 | J23: =J19-J10 -> 2233.082 | ... L23: =L19-L10 -> 2432.8295
A24: Memo: implied owner FCF margin | C24: =C19/C6 -> 0.036244828 | D24: =D19/D6 -> 0.062146903 | E24: =E19/E6 -> 0.079663063 | F24: =F19/F6 -> 0.092870183 | G24: =G19/G6 -> 0.10956628 | H24: =H19/H6 -> 0.1141277 | I24: =I19/I6 -> 0.11870071 | J24: =J19/J6 -> 0.12296667 | ... L24: =L19/L6 -> 0.12360769
A25: Valuation
A26: PV of FCF, explicit years | B26: =SUM(C21:L21) -> 3994.1737
A27: Terminal growth rate | B27: =Assumptions!$D$15 -> 0.03
A28: Terminal-year owner FCF x (1+g) | B28: =L19*(1+B27) -> 1174.9958
A29: Terminal value - Gordon | B29: =B28/(Assumptions!$B$5-B27) -> 15666.611
A30: Terminal value - cap | B30: =Assumptions!$B$12*L19 -> 22815.453
A31: Terminal value used (lower of the two) | B31: =MIN(B29,B30) -> 15666.611
A32: Implied exit multiple | B32: =B31/L19 -> 13.733333
A33: PV of terminal value | B33: =B31*L20 -> 5772.345
A34: Enterprise value | B34: =B26+B33 -> 9766.5187
A35: add: net cash | B35: =Assumptions!$B$9 -> 274.9
A36: Equity value | B36: =B34+B35 -> 10041.419
A37: Fully diluted shares (mm) | B37: =Assumptions!$B$10 -> 577.6
A38: Value per share | B38: =B36/B37 -> 17.384728
A39: Upside / (downside) vs current price | B39: =B38/Assumptions!$B$11-1 -> -0.25483379
A41: Memo: value if SBC treated as non-cash | B41: =SUMPRODUCT(-C10:L10/(1+Assumptions!$B$5)^C4:L4) -> 7030.4795
A42: plus PV of terminal SBC | B42: =(-L10*(1+B27)/(Assumptions!$B$5-B27))*L20 -> 6537.8479
...

Sheet DCF_Bull
A1: PINS DCF - Bull - Meta-gap closure runs; Assistant + CTV open budgets
A2: Owner-FCF basis: SBC fully expensed, interest income excluded, share count flat. Blue rows = per-year drivers (edit).
B3: 2025A | C3: 2026E | D3: 2027E | E3: 2028E | F3: 2029E | G3: 2030E | H3: 2031E | I3: 2032E | J3: 2033E | K3: 2034E | L3: 2035E
A4: Year index (for discounting) | B4: 0 | C4: 1 | D4: 2 | E4: 3 | F4: 4 | G4: 5 | H4: 6 | I4: 7 | J4: 8 | K4: 9 | L4: 10
A5: Revenue growth YoY | C5: 0.175 | D5: 0.16 | E5: 0.15 | F5: 0.13 | G5: 0.11 | H5: 0.1 | I5: 0.09 | J5: 0.08 | K5: 0.07 | L5: 0.06
A6: Revenue | B6: 4222 | C6: =B6*(1+C5) -> 4960.85 | D6: =C6*(1+D5) -> 5754.586 | E6: =D6*(1+E5) -> 6617.7739 | F6: =E6*(1+F5) -> 7478.0845 | G6: =F6*(1+G5) -> 8300.6738 | H6: =G6*(1+H5) -> 9130.7412 | I6: =H6*(1+I5) -> 9952.5079 | J6: =I6*(1+J5) -> 10748.709 | ... L6: =K6*(1+L5) -> 12191.185
A7: Adj EBITDA margin | B7: 0.3008 | C7: 0.305 | D7: 0.315 | E7: 0.325 | F7: 0.335 | G7: 0.345 | H7: 0.35 | I7: 0.35 | J7: 0.35 | K7: 0.35 | L7: 0.35
A8: Adjusted EBITDA | C8: =C6*C7 -> 1513.0593 | D8: =D6*D7 -> 1812.6946 | E8: =E6*E7 -> 2150.7765 | F8: =F6*F7 -> 2505.1583 | G8: =G6*G7 -> 2863.7325 | H8: =H6*H7 -> 3195.7594 | I8: =I6*I7 -> 3483.3778 | J8: =J6*J7 -> 3762.048 | ... L8: =L6*L7 -> 4266.9148
A9: SBC (% of revenue) | B9: 0.214 | C9: 0.23 | D9: 0.195 | E9: 0.17 | F9: 0.145 | G9: 0.125 | H9: 0.115 | I9: 0.11 | J9: 0.11 | K9: 0.11 | L9: 0.11
A10: SBC (incl. equity-award taxes) | C10: =-C6*C9 -> -1140.9955 | D10: =-D6*D9 -> -1122.1443 | E10: =-E6*E9 -> -1125.0216 | F10: =-F6*F9 -> -1084.3223 | G10: =-G6*G9 -> -1037.5842 | H10: =-H6*H9 -> -1050.0352 | I10: =-I6*I9 -> -1094.7759 | J10: =-J6*J9 -> -1182.3579 | ... L10: =-L6*L9 -> -1341.0304
A11: EBITDA less SBC ('owner EBITDA') | C11: =C8+C10 -> 372.06375 | D11: =D8+D10 -> 690.55032 | E11: =E8+E10 -> 1025.755 | F11: =F8+F10 -> 1420.8361 | G11: =G8+G10 -> 1826.1482 | H11: =H8+H10 -> 2145.7242 | I11: =I8+I10 -> 2388.6019 | J11: =J8+J10 -> 2579.69 | ... L11: =L8+L10 -> 2925.8844
A12: D&A | C12: =-C6*Assumptions!$B$6 -> -49.6085 | D12: =-D6*Assumptions!$B$6 -> -57.54586 | E12: =-E6*Assumptions!$B$6 -> -66.177739 | F12: =-F6*Assumptions!$B$6 -> -74.780845 | G12: =-G6*Assumptions!$B$6 -> -83.006738 | H12: =-H6*Assumptions!$B$6 -> -91.307412 | I12: =-I6*Assumptions!$B$6 -> -99.525079 | J12: =-J6*Assumptions!$B$6 -> -107.48709 | ... L12: =-L6*Assumptions!$B$6 -> -121.91185
A13: EBIT (SBC expensed) | C13: =C11+C12 -> 322.45525 | D13: =D11+D12 -> 633.00446 | E13: =E11+E12 -> 959.57722 | F13: =F11+F12 -> 1346.0552 | G13: =G11+G12 -> 1743.1415 | H13: =H11+H12 -> 2054.4168 | I13: =I11+I12 -> 2289.0768 | J13: =J11+J12 -> 2472.203 | ... L13: =L11+L12 -> 2803.9726
A14: Cash tax rate (neg = benefit) | C14: 0.02 | D14: 0.08 | E14: 0.14 | F14: 0.21 | G14: 0.21 | H14: 0.21 | I14: 0.21 | J14: 0.21 | K14: 0.21 | L14: 0.21
A15: NOPAT | C15: =C13*(1-C14) -> 316.00615 | D15: =D13*(1-D14) -> 582.3641 | E15: =E13*(1-E14) -> 825.23641 | F15: =F13*(1-F14) -> 1063.3836 | G15: =G13*(1-G14) -> 1377.0818 | H15: =H13*(1-H14) -> 1622.9892 | I15: =I13*(1-I14) -> 1808.3707 | J15: =J13*(1-J14) -> 1953.0403 | ... L15: =L13*(1-L14) -> 2215.1384
A16: add: D&A | C16: =-C12 -> 49.6085 | D16: =-D12 -> 57.54586 | E16: =-E12 -> 66.177739 | F16: =-F12 -> 74.780845 | G16: =-G12 -> 83.006738 | H16: =-H12 -> 91.307412 | I16: =-I12 -> 99.525079 | J16: =-J12 -> 107.48709 | ... L16: =-L12 -> 121.91185
A17: less: capex + capitalized software | C17: =-C6*Assumptions!$B$7 -> -89.2953 | D17: =-D6*Assumptions!$B$7 -> -103.58255 | E17: =-E6*Assumptions!$B$7 -> -119.11993 | F17: =-F6*Assumptions!$B$7 -> -134.60552 | G17: =-G6*Assumptions!$B$7 -> -149.41213 | H17: =-H6*Assumptions!$B$7 -> -164.35334 | I17: =-I6*Assumptions!$B$7 -> -179.14514 | J17: =-J6*Assumptions!$B$7 -> -193.47675 | ... L17: =-L6*Assumptions!$B$7 -> -219.44133
A18: add: working capital | C18: =Assumptions!$B$8*(C6-B6) -> -51.7195 | D18: =Assumptions!$B$8*(D6-C6) -> -55.56152 | E18: =Assumptions!$B$8*(E6-D6) -> -60.423153 | F18: =Assumptions!$B$8*(F6-E6) -> -60.221742 | G18: =Assumptions!$B$8*(G6-F6) -> -57.581251 | H18: =Assumptions!$B$8*(H6-G6) -> -58.104717 | I18: =Assumptions!$B$8*(I6-H6) -> -57.523669 | J18: =Assumptions!$B$8*(J6-I6) -> -55.734044 | ... L18: =Assumptions!$B$8*(L6-K6) -> -48.304696
A19: Unlevered owner FCF | C19: =C15+C16+C17+C18 -> 224.59984 | D19: =D15+D16+D17+D18 -> 480.7659 | E19: =E15+E16+E17+E18 -> 711.87106 | F19: =F15+F16+F17+F18 -> 943.3372 | G19: =G15+G16+G17+G18 -> 1253.0951 | H19: =H15+H16+H17+H18 -> 1491.8386 | I19: =I15+I16+I17+I18 -> 1671.227 | J19: =J15+J16+J17+J18 -> 1811.3166 | ... L19: =L15+L16+L17+L18 -> 2069.3042
A20: Discount factor | C20: =1/(1+Assumptions!$B$5)^C4 -> 0.90497738 | D20: =1/(1+Assumptions!$B$5)^D4 -> 0.81898405 | E20: =1/(1+Assumptions!$B$5)^E4 -> 0.74116204 | F20: =1/(1+Assumptions!$B$5)^F4 -> 0.67073487 | G20: =1/(1+Assumptions!$B$5)^G4 -> 0.60699989 | H20: =1/(1+Assumptions!$B$5)^H4 -> 0.54932116 | I20: =1/(1+Assumptions!$B$5)^I4 -> 0.49712323 | J20: =1/(1+Assumptions!$B$5)^J4 -> 0.44988527 | ... L20: =1/(1+Assumptions!$B$5)^L4 -> 0.36844886
A21: PV of FCF | C21: =C19*C20 -> 203.25778 | D21: =D19*D20 -> 393.7396 | E21: =E19*E20 -> 527.61181 | F21: =F19*F20 -> 632.72916 | G21: =G19*G20 -> 760.62861 | H21: =H19*H20 -> 819.49852 | I21: =I19*I20 -> 830.80573 | J21: =J19*J20 -> 814.88467 | ... L21: =L19*L20 -> 762.43277
A23: Memo: FCF before SBC (company-style) | C23: =C19-C10 -> 1365.5953 | D23: =D19-D10 -> 1602.9102 | E23: =E19-E10 -> 1836.8926 | F23: =F19-F10 -> 2027.6595 | G23: =G19-G10 -> 2290.6794 | H23: =H19-H10 -> 2541.8738 | I23: =I19-I10 -> 2766.0028 | J23: =J19-J10 -> 2993.6746 | ... L23: =L19-L10 -> 3410.3345
A24: Memo: implied owner FCF margin | C24: =C19/C6 -> 0.045274468 | D24: =D19/D6 -> 0.083544828 | E24: =E19/E6 -> 0.10756957 | F24: =F19/F6 -> 0.1261469 | G24: =G19/G6 -> 0.15096306 | H24: =H19/H6 -> 0.16338636 | I24: =I19/I6 -> 0.16792018 | J24: =J19/J6 -> 0.16851481 | ... L24: =L19/L6 -> 0.16973774
A25: Valuation
A26: PV of FCF, explicit years | B26: =SUM(C21:L21) -> 6537.4989
A27: Terminal growth rate | B27: =Assumptions!$E$15 -> 0.035
A28: Terminal-year owner FCF x (1+g) | B28: =L19*(1+B27) -> 2141.7298
A29: Terminal value - Gordon | B29: =B28/(Assumptions!$B$5-B27) -> 30596.14
A30: Terminal value - cap | B30: =Assumptions!$B$12*L19 -> 41386.083
A31: Terminal value used (lower of the two) | B31: =MIN(B29,B30) -> 30596.14
A32: Implied exit multiple | B32: =B31/L19 -> 14.785714
A33: PV of terminal value | B33: =B31*L20 -> 11273.113
A34: Enterprise value | B34: =B26+B33 -> 17810.612
A35: add: net cash | B35: =Assumptions!$B$9 -> 274.9
A36: Equity value | B36: =B34+B35 -> 18085.512
A37: Fully diluted shares (mm) | B37: =Assumptions!$B$10 -> 577.6
A38: Value per share | B38: =B36/B37 -> 31.311482
A39: Upside / (downside) vs current price | B39: =B38/Assumptions!$B$11-1 -> 0.34211239
A41: Memo: value if SBC treated as non-cash | B41: =SUMPRODUCT(-C10:L10/(1+Assumptions!$B$5)^C4:L4) -> 6804.6716
A42: plus PV of terminal SBC | B42: =(-L10*(1+B27)/(Assumptions!$B$5-B27))*L20 -> 7305.6379
...

Sheet Valuation
A1: PINS - Valuation Summary & Sensitivity
A2: Owner-FCF basis (SBC expensed) unless marked street. Green = links.
B4: Bear | C4: Base | D4: Bull
A5: Value per share | B5: =DCF_Bear!$B$38 -> 4.8294168 | C5: =DCF_Base!$B$38 -> 17.384728 | D5: =DCF_Bull!$B$38 -> 31.311482
A6: Upside / (downside) vs price | B6: =B5/Assumptions!$B$11-1 -> -0.79299542 | C6: =C5/Assumptions!$B$11-1 -> -0.25483379 | D6: =D5/Assumptions!$B$11-1 -> 0.34211239
A7: Probability | B7: =Assumptions!$C$16 -> 0.15 | C7: =Assumptions!$D$16 -> 0.5 | D7: =Assumptions!$E$16 -> 0.35
A8: Value per share, SBC as non-cash (street) | B8: =DCF_Bear!$B$43 -> 28.647459 | C8: =DCF_Base!$B$43 -> 40.875599 | D8: =DCF_Bull!$B$43 -> 55.740688
A10: Probability-weighted value per share | B10: =SUMPRODUCT(B5:D5,B7:D7) -> 20.375795
A11: Current price | B11: =Assumptions!$B$11 -> 23.33
A12: Margin of safety vs weighted value | B12: =1-B11/B10 -> -0.144986
A13: Weighted value, SBC as non-cash (street) | B13: =SUMPRODUCT(B8:D8,B7:D7) -> 44.244159
A14: Band position (0%=house, 100%=street) | B14: =(Assumptions!$B$11-B10)/(B13-B10) -> 0.12377073
A17: Base case - value per share at different required returns
A18: Required return | B18: Value / share
A19: 0.09 | B19: =(SUMPRODUCT(DCF_Base!$C$19:$L$19/(1+$A19)^DCF_Base!$C$4:$L$4)+MIN(DCF_Base!$L$19*(1+Assumptions!$D$15)/($A19-Assumptions!$D$15),Assumptions!$B$12*DCF_Base!$L$19)/(1+$A19)^10+Assumptions!$B$9)/Assumptions!$B$10 -> 22.311075
A20: 0.1 | B20: =(SUMPRODUCT(DCF_Base!$C$19:$L$19/(1+$A20)^DCF_Base!$C$4:$L$4)+MIN(DCF_Base!$L$19*(1+Assumptions!$D$15)/($A20-Assumptions!$D$15),Assumptions!$B$12*DCF_Base!$L$19)/(1+$A20)^10+Assumptions!$B$9)/Assumptions!$B$10 -> 18.787422
A21: 0.105 | B21: =(SUMPRODUCT(DCF_Base!$C$19:$L$19/(1+$A21)^DCF_Base!$C$4:$L$4)+MIN(DCF_Base!$L$19*(1+Assumptions!$D$15)/($A21-Assumptions!$D$15),Assumptions!$B$12*DCF_Base!$L$19)/(1+$A21)^10+Assumptions!$B$9)/Assumptions!$B$10 -> 17.384728
A22: 0.11 | B22: =(SUMPRODUCT(DCF_Base!$C$19:$L$19/(1+$A22)^DCF_Base!$C$4:$L$4)+MIN(DCF_Base!$L$19*(1+Assumptions!$D$15)/($A22-Assumptions!$D$15),Assumptions!$B$12*DCF_Base!$L$19)/(1+$A22)^10+Assumptions!$B$9)/Assumptions!$B$10 -> 16.16142
A23: 0.12 | B23: =(SUMPRODUCT(DCF_Base!$C$19:$L$19/(1+$A23)^DCF_Base!$C$4:$L$4)+MIN(DCF_Base!$L$19*(1+Assumptions!$D$15)/($A23-Assumptions!$D$15),Assumptions!$B$12*DCF_Base!$L$19)/(1+$A23)^10+Assumptions!$B$9)/Assumptions!$B$10 -> 14.132925
A24: 0.15 | B24: =(SUMPRODUCT(DCF_Base!$C$19:$L$19/(1+$A24)^DCF_Base!$C$4:$L$4)+MIN(DCF_Base!$L$19*(1+Assumptions!$D$15)/($A24-Assumptions!$D$15),Assumptions!$B$12*DCF_Base!$L$19)/(1+$A24)^10+Assumptions!$B$9)/Assumptions!$B$10 -> 10.132513
A25: 15%-hurdle entry per scenario + weighted | B25: =(SUMPRODUCT(DCF_Bear!$C$19:$L$19/(1+0.15)^DCF_Bear!$C$4:$L$4)+MIN(DCF_Bear!$L$19*(1+Assumptions!$C$15)/(0.15-Assumptions!$C$15),Assumptions!$B$12*DCF_Bear!$L$19)/(1+0.15)^10+Assumptions!$B$9)/Assumptions!$B$10 -> 3.2269692 | C25: =(SUMPRODUCT(DCF_Base!$C$19:$L$19/(1+0.15)^DCF_Base!$C$4:$L$4)+MIN(DCF_Base!$L$19*(1+Assumptions!$D$15)/(0.15-Assumptions!$D$15),Assumptions!$B$12*DCF_Base!$L$19)/(1+0.15)^10+Assumptions!$B$9)/Assumptions!$B$10 -> 10.132513 | D25: =(SUMPRODUCT(DCF_Bull!$C$19:$L$19/(1+0.15)^DCF_Bull!$C$4:$L$4)+MIN(DCF_Bull!$L$19*(1+Assumptions!$E$15)/(0.15-Assumptions!$E$15),Assumptions!$B$12*DCF_Bull!$L$19)/(1+0.15)^10+Assumptions!$B$9)/Assumptions!$B$10 -> 17.308591 | E25: =SUMPRODUCT(B25:D25,$B$7:$D$7) -> 11.608309 | G25: model buy-below price at a 15% hurdle
A26: same, street basis | B26: =B25+(SUMPRODUCT(-DCF_Bear!$C$10:$L$10/(1+0.15)^DCF_Bear!$C$4:$L$4)+(-DCF_Bear!$L$10*(1+Assumptions!$C$15)/(0.15-Assumptions!$C$15))/(1+0.15)^10)/Assumptions!$B$10 -> 18.997052 | C26: =C25+(SUMPRODUCT(-DCF_Base!$C$10:$L$10/(1+0.15)^DCF_Base!$C$4:$L$4)+(-DCF_Base!$L$10*(1+Assumptions!$D$15)/(0.15-Assumptions!$D$15))/(1+0.15)^10)/Assumptions!$B$10 -> 25.009581 | D26: =D25+(SUMPRODUCT(-DCF_Bull!$C$10:$L$10/(1+0.15)^DCF_Bull!$C$4:$L$4)+(-DCF_Bull!$L$10*(1+Assumptions!$E$15)/(0.15-Assumptions!$E$15))/(1+0.15)^10)/Assumptions!$B$10 -> 32.27173 | E26: =SUMPRODUCT(B26:D26,$B$7:$D$7) -> 26.649454
A28: Base case - value per share: WACC x terminal growth
A29: WACC \ g | B29: 0.02 | C29: 0.025 | D29: 0.03 | E29: 0.035 | F29: 0.04
A30: 0.095 | B30: =IF($A30>B$29,(SUMPRODUCT(DCF_Base!$C$19:$L$19/(1+$A30)^DCF_Base!$C$4:$L$4)+MIN(DCF_Base!$L$19*(1+B$29)/($A30-B$29),Assumptions!$B$12*DCF_Base!$L$19)/(1+$A30)^10+Assumptions!$B$9)/Assumptions!$B$10,"n/a") -> 18.620993 | C30: =IF($A30>C$29,(SUMPRODUCT(DCF_Base!$C$19:$L$19/(1+$A30)^DCF_Base!$C$4:$L$4)+MIN(DCF_Base!$L$19*(1+C$29)/($A30-C$29),Assumptions!$B$12*DCF_Base!$L$19)/(1+$A30)^10+Assumptions!$B$9)/Assumptions!$B$10,"n/a") -> 19.452098 | D30: =IF($A30>D$29,(SUMPRODUCT(DCF_Base!$C$19:$L$19/(1+$A30)^DCF_Base!$C$4:$L$4)+MIN(DCF_Base!$L$19*(1+D$29)/($A30-D$29),Assumptions!$B$12*DCF_Base!$L$19)/(1+$A30)^10+Assumptions!$B$9)/Assumptions!$B$10,"n/a") -> 20.411064 | E30: =IF($A30>E$29,(SUMPRODUCT(DCF_Base!$C$19:$L$19/(1+$A30)^DCF_Base!$C$4:$L$4)+MIN(DCF_Base!$L$19*(1+E$29)/($A30-E$29),Assumptions!$B$12*DCF_Base!$L$19)/(1+$A30)^10+Assumptions!$B$9)/Assumptions!$B$10,"n/a") -> 21.529858 | F30: =IF($A30>F$29,(SUMPRODUCT(DCF_Base!$C$19:$L$19/(1+$A30)^DCF_Base!$C$4:$L$4)+MIN(DCF_Base!$L$19*(1+F$29)/($A30-F$29),Assumptions!$B$12*DCF_Base!$L$19)/(1+$A30)^10+Assumptions!$B$9)/Assumptions!$B$10,"n/a") -> 22.85207
A31: 0.1 | B31: =IF($A31>B$29,(SUMPRODUCT(DCF_Base!$C$19:$L$19/(1+$A31)^DCF_Base!$C$4:$L$4)+MIN(DCF_Base!$L$19*(1+B$29)/($A31-B$29),Assumptions!$B$12*DCF_Base!$L$19)/(1+$A31)^10+Assumptions!$B$9)/Assumptions!$B$10,"n/a") -> 17.291704 | C31: =IF($A31>C$29,(SUMPRODUCT(DCF_Base!$C$19:$L$19/(1+$A31)^DCF_Base!$C$4:$L$4)+MIN(DCF_Base!$L$19*(1+C$29)/($A31-C$29),Assumptions!$B$12*DCF_Base!$L$19)/(1+$A31)^10+Assumptions!$B$9)/Assumptions!$B$10,"n/a") -> 17.989706 | D31: =IF($A31>D$29,(SUMPRODUCT(DCF_Base!$C$19:$L$19/(1+$A31)^DCF_Base!$C$4:$L$4)+MIN(DCF_Base!$L$19*(1+D$29)/($A31-D$29),Assumptions!$B$12*DCF_Base!$L$19)/(1+$A31)^10+Assumptions!$B$9)/Assumptions!$B$10,"n/a") -> 18.787422 | E31: =IF($A31>E$29,(SUMPRODUCT(DCF_Base!$C$19:$L$19/(1+$A31)^DCF_Base!$C$4:$L$4)+MIN(DCF_Base!$L$19*(1+E$29)/($A31-E$29),Assumptions!$B$12*DCF_Base!$L$19)/(1+$A31)^10+Assumptions!$B$9)/Assumptions!$B$10,"n/a") -> 19.707864 | F31: =IF($A31>F$29,(SUMPRODUCT(DCF_Base!$C$19:$L$19/(1+$A31)^DCF_Base!$C$4:$L$4)+MIN(DCF_Base!$L$19*(1+F$29)/($A31-F$29),Assumptions!$B$12*DCF_Base!$L$19)/(1+$A31)^10+Assumptions!$B$9)/Assumptions!$B$10,"n/a") -> 20.781713
A32: 0.105 | B32: =IF($A32>B$29,(SUMPRODUCT(DCF_Base!$C$19:$L$19/(1+$A32)^DCF_Base!$C$4:$L$4)+MIN(DCF_Base!$L$19*(1+B$29)/($A32-B$29),Assumptions!$B$12*DCF_Base!$L$19)/(1+$A32)^10+Assumptions!$B$9)/Assumptions!$B$10,"n/a") -> 16.12339 | C32: =IF($A32>C$29,(SUMPRODUCT(DCF_Base!$C$19:$L$19/(1+$A32)^DCF_Base!$C$4:$L$4)+MIN(DCF_Base!$L$19*(1+C$29)/($A32-C$29),Assumptions!$B$12*DCF_Base!$L$19)/(1+$A32)^10+Assumptions!$B$9)/Assumptions!$B$10,"n/a") -> 16.714642 | D32: =IF($A32>D$29,(SUMPRODUCT(DCF_Base!$C$19:$L$19/(1+$A32)^DCF_Base!$C$4:$L$4)+MIN(DCF_Base!$L$19*(1+D$29)/($A32-D$29),Assumptions!$B$12*DCF_Base!$L$19)/(1+$A32)^10+Assumptions!$B$9)/Assumptions!$B$10,"n/a") -> 17.384728 | E32: =IF($A32>E$29,(SUMPRODUCT(DCF_Base!$C$19:$L$19/(1+$A32)^DCF_Base!$C$4:$L$4)+MIN(DCF_Base!$L$19*(1+E$29)/($A32-E$29),Assumptions!$B$12*DCF_Base!$L$19)/(1+$A32)^10+Assumptions!$B$9)/Assumptions!$B$10,"n/a") -> 18.15054 | F32: =IF($A32>F$29,(SUMPRODUCT(DCF_Base!$C$19:$L$19/(1+$A32)^DCF_Base!$C$4:$L$4)+MIN(DCF_Base!$L$19*(1+F$29)/($A32-F$29),Assumptions!$B$12*DCF_Base!$L$19)/(1+$A32)^10+Assumptions!$B$9)/Assumptions!$B$10,"n/a") -> 19.034169
A33: 0.11 | B33: =IF($A33>B$29,(SUMPRODUCT(DCF_Base!$C$19:$L$19/(1+$A33)^DCF_Base!$C$4:$L$4)+MIN(DCF_Base!$L$19*(1+B$29)/($A33-B$29),Assumptions!$B$12*DCF_Base!$L$19)/(1+$A33)^10+Assumptions!$B$9)/Assumptions!$B$10,"n/a") -> 15.08908 | C33: =IF($A33>C$29,(SUMPRODUCT(DCF_Base!$C$19:$L$19/(1+$A33)^DCF_Base!$C$4:$L$4)+MIN(DCF_Base!$L$19*(1+C$29)/($A33-C$29),Assumptions!$B$12*DCF_Base!$L$19)/(1+$A33)^10+Assumptions!$B$9)/Assumptions!$B$10,"n/a") -> 15.593711 | D33: =IF($A33>D$29,(SUMPRODUCT(DCF_Base!$C$19:$L$19/(1+$A33)^DCF_Base!$C$4:$L$4)+MIN(DCF_Base!$L$19*(1+D$29)/($A33-D$29),Assumptions!$B$12*DCF_Base!$L$19)/(1+$A33)^10+Assumptions!$B$9)/Assumptions!$B$10,"n/a") -> 16.16142 | E33: =IF($A33>E$29,(SUMPRODUCT(DCF_Base!$C$19:$L$19/(1+$A33)^DCF_Base!$C$4:$L$4)+MIN(DCF_Base!$L$19*(1+E$29)/($A33-E$29),Assumptions!$B$12*DCF_Base!$L$19)/(1+$A33)^10+Assumptions!$B$9)/Assumptions!$B$10,"n/a") -> 16.804824 | F33: =IF($A33>F$29,(SUMPRODUCT(DCF_Base!$C$19:$L$19/(1+$A33)^DCF_Base!$C$4:$L$4)+MIN(DCF_Base!$L$19*(1+F$29)/($A33-F$29),Assumptions!$B$12*DCF_Base!$L$19)/(1+$A33)^10+Assumptions!$B$9)/Assumptions!$B$10,"n/a") -> 17.540144
A34: 0.115 | B34: =IF($A34>B$29,(SUMPRODUCT(DCF_Base!$C$19:$L$19/(1+$A34)^DCF_Base!$C$4:$L$4)+MIN(DCF_Base!$L$19*(1+B$29)/($A34-B$29),Assumptions!$B$12*DCF_Base!$L$19)/(1+$A34)^10+Assumptions!$B$9)/Assumptions!$B$10,"n/a") -> 14.167485 | C34: =IF($A34>C$29,(SUMPRODUCT(DCF_Base!$C$19:$L$19/(1+$A34)^DCF_Base!$C$4:$L$4)+MIN(DCF_Base!$L$19*(1+C$29)/($A34-C$29),Assumptions!$B$12*DCF_Base!$L$19)/(1+$A34)^10+Assumptions!$B$9)/Assumptions!$B$10,"n/a") -> 14.601097 | D34: =IF($A34>D$29,(SUMPRODUCT(DCF_Base!$C$19:$L$19/(1+$A34)^DCF_Base!$C$4:$L$4)+MIN(DCF_Base!$L$19*(1+D$29)/($A34-D$29),Assumptions!$B$12*DCF_Base!$L$19)/(1+$A34)^10+Assumptions!$B$9)/Assumptions!$B$10,"n/a") -> 15.085723 | E34: =IF($A34>E$29,(SUMPRODUCT(DCF_Base!$C$19:$L$19/(1+$A34)^DCF_Base!$C$4:$L$4)+MIN(DCF_Base!$L$19*(1+E$29)/($A34-E$29),Assumptions!$B$12*DCF_Base!$L$19)/(1+$A34)^10+Assumptions!$B$9)/Assumptions!$B$10,"n/a") -> 15.630927 | F34: =IF($A34>F$29,(SUMPRODUCT(DCF_Base!$C$19:$L$19/(1+$A34)^DCF_Base!$C$4:$L$4)+MIN(DCF_Base!$L$19*(1+F$29)/($A34-F$29),Assumptions!$B$12*DCF_Base!$L$19)/(1+$A34)^10+Assumptions!$B$9)/Assumptions!$B$10,"n/a") -> 16.248826
