Workbook

Sheet Model_Info
A1: BAP.AX owner-FCF DCF model
A2: Version | B2: 1.0 -- fresh build 2026-09-21; supersedes nothing (first valuation of this ticker)
A3: Built by | B3: dcf-analyst agent (Claude Fable 5.1) on 2026-09-21 at the orchestrator's request for the BAP.AX research run
A4: Data vintage: price | B4: A$0.81 Yahoo Finance, 2026-09-21T06:10:31Z regular close (16:10 AEST). Goes stale immediately.
A5: Data vintage: balance sheet | B5: 30-Jun-2026 FY26 annual report: gross borrowings A$205.0m, cash A$67.205m, lease liabilities A$228.97m, NCI A$1.916m
A6: Data vintage: shares | B6: 672,753,078 on issue at 30-Jun-2026 (note 21), post Feb-2026 entitlement offer; held flat
A7: Data vintage: guidance | B7: FY27 (27-Aug-2026): modest revenue growth, underlying NPAT weighted to 2H27, capex and D&A in line with FY26
A8: Method: model | B8: Owner-FCF DCF, 10-year component build (dcf-methods/references/owner-fcf.md + section 7)
A9: Method: margin base | B9: Mid-cycle: base recovers pre-AASB16 EBITDA margin to restated-FY25 level (7.85%), not the FY19-22 peak (11-13%) nor the FY26 trough (3.5%)
A10: Method: leases | B10: Treatment B: lease principal + interest charged inside the flows (lease_cost_pct); lease liabilities excluded from net debt; tax EBIT after D&A ex right-of-use
A11: Method: SBC | B11: Expensed at 0.05% of revenue, share count flat (charged once). SBC-zero market: street = house
A12: Method: NCI | B12: A$1.9m NCI deducted in the bridge; flows are consolidated
A13: Method: terminal | B13: TV = MAX(0, MIN(Gordon, 12x year-10 owner FCF)); 12x cap for a cyclical distributor with a broken track record
... A20: Staleness | B20: Every figure here goes stale: price daily, balance sheet at each half-year, drivers at each result. Check the dates above before relying on any output.

Sheet Actuals
A1: FY2026 actuals (A$m) | B1: Value | C1: Source
A2: Revenue | B2: 1924.144 | C2: FY26 AR income statement (Metrics.csv)
A3: Underlying EBITDA (post-AASB16) | B3: 152.5 | C3: FY26 AR segment overview
A4: Statutory EBITDA | B4: 138.8 | C4: Metrics.csv
A5: Lease principal paid | B5: 70.884 | C5: FY26 AR cash flow, financing (line 2869)
A6: Lease interest paid | B6: 15.087 | C6: FY26 AR cash flow, operating (line 2844)
A7: Lease cash total | B7: 85.971 | C7: sum
A8: Underlying EBITDA pre-AASB16 | B8: 66.529 | C8: derived
A9: SBC expense | B9: 0.712 | C9: FY26 AR changes in equity
A10: D&A total | B10: 101.137 | C10: FY26 AR note 6
A11: Right-of-use depreciation | B11: 65.901 | C11: FY26 AR note 12 (line 4023)
A12: D&A ex ROU | B12: 35.236 | C12: derived
A13: Capex (PPE + intangibles) | B13: 29.254 | C13: FY26 AR cash flow (lines 2856-2857)
... A25: Shares on issue (m) | B25: 672.753 | C25: FY26 AR note 21; 333.34m issued Feb-2026 at A$0.60
A26: FY27 guidance | B26: Modest revenue growth; NPAT weighted 2H27; capex and D&A in line with FY26 | C26: FY26 AR directors' report
A27: Buybacks | B27: 0.921 | C27: Treasury share purchases for rights; no programme; DRP suspended; no FY26 dividend

Sheet Assumptions
A1: Global | B1: Value | C1: Note
A2: wacc | B2: 0.095 | C2: AUD-built, all scenarios
A3: da_pct | B3: 0.018 | C3: D&A ex right-of-use, % revenue (FY26 1.83%)
A4: capex_pct | B4: 0.018 | C4: mid-cycle ~ D&A ex-ROU; FY27 guided in line with FY26 (1.5%)
A5: lease_cost_pct | B5: 0.0445 | C5: lease principal + interest, % revenue (FY26 4.47%)
A6: sbc_pct | B6: 0.0005 | C6: SBC % revenue (FY26 0.04%)
A7: wc_capture_pct | B7: -0.15 | C7: negative: distributor consumes WC on growth
A8: net_debt | B8: 137.795 | C8: gross borrowings - cash at 2026-06-30, A$m
A9: nci | B9: 1.916 | C9: non-controlling interest, A$m
A10: shares | B10: 672.753 | C10: millions, flat
A11: price | B11: 0.81 | C11: 2026-09-21T06:10:31Z regular close (16:10 AEST)
A12: tv_cap | B12: 12 | C12: x year-10 owner FCF
A13: hurdle | B13: 0.15 | C13: entry-price IRR
A14: revenue_fy0 | B14: 1924.144 | C14: FY2026 actual, A$m
A16: Scenario | B16: Terminal growth | C16: Weight | D16: Narrative
A17: bear | B17: 0.015 | C17: 0.3 | D17: Bear: the turnaround stalls. Pricing reset and stock availability stabilise Trade but Repco/NAPA and Supercheap keep the share they took in FY25-26; NZ stays in decline; Retail franchise network keeps shrinking. Payroll-underpayment remediation and further control fixes absorb the cost-out. Revenue flat in FY27 then ~1.5%/yr (below car-parc growth). Underlying EBITDA margin (post-AASB16) grinds from 7.9% to only 9.5% -- about 5% after the ~4.45% lease bill, never recovering the restated FY25 level of 7.9% pre-AASB16. The business survives (net leverage stays inside covenants on this path) but equity is worth little: year-10 owner FCF ~A$40m against ~A$140m of net debt and NCI.
A18: base | B18: 0.025 | C18: 0.5 | D18: Base: FY27 'modest' revenue growth (1.5%) as guided, with Trade parts and Networks growing and Retail/NZ/equipment still soft; from FY28 revenue tracks car-parc growth plus some share recovery (3-3.5%), fading to 2.5%. Underlying EBITDA margin (post-AASB16) rebuilds from 7.9% (FY26) to ~12.3% by FY34 -- ~7.85% after the lease bill, i.e. back to the restated FY25 pre-AASB16 level (7.9%) and well below the FY19-22 peak of 11-13%. Management says FY27 benefits are reinvested in technology and people, so year-1 margin gain is small. Cash tax shielded at 15%/25% in FY27-28 by FY25-26 tax losses, then 30% statutory. Capex held at ~D&A ex-ROU (1.8%), above the FY27 guide of 'in line with FY26' (1.5%). Working capital consumes 15c per dollar of revenue growth (distributor: inventory + receivables exceed payables).
A19: bull | B19: 0.03 | C19: 0.2 | D19: Bull: the Wilesmith turnaround executes like Supercheap's playbook -- pricing/ranging discipline restores Trade gross margin, the strategy reset divests sub-scale non-core assets, cost-out lands, and store network growth resumes; independent-workshop share gains and the ageing car parc lift revenue 4-5%/yr in FY28-31. Underlying EBITDA margin (post-AASB16) recovers to 14.5% -- ~10% pre-AASB16, roughly the FY23 level (9.4%) and still short of the FY19-22 peak. A private-equity or trade approach (Bain at A$5.40 in 2024 on the old 339m share count, Jefferies flagging renewed interest post-result) is the realisation path but is not modelled as a separate exit multiple.
A20: weights check | C20: =SUM(C17:C19) | D20: must equal 1

Sheet DCF_bear
A1: BEAR scenario -- owner-FCF DCF, A$m
A3: Year | B3: FY2026A | C3: FY2027E | D3: FY2028E | E3: FY2029E | F3: FY2030E | G3: FY2031E | H3: FY2032E | I3: FY2033E | J3: FY2034E | K3: FY2035E | L3: FY2036E
A4: Index | B4: 0 | C4: 1 | D4: 2 | E4: 3 | F4: 4 | G4: 5 | H4: 6 | I4: 7 | J4: 8 | K4: 9 | L4: 10
A5: Revenue growth | C5: 0 | D5: 0.01 | E5: 0.015 | F5: 0.015 | G5: 0.015 | H5: 0.015 | I5: 0.015 | J5: 0.015 | K5: 0.015 | L5: 0.015
A6: Revenue | B6: =Assumptions!$B$14 | C6: =B6*(1+C5) | D6: =C6*(1+D5) | E6: =D6*(1+E5) | F6: =E6*(1+F5) | G6: =F6*(1+G5) | H6: =G6*(1+H5) | I6: =H6*(1+I5) | J6: =I6*(1+J5) | ... L6: =K6*(1+L5)
A7: Underlying EBITDA margin (post-AASB16) | B7: =B8/B6 | C7: 0.08 | D7: 0.083 | E7: 0.086 | F7: 0.09 | G7: 0.092 | H7: 0.094 | I7: 0.095 | J7: 0.095 | K7: 0.095 | L7: 0.095
A8: Underlying EBITDA | B8: 152.5 | C8: =C6*C7 | D8: =D6*D7 | E8: =E6*E7 | F8: =F6*F7 | G8: =G6*G7 | H8: =H6*H7 | I8: =I6*I7 | J8: =J6*J7 | ... L8: =L6*L7
A9: SBC % revenue | C9: 0.0005 | D9: 0.0005 | E9: 0.0005 | F9: 0.0005 | G9: 0.0005 | H9: 0.0005 | I9: 0.0005 | J9: 0.0005 | K9: 0.0005 | L9: 0.0005
A10: SBC (negative) | C10: =-C6*C9 | D10: =-D6*D9 | E10: =-E6*E9 | F10: =-F6*F9 | G10: =-G6*G9 | H10: =-H6*H9 | I10: =-I6*I9 | J10: =-J6*J9 | ... L10: =-L6*L9
A11: Lease cost % revenue | C11: =Assumptions!$B$5 | D11: =Assumptions!$B$5 | E11: =Assumptions!$B$5 | F11: =Assumptions!$B$5 | G11: =Assumptions!$B$5 | H11: =Assumptions!$B$5 | I11: =Assumptions!$B$5 | J11: =Assumptions!$B$5 | ... L11: =Assumptions!$B$5
A12: Lease cash (negative) | C12: =-C6*C11 | D12: =-D6*D11 | E12: =-E6*E11 | F12: =-F6*F11 | G12: =-G6*G11 | H12: =-H6*H11 | I12: =-I6*I11 | J12: =-J6*J11 | ... L12: =-L6*L11
A13: Owner EBITDA pre-AASB16 after SBC | C13: =C8+C10+C12 | D13: =D8+D10+D12 | E13: =E8+E10+E12 | F13: =F8+F10+F12 | G13: =G8+G10+G12 | H13: =H8+H10+H12 | I13: =I8+I10+I12 | J13: =J8+J10+J12 | ... L13: =L8+L10+L12
A14: D&A ex ROU (negative) | C14: =-C6*Assumptions!$B$3 | D14: =-D6*Assumptions!$B$3 | E14: =-E6*Assumptions!$B$3 | F14: =-F6*Assumptions!$B$3 | G14: =-G6*Assumptions!$B$3 | H14: =-H6*Assumptions!$B$3 | I14: =-I6*Assumptions!$B$3 | J14: =-J6*Assumptions!$B$3 | ... L14: =-L6*Assumptions!$B$3
A15: EBIT | C15: =C13+C14 | D15: =D13+D14 | E15: =E13+E14 | F15: =F13+F14 | G15: =G13+G14 | H15: =H13+H14 | I15: =I13+I14 | J15: =J13+J14 | ... L15: =L13+L14
A16: Cash tax rate | C16: 0.1 | D16: 0.2 | E16: 0.3 | F16: 0.3 | G16: 0.3 | H16: 0.3 | I16: 0.3 | J16: 0.3 | K16: 0.3 | L16: 0.3
A17: Cash tax (negative) | C17: =-MAX(0,C15)*C16 | D17: =-MAX(0,D15)*D16 | E17: =-MAX(0,E15)*E16 | F17: =-MAX(0,F15)*F16 | G17: =-MAX(0,G15)*G16 | H17: =-MAX(0,H15)*H16 | I17: =-MAX(0,I15)*I16 | J17: =-MAX(0,J15)*J16 | ... L17: =-MAX(0,L15)*L16
A18: NOPAT | C18: =C15+C17 | D18: =D15+D17 | E18: =E15+E17 | F18: =F15+F17 | G18: =G15+G17 | H18: =H15+H17 | I18: =I15+I17 | J18: =J15+J17 | ... L18: =L15+L17
A19: add back D&A | C19: =-C14 | D19: =-D14 | E19: =-E14 | F19: =-F14 | G19: =-G14 | H19: =-H14 | I19: =-I14 | J19: =-J14 | ... L19: =-L14
A20: less capex | C20: =-C6*Assumptions!$B$4 | D20: =-D6*Assumptions!$B$4 | E20: =-E6*Assumptions!$B$4 | F20: =-F6*Assumptions!$B$4 | G20: =-G6*Assumptions!$B$4 | H20: =-H6*Assumptions!$B$4 | I20: =-I6*Assumptions!$B$4 | J20: =-J6*Assumptions!$B$4 | ... L20: =-L6*Assumptions!$B$4
A21: working capital (on revenue change) | C21: =Assumptions!$B$7*(C6-B6) | D21: =Assumptions!$B$7*(D6-C6) | E21: =Assumptions!$B$7*(E6-D6) | F21: =Assumptions!$B$7*(F6-E6) | G21: =Assumptions!$B$7*(G6-F6) | H21: =Assumptions!$B$7*(H6-G6) | I21: =Assumptions!$B$7*(I6-H6) | J21: =Assumptions!$B$7*(J6-I6) | ... L21: =Assumptions!$B$7*(L6-K6)
A22: Unlevered owner FCF | C22: =C18+C19+C20+C21 | D22: =D18+D19+D20+D21 | E22: =E18+E19+E20+E21 | F22: =F18+F19+F20+F21 | G22: =G18+G19+G20+G21 | H22: =H18+H19+H20+H21 | I22: =I18+I19+I20+I21 | J22: =J18+J19+J20+J21 | ... L22: =L18+L19+L20+L21
A23: Discount factor | C23: =1/(1+Assumptions!$B$2)^C4 | D23: =1/(1+Assumptions!$B$2)^D4 | E23: =1/(1+Assumptions!$B$2)^E4 | F23: =1/(1+Assumptions!$B$2)^F4 | G23: =1/(1+Assumptions!$B$2)^G4 | H23: =1/(1+Assumptions!$B$2)^H4 | I23: =1/(1+Assumptions!$B$2)^I4 | J23: =1/(1+Assumptions!$B$2)^J4 | ... L23: =1/(1+Assumptions!$B$2)^L4
A24: PV of FCF | C24: =C22*C23 | D24: =D22*D23 | E24: =E22*E23 | F24: =F22*F23 | G24: =G22*G23 | H24: =H22*H23 | I24: =I22*I23 | J24: =J22*J23 | ... L24: =L22*L23
A26: Memo: FCF before SBC (company-style) | C26: =C22-C10 | D26: =D22-D10 | E26: =E22-E10 | F26: =F22-F10 | G26: =G22-G10 | H26: =H22-H10 | I26: =I22-I10 | J26: =J22-J10 | ... L26: =L22-L10
A27: Memo: owner FCF margin | C27: =C22/C6 | D27: =D22/D6 | E27: =E22/E6 | F27: =F22/F6 | G27: =G22/G6 | H27: =H22/H6 | I27: =I22/I6 | J27: =J22/J6 | ... L27: =L22/L6
A29: Sum of PV of FCF | B29: =SUM(C24:L24)
A30: Terminal growth | B30: =Assumptions!$B$17
A31: Terminal-year FCF x (1+g) | B31: =L22*(1+B30)
A32: Gordon TV | B32: =IF(Assumptions!$B$2>B30,B31/(Assumptions!$B$2-B30),"n/a")
A33: Cap TV | B33: =Assumptions!$B$12*L22
A34: TV used = MAX(0,MIN(Gordon,cap)) | B34: =MAX(0,MIN(B32,B33))
A35: Implied exit multiple | B35: =IF(L22<>0,B34/L22,"n/a")
A36: PV of TV | B36: =B34*L23
A37: Enterprise value | B37: =B29+B36
A38: less net debt and NCI | B38: =-(Assumptions!$B$8+Assumptions!$B$9)
A39: Equity value | B39: =B37+B38
A40: Diluted shares (m) | B40: =Assumptions!$B$10
A41: Value per share (A$) | B41: =B39/B40
A42: Upside vs price | B42: =B41/Assumptions!$B$11-1
A44: Street memo: PV of explicit SBC | B44: =SUMPRODUCT(-C10:L10/(1+Assumptions!$B$2)^C4:L4)
...

Sheet DCF_base
A1: BASE scenario -- owner-FCF DCF, A$m
A3: Year | B3: FY2026A | C3: FY2027E | D3: FY2028E | E3: FY2029E | F3: FY2030E | G3: FY2031E | H3: FY2032E | I3: FY2033E | J3: FY2034E | K3: FY2035E | L3: FY2036E
A4: Index | B4: 0 | C4: 1 | D4: 2 | E4: 3 | F4: 4 | G4: 5 | H4: 6 | I4: 7 | J4: 8 | K4: 9 | L4: 10
A5: Revenue growth | C5: 0.015 | D5: 0.03 | E5: 0.035 | F5: 0.035 | G5: 0.035 | H5: 0.03 | I5: 0.03 | J5: 0.03 | K5: 0.025 | L5: 0.025
A6: Revenue | B6: =Assumptions!$B$14 | C6: =B6*(1+C5) | D6: =C6*(1+D5) | E6: =D6*(1+E5) | F6: =E6*(1+F5) | G6: =F6*(1+G5) | H6: =G6*(1+H5) | I6: =H6*(1+I5) | J6: =I6*(1+J5) | ... L6: =K6*(1+L5)
A7: Underlying EBITDA margin (post-AASB16) | B7: =B8/B6 | C7: 0.085 | D7: 0.095 | E7: 0.105 | F7: 0.112 | G7: 0.117 | H7: 0.12 | I7: 0.122 | J7: 0.123 | K7: 0.123 | L7: 0.123
A8: Underlying EBITDA | B8: 152.5 | C8: =C6*C7 | D8: =D6*D7 | E8: =E6*E7 | F8: =F6*F7 | G8: =G6*G7 | H8: =H6*H7 | I8: =I6*I7 | J8: =J6*J7 | ... L8: =L6*L7
A9: SBC % revenue | C9: 0.0005 | D9: 0.0005 | E9: 0.0005 | F9: 0.0005 | G9: 0.0005 | H9: 0.0005 | I9: 0.0005 | J9: 0.0005 | K9: 0.0005 | L9: 0.0005
A10: SBC (negative) | C10: =-C6*C9 | D10: =-D6*D9 | E10: =-E6*E9 | F10: =-F6*F9 | G10: =-G6*G9 | H10: =-H6*H9 | I10: =-I6*I9 | J10: =-J6*J9 | ... L10: =-L6*L9
A11: Lease cost % revenue | C11: =Assumptions!$B$5 | D11: =Assumptions!$B$5 | E11: =Assumptions!$B$5 | F11: =Assumptions!$B$5 | G11: =Assumptions!$B$5 | H11: =Assumptions!$B$5 | I11: =Assumptions!$B$5 | J11: =Assumptions!$B$5 | ... L11: =Assumptions!$B$5
A12: Lease cash (negative) | C12: =-C6*C11 | D12: =-D6*D11 | E12: =-E6*E11 | F12: =-F6*F11 | G12: =-G6*G11 | H12: =-H6*H11 | I12: =-I6*I11 | J12: =-J6*J11 | ... L12: =-L6*L11
A13: Owner EBITDA pre-AASB16 after SBC | C13: =C8+C10+C12 | D13: =D8+D10+D12 | E13: =E8+E10+E12 | F13: =F8+F10+F12 | G13: =G8+G10+G12 | H13: =H8+H10+H12 | I13: =I8+I10+I12 | J13: =J8+J10+J12 | ... L13: =L8+L10+L12
A14: D&A ex ROU (negative) | C14: =-C6*Assumptions!$B$3 | D14: =-D6*Assumptions!$B$3 | E14: =-E6*Assumptions!$B$3 | F14: =-F6*Assumptions!$B$3 | G14: =-G6*Assumptions!$B$3 | H14: =-H6*Assumptions!$B$3 | I14: =-I6*Assumptions!$B$3 | J14: =-J6*Assumptions!$B$3 | ... L14: =-L6*Assumptions!$B$3
A15: EBIT | C15: =C13+C14 | D15: =D13+D14 | E15: =E13+E14 | F15: =F13+F14 | G15: =G13+G14 | H15: =H13+H14 | I15: =I13+I14 | J15: =J13+J14 | ... L15: =L13+L14
A16: Cash tax rate | C16: 0.15 | D16: 0.25 | E16: 0.3 | F16: 0.3 | G16: 0.3 | H16: 0.3 | I16: 0.3 | J16: 0.3 | K16: 0.3 | L16: 0.3
A17: Cash tax (negative) | C17: =-MAX(0,C15)*C16 | D17: =-MAX(0,D15)*D16 | E17: =-MAX(0,E15)*E16 | F17: =-MAX(0,F15)*F16 | G17: =-MAX(0,G15)*G16 | H17: =-MAX(0,H15)*H16 | I17: =-MAX(0,I15)*I16 | J17: =-MAX(0,J15)*J16 | ... L17: =-MAX(0,L15)*L16
A18: NOPAT | C18: =C15+C17 | D18: =D15+D17 | E18: =E15+E17 | F18: =F15+F17 | G18: =G15+G17 | H18: =H15+H17 | I18: =I15+I17 | J18: =J15+J17 | ... L18: =L15+L17
A19: add back D&A | C19: =-C14 | D19: =-D14 | E19: =-E14 | F19: =-F14 | G19: =-G14 | H19: =-H14 | I19: =-I14 | J19: =-J14 | ... L19: =-L14
A20: less capex | C20: =-C6*Assumptions!$B$4 | D20: =-D6*Assumptions!$B$4 | E20: =-E6*Assumptions!$B$4 | F20: =-F6*Assumptions!$B$4 | G20: =-G6*Assumptions!$B$4 | H20: =-H6*Assumptions!$B$4 | I20: =-I6*Assumptions!$B$4 | J20: =-J6*Assumptions!$B$4 | ... L20: =-L6*Assumptions!$B$4
A21: working capital (on revenue change) | C21: =Assumptions!$B$7*(C6-B6) | D21: =Assumptions!$B$7*(D6-C6) | E21: =Assumptions!$B$7*(E6-D6) | F21: =Assumptions!$B$7*(F6-E6) | G21: =Assumptions!$B$7*(G6-F6) | H21: =Assumptions!$B$7*(H6-G6) | I21: =Assumptions!$B$7*(I6-H6) | J21: =Assumptions!$B$7*(J6-I6) | ... L21: =Assumptions!$B$7*(L6-K6)
A22: Unlevered owner FCF | C22: =C18+C19+C20+C21 | D22: =D18+D19+D20+D21 | E22: =E18+E19+E20+E21 | F22: =F18+F19+F20+F21 | G22: =G18+G19+G20+G21 | H22: =H18+H19+H20+H21 | I22: =I18+I19+I20+I21 | J22: =J18+J19+J20+J21 | ... L22: =L18+L19+L20+L21
A23: Discount factor | C23: =1/(1+Assumptions!$B$2)^C4 | D23: =1/(1+Assumptions!$B$2)^D4 | E23: =1/(1+Assumptions!$B$2)^E4 | F23: =1/(1+Assumptions!$B$2)^F4 | G23: =1/(1+Assumptions!$B$2)^G4 | H23: =1/(1+Assumptions!$B$2)^H4 | I23: =1/(1+Assumptions!$B$2)^I4 | J23: =1/(1+Assumptions!$B$2)^J4 | ... L23: =1/(1+Assumptions!$B$2)^L4
A24: PV of FCF | C24: =C22*C23 | D24: =D22*D23 | E24: =E22*E23 | F24: =F22*F23 | G24: =G22*G23 | H24: =H22*H23 | I24: =I22*I23 | J24: =J22*J23 | ... L24: =L22*L23
A26: Memo: FCF before SBC (company-style) | C26: =C22-C10 | D26: =D22-D10 | E26: =E22-E10 | F26: =F22-F10 | G26: =G22-G10 | H26: =H22-H10 | I26: =I22-I10 | J26: =J22-J10 | ... L26: =L22-L10
A27: Memo: owner FCF margin | C27: =C22/C6 | D27: =D22/D6 | E27: =E22/E6 | F27: =F22/F6 | G27: =G22/G6 | H27: =H22/H6 | I27: =I22/I6 | J27: =J22/J6 | ... L27: =L22/L6
A29: Sum of PV of FCF | B29: =SUM(C24:L24)
A30: Terminal growth | B30: =Assumptions!$B$18
A31: Terminal-year FCF x (1+g) | B31: =L22*(1+B30)
A32: Gordon TV | B32: =IF(Assumptions!$B$2>B30,B31/(Assumptions!$B$2-B30),"n/a")
A33: Cap TV | B33: =Assumptions!$B$12*L22
A34: TV used = MAX(0,MIN(Gordon,cap)) | B34: =MAX(0,MIN(B32,B33))
A35: Implied exit multiple | B35: =IF(L22<>0,B34/L22,"n/a")
A36: PV of TV | B36: =B34*L23
A37: Enterprise value | B37: =B29+B36
A38: less net debt and NCI | B38: =-(Assumptions!$B$8+Assumptions!$B$9)
A39: Equity value | B39: =B37+B38
A40: Diluted shares (m) | B40: =Assumptions!$B$10
A41: Value per share (A$) | B41: =B39/B40
A42: Upside vs price | B42: =B41/Assumptions!$B$11-1
A44: Street memo: PV of explicit SBC | B44: =SUMPRODUCT(-C10:L10/(1+Assumptions!$B$2)^C4:L4)
...

Sheet DCF_bull
A1: BULL scenario -- owner-FCF DCF, A$m
A3: Year | B3: FY2026A | C3: FY2027E | D3: FY2028E | E3: FY2029E | F3: FY2030E | G3: FY2031E | H3: FY2032E | I3: FY2033E | J3: FY2034E | K3: FY2035E | L3: FY2036E
A4: Index | B4: 0 | C4: 1 | D4: 2 | E4: 3 | F4: 4 | G4: 5 | H4: 6 | I4: 7 | J4: 8 | K4: 9 | L4: 10
A5: Revenue growth | C5: 0.03 | D5: 0.045 | E5: 0.05 | F5: 0.05 | G5: 0.045 | H5: 0.04 | I5: 0.04 | J5: 0.035 | K5: 0.03 | L5: 0.03
A6: Revenue | B6: =Assumptions!$B$14 | C6: =B6*(1+C5) | D6: =C6*(1+D5) | E6: =D6*(1+E5) | F6: =E6*(1+F5) | G6: =F6*(1+G5) | H6: =G6*(1+H5) | I6: =H6*(1+I5) | J6: =I6*(1+J5) | ... L6: =K6*(1+L5)
A7: Underlying EBITDA margin (post-AASB16) | B7: =B8/B6 | C7: 0.09 | D7: 0.105 | E7: 0.12 | F7: 0.13 | G7: 0.137 | H7: 0.142 | I7: 0.145 | J7: 0.145 | K7: 0.145 | L7: 0.145
A8: Underlying EBITDA | B8: 152.5 | C8: =C6*C7 | D8: =D6*D7 | E8: =E6*E7 | F8: =F6*F7 | G8: =G6*G7 | H8: =H6*H7 | I8: =I6*I7 | J8: =J6*J7 | ... L8: =L6*L7
A9: SBC % revenue | C9: 0.0005 | D9: 0.0005 | E9: 0.0005 | F9: 0.0005 | G9: 0.0005 | H9: 0.0005 | I9: 0.0005 | J9: 0.0005 | K9: 0.0005 | L9: 0.0005
A10: SBC (negative) | C10: =-C6*C9 | D10: =-D6*D9 | E10: =-E6*E9 | F10: =-F6*F9 | G10: =-G6*G9 | H10: =-H6*H9 | I10: =-I6*I9 | J10: =-J6*J9 | ... L10: =-L6*L9
A11: Lease cost % revenue | C11: =Assumptions!$B$5 | D11: =Assumptions!$B$5 | E11: =Assumptions!$B$5 | F11: =Assumptions!$B$5 | G11: =Assumptions!$B$5 | H11: =Assumptions!$B$5 | I11: =Assumptions!$B$5 | J11: =Assumptions!$B$5 | ... L11: =Assumptions!$B$5
A12: Lease cash (negative) | C12: =-C6*C11 | D12: =-D6*D11 | E12: =-E6*E11 | F12: =-F6*F11 | G12: =-G6*G11 | H12: =-H6*H11 | I12: =-I6*I11 | J12: =-J6*J11 | ... L12: =-L6*L11
A13: Owner EBITDA pre-AASB16 after SBC | C13: =C8+C10+C12 | D13: =D8+D10+D12 | E13: =E8+E10+E12 | F13: =F8+F10+F12 | G13: =G8+G10+G12 | H13: =H8+H10+H12 | I13: =I8+I10+I12 | J13: =J8+J10+J12 | ... L13: =L8+L10+L12
A14: D&A ex ROU (negative) | C14: =-C6*Assumptions!$B$3 | D14: =-D6*Assumptions!$B$3 | E14: =-E6*Assumptions!$B$3 | F14: =-F6*Assumptions!$B$3 | G14: =-G6*Assumptions!$B$3 | H14: =-H6*Assumptions!$B$3 | I14: =-I6*Assumptions!$B$3 | J14: =-J6*Assumptions!$B$3 | ... L14: =-L6*Assumptions!$B$3
A15: EBIT | C15: =C13+C14 | D15: =D13+D14 | E15: =E13+E14 | F15: =F13+F14 | G15: =G13+G14 | H15: =H13+H14 | I15: =I13+I14 | J15: =J13+J14 | ... L15: =L13+L14
A16: Cash tax rate | C16: 0.15 | D16: 0.25 | E16: 0.3 | F16: 0.3 | G16: 0.3 | H16: 0.3 | I16: 0.3 | J16: 0.3 | K16: 0.3 | L16: 0.3
A17: Cash tax (negative) | C17: =-MAX(0,C15)*C16 | D17: =-MAX(0,D15)*D16 | E17: =-MAX(0,E15)*E16 | F17: =-MAX(0,F15)*F16 | G17: =-MAX(0,G15)*G16 | H17: =-MAX(0,H15)*H16 | I17: =-MAX(0,I15)*I16 | J17: =-MAX(0,J15)*J16 | ... L17: =-MAX(0,L15)*L16
A18: NOPAT | C18: =C15+C17 | D18: =D15+D17 | E18: =E15+E17 | F18: =F15+F17 | G18: =G15+G17 | H18: =H15+H17 | I18: =I15+I17 | J18: =J15+J17 | ... L18: =L15+L17
A19: add back D&A | C19: =-C14 | D19: =-D14 | E19: =-E14 | F19: =-F14 | G19: =-G14 | H19: =-H14 | I19: =-I14 | J19: =-J14 | ... L19: =-L14
A20: less capex | C20: =-C6*Assumptions!$B$4 | D20: =-D6*Assumptions!$B$4 | E20: =-E6*Assumptions!$B$4 | F20: =-F6*Assumptions!$B$4 | G20: =-G6*Assumptions!$B$4 | H20: =-H6*Assumptions!$B$4 | I20: =-I6*Assumptions!$B$4 | J20: =-J6*Assumptions!$B$4 | ... L20: =-L6*Assumptions!$B$4
A21: working capital (on revenue change) | C21: =Assumptions!$B$7*(C6-B6) | D21: =Assumptions!$B$7*(D6-C6) | E21: =Assumptions!$B$7*(E6-D6) | F21: =Assumptions!$B$7*(F6-E6) | G21: =Assumptions!$B$7*(G6-F6) | H21: =Assumptions!$B$7*(H6-G6) | I21: =Assumptions!$B$7*(I6-H6) | J21: =Assumptions!$B$7*(J6-I6) | ... L21: =Assumptions!$B$7*(L6-K6)
A22: Unlevered owner FCF | C22: =C18+C19+C20+C21 | D22: =D18+D19+D20+D21 | E22: =E18+E19+E20+E21 | F22: =F18+F19+F20+F21 | G22: =G18+G19+G20+G21 | H22: =H18+H19+H20+H21 | I22: =I18+I19+I20+I21 | J22: =J18+J19+J20+J21 | ... L22: =L18+L19+L20+L21
A23: Discount factor | C23: =1/(1+Assumptions!$B$2)^C4 | D23: =1/(1+Assumptions!$B$2)^D4 | E23: =1/(1+Assumptions!$B$2)^E4 | F23: =1/(1+Assumptions!$B$2)^F4 | G23: =1/(1+Assumptions!$B$2)^G4 | H23: =1/(1+Assumptions!$B$2)^H4 | I23: =1/(1+Assumptions!$B$2)^I4 | J23: =1/(1+Assumptions!$B$2)^J4 | ... L23: =1/(1+Assumptions!$B$2)^L4
A24: PV of FCF | C24: =C22*C23 | D24: =D22*D23 | E24: =E22*E23 | F24: =F22*F23 | G24: =G22*G23 | H24: =H22*H23 | I24: =I22*I23 | J24: =J22*J23 | ... L24: =L22*L23
A26: Memo: FCF before SBC (company-style) | C26: =C22-C10 | D26: =D22-D10 | E26: =E22-E10 | F26: =F22-F10 | G26: =G22-G10 | H26: =H22-H10 | I26: =I22-I10 | J26: =J22-J10 | ... L26: =L22-L10
A27: Memo: owner FCF margin | C27: =C22/C6 | D27: =D22/D6 | E27: =E22/E6 | F27: =F22/F6 | G27: =G22/G6 | H27: =H22/H6 | I27: =I22/I6 | J27: =J22/J6 | ... L27: =L22/L6
A29: Sum of PV of FCF | B29: =SUM(C24:L24)
A30: Terminal growth | B30: =Assumptions!$B$19
A31: Terminal-year FCF x (1+g) | B31: =L22*(1+B30)
A32: Gordon TV | B32: =IF(Assumptions!$B$2>B30,B31/(Assumptions!$B$2-B30),"n/a")
A33: Cap TV | B33: =Assumptions!$B$12*L22
A34: TV used = MAX(0,MIN(Gordon,cap)) | B34: =MAX(0,MIN(B32,B33))
A35: Implied exit multiple | B35: =IF(L22<>0,B34/L22,"n/a")
A36: PV of TV | B36: =B34*L23
A37: Enterprise value | B37: =B29+B36
A38: less net debt and NCI | B38: =-(Assumptions!$B$8+Assumptions!$B$9)
A39: Equity value | B39: =B37+B38
A40: Diluted shares (m) | B40: =Assumptions!$B$10
A41: Value per share (A$) | B41: =B39/B40
A42: Upside vs price | B42: =B41/Assumptions!$B$11-1
A44: Street memo: PV of explicit SBC | B44: =SUMPRODUCT(-C10:L10/(1+Assumptions!$B$2)^C4:L4)
...

Sheet FCF_Quality
A1: FY | B1: Revenue | C1: Reported FCF (OCF-capex) | D1: less lease principal | E1: less SBC | F1: less interest income | G1: Owner FCF | H1: Reported FCF margin | I1: Owner FCF margin | J1: Cash tax paid | K1: Memo
A2: FY2020 | B2: 1462.747 | C2: 161.705 | D2: 54.552 | E2: 2.92 | F2: 0 | G2: =C2-D2-E2-F2 | H2: =C2/B2 | I2: =G2/B2 | J2: 35.487 | K2: first IFRS16 year; COVID
A3: FY2021 | B3: 1761.673 | C3: 80.818 | D3: 61.104 | E3: 2.864 | F3: 0 | G3: =C3-D3-E3-F3 | H3: =C3/B3 | I3: =G3/B3 | J3: 47.037
A4: FY2022 | B4: 1841.905 | C4: 47.422 | D4: 69.989 | E4: 3.369 | F4: 0 | G4: =C4-D4-E4-F4 | H4: =C4/B4 | I4: =G4/B4 | J4: 57.518 | K4: inventory build
A5: FY2023 | B5: 2021.135 | C5: 172.384 | D5: 66.29 | E5: 0 | F5: 0 | G5: =C5-D5-E5-F5 | H5: =C5/B5 | I5: =G5/B5 | J5: 53 | K5: inventory unwind; SBC reversal -0.31 floored at 0
A6: FY2024 | B6: 2036.938 | C6: 68.541 | D6: 61.352 | E6: 0 | F6: 0 | G6: =C6-D6-E6-F6 | H6: =C6/B6 | I6: =G6/B6 | J6: 27.526 | K6: impairment year; SBC reversal -0.259 floored at 0
A7: FY2025 | B7: 1975.767 | C7: 72.849 | D7: 62.07 | E7: 1.868 | F7: 0 | G7: =C7-D7-E7-F7 | H7: =C7/B7 | I7: =G7/B7 | J7: 12.157
A8: FY2026 | B8: 1924.144 | C8: 123.08 | D8: 70.884 | E8: 0.712 | F8: 0 | G8: =C8-D8-E8-F8 | H8: =C8/B8 | I8: =G8/B8 | J8: -21.031 | K8: A$21.0m tax refund; WC release, cash conversion 109%

Sheet Valuation
A1: Valuation summary (A$ per share)
A3: Scenario | B3: Value per share | C3: Upside vs price | D3: Weight | E3: Street value per share | F3: Entry price @ hurdle | G3: TV bound
A4: bear | B4: =DCF_bear!$B$41 | C4: =B4/Assumptions!$B$11-1 | D4: =Assumptions!$C$17 | E4: =DCF_bear!$B$46 | F4: =(SUMPRODUCT(DCF_bear!C22:L22/(1+Assumptions!$B$13)^DCF_bear!C4:L4)+MAX(0,MIN(IF(Assumptions!$B$13>Assumptions!$B$17,DCF_bear!L22*(1+Assumptions!$B$17)/(Assumptions!$B$13-Assumptions!$B$17),0),Assumptions!$B$12*DCF_bear!L22))/(1+Assumptions!$B$13)^10-Assumptions!$B$8-Assumptions!$B$9)/Assumptions!$B$10 | G4: =DCF_bear!$B$35
A5: base | B5: =DCF_base!$B$41 | C5: =B5/Assumptions!$B$11-1 | D5: =Assumptions!$C$18 | E5: =DCF_base!$B$46 | F5: =(SUMPRODUCT(DCF_base!C22:L22/(1+Assumptions!$B$13)^DCF_base!C4:L4)+MAX(0,MIN(IF(Assumptions!$B$13>Assumptions!$B$18,DCF_base!L22*(1+Assumptions!$B$18)/(Assumptions!$B$13-Assumptions!$B$18),0),Assumptions!$B$12*DCF_base!L22))/(1+Assumptions!$B$13)^10-Assumptions!$B$8-Assumptions!$B$9)/Assumptions!$B$10 | G5: =DCF_base!$B$35
A6: bull | B6: =DCF_bull!$B$41 | C6: =B6/Assumptions!$B$11-1 | D6: =Assumptions!$C$19 | E6: =DCF_bull!$B$46 | F6: =(SUMPRODUCT(DCF_bull!C22:L22/(1+Assumptions!$B$13)^DCF_bull!C4:L4)+MAX(0,MIN(IF(Assumptions!$B$13>Assumptions!$B$19,DCF_bull!L22*(1+Assumptions!$B$19)/(Assumptions!$B$13-Assumptions!$B$19),0),Assumptions!$B$12*DCF_bull!L22))/(1+Assumptions!$B$13)^10-Assumptions!$B$8-Assumptions!$B$9)/Assumptions!$B$10 | G6: =DCF_bull!$B$35
A8: Probability-weighted value | B8: =SUMPRODUCT(B4:B6,D4:D6)
A9: Current price | B9: =Assumptions!$B$11
A10: Margin of safety | B10: =1-Assumptions!$B$11/B8
A11: Street weighted value | B11: =SUMPRODUCT(E4:E6,D4:D6)
A12: Band position (house->street) | B12: =IF(ABS(B11-B8)<0.03,"n/a: SBC-zero, band collapsed",(Assumptions!$B$11-B8)/(B11-B8))
A13: Weighted entry price @ 15% hurdle | B13: =SUMPRODUCT(F4:F6,D4:D6)
A15: Required-return table (base case; TV rebuilt at each rate)
A16: Required return | B16: Value per share
A17: 0.09 | B17: =(SUMPRODUCT(DCF_base!C22:L22/(1+$A$17)^DCF_base!C4:L4)+MAX(0,MIN(IF($A$17>Assumptions!$B$18,DCF_base!L22*(1+Assumptions!$B$18)/($A$17-Assumptions!$B$18),0),Assumptions!$B$12*DCF_base!L22))/(1+$A$17)^10-Assumptions!$B$8-Assumptions!$B$9)/Assumptions!$B$10
A18: 0.1 | B18: =(SUMPRODUCT(DCF_base!C22:L22/(1+$A$18)^DCF_base!C4:L4)+MAX(0,MIN(IF($A$18>Assumptions!$B$18,DCF_base!L22*(1+Assumptions!$B$18)/($A$18-Assumptions!$B$18),0),Assumptions!$B$12*DCF_base!L22))/(1+$A$18)^10-Assumptions!$B$8-Assumptions!$B$9)/Assumptions!$B$10
A19: 0.11 | B19: =(SUMPRODUCT(DCF_base!C22:L22/(1+$A$19)^DCF_base!C4:L4)+MAX(0,MIN(IF($A$19>Assumptions!$B$18,DCF_base!L22*(1+Assumptions!$B$18)/($A$19-Assumptions!$B$18),0),Assumptions!$B$12*DCF_base!L22))/(1+$A$19)^10-Assumptions!$B$8-Assumptions!$B$9)/Assumptions!$B$10
A20: 0.12 | B20: =(SUMPRODUCT(DCF_base!C22:L22/(1+$A$20)^DCF_base!C4:L4)+MAX(0,MIN(IF($A$20>Assumptions!$B$18,DCF_base!L22*(1+Assumptions!$B$18)/($A$20-Assumptions!$B$18),0),Assumptions!$B$12*DCF_base!L22))/(1+$A$20)^10-Assumptions!$B$8-Assumptions!$B$9)/Assumptions!$B$10
A21: 0.15 | B21: =(SUMPRODUCT(DCF_base!C22:L22/(1+$A$21)^DCF_base!C4:L4)+MAX(0,MIN(IF($A$21>Assumptions!$B$18,DCF_base!L22*(1+Assumptions!$B$18)/($A$21-Assumptions!$B$18),0),Assumptions!$B$12*DCF_base!L22))/(1+$A$21)^10-Assumptions!$B$8-Assumptions!$B$9)/Assumptions!$B$10
A22: 0.095 | B22: =(SUMPRODUCT(DCF_base!C22:L22/(1+$A$22)^DCF_base!C4:L4)+MAX(0,MIN(IF($A$22>Assumptions!$B$18,DCF_base!L22*(1+Assumptions!$B$18)/($A$22-Assumptions!$B$18),0),Assumptions!$B$12*DCF_base!L22))/(1+$A$22)^10-Assumptions!$B$8-Assumptions!$B$9)/Assumptions!$B$10
A24: Sensitivity: base value per share, WACC (rows) x terminal growth (columns)
A25: WACC \ g | B25: 0.015 | C25: 0.02 | D25: 0.025 | E25: 0.03 | F25: 0.035
A26: 0.075 | B26: =(SUMPRODUCT(DCF_base!C22:L22/(1+$A$26)^DCF_base!C4:L4)+MAX(0,MIN(IF($A$26>B$25,DCF_base!L22*(1+B$25)/($A$26-B$25),0),Assumptions!$B$12*DCF_base!L22))/(1+$A$26)^10-Assumptions!$B$8-Assumptions!$B$9)/Assumptions!$B$10 | C26: =(SUMPRODUCT(DCF_base!C22:L22/(1+$A$26)^DCF_base!C4:L4)+MAX(0,MIN(IF($A$26>C$25,DCF_base!L22*(1+C$25)/($A$26-C$25),0),Assumptions!$B$12*DCF_base!L22))/(1+$A$26)^10-Assumptions!$B$8-Assumptions!$B$9)/Assumptions!$B$10 | D26: =(SUMPRODUCT(DCF_base!C22:L22/(1+$A$26)^DCF_base!C4:L4)+MAX(0,MIN(IF($A$26>D$25,DCF_base!L22*(1+D$25)/($A$26-D$25),0),Assumptions!$B$12*DCF_base!L22))/(1+$A$26)^10-Assumptions!$B$8-Assumptions!$B$9)/Assumptions!$B$10 | E26: =(SUMPRODUCT(DCF_base!C22:L22/(1+$A$26)^DCF_base!C4:L4)+MAX(0,MIN(IF($A$26>E$25,DCF_base!L22*(1+E$25)/($A$26-E$25),0),Assumptions!$B$12*DCF_base!L22))/(1+$A$26)^10-Assumptions!$B$8-Assumptions!$B$9)/Assumptions!$B$10 | F26: =(SUMPRODUCT(DCF_base!C22:L22/(1+$A$26)^DCF_base!C4:L4)+MAX(0,MIN(IF($A$26>F$25,DCF_base!L22*(1+F$25)/($A$26-F$25),0),Assumptions!$B$12*DCF_base!L22))/(1+$A$26)^10-Assumptions!$B$8-Assumptions!$B$9)/Assumptions!$B$10
A27: 0.085 | B27: =(SUMPRODUCT(DCF_base!C22:L22/(1+$A$27)^DCF_base!C4:L4)+MAX(0,MIN(IF($A$27>B$25,DCF_base!L22*(1+B$25)/($A$27-B$25),0),Assumptions!$B$12*DCF_base!L22))/(1+$A$27)^10-Assumptions!$B$8-Assumptions!$B$9)/Assumptions!$B$10 | C27: =(SUMPRODUCT(DCF_base!C22:L22/(1+$A$27)^DCF_base!C4:L4)+MAX(0,MIN(IF($A$27>C$25,DCF_base!L22*(1+C$25)/($A$27-C$25),0),Assumptions!$B$12*DCF_base!L22))/(1+$A$27)^10-Assumptions!$B$8-Assumptions!$B$9)/Assumptions!$B$10 | D27: =(SUMPRODUCT(DCF_base!C22:L22/(1+$A$27)^DCF_base!C4:L4)+MAX(0,MIN(IF($A$27>D$25,DCF_base!L22*(1+D$25)/($A$27-D$25),0),Assumptions!$B$12*DCF_base!L22))/(1+$A$27)^10-Assumptions!$B$8-Assumptions!$B$9)/Assumptions!$B$10 | E27: =(SUMPRODUCT(DCF_base!C22:L22/(1+$A$27)^DCF_base!C4:L4)+MAX(0,MIN(IF($A$27>E$25,DCF_base!L22*(1+E$25)/($A$27-E$25),0),Assumptions!$B$12*DCF_base!L22))/(1+$A$27)^10-Assumptions!$B$8-Assumptions!$B$9)/Assumptions!$B$10 | F27: =(SUMPRODUCT(DCF_base!C22:L22/(1+$A$27)^DCF_base!C4:L4)+MAX(0,MIN(IF($A$27>F$25,DCF_base!L22*(1+F$25)/($A$27-F$25),0),Assumptions!$B$12*DCF_base!L22))/(1+$A$27)^10-Assumptions!$B$8-Assumptions!$B$9)/Assumptions!$B$10
A28: 0.095 | B28: =(SUMPRODUCT(DCF_base!C22:L22/(1+$A$28)^DCF_base!C4:L4)+MAX(0,MIN(IF($A$28>B$25,DCF_base!L22*(1+B$25)/($A$28-B$25),0),Assumptions!$B$12*DCF_base!L22))/(1+$A$28)^10-Assumptions!$B$8-Assumptions!$B$9)/Assumptions!$B$10 | C28: =(SUMPRODUCT(DCF_base!C22:L22/(1+$A$28)^DCF_base!C4:L4)+MAX(0,MIN(IF($A$28>C$25,DCF_base!L22*(1+C$25)/($A$28-C$25),0),Assumptions!$B$12*DCF_base!L22))/(1+$A$28)^10-Assumptions!$B$8-Assumptions!$B$9)/Assumptions!$B$10 | D28: =(SUMPRODUCT(DCF_base!C22:L22/(1+$A$28)^DCF_base!C4:L4)+MAX(0,MIN(IF($A$28>D$25,DCF_base!L22*(1+D$25)/($A$28-D$25),0),Assumptions!$B$12*DCF_base!L22))/(1+$A$28)^10-Assumptions!$B$8-Assumptions!$B$9)/Assumptions!$B$10 | E28: =(SUMPRODUCT(DCF_base!C22:L22/(1+$A$28)^DCF_base!C4:L4)+MAX(0,MIN(IF($A$28>E$25,DCF_base!L22*(1+E$25)/($A$28-E$25),0),Assumptions!$B$12*DCF_base!L22))/(1+$A$28)^10-Assumptions!$B$8-Assumptions!$B$9)/Assumptions!$B$10 | F28: =(SUMPRODUCT(DCF_base!C22:L22/(1+$A$28)^DCF_base!C4:L4)+MAX(0,MIN(IF($A$28>F$25,DCF_base!L22*(1+F$25)/($A$28-F$25),0),Assumptions!$B$12*DCF_base!L22))/(1+$A$28)^10-Assumptions!$B$8-Assumptions!$B$9)/Assumptions!$B$10
A29: 0.105 | B29: =(SUMPRODUCT(DCF_base!C22:L22/(1+$A$29)^DCF_base!C4:L4)+MAX(0,MIN(IF($A$29>B$25,DCF_base!L22*(1+B$25)/($A$29-B$25),0),Assumptions!$B$12*DCF_base!L22))/(1+$A$29)^10-Assumptions!$B$8-Assumptions!$B$9)/Assumptions!$B$10 | C29: =(SUMPRODUCT(DCF_base!C22:L22/(1+$A$29)^DCF_base!C4:L4)+MAX(0,MIN(IF($A$29>C$25,DCF_base!L22*(1+C$25)/($A$29-C$25),0),Assumptions!$B$12*DCF_base!L22))/(1+$A$29)^10-Assumptions!$B$8-Assumptions!$B$9)/Assumptions!$B$10 | D29: =(SUMPRODUCT(DCF_base!C22:L22/(1+$A$29)^DCF_base!C4:L4)+MAX(0,MIN(IF($A$29>D$25,DCF_base!L22*(1+D$25)/($A$29-D$25),0),Assumptions!$B$12*DCF_base!L22))/(1+$A$29)^10-Assumptions!$B$8-Assumptions!$B$9)/Assumptions!$B$10 | E29: =(SUMPRODUCT(DCF_base!C22:L22/(1+$A$29)^DCF_base!C4:L4)+MAX(0,MIN(IF($A$29>E$25,DCF_base!L22*(1+E$25)/($A$29-E$25),0),Assumptions!$B$12*DCF_base!L22))/(1+$A$29)^10-Assumptions!$B$8-Assumptions!$B$9)/Assumptions!$B$10 | F29: =(SUMPRODUCT(DCF_base!C22:L22/(1+$A$29)^DCF_base!C4:L4)+MAX(0,MIN(IF($A$29>F$25,DCF_base!L22*(1+F$25)/($A$29-F$25),0),Assumptions!$B$12*DCF_base!L22))/(1+$A$29)^10-Assumptions!$B$8-Assumptions!$B$9)/Assumptions!$B$10
A30: 0.115 | B30: =(SUMPRODUCT(DCF_base!C22:L22/(1+$A$30)^DCF_base!C4:L4)+MAX(0,MIN(IF($A$30>B$25,DCF_base!L22*(1+B$25)/($A$30-B$25),0),Assumptions!$B$12*DCF_base!L22))/(1+$A$30)^10-Assumptions!$B$8-Assumptions!$B$9)/Assumptions!$B$10 | C30: =(SUMPRODUCT(DCF_base!C22:L22/(1+$A$30)^DCF_base!C4:L4)+MAX(0,MIN(IF($A$30>C$25,DCF_base!L22*(1+C$25)/($A$30-C$25),0),Assumptions!$B$12*DCF_base!L22))/(1+$A$30)^10-Assumptions!$B$8-Assumptions!$B$9)/Assumptions!$B$10 | D30: =(SUMPRODUCT(DCF_base!C22:L22/(1+$A$30)^DCF_base!C4:L4)+MAX(0,MIN(IF($A$30>D$25,DCF_base!L22*(1+D$25)/($A$30-D$25),0),Assumptions!$B$12*DCF_base!L22))/(1+$A$30)^10-Assumptions!$B$8-Assumptions!$B$9)/Assumptions!$B$10 | E30: =(SUMPRODUCT(DCF_base!C22:L22/(1+$A$30)^DCF_base!C4:L4)+MAX(0,MIN(IF($A$30>E$25,DCF_base!L22*(1+E$25)/($A$30-E$25),0),Assumptions!$B$12*DCF_base!L22))/(1+$A$30)^10-Assumptions!$B$8-Assumptions!$B$9)/Assumptions!$B$10 | F30: =(SUMPRODUCT(DCF_base!C22:L22/(1+$A$30)^DCF_base!C4:L4)+MAX(0,MIN(IF($A$30>F$25,DCF_base!L22*(1+F$25)/($A$30-F$25),0),Assumptions!$B$12*DCF_base!L22))/(1+$A$30)^10-Assumptions!$B$8-Assumptions!$B$9)/Assumptions!$B$10
