Workbook

Sheet DCF Model
A1: FPH.NZ DCF Valuation Model (Fisher & Paykel Healthcare)
A2: Gray cells are INPUTS - adjust to see valuation change. All figures NZ$ millions unless noted.
A4: KEY INPUTS
A5: Current Stock Price (NZD) | B5: 42.58
A6: Shares Outstanding (M) | B6: 587.3
A7: Cash & Equivalents (M) | B7: 461.1
A8: Total Debt (M) | B8: 59.8
A9: Net Debt (M) [negative = net cash] | B9: =B8-B7 -> 0
A10: Reported FCF FY2026 (M) | B10: 468
A11: Less: SBC incl. equity-award taxes (M) | B11: 13.9
A12: Less: Interest Income (M) | B12: 8.2
A13: Base Year Owner FCF (M) | B13: =B10-B11-B12 -> 0
A14: Annual Share Growth (uncovered dilution) | B14: 0.000556
A16: WACC (Base) | B16: 0.09
A17: Terminal Growth Rate (Base) | B17: 0.035
A18: Terminal Cap Multiple (Base) | B18: 20
A20: BASE CASE COMPONENT ASSUMPTIONS
B22: FY2027 | C22: FY2028 | D22: FY2029 | E22: FY2030 | F22: FY2031 | G22: FY2032 | H22: FY2033 | I22: FY2034 | J22: FY2035 | K22: FY2036
A23: Revenue Growth % | B23: 0.087 | C23: 0.105 | D23: 0.105 | E23: 0.095 | F23: 0.085 | G23: 0.075 | H23: 0.065 | I23: 0.055 | J23: 0.045 | K23: 0.04
A24: EBITDA Margin % | B24: 0.344 | C24: 0.348 | D24: 0.352 | E24: 0.356 | F24: 0.359 | G24: 0.361 | H24: 0.363 | I24: 0.364 | J24: 0.365 | K24: 0.365
A25: SBC % of Revenue | B25: 0.006 | C25: 0.006 | D25: 0.006 | E25: 0.006 | F25: 0.006 | G25: 0.006 | H25: 0.006 | I25: 0.006 | J25: 0.006 | K25: 0.006
A26: D&A % of Revenue | B26: 0.072 | C26: 0.078 | D26: 0.083 | E26: 0.085 | F26: 0.083 | G26: 0.08 | H26: 0.077 | I26: 0.075 | J26: 0.073 | K26: 0.072
A27: Capex % of Revenue | B27: 0.095 | C27: 0.098 | D27: 0.09 | E27: 0.08 | F27: 0.075 | G27: 0.07 | H27: 0.068 | I27: 0.066 | J27: 0.065 | K27: 0.065
A28: Cash Tax Rate % | B28: 0.258 | C28: 0.258 | D28: 0.26 | E28: 0.26 | F28: 0.265 | G28: 0.265 | H28: 0.27 | I28: 0.27 | J28: 0.27 | K28: 0.27
A29: WC Capture % of Rev Increase | B29: 0.17
A31: PROJECTIONS (Base Case)
B32: FY2027 | C32: FY2028 | D32: FY2029 | E32: FY2030 | F32: FY2031 | G32: FY2032 | H32: FY2033 | I32: FY2034 | J32: FY2035 | K32: FY2036
A33: Revenue | B33: =2308.4*(1+B23) -> 0 | C33: =B33*(1+C23) -> 0 | D33: =C33*(1+D23) -> 0 | E33: =D33*(1+E23) -> 0 | F33: =E33*(1+F23) -> 0 | G33: =F33*(1+G23) -> 0 | H33: =G33*(1+H23) -> 0 | I33: =H33*(1+I23) -> 0 | J33: =I33*(1+J23) -> 0 | K33: =J33*(1+K23) -> 0
A34: Adj. EBITDA | B34: =B33*B24 -> 0 | C34: =C33*C24 -> 0 | D34: =D33*D24 -> 0 | E34: =E33*E24 -> 0 | F34: =F33*F24 -> 0 | G34: =G33*G24 -> 0 | H34: =H33*H24 -> 0 | I34: =I33*I24 -> 0 | ... K34: =K33*K24 -> 0
A35: Less: SBC | B35: =B33*B25 -> 0 | C35: =C33*C25 -> 0 | D35: =D33*D25 -> 0 | E35: =E33*E25 -> 0 | F35: =F33*F25 -> 0 | G35: =G33*G25 -> 0 | H35: =H33*H25 -> 0 | I35: =I33*I25 -> 0 | ... K35: =K33*K25 -> 0
A36: Less: D&A | B36: =B33*B26 -> 0 | C36: =C33*C26 -> 0 | D36: =D33*D26 -> 0 | E36: =E33*E26 -> 0 | F36: =F33*F26 -> 0 | G36: =G33*G26 -> 0 | H36: =H33*H26 -> 0 | I36: =I33*I26 -> 0 | ... K36: =K33*K26 -> 0
A37: EBIT (owner, after SBC) | B37: =B34-B35-B36 -> 0 | C37: =C34-C35-C36 -> 0 | D37: =D34-D35-D36 -> 0 | E37: =E34-E35-E36 -> 0 | F37: =F34-F35-F36 -> 0 | G37: =G34-G35-G36 -> 0 | H37: =H34-H35-H36 -> 0 | I37: =I34-I35-I36 -> 0 | ... K37: =K34-K35-K36 -> 0
A38: NOPAT | B38: =B37*(1-B28) -> 0 | C38: =C37*(1-C28) -> 0 | D38: =D37*(1-D28) -> 0 | E38: =E37*(1-E28) -> 0 | F38: =F37*(1-F28) -> 0 | G38: =G37*(1-G28) -> 0 | H38: =H37*(1-H28) -> 0 | I38: =I37*(1-I28) -> 0 | ... K38: =K37*(1-K28) -> 0
A39: Less: Capex | B39: =B33*B27 -> 0 | C39: =C33*C27 -> 0 | D39: =D33*D27 -> 0 | E39: =E33*E27 -> 0 | F39: =F33*F27 -> 0 | G39: =G33*G27 -> 0 | H39: =H33*H27 -> 0 | I39: =I33*I27 -> 0 | ... K39: =K33*K27 -> 0
A40: Less: Working Capital (on rev change) | B40: =$B$29*(B33-2308.4) -> 0 | C40: =$B$29*(C33-B33) -> 0 | D40: =$B$29*(D33-C33) -> 0 | E40: =$B$29*(E33-D33) -> 0 | F40: =$B$29*(F33-E33) -> 0 | G40: =$B$29*(G33-F33) -> 0 | H40: =$B$29*(H33-G33) -> 0 | I40: =$B$29*(I33-H33) -> 0 | J40: =$B$29*(J33-I33) -> 0 | K40: =$B$29*(K33-J33) -> 0
A41: Owner FCF | B41: =B38+B36-B39-B40 -> 0 | C41: =C38+C36-C39-C40 -> 0 | D41: =D38+D36-D39-D40 -> 0 | E41: =E38+E36-E39-E40 -> 0 | F41: =F38+F36-F39-F40 -> 0 | G41: =G38+G36-G39-G40 -> 0 | H41: =H38+H36-H39-H40 -> 0 | I41: =I38+I36-I39-I40 -> 0 | ... K41: =K38+K36-K39-K40 -> 0
A42: Owner FCF Margin % | B42: =B41/B33 -> 0 | C42: =C41/C33 -> 0 | D42: =D41/D33 -> 0 | E42: =E41/E33 -> 0 | F42: =F41/F33 -> 0 | G42: =G41/G33 -> 0 | H42: =H41/H33 -> 0 | I42: =I41/I33 -> 0 | ... K42: =K41/K33 -> 0
A43: Shares Outstanding (M) | B43: =$B$6*(1+$B$14) -> 0 | C43: =B43*(1+$B$14) -> 0 | D43: =C43*(1+$B$14) -> 0 | E43: =D43*(1+$B$14) -> 0 | F43: =E43*(1+$B$14) -> 0 | G43: =F43*(1+$B$14) -> 0 | H43: =G43*(1+$B$14) -> 0 | I43: =H43*(1+$B$14) -> 0 | J43: =I43*(1+$B$14) -> 0 | K43: =J43*(1+$B$14) -> 0
A44: Discount Factor | B44: =1/(1+$B$16)^1 -> 0 | C44: =1/(1+$B$16)^2 -> 0 | D44: =1/(1+$B$16)^3 -> 0 | E44: =1/(1+$B$16)^4 -> 0 | F44: =1/(1+$B$16)^5 -> 0 | G44: =1/(1+$B$16)^6 -> 0 | H44: =1/(1+$B$16)^7 -> 0 | I44: =1/(1+$B$16)^8 -> 0 | J44: =1/(1+$B$16)^9 -> 0 | K44: =1/(1+$B$16)^10 -> 0
A45: PV of Owner FCF | B45: =B41*B44 -> 0 | C45: =C41*C44 -> 0 | D45: =D41*D44 -> 0 | E45: =E41*E44 -> 0 | F45: =F41*F44 -> 0 | G45: =G41*G44 -> 0 | H45: =H41*H44 -> 0 | I45: =I41*I44 -> 0 | ... K45: =K41*K44 -> 0
...

Sheet Sensitivity
A1: Sensitivity Analysis (Base Case)
A2: Intrinsic Value by WACC & Terminal Growth
A4: WACC \ Term G | B4: 0.025 | C4: 0.03 | D4: 0.035 | E4: 0.04 | F4: 0.045
A5: 0.07 | B5: =(SUMPRODUCT('DCF Model'!$B$41:$K$41,1/(1+0.07)^(COLUMN('DCF Model'!$B$41:$K$41)-COLUMN('DCF Model'!$B$41)+1))+MIN('DCF Model'!$K$41*(1+0.025)/(0.07-0.025),'DCF Model'!$B$18*'DCF Model'!$K$41)/(1+0.07)^10-'DCF Model'!$B$9)/'DCF Model'!$K$43 -> 0 | C5: =(SUMPRODUCT('DCF Model'!$B$41:$K$41,1/(1+0.07)^(COLUMN('DCF Model'!$B$41:$K$41)-COLUMN('DCF Model'!$B$41)+1))+MIN('DCF Model'!$K$41*(1+0.03)/(0.07-0.03),'DCF Model'!$B$18*'DCF Model'!$K$41)/(1+0.07)^10-'DCF Model'!$B$9)/'DCF Model'!$K$43 -> 0 | D5: =(SUMPRODUCT('DCF Model'!$B$41:$K$41,1/(1+0.07)^(COLUMN('DCF Model'!$B$41:$K$41)-COLUMN('DCF Model'!$B$41)+1))+MIN('DCF Model'!$K$41*(1+0.035)/(0.07-0.035),'DCF Model'!$B$18*'DCF Model'!$K$41)/(1+0.07)^10-'DCF Model'!$B$9)/'DCF Model'!$K$43 -> 0 | E5: =(SUMPRODUCT('DCF Model'!$B$41:$K$41,1/(1+0.07)^(COLUMN('DCF Model'!$B$41:$K$41)-COLUMN('DCF Model'!$B$41)+1))+MIN('DCF Model'!$K$41*(1+0.04)/(0.07-0.04),'DCF Model'!$B$18*'DCF Model'!$K$41)/(1+0.07)^10-'DCF Model'!$B$9)/'DCF Model'!$K$43 -> 0 | F5: =(SUMPRODUCT('DCF Model'!$B$41:$K$41,1/(1+0.07)^(COLUMN('DCF Model'!$B$41:$K$41)-COLUMN('DCF Model'!$B$41)+1))+MIN('DCF Model'!$K$41*(1+0.045)/(0.07-0.045),'DCF Model'!$B$18*'DCF Model'!$K$41)/(1+0.07)^10-'DCF Model'!$B$9)/'DCF Model'!$K$43 -> 0
A6: 0.08 | B6: =(SUMPRODUCT('DCF Model'!$B$41:$K$41,1/(1+0.08)^(COLUMN('DCF Model'!$B$41:$K$41)-COLUMN('DCF Model'!$B$41)+1))+MIN('DCF Model'!$K$41*(1+0.025)/(0.08-0.025),'DCF Model'!$B$18*'DCF Model'!$K$41)/(1+0.08)^10-'DCF Model'!$B$9)/'DCF Model'!$K$43 -> 0 | C6: =(SUMPRODUCT('DCF Model'!$B$41:$K$41,1/(1+0.08)^(COLUMN('DCF Model'!$B$41:$K$41)-COLUMN('DCF Model'!$B$41)+1))+MIN('DCF Model'!$K$41*(1+0.03)/(0.08-0.03),'DCF Model'!$B$18*'DCF Model'!$K$41)/(1+0.08)^10-'DCF Model'!$B$9)/'DCF Model'!$K$43 -> 0 | D6: =(SUMPRODUCT('DCF Model'!$B$41:$K$41,1/(1+0.08)^(COLUMN('DCF Model'!$B$41:$K$41)-COLUMN('DCF Model'!$B$41)+1))+MIN('DCF Model'!$K$41*(1+0.035)/(0.08-0.035),'DCF Model'!$B$18*'DCF Model'!$K$41)/(1+0.08)^10-'DCF Model'!$B$9)/'DCF Model'!$K$43 -> 0 | E6: =(SUMPRODUCT('DCF Model'!$B$41:$K$41,1/(1+0.08)^(COLUMN('DCF Model'!$B$41:$K$41)-COLUMN('DCF Model'!$B$41)+1))+MIN('DCF Model'!$K$41*(1+0.04)/(0.08-0.04),'DCF Model'!$B$18*'DCF Model'!$K$41)/(1+0.08)^10-'DCF Model'!$B$9)/'DCF Model'!$K$43 -> 0 | F6: =(SUMPRODUCT('DCF Model'!$B$41:$K$41,1/(1+0.08)^(COLUMN('DCF Model'!$B$41:$K$41)-COLUMN('DCF Model'!$B$41)+1))+MIN('DCF Model'!$K$41*(1+0.045)/(0.08-0.045),'DCF Model'!$B$18*'DCF Model'!$K$41)/(1+0.08)^10-'DCF Model'!$B$9)/'DCF Model'!$K$43 -> 0
A7: 0.09 | B7: =(SUMPRODUCT('DCF Model'!$B$41:$K$41,1/(1+0.09)^(COLUMN('DCF Model'!$B$41:$K$41)-COLUMN('DCF Model'!$B$41)+1))+MIN('DCF Model'!$K$41*(1+0.025)/(0.09-0.025),'DCF Model'!$B$18*'DCF Model'!$K$41)/(1+0.09)^10-'DCF Model'!$B$9)/'DCF Model'!$K$43 -> 0 | C7: =(SUMPRODUCT('DCF Model'!$B$41:$K$41,1/(1+0.09)^(COLUMN('DCF Model'!$B$41:$K$41)-COLUMN('DCF Model'!$B$41)+1))+MIN('DCF Model'!$K$41*(1+0.03)/(0.09-0.03),'DCF Model'!$B$18*'DCF Model'!$K$41)/(1+0.09)^10-'DCF Model'!$B$9)/'DCF Model'!$K$43 -> 0 | D7: =(SUMPRODUCT('DCF Model'!$B$41:$K$41,1/(1+0.09)^(COLUMN('DCF Model'!$B$41:$K$41)-COLUMN('DCF Model'!$B$41)+1))+MIN('DCF Model'!$K$41*(1+0.035)/(0.09-0.035),'DCF Model'!$B$18*'DCF Model'!$K$41)/(1+0.09)^10-'DCF Model'!$B$9)/'DCF Model'!$K$43 -> 0 | E7: =(SUMPRODUCT('DCF Model'!$B$41:$K$41,1/(1+0.09)^(COLUMN('DCF Model'!$B$41:$K$41)-COLUMN('DCF Model'!$B$41)+1))+MIN('DCF Model'!$K$41*(1+0.04)/(0.09-0.04),'DCF Model'!$B$18*'DCF Model'!$K$41)/(1+0.09)^10-'DCF Model'!$B$9)/'DCF Model'!$K$43 -> 0 | F7: =(SUMPRODUCT('DCF Model'!$B$41:$K$41,1/(1+0.09)^(COLUMN('DCF Model'!$B$41:$K$41)-COLUMN('DCF Model'!$B$41)+1))+MIN('DCF Model'!$K$41*(1+0.045)/(0.09-0.045),'DCF Model'!$B$18*'DCF Model'!$K$41)/(1+0.09)^10-'DCF Model'!$B$9)/'DCF Model'!$K$43 -> 0
A8: 0.1 | B8: =(SUMPRODUCT('DCF Model'!$B$41:$K$41,1/(1+0.1)^(COLUMN('DCF Model'!$B$41:$K$41)-COLUMN('DCF Model'!$B$41)+1))+MIN('DCF Model'!$K$41*(1+0.025)/(0.1-0.025),'DCF Model'!$B$18*'DCF Model'!$K$41)/(1+0.1)^10-'DCF Model'!$B$9)/'DCF Model'!$K$43 -> 0 | C8: =(SUMPRODUCT('DCF Model'!$B$41:$K$41,1/(1+0.1)^(COLUMN('DCF Model'!$B$41:$K$41)-COLUMN('DCF Model'!$B$41)+1))+MIN('DCF Model'!$K$41*(1+0.03)/(0.1-0.03),'DCF Model'!$B$18*'DCF Model'!$K$41)/(1+0.1)^10-'DCF Model'!$B$9)/'DCF Model'!$K$43 -> 0 | D8: =(SUMPRODUCT('DCF Model'!$B$41:$K$41,1/(1+0.1)^(COLUMN('DCF Model'!$B$41:$K$41)-COLUMN('DCF Model'!$B$41)+1))+MIN('DCF Model'!$K$41*(1+0.035)/(0.1-0.035),'DCF Model'!$B$18*'DCF Model'!$K$41)/(1+0.1)^10-'DCF Model'!$B$9)/'DCF Model'!$K$43 -> 0 | E8: =(SUMPRODUCT('DCF Model'!$B$41:$K$41,1/(1+0.1)^(COLUMN('DCF Model'!$B$41:$K$41)-COLUMN('DCF Model'!$B$41)+1))+MIN('DCF Model'!$K$41*(1+0.04)/(0.1-0.04),'DCF Model'!$B$18*'DCF Model'!$K$41)/(1+0.1)^10-'DCF Model'!$B$9)/'DCF Model'!$K$43 -> 0 | F8: =(SUMPRODUCT('DCF Model'!$B$41:$K$41,1/(1+0.1)^(COLUMN('DCF Model'!$B$41:$K$41)-COLUMN('DCF Model'!$B$41)+1))+MIN('DCF Model'!$K$41*(1+0.045)/(0.1-0.045),'DCF Model'!$B$18*'DCF Model'!$K$41)/(1+0.1)^10-'DCF Model'!$B$9)/'DCF Model'!$K$43 -> 0
A9: 0.11 | B9: =(SUMPRODUCT('DCF Model'!$B$41:$K$41,1/(1+0.11)^(COLUMN('DCF Model'!$B$41:$K$41)-COLUMN('DCF Model'!$B$41)+1))+MIN('DCF Model'!$K$41*(1+0.025)/(0.11-0.025),'DCF Model'!$B$18*'DCF Model'!$K$41)/(1+0.11)^10-'DCF Model'!$B$9)/'DCF Model'!$K$43 -> 0 | C9: =(SUMPRODUCT('DCF Model'!$B$41:$K$41,1/(1+0.11)^(COLUMN('DCF Model'!$B$41:$K$41)-COLUMN('DCF Model'!$B$41)+1))+MIN('DCF Model'!$K$41*(1+0.03)/(0.11-0.03),'DCF Model'!$B$18*'DCF Model'!$K$41)/(1+0.11)^10-'DCF Model'!$B$9)/'DCF Model'!$K$43 -> 0 | D9: =(SUMPRODUCT('DCF Model'!$B$41:$K$41,1/(1+0.11)^(COLUMN('DCF Model'!$B$41:$K$41)-COLUMN('DCF Model'!$B$41)+1))+MIN('DCF Model'!$K$41*(1+0.035)/(0.11-0.035),'DCF Model'!$B$18*'DCF Model'!$K$41)/(1+0.11)^10-'DCF Model'!$B$9)/'DCF Model'!$K$43 -> 0 | E9: =(SUMPRODUCT('DCF Model'!$B$41:$K$41,1/(1+0.11)^(COLUMN('DCF Model'!$B$41:$K$41)-COLUMN('DCF Model'!$B$41)+1))+MIN('DCF Model'!$K$41*(1+0.04)/(0.11-0.04),'DCF Model'!$B$18*'DCF Model'!$K$41)/(1+0.11)^10-'DCF Model'!$B$9)/'DCF Model'!$K$43 -> 0 | F9: =(SUMPRODUCT('DCF Model'!$B$41:$K$41,1/(1+0.11)^(COLUMN('DCF Model'!$B$41:$K$41)-COLUMN('DCF Model'!$B$41)+1))+MIN('DCF Model'!$K$41*(1+0.045)/(0.11-0.045),'DCF Model'!$B$18*'DCF Model'!$K$41)/(1+0.11)^10-'DCF Model'!$B$9)/'DCF Model'!$K$43 -> 0
A11: Note: array-style SUMPRODUCT formula recomputes full 10yr DCF at each
A12: WACC/terminal-growth combination using the Base Case FCF path fixed.

Sheet FCF Quality
A1: FCF Quality: Reported vs Owner FCF
A2: Reconciliation across available historical years (NZ$ millions)
B4: FY2018 | C4: FY2019 | D4: FY2020 | E4: FY2021 | F4: FY2022 | G4: FY2023 | H4: FY2024 | I4: FY2025 | J4: FY2026
A5: Reported FCF (company definition) | B5: 149.1 | C5: 120 | D5: 150.7 | E5: 440.6 | F5: 154.5 | G5: 26.9 | H5: 90.6 | I5: 445.6 | J5: 468
A6: Less: SBC incl. equity-award taxes | B6: 4.9 | C6: 5.5 | D6: 6.1 | E6: 7.7 | F6: 8.1 | G6: 9 | H6: 10.8 | I6: 11.2 | J6: 13.9
A7: Less: Interest Income | B7: 1.6 | C7: 3.3 | D7: 2.2 | E7: 1.5 | F7: 2.6 | G7: 2.6 | H7: 3.3 | I7: 4.3 | J7: 8.2
A8: Owner FCF | B8: =B5-B6-B7 -> 0 | C8: =C5-C6-C7 -> 0 | D8: =D5-D6-D7 -> 0 | E8: =E5-E6-E7 -> 0 | F8: =F5-F6-F7 -> 0 | G8: =G5-G6-G7 -> 0 | H8: =H5-H6-H7 -> 0 | I8: =I5-I6-I7 -> 0 | J8: =J5-J6-J7 -> 0
A9: Reported FCF Margin % | B9: =B5/B10 -> 0 | C9: =C5/C10 -> 0 | D9: =D5/D10 -> 0 | E9: =E5/E10 -> 0 | F9: =F5/F10 -> 0 | G9: =G5/G10 -> 0 | H9: =H5/H10 -> 0 | I9: =I5/I10 -> 0 | J9: =J5/J10 -> 0
A10: Revenue (memo) | B10: 980.8 | C10: 1070.4 | D10: 1263.7 | E10: 1971.2 | F10: 1681.7 | G10: 1581.1 | H10: 1742.8 | I10: 2021 | J10: 2308.4
A11: Owner FCF Margin % | B11: =B8/B10 -> 0 | C11: =C8/C10 -> 0 | D11: =D8/D10 -> 0 | E11: =E8/E10 -> 0 | F11: =F8/F10 -> 0 | G11: =G8/G10 -> 0 | H11: =H8/H10 -> 0 | I11: =I8/I10 -> 0 | J11: =J8/J10 -> 0
A13: Memo: Cash tax rate (effective, %) | B13: 0.29 | C13: 0.282 | D13: 0.225 | E13: 0.27 | F13: 0.252 | G13: 0.237 | H13: 0.437 | I13: 0.251 | J13: 0.258
A14: FY2024 flagged: 43.7% is abnormal (recall provision
A15: + $98.1m land revaluation charge + NZ depreciation tax law change
A16: distorted both numerator (NPAT) and effective rate; underlying
A17: NPAT for FY2024 was $264.4m per company disclosure).
A19: Note: FPH is NOT a deferred-revenue/subscription business, so unlike
A20: SaaS names, historical OCF is not inflated by deferred-revenue timing.
A21: FY2026 capex ($195.2m) is LOW relative to the FY2023-26 average (~$210m)
A22: and the ongoing capex supercycle (5th East Tamaki bldg, Karaka, Mexico,
A23: China) — do not extrapolate FY2026 reported FCF margin flat forward.
A25: SBC as % of Revenue (FY2026) | B25: 0.0060214867
A26: FPH funds equity comp via employee share schemes / DRP, NOT net-settled
A27: RSUs, so equity_award_taxes = 0 in the KPI table (no separate cash tax
A28: withholding outflow on vesting to add). Buybacks = 0 (FPH has never run
A29: a repurchase program) so 100% of SBC is uncovered/dilutive (small: ~0.06%/yr).

Sheet Historical
A1: Historical Growth Rates
A2: Standard 3yr/5yr CAGR windows are COVID-distorted for FPH — see notes.
A4: Metric | B4: Value
A5: Revenue 3yr CAGR (distorted, low base) | B5: 0.134
A6: Revenue 5yr CAGR (COVID-distorted) | B6: 0.032
A7: Revenue FY19-FY26 through-cycle CAGR | B7: 0.116
A8: EPS FY19-FY26 through-cycle CAGR | B8: 0.118
A9: Equity FY19-FY26 through-cycle CAGR | B9: 0.128
A11: Selected Growth Rate (DCF Year-1 anchor basis): | B11: 0.116
A12: Source: | B12: revenue_through_cycle_cagr_fy19_fy26
A14: FY2027 explicit guidance (anchors Year 1):
A15: Revenue NZ$2.45-2.57bn (mid NZ$2.51bn); NPAT NZ$500-550m (mid NZ$525m)
A17: Standard trailing 3yr/5yr CAGR windows are unusable for FPH: any window starting or ending in FY2021/FY2022 is COVID-hardware-pull-forward distorted (5yr revenue CAGR of only 3.2% reflects the post-COVID consumables/utilisation normalization, not a growth slowdown), and the 3yr window (13.4%) is inflated by the low FY2023 base. Per ticker guidance, the FY2019->FY2026 through-cycle CAGR (spanning one full pre-COVID to post-COVID cycle) is used instead: revenue 11.6%, EPS 11.8%, shareholders' equity 12.8%, NPAT 12.2% — all clustered within a few points of each other (no >30% divergence flag needed). FY2024 NPAT/EPS (7.6% margin, 22.8cps) is a genuine reported low from a product recall + $98.1m land revaluation charge + an NZ building-depreciation tax law change; FPH's own underlying NPAT for FY2024 was $264.4m (15.2% margin) — the through-cycle CAGR calc uses reported FY2026 vs reported FY2019 endpoints so this one-off does not touch the anchor years, but readers should not mistake FY2024 for a genuine cyclical trough when eyeballing the raw series.

Sheet Sanity Check
A1: Valuation Sanity Check: Historical Multiples
A2: March fiscal-year-end closes, 10yr Yahoo Finance history
A5: FY | B5: Price | C5: P/E | D5: P/B | E5: EV/EBITDA | F5: P/S | G5: Excluded?
A6: FY2018 | B6: 13.2 | C6: 39.5 | D6: 9.9 | E6: 24.1 | F6: 7.69
A7: FY2019 | B7: 15.7 | C7: 43 | D7: 9.86 | E7: 27.1 | F7: 8.41
A8: FY2020 | B8: 30.38 | C8: 60.8 | D8: 17.93 | E8: 39.7 | F8: 13.81
A9: FY2021 | B9: 32.1 | C9: 35.2 | D9: 12.17 | E9: 23.2 | F9: 9.39 | G9: COVID hardware pull-forward
A10: FY2022 | B10: 24.35 | C10: 37.3 | D10: 8.37 | E10: 23.3 | F10: 8.36 | G10: COVID normalization
A11: FY2023 | B11: 26.65 | C11: 61.5 | D11: 8.81 | E11: 35.7 | F11: 9.77
A12: FY2024 | B12: 25.65 | C12: 112.5 | D12: 8.51 | E12: 32.1 | F12: 8.59 | G12: recall + land revaluation + tax law change depressed reported NPAT; underlying P/E ~56.7x
A13: FY2025 | B13: 33.54 | C13: 52.1 | D13: 10.4 | E13: 30 | F13: 9.73
A14: FY2026 | B14: 37.39 | C14: 46.9 | D14: 10.38 | E14: 27.1 | F14: 9.51
A16: Historical Avg (ex-outliers) | C16: 50.6 | D16: 11.2 | E16: 30.6 | F16: 9.8
A17: Current Price Multiples | C17: 53.4 | D17: 11.82 | E17: 30.9 | F17: 10.83
A18: Implied Multiples at Base IV | C18: 26.9 | D18: 5.96 | E18: 15.3 | F18: 5.46
A20: RESULT: | B20: PASS
A22: Current market price (P/E 53.4x, P/B 11.8x, EV/EBITDA 30.9x, P/S 10.8x) trades essentially IN LINE with FPH's own historical average premium multiples (ex-COVID/FY24: P/E 50.6x, P/B 11.2x, EV/EBITDA 30.6x, P/S 9.8x) — the market is not currently pricing FPH at an unusual extreme versus its own history. The base-case DCF's implied multiples (P/E 26.9x, P/B 6.0x, EV/EBITDA 15.4x, P/S 5.5x) sit well BELOW both the historical average and the current price. Per the ticker-specific guidance for this valuation, this is the expected and correct sanity-check outcome for FPH: the check exists to catch implied multiples that are IMPLAUSIBLY HIGH versus history (i.e., a DCF that has over-shot on optimism), and it PASSES cleanly here because the implied multiples are conservative, not inflated. No assumptions were adjusted to close this gap.

Sheet Model_Info
A1: Model Provenance & Methodology
A4: Ticker | B4: FPH.NZ (Fisher & Paykel Healthcare Corporation Limited, NZX/ASX: FPH)
A5: Built by | B5: Claude agent (DCF valuation skill), per project research pipeline
A6: Valuation date | B6: 2026-08-11
A7: Share price date/source | B7: NZ$42.58 — live quote via Yahoo Finance FPH.NZ chart API, fetched 2026-08-11 (regularMarketTime confirmed same-day, actively traded)
A8: Data vintage | B8: FY2026 (year ended 31 March 2026) annual result, 25-May-2026; FY2027 guidance revenue NZ$2.45-2.57bn / NPAT NZ$500-550m issued alongside FY2026 result
A9: Fiscal year | B9: Ends 31 March. FY2026 = year ended 31-Mar-2026 (most recent actual). Projections FY2027 (Year 1) through FY2036 (Year 10).
A10: Horizon | B10: 10-year explicit component build, per project policy — Year-5 owner-FCF margin (19.3%) is still materially below the Year-10 mature margin (21.0%), driven by the ongoing capex supercycle, so a 10yr horizon is required rather than 5yr.
A11: Methodology | B11: Component-built owner FCF: Revenue -> Adj. EBITDA (margin path) -> less SBC (% of revenue) -> less D&A (% of revenue, ramped up for new buildings then tapered) -> EBIT -> NOPAT (after ramped cash tax rate) -> +D&A -> less Capex (% of revenue, elevated during build years then taper to ~6.5% maintenance) -> less Working Capital (17% capture rate on YoY revenue INCREASE, not on revenue level) -> Owner FCF.
A12: SBC treatment | B12: FY2026 SBC $13.9m (0.60% of revenue) per Metrics.csv StockBasedComp. equity_award_taxes and buybacks both = 0 in DuckDB kpis (FPH funds equity comp via employee share schemes/DRP, not net-settled RSUs, and has never run a share repurchase program) — so 100% of SBC is uncovered dilution. This is a SMALL annual dilution effect (~0.056%/yr) unlike SBC-heavy tech names, because FPH SBC is <1% of revenue.
A13: Interest income treatment | B13: Stripped from owner FCF (NZ$8.2m FY2026) despite net cash/FCF ratio (0.86x) sitting just under the project 1x materiality threshold — done for consistency since net cash is added back to enterprise value at the end of the DCF, and the amount is immaterial (<2% of FCF) either way.
A14: Working capital | B14: Modelled as 17% (base case) of the YEAR-OVER-YEAR REVENUE INCREASE, not a flat % of revenue level — FPH carries heavy manufacturing inventory (NZ/Mexico/China) so a genuine WC drag scales with growth, consistent with project policy.
A15: Capex supercycle | B15: FY2026 actual capex $195.2m is LOW relative to the FY2023-26 average (~$210m) and does NOT reflect the ongoing build programme (5th East Tamaki building opening 2027, Karaka campus final land payment due Dec-2026, continued Mexico/China expansion). Capex % of revenue is modelled at 9.5-9.8% in Years 1-2 (peak build), tapering to ~6.5% maintenance by Year 8-10.
... A22: Staleness warning | B22: This model reflects data as of the valuation date above. Figures WILL go stale — re-check price, guidance, and capex actuals before relying on this model for a live investment decision.
