Workbook

Sheet Model_Info
A1: Amcor plc (AMC.AX / AMCR) -- owner-FCF DCF model
A2: Version | B2: 1.1 sanity-check fix pass 2026-09-21 (supersedes the 1.0 fresh build of the same day): mid-cycle margin paths, WACC 7.3% -> 7.8%, per-scenario exit EV/EBITDA caps (non-binding). See AMC.AX_DCF.json reconciliation + sanity_check.fix_applied.
A3: Built by | B3: dcf-analyst agent (Claude Fable 5.1), 2026-09-21, at the request of the research-stock orchestrator
A4: Model | B4: Owner-FCF DCF, 10-year component build, TV = max(0, min(Gordon, 15x FCF_10)), end-of-year discounting, SBC expensed and share count flat, street basis as memo
A5: Currency | B5: Flows and statements USD millions (US GAAP 10-K). Quote AUD (ASX CDI). Per-share values in USD converted to AUD at USD/AUD 1.4023 (AUDUSD 0.7131, Yahoo 2026-09-21T10:08Z). Parity: AMCR US$41.90 / 0.7131 = A$58.76 vs A$59.11 observed (0.6%).
A6: Price | B6: A$59.11 ASX regular close 2026-09-21T06:10:31Z (Yahoo AMC.AX). GOES STALE.
A7: Balance sheet | B7: 30-Jun-2026 10-K (filed 2026-08-14): net debt 12,897 (debt 14,012 - cash 1,115) + NCI 11 = 12,908 bridge. Operating leases (1,068) excluded (cost is inside EBITDA). GOES STALE at the Jul-Dec 2026 10-K/T.
A8: Share count | B8: 462.9m fully diluted: 462.3m issued - 0.4m treasury + 0.6m dilutive awards, all post the 1-for-5 reverse split of 14-Jan-2026. Held flat (SBC expensed).
A9: Base year | B9: FY2026 (Jul-2025 to Jun-2026) -- first full year with Berry Global (closed 30-Apr-2025). Revenue 23,506; adjusted EBITDA 3,673; adjusted EBIT 2,813; company FCF 1,303; SBC 83 + withholding 42.
A10: EBITDA basis | B10: ebitda margin rows are CASH-ADJUSTED: company adjusted EBITDA less the recurring 'Other' operating cash line (156 = 0.6% of revenue) in the company's adjusted-FCF reconciliation. Add ~0.6pp to compare with the company's adjusted EBITDA margin (15.6% FY2026).
A11: Guidance used | B11: Transition Period (Jul-Dec 2026) adjusted EPS $1.80-1.90 and leverage 3.5-3.6x at 31-Dec-2026; CY2027 'double-digit adjusted EPS growth'; $650m synergies by Jun-2028 ($285m captured FY2026); >$500m working-capital recovery (NOT in the flows).
A12: WACC | B12: 7.8% = 7.3% standard build (0.6 x 9.55% CoE [UST 4.2% + beta 1.07 x ERP 5.0%] + 0.4 x 4.0% after-tax Kd) + 0.5% fix-pass premium for the ~3.5x leverage / concurrent-integration window. Same in all scenarios (scenario risk charged once, in the flows and weights).
A13: Terminal value | B13: TV = MAX(0, MIN(Gordon, 15 x FCF_10, exit EV/EBITDA cap x EBITDA_10)). Exit caps bear 10.9x / base 14.0x / bull 15.2x from the sanity-check 10yr range; the 15x FCF cap (~8x terminal EBITDA) is the tighter constraint everywhere.
... A19: Verification | B19: Recalculated in LibreOffice headless with zero formula errors; DCF_*!B38 and Valuation!weighted tie to AMC.AX_DCF.json within rounding.

Sheet Actuals
A1: USD m | B1: FY2021 | C1: FY2022 | D1: FY2023 | E1: FY2024 | F1: FY2025 | G1: FY2026 | H1: Source
A2: Revenue | B2: 12861 | C2: 14544 | D2: 14694 | E2: 13640 | F2: 15009 | G2: 23506 | H2: 10-K income statements; FY2025 has 2 months of Berry, FY2026 the first full year
A3: Adjusted EBITDA (company) | D3: 2018 | E3: 1962 | F3: 2186 | G3: 3673 | H3: 8-K Ex99.1 non-GAAP reconciliation
A4: Adjusted EBIT (company) | D4: 1608 | E4: 1560 | F4: 1723 | G4: 2813 | H4: 10-K non-GAAP reconciliation
A5: GAAP net income attributable | B5: 939 | C5: 805 | D5: 1048 | E5: 730 | F5: 511 | G5: 1106 | H5: 10-K
A6: Adjusted net income (company) | D6: 1089 | E6: 1015 | F6: 1136 | G6: 1863 | H6: 10-K non-GAAP reconciliation
A7: Operating cash flow | B7: 1461 | C7: 1526 | D7: 1261 | E7: 1321 | F7: 1390 | G7: 2151 | H7: 10-K cash flow statements
A8: Capex (PP&E + intangibles) | B8: 468 | C8: 527 | D8: 526 | E8: 492 | F8: 580 | G8: 922 | H8: 10-K cash flow statements
A9: Company free cash flow | B9: 993 | C9: 999 | D9: 735 | E9: 829 | F9: 810 | G9: 1303 | H9: OCF - capex + PP&E sale proceeds (company definition)
A10: Share-based compensation add-back | B10: 58 | C10: 63 | D10: 54 | E10: 32 | F10: 74 | G10: 83 | H10: 10-K cash flow statements
A11: Tax withholding on equity awards | B11: 0 | C11: 0 | D11: 0 | E11: 3 | F11: 75 | G11: 42 | H11: 'Purchase of treasury shares and tax withholdings' less open-market treasury purchases
A12: Interest income | B12: 14 | C12: 24 | D12: 31 | E12: 38 | F12: 49 | G12: 66 | H12: 10-K income statements
A13: Cash taxes paid | B13: 321 | C13: 256 | D13: 225 | E13: 253 | F13: 261 | G13: 451 | H13: 10-K supplemental cash flow
A14: Dividends paid | B14: 742 | C14: 732 | D14: 723 | E14: 722 | F14: 845 | G14: 1195 | H14: 10-K cash flow statements
A15: Share buyback / cancellations | B15: 351 | C15: 601 | D15: 432 | E15: 30 | F15: 0 | G15: 1 | H15: 10-K cash flow statements (authorised vs spent: only spent counts)
A16: Total debt (year end) | B16: 6289 | C16: 6490 | D16: 6746 | E16: 6699 | F16: 14098 | G16: 14012 | H16: 10-K net debt reconciliation
A17: Cash (year end) | B17: 850 | C17: 775 | D17: 689 | E17: 588 | F17: 827 | G17: 1115 | H17: 10-K balance sheets
A18: Net debt (company) | B18: 5439 | C18: 5715 | D18: 6057 | E18: 6111 | F18: 13271 | G18: 12897 | H18: 10-K net debt reconciliation
... A21: Adjusted diluted EPS (USD, post-split) | B21: 3.705 | C21: 4.025 | D21: 3.665 | E21: 3.51 | F21: 3.56 | G21: 4.02 | H21: company adjusted EPS series x 5
A22: Pro-forma combined revenue (Amcor+Berry) | E22: 23321 | F22: 23242 | G22: 23506 | H22: 10-K Note 4 unaudited pro forma (FY2024, FY2025); FY2026 actual
A24: Guidance (12-Aug-2026 release)
A25: Transition Period Jul-Dec 2026 adjusted EPS | B25: USD 1.80 - 1.90
A26: Leverage at 31-Dec-2026 (net debt / LTM adj EBITDA + SBC) | B26: 3.5x - 3.6x
A27: CY2027 adjusted EPS growth | B27: double-digit (Sept-2026 Jefferies conference)
A28: Berry synergies | B28: USD 650m by Jun-2028 (530 cost + 60 financial + 60 growth); 285 captured FY2026
A29: Working-capital recovery | B29: more than USD 500m over ~12 months from Aug-2026 (not in the flows)
A30: Quarterly dividend | B30: USD 0.65 (A$0.92 per CDI), ex 3-Sep-2026, paid 24-Sep-2026

Sheet Assumptions
A1: Globals
A4: WACC | B4: 0.078 | C4: 7.3% USD standard build + 0.5% fix-pass leverage/integration premium; same in every scenario
A5: Terminal cap multiple (x FCF_10) | B5: 15 | C5: structurally slower business; today's EV/owner-FCF ~16.7x, so no expansion assumed
A6: Net debt incl. NCI (USD m) | B6: 12908 | C6: 30-Jun-2026: 14,012 debt - 1,115 cash + 11 NCI; operating leases excluded
A7: Diluted shares (m) | B7: 462.9 | C7: post 1-for-5 split; held flat
A8: Price (AUD, ASX) | B8: 59.11 | C8: 2026-09-21T06:10Z close
A9: AUDUSD | B9: 0.7131 | C9: Yahoo AUDUSD=X 2026-09-21; USD->AUD = 1/this
A10: Hurdle rate | B10: 0.15 | C10: entry-price IRR
A11: FY0 revenue (USD m) | B11: 23506 | C11: FY2026
A12: USD->AUD | B12: =1/B9 | C12: derived
A14: Per-scenario | B14: Bear | C14: Base | D14: Bull
A15: Terminal growth | B15: 0.015 | C15: 0.025 | D15: 0.03
A16: Probability weight | B16: 0.25 | C16: 0.5 | D16: 0.25
A17: D&A % revenue | B17: 0.037 | C17: 0.037 | D17: 0.037
A18: Capex % revenue | B18: 0.039 | C18: 0.038 | D18: 0.038
A19: WC capture % of revenue change | B19: -0.1 | C19: -0.1 | D19: -0.1
A20: Weights check (must be 1.0) | B20: =SUM(B16:D16)
A21: Exit EV/EBITDA cap (x terminal EBITDA) | B21: 10.9 | C21: 14 | D21: 15.2
A22: Scenario narratives
A23: Bear | B23: The FY2026 pattern repeats and worsens: guidance is met on adjusted EPS but missed on cash. Volumes stay negative (-1 to -3% as in FY2024-FY2026 organic), Middle-East-driven input costs and the pass-through lag bite, and the remaining synergies are conceded to consolidating CPG customers so the cash-adjusted margin drifts back to pre-merger Amcor's ~14.5%. The non-core review drags on without a clean exit, and the three concurrent organisational changes (calendar year-end, Miami HQ, new auditor) distract an integration that Berry was excluded from FY2025 controls testing for. Leverage stays at 3.5x+, so the ~$1.2bn dividend consumes all of levered FCF. Terminal growth 1.5%; Gordon at 7.8% is 16.1x so the 15x cap still binds -- a slow-erosion case, not a solvency case.
A24: Base | B24: Berry integration continues but the margin only partly shows it: of the remaining ~$300m of EBITDA-relevant synergies (of the $650m total, $285m captured in FY2026; ~$60m is interest, not EBITDA) roughly a quarter reaches the cash-adjusted EBITDA margin, which drifts from 15.0% to 15.3% (company adjusted basis ~15.9%) by Y4 -- the rest is absorbed by inflation not fully passed through, continued price/mix drag and CPG customer consolidation, as it was in FY2026. Revenue grows 2-3% nominal -- raw-material pass-through and modest volume in nutrition/healthcare -- with the ~$2.5bn non-core review treated as value-neutral. Cash tax ramps 19%->21% as Pillar Two bites. Leverage falls toward 3x by end-2027 on the company's own path; the 7.8% WACC carries a 0.5% premium for that window. No re-rating is assumed: the 15x owner-FCF terminal cap (~8x terminal EBITDA) holds the exit below Amcor's own 10-year EV/EBITDA range.
A25: Bull | B25: Synergies deliver in full and the North America beverage and other non-core units are exited or fixed, so the retained portfolio's cash-adjusted margin reaches 17.0% (company basis ~17.6%) -- a full-synergy case, no longer a Berry-like 17.6% margin on the whole book. The ~$140m of new business wins plus healthcare/pet-food/protein mix push volumes back to positive and revenue compounds 3-4.5%. Working-capital recovery (>$500m guided) and deleveraging arrive faster, freeing cash for buybacks that the flat share count already assumes. Terminal growth 3.0%, still capped at 15x FCF (the 15.2x EV/EBITDA cap sits far above).

Sheet DCF_Bear
A1: Bear case -- USD millions; only rows 5, 7, 9, 14 are inputs
A3: Year | B3: FY2026A | C3: Y1E | D3: Y2E | E3: Y3E | F3: Y4E | G3: Y5E | H3: Y6E | I3: Y7E | J3: Y8E | K3: Y9E | L3: Y10E
A4: Index | B4: 0 | C4: 1 | D4: 2 | E4: 3 | F4: 4 | G4: 5 | H4: 6 | I4: 7 | J4: 8 | K4: 9 | L4: 10
A5: Revenue growth YoY | C5: 0 | D5: 0.005 | E5: 0.01 | F5: 0.015 | G5: 0.015 | H5: 0.015 | I5: 0.015 | J5: 0.015 | K5: 0.015 | L5: 0.015
A6: Revenue | B6: =Assumptions!B11 | C6: =B6*(1+C5) | D6: =C6*(1+D5) | E6: =D6*(1+E5) | F6: =E6*(1+F5) | G6: =F6*(1+G5) | H6: =G6*(1+H5) | I6: =H6*(1+I5) | J6: =I6*(1+J5) | ... L6: =K6*(1+L5)
A7: Cash-adjusted EBITDA margin | B7: 0.14962137 | C7: 0.148 | D7: 0.146 | E7: 0.145 | F7: 0.145 | G7: 0.145 | H7: 0.145 | I7: 0.145 | J7: 0.145 | K7: 0.145 | L7: 0.145
A8: Cash-adjusted EBITDA | B8: =B6*B7 | C8: =C6*C7 | D8: =D6*D7 | E8: =E6*E7 | F8: =F6*F7 | G8: =G6*G7 | H8: =H6*H7 | I8: =I6*I7 | ... L8: =L6*L7
A9: SBC incl. withholding % revenue | B9: 0.0053177912 | C9: 0.0053 | D9: 0.0053 | E9: 0.0053 | F9: 0.0053 | G9: 0.0053 | H9: 0.0053 | I9: 0.0053 | J9: 0.0053 | K9: 0.0053 | L9: 0.0053
A10: SBC (negative) | B10: =-B6*B9 | C10: =-C6*C9 | D10: =-D6*D9 | E10: =-E6*E9 | F10: =-F6*F9 | G10: =-G6*G9 | H10: =-H6*H9 | I10: =-I6*I9 | ... L10: =-L6*L9
A11: Owner EBITDA | B11: =B8+B10 | C11: =C8+C10 | D11: =D8+D10 | E11: =E8+E10 | F11: =F8+F10 | G11: =G8+G10 | H11: =H8+H10 | I11: =I8+I10 | ... L11: =L8+L10
A12: D&A ex acquired intangibles (negative) | B12: -860 | C12: =-C6*Assumptions!$B$17 | D12: =-D6*Assumptions!$B$17 | E12: =-E6*Assumptions!$B$17 | F12: =-F6*Assumptions!$B$17 | G12: =-G6*Assumptions!$B$17 | H12: =-H6*Assumptions!$B$17 | I12: =-I6*Assumptions!$B$17 | J12: =-J6*Assumptions!$B$17 | ... L12: =-L6*Assumptions!$B$17
A13: EBIT, SBC expensed | B13: =B11+B12 | C13: =C11+C12 | D13: =D11+D12 | E13: =E11+E12 | F13: =F11+F12 | G13: =G11+G12 | H13: =H11+H12 | I13: =I11+I12 | ... L13: =L11+L12
A14: Cash tax rate | B14: 0.2 | C14: 0.2 | D14: 0.21 | E14: 0.21 | F14: 0.21 | G14: 0.21 | H14: 0.21 | I14: 0.21 | J14: 0.21 | K14: 0.21 | L14: 0.21
A15: NOPAT | B15: =B13-MAX(0,B13)*B14 | C15: =C13-MAX(0,C13)*C14 | D15: =D13-MAX(0,D13)*D14 | E15: =E13-MAX(0,E13)*E14 | F15: =F13-MAX(0,F13)*F14 | G15: =G13-MAX(0,G13)*G14 | H15: =H13-MAX(0,H13)*H14 | I15: =I13-MAX(0,I13)*I14 | ... L15: =L13-MAX(0,L13)*L14
A16: add back D&A | B16: =-B12 | C16: =-C12 | D16: =-D12 | E16: =-E12 | F16: =-F12 | G16: =-G12 | H16: =-H12 | I16: =-I12 | ... L16: =-L12
A17: less capex | B17: -922 | C17: =-C6*Assumptions!$B$18 | D17: =-D6*Assumptions!$B$18 | E17: =-E6*Assumptions!$B$18 | F17: =-F6*Assumptions!$B$18 | G17: =-G6*Assumptions!$B$18 | H17: =-H6*Assumptions!$B$18 | I17: =-I6*Assumptions!$B$18 | J17: =-J6*Assumptions!$B$18 | ... L17: =-L6*Assumptions!$B$18
A18: add working capital (on revenue change) | B18: 0 | C18: =Assumptions!$B$19*(C6-B6) | D18: =Assumptions!$B$19*(D6-C6) | E18: =Assumptions!$B$19*(E6-D6) | F18: =Assumptions!$B$19*(F6-E6) | G18: =Assumptions!$B$19*(G6-F6) | H18: =Assumptions!$B$19*(H6-G6) | I18: =Assumptions!$B$19*(I6-H6) | J18: =Assumptions!$B$19*(J6-I6) | ... L18: =Assumptions!$B$19*(L6-K6)
A19: Unlevered owner FCF | B19: =B15+B16+B17+B18 | C19: =C15+C16+C17+C18 | D19: =D15+D16+D17+D18 | E19: =E15+E16+E17+E18 | F19: =F15+F16+F17+F18 | G19: =G15+G16+G17+G18 | H19: =H15+H16+H17+H18 | I19: =I15+I16+I17+I18 | ... L19: =L15+L16+L17+L18
A20: Discount factor | C20: =1/(1+Assumptions!$B$4)^C4 | D20: =1/(1+Assumptions!$B$4)^D4 | E20: =1/(1+Assumptions!$B$4)^E4 | F20: =1/(1+Assumptions!$B$4)^F4 | G20: =1/(1+Assumptions!$B$4)^G4 | H20: =1/(1+Assumptions!$B$4)^H4 | I20: =1/(1+Assumptions!$B$4)^I4 | J20: =1/(1+Assumptions!$B$4)^J4 | ... L20: =1/(1+Assumptions!$B$4)^L4
A21: PV of FCF | C21: =C19*C20 | D21: =D19*D20 | E21: =E19*E20 | F21: =F19*F20 | G21: =G19*G20 | H21: =H19*H20 | I21: =I19*I20 | J21: =J19*J20 | ... L21: =L19*L20
A23: Memo: FCF before SBC (company-style) | B23: =B19-B10 | C23: =C19-C10 | D23: =D19-D10 | E23: =E19-E10 | F23: =F19-F10 | G23: =G19-G10 | H23: =H19-H10 | I23: =I19-I10 | ... L23: =L19-L10
A24: Memo: owner-FCF margin | B24: =B19/B6 | C24: =C19/C6 | D24: =D19/D6 | E24: =E19/E6 | F24: =F19/F6 | G24: =G19/G6 | H24: =H19/H6 | I24: =I19/I6 | ... L24: =L19/L6
A26: Sum of PV (Y1-Y10) | B26: =SUM(C21:L21)
A27: Terminal growth | B27: =Assumptions!B15
A28: Terminal FCF (Y10 x (1+g)) | B28: =L19*(1+B27)
A29: Gordon TV | B29: =IF(Assumptions!B4>B27,B28/(Assumptions!B4-B27),1E+15)
A30: Cap TV (cap x FCF_10) | B30: =Assumptions!B5*L19
A31: TV used = MAX(0,MIN(Gordon,FCF cap,EV/EBITDA cap)) | B31: =MAX(0,MIN(B29,B30,B47))
A32: Implied exit multiple (TV / FCF_10) | B32: =IF(L19<>0,B31/L19,0)
A33: PV of TV | B33: =B31*L20
A34: Enterprise value | B34: =B26+B33
A35: less net debt incl. NCI | B35: =-Assumptions!B6
A36: Equity value | B36: =B34+B35
A37: Diluted shares (m) | B37: =Assumptions!B7
A38: Value per share (USD) | B38: =B36/B37
A39: Value per share (AUD) | B39: =B38*Assumptions!B12
A40: Upside vs price (AUD) | B40: =B39/Assumptions!B8-1
A42: Street memo: PV of explicit SBC | B42: =SUMPRODUCT(-C10:L10/(1+Assumptions!B4)^C4:L4)
A43: Street memo: PV of terminal SBC | B43: =MIN(IF(Assumptions!B4>B27,-L10*(1+B27)/(Assumptions!B4-B27),1E+15),Assumptions!B5*-L10)*L20
A44: Street value per share (USD) | B44: =(B36+B42+B43)/B37
...

Sheet DCF_Base
A1: Base case -- USD millions; only rows 5, 7, 9, 14 are inputs
A3: Year | B3: FY2026A | C3: Y1E | D3: Y2E | E3: Y3E | F3: Y4E | G3: Y5E | H3: Y6E | I3: Y7E | J3: Y8E | K3: Y9E | L3: Y10E
A4: Index | B4: 0 | C4: 1 | D4: 2 | E4: 3 | F4: 4 | G4: 5 | H4: 6 | I4: 7 | J4: 8 | K4: 9 | L4: 10
A5: Revenue growth YoY | C5: 0.02 | D5: 0.025 | E5: 0.03 | F5: 0.03 | G5: 0.03 | H5: 0.0275 | I5: 0.025 | J5: 0.025 | K5: 0.025 | L5: 0.025
A6: Revenue | B6: =Assumptions!B11 | C6: =B6*(1+C5) | D6: =C6*(1+D5) | E6: =D6*(1+E5) | F6: =E6*(1+F5) | G6: =F6*(1+G5) | H6: =G6*(1+H5) | I6: =H6*(1+I5) | J6: =I6*(1+J5) | ... L6: =K6*(1+L5)
A7: Cash-adjusted EBITDA margin | B7: 0.14962137 | C7: 0.15 | D7: 0.151 | E7: 0.152 | F7: 0.153 | G7: 0.153 | H7: 0.153 | I7: 0.153 | J7: 0.153 | K7: 0.153 | L7: 0.153
A8: Cash-adjusted EBITDA | B8: =B6*B7 | C8: =C6*C7 | D8: =D6*D7 | E8: =E6*E7 | F8: =F6*F7 | G8: =G6*G7 | H8: =H6*H7 | I8: =I6*I7 | ... L8: =L6*L7
A9: SBC incl. withholding % revenue | B9: 0.0053177912 | C9: 0.0053 | D9: 0.0053 | E9: 0.0052 | F9: 0.0052 | G9: 0.0051 | H9: 0.0051 | I9: 0.005 | J9: 0.005 | K9: 0.005 | L9: 0.005
A10: SBC (negative) | B10: =-B6*B9 | C10: =-C6*C9 | D10: =-D6*D9 | E10: =-E6*E9 | F10: =-F6*F9 | G10: =-G6*G9 | H10: =-H6*H9 | I10: =-I6*I9 | ... L10: =-L6*L9
A11: Owner EBITDA | B11: =B8+B10 | C11: =C8+C10 | D11: =D8+D10 | E11: =E8+E10 | F11: =F8+F10 | G11: =G8+G10 | H11: =H8+H10 | I11: =I8+I10 | ... L11: =L8+L10
A12: D&A ex acquired intangibles (negative) | B12: -860 | C12: =-C6*Assumptions!$C$17 | D12: =-D6*Assumptions!$C$17 | E12: =-E6*Assumptions!$C$17 | F12: =-F6*Assumptions!$C$17 | G12: =-G6*Assumptions!$C$17 | H12: =-H6*Assumptions!$C$17 | I12: =-I6*Assumptions!$C$17 | J12: =-J6*Assumptions!$C$17 | ... L12: =-L6*Assumptions!$C$17
A13: EBIT, SBC expensed | B13: =B11+B12 | C13: =C11+C12 | D13: =D11+D12 | E13: =E11+E12 | F13: =F11+F12 | G13: =G11+G12 | H13: =H11+H12 | I13: =I11+I12 | ... L13: =L11+L12
A14: Cash tax rate | B14: 0.2 | C14: 0.19 | D14: 0.19 | E14: 0.2 | F14: 0.2 | G14: 0.21 | H14: 0.21 | I14: 0.21 | J14: 0.21 | K14: 0.21 | L14: 0.21
A15: NOPAT | B15: =B13-MAX(0,B13)*B14 | C15: =C13-MAX(0,C13)*C14 | D15: =D13-MAX(0,D13)*D14 | E15: =E13-MAX(0,E13)*E14 | F15: =F13-MAX(0,F13)*F14 | G15: =G13-MAX(0,G13)*G14 | H15: =H13-MAX(0,H13)*H14 | I15: =I13-MAX(0,I13)*I14 | ... L15: =L13-MAX(0,L13)*L14
A16: add back D&A | B16: =-B12 | C16: =-C12 | D16: =-D12 | E16: =-E12 | F16: =-F12 | G16: =-G12 | H16: =-H12 | I16: =-I12 | ... L16: =-L12
A17: less capex | B17: -922 | C17: =-C6*Assumptions!$C$18 | D17: =-D6*Assumptions!$C$18 | E17: =-E6*Assumptions!$C$18 | F17: =-F6*Assumptions!$C$18 | G17: =-G6*Assumptions!$C$18 | H17: =-H6*Assumptions!$C$18 | I17: =-I6*Assumptions!$C$18 | J17: =-J6*Assumptions!$C$18 | ... L17: =-L6*Assumptions!$C$18
A18: add working capital (on revenue change) | B18: 0 | C18: =Assumptions!$C$19*(C6-B6) | D18: =Assumptions!$C$19*(D6-C6) | E18: =Assumptions!$C$19*(E6-D6) | F18: =Assumptions!$C$19*(F6-E6) | G18: =Assumptions!$C$19*(G6-F6) | H18: =Assumptions!$C$19*(H6-G6) | I18: =Assumptions!$C$19*(I6-H6) | J18: =Assumptions!$C$19*(J6-I6) | ... L18: =Assumptions!$C$19*(L6-K6)
A19: Unlevered owner FCF | B19: =B15+B16+B17+B18 | C19: =C15+C16+C17+C18 | D19: =D15+D16+D17+D18 | E19: =E15+E16+E17+E18 | F19: =F15+F16+F17+F18 | G19: =G15+G16+G17+G18 | H19: =H15+H16+H17+H18 | I19: =I15+I16+I17+I18 | ... L19: =L15+L16+L17+L18
A20: Discount factor | C20: =1/(1+Assumptions!$B$4)^C4 | D20: =1/(1+Assumptions!$B$4)^D4 | E20: =1/(1+Assumptions!$B$4)^E4 | F20: =1/(1+Assumptions!$B$4)^F4 | G20: =1/(1+Assumptions!$B$4)^G4 | H20: =1/(1+Assumptions!$B$4)^H4 | I20: =1/(1+Assumptions!$B$4)^I4 | J20: =1/(1+Assumptions!$B$4)^J4 | ... L20: =1/(1+Assumptions!$B$4)^L4
A21: PV of FCF | C21: =C19*C20 | D21: =D19*D20 | E21: =E19*E20 | F21: =F19*F20 | G21: =G19*G20 | H21: =H19*H20 | I21: =I19*I20 | J21: =J19*J20 | ... L21: =L19*L20
A23: Memo: FCF before SBC (company-style) | B23: =B19-B10 | C23: =C19-C10 | D23: =D19-D10 | E23: =E19-E10 | F23: =F19-F10 | G23: =G19-G10 | H23: =H19-H10 | I23: =I19-I10 | ... L23: =L19-L10
A24: Memo: owner-FCF margin | B24: =B19/B6 | C24: =C19/C6 | D24: =D19/D6 | E24: =E19/E6 | F24: =F19/F6 | G24: =G19/G6 | H24: =H19/H6 | I24: =I19/I6 | ... L24: =L19/L6
A26: Sum of PV (Y1-Y10) | B26: =SUM(C21:L21)
A27: Terminal growth | B27: =Assumptions!C15
A28: Terminal FCF (Y10 x (1+g)) | B28: =L19*(1+B27)
A29: Gordon TV | B29: =IF(Assumptions!B4>B27,B28/(Assumptions!B4-B27),1E+15)
A30: Cap TV (cap x FCF_10) | B30: =Assumptions!B5*L19
A31: TV used = MAX(0,MIN(Gordon,FCF cap,EV/EBITDA cap)) | B31: =MAX(0,MIN(B29,B30,B47))
A32: Implied exit multiple (TV / FCF_10) | B32: =IF(L19<>0,B31/L19,0)
A33: PV of TV | B33: =B31*L20
A34: Enterprise value | B34: =B26+B33
A35: less net debt incl. NCI | B35: =-Assumptions!B6
A36: Equity value | B36: =B34+B35
A37: Diluted shares (m) | B37: =Assumptions!B7
A38: Value per share (USD) | B38: =B36/B37
A39: Value per share (AUD) | B39: =B38*Assumptions!B12
A40: Upside vs price (AUD) | B40: =B39/Assumptions!B8-1
A42: Street memo: PV of explicit SBC | B42: =SUMPRODUCT(-C10:L10/(1+Assumptions!B4)^C4:L4)
A43: Street memo: PV of terminal SBC | B43: =MIN(IF(Assumptions!B4>B27,-L10*(1+B27)/(Assumptions!B4-B27),1E+15),Assumptions!B5*-L10)*L20
A44: Street value per share (USD) | B44: =(B36+B42+B43)/B37
...

Sheet DCF_Bull
A1: Bull case -- USD millions; only rows 5, 7, 9, 14 are inputs
A3: Year | B3: FY2026A | C3: Y1E | D3: Y2E | E3: Y3E | F3: Y4E | G3: Y5E | H3: Y6E | I3: Y7E | J3: Y8E | K3: Y9E | L3: Y10E
A4: Index | B4: 0 | C4: 1 | D4: 2 | E4: 3 | F4: 4 | G4: 5 | H4: 6 | I4: 7 | J4: 8 | K4: 9 | L4: 10
A5: Revenue growth YoY | C5: 0.03 | D5: 0.04 | E5: 0.045 | F5: 0.045 | G5: 0.04 | H5: 0.035 | I5: 0.035 | J5: 0.03 | K5: 0.03 | L5: 0.03
A6: Revenue | B6: =Assumptions!B11 | C6: =B6*(1+C5) | D6: =C6*(1+D5) | E6: =D6*(1+E5) | F6: =E6*(1+F5) | G6: =F6*(1+G5) | H6: =G6*(1+H5) | I6: =H6*(1+I5) | J6: =I6*(1+J5) | ... L6: =K6*(1+L5)
A7: Cash-adjusted EBITDA margin | B7: 0.14962137 | C7: 0.155 | D7: 0.162 | E7: 0.167 | F7: 0.17 | G7: 0.17 | H7: 0.17 | I7: 0.17 | J7: 0.17 | K7: 0.17 | L7: 0.17
A8: Cash-adjusted EBITDA | B8: =B6*B7 | C8: =C6*C7 | D8: =D6*D7 | E8: =E6*E7 | F8: =F6*F7 | G8: =G6*G7 | H8: =H6*H7 | I8: =I6*I7 | ... L8: =L6*L7
A9: SBC incl. withholding % revenue | B9: 0.0053177912 | C9: 0.0053 | D9: 0.0053 | E9: 0.0052 | F9: 0.0052 | G9: 0.0051 | H9: 0.0051 | I9: 0.005 | J9: 0.005 | K9: 0.005 | L9: 0.005
A10: SBC (negative) | B10: =-B6*B9 | C10: =-C6*C9 | D10: =-D6*D9 | E10: =-E6*E9 | F10: =-F6*F9 | G10: =-G6*G9 | H10: =-H6*H9 | I10: =-I6*I9 | ... L10: =-L6*L9
A11: Owner EBITDA | B11: =B8+B10 | C11: =C8+C10 | D11: =D8+D10 | E11: =E8+E10 | F11: =F8+F10 | G11: =G8+G10 | H11: =H8+H10 | I11: =I8+I10 | ... L11: =L8+L10
A12: D&A ex acquired intangibles (negative) | B12: -860 | C12: =-C6*Assumptions!$D$17 | D12: =-D6*Assumptions!$D$17 | E12: =-E6*Assumptions!$D$17 | F12: =-F6*Assumptions!$D$17 | G12: =-G6*Assumptions!$D$17 | H12: =-H6*Assumptions!$D$17 | I12: =-I6*Assumptions!$D$17 | J12: =-J6*Assumptions!$D$17 | ... L12: =-L6*Assumptions!$D$17
A13: EBIT, SBC expensed | B13: =B11+B12 | C13: =C11+C12 | D13: =D11+D12 | E13: =E11+E12 | F13: =F11+F12 | G13: =G11+G12 | H13: =H11+H12 | I13: =I11+I12 | ... L13: =L11+L12
A14: Cash tax rate | B14: 0.2 | C14: 0.19 | D14: 0.19 | E14: 0.2 | F14: 0.2 | G14: 0.21 | H14: 0.21 | I14: 0.21 | J14: 0.21 | K14: 0.21 | L14: 0.21
A15: NOPAT | B15: =B13-MAX(0,B13)*B14 | C15: =C13-MAX(0,C13)*C14 | D15: =D13-MAX(0,D13)*D14 | E15: =E13-MAX(0,E13)*E14 | F15: =F13-MAX(0,F13)*F14 | G15: =G13-MAX(0,G13)*G14 | H15: =H13-MAX(0,H13)*H14 | I15: =I13-MAX(0,I13)*I14 | ... L15: =L13-MAX(0,L13)*L14
A16: add back D&A | B16: =-B12 | C16: =-C12 | D16: =-D12 | E16: =-E12 | F16: =-F12 | G16: =-G12 | H16: =-H12 | I16: =-I12 | ... L16: =-L12
A17: less capex | B17: -922 | C17: =-C6*Assumptions!$D$18 | D17: =-D6*Assumptions!$D$18 | E17: =-E6*Assumptions!$D$18 | F17: =-F6*Assumptions!$D$18 | G17: =-G6*Assumptions!$D$18 | H17: =-H6*Assumptions!$D$18 | I17: =-I6*Assumptions!$D$18 | J17: =-J6*Assumptions!$D$18 | ... L17: =-L6*Assumptions!$D$18
A18: add working capital (on revenue change) | B18: 0 | C18: =Assumptions!$D$19*(C6-B6) | D18: =Assumptions!$D$19*(D6-C6) | E18: =Assumptions!$D$19*(E6-D6) | F18: =Assumptions!$D$19*(F6-E6) | G18: =Assumptions!$D$19*(G6-F6) | H18: =Assumptions!$D$19*(H6-G6) | I18: =Assumptions!$D$19*(I6-H6) | J18: =Assumptions!$D$19*(J6-I6) | ... L18: =Assumptions!$D$19*(L6-K6)
A19: Unlevered owner FCF | B19: =B15+B16+B17+B18 | C19: =C15+C16+C17+C18 | D19: =D15+D16+D17+D18 | E19: =E15+E16+E17+E18 | F19: =F15+F16+F17+F18 | G19: =G15+G16+G17+G18 | H19: =H15+H16+H17+H18 | I19: =I15+I16+I17+I18 | ... L19: =L15+L16+L17+L18
A20: Discount factor | C20: =1/(1+Assumptions!$B$4)^C4 | D20: =1/(1+Assumptions!$B$4)^D4 | E20: =1/(1+Assumptions!$B$4)^E4 | F20: =1/(1+Assumptions!$B$4)^F4 | G20: =1/(1+Assumptions!$B$4)^G4 | H20: =1/(1+Assumptions!$B$4)^H4 | I20: =1/(1+Assumptions!$B$4)^I4 | J20: =1/(1+Assumptions!$B$4)^J4 | ... L20: =1/(1+Assumptions!$B$4)^L4
A21: PV of FCF | C21: =C19*C20 | D21: =D19*D20 | E21: =E19*E20 | F21: =F19*F20 | G21: =G19*G20 | H21: =H19*H20 | I21: =I19*I20 | J21: =J19*J20 | ... L21: =L19*L20
A23: Memo: FCF before SBC (company-style) | B23: =B19-B10 | C23: =C19-C10 | D23: =D19-D10 | E23: =E19-E10 | F23: =F19-F10 | G23: =G19-G10 | H23: =H19-H10 | I23: =I19-I10 | ... L23: =L19-L10
A24: Memo: owner-FCF margin | B24: =B19/B6 | C24: =C19/C6 | D24: =D19/D6 | E24: =E19/E6 | F24: =F19/F6 | G24: =G19/G6 | H24: =H19/H6 | I24: =I19/I6 | ... L24: =L19/L6
A26: Sum of PV (Y1-Y10) | B26: =SUM(C21:L21)
A27: Terminal growth | B27: =Assumptions!D15
A28: Terminal FCF (Y10 x (1+g)) | B28: =L19*(1+B27)
A29: Gordon TV | B29: =IF(Assumptions!B4>B27,B28/(Assumptions!B4-B27),1E+15)
A30: Cap TV (cap x FCF_10) | B30: =Assumptions!B5*L19
A31: TV used = MAX(0,MIN(Gordon,FCF cap,EV/EBITDA cap)) | B31: =MAX(0,MIN(B29,B30,B47))
A32: Implied exit multiple (TV / FCF_10) | B32: =IF(L19<>0,B31/L19,0)
A33: PV of TV | B33: =B31*L20
A34: Enterprise value | B34: =B26+B33
A35: less net debt incl. NCI | B35: =-Assumptions!B6
A36: Equity value | B36: =B34+B35
A37: Diluted shares (m) | B37: =Assumptions!B7
A38: Value per share (USD) | B38: =B36/B37
A39: Value per share (AUD) | B39: =B38*Assumptions!B12
A40: Upside vs price (AUD) | B40: =B39/Assumptions!B8-1
A42: Street memo: PV of explicit SBC | B42: =SUMPRODUCT(-C10:L10/(1+Assumptions!B4)^C4:L4)
A43: Street memo: PV of terminal SBC | B43: =MIN(IF(Assumptions!B4>B27,-L10*(1+B27)/(Assumptions!B4-B27),1E+15),Assumptions!B5*-L10)*L20
A44: Street value per share (USD) | B44: =(B36+B42+B43)/B37
...

Sheet FCF_Quality
A1: Reported FCF reconciled to owner FCF (USD m)
B2: FY2021 | C2: FY2022 | D2: FY2023 | E2: FY2024 | F2: FY2025 | G2: FY2026
A3: Company free cash flow | B3: =Actuals!B9 | C3: =Actuals!C9 | D3: =Actuals!D9 | E3: =Actuals!E9 | F3: =Actuals!F9 | G3: =Actuals!G9
A4: less: SBC add-back | B4: =-Actuals!B10 | C4: =-Actuals!C10 | D4: =-Actuals!D10 | E4: =-Actuals!E10 | F4: =-Actuals!F10 | G4: =-Actuals!G10
A5: less: tax withholding on equity awards | B5: =-Actuals!B11 | C5: =-Actuals!C11 | D5: =-Actuals!D11 | E5: =-Actuals!E11 | F5: =-Actuals!F11 | G5: =-Actuals!G11
A6: Equals: Levered owner FCF | B6: =B3+B4+B5 | C6: =C3+C4+C5 | D6: =D3+D4+D5 | E6: =E3+E4+E5 | F6: =F3+F4+F5 | G6: =G3+G4+G5
A7: Revenue | B7: =Actuals!B2 | C7: =Actuals!C2 | D7: =Actuals!D2 | E7: =Actuals!E2 | F7: =Actuals!F2 | G7: =Actuals!G2
A8: Reported FCF margin | B8: =B3/B7 | C8: =C3/C7 | D8: =D3/D7 | E8: =E3/E7 | F8: =F3/F7 | G8: =G3/G7
A9: Owner FCF margin | B9: =B6/B7 | C9: =C6/C7 | D9: =D6/D7 | E9: =E6/E7 | F9: =F6/F7 | G9: =G6/G7
A10: Memo: interest income (not stripped -- net debt) | B10: =Actuals!B12 | C10: =Actuals!C12 | D10: =Actuals!D12 | E10: =Actuals!E12 | F10: =Actuals!F12 | G10: =Actuals!G12
A11: Memo: cash taxes paid | B11: =Actuals!B13 | C11: =Actuals!C13 | D11: =Actuals!D13 | E11: =Actuals!E13 | F11: =Actuals!F13 | G11: =Actuals!G13
A12: Memo: diluted shares (m, post-split) | B12: =Actuals!B19 | C12: =Actuals!C19 | D12: =Actuals!D19 | E12: =Actuals!E19 | F12: =Actuals!F19 | G12: =Actuals!G19
A13: Owner FCF per share (USD) | B13: =B6/B12 | C13: =C6/C12 | D13: =D6/D12 | E13: =E6/E12 | F13: =F6/F12 | G13: =G6/G12
A14: Memo: cash tax / GAAP pre-tax proxy (NI + tax)
A15: FY2026 unlevered FY0 build (ties to DCF_*!B19)
A16: Adjusted EBITDA (company) | B16: 3673
A17: less recurring 'Other' operating cash items | B17: -156
A18: Equals: Cash-adjusted EBITDA | B18: =B16+B17
A19: less SBC incl. withholding | B19: -125
A20: less D&A ex acquired intangibles | B20: -860
A21: Equals: EBIT | B21: =B18+B19+B20
A22: tax at 20% | B22: =-MAX(0,B21)*0.2
A23: Equals: NOPAT | B23: =B21+B22
A24: add D&A | B24: 860
A25: less capex | B25: -922
A26: Equals: Unlevered owner FCF FY0 | B26: =B23+B24+B25
A28: Memo: FY2026 company FCF 1,303 is after ~$290m Berry integration cash costs and $549m net interest; adjusted FCF before integration costs 1,593. The FY0 above is pre-interest because net debt is deducted in the bridge.

Sheet Valuation
A1: Valuation summary
A2: Scenario | B2: Value/share USD | C2: Value/share AUD | D2: Upside vs A$ price | E2: Weight | F2: Street USD | G2: Street AUD | H2: Exit multiple | I2: TV %
A3: Bear | B3: =DCF_Bear!B38 | C3: =DCF_Bear!B39 | D3: =C3/Assumptions!B8-1 | E3: =Assumptions!B16 | F3: =DCF_Bear!B44 | G3: =DCF_Bear!B45 | H3: =DCF_Bear!B32 | I3: =DCF_Bear!B46
A4: Base | B4: =DCF_Base!B38 | C4: =DCF_Base!B39 | D4: =C4/Assumptions!B8-1 | E4: =Assumptions!C16 | F4: =DCF_Base!B44 | G4: =DCF_Base!B45 | H4: =DCF_Base!B32 | I4: =DCF_Base!B46
A5: Bull | B5: =DCF_Bull!B38 | C5: =DCF_Bull!B39 | D5: =C5/Assumptions!B8-1 | E5: =Assumptions!D16 | F5: =DCF_Bull!B44 | G5: =DCF_Bull!B45 | H5: =DCF_Bull!B32 | I5: =DCF_Bull!B46
A7: Probability-weighted value (USD) | B7: =SUMPRODUCT(B3:B5,E3:E5)
A8: Probability-weighted value (AUD) | B8: =SUMPRODUCT(C3:C5,E3:E5)
A9: Margin of safety vs A$ price | B9: =1-Assumptions!B8/B8
A10: Street weighted (AUD) | B10: =SUMPRODUCT(G3:G5,E3:E5)
A11: Band position (0%=house, 100%=street) | B11: =IF(B10<>B8,(Assumptions!B8-B8)/(B10-B8),"n/a")
A13: Required-return table (base case; TV rebuilt at each rate)
A14: Required return | B14: Value/share USD | C14: Value/share AUD
A15: 0.09 | B15: =(SUMPRODUCT(DCF_Base!$C$19:$L$19/(1+$A15)^DCF_Base!$C$4:$L$4)+MAX(0,MIN(IF($A15>Assumptions!$C$15,DCF_Base!$L$19*(1+Assumptions!$C$15)/($A15-Assumptions!$C$15),1E+15),Assumptions!$B$5*DCF_Base!$L$19,DCF_Base!$B$47))/(1+$A15)^10-Assumptions!$B$6)/Assumptions!$B$7 | C15: =B15*Assumptions!$B$12
A16: 0.1 | B16: =(SUMPRODUCT(DCF_Base!$C$19:$L$19/(1+$A16)^DCF_Base!$C$4:$L$4)+MAX(0,MIN(IF($A16>Assumptions!$C$15,DCF_Base!$L$19*(1+Assumptions!$C$15)/($A16-Assumptions!$C$15),1E+15),Assumptions!$B$5*DCF_Base!$L$19,DCF_Base!$B$47))/(1+$A16)^10-Assumptions!$B$6)/Assumptions!$B$7 | C16: =B16*Assumptions!$B$12
A17: 0.11 | B17: =(SUMPRODUCT(DCF_Base!$C$19:$L$19/(1+$A17)^DCF_Base!$C$4:$L$4)+MAX(0,MIN(IF($A17>Assumptions!$C$15,DCF_Base!$L$19*(1+Assumptions!$C$15)/($A17-Assumptions!$C$15),1E+15),Assumptions!$B$5*DCF_Base!$L$19,DCF_Base!$B$47))/(1+$A17)^10-Assumptions!$B$6)/Assumptions!$B$7 | C17: =B17*Assumptions!$B$12
A18: 0.12 | B18: =(SUMPRODUCT(DCF_Base!$C$19:$L$19/(1+$A18)^DCF_Base!$C$4:$L$4)+MAX(0,MIN(IF($A18>Assumptions!$C$15,DCF_Base!$L$19*(1+Assumptions!$C$15)/($A18-Assumptions!$C$15),1E+15),Assumptions!$B$5*DCF_Base!$L$19,DCF_Base!$B$47))/(1+$A18)^10-Assumptions!$B$6)/Assumptions!$B$7 | C18: =B18*Assumptions!$B$12
A19: 0.15 | B19: =(SUMPRODUCT(DCF_Base!$C$19:$L$19/(1+$A19)^DCF_Base!$C$4:$L$4)+MAX(0,MIN(IF($A19>Assumptions!$C$15,DCF_Base!$L$19*(1+Assumptions!$C$15)/($A19-Assumptions!$C$15),1E+15),Assumptions!$B$5*DCF_Base!$L$19,DCF_Base!$B$47))/(1+$A19)^10-Assumptions!$B$6)/Assumptions!$B$7 | C19: =B19*Assumptions!$B$12
A20: =Assumptions!B4 | B20: =(SUMPRODUCT(DCF_Base!$C$19:$L$19/(1+$A20)^DCF_Base!$C$4:$L$4)+MAX(0,MIN(IF($A20>Assumptions!$C$15,DCF_Base!$L$19*(1+Assumptions!$C$15)/($A20-Assumptions!$C$15),1E+15),Assumptions!$B$5*DCF_Base!$L$19,DCF_Base!$B$47))/(1+$A20)^10-Assumptions!$B$6)/Assumptions!$B$7 | C20: =B20*Assumptions!$B$12 | D20: must equal DCF_Base!B38 (WACC row)
A22: 15%-hurdle entry prices (TV rebuilt at the hurdle)
A23: Scenario | B23: Entry USD | C23: Entry AUD | D23: Discount vs price | E23: Weight
A24: Bear | B24: =(SUMPRODUCT(DCF_Bear!$C$19:$L$19/(1+Assumptions!$B$10)^DCF_Bear!$C$4:$L$4)+MAX(0,MIN(IF(Assumptions!$B$10>Assumptions!$B$15,DCF_Bear!$L$19*(1+Assumptions!$B$15)/(Assumptions!$B$10-Assumptions!$B$15),1E+15),Assumptions!$B$5*DCF_Bear!$L$19,DCF_Bear!$B$47))/(1+Assumptions!$B$10)^10-Assumptions!$B$6)/Assumptions!$B$7 | C24: =B24*Assumptions!$B$12 | D24: =C24/Assumptions!$B$8-1 | E24: =Assumptions!B16
A25: Base | B25: =(SUMPRODUCT(DCF_Base!$C$19:$L$19/(1+Assumptions!$B$10)^DCF_Base!$C$4:$L$4)+MAX(0,MIN(IF(Assumptions!$B$10>Assumptions!$C$15,DCF_Base!$L$19*(1+Assumptions!$C$15)/(Assumptions!$B$10-Assumptions!$C$15),1E+15),Assumptions!$B$5*DCF_Base!$L$19,DCF_Base!$B$47))/(1+Assumptions!$B$10)^10-Assumptions!$B$6)/Assumptions!$B$7 | C25: =B25*Assumptions!$B$12 | D25: =C25/Assumptions!$B$8-1 | E25: =Assumptions!C16
A26: Bull | B26: =(SUMPRODUCT(DCF_Bull!$C$19:$L$19/(1+Assumptions!$B$10)^DCF_Bull!$C$4:$L$4)+MAX(0,MIN(IF(Assumptions!$B$10>Assumptions!$D$15,DCF_Bull!$L$19*(1+Assumptions!$D$15)/(Assumptions!$B$10-Assumptions!$D$15),1E+15),Assumptions!$B$5*DCF_Bull!$L$19,DCF_Bull!$B$47))/(1+Assumptions!$B$10)^10-Assumptions!$B$6)/Assumptions!$B$7 | C26: =B26*Assumptions!$B$12 | D26: =C26/Assumptions!$B$8-1 | E26: =Assumptions!D16
A27: Weighted entry price (USD) | B27: =SUMPRODUCT(B24:B26,E24:E26)
A28: Weighted entry price (AUD) | B28: =SUMPRODUCT(C24:C26,E24:E26)
A30: Sensitivity: base value/share AUD -- rows WACC, columns terminal growth
B31: 0.015 | C31: 0.02 | D31: 0.025 | E31: 0.03 | F31: 0.035
A32: 0.058 | B32: =IF($A32>B$31,(SUMPRODUCT(DCF_Base!$C$19:$L$19/(1+$A32)^DCF_Base!$C$4:$L$4)+MAX(0,MIN(IF($A32>B$31,DCF_Base!$L$19*(1+B$31)/($A32-B$31),1E+15),Assumptions!$B$5*DCF_Base!$L$19,DCF_Base!$B$47))/(1+$A32)^10-Assumptions!$B$6)/Assumptions!$B$7*Assumptions!$B$12,"n/a") | C32: =IF($A32>C$31,(SUMPRODUCT(DCF_Base!$C$19:$L$19/(1+$A32)^DCF_Base!$C$4:$L$4)+MAX(0,MIN(IF($A32>C$31,DCF_Base!$L$19*(1+C$31)/($A32-C$31),1E+15),Assumptions!$B$5*DCF_Base!$L$19,DCF_Base!$B$47))/(1+$A32)^10-Assumptions!$B$6)/Assumptions!$B$7*Assumptions!$B$12,"n/a") | D32: =IF($A32>D$31,(SUMPRODUCT(DCF_Base!$C$19:$L$19/(1+$A32)^DCF_Base!$C$4:$L$4)+MAX(0,MIN(IF($A32>D$31,DCF_Base!$L$19*(1+D$31)/($A32-D$31),1E+15),Assumptions!$B$5*DCF_Base!$L$19,DCF_Base!$B$47))/(1+$A32)^10-Assumptions!$B$6)/Assumptions!$B$7*Assumptions!$B$12,"n/a") | E32: =IF($A32>E$31,(SUMPRODUCT(DCF_Base!$C$19:$L$19/(1+$A32)^DCF_Base!$C$4:$L$4)+MAX(0,MIN(IF($A32>E$31,DCF_Base!$L$19*(1+E$31)/($A32-E$31),1E+15),Assumptions!$B$5*DCF_Base!$L$19,DCF_Base!$B$47))/(1+$A32)^10-Assumptions!$B$6)/Assumptions!$B$7*Assumptions!$B$12,"n/a") | F32: =IF($A32>F$31,(SUMPRODUCT(DCF_Base!$C$19:$L$19/(1+$A32)^DCF_Base!$C$4:$L$4)+MAX(0,MIN(IF($A32>F$31,DCF_Base!$L$19*(1+F$31)/($A32-F$31),1E+15),Assumptions!$B$5*DCF_Base!$L$19,DCF_Base!$B$47))/(1+$A32)^10-Assumptions!$B$6)/Assumptions!$B$7*Assumptions!$B$12,"n/a")
A33: 0.068 | B33: =IF($A33>B$31,(SUMPRODUCT(DCF_Base!$C$19:$L$19/(1+$A33)^DCF_Base!$C$4:$L$4)+MAX(0,MIN(IF($A33>B$31,DCF_Base!$L$19*(1+B$31)/($A33-B$31),1E+15),Assumptions!$B$5*DCF_Base!$L$19,DCF_Base!$B$47))/(1+$A33)^10-Assumptions!$B$6)/Assumptions!$B$7*Assumptions!$B$12,"n/a") | C33: =IF($A33>C$31,(SUMPRODUCT(DCF_Base!$C$19:$L$19/(1+$A33)^DCF_Base!$C$4:$L$4)+MAX(0,MIN(IF($A33>C$31,DCF_Base!$L$19*(1+C$31)/($A33-C$31),1E+15),Assumptions!$B$5*DCF_Base!$L$19,DCF_Base!$B$47))/(1+$A33)^10-Assumptions!$B$6)/Assumptions!$B$7*Assumptions!$B$12,"n/a") | D33: =IF($A33>D$31,(SUMPRODUCT(DCF_Base!$C$19:$L$19/(1+$A33)^DCF_Base!$C$4:$L$4)+MAX(0,MIN(IF($A33>D$31,DCF_Base!$L$19*(1+D$31)/($A33-D$31),1E+15),Assumptions!$B$5*DCF_Base!$L$19,DCF_Base!$B$47))/(1+$A33)^10-Assumptions!$B$6)/Assumptions!$B$7*Assumptions!$B$12,"n/a") | E33: =IF($A33>E$31,(SUMPRODUCT(DCF_Base!$C$19:$L$19/(1+$A33)^DCF_Base!$C$4:$L$4)+MAX(0,MIN(IF($A33>E$31,DCF_Base!$L$19*(1+E$31)/($A33-E$31),1E+15),Assumptions!$B$5*DCF_Base!$L$19,DCF_Base!$B$47))/(1+$A33)^10-Assumptions!$B$6)/Assumptions!$B$7*Assumptions!$B$12,"n/a") | F33: =IF($A33>F$31,(SUMPRODUCT(DCF_Base!$C$19:$L$19/(1+$A33)^DCF_Base!$C$4:$L$4)+MAX(0,MIN(IF($A33>F$31,DCF_Base!$L$19*(1+F$31)/($A33-F$31),1E+15),Assumptions!$B$5*DCF_Base!$L$19,DCF_Base!$B$47))/(1+$A33)^10-Assumptions!$B$6)/Assumptions!$B$7*Assumptions!$B$12,"n/a")
A34: 0.078 | B34: =IF($A34>B$31,(SUMPRODUCT(DCF_Base!$C$19:$L$19/(1+$A34)^DCF_Base!$C$4:$L$4)+MAX(0,MIN(IF($A34>B$31,DCF_Base!$L$19*(1+B$31)/($A34-B$31),1E+15),Assumptions!$B$5*DCF_Base!$L$19,DCF_Base!$B$47))/(1+$A34)^10-Assumptions!$B$6)/Assumptions!$B$7*Assumptions!$B$12,"n/a") | C34: =IF($A34>C$31,(SUMPRODUCT(DCF_Base!$C$19:$L$19/(1+$A34)^DCF_Base!$C$4:$L$4)+MAX(0,MIN(IF($A34>C$31,DCF_Base!$L$19*(1+C$31)/($A34-C$31),1E+15),Assumptions!$B$5*DCF_Base!$L$19,DCF_Base!$B$47))/(1+$A34)^10-Assumptions!$B$6)/Assumptions!$B$7*Assumptions!$B$12,"n/a") | D34: =IF($A34>D$31,(SUMPRODUCT(DCF_Base!$C$19:$L$19/(1+$A34)^DCF_Base!$C$4:$L$4)+MAX(0,MIN(IF($A34>D$31,DCF_Base!$L$19*(1+D$31)/($A34-D$31),1E+15),Assumptions!$B$5*DCF_Base!$L$19,DCF_Base!$B$47))/(1+$A34)^10-Assumptions!$B$6)/Assumptions!$B$7*Assumptions!$B$12,"n/a") | E34: =IF($A34>E$31,(SUMPRODUCT(DCF_Base!$C$19:$L$19/(1+$A34)^DCF_Base!$C$4:$L$4)+MAX(0,MIN(IF($A34>E$31,DCF_Base!$L$19*(1+E$31)/($A34-E$31),1E+15),Assumptions!$B$5*DCF_Base!$L$19,DCF_Base!$B$47))/(1+$A34)^10-Assumptions!$B$6)/Assumptions!$B$7*Assumptions!$B$12,"n/a") | F34: =IF($A34>F$31,(SUMPRODUCT(DCF_Base!$C$19:$L$19/(1+$A34)^DCF_Base!$C$4:$L$4)+MAX(0,MIN(IF($A34>F$31,DCF_Base!$L$19*(1+F$31)/($A34-F$31),1E+15),Assumptions!$B$5*DCF_Base!$L$19,DCF_Base!$B$47))/(1+$A34)^10-Assumptions!$B$6)/Assumptions!$B$7*Assumptions!$B$12,"n/a")
A35: 0.088 | B35: =IF($A35>B$31,(SUMPRODUCT(DCF_Base!$C$19:$L$19/(1+$A35)^DCF_Base!$C$4:$L$4)+MAX(0,MIN(IF($A35>B$31,DCF_Base!$L$19*(1+B$31)/($A35-B$31),1E+15),Assumptions!$B$5*DCF_Base!$L$19,DCF_Base!$B$47))/(1+$A35)^10-Assumptions!$B$6)/Assumptions!$B$7*Assumptions!$B$12,"n/a") | C35: =IF($A35>C$31,(SUMPRODUCT(DCF_Base!$C$19:$L$19/(1+$A35)^DCF_Base!$C$4:$L$4)+MAX(0,MIN(IF($A35>C$31,DCF_Base!$L$19*(1+C$31)/($A35-C$31),1E+15),Assumptions!$B$5*DCF_Base!$L$19,DCF_Base!$B$47))/(1+$A35)^10-Assumptions!$B$6)/Assumptions!$B$7*Assumptions!$B$12,"n/a") | D35: =IF($A35>D$31,(SUMPRODUCT(DCF_Base!$C$19:$L$19/(1+$A35)^DCF_Base!$C$4:$L$4)+MAX(0,MIN(IF($A35>D$31,DCF_Base!$L$19*(1+D$31)/($A35-D$31),1E+15),Assumptions!$B$5*DCF_Base!$L$19,DCF_Base!$B$47))/(1+$A35)^10-Assumptions!$B$6)/Assumptions!$B$7*Assumptions!$B$12,"n/a") | E35: =IF($A35>E$31,(SUMPRODUCT(DCF_Base!$C$19:$L$19/(1+$A35)^DCF_Base!$C$4:$L$4)+MAX(0,MIN(IF($A35>E$31,DCF_Base!$L$19*(1+E$31)/($A35-E$31),1E+15),Assumptions!$B$5*DCF_Base!$L$19,DCF_Base!$B$47))/(1+$A35)^10-Assumptions!$B$6)/Assumptions!$B$7*Assumptions!$B$12,"n/a") | F35: =IF($A35>F$31,(SUMPRODUCT(DCF_Base!$C$19:$L$19/(1+$A35)^DCF_Base!$C$4:$L$4)+MAX(0,MIN(IF($A35>F$31,DCF_Base!$L$19*(1+F$31)/($A35-F$31),1E+15),Assumptions!$B$5*DCF_Base!$L$19,DCF_Base!$B$47))/(1+$A35)^10-Assumptions!$B$6)/Assumptions!$B$7*Assumptions!$B$12,"n/a")
A36: 0.098 | B36: =IF($A36>B$31,(SUMPRODUCT(DCF_Base!$C$19:$L$19/(1+$A36)^DCF_Base!$C$4:$L$4)+MAX(0,MIN(IF($A36>B$31,DCF_Base!$L$19*(1+B$31)/($A36-B$31),1E+15),Assumptions!$B$5*DCF_Base!$L$19,DCF_Base!$B$47))/(1+$A36)^10-Assumptions!$B$6)/Assumptions!$B$7*Assumptions!$B$12,"n/a") | C36: =IF($A36>C$31,(SUMPRODUCT(DCF_Base!$C$19:$L$19/(1+$A36)^DCF_Base!$C$4:$L$4)+MAX(0,MIN(IF($A36>C$31,DCF_Base!$L$19*(1+C$31)/($A36-C$31),1E+15),Assumptions!$B$5*DCF_Base!$L$19,DCF_Base!$B$47))/(1+$A36)^10-Assumptions!$B$6)/Assumptions!$B$7*Assumptions!$B$12,"n/a") | D36: =IF($A36>D$31,(SUMPRODUCT(DCF_Base!$C$19:$L$19/(1+$A36)^DCF_Base!$C$4:$L$4)+MAX(0,MIN(IF($A36>D$31,DCF_Base!$L$19*(1+D$31)/($A36-D$31),1E+15),Assumptions!$B$5*DCF_Base!$L$19,DCF_Base!$B$47))/(1+$A36)^10-Assumptions!$B$6)/Assumptions!$B$7*Assumptions!$B$12,"n/a") | E36: =IF($A36>E$31,(SUMPRODUCT(DCF_Base!$C$19:$L$19/(1+$A36)^DCF_Base!$C$4:$L$4)+MAX(0,MIN(IF($A36>E$31,DCF_Base!$L$19*(1+E$31)/($A36-E$31),1E+15),Assumptions!$B$5*DCF_Base!$L$19,DCF_Base!$B$47))/(1+$A36)^10-Assumptions!$B$6)/Assumptions!$B$7*Assumptions!$B$12,"n/a") | F36: =IF($A36>F$31,(SUMPRODUCT(DCF_Base!$C$19:$L$19/(1+$A36)^DCF_Base!$C$4:$L$4)+MAX(0,MIN(IF($A36>F$31,DCF_Base!$L$19*(1+F$31)/($A36-F$31),1E+15),Assumptions!$B$5*DCF_Base!$L$19,DCF_Base!$B$47))/(1+$A36)^10-Assumptions!$B$6)/Assumptions!$B$7*Assumptions!$B$12,"n/a")
