Workbook

Sheet DCF Model
A1: NFLX DCF Valuation Model
A2: Valuation Date: 2026-06-24 | Gray cells are INPUTS - adjust to see valuation change
A4: KEY INPUTS
A5: Current Stock Price ($) | B5: 73.78
A6: Shares Outstanding (M, post-split) | B6: 4223
A7: Cash & Equivalents ($M) | B7: 12259.77
A8: Total Debt ($M) | B8: 14360.52
A9: Net Debt ($M) [Debt - Cash] | B9: =B8-B7 -> 0
A10: Base Year FCF ($M) [FY2025] | B10: 9461.1
A12: WACC (Base Case) | B12: 0.095
A13: Terminal Growth Rate (Base) | B13: 0.03
A14: Split Note | B14: 10-for-1 forward split Nov 2025. 422.3M pre-split x10 = 4,223M shares.
A16: BASE CASE FCF GROWTH ASSUMPTIONS
A17: FCF Growth Rate | B17: Year 1 | C17: Year 2 | D17: Year 3 | E17: Year 4 | F17: Year 5
B18: 0.16 | C18: 0.13 | D18: 0.11 | E18: 0.09 | F18: 0.07
A20: BASE CASE PROJECTIONS ($M)
B21: Year 1 | C21: Year 2 | D21: Year 3 | E21: Year 4 | F21: Year 5
A22: FCF ($M) | B22: =B10*(1+B17) -> 0 | C22: =B22*(1+C17) -> 0 | D22: =C22*(1+D17) -> 0 | E22: =D22*(1+E17) -> 0 | F22: =E22*(1+F17) -> 0
A23: Discount Factor | B23: =1/(1+$B$12)^1 -> 0 | C23: =1/(1+$B$12)^2 -> 0 | D23: =1/(1+$B$12)^3 -> 0 | E23: =1/(1+$B$12)^4 -> 0 | F23: =1/(1+$B$12)^5 -> 0
A24: PV of FCF ($M) | B24: =B22*B23 -> 0 | C24: =C22*C23 -> 0 | D24: =D22*D23 -> 0 | E24: =E22*E23 -> 0 | F24: =F22*F23 -> 0
A29: BASE CASE VALUATION
A30: Sum of PV of FCF ($M) | B30: =SUM(B24:F24) -> 0
A31: Terminal FCF [Year 5 FCF x (1+g)] | B31: =F22*(1+$B$13) -> 0
A32: Terminal Value ($M) | B32: =B31/($B$12-$B$13) -> 0
A33: PV of Terminal Value ($M) | B33: =B32*F23 -> 0
A34: Enterprise Value ($M) | B34: =B30+B33 -> 0
A35: Less: Net Debt ($M) | B35: =B9 -> 0
A36: Equity Value ($M) | B36: =B34-B35 -> 0
A37: INTRINSIC VALUE / SHARE | B37: =B36/B6 -> 0
A38: Current Price | B38: =B5 -> 0
A39: Upside / (Downside) | B39: =(B37-B5)/B5 -> 0
A41: ENTRY PRICE (15% CAGR Target)
A42: Terminal Value per Share | B42: =B32/B6 -> 0
A43: Entry Price for 15% CAGR over 5 Years | B43: =B42/(1.15^5) -> 0
A44: Discount from Current Price | B44: =(B5-B43)/B5 -> 0
A46: SCENARIO SUMMARY
A47: Metric | B47: Bear Case | C47: Base Case | D47: Bull Case | E47: Prob-Weighted
A48: WACC | B48: 0.11 | C48: 0.095 | D48: 0.085
A49: Terminal Growth | B49: 0.02 | C49: 0.03 | D49: 0.035
A50: IV / Share | B50: 29.04 | C50: 49.95 | D50: 72.26 | E50: 50.3
...

Sheet Sensitivity
A1: Sensitivity Analysis — Intrinsic Value per Share
A2: Base case FCF growth assumptions. Rows = WACC, Columns = Terminal Growth Rate
A4: WACC \ Term G | B4: 2.0% | C4: 2.5% | D4: 3.0% | E4: 3.5% | F4: 4.0%
A5: 0.08 | B5: 56.23 | C5: 60.46 | D5: 65.55 | E5: 71.76 | F5: 79.53
A6: 0.09 | B6: 47.87 | C6: 50.83 | D6: 54.28 | E6: 58.36 | F6: 63.26
A7: 0.1 | B7: 41.63 | C7: 43.79 | D7: 46.27 | E7: 49.12 | F7: 52.45
A8: 0.11 | B8: 36.76 | C8: 38.39 | D8: 40.23 | E8: 42.32 | F8: 44.7
A9: 0.12 | B9: 32.89 | C9: 34.16 | D9: 35.57 | E9: 37.15 | F9: 38.92
A10: Current Price: $73.78
A11: Green = above current price (+5%), Orange = within 5%, Red = below current price
A13: NOTE: All cells use base-case FCF growth rates. Only WACC and terminal growth vary.
A15: LIVE SENSITIVITY (links to DCF Model inputs):
A16: WACC \ Term G | B16: 2.0% | C16: 2.5% | D16: 3.0% | E16: 3.5% | F16: 4.0%
A17: 0.08 | B17: =((('DCF Model'!B22*(1/1.08)^1)+('DCF Model'!C22*(1/1.08)^2)+('DCF Model'!D22*(1/1.08)^3)+('DCF Model'!E22*(1/1.08)^4)+('DCF Model'!F22*(1/1.08)^5))+('DCF Model'!F22*(1+0.02)/(0.08-0.02)*(1/1.08)^5)-'DCF Model'!B9)/'DCF Model'!B6 -> 0 | C17: =((('DCF Model'!B22*(1/1.08)^1)+('DCF Model'!C22*(1/1.08)^2)+('DCF Model'!D22*(1/1.08)^3)+('DCF Model'!E22*(1/1.08)^4)+('DCF Model'!F22*(1/1.08)^5))+('DCF Model'!F22*(1+0.025)/(0.08-0.025)*(1/1.08)^5)-'DCF Model'!B9)/'DCF Model'!B6 -> 0 | D17: =((('DCF Model'!B22*(1/1.08)^1)+('DCF Model'!C22*(1/1.08)^2)+('DCF Model'!D22*(1/1.08)^3)+('DCF Model'!E22*(1/1.08)^4)+('DCF Model'!F22*(1/1.08)^5))+('DCF Model'!F22*(1+0.03)/(0.08-0.03)*(1/1.08)^5)-'DCF Model'!B9)/'DCF Model'!B6 -> 0 | E17: =((('DCF Model'!B22*(1/1.08)^1)+('DCF Model'!C22*(1/1.08)^2)+('DCF Model'!D22*(1/1.08)^3)+('DCF Model'!E22*(1/1.08)^4)+('DCF Model'!F22*(1/1.08)^5))+('DCF Model'!F22*(1+0.035)/(0.08-0.035)*(1/1.08)^5)-'DCF Model'!B9)/'DCF Model'!B6 -> 0 | F17: =((('DCF Model'!B22*(1/1.08)^1)+('DCF Model'!C22*(1/1.08)^2)+('DCF Model'!D22*(1/1.08)^3)+('DCF Model'!E22*(1/1.08)^4)+('DCF Model'!F22*(1/1.08)^5))+('DCF Model'!F22*(1+0.04)/(0.08-0.04)*(1/1.08)^5)-'DCF Model'!B9)/'DCF Model'!B6 -> 0
A18: 0.09 | B18: =((('DCF Model'!B22*(1/1.09)^1)+('DCF Model'!C22*(1/1.09)^2)+('DCF Model'!D22*(1/1.09)^3)+('DCF Model'!E22*(1/1.09)^4)+('DCF Model'!F22*(1/1.09)^5))+('DCF Model'!F22*(1+0.02)/(0.09-0.02)*(1/1.09)^5)-'DCF Model'!B9)/'DCF Model'!B6 -> 0 | C18: =((('DCF Model'!B22*(1/1.09)^1)+('DCF Model'!C22*(1/1.09)^2)+('DCF Model'!D22*(1/1.09)^3)+('DCF Model'!E22*(1/1.09)^4)+('DCF Model'!F22*(1/1.09)^5))+('DCF Model'!F22*(1+0.025)/(0.09-0.025)*(1/1.09)^5)-'DCF Model'!B9)/'DCF Model'!B6 -> 0 | D18: =((('DCF Model'!B22*(1/1.09)^1)+('DCF Model'!C22*(1/1.09)^2)+('DCF Model'!D22*(1/1.09)^3)+('DCF Model'!E22*(1/1.09)^4)+('DCF Model'!F22*(1/1.09)^5))+('DCF Model'!F22*(1+0.03)/(0.09-0.03)*(1/1.09)^5)-'DCF Model'!B9)/'DCF Model'!B6 -> 0 | E18: =((('DCF Model'!B22*(1/1.09)^1)+('DCF Model'!C22*(1/1.09)^2)+('DCF Model'!D22*(1/1.09)^3)+('DCF Model'!E22*(1/1.09)^4)+('DCF Model'!F22*(1/1.09)^5))+('DCF Model'!F22*(1+0.035)/(0.09-0.035)*(1/1.09)^5)-'DCF Model'!B9)/'DCF Model'!B6 -> 0 | F18: =((('DCF Model'!B22*(1/1.09)^1)+('DCF Model'!C22*(1/1.09)^2)+('DCF Model'!D22*(1/1.09)^3)+('DCF Model'!E22*(1/1.09)^4)+('DCF Model'!F22*(1/1.09)^5))+('DCF Model'!F22*(1+0.04)/(0.09-0.04)*(1/1.09)^5)-'DCF Model'!B9)/'DCF Model'!B6 -> 0
A19: 0.1 | B19: =((('DCF Model'!B22*(1/1.1)^1)+('DCF Model'!C22*(1/1.1)^2)+('DCF Model'!D22*(1/1.1)^3)+('DCF Model'!E22*(1/1.1)^4)+('DCF Model'!F22*(1/1.1)^5))+('DCF Model'!F22*(1+0.02)/(0.1-0.02)*(1/1.1)^5)-'DCF Model'!B9)/'DCF Model'!B6 -> 0 | C19: =((('DCF Model'!B22*(1/1.1)^1)+('DCF Model'!C22*(1/1.1)^2)+('DCF Model'!D22*(1/1.1)^3)+('DCF Model'!E22*(1/1.1)^4)+('DCF Model'!F22*(1/1.1)^5))+('DCF Model'!F22*(1+0.025)/(0.1-0.025)*(1/1.1)^5)-'DCF Model'!B9)/'DCF Model'!B6 -> 0 | D19: =((('DCF Model'!B22*(1/1.1)^1)+('DCF Model'!C22*(1/1.1)^2)+('DCF Model'!D22*(1/1.1)^3)+('DCF Model'!E22*(1/1.1)^4)+('DCF Model'!F22*(1/1.1)^5))+('DCF Model'!F22*(1+0.03)/(0.1-0.03)*(1/1.1)^5)-'DCF Model'!B9)/'DCF Model'!B6 -> 0 | E19: =((('DCF Model'!B22*(1/1.1)^1)+('DCF Model'!C22*(1/1.1)^2)+('DCF Model'!D22*(1/1.1)^3)+('DCF Model'!E22*(1/1.1)^4)+('DCF Model'!F22*(1/1.1)^5))+('DCF Model'!F22*(1+0.035)/(0.1-0.035)*(1/1.1)^5)-'DCF Model'!B9)/'DCF Model'!B6 -> 0 | F19: =((('DCF Model'!B22*(1/1.1)^1)+('DCF Model'!C22*(1/1.1)^2)+('DCF Model'!D22*(1/1.1)^3)+('DCF Model'!E22*(1/1.1)^4)+('DCF Model'!F22*(1/1.1)^5))+('DCF Model'!F22*(1+0.04)/(0.1-0.04)*(1/1.1)^5)-'DCF Model'!B9)/'DCF Model'!B6 -> 0
A20: 0.11 | B20: =((('DCF Model'!B22*(1/1.11)^1)+('DCF Model'!C22*(1/1.11)^2)+('DCF Model'!D22*(1/1.11)^3)+('DCF Model'!E22*(1/1.11)^4)+('DCF Model'!F22*(1/1.11)^5))+('DCF Model'!F22*(1+0.02)/(0.11-0.02)*(1/1.11)^5)-'DCF Model'!B9)/'DCF Model'!B6 -> 0 | C20: =((('DCF Model'!B22*(1/1.11)^1)+('DCF Model'!C22*(1/1.11)^2)+('DCF Model'!D22*(1/1.11)^3)+('DCF Model'!E22*(1/1.11)^4)+('DCF Model'!F22*(1/1.11)^5))+('DCF Model'!F22*(1+0.025)/(0.11-0.025)*(1/1.11)^5)-'DCF Model'!B9)/'DCF Model'!B6 -> 0 | D20: =((('DCF Model'!B22*(1/1.11)^1)+('DCF Model'!C22*(1/1.11)^2)+('DCF Model'!D22*(1/1.11)^3)+('DCF Model'!E22*(1/1.11)^4)+('DCF Model'!F22*(1/1.11)^5))+('DCF Model'!F22*(1+0.03)/(0.11-0.03)*(1/1.11)^5)-'DCF Model'!B9)/'DCF Model'!B6 -> 0 | E20: =((('DCF Model'!B22*(1/1.11)^1)+('DCF Model'!C22*(1/1.11)^2)+('DCF Model'!D22*(1/1.11)^3)+('DCF Model'!E22*(1/1.11)^4)+('DCF Model'!F22*(1/1.11)^5))+('DCF Model'!F22*(1+0.035)/(0.11-0.035)*(1/1.11)^5)-'DCF Model'!B9)/'DCF Model'!B6 -> 0 | F20: =((('DCF Model'!B22*(1/1.11)^1)+('DCF Model'!C22*(1/1.11)^2)+('DCF Model'!D22*(1/1.11)^3)+('DCF Model'!E22*(1/1.11)^4)+('DCF Model'!F22*(1/1.11)^5))+('DCF Model'!F22*(1+0.04)/(0.11-0.04)*(1/1.11)^5)-'DCF Model'!B9)/'DCF Model'!B6 -> 0
A21: 0.12 | B21: =((('DCF Model'!B22*(1/1.12)^1)+('DCF Model'!C22*(1/1.12)^2)+('DCF Model'!D22*(1/1.12)^3)+('DCF Model'!E22*(1/1.12)^4)+('DCF Model'!F22*(1/1.12)^5))+('DCF Model'!F22*(1+0.02)/(0.12-0.02)*(1/1.12)^5)-'DCF Model'!B9)/'DCF Model'!B6 -> 0 | C21: =((('DCF Model'!B22*(1/1.12)^1)+('DCF Model'!C22*(1/1.12)^2)+('DCF Model'!D22*(1/1.12)^3)+('DCF Model'!E22*(1/1.12)^4)+('DCF Model'!F22*(1/1.12)^5))+('DCF Model'!F22*(1+0.025)/(0.12-0.025)*(1/1.12)^5)-'DCF Model'!B9)/'DCF Model'!B6 -> 0 | D21: =((('DCF Model'!B22*(1/1.12)^1)+('DCF Model'!C22*(1/1.12)^2)+('DCF Model'!D22*(1/1.12)^3)+('DCF Model'!E22*(1/1.12)^4)+('DCF Model'!F22*(1/1.12)^5))+('DCF Model'!F22*(1+0.03)/(0.12-0.03)*(1/1.12)^5)-'DCF Model'!B9)/'DCF Model'!B6 -> 0 | E21: =((('DCF Model'!B22*(1/1.12)^1)+('DCF Model'!C22*(1/1.12)^2)+('DCF Model'!D22*(1/1.12)^3)+('DCF Model'!E22*(1/1.12)^4)+('DCF Model'!F22*(1/1.12)^5))+('DCF Model'!F22*(1+0.035)/(0.12-0.035)*(1/1.12)^5)-'DCF Model'!B9)/'DCF Model'!B6 -> 0 | F21: =((('DCF Model'!B22*(1/1.12)^1)+('DCF Model'!C22*(1/1.12)^2)+('DCF Model'!D22*(1/1.12)^3)+('DCF Model'!E22*(1/1.12)^4)+('DCF Model'!F22*(1/1.12)^5))+('DCF Model'!F22*(1+0.04)/(0.12-0.04)*(1/1.12)^5)-'DCF Model'!B9)/'DCF Model'!B6 -> 0
A22: Green = above $73.78, Orange = within 5%, Red = below $73.78

Sheet Scenarios
A1: NFLX — Bear / Base / Bull Scenarios
A2: Based on FY2025 FCF of $9,461.1M | Shares: 4,223M post-split
A4: Item | B4: Bear Case | C4: Base Case | D4: Bull Case
A5: WACC | B5: 11.0% | C5: 9.5% | D5: 8.5%
A6: Terminal Growth | B6: 2.0% | C6: 3.0% | D6: 3.5%
A7: FCF Margin | B7: 18.0% | C7: 21.0% | D7: 25.0%
A8: FCF Growth Y1 | B8: 10% | C8: 16% | D8: 18%
A9: FCF Growth Y2 | B9: 7% | C9: 13% | D9: 16%
A10: FCF Growth Y3 | B10: 5% | C10: 11% | D10: 14%
A11: FCF Growth Y4 | B11: 3% | C11: 9% | D11: 12%
A12: FCF Growth Y5 | B12: 2% | C12: 7% | D12: 10%
A13: --- Outputs --- | B13: --- | C13: --- | D13: ---
A14: Sum PV of FCF ($M) | B14: $42,187.3 | C14: $51,490.7 | D14: $56,881.6
A15: Terminal Value ($M) | B15: $139,219.8 | C15: $254,410.0 | D15: $376,501.9
... A24: Probability-Weighted IV | B24: 25% weight | C24: 50% weight -> $50.30 | D24: 25% weight

Sheet Historical Growth
A1: Historical Growth Rates — NFLX
A2: Data source: NFLX_Metrics.csv (FY2020-FY2025)
A4: Metric | B4: 3-Year CAGR | C4: 5-Year CAGR
A5: Revenue | B5: 0.1264 | C5: 0.1257
A6: EPS (split-adj) | B6: -0.2734 | C6: -0.0913
A7: Shareholders Equity | B7: 0.086 | C7: 0.0991
A8: Free Cash Flow | B8: 0.7758 | C8: 0.375
A10: Selected Growth Rate: | B10: 0.1257
A11: Source: | B11: revenue_5yr_cagr
A13: Notes: | B13: EPS CAGR computed from NI divided by post-split equivalent diluted shares (FY2022: NI/667M post-split eq, FY2025: NI/4250M post-split eq). EPS CAGR shows negative because pre-split EPS denominators are inconsistent across the split. FCF CAGR distorted by FY2021 trough ($184M). Equity CAGR understates business growth due to buybacks. Revenue 5yr CAGR selected as most representative.
A16: Key Historical Data Points:
A17: Period | B17: Revenue ($M) | C17: FCF ($M) | D17: Shareholders' Equity ($M)
A18: FY2020 | B18: 24996.1 | C18: 1924.7 | D18: 16594.4
A19: FY2021 | B19: 29697.8 | C19: 184.2 | D19: 22717.1
A20: FY2022 | B20: 31615.5 | C20: 1689.6 | D20: 20777.4
A21: FY2023 | B21: 33723.3 | C21: 6925.4 | D21: 20588.3
A22: FY2024 | B22: 39000.97 | C22: 6921.8 | D22: 24743.57
A23: FY2025 | B23: 45183.04 | C23: 9461.1 | D23: 26615.49
