Workbook

Sheet Model_Info
A1: Ticker | B1: DG.PA
A2: Company | B2: Vinci SA
A3: Valuation date | B3: 2026-10-26
A4: Current price | B4: 106.45
A5: Price as of | B5: 2026-10-23T15:39:30Z (Euronext Paris regular close, Friday; valuation written Monday 2026-10-26 before the open)
A6: Balance sheet date | B6: 2026-06-30
A7: Model | B7: owner_fcf_dcf_component
A8: Currency (model) | B8: EUR
A9: Currency (quote) | B9: EUR
A10: Units | B10: millions
A11: Engine | B11: dcf_engine v1
A12: Built at | B12: 2026-10-25T11:37:35Z
A13: Drivers file | B13: DG.PA_Drivers.json
A14: Convention | B14: Percents stored as percents; formulas divide by 100. Blue = input, green = link, black = formula.
A15: Methodology | B15: summary: Value Vinci as an owner would: unlevered owner FCF on the whole group, SBC and the full lease charge expensed, working capital tied to growth rather than to 2025's windfall, the French motorway concessions treated as the finite annuities they contractually are (zero terminal value after ASF's April 2036 expiry), NCI taken out at what the minorities are worth rather than at book, and one EUR WACC for all scenarios with the risks carried in the flows and weights. The question the model answers is what the post-2036 Vinci - airports, Energy Solutions, Construction - plus ten years of motorway cash is worth, not what a perpetuity on today's 18% margin would be. key_risks_to_valuation: Terminal mix: the 2037 group is capitalised at 16x owner FCF; every 1x on the cap is roughly EUR4-5/share; Working-capital capture: 25% of the revenue change vs a 2022-2025 history of EUR1.4-2.5bn/yr inflows - 10pp of capture is ~EUR8/share over the horizon; French taxation: each extra year of the exceptional surcharge is ~EUR0.8/share; a permanent +1.5pp on the cash tax rate is ~EUR6/share; Successor motorway arrangements: the base gives them zero; a 10% residual at concession margins (bull) is worth ~EUR5/share; NCI fair value is an estimate (EUR6.0bn vs EUR3.65bn book); airport M&A multiples decide which is right; Airport capex (Gatwick runway, Lisbon Alcochete in the 2030s) is charged as capex at 5.0-5.3% of revenue without a matching revenue uplift beyond the growth path
A16: Data sources | B16: price: Yahoo Finance chart API at inputs.price_as_of; 52-week range 104.25-143.15 financials: DG.PA_Metrics.csv (FY2016-FY2025 annual, H1-2016 to H1-2026 half-years, EUR millions) from the ticker DuckDB; FY2025 Universal Registration Document (cash-flow table 1.5, segment information note 1.1, net financial debt 1.6, EPS note, Note E.11 ADP stake, concession table p.398-400); H1 2026 half-year report (net financial debt, diluted-EPS note, balance sheet, outlook 7.2) qualitative: DG.PA_Analysis.json (2026-10-26): French transport-tax and surcharge risk, concession expiry overhang, record EUR76.8bn order book, FY2026 guidance (FCF could reach EUR6bn)
... A19: Scenario narrative: bull | B19: Energy Solutions rides electrification, data-centre and defence spending at high single-digit growth with margin to ~11%; airport capacity additions (Gatwick runway, OMA, Lisbon) lift airport growth; French fiscal measures lapse and the transport-tax case is won; order-book growth sustains large working-capital inflows; Vinci keeps a toehold in French motorways after 2036 via new concessions and operating contracts.

Sheet Actuals
A1: Period | B1: Revenue | C1: CostOfRevenue | D1: GrossProfit | E1: GrossMargin | F1: OperatingIncome | G1: OperatingMargin | H1: EBITDA | I1: NetIncome | J1: NetMargin | K1: EPS | L1: OperatingCashFlow | M1: CapEx | N1: FreeCashFlow | O1: ShareholdersEquity | P1: TotalAssets | Q1: TotalLiabilities | R1: TotalDebt | S1: CashAndEquivalents | T1: SharesOutstanding | U1: StockBasedComp | V1: DividendPerShare | W1: EBITDABeforeSignificant | X1: RevenueContinuing | Y1: EBITDAContinuingBeforeSignificant | Z1: EBITContinuingBeforeSignificant | AA1: Units | AB1: Currency | AC1: LeasePayments | AD1: OrderBook | AE1: OrderIntake
A2: FY2016 | B2: 38073 | F2: 4118 | G2: 10.8 | H2: 5966 | I2: 2505 | J2: 6.6 | K2: 4.48 | L2: 4346 | M2: 1397 | N2: 2949 | O2: 16465 | P2: 67931 | Q2: 50925 | R2: 21494 | S2: 6832 | T2: 559.2 | U2: 118 | AA2: millions | AB2: EUR
A3: FY2017 | B3: 40248 | F3: 4550 | G3: 11.3 | H3: 6500 | I3: 2747 | J3: 6.8 | K3: 4.91 | L3: 4280 | M3: 1755 | N3: 2525 | O3: 17812 | P3: 69803 | Q3: 51420 | R3: 21472 | S3: 6991 | T3: 559.5 | U3: 163 | AA3: millions | AB3: EUR
A4: FY2018 | B4: 43519 | F4: 4920 | G4: 11.3 | H4: 6898 | I4: 2983 | J4: 6.9 | K4: 5.32 | L4: 5142 | M4: 1963 | N4: 3179 | O4: 19185 | P4: 75357 | Q4: 55539 | R4: 24246 | S4: 8205 | T4: 560.7 | U4: 206 | AA4: millions | AB4: EUR
A5: FY2019 | B5: 48053 | F5: 5664 | G5: 11.8 | H5: 8497 | I5: 3260 | J5: 6.8 | K5: 5.82 | L5: 7090 | M5: 2314 | N5: 4776 | O5: 20438 | P5: 91159 | Q5: 68117 | R5: 30592 | S5: 8544 | T5: 560.1 | U5: 291 | AA5: millions | AB5: EUR | AC5: 575
A6: FY2020 | B6: 43234 | F6: 2459 | G6: 5.7 | H6: 5919 | I6: 1242 | J6: 2.9 | K6: 2.2 | L6: 6675 | M6: 2079 | N6: 4596 | O6: 20863 | P6: 91165 | Q6: 68141 | R6: 30593 | S6: 11902 | T6: 564.5 | U6: 239 | AA6: millions | AB6: EUR | AC6: 607
A7: FY2021 | B7: 49396 | F7: 4438 | G7: 9 | H7: 7884 | I7: 2597 | J7: 5.3 | K7: 4.51 | L7: 7806 | M7: 1892 | N7: 5914 | O7: 22881 | P7: 100816 | Q7: 76045 | R7: 30738 | S7: 11265 | T7: 575.8 | U7: 288 | AA7: millions | AB7: EUR | AC7: 631
A8: FY2022 | B8: 61675 | F8: 6489 | G8: 10.5 | H8: 10215 | I8: 4259 | J8: 6.9 | K8: 7.47 | L8: 9387 | M8: 3292 | N8: 6095 | O8: 25939 | P8: 111991 | Q8: 82582 | R8: 29998 | S8: 13333 | T8: 570.1 | U8: 356 | AA8: millions | AB8: EUR | AC8: 661
A9: FY2023 | B9: 68838 | F9: 8071 | G9: 11.7 | H9: 11964 | I9: 4702 | J9: 6.8 | K9: 8.18 | L9: 10540 | M9: 3233 | N9: 7307 | O9: 28113 | P9: 118558 | Q9: 86518 | R9: 30789 | S9: 16172 | T9: 574.8 | U9: 360 | AA9: millions | AB9: EUR | AC9: 679 | AD9: 61400 | AE9: 61900
A10: FY2024 | B10: 71623 | F10: 8783 | G10: 12.3 | H10: 12689 | I10: 4863 | J10: 6.8 | K10: 8.43 | L10: 11714 | M10: 4161 | N10: 7553 | O10: 29947 | P10: 129491 | Q10: 95459 | R10: 35270 | S10: 16094 | T10: 576.9 | U10: 462 | AA10: millions | AB10: EUR | AC10: 745 | AD10: 69100 | AE10: 66300
A11: FY2025 | B11: 74599 | F11: 9364 | G11: 12.6 | H11: 13507 | I11: 4903 | J11: 6.6 | K11: 8.65 | L11: 11886 | M11: 4005 | N11: 7881 | O11: 30752 | P11: 133065 | Q11: 98737 | R11: 36712 | S11: 18498 | T11: 566.8 | U11: 567 | AA11: millions | AB11: EUR | AC11: 871 | AD11: 69800 | AE11: 63000

Sheet Assumptions
A1: Input | B1: Value
A2: Current price (quote currency) | B2: 106.45
A3: Shares, final projected (m) | B3: 560.6
A4: Net debt (m, model currency) | B4: 22450
A5: Equity bridge total (m, + adds) | B5: -3105
A6: Hurdle rate (%) | B6: 15
A7: Base revenue FY0 (m) | B7: 74599
A8: FY0 | B8: FY2025
A9: Currency / units | B9: EUR millions
A10: FX rate (model -> quote) | B10: 1
A12: BEAR | C12: FY2026 | D12: FY2027 | E12: FY2028 | F12: FY2029 | G12: FY2030 | H12: FY2031 | I12: FY2032 | J12: FY2033 | K12: FY2034 | L12: FY2035 | M12: FY2036 | N12: FY2037
A13: Revenue growth (%) | C13: 1.36 | D13: 2.87 | E13: 2.87 | F13: 2.69 | G13: 2.41 | H13: 2.42 | I13: 1.24 | J13: 1.83 | K13: 0.9 | L13: 0.89 | M13: -1.61 | N13: 0.47
A14: EBITDA margin (%) | C14: 17.58 | D14: 17.51 | E14: 17.54 | F14: 17.58 | G14: 17.63 | H14: 17.58 | I14: 17.19 | J14: 17.11 | K14: 16.55 | L14: 15.98 | M14: 14.05 | N14: 13.22
A15: SBC (% of revenue) | C15: 0.85 | D15: 0.85 | E15: 0.85 | F15: 0.85 | G15: 0.85 | H15: 0.85 | I15: 0.85 | J15: 0.85 | K15: 0.85 | L15: 0.85 | M15: 0.85 | N15: 0.85
A16: Lease cost (% of revenue) | C16: 1.17 | D16: 1.17 | E16: 1.17 | F16: 1.17 | G16: 1.17 | H16: 1.18 | I16: 1.19 | J16: 1.19 | K16: 1.2 | L16: 1.21 | M16: 1.26 | N16: 1.28
A17: D&A (% of revenue) | C17: 4.63 | D17: 4.58 | E17: 4.53 | F17: 4.49 | G17: 4.45 | H17: 4.41 | I17: 4.23 | J17: 4.19 | K17: 4 | L17: 3.82 | M17: 3.25 | N17: 3.01
A18: Capex (% of revenue) | C18: 5.69 | D18: 5.89 | E18: 5.91 | F18: 5.85 | G18: 5.7 | H18: 5.53 | I18: 5.51 | J18: 5.34 | K18: 5.3 | L18: 5.26 | M18: 5.17 | N18: 5.2
A19: Cash tax rate (%) | C19: 34 | D19: 34 | E19: 31 | F19: 31 | G19: 31 | H19: 31 | I19: 31 | J19: 31 | K19: 31 | L19: 31 | M19: 31 | N19: 31
A20: WACC (%) | B20: 7
A21: Terminal growth (%) | B21: 1.5
A22: Terminal cap multiple (x FCF) | B22: 13
A23: Working-capital capture (% of revenue change) | B23: 10
A24: Scenario weight | B24: 0.25
A26: BASE | C26: FY2026 | D26: FY2027 | E26: FY2028 | F26: FY2029 | G26: FY2030 | H26: FY2031 | I26: FY2032 | J26: FY2033 | K26: FY2034 | L26: FY2035 | M26: FY2036 | N26: FY2037
A27: Revenue growth (%) | C27: 2.55 | D27: 4.32 | E27: 4.33 | F27: 4.05 | G27: 3.87 | H27: 3.69 | I27: 2.53 | J27: 3.02 | K27: 1.91 | L27: 1.72 | M27: -1.03 | N27: 0.99
A28: EBITDA margin (%) | C28: 18.07 | D28: 18.16 | E28: 18.26 | F28: 18.27 | G28: 18.3 | H28: 18.34 | I28: 17.93 | J28: 17.84 | K28: 17.37 | L28: 16.8 | M28: 14.86 | N28: 14.03
A29: SBC (% of revenue) | C29: 0.75 | D29: 0.75 | E29: 0.75 | F29: 0.75 | G29: 0.75 | H29: 0.75 | I29: 0.75 | J29: 0.75 | K29: 0.75 | L29: 0.75 | M29: 0.75 | N29: 0.75
A30: Lease cost (% of revenue) | C30: 1.17 | D30: 1.17 | E30: 1.17 | F30: 1.17 | G30: 1.18 | H30: 1.18 | I30: 1.19 | J30: 1.19 | K30: 1.2 | L30: 1.22 | M30: 1.26 | N30: 1.28
A31: D&A (% of revenue) | C31: 4.61 | D31: 4.53 | E31: 4.46 | F31: 4.4 | G31: 4.34 | H31: 4.28 | I31: 4.11 | J31: 4.05 | K31: 3.87 | L31: 3.7 | M31: 3.21 | N31: 3
A32: Capex (% of revenue) | C32: 5.47 | D32: 5.56 | E32: 5.57 | F32: 5.49 | G32: 5.32 | H32: 5.16 | I32: 5.14 | J32: 5.09 | K32: 5.06 | L32: 4.93 | M32: 4.97 | N32: 5
A33: Cash tax rate (%) | C33: 34 | D33: 29.5 | E33: 29.5 | F33: 29.5 | G33: 29.5 | H33: 29.5 | I33: 29.5 | J33: 29.5 | K33: 29.5 | L33: 29.5 | M33: 29.5 | N33: 29.5
A34: WACC (%) | B34: 7
A35: Terminal growth (%) | B35: 2
A36: Terminal cap multiple (x FCF) | B36: 16
A37: Working-capital capture (% of revenue change) | B37: 25
A38: Scenario weight | B38: 0.5
A40: BULL | C40: FY2026 | D40: FY2027 | E40: FY2028 | F40: FY2029 | G40: FY2030 | H40: FY2031 | I40: FY2032 | J40: FY2033 | K40: FY2034 | L40: FY2035 | M40: FY2036 | N40: FY2037
A41: Revenue growth (%) | C41: 3.36 | D41: 5.73 | E41: 5.74 | F41: 5.29 | G41: 4.83 | H41: 4.38 | I41: 3.05 | J41: 3.34 | K41: 2.16 | L41: 1.96 | M41: -0.66 | N41: 1.5
A42: EBITDA margin (%) | C42: 18.26 | D42: 18.49 | E42: 18.63 | F42: 18.8 | G42: 18.9 | H42: 19.02 | I42: 18.63 | J42: 18.64 | K42: 18.19 | L42: 17.64 | M42: 15.74 | N42: 15.19
A43: SBC (% of revenue) | C43: 0.7 | D43: 0.7 | E43: 0.7 | F43: 0.7 | G43: 0.7 | H43: 0.7 | I43: 0.7 | J43: 0.7 | K43: 0.7 | L43: 0.7 | M43: 0.7 | N43: 0.7
...

Sheet DCF_Bear
A1: DG.PA owner-FCF component DCF: bear case (millions, EUR)
A3: Line | B3: FY2025 | C3: FY2026 | D3: FY2027 | E3: FY2028 | F3: FY2029 | G3: FY2030 | H3: FY2031 | I3: FY2032 | J3: FY2033 | K3: FY2034 | L3: FY2035 | M3: FY2036 | N3: FY2037
A4: Year index (discount exponent) | B4: 0 | C4: =B4+1 -> 1 | D4: =C4+1 -> 2 | E4: =D4+1 -> 3 | F4: =E4+1 -> 4 | G4: =F4+1 -> 5 | H4: =G4+1 -> 6 | I4: =H4+1 -> 7 | J4: =I4+1 -> 8 | ... N4: =M4+1 -> 12
A5: Revenue growth (%) | C5: =Assumptions!C13 -> 1.36 | D5: =Assumptions!D13 -> 2.87 | E5: =Assumptions!E13 -> 2.87 | F5: =Assumptions!F13 -> 2.69 | G5: =Assumptions!G13 -> 2.41 | H5: =Assumptions!H13 -> 2.42 | I5: =Assumptions!I13 -> 1.24 | J5: =Assumptions!J13 -> 1.83 | ... N5: =Assumptions!N13 -> 0.47
A6: Revenue | B6: 74599 | C6: =B6*(1+C5/100) -> 75613.546 | D6: =C6*(1+D5/100) -> 77783.655 | E6: =D6*(1+E5/100) -> 80016.046 | F6: =E6*(1+F5/100) -> 82168.478 | G6: =F6*(1+G5/100) -> 84148.738 | H6: =G6*(1+H5/100) -> 86185.137 | I6: =H6*(1+I5/100) -> 87253.833 | J6: =I6*(1+J5/100) -> 88850.578 | ... N6: =M6*(1+N5/100) -> 89410.168
A7: EBITDA margin (%) | C7: =Assumptions!C14 -> 17.58 | D7: =Assumptions!D14 -> 17.51 | E7: =Assumptions!E14 -> 17.54 | F7: =Assumptions!F14 -> 17.58 | G7: =Assumptions!G14 -> 17.63 | H7: =Assumptions!H14 -> 17.58 | I7: =Assumptions!I14 -> 17.19 | J7: =Assumptions!J14 -> 17.11 | ... N7: =Assumptions!N14 -> 13.22
A8: EBITDA | C8: =C6*C7/100 -> 13292.861 | D8: =D6*D7/100 -> 13619.918 | E8: =E6*E7/100 -> 14034.814 | F8: =F6*F7/100 -> 14445.218 | G8: =G6*G7/100 -> 14835.423 | H8: =H6*H7/100 -> 15151.347 | I8: =I6*I7/100 -> 14998.934 | J8: =J6*J7/100 -> 15202.334 | ... N8: =N6*N7/100 -> 11820.024
A9: SBC (% of revenue) | C9: =Assumptions!C15 -> 0.85 | D9: =Assumptions!D15 -> 0.85 | E9: =Assumptions!E15 -> 0.85 | F9: =Assumptions!F15 -> 0.85 | G9: =Assumptions!G15 -> 0.85 | H9: =Assumptions!H15 -> 0.85 | I9: =Assumptions!I15 -> 0.85 | J9: =Assumptions!J15 -> 0.85 | ... N9: =Assumptions!N15 -> 0.85
A10: SBC charge | C10: =-C6*C9/100 -> -642.71514 | D10: =-D6*D9/100 -> -661.16107 | E10: =-E6*E9/100 -> -680.13639 | F10: =-F6*F9/100 -> -698.43206 | G10: =-G6*G9/100 -> -715.26427 | H10: =-H6*H9/100 -> -732.57367 | I10: =-I6*I9/100 -> -741.65758 | J10: =-J6*J9/100 -> -755.22992 | ... N10: =-N6*N9/100 -> -759.98643
A11: Owner EBITDA (after SBC and leases) | C11: =C8+C10+C24 -> 11765.468 | D11: =D8+D10+D24 -> 12048.688 | E11: =E8+E10+E24 -> 12418.49 | F11: =F8+F10+F24 -> 12785.415 | G11: =G8+G10+G24 -> 13135.618 | H11: =H8+H10+H24 -> 13401.789 | I11: =I8+I10+I24 -> 13218.956 | J11: =J8+J10+J24 -> 13389.782 | ... N11: =N8+N10+N24 -> 9915.5876
A12: D&A | C12: =-C6*Assumptions!C17/100 -> -3500.9072 | D12: =-D6*Assumptions!D17/100 -> -3562.4914 | E12: =-E6*Assumptions!E17/100 -> -3624.7269 | F12: =-F6*Assumptions!F17/100 -> -3689.3646 | G12: =-G6*Assumptions!G17/100 -> -3744.6188 | H12: =-H6*Assumptions!H17/100 -> -3800.7646 | I12: =-I6*Assumptions!I17/100 -> -3690.8371 | J12: =-J6*Assumptions!J17/100 -> -3722.8392 | ... N12: =-N6*Assumptions!N17/100 -> -2691.2461
A13: EBIT | C13: =C11+C12 -> 8264.5606 | D13: =D11+D12 -> 8486.1968 | E13: =E11+E12 -> 8793.7635 | F13: =F11+F12 -> 9096.0505 | G13: =G11+G12 -> 9390.9992 | H13: =H11+H12 -> 9601.0243 | I13: =I11+I12 -> 9528.1186 | J13: =J11+J12 -> 9666.9429 | ... N13: =N11+N12 -> 7224.3416
A14: Cash tax rate (%) | C14: =Assumptions!C19 -> 34 | D14: =Assumptions!D19 -> 34 | E14: =Assumptions!E19 -> 31 | F14: =Assumptions!F19 -> 31 | G14: =Assumptions!G19 -> 31 | H14: =Assumptions!H19 -> 31 | I14: =Assumptions!I19 -> 31 | J14: =Assumptions!J19 -> 31 | ... N14: =Assumptions!N19 -> 31
A15: NOPAT | C15: =C13-MAX(0,C13)*C14/100 -> 5454.61 | D15: =D13-MAX(0,D13)*D14/100 -> 5600.8899 | E15: =E13-MAX(0,E13)*E14/100 -> 6067.6968 | F15: =F13-MAX(0,F13)*F14/100 -> 6276.2748 | G15: =G13-MAX(0,G13)*G14/100 -> 6479.7894 | H15: =H13-MAX(0,H13)*H14/100 -> 6624.7068 | I15: =I13-MAX(0,I13)*I14/100 -> 6574.4018 | J15: =J13-MAX(0,J13)*J14/100 -> 6670.1906 | ... N15: =N13-MAX(0,N13)*N14/100 -> 4984.7957
A16: D&A add-back | C16: =-C12 -> 3500.9072 | D16: =-D12 -> 3562.4914 | E16: =-E12 -> 3624.7269 | F16: =-F12 -> 3689.3646 | G16: =-G12 -> 3744.6188 | H16: =-H12 -> 3800.7646 | I16: =-I12 -> 3690.8371 | J16: =-J12 -> 3722.8392 | ... N16: =-N12 -> 2691.2461
A17: Capex | C17: =-C6*Assumptions!C18/100 -> -4302.4108 | D17: =-D6*Assumptions!D18/100 -> -4581.4573 | E17: =-E6*Assumptions!E18/100 -> -4728.9483 | F17: =-F6*Assumptions!F18/100 -> -4806.8559 | G17: =-G6*Assumptions!G18/100 -> -4796.4781 | H17: =-H6*Assumptions!H18/100 -> -4766.0381 | I17: =-I6*Assumptions!I18/100 -> -4807.6862 | J17: =-J6*Assumptions!J18/100 -> -4744.6209 | ... N17: =-N6*Assumptions!N18/100 -> -4649.3287
A18: Working capital | C18: =(C6-B6)*Assumptions!$B$23/100 -> 101.45464 | D18: =(D6-C6)*Assumptions!$B$23/100 -> 217.01088 | E18: =(E6-D6)*Assumptions!$B$23/100 -> 223.23909 | F18: =(F6-E6)*Assumptions!$B$23/100 -> 215.24316 | G18: =(G6-F6)*Assumptions!$B$23/100 -> 198.02603 | H18: =(H6-G6)*Assumptions!$B$23/100 -> 203.63995 | I18: =(I6-H6)*Assumptions!$B$23/100 -> 106.86957 | J18: =(J6-I6)*Assumptions!$B$23/100 -> 159.67451 | ... N18: =(N6-M6)*Assumptions!$B$23/100 -> 41.826196
A19: Unlevered owner FCF | C19: =C15+C16+C17+C18 -> 4754.5611 | D19: =D15+D16+D17+D18 -> 4798.9349 | E19: =E15+E16+E17+E18 -> 5186.7144 | F19: =F15+F16+F17+F18 -> 5374.0267 | G19: =G15+G16+G17+G18 -> 5625.9562 | H19: =H15+H16+H17+H18 -> 5863.0732 | I19: =I15+I16+I17+I18 -> 5564.4223 | J19: =J15+J16+J17+J18 -> 5808.0835 | ... N19: =N15+N16+N17+N18 -> 3068.5392
A20: Discount factor | C20: =1/(1+$B$27/100)^C4 -> 0.93457944 | D20: =1/(1+$B$27/100)^D4 -> 0.87343873 | E20: =1/(1+$B$27/100)^E4 -> 0.81629788 | F20: =1/(1+$B$27/100)^F4 -> 0.76289521 | G20: =1/(1+$B$27/100)^G4 -> 0.71298618 | H20: =1/(1+$B$27/100)^H4 -> 0.66634222 | I20: =1/(1+$B$27/100)^I4 -> 0.62274974 | J20: =1/(1+$B$27/100)^J4 -> 0.5820091 | ... N20: =1/(1+$B$27/100)^N4 -> 0.44401196
A21: PV of FCF | C21: =C19*C20 -> 4443.515 | D21: =D19*D20 -> 4191.5756 | E21: =E19*E20 -> 4233.904 | F21: =F19*F20 -> 4099.8192 | G21: =G19*G20 -> 4011.229 | H21: =H19*H20 -> 3906.8132 | I21: =I19*I20 -> 3465.2426 | J21: =J19*J20 -> 3380.3575 | ... N21: =N19*N20 -> 1362.4681
A23: Lease cost (% of revenue) | C23: =Assumptions!C16 -> 1.17 | D23: =Assumptions!D16 -> 1.17 | E23: =Assumptions!E16 -> 1.17 | F23: =Assumptions!F16 -> 1.17 | G23: =Assumptions!G16 -> 1.17 | H23: =Assumptions!H16 -> 1.18 | I23: =Assumptions!I16 -> 1.19 | J23: =Assumptions!J16 -> 1.19 | ... N23: =Assumptions!N16 -> 1.28
A24: Lease cost | C24: =-C6*C23/100 -> -884.67849 | D24: =-D6*D23/100 -> -910.06877 | E24: =-E6*E23/100 -> -936.18774 | F24: =-F6*F23/100 -> -961.37119 | G24: =-G6*G23/100 -> -984.54024 | H24: =-H6*H23/100 -> -1016.9846 | I24: =-I6*I23/100 -> -1038.3206 | J24: =-J6*J23/100 -> -1057.3219 | ... N24: =-N6*N23/100 -> -1144.4501
A26: Valuation
A27: WACC (%) | B27: =Assumptions!$B$20 -> 7
A28: Terminal growth (%) | B28: =Assumptions!$B$21 -> 1.5
A29: Terminal cap multiple (x FCF) | B29: =Assumptions!$B$22 -> 13
A30: Sum of PV of FCF | B30: =SUM(C21:N21) -> 40274.347
A31: Terminal-year FCF | B31: =N19 -> 3068.5392
A32: Gordon terminal value | B32: =IF(B27>B28,B31*(1+B28/100)/((B27-B28)/100),B31*B29) -> 56628.496
A33: Cap terminal value | B33: =B31*B29 -> 39891.01
A34: Terminal value used: MAX(0,MIN(Gordon,cap)) | B34: =MAX(0,MIN(B32,B33)) -> 39891.01
A35: PV of terminal value | B35: =B34/(1+B27/100)^N4 -> 17712.085
A36: Enterprise value | B36: =B30+B35 -> 57986.433
A37: Equity value (EV + bridge - net debt) | B37: =B36+Assumptions!$B$5-Assumptions!$B$4 -> 32431.433
A38: Value per share (quote currency) | B38: =B37/Assumptions!$B$3*Assumptions!$B$10 -> 57.851289
A39: Upside vs price | B39: =B38/Assumptions!$B$2-1 -> -0.45654026
A41: Street memo: PV of explicit-period SBC | B41: =SUMPRODUCT(-C10:N10/(1+$B$27/100)^C4:N4) -> 5667.8463
A42: Street memo: PV of terminal SBC (Gordon) | B42: =IF(B27>B28,-N10*(1+B28/100)/((B27-B28)/100),-N10*20)/(1+B27/100)^N4 -> 6227.3583
A43: Street value per share | B43: =(B37+B41+B42)/Assumptions!$B$3*Assumptions!$B$10 -> 79.069992
A45: Hurdle rate (%) | B45: =Assumptions!$B$6 -> 15
...

Sheet DCF_Base
A1: DG.PA owner-FCF component DCF: base case (millions, EUR)
A3: Line | B3: FY2025 | C3: FY2026 | D3: FY2027 | E3: FY2028 | F3: FY2029 | G3: FY2030 | H3: FY2031 | I3: FY2032 | J3: FY2033 | K3: FY2034 | L3: FY2035 | M3: FY2036 | N3: FY2037
A4: Year index (discount exponent) | B4: 0 | C4: =B4+1 -> 1 | D4: =C4+1 -> 2 | E4: =D4+1 -> 3 | F4: =E4+1 -> 4 | G4: =F4+1 -> 5 | H4: =G4+1 -> 6 | I4: =H4+1 -> 7 | J4: =I4+1 -> 8 | ... N4: =M4+1 -> 12
A5: Revenue growth (%) | C5: =Assumptions!C27 -> 2.55 | D5: =Assumptions!D27 -> 4.32 | E5: =Assumptions!E27 -> 4.33 | F5: =Assumptions!F27 -> 4.05 | G5: =Assumptions!G27 -> 3.87 | H5: =Assumptions!H27 -> 3.69 | I5: =Assumptions!I27 -> 2.53 | J5: =Assumptions!J27 -> 3.02 | ... N5: =Assumptions!N27 -> 0.99
A6: Revenue | B6: 74599 | C6: =B6*(1+C5/100) -> 76501.274 | D6: =C6*(1+D5/100) -> 79806.13 | E6: =D6*(1+E5/100) -> 83261.735 | F6: =E6*(1+F5/100) -> 86633.835 | G6: =F6*(1+G5/100) -> 89986.565 | H6: =G6*(1+H5/100) -> 93307.069 | I6: =H6*(1+I5/100) -> 95667.738 | J6: =I6*(1+J5/100) -> 98556.903 | ... N6: =M6*(1+N5/100) -> 102115.61
A7: EBITDA margin (%) | C7: =Assumptions!C28 -> 18.07 | D7: =Assumptions!D28 -> 18.16 | E7: =Assumptions!E28 -> 18.26 | F7: =Assumptions!F28 -> 18.27 | G7: =Assumptions!G28 -> 18.3 | H7: =Assumptions!H28 -> 18.34 | I7: =Assumptions!I28 -> 17.93 | J7: =Assumptions!J28 -> 17.84 | ... N7: =Assumptions!N28 -> 14.03
A8: EBITDA | C8: =C6*C7/100 -> 13823.78 | D8: =D6*D7/100 -> 14492.793 | E8: =E6*E7/100 -> 15203.593 | F8: =F6*F7/100 -> 15828.002 | G8: =G6*G7/100 -> 16467.541 | H8: =H6*H7/100 -> 17112.516 | I8: =I6*I7/100 -> 17153.225 | J8: =J6*J7/100 -> 17582.552 | ... N8: =N6*N7/100 -> 14326.82
A9: SBC (% of revenue) | C9: =Assumptions!C29 -> 0.75 | D9: =Assumptions!D29 -> 0.75 | E9: =Assumptions!E29 -> 0.75 | F9: =Assumptions!F29 -> 0.75 | G9: =Assumptions!G29 -> 0.75 | H9: =Assumptions!H29 -> 0.75 | I9: =Assumptions!I29 -> 0.75 | J9: =Assumptions!J29 -> 0.75 | ... N9: =Assumptions!N29 -> 0.75
A10: SBC charge | C10: =-C6*C9/100 -> -573.75956 | D10: =-D6*D9/100 -> -598.54597 | E10: =-E6*E9/100 -> -624.46301 | F10: =-F6*F9/100 -> -649.75376 | G10: =-G6*G9/100 -> -674.89923 | H10: =-H6*H9/100 -> -699.80302 | I10: =-I6*I9/100 -> -717.50803 | J10: =-J6*J9/100 -> -739.17678 | ... N10: =-N6*N9/100 -> -765.86709
A11: Owner EBITDA (after SBC and leases) | C11: =C8+C10+C24 -> 12354.956 | D11: =D8+D10+D24 -> 12960.515 | E11: =E8+E10+E24 -> 13604.967 | F11: =F8+F10+F24 -> 14164.632 | G11: =G8+G10+G24 -> 14730.801 | H11: =H8+H10+H24 -> 15311.69 | I11: =I8+I10+I24 -> 15297.271 | J11: =J8+J10+J24 -> 15670.548 | ... N11: =N8+N10+N24 -> 12253.873
A12: D&A | C12: =-C6*Assumptions!C31/100 -> -3526.7088 | D12: =-D6*Assumptions!D31/100 -> -3615.2177 | E12: =-E6*Assumptions!E31/100 -> -3713.4734 | F12: =-F6*Assumptions!F31/100 -> -3811.8888 | G12: =-G6*Assumptions!G31/100 -> -3905.4169 | H12: =-H6*Assumptions!H31/100 -> -3993.5425 | I12: =-I6*Assumptions!I31/100 -> -3931.944 | J12: =-J6*Assumptions!J31/100 -> -3991.5546 | ... N12: =-N6*Assumptions!N31/100 -> -3063.4684
A13: EBIT | C13: =C11+C12 -> 8828.2471 | D13: =D11+D12 -> 9345.2978 | E13: =E11+E12 -> 9891.4941 | F13: =F11+F12 -> 10352.743 | G13: =G11+G12 -> 10825.384 | H13: =H11+H12 -> 11318.147 | I13: =I11+I12 -> 11365.327 | J13: =J11+J12 -> 11678.993 | ... N13: =N11+N12 -> 9190.4051
A14: Cash tax rate (%) | C14: =Assumptions!C33 -> 34 | D14: =Assumptions!D33 -> 29.5 | E14: =Assumptions!E33 -> 29.5 | F14: =Assumptions!F33 -> 29.5 | G14: =Assumptions!G33 -> 29.5 | H14: =Assumptions!H33 -> 29.5 | I14: =Assumptions!I33 -> 29.5 | J14: =Assumptions!J33 -> 29.5 | ... N14: =Assumptions!N33 -> 29.5
A15: NOPAT | C15: =C13-MAX(0,C13)*C14/100 -> 5826.6431 | D15: =D13-MAX(0,D13)*D14/100 -> 6588.4349 | E15: =E13-MAX(0,E13)*E14/100 -> 6973.5034 | F15: =F13-MAX(0,F13)*F14/100 -> 7298.684 | G15: =G13-MAX(0,G13)*G14/100 -> 7631.8955 | H15: =H13-MAX(0,H13)*H14/100 -> 7979.294 | I15: =I13-MAX(0,I13)*I14/100 -> 8012.5557 | J15: =J13-MAX(0,J13)*J14/100 -> 8233.6901 | ... N15: =N13-MAX(0,N13)*N14/100 -> 6479.2356
A16: D&A add-back | C16: =-C12 -> 3526.7088 | D16: =-D12 -> 3615.2177 | E16: =-E12 -> 3713.4734 | F16: =-F12 -> 3811.8888 | G16: =-G12 -> 3905.4169 | H16: =-H12 -> 3993.5425 | I16: =-I12 -> 3931.944 | J16: =-J12 -> 3991.5546 | ... N16: =-N12 -> 3063.4684
A17: Capex | C17: =-C6*Assumptions!C32/100 -> -4184.6197 | D17: =-D6*Assumptions!D32/100 -> -4437.2208 | E17: =-E6*Assumptions!E32/100 -> -4637.6786 | F17: =-F6*Assumptions!F32/100 -> -4756.1976 | G17: =-G6*Assumptions!G32/100 -> -4787.2852 | H17: =-H6*Assumptions!H32/100 -> -4814.6448 | I17: =-I6*Assumptions!I32/100 -> -4917.3217 | J17: =-J6*Assumptions!J32/100 -> -5016.5464 | ... N17: =-N6*Assumptions!N32/100 -> -5105.7806
A18: Working capital | C18: =(C6-B6)*Assumptions!$B$37/100 -> 475.56862 | D18: =(D6-C6)*Assumptions!$B$37/100 -> 826.21376 | E18: =(E6-D6)*Assumptions!$B$37/100 -> 863.90135 | F18: =(F6-E6)*Assumptions!$B$37/100 -> 843.02507 | G18: =(G6-F6)*Assumptions!$B$37/100 -> 838.18236 | H18: =(H6-G6)*Assumptions!$B$37/100 -> 830.12606 | I18: =(I6-H6)*Assumptions!$B$37/100 -> 590.16721 | J18: =(J6-I6)*Assumptions!$B$37/100 -> 722.29142 | ... N18: =(N6-M6)*Assumptions!$B$37/100 -> 250.25858
A19: Unlevered owner FCF | C19: =C15+C16+C17+C18 -> 5644.3007 | D19: =D15+D16+D17+D18 -> 6592.6456 | E19: =E15+E16+E17+E18 -> 6913.1994 | F19: =F15+F16+F17+F18 -> 7197.4003 | G19: =G15+G16+G17+G18 -> 7588.2096 | H19: =H15+H16+H17+H18 -> 7988.3178 | I19: =I15+I16+I17+I18 -> 7617.3452 | J19: =J15+J16+J17+J18 -> 7930.9897 | ... N19: =N15+N16+N17+N18 -> 4687.1819
A20: Discount factor | C20: =1/(1+$B$27/100)^C4 -> 0.93457944 | D20: =1/(1+$B$27/100)^D4 -> 0.87343873 | E20: =1/(1+$B$27/100)^E4 -> 0.81629788 | F20: =1/(1+$B$27/100)^F4 -> 0.76289521 | G20: =1/(1+$B$27/100)^G4 -> 0.71298618 | H20: =1/(1+$B$27/100)^H4 -> 0.66634222 | I20: =1/(1+$B$27/100)^I4 -> 0.62274974 | J20: =1/(1+$B$27/100)^J4 -> 0.5820091 | ... N20: =1/(1+$B$27/100)^N4 -> 0.44401196
A21: PV of FCF | C21: =C19*C20 -> 5275.0474 | D21: =D19*D20 -> 5758.272 | E21: =E19*E20 -> 5643.23 | F21: =F19*F20 -> 5490.8622 | G21: =G19*G20 -> 5410.2885 | H21: =H19*H20 -> 5322.9535 | I21: =I19*I20 -> 4743.6998 | J21: =J19*J20 -> 4615.9082 | ... N21: =N19*N20 -> 2081.1648
A23: Lease cost (% of revenue) | C23: =Assumptions!C30 -> 1.17 | D23: =Assumptions!D30 -> 1.17 | E23: =Assumptions!E30 -> 1.17 | F23: =Assumptions!F30 -> 1.17 | G23: =Assumptions!G30 -> 1.18 | H23: =Assumptions!H30 -> 1.18 | I23: =Assumptions!I30 -> 1.19 | J23: =Assumptions!J30 -> 1.19 | ... N23: =Assumptions!N30 -> 1.28
A24: Lease cost | C24: =-C6*C23/100 -> -895.06491 | D24: =-D6*D23/100 -> -933.73172 | E24: =-E6*E23/100 -> -974.1623 | F24: =-F6*F23/100 -> -1013.6159 | G24: =-G6*G23/100 -> -1061.8415 | H24: =-H6*H23/100 -> -1101.0234 | I24: =-I6*I23/100 -> -1138.4461 | J24: =-J6*J23/100 -> -1172.8272 | ... N24: =-N6*N23/100 -> -1307.0798
A26: Valuation
A27: WACC (%) | B27: =Assumptions!$B$34 -> 7
A28: Terminal growth (%) | B28: =Assumptions!$B$35 -> 2
A29: Terminal cap multiple (x FCF) | B29: =Assumptions!$B$36 -> 16
A30: Sum of PV of FCF | B30: =SUM(C21:N21) -> 54346.205
A31: Terminal-year FCF | B31: =N19 -> 4687.1819
A32: Gordon terminal value | B32: =IF(B27>B28,B31*(1+B28/100)/((B27-B28)/100),B31*B29) -> 95618.511
A33: Cap terminal value | B33: =B31*B29 -> 74994.911
A34: Terminal value used: MAX(0,MIN(Gordon,cap)) | B34: =MAX(0,MIN(B32,B33)) -> 74994.911
A35: PV of terminal value | B35: =B34/(1+B27/100)^N4 -> 33298.637
A36: Enterprise value | B36: =B30+B35 -> 87644.843
A37: Equity value (EV + bridge - net debt) | B37: =B36+Assumptions!$B$5-Assumptions!$B$4 -> 62089.843
A38: Value per share (quote currency) | B38: =B37/Assumptions!$B$3*Assumptions!$B$10 -> 110.75605
A39: Upside vs price | B39: =B38/Assumptions!$B$2-1 -> 0.040451401
A41: Street memo: PV of explicit-period SBC | B41: =SUMPRODUCT(-C10:N10/(1+$B$27/100)^C4:N4) -> 5388.608
A42: Street memo: PV of terminal SBC (Gordon) | B42: =IF(B27>B28,-N10*(1+B28/100)/((B27-B28)/100),-N10*20)/(1+B27/100)^N4 -> 6937.1046
A43: Street value per share | B43: =(B37+B41+B42)/Assumptions!$B$3*Assumptions!$B$10 -> 132.7427
A45: Hurdle rate (%) | B45: =Assumptions!$B$6 -> 15
...

Sheet DCF_Bull
A1: DG.PA owner-FCF component DCF: bull case (millions, EUR)
A3: Line | B3: FY2025 | C3: FY2026 | D3: FY2027 | E3: FY2028 | F3: FY2029 | G3: FY2030 | H3: FY2031 | I3: FY2032 | J3: FY2033 | K3: FY2034 | L3: FY2035 | M3: FY2036 | N3: FY2037
A4: Year index (discount exponent) | B4: 0 | C4: =B4+1 -> 1 | D4: =C4+1 -> 2 | E4: =D4+1 -> 3 | F4: =E4+1 -> 4 | G4: =F4+1 -> 5 | H4: =G4+1 -> 6 | I4: =H4+1 -> 7 | J4: =I4+1 -> 8 | ... N4: =M4+1 -> 12
A5: Revenue growth (%) | C5: =Assumptions!C41 -> 3.36 | D5: =Assumptions!D41 -> 5.73 | E5: =Assumptions!E41 -> 5.74 | F5: =Assumptions!F41 -> 5.29 | G5: =Assumptions!G41 -> 4.83 | H5: =Assumptions!H41 -> 4.38 | I5: =Assumptions!I41 -> 3.05 | J5: =Assumptions!J41 -> 3.34 | ... N5: =Assumptions!N41 -> 1.5
A6: Revenue | B6: 74599 | C6: =B6*(1+C5/100) -> 77105.526 | D6: =C6*(1+D5/100) -> 81523.673 | E6: =D6*(1+E5/100) -> 86203.132 | F6: =E6*(1+F5/100) -> 90763.278 | G6: =F6*(1+G5/100) -> 95147.144 | H6: =G6*(1+H5/100) -> 99314.589 | I6: =H6*(1+I5/100) -> 102343.68 | J6: =I6*(1+J5/100) -> 105761.96 | ... N6: =M6*(1+N5/100) -> 111078.6
A7: EBITDA margin (%) | C7: =Assumptions!C42 -> 18.26 | D7: =Assumptions!D42 -> 18.49 | E7: =Assumptions!E42 -> 18.63 | F7: =Assumptions!F42 -> 18.8 | G7: =Assumptions!G42 -> 18.9 | H7: =Assumptions!H42 -> 19.02 | I7: =Assumptions!I42 -> 18.63 | J7: =Assumptions!J42 -> 18.64 | ... N7: =Assumptions!N42 -> 15.19
A8: EBITDA | C8: =C6*C7/100 -> 14079.469 | D8: =D6*D7/100 -> 15073.727 | E8: =E6*E7/100 -> 16059.643 | F8: =F6*F7/100 -> 17063.496 | G8: =G6*G7/100 -> 17982.81 | H8: =H6*H7/100 -> 18889.635 | I8: =I6*I7/100 -> 19066.628 | J8: =J6*J7/100 -> 19714.03 | ... N8: =N6*N7/100 -> 16872.84
A9: SBC (% of revenue) | C9: =Assumptions!C43 -> 0.7 | D9: =Assumptions!D43 -> 0.7 | E9: =Assumptions!E43 -> 0.7 | F9: =Assumptions!F43 -> 0.7 | G9: =Assumptions!G43 -> 0.7 | H9: =Assumptions!H43 -> 0.7 | I9: =Assumptions!I43 -> 0.7 | J9: =Assumptions!J43 -> 0.7 | ... N9: =Assumptions!N43 -> 0.7
A10: SBC charge | C10: =-C6*C9/100 -> -539.73868 | D10: =-D6*D9/100 -> -570.66571 | E10: =-E6*E9/100 -> -603.42192 | F10: =-F6*F9/100 -> -635.34294 | G10: =-G6*G9/100 -> -666.03001 | H10: =-H6*H9/100 -> -695.20212 | I10: =-I6*I9/100 -> -716.40579 | J10: =-J6*J9/100 -> -740.33374 | ... N10: =-N6*N9/100 -> -777.55022
A11: Owner EBITDA (after SBC and leases) | C11: =C8+C10+C24 -> 12637.596 | D11: =D8+D10+D24 -> 13549.234 | E11: =E8+E10+E24 -> 14447.645 | F11: =F8+F10+F24 -> 15357.147 | G11: =G8+G10+G24 -> 16194.044 | H11: =H8+H10+H24 -> 17022.521 | I11: =I8+I10+I24 -> 17132.333 | J11: =J8+J10+J24 -> 17715.129 | ... N11: =N8+N10+N24 -> 14684.591
A12: D&A | C12: =-C6*Assumptions!C45/100 -> -3539.1437 | D12: =-D6*Assumptions!D45/100 -> -3668.5653 | E12: =-E6*Assumptions!E45/100 -> -3801.5581 | F12: =-F6*Assumptions!F45/100 -> -3930.0499 | G12: =-G6*Assumptions!G45/100 -> -4053.2683 | H12: =-H6*Assumptions!H45/100 -> -4161.2813 | I12: =-I6*Assumptions!I45/100 -> -4114.2161 | J12: =-J6*Assumptions!J45/100 -> -4198.7499 | ... N12: =-N6*Assumptions!N45/100 -> -3399.0053
A13: EBIT | C13: =C11+C12 -> 9098.4521 | D13: =D11+D12 -> 9880.6692 | E13: =E11+E12 -> 10646.087 | F13: =F11+F12 -> 11427.097 | G13: =G11+G12 -> 12140.776 | H13: =H11+H12 -> 12861.239 | I13: =I11+I12 -> 13018.117 | J13: =J11+J12 -> 13516.379 | ... N13: =N11+N12 -> 11285.586
A14: Cash tax rate (%) | C14: =Assumptions!C47 -> 33 | D14: =Assumptions!D47 -> 28.5 | E14: =Assumptions!E47 -> 28.5 | F14: =Assumptions!F47 -> 28.5 | G14: =Assumptions!G47 -> 28.5 | H14: =Assumptions!H47 -> 28.5 | I14: =Assumptions!I47 -> 28.5 | J14: =Assumptions!J47 -> 28.5 | ... N14: =Assumptions!N47 -> 28.5
A15: NOPAT | C15: =C13-MAX(0,C13)*C14/100 -> 6095.9629 | D15: =D13-MAX(0,D13)*D14/100 -> 7064.6785 | E15: =E13-MAX(0,E13)*E14/100 -> 7611.9521 | F15: =F13-MAX(0,F13)*F14/100 -> 8170.3741 | G15: =G13-MAX(0,G13)*G14/100 -> 8680.6545 | H15: =H13-MAX(0,H13)*H14/100 -> 9195.7861 | I15: =I13-MAX(0,I13)*I14/100 -> 9307.9533 | J15: =J13-MAX(0,J13)*J14/100 -> 9664.2109 | ... N15: =N13-MAX(0,N13)*N14/100 -> 8069.1941
A16: D&A add-back | C16: =-C12 -> 3539.1437 | D16: =-D12 -> 3668.5653 | E16: =-E12 -> 3801.5581 | F16: =-F12 -> 3930.0499 | G16: =-G12 -> 4053.2683 | H16: =-H12 -> 4161.2813 | I16: =-I12 -> 4114.2161 | J16: =-J12 -> 4198.7499 | ... N16: =-N12 -> 3399.0053
A17: Capex | C17: =-C6*Assumptions!C46/100 -> -4209.9617 | D17: =-D6*Assumptions!D46/100 -> -4443.0402 | E17: =-E6*Assumptions!E46/100 -> -4706.691 | F17: =-F6*Assumptions!F46/100 -> -4883.0643 | G17: =-G6*Assumptions!G46/100 -> -4957.1662 | H17: =-H6*Assumptions!H46/100 -> -5015.3867 | I17: =-I6*Assumptions!I46/100 -> -5147.8873 | J17: =-J6*Assumptions!J46/100 -> -5266.9457 | ... N17: =-N6*Assumptions!N46/100 -> -5453.9594
A18: Working capital | C18: =(C6-B6)*Assumptions!$B$51/100 -> 877.28424 | D18: =(D6-C6)*Assumptions!$B$51/100 -> 1546.3513 | E18: =(E6-D6)*Assumptions!$B$51/100 -> 1637.8106 | F18: =(F6-E6)*Assumptions!$B$51/100 -> 1596.051 | G18: =(G6-F6)*Assumptions!$B$51/100 -> 1534.3532 | H18: =(H6-G6)*Assumptions!$B$51/100 -> 1458.6057 | I18: =(I6-H6)*Assumptions!$B$51/100 -> 1060.1832 | J18: =(J6-I6)*Assumptions!$B$51/100 -> 1196.3977 | ... N18: =(N6-M6)*Assumptions!$B$51/100 -> 574.5445
A19: Unlevered owner FCF | C19: =C15+C16+C17+C18 -> 6302.4291 | D19: =D15+D16+D17+D18 -> 7836.5549 | E19: =E15+E16+E17+E18 -> 8344.6298 | F19: =F15+F16+F17+F18 -> 8813.4107 | G19: =G15+G16+G17+G18 -> 9311.1099 | H19: =H15+H16+H17+H18 -> 9800.2863 | I19: =I15+I16+I17+I18 -> 9334.4654 | J19: =J15+J16+J17+J18 -> 9792.4127 | ... N19: =N15+N16+N17+N18 -> 6588.7844
A20: Discount factor | C20: =1/(1+$B$27/100)^C4 -> 0.93457944 | D20: =1/(1+$B$27/100)^D4 -> 0.87343873 | E20: =1/(1+$B$27/100)^E4 -> 0.81629788 | F20: =1/(1+$B$27/100)^F4 -> 0.76289521 | G20: =1/(1+$B$27/100)^G4 -> 0.71298618 | H20: =1/(1+$B$27/100)^H4 -> 0.66634222 | I20: =1/(1+$B$27/100)^I4 -> 0.62274974 | J20: =1/(1+$B$27/100)^J4 -> 0.5820091 | ... N20: =1/(1+$B$27/100)^N4 -> 0.44401196
A21: PV of FCF | C21: =C19*C20 -> 5890.1206 | D21: =D19*D20 -> 6844.7505 | E21: =E19*E20 -> 6811.7036 | F21: =F19*F20 -> 6723.7088 | G21: =G19*G20 -> 6638.6926 | H21: =H19*H20 -> 6530.3446 | I21: =I19*I20 -> 5813.0359 | J21: =J19*J20 -> 5699.2734 | ... N21: =N19*N20 -> 2925.4991
A23: Lease cost (% of revenue) | C23: =Assumptions!C44 -> 1.17 | D23: =Assumptions!D44 -> 1.17 | E23: =Assumptions!E44 -> 1.17 | F23: =Assumptions!F44 -> 1.18 | G23: =Assumptions!G44 -> 1.18 | H23: =Assumptions!H44 -> 1.18 | I23: =Assumptions!I44 -> 1.19 | J23: =Assumptions!J44 -> 1.19 | ... N23: =Assumptions!N44 -> 1.27
A24: Lease cost | C24: =-C6*C23/100 -> -902.13466 | D24: =-D6*D23/100 -> -953.82697 | E24: =-E6*E23/100 -> -1008.5766 | F24: =-F6*F23/100 -> -1071.0067 | G24: =-G6*G23/100 -> -1122.7363 | H24: =-H6*H23/100 -> -1171.9121 | I24: =-I6*I23/100 -> -1217.8898 | J24: =-J6*J23/100 -> -1258.5674 | ... N24: =-N6*N23/100 -> -1410.6983
A26: Valuation
A27: WACC (%) | B27: =Assumptions!$B$48 -> 7
A28: Terminal growth (%) | B28: =Assumptions!$B$49 -> 2.5
A29: Terminal cap multiple (x FCF) | B29: =Assumptions!$B$50 -> 18
A30: Sum of PV of FCF | B30: =SUM(C21:N21) -> 66407.441
A31: Terminal-year FCF | B31: =N19 -> 6588.7844
A32: Gordon terminal value | B32: =IF(B27>B28,B31*(1+B28/100)/((B27-B28)/100),B31*B29) -> 150077.87
A33: Cap terminal value | B33: =B31*B29 -> 118598.12
A34: Terminal value used: MAX(0,MIN(Gordon,cap)) | B34: =MAX(0,MIN(B32,B33)) -> 118598.12
A35: PV of terminal value | B35: =B34/(1+B27/100)^N4 -> 52658.983
A36: Enterprise value | B36: =B30+B35 -> 119066.42
A37: Equity value (EV + bridge - net debt) | B37: =B36+Assumptions!$B$5-Assumptions!$B$4 -> 93511.424
A38: Value per share (quote currency) | B38: =B37/Assumptions!$B$3*Assumptions!$B$10 -> 166.80597
A39: Upside vs price | B39: =B38/Assumptions!$B$2-1 -> 0.56698888
A41: Street memo: PV of explicit-period SBC | B41: =SUMPRODUCT(-C10:N10/(1+$B$27/100)^C4:N4) -> 5307.8721
A42: Street memo: PV of terminal SBC (Gordon) | B42: =IF(B27>B28,-N10*(1+B28/100)/((B27-B28)/100),-N10*20)/(1+B27/100)^N4 -> 7863.8364
A43: Street value per share | B43: =(B37+B41+B42)/Assumptions!$B$3*Assumptions!$B$10 -> 190.3017
A45: Hurdle rate (%) | B45: =Assumptions!$B$6 -> 15
...

Sheet Valuation
A1: DG.PA valuation summary
A3: Scenario | B3: Value per share | C3: Upside vs price | D3: Weight | E3: Street value per share | F3: Hurdle entry price
A4: Bear | B4: =DCF_Bear!$B$38 -> 57.851289 | C4: =B4/Assumptions!$B$2-1 -> -0.45654026 | D4: =Assumptions!$B$24 -> 0.25 | E4: =DCF_Bear!$B$43 -> 79.069992 | F4: =DCF_Bear!$B$47 -> 11.489681
A5: Base | B5: =DCF_Base!$B$38 -> 110.75605 | C5: =B5/Assumptions!$B$2-1 -> 0.040451401 | D5: =Assumptions!$B$38 -> 0.5 | E5: =DCF_Base!$B$43 -> 132.7427 | F5: =DCF_Base!$B$47 -> 32.760869
A6: Bull | B6: =DCF_Bull!$B$38 -> 166.80597 | C6: =B6/Assumptions!$B$2-1 -> 0.56698888 | D6: =Assumptions!$B$52 -> 0.25 | E6: =DCF_Bull!$B$43 -> 190.3017 | F6: =DCF_Bull!$B$47 -> 52.552051
A8: Probability-weighted value per share | B8: =SUMPRODUCT(B4:B6,D4:D6) -> 111.54234
A9: Street weighted value per share | B9: =SUMPRODUCT(E4:E6,D4:D6) -> 133.71427
A10: Margin of safety (1 - price/weighted) | B10: =1-Assumptions!$B$2/B8 -> 0.045653871
A11: Band position (%; 0 = house, 100 = street) | B11: =IF(ABS(B9-B8)>0.01*ABS(B8),(Assumptions!$B$2-B8)/(B9-B8)*100,"n/a") -> -22.967506
A12: Weighted 15% hurdle entry price | B12: =SUMPRODUCT(F4:F6,D4:D6) -> 32.390868
A14: Required-return table (base case; each row rebuilds its own terminal value) | C14: Rate (%)
A15: Value per share at 7% (WACC) | B15: =(SUMPRODUCT(DCF_Base!$C$19:$N$19/(1+$C$15/100)^DCF_Base!$C$4:$N$4)+MAX(0,MIN(IF($C$15>DCF_Base!$B$28,DCF_Base!$N$19*(1+DCF_Base!$B$28/100)/(($C$15-DCF_Base!$B$28)/100),DCF_Base!$N$19*DCF_Base!$B$29),DCF_Base!$N$19*DCF_Base!$B$29))/(1+$C$15/100)^DCF_Base!$N$4+Assumptions!$B$5-Assumptions!$B$4)/Assumptions!$B$3*Assumptions!$B$10 -> 110.75605 | C15: 7
A16: Value per share at 9% | B16: =(SUMPRODUCT(DCF_Base!$C$19:$N$19/(1+$C$16/100)^DCF_Base!$C$4:$N$4)+MAX(0,MIN(IF($C$16>DCF_Base!$B$28,DCF_Base!$N$19*(1+DCF_Base!$B$28/100)/(($C$16-DCF_Base!$B$28)/100),DCF_Base!$N$19*DCF_Base!$B$29),DCF_Base!$N$19*DCF_Base!$B$29))/(1+$C$16/100)^DCF_Base!$N$4+Assumptions!$B$5-Assumptions!$B$4)/Assumptions!$B$3*Assumptions!$B$10 -> 85.162306 | C16: 9
A17: Value per share at 10% | B17: =(SUMPRODUCT(DCF_Base!$C$19:$N$19/(1+$C$17/100)^DCF_Base!$C$4:$N$4)+MAX(0,MIN(IF($C$17>DCF_Base!$B$28,DCF_Base!$N$19*(1+DCF_Base!$B$28/100)/(($C$17-DCF_Base!$B$28)/100),DCF_Base!$N$19*DCF_Base!$B$29),DCF_Base!$N$19*DCF_Base!$B$29))/(1+$C$17/100)^DCF_Base!$N$4+Assumptions!$B$5-Assumptions!$B$4)/Assumptions!$B$3*Assumptions!$B$10 -> 71.577179 | C17: 10
A18: Value per share at 11% | B18: =(SUMPRODUCT(DCF_Base!$C$19:$N$19/(1+$C$18/100)^DCF_Base!$C$4:$N$4)+MAX(0,MIN(IF($C$18>DCF_Base!$B$28,DCF_Base!$N$19*(1+DCF_Base!$B$28/100)/(($C$18-DCF_Base!$B$28)/100),DCF_Base!$N$19*DCF_Base!$B$29),DCF_Base!$N$19*DCF_Base!$B$29))/(1+$C$18/100)^DCF_Base!$N$4+Assumptions!$B$5-Assumptions!$B$4)/Assumptions!$B$3*Assumptions!$B$10 -> 60.764084 | C18: 11
A19: Value per share at 12% | B19: =(SUMPRODUCT(DCF_Base!$C$19:$N$19/(1+$C$19/100)^DCF_Base!$C$4:$N$4)+MAX(0,MIN(IF($C$19>DCF_Base!$B$28,DCF_Base!$N$19*(1+DCF_Base!$B$28/100)/(($C$19-DCF_Base!$B$28)/100),DCF_Base!$N$19*DCF_Base!$B$29),DCF_Base!$N$19*DCF_Base!$B$29))/(1+$C$19/100)^DCF_Base!$N$4+Assumptions!$B$5-Assumptions!$B$4)/Assumptions!$B$3*Assumptions!$B$10 -> 51.914174 | C19: 12
A20: Value per share at 15% | B20: =(SUMPRODUCT(DCF_Base!$C$19:$N$19/(1+$C$20/100)^DCF_Base!$C$4:$N$4)+MAX(0,MIN(IF($C$20>DCF_Base!$B$28,DCF_Base!$N$19*(1+DCF_Base!$B$28/100)/(($C$20-DCF_Base!$B$28)/100),DCF_Base!$N$19*DCF_Base!$B$29),DCF_Base!$N$19*DCF_Base!$B$29))/(1+$C$20/100)^DCF_Base!$N$4+Assumptions!$B$5-Assumptions!$B$4)/Assumptions!$B$3*Assumptions!$B$10 -> 32.760869 | C20: 15
A22: Sensitivity: value per share, rows WACC (%) x columns terminal growth (%)
B23: 1 | C23: 1.5 | D23: 2 | E23: 2.5 | F23: 3
A24: 5 | B24: =(SUMPRODUCT(DCF_Base!$C$19:$N$19/(1+$A$24/100)^DCF_Base!$C$4:$N$4)+MAX(0,MIN(IF($A$24>$B$23,DCF_Base!$N$19*(1+$B$23/100)/(($A$24-$B$23)/100),DCF_Base!$N$19*DCF_Base!$B$29),DCF_Base!$N$19*DCF_Base!$B$29))/(1+$A$24/100)^DCF_Base!$N$4+Assumptions!$B$5-Assumptions!$B$4)/Assumptions!$B$3*Assumptions!$B$10 -> 136.98738 | C24: =(SUMPRODUCT(DCF_Base!$C$19:$N$19/(1+$A$24/100)^DCF_Base!$C$4:$N$4)+MAX(0,MIN(IF($A$24>$C$23,DCF_Base!$N$19*(1+$C$23/100)/(($A$24-$C$23)/100),DCF_Base!$N$19*DCF_Base!$B$29),DCF_Base!$N$19*DCF_Base!$B$29))/(1+$A$24/100)^DCF_Base!$N$4+Assumptions!$B$5-Assumptions!$B$4)/Assumptions!$B$3*Assumptions!$B$10 -> 136.98738 | D24: =(SUMPRODUCT(DCF_Base!$C$19:$N$19/(1+$A$24/100)^DCF_Base!$C$4:$N$4)+MAX(0,MIN(IF($A$24>$D$23,DCF_Base!$N$19*(1+$D$23/100)/(($A$24-$D$23)/100),DCF_Base!$N$19*DCF_Base!$B$29),DCF_Base!$N$19*DCF_Base!$B$29))/(1+$A$24/100)^DCF_Base!$N$4+Assumptions!$B$5-Assumptions!$B$4)/Assumptions!$B$3*Assumptions!$B$10 -> 136.98738 | E24: =(SUMPRODUCT(DCF_Base!$C$19:$N$19/(1+$A$24/100)^DCF_Base!$C$4:$N$4)+MAX(0,MIN(IF($A$24>$E$23,DCF_Base!$N$19*(1+$E$23/100)/(($A$24-$E$23)/100),DCF_Base!$N$19*DCF_Base!$B$29),DCF_Base!$N$19*DCF_Base!$B$29))/(1+$A$24/100)^DCF_Base!$N$4+Assumptions!$B$5-Assumptions!$B$4)/Assumptions!$B$3*Assumptions!$B$10 -> 136.98738 | F24: =(SUMPRODUCT(DCF_Base!$C$19:$N$19/(1+$A$24/100)^DCF_Base!$C$4:$N$4)+MAX(0,MIN(IF($A$24>$F$23,DCF_Base!$N$19*(1+$F$23/100)/(($A$24-$F$23)/100),DCF_Base!$N$19*DCF_Base!$B$29),DCF_Base!$N$19*DCF_Base!$B$29))/(1+$A$24/100)^DCF_Base!$N$4+Assumptions!$B$5-Assumptions!$B$4)/Assumptions!$B$3*Assumptions!$B$10 -> 136.98738
A25: 6 | B25: =(SUMPRODUCT(DCF_Base!$C$19:$N$19/(1+$A$25/100)^DCF_Base!$C$4:$N$4)+MAX(0,MIN(IF($A$25>$B$23,DCF_Base!$N$19*(1+$B$23/100)/(($A$25-$B$23)/100),DCF_Base!$N$19*DCF_Base!$B$29),DCF_Base!$N$19*DCF_Base!$B$29))/(1+$A$25/100)^DCF_Base!$N$4+Assumptions!$B$5-Assumptions!$B$4)/Assumptions!$B$3*Assumptions!$B$10 -> 123.18572 | C25: =(SUMPRODUCT(DCF_Base!$C$19:$N$19/(1+$A$25/100)^DCF_Base!$C$4:$N$4)+MAX(0,MIN(IF($A$25>$C$23,DCF_Base!$N$19*(1+$C$23/100)/(($A$25-$C$23)/100),DCF_Base!$N$19*DCF_Base!$B$29),DCF_Base!$N$19*DCF_Base!$B$29))/(1+$A$25/100)^DCF_Base!$N$4+Assumptions!$B$5-Assumptions!$B$4)/Assumptions!$B$3*Assumptions!$B$10 -> 123.18572 | D25: =(SUMPRODUCT(DCF_Base!$C$19:$N$19/(1+$A$25/100)^DCF_Base!$C$4:$N$4)+MAX(0,MIN(IF($A$25>$D$23,DCF_Base!$N$19*(1+$D$23/100)/(($A$25-$D$23)/100),DCF_Base!$N$19*DCF_Base!$B$29),DCF_Base!$N$19*DCF_Base!$B$29))/(1+$A$25/100)^DCF_Base!$N$4+Assumptions!$B$5-Assumptions!$B$4)/Assumptions!$B$3*Assumptions!$B$10 -> 123.18572 | E25: =(SUMPRODUCT(DCF_Base!$C$19:$N$19/(1+$A$25/100)^DCF_Base!$C$4:$N$4)+MAX(0,MIN(IF($A$25>$E$23,DCF_Base!$N$19*(1+$E$23/100)/(($A$25-$E$23)/100),DCF_Base!$N$19*DCF_Base!$B$29),DCF_Base!$N$19*DCF_Base!$B$29))/(1+$A$25/100)^DCF_Base!$N$4+Assumptions!$B$5-Assumptions!$B$4)/Assumptions!$B$3*Assumptions!$B$10 -> 123.18572 | F25: =(SUMPRODUCT(DCF_Base!$C$19:$N$19/(1+$A$25/100)^DCF_Base!$C$4:$N$4)+MAX(0,MIN(IF($A$25>$F$23,DCF_Base!$N$19*(1+$F$23/100)/(($A$25-$F$23)/100),DCF_Base!$N$19*DCF_Base!$B$29),DCF_Base!$N$19*DCF_Base!$B$29))/(1+$A$25/100)^DCF_Base!$N$4+Assumptions!$B$5-Assumptions!$B$4)/Assumptions!$B$3*Assumptions!$B$10 -> 123.18572
A26: 7 | B26: =(SUMPRODUCT(DCF_Base!$C$19:$N$19/(1+$A$26/100)^DCF_Base!$C$4:$N$4)+MAX(0,MIN(IF($A$26>$B$23,DCF_Base!$N$19*(1+$B$23/100)/(($A$26-$B$23)/100),DCF_Base!$N$19*DCF_Base!$B$29),DCF_Base!$N$19*DCF_Base!$B$29))/(1+$A$26/100)^DCF_Base!$N$4+Assumptions!$B$5-Assumptions!$B$4)/Assumptions!$B$3*Assumptions!$B$10 -> 110.75605 | C26: =(SUMPRODUCT(DCF_Base!$C$19:$N$19/(1+$A$26/100)^DCF_Base!$C$4:$N$4)+MAX(0,MIN(IF($A$26>$C$23,DCF_Base!$N$19*(1+$C$23/100)/(($A$26-$C$23)/100),DCF_Base!$N$19*DCF_Base!$B$29),DCF_Base!$N$19*DCF_Base!$B$29))/(1+$A$26/100)^DCF_Base!$N$4+Assumptions!$B$5-Assumptions!$B$4)/Assumptions!$B$3*Assumptions!$B$10 -> 110.75605 | D26: =(SUMPRODUCT(DCF_Base!$C$19:$N$19/(1+$A$26/100)^DCF_Base!$C$4:$N$4)+MAX(0,MIN(IF($A$26>$D$23,DCF_Base!$N$19*(1+$D$23/100)/(($A$26-$D$23)/100),DCF_Base!$N$19*DCF_Base!$B$29),DCF_Base!$N$19*DCF_Base!$B$29))/(1+$A$26/100)^DCF_Base!$N$4+Assumptions!$B$5-Assumptions!$B$4)/Assumptions!$B$3*Assumptions!$B$10 -> 110.75605 | E26: =(SUMPRODUCT(DCF_Base!$C$19:$N$19/(1+$A$26/100)^DCF_Base!$C$4:$N$4)+MAX(0,MIN(IF($A$26>$E$23,DCF_Base!$N$19*(1+$E$23/100)/(($A$26-$E$23)/100),DCF_Base!$N$19*DCF_Base!$B$29),DCF_Base!$N$19*DCF_Base!$B$29))/(1+$A$26/100)^DCF_Base!$N$4+Assumptions!$B$5-Assumptions!$B$4)/Assumptions!$B$3*Assumptions!$B$10 -> 110.75605 | F26: =(SUMPRODUCT(DCF_Base!$C$19:$N$19/(1+$A$26/100)^DCF_Base!$C$4:$N$4)+MAX(0,MIN(IF($A$26>$F$23,DCF_Base!$N$19*(1+$F$23/100)/(($A$26-$F$23)/100),DCF_Base!$N$19*DCF_Base!$B$29),DCF_Base!$N$19*DCF_Base!$B$29))/(1+$A$26/100)^DCF_Base!$N$4+Assumptions!$B$5-Assumptions!$B$4)/Assumptions!$B$3*Assumptions!$B$10 -> 110.75605
A27: 8 | B27: =(SUMPRODUCT(DCF_Base!$C$19:$N$19/(1+$A$27/100)^DCF_Base!$C$4:$N$4)+MAX(0,MIN(IF($A$27>$B$23,DCF_Base!$N$19*(1+$B$23/100)/(($A$27-$B$23)/100),DCF_Base!$N$19*DCF_Base!$B$29),DCF_Base!$N$19*DCF_Base!$B$29))/(1+$A$27/100)^DCF_Base!$N$4+Assumptions!$B$5-Assumptions!$B$4)/Assumptions!$B$3*Assumptions!$B$10 -> 94.325016 | C27: =(SUMPRODUCT(DCF_Base!$C$19:$N$19/(1+$A$27/100)^DCF_Base!$C$4:$N$4)+MAX(0,MIN(IF($A$27>$C$23,DCF_Base!$N$19*(1+$C$23/100)/(($A$27-$C$23)/100),DCF_Base!$N$19*DCF_Base!$B$29),DCF_Base!$N$19*DCF_Base!$B$29))/(1+$A$27/100)^DCF_Base!$N$4+Assumptions!$B$5-Assumptions!$B$4)/Assumptions!$B$3*Assumptions!$B$10 -> 98.265558 | D27: =(SUMPRODUCT(DCF_Base!$C$19:$N$19/(1+$A$27/100)^DCF_Base!$C$4:$N$4)+MAX(0,MIN(IF($A$27>$D$23,DCF_Base!$N$19*(1+$D$23/100)/(($A$27-$D$23)/100),DCF_Base!$N$19*DCF_Base!$B$29),DCF_Base!$N$19*DCF_Base!$B$29))/(1+$A$27/100)^DCF_Base!$N$4+Assumptions!$B$5-Assumptions!$B$4)/Assumptions!$B$3*Assumptions!$B$10 -> 99.542586 | E27: =(SUMPRODUCT(DCF_Base!$C$19:$N$19/(1+$A$27/100)^DCF_Base!$C$4:$N$4)+MAX(0,MIN(IF($A$27>$E$23,DCF_Base!$N$19*(1+$E$23/100)/(($A$27-$E$23)/100),DCF_Base!$N$19*DCF_Base!$B$29),DCF_Base!$N$19*DCF_Base!$B$29))/(1+$A$27/100)^DCF_Base!$N$4+Assumptions!$B$5-Assumptions!$B$4)/Assumptions!$B$3*Assumptions!$B$10 -> 99.542586 | F27: =(SUMPRODUCT(DCF_Base!$C$19:$N$19/(1+$A$27/100)^DCF_Base!$C$4:$N$4)+MAX(0,MIN(IF($A$27>$F$23,DCF_Base!$N$19*(1+$F$23/100)/(($A$27-$F$23)/100),DCF_Base!$N$19*DCF_Base!$B$29),DCF_Base!$N$19*DCF_Base!$B$29))/(1+$A$27/100)^DCF_Base!$N$4+Assumptions!$B$5-Assumptions!$B$4)/Assumptions!$B$3*Assumptions!$B$10 -> 99.542586
A28: 9 | B28: =(SUMPRODUCT(DCF_Base!$C$19:$N$19/(1+$A$28/100)^DCF_Base!$C$4:$N$4)+MAX(0,MIN(IF($A$28>$B$23,DCF_Base!$N$19*(1+$B$23/100)/(($A$28-$B$23)/100),DCF_Base!$N$19*DCF_Base!$B$29),DCF_Base!$N$19*DCF_Base!$B$29))/(1+$A$28/100)^DCF_Base!$N$4+Assumptions!$B$5-Assumptions!$B$4)/Assumptions!$B$3*Assumptions!$B$10 -> 79.376295 | C28: =(SUMPRODUCT(DCF_Base!$C$19:$N$19/(1+$A$28/100)^DCF_Base!$C$4:$N$4)+MAX(0,MIN(IF($A$28>$C$23,DCF_Base!$N$19*(1+$C$23/100)/(($A$28-$C$23)/100),DCF_Base!$N$19*DCF_Base!$B$29),DCF_Base!$N$19*DCF_Base!$B$29))/(1+$A$28/100)^DCF_Base!$N$4+Assumptions!$B$5-Assumptions!$B$4)/Assumptions!$B$3*Assumptions!$B$10 -> 82.076433 | D28: =(SUMPRODUCT(DCF_Base!$C$19:$N$19/(1+$A$28/100)^DCF_Base!$C$4:$N$4)+MAX(0,MIN(IF($A$28>$D$23,DCF_Base!$N$19*(1+$D$23/100)/(($A$28-$D$23)/100),DCF_Base!$N$19*DCF_Base!$B$29),DCF_Base!$N$19*DCF_Base!$B$29))/(1+$A$28/100)^DCF_Base!$N$4+Assumptions!$B$5-Assumptions!$B$4)/Assumptions!$B$3*Assumptions!$B$10 -> 85.162306 | E28: =(SUMPRODUCT(DCF_Base!$C$19:$N$19/(1+$A$28/100)^DCF_Base!$C$4:$N$4)+MAX(0,MIN(IF($A$28>$E$23,DCF_Base!$N$19*(1+$E$23/100)/(($A$28-$E$23)/100),DCF_Base!$N$19*DCF_Base!$B$29),DCF_Base!$N$19*DCF_Base!$B$29))/(1+$A$28/100)^DCF_Base!$N$4+Assumptions!$B$5-Assumptions!$B$4)/Assumptions!$B$3*Assumptions!$B$10 -> 88.722928 | F28: =(SUMPRODUCT(DCF_Base!$C$19:$N$19/(1+$A$28/100)^DCF_Base!$C$4:$N$4)+MAX(0,MIN(IF($A$28>$F$23,DCF_Base!$N$19*(1+$F$23/100)/(($A$28-$F$23)/100),DCF_Base!$N$19*DCF_Base!$B$29),DCF_Base!$N$19*DCF_Base!$B$29))/(1+$A$28/100)^DCF_Base!$N$4+Assumptions!$B$5-Assumptions!$B$4)/Assumptions!$B$3*Assumptions!$B$10 -> 89.408919
