Workbook

Sheet Inputs
A1: Ticker | B1: SPG.NZ
A2: Valuation date | B2: 2026-09-02
A3: Current price (NZD) | B3: 1.09
A4: Shares outstanding (m) | B4: 559.462
A5: Group NTA/share 31-Mar-2026 | B5: 1.69
A6: Shareholders equity (m) | B6: 945.68
A7: SIML segment net assets (m) | B7: 23.598
A8: Property-leg NTA/share | B8: =(B6-B7)/B4
A9: AFFO FY2026 (m) | B9: 42.51
A10: AFFO/share FY2026 (cents) | B10: =B9/B4*100
A11: Distributable profit/share FY2026 (cents) | B11: 8.78
A12: Dividend FY2026 (cents) | B12: 8
A13: SIML NPAT FY2026 (m) | B13: 9.571
A14: Net debt (m) -- audit only, NEVER deducted | B14: 278.566
A15: Hurdle rate | B15: 0.15
A16: Blend weight: AFFO leg | B16: 0.5
A17: Blend weight: SOTP leg | B17: 0.5
A19: Scenario assumptions
A20: Parameter | B20: base | C20: bull | D20: bear | E20: weight
A21: Cost of equity | B21: 0.11 | C21: 0.1 | D21: 0.125
A22: Terminal growth % | B22: 2.5 | C22: 3 | D22: 1.5
A23: Exit AFFO yield % (cap) | B23: 7.5 | C23: 6.5 | D23: 8.5
A24: Exit P/NTA (property leg) | B24: 0.72 | C24: 0.88 | D24: 0.55
A25: SIML exit P/E | B25: 9 | C25: 11 | D25: 6
A26: Scenario weight | B26: 0.5 | C26: 0.25 | D26: 0.25
A28: Year paths
A29: Path | B29: Scenario | C29: FY2027 | D29: FY2028 | E29: FY2029 | F29: FY2030 | G29: FY2031
A30: AFFO growth % | B30: base | C30: 1.5 | D30: -2 | E30: -1 | F30: 3 | G30: 3
A31: AFFO growth % | B31: bull | C31: 3 | D31: 3.5 | E31: 4 | F31: 4 | G31: 3.5
A32: AFFO growth % | B32: bear | C32: -2 | D32: -5 | E32: -3 | F32: 0 | G32: 1
A33: NTA growth % (property leg) | B33: base | C33: -1.5 | D33: -0.5 | E33: 1 | F33: 1.5 | G33: 2
A34: NTA growth % (property leg) | B34: bull | C34: 0.5 | D34: 2 | E34: 2.5 | F34: 2.5 | G34: 2.5
A35: NTA growth % (property leg) | B35: bear | C35: -4 | D35: -3 | E35: -1.5 | F35: 0 | G35: 0.5
A36: SIML NPAT (m) | B36: base | C36: 9.9 | D36: 8.6 | E36: 8 | F36: 8.4 | G36: 8.8
A37: SIML NPAT (m) | B37: bull | C37: 10.3 | D37: 11 | E37: 11.8 | F37: 12.6 | G37: 13.4
A38: SIML NPAT (m) | B38: bear | C38: 9 | D38: 7 | E38: 6 | F38: 6 | G38: 6
A39: DPS (cents) | B39: base | C39: 8 | D39: 8 | E39: 8 | F39: 8 | G39: 8
A40: DPS (cents) | B40: bull | C40: 8 | D40: 8 | E40: 8.25 | F40: 8.5 | G40: 8.75
A41: DPS (cents) | B41: bear | C41: 8 | D41: 7 | E41: 7 | F41: 7 | G41: 7

Sheet AFFO_Leg
A1: AFFO/share capitalised at cost of equity; TV = MIN(Gordon at CoE, AFFO5 / exit yield). No net-debt deduction (AFFO is post-interest).
A3: BASE
A4: Year | B4: Growth % | C4: AFFO cps | D4: Discount factor | E4: PV cps
A5: FY2027 | B5: =Inputs!C30 | C5: =Inputs!$B$10*(1+B5/100) | D5: =1/(1+Inputs!$B$21)^1 | E5: =C5*D5
A6: FY2028 | B6: =Inputs!D30 | C6: =C5*(1+B6/100) | D6: =1/(1+Inputs!$B$21)^2 | E6: =C6*D6
A7: FY2029 | B7: =Inputs!E30 | C7: =C6*(1+B7/100) | D7: =1/(1+Inputs!$B$21)^3 | E7: =C7*D7
A8: FY2030 | B8: =Inputs!F30 | C8: =C7*(1+B8/100) | D8: =1/(1+Inputs!$B$21)^4 | E8: =C8*D8
A9: FY2031 | B9: =Inputs!G30 | C9: =C8*(1+B9/100) | D9: =1/(1+Inputs!$B$21)^5 | E9: =C9*D9
A11: Sum PV AFFO (cents) | B11: =SUM(E5:E9)
A12: Gordon TV (cents) | B12: =C9*(1+Inputs!B22/100)/(Inputs!$B$21-Inputs!B22/100)
A13: Exit-yield cap (cents) | B13: =C9/(Inputs!B23/100)
A14: Terminal value (cents) | B14: =MIN(B12,B13)
A15: PV terminal (cents) | B15: =B14*D9
A16: AFFO-leg value per share (NZD) | B16: =(B11+B15)/100
A17: Implied exit P/AFFO | B17: =B14/C9
A18: Terminal % of value | B18: =B15/(B11+B15)
A20: Entry price at hurdle (TV rebuilt at hurdle)
A21: PV interim AFFO at hurdle (cents) | B21: =C5/(1+Inputs!$B$15)^1+C6/(1+Inputs!$B$15)^2+C7/(1+Inputs!$B$15)^3+C8/(1+Inputs!$B$15)^4+C9/(1+Inputs!$B$15)^5
A22: TV at hurdle (cents) | B22: =MIN(C9*(1+Inputs!B22/100)/(Inputs!$B$15-Inputs!B22/100),B13)
A23: PV TV at hurdle (cents) | B23: =B22/(1+Inputs!$B$15)^5
A24: Entry price (NZD) | B24: =(B21+B23)/100
A27: BULL
A28: Year | B28: Growth % | C28: AFFO cps | D28: Discount factor | E28: PV cps
A29: FY2027 | B29: =Inputs!C31 | C29: =Inputs!$B$10*(1+B29/100) | D29: =1/(1+Inputs!$C$21)^1 | E29: =C29*D29
A30: FY2028 | B30: =Inputs!D31 | C30: =C29*(1+B30/100) | D30: =1/(1+Inputs!$C$21)^2 | E30: =C30*D30
A31: FY2029 | B31: =Inputs!E31 | C31: =C30*(1+B31/100) | D31: =1/(1+Inputs!$C$21)^3 | E31: =C31*D31
A32: FY2030 | B32: =Inputs!F31 | C32: =C31*(1+B32/100) | D32: =1/(1+Inputs!$C$21)^4 | E32: =C32*D32
A33: FY2031 | B33: =Inputs!G31 | C33: =C32*(1+B33/100) | D33: =1/(1+Inputs!$C$21)^5 | E33: =C33*D33
A35: Sum PV AFFO (cents) | B35: =SUM(E29:E33)
A36: Gordon TV (cents) | B36: =C33*(1+Inputs!C22/100)/(Inputs!$C$21-Inputs!C22/100)
A37: Exit-yield cap (cents) | B37: =C33/(Inputs!C23/100)
A38: Terminal value (cents) | B38: =MIN(B36,B37)
A39: PV terminal (cents) | B39: =B38*D33
A40: AFFO-leg value per share (NZD) | B40: =(B35+B39)/100
A41: Implied exit P/AFFO | B41: =B38/C33
A42: Terminal % of value | B42: =B39/(B35+B39)
A44: Entry price at hurdle (TV rebuilt at hurdle)
A45: PV interim AFFO at hurdle (cents) | B45: =C29/(1+Inputs!$B$15)^1+C30/(1+Inputs!$B$15)^2+C31/(1+Inputs!$B$15)^3+C32/(1+Inputs!$B$15)^4+C33/(1+Inputs!$B$15)^5
A46: TV at hurdle (cents) | B46: =MIN(C33*(1+Inputs!C22/100)/(Inputs!$B$15-Inputs!C22/100),B37)
A47: PV TV at hurdle (cents) | B47: =B46/(1+Inputs!$B$15)^5
...

Sheet SOTP_Leg
A1: Sum-of-parts asset leg: PV(dividends) + PV(year-5 property NTA x exit P/NTA + SIML NPAT x exit P/E). No net-debt deduction (NTA is post-debt).
A3: BASE
A4: Year | B4: NTA growth % | C4: Property NTA/share | D4: SIML NPAT (m) | E4: DPS cents | F4: Discount factor | G4: PV DPS cents
A5: FY2027 | B5: =Inputs!C33 | C5: =Inputs!$B$8*(1+B5/100) | D5: =Inputs!C36 | E5: =Inputs!C39 | F5: =1/(1+Inputs!$B$21)^1 | G5: =E5*F5
A6: FY2028 | B6: =Inputs!D33 | C6: =C5*(1+B6/100) | D6: =Inputs!D36 | E6: =Inputs!D39 | F6: =1/(1+Inputs!$B$21)^2 | G6: =E6*F6
A7: FY2029 | B7: =Inputs!E33 | C7: =C6*(1+B7/100) | D7: =Inputs!E36 | E7: =Inputs!E39 | F7: =1/(1+Inputs!$B$21)^3 | G7: =E7*F7
A8: FY2030 | B8: =Inputs!F33 | C8: =C7*(1+B8/100) | D8: =Inputs!F36 | E8: =Inputs!F39 | F8: =1/(1+Inputs!$B$21)^4 | G8: =E8*F8
A9: FY2031 | B9: =Inputs!G33 | C9: =C8*(1+B9/100) | D9: =Inputs!G36 | E9: =Inputs!G39 | F9: =1/(1+Inputs!$B$21)^5 | G9: =E9*F9
A11: PV dividends (cents) | B11: =SUM(G5:G9)
A12: Year-5 property value/share | B12: =C9*Inputs!B24
A13: Year-5 SIML value (m) | B13: =D9*Inputs!B25
A14: Year-5 SIML value/share | B14: =B13/Inputs!$B$4
A15: Year-5 exit value/share | B15: =B12+B14
A16: PV exit value/share | B16: =B15*F9
A17: SOTP-leg value per share (NZD) | B17: =B11/100+B16
A20: BULL
A21: Year | B21: NTA growth % | C21: Property NTA/share | D21: SIML NPAT (m) | E21: DPS cents | F21: Discount factor | G21: PV DPS cents
A22: FY2027 | B22: =Inputs!C34 | C22: =Inputs!$B$8*(1+B22/100) | D22: =Inputs!C37 | E22: =Inputs!C40 | F22: =1/(1+Inputs!$C$21)^1 | G22: =E22*F22
A23: FY2028 | B23: =Inputs!D34 | C23: =C22*(1+B23/100) | D23: =Inputs!D37 | E23: =Inputs!D40 | F23: =1/(1+Inputs!$C$21)^2 | G23: =E23*F23
A24: FY2029 | B24: =Inputs!E34 | C24: =C23*(1+B24/100) | D24: =Inputs!E37 | E24: =Inputs!E40 | F24: =1/(1+Inputs!$C$21)^3 | G24: =E24*F24
A25: FY2030 | B25: =Inputs!F34 | C25: =C24*(1+B25/100) | D25: =Inputs!F37 | E25: =Inputs!F40 | F25: =1/(1+Inputs!$C$21)^4 | G25: =E25*F25
A26: FY2031 | B26: =Inputs!G34 | C26: =C25*(1+B26/100) | D26: =Inputs!G37 | E26: =Inputs!G40 | F26: =1/(1+Inputs!$C$21)^5 | G26: =E26*F26
A28: PV dividends (cents) | B28: =SUM(G22:G26)
A29: Year-5 property value/share | B29: =C26*Inputs!C24
A30: Year-5 SIML value (m) | B30: =D26*Inputs!C25
A31: Year-5 SIML value/share | B31: =B30/Inputs!$B$4
A32: Year-5 exit value/share | B32: =B29+B31
A33: PV exit value/share | B33: =B32*F26
A34: SOTP-leg value per share (NZD) | B34: =B28/100+B33
A37: BEAR
A38: Year | B38: NTA growth % | C38: Property NTA/share | D38: SIML NPAT (m) | E38: DPS cents | F38: Discount factor | G38: PV DPS cents
A39: FY2027 | B39: =Inputs!C35 | C39: =Inputs!$B$8*(1+B39/100) | D39: =Inputs!C38 | E39: =Inputs!C41 | F39: =1/(1+Inputs!$D$21)^1 | G39: =E39*F39
A40: FY2028 | B40: =Inputs!D35 | C40: =C39*(1+B40/100) | D40: =Inputs!D38 | E40: =Inputs!D41 | F40: =1/(1+Inputs!$D$21)^2 | G40: =E40*F40
A41: FY2029 | B41: =Inputs!E35 | C41: =C40*(1+B41/100) | D41: =Inputs!E38 | E41: =Inputs!E41 | F41: =1/(1+Inputs!$D$21)^3 | G41: =E41*F41
A42: FY2030 | B42: =Inputs!F35 | C42: =C41*(1+B42/100) | D42: =Inputs!F38 | E42: =Inputs!F41 | F42: =1/(1+Inputs!$D$21)^4 | G42: =E42*F42
A43: FY2031 | B43: =Inputs!G35 | C43: =C42*(1+B43/100) | D43: =Inputs!G38 | E43: =Inputs!G41 | F43: =1/(1+Inputs!$D$21)^5 | G43: =E43*F43
A45: PV dividends (cents) | B45: =SUM(G39:G43)
A46: Year-5 property value/share | B46: =C43*Inputs!D24
A47: Year-5 SIML value (m) | B47: =D43*Inputs!D25
A48: Year-5 SIML value/share | B48: =B47/Inputs!$B$4
...

Sheet Valuation
A1: Scenario | B1: AFFO leg | C1: SOTP leg | D1: Blended IV | E1: Upside vs price | F1: Weight | G1: Entry price @ hurdle | H1: Implied P/NTA
A2: base | B2: =AFFO_Leg!$B$16 | C2: =SOTP_Leg!$B$17 | D2: =Inputs!$B$16*B2+Inputs!$B$17*C2 | E2: =D2/Inputs!$B$3-1 | F2: =Inputs!B26 | G2: =AFFO_Leg!$B$24 | H2: =D2/Inputs!$B$5
A3: bull | B3: =AFFO_Leg!$B$40 | C3: =SOTP_Leg!$B$34 | D3: =Inputs!$B$16*B3+Inputs!$B$17*C3 | E3: =D3/Inputs!$B$3-1 | F3: =Inputs!C26 | G3: =AFFO_Leg!$B$48 | H3: =D3/Inputs!$B$5
A4: bear | B4: =AFFO_Leg!$B$64 | C4: =SOTP_Leg!$B$51 | D4: =Inputs!$B$16*B4+Inputs!$B$17*C4 | E4: =D4/Inputs!$B$3-1 | F4: =Inputs!D26 | G4: =AFFO_Leg!$B$72 | H4: =D4/Inputs!$B$5
A6: Probability-weighted IV | D6: =SUMPRODUCT(D2:D4,F2:F4)
A7: Weighted upside vs price | D7: =D6/Inputs!$B$3-1
A8: Weighted entry price | G8: =SUMPRODUCT(G2:G4,F2:F4)
A9: Weights sum | F9: =SUM(F2:F4)
A11: Required-return table (base AFFO leg; TV rebuilt at each rate)
A12: Rate % | B12: Value/share
A13: 9 | B13: =(AFFO_Leg!$C$5/(1+$A13/100)^1+AFFO_Leg!$C$6/(1+$A13/100)^2+AFFO_Leg!$C$7/(1+$A13/100)^3+AFFO_Leg!$C$8/(1+$A13/100)^4+AFFO_Leg!$C$9/(1+$A13/100)^5+MIN(AFFO_Leg!$C$9*(1+Inputs!$B$22/100)/($A13/100-Inputs!$B$22/100),AFFO_Leg!$C$9/(Inputs!$B$23/100))/(1+$A13/100)^5)/100
A14: 10 | B14: =(AFFO_Leg!$C$5/(1+$A14/100)^1+AFFO_Leg!$C$6/(1+$A14/100)^2+AFFO_Leg!$C$7/(1+$A14/100)^3+AFFO_Leg!$C$8/(1+$A14/100)^4+AFFO_Leg!$C$9/(1+$A14/100)^5+MIN(AFFO_Leg!$C$9*(1+Inputs!$B$22/100)/($A14/100-Inputs!$B$22/100),AFFO_Leg!$C$9/(Inputs!$B$23/100))/(1+$A14/100)^5)/100
A15: 11 | B15: =(AFFO_Leg!$C$5/(1+$A15/100)^1+AFFO_Leg!$C$6/(1+$A15/100)^2+AFFO_Leg!$C$7/(1+$A15/100)^3+AFFO_Leg!$C$8/(1+$A15/100)^4+AFFO_Leg!$C$9/(1+$A15/100)^5+MIN(AFFO_Leg!$C$9*(1+Inputs!$B$22/100)/($A15/100-Inputs!$B$22/100),AFFO_Leg!$C$9/(Inputs!$B$23/100))/(1+$A15/100)^5)/100
A16: 12 | B16: =(AFFO_Leg!$C$5/(1+$A16/100)^1+AFFO_Leg!$C$6/(1+$A16/100)^2+AFFO_Leg!$C$7/(1+$A16/100)^3+AFFO_Leg!$C$8/(1+$A16/100)^4+AFFO_Leg!$C$9/(1+$A16/100)^5+MIN(AFFO_Leg!$C$9*(1+Inputs!$B$22/100)/($A16/100-Inputs!$B$22/100),AFFO_Leg!$C$9/(Inputs!$B$23/100))/(1+$A16/100)^5)/100
A17: 15 | B17: =(AFFO_Leg!$C$5/(1+$A17/100)^1+AFFO_Leg!$C$6/(1+$A17/100)^2+AFFO_Leg!$C$7/(1+$A17/100)^3+AFFO_Leg!$C$8/(1+$A17/100)^4+AFFO_Leg!$C$9/(1+$A17/100)^5+MIN(AFFO_Leg!$C$9*(1+Inputs!$B$22/100)/($A17/100-Inputs!$B$22/100),AFFO_Leg!$C$9/(Inputs!$B$23/100))/(1+$A17/100)^5)/100
A20: Sensitivity: base AFFO leg -- rows CoE %, columns terminal growth % (cap fixed at base exit yield)
B21: 1.5 | C21: 2 | D21: 2.5 | E21: 3 | F21: 3.5
A22: 9 | B22: =(AFFO_Leg!$C$5/(1+$A22/100)^1+AFFO_Leg!$C$6/(1+$A22/100)^2+AFFO_Leg!$C$7/(1+$A22/100)^3+AFFO_Leg!$C$8/(1+$A22/100)^4+AFFO_Leg!$C$9/(1+$A22/100)^5+MIN(AFFO_Leg!$C$9*(1+B$21/100)/($A22/100-B$21/100),AFFO_Leg!$C$9/(Inputs!$B$23/100))/(1+$A22/100)^5)/100 | C22: =(AFFO_Leg!$C$5/(1+$A22/100)^1+AFFO_Leg!$C$6/(1+$A22/100)^2+AFFO_Leg!$C$7/(1+$A22/100)^3+AFFO_Leg!$C$8/(1+$A22/100)^4+AFFO_Leg!$C$9/(1+$A22/100)^5+MIN(AFFO_Leg!$C$9*(1+C$21/100)/($A22/100-C$21/100),AFFO_Leg!$C$9/(Inputs!$B$23/100))/(1+$A22/100)^5)/100 | D22: =(AFFO_Leg!$C$5/(1+$A22/100)^1+AFFO_Leg!$C$6/(1+$A22/100)^2+AFFO_Leg!$C$7/(1+$A22/100)^3+AFFO_Leg!$C$8/(1+$A22/100)^4+AFFO_Leg!$C$9/(1+$A22/100)^5+MIN(AFFO_Leg!$C$9*(1+D$21/100)/($A22/100-D$21/100),AFFO_Leg!$C$9/(Inputs!$B$23/100))/(1+$A22/100)^5)/100 | E22: =(AFFO_Leg!$C$5/(1+$A22/100)^1+AFFO_Leg!$C$6/(1+$A22/100)^2+AFFO_Leg!$C$7/(1+$A22/100)^3+AFFO_Leg!$C$8/(1+$A22/100)^4+AFFO_Leg!$C$9/(1+$A22/100)^5+MIN(AFFO_Leg!$C$9*(1+E$21/100)/($A22/100-E$21/100),AFFO_Leg!$C$9/(Inputs!$B$23/100))/(1+$A22/100)^5)/100 | F22: =(AFFO_Leg!$C$5/(1+$A22/100)^1+AFFO_Leg!$C$6/(1+$A22/100)^2+AFFO_Leg!$C$7/(1+$A22/100)^3+AFFO_Leg!$C$8/(1+$A22/100)^4+AFFO_Leg!$C$9/(1+$A22/100)^5+MIN(AFFO_Leg!$C$9*(1+F$21/100)/($A22/100-F$21/100),AFFO_Leg!$C$9/(Inputs!$B$23/100))/(1+$A22/100)^5)/100
A23: 10 | B23: =(AFFO_Leg!$C$5/(1+$A23/100)^1+AFFO_Leg!$C$6/(1+$A23/100)^2+AFFO_Leg!$C$7/(1+$A23/100)^3+AFFO_Leg!$C$8/(1+$A23/100)^4+AFFO_Leg!$C$9/(1+$A23/100)^5+MIN(AFFO_Leg!$C$9*(1+B$21/100)/($A23/100-B$21/100),AFFO_Leg!$C$9/(Inputs!$B$23/100))/(1+$A23/100)^5)/100 | C23: =(AFFO_Leg!$C$5/(1+$A23/100)^1+AFFO_Leg!$C$6/(1+$A23/100)^2+AFFO_Leg!$C$7/(1+$A23/100)^3+AFFO_Leg!$C$8/(1+$A23/100)^4+AFFO_Leg!$C$9/(1+$A23/100)^5+MIN(AFFO_Leg!$C$9*(1+C$21/100)/($A23/100-C$21/100),AFFO_Leg!$C$9/(Inputs!$B$23/100))/(1+$A23/100)^5)/100 | D23: =(AFFO_Leg!$C$5/(1+$A23/100)^1+AFFO_Leg!$C$6/(1+$A23/100)^2+AFFO_Leg!$C$7/(1+$A23/100)^3+AFFO_Leg!$C$8/(1+$A23/100)^4+AFFO_Leg!$C$9/(1+$A23/100)^5+MIN(AFFO_Leg!$C$9*(1+D$21/100)/($A23/100-D$21/100),AFFO_Leg!$C$9/(Inputs!$B$23/100))/(1+$A23/100)^5)/100 | E23: =(AFFO_Leg!$C$5/(1+$A23/100)^1+AFFO_Leg!$C$6/(1+$A23/100)^2+AFFO_Leg!$C$7/(1+$A23/100)^3+AFFO_Leg!$C$8/(1+$A23/100)^4+AFFO_Leg!$C$9/(1+$A23/100)^5+MIN(AFFO_Leg!$C$9*(1+E$21/100)/($A23/100-E$21/100),AFFO_Leg!$C$9/(Inputs!$B$23/100))/(1+$A23/100)^5)/100 | F23: =(AFFO_Leg!$C$5/(1+$A23/100)^1+AFFO_Leg!$C$6/(1+$A23/100)^2+AFFO_Leg!$C$7/(1+$A23/100)^3+AFFO_Leg!$C$8/(1+$A23/100)^4+AFFO_Leg!$C$9/(1+$A23/100)^5+MIN(AFFO_Leg!$C$9*(1+F$21/100)/($A23/100-F$21/100),AFFO_Leg!$C$9/(Inputs!$B$23/100))/(1+$A23/100)^5)/100
A24: 11 | B24: =(AFFO_Leg!$C$5/(1+$A24/100)^1+AFFO_Leg!$C$6/(1+$A24/100)^2+AFFO_Leg!$C$7/(1+$A24/100)^3+AFFO_Leg!$C$8/(1+$A24/100)^4+AFFO_Leg!$C$9/(1+$A24/100)^5+MIN(AFFO_Leg!$C$9*(1+B$21/100)/($A24/100-B$21/100),AFFO_Leg!$C$9/(Inputs!$B$23/100))/(1+$A24/100)^5)/100 | C24: =(AFFO_Leg!$C$5/(1+$A24/100)^1+AFFO_Leg!$C$6/(1+$A24/100)^2+AFFO_Leg!$C$7/(1+$A24/100)^3+AFFO_Leg!$C$8/(1+$A24/100)^4+AFFO_Leg!$C$9/(1+$A24/100)^5+MIN(AFFO_Leg!$C$9*(1+C$21/100)/($A24/100-C$21/100),AFFO_Leg!$C$9/(Inputs!$B$23/100))/(1+$A24/100)^5)/100 | D24: =(AFFO_Leg!$C$5/(1+$A24/100)^1+AFFO_Leg!$C$6/(1+$A24/100)^2+AFFO_Leg!$C$7/(1+$A24/100)^3+AFFO_Leg!$C$8/(1+$A24/100)^4+AFFO_Leg!$C$9/(1+$A24/100)^5+MIN(AFFO_Leg!$C$9*(1+D$21/100)/($A24/100-D$21/100),AFFO_Leg!$C$9/(Inputs!$B$23/100))/(1+$A24/100)^5)/100 | E24: =(AFFO_Leg!$C$5/(1+$A24/100)^1+AFFO_Leg!$C$6/(1+$A24/100)^2+AFFO_Leg!$C$7/(1+$A24/100)^3+AFFO_Leg!$C$8/(1+$A24/100)^4+AFFO_Leg!$C$9/(1+$A24/100)^5+MIN(AFFO_Leg!$C$9*(1+E$21/100)/($A24/100-E$21/100),AFFO_Leg!$C$9/(Inputs!$B$23/100))/(1+$A24/100)^5)/100 | F24: =(AFFO_Leg!$C$5/(1+$A24/100)^1+AFFO_Leg!$C$6/(1+$A24/100)^2+AFFO_Leg!$C$7/(1+$A24/100)^3+AFFO_Leg!$C$8/(1+$A24/100)^4+AFFO_Leg!$C$9/(1+$A24/100)^5+MIN(AFFO_Leg!$C$9*(1+F$21/100)/($A24/100-F$21/100),AFFO_Leg!$C$9/(Inputs!$B$23/100))/(1+$A24/100)^5)/100
A25: 12 | B25: =(AFFO_Leg!$C$5/(1+$A25/100)^1+AFFO_Leg!$C$6/(1+$A25/100)^2+AFFO_Leg!$C$7/(1+$A25/100)^3+AFFO_Leg!$C$8/(1+$A25/100)^4+AFFO_Leg!$C$9/(1+$A25/100)^5+MIN(AFFO_Leg!$C$9*(1+B$21/100)/($A25/100-B$21/100),AFFO_Leg!$C$9/(Inputs!$B$23/100))/(1+$A25/100)^5)/100 | C25: =(AFFO_Leg!$C$5/(1+$A25/100)^1+AFFO_Leg!$C$6/(1+$A25/100)^2+AFFO_Leg!$C$7/(1+$A25/100)^3+AFFO_Leg!$C$8/(1+$A25/100)^4+AFFO_Leg!$C$9/(1+$A25/100)^5+MIN(AFFO_Leg!$C$9*(1+C$21/100)/($A25/100-C$21/100),AFFO_Leg!$C$9/(Inputs!$B$23/100))/(1+$A25/100)^5)/100 | D25: =(AFFO_Leg!$C$5/(1+$A25/100)^1+AFFO_Leg!$C$6/(1+$A25/100)^2+AFFO_Leg!$C$7/(1+$A25/100)^3+AFFO_Leg!$C$8/(1+$A25/100)^4+AFFO_Leg!$C$9/(1+$A25/100)^5+MIN(AFFO_Leg!$C$9*(1+D$21/100)/($A25/100-D$21/100),AFFO_Leg!$C$9/(Inputs!$B$23/100))/(1+$A25/100)^5)/100 | E25: =(AFFO_Leg!$C$5/(1+$A25/100)^1+AFFO_Leg!$C$6/(1+$A25/100)^2+AFFO_Leg!$C$7/(1+$A25/100)^3+AFFO_Leg!$C$8/(1+$A25/100)^4+AFFO_Leg!$C$9/(1+$A25/100)^5+MIN(AFFO_Leg!$C$9*(1+E$21/100)/($A25/100-E$21/100),AFFO_Leg!$C$9/(Inputs!$B$23/100))/(1+$A25/100)^5)/100 | F25: =(AFFO_Leg!$C$5/(1+$A25/100)^1+AFFO_Leg!$C$6/(1+$A25/100)^2+AFFO_Leg!$C$7/(1+$A25/100)^3+AFFO_Leg!$C$8/(1+$A25/100)^4+AFFO_Leg!$C$9/(1+$A25/100)^5+MIN(AFFO_Leg!$C$9*(1+F$21/100)/($A25/100-F$21/100),AFFO_Leg!$C$9/(Inputs!$B$23/100))/(1+$A25/100)^5)/100
A26: 13 | B26: =(AFFO_Leg!$C$5/(1+$A26/100)^1+AFFO_Leg!$C$6/(1+$A26/100)^2+AFFO_Leg!$C$7/(1+$A26/100)^3+AFFO_Leg!$C$8/(1+$A26/100)^4+AFFO_Leg!$C$9/(1+$A26/100)^5+MIN(AFFO_Leg!$C$9*(1+B$21/100)/($A26/100-B$21/100),AFFO_Leg!$C$9/(Inputs!$B$23/100))/(1+$A26/100)^5)/100 | C26: =(AFFO_Leg!$C$5/(1+$A26/100)^1+AFFO_Leg!$C$6/(1+$A26/100)^2+AFFO_Leg!$C$7/(1+$A26/100)^3+AFFO_Leg!$C$8/(1+$A26/100)^4+AFFO_Leg!$C$9/(1+$A26/100)^5+MIN(AFFO_Leg!$C$9*(1+C$21/100)/($A26/100-C$21/100),AFFO_Leg!$C$9/(Inputs!$B$23/100))/(1+$A26/100)^5)/100 | D26: =(AFFO_Leg!$C$5/(1+$A26/100)^1+AFFO_Leg!$C$6/(1+$A26/100)^2+AFFO_Leg!$C$7/(1+$A26/100)^3+AFFO_Leg!$C$8/(1+$A26/100)^4+AFFO_Leg!$C$9/(1+$A26/100)^5+MIN(AFFO_Leg!$C$9*(1+D$21/100)/($A26/100-D$21/100),AFFO_Leg!$C$9/(Inputs!$B$23/100))/(1+$A26/100)^5)/100 | E26: =(AFFO_Leg!$C$5/(1+$A26/100)^1+AFFO_Leg!$C$6/(1+$A26/100)^2+AFFO_Leg!$C$7/(1+$A26/100)^3+AFFO_Leg!$C$8/(1+$A26/100)^4+AFFO_Leg!$C$9/(1+$A26/100)^5+MIN(AFFO_Leg!$C$9*(1+E$21/100)/($A26/100-E$21/100),AFFO_Leg!$C$9/(Inputs!$B$23/100))/(1+$A26/100)^5)/100 | F26: =(AFFO_Leg!$C$5/(1+$A26/100)^1+AFFO_Leg!$C$6/(1+$A26/100)^2+AFFO_Leg!$C$7/(1+$A26/100)^3+AFFO_Leg!$C$8/(1+$A26/100)^4+AFFO_Leg!$C$9/(1+$A26/100)^5+MIN(AFFO_Leg!$C$9*(1+F$21/100)/($A26/100-F$21/100),AFFO_Leg!$C$9/(Inputs!$B$23/100))/(1+$A26/100)^5)/100

Sheet History
A1: FY | B1: Price (31-Mar close) | C1: NTA/share | D1: P/NTA | E1: AFFO cps | F1: P/AFFO | G1: DPPS cents | H1: Ext mgmt fees (m)
A2: FY2017 | B2: 1.75 | C2: 1.67 | D2: =B2/C2 | E2: 8.72 | F2: =B2/E2*100 | G2: 10.33 | H2: 8.541
A3: FY2018 | B3: 1.73 | C3: 1.82 | D3: =B3/C3 | E3: 9.12 | F3: =B3/E3*100 | G3: 10.63 | H3: 13.275
A4: FY2019 | B4: 2.03 | C4: 1.92 | D4: =B4/C4 | E4: 8.88 | F4: =B4/E4*100 | G4: 10.62 | H4: 15.707
A5: FY2020 | B5: 1.51 | C5: 1.91 | D5: =B5/C5 | E5: 8.71 | F5: =B5/E5*100 | G5: 10.32 | H5: 18.279
A6: FY2021 | B6: 2.32 | C6: 2.15 | D6: =B6/C6 | E6: 10.83 | F6: =B6/E6*100 | G6: 11.58 | H6: 25.057
A7: FY2022 | B7: 1.98 | C7: 2.28 | D7: =B7/C7 | E7: 10.09 | F7: =B7/E7*100 | G7: 10.95 | H7: 24.272
A8: FY2023 | B8: 1.29 | C8: 1.98 | D8: =B8/C8 | E8: 9.54 | F8: =B8/E8*100 | G8: 10.66 | H8: 23.312
A9: FY2024 | B9: 1.25 | C9: 1.78 | D9: =B9/C9 | E9: 9.62 | F9: =B9/E9*100 | G9: 10.76 | H9: 19.853
A10: FY2025 | B10: 1.1 | C10: 1.72 | D10: =B10/C10 | E10: 7.53 | F10: =B10/E10*100 | G10: 8.64 | H10: 20.415
A11: FY2026 | B11: 1.11 | C11: 1.69 | D11: =B11/C11 | E11: 7.6 | F11: =B11/E11*100 | G11: 8.78 | H11: 22.909
A13: Average P/NTA | D13: =AVERAGE(D2:D11) | F13: =AVERAGE(F2:F11)
A14: Current P/NTA | D14: =Inputs!B3/Inputs!B5 | F14: =Inputs!B3/Inputs!B10*100
