Workbook

Sheet Model_Info
A1: ALL.AX -- Aristocrat Leisure Limited -- owner-FCF DCF model
A2: Version 1.0, fresh build 2026-09-21. Supersedes nothing (first valuation of this ticker).
A3: Built by the dcf-analyst agent (Claude Fable 5.1) on 2026-09-21 at the orchestrator's request as part of /research-stock ALL.AX.
A5: DATA VINTAGE -- these figures go stale
A6: Price: A$60.55 as of 2026-09-21T06:10:31Z regular close (ASX) (Yahoo Finance chart endpoint).
A7: Balance sheet: 30-Sep-2025 (FY2025 annual report). Net debt A$423.3m = borrowings A$1705.1m less cash A$1281.8m; lease liabilities A$325.1m excluded (treatment B).
A8: Share count: 620.16m fully diluted = 616,871,882 on issue at 30-Sep-2025 (note 3-4) + 3,288,200 dilutive PSRs (note 1-5). Buybacks continued after balance date -- refresh.
A9: Guidance: FY2026 NPATA growth on a constant-currency basis, read by analysts as high-single-digit, second-half weighted (results call 12-Nov-2025).
A10: NOT in the folder: the H1 FY2026 result (May-2026). Refresh shares, net debt and guidance from it and from the FY2026 annual report (Nov-2026).
A12: METHODOLOGY
A13: Model: owner-FCF DCF, component build, 10-year explicit horizon, end-of-year discounting, three probability-weighted scenarios (dcf-methods/references/owner-fcf.md + section 7).
A14: SBC: expensed in the flows at 1.1% of revenue AND the share count held flat (charge once). Employee-share-trust purchases (A$123.5m) and buybacks (A$853.5m) are the cash mechanism that keeps the count flat and are value-neutral.
... A29: CELL LEGEND: blue font = hardcoded input; yellow fill = key driver row; black = formula; green font = cross-sheet link. Sheet names have no spaces. Only rows 5, 7, 9 and 15 of each DCF tab are hardcoded drivers.

Sheet Actuals
A1: Reported history, A$ millions (ALL.AX_Metrics.csv / annual reports); hardcoded
A3: Period | B3: Revenue | C3: EBITDA (post-SBC) | D3: NetIncome | E3: OCF | F3: CapEx | G3: ReportedFCF | H3: SBC | I3: LeasePrincipal | J3: Equity | K3: Cash | L3: Borrowings+Leases | M3: Shares(m) | N3: EPS | O3: CashTaxPaid | P3: Buybacks | Q3: Dividends
A4: FY2016 | B4: 2128.7 | C4: 806 | D4: 350.5 | E4: 680.5 | F4: 192.6 | G4: 487.9 | H4: 19.3 | I4: 0 | J4: 1075.5 | K4: 283.2 | L4: 1287.8 | M4: 637.869 | N4: 0.549 | O4: 84.6 | P4: 0 | Q4: 121
A5: FY2017 | B5: 2453.8 | C5: 1001.2 | D5: 495.1 | E5: 799.1 | F5: 214.3 | G5: 584.8 | H5: 16.1 | I5: 0 | J5: 1345.6 | K5: 547.1 | L5: 1199.4 | M5: 639.146 | N5: 0.775 | O5: 127 | P5: 0 | Q5: 185.2
A6: FY2018 | B6: 3624.1 | C6: 1328.6 | D6: 542.6 | E6: 933.8 | F6: 270.1 | G6: 663.7 | H6: 24.2 | I6: 0 | J6: 1732.5 | K6: 428.1 | L6: 2881.1 | M6: 639.303 | N6: 0.849 | O6: 234.3 | P6: 0 | Q6: 249
A7: FY2019 | B7: 4397.4 | C7: 1596.8 | D7: 698.8 | E7: 1085.5 | F7: 316.6 | G7: 768.9 | H7: 26 | I7: 0 | J7: 2143.6 | K7: 568.6 | L7: 2792.7 | M7: 637.904 | N7: 1.095 | O7: 232.9 | P7: 0 | Q7: 312.4
A8: FY2020 | B8: 4139.1 | C8: 1089.4 | D8: 1377.7 | E8: 1022.9 | F8: 247.8 | G8: 775.1 | H8: 34.4 | I8: 36.6 | J8: 3180 | K8: 1675.7 | L8: 3519.2 | M8: 637.941 | N8: 2.16 | O8: 56.1 | P8: 0 | Q8: 217.1
A9: FY2021 | B9: 4736.6 | C9: 1542.9 | D9: 820 | E9: 1328.4 | F9: 227.7 | G9: 1100.7 | H9: 66.2 | I9: 36.3 | J9: 3878.9 | K9: 2431.6 | L9: 3525 | M9: 637.909 | N9: 1.285 | O9: 218.3 | P9: 0 | Q9: 159.4
A10: FY2022 | B10: 5573.7 | C10: 1850.9 | D10: 948.5 | E10: 1246 | F10: 268.8 | G10: 977.2 | H10: 56.9 | I10: 39.4 | J10: 6022.7 | K10: 3021.3 | L10: 2785.1 | M10: 666.406 | N10: 1.423 | O10: 365 | P10: 312 | Q10: 348.2
A11: FY2023 | B11: 6295.7 | C11: 2105.4 | D11: 1454.1 | E11: 1799.1 | F11: 452.7 | G11: 1346.4 | H11: 76.4 | I11: 42.9 | J11: 6726.1 | K11: 3151 | L11: 2681.9 | M11: 656.812 | N11: 2.214 | O11: 384.8 | P11: 443.3 | Q11: 367.9
A12: FY2024 | B12: 6603.6 | C12: 2469.1 | D12: 1303.4 | E12: 1765.2 | F12: 494.1 | G12: 1271.1 | H12: 73.8 | I12: 47 | J12: 6279.9 | K12: 943.8 | L12: 2407.7 | M12: 640.064 | N12: 2.036 | O12: 553.6 | P12: 837.4 | Q12: 447.7
A13: FY2025 | B13: 6297 | C13: 2628.9 | D13: 1640.3 | E13: 1933.7 | F13: 458.3 | G13: 1475.4 | H13: 67.5 | I13: 44.8 | J13: 6557.2 | K13: 1281.8 | L13: 2030.2 | M13: 627.367 | N13: 2.615 | O13: 555.9 | P13: 853.5 | Q13: 538.4
A16: Notes:
A17: FY2025 revenue/EBITDA/NetIncome are continuing operations (Plarium divested Feb-2025); FY2016-24 include Plarium. FY2024 restated continuing revenue A$5,673.4m.
A18: FY2020 NetIncome includes a ~A$1,018m one-off deferred-tax benefit; FY2025 NetIncome includes the A$456.2m Plarium gain (discontinued) and a A$109.4m pre-tax Big Fish charge. Neither year is a base.
A19: Borrowings+Leases column is the CSV TotalDebt (IFRS 16 lease liabilities included from FY2020). Model net debt uses borrowings only: A$1,705.1m - cash A$1,281.8m = A$423.3m at 30-Sep-2025.
A20: Shares(m) is the diluted WANOS for the year. Model divisor is the year-end fully diluted count 620.16m.
A21: FY2025 OCF includes A$63.6m from discontinued operations (note 4-4); the model's continuing reported FCF is 1,933.7 - 63.6 - 458.3 = 1,411.8.
A22: Buyback status at 30-Sep-2025: A$1.85bn program complete; A$584m of the A$750m program (Feb-2025) purchased. Dividends FY2025 93.0c/share.

Sheet Assumptions
A1: Global assumptions (blue = input)
A4: WACC | B4: 0.095 | C4: AUD-built; same for all scenarios
A5: Lease cost % revenue | B5: 0.0104 | C5: lease principal 44.8 + lease interest 20.7 over FY2025 revenue (treatment B)
A6: Net debt (A$m) | B6: 423.3 | C6: borrowings 1,705.1 - cash 1,281.8 at 30-Sep-2025; leases excluded
A7: Diluted shares (m) | B7: 620.16 | C7: 616.87m on issue + 3.29m PSRs; held flat
A8: Current price (A$) | B8: 60.55 | C8: 2026-09-21T06:10:31Z regular close (ASX)
A9: Terminal value cap (x FCF_10) | B9: 15 | C9: 15x: moderately cyclical gaming business
A10: Hurdle rate | B10: 0.15 | C10: entry-price IRR
A11: FY2025 revenue (A$m) | B11: 6297 | C11: continuing operations
A13: Scenario | B13: Terminal growth | C13: Weight | D13: Capex % rev | E13: WC capture (of rev change)
A14: bear | B14: 0.02 | C14: 0.2 | D14: 0.075 | E14: -0.12
A15: base | B15: 0.03 | C15: 0.55 | D15: 0.07 | E15: -0.12
A16: bull | B16: 0.035 | C16: 0.25 | D16: 0.068 | E16: -0.12
A17: Weight check (must be 100%) | C17: =SUM(C14:C16)
A19: D&A % of revenue (ex right-of-use), by forecast year -> all scenarios | C19: FY2026E | D19: FY2027E | E19: FY2028E | F19: FY2029E | G19: FY2030E | H19: FY2031E | I19: FY2032E | J19: FY2033E | K19: FY2034E | L19: FY2035E
A20: D&A % | C20: 0.084 | D20: 0.083 | E20: 0.082 | F20: 0.081 | G20: 0.08 | H20: 0.079 | I20: 0.078 | J20: 0.077 | K20: 0.076 | L20: 0.075
A22: Scenario narratives
A23: BEAR: Deceleration compounds: the Apollo-backed Everi/IGT Gaming combination wins floor share in North American Gaming Operations, social casino keeps shrinking (-9% market, DAU 1.9m and falling) with Product Madness unable to offset via share gains, and an Apple/Google policy change or adverse gambling-classification ruling cuts social-casino economics. AUD strength reverses the FY2025 translational tailwind. Revenue grows 2-2.5%, pre-SBC EBITDA margin compresses from 42.8% to 39% by year 5, capex stays elevated at 7.5% to defend the installed base, terminal growth 2%.
A24: BASE: FY2026 lands on guidance (high-single-digit constant-currency NPATA growth, second-half weighted) and growth decays from 7% toward 3% over ten years. Gaming holds its ~43% North American installed-base share and keeps winning Outright Sales on new titles (Spooky Link, Baron, Phoenix Link) plus HHR/VLT/COAM adjacencies; Interactive scales with iLottery wins (Michigan, Massachusetts) and Awager; Product Madness gains share in a shrinking market with margin expansion from disciplined UA and direct-to-consumer. Pre-SBC EBITDA margin drifts up 1pp to 43.8% as Interactive matures and Big Fish casual drag is gone. Capex 7.0%, tax 28%, terminal growth 3%, terminal value capped at 15x FCF.
A25: BULL: All three segments outperform simultaneously: North American Gaming Operations installed base keeps adding 4-7k units a year while share holds against the Everi/IGT entity; Interactive sustains 30%+ growth into a still-expanding US iGaming/iLottery market; social casino stabilises and Product Madness converts share gains into margin. AUD stays weak. Revenue grows 10% in FY2026 fading to 3.5% by year 10, pre-SBC EBITDA margin reaches 46%, capex 6.8%, terminal growth 3.5%, terminal value capped at 15x.

Sheet DCF_Bear
A1: BEAR scenario -- unlevered owner FCF, A$ millions
A3: Year | B3: 2025A | C3: FY2026E | D3: FY2027E | E3: FY2028E | F3: FY2029E | G3: FY2030E | H3: FY2031E | I3: FY2032E | J3: FY2033E | K3: FY2034E | L3: FY2035E
A4: Index | B4: 0 | C4: 1 | D4: 2 | E4: 3 | F4: 4 | G4: 5 | H4: 6 | I4: 7 | J4: 8 | K4: 9 | L4: 10
A5: Revenue growth | C5: 0.02 | D5: 0.015 | E5: 0.02 | F5: 0.025 | G5: 0.025 | H5: 0.025 | I5: 0.025 | J5: 0.025 | K5: 0.025 | L5: 0.025
A6: Revenue | B6: =Assumptions!$B$11 | C6: =B6*(1+C5) | D6: =C6*(1+D5) | E6: =D6*(1+E5) | F6: =E6*(1+F5) | G6: =F6*(1+G5) | H6: =G6*(1+H5) | I6: =H6*(1+I5) | J6: =I6*(1+J5) | ... L6: =K6*(1+L5)
A7: Adj EBITDA margin (pre-SBC) | C7: 0.415 | D7: 0.405 | E7: 0.4 | F7: 0.395 | G7: 0.39 | H7: 0.39 | I7: 0.39 | J7: 0.39 | K7: 0.39 | L7: 0.39
A8: Adjusted EBITDA | C8: =C6*C7 | D8: =D6*D7 | E8: =E6*E7 | F8: =F6*F7 | G8: =G6*G7 | H8: =H6*H7 | I8: =I6*I7 | J8: =J6*J7 | ... L8: =L6*L7
A9: SBC % revenue | C9: 0.011 | D9: 0.011 | E9: 0.011 | F9: 0.011 | G9: 0.011 | H9: 0.011 | I9: 0.011 | J9: 0.011 | K9: 0.011 | L9: 0.011
A10: SBC (negative) | C10: =-C6*C9 | D10: =-D6*D9 | E10: =-E6*E9 | F10: =-F6*F9 | G10: =-G6*G9 | H10: =-H6*H9 | I10: =-I6*I9 | J10: =-J6*J9 | ... L10: =-L6*L9
A11: Lease cost (principal+interest) | C11: =-C6*Assumptions!$B$5 | D11: =-D6*Assumptions!$B$5 | E11: =-E6*Assumptions!$B$5 | F11: =-F6*Assumptions!$B$5 | G11: =-G6*Assumptions!$B$5 | H11: =-H6*Assumptions!$B$5 | I11: =-I6*Assumptions!$B$5 | J11: =-J6*Assumptions!$B$5 | ... L11: =-L6*Assumptions!$B$5
A12: Owner EBITDA | C12: =C8+C10+C11 | D12: =D8+D10+D11 | E12: =E8+E10+E11 | F12: =F8+F10+F11 | G12: =G8+G10+G11 | H12: =H8+H10+H11 | I12: =I8+I10+I11 | J12: =J8+J10+J11 | ... L12: =L8+L10+L11
A13: D&A ex-ROU (negative) | C13: =-C6*Assumptions!C$20 | D13: =-D6*Assumptions!D$20 | E13: =-E6*Assumptions!E$20 | F13: =-F6*Assumptions!F$20 | G13: =-G6*Assumptions!G$20 | H13: =-H6*Assumptions!H$20 | I13: =-I6*Assumptions!I$20 | J13: =-J6*Assumptions!J$20 | ... L13: =-L6*Assumptions!L$20
A14: EBIT, SBC + leases expensed | C14: =C12+C13 | D14: =D12+D13 | E14: =E12+E13 | F14: =F12+F13 | G14: =G12+G13 | H14: =H12+H13 | I14: =I12+I13 | J14: =J12+J13 | ... L14: =L12+L13
A15: Cash tax rate | C15: 0.28 | D15: 0.28 | E15: 0.28 | F15: 0.28 | G15: 0.28 | H15: 0.28 | I15: 0.28 | J15: 0.28 | K15: 0.28 | L15: 0.28
A16: NOPAT | C16: =C14-MAX(0,C14)*C15 | D16: =D14-MAX(0,D14)*D15 | E16: =E14-MAX(0,E14)*E15 | F16: =F14-MAX(0,F14)*F15 | G16: =G14-MAX(0,G14)*G15 | H16: =H14-MAX(0,H14)*H15 | I16: =I14-MAX(0,I14)*I15 | J16: =J14-MAX(0,J14)*J15 | ... L16: =L14-MAX(0,L14)*L15
A17: add back D&A | C17: =-C13 | D17: =-D13 | E17: =-E13 | F17: =-F13 | G17: =-G13 | H17: =-H13 | I17: =-I13 | J17: =-J13 | ... L17: =-L13
A18: less capex | C18: =-C6*Assumptions!$D$14 | D18: =-D6*Assumptions!$D$14 | E18: =-E6*Assumptions!$D$14 | F18: =-F6*Assumptions!$D$14 | G18: =-G6*Assumptions!$D$14 | H18: =-H6*Assumptions!$D$14 | I18: =-I6*Assumptions!$D$14 | J18: =-J6*Assumptions!$D$14 | ... L18: =-L6*Assumptions!$D$14
A19: add working capital | C19: =Assumptions!$E$14*(C6-B6) | D19: =Assumptions!$E$14*(D6-C6) | E19: =Assumptions!$E$14*(E6-D6) | F19: =Assumptions!$E$14*(F6-E6) | G19: =Assumptions!$E$14*(G6-F6) | H19: =Assumptions!$E$14*(H6-G6) | I19: =Assumptions!$E$14*(I6-H6) | J19: =Assumptions!$E$14*(J6-I6) | ... L19: =Assumptions!$E$14*(L6-K6)
A20: Unlevered owner FCF | C20: =C16+C17+C18+C19 | D20: =D16+D17+D18+D19 | E20: =E16+E17+E18+E19 | F20: =F16+F17+F18+F19 | G20: =G16+G17+G18+G19 | H20: =H16+H17+H18+H19 | I20: =I16+I17+I18+I19 | J20: =J16+J17+J18+J19 | ... L20: =L16+L17+L18+L19
A21: Discount factor | C21: =1/(1+Assumptions!$B$4)^C4 | D21: =1/(1+Assumptions!$B$4)^D4 | E21: =1/(1+Assumptions!$B$4)^E4 | F21: =1/(1+Assumptions!$B$4)^F4 | G21: =1/(1+Assumptions!$B$4)^G4 | H21: =1/(1+Assumptions!$B$4)^H4 | I21: =1/(1+Assumptions!$B$4)^I4 | J21: =1/(1+Assumptions!$B$4)^J4 | ... L21: =1/(1+Assumptions!$B$4)^L4
A22: PV of FCF | C22: =C20*C21 | D22: =D20*D21 | E22: =E20*E21 | F22: =F20*F21 | G22: =G20*G21 | H22: =H20*H21 | I22: =I20*I21 | J22: =J20*J21 | ... L22: =L20*L21
A24: Memo: FCF before SBC (company-style) | C24: =C20-C10 | D24: =D20-D10 | E24: =E20-E10 | F24: =F20-F10 | G24: =G20-G10 | H24: =H20-H10 | I24: =I20-I10 | J24: =J20-J10 | ... L24: =L20-L10
A25: Memo: owner-FCF margin | C25: =C20/C6 | D25: =D20/D6 | E25: =E20/E6 | F25: =F20/F6 | G25: =G20/G6 | H25: =H20/H6 | I25: =I20/I6 | J25: =J20/J6 | ... L25: =L20/L6
A27: Sum of PV of FCF | B27: =SUM(C22:L22)
A28: Terminal growth | B28: =Assumptions!$B$14
A29: Terminal-year FCF x (1+g) | B29: =L20*(1+B28)
A30: Gordon terminal value | B30: =B29/(Assumptions!$B$4-B28)
A31: Cap terminal value | B31: =Assumptions!$B$9*L20
A32: Terminal value used = MAX(0,MIN(Gordon,cap)) | B32: =MAX(0,MIN(B30,B31))
A33: Implied exit multiple (TV / FCF_10) | B33: =B32/L20
A34: PV of terminal value | B34: =B32*L21
A35: Enterprise value | B35: =B27+B34
A36: less net debt | B36: =-Assumptions!$B$6
A37: Equity value | B37: =B35+B36
A38: Diluted shares (m) | B38: =Assumptions!$B$7
A39: VALUE PER SHARE (A$) | B39: =B37/B38
A40: Upside vs price | B40: =B39/Assumptions!$B$8-1
A42: Street memo: PV of explicit SBC | B42: =-NPV(Assumptions!$B$4,C10:L10)
A43: Street memo: PV of terminal SBC | B43: =(-L10*(1+B28)/(Assumptions!$B$4-B28))*L21
A44: Street value per share (SBC as non-cash) | B44: =(B37+B42+B43)/B38
...

Sheet DCF_Base
A1: BASE scenario -- unlevered owner FCF, A$ millions
A3: Year | B3: 2025A | C3: FY2026E | D3: FY2027E | E3: FY2028E | F3: FY2029E | G3: FY2030E | H3: FY2031E | I3: FY2032E | J3: FY2033E | K3: FY2034E | L3: FY2035E
A4: Index | B4: 0 | C4: 1 | D4: 2 | E4: 3 | F4: 4 | G4: 5 | H4: 6 | I4: 7 | J4: 8 | K4: 9 | L4: 10
A5: Revenue growth | C5: 0.07 | D5: 0.065 | E5: 0.06 | F5: 0.055 | G5: 0.05 | H5: 0.045 | I5: 0.04 | J5: 0.035 | K5: 0.03 | L5: 0.03
A6: Revenue | B6: =Assumptions!$B$11 | C6: =B6*(1+C5) | D6: =C6*(1+D5) | E6: =D6*(1+E5) | F6: =E6*(1+F5) | G6: =F6*(1+G5) | H6: =G6*(1+H5) | I6: =H6*(1+I5) | J6: =I6*(1+J5) | ... L6: =K6*(1+L5)
A7: Adj EBITDA margin (pre-SBC) | C7: 0.428 | D7: 0.43 | E7: 0.432 | F7: 0.434 | G7: 0.435 | H7: 0.436 | I7: 0.437 | J7: 0.438 | K7: 0.438 | L7: 0.438
A8: Adjusted EBITDA | C8: =C6*C7 | D8: =D6*D7 | E8: =E6*E7 | F8: =F6*F7 | G8: =G6*G7 | H8: =H6*H7 | I8: =I6*I7 | J8: =J6*J7 | ... L8: =L6*L7
A9: SBC % revenue | C9: 0.011 | D9: 0.011 | E9: 0.011 | F9: 0.011 | G9: 0.011 | H9: 0.011 | I9: 0.011 | J9: 0.011 | K9: 0.011 | L9: 0.011
A10: SBC (negative) | C10: =-C6*C9 | D10: =-D6*D9 | E10: =-E6*E9 | F10: =-F6*F9 | G10: =-G6*G9 | H10: =-H6*H9 | I10: =-I6*I9 | J10: =-J6*J9 | ... L10: =-L6*L9
A11: Lease cost (principal+interest) | C11: =-C6*Assumptions!$B$5 | D11: =-D6*Assumptions!$B$5 | E11: =-E6*Assumptions!$B$5 | F11: =-F6*Assumptions!$B$5 | G11: =-G6*Assumptions!$B$5 | H11: =-H6*Assumptions!$B$5 | I11: =-I6*Assumptions!$B$5 | J11: =-J6*Assumptions!$B$5 | ... L11: =-L6*Assumptions!$B$5
A12: Owner EBITDA | C12: =C8+C10+C11 | D12: =D8+D10+D11 | E12: =E8+E10+E11 | F12: =F8+F10+F11 | G12: =G8+G10+G11 | H12: =H8+H10+H11 | I12: =I8+I10+I11 | J12: =J8+J10+J11 | ... L12: =L8+L10+L11
A13: D&A ex-ROU (negative) | C13: =-C6*Assumptions!C$20 | D13: =-D6*Assumptions!D$20 | E13: =-E6*Assumptions!E$20 | F13: =-F6*Assumptions!F$20 | G13: =-G6*Assumptions!G$20 | H13: =-H6*Assumptions!H$20 | I13: =-I6*Assumptions!I$20 | J13: =-J6*Assumptions!J$20 | ... L13: =-L6*Assumptions!L$20
A14: EBIT, SBC + leases expensed | C14: =C12+C13 | D14: =D12+D13 | E14: =E12+E13 | F14: =F12+F13 | G14: =G12+G13 | H14: =H12+H13 | I14: =I12+I13 | J14: =J12+J13 | ... L14: =L12+L13
A15: Cash tax rate | C15: 0.28 | D15: 0.28 | E15: 0.28 | F15: 0.28 | G15: 0.28 | H15: 0.28 | I15: 0.28 | J15: 0.28 | K15: 0.28 | L15: 0.28
A16: NOPAT | C16: =C14-MAX(0,C14)*C15 | D16: =D14-MAX(0,D14)*D15 | E16: =E14-MAX(0,E14)*E15 | F16: =F14-MAX(0,F14)*F15 | G16: =G14-MAX(0,G14)*G15 | H16: =H14-MAX(0,H14)*H15 | I16: =I14-MAX(0,I14)*I15 | J16: =J14-MAX(0,J14)*J15 | ... L16: =L14-MAX(0,L14)*L15
A17: add back D&A | C17: =-C13 | D17: =-D13 | E17: =-E13 | F17: =-F13 | G17: =-G13 | H17: =-H13 | I17: =-I13 | J17: =-J13 | ... L17: =-L13
A18: less capex | C18: =-C6*Assumptions!$D$15 | D18: =-D6*Assumptions!$D$15 | E18: =-E6*Assumptions!$D$15 | F18: =-F6*Assumptions!$D$15 | G18: =-G6*Assumptions!$D$15 | H18: =-H6*Assumptions!$D$15 | I18: =-I6*Assumptions!$D$15 | J18: =-J6*Assumptions!$D$15 | ... L18: =-L6*Assumptions!$D$15
A19: add working capital | C19: =Assumptions!$E$15*(C6-B6) | D19: =Assumptions!$E$15*(D6-C6) | E19: =Assumptions!$E$15*(E6-D6) | F19: =Assumptions!$E$15*(F6-E6) | G19: =Assumptions!$E$15*(G6-F6) | H19: =Assumptions!$E$15*(H6-G6) | I19: =Assumptions!$E$15*(I6-H6) | J19: =Assumptions!$E$15*(J6-I6) | ... L19: =Assumptions!$E$15*(L6-K6)
A20: Unlevered owner FCF | C20: =C16+C17+C18+C19 | D20: =D16+D17+D18+D19 | E20: =E16+E17+E18+E19 | F20: =F16+F17+F18+F19 | G20: =G16+G17+G18+G19 | H20: =H16+H17+H18+H19 | I20: =I16+I17+I18+I19 | J20: =J16+J17+J18+J19 | ... L20: =L16+L17+L18+L19
A21: Discount factor | C21: =1/(1+Assumptions!$B$4)^C4 | D21: =1/(1+Assumptions!$B$4)^D4 | E21: =1/(1+Assumptions!$B$4)^E4 | F21: =1/(1+Assumptions!$B$4)^F4 | G21: =1/(1+Assumptions!$B$4)^G4 | H21: =1/(1+Assumptions!$B$4)^H4 | I21: =1/(1+Assumptions!$B$4)^I4 | J21: =1/(1+Assumptions!$B$4)^J4 | ... L21: =1/(1+Assumptions!$B$4)^L4
A22: PV of FCF | C22: =C20*C21 | D22: =D20*D21 | E22: =E20*E21 | F22: =F20*F21 | G22: =G20*G21 | H22: =H20*H21 | I22: =I20*I21 | J22: =J20*J21 | ... L22: =L20*L21
A24: Memo: FCF before SBC (company-style) | C24: =C20-C10 | D24: =D20-D10 | E24: =E20-E10 | F24: =F20-F10 | G24: =G20-G10 | H24: =H20-H10 | I24: =I20-I10 | J24: =J20-J10 | ... L24: =L20-L10
A25: Memo: owner-FCF margin | C25: =C20/C6 | D25: =D20/D6 | E25: =E20/E6 | F25: =F20/F6 | G25: =G20/G6 | H25: =H20/H6 | I25: =I20/I6 | J25: =J20/J6 | ... L25: =L20/L6
A27: Sum of PV of FCF | B27: =SUM(C22:L22)
A28: Terminal growth | B28: =Assumptions!$B$15
A29: Terminal-year FCF x (1+g) | B29: =L20*(1+B28)
A30: Gordon terminal value | B30: =B29/(Assumptions!$B$4-B28)
A31: Cap terminal value | B31: =Assumptions!$B$9*L20
A32: Terminal value used = MAX(0,MIN(Gordon,cap)) | B32: =MAX(0,MIN(B30,B31))
A33: Implied exit multiple (TV / FCF_10) | B33: =B32/L20
A34: PV of terminal value | B34: =B32*L21
A35: Enterprise value | B35: =B27+B34
A36: less net debt | B36: =-Assumptions!$B$6
A37: Equity value | B37: =B35+B36
A38: Diluted shares (m) | B38: =Assumptions!$B$7
A39: VALUE PER SHARE (A$) | B39: =B37/B38
A40: Upside vs price | B40: =B39/Assumptions!$B$8-1
A42: Street memo: PV of explicit SBC | B42: =-NPV(Assumptions!$B$4,C10:L10)
A43: Street memo: PV of terminal SBC | B43: =(-L10*(1+B28)/(Assumptions!$B$4-B28))*L21
A44: Street value per share (SBC as non-cash) | B44: =(B37+B42+B43)/B38
...

Sheet DCF_Bull
A1: BULL scenario -- unlevered owner FCF, A$ millions
A3: Year | B3: 2025A | C3: FY2026E | D3: FY2027E | E3: FY2028E | F3: FY2029E | G3: FY2030E | H3: FY2031E | I3: FY2032E | J3: FY2033E | K3: FY2034E | L3: FY2035E
A4: Index | B4: 0 | C4: 1 | D4: 2 | E4: 3 | F4: 4 | G4: 5 | H4: 6 | I4: 7 | J4: 8 | K4: 9 | L4: 10
A5: Revenue growth | C5: 0.1 | D5: 0.095 | E5: 0.09 | F5: 0.08 | G5: 0.07 | H5: 0.06 | I5: 0.05 | J5: 0.045 | K5: 0.04 | L5: 0.035
A6: Revenue | B6: =Assumptions!$B$11 | C6: =B6*(1+C5) | D6: =C6*(1+D5) | E6: =D6*(1+E5) | F6: =E6*(1+F5) | G6: =F6*(1+G5) | H6: =G6*(1+H5) | I6: =H6*(1+I5) | J6: =I6*(1+J5) | ... L6: =K6*(1+L5)
A7: Adj EBITDA margin (pre-SBC) | C7: 0.43 | D7: 0.435 | E7: 0.44 | F7: 0.445 | G7: 0.45 | H7: 0.453 | I7: 0.456 | J7: 0.458 | K7: 0.46 | L7: 0.46
A8: Adjusted EBITDA | C8: =C6*C7 | D8: =D6*D7 | E8: =E6*E7 | F8: =F6*F7 | G8: =G6*G7 | H8: =H6*H7 | I8: =I6*I7 | J8: =J6*J7 | ... L8: =L6*L7
A9: SBC % revenue | C9: 0.011 | D9: 0.011 | E9: 0.011 | F9: 0.011 | G9: 0.011 | H9: 0.011 | I9: 0.011 | J9: 0.011 | K9: 0.011 | L9: 0.011
A10: SBC (negative) | C10: =-C6*C9 | D10: =-D6*D9 | E10: =-E6*E9 | F10: =-F6*F9 | G10: =-G6*G9 | H10: =-H6*H9 | I10: =-I6*I9 | J10: =-J6*J9 | ... L10: =-L6*L9
A11: Lease cost (principal+interest) | C11: =-C6*Assumptions!$B$5 | D11: =-D6*Assumptions!$B$5 | E11: =-E6*Assumptions!$B$5 | F11: =-F6*Assumptions!$B$5 | G11: =-G6*Assumptions!$B$5 | H11: =-H6*Assumptions!$B$5 | I11: =-I6*Assumptions!$B$5 | J11: =-J6*Assumptions!$B$5 | ... L11: =-L6*Assumptions!$B$5
A12: Owner EBITDA | C12: =C8+C10+C11 | D12: =D8+D10+D11 | E12: =E8+E10+E11 | F12: =F8+F10+F11 | G12: =G8+G10+G11 | H12: =H8+H10+H11 | I12: =I8+I10+I11 | J12: =J8+J10+J11 | ... L12: =L8+L10+L11
A13: D&A ex-ROU (negative) | C13: =-C6*Assumptions!C$20 | D13: =-D6*Assumptions!D$20 | E13: =-E6*Assumptions!E$20 | F13: =-F6*Assumptions!F$20 | G13: =-G6*Assumptions!G$20 | H13: =-H6*Assumptions!H$20 | I13: =-I6*Assumptions!I$20 | J13: =-J6*Assumptions!J$20 | ... L13: =-L6*Assumptions!L$20
A14: EBIT, SBC + leases expensed | C14: =C12+C13 | D14: =D12+D13 | E14: =E12+E13 | F14: =F12+F13 | G14: =G12+G13 | H14: =H12+H13 | I14: =I12+I13 | J14: =J12+J13 | ... L14: =L12+L13
A15: Cash tax rate | C15: 0.28 | D15: 0.28 | E15: 0.28 | F15: 0.28 | G15: 0.28 | H15: 0.28 | I15: 0.28 | J15: 0.28 | K15: 0.28 | L15: 0.28
A16: NOPAT | C16: =C14-MAX(0,C14)*C15 | D16: =D14-MAX(0,D14)*D15 | E16: =E14-MAX(0,E14)*E15 | F16: =F14-MAX(0,F14)*F15 | G16: =G14-MAX(0,G14)*G15 | H16: =H14-MAX(0,H14)*H15 | I16: =I14-MAX(0,I14)*I15 | J16: =J14-MAX(0,J14)*J15 | ... L16: =L14-MAX(0,L14)*L15
A17: add back D&A | C17: =-C13 | D17: =-D13 | E17: =-E13 | F17: =-F13 | G17: =-G13 | H17: =-H13 | I17: =-I13 | J17: =-J13 | ... L17: =-L13
A18: less capex | C18: =-C6*Assumptions!$D$16 | D18: =-D6*Assumptions!$D$16 | E18: =-E6*Assumptions!$D$16 | F18: =-F6*Assumptions!$D$16 | G18: =-G6*Assumptions!$D$16 | H18: =-H6*Assumptions!$D$16 | I18: =-I6*Assumptions!$D$16 | J18: =-J6*Assumptions!$D$16 | ... L18: =-L6*Assumptions!$D$16
A19: add working capital | C19: =Assumptions!$E$16*(C6-B6) | D19: =Assumptions!$E$16*(D6-C6) | E19: =Assumptions!$E$16*(E6-D6) | F19: =Assumptions!$E$16*(F6-E6) | G19: =Assumptions!$E$16*(G6-F6) | H19: =Assumptions!$E$16*(H6-G6) | I19: =Assumptions!$E$16*(I6-H6) | J19: =Assumptions!$E$16*(J6-I6) | ... L19: =Assumptions!$E$16*(L6-K6)
A20: Unlevered owner FCF | C20: =C16+C17+C18+C19 | D20: =D16+D17+D18+D19 | E20: =E16+E17+E18+E19 | F20: =F16+F17+F18+F19 | G20: =G16+G17+G18+G19 | H20: =H16+H17+H18+H19 | I20: =I16+I17+I18+I19 | J20: =J16+J17+J18+J19 | ... L20: =L16+L17+L18+L19
A21: Discount factor | C21: =1/(1+Assumptions!$B$4)^C4 | D21: =1/(1+Assumptions!$B$4)^D4 | E21: =1/(1+Assumptions!$B$4)^E4 | F21: =1/(1+Assumptions!$B$4)^F4 | G21: =1/(1+Assumptions!$B$4)^G4 | H21: =1/(1+Assumptions!$B$4)^H4 | I21: =1/(1+Assumptions!$B$4)^I4 | J21: =1/(1+Assumptions!$B$4)^J4 | ... L21: =1/(1+Assumptions!$B$4)^L4
A22: PV of FCF | C22: =C20*C21 | D22: =D20*D21 | E22: =E20*E21 | F22: =F20*F21 | G22: =G20*G21 | H22: =H20*H21 | I22: =I20*I21 | J22: =J20*J21 | ... L22: =L20*L21
A24: Memo: FCF before SBC (company-style) | C24: =C20-C10 | D24: =D20-D10 | E24: =E20-E10 | F24: =F20-F10 | G24: =G20-G10 | H24: =H20-H10 | I24: =I20-I10 | J24: =J20-J10 | ... L24: =L20-L10
A25: Memo: owner-FCF margin | C25: =C20/C6 | D25: =D20/D6 | E25: =E20/E6 | F25: =F20/F6 | G25: =G20/G6 | H25: =H20/H6 | I25: =I20/I6 | J25: =J20/J6 | ... L25: =L20/L6
A27: Sum of PV of FCF | B27: =SUM(C22:L22)
A28: Terminal growth | B28: =Assumptions!$B$16
A29: Terminal-year FCF x (1+g) | B29: =L20*(1+B28)
A30: Gordon terminal value | B30: =B29/(Assumptions!$B$4-B28)
A31: Cap terminal value | B31: =Assumptions!$B$9*L20
A32: Terminal value used = MAX(0,MIN(Gordon,cap)) | B32: =MAX(0,MIN(B30,B31))
A33: Implied exit multiple (TV / FCF_10) | B33: =B32/L20
A34: PV of terminal value | B34: =B32*L21
A35: Enterprise value | B35: =B27+B34
A36: less net debt | B36: =-Assumptions!$B$6
A37: Equity value | B37: =B35+B36
A38: Diluted shares (m) | B38: =Assumptions!$B$7
A39: VALUE PER SHARE (A$) | B39: =B37/B38
A40: Upside vs price | B40: =B39/Assumptions!$B$8-1
A42: Street memo: PV of explicit SBC | B42: =-NPV(Assumptions!$B$4,C10:L10)
A43: Street memo: PV of terminal SBC | B43: =(-L10*(1+B28)/(Assumptions!$B$4-B28))*L21
A44: Street value per share (SBC as non-cash) | B44: =(B37+B42+B43)/B38
...

Sheet FCF_Quality
A1: Reported FCF reconciled to owner FCF (A$m). Lease principal applies from FY2020 (IFRS 16).
A3: Line | B3: FY2016 | C3: FY2017 | D3: FY2018 | E3: FY2019 | F3: FY2020 | G3: FY2021 | H3: FY2022 | I3: FY2023 | J3: FY2024 | K3: FY2025
A4: Revenue | B4: =Actuals!B4 | C4: =Actuals!B5 | D4: =Actuals!B6 | E4: =Actuals!B7 | F4: =Actuals!B8 | G4: =Actuals!B9 | H4: =Actuals!B10 | I4: =Actuals!B11 | J4: =Actuals!B12 | K4: =Actuals!B13
A5: Free cash flow (company: OCF - capex) | B5: =Actuals!G4 | C5: =Actuals!G5 | D5: =Actuals!G6 | E5: =Actuals!G7 | F5: =Actuals!G8 | G5: =Actuals!G9 | H5: =Actuals!G10 | I5: =Actuals!G11 | J5: =Actuals!G12 | K5: =Actuals!G13
A6: less: SBC | B6: =Actuals!H4 | C6: =Actuals!H5 | D6: =Actuals!H6 | E6: =Actuals!H7 | F6: =Actuals!H8 | G6: =Actuals!H9 | H6: =Actuals!H10 | I6: =Actuals!H11 | J6: =Actuals!H12 | K6: =Actuals!H13
A7: less: lease principal | B7: =Actuals!I4 | C7: =Actuals!I5 | D7: =Actuals!I6 | E7: =Actuals!I7 | F7: =Actuals!I8 | G7: =Actuals!I9 | H7: =Actuals!I10 | I7: =Actuals!I11 | J7: =Actuals!I12 | K7: =Actuals!I13
A8: less: interest income (not stripped: net-debt company) | B8: 0 | C8: 0 | D8: 0 | E8: 0 | F8: 0 | G8: 0 | H8: 0 | I8: 0 | J8: 0 | K8: 0
A9: Owner FCF (reported less SBC less lease principal) | B9: =B5-B6-B7-B8 | C9: =C5-C6-C7-C8 | D9: =D5-D6-D7-D8 | E9: =E5-E6-E7-E8 | F9: =F5-F6-F7-F8 | G9: =G5-G6-G7-G8 | H9: =H5-H6-H7-H8 | I9: =I5-I6-I7-I8 | ... K9: =K5-K6-K7-K8
A10: Reported FCF margin | B10: =B5/B4 | C10: =C5/C4 | D10: =D5/D4 | E10: =E5/E4 | F10: =F5/F4 | G10: =G5/G4 | H10: =H5/H4 | I10: =I5/I4 | ... K10: =K5/K4
A11: Owner FCF margin | B11: =B9/B4 | C11: =C9/C4 | D11: =D9/D4 | E11: =E9/E4 | F11: =F9/F4 | G11: =G9/G4 | H11: =H9/H4 | I11: =I9/I4 | ... K11: =K9/K4
A12: Memo: cash tax paid | B12: =Actuals!O4 | C12: =Actuals!O5 | D12: =Actuals!O6 | E12: =Actuals!O7 | F12: =Actuals!O8 | G12: =Actuals!O9 | H12: =Actuals!O10 | I12: =Actuals!O11 | J12: =Actuals!O12 | K12: =Actuals!O13
A13: Memo: cash tax / EBITDA (flag FY2020 abnormal) | B13: =B12/Actuals!C4 | C13: =C12/Actuals!C5 | D13: =D12/Actuals!C6 | E13: =E12/Actuals!C7 | F13: =F12/Actuals!C8 | G13: =G12/Actuals!C9 | H13: =H12/Actuals!C10 | I13: =I12/Actuals!C11 | J13: =J12/Actuals!C12 | K13: =K12/Actuals!C13
A15: FY2025 reported FCF above is total (incl. A$63.6m Plarium stub OCF). Continuing reported FCF 1,411.8; continuing owner FCF 1,299.5 = inputs.last_fcf.
A16: Deferred revenue moved 198.1 -> 188.5 in FY2025 (-A$9.6m): no working-capital tailwind inside OCF; NWC was an A$136.3m OUTFLOW.

Sheet Valuation
A1: Valuation summary (A$ per share)
A3: Scenario | B3: Value/share | C3: Upside vs price | D3: Weight | E3: Street value/share | F3: Entry price @15% | G3: Street entry @15%
A4: bear | B4: =DCF_Bear!$B$39 | C4: =B4/Assumptions!$B$8-1 | D4: =Assumptions!$C$14 | E4: =DCF_Bear!$B$44 | F4: =IF(Assumptions!$B$10>Assumptions!$B$14,(NPV(Assumptions!$B$10,DCF_Bear!$C$20:$L$20)+MAX(0,MIN(DCF_Bear!$L$20*(1+Assumptions!$B$14)/(Assumptions!$B$10-Assumptions!$B$14),Assumptions!$B$9*DCF_Bear!$L$20))/(1+Assumptions!$B$10)^10-Assumptions!$B$6)/Assumptions!$B$7,"n/a") | G4: =IF(Assumptions!$B$10>Assumptions!$B$14,(NPV(Assumptions!$B$10,DCF_Bear!$C$20:$L$20)+MAX(0,MIN(DCF_Bear!$L$20*(1+Assumptions!$B$14)/(Assumptions!$B$10-Assumptions!$B$14),Assumptions!$B$9*DCF_Bear!$L$20))/(1+Assumptions!$B$10)^10-Assumptions!$B$6-NPV(Assumptions!$B$10,DCF_Bear!$C$10:$L$10)+(-DCF_Bear!$L$10*(1+Assumptions!$B$14)/(Assumptions!$B$10-Assumptions!$B$14))/(1+Assumptions!$B$10)^10)/Assumptions!$B$7,"n/a")
A5: base | B5: =DCF_Base!$B$39 | C5: =B5/Assumptions!$B$8-1 | D5: =Assumptions!$C$15 | E5: =DCF_Base!$B$44 | F5: =IF(Assumptions!$B$10>Assumptions!$B$15,(NPV(Assumptions!$B$10,DCF_Base!$C$20:$L$20)+MAX(0,MIN(DCF_Base!$L$20*(1+Assumptions!$B$15)/(Assumptions!$B$10-Assumptions!$B$15),Assumptions!$B$9*DCF_Base!$L$20))/(1+Assumptions!$B$10)^10-Assumptions!$B$6)/Assumptions!$B$7,"n/a") | G5: =IF(Assumptions!$B$10>Assumptions!$B$15,(NPV(Assumptions!$B$10,DCF_Base!$C$20:$L$20)+MAX(0,MIN(DCF_Base!$L$20*(1+Assumptions!$B$15)/(Assumptions!$B$10-Assumptions!$B$15),Assumptions!$B$9*DCF_Base!$L$20))/(1+Assumptions!$B$10)^10-Assumptions!$B$6-NPV(Assumptions!$B$10,DCF_Base!$C$10:$L$10)+(-DCF_Base!$L$10*(1+Assumptions!$B$15)/(Assumptions!$B$10-Assumptions!$B$15))/(1+Assumptions!$B$10)^10)/Assumptions!$B$7,"n/a")
A6: bull | B6: =DCF_Bull!$B$39 | C6: =B6/Assumptions!$B$8-1 | D6: =Assumptions!$C$16 | E6: =DCF_Bull!$B$44 | F6: =IF(Assumptions!$B$10>Assumptions!$B$16,(NPV(Assumptions!$B$10,DCF_Bull!$C$20:$L$20)+MAX(0,MIN(DCF_Bull!$L$20*(1+Assumptions!$B$16)/(Assumptions!$B$10-Assumptions!$B$16),Assumptions!$B$9*DCF_Bull!$L$20))/(1+Assumptions!$B$10)^10-Assumptions!$B$6)/Assumptions!$B$7,"n/a") | G6: =IF(Assumptions!$B$10>Assumptions!$B$16,(NPV(Assumptions!$B$10,DCF_Bull!$C$20:$L$20)+MAX(0,MIN(DCF_Bull!$L$20*(1+Assumptions!$B$16)/(Assumptions!$B$10-Assumptions!$B$16),Assumptions!$B$9*DCF_Bull!$L$20))/(1+Assumptions!$B$10)^10-Assumptions!$B$6-NPV(Assumptions!$B$10,DCF_Bull!$C$10:$L$10)+(-DCF_Bull!$L$10*(1+Assumptions!$B$16)/(Assumptions!$B$10-Assumptions!$B$16))/(1+Assumptions!$B$10)^10)/Assumptions!$B$7,"n/a")
A8: Probability-weighted value | B8: =SUMPRODUCT(B4:B6,D4:D6) | E8: =SUMPRODUCT(E4:E6,D4:D6) | F8: =SUMPRODUCT(F4:F6,D4:D6) | G8: =SUMPRODUCT(G4:G6,D4:D6)
A9: Margin of safety (1 - price/weighted) | B9: =1-Assumptions!$B$8/B8
A10: Band position (price-house)/(street-house) | B10: =(Assumptions!$B$8-B8)/(E8-B8)
A11: Band note: SBC is 1.1% of revenue, so the band is ~A$2/share wide; price sits above both bases. Above 100% means the market pays more than even the street basis.
A13: Required-return table (base case; TV rebuilt at each rate)
A14: Required return | B14: Value/share
A15: 0.09 | B15: =IF($A$15>Assumptions!$B$15,(NPV($A$15,DCF_Base!$C$20:$L$20)+MAX(0,MIN(DCF_Base!$L$20*(1+Assumptions!$B$15)/($A$15-Assumptions!$B$15),Assumptions!$B$9*DCF_Base!$L$20))/(1+$A$15)^10-Assumptions!$B$6)/Assumptions!$B$7,"n/a")
A16: 0.095 | B16: =IF($A$16>Assumptions!$B$15,(NPV($A$16,DCF_Base!$C$20:$L$20)+MAX(0,MIN(DCF_Base!$L$20*(1+Assumptions!$B$15)/($A$16-Assumptions!$B$15),Assumptions!$B$9*DCF_Base!$L$20))/(1+$A$16)^10-Assumptions!$B$6)/Assumptions!$B$7,"n/a") | C16: model WACC row: must equal DCF_Base!B39
A17: 0.1 | B17: =IF($A$17>Assumptions!$B$15,(NPV($A$17,DCF_Base!$C$20:$L$20)+MAX(0,MIN(DCF_Base!$L$20*(1+Assumptions!$B$15)/($A$17-Assumptions!$B$15),Assumptions!$B$9*DCF_Base!$L$20))/(1+$A$17)^10-Assumptions!$B$6)/Assumptions!$B$7,"n/a")
A18: 0.11 | B18: =IF($A$18>Assumptions!$B$15,(NPV($A$18,DCF_Base!$C$20:$L$20)+MAX(0,MIN(DCF_Base!$L$20*(1+Assumptions!$B$15)/($A$18-Assumptions!$B$15),Assumptions!$B$9*DCF_Base!$L$20))/(1+$A$18)^10-Assumptions!$B$6)/Assumptions!$B$7,"n/a")
A19: 0.12 | B19: =IF($A$19>Assumptions!$B$15,(NPV($A$19,DCF_Base!$C$20:$L$20)+MAX(0,MIN(DCF_Base!$L$20*(1+Assumptions!$B$15)/($A$19-Assumptions!$B$15),Assumptions!$B$9*DCF_Base!$L$20))/(1+$A$19)^10-Assumptions!$B$6)/Assumptions!$B$7,"n/a")
A20: 0.15 | B20: =IF($A$20>Assumptions!$B$15,(NPV($A$20,DCF_Base!$C$20:$L$20)+MAX(0,MIN(DCF_Base!$L$20*(1+Assumptions!$B$15)/($A$20-Assumptions!$B$15),Assumptions!$B$9*DCF_Base!$L$20))/(1+$A$20)^10-Assumptions!$B$6)/Assumptions!$B$7,"n/a") | C20: hurdle row: must equal base entry price (F5)
A23: Sensitivity: base value/share, WACC (rows) x terminal growth (columns); TV = MIN(Gordon, cap) per cell
B24: 0.02 | C24: 0.025 | D24: 0.03 | E24: 0.035 | F24: 0.04
A25: 0.075 | B25: =IF($A$25>B$24,(NPV($A$25,DCF_Base!$C$20:$L$20)+MAX(0,MIN(DCF_Base!$L$20*(1+B$24)/($A$25-B$24),Assumptions!$B$9*DCF_Base!$L$20))/(1+$A$25)^10-Assumptions!$B$6)/Assumptions!$B$7,"n/a") | C25: =IF($A$25>C$24,(NPV($A$25,DCF_Base!$C$20:$L$20)+MAX(0,MIN(DCF_Base!$L$20*(1+C$24)/($A$25-C$24),Assumptions!$B$9*DCF_Base!$L$20))/(1+$A$25)^10-Assumptions!$B$6)/Assumptions!$B$7,"n/a") | D25: =IF($A$25>D$24,(NPV($A$25,DCF_Base!$C$20:$L$20)+MAX(0,MIN(DCF_Base!$L$20*(1+D$24)/($A$25-D$24),Assumptions!$B$9*DCF_Base!$L$20))/(1+$A$25)^10-Assumptions!$B$6)/Assumptions!$B$7,"n/a") | E25: =IF($A$25>E$24,(NPV($A$25,DCF_Base!$C$20:$L$20)+MAX(0,MIN(DCF_Base!$L$20*(1+E$24)/($A$25-E$24),Assumptions!$B$9*DCF_Base!$L$20))/(1+$A$25)^10-Assumptions!$B$6)/Assumptions!$B$7,"n/a") | F25: =IF($A$25>F$24,(NPV($A$25,DCF_Base!$C$20:$L$20)+MAX(0,MIN(DCF_Base!$L$20*(1+F$24)/($A$25-F$24),Assumptions!$B$9*DCF_Base!$L$20))/(1+$A$25)^10-Assumptions!$B$6)/Assumptions!$B$7,"n/a")
A26: 0.085 | B26: =IF($A$26>B$24,(NPV($A$26,DCF_Base!$C$20:$L$20)+MAX(0,MIN(DCF_Base!$L$20*(1+B$24)/($A$26-B$24),Assumptions!$B$9*DCF_Base!$L$20))/(1+$A$26)^10-Assumptions!$B$6)/Assumptions!$B$7,"n/a") | C26: =IF($A$26>C$24,(NPV($A$26,DCF_Base!$C$20:$L$20)+MAX(0,MIN(DCF_Base!$L$20*(1+C$24)/($A$26-C$24),Assumptions!$B$9*DCF_Base!$L$20))/(1+$A$26)^10-Assumptions!$B$6)/Assumptions!$B$7,"n/a") | D26: =IF($A$26>D$24,(NPV($A$26,DCF_Base!$C$20:$L$20)+MAX(0,MIN(DCF_Base!$L$20*(1+D$24)/($A$26-D$24),Assumptions!$B$9*DCF_Base!$L$20))/(1+$A$26)^10-Assumptions!$B$6)/Assumptions!$B$7,"n/a") | E26: =IF($A$26>E$24,(NPV($A$26,DCF_Base!$C$20:$L$20)+MAX(0,MIN(DCF_Base!$L$20*(1+E$24)/($A$26-E$24),Assumptions!$B$9*DCF_Base!$L$20))/(1+$A$26)^10-Assumptions!$B$6)/Assumptions!$B$7,"n/a") | F26: =IF($A$26>F$24,(NPV($A$26,DCF_Base!$C$20:$L$20)+MAX(0,MIN(DCF_Base!$L$20*(1+F$24)/($A$26-F$24),Assumptions!$B$9*DCF_Base!$L$20))/(1+$A$26)^10-Assumptions!$B$6)/Assumptions!$B$7,"n/a")
A27: 0.095 | B27: =IF($A$27>B$24,(NPV($A$27,DCF_Base!$C$20:$L$20)+MAX(0,MIN(DCF_Base!$L$20*(1+B$24)/($A$27-B$24),Assumptions!$B$9*DCF_Base!$L$20))/(1+$A$27)^10-Assumptions!$B$6)/Assumptions!$B$7,"n/a") | C27: =IF($A$27>C$24,(NPV($A$27,DCF_Base!$C$20:$L$20)+MAX(0,MIN(DCF_Base!$L$20*(1+C$24)/($A$27-C$24),Assumptions!$B$9*DCF_Base!$L$20))/(1+$A$27)^10-Assumptions!$B$6)/Assumptions!$B$7,"n/a") | D27: =IF($A$27>D$24,(NPV($A$27,DCF_Base!$C$20:$L$20)+MAX(0,MIN(DCF_Base!$L$20*(1+D$24)/($A$27-D$24),Assumptions!$B$9*DCF_Base!$L$20))/(1+$A$27)^10-Assumptions!$B$6)/Assumptions!$B$7,"n/a") | E27: =IF($A$27>E$24,(NPV($A$27,DCF_Base!$C$20:$L$20)+MAX(0,MIN(DCF_Base!$L$20*(1+E$24)/($A$27-E$24),Assumptions!$B$9*DCF_Base!$L$20))/(1+$A$27)^10-Assumptions!$B$6)/Assumptions!$B$7,"n/a") | F27: =IF($A$27>F$24,(NPV($A$27,DCF_Base!$C$20:$L$20)+MAX(0,MIN(DCF_Base!$L$20*(1+F$24)/($A$27-F$24),Assumptions!$B$9*DCF_Base!$L$20))/(1+$A$27)^10-Assumptions!$B$6)/Assumptions!$B$7,"n/a")
A28: 0.105 | B28: =IF($A$28>B$24,(NPV($A$28,DCF_Base!$C$20:$L$20)+MAX(0,MIN(DCF_Base!$L$20*(1+B$24)/($A$28-B$24),Assumptions!$B$9*DCF_Base!$L$20))/(1+$A$28)^10-Assumptions!$B$6)/Assumptions!$B$7,"n/a") | C28: =IF($A$28>C$24,(NPV($A$28,DCF_Base!$C$20:$L$20)+MAX(0,MIN(DCF_Base!$L$20*(1+C$24)/($A$28-C$24),Assumptions!$B$9*DCF_Base!$L$20))/(1+$A$28)^10-Assumptions!$B$6)/Assumptions!$B$7,"n/a") | D28: =IF($A$28>D$24,(NPV($A$28,DCF_Base!$C$20:$L$20)+MAX(0,MIN(DCF_Base!$L$20*(1+D$24)/($A$28-D$24),Assumptions!$B$9*DCF_Base!$L$20))/(1+$A$28)^10-Assumptions!$B$6)/Assumptions!$B$7,"n/a") | E28: =IF($A$28>E$24,(NPV($A$28,DCF_Base!$C$20:$L$20)+MAX(0,MIN(DCF_Base!$L$20*(1+E$24)/($A$28-E$24),Assumptions!$B$9*DCF_Base!$L$20))/(1+$A$28)^10-Assumptions!$B$6)/Assumptions!$B$7,"n/a") | F28: =IF($A$28>F$24,(NPV($A$28,DCF_Base!$C$20:$L$20)+MAX(0,MIN(DCF_Base!$L$20*(1+F$24)/($A$28-F$24),Assumptions!$B$9*DCF_Base!$L$20))/(1+$A$28)^10-Assumptions!$B$6)/Assumptions!$B$7,"n/a")
A29: 0.115 | B29: =IF($A$29>B$24,(NPV($A$29,DCF_Base!$C$20:$L$20)+MAX(0,MIN(DCF_Base!$L$20*(1+B$24)/($A$29-B$24),Assumptions!$B$9*DCF_Base!$L$20))/(1+$A$29)^10-Assumptions!$B$6)/Assumptions!$B$7,"n/a") | C29: =IF($A$29>C$24,(NPV($A$29,DCF_Base!$C$20:$L$20)+MAX(0,MIN(DCF_Base!$L$20*(1+C$24)/($A$29-C$24),Assumptions!$B$9*DCF_Base!$L$20))/(1+$A$29)^10-Assumptions!$B$6)/Assumptions!$B$7,"n/a") | D29: =IF($A$29>D$24,(NPV($A$29,DCF_Base!$C$20:$L$20)+MAX(0,MIN(DCF_Base!$L$20*(1+D$24)/($A$29-D$24),Assumptions!$B$9*DCF_Base!$L$20))/(1+$A$29)^10-Assumptions!$B$6)/Assumptions!$B$7,"n/a") | E29: =IF($A$29>E$24,(NPV($A$29,DCF_Base!$C$20:$L$20)+MAX(0,MIN(DCF_Base!$L$20*(1+E$24)/($A$29-E$24),Assumptions!$B$9*DCF_Base!$L$20))/(1+$A$29)^10-Assumptions!$B$6)/Assumptions!$B$7,"n/a") | F29: =IF($A$29>F$24,(NPV($A$29,DCF_Base!$C$20:$L$20)+MAX(0,MIN(DCF_Base!$L$20*(1+F$24)/($A$29-F$24),Assumptions!$B$9*DCF_Base!$L$20))/(1+$A$29)^10-Assumptions!$B$6)/Assumptions!$B$7,"n/a")
