Workbook

Sheet Model_Info
A1: ALS Limited (ALQ.AX) owner-FCF DCF model
A2: Version 1.0, built 2026-09-21. Fresh build; supersedes nothing (first valuation of this ticker).
A3: Built by the dcf-analyst agent (Claude Fable 5.1) at the request of Stephen Williams, from the research-stock pipeline.
A5: DATA VINTAGE (all figures go stale; refresh after the next print)
A6: Price: A$21.35, Yahoo Finance regular ASX close 2026-09-21T06:10:32Z (16:10 AEST). 52-week range 19.00-26.17.
A7: Balance sheet: 31 March 2026 (FY2026 annual report). Net borrowings ex leases 1,069.5; lease liabilities 352.7 (excluded); NCI 5.2; cash 149.7.
A8: Shares: 507.54m issued at 10-Jun-2026 (annual report p.152) + 3.0m unvested performance rights (diluted EPS note) = 510.5m fully diluted, held flat.
A9: Guidance: FY27 guidance from the FY26 results of 18-May-2026 (Commodities organic +13-15%, Life Sciences mid-single-digit, margin expansion at a similar pace to FY26, capex ~A$240m, net interest A$65-67m).
A10: History: ALQ.AX_Metrics.csv (core_metrics DB) plus FY2026 annual report cash flow statement and underlying-earnings reconciliation (pp.30, 66).
A12: METHODOLOGY
A13: Model: owner-FCF DCF, 10-year explicit horizon, end-of-year discounting, scenario-weighted (bear/base/bull). Routed via .claude/skills/dcf-methods (operating company, non-US, cyclical).
A14: Owner FCF: SBC fully expensed as a % of revenue, share count held flat (charge dilution once). Interest income not stripped: ALS is a net-debt company so no cash pile is added to EV.
... A30: Text cells never begin with '='. Sheet names contain no spaces. Never paste a value over a formula; add a labelled input on Assumptions and link to it.

Sheet Actuals
A1: Reported history (AUD millions unless stated); hardcoded from ALQ.AX_Metrics.csv and the FY2026 annual report
A3: Period | B3: Revenue | C3: Reported FCF | D3: SBC | E3: OCF | F3: Capex | G3: Taxes paid | H3: PBT | I3: Lease principal | J3: Equity | K3: EPS (cents)
A4: FY2015 | B4: 1422.2 | C4: 138.7 | D4: 0.6 | E4: 215.2 | F4: 76.5 | G4: 48 | H4: -120.2 | J4: 1228.4 | K4: -41.13
A5: FY2016 | B5: 1364.9 | C5: 95.9 | D5: 1.4 | E5: 169.6 | F5: 73.7 | G5: 39 | H5: -203.6 | J5: 1185.6 | K5: -52.51
A6: FY2017 | B6: 1261.5 | C6: 116.6 | D6: 2 | E6: 175.3 | F6: 58.7 | G6: 41 | H6: 146.1 | J6: 1185.2 | K6: 16.18
A7: FY2018 | B7: 1446.9 | C7: 112.4 | E7: 185.8 | F7: 73.4 | G7: 47.3 | H7: 115.4 | J7: 1122 | K7: 10.34
A8: FY2019 | B8: 1664.8 | C8: 109.9 | D8: 3.6 | E8: 218.8 | F8: 108.9 | G8: 50.3 | H8: 230.3 | J8: 1103.2 | K8: 31.57
A9: FY2020 | B9: 1831.9 | C9: 137.9 | D9: 5.7 | E9: 259 | F9: 121.1 | G9: 96 | H9: 151.1 | I9: 43 | J9: 1110.6 | K9: 26.46
A10: FY2021 | B10: 1761.4 | C10: 188.9 | D10: 4.6 | E10: 265.8 | F10: 76.9 | G10: 67.9 | H10: 248.5 | I10: 42.9 | J10: 1079.8 | K10: 35.78
A11: FY2022 | B11: 1951.8 | C11: 167.9 | D11: 5.3 | E11: 286.8 | F11: 118.9 | G11: 106.1 | H11: 280 | I11: 45.2 | J11: 1130.7 | K11: 39.45
A12: FY2023 | B12: 2279.2 | C12: 293.8 | D12: 7.9 | E12: 439.9 | F12: 146.1 | G12: 89.9 | H12: 390.7 | I12: 52.9 | J12: 1378.2 | K12: 60.23
A13: FY2024 | B13: 2461.6 | C13: 198.4 | D13: 7 | E13: 350.1 | F13: 151.7 | G13: 127.9 | H13: 121.3 | I13: 61 | J13: 1196.9 | K13: 2.66
A14: FY2025 | B14: 2999.4 | C14: 244.6 | D14: 10.4 | E14: 409.6 | F14: 165 | G14: 119.4 | H14: 362.7 | I14: 89.6 | J14: 1294.1 | K14: 52.8
A15: FY2026 | B15: 3320.1 | C15: 222.7 | D15: 9.6 | E15: 485.7 | F15: 263 | G15: 137.5 | H15: 454.7 | I15: 100.6 | J15: 1705 | K15: 63.3
A17: Balance-sheet snapshot, 31 March 2026 (FY26 annual report note 3 / p.30)
A18: Cash and cash equivalents | B18: 149.7
A19: Loans and borrowings ex leases | B19: 1219.2
A20: Net borrowings ex leases | B20: 1069.5
A21: Lease liabilities (excluded from net debt; treatment B) | B21: 352.7
A22: Non-controlling interests | B22: 5.2
A23: Underlying EBITDA post-IFRS16 (p.30) | B23: 833
A24: Underlying EBITDA pre-IFRS16 (p.30) | B24: 715.7
A25: Underlying EBIT (p.30) | B25: 599
A26: Lease cash: principal 100.6 (financing) + interest 15.2 (operating); company 'ROU payments' | B26: 115.7
A27: Cash 'one-offs' excluded from underlying: FY26 70.6, FY25 70.9 | B27: 70.6
A28: Treasury shares bought to settle awards (inside OCF) | B28: 22.5
A29: Shares on issue 10-Jun-2026 (m) | B29: 507.54
... A33: Dividends paid FY26 | B33: 193.6
A34: FY27 guidance (18-May-2026): Commodities organic +13-15%; Life Sciences mid-single-digit; margin expansion similar to FY26 (+130-150bps); capex ~A$240m; net interest A$65-67m; cash conversion >90% of EBITDA

Sheet Assumptions
A1: Global assumptions (blue = input). Links from DCF tabs reference these cells.
A3: WACC (AUD-built, all scenarios) | B3: 0.09 | C3: rf ~4.4% + 5.5% ERP x beta ~1.0; Kd ~5% pre-tax; ~9% debt weight; risk otherwise in the flows
A4: D&A % of revenue (ex right-of-use) | B4: 0.042 | C4: underlying 131.9 (4.0%) / statutory 151.3 (4.6%) in FY26
A5: Lease cost % of revenue (principal + interest) | B5: 0.035 | C5: FY26 ROU payments 115.7 / 3,320.1; treatment B
A6: SBC % of revenue | B6: 0.003 | C6: FY26 9.6 / 3,320.1; flat
A7: Cash tax rate on positive EBIT | B7: 0.28 | C7: FY26 underlying ETR 28.0%; AU statutory 30%
A8: Terminal value cap (x FCF_10) | B8: 18 | C8: 18x: below the 20x compounder default for a blended cyclical
A9: Net debt for bridge (net borrowings 1,069.5 + NCI 5.2), 31-Mar-2026 | B9: 1074.7 | C9: lease liabilities 352.7 excluded (treatment B)
A10: Fully diluted shares (m), flat | B10: 510.5 | C10: 507.54 issued + 3.0 rights
A11: Current price A$ (2026-09-21T06:10:32Z, ASX close) | B11: 21.35 | C11: refresh before use
A12: FY2026 revenue (base year) | B12: 3320.1 | C12: underlying revenue
A13: Hurdle rate for entry price | B13: 0.15 | C13: 15% IRR
A15: Per-scenario | B15: Bear | C15: Base | D15: Bull
A16: Terminal growth | B16: 0.025 | C16: 0.03 | D16: 0.035
A17: Probability weight | B17: 0.25 | C17: 0.5 | D17: 0.25 | E17: =SUM(B17:D17) | F17: weights check: must equal 1.0
A18: WC capture % of revenue change (negative = growth consumes cash) | B18: -0.12 | C18: -0.12 | D18: -0.1
A20: Scenario narratives
A21: BEAR: Commodities down-cycle FY28-FY29: exploration budgets and junior-miner raisings fall, Minerals volumes and pricing compress (Commodities is 39% of revenue but ~64% of segment EBIT), Group revenue falls 6% in FY29 and margins trough at 21.5% (pre-IFRS16 ~17.7%). The May-2026 cyber incident costs clients and remediation spend, Americas Environmental (York) is never fixed, and the ~A$70m/yr of 'one-off' restructuring cash keeps recurring in full. Recovery to a 23.5% margin by FY32 (pre-IFRS16 ~19.7%, below FY26) and 3% growth; capex is cut to 5.2% once the hub program completes.
A22: BASE: FY27 tracks guidance (Commodities +13-15%, Life Sciences mid-single-digit, blended ~8%), then growth fades to 3% nominal AUD as the exploration up-cycle matures. Margin: FY27 25.8% pre-SBC post-IFRS16 (guided +130-150bps is offset by a ~0.8pp haircut for half of the recurring ~A$70m 'one-off' restructuring cash and Middle East/cyber costs), then mid-cycled to 25.0% (pre-IFRS16 owner ~21.2%, between FY25 20.3% and FY26 21.6%; FY19-FY22 ran 20-21%). Capex steps down from FY26's 7.9% to FY27 guidance ~A$240m (6.7%) and 5.5% once the A$230m hub program is done; working capital consumes 12% of incremental revenue (FY26: 18%, FY25: 6%).
A23: BULL: Critical-minerals exploration up-cycle runs multi-year (electrification, AI power demand), PFAS and emerging-contaminant testing compounds mid-teens, Nuvisan savings and automation/AI lab productivity deliver the guided margin expansion for four years to 28.0% (pre-IFRS16 ~24.2%, SGS/Bureau Veritas territory), Americas Environmental is fixed and bolt-on M&A funded from a 1.5x balance sheet keeps growth at high-single digits for five years. Terminal growth 3.5%; capex stays ~5.8% to fund it.

Sheet DCF_Bear
A1: BEAR scenario: owner-FCF component build, AUD millions. Drivers in blue on yellow (rows 5, 7, 9, 16, 19).
A3: Year | B3: FY2026A | C3: FY2027E | D3: FY2028E | E3: FY2029E | F3: FY2030E | G3: FY2031E | H3: FY2032E | I3: FY2033E | J3: FY2034E | K3: FY2035E | L3: FY2036E
A4: Index | B4: 0 | C4: 1 | D4: 2 | E4: 3 | F4: 4 | G4: 5 | H4: 6 | I4: 7 | J4: 8 | K4: 9 | L4: 10
A5: Revenue growth YoY | C5: 0.05 | D5: 0 | E5: -0.06 | F5: 0.02 | G5: 0.04 | H5: 0.04 | I5: 0.035 | J5: 0.03 | K5: 0.03 | L5: 0.03
A6: Revenue | B6: =Assumptions!$B$12 | C6: =B6*(1+C5) | D6: =C6*(1+D5) | E6: =D6*(1+E5) | F6: =E6*(1+F5) | G6: =F6*(1+G5) | H6: =G6*(1+H5) | I6: =H6*(1+I5) | J6: =I6*(1+J5) | ... L6: =K6*(1+L5)
A7: Adj EBITDA margin (post-IFRS16, pre-SBC) | B7: 0.254 | C7: 0.25 | D7: 0.235 | E7: 0.215 | F7: 0.22 | G7: 0.228 | H7: 0.232 | I7: 0.235 | J7: 0.235 | K7: 0.235 | L7: 0.235
A8: Adjusted EBITDA | B8: =B6*B7 | C8: =C6*C7 | D8: =D6*D7 | E8: =E6*E7 | F8: =F6*F7 | G8: =G6*G7 | H8: =H6*H7 | I8: =I6*I7 | ... L8: =L6*L7
A9: SBC % of revenue | C9: 0.003 | D9: 0.003 | E9: 0.003 | F9: 0.003 | G9: 0.003 | H9: 0.003 | I9: 0.003 | J9: 0.003 | K9: 0.003 | L9: 0.003
A10: SBC (negative) | C10: =-C6*C9 | D10: =-D6*D9 | E10: =-E6*E9 | F10: =-F6*F9 | G10: =-G6*G9 | H10: =-H6*H9 | I10: =-I6*I9 | J10: =-J6*J9 | ... L10: =-L6*L9
A11: Lease cost % of revenue | C11: =Assumptions!$B$5 | D11: =Assumptions!$B$5 | E11: =Assumptions!$B$5 | F11: =Assumptions!$B$5 | G11: =Assumptions!$B$5 | H11: =Assumptions!$B$5 | I11: =Assumptions!$B$5 | J11: =Assumptions!$B$5 | ... L11: =Assumptions!$B$5
A12: Lease cost (negative) | C12: =-C6*C11 | D12: =-D6*D11 | E12: =-E6*E11 | F12: =-F6*F11 | G12: =-G6*G11 | H12: =-H6*H11 | I12: =-I6*I11 | J12: =-J6*J11 | ... L12: =-L6*L11
A13: Owner EBITDA (post lease, post SBC) | C13: =C8+C10+C12 | D13: =D8+D10+D12 | E13: =E8+E10+E12 | F13: =F8+F10+F12 | G13: =G8+G10+G12 | H13: =H8+H10+H12 | I13: =I8+I10+I12 | J13: =J8+J10+J12 | ... L13: =L8+L10+L12
A14: D&A ex-ROU (negative) | C14: =-C6*Assumptions!$B$4 | D14: =-D6*Assumptions!$B$4 | E14: =-E6*Assumptions!$B$4 | F14: =-F6*Assumptions!$B$4 | G14: =-G6*Assumptions!$B$4 | H14: =-H6*Assumptions!$B$4 | I14: =-I6*Assumptions!$B$4 | J14: =-J6*Assumptions!$B$4 | ... L14: =-L6*Assumptions!$B$4
A15: EBIT | C15: =C13+C14 | D15: =D13+D14 | E15: =E13+E14 | F15: =F13+F14 | G15: =G13+G14 | H15: =H13+H14 | I15: =I13+I14 | J15: =J13+J14 | ... L15: =L13+L14
A16: Cash tax rate | C16: 0.28 | D16: 0.28 | E16: 0.28 | F16: 0.28 | G16: 0.28 | H16: 0.28 | I16: 0.28 | J16: 0.28 | K16: 0.28 | L16: 0.28
A17: NOPAT | C17: =C15-MAX(0,C15)*C16 | D17: =D15-MAX(0,D15)*D16 | E17: =E15-MAX(0,E15)*E16 | F17: =F15-MAX(0,F15)*F16 | G17: =G15-MAX(0,G15)*G16 | H17: =H15-MAX(0,H15)*H16 | I17: =I15-MAX(0,I15)*I16 | J17: =J15-MAX(0,J15)*J16 | ... L17: =L15-MAX(0,L15)*L16
A18: add back D&A | C18: =-C14 | D18: =-D14 | E18: =-E14 | F18: =-F14 | G18: =-G14 | H18: =-H14 | I18: =-I14 | J18: =-J14 | ... L18: =-L14
A19: Capex % of revenue | C19: 0.067 | D19: 0.065 | E19: 0.06 | F19: 0.055 | G19: 0.052 | H19: 0.052 | I19: 0.052 | J19: 0.052 | K19: 0.052 | L19: 0.052
A20: less capex | C20: =-C6*C19 | D20: =-D6*D19 | E20: =-E6*E19 | F20: =-F6*F19 | G20: =-G6*G19 | H20: =-H6*H19 | I20: =-I6*I19 | J20: =-J6*J19 | ... L20: =-L6*L19
A21: Working capital (on revenue change) | C21: =Assumptions!$B$18*(C6-B6) | D21: =Assumptions!$B$18*(D6-C6) | E21: =Assumptions!$B$18*(E6-D6) | F21: =Assumptions!$B$18*(F6-E6) | G21: =Assumptions!$B$18*(G6-F6) | H21: =Assumptions!$B$18*(H6-G6) | I21: =Assumptions!$B$18*(I6-H6) | J21: =Assumptions!$B$18*(J6-I6) | ... L21: =Assumptions!$B$18*(L6-K6)
A22: Unlevered owner FCF | C22: =C17+C18+C20+C21 | D22: =D17+D18+D20+D21 | E22: =E17+E18+E20+E21 | F22: =F17+F18+F20+F21 | G22: =G17+G18+G20+G21 | H22: =H17+H18+H20+H21 | I22: =I17+I18+I20+I21 | J22: =J17+J18+J20+J21 | ... L22: =L17+L18+L20+L21
A23: Discount factor | C23: =1/(1+Assumptions!$B$3)^C4 | D23: =1/(1+Assumptions!$B$3)^D4 | E23: =1/(1+Assumptions!$B$3)^E4 | F23: =1/(1+Assumptions!$B$3)^F4 | G23: =1/(1+Assumptions!$B$3)^G4 | H23: =1/(1+Assumptions!$B$3)^H4 | I23: =1/(1+Assumptions!$B$3)^I4 | J23: =1/(1+Assumptions!$B$3)^J4 | ... L23: =1/(1+Assumptions!$B$3)^L4
A24: PV of FCF | C24: =C22*C23 | D24: =D22*D23 | E24: =E22*E23 | F24: =F22*F23 | G24: =G22*G23 | H24: =H22*H23 | I24: =I22*I23 | J24: =J22*J23 | ... L24: =L22*L23
A26: Memo: FCF before SBC (company-style) | C26: =C22-C10 | D26: =D22-D10 | E26: =E22-E10 | F26: =F22-F10 | G26: =G22-G10 | H26: =H22-H10 | I26: =I22-I10 | J26: =J22-J10 | ... L26: =L22-L10
A27: Memo: owner-FCF margin | C27: =C22/C6 | D27: =D22/D6 | E27: =E22/E6 | F27: =F22/F6 | G27: =G22/G6 | H27: =H22/H6 | I27: =I22/I6 | J27: =J22/J6 | ... L27: =L22/L6
A29: Sum of PV of FCF | B29: =SUM(C24:L24)
A30: Terminal growth | B30: =Assumptions!$B$16
A31: Terminal-year FCF x (1+g) | B31: =L22*(1+B30)
A32: Gordon terminal value | B32: =IF(Assumptions!$B$3>B30,B31/(Assumptions!$B$3-B30),0)
A33: Cap terminal value (cap x FCF_10) | B33: =Assumptions!$B$8*L22
A34: Terminal value used = MAX(0, MIN(Gordon, cap)) | B34: =MAX(0,MIN(B32,B33))
A35: Implied exit multiple (TV / FCF_10) | B35: =IF(L22<>0,B34/L22,0)
A36: PV of terminal value | B36: =B34*L23
A37: Enterprise value | B37: =B29+B36
A38: less net debt (incl. NCI) | B38: =-Assumptions!$B$9
A39: Equity value | B39: =B37+B38
A40: Diluted shares (m) | B40: =Assumptions!$B$10
A41: VALUE PER SHARE (A$) | B41: =B39/B40
A42: Upside vs price | B42: =B41/Assumptions!$B$11-1
A44: Street memo: PV of explicit SBC | B44: =SUMPRODUCT(-C10:L10/(1+Assumptions!$B$3)^C4:L4)
...

Sheet DCF_Base
A1: BASE scenario: owner-FCF component build, AUD millions. Drivers in blue on yellow (rows 5, 7, 9, 16, 19).
A3: Year | B3: FY2026A | C3: FY2027E | D3: FY2028E | E3: FY2029E | F3: FY2030E | G3: FY2031E | H3: FY2032E | I3: FY2033E | J3: FY2034E | K3: FY2035E | L3: FY2036E
A4: Index | B4: 0 | C4: 1 | D4: 2 | E4: 3 | F4: 4 | G4: 5 | H4: 6 | I4: 7 | J4: 8 | K4: 9 | L4: 10
A5: Revenue growth YoY | C5: 0.08 | D5: 0.06 | E5: 0.05 | F5: 0.045 | G5: 0.04 | H5: 0.035 | I5: 0.035 | J5: 0.03 | K5: 0.03 | L5: 0.03
A6: Revenue | B6: =Assumptions!$B$12 | C6: =B6*(1+C5) | D6: =C6*(1+D5) | E6: =D6*(1+E5) | F6: =E6*(1+F5) | G6: =F6*(1+G5) | H6: =G6*(1+H5) | I6: =H6*(1+I5) | J6: =I6*(1+J5) | ... L6: =K6*(1+L5)
A7: Adj EBITDA margin (post-IFRS16, pre-SBC) | B7: 0.254 | C7: 0.258 | D7: 0.258 | E7: 0.255 | F7: 0.252 | G7: 0.25 | H7: 0.25 | I7: 0.25 | J7: 0.25 | K7: 0.25 | L7: 0.25
A8: Adjusted EBITDA | B8: =B6*B7 | C8: =C6*C7 | D8: =D6*D7 | E8: =E6*E7 | F8: =F6*F7 | G8: =G6*G7 | H8: =H6*H7 | I8: =I6*I7 | ... L8: =L6*L7
A9: SBC % of revenue | C9: 0.003 | D9: 0.003 | E9: 0.003 | F9: 0.003 | G9: 0.003 | H9: 0.003 | I9: 0.003 | J9: 0.003 | K9: 0.003 | L9: 0.003
A10: SBC (negative) | C10: =-C6*C9 | D10: =-D6*D9 | E10: =-E6*E9 | F10: =-F6*F9 | G10: =-G6*G9 | H10: =-H6*H9 | I10: =-I6*I9 | J10: =-J6*J9 | ... L10: =-L6*L9
A11: Lease cost % of revenue | C11: =Assumptions!$B$5 | D11: =Assumptions!$B$5 | E11: =Assumptions!$B$5 | F11: =Assumptions!$B$5 | G11: =Assumptions!$B$5 | H11: =Assumptions!$B$5 | I11: =Assumptions!$B$5 | J11: =Assumptions!$B$5 | ... L11: =Assumptions!$B$5
A12: Lease cost (negative) | C12: =-C6*C11 | D12: =-D6*D11 | E12: =-E6*E11 | F12: =-F6*F11 | G12: =-G6*G11 | H12: =-H6*H11 | I12: =-I6*I11 | J12: =-J6*J11 | ... L12: =-L6*L11
A13: Owner EBITDA (post lease, post SBC) | C13: =C8+C10+C12 | D13: =D8+D10+D12 | E13: =E8+E10+E12 | F13: =F8+F10+F12 | G13: =G8+G10+G12 | H13: =H8+H10+H12 | I13: =I8+I10+I12 | J13: =J8+J10+J12 | ... L13: =L8+L10+L12
A14: D&A ex-ROU (negative) | C14: =-C6*Assumptions!$B$4 | D14: =-D6*Assumptions!$B$4 | E14: =-E6*Assumptions!$B$4 | F14: =-F6*Assumptions!$B$4 | G14: =-G6*Assumptions!$B$4 | H14: =-H6*Assumptions!$B$4 | I14: =-I6*Assumptions!$B$4 | J14: =-J6*Assumptions!$B$4 | ... L14: =-L6*Assumptions!$B$4
A15: EBIT | C15: =C13+C14 | D15: =D13+D14 | E15: =E13+E14 | F15: =F13+F14 | G15: =G13+G14 | H15: =H13+H14 | I15: =I13+I14 | J15: =J13+J14 | ... L15: =L13+L14
A16: Cash tax rate | C16: 0.28 | D16: 0.28 | E16: 0.28 | F16: 0.28 | G16: 0.28 | H16: 0.28 | I16: 0.28 | J16: 0.28 | K16: 0.28 | L16: 0.28
A17: NOPAT | C17: =C15-MAX(0,C15)*C16 | D17: =D15-MAX(0,D15)*D16 | E17: =E15-MAX(0,E15)*E16 | F17: =F15-MAX(0,F15)*F16 | G17: =G15-MAX(0,G15)*G16 | H17: =H15-MAX(0,H15)*H16 | I17: =I15-MAX(0,I15)*I16 | J17: =J15-MAX(0,J15)*J16 | ... L17: =L15-MAX(0,L15)*L16
A18: add back D&A | C18: =-C14 | D18: =-D14 | E18: =-E14 | F18: =-F14 | G18: =-G14 | H18: =-H14 | I18: =-I14 | J18: =-J14 | ... L18: =-L14
A19: Capex % of revenue | C19: 0.067 | D19: 0.063 | E19: 0.06 | F19: 0.058 | G19: 0.055 | H19: 0.055 | I19: 0.055 | J19: 0.055 | K19: 0.055 | L19: 0.055
A20: less capex | C20: =-C6*C19 | D20: =-D6*D19 | E20: =-E6*E19 | F20: =-F6*F19 | G20: =-G6*G19 | H20: =-H6*H19 | I20: =-I6*I19 | J20: =-J6*J19 | ... L20: =-L6*L19
A21: Working capital (on revenue change) | C21: =Assumptions!$C$18*(C6-B6) | D21: =Assumptions!$C$18*(D6-C6) | E21: =Assumptions!$C$18*(E6-D6) | F21: =Assumptions!$C$18*(F6-E6) | G21: =Assumptions!$C$18*(G6-F6) | H21: =Assumptions!$C$18*(H6-G6) | I21: =Assumptions!$C$18*(I6-H6) | J21: =Assumptions!$C$18*(J6-I6) | ... L21: =Assumptions!$C$18*(L6-K6)
A22: Unlevered owner FCF | C22: =C17+C18+C20+C21 | D22: =D17+D18+D20+D21 | E22: =E17+E18+E20+E21 | F22: =F17+F18+F20+F21 | G22: =G17+G18+G20+G21 | H22: =H17+H18+H20+H21 | I22: =I17+I18+I20+I21 | J22: =J17+J18+J20+J21 | ... L22: =L17+L18+L20+L21
A23: Discount factor | C23: =1/(1+Assumptions!$B$3)^C4 | D23: =1/(1+Assumptions!$B$3)^D4 | E23: =1/(1+Assumptions!$B$3)^E4 | F23: =1/(1+Assumptions!$B$3)^F4 | G23: =1/(1+Assumptions!$B$3)^G4 | H23: =1/(1+Assumptions!$B$3)^H4 | I23: =1/(1+Assumptions!$B$3)^I4 | J23: =1/(1+Assumptions!$B$3)^J4 | ... L23: =1/(1+Assumptions!$B$3)^L4
A24: PV of FCF | C24: =C22*C23 | D24: =D22*D23 | E24: =E22*E23 | F24: =F22*F23 | G24: =G22*G23 | H24: =H22*H23 | I24: =I22*I23 | J24: =J22*J23 | ... L24: =L22*L23
A26: Memo: FCF before SBC (company-style) | C26: =C22-C10 | D26: =D22-D10 | E26: =E22-E10 | F26: =F22-F10 | G26: =G22-G10 | H26: =H22-H10 | I26: =I22-I10 | J26: =J22-J10 | ... L26: =L22-L10
A27: Memo: owner-FCF margin | C27: =C22/C6 | D27: =D22/D6 | E27: =E22/E6 | F27: =F22/F6 | G27: =G22/G6 | H27: =H22/H6 | I27: =I22/I6 | J27: =J22/J6 | ... L27: =L22/L6
A29: Sum of PV of FCF | B29: =SUM(C24:L24)
A30: Terminal growth | B30: =Assumptions!$C$16
A31: Terminal-year FCF x (1+g) | B31: =L22*(1+B30)
A32: Gordon terminal value | B32: =IF(Assumptions!$B$3>B30,B31/(Assumptions!$B$3-B30),0)
A33: Cap terminal value (cap x FCF_10) | B33: =Assumptions!$B$8*L22
A34: Terminal value used = MAX(0, MIN(Gordon, cap)) | B34: =MAX(0,MIN(B32,B33))
A35: Implied exit multiple (TV / FCF_10) | B35: =IF(L22<>0,B34/L22,0)
A36: PV of terminal value | B36: =B34*L23
A37: Enterprise value | B37: =B29+B36
A38: less net debt (incl. NCI) | B38: =-Assumptions!$B$9
A39: Equity value | B39: =B37+B38
A40: Diluted shares (m) | B40: =Assumptions!$B$10
A41: VALUE PER SHARE (A$) | B41: =B39/B40
A42: Upside vs price | B42: =B41/Assumptions!$B$11-1
A44: Street memo: PV of explicit SBC | B44: =SUMPRODUCT(-C10:L10/(1+Assumptions!$B$3)^C4:L4)
...

Sheet DCF_Bull
A1: BULL scenario: owner-FCF component build, AUD millions. Drivers in blue on yellow (rows 5, 7, 9, 16, 19).
A3: Year | B3: FY2026A | C3: FY2027E | D3: FY2028E | E3: FY2029E | F3: FY2030E | G3: FY2031E | H3: FY2032E | I3: FY2033E | J3: FY2034E | K3: FY2035E | L3: FY2036E
A4: Index | B4: 0 | C4: 1 | D4: 2 | E4: 3 | F4: 4 | G4: 5 | H4: 6 | I4: 7 | J4: 8 | K4: 9 | L4: 10
A5: Revenue growth YoY | C5: 0.1 | D5: 0.09 | E5: 0.08 | F5: 0.07 | G5: 0.06 | H5: 0.05 | I5: 0.045 | J5: 0.04 | K5: 0.035 | L5: 0.035
A6: Revenue | B6: =Assumptions!$B$12 | C6: =B6*(1+C5) | D6: =C6*(1+D5) | E6: =D6*(1+E5) | F6: =E6*(1+F5) | G6: =F6*(1+G5) | H6: =G6*(1+H5) | I6: =H6*(1+I5) | J6: =I6*(1+J5) | ... L6: =K6*(1+L5)
A7: Adj EBITDA margin (post-IFRS16, pre-SBC) | B7: 0.254 | C7: 0.266 | D7: 0.272 | E7: 0.276 | F7: 0.28 | G7: 0.28 | H7: 0.28 | I7: 0.28 | J7: 0.28 | K7: 0.28 | L7: 0.28
A8: Adjusted EBITDA | B8: =B6*B7 | C8: =C6*C7 | D8: =D6*D7 | E8: =E6*E7 | F8: =F6*F7 | G8: =G6*G7 | H8: =H6*H7 | I8: =I6*I7 | ... L8: =L6*L7
A9: SBC % of revenue | C9: 0.003 | D9: 0.003 | E9: 0.003 | F9: 0.003 | G9: 0.003 | H9: 0.003 | I9: 0.003 | J9: 0.003 | K9: 0.003 | L9: 0.003
A10: SBC (negative) | C10: =-C6*C9 | D10: =-D6*D9 | E10: =-E6*E9 | F10: =-F6*F9 | G10: =-G6*G9 | H10: =-H6*H9 | I10: =-I6*I9 | J10: =-J6*J9 | ... L10: =-L6*L9
A11: Lease cost % of revenue | C11: =Assumptions!$B$5 | D11: =Assumptions!$B$5 | E11: =Assumptions!$B$5 | F11: =Assumptions!$B$5 | G11: =Assumptions!$B$5 | H11: =Assumptions!$B$5 | I11: =Assumptions!$B$5 | J11: =Assumptions!$B$5 | ... L11: =Assumptions!$B$5
A12: Lease cost (negative) | C12: =-C6*C11 | D12: =-D6*D11 | E12: =-E6*E11 | F12: =-F6*F11 | G12: =-G6*G11 | H12: =-H6*H11 | I12: =-I6*I11 | J12: =-J6*J11 | ... L12: =-L6*L11
A13: Owner EBITDA (post lease, post SBC) | C13: =C8+C10+C12 | D13: =D8+D10+D12 | E13: =E8+E10+E12 | F13: =F8+F10+F12 | G13: =G8+G10+G12 | H13: =H8+H10+H12 | I13: =I8+I10+I12 | J13: =J8+J10+J12 | ... L13: =L8+L10+L12
A14: D&A ex-ROU (negative) | C14: =-C6*Assumptions!$B$4 | D14: =-D6*Assumptions!$B$4 | E14: =-E6*Assumptions!$B$4 | F14: =-F6*Assumptions!$B$4 | G14: =-G6*Assumptions!$B$4 | H14: =-H6*Assumptions!$B$4 | I14: =-I6*Assumptions!$B$4 | J14: =-J6*Assumptions!$B$4 | ... L14: =-L6*Assumptions!$B$4
A15: EBIT | C15: =C13+C14 | D15: =D13+D14 | E15: =E13+E14 | F15: =F13+F14 | G15: =G13+G14 | H15: =H13+H14 | I15: =I13+I14 | J15: =J13+J14 | ... L15: =L13+L14
A16: Cash tax rate | C16: 0.28 | D16: 0.28 | E16: 0.28 | F16: 0.28 | G16: 0.28 | H16: 0.28 | I16: 0.28 | J16: 0.28 | K16: 0.28 | L16: 0.28
A17: NOPAT | C17: =C15-MAX(0,C15)*C16 | D17: =D15-MAX(0,D15)*D16 | E17: =E15-MAX(0,E15)*E16 | F17: =F15-MAX(0,F15)*F16 | G17: =G15-MAX(0,G15)*G16 | H17: =H15-MAX(0,H15)*H16 | I17: =I15-MAX(0,I15)*I16 | J17: =J15-MAX(0,J15)*J16 | ... L17: =L15-MAX(0,L15)*L16
A18: add back D&A | C18: =-C14 | D18: =-D14 | E18: =-E14 | F18: =-F14 | G18: =-G14 | H18: =-H14 | I18: =-I14 | J18: =-J14 | ... L18: =-L14
A19: Capex % of revenue | C19: 0.067 | D19: 0.065 | E19: 0.063 | F19: 0.06 | G19: 0.06 | H19: 0.058 | I19: 0.058 | J19: 0.058 | K19: 0.058 | L19: 0.058
A20: less capex | C20: =-C6*C19 | D20: =-D6*D19 | E20: =-E6*E19 | F20: =-F6*F19 | G20: =-G6*G19 | H20: =-H6*H19 | I20: =-I6*I19 | J20: =-J6*J19 | ... L20: =-L6*L19
A21: Working capital (on revenue change) | C21: =Assumptions!$D$18*(C6-B6) | D21: =Assumptions!$D$18*(D6-C6) | E21: =Assumptions!$D$18*(E6-D6) | F21: =Assumptions!$D$18*(F6-E6) | G21: =Assumptions!$D$18*(G6-F6) | H21: =Assumptions!$D$18*(H6-G6) | I21: =Assumptions!$D$18*(I6-H6) | J21: =Assumptions!$D$18*(J6-I6) | ... L21: =Assumptions!$D$18*(L6-K6)
A22: Unlevered owner FCF | C22: =C17+C18+C20+C21 | D22: =D17+D18+D20+D21 | E22: =E17+E18+E20+E21 | F22: =F17+F18+F20+F21 | G22: =G17+G18+G20+G21 | H22: =H17+H18+H20+H21 | I22: =I17+I18+I20+I21 | J22: =J17+J18+J20+J21 | ... L22: =L17+L18+L20+L21
A23: Discount factor | C23: =1/(1+Assumptions!$B$3)^C4 | D23: =1/(1+Assumptions!$B$3)^D4 | E23: =1/(1+Assumptions!$B$3)^E4 | F23: =1/(1+Assumptions!$B$3)^F4 | G23: =1/(1+Assumptions!$B$3)^G4 | H23: =1/(1+Assumptions!$B$3)^H4 | I23: =1/(1+Assumptions!$B$3)^I4 | J23: =1/(1+Assumptions!$B$3)^J4 | ... L23: =1/(1+Assumptions!$B$3)^L4
A24: PV of FCF | C24: =C22*C23 | D24: =D22*D23 | E24: =E22*E23 | F24: =F22*F23 | G24: =G22*G23 | H24: =H22*H23 | I24: =I22*I23 | J24: =J22*J23 | ... L24: =L22*L23
A26: Memo: FCF before SBC (company-style) | C26: =C22-C10 | D26: =D22-D10 | E26: =E22-E10 | F26: =F22-F10 | G26: =G22-G10 | H26: =H22-H10 | I26: =I22-I10 | J26: =J22-J10 | ... L26: =L22-L10
A27: Memo: owner-FCF margin | C27: =C22/C6 | D27: =D22/D6 | E27: =E22/E6 | F27: =F22/F6 | G27: =G22/G6 | H27: =H22/H6 | I27: =I22/I6 | J27: =J22/J6 | ... L27: =L22/L6
A29: Sum of PV of FCF | B29: =SUM(C24:L24)
A30: Terminal growth | B30: =Assumptions!$D$16
A31: Terminal-year FCF x (1+g) | B31: =L22*(1+B30)
A32: Gordon terminal value | B32: =IF(Assumptions!$B$3>B30,B31/(Assumptions!$B$3-B30),0)
A33: Cap terminal value (cap x FCF_10) | B33: =Assumptions!$B$8*L22
A34: Terminal value used = MAX(0, MIN(Gordon, cap)) | B34: =MAX(0,MIN(B32,B33))
A35: Implied exit multiple (TV / FCF_10) | B35: =IF(L22<>0,B34/L22,0)
A36: PV of terminal value | B36: =B34*L23
A37: Enterprise value | B37: =B29+B36
A38: less net debt (incl. NCI) | B38: =-Assumptions!$B$9
A39: Equity value | B39: =B37+B38
A40: Diluted shares (m) | B40: =Assumptions!$B$10
A41: VALUE PER SHARE (A$) | B41: =B39/B40
A42: Upside vs price | B42: =B41/Assumptions!$B$11-1
A44: Street memo: PV of explicit SBC | B44: =SUMPRODUCT(-C10:L10/(1+Assumptions!$B$3)^C4:L4)
...

Sheet FCF_Quality
A1: Reported FCF reconciled to owner FCF (AUD m). Interest income NOT stripped (net-debt company). Lease principal shown as memo: it sits in financing, so reported FCF is flattered by it.
A3: Period | B3: Revenue | C3: Reported FCF | D3: less SBC | E3: less interest income (0) | F3: Owner FCF | G3: Reported FCF margin | H3: Owner FCF margin | I3: Memo: lease principal (financing) | J3: Memo: FCF after lease principal | K3: Memo: taxes paid | L3: Memo: PBT | M3: Memo: cash tax rate | N3: Flag
A4: FY2015 | B4: 1422.2 | C4: 138.7 | D4: -0.6 | E4: 0 | F4: =C4+D4+E4 | G4: =C4/B4 | H4: =F4/B4 | I4: 0 | J4: =F4-I4 | K4: 48 | L4: -120.2 | M4: =IF(L4>0,K4/L4,"n/a") | N4: loss year (impairments); cash tax rate n/a
A5: FY2016 | B5: 1364.9 | C5: 95.9 | D5: -1.4 | E5: 0 | F5: =C5+D5+E5 | G5: =C5/B5 | H5: =F5/B5 | I5: 0 | J5: =F5-I5 | K5: 39 | L5: -203.6 | M5: =IF(L5>0,K5/L5,"n/a") | N5: loss year (impairments); cash tax rate n/a
A6: FY2017 | B6: 1261.5 | C6: 116.6 | D6: -2 | E6: 0 | F6: =C6+D6+E6 | G6: =C6/B6 | H6: =F6/B6 | I6: 0 | J6: =F6-I6 | K6: 41 | L6: 146.1 | M6: =IF(L6>0,K6/L6,"n/a")
A7: FY2018 | B7: 1446.9 | C7: 112.4 | D7: 0 | E7: 0 | F7: =C7+D7+E7 | G7: =C7/B7 | H7: =F7/B7 | I7: 0 | J7: =F7-I7 | K7: 47.3 | L7: 115.4 | M7: =IF(L7>0,K7/L7,"n/a") | N7: SBC not in corpus (FY2019 file duplicates FY2018)
A8: FY2019 | B8: 1664.8 | C8: 109.9 | D8: -3.6 | E8: 0 | F8: =C8+D8+E8 | G8: =C8/B8 | H8: =F8/B8 | I8: 0 | J8: =F8-I8 | K8: 50.3 | L8: 230.3 | M8: =IF(L8>0,K8/L8,"n/a")
A9: FY2020 | B9: 1831.9 | C9: 137.9 | D9: -5.7 | E9: 0 | F9: =C9+D9+E9 | G9: =C9/B9 | H9: =F9/B9 | I9: 43 | J9: =F9-I9 | K9: 96 | L9: 151.1 | M9: =IF(L9>0,K9/L9,"n/a")
A10: FY2021 | B10: 1761.4 | C10: 188.9 | D10: -4.6 | E10: 0 | F10: =C10+D10+E10 | G10: =C10/B10 | H10: =F10/B10 | I10: 42.9 | J10: =F10-I10 | K10: 67.9 | L10: 248.5 | M10: =IF(L10>0,K10/L10,"n/a")
A11: FY2022 | B11: 1951.8 | C11: 167.9 | D11: -5.3 | E11: 0 | F11: =C11+D11+E11 | G11: =C11/B11 | H11: =F11/B11 | I11: 45.2 | J11: =F11-I11 | K11: 106.1 | L11: 280 | M11: =IF(L11>0,K11/L11,"n/a")
A12: FY2023 | B12: 2279.2 | C12: 293.8 | D12: -7.9 | E12: 0 | F12: =C12+D12+E12 | G12: =C12/B12 | H12: =F12/B12 | I12: 52.9 | J12: =F12-I12 | K12: 89.9 | L12: 390.7 | M12: =IF(L12>0,K12/L12,"n/a")
A13: FY2024 | B13: 2461.6 | C13: 198.4 | D13: -7 | E13: 0 | F13: =C13+D13+E13 | G13: =C13/B13 | H13: =F13/B13 | I13: 61 | J13: =F13-I13 | K13: 127.9 | L13: 121.3 | M13: =IF(L13>0,K13/L13,"n/a") | N13: PBT hit by Nuvisan impairment; cash tax 105% of PBT
A14: FY2025 | B14: 2999.4 | C14: 244.6 | D14: -10.4 | E14: 0 | F14: =C14+D14+E14 | G14: =C14/B14 | H14: =F14/B14 | I14: 89.6 | J14: =F14-I14 | K14: 119.4 | L14: 362.7 | M14: =IF(L14>0,K14/L14,"n/a")
A15: FY2026 | B15: 3320.1 | C15: 222.7 | D15: -9.6 | E15: 0 | F15: =C15+D15+E15 | G15: =C15/B15 | H15: =F15/B15 | I15: 100.6 | J15: =F15-I15 | K15: 137.5 | L15: 454.7 | M15: =IF(L15>0,K15/L15,"n/a") | N15: capex peak 7.9% of revenue (hub labs); OCF already bears 22.5 treasury-share purchases and ~70.6 'one-off' cash

Sheet Valuation
A1: Valuation summary (all per-share figures A$; live links to the DCF tabs)
A3: Scenario | B3: Value per share | C3: Upside vs price | D3: Probability | E3: Street value per share | F3: TV % of EV | G3: Exit multiple
A4: Bear | B4: =DCF_Bear!$B$41 | C4: =B4/Assumptions!$B$11-1 | D4: =Assumptions!$B$17 | E4: =DCF_Bear!$B$46 | F4: =DCF_Bear!$B$47 | G4: =DCF_Bear!$B$35
A5: Base | B5: =DCF_Base!$B$41 | C5: =B5/Assumptions!$B$11-1 | D5: =Assumptions!$C$17 | E5: =DCF_Base!$B$46 | F5: =DCF_Base!$B$47 | G5: =DCF_Base!$B$35
A6: Bull | B6: =DCF_Bull!$B$41 | C6: =B6/Assumptions!$B$11-1 | D6: =Assumptions!$D$17 | E6: =DCF_Bull!$B$46 | F6: =DCF_Bull!$B$47 | G6: =DCF_Bull!$B$35
A8: Probability-weighted value per share (house) | B8: =SUMPRODUCT(B4:B6,D4:D6)
A9: Current price | B9: =Assumptions!$B$11
A10: Margin of safety (1 - price/weighted) | B10: =1-B9/B8
A11: Probability-weighted value per share (street) | B11: =SUMPRODUCT(E4:E6,D4:D6)
A12: Band position (price - house)/(street - house); n/a: band ~A$0.4 wide, SBC 0.3% of revenue | B12: =IF(ABS(B11-B8)<0.05*B8,"n/a",(B9-B8)/(B11-B8))
A14: 15%-hurdle entry prices (TV built at the hurdle rate)
A15: Scenario | B15: Entry price | C15: Discount from current | D15: Probability
A16: Bear | B16: =(SUMPRODUCT(DCF_Bear!$C$22:$L$22/(1+Assumptions!$B$13)^DCF_Bear!$C$4:$L$4)+MAX(0,MIN(IF(Assumptions!$B$13>Assumptions!$B$16,DCF_Bear!$L$22*(1+Assumptions!$B$16)/(Assumptions!$B$13-Assumptions!$B$16),0),Assumptions!$B$8*DCF_Bear!$L$22))/(1+Assumptions!$B$13)^10-Assumptions!$B$9)/Assumptions!$B$10 | C16: =B16/Assumptions!$B$11-1 | D16: =Assumptions!$B$17
A17: Base | B17: =(SUMPRODUCT(DCF_Base!$C$22:$L$22/(1+Assumptions!$B$13)^DCF_Base!$C$4:$L$4)+MAX(0,MIN(IF(Assumptions!$B$13>Assumptions!$C$16,DCF_Base!$L$22*(1+Assumptions!$C$16)/(Assumptions!$B$13-Assumptions!$C$16),0),Assumptions!$B$8*DCF_Base!$L$22))/(1+Assumptions!$B$13)^10-Assumptions!$B$9)/Assumptions!$B$10 | C17: =B17/Assumptions!$B$11-1 | D17: =Assumptions!$C$17
A18: Bull | B18: =(SUMPRODUCT(DCF_Bull!$C$22:$L$22/(1+Assumptions!$B$13)^DCF_Bull!$C$4:$L$4)+MAX(0,MIN(IF(Assumptions!$B$13>Assumptions!$D$16,DCF_Bull!$L$22*(1+Assumptions!$D$16)/(Assumptions!$B$13-Assumptions!$D$16),0),Assumptions!$B$8*DCF_Bull!$L$22))/(1+Assumptions!$B$13)^10-Assumptions!$B$9)/Assumptions!$B$10 | C18: =B18/Assumptions!$B$11-1 | D18: =Assumptions!$D$17
A19: Probability-weighted entry price (buy-below) | B19: =SUMPRODUCT(B16:B18,D16:D18)
A21: Required-return table, base case (TV rebuilt at each rate; WACC row must equal DCF_Base!B41, 15% row must equal the base entry price)
A22: Required return | B22: 0.09 | C22: 0.1 | D22: 0.11 | E22: 0.12 | F22: 0.15 | G22: =Assumptions!$B$3
A23: Base value per share | B23: =(SUMPRODUCT(DCF_Base!$C$22:$L$22/(1+B$22)^DCF_Base!$C$4:$L$4)+MAX(0,MIN(IF(B$22>Assumptions!$C$16,DCF_Base!$L$22*(1+Assumptions!$C$16)/(B$22-Assumptions!$C$16),0),Assumptions!$B$8*DCF_Base!$L$22))/(1+B$22)^10-Assumptions!$B$9)/Assumptions!$B$10 | C23: =(SUMPRODUCT(DCF_Base!$C$22:$L$22/(1+C$22)^DCF_Base!$C$4:$L$4)+MAX(0,MIN(IF(C$22>Assumptions!$C$16,DCF_Base!$L$22*(1+Assumptions!$C$16)/(C$22-Assumptions!$C$16),0),Assumptions!$B$8*DCF_Base!$L$22))/(1+C$22)^10-Assumptions!$B$9)/Assumptions!$B$10 | D23: =(SUMPRODUCT(DCF_Base!$C$22:$L$22/(1+D$22)^DCF_Base!$C$4:$L$4)+MAX(0,MIN(IF(D$22>Assumptions!$C$16,DCF_Base!$L$22*(1+Assumptions!$C$16)/(D$22-Assumptions!$C$16),0),Assumptions!$B$8*DCF_Base!$L$22))/(1+D$22)^10-Assumptions!$B$9)/Assumptions!$B$10 | E23: =(SUMPRODUCT(DCF_Base!$C$22:$L$22/(1+E$22)^DCF_Base!$C$4:$L$4)+MAX(0,MIN(IF(E$22>Assumptions!$C$16,DCF_Base!$L$22*(1+Assumptions!$C$16)/(E$22-Assumptions!$C$16),0),Assumptions!$B$8*DCF_Base!$L$22))/(1+E$22)^10-Assumptions!$B$9)/Assumptions!$B$10 | F23: =(SUMPRODUCT(DCF_Base!$C$22:$L$22/(1+F$22)^DCF_Base!$C$4:$L$4)+MAX(0,MIN(IF(F$22>Assumptions!$C$16,DCF_Base!$L$22*(1+Assumptions!$C$16)/(F$22-Assumptions!$C$16),0),Assumptions!$B$8*DCF_Base!$L$22))/(1+F$22)^10-Assumptions!$B$9)/Assumptions!$B$10 | G23: =(SUMPRODUCT(DCF_Base!$C$22:$L$22/(1+G$22)^DCF_Base!$C$4:$L$4)+MAX(0,MIN(IF(G$22>Assumptions!$C$16,DCF_Base!$L$22*(1+Assumptions!$C$16)/(G$22-Assumptions!$C$16),0),Assumptions!$B$8*DCF_Base!$L$22))/(1+G$22)^10-Assumptions!$B$9)/Assumptions!$B$10
A25: Sensitivity: base value per share, WACC (rows) x terminal growth (columns); TV re-capped in every cell
B26: 0.02 | C26: 0.025 | D26: 0.03 | E26: 0.035 | F26: 0.04
A27: 0.07 | B27: =IF($A27>B$26,(SUMPRODUCT(DCF_Base!$C$22:$L$22/(1+$A27)^DCF_Base!$C$4:$L$4)+MAX(0,MIN(IF($A27>B$26,DCF_Base!$L$22*(1+B$26)/($A27-B$26),0),Assumptions!$B$8*DCF_Base!$L$22))/(1+$A27)^10-Assumptions!$B$9)/Assumptions!$B$10,"n/a") | C27: =IF($A27>C$26,(SUMPRODUCT(DCF_Base!$C$22:$L$22/(1+$A27)^DCF_Base!$C$4:$L$4)+MAX(0,MIN(IF($A27>C$26,DCF_Base!$L$22*(1+C$26)/($A27-C$26),0),Assumptions!$B$8*DCF_Base!$L$22))/(1+$A27)^10-Assumptions!$B$9)/Assumptions!$B$10,"n/a") | D27: =IF($A27>D$26,(SUMPRODUCT(DCF_Base!$C$22:$L$22/(1+$A27)^DCF_Base!$C$4:$L$4)+MAX(0,MIN(IF($A27>D$26,DCF_Base!$L$22*(1+D$26)/($A27-D$26),0),Assumptions!$B$8*DCF_Base!$L$22))/(1+$A27)^10-Assumptions!$B$9)/Assumptions!$B$10,"n/a") | E27: =IF($A27>E$26,(SUMPRODUCT(DCF_Base!$C$22:$L$22/(1+$A27)^DCF_Base!$C$4:$L$4)+MAX(0,MIN(IF($A27>E$26,DCF_Base!$L$22*(1+E$26)/($A27-E$26),0),Assumptions!$B$8*DCF_Base!$L$22))/(1+$A27)^10-Assumptions!$B$9)/Assumptions!$B$10,"n/a") | F27: =IF($A27>F$26,(SUMPRODUCT(DCF_Base!$C$22:$L$22/(1+$A27)^DCF_Base!$C$4:$L$4)+MAX(0,MIN(IF($A27>F$26,DCF_Base!$L$22*(1+F$26)/($A27-F$26),0),Assumptions!$B$8*DCF_Base!$L$22))/(1+$A27)^10-Assumptions!$B$9)/Assumptions!$B$10,"n/a")
A28: 0.08 | B28: =IF($A28>B$26,(SUMPRODUCT(DCF_Base!$C$22:$L$22/(1+$A28)^DCF_Base!$C$4:$L$4)+MAX(0,MIN(IF($A28>B$26,DCF_Base!$L$22*(1+B$26)/($A28-B$26),0),Assumptions!$B$8*DCF_Base!$L$22))/(1+$A28)^10-Assumptions!$B$9)/Assumptions!$B$10,"n/a") | C28: =IF($A28>C$26,(SUMPRODUCT(DCF_Base!$C$22:$L$22/(1+$A28)^DCF_Base!$C$4:$L$4)+MAX(0,MIN(IF($A28>C$26,DCF_Base!$L$22*(1+C$26)/($A28-C$26),0),Assumptions!$B$8*DCF_Base!$L$22))/(1+$A28)^10-Assumptions!$B$9)/Assumptions!$B$10,"n/a") | D28: =IF($A28>D$26,(SUMPRODUCT(DCF_Base!$C$22:$L$22/(1+$A28)^DCF_Base!$C$4:$L$4)+MAX(0,MIN(IF($A28>D$26,DCF_Base!$L$22*(1+D$26)/($A28-D$26),0),Assumptions!$B$8*DCF_Base!$L$22))/(1+$A28)^10-Assumptions!$B$9)/Assumptions!$B$10,"n/a") | E28: =IF($A28>E$26,(SUMPRODUCT(DCF_Base!$C$22:$L$22/(1+$A28)^DCF_Base!$C$4:$L$4)+MAX(0,MIN(IF($A28>E$26,DCF_Base!$L$22*(1+E$26)/($A28-E$26),0),Assumptions!$B$8*DCF_Base!$L$22))/(1+$A28)^10-Assumptions!$B$9)/Assumptions!$B$10,"n/a") | F28: =IF($A28>F$26,(SUMPRODUCT(DCF_Base!$C$22:$L$22/(1+$A28)^DCF_Base!$C$4:$L$4)+MAX(0,MIN(IF($A28>F$26,DCF_Base!$L$22*(1+F$26)/($A28-F$26),0),Assumptions!$B$8*DCF_Base!$L$22))/(1+$A28)^10-Assumptions!$B$9)/Assumptions!$B$10,"n/a")
A29: 0.09 | B29: =IF($A29>B$26,(SUMPRODUCT(DCF_Base!$C$22:$L$22/(1+$A29)^DCF_Base!$C$4:$L$4)+MAX(0,MIN(IF($A29>B$26,DCF_Base!$L$22*(1+B$26)/($A29-B$26),0),Assumptions!$B$8*DCF_Base!$L$22))/(1+$A29)^10-Assumptions!$B$9)/Assumptions!$B$10,"n/a") | C29: =IF($A29>C$26,(SUMPRODUCT(DCF_Base!$C$22:$L$22/(1+$A29)^DCF_Base!$C$4:$L$4)+MAX(0,MIN(IF($A29>C$26,DCF_Base!$L$22*(1+C$26)/($A29-C$26),0),Assumptions!$B$8*DCF_Base!$L$22))/(1+$A29)^10-Assumptions!$B$9)/Assumptions!$B$10,"n/a") | D29: =IF($A29>D$26,(SUMPRODUCT(DCF_Base!$C$22:$L$22/(1+$A29)^DCF_Base!$C$4:$L$4)+MAX(0,MIN(IF($A29>D$26,DCF_Base!$L$22*(1+D$26)/($A29-D$26),0),Assumptions!$B$8*DCF_Base!$L$22))/(1+$A29)^10-Assumptions!$B$9)/Assumptions!$B$10,"n/a") | E29: =IF($A29>E$26,(SUMPRODUCT(DCF_Base!$C$22:$L$22/(1+$A29)^DCF_Base!$C$4:$L$4)+MAX(0,MIN(IF($A29>E$26,DCF_Base!$L$22*(1+E$26)/($A29-E$26),0),Assumptions!$B$8*DCF_Base!$L$22))/(1+$A29)^10-Assumptions!$B$9)/Assumptions!$B$10,"n/a") | F29: =IF($A29>F$26,(SUMPRODUCT(DCF_Base!$C$22:$L$22/(1+$A29)^DCF_Base!$C$4:$L$4)+MAX(0,MIN(IF($A29>F$26,DCF_Base!$L$22*(1+F$26)/($A29-F$26),0),Assumptions!$B$8*DCF_Base!$L$22))/(1+$A29)^10-Assumptions!$B$9)/Assumptions!$B$10,"n/a")
A30: 0.1 | B30: =IF($A30>B$26,(SUMPRODUCT(DCF_Base!$C$22:$L$22/(1+$A30)^DCF_Base!$C$4:$L$4)+MAX(0,MIN(IF($A30>B$26,DCF_Base!$L$22*(1+B$26)/($A30-B$26),0),Assumptions!$B$8*DCF_Base!$L$22))/(1+$A30)^10-Assumptions!$B$9)/Assumptions!$B$10,"n/a") | C30: =IF($A30>C$26,(SUMPRODUCT(DCF_Base!$C$22:$L$22/(1+$A30)^DCF_Base!$C$4:$L$4)+MAX(0,MIN(IF($A30>C$26,DCF_Base!$L$22*(1+C$26)/($A30-C$26),0),Assumptions!$B$8*DCF_Base!$L$22))/(1+$A30)^10-Assumptions!$B$9)/Assumptions!$B$10,"n/a") | D30: =IF($A30>D$26,(SUMPRODUCT(DCF_Base!$C$22:$L$22/(1+$A30)^DCF_Base!$C$4:$L$4)+MAX(0,MIN(IF($A30>D$26,DCF_Base!$L$22*(1+D$26)/($A30-D$26),0),Assumptions!$B$8*DCF_Base!$L$22))/(1+$A30)^10-Assumptions!$B$9)/Assumptions!$B$10,"n/a") | E30: =IF($A30>E$26,(SUMPRODUCT(DCF_Base!$C$22:$L$22/(1+$A30)^DCF_Base!$C$4:$L$4)+MAX(0,MIN(IF($A30>E$26,DCF_Base!$L$22*(1+E$26)/($A30-E$26),0),Assumptions!$B$8*DCF_Base!$L$22))/(1+$A30)^10-Assumptions!$B$9)/Assumptions!$B$10,"n/a") | F30: =IF($A30>F$26,(SUMPRODUCT(DCF_Base!$C$22:$L$22/(1+$A30)^DCF_Base!$C$4:$L$4)+MAX(0,MIN(IF($A30>F$26,DCF_Base!$L$22*(1+F$26)/($A30-F$26),0),Assumptions!$B$8*DCF_Base!$L$22))/(1+$A30)^10-Assumptions!$B$9)/Assumptions!$B$10,"n/a")
A31: 0.11 | B31: =IF($A31>B$26,(SUMPRODUCT(DCF_Base!$C$22:$L$22/(1+$A31)^DCF_Base!$C$4:$L$4)+MAX(0,MIN(IF($A31>B$26,DCF_Base!$L$22*(1+B$26)/($A31-B$26),0),Assumptions!$B$8*DCF_Base!$L$22))/(1+$A31)^10-Assumptions!$B$9)/Assumptions!$B$10,"n/a") | C31: =IF($A31>C$26,(SUMPRODUCT(DCF_Base!$C$22:$L$22/(1+$A31)^DCF_Base!$C$4:$L$4)+MAX(0,MIN(IF($A31>C$26,DCF_Base!$L$22*(1+C$26)/($A31-C$26),0),Assumptions!$B$8*DCF_Base!$L$22))/(1+$A31)^10-Assumptions!$B$9)/Assumptions!$B$10,"n/a") | D31: =IF($A31>D$26,(SUMPRODUCT(DCF_Base!$C$22:$L$22/(1+$A31)^DCF_Base!$C$4:$L$4)+MAX(0,MIN(IF($A31>D$26,DCF_Base!$L$22*(1+D$26)/($A31-D$26),0),Assumptions!$B$8*DCF_Base!$L$22))/(1+$A31)^10-Assumptions!$B$9)/Assumptions!$B$10,"n/a") | E31: =IF($A31>E$26,(SUMPRODUCT(DCF_Base!$C$22:$L$22/(1+$A31)^DCF_Base!$C$4:$L$4)+MAX(0,MIN(IF($A31>E$26,DCF_Base!$L$22*(1+E$26)/($A31-E$26),0),Assumptions!$B$8*DCF_Base!$L$22))/(1+$A31)^10-Assumptions!$B$9)/Assumptions!$B$10,"n/a") | F31: =IF($A31>F$26,(SUMPRODUCT(DCF_Base!$C$22:$L$22/(1+$A31)^DCF_Base!$C$4:$L$4)+MAX(0,MIN(IF($A31>F$26,DCF_Base!$L$22*(1+F$26)/($A31-F$26),0),Assumptions!$B$8*DCF_Base!$L$22))/(1+$A31)^10-Assumptions!$B$9)/Assumptions!$B$10,"n/a")
