Workbook

Sheet DCF Model
A1: SPOT — Spotify Technology S.A. — DCF Valuation
A2: Gray cells are INPUT assumptions — edit them to see results update automatically
A3: Valuation date: 2026-06-30 | All financials in EUR millions | Intrinsic value in USD
A5: A. KEY INPUTS
A6: Current Stock Price (USD) | B6: 462.29
A7: EUR/USD Exchange Rate | B7: 1.1396
A8: Shares Outstanding (M) | B8: 205.6
A9: Cash + ST Investments (EUR M) | B9: 8746
A10: Total Debt (EUR M, lease liabilities) | B10: 476
A11: Net Debt (EUR M) | B11: =B10-B9 -> 0
A12: Base Year Revenue (EUR M, FY2025) | B12: 17186
A13: Base Year FCF (EUR M, FY2025) | B13: 2874
A14: WACC (Base) | B14: 0.1
A15: Terminal Growth Rate (Base) | B15: 0.03
A16: Note: Bull/Bear WACC & TG hardcoded in columns E/F on projections sheet
A18: B. REVENUE GROWTH & FCF MARGIN ASSUMPTIONS (BASE CASE)
A19: Year | B19: Year 1 | C19: Year 2 | D19: Year 3 | E19: Year 4 | F19: Year 5
A20: Revenue Growth Rate | B20: 0.15 | C20: 0.14 | D20: 0.12 | E20: 0.1 | F20: 0.08
A21: FCF Margin (%) | B21: 0.175 | C21: 0.185 | D21: 0.195 | E21: 0.205 | F21: 0.215
A22: Projected Revenue (EUR M) | B22: =$B$12*(1+B20) -> 0 | C22: =B22*(1+C20) -> 0 | D22: =C22*(1+D20) -> 0 | E22: =D22*(1+E20) -> 0 | F22: =E22*(1+F20) -> 0
A23: Projected FCF (EUR M) | B23: =B22*B21 -> 0 | C23: =C22*C21 -> 0 | D23: =D22*D21 -> 0 | E23: =E22*E21 -> 0 | F23: =F22*F21 -> 0
A24: Discount Factor (WACC) | B24: =1/(1+$B$14)^1 -> 0 | C24: =1/(1+$B$14)^2 -> 0 | D24: =1/(1+$B$14)^3 -> 0 | E24: =1/(1+$B$14)^4 -> 0 | F24: =1/(1+$B$14)^5 -> 0
A25: PV of FCF (EUR M) | B25: =B23*B24 -> 0 | C25: =C23*C24 -> 0 | D25: =D23*D24 -> 0 | E25: =E23*E24 -> 0 | F25: =F23*F24 -> 0
A27: C. BASE CASE VALUATION
A28: Sum of PV of FCF (EUR M) | B28: =SUM(B25:F25) -> 0
A29: Terminal FCF = Y5 FCF × (1 + TG) | B29: =F23*(1+$B$15) -> 0
A30: Terminal Value (EUR M) | B30: =B29/($B$14-$B$15) -> 0
A31: PV of Terminal Value (EUR M) | B31: =B30*F24 -> 0
A32: Enterprise Value (EUR M) | B32: =B28+B31 -> 0
A33: Less: Net Debt (EUR M) [neg = net cash] | B33: =B11 -> 0
A34: Equity Value (EUR M) | B34: =B32-B33 -> 0
A35: Intrinsic Value / Share (EUR) | B35: =B34/B8 -> 0
A36: INTRINSIC VALUE / SHARE (USD) | B36: =B35*B7 -> 0
A37: Upside / (Downside) vs. Current Price | B37: =(B36-B6)/B6 -> 0
A39: Terminal Value % of Enterprise Value | B39: =B31/B32 -> 0
A40: Implied Terminal EV/FCF Multiple | B40: =B30/F23 -> 0
A42: D. ENTRY PRICE (15% CAGR TARGET)
A43: Terminal Value per Share (USD) | B43: =(B30/B8)*B7 -> 0
A44: Entry Price for 15% CAGR (USD) | B44: =B43/(1.15^5) -> 0
A45: Entry Discount from Current Price | B45: =(B44-B6)/B6 -> 0
...

Sheet Scenarios
A1: SPOT — All Three Scenarios (Bull / Base / Bear)
A2: Gray = editable inputs. Intrinsic values linked to DCF Model sheet for shared inputs (price, shares, FX, balance sheet).
B3: BASE CASE | D3: BULL CASE | F3: BEAR CASE
A4: WACC | B4: ='DCF Model'!B14 -> 0 | D4: 0.09 | F4: 0.12
A5: Terminal Growth Rate | B5: ='DCF Model'!B15 -> 0 | D5: 0.035 | F5: 0.025
A7: Revenue Growth Rates
A8: Y1 | B8: 0.15 | D8: 0.18 | F8: 0.1
A9: Y2 | B9: 0.14 | D9: 0.17 | F9: 0.08
A10: Y3 | B10: 0.12 | D10: 0.16 | F10: 0.06
A11: Y4 | B11: 0.1 | D11: 0.14 | F11: 0.05
A12: Y5 | B12: 0.08 | D12: 0.12 | F12: 0.04
A13: FCF Margin per Year
A14: Y1 | B14: 0.175 | D14: 0.185 | F14: 0.15
A15: Y2 | B15: 0.185 | D15: 0.205 | F15: 0.155
A16: Y3 | B16: 0.195 | D16: 0.22 | F16: 0.16
A17: Y4 | B17: 0.205 | D17: 0.23 | F17: 0.165
A18: Y5 | B18: 0.215 | D18: 0.24 | F18: 0.17
A19: Revenue Projections (EUR M)
A20: Y1 | B20: ='DCF Model'!$B$12*(1+B8) -> 0 | D20: ='DCF Model'!$B$12*(1+D8) -> 0 | F20: ='DCF Model'!$B$12*(1+F8) -> 0
A21: Y2 | B21: =B20*(1+B9) -> 0 | D21: =D20*(1+D9) -> 0 | F21: =F20*(1+F9) -> 0
A22: Y3 | B22: =B21*(1+B10) -> 0 | D22: =D21*(1+D10) -> 0 | F22: =F21*(1+F10) -> 0
A23: Y4 | B23: =B22*(1+B11) -> 0 | D23: =D22*(1+D11) -> 0 | F23: =F22*(1+F11) -> 0
A24: Y5 | B24: =B23*(1+B12) -> 0 | D24: =D23*(1+D12) -> 0 | F24: =F23*(1+F12) -> 0
A26: Y1 | B26: =B20*B14 -> 0 | D26: =D20*D14 -> 0 | F26: =F20*F14 -> 0
A27: Y2 | B27: =B21*B15 -> 0 | D27: =D21*D15 -> 0 | F27: =F21*F15 -> 0
A28: Y3 | B28: =B22*B16 -> 0 | D28: =D22*D16 -> 0 | F28: =F22*F16 -> 0
A29: Y4 | B29: =B23*B17 -> 0 | D29: =D23*D17 -> 0 | F29: =F23*F17 -> 0
A30: Y5 | B30: =B24*B18 -> 0 | D30: =D24*D18 -> 0 | F30: =F24*F18 -> 0
A32: Y1 | B32: =1/(1+'Scenarios'!B4)^1 -> 0 | D32: =1/(1+'Scenarios'!D4)^1 -> 0 | F32: =1/(1+'Scenarios'!F4)^1 -> 0
A33: Y2 | B33: =1/(1+'Scenarios'!B4)^2 -> 0 | D33: =1/(1+'Scenarios'!D4)^2 -> 0 | F33: =1/(1+'Scenarios'!F4)^2 -> 0
A34: Y3 | B34: =1/(1+'Scenarios'!B4)^3 -> 0 | D34: =1/(1+'Scenarios'!D4)^3 -> 0 | F34: =1/(1+'Scenarios'!F4)^3 -> 0
A35: Y4 | B35: =1/(1+'Scenarios'!B4)^4 -> 0 | D35: =1/(1+'Scenarios'!D4)^4 -> 0 | F35: =1/(1+'Scenarios'!F4)^4 -> 0
A36: Y5 | B36: =1/(1+'Scenarios'!B4)^5 -> 0 | D36: =1/(1+'Scenarios'!D4)^5 -> 0 | F36: =1/(1+'Scenarios'!F4)^5 -> 0
A38: Y1 | B38: =B26*B32 -> 0 | D38: =D26*D32 -> 0 | F38: =F26*F32 -> 0
A39: Y2 | B39: =B27*B33 -> 0 | D39: =D27*D33 -> 0 | F39: =F27*F33 -> 0
A40: Y3 | B40: =B28*B34 -> 0 | D40: =D28*D34 -> 0 | F40: =F28*F34 -> 0
A41: Y4 | B41: =B29*B35 -> 0 | D41: =D29*D35 -> 0 | F41: =F29*F35 -> 0
A42: Y5 | B42: =B30*B36 -> 0 | D42: =D30*D36 -> 0 | F42: =F30*F36 -> 0
A44: Valuation | B44: =SUM(B38:B42) -> 0 | D44: =SUM(D38:D42) -> 0 | F44: =SUM(F38:F42) -> 0
A45: Sum PV of FCF (EUR M) | B45: =B30*(1+'Scenarios'!B5) -> 0 | D45: =D30*(1+'Scenarios'!D5) -> 0 | F45: =F30*(1+'Scenarios'!F5) -> 0
...

Sheet Sensitivity
A1: SPOT — Sensitivity Analysis: Intrinsic Value (USD) by WACC & Terminal Growth
A2: Base case revenue growth rates [15,14,12,10,8]% and FCF margins [17.5,18.5,19.5,20.5,21.5]% held constant.
A3: Net cash €8,270M added; shares 205.6M; EUR/USD linked to DCF Model sheet.
A5: WACC \ Term G | B5: 2.0% | C5: 2.5% | D5: 3.0% | E5: 3.5% | F5: 4.0%
A6: 8% | B6: 566 | C6: 606 | D6: 653 | E6: 712 | F6: 785
A7: 9% | B7: 488 | C7: 516 | D7: 548 | E7: 586 | F7: 632
A8: 10% | B8: 429 | C8: 450 | D8: 473 | E8: 500 | F8: 531
A9: 11% | B9: 384 | C9: 399 | D9: 417 | E9: 436 | F9: 459
A10: 12% | B10: 348 | C10: 360 | D10: 373 | E10: 388 | F10: 405
A12: Blue cell = Base case (WACC 10%, TG 3%)
A13: Green = IV more than 20% above current price ($462.29)
A14: Red = IV more than 20% below current price
A15: Current price: $462.29 | EUR/USD: 1.1396
A17: For reference:
A18: Current Price (USD) | B18: 462.29
A19: EUR/USD Rate | B19: 1.1396

Sheet Historical
A1: SPOT — Historical Financials (EUR Millions)
A2: Source: SPOT_Metrics.csv. All values in EUR millions except EPS, shares (M), margins (%).
A4: Period | B4: Revenue | C4: Gross Profit | D4: Gross Margin | E4: Op Income | F4: Op Margin | G4: Net Income | H4: EPS (Dil) | I4: FCF | J4: Equity | K4: Cash | L4: Debt | M4: Shares (M)
A5: FY2016 | B5: 2952 | C5: 401 | D5: 0.136 | E5: -349 | F5: -0.118 | G5: -539 | H5: -3.63 | I5: 73 | K5: 755 | M5: 148.4
A6: FY2017 | B6: 4090 | C6: 849 | D6: 0.208 | E6: -378 | F6: -0.092 | G6: -1235 | H6: -8.14 | I6: 109 | J6: 238 | K6: 944 | M6: 151.7
A7: FY2018 | B7: 5259 | C7: 1353 | D7: 0.257 | E7: -43 | F7: -0.008 | G7: -78 | H7: -0.51 | I7: 209 | J7: 2094 | K7: 891 | M7: 177.2
A8: FY2019 | B8: 6764 | C8: 1722 | D8: 0.255 | E8: -73 | F8: -0.011 | G8: -186 | H8: -1.03 | I8: 440 | J8: 2037 | K8: 1065 | M8: 181
A9: FY2020 | B9: 7880 | C9: 2015 | D9: 0.256 | E9: -293 | F9: -0.037 | G9: -581 | H9: -3.1 | I9: 183 | J9: 2805 | K9: 1151 | M9: 187.6
A10: FY2021 | B10: 9668 | C10: 2591 | D10: 0.268 | E10: 94 | F10: 0.01 | G10: -34 | H10: -1.03 | I10: 277 | J10: 2119 | K10: 2744 | L10: 1202 | M10: 193.9
A11: FY2022 | B11: 11727 | C11: 2926 | D11: 0.249 | E11: -659 | F11: -0.056 | G11: -430 | H11: -2.93 | I11: 21 | J11: 2401 | K11: 2483 | L11: 1128 | M11: 195.8
A12: FY2023 | B12: 13247 | C12: 3397 | D12: 0.257 | E12: -446 | F12: -0.034 | G12: -532 | H12: -2.73 | I12: 678 | J12: 2523 | K12: 3114 | L12: 1203 | M12: 194.7
A13: FY2024 | B13: 15673 | C13: 4724 | D13: 0.301 | E13: 1365 | F13: 0.087 | G13: 1138 | H13: 5.5 | I13: 2285 | J13: 5525 | K13: 4781 | L13: 1539 | M13: 207
A14: FY2025 | B14: 17186 | C14: 5496 | D14: 0.32 | E14: 2198 | F14: 0.128 | G14: 2212 | H14: 10.51 | I14: 2874 | J14: 8329 | K14: 5258 | L14: 1458 | M14: 210.5
A16: Historical Growth Rates
A18: Metric | B18: 3-Year CAGR | C18: 5-Year CAGR | D18: Notes
A19: Revenue | B19: 0.1359 | C19: 0.1688 | D19: FY2022-FY2025 / FY2020-FY2025
A20: EPS | B20: N/A — loss years | C20: N/A — loss years | D20: All years negative through FY2023; 1yr CAGR FY2024-25: +91%
A21: Equity (Book Value) | B21: 0.5138 | C21: 0.2432 | D21: Distorted by accumulated deficit reversal and SBC — not primary driver
A22: FCF | B22: N/A — near-zero base | C22: 0.7346 | D22: FY2022 FCF €21M (trough); 5yr CAGR = inflection, not repeatable
A23: Selected Anchor Rate | B23: 0.1688 | D23: Revenue 5yr CAGR; aligns with management mid-teens 2030 Investor Day target

Sheet Sanity Check
A1: SPOT — Sanity Check: Implied Multiples vs. History
A2: Excludes loss years (FY2016-FY2023) from P/E averages per methodology.
A4: Current Market Multiples
A5: Current Stock Price (USD) | B5: $462.29
A6: Market Cap (USD M) | B6: 95,047
A7: Net Cash (USD M) | B7: 9,424
A8: Enterprise Value (USD M) | B8: 85,622
A9: EV / FCF (FY2025) | B9: 26.1×
A10: P / FCF (FY2025) | B10: 29.0×
A11: EV / Revenue (FY2025) | B11: 4.37×
A12: P/E (FY2025, includes TME MTM) | B12: 37.7×
A14: Historical EV/FCF at Year-End Price
A15: Year | B15: Year-End Price | C15: FCF (EUR M) | D15: EV/FCF
A16: FY2023 | B16: 187.91 | C16: 678 | D16: 44.5
A17: FY2024 | B17: 447.38 | C17: 2285 | D17: 34.1
A18: FY2025 | B18: 580.71 | C18: 2874 | D18: 36
A19: Current (2026-06-30) | B19: 462.29 | C19: 2874 | D19: 26.1
A20: Historical P/E (profitable years only)
A21: Year | B21: Year-End Price | C21: EPS (USD) | D21: P/E
A22: FY2024 (at year-end) | B22: 447.38 | C22: 6.27 | D22: 71.4
A23: FY2025 (at year-end) | B23: 580.71 | C23: 11.97 | D23: 48.5
A24: FY2025 (at current) | B24: 462.29 | C24: 12.26 | D24: 37.7
A25: DCF Implied Terminal Multiple
A26: Terminal EV/FCF (Base, at Year 5) | B26: 14.3×
A27: Current market EV/FCF | B27: 26.1×
A28: Implied de-rating required | B28: -46% over 5 years
A29: Assessment | B29: Conservative — model does NOT require stock to hold current multiple
A31: VERDICT: PASSED | B31: No structural anomaly. Base case ~$473 ≈ current price $462. Implied terminal multiple 14.3× < current 26× — conservative assumption.
