Workbook

Sheet Model_Info
A1: PaySauce Limited (PYS.NZ) DCF model - version 1.0 (fresh build, supersedes nothing)
A2: Built by the dcf-analyst agent (Claude Fable 5) on 2026-08-26 at the user's request, alongside PYS.NZ_DCF.json (the two must agree).
A3: MODEL: owner-FCF DCF, two-driver revenue variant. Processing/subscription fees (+other) are grown on scenario paths; interest income on the customer payroll FLOAT is a separate hardcoded rate-dependent driver in dollars - the two lines must never share a blended growth rate.
A4: DATA VINTAGE: price NZD 0.225 (Yahoo Finance, 2026-08-26 12:39 NZT, regular session, intraday). Balance sheet 31-Mar-2026 (FY2026 Annual Report): own cash 4.521m, total debt 0, closing shares on issue 164.246m (kpis SharesOnIssueClosing - NOT the CSV weighted average 149.553m; the NZ$5m raise closed Jan-2026). Tax losses 8.258m (FY2026 AR income tax note). Figures go stale: refresh price, cash, shares and the FY2027 interim (due ~Nov 2026) before relying on this file.
A5: CUSTOMER FLOAT: PaySauce held 45.155m of customer payroll funds at FY2026, exactly offset by a matching liability. It is NOT the company's money: excluded from net cash, never netted into EV. OCF used is the float-excluded figure (1.975 FY2026). The float-inclusive OCF headline (9.196) is not distributable.
A6: SHELL YEARS: FY2017-FY2018 rows in the metrics CSV are Energy Mad Ltd (reverse-takeover shell) - excluded from every CAGR and multiple.
A7: METHODOLOGY CHOICES: (1) SBC fully expensed in flows, share count held FLAT at 164.246m (charge once). (2) Owner FCF = float-excluded OCF - capex - SBC - own-cash interest; capex is predominantly capitalised software development, which this cash basis correctly expenses. (3) Only own-cash interest (~0.02) is stripped; float interest stays in flows because its source asset is not added to EV (matching rule). (4) D&A set equal to capex each year (steady-state convention; tax shield flows through EBIT). (5) NZ tax-loss pool of 8.258m shelters cash tax in the explicit window via rows 17-20; the TERMINAL year is tax-normalised at the full 28% so the shelter is not perpetuated. (6) Terminal value = MAX(0, MIN(Gordon, 15x terminal FCF)). (7) WACC 16.0% NZD-built: 11.5% NZ small-cap base + 2.0 micro-cap illiquidity + 1.0 country/sector-agri concentration + 0.5 key-person + 0.5 residual AU execution + 0.5 float rate-sensitivity; identical across scenarios (risk charged once - AU execution risk lives mainly in scenario flows and the 25% bear weight).
A8: SCENARIO DRIVERS are the agent's judgment set 2026-08-26 from the FY2026 AR, the July-2026 AU update and the Analysis JSON. Forsyth Barr forecasts are commissioned research - used only as a directional cross-check on FY2027 losses.
A9: NOTE ON ENTRY PRICE: the 15% hurdle is BELOW the 16% WACC, so hurdle entry prices sit slightly above intrinsic value; the operative buy-below number is the probability-weighted IV.
A10: CELL LEGEND: blue font = hardcoded input; yellow fill = key driver row (flex these); black = formula; green font = cross-sheet link.

Sheet Actuals
A1: Actuals (NZ$m, PaySauce era only; source Metrics.csv / FY Annual Reports)
A2: Metric | B2: FY2021 | C2: FY2022 | D2: FY2023 | E2: FY2024 | F2: FY2025 | G2: FY2026 | H2: Source note
A3: Revenue | B3: 2.198 | C3: 3.517 | D3: 5.813 | E3: 7.717 | F3: 8.995 | G3: 9.247 | H3: statutory operating revenue
A4: of which float interest income | B4: 0.207 | C4: 0.21 | D4: 1.138 | E4: 2.22 | F4: 2.329 | G4: 1.813 | H4: AR revenue notes (incl other interest)
A5: Processing + other revenue | B5: 1.991 | C5: 3.307 | D5: 4.675 | E5: 5.497 | F5: 6.666 | G5: 7.434 | H5: revenue less interest income
A6: Reported EBTDA (post-SBC) | F6: 1.352 | G6: 1.218 | H6: company EBTDA; not disclosed consistently pre-FY2025
A7: Net income | B7: -1.688 | C7: -1.282 | D7: -0.558 | E7: 1.232 | F7: 0.681 | G7: 0.29 | H7: FY2024 includes deferred-tax benefit
A8: OCF (float-EXCLUDED) | B8: -1.118 | C8: -0.666 | D8: 0.264 | E8: 1.475 | F8: 2.166 | G8: 1.975 | H8: before increase in funds due to customers and IRD
A9: Capex (mostly capitalised dev) | B9: 0.53 | C9: 0.042 | D9: 0.118 | E9: 1.179 | F9: 1.664 | G9: 2.21 | H9: cash flow statement
A10: Reported FCF | B10: -1.648 | C10: -0.708 | D10: 0.146 | E10: 0.296 | F10: 0.502 | G10: -0.235 | H10: OCF - capex
A11: SBC | B11: 0.175 | C11: 0.131 | D11: 0.257 | E11: 0.211 | F11: 0.703 | G11: 0.704 | H11: cash flow add-back
A12: Own cash (float-excluded) | E12: 0.603 | F12: 0.309 | G12: 4.521 | H12: FY2026 post Jan-2026 raise; earlier years approximate
A13: Customer funds held (float) | F13: 37.935 | G13: 45.155 | H13: NOT company money; matching liability
A14: Shareholders equity | B14: 2.432 | C14: 1.668 | D14: 1.395 | E14: 3.044 | F14: 4.171 | G14: 9.454 | H14: balance sheet
A15: Shares on issue (m) | B15: 135.9 | C15: 138.2 | D15: 138.4 | E15: 139.7 | F15: 142 | G15: 164.246 | H15: FY2026 = closing count; earlier = weighted avg
A16: Tax losses carried forward | F16: 8.346 | G16: 8.258 | H16: FY2026 AR income tax note
A17: ARR | B17: 2.436 | F17: 8.651 | G17: 8.975 | H17: kpis; company-defined
A18: FY2027 guidance: ARR ~NZ$10m target Q1 FY27; AU ramp weighted to 2H FY27; no dividend.

Sheet Assumptions
A1: Global assumptions
A2: WACC (all scenarios) | B2: 0.16 | C2: NZD-built; see Model_Info for the six components
A3: Cash tax rate (statutory NZ) | B3: 0.28 | C3: applied after loss-pool offset; terminal always full rate
A4: Terminal value cap multiple | B4: 15 | C4: x terminal owner FCF; micro-cap, below the 20x compounder default
A5: Net cash (own, 31-Mar-2026) | B5: 4.521 | C5: customer float 45.155 EXCLUDED
A6: Shares on issue (m, closing) | B6: 164.24599 | C6: kpis SharesOnIssueClosing; held flat - SBC expensed
A7: Current price (NZD) | B7: 0.225 | C7: Yahoo 2026-08-26 12:39 NZT
A8: Hurdle rate (entry price) | B8: 0.15 | C8: below WACC here - see Model_Info note
A9: Tax-loss pool at FY2026 | B9: 8.258 | C9: FY2026 AR; grows with projected losses
A10: WC capture, Base and Bull | B10: 0.05 | C10: share of YoY revenue increase; monthly billing, little deferred rev
A11: WC capture, Bear | B11: 0 | C11: no growth tailwind
A13: Per scenario | B13: Bear | C13: Base | D13: Bull
A14: Terminal growth | B14: 0.02 | C14: 0.025 | D14: 0.03
A15: Probability weight | B15: 0.25 | C15: 0.5 | D15: 0.25 | E15: =SUM(B15:D15)
E16: weights must sum to 1.00
A18: Scenario narratives
A19: BEAR: Australia consumes the Jan-2026 raise and is wound back by FY2029; partner channel stalls (60% of the AU plan), AU pricing already 20% below plan. NZ squeezed by Xero/MYOB bundling, migration churn and an agri downturn: processing growth 2-6%. Float interest troughs at 1.0m. The NZ-only business never covers dev spend plus SBC; terminal value sits near the zero floor and EQUITY VALUE IS NEGATIVE - a second dilutive raise would be needed.
A20: BASE: Australia gains a modest foothold. Processing growth 10% rising to 13% then decaying to 5% (revenue 19.7m FY2036). Pre-SBC margin dips to 8% in FY2027 on AU spend, matures at 28%. Capex tapers 22% to 10% post platform build. Float interest steps down to ~1.45m then grows slowly. Loss pool shelters cash tax through the window; terminal tax-normalised at 28%.
A21: BULL: Payday Super (1-Jul-2026) is a genuine forced-adoption catalyst; partner channel activates. Processing fees compound 15-28% through FY2030 (revenue 40m FY2036), margins reach 32% pre-SBC, AU float roughly doubles interest income. Fully taxed by FY2036.

Sheet DCF_Bear
A1: Bear scenario - owner-FCF DCF (NZ$m). Drivers (yellow): rows 5,7,9,11,14.
B3: 2026A | C3: FY2027E | D3: FY2028E | E3: FY2029E | F3: FY2030E | G3: FY2031E | H3: FY2032E | I3: FY2033E | J3: FY2034E | K3: FY2035E | L3: FY2036E
A4: Year index | B4: 0 | C4: 1 | D4: 2 | E4: 3 | F4: 4 | G4: 5 | H4: 6 | I4: 7 | J4: 8 | K4: 9 | L4: 10
A5: Processing+other rev growth % | C5: 0.06 | D5: 0.05 | E5: 0.04 | F5: 0.03 | G5: 0.03 | H5: 0.025 | I5: 0.025 | J5: 0.02 | K5: 0.02 | L5: 0.02
A6: Processing+other revenue | B6: 7.434 | C6: =B6*(1+C5) | D6: =C6*(1+D5) | E6: =D6*(1+E5) | F6: =E6*(1+F5) | G6: =F6*(1+G5) | H6: =G6*(1+H5) | I6: =H6*(1+I5) | J6: =I6*(1+J5) | ... L6: =K6*(1+L5)
A7: Float interest income (driver, $) | B7: 1.813 | C7: 1.4 | D7: 1.2 | E7: 1.1 | F7: 1.05 | G7: 1 | H7: 1 | I7: 1 | J7: 1 | K7: 1 | L7: 1
A8: Total revenue | B8: 9.247 | C8: =C6+C7 | D8: =D6+D7 | E8: =E6+E7 | F8: =F6+F7 | G8: =G6+G7 | H8: =H6+H7 | I8: =I6+I7 | J8: =J6+J7 | ... L8: =L6+L7
A9: Adj EBITDA margin % (pre-SBC) | C9: 0.04 | D9: 0.02 | E9: 0.05 | F9: 0.09 | G9: 0.11 | H9: 0.13 | I9: 0.14 | J9: 0.15 | K9: 0.155 | L9: 0.16
A10: Adjusted EBITDA | B10: 1.922 | C10: =C8*C9 | D10: =D8*D9 | E10: =E8*E9 | F10: =F8*F9 | G10: =G8*G9 | H10: =H8*H9 | I10: =I8*I9 | J10: =J8*J9 | ... L10: =L8*L9
A11: SBC % of revenue | C11: 0.075 | D11: 0.075 | E11: 0.0725 | F11: 0.07 | G11: 0.0675 | H11: 0.065 | I11: 0.0625 | J11: 0.06 | K11: 0.06 | L11: 0.06
A12: SBC $ | B12: -0.704 | C12: =-C8*C11 | D12: =-D8*D11 | E12: =-E8*E11 | F12: =-F8*F11 | G12: =-G8*G11 | H12: =-H8*H11 | I12: =-I8*I11 | J12: =-J8*J11 | ... L12: =-L8*L11
A13: Owner EBITDA | C13: =C10+C12 | D13: =D10+D12 | E13: =E10+E12 | F13: =F10+F12 | G13: =G10+G12 | H13: =H10+H12 | I13: =I10+I12 | J13: =J10+J12 | ... L13: =L10+L12
A14: Capex and D&A % of revenue | C14: 0.2 | D14: 0.16 | E14: 0.14 | F14: 0.12 | G14: 0.11 | H14: 0.1 | I14: 0.095 | J14: 0.09 | K14: 0.09 | L14: 0.09
A15: D&A | C15: =-C8*C14 | D15: =-D8*D14 | E15: =-E8*E14 | F15: =-F8*F14 | G15: =-G8*G14 | H15: =-H8*H14 | I15: =-I8*I14 | J15: =-J8*J14 | ... L15: =-L8*L14
A16: EBIT (owner basis) | C16: =C13+C15 | D16: =D13+D15 | E16: =E13+E15 | F16: =F13+F15 | G16: =G13+G15 | H16: =H13+H15 | I16: =I13+I15 | J16: =J13+J15 | ... L16: =L13+L15
A17: Tax-loss pool, opening | C17: =Assumptions!$B$9 | D17: =C19 | E17: =D19 | F17: =E19 | G17: =F19 | H17: =G19 | I17: =H19 | J17: =I19 | K17: =J19 | L17: =K19
A18: Losses used | C18: =MIN(MAX(C16,0),C17) | D18: =MIN(MAX(D16,0),D17) | E18: =MIN(MAX(E16,0),E17) | F18: =MIN(MAX(F16,0),F17) | G18: =MIN(MAX(G16,0),G17) | H18: =MIN(MAX(H16,0),H17) | I18: =MIN(MAX(I16,0),I17) | J18: =MIN(MAX(J16,0),J17) | ... L18: =MIN(MAX(L16,0),L17)
A19: Tax-loss pool, closing | C19: =C17-C18+MAX(-C16,0) | D19: =D17-D18+MAX(-D16,0) | E19: =E17-E18+MAX(-E16,0) | F19: =F17-F18+MAX(-F16,0) | G19: =G17-G18+MAX(-G16,0) | H19: =H17-H18+MAX(-H16,0) | I19: =I17-I18+MAX(-I16,0) | J19: =J17-J18+MAX(-J16,0) | ... L19: =L17-L18+MAX(-L16,0)
A20: Cash tax | C20: =-Assumptions!$B$3*(MAX(C16,0)-C18) | D20: =-Assumptions!$B$3*(MAX(D16,0)-D18) | E20: =-Assumptions!$B$3*(MAX(E16,0)-E18) | F20: =-Assumptions!$B$3*(MAX(F16,0)-F18) | G20: =-Assumptions!$B$3*(MAX(G16,0)-G18) | H20: =-Assumptions!$B$3*(MAX(H16,0)-H18) | I20: =-Assumptions!$B$3*(MAX(I16,0)-I18) | J20: =-Assumptions!$B$3*(MAX(J16,0)-J18) | ... L20: =-Assumptions!$B$3*(MAX(L16,0)-L18)
A21: NOPAT | C21: =C16+C20 | D21: =D16+D20 | E21: =E16+E20 | F21: =F16+F20 | G21: =G16+G20 | H21: =H16+H20 | I21: =I16+I20 | J21: =J16+J20 | ... L21: =L16+L20
A22: Add back D&A | C22: =-C15 | D22: =-D15 | E22: =-E15 | F22: =-F15 | G22: =-G15 | H22: =-H15 | I22: =-I15 | J22: =-J15 | ... L22: =-L15
A23: Less capex | C23: =-C8*C14 | D23: =-D8*D14 | E23: =-E8*E14 | F23: =-F8*F14 | G23: =-G8*G14 | H23: =-H8*H14 | I23: =-I8*I14 | J23: =-J8*J14 | ... L23: =-L8*L14
A24: Working capital (on rev change) | C24: =Assumptions!$B$11*(C8-B8) | D24: =Assumptions!$B$11*(D8-C8) | E24: =Assumptions!$B$11*(E8-D8) | F24: =Assumptions!$B$11*(F8-E8) | G24: =Assumptions!$B$11*(G8-F8) | H24: =Assumptions!$B$11*(H8-G8) | I24: =Assumptions!$B$11*(I8-H8) | J24: =Assumptions!$B$11*(J8-I8) | ... L24: =Assumptions!$B$11*(L8-K8)
A25: Unlevered owner FCF | B25: -0.959 | C25: =C21+C22+C23+C24 | D25: =D21+D22+D23+D24 | E25: =E21+E22+E23+E24 | F25: =F21+F22+F23+F24 | G25: =G21+G22+G23+G24 | H25: =H21+H22+H23+H24 | I25: =I21+I22+I23+I24 | J25: =J21+J22+J23+J24 | ... L25: =L21+L22+L23+L24
A26: Discount factor | C26: =1/(1+Assumptions!$B$2)^C4 | D26: =1/(1+Assumptions!$B$2)^D4 | E26: =1/(1+Assumptions!$B$2)^E4 | F26: =1/(1+Assumptions!$B$2)^F4 | G26: =1/(1+Assumptions!$B$2)^G4 | H26: =1/(1+Assumptions!$B$2)^H4 | I26: =1/(1+Assumptions!$B$2)^I4 | J26: =1/(1+Assumptions!$B$2)^J4 | ... L26: =1/(1+Assumptions!$B$2)^L4
A27: PV of FCF | C27: =C25*C26 | D27: =D25*D26 | E27: =E25*E26 | F27: =F25*F26 | G27: =G25*G26 | H27: =H25*H26 | I27: =I25*I26 | J27: =J25*J26 | ... L27: =L25*L26
A29: Memo: FCF before SBC (company-style) | C29: =C25-C12 | D29: =D25-D12 | E29: =E25-E12 | F29: =F25-F12 | G29: =G25-G12 | H29: =H25-H12 | I29: =I25-I12 | J29: =J25-J12 | ... L29: =L25-L12
A30: Memo: owner-FCF margin | C30: =C25/C8 | D30: =D25/D8 | E30: =E25/E8 | F30: =F25/F8 | G30: =G25/G8 | H30: =H25/H8 | I30: =I25/I8 | J30: =J25/J8 | ... L30: =L25/L8
A32: Sum PV of FCF (yrs 1-10) | B32: =SUM(C27:L27)
A33: Terminal growth | B33: =Assumptions!$B$14
A34: Terminal FCF (tax-normalised @28%) | B34: =L16*(1-Assumptions!$B$3)+L24
A35: Gordon TV | B35: =B34*(1+B33)/(Assumptions!$B$2-B33)
A36: Cap TV (15x) | B36: =Assumptions!$B$4*B34
A37: TV used = MAX(0,MIN(Gordon,Cap)) | B37: =MAX(0,MIN(B35,B36))
A38: Implied exit multiple | B38: =IF(B34>0,B37/B34,"n/a")
A39: PV of terminal value | B39: =B37*L26
A40: Enterprise value | B40: =B32+B39
A41: Add net cash (own only) | B41: =Assumptions!$B$5
A42: Equity value | B42: =B40+B41
A43: Shares on issue (m) | B43: =Assumptions!$B$6
...

Sheet DCF_Base
A1: Base scenario - owner-FCF DCF (NZ$m). Drivers (yellow): rows 5,7,9,11,14.
B3: 2026A | C3: FY2027E | D3: FY2028E | E3: FY2029E | F3: FY2030E | G3: FY2031E | H3: FY2032E | I3: FY2033E | J3: FY2034E | K3: FY2035E | L3: FY2036E
A4: Year index | B4: 0 | C4: 1 | D4: 2 | E4: 3 | F4: 4 | G4: 5 | H4: 6 | I4: 7 | J4: 8 | K4: 9 | L4: 10
A5: Processing+other rev growth % | C5: 0.1 | D5: 0.12 | E5: 0.13 | F5: 0.12 | G5: 0.1 | H5: 0.09 | I5: 0.08 | J5: 0.07 | K5: 0.06 | L5: 0.05
A6: Processing+other revenue | B6: 7.434 | C6: =B6*(1+C5) | D6: =C6*(1+D5) | E6: =D6*(1+E5) | F6: =E6*(1+F5) | G6: =F6*(1+G5) | H6: =G6*(1+H5) | I6: =H6*(1+I5) | J6: =I6*(1+J5) | ... L6: =K6*(1+L5)
A7: Float interest income (driver, $) | B7: 1.813 | C7: 1.55 | D7: 1.45 | E7: 1.45 | F7: 1.5 | G7: 1.55 | H7: 1.6 | I7: 1.65 | J7: 1.7 | K7: 1.75 | L7: 1.8
A8: Total revenue | B8: 9.247 | C8: =C6+C7 | D8: =D6+D7 | E8: =E6+E7 | F8: =F6+F7 | G8: =G6+G7 | H8: =H6+H7 | I8: =I6+I7 | J8: =J6+J7 | ... L8: =L6+L7
A9: Adj EBITDA margin % (pre-SBC) | C9: 0.08 | D9: 0.1 | E9: 0.14 | F9: 0.18 | G9: 0.21 | H9: 0.23 | I9: 0.25 | J9: 0.26 | K9: 0.27 | L9: 0.28
A10: Adjusted EBITDA | B10: 1.922 | C10: =C8*C9 | D10: =D8*D9 | E10: =E8*E9 | F10: =F8*F9 | G10: =G8*G9 | H10: =H8*H9 | I10: =I8*I9 | J10: =J8*J9 | ... L10: =L8*L9
A11: SBC % of revenue | C11: 0.075 | D11: 0.0725 | E11: 0.07 | F11: 0.0675 | G11: 0.065 | H11: 0.0625 | I11: 0.06 | J11: 0.0575 | K11: 0.055 | L11: 0.0525
A12: SBC $ | B12: -0.704 | C12: =-C8*C11 | D12: =-D8*D11 | E12: =-E8*E11 | F12: =-F8*F11 | G12: =-G8*G11 | H12: =-H8*H11 | I12: =-I8*I11 | J12: =-J8*J11 | ... L12: =-L8*L11
A13: Owner EBITDA | C13: =C10+C12 | D13: =D10+D12 | E13: =E10+E12 | F13: =F10+F12 | G13: =G10+G12 | H13: =H10+H12 | I13: =I10+I12 | J13: =J10+J12 | ... L13: =L10+L12
A14: Capex and D&A % of revenue | C14: 0.22 | D14: 0.2 | E14: 0.18 | F14: 0.16 | G14: 0.15 | H14: 0.14 | I14: 0.13 | J14: 0.12 | K14: 0.11 | L14: 0.1
A15: D&A | C15: =-C8*C14 | D15: =-D8*D14 | E15: =-E8*E14 | F15: =-F8*F14 | G15: =-G8*G14 | H15: =-H8*H14 | I15: =-I8*I14 | J15: =-J8*J14 | ... L15: =-L8*L14
A16: EBIT (owner basis) | C16: =C13+C15 | D16: =D13+D15 | E16: =E13+E15 | F16: =F13+F15 | G16: =G13+G15 | H16: =H13+H15 | I16: =I13+I15 | J16: =J13+J15 | ... L16: =L13+L15
A17: Tax-loss pool, opening | C17: =Assumptions!$B$9 | D17: =C19 | E17: =D19 | F17: =E19 | G17: =F19 | H17: =G19 | I17: =H19 | J17: =I19 | K17: =J19 | L17: =K19
A18: Losses used | C18: =MIN(MAX(C16,0),C17) | D18: =MIN(MAX(D16,0),D17) | E18: =MIN(MAX(E16,0),E17) | F18: =MIN(MAX(F16,0),F17) | G18: =MIN(MAX(G16,0),G17) | H18: =MIN(MAX(H16,0),H17) | I18: =MIN(MAX(I16,0),I17) | J18: =MIN(MAX(J16,0),J17) | ... L18: =MIN(MAX(L16,0),L17)
A19: Tax-loss pool, closing | C19: =C17-C18+MAX(-C16,0) | D19: =D17-D18+MAX(-D16,0) | E19: =E17-E18+MAX(-E16,0) | F19: =F17-F18+MAX(-F16,0) | G19: =G17-G18+MAX(-G16,0) | H19: =H17-H18+MAX(-H16,0) | I19: =I17-I18+MAX(-I16,0) | J19: =J17-J18+MAX(-J16,0) | ... L19: =L17-L18+MAX(-L16,0)
A20: Cash tax | C20: =-Assumptions!$B$3*(MAX(C16,0)-C18) | D20: =-Assumptions!$B$3*(MAX(D16,0)-D18) | E20: =-Assumptions!$B$3*(MAX(E16,0)-E18) | F20: =-Assumptions!$B$3*(MAX(F16,0)-F18) | G20: =-Assumptions!$B$3*(MAX(G16,0)-G18) | H20: =-Assumptions!$B$3*(MAX(H16,0)-H18) | I20: =-Assumptions!$B$3*(MAX(I16,0)-I18) | J20: =-Assumptions!$B$3*(MAX(J16,0)-J18) | ... L20: =-Assumptions!$B$3*(MAX(L16,0)-L18)
A21: NOPAT | C21: =C16+C20 | D21: =D16+D20 | E21: =E16+E20 | F21: =F16+F20 | G21: =G16+G20 | H21: =H16+H20 | I21: =I16+I20 | J21: =J16+J20 | ... L21: =L16+L20
A22: Add back D&A | C22: =-C15 | D22: =-D15 | E22: =-E15 | F22: =-F15 | G22: =-G15 | H22: =-H15 | I22: =-I15 | J22: =-J15 | ... L22: =-L15
A23: Less capex | C23: =-C8*C14 | D23: =-D8*D14 | E23: =-E8*E14 | F23: =-F8*F14 | G23: =-G8*G14 | H23: =-H8*H14 | I23: =-I8*I14 | J23: =-J8*J14 | ... L23: =-L8*L14
A24: Working capital (on rev change) | C24: =Assumptions!$B$10*(C8-B8) | D24: =Assumptions!$B$10*(D8-C8) | E24: =Assumptions!$B$10*(E8-D8) | F24: =Assumptions!$B$10*(F8-E8) | G24: =Assumptions!$B$10*(G8-F8) | H24: =Assumptions!$B$10*(H8-G8) | I24: =Assumptions!$B$10*(I8-H8) | J24: =Assumptions!$B$10*(J8-I8) | ... L24: =Assumptions!$B$10*(L8-K8)
A25: Unlevered owner FCF | B25: -0.959 | C25: =C21+C22+C23+C24 | D25: =D21+D22+D23+D24 | E25: =E21+E22+E23+E24 | F25: =F21+F22+F23+F24 | G25: =G21+G22+G23+G24 | H25: =H21+H22+H23+H24 | I25: =I21+I22+I23+I24 | J25: =J21+J22+J23+J24 | ... L25: =L21+L22+L23+L24
A26: Discount factor | C26: =1/(1+Assumptions!$B$2)^C4 | D26: =1/(1+Assumptions!$B$2)^D4 | E26: =1/(1+Assumptions!$B$2)^E4 | F26: =1/(1+Assumptions!$B$2)^F4 | G26: =1/(1+Assumptions!$B$2)^G4 | H26: =1/(1+Assumptions!$B$2)^H4 | I26: =1/(1+Assumptions!$B$2)^I4 | J26: =1/(1+Assumptions!$B$2)^J4 | ... L26: =1/(1+Assumptions!$B$2)^L4
A27: PV of FCF | C27: =C25*C26 | D27: =D25*D26 | E27: =E25*E26 | F27: =F25*F26 | G27: =G25*G26 | H27: =H25*H26 | I27: =I25*I26 | J27: =J25*J26 | ... L27: =L25*L26
A29: Memo: FCF before SBC (company-style) | C29: =C25-C12 | D29: =D25-D12 | E29: =E25-E12 | F29: =F25-F12 | G29: =G25-G12 | H29: =H25-H12 | I29: =I25-I12 | J29: =J25-J12 | ... L29: =L25-L12
A30: Memo: owner-FCF margin | C30: =C25/C8 | D30: =D25/D8 | E30: =E25/E8 | F30: =F25/F8 | G30: =G25/G8 | H30: =H25/H8 | I30: =I25/I8 | J30: =J25/J8 | ... L30: =L25/L8
A32: Sum PV of FCF (yrs 1-10) | B32: =SUM(C27:L27)
A33: Terminal growth | B33: =Assumptions!$C$14
A34: Terminal FCF (tax-normalised @28%) | B34: =L16*(1-Assumptions!$B$3)+L24
A35: Gordon TV | B35: =B34*(1+B33)/(Assumptions!$B$2-B33)
A36: Cap TV (15x) | B36: =Assumptions!$B$4*B34
A37: TV used = MAX(0,MIN(Gordon,Cap)) | B37: =MAX(0,MIN(B35,B36))
A38: Implied exit multiple | B38: =IF(B34>0,B37/B34,"n/a")
A39: PV of terminal value | B39: =B37*L26
A40: Enterprise value | B40: =B32+B39
A41: Add net cash (own only) | B41: =Assumptions!$B$5
A42: Equity value | B42: =B40+B41
A43: Shares on issue (m) | B43: =Assumptions!$B$6
...

Sheet DCF_Bull
A1: Bull scenario - owner-FCF DCF (NZ$m). Drivers (yellow): rows 5,7,9,11,14.
B3: 2026A | C3: FY2027E | D3: FY2028E | E3: FY2029E | F3: FY2030E | G3: FY2031E | H3: FY2032E | I3: FY2033E | J3: FY2034E | K3: FY2035E | L3: FY2036E
A4: Year index | B4: 0 | C4: 1 | D4: 2 | E4: 3 | F4: 4 | G4: 5 | H4: 6 | I4: 7 | J4: 8 | K4: 9 | L4: 10
A5: Processing+other rev growth % | C5: 0.15 | D5: 0.22 | E5: 0.28 | F5: 0.26 | G5: 0.22 | H5: 0.18 | I5: 0.15 | J5: 0.12 | K5: 0.1 | L5: 0.08
A6: Processing+other revenue | B6: 7.434 | C6: =B6*(1+C5) | D6: =C6*(1+D5) | E6: =D6*(1+E5) | F6: =E6*(1+F5) | G6: =F6*(1+G5) | H6: =G6*(1+H5) | I6: =H6*(1+I5) | J6: =I6*(1+J5) | ... L6: =K6*(1+L5)
A7: Float interest income (driver, $) | B7: 1.813 | C7: 1.65 | D7: 1.6 | E7: 1.7 | F7: 1.85 | G7: 2 | H7: 2.2 | I7: 2.4 | J7: 2.6 | K7: 2.8 | L7: 3
A8: Total revenue | B8: 9.247 | C8: =C6+C7 | D8: =D6+D7 | E8: =E6+E7 | F8: =F6+F7 | G8: =G6+G7 | H8: =H6+H7 | I8: =I6+I7 | J8: =J6+J7 | ... L8: =L6+L7
A9: Adj EBITDA margin % (pre-SBC) | C9: 0.1 | D9: 0.12 | E9: 0.16 | F9: 0.2 | G9: 0.24 | H9: 0.27 | I9: 0.29 | J9: 0.3 | K9: 0.31 | L9: 0.32
A10: Adjusted EBITDA | B10: 1.922 | C10: =C8*C9 | D10: =D8*D9 | E10: =E8*E9 | F10: =F8*F9 | G10: =G8*G9 | H10: =H8*H9 | I10: =I8*I9 | J10: =J8*J9 | ... L10: =L8*L9
A11: SBC % of revenue | C11: 0.07 | D11: 0.0675 | E11: 0.065 | F11: 0.0625 | G11: 0.06 | H11: 0.0575 | I11: 0.055 | J11: 0.0525 | K11: 0.05 | L11: 0.0475
A12: SBC $ | B12: -0.704 | C12: =-C8*C11 | D12: =-D8*D11 | E12: =-E8*E11 | F12: =-F8*F11 | G12: =-G8*G11 | H12: =-H8*H11 | I12: =-I8*I11 | J12: =-J8*J11 | ... L12: =-L8*L11
A13: Owner EBITDA | C13: =C10+C12 | D13: =D10+D12 | E13: =E10+E12 | F13: =F10+F12 | G13: =G10+G12 | H13: =H10+H12 | I13: =I10+I12 | J13: =J10+J12 | ... L13: =L10+L12
A14: Capex and D&A % of revenue | C14: 0.22 | D14: 0.2 | E14: 0.18 | F14: 0.16 | G14: 0.14 | H14: 0.13 | I14: 0.12 | J14: 0.11 | K14: 0.1 | L14: 0.1
A15: D&A | C15: =-C8*C14 | D15: =-D8*D14 | E15: =-E8*E14 | F15: =-F8*F14 | G15: =-G8*G14 | H15: =-H8*H14 | I15: =-I8*I14 | J15: =-J8*J14 | ... L15: =-L8*L14
A16: EBIT (owner basis) | C16: =C13+C15 | D16: =D13+D15 | E16: =E13+E15 | F16: =F13+F15 | G16: =G13+G15 | H16: =H13+H15 | I16: =I13+I15 | J16: =J13+J15 | ... L16: =L13+L15
A17: Tax-loss pool, opening | C17: =Assumptions!$B$9 | D17: =C19 | E17: =D19 | F17: =E19 | G17: =F19 | H17: =G19 | I17: =H19 | J17: =I19 | K17: =J19 | L17: =K19
A18: Losses used | C18: =MIN(MAX(C16,0),C17) | D18: =MIN(MAX(D16,0),D17) | E18: =MIN(MAX(E16,0),E17) | F18: =MIN(MAX(F16,0),F17) | G18: =MIN(MAX(G16,0),G17) | H18: =MIN(MAX(H16,0),H17) | I18: =MIN(MAX(I16,0),I17) | J18: =MIN(MAX(J16,0),J17) | ... L18: =MIN(MAX(L16,0),L17)
A19: Tax-loss pool, closing | C19: =C17-C18+MAX(-C16,0) | D19: =D17-D18+MAX(-D16,0) | E19: =E17-E18+MAX(-E16,0) | F19: =F17-F18+MAX(-F16,0) | G19: =G17-G18+MAX(-G16,0) | H19: =H17-H18+MAX(-H16,0) | I19: =I17-I18+MAX(-I16,0) | J19: =J17-J18+MAX(-J16,0) | ... L19: =L17-L18+MAX(-L16,0)
A20: Cash tax | C20: =-Assumptions!$B$3*(MAX(C16,0)-C18) | D20: =-Assumptions!$B$3*(MAX(D16,0)-D18) | E20: =-Assumptions!$B$3*(MAX(E16,0)-E18) | F20: =-Assumptions!$B$3*(MAX(F16,0)-F18) | G20: =-Assumptions!$B$3*(MAX(G16,0)-G18) | H20: =-Assumptions!$B$3*(MAX(H16,0)-H18) | I20: =-Assumptions!$B$3*(MAX(I16,0)-I18) | J20: =-Assumptions!$B$3*(MAX(J16,0)-J18) | ... L20: =-Assumptions!$B$3*(MAX(L16,0)-L18)
A21: NOPAT | C21: =C16+C20 | D21: =D16+D20 | E21: =E16+E20 | F21: =F16+F20 | G21: =G16+G20 | H21: =H16+H20 | I21: =I16+I20 | J21: =J16+J20 | ... L21: =L16+L20
A22: Add back D&A | C22: =-C15 | D22: =-D15 | E22: =-E15 | F22: =-F15 | G22: =-G15 | H22: =-H15 | I22: =-I15 | J22: =-J15 | ... L22: =-L15
A23: Less capex | C23: =-C8*C14 | D23: =-D8*D14 | E23: =-E8*E14 | F23: =-F8*F14 | G23: =-G8*G14 | H23: =-H8*H14 | I23: =-I8*I14 | J23: =-J8*J14 | ... L23: =-L8*L14
A24: Working capital (on rev change) | C24: =Assumptions!$B$10*(C8-B8) | D24: =Assumptions!$B$10*(D8-C8) | E24: =Assumptions!$B$10*(E8-D8) | F24: =Assumptions!$B$10*(F8-E8) | G24: =Assumptions!$B$10*(G8-F8) | H24: =Assumptions!$B$10*(H8-G8) | I24: =Assumptions!$B$10*(I8-H8) | J24: =Assumptions!$B$10*(J8-I8) | ... L24: =Assumptions!$B$10*(L8-K8)
A25: Unlevered owner FCF | B25: -0.959 | C25: =C21+C22+C23+C24 | D25: =D21+D22+D23+D24 | E25: =E21+E22+E23+E24 | F25: =F21+F22+F23+F24 | G25: =G21+G22+G23+G24 | H25: =H21+H22+H23+H24 | I25: =I21+I22+I23+I24 | J25: =J21+J22+J23+J24 | ... L25: =L21+L22+L23+L24
A26: Discount factor | C26: =1/(1+Assumptions!$B$2)^C4 | D26: =1/(1+Assumptions!$B$2)^D4 | E26: =1/(1+Assumptions!$B$2)^E4 | F26: =1/(1+Assumptions!$B$2)^F4 | G26: =1/(1+Assumptions!$B$2)^G4 | H26: =1/(1+Assumptions!$B$2)^H4 | I26: =1/(1+Assumptions!$B$2)^I4 | J26: =1/(1+Assumptions!$B$2)^J4 | ... L26: =1/(1+Assumptions!$B$2)^L4
A27: PV of FCF | C27: =C25*C26 | D27: =D25*D26 | E27: =E25*E26 | F27: =F25*F26 | G27: =G25*G26 | H27: =H25*H26 | I27: =I25*I26 | J27: =J25*J26 | ... L27: =L25*L26
A29: Memo: FCF before SBC (company-style) | C29: =C25-C12 | D29: =D25-D12 | E29: =E25-E12 | F29: =F25-F12 | G29: =G25-G12 | H29: =H25-H12 | I29: =I25-I12 | J29: =J25-J12 | ... L29: =L25-L12
A30: Memo: owner-FCF margin | C30: =C25/C8 | D30: =D25/D8 | E30: =E25/E8 | F30: =F25/F8 | G30: =G25/G8 | H30: =H25/H8 | I30: =I25/I8 | J30: =J25/J8 | ... L30: =L25/L8
A32: Sum PV of FCF (yrs 1-10) | B32: =SUM(C27:L27)
A33: Terminal growth | B33: =Assumptions!$D$14
A34: Terminal FCF (tax-normalised @28%) | B34: =L16*(1-Assumptions!$B$3)+L24
A35: Gordon TV | B35: =B34*(1+B33)/(Assumptions!$B$2-B33)
A36: Cap TV (15x) | B36: =Assumptions!$B$4*B34
A37: TV used = MAX(0,MIN(Gordon,Cap)) | B37: =MAX(0,MIN(B35,B36))
A38: Implied exit multiple | B38: =IF(B34>0,B37/B34,"n/a")
A39: PV of terminal value | B39: =B37*L26
A40: Enterprise value | B40: =B32+B39
A41: Add net cash (own only) | B41: =Assumptions!$B$5
A42: Equity value | B42: =B40+B41
A43: Shares on issue (m) | B43: =Assumptions!$B$6
...

Sheet FCF_Quality
A1: Reported FCF reconciled to owner FCF (NZ$m). OCF is the float-EXCLUDED figure throughout.
B2: FY2021 | C2: FY2022 | D2: FY2023 | E2: FY2024 | F2: FY2025 | G2: FY2026
A3: Free cash flow (company definition) | B3: -1.648 | C3: -0.708 | D3: 0.146 | E3: 0.296 | F3: 0.502 | G3: -0.235
A4: less: SBC (no separate equity-tax line disclosed) | B4: -0.175 | C4: -0.131 | D4: -0.257 | E4: -0.211 | F4: -0.703 | G4: -0.704
A5: less: interest on OWN cash (float interest retained) | B5: 0 | C5: 0 | D5: 0 | E5: 0 | F5: 0 | G5: -0.02
A6: Owner FCF | B6: =B3+B4+B5 | C6: =C3+C4+C5 | D6: =D3+D4+D5 | E6: =E3+E4+E5 | F6: =F3+F4+F5 | G6: =G3+G4+G5
A7: Revenue | B7: 2.198 | C7: 3.517 | D7: 5.813 | E7: 7.717 | F7: 8.995 | G7: 9.247
A8: Reported FCF margin | B8: =B3/B7 | C8: =C3/C7 | D8: =D3/D7 | E8: =E3/E7 | F8: =F3/F7 | G8: =G3/G7
A9: Owner FCF margin | B9: =B6/B7 | C9: =C6/C7 | D9: =D6/D7 | E9: =E6/E7 | F9: =F6/F7 | G9: =G6/G7
A11: Memo: capex is predominantly capitalised software development (FY2026: 2.210 of 2.210). Reported NPAT (+0.290 FY2026) is flattered because amortisation lags capitalisation; the cash FCF basis above expenses it fully.
A12: Memo: float interest income (FY2021-26: 0.207 / 0.210 / 1.138 / 2.220 / 2.329 / 1.813) STAYS in the flows - its source asset (customer float, 45.155 at FY2026) is never added to EV. Only own-cash interest is stripped.
A13: Memo: cash tax ~0 across history (loss pool 8.258 at FY2026); FY2024 net income included a deferred-tax benefit - flagged abnormal.
A14: Memo: FY2019-FY2020 are excluded above - CSV cash/OCF in those years still include the customer float.

Sheet Valuation
A1: Valuation summary (NZD per share)
B2: Bear | C2: Base | D2: Bull
A3: Value per share (house, SBC expensed) | B3: =DCF_Bear!B44 | C3: =DCF_Base!B44 | D3: =DCF_Bull!B44
A4: Street value per share (SBC as non-cash) | B4: =DCF_Bear!B49 | C4: =DCF_Base!B49 | D4: =DCF_Bull!B49
A5: Upside vs price | B5: =B3/Assumptions!$B$7-1 | C5: =C3/Assumptions!$B$7-1 | D5: =D3/Assumptions!$B$7-1
A6: Probability weight | B6: =Assumptions!B15 | C6: =Assumptions!C15 | D6: =Assumptions!D15
A8: PROBABILITY-WEIGHTED IV | B8: =SUMPRODUCT(B3:D3,B6:D6)
A9: Street weighted IV | B9: =SUMPRODUCT(B4:D4,B6:D6)
A10: Margin of safety at current price | B10: =1-Assumptions!B7/B8
A11: Band position (price within house-street band, base) | B11: =(Assumptions!B7-C3)/(C4-C3)
A12: Note: band position far above 100% means the price exceeds even the street ceiling - the market is paying for bull-case Australia at a lower discount rate, not for the current business on either SBC basis.
A14: Entry prices at 15% hurdle (TV at WACC-fair value; hurdle < WACC so these sit ABOVE IV - see Model_Info)
B15: Bear | C15: Base | D15: Bull
A16: Entry price | B16: =(SUMPRODUCT(DCF_Bear!C25:L25/(1+Assumptions!$B$8)^DCF_Bear!C4:L4)+DCF_Bear!B37/(1+Assumptions!$B$8)^10+Assumptions!$B$5)/Assumptions!$B$6 | C16: =(SUMPRODUCT(DCF_Base!C25:L25/(1+Assumptions!$B$8)^DCF_Base!C4:L4)+DCF_Base!B37/(1+Assumptions!$B$8)^10+Assumptions!$B$5)/Assumptions!$B$6 | D16: =(SUMPRODUCT(DCF_Bull!C25:L25/(1+Assumptions!$B$8)^DCF_Bull!C4:L4)+DCF_Bull!B37/(1+Assumptions!$B$8)^10+Assumptions!$B$5)/Assumptions!$B$6
A17: Weighted entry price | B17: =SUMPRODUCT(B16:D16,B6:D6)
A19: Required-return table (base flows, WACC-Gordon TV held fixed)
A20: Required return | B20: 0.09 | C20: 0.1 | D20: 0.11 | E20: 0.12 | F20: 0.15 | G20: 0.16
A21: Value per share | B21: =(SUMPRODUCT(DCF_Base!$C$25:$L$25/(1+B20)^DCF_Base!$C$4:$L$4)+DCF_Base!$B$37/(1+B20)^10+Assumptions!$B$5)/Assumptions!$B$6 | C21: =(SUMPRODUCT(DCF_Base!$C$25:$L$25/(1+C20)^DCF_Base!$C$4:$L$4)+DCF_Base!$B$37/(1+C20)^10+Assumptions!$B$5)/Assumptions!$B$6 | D21: =(SUMPRODUCT(DCF_Base!$C$25:$L$25/(1+D20)^DCF_Base!$C$4:$L$4)+DCF_Base!$B$37/(1+D20)^10+Assumptions!$B$5)/Assumptions!$B$6 | E21: =(SUMPRODUCT(DCF_Base!$C$25:$L$25/(1+E20)^DCF_Base!$C$4:$L$4)+DCF_Base!$B$37/(1+E20)^10+Assumptions!$B$5)/Assumptions!$B$6 | F21: =(SUMPRODUCT(DCF_Base!$C$25:$L$25/(1+F20)^DCF_Base!$C$4:$L$4)+DCF_Base!$B$37/(1+F20)^10+Assumptions!$B$5)/Assumptions!$B$6 | G21: =(SUMPRODUCT(DCF_Base!$C$25:$L$25/(1+G20)^DCF_Base!$C$4:$L$4)+DCF_Base!$B$37/(1+G20)^10+Assumptions!$B$5)/Assumptions!$B$6
A23: Sensitivity: WACC (rows) x terminal growth (cols), base scenario, TV recomputed and capped per cell
C24: 0.015 | D24: 0.02 | E24: 0.025 | F24: 0.03 | G24: 0.035
B25: 0.14 | C25: =IF($B25>C$24,(SUMPRODUCT(DCF_Base!$C$25:$L$25/(1+$B25)^DCF_Base!$C$4:$L$4)+MAX(0,MIN(DCF_Base!$B$34*(1+C$24)/($B25-C$24),Assumptions!$B$4*DCF_Base!$B$34))/(1+$B25)^10+Assumptions!$B$5)/Assumptions!$B$6,"n/a") | D25: =IF($B25>D$24,(SUMPRODUCT(DCF_Base!$C$25:$L$25/(1+$B25)^DCF_Base!$C$4:$L$4)+MAX(0,MIN(DCF_Base!$B$34*(1+D$24)/($B25-D$24),Assumptions!$B$4*DCF_Base!$B$34))/(1+$B25)^10+Assumptions!$B$5)/Assumptions!$B$6,"n/a") | E25: =IF($B25>E$24,(SUMPRODUCT(DCF_Base!$C$25:$L$25/(1+$B25)^DCF_Base!$C$4:$L$4)+MAX(0,MIN(DCF_Base!$B$34*(1+E$24)/($B25-E$24),Assumptions!$B$4*DCF_Base!$B$34))/(1+$B25)^10+Assumptions!$B$5)/Assumptions!$B$6,"n/a") | F25: =IF($B25>F$24,(SUMPRODUCT(DCF_Base!$C$25:$L$25/(1+$B25)^DCF_Base!$C$4:$L$4)+MAX(0,MIN(DCF_Base!$B$34*(1+F$24)/($B25-F$24),Assumptions!$B$4*DCF_Base!$B$34))/(1+$B25)^10+Assumptions!$B$5)/Assumptions!$B$6,"n/a") | G25: =IF($B25>G$24,(SUMPRODUCT(DCF_Base!$C$25:$L$25/(1+$B25)^DCF_Base!$C$4:$L$4)+MAX(0,MIN(DCF_Base!$B$34*(1+G$24)/($B25-G$24),Assumptions!$B$4*DCF_Base!$B$34))/(1+$B25)^10+Assumptions!$B$5)/Assumptions!$B$6,"n/a")
B26: 0.15 | C26: =IF($B26>C$24,(SUMPRODUCT(DCF_Base!$C$25:$L$25/(1+$B26)^DCF_Base!$C$4:$L$4)+MAX(0,MIN(DCF_Base!$B$34*(1+C$24)/($B26-C$24),Assumptions!$B$4*DCF_Base!$B$34))/(1+$B26)^10+Assumptions!$B$5)/Assumptions!$B$6,"n/a") | D26: =IF($B26>D$24,(SUMPRODUCT(DCF_Base!$C$25:$L$25/(1+$B26)^DCF_Base!$C$4:$L$4)+MAX(0,MIN(DCF_Base!$B$34*(1+D$24)/($B26-D$24),Assumptions!$B$4*DCF_Base!$B$34))/(1+$B26)^10+Assumptions!$B$5)/Assumptions!$B$6,"n/a") | E26: =IF($B26>E$24,(SUMPRODUCT(DCF_Base!$C$25:$L$25/(1+$B26)^DCF_Base!$C$4:$L$4)+MAX(0,MIN(DCF_Base!$B$34*(1+E$24)/($B26-E$24),Assumptions!$B$4*DCF_Base!$B$34))/(1+$B26)^10+Assumptions!$B$5)/Assumptions!$B$6,"n/a") | F26: =IF($B26>F$24,(SUMPRODUCT(DCF_Base!$C$25:$L$25/(1+$B26)^DCF_Base!$C$4:$L$4)+MAX(0,MIN(DCF_Base!$B$34*(1+F$24)/($B26-F$24),Assumptions!$B$4*DCF_Base!$B$34))/(1+$B26)^10+Assumptions!$B$5)/Assumptions!$B$6,"n/a") | G26: =IF($B26>G$24,(SUMPRODUCT(DCF_Base!$C$25:$L$25/(1+$B26)^DCF_Base!$C$4:$L$4)+MAX(0,MIN(DCF_Base!$B$34*(1+G$24)/($B26-G$24),Assumptions!$B$4*DCF_Base!$B$34))/(1+$B26)^10+Assumptions!$B$5)/Assumptions!$B$6,"n/a")
B27: 0.16 | C27: =IF($B27>C$24,(SUMPRODUCT(DCF_Base!$C$25:$L$25/(1+$B27)^DCF_Base!$C$4:$L$4)+MAX(0,MIN(DCF_Base!$B$34*(1+C$24)/($B27-C$24),Assumptions!$B$4*DCF_Base!$B$34))/(1+$B27)^10+Assumptions!$B$5)/Assumptions!$B$6,"n/a") | D27: =IF($B27>D$24,(SUMPRODUCT(DCF_Base!$C$25:$L$25/(1+$B27)^DCF_Base!$C$4:$L$4)+MAX(0,MIN(DCF_Base!$B$34*(1+D$24)/($B27-D$24),Assumptions!$B$4*DCF_Base!$B$34))/(1+$B27)^10+Assumptions!$B$5)/Assumptions!$B$6,"n/a") | E27: =IF($B27>E$24,(SUMPRODUCT(DCF_Base!$C$25:$L$25/(1+$B27)^DCF_Base!$C$4:$L$4)+MAX(0,MIN(DCF_Base!$B$34*(1+E$24)/($B27-E$24),Assumptions!$B$4*DCF_Base!$B$34))/(1+$B27)^10+Assumptions!$B$5)/Assumptions!$B$6,"n/a") | F27: =IF($B27>F$24,(SUMPRODUCT(DCF_Base!$C$25:$L$25/(1+$B27)^DCF_Base!$C$4:$L$4)+MAX(0,MIN(DCF_Base!$B$34*(1+F$24)/($B27-F$24),Assumptions!$B$4*DCF_Base!$B$34))/(1+$B27)^10+Assumptions!$B$5)/Assumptions!$B$6,"n/a") | G27: =IF($B27>G$24,(SUMPRODUCT(DCF_Base!$C$25:$L$25/(1+$B27)^DCF_Base!$C$4:$L$4)+MAX(0,MIN(DCF_Base!$B$34*(1+G$24)/($B27-G$24),Assumptions!$B$4*DCF_Base!$B$34))/(1+$B27)^10+Assumptions!$B$5)/Assumptions!$B$6,"n/a")
B28: 0.17 | C28: =IF($B28>C$24,(SUMPRODUCT(DCF_Base!$C$25:$L$25/(1+$B28)^DCF_Base!$C$4:$L$4)+MAX(0,MIN(DCF_Base!$B$34*(1+C$24)/($B28-C$24),Assumptions!$B$4*DCF_Base!$B$34))/(1+$B28)^10+Assumptions!$B$5)/Assumptions!$B$6,"n/a") | D28: =IF($B28>D$24,(SUMPRODUCT(DCF_Base!$C$25:$L$25/(1+$B28)^DCF_Base!$C$4:$L$4)+MAX(0,MIN(DCF_Base!$B$34*(1+D$24)/($B28-D$24),Assumptions!$B$4*DCF_Base!$B$34))/(1+$B28)^10+Assumptions!$B$5)/Assumptions!$B$6,"n/a") | E28: =IF($B28>E$24,(SUMPRODUCT(DCF_Base!$C$25:$L$25/(1+$B28)^DCF_Base!$C$4:$L$4)+MAX(0,MIN(DCF_Base!$B$34*(1+E$24)/($B28-E$24),Assumptions!$B$4*DCF_Base!$B$34))/(1+$B28)^10+Assumptions!$B$5)/Assumptions!$B$6,"n/a") | F28: =IF($B28>F$24,(SUMPRODUCT(DCF_Base!$C$25:$L$25/(1+$B28)^DCF_Base!$C$4:$L$4)+MAX(0,MIN(DCF_Base!$B$34*(1+F$24)/($B28-F$24),Assumptions!$B$4*DCF_Base!$B$34))/(1+$B28)^10+Assumptions!$B$5)/Assumptions!$B$6,"n/a") | G28: =IF($B28>G$24,(SUMPRODUCT(DCF_Base!$C$25:$L$25/(1+$B28)^DCF_Base!$C$4:$L$4)+MAX(0,MIN(DCF_Base!$B$34*(1+G$24)/($B28-G$24),Assumptions!$B$4*DCF_Base!$B$34))/(1+$B28)^10+Assumptions!$B$5)/Assumptions!$B$6,"n/a")
B29: 0.18 | C29: =IF($B29>C$24,(SUMPRODUCT(DCF_Base!$C$25:$L$25/(1+$B29)^DCF_Base!$C$4:$L$4)+MAX(0,MIN(DCF_Base!$B$34*(1+C$24)/($B29-C$24),Assumptions!$B$4*DCF_Base!$B$34))/(1+$B29)^10+Assumptions!$B$5)/Assumptions!$B$6,"n/a") | D29: =IF($B29>D$24,(SUMPRODUCT(DCF_Base!$C$25:$L$25/(1+$B29)^DCF_Base!$C$4:$L$4)+MAX(0,MIN(DCF_Base!$B$34*(1+D$24)/($B29-D$24),Assumptions!$B$4*DCF_Base!$B$34))/(1+$B29)^10+Assumptions!$B$5)/Assumptions!$B$6,"n/a") | E29: =IF($B29>E$24,(SUMPRODUCT(DCF_Base!$C$25:$L$25/(1+$B29)^DCF_Base!$C$4:$L$4)+MAX(0,MIN(DCF_Base!$B$34*(1+E$24)/($B29-E$24),Assumptions!$B$4*DCF_Base!$B$34))/(1+$B29)^10+Assumptions!$B$5)/Assumptions!$B$6,"n/a") | F29: =IF($B29>F$24,(SUMPRODUCT(DCF_Base!$C$25:$L$25/(1+$B29)^DCF_Base!$C$4:$L$4)+MAX(0,MIN(DCF_Base!$B$34*(1+F$24)/($B29-F$24),Assumptions!$B$4*DCF_Base!$B$34))/(1+$B29)^10+Assumptions!$B$5)/Assumptions!$B$6,"n/a") | G29: =IF($B29>G$24,(SUMPRODUCT(DCF_Base!$C$25:$L$25/(1+$B29)^DCF_Base!$C$4:$L$4)+MAX(0,MIN(DCF_Base!$B$34*(1+G$24)/($B29-G$24),Assumptions!$B$4*DCF_Base!$B$34))/(1+$B29)^10+Assumptions!$B$5)/Assumptions!$B$6,"n/a")
