Workbook

Sheet DCF Model
A1: MA DCF Valuation Model
A2: Gray cells are INPUTS - adjust to see valuation change
A4: KEY INPUTS
A5: Current Stock Price | B5: 530
A6: Shares Outstanding (M) | B6: 927
A7: Cash & Equivalents (M) | B7: 8442
A8: Total Debt (M) | B8: 18226
A9: Net Debt (M) | B9: =B8-B7 -> 0
A10: Base Year FCF (M) | B10: 13586
A12: WACC | B12: 0.1
A13: Terminal Growth Rate | B13: 0.03
A14: FCF Margin | B14: 0.482
A16: GROWTH ASSUMPTIONS | B16: Year 1 | C16: Year 2 | D16: Year 3 | E16: Year 4 | F16: Year 5
A17: FCF Growth Rate | B17: 0.12 | C17: 0.11 | D17: 0.1 | E17: 0.09 | F17: 0.07
A19: PROJECTIONS
B20: Base | C20: Year 1 | D20: Year 2 | E20: Year 3 | F20: Year 4 | G20: Year 5
A21: Free Cash Flow | B21: =B10 -> 0 | C21: =B21*(1+B17) -> 0 | D21: =C21*(1+C17) -> 0 | E21: =D21*(1+D17) -> 0 | F21: =E21*(1+E17) -> 0 | G21: =F21*(1+F17) -> 0
A22: Discount Factor | C22: =1/(1+$B$12)^1 -> 0 | D22: =1/(1+$B$12)^2 -> 0 | E22: =1/(1+$B$12)^3 -> 0 | F22: =1/(1+$B$12)^4 -> 0 | G22: =1/(1+$B$12)^5 -> 0
A23: PV of FCF | C23: =C21*C22 -> 0 | D23: =D21*D22 -> 0 | E23: =E21*E22 -> 0 | F23: =F21*F22 -> 0 | G23: =G21*G22 -> 0
A25: VALUATION
A26: Sum of PV of FCF | B26: =SUM(C23:G23) -> 0
A27: Terminal FCF (Year 5 * (1+g)) | B27: =G21*(1+$B$13) -> 0
A28: Terminal Value | B28: =B27/($B$12-$B$13) -> 0
A29: PV of Terminal Value | B29: =B28*G22 -> 0
A30: Enterprise Value | B30: =B26+B29 -> 0
A31: Less: Net Debt | B31: =B9 -> 0
A32: Equity Value | B32: =B30-B31 -> 0
A33: INTRINSIC VALUE/SHARE | B33: =B32/B6 -> 0
A34: Upside/(Downside) | B34: =(B33-B5)/B5 -> 0
A36: ENTRY PRICE ANALYSIS
A37: Terminal Value per Share | B37: =B28/B6 -> 0
A38: Entry Price (15% CAGR) | B38: =B37/(1.15^5) -> 0
A39: Discount from Current Price | B39: =(B38-B5)/B5 -> 0
A41: SCENARIO ANALYSIS
A42: Scenario | B42: Growth Y1-Y5 | C42: WACC | D42: Term G | E42: FCF Y5 | F42: Terminal Val | G42: Intrinsic Val | H42: Upside
A43: Bull Case | B43: 18%, 16%, 14%, 12%, 10% | C43: 0.09 | D43: 0.035 | E43: 26118.436 | F43: 491501.48 | G43: 519.65208 | H43: =(G43-$B$5)/$B$5 -> 0
A44: Base Case | B44: 12%, 11%, 10%, 9%, 7% | C44: =B12 -> 0 | D44: =B13 -> 0 | E44: =G21 -> 0 | F44: =B28 -> 0 | G44: =B33 -> 0 | H44: =B34 -> 0
A45: Bear Case | B45: 7%, 6%, 5%, 4%, 3% | C45: 0.115 | D45: 0.025 | E45: 17331.698 | F45: 197388.78 | G45: 202.37841 | H45: =(G45-$B$5)/$B$5 -> 0
A47: Probability Weighted IV | B47: Bull 25%, Base 50%, Bear 25% | G47: =G43*0.25+G44*0.50+G45*0.25 -> 0 | H47: =(G47-$B$5)/$B$5 -> 0
A49: HISTORICAL METRICS (FY2024)
...

Sheet Sensitivity
A1: Sensitivity Analysis
A2: Intrinsic Value per Share by WACC & Terminal Growth
A4: WACC \ Term G | B4: 0.02 | C4: 0.025 | D4: 0.03 | E4: 0.035 | F4: 0.04
A5: 0.08 | B5: =(('DCF Model'!$G$21*(1+0.02)/(0.08-0.02))/(1+0.08)^5 + 'DCF Model'!$B$26 - 'DCF Model'!$B$9)/'DCF Model'!$B$6 -> 0 | C5: =(('DCF Model'!$G$21*(1+0.025)/(0.08-0.025))/(1+0.08)^5 + 'DCF Model'!$B$26 - 'DCF Model'!$B$9)/'DCF Model'!$B$6 -> 0 | D5: =(('DCF Model'!$G$21*(1+0.03)/(0.08-0.03))/(1+0.08)^5 + 'DCF Model'!$B$26 - 'DCF Model'!$B$9)/'DCF Model'!$B$6 -> 0 | E5: =(('DCF Model'!$G$21*(1+0.035)/(0.08-0.035))/(1+0.08)^5 + 'DCF Model'!$B$26 - 'DCF Model'!$B$9)/'DCF Model'!$B$6 -> 0 | F5: =(('DCF Model'!$G$21*(1+0.04)/(0.08-0.04))/(1+0.08)^5 + 'DCF Model'!$B$26 - 'DCF Model'!$B$9)/'DCF Model'!$B$6 -> 0
A6: 0.09 | B6: =(('DCF Model'!$G$21*(1+0.02)/(0.09-0.02))/(1+0.09)^5 + 'DCF Model'!$B$26 - 'DCF Model'!$B$9)/'DCF Model'!$B$6 -> 0 | C6: =(('DCF Model'!$G$21*(1+0.025)/(0.09-0.025))/(1+0.09)^5 + 'DCF Model'!$B$26 - 'DCF Model'!$B$9)/'DCF Model'!$B$6 -> 0 | D6: =(('DCF Model'!$G$21*(1+0.03)/(0.10-0.03))/(1+0.10)^5 + 'DCF Model'!$B$26 - 'DCF Model'!$B$9)/'DCF Model'!$B$6 -> 0 | E6: =(('DCF Model'!$G$21*(1+0.035)/(0.09-0.035))/(1+0.09)^5 + 'DCF Model'!$B$26 - 'DCF Model'!$B$9)/'DCF Model'!$B$6 -> 0 | F6: =(('DCF Model'!$G$21*(1+0.04)/(0.09-0.04))/(1+0.09)^5 + 'DCF Model'!$B$26 - 'DCF Model'!$B$9)/'DCF Model'!$B$6 -> 0
A7: 0.1 | B7: =(('DCF Model'!$G$21*(1+0.02)/(0.1-0.02))/(1+0.1)^5 + 'DCF Model'!$B$26 - 'DCF Model'!$B$9)/'DCF Model'!$B$6 -> 0 | C7: =(('DCF Model'!$G$21*(1+0.025)/(0.1-0.025))/(1+0.1)^5 + 'DCF Model'!$B$26 - 'DCF Model'!$B$9)/'DCF Model'!$B$6 -> 0 | D7: =(('DCF Model'!$G$21*(1+0.03)/(0.1-0.03))/(1+0.1)^5 + 'DCF Model'!$B$26 - 'DCF Model'!$B$9)/'DCF Model'!$B$6 -> 0 | E7: =(('DCF Model'!$G$21*(1+0.035)/(0.1-0.035))/(1+0.1)^5 + 'DCF Model'!$B$26 - 'DCF Model'!$B$9)/'DCF Model'!$B$6 -> 0 | F7: =(('DCF Model'!$G$21*(1+0.04)/(0.1-0.04))/(1+0.1)^5 + 'DCF Model'!$B$26 - 'DCF Model'!$B$9)/'DCF Model'!$B$6 -> 0
A8: 0.11 | B8: =(('DCF Model'!$G$21*(1+0.02)/(0.11-0.02))/(1+0.11)^5 + 'DCF Model'!$B$26 - 'DCF Model'!$B$9)/'DCF Model'!$B$6 -> 0 | C8: =(('DCF Model'!$G$21*(1+0.025)/(0.11-0.025))/(1+0.11)^5 + 'DCF Model'!$B$26 - 'DCF Model'!$B$9)/'DCF Model'!$B$6 -> 0 | D8: =(('DCF Model'!$G$21*(1+0.03)/(0.11-0.03))/(1+0.11)^5 + 'DCF Model'!$B$26 - 'DCF Model'!$B$9)/'DCF Model'!$B$6 -> 0 | E8: =(('DCF Model'!$G$21*(1+0.035)/(0.11-0.035))/(1+0.11)^5 + 'DCF Model'!$B$26 - 'DCF Model'!$B$9)/'DCF Model'!$B$6 -> 0 | F8: =(('DCF Model'!$G$21*(1+0.04)/(0.11-0.04))/(1+0.11)^5 + 'DCF Model'!$B$26 - 'DCF Model'!$B$9)/'DCF Model'!$B$6 -> 0
A9: 0.12 | B9: =(('DCF Model'!$G$21*(1+0.02)/(0.12-0.02))/(1+0.12)^5 + 'DCF Model'!$B$26 - 'DCF Model'!$B$9)/'DCF Model'!$B$6 -> 0 | C9: =(('DCF Model'!$G$21*(1+0.025)/(0.12-0.025))/(1+0.12)^5 + 'DCF Model'!$B$26 - 'DCF Model'!$B$9)/'DCF Model'!$B$6 -> 0 | D9: =(('DCF Model'!$G$21*(1+0.03)/(0.12-0.03))/(1+0.12)^5 + 'DCF Model'!$B$26 - 'DCF Model'!$B$9)/'DCF Model'!$B$6 -> 0 | E9: =(('DCF Model'!$G$21*(1+0.035)/(0.12-0.035))/(1+0.12)^5 + 'DCF Model'!$B$26 - 'DCF Model'!$B$9)/'DCF Model'!$B$6 -> 0 | F9: =(('DCF Model'!$G$21*(1+0.04)/(0.12-0.04))/(1+0.12)^5 + 'DCF Model'!$B$26 - 'DCF Model'!$B$9)/'DCF Model'!$B$6 -> 0

Sheet Historical
A1: Historical Growth Rates
A3: Metric | B3: 3-Year CAGR | C3: 5-Year CAGR | D3: Notes
A4: Revenue | B4: 0.141 | C4: 0.108 | D4: FY2019-2024
A5: EPS | B5: 0.165 | C5: 0.118 | D5: Strong buyback impact
A6: Equity | B6: -0.039 | C6: 0.019 | D6: Distorted by buybacks
A7: FCF | B7: 0.163 | C7: 0.128 | D7: ~48% FCF margin
A9: Selected Growth Rate: | B9: 0.108
A10: Source: | B10: revenue_5yr_cagr
A12: Historical Annual Data (FY2019-2024)
A13: Year | B13: Revenue (M) | C13: Net Income (M) | D13: FCF (M) | E13: EPS | F13: Equity (M)
A14: FY2019 | B14: 16883 | C14: 8118 | D14: 7455 | E14: 7.94 | F14: 5893
A15: FY2020 | B15: 15301 | C15: 6411 | D15: 6516 | E15: 6.37 | F15: 6391
A16: FY2021 | B16: 18884 | C16: 8687 | D16: 8649 | E16: 8.76 | F16: 7312
A17: FY2022 | B17: 22237 | C17: 9930 | D17: 10098 | E17: 10.22 | F17: 6298
A18: FY2023 | B18: 25098 | C18: 11195 | D18: 10892 | E18: 11.83 | F18: 6929
A19: FY2024 | B19: 28167 | C19: 12874 | D19: 13586 | E19: 13.89 | F19: 6485

Sheet Assumptions
A1: DCF Model Assumptions & Notes
A3: BASE CASE RATIONALE:
A4: Conservative deceleration from historical 10.8% revenue CAGR; reflects maturity in developed markets offset by continued emerging market penetration, value-added services growth, and B2B opportunity
A6: BULL CASE RATIONALE:
A7: Assumes value-added services accelerate (20%+ growth), cross-border volumes remain strong, successful B2B penetration, margin expansion from operating leverage, and limited regulatory headwinds
A9: BEAR CASE RATIONALE:
A10: Reflects severe interchange fee regulation, recession impact on consumer spending and cross-border travel, increased competition from national payment schemes and fintechs, margin pressure from customer incentives
A12: KEY SENSITIVITIES:
A13: • WACC assumption: Each 1% change in WACC changes IV by ~$40-60/share
A14: • Terminal growth: Each 0.5% change in terminal growth changes IV by ~$20-35/share
A15: • FCF margin: Each 1% change in margin changes IV by ~$15-20/share
A16: • Growth rates: Near-term growth most impactful due to discounting
... A25: At $530, Mastercard appears overvalued relative to DCF intrinsic value of $277 (48% downside). Stock has benefited from multiple expansion in recent years. While business fundamentals remain strong with excellent FCF generation and growth opportunities, current price requires sustained double-digit growth that may be challenging given maturity in developed markets and regulatory pressures. Entry price of $171 (68% below current) would provide 15% CAGR to terminal value.
