Workbook

Sheet Company Overview
A1: Atlassian Corporation (NASDAQ: TEAM)
A2: Deep Dive & DCF Valuation — SBC-Adjusted
A3: As of February 24, 2026
A5: Company Snapshot
A6: Headquarters | B6: Sydney, Australia
A7: CEO & Co-Founder | B7: Mike Cannon-Brookes
A8: Fiscal Year End | B8: June 30
A9: Employees | B9: ~13,000
A10: Customers | B10: 350,000+
A11: Cloud ARR Customers >$10K | B11: 49,449+ (as of Q2 FY25)
A12: AI Monthly Active Users (Rovo) | B12: 5,000,000+
A14: Historical Financials ($mm)
B15: FY2022 | C15: FY2023 | D15: FY2024 | E15: FY2025 | F15: Q2 FY2026 (TTM)
A16: Total Revenue | B16: 2803 | C16: 3535 | D16: 4359 | E16: 5215 | F16: 5760
A17: YoY Growth | B17: N/A | C17: 0.261 | D17: 0.233 | E17: 0.197 | F17: N/A
A18: Gross Profit | B18: 2350 | C18: 2901 | D18: 3555 | E18: 4320 | F18: N/A
A19: Gross Margin | B19: 0.838 | C19: 0.821 | D19: 0.816 | E19: 0.828 | F19: N/A
A20: GAAP Operating Income | B20: 70 | C20: -345 | D20: -117 | E20: -130 | F20: N/A
A21: Non-GAAP Operating Margin | B21: N/A | C21: N/A | D21: 0.2 | E21: 0.22 | F21: 0.271
A22: Stock-Based Compensation | B22: N/A | C22: N/A | D22: 1081 | E22: 1362 | F22: N/A
A23: SBC as % of Revenue | B23: N/A | C23: N/A | D23: 0.248 | E23: 0.261 | F23: N/A
A24: Free Cash Flow | B24: 746 | C24: 842 | D24: 1415 | E24: 1416 | F24: 1456
A25: FCF Margin | B25: 0.266 | C25: 0.238 | D25: 0.325 | E25: 0.272 | F25: 0.253
A27: Market Data (as of Feb 2026)
A28: Current Stock Price | B28: $68.81
A29: Shares Outstanding | B29: 263.7M
A30: Market Capitalization | B30: ~$18.1B
A31: 52-Week Range | B31: $75.01 - $298.63
A32: Total Debt | B32: $1.24B
A33: Cash & Equivalents | B33: $2.51B
A34: Enterprise Value | B34: ~$16.8B
A35: P/S (TTM) | B35: ~3.1x
A37: Key Risks (SBC Focus)
A38: • SBC is 26% of revenue ($1.36B FY2025) — growing 25%+ YoY, diluting shareholders
A39: • GAAP operating loss of $130M despite $5.2B revenue — SBC is the primary reason
A40: • Buybacks ($800M+ in H1 FY2026) consume real cash to offset dilution
A41: • AI / vibe-coding disruption risk to developer tool demand (Klarna narrative)
A42: • Data Center revenue is a melting ice cube — support ends March 2029
A43: • Dual-class share structure limits shareholder governance

Sheet DCF Model
A1: Atlassian (TEAM) — SBC-Adjusted DCF Model
A2: All figures in $mm unless noted. Blue = input. Red = SBC adjustment.
A4: KEY ASSUMPTIONS
A5: Tax Rate | B5: 0.26 | C5: Source: TEAM 10-K FY2025, non-GAAP tax rate
A6: Risk-Free Rate | B6: 0.0417 | C6: Source: 10-Year US Treasury, Feb 2026
A7: Equity Risk Premium | B7: 0.0418 | C7: Source: Damodaran, Jan 2026
A8: Beta (adjusted) | B8: 1.4 | C8: Adjusted for 70% drawdown, SaaS repricing risk
A9: Cost of Equity (CAPM) | B9: =B6+B8*B7 -> 0.10022 | C9: Formula: Rf + Beta × ERP
A10: Cost of Debt (pre-tax) | B10: 0.055 | C10: Source: ValueInvesting.io
A11: Debt Weight | B11: 0.0226 | C11: Source: Alpha Spread
A12: WACC | B12: =B9*(1-B11)+B10*(1-B5)*B11 -> 0.098874848 | C12: Formula
A13: Terminal Growth Rate | B13: 0.03 | C13: Assumption: long-run GDP + inflation
A14: Shares Outstanding (mm) | B14: 263.7 | C14: Source: Latest filing
A15: Current Stock Price ($) | B15: 68.81 | C15: Source: Market data, Feb 24, 2026
A16: Net Debt ($mm) | B16: -1270 | C16: Debt $1,240 minus Cash $2,510
A18: REVENUE PROJECTION
B19: Base (FY25) | C19: FY2026E | D19: FY2027E | E19: FY2028E | F19: FY2029E | G19: FY2030E | H19: FY2031E | I19: FY2032E | J19: FY2033E | K19: FY2034E | L19: FY2035E
A20: Revenue Growth Rate | B20: 0.197 | C20: 0.22 | D20: 0.2 | E20: 0.18 | F20: 0.16 | G20: 0.14 | H20: 0.12 | I20: 0.1 | J20: 0.08 | K20: 0.06 | L20: 0.05
A21: Total Revenue | B21: 5215 | C21: =B21*(1+C20) -> 6362.3 | D21: =C21*(1+D20) -> 7634.76 | E21: =D21*(1+E20) -> 9009.0168 | F21: =E21*(1+F20) -> 10450.459 | G21: =F21*(1+G20) -> 11913.524 | H21: =G21*(1+H20) -> 13343.147 | I21: =H21*(1+I20) -> 14677.461 | J21: =I21*(1+J20) -> 15851.658 | ... L21: =K21*(1+L20) -> 17642.896
A23: FREE CASH FLOW BUILD (Non-GAAP)
A24: Non-GAAP Operating Margin | B24: 0.22 | C24: 0.255 | D24: 0.27 | E24: 0.285 | F24: 0.3 | G24: 0.31 | H24: 0.32 | I24: 0.325 | J24: 0.33 | K24: 0.335 | L24: 0.34
A25: Non-GAAP Operating Income | B25: =B21*B24 -> 1147.3 | C25: =C21*C24 -> 1622.3865 | D25: =D21*D24 -> 2061.3852 | E25: =E21*E24 -> 2567.5698 | F25: =F21*F24 -> 3135.1378 | G25: =G21*G24 -> 3693.1924 | H25: =H21*H24 -> 4269.8069 | I25: =I21*I24 -> 4770.1749 | ... L25: =L21*L24 -> 5998.5845
A26: Less: Taxes | B26: =-B25*$B$5 -> -298.298 | C26: =-C25*$B$5 -> -421.82049 | D26: =-D25*$B$5 -> -535.96015 | E26: =-E25*$B$5 -> -667.56814 | F26: =-F25*$B$5 -> -815.13584 | G26: =-G25*$B$5 -> -960.23002 | H26: =-H25*$B$5 -> -1110.1498 | I26: =-I25*$B$5 -> -1240.2455 | ... L26: =-L25*$B$5 -> -1559.632
A27: NOPAT | B27: =B25+B26 -> 849.002 | C27: =C25+C26 -> 1200.566 | D27: =D25+D26 -> 1525.425 | E27: =E25+E26 -> 1900.0016 | F27: =F25+F26 -> 2320.002 | G27: =G25+G26 -> 2732.9624 | H27: =H25+H26 -> 3159.6571 | I27: =I25+I26 -> 3529.9295 | ... L27: =L25+L26 -> 4438.9525
A28: Add: D&A + Non-cash Adj (% Rev) | B28: 0.04 | C28: 0.04 | D28: 0.035 | E28: 0.035 | F28: 0.03 | G28: 0.03 | H28: 0.025 | I28: 0.025 | J28: 0.02 | K28: 0.02 | L28: 0.02
A29: D&A + Non-cash adjustments | B29: =B21*B28 -> 208.6 | C29: =C21*C28 -> 254.492 | D29: =D21*D28 -> 267.2166 | E29: =E21*E28 -> 315.31559 | F29: =F21*F28 -> 313.51378 | G29: =G21*G28 -> 357.40571 | H29: =H21*H28 -> 333.57867 | I29: =I21*I28 -> 366.93653 | ... L29: =L21*L28 -> 352.85791
A30: Less: CapEx (% of Rev) | B30: 0.009 | C30: 0.009 | D30: 0.009 | E30: 0.008 | F30: 0.008 | G30: 0.008 | H30: 0.007 | I30: 0.007 | J30: 0.007 | K30: 0.007 | L30: 0.007
A31: CapEx | B31: =-B21*B30 -> -46.935 | C31: =-C21*C30 -> -57.2607 | D31: =-D21*D30 -> -68.71284 | E31: =-E21*E30 -> -72.072134 | F31: =-F21*F30 -> -83.603676 | G31: =-G21*G30 -> -95.308191 | H31: =-H21*H30 -> -93.402027 | I31: =-I21*I30 -> -102.74223 | ... L31: =-L21*L30 -> -123.50027
A32: Change in WC (% Rev) | B32: 0.02 | C32: 0.02 | D32: 0.015 | E32: 0.015 | F32: 0.01 | G32: 0.01 | H32: 0.01 | I32: 0.01 | J32: 0.005 | K32: 0.005 | L32: 0.005
A33: Working Capital Benefit | B33: =B21*B32 -> 104.3 | C33: =C21*C32 -> 127.246 | D33: =D21*D32 -> 114.5214 | E33: =E21*E32 -> 135.13525 | F33: =F21*F32 -> 104.50459 | G33: =G21*G32 -> 119.13524 | H33: =H21*H32 -> 133.43147 | I33: =I21*I32 -> 146.77461 | ... L33: =L21*L32 -> 88.214478
A34: Standard UFCF (excl. SBC cost) | B34: =B27+B29+B31+B33 -> 1114.967 | C34: =C27+C29+C31+C33 -> 1525.0433 | D34: =D27+D29+D31+D33 -> 1838.4502 | E34: =E27+E29+E31+E33 -> 2278.3803 | F34: =F27+F29+F31+F33 -> 2654.4167 | G34: =G27+G29+G31+G33 -> 3114.1951 | H34: =H27+H29+H31+H33 -> 3533.2652 | I34: =I27+I29+I31+I33 -> 3940.8984 | ... L34: =L27+L29+L31+L33 -> 4756.5247
A35: Standard FCF Margin | B35: =B34/B21 -> 0.2138 | C35: =C34/C21 -> 0.2397 | D35: =D34/D21 -> 0.2408 | E35: =E34/E21 -> 0.2529 | F35: =F34/F21 -> 0.254 | G35: =G34/G21 -> 0.2614 | H35: =H34/H21 -> 0.2648 | I35: =I34/I21 -> 0.2685 | ... L35: =L34/L21 -> 0.2696
A37: SBC ADJUSTMENT — REAL ECONOMIC COST OF DILUTION
A38: SBC as % of Revenue | B38: 0.261 | C38: 0.24 | D38: 0.22 | E38: 0.2 | F38: 0.18 | G38: 0.17 | H38: 0.16 | I38: 0.15 | J38: 0.14 | K38: 0.13 | L38: 0.12
A39: Gross SBC Expense | B39: =B21*B38 -> 1361.115 | C39: =C21*C38 -> 1526.952 | D39: =D21*D38 -> 1679.6472 | E39: =E21*E38 -> 1801.8034 | F39: =F21*F38 -> 1881.0827 | G39: =G21*G38 -> 2025.299 | H39: =H21*H38 -> 2134.9035 | I39: =I21*I38 -> 2201.6192 | ... L39: =L21*L38 -> 2117.1475
A40: Buyback Offset (% of SBC) | B40: 0 | C40: 0.5 | D40: 0.5 | E40: 0.5 | F40: 0.5 | G40: 0.55 | H40: 0.55 | I40: 0.6 | J40: 0.6 | K40: 0.65 | L40: 0.65
A41: Net SBC Cost to Shareholders | B41: =-B39*(1-B40) -> -1361.115 | C41: =-C39*(1-C40) -> -763.476 | D41: =-D39*(1-D40) -> -839.8236 | E41: =-E39*(1-E40) -> -900.90168 | F41: =-F39*(1-F40) -> -940.54135 | G41: =-G39*(1-G40) -> -911.38457 | H41: =-H39*(1-H40) -> -960.70656 | I41: =-I39*(1-I40) -> -880.64768 | ... L41: =-L39*(1-L40) -> -741.00162
A42: Less: Buyback Cash Spent | B42: =-B39*B40 -> 0 | C42: =-C39*C40 -> -763.476 | D42: =-D39*D40 -> -839.8236 | E42: =-E39*E40 -> -900.90168 | F42: =-F39*F40 -> -940.54135 | G42: =-G39*G40 -> -1113.9145 | H42: =-H39*H40 -> -1174.1969 | I42: =-I39*I40 -> -1320.9715 | ... L42: =-L39*L40 -> -1376.1459
A43: Total SBC Drag (dilution + buybacks) | B43: =B41+B42 -> -1361.115 | C43: =C41+C42 -> -1526.952 | D43: =D41+D42 -> -1679.6472 | E43: =E41+E42 -> -1801.8034 | F43: =F41+F42 -> -1881.0827 | G43: =G41+G42 -> -2025.299 | H43: =H41+H42 -> -2134.9035 | I43: =I41+I42 -> -2201.6192 | ... L43: =L41+L42 -> -2117.1475
A44: SBC-ADJUSTED UFCF | B44: =B34+B43 -> -246.148 | C44: =C34+C43 -> -1.90869 | D44: =D34+D43 -> 158.80301 | E44: =E34+E43 -> 476.57699 | F44: =F34+F43 -> 773.334 | G44: =G34+G43 -> 1088.8961 | H44: =H34+H43 -> 1398.3618 | I44: =I34+I43 -> 1739.2792 | ... L44: =L34+L43 -> 2639.3772
...

Sheet Sensitivity Analysis
A1: Sensitivity Analysis — SBC-Adjusted Implied Price
A3: WACC vs. Terminal Growth Rate (SBC-Adjusted)
A4: WACC \ TGR | B4: 0.02 | C4: 0.025 | D4: 0.03 | E4: 0.035 | F4: 0.04
A5: 0.08 | B5: =('DCF Model'!D62 * ('DCF Model'!B12/A5) + 'DCF Model'!L44*(1+B4)/(A5-B4)/(1+A5)^10 - 'DCF Model'!B16) / 'DCF Model'!B14 -> 113.19756 | C5: =('DCF Model'!D62 * ('DCF Model'!B12/A5) + 'DCF Model'!L44*(1+C4)/(A5-C4)/(1+A5)^10 - 'DCF Model'!B16) / 'DCF Model'!B14 -> 120.78392 | D5: =('DCF Model'!D62 * ('DCF Model'!B12/A5) + 'DCF Model'!L44*(1+D4)/(A5-D4)/(1+A5)^10 - 'DCF Model'!B16) / 'DCF Model'!B14 -> 129.88756 | E5: =('DCF Model'!D62 * ('DCF Model'!B12/A5) + 'DCF Model'!L44*(1+E4)/(A5-E4)/(1+A5)^10 - 'DCF Model'!B16) / 'DCF Model'!B14 -> 141.01422 | F5: =('DCF Model'!D62 * ('DCF Model'!B12/A5) + 'DCF Model'!L44*(1+F4)/(A5-F4)/(1+A5)^10 - 'DCF Model'!B16) / 'DCF Model'!B14 -> 154.92256
A6: 0.085 | B6: =('DCF Model'!D62 * ('DCF Model'!B12/A6) + 'DCF Model'!L44*(1+B4)/(A6-B4)/(1+A6)^10 - 'DCF Model'!B16) / 'DCF Model'!B14 -> 102.11177 | C6: =('DCF Model'!D62 * ('DCF Model'!B12/A6) + 'DCF Model'!L44*(1+C4)/(A6-C4)/(1+A6)^10 - 'DCF Model'!B16) / 'DCF Model'!B14 -> 108.26962 | D6: =('DCF Model'!D62 * ('DCF Model'!B12/A6) + 'DCF Model'!L44*(1+D4)/(A6-D4)/(1+A6)^10 - 'DCF Model'!B16) / 'DCF Model'!B14 -> 115.54708 | E6: =('DCF Model'!D62 * ('DCF Model'!B12/A6) + 'DCF Model'!L44*(1+E4)/(A6-E4)/(1+A6)^10 - 'DCF Model'!B16) / 'DCF Model'!B14 -> 124.28003 | F6: =('DCF Model'!D62 * ('DCF Model'!B12/A6) + 'DCF Model'!L44*(1+F4)/(A6-F4)/(1+A6)^10 - 'DCF Model'!B16) / 'DCF Model'!B14 -> 134.95363
A7: 0.09 | B7: =('DCF Model'!D62 * ('DCF Model'!B12/A7) + 'DCF Model'!L44*(1+B4)/(A7-B4)/(1+A7)^10 - 'DCF Model'!B16) / 'DCF Model'!B14 -> 92.705171 | C7: =('DCF Model'!D62 * ('DCF Model'!B12/A7) + 'DCF Model'!L44*(1+C4)/(A7-C4)/(1+A7)^10 - 'DCF Model'!B16) / 'DCF Model'!B14 -> 97.769378 | D7: =('DCF Model'!D62 * ('DCF Model'!B12/A7) + 'DCF Model'!L44*(1+D4)/(A7-D4)/(1+A7)^10 - 'DCF Model'!B16) / 'DCF Model'!B14 -> 103.67762 | E7: =('DCF Model'!D62 * ('DCF Model'!B12/A7) + 'DCF Model'!L44*(1+E4)/(A7-E4)/(1+A7)^10 - 'DCF Model'!B16) / 'DCF Model'!B14 -> 110.66009 | F7: =('DCF Model'!D62 * ('DCF Model'!B12/A7) + 'DCF Model'!L44*(1+F4)/(A7-F4)/(1+A7)^10 - 'DCF Model'!B16) / 'DCF Model'!B14 -> 119.03905
A8: 0.095 | B8: =('DCF Model'!D62 * ('DCF Model'!B12/A8) + 'DCF Model'!L44*(1+B4)/(A8-B4)/(1+A8)^10 - 'DCF Model'!B16) / 'DCF Model'!B14 -> 84.642515 | C8: =('DCF Model'!D62 * ('DCF Model'!B12/A8) + 'DCF Model'!L44*(1+C4)/(A8-C4)/(1+A8)^10 - 'DCF Model'!B16) / 'DCF Model'!B14 -> 88.854385 | D8: =('DCF Model'!D62 * ('DCF Model'!B12/A8) + 'DCF Model'!L44*(1+D4)/(A8-D4)/(1+A8)^10 - 'DCF Model'!B16) / 'DCF Model'!B14 -> 93.714235 | E8: =('DCF Model'!D62 * ('DCF Model'!B12/A8) + 'DCF Model'!L44*(1+E4)/(A8-E4)/(1+A8)^10 - 'DCF Model'!B16) / 'DCF Model'!B14 -> 99.38406 | F8: =('DCF Model'!D62 * ('DCF Model'!B12/A8) + 'DCF Model'!L44*(1+F4)/(A8-F4)/(1+A8)^10 - 'DCF Model'!B16) / 'DCF Model'!B14 -> 106.08476
A9: 0.1 | B9: =('DCF Model'!D62 * ('DCF Model'!B12/A9) + 'DCF Model'!L44*(1+B4)/(A9-B4)/(1+A9)^10 - 'DCF Model'!B16) / 'DCF Model'!B14 -> 77.671246 | C9: =('DCF Model'!D62 * ('DCF Model'!B12/A9) + 'DCF Model'!L44*(1+C4)/(A9-C4)/(1+A9)^10 - 'DCF Model'!B16) / 'DCF Model'!B14 -> 81.208579 | D9: =('DCF Model'!D62 * ('DCF Model'!B12/A9) + 'DCF Model'!L44*(1+D4)/(A9-D4)/(1+A9)^10 - 'DCF Model'!B16) / 'DCF Model'!B14 -> 85.251245 | E9: =('DCF Model'!D62 * ('DCF Model'!B12/A9) + 'DCF Model'!L44*(1+E4)/(A9-E4)/(1+A9)^10 - 'DCF Model'!B16) / 'DCF Model'!B14 -> 89.91586 | F9: =('DCF Model'!D62 * ('DCF Model'!B12/A9) + 'DCF Model'!L44*(1+F4)/(A9-F4)/(1+A9)^10 - 'DCF Model'!B16) / 'DCF Model'!B14 -> 95.35791
A10: 0.105 | B10: =('DCF Model'!D62 * ('DCF Model'!B12/A10) + 'DCF Model'!L44*(1+B4)/(A10-B4)/(1+A10)^10 - 'DCF Model'!B16) / 'DCF Model'!B14 -> 71.597499 | C10: =('DCF Model'!D62 * ('DCF Model'!B12/A10) + 'DCF Model'!L44*(1+C4)/(A10-C4)/(1+A10)^10 - 'DCF Model'!B16) / 'DCF Model'!B14 -> 74.593845 | D10: =('DCF Model'!D62 * ('DCF Model'!B12/A10) + 'DCF Model'!L44*(1+D4)/(A10-D4)/(1+A10)^10 - 'DCF Model'!B16) / 'DCF Model'!B14 -> 77.989703 | E10: =('DCF Model'!D62 * ('DCF Model'!B12/A10) + 'DCF Model'!L44*(1+E4)/(A10-E4)/(1+A10)^10 - 'DCF Model'!B16) / 'DCF Model'!B14 -> 81.870685 | F10: =('DCF Model'!D62 * ('DCF Model'!B12/A10) + 'DCF Model'!L44*(1+F4)/(A10-F4)/(1+A10)^10 - 'DCF Model'!B16) / 'DCF Model'!B14 -> 86.34874
A11: 0.11 | B11: =('DCF Model'!D62 * ('DCF Model'!B12/A11) + 'DCF Model'!L44*(1+B4)/(A11-B4)/(1+A11)^10 - 'DCF Model'!B16) / 'DCF Model'!B14 -> 66.270014 | C11: =('DCF Model'!D62 * ('DCF Model'!B12/A11) + 'DCF Model'!L44*(1+C4)/(A11-C4)/(1+A11)^10 - 'DCF Model'!B16) / 'DCF Model'!B14 -> 68.827382 | D11: =('DCF Model'!D62 * ('DCF Model'!B12/A11) + 'DCF Model'!L44*(1+D4)/(A11-D4)/(1+A11)^10 - 'DCF Model'!B16) / 'DCF Model'!B14 -> 71.70442 | E11: =('DCF Model'!D62 * ('DCF Model'!B12/A11) + 'DCF Model'!L44*(1+E4)/(A11-E4)/(1+A11)^10 - 'DCF Model'!B16) / 'DCF Model'!B14 -> 74.965063 | F11: =('DCF Model'!D62 * ('DCF Model'!B12/A11) + 'DCF Model'!L44*(1+F4)/(A11-F4)/(1+A11)^10 - 'DCF Model'!B16) / 'DCF Model'!B14 -> 78.691512
A14: SBC % of Revenue vs. Revenue Growth (Implied Price)
A15: SBC% \ Rev Gr | B15: 0.08 | C15: 0.1 | D15: 0.12 | E15: 0.14 | F15: 0.16
A16: 0.1 | B16: =(('DCF Model'!B21*(1+B15)^10*0.32*(1-'DCF Model'!B5)*1.01-'DCF Model'!B21*(1+B15)^10*A16)*(1+'DCF Model'!B13)/('DCF Model'!B12-'DCF Model'!B13)/(1+'DCF Model'!B12)^10+'DCF Model'!B21*(1+B15)^5*(0.28*(1-'DCF Model'!B5)*1.01-A16)*5/(1+'DCF Model'!B12)^5-'DCF Model'!B16)/'DCF Model'!B14 -> 49.335511 | C16: =(('DCF Model'!B21*(1+C15)^10*0.32*(1-'DCF Model'!B5)*1.01-'DCF Model'!B21*(1+C15)^10*A16)*(1+'DCF Model'!B13)/('DCF Model'!B12-'DCF Model'!B13)/(1+'DCF Model'!B12)^10+'DCF Model'!B21*(1+C15)^5*(0.28*(1-'DCF Model'!B5)*1.01-A16)*5/(1+'DCF Model'!B12)^5-'DCF Model'!B16)/'DCF Model'!B14 -> 57.258399 | D16: =(('DCF Model'!B21*(1+D15)^10*0.32*(1-'DCF Model'!B5)*1.01-'DCF Model'!B21*(1+D15)^10*A16)*(1+'DCF Model'!B13)/('DCF Model'!B12-'DCF Model'!B13)/(1+'DCF Model'!B12)^10+'DCF Model'!B21*(1+D15)^5*(0.28*(1-'DCF Model'!B5)*1.01-A16)*5/(1+'DCF Model'!B12)^5-'DCF Model'!B16)/'DCF Model'!B14 -> 66.49216 | E16: =(('DCF Model'!B21*(1+E15)^10*0.32*(1-'DCF Model'!B5)*1.01-'DCF Model'!B21*(1+E15)^10*A16)*(1+'DCF Model'!B13)/('DCF Model'!B12-'DCF Model'!B13)/(1+'DCF Model'!B12)^10+'DCF Model'!B21*(1+E15)^5*(0.28*(1-'DCF Model'!B5)*1.01-A16)*5/(1+'DCF Model'!B12)^5-'DCF Model'!B16)/'DCF Model'!B14 -> 77.232827 | F16: =(('DCF Model'!B21*(1+F15)^10*0.32*(1-'DCF Model'!B5)*1.01-'DCF Model'!B21*(1+F15)^10*A16)*(1+'DCF Model'!B13)/('DCF Model'!B12-'DCF Model'!B13)/(1+'DCF Model'!B12)^10+'DCF Model'!B21*(1+F15)^5*(0.28*(1-'DCF Model'!B5)*1.01-A16)*5/(1+'DCF Model'!B12)^5-'DCF Model'!B16)/'DCF Model'!B14 -> 89.702136
A17: 0.15 | B17: =(('DCF Model'!B21*(1+B15)^10*0.32*(1-'DCF Model'!B5)*1.01-'DCF Model'!B21*(1+B15)^10*A17)*(1+'DCF Model'!B13)/('DCF Model'!B12-'DCF Model'!B13)/(1+'DCF Model'!B12)^10+'DCF Model'!B21*(1+B15)^5*(0.28*(1-'DCF Model'!B5)*1.01-A17)*5/(1+'DCF Model'!B12)^5-'DCF Model'!B16)/'DCF Model'!B14 -> 32.366711 | C17: =(('DCF Model'!B21*(1+C15)^10*0.32*(1-'DCF Model'!B5)*1.01-'DCF Model'!B21*(1+C15)^10*A17)*(1+'DCF Model'!B13)/('DCF Model'!B12-'DCF Model'!B13)/(1+'DCF Model'!B12)^10+'DCF Model'!B21*(1+C15)^5*(0.28*(1-'DCF Model'!B5)*1.01-A17)*5/(1+'DCF Model'!B12)^5-'DCF Model'!B16)/'DCF Model'!B14 -> 37.349497 | D17: =(('DCF Model'!B21*(1+D15)^10*0.32*(1-'DCF Model'!B5)*1.01-'DCF Model'!B21*(1+D15)^10*A17)*(1+'DCF Model'!B13)/('DCF Model'!B12-'DCF Model'!B13)/(1+'DCF Model'!B12)^10+'DCF Model'!B21*(1+D15)^5*(0.28*(1-'DCF Model'!B5)*1.01-A17)*5/(1+'DCF Model'!B12)^5-'DCF Model'!B16)/'DCF Model'!B14 -> 43.165129 | E17: =(('DCF Model'!B21*(1+E15)^10*0.32*(1-'DCF Model'!B5)*1.01-'DCF Model'!B21*(1+E15)^10*A17)*(1+'DCF Model'!B13)/('DCF Model'!B12-'DCF Model'!B13)/(1+'DCF Model'!B12)^10+'DCF Model'!B21*(1+E15)^5*(0.28*(1-'DCF Model'!B5)*1.01-A17)*5/(1+'DCF Model'!B12)^5-'DCF Model'!B16)/'DCF Model'!B14 -> 49.938818 | F17: =(('DCF Model'!B21*(1+F15)^10*0.32*(1-'DCF Model'!B5)*1.01-'DCF Model'!B21*(1+F15)^10*A17)*(1+'DCF Model'!B13)/('DCF Model'!B12-'DCF Model'!B13)/(1+'DCF Model'!B12)^10+'DCF Model'!B21*(1+F15)^5*(0.28*(1-'DCF Model'!B5)*1.01-A17)*5/(1+'DCF Model'!B12)^5-'DCF Model'!B16)/'DCF Model'!B14 -> 57.812228
A18: 0.2 | B18: =(('DCF Model'!B21*(1+B15)^10*0.32*(1-'DCF Model'!B5)*1.01-'DCF Model'!B21*(1+B15)^10*A18)*(1+'DCF Model'!B13)/('DCF Model'!B12-'DCF Model'!B13)/(1+'DCF Model'!B12)^10+'DCF Model'!B21*(1+B15)^5*(0.28*(1-'DCF Model'!B5)*1.01-A18)*5/(1+'DCF Model'!B12)^5-'DCF Model'!B16)/'DCF Model'!B14 -> 15.397912 | C18: =(('DCF Model'!B21*(1+C15)^10*0.32*(1-'DCF Model'!B5)*1.01-'DCF Model'!B21*(1+C15)^10*A18)*(1+'DCF Model'!B13)/('DCF Model'!B12-'DCF Model'!B13)/(1+'DCF Model'!B12)^10+'DCF Model'!B21*(1+C15)^5*(0.28*(1-'DCF Model'!B5)*1.01-A18)*5/(1+'DCF Model'!B12)^5-'DCF Model'!B16)/'DCF Model'!B14 -> 17.440595 | D18: =(('DCF Model'!B21*(1+D15)^10*0.32*(1-'DCF Model'!B5)*1.01-'DCF Model'!B21*(1+D15)^10*A18)*(1+'DCF Model'!B13)/('DCF Model'!B12-'DCF Model'!B13)/(1+'DCF Model'!B12)^10+'DCF Model'!B21*(1+D15)^5*(0.28*(1-'DCF Model'!B5)*1.01-A18)*5/(1+'DCF Model'!B12)^5-'DCF Model'!B16)/'DCF Model'!B14 -> 19.838098 | E18: =(('DCF Model'!B21*(1+E15)^10*0.32*(1-'DCF Model'!B5)*1.01-'DCF Model'!B21*(1+E15)^10*A18)*(1+'DCF Model'!B13)/('DCF Model'!B12-'DCF Model'!B13)/(1+'DCF Model'!B12)^10+'DCF Model'!B21*(1+E15)^5*(0.28*(1-'DCF Model'!B5)*1.01-A18)*5/(1+'DCF Model'!B12)^5-'DCF Model'!B16)/'DCF Model'!B14 -> 22.644808 | F18: =(('DCF Model'!B21*(1+F15)^10*0.32*(1-'DCF Model'!B5)*1.01-'DCF Model'!B21*(1+F15)^10*A18)*(1+'DCF Model'!B13)/('DCF Model'!B12-'DCF Model'!B13)/(1+'DCF Model'!B12)^10+'DCF Model'!B21*(1+F15)^5*(0.28*(1-'DCF Model'!B5)*1.01-A18)*5/(1+'DCF Model'!B12)^5-'DCF Model'!B16)/'DCF Model'!B14 -> 25.922319
A19: 0.25 | B19: =(('DCF Model'!B21*(1+B15)^10*0.32*(1-'DCF Model'!B5)*1.01-'DCF Model'!B21*(1+B15)^10*A19)*(1+'DCF Model'!B13)/('DCF Model'!B12-'DCF Model'!B13)/(1+'DCF Model'!B12)^10+'DCF Model'!B21*(1+B15)^5*(0.28*(1-'DCF Model'!B5)*1.01-A19)*5/(1+'DCF Model'!B12)^5-'DCF Model'!B16)/'DCF Model'!B14 -> -1.5708881 | C19: =(('DCF Model'!B21*(1+C15)^10*0.32*(1-'DCF Model'!B5)*1.01-'DCF Model'!B21*(1+C15)^10*A19)*(1+'DCF Model'!B13)/('DCF Model'!B12-'DCF Model'!B13)/(1+'DCF Model'!B12)^10+'DCF Model'!B21*(1+C15)^5*(0.28*(1-'DCF Model'!B5)*1.01-A19)*5/(1+'DCF Model'!B12)^5-'DCF Model'!B16)/'DCF Model'!B14 -> -2.4683063 | D19: =(('DCF Model'!B21*(1+D15)^10*0.32*(1-'DCF Model'!B5)*1.01-'DCF Model'!B21*(1+D15)^10*A19)*(1+'DCF Model'!B13)/('DCF Model'!B12-'DCF Model'!B13)/(1+'DCF Model'!B12)^10+'DCF Model'!B21*(1+D15)^5*(0.28*(1-'DCF Model'!B5)*1.01-A19)*5/(1+'DCF Model'!B12)^5-'DCF Model'!B16)/'DCF Model'!B14 -> -3.4889326 | E19: =(('DCF Model'!B21*(1+E15)^10*0.32*(1-'DCF Model'!B5)*1.01-'DCF Model'!B21*(1+E15)^10*A19)*(1+'DCF Model'!B13)/('DCF Model'!B12-'DCF Model'!B13)/(1+'DCF Model'!B12)^10+'DCF Model'!B21*(1+E15)^5*(0.28*(1-'DCF Model'!B5)*1.01-A19)*5/(1+'DCF Model'!B12)^5-'DCF Model'!B16)/'DCF Model'!B14 -> -4.6492013 | F19: =(('DCF Model'!B21*(1+F15)^10*0.32*(1-'DCF Model'!B5)*1.01-'DCF Model'!B21*(1+F15)^10*A19)*(1+'DCF Model'!B13)/('DCF Model'!B12-'DCF Model'!B13)/(1+'DCF Model'!B12)^10+'DCF Model'!B21*(1+F15)^5*(0.28*(1-'DCF Model'!B5)*1.01-A19)*5/(1+'DCF Model'!B12)^5-'DCF Model'!B16)/'DCF Model'!B14 -> -5.9675897
A20: 0.3 | B20: =(('DCF Model'!B21*(1+B15)^10*0.32*(1-'DCF Model'!B5)*1.01-'DCF Model'!B21*(1+B15)^10*A20)*(1+'DCF Model'!B13)/('DCF Model'!B12-'DCF Model'!B13)/(1+'DCF Model'!B12)^10+'DCF Model'!B21*(1+B15)^5*(0.28*(1-'DCF Model'!B5)*1.01-A20)*5/(1+'DCF Model'!B12)^5-'DCF Model'!B16)/'DCF Model'!B14 -> -18.539688 | C20: =(('DCF Model'!B21*(1+C15)^10*0.32*(1-'DCF Model'!B5)*1.01-'DCF Model'!B21*(1+C15)^10*A20)*(1+'DCF Model'!B13)/('DCF Model'!B12-'DCF Model'!B13)/(1+'DCF Model'!B12)^10+'DCF Model'!B21*(1+C15)^5*(0.28*(1-'DCF Model'!B5)*1.01-A20)*5/(1+'DCF Model'!B12)^5-'DCF Model'!B16)/'DCF Model'!B14 -> -22.377208 | D20: =(('DCF Model'!B21*(1+D15)^10*0.32*(1-'DCF Model'!B5)*1.01-'DCF Model'!B21*(1+D15)^10*A20)*(1+'DCF Model'!B13)/('DCF Model'!B12-'DCF Model'!B13)/(1+'DCF Model'!B12)^10+'DCF Model'!B21*(1+D15)^5*(0.28*(1-'DCF Model'!B5)*1.01-A20)*5/(1+'DCF Model'!B12)^5-'DCF Model'!B16)/'DCF Model'!B14 -> -26.815963 | E20: =(('DCF Model'!B21*(1+E15)^10*0.32*(1-'DCF Model'!B5)*1.01-'DCF Model'!B21*(1+E15)^10*A20)*(1+'DCF Model'!B13)/('DCF Model'!B12-'DCF Model'!B13)/(1+'DCF Model'!B12)^10+'DCF Model'!B21*(1+E15)^5*(0.28*(1-'DCF Model'!B5)*1.01-A20)*5/(1+'DCF Model'!B12)^5-'DCF Model'!B16)/'DCF Model'!B14 -> -31.943211 | F20: =(('DCF Model'!B21*(1+F15)^10*0.32*(1-'DCF Model'!B5)*1.01-'DCF Model'!B21*(1+F15)^10*A20)*(1+'DCF Model'!B13)/('DCF Model'!B12-'DCF Model'!B13)/(1+'DCF Model'!B12)^10+'DCF Model'!B21*(1+F15)^5*(0.28*(1-'DCF Model'!B5)*1.01-A20)*5/(1+'DCF Model'!B12)^5-'DCF Model'!B16)/'DCF Model'!B14 -> -37.857498
A22: Notes:
A23: 1. All prices use SBC-ADJUSTED free cash flows — SBC treated as real economic cost.
A24: 2. WACC vs TGR table uses SBC-adjusted terminal FCF from DCF Model sheet.
A25: 3. SBC% vs Revenue Growth shows impact of SBC intensity on valuation at different growth rates.
A26: 4. At 26% SBC/Rev (current level), even 16% revenue growth produces modest valuations.
A27: 5. The key to upside: SBC % declining toward 12-15% while revenue growth stays >12%.

Sheet Scenario Analysis
A1: Scenario Analysis — SBC-Adjusted
A2: All scenarios deduct SBC as a real economic cost
B4: Bear Case | C4: Base Case | D4: Bull Case
A5: 5-Yr Avg Revenue CAGR | B5: 0.12 | C5: 0.16 | D5: 0.2
A6: Terminal Revenue Growth | B6: 0.02 | C6: 0.03 | D6: 0.04
A7: Terminal Non-GAAP Op Margin | B7: 0.28 | C7: 0.33 | D7: 0.38
A8: Terminal SBC % of Revenue | B8: 0.18 | C8: 0.12 | D8: 0.08
A9: WACC | B9: 0.11 | C9: 0.1 | D9: 0.085
A11: FY2035E Revenue ($mm) | B11: 16197 | C11: 23006 | D11: 32290
A12: FY2035E Standard UFCF ($mm) | B12: 3390 | C12: 5674 | D12: 9171
A13: Less: Terminal SBC ($mm) | B13: -2915 | C13: -2761 | D13: -2583
A14: FY2035E SBC-Adjusted UFCF ($mm) | B14: 474 | C14: 2913 | D14: 6588
A15: Terminal Value ($mm) | B15: 5373 | C15: 42870 | D15: 152245
A16: PV of Terminal Value ($mm) | B16: 1892 | C16: 16528 | D16: 67336
A17: Approx PV of Adj FCFs 1-10 ($mm) | B17: -1302 | C17: 2712 | D17: 9039
... A24: Margin of Safety | B24: -8.7508306 | C24: 0.11532682 | D24: 0.76630477
A26: Scenario Narratives:
A27: Bear Case: | B27: Growth decelerates to 12% CAGR. SBC remains elevated at 18% of revenue through terminal year. AI competition compresses margins. Higher WACC reflects sustained uncertainty.
A28: Base Case: | B28: 16% revenue CAGR from cloud migration + enterprise wins. SBC declines to 12% of revenue as company matures. 10% WACC reflects elevated but manageable risk.
A29: Bull Case: | B29: AI tailwinds via Rovo drive 20% CAGR. SBC drops to 8% as scale reduces reliance on equity comp. Enterprise ITSM + marketing WM expand TAM significantly.
A31: KEY INSIGHT — SBC Impact:
A32: Standard DCF (no SBC adj) implied price: | B32: ~$179
A33: SBC-Adjusted base case implied price: | B33: See above
A34: SBC haircut to intrinsic value: | B34: ~30-45% reduction from standard DCF
