Workbook

Sheet Model_Info
A1: BHP.AX owner-FCF DCF model
A2: Version | B2: v1 fresh build, 2026-09-22. Supersedes nothing (first valuation of this ticker).
A3: Built by | B3: dcf-analyst agent (Claude Fable 5.1) at the research-stock orchestrator's request, 2026-09-22
A4: Data vintage: price | B4: A$60.78 ASX, Yahoo 2026-09-21T06:18:34Z (ASX regular session; Yahoo regularMarketPrice)
A5: Data vintage: FX | B5: AUD/USD 0.714 (Yahoo AUDUSD=X 2026-09-21); NYSE ADR parity check in JSON inputs.fx_note
A6: Data vintage: balance sheet | B6: 30 June 2026 (FY2026 Annual Report, approved 18-Aug-2026): net debt Bridge deduction US$18,150m = BHP-defined net debt US$8,694m (30-Jun-2026; borrowings 23,625 + leases 3,496 less 735 fre...
A7: Data vintage: share count | B7: 5,081.4m ordinary shares on issue at the report date + 11m dilutive awards = 5,092m, held flat
A8: Data vintage: guidance | B8: FY2026 results (Aug-2026): ~US$11bn/yr capex medium term; copper growth capex US$1.4bn FY27, US$1.9bn FY28, ~US$3bn/yr FY29-31; Jansen S1 first potash mid-CY2027, S2 FY2031; WAIO >305Mt by Q4 FY2028
A9: Method: model | B9: Owner-FCF DCF (dcf-methods/references/owner-fcf.md) with section 7 cyclical adaptations; 10-year component build; end-of-year discounting
A10: Method: mid-cycle | B10: FY2026 is a margin peak (56.1%); base fades to the 52% ten-year median and resets revenue ~5% before volume growth
A11: Method: tax + NCI | B11: Row 14 'Tax + NCI leakage' = 1-(1-tax)(1-NCI): ~35% tax/royalty on EBIT and 19.5-23% NCI on PAT -> 46-50%. Flows are attributable-only; book NCI NOT deducted in the bridge
A12: Method: leases | B12: Treatment A: lease liabilities inside BHP net debt; lease additions folded into capex %
A13: Method: bridge | B13: EV less BHP net debt 8,694 + Samarco provision 5,197 + Antamina silver-stream liability 4,259 = 18,150 (Assumptions!B9)
... A19: Cell legend | B19: Blue font = hardcoded input; yellow fill = key lever; black = formula; green font = cross-sheet link

Sheet Actuals
A1: Reported history, US$M (source: BHP.AX_Metrics.csv / FY2016-FY2026 Annual Reports; Employee share awards = note 5; interest income = net finance costs note)
A2: Line | B2: FY2016 | C2: FY2017 | D2: FY2018 | E2: FY2019 | F2: FY2020 | G2: FY2021 | H2: FY2022 | I2: FY2023 | J2: FY2024 | K2: FY2025 | L2: FY2026
A3: Revenue | B3: 30912 | C3: 38285 | D3: 43129 | E3: 44288 | F3: 42931 | G3: 60817 | H3: 65098 | I3: 53817 | J3: 55658 | K3: 51262 | L3: 58760
A4: Underlying EBITDA | B4: 12340 | C4: 20296 | D4: 23183 | E4: 23158 | F4: 22071 | G4: 37379 | H4: 40634 | I4: 27956 | J4: 29016 | K4: 25978 | L4: 32947
A5: Net operating cash flows | B5: 10625 | C5: 16804 | D5: 18461 | E5: 17871 | F5: 15706 | G5: 27234 | H5: 32174 | I5: 18701 | J5: 20665 | K5: 18692 | L5: 21778
A6: Capital & exploration expenditure | B6: 7711 | C6: 5220 | D6: 6753 | E6: 7566 | F6: 7640 | G6: 7120 | H6: 7545 | I6: 7083 | J6: 9273 | K6: 9794 | L6: 10257
A7: Reported FCF (OCF - capex&expl) | B7: 2914 | C7: 11584 | D7: 11708 | E7: 10305 | F7: 8066 | G7: 20114 | H7: 24629 | I7: 11618 | J7: 11392 | K7: 8898 | L7: 11521
A8: Employee share awards (SBC) | B8: 140 | C8: 105 | D8: 123 | E8: 138 | F8: 129 | G8: 88 | H8: 109 | I8: 97 | J8: 112 | K8: 127 | L8: 123
A9: Interest income | B9: 137 | C9: 143 | D9: 322 | E9: 446 | F9: 351 | G9: 73 | H9: 81 | I9: 529 | J9: 709 | K9: 603 | L9: 573
A10: Underlying attributable profit | B10: 1215 | C10: 6732 | D10: 8933 | E10: 9124 | F10: 9060 | G10: 17077 | H10: 23815 | I10: 13420 | J10: 13660 | K10: 10157 | L10: 13204
A11: Net debt (BHP definition) | B11: 26102 | C11: 16321 | D11: 11605 | E11: 9446 | F11: 12044 | G11: 4121 | H11: 333 | I11: 11166 | J11: 9120 | K11: 12924 | L11: 8694
A13: Underlying EBITDA margin % | B13: =B4/B3 | C13: =C4/C3 | D13: =D4/D3 | E13: =E4/E3 | F13: =F4/F3 | G13: =G4/G3 | H13: =H4/H3 | I13: =I4/I3 | ... L13: =L4/L3
A15: Balance sheet 30-Jun-2026 (US$M)
A16: Borrowings | B16: 23625
A17: Lease liabilities | B17: 3496
A18: less freight-index leases | B18: -735
A19: Cash and equivalents | B19: 18532
A20: Net debt-management derivatives | B20: 840
A21: BHP net debt | B21: 8694
A22: Samarco provision (current 1,653 / non-current 3,544) | B22: 5197
A23: Antamina silver-stream liability (4,300 - 41) | B23: 4259
A24: Book NCI (not deducted; charged in flows) | B24: 5398
A25: Shares on issue (m, report date) | B25: 5081.39
A26: Dilutive awards (m) | B26: 11
A27: Buy-back FY2024-26 (US$M) | B27: 0
A29: Guidance (FY2026 results, Aug-2026)
A30: Capex ~US$11bn/yr medium term (FY2026 actual 10,257 + 1,111 lease additions)
A31: Copper growth capex: US$1.4bn FY2027, US$1.9bn FY2028, ~US$3bn/yr FY2029-31
A32: Copper production 1,900-2,000kt FY2026 (upper half); +900-1,000ktpa FY28-31
A33: Jansen S1 first potash mid-CY2027 (4.15Mtpa); S2 FY2031 (8.5Mtpa combined, cost US$6.9bn)
A34: WAIO >305Mt/yr run-rate by Q4 FY2028
A35: Dividend policy: minimum 50% of underlying attributable profit (FY2026: 172 US cents, US$8.7bn)

Sheet Assumptions
A1: Global inputs (US$M unless stated)
A3: WACC (nominal USD, all scenarios) | B3: 0.09 | C3: rf 4.2% + 1.05 x 5.0% ERP = 9.45% CoE; Kd 3.6% after tax; 11% debt -> 8.8%, rounded 9.0%
A4: D&A % of revenue | B4: 0.11 | C4: FY2026 10.6%; rises with the capex programme
A5: Working-capital capture (x change in revenue) | B5: -0.1 | C5: negative: receivables + inventory > payables
A6: BHP net debt 30-Jun-2026 | B6: 8694 | C6: note 21; includes leases ex freight-index, derivatives
A7: Samarco dam-failure provision 30-Jun-2026 | B7: 5197 | C7: note 4, discounted; paid over ~20 years via EAI funding (outside FCF)
A8: Antamina silver-stream liability | B8: 4259 | C8: US$4,300m proceeds less US$41m settled; BHP excludes from net debt
A9: Total bridge deduction | B9: =B6+B7+B8 | C9: EV less this = equity
A10: Diluted shares (m), held flat | B10: 5092 | C10: 5,081.4m on issue + 11m dilutive awards
A11: Price (AUD) | B11: 60.78 | C11: 2026-09-21T06:18:34Z (ASX regular session; Yahoo regularMarketPrice)
A12: Price timestamp | B12: 2026-09-21T06:18:34Z (ASX regular session; Yahoo regularMarketPrice) | C12: Yahoo regularMarketTime
A13: AUD/USD (USD per AUD) | B13: 0.714 | C13: Yahoo AUDUSD=X 2026-09-21; ADR parity check in JSON
A14: Terminal cap multiple (x FCF_10) | B14: 15 | C14: top of the 12-15x cyclical band; tier-1 cost position
A15: Hurdle rate for entry price | B15: 0.15 | C15: TV rebuilt at this rate
A16: FY2026 revenue (US$M) | B16: 58760 | C16: base for all scenario revenue paths
A19: Scenario | B19: Terminal growth | C19: Probability
A20: Bear | B20: 0.02 | C20: 0.25
A21: Base | B21: 0.025 | C21: 0.5
A22: Bull | B22: 0.03 | C22: 0.25
A23: Weights check (must be 1.0) | C23: =SUM(C20:C22)
A24: Weights rationale | B24: 25% bear / 50% base / 25% bull, moved from the house 15/50/35. Bear raised to 25% because the FY2026 base year is a commodity-price peak (record copper, 56% margin) and mean reversion is the central risk for a price-taker, not a tail - management itself was wrong-footed on the last China steel call, and the Samarco UK causation trial (Oct-2026 to Mar-2027) is a dated, live liability catalyst. Bull cut to 25% because it needs two independent prices (copper AND iron ore) to hold near record simultaneously while Jansen and the Escondida concentrator execute on schedule. Balance sheet (13% gearing, US$18.5bn cash) rules out solvency-type bear weights above 25%.
A26: Scenario narratives
A27: Bear | B27: China steel peak, copper reset, and the liability tail bites. Iron ore falls to ~US$75/t as Chinese property-led steel demand finally rolls over (management has already been wrong-footed once on the timing), copper resets to ~US$3.75/lb as new supply (Anglo-Teck, Rio-Glencore scale, Kamoa, Oyu Tolgoi) arrives, and metallurgical coal stays weak. Revenue falls 15% in FY2027 and 6% in FY2028 before growing 2-3% on volume; margins compress to 46% (FY2016-style cost-curve pressure with AUD/CLP tailwinds partly offsetting). Capex cannot flex below ~US$11bn until Jansen S1/S2 and the copper program finish, so capex intensity peaks at 23% of revenue. The UK Samarco causation trial (Oct-2026 to Mar-2027) and a possible damages trial add unquantified cost beyond the US$5.2bn provision; Jansen Stage 2 shows a second overrun. Terminal growth 2%.
A28: Base | B28: Mid-cycle reversion with volume growth. Copper fades from the FY2026 record toward a long-run ~US$4.25/lb and iron ore settles around US$90-95/t, so revenue slips ~5% over FY2027-28 even as volumes rise; from FY2029 the Escondida growth program, Copper SA, Jansen Stage 1 (first potash mid-CY2027 = FY2028) and Stage 2 (FY2031) plus WAIO >305Mt lift nominal revenue 4-5%/yr, tapering to 2.5%. Underlying EBITDA margin fades from 56.1% (FY2026) to the 52% ten-year median by FY2029 and stays there (Jansen's >65% margin is too small to move the group). Capex plus lease additions held at the US$11bn guidance run-rate (20% of revenue) through the Jansen/Escondida build, then declines to ~13.5% (sustaining plus depletion replacement) by FY2036. Tax+royalty at 35% of EBIT and NCI (42.5% of Escondida, Samarco-adjacent JV partners) at 19.5-21% of after-tax profit are combined into one 47.5-49% leakage driver that rises with copper mix. Samarco settlement (US$5.2bn provision, paid over 20 years), the US$4.3bn Antamina silver stream and BHP's own US$8.7bn net debt are deducted once in the bridge.
A29: Bull | B29: Copper supercycle plus resilient China steel. Copper holds at or above US$5/lb on electrification, grid and AI data-centre demand; iron ore stays ~US$100/t because Chinese steel output has now exceeded 1bn t for six straight years; Jansen delivers on the revised schedule and the Escondida concentrator (230-270ktpa) is approved. Revenue grows 3-6%/yr through FY2032 with margins at 56-57%. Because copper (higher-NCI) drives the mix, the tax+NCI leakage rises to 50%. Same WACC as base: cyclicality is priced in the flows, not the discount rate.

Sheet DCF_Bear
A1: Bear case - owner FCF component build (US$M). Drivers in blue rows 5, 7, 9, 14, 22.
A3: Year | B3: FY2026A | C3: FY2027E | D3: FY2028E | E3: FY2029E | F3: FY2030E | G3: FY2031E | H3: FY2032E | I3: FY2033E | J3: FY2034E | K3: FY2035E | L3: FY2036E
A4: Year index | B4: 0 | C4: 1 | D4: 2 | E4: 3 | F4: 4 | G4: 5 | H4: 6 | I4: 7 | J4: 8 | K4: 9 | L4: 10
A5: Revenue growth YoY (driver) | C5: -0.15 | D5: -0.06 | E5: 0.02 | F5: 0.03 | G5: 0.03 | H5: 0.03 | I5: 0.025 | J5: 0.02 | K5: 0.02 | L5: 0.02
A6: Revenue | B6: =Assumptions!$B$16 | C6: =B6*(1+C5) | D6: =C6*(1+D5) | E6: =D6*(1+E5) | F6: =E6*(1+F5) | G6: =F6*(1+G5) | H6: =G6*(1+H5) | I6: =H6*(1+I5) | J6: =I6*(1+J5) | ... L6: =K6*(1+L5)
A7: Underlying EBITDA margin (driver) | B7: =B8/B6 | C7: 0.48 | D7: 0.46 | E7: 0.46 | F7: 0.46 | G7: 0.46 | H7: 0.46 | I7: 0.46 | J7: 0.46 | K7: 0.46 | L7: 0.46
A8: Underlying EBITDA | B8: 32947 | C8: =C6*C7 | D8: =D6*D7 | E8: =E6*E7 | F8: =F6*F7 | G8: =G6*G7 | H8: =H6*H7 | I8: =I6*I7 | J8: =J6*J7 | ... L8: =L6*L7
A9: SBC % of revenue (driver) | C9: 0.002 | D9: 0.002 | E9: 0.002 | F9: 0.002 | G9: 0.002 | H9: 0.002 | I9: 0.002 | J9: 0.002 | K9: 0.002 | L9: 0.002
A10: SBC (negative) | C10: =-C6*C9 | D10: =-D6*D9 | E10: =-E6*E9 | F10: =-F6*F9 | G10: =-G6*G9 | H10: =-H6*H9 | I10: =-I6*I9 | J10: =-J6*J9 | ... L10: =-L6*L9
A11: Owner EBITDA | C11: =C8+C10 | D11: =D8+D10 | E11: =E8+E10 | F11: =F8+F10 | G11: =G8+G10 | H11: =H8+H10 | I11: =I8+I10 | J11: =J8+J10 | ... L11: =L8+L10
A12: D&A (negative) | C12: =-C6*Assumptions!$B$4 | D12: =-D6*Assumptions!$B$4 | E12: =-E6*Assumptions!$B$4 | F12: =-F6*Assumptions!$B$4 | G12: =-G6*Assumptions!$B$4 | H12: =-H6*Assumptions!$B$4 | I12: =-I6*Assumptions!$B$4 | J12: =-J6*Assumptions!$B$4 | ... L12: =-L6*Assumptions!$B$4
A13: EBIT, SBC expensed | C13: =C11+C12 | D13: =D11+D12 | E13: =E11+E12 | F13: =F11+F12 | G13: =G11+G12 | H13: =H11+H12 | I13: =I11+I12 | J13: =J11+J12 | ... L13: =L11+L12
A14: Tax + NCI leakage rate on EBIT (driver) | C14: 0.465 | D14: 0.46 | E14: 0.46 | F14: 0.46 | G14: 0.46 | H14: 0.46 | I14: 0.46 | J14: 0.46 | K14: 0.46 | L14: 0.46
A15: NOPAT attributable | C15: =C13-MAX(0,C13)*C14 | D15: =D13-MAX(0,D13)*D14 | E15: =E13-MAX(0,E13)*E14 | F15: =F13-MAX(0,F13)*F14 | G15: =G13-MAX(0,G13)*G14 | H15: =H13-MAX(0,H13)*H14 | I15: =I13-MAX(0,I13)*I14 | J15: =J13-MAX(0,J13)*J14 | ... L15: =L13-MAX(0,L13)*L14
A16: add back D&A | C16: =-C12 | D16: =-D12 | E16: =-E12 | F16: =-F12 | G16: =-G12 | H16: =-H12 | I16: =-I12 | J16: =-J12 | ... L16: =-L12
A17: less capex incl. lease additions | C17: =-C6*C22 | D17: =-D6*D22 | E17: =-E6*E22 | F17: =-F6*F22 | G17: =-G6*G22 | H17: =-H6*H22 | I17: =-I6*I22 | J17: =-J6*J22 | ... L17: =-L6*L22
A18: add working capital (on change in revenue) | C18: =Assumptions!$B$5*(C6-B6) | D18: =Assumptions!$B$5*(D6-C6) | E18: =Assumptions!$B$5*(E6-D6) | F18: =Assumptions!$B$5*(F6-E6) | G18: =Assumptions!$B$5*(G6-F6) | H18: =Assumptions!$B$5*(H6-G6) | I18: =Assumptions!$B$5*(I6-H6) | J18: =Assumptions!$B$5*(J6-I6) | ... L18: =Assumptions!$B$5*(L6-K6)
A19: Unlevered owner FCF (attributable) | C19: =C15+C16+C17+C18 | D19: =D15+D16+D17+D18 | E19: =E15+E16+E17+E18 | F19: =F15+F16+F17+F18 | G19: =G15+G16+G17+G18 | H19: =H15+H16+H17+H18 | I19: =I15+I16+I17+I18 | J19: =J15+J16+J17+J18 | ... L19: =L15+L16+L17+L18
A20: Discount factor | C20: =1/(1+Assumptions!$B$3)^C4 | D20: =1/(1+Assumptions!$B$3)^D4 | E20: =1/(1+Assumptions!$B$3)^E4 | F20: =1/(1+Assumptions!$B$3)^F4 | G20: =1/(1+Assumptions!$B$3)^G4 | H20: =1/(1+Assumptions!$B$3)^H4 | I20: =1/(1+Assumptions!$B$3)^I4 | J20: =1/(1+Assumptions!$B$3)^J4 | ... L20: =1/(1+Assumptions!$B$3)^L4
A21: PV of FCF | C21: =C19*C20 | D21: =D19*D20 | E21: =E19*E20 | F21: =F19*F20 | G21: =G19*G20 | H21: =H19*H20 | I21: =I19*I20 | J21: =J19*J20 | ... L21: =L19*L20
A22: Capex % of revenue (driver) | C22: 0.23 | D22: 0.23 | E22: 0.21 | F22: 0.195 | G22: 0.185 | H22: 0.175 | I22: 0.165 | J22: 0.155 | K22: 0.145 | L22: 0.14
A23: Memo: FCF before SBC (company-style) | C23: =C19-C10 | D23: =D19-D10 | E23: =E19-E10 | F23: =F19-F10 | G23: =G19-G10 | H23: =H19-H10 | I23: =I19-I10 | J23: =J19-J10 | ... L23: =L19-L10
A24: Memo: owner-FCF margin | C24: =C19/C6 | D24: =D19/D6 | E24: =E19/E6 | F24: =F19/F6 | G24: =G19/G6 | H24: =H19/H6 | I24: =I19/I6 | J24: =J19/J6 | ... L24: =L19/L6
A26: Sum of PV of FCF | B26: =SUM(C21:L21)
A27: Terminal growth | B27: =Assumptions!$B$20
A28: Terminal-year FCF x (1+g) | B28: =L19*(1+B27)
A29: Gordon TV | B29: =IF(Assumptions!$B$3>B27,B28/(Assumptions!$B$3-B27),0)
A30: Cap TV (cap x FCF_10) | B30: =Assumptions!$B$14*L19
A31: TV used = MAX(0,MIN(Gordon,cap)) | B31: =MAX(0,MIN(B29,B30))
A32: Implied exit multiple (TV / FCF_10) | B32: =IF(L19<>0,B31/L19,0)
A33: PV of TV | B33: =B31*L20
A34: Enterprise value | B34: =B26+B33
A35: less bridge (net debt + Samarco + stream) | B35: =-Assumptions!$B$9
A36: Equity value (US$M) | B36: =B34+B35
A37: Diluted shares (m) | B37: =Assumptions!$B$10
A38: Value per share (USD) | B38: =B36/B37
A39: Value per share (AUD) | B39: =B38/Assumptions!$B$13
A40: Upside vs price | B40: =B39/Assumptions!$B$11-1
A41: Street memo: PV of explicit SBC | B41: =SUMPRODUCT(-C10:L10/(1+Assumptions!$B$3)^C4:L4)
A42: Street memo: PV of terminal SBC | B42: =IF(Assumptions!$B$3>B27,(-L10*(1+B27)/(Assumptions!$B$3-B27))*L20,0)
...

Sheet DCF_Base
A1: Base case - owner FCF component build (US$M). Drivers in blue rows 5, 7, 9, 14, 22.
A3: Year | B3: FY2026A | C3: FY2027E | D3: FY2028E | E3: FY2029E | F3: FY2030E | G3: FY2031E | H3: FY2032E | I3: FY2033E | J3: FY2034E | K3: FY2035E | L3: FY2036E
A4: Year index | B4: 0 | C4: 1 | D4: 2 | E4: 3 | F4: 4 | G4: 5 | H4: 6 | I4: 7 | J4: 8 | K4: 9 | L4: 10
A5: Revenue growth YoY (driver) | C5: -0.04 | D5: -0.01 | E5: 0.045 | F5: 0.05 | G5: 0.05 | H5: 0.045 | I5: 0.04 | J5: 0.03 | K5: 0.025 | L5: 0.025
A6: Revenue | B6: =Assumptions!$B$16 | C6: =B6*(1+C5) | D6: =C6*(1+D5) | E6: =D6*(1+E5) | F6: =E6*(1+F5) | G6: =F6*(1+G5) | H6: =G6*(1+H5) | I6: =H6*(1+I5) | J6: =I6*(1+J5) | ... L6: =K6*(1+L5)
A7: Underlying EBITDA margin (driver) | B7: =B8/B6 | C7: 0.54 | D7: 0.525 | E7: 0.52 | F7: 0.52 | G7: 0.52 | H7: 0.52 | I7: 0.52 | J7: 0.52 | K7: 0.52 | L7: 0.52
A8: Underlying EBITDA | B8: 32947 | C8: =C6*C7 | D8: =D6*D7 | E8: =E6*E7 | F8: =F6*F7 | G8: =G6*G7 | H8: =H6*H7 | I8: =I6*I7 | J8: =J6*J7 | ... L8: =L6*L7
A9: SBC % of revenue (driver) | C9: 0.002 | D9: 0.002 | E9: 0.002 | F9: 0.002 | G9: 0.002 | H9: 0.002 | I9: 0.002 | J9: 0.002 | K9: 0.002 | L9: 0.002
A10: SBC (negative) | C10: =-C6*C9 | D10: =-D6*D9 | E10: =-E6*E9 | F10: =-F6*F9 | G10: =-G6*G9 | H10: =-H6*H9 | I10: =-I6*I9 | J10: =-J6*J9 | ... L10: =-L6*L9
A11: Owner EBITDA | C11: =C8+C10 | D11: =D8+D10 | E11: =E8+E10 | F11: =F8+F10 | G11: =G8+G10 | H11: =H8+H10 | I11: =I8+I10 | J11: =J8+J10 | ... L11: =L8+L10
A12: D&A (negative) | C12: =-C6*Assumptions!$B$4 | D12: =-D6*Assumptions!$B$4 | E12: =-E6*Assumptions!$B$4 | F12: =-F6*Assumptions!$B$4 | G12: =-G6*Assumptions!$B$4 | H12: =-H6*Assumptions!$B$4 | I12: =-I6*Assumptions!$B$4 | J12: =-J6*Assumptions!$B$4 | ... L12: =-L6*Assumptions!$B$4
A13: EBIT, SBC expensed | C13: =C11+C12 | D13: =D11+D12 | E13: =E11+E12 | F13: =F11+F12 | G13: =G11+G12 | H13: =H11+H12 | I13: =I11+I12 | J13: =J11+J12 | ... L13: =L11+L12
A14: Tax + NCI leakage rate on EBIT (driver) | C14: 0.475 | D14: 0.475 | E14: 0.48 | F14: 0.48 | G14: 0.485 | H14: 0.485 | I14: 0.49 | J14: 0.49 | K14: 0.49 | L14: 0.49
A15: NOPAT attributable | C15: =C13-MAX(0,C13)*C14 | D15: =D13-MAX(0,D13)*D14 | E15: =E13-MAX(0,E13)*E14 | F15: =F13-MAX(0,F13)*F14 | G15: =G13-MAX(0,G13)*G14 | H15: =H13-MAX(0,H13)*H14 | I15: =I13-MAX(0,I13)*I14 | J15: =J13-MAX(0,J13)*J14 | ... L15: =L13-MAX(0,L13)*L14
A16: add back D&A | C16: =-C12 | D16: =-D12 | E16: =-E12 | F16: =-F12 | G16: =-G12 | H16: =-H12 | I16: =-I12 | J16: =-J12 | ... L16: =-L12
A17: less capex incl. lease additions | C17: =-C6*C22 | D17: =-D6*D22 | E17: =-E6*E22 | F17: =-F6*F22 | G17: =-G6*G22 | H17: =-H6*H22 | I17: =-I6*I22 | J17: =-J6*J22 | ... L17: =-L6*L22
A18: add working capital (on change in revenue) | C18: =Assumptions!$B$5*(C6-B6) | D18: =Assumptions!$B$5*(D6-C6) | E18: =Assumptions!$B$5*(E6-D6) | F18: =Assumptions!$B$5*(F6-E6) | G18: =Assumptions!$B$5*(G6-F6) | H18: =Assumptions!$B$5*(H6-G6) | I18: =Assumptions!$B$5*(I6-H6) | J18: =Assumptions!$B$5*(J6-I6) | ... L18: =Assumptions!$B$5*(L6-K6)
A19: Unlevered owner FCF (attributable) | C19: =C15+C16+C17+C18 | D19: =D15+D16+D17+D18 | E19: =E15+E16+E17+E18 | F19: =F15+F16+F17+F18 | G19: =G15+G16+G17+G18 | H19: =H15+H16+H17+H18 | I19: =I15+I16+I17+I18 | J19: =J15+J16+J17+J18 | ... L19: =L15+L16+L17+L18
A20: Discount factor | C20: =1/(1+Assumptions!$B$3)^C4 | D20: =1/(1+Assumptions!$B$3)^D4 | E20: =1/(1+Assumptions!$B$3)^E4 | F20: =1/(1+Assumptions!$B$3)^F4 | G20: =1/(1+Assumptions!$B$3)^G4 | H20: =1/(1+Assumptions!$B$3)^H4 | I20: =1/(1+Assumptions!$B$3)^I4 | J20: =1/(1+Assumptions!$B$3)^J4 | ... L20: =1/(1+Assumptions!$B$3)^L4
A21: PV of FCF | C21: =C19*C20 | D21: =D19*D20 | E21: =E19*E20 | F21: =F19*F20 | G21: =G19*G20 | H21: =H19*H20 | I21: =I19*I20 | J21: =J19*J20 | ... L21: =L19*L20
A22: Capex % of revenue (driver) | C22: 0.2 | D22: 0.2 | E22: 0.19 | F22: 0.18 | G22: 0.175 | H22: 0.17 | I22: 0.16 | J22: 0.15 | K22: 0.14 | L22: 0.135
A23: Memo: FCF before SBC (company-style) | C23: =C19-C10 | D23: =D19-D10 | E23: =E19-E10 | F23: =F19-F10 | G23: =G19-G10 | H23: =H19-H10 | I23: =I19-I10 | J23: =J19-J10 | ... L23: =L19-L10
A24: Memo: owner-FCF margin | C24: =C19/C6 | D24: =D19/D6 | E24: =E19/E6 | F24: =F19/F6 | G24: =G19/G6 | H24: =H19/H6 | I24: =I19/I6 | J24: =J19/J6 | ... L24: =L19/L6
A26: Sum of PV of FCF | B26: =SUM(C21:L21)
A27: Terminal growth | B27: =Assumptions!$B$21
A28: Terminal-year FCF x (1+g) | B28: =L19*(1+B27)
A29: Gordon TV | B29: =IF(Assumptions!$B$3>B27,B28/(Assumptions!$B$3-B27),0)
A30: Cap TV (cap x FCF_10) | B30: =Assumptions!$B$14*L19
A31: TV used = MAX(0,MIN(Gordon,cap)) | B31: =MAX(0,MIN(B29,B30))
A32: Implied exit multiple (TV / FCF_10) | B32: =IF(L19<>0,B31/L19,0)
A33: PV of TV | B33: =B31*L20
A34: Enterprise value | B34: =B26+B33
A35: less bridge (net debt + Samarco + stream) | B35: =-Assumptions!$B$9
A36: Equity value (US$M) | B36: =B34+B35
A37: Diluted shares (m) | B37: =Assumptions!$B$10
A38: Value per share (USD) | B38: =B36/B37
A39: Value per share (AUD) | B39: =B38/Assumptions!$B$13
A40: Upside vs price | B40: =B39/Assumptions!$B$11-1
A41: Street memo: PV of explicit SBC | B41: =SUMPRODUCT(-C10:L10/(1+Assumptions!$B$3)^C4:L4)
A42: Street memo: PV of terminal SBC | B42: =IF(Assumptions!$B$3>B27,(-L10*(1+B27)/(Assumptions!$B$3-B27))*L20,0)
...

Sheet DCF_Bull
A1: Bull case - owner FCF component build (US$M). Drivers in blue rows 5, 7, 9, 14, 22.
A3: Year | B3: FY2026A | C3: FY2027E | D3: FY2028E | E3: FY2029E | F3: FY2030E | G3: FY2031E | H3: FY2032E | I3: FY2033E | J3: FY2034E | K3: FY2035E | L3: FY2036E
A4: Year index | B4: 0 | C4: 1 | D4: 2 | E4: 3 | F4: 4 | G4: 5 | H4: 6 | I4: 7 | J4: 8 | K4: 9 | L4: 10
A5: Revenue growth YoY (driver) | C5: 0.03 | D5: 0.04 | E5: 0.06 | F5: 0.06 | G5: 0.06 | H5: 0.05 | I5: 0.045 | J5: 0.035 | K5: 0.03 | L5: 0.03
A6: Revenue | B6: =Assumptions!$B$16 | C6: =B6*(1+C5) | D6: =C6*(1+D5) | E6: =D6*(1+E5) | F6: =E6*(1+F5) | G6: =F6*(1+G5) | H6: =G6*(1+H5) | I6: =H6*(1+I5) | J6: =I6*(1+J5) | ... L6: =K6*(1+L5)
A7: Underlying EBITDA margin (driver) | B7: =B8/B6 | C7: 0.57 | D7: 0.57 | E7: 0.57 | F7: 0.57 | G7: 0.565 | H7: 0.56 | I7: 0.56 | J7: 0.56 | K7: 0.56 | L7: 0.56
A8: Underlying EBITDA | B8: 32947 | C8: =C6*C7 | D8: =D6*D7 | E8: =E6*E7 | F8: =F6*F7 | G8: =G6*G7 | H8: =H6*H7 | I8: =I6*I7 | J8: =J6*J7 | ... L8: =L6*L7
A9: SBC % of revenue (driver) | C9: 0.002 | D9: 0.002 | E9: 0.002 | F9: 0.002 | G9: 0.002 | H9: 0.002 | I9: 0.002 | J9: 0.002 | K9: 0.002 | L9: 0.002
A10: SBC (negative) | C10: =-C6*C9 | D10: =-D6*D9 | E10: =-E6*E9 | F10: =-F6*F9 | G10: =-G6*G9 | H10: =-H6*H9 | I10: =-I6*I9 | J10: =-J6*J9 | ... L10: =-L6*L9
A11: Owner EBITDA | C11: =C8+C10 | D11: =D8+D10 | E11: =E8+E10 | F11: =F8+F10 | G11: =G8+G10 | H11: =H8+H10 | I11: =I8+I10 | J11: =J8+J10 | ... L11: =L8+L10
A12: D&A (negative) | C12: =-C6*Assumptions!$B$4 | D12: =-D6*Assumptions!$B$4 | E12: =-E6*Assumptions!$B$4 | F12: =-F6*Assumptions!$B$4 | G12: =-G6*Assumptions!$B$4 | H12: =-H6*Assumptions!$B$4 | I12: =-I6*Assumptions!$B$4 | J12: =-J6*Assumptions!$B$4 | ... L12: =-L6*Assumptions!$B$4
A13: EBIT, SBC expensed | C13: =C11+C12 | D13: =D11+D12 | E13: =E11+E12 | F13: =F11+F12 | G13: =G11+G12 | H13: =H11+H12 | I13: =I11+I12 | J13: =J11+J12 | ... L13: =L11+L12
A14: Tax + NCI leakage rate on EBIT (driver) | C14: 0.48 | D14: 0.485 | E14: 0.49 | F14: 0.49 | G14: 0.495 | H14: 0.495 | I14: 0.5 | J14: 0.5 | K14: 0.5 | L14: 0.5
A15: NOPAT attributable | C15: =C13-MAX(0,C13)*C14 | D15: =D13-MAX(0,D13)*D14 | E15: =E13-MAX(0,E13)*E14 | F15: =F13-MAX(0,F13)*F14 | G15: =G13-MAX(0,G13)*G14 | H15: =H13-MAX(0,H13)*H14 | I15: =I13-MAX(0,I13)*I14 | J15: =J13-MAX(0,J13)*J14 | ... L15: =L13-MAX(0,L13)*L14
A16: add back D&A | C16: =-C12 | D16: =-D12 | E16: =-E12 | F16: =-F12 | G16: =-G12 | H16: =-H12 | I16: =-I12 | J16: =-J12 | ... L16: =-L12
A17: less capex incl. lease additions | C17: =-C6*C22 | D17: =-D6*D22 | E17: =-E6*E22 | F17: =-F6*F22 | G17: =-G6*G22 | H17: =-H6*H22 | I17: =-I6*I22 | J17: =-J6*J22 | ... L17: =-L6*L22
A18: add working capital (on change in revenue) | C18: =Assumptions!$B$5*(C6-B6) | D18: =Assumptions!$B$5*(D6-C6) | E18: =Assumptions!$B$5*(E6-D6) | F18: =Assumptions!$B$5*(F6-E6) | G18: =Assumptions!$B$5*(G6-F6) | H18: =Assumptions!$B$5*(H6-G6) | I18: =Assumptions!$B$5*(I6-H6) | J18: =Assumptions!$B$5*(J6-I6) | ... L18: =Assumptions!$B$5*(L6-K6)
A19: Unlevered owner FCF (attributable) | C19: =C15+C16+C17+C18 | D19: =D15+D16+D17+D18 | E19: =E15+E16+E17+E18 | F19: =F15+F16+F17+F18 | G19: =G15+G16+G17+G18 | H19: =H15+H16+H17+H18 | I19: =I15+I16+I17+I18 | J19: =J15+J16+J17+J18 | ... L19: =L15+L16+L17+L18
A20: Discount factor | C20: =1/(1+Assumptions!$B$3)^C4 | D20: =1/(1+Assumptions!$B$3)^D4 | E20: =1/(1+Assumptions!$B$3)^E4 | F20: =1/(1+Assumptions!$B$3)^F4 | G20: =1/(1+Assumptions!$B$3)^G4 | H20: =1/(1+Assumptions!$B$3)^H4 | I20: =1/(1+Assumptions!$B$3)^I4 | J20: =1/(1+Assumptions!$B$3)^J4 | ... L20: =1/(1+Assumptions!$B$3)^L4
A21: PV of FCF | C21: =C19*C20 | D21: =D19*D20 | E21: =E19*E20 | F21: =F19*F20 | G21: =G19*G20 | H21: =H19*H20 | I21: =I19*I20 | J21: =J19*J20 | ... L21: =L19*L20
A22: Capex % of revenue (driver) | C22: 0.2 | D22: 0.2 | E22: 0.195 | F22: 0.19 | G22: 0.18 | H22: 0.17 | I22: 0.16 | J22: 0.15 | K22: 0.14 | L22: 0.135
A23: Memo: FCF before SBC (company-style) | C23: =C19-C10 | D23: =D19-D10 | E23: =E19-E10 | F23: =F19-F10 | G23: =G19-G10 | H23: =H19-H10 | I23: =I19-I10 | J23: =J19-J10 | ... L23: =L19-L10
A24: Memo: owner-FCF margin | C24: =C19/C6 | D24: =D19/D6 | E24: =E19/E6 | F24: =F19/F6 | G24: =G19/G6 | H24: =H19/H6 | I24: =I19/I6 | J24: =J19/J6 | ... L24: =L19/L6
A26: Sum of PV of FCF | B26: =SUM(C21:L21)
A27: Terminal growth | B27: =Assumptions!$B$22
A28: Terminal-year FCF x (1+g) | B28: =L19*(1+B27)
A29: Gordon TV | B29: =IF(Assumptions!$B$3>B27,B28/(Assumptions!$B$3-B27),0)
A30: Cap TV (cap x FCF_10) | B30: =Assumptions!$B$14*L19
A31: TV used = MAX(0,MIN(Gordon,cap)) | B31: =MAX(0,MIN(B29,B30))
A32: Implied exit multiple (TV / FCF_10) | B32: =IF(L19<>0,B31/L19,0)
A33: PV of TV | B33: =B31*L20
A34: Enterprise value | B34: =B26+B33
A35: less bridge (net debt + Samarco + stream) | B35: =-Assumptions!$B$9
A36: Equity value (US$M) | B36: =B34+B35
A37: Diluted shares (m) | B37: =Assumptions!$B$10
A38: Value per share (USD) | B38: =B36/B37
A39: Value per share (AUD) | B39: =B38/Assumptions!$B$13
A40: Upside vs price | B40: =B39/Assumptions!$B$11-1
A41: Street memo: PV of explicit SBC | B41: =SUMPRODUCT(-C10:L10/(1+Assumptions!$B$3)^C4:L4)
A42: Street memo: PV of terminal SBC | B42: =IF(Assumptions!$B$3>B27,(-L10*(1+B27)/(Assumptions!$B$3-B27))*L20,0)
...

Sheet FCF_Quality
A1: Reported FCF reconciled to owner FCF (US$M)
B2: FY2016 | C2: FY2017 | D2: FY2018 | E2: FY2019 | F2: FY2020 | G2: FY2021 | H2: FY2022 | I2: FY2023 | J2: FY2024 | K2: FY2025 | L2: FY2026
A3: Free cash flow (OCF - capital & exploration) | B3: =Actuals!B7 | C3: =Actuals!C7 | D3: =Actuals!D7 | E3: =Actuals!E7 | F3: =Actuals!F7 | G3: =Actuals!G7 | H3: =Actuals!H7 | I3: =Actuals!I7 | ... L3: =Actuals!L7
A4: less: employee share awards (SBC) | B4: =-Actuals!B8 | C4: =-Actuals!C8 | D4: =-Actuals!D8 | E4: =-Actuals!E8 | F4: =-Actuals!F8 | G4: =-Actuals!G8 | H4: =-Actuals!H8 | I4: =-Actuals!I8 | ... L4: =-Actuals!L8
A5: less: interest income | B5: =-Actuals!B9 | C5: =-Actuals!C9 | D5: =-Actuals!D9 | E5: =-Actuals!E9 | F5: =-Actuals!F9 | G5: =-Actuals!G9 | H5: =-Actuals!H9 | I5: =-Actuals!I9 | ... L5: =-Actuals!L9
A6: Owner FCF (equals FCF less SBC less interest income) | B6: =B3+B4+B5 | C6: =C3+C4+C5 | D6: =D3+D4+D5 | E6: =E3+E4+E5 | F6: =F3+F4+F5 | G6: =G3+G4+G5 | H6: =H3+H4+H5 | I6: =I3+I4+I5 | ... L6: =L3+L4+L5
A7: Reported FCF margin | B7: =B3/Actuals!B3 | C7: =C3/Actuals!C3 | D7: =D3/Actuals!D3 | E7: =E3/Actuals!E3 | F7: =F3/Actuals!F3 | G7: =G3/Actuals!G3 | H7: =H3/Actuals!H3 | I7: =I3/Actuals!I3 | ... L7: =L3/Actuals!L3
A8: Owner FCF margin | B8: =B6/Actuals!B3 | C8: =C6/Actuals!C3 | D8: =D6/Actuals!D3 | E8: =E6/Actuals!E3 | F8: =F6/Actuals!F3 | G8: =G6/Actuals!G3 | H8: =H6/Actuals!H3 | I8: =I6/Actuals!I3 | ... L8: =L6/Actuals!L3
A9: Memo: Underlying EBITDA margin | B9: =Actuals!B13 | C9: =Actuals!C13 | D9: =Actuals!D13 | E9: =Actuals!E13 | F9: =Actuals!F13 | G9: =Actuals!G13 | H9: =Actuals!H13 | I9: =Actuals!I13 | ... L9: =Actuals!L13
A10: Memo: owner FCF / underlying attributable profit | B10: =B6/Actuals!B10 | C10: =C6/Actuals!C10 | D10: =D6/Actuals!D10 | E10: =E6/Actuals!E10 | F10: =F6/Actuals!F10 | G10: =G6/Actuals!G10 | H10: =H6/Actuals!H10 | I10: =I6/Actuals!I10 | ... L10: =L6/Actuals!L10
A12: Memo: net income tax and royalty-related taxation paid FY2024-26: 7,503 / 7,721 / 9,541 (34-36% of underlying EBIT); no abnormal cash-tax year. Samarco funding (US$2,030m FY2026) runs through investing (EAI funding), so it is outside both FCF lines above and is deducted in the bridge instead.

Sheet Valuation
A1: Valuation summary (per share, AUD unless stated)
A3: Scenario | B3: Value/share AUD | C3: Value/share USD | D3: Upside vs price | E3: Probability | F3: Street value AUD | G3: Entry price AUD @15% | H3: Entry price USD @15%
A4: Bear | B4: =DCF_Bear!$B$39 | C4: =DCF_Bear!$B$38 | D4: =B4/Assumptions!$B$11-1 | E4: =Assumptions!$C$20 | F4: =DCF_Bear!$B$43 | G4: =H4/Assumptions!$B$13 | H4: =((SUMPRODUCT(DCF_Bear!$C$19:$L$19/(1+Assumptions!$B$15)^DCF_Bear!$C$4:$L$4)+MAX(0,MIN(IF(Assumptions!$B$15>Assumptions!$B$20,DCF_Bear!$L$19*(1+Assumptions!$B$20)/(Assumptions!$B$15-Assumptions!$B$20),0),Assumptions!$B$14*DCF_Bear!$L$19))/(1+Assumptions!$B$15)^10-Assumptions!$B$9)/Assumptions!$B$10
A5: Base | B5: =DCF_Base!$B$39 | C5: =DCF_Base!$B$38 | D5: =B5/Assumptions!$B$11-1 | E5: =Assumptions!$C$21 | F5: =DCF_Base!$B$43 | G5: =H5/Assumptions!$B$13 | H5: =((SUMPRODUCT(DCF_Base!$C$19:$L$19/(1+Assumptions!$B$15)^DCF_Base!$C$4:$L$4)+MAX(0,MIN(IF(Assumptions!$B$15>Assumptions!$B$21,DCF_Base!$L$19*(1+Assumptions!$B$21)/(Assumptions!$B$15-Assumptions!$B$21),0),Assumptions!$B$14*DCF_Base!$L$19))/(1+Assumptions!$B$15)^10-Assumptions!$B$9)/Assumptions!$B$10
A6: Bull | B6: =DCF_Bull!$B$39 | C6: =DCF_Bull!$B$38 | D6: =B6/Assumptions!$B$11-1 | E6: =Assumptions!$C$22 | F6: =DCF_Bull!$B$43 | G6: =H6/Assumptions!$B$13 | H6: =((SUMPRODUCT(DCF_Bull!$C$19:$L$19/(1+Assumptions!$B$15)^DCF_Bull!$C$4:$L$4)+MAX(0,MIN(IF(Assumptions!$B$15>Assumptions!$B$22,DCF_Bull!$L$19*(1+Assumptions!$B$22)/(Assumptions!$B$15-Assumptions!$B$22),0),Assumptions!$B$14*DCF_Bull!$L$19))/(1+Assumptions!$B$15)^10-Assumptions!$B$9)/Assumptions!$B$10
A8: Probability-weighted value (AUD) | B8: =SUMPRODUCT(B4:B6,E4:E6)
A9: Probability-weighted value (USD) | B9: =SUMPRODUCT(C4:C6,E4:E6)
A10: Margin of safety vs price | B10: =1-Assumptions!$B$11/B8
A11: Street weighted value (AUD) | B11: =SUMPRODUCT(F4:F6,E4:E6)
A12: Band position (0%=house, 100%=street) - degenerate, SBC 0.2% of revenue | B12: =IF(ABS(B11-B8)<0.01,"n/a",(Assumptions!$B$11-B8)/(B11-B8))
A13: Weighted 15%-hurdle entry price (AUD) | B13: =SUMPRODUCT(G4:G6,E4:E6)
A14: Entry discount vs price | B14: =B13/Assumptions!$B$11-1
A16: Required-return table (base case, AUD; TV rebuilt at each rate)
A17: Required return | B17: Value/share AUD | C17: Value/share USD
A18: 0.09 | B18: =C18/Assumptions!$B$13 | C18: =((SUMPRODUCT(DCF_Base!$C$19:$L$19/(1+$A$18)^DCF_Base!$C$4:$L$4)+MAX(0,MIN(IF($A$18>Assumptions!$B$21,DCF_Base!$L$19*(1+Assumptions!$B$21)/($A$18-Assumptions!$B$21),0),Assumptions!$B$14*DCF_Base!$L$19))/(1+$A$18)^10-Assumptions!$B$9)/Assumptions!$B$10
A19: 0.1 | B19: =C19/Assumptions!$B$13 | C19: =((SUMPRODUCT(DCF_Base!$C$19:$L$19/(1+$A$19)^DCF_Base!$C$4:$L$4)+MAX(0,MIN(IF($A$19>Assumptions!$B$21,DCF_Base!$L$19*(1+Assumptions!$B$21)/($A$19-Assumptions!$B$21),0),Assumptions!$B$14*DCF_Base!$L$19))/(1+$A$19)^10-Assumptions!$B$9)/Assumptions!$B$10
A20: 0.11 | B20: =C20/Assumptions!$B$13 | C20: =((SUMPRODUCT(DCF_Base!$C$19:$L$19/(1+$A$20)^DCF_Base!$C$4:$L$4)+MAX(0,MIN(IF($A$20>Assumptions!$B$21,DCF_Base!$L$19*(1+Assumptions!$B$21)/($A$20-Assumptions!$B$21),0),Assumptions!$B$14*DCF_Base!$L$19))/(1+$A$20)^10-Assumptions!$B$9)/Assumptions!$B$10
A21: 0.12 | B21: =C21/Assumptions!$B$13 | C21: =((SUMPRODUCT(DCF_Base!$C$19:$L$19/(1+$A$21)^DCF_Base!$C$4:$L$4)+MAX(0,MIN(IF($A$21>Assumptions!$B$21,DCF_Base!$L$19*(1+Assumptions!$B$21)/($A$21-Assumptions!$B$21),0),Assumptions!$B$14*DCF_Base!$L$19))/(1+$A$21)^10-Assumptions!$B$9)/Assumptions!$B$10
A22: 0.15 | B22: =C22/Assumptions!$B$13 | C22: =((SUMPRODUCT(DCF_Base!$C$19:$L$19/(1+$A$22)^DCF_Base!$C$4:$L$4)+MAX(0,MIN(IF($A$22>Assumptions!$B$21,DCF_Base!$L$19*(1+Assumptions!$B$21)/($A$22-Assumptions!$B$21),0),Assumptions!$B$14*DCF_Base!$L$19))/(1+$A$22)^10-Assumptions!$B$9)/Assumptions!$B$10
A23: =Assumptions!$B$3 | B23: =C23/Assumptions!$B$13 | C23: =((SUMPRODUCT(DCF_Base!$C$19:$L$19/(1+$A$23)^DCF_Base!$C$4:$L$4)+MAX(0,MIN(IF($A$23>Assumptions!$B$21,DCF_Base!$L$19*(1+Assumptions!$B$21)/($A$23-Assumptions!$B$21),0),Assumptions!$B$14*DCF_Base!$L$19))/(1+$A$23)^10-Assumptions!$B$9)/Assumptions!$B$10
A24: Check: WACC row = DCF_Base!B39, 15% row = base entry price | B24: =AND(ABS(B23-DCF_Base!$B$39)<0.01,ABS(B22-G5)<0.01)
A26: Sensitivity: value/share AUD, base case. Rows = WACC, columns = terminal growth (TV re-capped in every cell; Gordon guarded to 0 when WACC <= g, so the cap applies there)
B27: 0.015 | C27: 0.02 | D27: 0.025 | E27: 0.03 | F27: 0.035
A28: 0.07 | B28: =((SUMPRODUCT(DCF_Base!$C$19:$L$19/(1+$A28)^DCF_Base!$C$4:$L$4)+MAX(0,MIN(IF($A28>B$27,DCF_Base!$L$19*(1+B$27)/($A28-B$27),0),Assumptions!$B$14*DCF_Base!$L$19))/(1+$A28)^10-Assumptions!$B$9)/Assumptions!$B$10/Assumptions!$B$13 | C28: =((SUMPRODUCT(DCF_Base!$C$19:$L$19/(1+$A28)^DCF_Base!$C$4:$L$4)+MAX(0,MIN(IF($A28>C$27,DCF_Base!$L$19*(1+C$27)/($A28-C$27),0),Assumptions!$B$14*DCF_Base!$L$19))/(1+$A28)^10-Assumptions!$B$9)/Assumptions!$B$10/Assumptions!$B$13 | D28: =((SUMPRODUCT(DCF_Base!$C$19:$L$19/(1+$A28)^DCF_Base!$C$4:$L$4)+MAX(0,MIN(IF($A28>D$27,DCF_Base!$L$19*(1+D$27)/($A28-D$27),0),Assumptions!$B$14*DCF_Base!$L$19))/(1+$A28)^10-Assumptions!$B$9)/Assumptions!$B$10/Assumptions!$B$13 | E28: =((SUMPRODUCT(DCF_Base!$C$19:$L$19/(1+$A28)^DCF_Base!$C$4:$L$4)+MAX(0,MIN(IF($A28>E$27,DCF_Base!$L$19*(1+E$27)/($A28-E$27),0),Assumptions!$B$14*DCF_Base!$L$19))/(1+$A28)^10-Assumptions!$B$9)/Assumptions!$B$10/Assumptions!$B$13 | F28: =((SUMPRODUCT(DCF_Base!$C$19:$L$19/(1+$A28)^DCF_Base!$C$4:$L$4)+MAX(0,MIN(IF($A28>F$27,DCF_Base!$L$19*(1+F$27)/($A28-F$27),0),Assumptions!$B$14*DCF_Base!$L$19))/(1+$A28)^10-Assumptions!$B$9)/Assumptions!$B$10/Assumptions!$B$13
A29: 0.08 | B29: =((SUMPRODUCT(DCF_Base!$C$19:$L$19/(1+$A29)^DCF_Base!$C$4:$L$4)+MAX(0,MIN(IF($A29>B$27,DCF_Base!$L$19*(1+B$27)/($A29-B$27),0),Assumptions!$B$14*DCF_Base!$L$19))/(1+$A29)^10-Assumptions!$B$9)/Assumptions!$B$10/Assumptions!$B$13 | C29: =((SUMPRODUCT(DCF_Base!$C$19:$L$19/(1+$A29)^DCF_Base!$C$4:$L$4)+MAX(0,MIN(IF($A29>C$27,DCF_Base!$L$19*(1+C$27)/($A29-C$27),0),Assumptions!$B$14*DCF_Base!$L$19))/(1+$A29)^10-Assumptions!$B$9)/Assumptions!$B$10/Assumptions!$B$13 | D29: =((SUMPRODUCT(DCF_Base!$C$19:$L$19/(1+$A29)^DCF_Base!$C$4:$L$4)+MAX(0,MIN(IF($A29>D$27,DCF_Base!$L$19*(1+D$27)/($A29-D$27),0),Assumptions!$B$14*DCF_Base!$L$19))/(1+$A29)^10-Assumptions!$B$9)/Assumptions!$B$10/Assumptions!$B$13 | E29: =((SUMPRODUCT(DCF_Base!$C$19:$L$19/(1+$A29)^DCF_Base!$C$4:$L$4)+MAX(0,MIN(IF($A29>E$27,DCF_Base!$L$19*(1+E$27)/($A29-E$27),0),Assumptions!$B$14*DCF_Base!$L$19))/(1+$A29)^10-Assumptions!$B$9)/Assumptions!$B$10/Assumptions!$B$13 | F29: =((SUMPRODUCT(DCF_Base!$C$19:$L$19/(1+$A29)^DCF_Base!$C$4:$L$4)+MAX(0,MIN(IF($A29>F$27,DCF_Base!$L$19*(1+F$27)/($A29-F$27),0),Assumptions!$B$14*DCF_Base!$L$19))/(1+$A29)^10-Assumptions!$B$9)/Assumptions!$B$10/Assumptions!$B$13
A30: 0.09 | B30: =((SUMPRODUCT(DCF_Base!$C$19:$L$19/(1+$A30)^DCF_Base!$C$4:$L$4)+MAX(0,MIN(IF($A30>B$27,DCF_Base!$L$19*(1+B$27)/($A30-B$27),0),Assumptions!$B$14*DCF_Base!$L$19))/(1+$A30)^10-Assumptions!$B$9)/Assumptions!$B$10/Assumptions!$B$13 | C30: =((SUMPRODUCT(DCF_Base!$C$19:$L$19/(1+$A30)^DCF_Base!$C$4:$L$4)+MAX(0,MIN(IF($A30>C$27,DCF_Base!$L$19*(1+C$27)/($A30-C$27),0),Assumptions!$B$14*DCF_Base!$L$19))/(1+$A30)^10-Assumptions!$B$9)/Assumptions!$B$10/Assumptions!$B$13 | D30: =((SUMPRODUCT(DCF_Base!$C$19:$L$19/(1+$A30)^DCF_Base!$C$4:$L$4)+MAX(0,MIN(IF($A30>D$27,DCF_Base!$L$19*(1+D$27)/($A30-D$27),0),Assumptions!$B$14*DCF_Base!$L$19))/(1+$A30)^10-Assumptions!$B$9)/Assumptions!$B$10/Assumptions!$B$13 | E30: =((SUMPRODUCT(DCF_Base!$C$19:$L$19/(1+$A30)^DCF_Base!$C$4:$L$4)+MAX(0,MIN(IF($A30>E$27,DCF_Base!$L$19*(1+E$27)/($A30-E$27),0),Assumptions!$B$14*DCF_Base!$L$19))/(1+$A30)^10-Assumptions!$B$9)/Assumptions!$B$10/Assumptions!$B$13 | F30: =((SUMPRODUCT(DCF_Base!$C$19:$L$19/(1+$A30)^DCF_Base!$C$4:$L$4)+MAX(0,MIN(IF($A30>F$27,DCF_Base!$L$19*(1+F$27)/($A30-F$27),0),Assumptions!$B$14*DCF_Base!$L$19))/(1+$A30)^10-Assumptions!$B$9)/Assumptions!$B$10/Assumptions!$B$13
A31: 0.1 | B31: =((SUMPRODUCT(DCF_Base!$C$19:$L$19/(1+$A31)^DCF_Base!$C$4:$L$4)+MAX(0,MIN(IF($A31>B$27,DCF_Base!$L$19*(1+B$27)/($A31-B$27),0),Assumptions!$B$14*DCF_Base!$L$19))/(1+$A31)^10-Assumptions!$B$9)/Assumptions!$B$10/Assumptions!$B$13 | C31: =((SUMPRODUCT(DCF_Base!$C$19:$L$19/(1+$A31)^DCF_Base!$C$4:$L$4)+MAX(0,MIN(IF($A31>C$27,DCF_Base!$L$19*(1+C$27)/($A31-C$27),0),Assumptions!$B$14*DCF_Base!$L$19))/(1+$A31)^10-Assumptions!$B$9)/Assumptions!$B$10/Assumptions!$B$13 | D31: =((SUMPRODUCT(DCF_Base!$C$19:$L$19/(1+$A31)^DCF_Base!$C$4:$L$4)+MAX(0,MIN(IF($A31>D$27,DCF_Base!$L$19*(1+D$27)/($A31-D$27),0),Assumptions!$B$14*DCF_Base!$L$19))/(1+$A31)^10-Assumptions!$B$9)/Assumptions!$B$10/Assumptions!$B$13 | E31: =((SUMPRODUCT(DCF_Base!$C$19:$L$19/(1+$A31)^DCF_Base!$C$4:$L$4)+MAX(0,MIN(IF($A31>E$27,DCF_Base!$L$19*(1+E$27)/($A31-E$27),0),Assumptions!$B$14*DCF_Base!$L$19))/(1+$A31)^10-Assumptions!$B$9)/Assumptions!$B$10/Assumptions!$B$13 | F31: =((SUMPRODUCT(DCF_Base!$C$19:$L$19/(1+$A31)^DCF_Base!$C$4:$L$4)+MAX(0,MIN(IF($A31>F$27,DCF_Base!$L$19*(1+F$27)/($A31-F$27),0),Assumptions!$B$14*DCF_Base!$L$19))/(1+$A31)^10-Assumptions!$B$9)/Assumptions!$B$10/Assumptions!$B$13
A32: 0.11 | B32: =((SUMPRODUCT(DCF_Base!$C$19:$L$19/(1+$A32)^DCF_Base!$C$4:$L$4)+MAX(0,MIN(IF($A32>B$27,DCF_Base!$L$19*(1+B$27)/($A32-B$27),0),Assumptions!$B$14*DCF_Base!$L$19))/(1+$A32)^10-Assumptions!$B$9)/Assumptions!$B$10/Assumptions!$B$13 | C32: =((SUMPRODUCT(DCF_Base!$C$19:$L$19/(1+$A32)^DCF_Base!$C$4:$L$4)+MAX(0,MIN(IF($A32>C$27,DCF_Base!$L$19*(1+C$27)/($A32-C$27),0),Assumptions!$B$14*DCF_Base!$L$19))/(1+$A32)^10-Assumptions!$B$9)/Assumptions!$B$10/Assumptions!$B$13 | D32: =((SUMPRODUCT(DCF_Base!$C$19:$L$19/(1+$A32)^DCF_Base!$C$4:$L$4)+MAX(0,MIN(IF($A32>D$27,DCF_Base!$L$19*(1+D$27)/($A32-D$27),0),Assumptions!$B$14*DCF_Base!$L$19))/(1+$A32)^10-Assumptions!$B$9)/Assumptions!$B$10/Assumptions!$B$13 | E32: =((SUMPRODUCT(DCF_Base!$C$19:$L$19/(1+$A32)^DCF_Base!$C$4:$L$4)+MAX(0,MIN(IF($A32>E$27,DCF_Base!$L$19*(1+E$27)/($A32-E$27),0),Assumptions!$B$14*DCF_Base!$L$19))/(1+$A32)^10-Assumptions!$B$9)/Assumptions!$B$10/Assumptions!$B$13 | F32: =((SUMPRODUCT(DCF_Base!$C$19:$L$19/(1+$A32)^DCF_Base!$C$4:$L$4)+MAX(0,MIN(IF($A32>F$27,DCF_Base!$L$19*(1+F$27)/($A32-F$27),0),Assumptions!$B$14*DCF_Base!$L$19))/(1+$A32)^10-Assumptions!$B$9)/Assumptions!$B$10/Assumptions!$B$13
