Workbook

Sheet Model_Info
A1: AMP Limited (AMP.AX) valuation model
A2: Version | B2: v1.0 fresh build, 2026-09-21. Supersedes nothing (first valuation of this ticker).
A3: Built by | B3: dcf-analyst agent (Claude Fable 5.1) on 2026-09-21 at the request of the research-stock orchestrator.
A4: Model | B4: Distributable Underlying NPAT at AUD cost of equity, built per segment and summed; terminal = MAX(0, MIN(Gordon, exit-P/E cap)). NOT an owner-FCF DCF: AMP Bank makes OCF/FCF meaningless.
A5: Why no net debt | B5: Interest-bearing liabilities (A$28.8bn) are bank deposits, wholesale funding and sub-debt, plus A$480m corporate MTNs whose interest is already inside Partnerships & Group NPAT. Flows are post-interest, so nothing is deducted. The bridge ADDS the CET1 surplus and the PV of the net DTA.
A6: Price | B6: A$2.55, ASX regular close 2026-09-21 (Yahoo regularMarketTime 06:10:30Z). This is the 52-week high (1.14-2.55). Refresh at each use.
A7: Balance sheet | B7: 30 June 2026 half-year report: shares on issue 2,432.8m (note 4.1), CET1 surplus A$322m and net DTA A$418m (note 4.3), equity A$3,696m.
A8: Share count | B8: Fully diluted 2,475.7m = 2,432.8m issued - 2.1m treasury + ~45m dilutive rights (FY25 diluted 2,577m vs basic 2,532m). Held flat: SBC is expensed inside underlying NPAT.
A9: Earnings base | B9: TTM to 30-Jun-2026 underlying NPAT A$328m = FY25 285 - 1H25 131 + 1H26 174, by segment (Actuals tab). Statutory TTM A$189m.
A10: Guidance used | B10: 1H26 results (6-Aug-2026): Platforms margin 40-41bps FY26, S&I 60-61bps, bank NIM ~1.25% flat, GO deposits target A$2.0bn, buyback up to A$300m CY2026 (second A$150m tranche), 3.0c interim dividend.
A11: Cost of equity | B11: 10.5% AUD: ~4.4% AGB 10yr + ~1.1 beta x 5.5% ERP. One rate for all scenarios (risk charged once, in the flows).
A12: Drivers | B12: Scenario driver paths (segment growth, below-the-line %, retention %, g, cap, weights) are the dcf-analyst agent's judgment set 2026-09-21 from the FY25 annual report, 1H26 report and AMP.AX_Analysis.json. Weights 25/50/25.
A13: Refresh after next print | B13: FY26 result (Feb 2027): TTM segment NPAT, below-the-line items, CET1 surplus, DTA, share count after the 2H26 buyback, dividend, and the price.
... A16: Staleness | B16: All figures go stale: price daily, balance sheet each half. Do not act on this file without refreshing the Assumptions inputs.

Sheet Actuals
A1: Reported history (A$m unless stated). Sources: AMP annual reports FY2020-FY2025, half-year reports 1H25/1H26 (Extracted/*.txt).
A3: Metric | B3: FY2020 | C3: FY2021 | D3: FY2022 | E3: FY2023 | F3: FY2024 | G3: FY2025 | H3: 1H2025 | I3: 1H2026 | J3: TTM Jun-26 | K3: Source / note
A4: Underlying NPAT | B4: 295 | C4: 356 | D4: 184 | E4: 210 | F4: 236 | G4: 285 | H4: 131 | I4: 174 | J4: =G4-H4+I4 | K4: kpis UnderlyingNPAT; FY24/1H25 restated for cost allocation
A5: Platforms | F5: 97 | G5: 106 | H5: 53 | I5: 61 | J5: =G5-H5+I5 | K5: FY25 AR p15; 1H26 directors' report
A6: Superannuation & Investments | F6: 54 | G6: 62 | H6: 27 | I6: 32 | J6: =G6-H6+I6
A7: NZ Wealth Management | F7: 37 | G7: 39 | H7: 19 | I7: 18 | J7: =G7-H7+I7
A8: AMP Bank | F8: 61 | G8: 55 | H8: 30 | I8: 20 | J8: =G8-H8+I8 | K8: FY25 incl. GO loss -10; 1H26 GO investment
A9: Partnerships & Group | F9: -13 | G9: 23 | H9: 2 | I9: 43 | J9: =G9-H9+I9 | K9: China partnerships 72 FY25, 56 1H26
A10: Statutory NPAT attributable | B10: 177 | C10: -252 | D10: 387 | E10: 265 | F10: 150 | G10: 133 | H10: 98 | I10: 154 | J10: =G10-H10+I10 | K10: core_metrics net_income
A11: Below-the-line items | B11: -118 | C11: -608 | D11: 203 | E11: 55 | F11: -87 | G11: -152 | H11: -33 | I11: -20 | J11: =G11-H11+I11 | K11: statutory - underlying; FY22-23 positive on disposal gains
A12: Total revenue (proxy) | B12: 3427 | C12: 3297 | D12: 2369 | E12: 2976 | F12: 2869 | G12: 2811 | H12: 1376 | I12: 1425 | J12: =G12-H12+I12 | K12: core_metrics revenue; includes gross bank interest
A13: Operating cash flow | B13: -5410 | C13: 1689 | D13: 2566 | E13: -105 | F13: 216 | G13: -1375 | H13: -192 | I13: -1181 | K13: MEANINGLESS for valuation: loan/deposit movements
A14: Cash tax paid | B14: 417 | E14: -20 | F14: -69 | G14: 18 | H14: 11 | I14: 7 | K14: kpis CashTaxesPaid, sign as paid; DTA utilisation keeps it low
A15: Share-based payment expense | B15: 22 | C15: 17 | D15: 11 | E15: 9 | F15: 7 | G15: 11 | H15: 10 | I15: 21 | J15: =G15-H15+I15 | K15: statement of changes in equity
A16: Share buy-backs | B16: 0 | C16: 196 | D16: 267 | E16: 338 | F16: 244 | G16: 0 | H16: 0 | I16: 150 | K16: cash flow statement, actual outflow
A17: Dividends paid | B17: 360 | C17: 0 | D17: 0 | E17: 145 | F17: 106 | G17: 76 | H17: 25 | I17: 51 | K17: cash flow statement
A18: Shares on issue (m) | B18: 3428 | C18: 3335 | D18: 3213 | E18: 2860 | F18: 2625 | G18: 2530 | H18: 2532 | I18: 2433 | K18: period end; 1H26 after 98.9m buyback
A19: Shareholders' equity | B19: 4282 | C19: 3983 | D19: 4171 | E19: 3874 | F19: 3652 | G19: 3744 | H19: 3735 | I19: 3696 | K19: core_metrics
A20: Underlying EPS (cents) | B20: 8.6 | C20: 10.7 | D20: 5.7 | E20: 7.3 | F20: 9 | G20: 11.3 | H20: 5.2 | I20: 6.9 | J20: =G20-H20+I20 | K20: FY20-23 derived NPAT/shares; FY24+ reported
A21: Underlying ROE % | F21: 6.4 | G21: 8 | H21: 7.4 | I21: 9.8 | K21: reported
A22: Total AUM (A$bn) | F22: 148.4 | G22: 161.7 | H22: 153.9 | I22: 167.6 | K22: kpis TotalAUM
A23: AMP Bank loans | F23: 23274 | G23: 24098 | H23: 23521 | I23: 23734 | K23: gross loans
A24: CET1 surplus capital | F24: 139 | G24: 287 | I24: 322 | K24: capital note

Sheet Assumptions
A1: Global inputs (blue) and scenario levers (yellow). Every DCF tab links here.
A3: Share price (A$) | B3: 2.55 | C3: ASX close 2026-09-21 06:10:30Z
A4: Diluted shares (m) | B4: 2475.7 | C4: 2,432.8 issued - 2.1 treasury + 45 dilutive, 30-Jun-2026
A5: CET1 surplus capital (A$m) | B5: 322 | C5: 30-Jun-2026, note 4.3
A6: Net DTA at PV (A$m) | B6: 300 | C6: A$418m face, ~4yr utilisation, haircut to 300
A7: Net distributable capital added (A$m) | B7: =B5+B6 | C7: enters the bridge as net cash; no debt deducted
A8: Cost of equity | B8: 0.105 | C8: AUD: 4.4% rf + 1.1 x 5.5% ERP; same for all scenarios
A9: Hurdle rate | B9: 0.15 | C9: entry-price IRR
A10: SBC TTM (A$m) | B10: 22 | C10: expensed in underlying NPAT; street memo adds back
A11: Revenue proxy TTM (A$m) | B11: 2860 | C11: engine scaler only
A12: Tax rate (mapping) | B12: 0.3 | C12: engine mapping only
A14: Scenario levers
B15: Bear | C15: Base | D15: Bull
A16: Terminal growth | B16: 0.015 | C16: 0.025 | D16: 0.03
A17: Exit P/E cap (x distributable) | B17: 12 | C17: 15 | D17: 15
A18: Probability weight | B18: 0.25 | C18: 0.5 | D18: 0.25
A19: Revenue proxy growth %/yr | B19: 0.01 | C19: 0.04 | D19: 0.06
A20: Weights check (must be 1.0) | B20: =SUM(B18:D18)
A22: Scenario narratives
A23: Bear | B23: An equity-market drawdown plus fee caps stall Platforms at ~3% and put S&I back into net outflows; NIM pressure and a failed GO scale-up hold the bank at $43-50m; China partnership earnings halve on regulatory or repatriation constraints (they were 32% of 1H26 underlying NPAT); a new remediation/litigation cycle keeps below-the-line items at 15-20% of NPAT; mega super funds use DBFO Tranche 2 to take retirement flows from adviser platforms; new CEO Blair Vernon's strategy reset consumes capital. g 1.5%, 12x cap.
A24: Base | B24: Platforms (North) keeps compounding on adviser activations and managed-portfolio flows (~$3bn/half net inflows, AUM +10-11%/yr) with ~2bps/yr fee-margin compression (FY26 guided 40-41bps vs 42bps FY25), so NPAT grows ~10% fading to 3%. S&I has just reached cashflow break-even; growth is market beta net of fee caps. NZ Wealth tracks KiwiSaver contributions. AMP Bank absorbs GO start-up losses through 2027 then recovers to ~$66-70m by Y3-4 (NIM guided flat ~1.25%, GO deposits scaling toward the $2bn target, ROC back to 5-6%). Partnerships & Group steps down in Y1 (surplus-capital interest stripped, buyback cash gone, China partnership growth slows from the 107% 1H26 spike to ~10%) then grows 3-4%. Below-the-line items persist at 10% of underlying NPAT for two years then settle at 5% - AMP has never had a clean statutory year outside disposal gains. 10% of statutory profit retained for bank capital. CoE 10.5%, g 2.5%, 15x cap (Gordon at 12.8x binds).
A25: Bull | B25: North wins platform share faster (AUM +13%, margin compression slower as managed portfolios scale), S&I turns to sustained net inflows, AMP Bank GO reaches breakeven by Y2 and the bank's ROC rises toward 7%, China's CLPC keeps compounding at 10%+ as the pension market opens, cost-out delivers a cost-to-income ratio under 55%, and remediation finally fades to 3% of NPAT. g 3.0%, 15x cap.

Sheet DCF_Bear
A1: Bear case: segment underlying NPAT -> distributable earnings -> value. A$m. Drivers in yellow.
A3: Year | B3: TTM Jun-26A | C3: Y1E | D3: Y2E | E3: Y3E | F3: Y4E | G3: Y5E | H3: Y6E | I3: Y7E | J3: Y8E | K3: Y9E | L3: Y10E
A4: Year index | B4: 0 | C4: 1 | D4: 2 | E4: 3 | F4: 4 | G4: 5 | H4: 6 | I4: 7 | J4: 8 | K4: 9 | L4: 10
A5: Platforms NPAT growth % | C5: 0.03 | D5: 0.02 | E5: 0.03 | F5: 0.03 | G5: 0.03 | H5: 0.03 | I5: 0.03 | J5: 0.03 | K5: 0.03 | L5: 0.03
A6: Superannuation & Investments NPAT growth % | C6: -0.02 | D6: -0.02 | E6: 0 | F6: 0.01 | G6: 0.01 | H6: 0.02 | I6: 0.02 | J6: 0.02 | K6: 0.02 | L6: 0.02
A7: NZ Wealth Management NPAT growth % | C7: 0 | D7: 0.01 | E7: 0.01 | F7: 0.02 | G7: 0.02 | H7: 0.02 | I7: 0.02 | J7: 0.02 | K7: 0.02 | L7: 0.02
A8: AMP Bank NPAT growth % | C8: -0.05 | D8: 0 | E8: 0.05 | F8: 0.05 | G8: 0.03 | H8: 0.03 | I8: 0.03 | J8: 0.03 | K8: 0.03 | L8: 0.03
A9: Partnerships & Group NPAT growth % | C9: -0.4 | D9: 0 | E9: 0.02 | F9: 0.02 | G9: 0.02 | H9: 0.02 | I9: 0.02 | J9: 0.02 | K9: 0.02 | L9: 0.02
A10: Platforms underlying NPAT | B10: =Actuals!J5 | C10: =B10*(1+C5) | D10: =C10*(1+D5) | E10: =D10*(1+E5) | F10: =E10*(1+F5) | G10: =F10*(1+G5) | H10: =G10*(1+H5) | I10: =H10*(1+I5) | J10: =I10*(1+J5) | ... L10: =K10*(1+L5)
A11: Superannuation & Investments underlying NPAT | B11: =Actuals!J6 | C11: =B11*(1+C6) | D11: =C11*(1+D6) | E11: =D11*(1+E6) | F11: =E11*(1+F6) | G11: =F11*(1+G6) | H11: =G11*(1+H6) | I11: =H11*(1+I6) | J11: =I11*(1+J6) | ... L11: =K11*(1+L6)
A12: NZ Wealth Management underlying NPAT | B12: =Actuals!J7 | C12: =B12*(1+C7) | D12: =C12*(1+D7) | E12: =D12*(1+E7) | F12: =E12*(1+F7) | G12: =F12*(1+G7) | H12: =G12*(1+H7) | I12: =H12*(1+I7) | J12: =I12*(1+J7) | ... L12: =K12*(1+L7)
A13: AMP Bank underlying NPAT | B13: =Actuals!J8 | C13: =B13*(1+C8) | D13: =C13*(1+D8) | E13: =D13*(1+E8) | F13: =E13*(1+F8) | G13: =F13*(1+G8) | H13: =G13*(1+H8) | I13: =H13*(1+I8) | J13: =I13*(1+J8) | ... L13: =K13*(1+L8)
A14: Partnerships & Group underlying NPAT | B14: =Actuals!J9 | C14: =B14*(1+C9) | D14: =C14*(1+D9) | E14: =D14*(1+E9) | F14: =E14*(1+F9) | G14: =F14*(1+G9) | H14: =G14*(1+H9) | I14: =H14*(1+I9) | J14: =I14*(1+J9) | ... L14: =K14*(1+L9)
A15: Underlying NPAT (group) | B15: =SUM(B10:B14) | C15: =SUM(C10:C14) | D15: =SUM(D10:D14) | E15: =SUM(E10:E14) | F15: =SUM(F10:F14) | G15: =SUM(G10:G14) | H15: =SUM(H10:H14) | I15: =SUM(I10:I14) | ... L15: =SUM(L10:L14)
A16: Below-the-line items % of underlying NPAT | C16: 0.2 | D16: 0.2 | E16: 0.15 | F16: 0.12 | G16: 0.1 | H16: 0.1 | I16: 0.1 | J16: 0.1 | K16: 0.1 | L16: 0.1
A17: Below-the-line items (simplification, remediation, litigation) | C17: =-C15*C16 | D17: =-D15*D16 | E17: =-E15*E16 | F17: =-F15*F16 | G17: =-G15*G16 | H17: =-H15*H16 | I17: =-I15*I16 | J17: =-J15*J16 | ... L17: =-L15*L16
A18: Statutory NPAT proxy | C18: =C15+C17 | D18: =D15+D17 | E18: =E15+E17 | F18: =F15+F17 | G18: =G15+G17 | H18: =H15+H17 | I18: =I15+I17 | J18: =J15+J17 | ... L18: =L15+L17
A19: Capital retained % of statutory NPAT | C19: 0.12 | D19: 0.12 | E19: 0.12 | F19: 0.12 | G19: 0.12 | H19: 0.12 | I19: 0.12 | J19: 0.12 | K19: 0.12 | L19: 0.12
A20: Capital retained for growth | C20: =-C18*C19 | D20: =-D18*D19 | E20: =-E18*E19 | F20: =-F18*F19 | G20: =-G18*G19 | H20: =-H18*H19 | I20: =-I18*I19 | J20: =-J18*J19 | ... L20: =-L18*L19
A21: Distributable earnings | C21: =C18+C20 | D21: =D18+D20 | E21: =E18+E20 | F21: =F18+F20 | G21: =G18+G20 | H21: =H18+H20 | I21: =I18+I20 | J21: =J18+J20 | ... L21: =L18+L20
A22: Discount factor at cost of equity | C22: =1/(1+Assumptions!$B$8)^C4 | D22: =1/(1+Assumptions!$B$8)^D4 | E22: =1/(1+Assumptions!$B$8)^E4 | F22: =1/(1+Assumptions!$B$8)^F4 | G22: =1/(1+Assumptions!$B$8)^G4 | H22: =1/(1+Assumptions!$B$8)^H4 | I22: =1/(1+Assumptions!$B$8)^I4 | J22: =1/(1+Assumptions!$B$8)^J4 | ... L22: =1/(1+Assumptions!$B$8)^L4
A23: PV of distributable earnings | C23: =C21*C22 | D23: =D21*D22 | E23: =E21*E22 | F23: =F21*F22 | G23: =G21*G22 | H23: =H21*H22 | I23: =I21*I22 | J23: =J21*J22 | ... L23: =L21*L22
A25: Memo: revenue proxy (engine scaler) | B25: =Assumptions!B11 | C25: =B25*(1+Assumptions!B$19) | D25: =C25*(1+Assumptions!B$19) | E25: =D25*(1+Assumptions!B$19) | F25: =E25*(1+Assumptions!B$19) | G25: =F25*(1+Assumptions!B$19) | H25: =G25*(1+Assumptions!B$19) | I25: =H25*(1+Assumptions!B$19) | J25: =I25*(1+Assumptions!B$19) | K25: =J25*(1+Assumptions!B$19) | L25: =K25*(1+Assumptions!B$19)
A26: Memo: SBC expensed inside NPAT (street add-back) | B26: =Assumptions!B10 | C26: =C25*Assumptions!$B$10/Assumptions!$B$11 | D26: =D25*Assumptions!$B$10/Assumptions!$B$11 | E26: =E25*Assumptions!$B$10/Assumptions!$B$11 | F26: =F25*Assumptions!$B$10/Assumptions!$B$11 | G26: =G25*Assumptions!$B$10/Assumptions!$B$11 | H26: =H25*Assumptions!$B$10/Assumptions!$B$11 | I26: =I25*Assumptions!$B$10/Assumptions!$B$11 | J26: =J25*Assumptions!$B$10/Assumptions!$B$11 | ... L26: =L25*Assumptions!$B$10/Assumptions!$B$11
A28: Sum of PV, years 1-10 | B28: =SUM(C23:L23)
A29: Terminal growth | B29: =Assumptions!B16
A30: Terminal distributable earnings (Y10 x (1+g)) | B30: =L21*(1+B29)
A31: Gordon terminal value | B31: =B30/(Assumptions!B8-B29)
A32: Exit P/E cap x Y10 distributable | B32: =Assumptions!B17*L21
A33: Terminal value used = MAX(0,MIN(Gordon,cap)) | B33: =MAX(0,MIN(B31,B32))
A34: Implied exit multiple on Y10 distributable | B34: =B33/L21
A35: PV of terminal value | B35: =B33*L22
A36: Value of earnings stream (EV-equivalent) | B36: =B28+B35
A37: Add: CET1 surplus + DTA PV | B37: =Assumptions!B7
A38: Equity value | B38: =B36+B37
A39: Diluted shares (m) | B39: =Assumptions!B4
A40: Value per share (A$) | B40: =B38/B39
A41: Upside vs price | B41: =B40/Assumptions!B3-1
A42: Terminal % of value | B42: =B35/B36
A44: Street memo: PV of explicit SBC | B44: =SUMPRODUCT(C26:L26/(1+Assumptions!$B$8)^C4:L4)
...

Sheet DCF_Base
A1: Base case: segment underlying NPAT -> distributable earnings -> value. A$m. Drivers in yellow.
A3: Year | B3: TTM Jun-26A | C3: Y1E | D3: Y2E | E3: Y3E | F3: Y4E | G3: Y5E | H3: Y6E | I3: Y7E | J3: Y8E | K3: Y9E | L3: Y10E
A4: Year index | B4: 0 | C4: 1 | D4: 2 | E4: 3 | F4: 4 | G4: 5 | H4: 6 | I4: 7 | J4: 8 | K4: 9 | L4: 10
A5: Platforms NPAT growth % | C5: 0.1 | D5: 0.09 | E5: 0.08 | F5: 0.07 | G5: 0.06 | H5: 0.05 | I5: 0.05 | J5: 0.04 | K5: 0.04 | L5: 0.03
A6: Superannuation & Investments NPAT growth % | C6: 0.05 | D6: 0.04 | E6: 0.04 | F6: 0.03 | G6: 0.03 | H6: 0.03 | I6: 0.03 | J6: 0.03 | K6: 0.03 | L6: 0.03
A7: NZ Wealth Management NPAT growth % | C7: 0.02 | D7: 0.03 | E7: 0.03 | F7: 0.03 | G7: 0.03 | H7: 0.03 | I7: 0.03 | J7: 0.03 | K7: 0.03 | L7: 0.03
A8: AMP Bank NPAT growth % | C8: 0.07 | D8: 0.21 | E8: 0.14 | F8: 0.06 | G8: 0.03 | H8: 0.03 | I8: 0.03 | J8: 0.03 | K8: 0.03 | L8: 0.03
A9: Partnerships & Group NPAT growth % | C9: -0.14 | D9: 0.04 | E9: 0.04 | F9: 0.04 | G9: 0.04 | H9: 0.03 | I9: 0.03 | J9: 0.03 | K9: 0.03 | L9: 0.03
A10: Platforms underlying NPAT | B10: =Actuals!J5 | C10: =B10*(1+C5) | D10: =C10*(1+D5) | E10: =D10*(1+E5) | F10: =E10*(1+F5) | G10: =F10*(1+G5) | H10: =G10*(1+H5) | I10: =H10*(1+I5) | J10: =I10*(1+J5) | ... L10: =K10*(1+L5)
A11: Superannuation & Investments underlying NPAT | B11: =Actuals!J6 | C11: =B11*(1+C6) | D11: =C11*(1+D6) | E11: =D11*(1+E6) | F11: =E11*(1+F6) | G11: =F11*(1+G6) | H11: =G11*(1+H6) | I11: =H11*(1+I6) | J11: =I11*(1+J6) | ... L11: =K11*(1+L6)
A12: NZ Wealth Management underlying NPAT | B12: =Actuals!J7 | C12: =B12*(1+C7) | D12: =C12*(1+D7) | E12: =D12*(1+E7) | F12: =E12*(1+F7) | G12: =F12*(1+G7) | H12: =G12*(1+H7) | I12: =H12*(1+I7) | J12: =I12*(1+J7) | ... L12: =K12*(1+L7)
A13: AMP Bank underlying NPAT | B13: =Actuals!J8 | C13: =B13*(1+C8) | D13: =C13*(1+D8) | E13: =D13*(1+E8) | F13: =E13*(1+F8) | G13: =F13*(1+G8) | H13: =G13*(1+H8) | I13: =H13*(1+I8) | J13: =I13*(1+J8) | ... L13: =K13*(1+L8)
A14: Partnerships & Group underlying NPAT | B14: =Actuals!J9 | C14: =B14*(1+C9) | D14: =C14*(1+D9) | E14: =D14*(1+E9) | F14: =E14*(1+F9) | G14: =F14*(1+G9) | H14: =G14*(1+H9) | I14: =H14*(1+I9) | J14: =I14*(1+J9) | ... L14: =K14*(1+L9)
A15: Underlying NPAT (group) | B15: =SUM(B10:B14) | C15: =SUM(C10:C14) | D15: =SUM(D10:D14) | E15: =SUM(E10:E14) | F15: =SUM(F10:F14) | G15: =SUM(G10:G14) | H15: =SUM(H10:H14) | I15: =SUM(I10:I14) | ... L15: =SUM(L10:L14)
A16: Below-the-line items % of underlying NPAT | C16: 0.1 | D16: 0.1 | E16: 0.07 | F16: 0.07 | G16: 0.07 | H16: 0.05 | I16: 0.05 | J16: 0.05 | K16: 0.05 | L16: 0.05
A17: Below-the-line items (simplification, remediation, litigation) | C17: =-C15*C16 | D17: =-D15*D16 | E17: =-E15*E16 | F17: =-F15*F16 | G17: =-G15*G16 | H17: =-H15*H16 | I17: =-I15*I16 | J17: =-J15*J16 | ... L17: =-L15*L16
A18: Statutory NPAT proxy | C18: =C15+C17 | D18: =D15+D17 | E18: =E15+E17 | F18: =F15+F17 | G18: =G15+G17 | H18: =H15+H17 | I18: =I15+I17 | J18: =J15+J17 | ... L18: =L15+L17
A19: Capital retained % of statutory NPAT | C19: 0.1 | D19: 0.1 | E19: 0.1 | F19: 0.1 | G19: 0.1 | H19: 0.1 | I19: 0.1 | J19: 0.1 | K19: 0.1 | L19: 0.1
A20: Capital retained for growth | C20: =-C18*C19 | D20: =-D18*D19 | E20: =-E18*E19 | F20: =-F18*F19 | G20: =-G18*G19 | H20: =-H18*H19 | I20: =-I18*I19 | J20: =-J18*J19 | ... L20: =-L18*L19
A21: Distributable earnings | C21: =C18+C20 | D21: =D18+D20 | E21: =E18+E20 | F21: =F18+F20 | G21: =G18+G20 | H21: =H18+H20 | I21: =I18+I20 | J21: =J18+J20 | ... L21: =L18+L20
A22: Discount factor at cost of equity | C22: =1/(1+Assumptions!$B$8)^C4 | D22: =1/(1+Assumptions!$B$8)^D4 | E22: =1/(1+Assumptions!$B$8)^E4 | F22: =1/(1+Assumptions!$B$8)^F4 | G22: =1/(1+Assumptions!$B$8)^G4 | H22: =1/(1+Assumptions!$B$8)^H4 | I22: =1/(1+Assumptions!$B$8)^I4 | J22: =1/(1+Assumptions!$B$8)^J4 | ... L22: =1/(1+Assumptions!$B$8)^L4
A23: PV of distributable earnings | C23: =C21*C22 | D23: =D21*D22 | E23: =E21*E22 | F23: =F21*F22 | G23: =G21*G22 | H23: =H21*H22 | I23: =I21*I22 | J23: =J21*J22 | ... L23: =L21*L22
A25: Memo: revenue proxy (engine scaler) | B25: =Assumptions!B11 | C25: =B25*(1+Assumptions!C$19) | D25: =C25*(1+Assumptions!C$19) | E25: =D25*(1+Assumptions!C$19) | F25: =E25*(1+Assumptions!C$19) | G25: =F25*(1+Assumptions!C$19) | H25: =G25*(1+Assumptions!C$19) | I25: =H25*(1+Assumptions!C$19) | J25: =I25*(1+Assumptions!C$19) | K25: =J25*(1+Assumptions!C$19) | L25: =K25*(1+Assumptions!C$19)
A26: Memo: SBC expensed inside NPAT (street add-back) | B26: =Assumptions!B10 | C26: =C25*Assumptions!$B$10/Assumptions!$B$11 | D26: =D25*Assumptions!$B$10/Assumptions!$B$11 | E26: =E25*Assumptions!$B$10/Assumptions!$B$11 | F26: =F25*Assumptions!$B$10/Assumptions!$B$11 | G26: =G25*Assumptions!$B$10/Assumptions!$B$11 | H26: =H25*Assumptions!$B$10/Assumptions!$B$11 | I26: =I25*Assumptions!$B$10/Assumptions!$B$11 | J26: =J25*Assumptions!$B$10/Assumptions!$B$11 | ... L26: =L25*Assumptions!$B$10/Assumptions!$B$11
A28: Sum of PV, years 1-10 | B28: =SUM(C23:L23)
A29: Terminal growth | B29: =Assumptions!C16
A30: Terminal distributable earnings (Y10 x (1+g)) | B30: =L21*(1+B29)
A31: Gordon terminal value | B31: =B30/(Assumptions!B8-B29)
A32: Exit P/E cap x Y10 distributable | B32: =Assumptions!C17*L21
A33: Terminal value used = MAX(0,MIN(Gordon,cap)) | B33: =MAX(0,MIN(B31,B32))
A34: Implied exit multiple on Y10 distributable | B34: =B33/L21
A35: PV of terminal value | B35: =B33*L22
A36: Value of earnings stream (EV-equivalent) | B36: =B28+B35
A37: Add: CET1 surplus + DTA PV | B37: =Assumptions!B7
A38: Equity value | B38: =B36+B37
A39: Diluted shares (m) | B39: =Assumptions!B4
A40: Value per share (A$) | B40: =B38/B39
A41: Upside vs price | B41: =B40/Assumptions!B3-1
A42: Terminal % of value | B42: =B35/B36
A44: Street memo: PV of explicit SBC | B44: =SUMPRODUCT(C26:L26/(1+Assumptions!$B$8)^C4:L4)
...

Sheet DCF_Bull
A1: Bull case: segment underlying NPAT -> distributable earnings -> value. A$m. Drivers in yellow.
A3: Year | B3: TTM Jun-26A | C3: Y1E | D3: Y2E | E3: Y3E | F3: Y4E | G3: Y5E | H3: Y6E | I3: Y7E | J3: Y8E | K3: Y9E | L3: Y10E
A4: Year index | B4: 0 | C4: 1 | D4: 2 | E4: 3 | F4: 4 | G4: 5 | H4: 6 | I4: 7 | J4: 8 | K4: 9 | L4: 10
A5: Platforms NPAT growth % | C5: 0.13 | D5: 0.12 | E5: 0.11 | F5: 0.1 | G5: 0.09 | H5: 0.08 | I5: 0.07 | J5: 0.06 | K5: 0.05 | L5: 0.04
A6: Superannuation & Investments NPAT growth % | C6: 0.07 | D6: 0.06 | E6: 0.05 | F6: 0.05 | G6: 0.04 | H6: 0.04 | I6: 0.04 | J6: 0.03 | K6: 0.03 | L6: 0.03
A7: NZ Wealth Management NPAT growth % | C7: 0.04 | D7: 0.04 | E7: 0.04 | F7: 0.04 | G7: 0.04 | H7: 0.03 | I7: 0.03 | J7: 0.03 | K7: 0.03 | L7: 0.03
A8: AMP Bank NPAT growth % | C8: 0.15 | D8: 0.3 | E8: 0.2 | F8: 0.1 | G8: 0.05 | H8: 0.04 | I8: 0.04 | J8: 0.04 | K8: 0.04 | L8: 0.04
A9: Partnerships & Group NPAT growth % | C9: -0.05 | D9: 0.12 | E9: 0.1 | F9: 0.08 | G9: 0.06 | H9: 0.05 | I9: 0.04 | J9: 0.04 | K9: 0.04 | L9: 0.04
A10: Platforms underlying NPAT | B10: =Actuals!J5 | C10: =B10*(1+C5) | D10: =C10*(1+D5) | E10: =D10*(1+E5) | F10: =E10*(1+F5) | G10: =F10*(1+G5) | H10: =G10*(1+H5) | I10: =H10*(1+I5) | J10: =I10*(1+J5) | ... L10: =K10*(1+L5)
A11: Superannuation & Investments underlying NPAT | B11: =Actuals!J6 | C11: =B11*(1+C6) | D11: =C11*(1+D6) | E11: =D11*(1+E6) | F11: =E11*(1+F6) | G11: =F11*(1+G6) | H11: =G11*(1+H6) | I11: =H11*(1+I6) | J11: =I11*(1+J6) | ... L11: =K11*(1+L6)
A12: NZ Wealth Management underlying NPAT | B12: =Actuals!J7 | C12: =B12*(1+C7) | D12: =C12*(1+D7) | E12: =D12*(1+E7) | F12: =E12*(1+F7) | G12: =F12*(1+G7) | H12: =G12*(1+H7) | I12: =H12*(1+I7) | J12: =I12*(1+J7) | ... L12: =K12*(1+L7)
A13: AMP Bank underlying NPAT | B13: =Actuals!J8 | C13: =B13*(1+C8) | D13: =C13*(1+D8) | E13: =D13*(1+E8) | F13: =E13*(1+F8) | G13: =F13*(1+G8) | H13: =G13*(1+H8) | I13: =H13*(1+I8) | J13: =I13*(1+J8) | ... L13: =K13*(1+L8)
A14: Partnerships & Group underlying NPAT | B14: =Actuals!J9 | C14: =B14*(1+C9) | D14: =C14*(1+D9) | E14: =D14*(1+E9) | F14: =E14*(1+F9) | G14: =F14*(1+G9) | H14: =G14*(1+H9) | I14: =H14*(1+I9) | J14: =I14*(1+J9) | ... L14: =K14*(1+L9)
A15: Underlying NPAT (group) | B15: =SUM(B10:B14) | C15: =SUM(C10:C14) | D15: =SUM(D10:D14) | E15: =SUM(E10:E14) | F15: =SUM(F10:F14) | G15: =SUM(G10:G14) | H15: =SUM(H10:H14) | I15: =SUM(I10:I14) | ... L15: =SUM(L10:L14)
A16: Below-the-line items % of underlying NPAT | C16: 0.06 | D16: 0.05 | E16: 0.04 | F16: 0.03 | G16: 0.03 | H16: 0.03 | I16: 0.03 | J16: 0.03 | K16: 0.03 | L16: 0.03
A17: Below-the-line items (simplification, remediation, litigation) | C17: =-C15*C16 | D17: =-D15*D16 | E17: =-E15*E16 | F17: =-F15*F16 | G17: =-G15*G16 | H17: =-H15*H16 | I17: =-I15*I16 | J17: =-J15*J16 | ... L17: =-L15*L16
A18: Statutory NPAT proxy | C18: =C15+C17 | D18: =D15+D17 | E18: =E15+E17 | F18: =F15+F17 | G18: =G15+G17 | H18: =H15+H17 | I18: =I15+I17 | J18: =J15+J17 | ... L18: =L15+L17
A19: Capital retained % of statutory NPAT | C19: 0.08 | D19: 0.08 | E19: 0.08 | F19: 0.08 | G19: 0.08 | H19: 0.08 | I19: 0.08 | J19: 0.08 | K19: 0.08 | L19: 0.08
A20: Capital retained for growth | C20: =-C18*C19 | D20: =-D18*D19 | E20: =-E18*E19 | F20: =-F18*F19 | G20: =-G18*G19 | H20: =-H18*H19 | I20: =-I18*I19 | J20: =-J18*J19 | ... L20: =-L18*L19
A21: Distributable earnings | C21: =C18+C20 | D21: =D18+D20 | E21: =E18+E20 | F21: =F18+F20 | G21: =G18+G20 | H21: =H18+H20 | I21: =I18+I20 | J21: =J18+J20 | ... L21: =L18+L20
A22: Discount factor at cost of equity | C22: =1/(1+Assumptions!$B$8)^C4 | D22: =1/(1+Assumptions!$B$8)^D4 | E22: =1/(1+Assumptions!$B$8)^E4 | F22: =1/(1+Assumptions!$B$8)^F4 | G22: =1/(1+Assumptions!$B$8)^G4 | H22: =1/(1+Assumptions!$B$8)^H4 | I22: =1/(1+Assumptions!$B$8)^I4 | J22: =1/(1+Assumptions!$B$8)^J4 | ... L22: =1/(1+Assumptions!$B$8)^L4
A23: PV of distributable earnings | C23: =C21*C22 | D23: =D21*D22 | E23: =E21*E22 | F23: =F21*F22 | G23: =G21*G22 | H23: =H21*H22 | I23: =I21*I22 | J23: =J21*J22 | ... L23: =L21*L22
A25: Memo: revenue proxy (engine scaler) | B25: =Assumptions!B11 | C25: =B25*(1+Assumptions!D$19) | D25: =C25*(1+Assumptions!D$19) | E25: =D25*(1+Assumptions!D$19) | F25: =E25*(1+Assumptions!D$19) | G25: =F25*(1+Assumptions!D$19) | H25: =G25*(1+Assumptions!D$19) | I25: =H25*(1+Assumptions!D$19) | J25: =I25*(1+Assumptions!D$19) | K25: =J25*(1+Assumptions!D$19) | L25: =K25*(1+Assumptions!D$19)
A26: Memo: SBC expensed inside NPAT (street add-back) | B26: =Assumptions!B10 | C26: =C25*Assumptions!$B$10/Assumptions!$B$11 | D26: =D25*Assumptions!$B$10/Assumptions!$B$11 | E26: =E25*Assumptions!$B$10/Assumptions!$B$11 | F26: =F25*Assumptions!$B$10/Assumptions!$B$11 | G26: =G25*Assumptions!$B$10/Assumptions!$B$11 | H26: =H25*Assumptions!$B$10/Assumptions!$B$11 | I26: =I25*Assumptions!$B$10/Assumptions!$B$11 | J26: =J25*Assumptions!$B$10/Assumptions!$B$11 | ... L26: =L25*Assumptions!$B$10/Assumptions!$B$11
A28: Sum of PV, years 1-10 | B28: =SUM(C23:L23)
A29: Terminal growth | B29: =Assumptions!D16
A30: Terminal distributable earnings (Y10 x (1+g)) | B30: =L21*(1+B29)
A31: Gordon terminal value | B31: =B30/(Assumptions!B8-B29)
A32: Exit P/E cap x Y10 distributable | B32: =Assumptions!D17*L21
A33: Terminal value used = MAX(0,MIN(Gordon,cap)) | B33: =MAX(0,MIN(B31,B32))
A34: Implied exit multiple on Y10 distributable | B34: =B33/L21
A35: PV of terminal value | B35: =B33*L22
A36: Value of earnings stream (EV-equivalent) | B36: =B28+B35
A37: Add: CET1 surplus + DTA PV | B37: =Assumptions!B7
A38: Equity value | B38: =B36+B37
A39: Diluted shares (m) | B39: =Assumptions!B4
A40: Value per share (A$) | B40: =B38/B39
A41: Upside vs price | B41: =B40/Assumptions!B3-1
A42: Terminal % of value | B42: =B35/B36
A44: Street memo: PV of explicit SBC | B44: =SUMPRODUCT(C26:L26/(1+Assumptions!$B$8)^C4:L4)
...

Sheet Earnings_Quality
A1: Underlying vs statutory reconciliation, replacing the owner-FCF FCF_Quality tab: reported FCF is not a valuation input for a bank-inclusive group.
A3: Metric | B3: FY2020 | C3: FY2021 | D3: FY2022 | E3: FY2023 | F3: FY2024 | G3: FY2025 | H3: 1H2025 | I3: 1H2026 | J3: TTM Jun-26
A4: Underlying NPAT | B4: =Actuals!B4 | C4: =Actuals!C4 | D4: =Actuals!D4 | E4: =Actuals!E4 | F4: =Actuals!F4 | G4: =Actuals!G4 | H4: =Actuals!H4 | I4: =Actuals!I4 | J4: =Actuals!J4
A5: Below-the-line items | B5: =Actuals!B11 | C5: =Actuals!C11 | D5: =Actuals!D11 | E5: =Actuals!E11 | F5: =Actuals!F11 | G5: =Actuals!G11 | H5: =Actuals!H11 | I5: =Actuals!I11 | J5: =Actuals!J11
A6: Statutory NPAT | B6: =Actuals!B10 | C6: =Actuals!C10 | D6: =Actuals!D10 | E6: =Actuals!E10 | F6: =Actuals!F10 | G6: =Actuals!G10 | H6: =Actuals!H10 | I6: =Actuals!I10 | J6: =Actuals!J10
A7: Leakage % of underlying | B7: =IF(Actuals!B4=0,"",-Actuals!B11/Actuals!B4) | C7: =IF(Actuals!C4=0,"",-Actuals!C11/Actuals!C4) | D7: =IF(Actuals!D4=0,"",-Actuals!D11/Actuals!D4) | E7: =IF(Actuals!E4=0,"",-Actuals!E11/Actuals!E4) | F7: =IF(Actuals!F4=0,"",-Actuals!F11/Actuals!F4) | G7: =IF(Actuals!G4=0,"",-Actuals!G11/Actuals!G4) | H7: =IF(Actuals!H4=0,"",-Actuals!H11/Actuals!H4) | I7: =IF(Actuals!I4=0,"",-Actuals!I11/Actuals!I4) | J7: =IF(Actuals!J4=0,"",-Actuals!J11/Actuals!J4)
A8: Statutory / underlying conversion | B8: =IF(Actuals!B4=0,"",Actuals!B10/Actuals!B4) | C8: =IF(Actuals!C4=0,"",Actuals!C10/Actuals!C4) | D8: =IF(Actuals!D4=0,"",Actuals!D10/Actuals!D4) | E8: =IF(Actuals!E4=0,"",Actuals!E10/Actuals!E4) | F8: =IF(Actuals!F4=0,"",Actuals!F10/Actuals!F4) | G8: =IF(Actuals!G4=0,"",Actuals!G10/Actuals!G4) | H8: =IF(Actuals!H4=0,"",Actuals!H10/Actuals!H4) | I8: =IF(Actuals!I4=0,"",Actuals!I10/Actuals!I4) | J8: =IF(Actuals!J4=0,"",Actuals!J10/Actuals!J4)
A9: Memo: OCF (loan/deposit driven, not earnings) | B9: =Actuals!B13 | C9: =Actuals!C13 | D9: =Actuals!D13 | E9: =Actuals!E13 | F9: =Actuals!F13 | G9: =Actuals!G13 | H9: =Actuals!H13 | I9: =Actuals!I13 | J9: =Actuals!J13
A10: Memo: cash tax paid vs ~30% of underlying pre-tax | B10: =Actuals!B14 | C10: =Actuals!C14 | D10: =Actuals!D14 | E10: =Actuals!E14 | F10: =Actuals!F14 | G10: =Actuals!G14 | H10: =Actuals!H14 | I10: =Actuals!I14 | J10: =Actuals!J14
A11: Memo: SBC expensed | B11: =Actuals!B15 | C11: =Actuals!C15 | D11: =Actuals!D15 | E11: =Actuals!E15 | F11: =Actuals!F15 | G11: =Actuals!G15 | H11: =Actuals!H15 | I11: =Actuals!I15 | J11: =Actuals!J15
A12: Memo: buybacks + dividends paid | B12: =Actuals!B16+Actuals!B17 | C12: =Actuals!C16+Actuals!C17 | D12: =Actuals!D16+Actuals!D17 | E12: =Actuals!E16+Actuals!E17 | F12: =Actuals!F16+Actuals!F17 | G12: =Actuals!G16+Actuals!G17 | H12: =Actuals!H16+Actuals!H17 | I12: =Actuals!I16+Actuals!I17 | J12: =Actuals!J16+Actuals!J17
A14: Reading: statutory has been below underlying in every year except the FY22-23 disposal-gain years; the model charges 10% -> 5% of underlying NPAT (base) as a persistent below-the-line leakage rather than treating underlying as fully distributable.

Sheet Valuation
A1: Summary - all cells are formulas over the DCF tabs and Assumptions.
A3: Scenario | B3: Value per share | C3: Upside vs price | D3: Probability | E3: Street value/share | F3: Entry price @15% hurdle
A4: Bear | B4: =DCF_Bear!B40 | C4: =B4/Assumptions!B3-1 | D4: =Assumptions!B18 | E4: =DCF_Bear!B46 | F4: =(SUMPRODUCT(DCF_Bear!$C$21:$L$21/(1+Assumptions!$B$9)^DCF_Bear!$C$4:$L$4)+MAX(0,MIN(DCF_Bear!$L$21*(1+Assumptions!B$16)/(Assumptions!$B$9-Assumptions!B$16),Assumptions!B$17*DCF_Bear!$L$21))/(1+Assumptions!$B$9)^10+Assumptions!$B$7)/Assumptions!$B$4
A5: Base | B5: =DCF_Base!B40 | C5: =B5/Assumptions!B3-1 | D5: =Assumptions!C18 | E5: =DCF_Base!B46 | F5: =(SUMPRODUCT(DCF_Base!$C$21:$L$21/(1+Assumptions!$B$9)^DCF_Base!$C$4:$L$4)+MAX(0,MIN(DCF_Base!$L$21*(1+Assumptions!C$16)/(Assumptions!$B$9-Assumptions!C$16),Assumptions!C$17*DCF_Base!$L$21))/(1+Assumptions!$B$9)^10+Assumptions!$B$7)/Assumptions!$B$4
A6: Bull | B6: =DCF_Bull!B40 | C6: =B6/Assumptions!B3-1 | D6: =Assumptions!D18 | E6: =DCF_Bull!B46 | F6: =(SUMPRODUCT(DCF_Bull!$C$21:$L$21/(1+Assumptions!$B$9)^DCF_Bull!$C$4:$L$4)+MAX(0,MIN(DCF_Bull!$L$21*(1+Assumptions!D$16)/(Assumptions!$B$9-Assumptions!D$16),Assumptions!D$17*DCF_Bull!$L$21))/(1+Assumptions!$B$9)^10+Assumptions!$B$7)/Assumptions!$B$4
A8: Probability-weighted value per share | B8: =SUMPRODUCT(B4:B6,D4:D6)
A9: Current price | B9: =Assumptions!B3
A10: Margin of safety (1 - price/weighted) | B10: =1-B9/B8
A11: Street weighted value per share | B11: =SUMPRODUCT(E4:E6,D4:D6)
A12: Band position (price-house)/(street-house) | B12: =IF(B11=B8,"n/a",(B9-B8)/(B11-B8))
A13: Weighted entry price @15% hurdle (buy-below) | B13: =SUMPRODUCT(F4:F6,D4:D6)
A14: Entry discount vs price | B14: =B13/B9-1
A16: Required-return table (base case; TV rebuilt at each rate)
A17: Required return | B17: Value per share
A18: 0.09 | B18: =(SUMPRODUCT(DCF_Base!$C$21:$L$21/(1+$A18)^DCF_Base!$C$4:$L$4)+MAX(0,MIN(DCF_Base!$L$21*(1+Assumptions!C$16)/($A18-Assumptions!C$16),Assumptions!C$17*DCF_Base!$L$21))/(1+$A18)^10+Assumptions!$B$7)/Assumptions!$B$4
A19: 0.1 | B19: =(SUMPRODUCT(DCF_Base!$C$21:$L$21/(1+$A19)^DCF_Base!$C$4:$L$4)+MAX(0,MIN(DCF_Base!$L$21*(1+Assumptions!C$16)/($A19-Assumptions!C$16),Assumptions!C$17*DCF_Base!$L$21))/(1+$A19)^10+Assumptions!$B$7)/Assumptions!$B$4
A20: =Assumptions!B8 | B20: =(SUMPRODUCT(DCF_Base!$C$21:$L$21/(1+$A20)^DCF_Base!$C$4:$L$4)+MAX(0,MIN(DCF_Base!$L$21*(1+Assumptions!C$16)/($A20-Assumptions!C$16),Assumptions!C$17*DCF_Base!$L$21))/(1+$A20)^10+Assumptions!$B$7)/Assumptions!$B$4
A21: 0.11 | B21: =(SUMPRODUCT(DCF_Base!$C$21:$L$21/(1+$A21)^DCF_Base!$C$4:$L$4)+MAX(0,MIN(DCF_Base!$L$21*(1+Assumptions!C$16)/($A21-Assumptions!C$16),Assumptions!C$17*DCF_Base!$L$21))/(1+$A21)^10+Assumptions!$B$7)/Assumptions!$B$4
A22: 0.12 | B22: =(SUMPRODUCT(DCF_Base!$C$21:$L$21/(1+$A22)^DCF_Base!$C$4:$L$4)+MAX(0,MIN(DCF_Base!$L$21*(1+Assumptions!C$16)/($A22-Assumptions!C$16),Assumptions!C$17*DCF_Base!$L$21))/(1+$A22)^10+Assumptions!$B$7)/Assumptions!$B$4
A23: =Assumptions!B9 | B23: =(SUMPRODUCT(DCF_Base!$C$21:$L$21/(1+$A23)^DCF_Base!$C$4:$L$4)+MAX(0,MIN(DCF_Base!$L$21*(1+Assumptions!C$16)/($A23-Assumptions!C$16),Assumptions!C$17*DCF_Base!$L$21))/(1+$A23)^10+Assumptions!$B$7)/Assumptions!$B$4
A26: Sensitivity: base-case value per share, cost of equity (rows) x terminal growth (cols)
B27: 0.015 | C27: 0.02 | D27: 0.025 | E27: 0.03 | F27: 0.035
A28: 0.085 | B28: =IF($A28>B$27,(SUMPRODUCT(DCF_Base!$C$21:$L$21/(1+$A28)^DCF_Base!$C$4:$L$4)+MAX(0,MIN(DCF_Base!$L$21*(1+B$27)/($A28-B$27),Assumptions!$C$17*DCF_Base!$L$21))/(1+$A28)^10+Assumptions!$B$7)/Assumptions!$B$4,"n/a") | C28: =IF($A28>C$27,(SUMPRODUCT(DCF_Base!$C$21:$L$21/(1+$A28)^DCF_Base!$C$4:$L$4)+MAX(0,MIN(DCF_Base!$L$21*(1+C$27)/($A28-C$27),Assumptions!$C$17*DCF_Base!$L$21))/(1+$A28)^10+Assumptions!$B$7)/Assumptions!$B$4,"n/a") | D28: =IF($A28>D$27,(SUMPRODUCT(DCF_Base!$C$21:$L$21/(1+$A28)^DCF_Base!$C$4:$L$4)+MAX(0,MIN(DCF_Base!$L$21*(1+D$27)/($A28-D$27),Assumptions!$C$17*DCF_Base!$L$21))/(1+$A28)^10+Assumptions!$B$7)/Assumptions!$B$4,"n/a") | E28: =IF($A28>E$27,(SUMPRODUCT(DCF_Base!$C$21:$L$21/(1+$A28)^DCF_Base!$C$4:$L$4)+MAX(0,MIN(DCF_Base!$L$21*(1+E$27)/($A28-E$27),Assumptions!$C$17*DCF_Base!$L$21))/(1+$A28)^10+Assumptions!$B$7)/Assumptions!$B$4,"n/a") | F28: =IF($A28>F$27,(SUMPRODUCT(DCF_Base!$C$21:$L$21/(1+$A28)^DCF_Base!$C$4:$L$4)+MAX(0,MIN(DCF_Base!$L$21*(1+F$27)/($A28-F$27),Assumptions!$C$17*DCF_Base!$L$21))/(1+$A28)^10+Assumptions!$B$7)/Assumptions!$B$4,"n/a")
A29: 0.095 | B29: =IF($A29>B$27,(SUMPRODUCT(DCF_Base!$C$21:$L$21/(1+$A29)^DCF_Base!$C$4:$L$4)+MAX(0,MIN(DCF_Base!$L$21*(1+B$27)/($A29-B$27),Assumptions!$C$17*DCF_Base!$L$21))/(1+$A29)^10+Assumptions!$B$7)/Assumptions!$B$4,"n/a") | C29: =IF($A29>C$27,(SUMPRODUCT(DCF_Base!$C$21:$L$21/(1+$A29)^DCF_Base!$C$4:$L$4)+MAX(0,MIN(DCF_Base!$L$21*(1+C$27)/($A29-C$27),Assumptions!$C$17*DCF_Base!$L$21))/(1+$A29)^10+Assumptions!$B$7)/Assumptions!$B$4,"n/a") | D29: =IF($A29>D$27,(SUMPRODUCT(DCF_Base!$C$21:$L$21/(1+$A29)^DCF_Base!$C$4:$L$4)+MAX(0,MIN(DCF_Base!$L$21*(1+D$27)/($A29-D$27),Assumptions!$C$17*DCF_Base!$L$21))/(1+$A29)^10+Assumptions!$B$7)/Assumptions!$B$4,"n/a") | E29: =IF($A29>E$27,(SUMPRODUCT(DCF_Base!$C$21:$L$21/(1+$A29)^DCF_Base!$C$4:$L$4)+MAX(0,MIN(DCF_Base!$L$21*(1+E$27)/($A29-E$27),Assumptions!$C$17*DCF_Base!$L$21))/(1+$A29)^10+Assumptions!$B$7)/Assumptions!$B$4,"n/a") | F29: =IF($A29>F$27,(SUMPRODUCT(DCF_Base!$C$21:$L$21/(1+$A29)^DCF_Base!$C$4:$L$4)+MAX(0,MIN(DCF_Base!$L$21*(1+F$27)/($A29-F$27),Assumptions!$C$17*DCF_Base!$L$21))/(1+$A29)^10+Assumptions!$B$7)/Assumptions!$B$4,"n/a")
A30: 0.105 | B30: =IF($A30>B$27,(SUMPRODUCT(DCF_Base!$C$21:$L$21/(1+$A30)^DCF_Base!$C$4:$L$4)+MAX(0,MIN(DCF_Base!$L$21*(1+B$27)/($A30-B$27),Assumptions!$C$17*DCF_Base!$L$21))/(1+$A30)^10+Assumptions!$B$7)/Assumptions!$B$4,"n/a") | C30: =IF($A30>C$27,(SUMPRODUCT(DCF_Base!$C$21:$L$21/(1+$A30)^DCF_Base!$C$4:$L$4)+MAX(0,MIN(DCF_Base!$L$21*(1+C$27)/($A30-C$27),Assumptions!$C$17*DCF_Base!$L$21))/(1+$A30)^10+Assumptions!$B$7)/Assumptions!$B$4,"n/a") | D30: =IF($A30>D$27,(SUMPRODUCT(DCF_Base!$C$21:$L$21/(1+$A30)^DCF_Base!$C$4:$L$4)+MAX(0,MIN(DCF_Base!$L$21*(1+D$27)/($A30-D$27),Assumptions!$C$17*DCF_Base!$L$21))/(1+$A30)^10+Assumptions!$B$7)/Assumptions!$B$4,"n/a") | E30: =IF($A30>E$27,(SUMPRODUCT(DCF_Base!$C$21:$L$21/(1+$A30)^DCF_Base!$C$4:$L$4)+MAX(0,MIN(DCF_Base!$L$21*(1+E$27)/($A30-E$27),Assumptions!$C$17*DCF_Base!$L$21))/(1+$A30)^10+Assumptions!$B$7)/Assumptions!$B$4,"n/a") | F30: =IF($A30>F$27,(SUMPRODUCT(DCF_Base!$C$21:$L$21/(1+$A30)^DCF_Base!$C$4:$L$4)+MAX(0,MIN(DCF_Base!$L$21*(1+F$27)/($A30-F$27),Assumptions!$C$17*DCF_Base!$L$21))/(1+$A30)^10+Assumptions!$B$7)/Assumptions!$B$4,"n/a")
A31: 0.115 | B31: =IF($A31>B$27,(SUMPRODUCT(DCF_Base!$C$21:$L$21/(1+$A31)^DCF_Base!$C$4:$L$4)+MAX(0,MIN(DCF_Base!$L$21*(1+B$27)/($A31-B$27),Assumptions!$C$17*DCF_Base!$L$21))/(1+$A31)^10+Assumptions!$B$7)/Assumptions!$B$4,"n/a") | C31: =IF($A31>C$27,(SUMPRODUCT(DCF_Base!$C$21:$L$21/(1+$A31)^DCF_Base!$C$4:$L$4)+MAX(0,MIN(DCF_Base!$L$21*(1+C$27)/($A31-C$27),Assumptions!$C$17*DCF_Base!$L$21))/(1+$A31)^10+Assumptions!$B$7)/Assumptions!$B$4,"n/a") | D31: =IF($A31>D$27,(SUMPRODUCT(DCF_Base!$C$21:$L$21/(1+$A31)^DCF_Base!$C$4:$L$4)+MAX(0,MIN(DCF_Base!$L$21*(1+D$27)/($A31-D$27),Assumptions!$C$17*DCF_Base!$L$21))/(1+$A31)^10+Assumptions!$B$7)/Assumptions!$B$4,"n/a") | E31: =IF($A31>E$27,(SUMPRODUCT(DCF_Base!$C$21:$L$21/(1+$A31)^DCF_Base!$C$4:$L$4)+MAX(0,MIN(DCF_Base!$L$21*(1+E$27)/($A31-E$27),Assumptions!$C$17*DCF_Base!$L$21))/(1+$A31)^10+Assumptions!$B$7)/Assumptions!$B$4,"n/a") | F31: =IF($A31>F$27,(SUMPRODUCT(DCF_Base!$C$21:$L$21/(1+$A31)^DCF_Base!$C$4:$L$4)+MAX(0,MIN(DCF_Base!$L$21*(1+F$27)/($A31-F$27),Assumptions!$C$17*DCF_Base!$L$21))/(1+$A31)^10+Assumptions!$B$7)/Assumptions!$B$4,"n/a")
A32: 0.125 | B32: =IF($A32>B$27,(SUMPRODUCT(DCF_Base!$C$21:$L$21/(1+$A32)^DCF_Base!$C$4:$L$4)+MAX(0,MIN(DCF_Base!$L$21*(1+B$27)/($A32-B$27),Assumptions!$C$17*DCF_Base!$L$21))/(1+$A32)^10+Assumptions!$B$7)/Assumptions!$B$4,"n/a") | C32: =IF($A32>C$27,(SUMPRODUCT(DCF_Base!$C$21:$L$21/(1+$A32)^DCF_Base!$C$4:$L$4)+MAX(0,MIN(DCF_Base!$L$21*(1+C$27)/($A32-C$27),Assumptions!$C$17*DCF_Base!$L$21))/(1+$A32)^10+Assumptions!$B$7)/Assumptions!$B$4,"n/a") | D32: =IF($A32>D$27,(SUMPRODUCT(DCF_Base!$C$21:$L$21/(1+$A32)^DCF_Base!$C$4:$L$4)+MAX(0,MIN(DCF_Base!$L$21*(1+D$27)/($A32-D$27),Assumptions!$C$17*DCF_Base!$L$21))/(1+$A32)^10+Assumptions!$B$7)/Assumptions!$B$4,"n/a") | E32: =IF($A32>E$27,(SUMPRODUCT(DCF_Base!$C$21:$L$21/(1+$A32)^DCF_Base!$C$4:$L$4)+MAX(0,MIN(DCF_Base!$L$21*(1+E$27)/($A32-E$27),Assumptions!$C$17*DCF_Base!$L$21))/(1+$A32)^10+Assumptions!$B$7)/Assumptions!$B$4,"n/a") | F32: =IF($A32>F$27,(SUMPRODUCT(DCF_Base!$C$21:$L$21/(1+$A32)^DCF_Base!$C$4:$L$4)+MAX(0,MIN(DCF_Base!$L$21*(1+F$27)/($A32-F$27),Assumptions!$C$17*DCF_Base!$L$21))/(1+$A32)^10+Assumptions!$B$7)/Assumptions!$B$4,"n/a")
A34: Sanity: price / TTM underlying EPS | B34: =Assumptions!B3/(Actuals!J20/100)
A35: Sanity: price / book (30-Jun-2026) | B35: =Assumptions!B3*(Actuals!I18-2.1)/Actuals!I19
A36: Sanity: house base IV / TTM underlying NPAT (implied P/E) | B36: =DCF_Base!B38/Actuals!J4
