Workbook

Sheet Model_Info
A1: SVR.NZ -- Savor Limited: owner-FCF DCF model
A2: Version 1.0, built 2026-09-03 by the dcf-analyst agent (Claude, claude-fable-5-1) at the user's request. Fresh build; supersedes nothing.
A3: FIGURES GO STALE. Price NZ$0.172 at 2026-09-03T04:59:55Z (Yahoo, NZX close). Balance sheet: FY2026 results release 26-May-2026 (unaudited: cash 1.7m, leverage 1.92x); FY2025 Annual Report (audited 31-Mar-2025) for lease liabilities, tax losses, share count. Share count 76,780,666 (FY2025 AR note 11), options 283,334 @22c out of the money.
A4: Guidance: FY27 NZ$9-10m operating earnings NOT reconfirmed at the May-2026 result; update due at the Sept-2026 ASM. First dividend 2c targeted Jan-2027, conditional on 1.5x covenant leverage.
A5: METHOD: owner-FCF DCF, 10-year component build (owner-fcf.md s2), scenario-weighted 25/50/25, TV = MAX(0, MIN(Gordon, 12x FCF10)), end-of-year discounting, WACC 16.5% NZD-built (see Assumptions note).
A6: LEASES: treatment B. Full lease cash (principal + lease interest, ~7% of revenue) is charged in the flows against the post-IFRS-16 headline operating-earnings margin; lease liabilities are EXCLUDED from net debt. Net debt = bank borrowings (8.0m, estimated from the covenant arithmetic) - cash 1.7m = 6.3m.
A7: EBITDA MARGIN: row 7 on each DCF tab is the HEADLINE operating-earnings margin (company metric, 14.5% FY26); row 8 deducts a 1.25%-of-revenue recurring restructuring/venue-churn cash allowance; row 9 is the modelled EBITDA margin that the JSON records as ebitda_margin_path.
A8: TAX: unlevered EBIT taxed at 0% while ~NZ$25m of tax losses shelter it, ramping to the 28% NZ rate by FY34 (base) -- more tax than the losses strictly imply, to reflect shareholder-continuity forfeiture risk.
A9: ENTRY PRICE: 15% IRR with the terminal value REBUILT at the hurdle. Because WACC (16.5%) > hurdle (15%), entry prices sit ABOVE intrinsic values; the buy-below price at the house rate is the weighted IV on the Valuation tab.
A10: SCENARIO DRIVERS are the agent's judgment set 2026-09-03 from the FY2026 release, the FY2025 Annual Report and the Analysis JSON. Only rows 5, 7, 11 and 18 on each DCF tab are hardcoded drivers; everything else is a formula.
A11: REFRESH after the FY2026 Annual Report (bank borrowings, lease liabilities, capex, tax losses, restructuring cash) and after the Sept-2026 ASM guidance update.
A12: ROW MAP (DCF tabs): 5 growth | 6 revenue | 7 headline margin | 8 restructuring allowance | 9 modelled EBITDA margin | 10 EBITDA | 11 SBC % | 12 SBC | 13 owner EBITDA | 14 lease % | 15 lease cash | 16 D&A | 17 EBIT | 18 cash tax rate | 19 cash tax | 20 NOPAT | 21 +D&A | 22 capex | 23 WC | 24 owner FCF | 25 DF | 26 PV | 28-29 memos | 31-44 valuation | 46-48 street memo | 50 entry price at hurdle.
A13: CELL LEGEND: blue font = hardcoded input; yellow fill = key lever; black = formula; green font = cross-sheet link; green fill = headline value.

Sheet Actuals
A1: Metric (NZ$m) | B1: FY2021 | C1: FY2022 | D1: FY2023 | E1: FY2024 | F1: FY2025 | G1: FY2026 (release) | H1: Source
A2: Revenue | B2: 16.134 | C2: 30.581 | D2: 52.378 | E2: 61.858 | F2: 56.643 | G2: 55.2 | H2: Metrics.csv / FY26 release
A3: Operating earnings (EBITDA pre restructuring, post-IFRS16) | B3: 1.839 | C3: 2.995 | D3: 5.22 | E3: 8.773 | F3: 7.267 | G3: 8 | H3: P&L subtotal / FY26 release
A4: Operating earnings margin % | B4: 11.4 | C4: 9.8 | D4: 10 | E4: 14.2 | F4: 12.8 | G4: 14.5 | H4: derived
A5: Restructuring and other costs | B5: 0.921 | C5: 1.2 | D5: 1.395 | E5: 0.87 | F5: 2.514 | H5: P&L (FY25 incl. 1.8m non-cash Seafarers loss)
A6: Impairment | B6: 2 | C6: 1.564 | D6: 0 | E6: 4.32 | F6: 0 | H6: P&L
A7: Depreciation & amortisation (total) | B7: 2.191 | C7: 4.001 | D7: 4.617 | E7: 5.099 | F7: 4.732 | H7: P&L
A8: of which ROU (lease) depreciation | B8: 1.319 | C8: 2.506 | D8: 2.75 | E8: 3.124 | F8: 3.113 | H8: Leases note
A9: Interest expense (bank + lease) | B9: 0.85 | C9: 1.266 | D9: 1.542 | E9: 1.342 | F9: 1.465 | H9: P&L; ALL interest paid sits in financing
A10: of which lease interest | B10: 0.394 | C10: 0.769 | D10: 0.744 | E10: 0.815 | F10: 0.722 | H10: Leases note
A11: NPAT | B11: -6.586 | C11: -5.036 | D11: -2.334 | E11: 0.65 | F11: -1.212 | G11: 1.3 | H11: P&L / FY26 release (untaxed; cash-equivalent 1.8)
A12: EPS (cents) | B12: -13.9 | C12: -8.2 | D12: -3.5 | E12: 0.9 | F12: -1.6 | G12: 1.7 | H12: P&L / FY26 release
A13: Operating cash flow (pre-interest) | B13: 0.401 | C13: 2.952 | D13: 6.067 | E13: 6.4 | F13: 7.097 | G13: 6.9 | H13: Cash flow statement / FY26 release (7.2 pre-WC)
A14: Purchase of PPE & intangibles | B14: 0.924 | C14: 1.798 | D14: 4.271 | E14: 0.311 | F14: 1.116 | H14: Cash flow statement
A15: Venue development costs (investing) | B15: 0.364 | C15: 0.137 | D15: 0.569 | E15: 0.164 | F15: 0.189 | H15: Cash flow statement
A16: Capex FY2026 ESTIMATE (incl. dev costs) | G16: 2.4 | H16: agent estimate: cash reconciliation of the release; two fit-outs
A17: Lease principal repaid (financing) | B17: 1.253 | C17: 2.738 | D17: 2.45 | E17: 2.918 | F17: 3.053 | G17: 3.2 | H17: Cash flow statement; FY26 estimate
A18: Bank borrowings | B18: 7.021 | C18: 13.426 | D18: 11.35 | E18: 8.407 | F18: 9 | G18: 8 | H18: Borrowings note; FY26 estimate from 1.92x covenant arithmetic
A19: Lease liabilities | B19: 8.909 | C19: 17.347 | D19: 17.683 | E19: 17.504 | F19: 17.285 | G19: 18 | H19: Leases note; FY26 estimate
A20: Cash (net of overdraft) | B20: 3.402 | C20: 1.35 | D20: -0.514 | E20: -0.653 | F20: 1.786 | G20: 1.7 | H20: Balance sheet / FY26 release
A21: Shareholders' equity | B21: 12.726 | C21: 14.344 | D21: 17.324 | E21: 18.761 | F21: 17.383 | G21: 18.683 | H21: Balance sheet; FY26 = FY25 + NPAT (estimate)
A22: Shares on issue (m) | B22: 146.272 | C22: 61.482 | D22: 74.638 | E22: 77.585 | F22: 76.781 | G22: 76.781 | H22: Capital note (1-for-3 consolidation Aug-2021)
A23: Cash taxes paid | B23: 0 | C23: 0 | D23: 0 | E23: 0 | F23: 0 | G23: 0 | H23: Tax note / release
A24: Dividends paid | B24: 0 | C24: 0 | D24: 0 | E24: 0 | F24: 0 | G24: 0 | H24: first 2c dividend targeted Jan-2027
A27: Guidance / outlook
A28: FY27 operating earnings NZ$9-10m (NOT reconfirmed May-2026; ASM Sept-2026). COGS <28% of revenue maintained. Dividend 2c Jan-2027 on 1.5x covenant leverage. Bank borrowings ~7.5m post-April-2026 (7.0 if 8.0 is 0.5 high).

Sheet Assumptions
A1: Global inputs
A3: Current price (NZ$) | B3: 0.172 | C3: Yahoo 2026-09-03T04:59:55Z
A4: Diluted shares (m) | B4: 76.780666 | C4: 76,780,666 on issue; 283,334 options @22c out of the money
A5: Bank borrowings (NZ$m) | B5: 8 | C5: 31-Mar-2026 estimate from 1.92x covenant leverage on pre-IFRS-16 EBITDA; FY25 audited 9.0
A6: Cash (NZ$m) | B6: 1.7 | C6: FY26 release 'net cash on hand'
A7: Net debt ex-lease (NZ$m) | B7: =B5-B6 | C7: treatment B: lease liabilities (~18m) excluded because lease cash is charged in the flows
A8: Terminal FCF multiple cap (x) | B8: 12 | C8: cyclical, single-city restaurant group (owner-fcf.md s4: 12-15x for cyclicals)
A9: Hurdle rate (decimal) | B9: 0.15 | C9: house 15% IRR
A10: WACC (%) | B10: 16.5 | C10: NZ 10y 4.4% + 5.5% ERP x 1.3 beta = 11.5% base; +2.5 illiquidity (NZ$13m cap); +1.0 single-city; +1.0 cyclicality/operating leverage; +0.5 lease-heavy leverage. Same in all scenarios.
A12: Scenario inputs | C12: Bear | D12: Base | E12: Bull
A13: Terminal growth (%) | C13: 1.5 | D13: 2.25 | E13: 2.5
A14: Probability weight | C14: 0.25 | D14: 0.5 | E14: 0.25
A15: Lease cash cost (% revenue) | C15: 7.5 | D15: 7 | E15: 6.7
A16: D&A ex-ROU (% revenue) | C16: 3 | D16: 2.9 | E16: 2.9
A17: Capex incl. venue development (% revenue) | C17: 2.5 | D17: 2.5 | E17: 2.5
A18: WC capture on revenue change (%) | C18: 5 | D18: 5 | E18: 5
A19: Recurring restructuring allowance (% revenue) | C19: 1.25 | D19: 1.25 | E19: 1.25
A20: Weights check (must be 1.0) | C20: =SUM(C14:E14)
A22: Scenario narratives
A23: Bear | B23: NZ hospitality's 3.3x-average insolvency rate and the cost-of-living squeeze produce another FY2025-style year: revenue -4% then -2%, flat, then 1-1.5%. Operating leverage does what it did in FY2025 -- the headline margin falls back to 12.0-12.5% -- but rent does not fall, so lease cash rises to 7.5% of revenue and the group services its landlords and its bank but generates almost nothing for equity (owner FCF NZ$0.5-0.7m/yr). Tax losses shelter for longer. Terminal growth 1.5%. The January-2027 dividend is deferred because the 1.5x covenant leverage trigger is not met. Equity value is NEGATIVE on this path: it is a going-concern-at-the-bank's-pleasure outcome, not a liquidation.
A24: Base | B24: Revenue +3.0% in FY27 (full-year Bar Ziti and Flush Golf against 6.5 months in FY26, City Rail Link opening 13-Sep-2026 beside the Britomart cluster, CBD foot traffic +4%), then 2.0-2.5% -- CPI-like like-for-like growth for a fixed 18-venue estate with no rollout assumed. Headline operating-earnings margin 15.0% in FY27 (op earnings NZ$8.5m, deliberately BELOW the unconfirmed NZ$9-10m FY27 target) rising to 15.5% by FY29 and held there; a 1.25%-of-revenue recurring restructuring/venue-churn cash allowance is charged inside the modelled EBITDA (restructuring costs have been NZ$0.9-2.5m every year FY2021-25 and OCF has converted only ~86% of operating earnings). Lease cash (principal + lease interest) 7.0% of revenue, ex-ROU D&A 2.9%, capex 2.5% (NZ$1.4m/yr, above the FY24-25 underspend but below D&A), 5% of the revenue change captured as working capital (cash-sales business). Cash tax 0% for FY27-30 on ~NZ$25m of carried-forward tax losses then ramping 7/14/21/28% to the NZ statutory rate by FY34.
A25: Bull | B25: Flush Golf's entertainment format is replicated once or twice and the CRL/CBD recovery lifts like-for-like: revenue +6%/+5%/+4% then 2.5-3.5%. Management delivers the FY27 target (16.5% margin = NZ$9.6m op earnings) and cost-out takes the headline margin to 17.5% by FY29 -- the level Flush Golf's lower-labour model makes plausible at group level only if food-led venues hold 15%+. Rent is fixed so lease cash falls to 6.7% of revenue on the larger base; tax losses are used faster (ramp starts FY30). Terminal growth 2.5%. Same 16.5% WACC.
A27: Weights rationale | B27: 25/50/25 against the house 15/50/35. Bear raised to 25%: FY27 guidance was explicitly NOT reconfirmed, the ANZ facility has leverage and fixed-charge covenants with the 1.5x dividend trigger not yet met, four of the last five years were NPAT losses, and the sector's insolvency rate is 3.3x the NZ average -- though not higher, because 1.0pp of cyclicality is already in the WACC (charge risk once). Bull cut to 25%: it needs margin expansion to 17.5% AND a return to 4-6% revenue growth AND the entertainment format to replicate -- three independent things -- with no scarcity or balance-sheet optionality to offset.

Sheet DCF_Bear
A1: BEAR scenario -- owner FCF build (NZ$m)
A3: Year | B3: FY2026A | C3: FY2027E | D3: FY2028E | E3: FY2029E | F3: FY2030E | G3: FY2031E | H3: FY2032E | I3: FY2033E | J3: FY2034E | K3: FY2035E | L3: FY2036E
A4: Index | B4: 0 | C4: 1 | D4: 2 | E4: 3 | F4: 4 | G4: 5 | H4: 6 | I4: 7 | J4: 8 | K4: 9 | L4: 10
A5: Revenue growth % | C5: -4 | D5: -2 | E5: 0 | F5: 1 | G5: 1.5 | H5: 1.5 | I5: 1.5 | J5: 1.5 | K5: 1.5 | L5: 1.5
A6: Revenue | B6: 55.2 | C6: =B6*(1+C5/100) | D6: =C6*(1+D5/100) | E6: =D6*(1+E5/100) | F6: =E6*(1+F5/100) | G6: =F6*(1+G5/100) | H6: =G6*(1+H5/100) | I6: =H6*(1+I5/100) | J6: =I6*(1+J5/100) | ... L6: =K6*(1+L5/100)
A7: Headline operating-earnings margin % | B7: 14.5 | C7: 12.5 | D7: 12 | E7: 12 | F7: 12.25 | G7: 12.5 | H7: 12.5 | I7: 12.5 | J7: 12.5 | K7: 12.5 | L7: 12.5
A8: less recurring restructuring allowance % | C8: =Assumptions!$C$19 | D8: =Assumptions!$C$19 | E8: =Assumptions!$C$19 | F8: =Assumptions!$C$19 | G8: =Assumptions!$C$19 | H8: =Assumptions!$C$19 | I8: =Assumptions!$C$19 | J8: =Assumptions!$C$19 | ... L8: =Assumptions!$C$19
A9: Modelled EBITDA margin % | C9: =C7-C8 | D9: =D7-D8 | E9: =E7-E8 | F9: =F7-F8 | G9: =G7-G8 | H9: =H7-H8 | I9: =I7-I8 | J9: =J7-J8 | ... L9: =L7-L8
A10: Adjusted EBITDA | C10: =C6*C9/100 | D10: =D6*D9/100 | E10: =E6*E9/100 | F10: =F6*F9/100 | G10: =G6*G9/100 | H10: =H6*H9/100 | I10: =I6*I9/100 | J10: =J6*J9/100 | ... L10: =L6*L9/100
A11: SBC % of revenue | C11: 0 | D11: 0 | E11: 0 | F11: 0 | G11: 0 | H11: 0 | I11: 0 | J11: 0 | K11: 0 | L11: 0
A12: SBC (negative) | C12: =-C6*C11/100 | D12: =-D6*D11/100 | E12: =-E6*E11/100 | F12: =-F6*F11/100 | G12: =-G6*G11/100 | H12: =-H6*H11/100 | I12: =-I6*I11/100 | J12: =-J6*J11/100 | ... L12: =-L6*L11/100
A13: Owner EBITDA | C13: =C10+C12 | D13: =D10+D12 | E13: =E10+E12 | F13: =F10+F12 | G13: =G10+G12 | H13: =H10+H12 | I13: =I10+I12 | J13: =J10+J12 | ... L13: =L10+L12
A14: Lease cash cost % of revenue | C14: =Assumptions!$C$15 | D14: =Assumptions!$C$15 | E14: =Assumptions!$C$15 | F14: =Assumptions!$C$15 | G14: =Assumptions!$C$15 | H14: =Assumptions!$C$15 | I14: =Assumptions!$C$15 | J14: =Assumptions!$C$15 | ... L14: =Assumptions!$C$15
A15: Lease cash (principal + interest) | C15: =-C6*C14/100 | D15: =-D6*D14/100 | E15: =-E6*E14/100 | F15: =-F6*F14/100 | G15: =-G6*G14/100 | H15: =-H6*H14/100 | I15: =-I6*I14/100 | J15: =-J6*J14/100 | ... L15: =-L6*L14/100
A16: D&A ex-ROU | C16: =-C6*Assumptions!$C$16/100 | D16: =-D6*Assumptions!$C$16/100 | E16: =-E6*Assumptions!$C$16/100 | F16: =-F6*Assumptions!$C$16/100 | G16: =-G6*Assumptions!$C$16/100 | H16: =-H6*Assumptions!$C$16/100 | I16: =-I6*Assumptions!$C$16/100 | J16: =-J6*Assumptions!$C$16/100 | ... L16: =-L6*Assumptions!$C$16/100
A17: EBIT (SBC expensed, post-lease) | C17: =C13+C15+C16 | D17: =D13+D15+D16 | E17: =E13+E15+E16 | F17: =F13+F15+F16 | G17: =G13+G15+G16 | H17: =H13+H15+H16 | I17: =I13+I15+I16 | J17: =J13+J15+J16 | ... L17: =L13+L15+L16
A18: Cash tax rate % | C18: 0 | D18: 0 | E18: 0 | F18: 0 | G18: 0 | H18: 7 | I18: 14 | J18: 21 | K18: 28 | L18: 28
A19: Cash tax | C19: =-MAX(0,C17)*C18/100 | D19: =-MAX(0,D17)*D18/100 | E19: =-MAX(0,E17)*E18/100 | F19: =-MAX(0,F17)*F18/100 | G19: =-MAX(0,G17)*G18/100 | H19: =-MAX(0,H17)*H18/100 | I19: =-MAX(0,I17)*I18/100 | J19: =-MAX(0,J17)*J18/100 | ... L19: =-MAX(0,L17)*L18/100
A20: NOPAT | C20: =C17+C19 | D20: =D17+D19 | E20: =E17+E19 | F20: =F17+F19 | G20: =G17+G19 | H20: =H17+H19 | I20: =I17+I19 | J20: =J17+J19 | ... L20: =L17+L19
A21: add back D&A | C21: =-C16 | D21: =-D16 | E21: =-E16 | F21: =-F16 | G21: =-G16 | H21: =-H16 | I21: =-I16 | J21: =-J16 | ... L21: =-L16
A22: less capex | C22: =-C6*Assumptions!$C$17/100 | D22: =-D6*Assumptions!$C$17/100 | E22: =-E6*Assumptions!$C$17/100 | F22: =-F6*Assumptions!$C$17/100 | G22: =-G6*Assumptions!$C$17/100 | H22: =-H6*Assumptions!$C$17/100 | I22: =-I6*Assumptions!$C$17/100 | J22: =-J6*Assumptions!$C$17/100 | ... L22: =-L6*Assumptions!$C$17/100
A23: add working capital | C23: =Assumptions!$C$18/100*(C6-B6) | D23: =Assumptions!$C$18/100*(D6-C6) | E23: =Assumptions!$C$18/100*(E6-D6) | F23: =Assumptions!$C$18/100*(F6-E6) | G23: =Assumptions!$C$18/100*(G6-F6) | H23: =Assumptions!$C$18/100*(H6-G6) | I23: =Assumptions!$C$18/100*(I6-H6) | J23: =Assumptions!$C$18/100*(J6-I6) | ... L23: =Assumptions!$C$18/100*(L6-K6)
A24: Unlevered owner FCF | B24: 0.55 | C24: =C20+C21+C22+C23 | D24: =D20+D21+D22+D23 | E24: =E20+E21+E22+E23 | F24: =F20+F21+F22+F23 | G24: =G20+G21+G22+G23 | H24: =H20+H21+H22+H23 | I24: =I20+I21+I22+I23 | J24: =J20+J21+J22+J23 | ... L24: =L20+L21+L22+L23 | M24: B24 = FY2026E owner FCF (capex-elevated); not a driver
A25: Discount factor | C25: =1/(1+Assumptions!$B$10/100)^C4 | D25: =1/(1+Assumptions!$B$10/100)^D4 | E25: =1/(1+Assumptions!$B$10/100)^E4 | F25: =1/(1+Assumptions!$B$10/100)^F4 | G25: =1/(1+Assumptions!$B$10/100)^G4 | H25: =1/(1+Assumptions!$B$10/100)^H4 | I25: =1/(1+Assumptions!$B$10/100)^I4 | J25: =1/(1+Assumptions!$B$10/100)^J4 | ... L25: =1/(1+Assumptions!$B$10/100)^L4
A26: PV of FCF | C26: =C24*C25 | D26: =D24*D25 | E26: =E24*E25 | F26: =F24*F25 | G26: =G24*G25 | H26: =H24*H25 | I26: =I24*I25 | J26: =J24*J25 | ... L26: =L24*L25
A28: Memo: FCF before lease & SBC (company-style) | C28: =C24-C15-C12 | D28: =D24-D15-D12 | E28: =E24-E15-E12 | F28: =F24-F15-F12 | G28: =G24-G15-G12 | H28: =H24-H15-H12 | I28: =I24-I15-I12 | J28: =J24-J15-J12 | ... L28: =L24-L15-L12
A29: Memo: owner FCF margin % | C29: =C24/C6*100 | D29: =D24/D6*100 | E29: =E24/E6*100 | F29: =F24/F6*100 | G29: =G24/G6*100 | H29: =H24/H6*100 | I29: =I24/I6*100 | J29: =J24/J6*100 | ... L29: =L24/L6*100
A31: Sum of PV of FCF | B31: =SUM(C26:L26)
A32: Terminal growth % | B32: =Assumptions!$C$13
A33: Terminal-year FCF x (1+g) | B33: =L24*(1+B32/100)
A34: Gordon terminal value | B34: =IF(Assumptions!$B$10>B32,B33/((Assumptions!$B$10-B32)/100),L24*Assumptions!$B$8)
A35: Cap terminal value (cap x FCF10) | B35: =Assumptions!$B$8*L24
A36: Terminal value used = MAX(0,MIN(Gordon,cap)) | B36: =MAX(0,MIN(B34,B35))
A37: Implied exit multiple (x FCF10) | B37: =IF(L24>0,B36/L24,"n/a")
A38: PV of terminal value | B38: =B36*L25
A39: Enterprise value | B39: =B31+B38
A40: less net debt (ex-lease) | B40: =-Assumptions!$B$7
A41: Equity value | B41: =B39+B40
A42: Diluted shares (m) | B42: =Assumptions!$B$4
A43: VALUE PER SHARE (NZ$) | B43: =B41/B42
...

Sheet DCF_Base
A1: BASE scenario -- owner FCF build (NZ$m)
A3: Year | B3: FY2026A | C3: FY2027E | D3: FY2028E | E3: FY2029E | F3: FY2030E | G3: FY2031E | H3: FY2032E | I3: FY2033E | J3: FY2034E | K3: FY2035E | L3: FY2036E
A4: Index | B4: 0 | C4: 1 | D4: 2 | E4: 3 | F4: 4 | G4: 5 | H4: 6 | I4: 7 | J4: 8 | K4: 9 | L4: 10
A5: Revenue growth % | C5: 3 | D5: 2.5 | E5: 2.5 | F5: 2.5 | G5: 2.25 | H5: 2.25 | I5: 2 | J5: 2 | K5: 2 | L5: 2
A6: Revenue | B6: 55.2 | C6: =B6*(1+C5/100) | D6: =C6*(1+D5/100) | E6: =D6*(1+E5/100) | F6: =E6*(1+F5/100) | G6: =F6*(1+G5/100) | H6: =G6*(1+H5/100) | I6: =H6*(1+I5/100) | J6: =I6*(1+J5/100) | ... L6: =K6*(1+L5/100)
A7: Headline operating-earnings margin % | B7: 14.5 | C7: 15 | D7: 15.25 | E7: 15.5 | F7: 15.5 | G7: 15.5 | H7: 15.5 | I7: 15.5 | J7: 15.5 | K7: 15.5 | L7: 15.5
A8: less recurring restructuring allowance % | C8: =Assumptions!$D$19 | D8: =Assumptions!$D$19 | E8: =Assumptions!$D$19 | F8: =Assumptions!$D$19 | G8: =Assumptions!$D$19 | H8: =Assumptions!$D$19 | I8: =Assumptions!$D$19 | J8: =Assumptions!$D$19 | ... L8: =Assumptions!$D$19
A9: Modelled EBITDA margin % | C9: =C7-C8 | D9: =D7-D8 | E9: =E7-E8 | F9: =F7-F8 | G9: =G7-G8 | H9: =H7-H8 | I9: =I7-I8 | J9: =J7-J8 | ... L9: =L7-L8
A10: Adjusted EBITDA | C10: =C6*C9/100 | D10: =D6*D9/100 | E10: =E6*E9/100 | F10: =F6*F9/100 | G10: =G6*G9/100 | H10: =H6*H9/100 | I10: =I6*I9/100 | J10: =J6*J9/100 | ... L10: =L6*L9/100
A11: SBC % of revenue | C11: 0 | D11: 0 | E11: 0 | F11: 0 | G11: 0 | H11: 0 | I11: 0 | J11: 0 | K11: 0 | L11: 0
A12: SBC (negative) | C12: =-C6*C11/100 | D12: =-D6*D11/100 | E12: =-E6*E11/100 | F12: =-F6*F11/100 | G12: =-G6*G11/100 | H12: =-H6*H11/100 | I12: =-I6*I11/100 | J12: =-J6*J11/100 | ... L12: =-L6*L11/100
A13: Owner EBITDA | C13: =C10+C12 | D13: =D10+D12 | E13: =E10+E12 | F13: =F10+F12 | G13: =G10+G12 | H13: =H10+H12 | I13: =I10+I12 | J13: =J10+J12 | ... L13: =L10+L12
A14: Lease cash cost % of revenue | C14: =Assumptions!$D$15 | D14: =Assumptions!$D$15 | E14: =Assumptions!$D$15 | F14: =Assumptions!$D$15 | G14: =Assumptions!$D$15 | H14: =Assumptions!$D$15 | I14: =Assumptions!$D$15 | J14: =Assumptions!$D$15 | ... L14: =Assumptions!$D$15
A15: Lease cash (principal + interest) | C15: =-C6*C14/100 | D15: =-D6*D14/100 | E15: =-E6*E14/100 | F15: =-F6*F14/100 | G15: =-G6*G14/100 | H15: =-H6*H14/100 | I15: =-I6*I14/100 | J15: =-J6*J14/100 | ... L15: =-L6*L14/100
A16: D&A ex-ROU | C16: =-C6*Assumptions!$D$16/100 | D16: =-D6*Assumptions!$D$16/100 | E16: =-E6*Assumptions!$D$16/100 | F16: =-F6*Assumptions!$D$16/100 | G16: =-G6*Assumptions!$D$16/100 | H16: =-H6*Assumptions!$D$16/100 | I16: =-I6*Assumptions!$D$16/100 | J16: =-J6*Assumptions!$D$16/100 | ... L16: =-L6*Assumptions!$D$16/100
A17: EBIT (SBC expensed, post-lease) | C17: =C13+C15+C16 | D17: =D13+D15+D16 | E17: =E13+E15+E16 | F17: =F13+F15+F16 | G17: =G13+G15+G16 | H17: =H13+H15+H16 | I17: =I13+I15+I16 | J17: =J13+J15+J16 | ... L17: =L13+L15+L16
A18: Cash tax rate % | C18: 0 | D18: 0 | E18: 0 | F18: 0 | G18: 7 | H18: 14 | I18: 21 | J18: 28 | K18: 28 | L18: 28
A19: Cash tax | C19: =-MAX(0,C17)*C18/100 | D19: =-MAX(0,D17)*D18/100 | E19: =-MAX(0,E17)*E18/100 | F19: =-MAX(0,F17)*F18/100 | G19: =-MAX(0,G17)*G18/100 | H19: =-MAX(0,H17)*H18/100 | I19: =-MAX(0,I17)*I18/100 | J19: =-MAX(0,J17)*J18/100 | ... L19: =-MAX(0,L17)*L18/100
A20: NOPAT | C20: =C17+C19 | D20: =D17+D19 | E20: =E17+E19 | F20: =F17+F19 | G20: =G17+G19 | H20: =H17+H19 | I20: =I17+I19 | J20: =J17+J19 | ... L20: =L17+L19
A21: add back D&A | C21: =-C16 | D21: =-D16 | E21: =-E16 | F21: =-F16 | G21: =-G16 | H21: =-H16 | I21: =-I16 | J21: =-J16 | ... L21: =-L16
A22: less capex | C22: =-C6*Assumptions!$D$17/100 | D22: =-D6*Assumptions!$D$17/100 | E22: =-E6*Assumptions!$D$17/100 | F22: =-F6*Assumptions!$D$17/100 | G22: =-G6*Assumptions!$D$17/100 | H22: =-H6*Assumptions!$D$17/100 | I22: =-I6*Assumptions!$D$17/100 | J22: =-J6*Assumptions!$D$17/100 | ... L22: =-L6*Assumptions!$D$17/100
A23: add working capital | C23: =Assumptions!$D$18/100*(C6-B6) | D23: =Assumptions!$D$18/100*(D6-C6) | E23: =Assumptions!$D$18/100*(E6-D6) | F23: =Assumptions!$D$18/100*(F6-E6) | G23: =Assumptions!$D$18/100*(G6-F6) | H23: =Assumptions!$D$18/100*(H6-G6) | I23: =Assumptions!$D$18/100*(I6-H6) | J23: =Assumptions!$D$18/100*(J6-I6) | ... L23: =Assumptions!$D$18/100*(L6-K6)
A24: Unlevered owner FCF | B24: 0.55 | C24: =C20+C21+C22+C23 | D24: =D20+D21+D22+D23 | E24: =E20+E21+E22+E23 | F24: =F20+F21+F22+F23 | G24: =G20+G21+G22+G23 | H24: =H20+H21+H22+H23 | I24: =I20+I21+I22+I23 | J24: =J20+J21+J22+J23 | ... L24: =L20+L21+L22+L23 | M24: B24 = FY2026E owner FCF (capex-elevated); not a driver
A25: Discount factor | C25: =1/(1+Assumptions!$B$10/100)^C4 | D25: =1/(1+Assumptions!$B$10/100)^D4 | E25: =1/(1+Assumptions!$B$10/100)^E4 | F25: =1/(1+Assumptions!$B$10/100)^F4 | G25: =1/(1+Assumptions!$B$10/100)^G4 | H25: =1/(1+Assumptions!$B$10/100)^H4 | I25: =1/(1+Assumptions!$B$10/100)^I4 | J25: =1/(1+Assumptions!$B$10/100)^J4 | ... L25: =1/(1+Assumptions!$B$10/100)^L4
A26: PV of FCF | C26: =C24*C25 | D26: =D24*D25 | E26: =E24*E25 | F26: =F24*F25 | G26: =G24*G25 | H26: =H24*H25 | I26: =I24*I25 | J26: =J24*J25 | ... L26: =L24*L25
A28: Memo: FCF before lease & SBC (company-style) | C28: =C24-C15-C12 | D28: =D24-D15-D12 | E28: =E24-E15-E12 | F28: =F24-F15-F12 | G28: =G24-G15-G12 | H28: =H24-H15-H12 | I28: =I24-I15-I12 | J28: =J24-J15-J12 | ... L28: =L24-L15-L12
A29: Memo: owner FCF margin % | C29: =C24/C6*100 | D29: =D24/D6*100 | E29: =E24/E6*100 | F29: =F24/F6*100 | G29: =G24/G6*100 | H29: =H24/H6*100 | I29: =I24/I6*100 | J29: =J24/J6*100 | ... L29: =L24/L6*100
A31: Sum of PV of FCF | B31: =SUM(C26:L26)
A32: Terminal growth % | B32: =Assumptions!$D$13
A33: Terminal-year FCF x (1+g) | B33: =L24*(1+B32/100)
A34: Gordon terminal value | B34: =IF(Assumptions!$B$10>B32,B33/((Assumptions!$B$10-B32)/100),L24*Assumptions!$B$8)
A35: Cap terminal value (cap x FCF10) | B35: =Assumptions!$B$8*L24
A36: Terminal value used = MAX(0,MIN(Gordon,cap)) | B36: =MAX(0,MIN(B34,B35))
A37: Implied exit multiple (x FCF10) | B37: =IF(L24>0,B36/L24,"n/a")
A38: PV of terminal value | B38: =B36*L25
A39: Enterprise value | B39: =B31+B38
A40: less net debt (ex-lease) | B40: =-Assumptions!$B$7
A41: Equity value | B41: =B39+B40
A42: Diluted shares (m) | B42: =Assumptions!$B$4
A43: VALUE PER SHARE (NZ$) | B43: =B41/B42
...

Sheet DCF_Bull
A1: BULL scenario -- owner FCF build (NZ$m)
A3: Year | B3: FY2026A | C3: FY2027E | D3: FY2028E | E3: FY2029E | F3: FY2030E | G3: FY2031E | H3: FY2032E | I3: FY2033E | J3: FY2034E | K3: FY2035E | L3: FY2036E
A4: Index | B4: 0 | C4: 1 | D4: 2 | E4: 3 | F4: 4 | G4: 5 | H4: 6 | I4: 7 | J4: 8 | K4: 9 | L4: 10
A5: Revenue growth % | C5: 6 | D5: 5 | E5: 4 | F5: 3.5 | G5: 3 | H5: 3 | I5: 2.5 | J5: 2.5 | K5: 2.5 | L5: 2.5
A6: Revenue | B6: 55.2 | C6: =B6*(1+C5/100) | D6: =C6*(1+D5/100) | E6: =D6*(1+E5/100) | F6: =E6*(1+F5/100) | G6: =F6*(1+G5/100) | H6: =G6*(1+H5/100) | I6: =H6*(1+I5/100) | J6: =I6*(1+J5/100) | ... L6: =K6*(1+L5/100)
A7: Headline operating-earnings margin % | B7: 14.5 | C7: 16.5 | D7: 17 | E7: 17.5 | F7: 17.5 | G7: 17.5 | H7: 17.5 | I7: 17.5 | J7: 17.5 | K7: 17.5 | L7: 17.5
A8: less recurring restructuring allowance % | C8: =Assumptions!$E$19 | D8: =Assumptions!$E$19 | E8: =Assumptions!$E$19 | F8: =Assumptions!$E$19 | G8: =Assumptions!$E$19 | H8: =Assumptions!$E$19 | I8: =Assumptions!$E$19 | J8: =Assumptions!$E$19 | ... L8: =Assumptions!$E$19
A9: Modelled EBITDA margin % | C9: =C7-C8 | D9: =D7-D8 | E9: =E7-E8 | F9: =F7-F8 | G9: =G7-G8 | H9: =H7-H8 | I9: =I7-I8 | J9: =J7-J8 | ... L9: =L7-L8
A10: Adjusted EBITDA | C10: =C6*C9/100 | D10: =D6*D9/100 | E10: =E6*E9/100 | F10: =F6*F9/100 | G10: =G6*G9/100 | H10: =H6*H9/100 | I10: =I6*I9/100 | J10: =J6*J9/100 | ... L10: =L6*L9/100
A11: SBC % of revenue | C11: 0 | D11: 0 | E11: 0 | F11: 0 | G11: 0 | H11: 0 | I11: 0 | J11: 0 | K11: 0 | L11: 0
A12: SBC (negative) | C12: =-C6*C11/100 | D12: =-D6*D11/100 | E12: =-E6*E11/100 | F12: =-F6*F11/100 | G12: =-G6*G11/100 | H12: =-H6*H11/100 | I12: =-I6*I11/100 | J12: =-J6*J11/100 | ... L12: =-L6*L11/100
A13: Owner EBITDA | C13: =C10+C12 | D13: =D10+D12 | E13: =E10+E12 | F13: =F10+F12 | G13: =G10+G12 | H13: =H10+H12 | I13: =I10+I12 | J13: =J10+J12 | ... L13: =L10+L12
A14: Lease cash cost % of revenue | C14: =Assumptions!$E$15 | D14: =Assumptions!$E$15 | E14: =Assumptions!$E$15 | F14: =Assumptions!$E$15 | G14: =Assumptions!$E$15 | H14: =Assumptions!$E$15 | I14: =Assumptions!$E$15 | J14: =Assumptions!$E$15 | ... L14: =Assumptions!$E$15
A15: Lease cash (principal + interest) | C15: =-C6*C14/100 | D15: =-D6*D14/100 | E15: =-E6*E14/100 | F15: =-F6*F14/100 | G15: =-G6*G14/100 | H15: =-H6*H14/100 | I15: =-I6*I14/100 | J15: =-J6*J14/100 | ... L15: =-L6*L14/100
A16: D&A ex-ROU | C16: =-C6*Assumptions!$E$16/100 | D16: =-D6*Assumptions!$E$16/100 | E16: =-E6*Assumptions!$E$16/100 | F16: =-F6*Assumptions!$E$16/100 | G16: =-G6*Assumptions!$E$16/100 | H16: =-H6*Assumptions!$E$16/100 | I16: =-I6*Assumptions!$E$16/100 | J16: =-J6*Assumptions!$E$16/100 | ... L16: =-L6*Assumptions!$E$16/100
A17: EBIT (SBC expensed, post-lease) | C17: =C13+C15+C16 | D17: =D13+D15+D16 | E17: =E13+E15+E16 | F17: =F13+F15+F16 | G17: =G13+G15+G16 | H17: =H13+H15+H16 | I17: =I13+I15+I16 | J17: =J13+J15+J16 | ... L17: =L13+L15+L16
A18: Cash tax rate % | C18: 0 | D18: 0 | E18: 0 | F18: 7 | G18: 14 | H18: 21 | I18: 28 | J18: 28 | K18: 28 | L18: 28
A19: Cash tax | C19: =-MAX(0,C17)*C18/100 | D19: =-MAX(0,D17)*D18/100 | E19: =-MAX(0,E17)*E18/100 | F19: =-MAX(0,F17)*F18/100 | G19: =-MAX(0,G17)*G18/100 | H19: =-MAX(0,H17)*H18/100 | I19: =-MAX(0,I17)*I18/100 | J19: =-MAX(0,J17)*J18/100 | ... L19: =-MAX(0,L17)*L18/100
A20: NOPAT | C20: =C17+C19 | D20: =D17+D19 | E20: =E17+E19 | F20: =F17+F19 | G20: =G17+G19 | H20: =H17+H19 | I20: =I17+I19 | J20: =J17+J19 | ... L20: =L17+L19
A21: add back D&A | C21: =-C16 | D21: =-D16 | E21: =-E16 | F21: =-F16 | G21: =-G16 | H21: =-H16 | I21: =-I16 | J21: =-J16 | ... L21: =-L16
A22: less capex | C22: =-C6*Assumptions!$E$17/100 | D22: =-D6*Assumptions!$E$17/100 | E22: =-E6*Assumptions!$E$17/100 | F22: =-F6*Assumptions!$E$17/100 | G22: =-G6*Assumptions!$E$17/100 | H22: =-H6*Assumptions!$E$17/100 | I22: =-I6*Assumptions!$E$17/100 | J22: =-J6*Assumptions!$E$17/100 | ... L22: =-L6*Assumptions!$E$17/100
A23: add working capital | C23: =Assumptions!$E$18/100*(C6-B6) | D23: =Assumptions!$E$18/100*(D6-C6) | E23: =Assumptions!$E$18/100*(E6-D6) | F23: =Assumptions!$E$18/100*(F6-E6) | G23: =Assumptions!$E$18/100*(G6-F6) | H23: =Assumptions!$E$18/100*(H6-G6) | I23: =Assumptions!$E$18/100*(I6-H6) | J23: =Assumptions!$E$18/100*(J6-I6) | ... L23: =Assumptions!$E$18/100*(L6-K6)
A24: Unlevered owner FCF | B24: 0.55 | C24: =C20+C21+C22+C23 | D24: =D20+D21+D22+D23 | E24: =E20+E21+E22+E23 | F24: =F20+F21+F22+F23 | G24: =G20+G21+G22+G23 | H24: =H20+H21+H22+H23 | I24: =I20+I21+I22+I23 | J24: =J20+J21+J22+J23 | ... L24: =L20+L21+L22+L23 | M24: B24 = FY2026E owner FCF (capex-elevated); not a driver
A25: Discount factor | C25: =1/(1+Assumptions!$B$10/100)^C4 | D25: =1/(1+Assumptions!$B$10/100)^D4 | E25: =1/(1+Assumptions!$B$10/100)^E4 | F25: =1/(1+Assumptions!$B$10/100)^F4 | G25: =1/(1+Assumptions!$B$10/100)^G4 | H25: =1/(1+Assumptions!$B$10/100)^H4 | I25: =1/(1+Assumptions!$B$10/100)^I4 | J25: =1/(1+Assumptions!$B$10/100)^J4 | ... L25: =1/(1+Assumptions!$B$10/100)^L4
A26: PV of FCF | C26: =C24*C25 | D26: =D24*D25 | E26: =E24*E25 | F26: =F24*F25 | G26: =G24*G25 | H26: =H24*H25 | I26: =I24*I25 | J26: =J24*J25 | ... L26: =L24*L25
A28: Memo: FCF before lease & SBC (company-style) | C28: =C24-C15-C12 | D28: =D24-D15-D12 | E28: =E24-E15-E12 | F28: =F24-F15-F12 | G28: =G24-G15-G12 | H28: =H24-H15-H12 | I28: =I24-I15-I12 | J28: =J24-J15-J12 | ... L28: =L24-L15-L12
A29: Memo: owner FCF margin % | C29: =C24/C6*100 | D29: =D24/D6*100 | E29: =E24/E6*100 | F29: =F24/F6*100 | G29: =G24/G6*100 | H29: =H24/H6*100 | I29: =I24/I6*100 | J29: =J24/J6*100 | ... L29: =L24/L6*100
A31: Sum of PV of FCF | B31: =SUM(C26:L26)
A32: Terminal growth % | B32: =Assumptions!$E$13
A33: Terminal-year FCF x (1+g) | B33: =L24*(1+B32/100)
A34: Gordon terminal value | B34: =IF(Assumptions!$B$10>B32,B33/((Assumptions!$B$10-B32)/100),L24*Assumptions!$B$8)
A35: Cap terminal value (cap x FCF10) | B35: =Assumptions!$B$8*L24
A36: Terminal value used = MAX(0,MIN(Gordon,cap)) | B36: =MAX(0,MIN(B34,B35))
A37: Implied exit multiple (x FCF10) | B37: =IF(L24>0,B36/L24,"n/a")
A38: PV of terminal value | B38: =B36*L25
A39: Enterprise value | B39: =B31+B38
A40: less net debt (ex-lease) | B40: =-Assumptions!$B$7
A41: Equity value | B41: =B39+B40
A42: Diluted shares (m) | B42: =Assumptions!$B$4
A43: VALUE PER SHARE (NZ$) | B43: =B41/B42
...

Sheet FCF_Quality
A1: Reported FCF reconciled to owner FCF (NZ$m) -- treatment B
B2: FY2021 | C2: FY2022 | D2: FY2023 | E2: FY2024 | F2: FY2025 | G2: FY2026E
A3: Operating cash flow (pre-interest) | B3: 0.401 | C3: 2.952 | D3: 6.067 | E3: 6.4 | F3: 7.097 | G3: 6.9
A4: less PPE capex | B4: 0.924 | C4: 1.798 | D4: 4.271 | E4: 0.311 | F4: 1.116 | G4: 2.4
A5: less venue development costs | B5: 0.364 | C5: 0.137 | D5: 0.569 | E5: 0.164 | F5: 0.189 | G5: 0
A6: less lease principal (financing) | B6: 1.253 | C6: 2.738 | D6: 2.45 | E6: 2.918 | F6: 3.053 | G6: 3.2
A7: less lease interest (financing) | B7: 0.394 | C7: 0.769 | D7: 0.744 | E7: 0.815 | F7: 0.722 | G7: 0.75
A8: less SBC incl. equity-award taxes | B8: 0.091 | C8: 0 | D8: 0 | E8: 0 | F8: 0 | G8: 0
A9: less interest income | B9: 0 | C9: 0 | D9: 0 | E9: 0 | F9: 0 | G9: 0
A10: Revenue | B10: 16.134 | C10: 30.581 | D10: 52.378 | E10: 61.858 | F10: 56.643 | G10: 55.2
A11: Operating earnings (EBITDA) | B11: 1.839 | C11: 2.995 | D11: 5.22 | E11: 8.773 | F11: 7.267 | G11: 8
A12: Restructuring costs (P&L) | B12: 0.921 | C12: 1.2 | D12: 1.395 | E12: 0.87 | F12: 2.514
A13: Cash taxes paid | B13: 0 | C13: 0 | D13: 0 | E13: 0 | F13: 0 | G13: 0
A15: Reported FCF (OCF - PPE capex) | B15: =B3-B4 | C15: =C3-C4 | D15: =D3-D4 | E15: =E3-E4 | F15: =F3-F4 | G15: =G3-G4
A16: OWNER FCF | B16: =B15-B5-B6-B7-B8-B9 | C16: =C15-C5-C6-C7-C8-C9 | D16: =D15-D5-D6-D7-D8-D9 | E16: =E15-E5-E6-E7-E8-E9 | F16: =F15-F5-F6-F7-F8-F9 | G16: =G15-G5-G6-G7-G8-G9
A17: Reported FCF margin % | B17: =B15/B10*100 | C17: =C15/C10*100 | D17: =D15/D10*100 | E17: =E15/E10*100 | F17: =F15/F10*100 | G17: =G15/G10*100
A18: Owner FCF margin % | B18: =B16/B10*100 | C18: =C16/C10*100 | D18: =D16/D10*100 | E18: =E16/E10*100 | F18: =F16/F10*100 | G18: =G16/G10*100
A19: Memo: OCF / operating earnings conversion % | B19: =B3/B11*100 | C19: =C3/C11*100 | D19: =D3/D11*100 | E19: =E3/E11*100 | F19: =F3/F11*100 | G19: =G3/G11*100
A20: Memo: lease cash as % of revenue | B20: =(B5+B6+B7)/B10*100 | C20: =(C5+C6+C7)/C10*100 | D20: =(D5+D6+D7)/D10*100 | E20: =(E5+E6+E7)/E10*100 | F20: =(F5+F6+F7)/F10*100 | G20: =(G5+G6+G7)/G10*100
A22: Memo: cash tax rate has been 0% every year (tax losses ~NZ$26.7m at 31-Mar-2025) -- abnormal, ramped to 28% in the model. FY2026E capex is an estimate (two Britomart fit-outs).

Sheet Valuation
A1: Valuation summary (NZ$ per share)
A2: Scenario | B2: Value per share | C2: Upside vs price % | D2: Probability | E2: Street value per share | F2: Entry price @15% hurdle
A3: Bear | B3: =DCF_Bear!$B$43 | C3: =(B3/Assumptions!$B$3-1)*100 | D3: =Assumptions!$C$14 | E3: =DCF_Bear!$B$48 | F3: =DCF_Bear!$B$50
A4: Base | B4: =DCF_Base!$B$43 | C4: =(B4/Assumptions!$B$3-1)*100 | D4: =Assumptions!$D$14 | E4: =DCF_Base!$B$48 | F4: =DCF_Base!$B$50
A5: Bull | B5: =DCF_Bull!$B$43 | C5: =(B5/Assumptions!$B$3-1)*100 | D5: =Assumptions!$E$14 | E5: =DCF_Bull!$B$48 | F5: =DCF_Bull!$B$50
A7: Probability-weighted value per share | B7: =SUMPRODUCT(B3:B5,D3:D5)
A8: Margin of safety vs price (1 - price/weighted) | B8: =1-Assumptions!$B$3/B7
A9: Street weighted value per share | B9: =SUMPRODUCT(E3:E5,D3:D5)
A10: Band position (house..street) | B10: =IF(ABS(B9-B7)<0.000001,"n/a (SBC-zero: house = street)",(Assumptions!$B$3-B7)/(B9-B7))
A11: Probability-weighted entry price @15% hurdle | B11: =SUMPRODUCT(F3:F5,D3:D5)
A12: Memo: weighted value with bear floored at zero (limited liability) | B12: =SUMPRODUCT(D3:D5,IF(B3:B5>0,B3:B5,0))
A13: Note: WACC 16.5% exceeds the 15% hurdle, so entry prices sit ABOVE intrinsic values; the buy-below price at the house rate is B7.
A15: Required-return table (base case; TV rebuilt at each rate)
A16: Required return % | B16: 9 | C16: 10 | D16: 11 | E16: 12 | F16: 15 | G16: 16.5
A17: Value per share | B17: =IF(B16>DCF_Base!$B$32,(SUMPRODUCT(DCF_Base!$C$24:$L$24/(1+B16/100)^DCF_Base!$C$4:$L$4)+MAX(0,MIN(DCF_Base!$L$24*(1+DCF_Base!$B$32/100)/((B16-DCF_Base!$B$32)/100),Assumptions!$B$8*DCF_Base!$L$24))/(1+B16/100)^10-Assumptions!$B$7)/Assumptions!$B$4,"n/a") | C17: =IF(C16>DCF_Base!$B$32,(SUMPRODUCT(DCF_Base!$C$24:$L$24/(1+C16/100)^DCF_Base!$C$4:$L$4)+MAX(0,MIN(DCF_Base!$L$24*(1+DCF_Base!$B$32/100)/((C16-DCF_Base!$B$32)/100),Assumptions!$B$8*DCF_Base!$L$24))/(1+C16/100)^10-Assumptions!$B$7)/Assumptions!$B$4,"n/a") | D17: =IF(D16>DCF_Base!$B$32,(SUMPRODUCT(DCF_Base!$C$24:$L$24/(1+D16/100)^DCF_Base!$C$4:$L$4)+MAX(0,MIN(DCF_Base!$L$24*(1+DCF_Base!$B$32/100)/((D16-DCF_Base!$B$32)/100),Assumptions!$B$8*DCF_Base!$L$24))/(1+D16/100)^10-Assumptions!$B$7)/Assumptions!$B$4,"n/a") | E17: =IF(E16>DCF_Base!$B$32,(SUMPRODUCT(DCF_Base!$C$24:$L$24/(1+E16/100)^DCF_Base!$C$4:$L$4)+MAX(0,MIN(DCF_Base!$L$24*(1+DCF_Base!$B$32/100)/((E16-DCF_Base!$B$32)/100),Assumptions!$B$8*DCF_Base!$L$24))/(1+E16/100)^10-Assumptions!$B$7)/Assumptions!$B$4,"n/a") | F17: =IF(F16>DCF_Base!$B$32,(SUMPRODUCT(DCF_Base!$C$24:$L$24/(1+F16/100)^DCF_Base!$C$4:$L$4)+MAX(0,MIN(DCF_Base!$L$24*(1+DCF_Base!$B$32/100)/((F16-DCF_Base!$B$32)/100),Assumptions!$B$8*DCF_Base!$L$24))/(1+F16/100)^10-Assumptions!$B$7)/Assumptions!$B$4,"n/a") | G17: =IF(G16>DCF_Base!$B$32,(SUMPRODUCT(DCF_Base!$C$24:$L$24/(1+G16/100)^DCF_Base!$C$4:$L$4)+MAX(0,MIN(DCF_Base!$L$24*(1+DCF_Base!$B$32/100)/((G16-DCF_Base!$B$32)/100),Assumptions!$B$8*DCF_Base!$L$24))/(1+G16/100)^10-Assumptions!$B$7)/Assumptions!$B$4,"n/a")
A18: Check: 15% column = DCF_Base!B50; 16.5% column = DCF_Base!B43
A20: Sensitivity: base-case value per share, WACC (rows) x terminal growth (columns)
B21: 1.25 | C21: 1.75 | D21: 2.25 | E21: 2.75 | F21: 3.25
A22: 14.5 | B22: =IF($A22>B$21,(SUMPRODUCT(DCF_Base!$C$24:$L$24/(1+$A22/100)^DCF_Base!$C$4:$L$4)+MAX(0,MIN(DCF_Base!$L$24*(1+B$21/100)/(($A22-B$21)/100),Assumptions!$B$8*DCF_Base!$L$24))/(1+$A22/100)^10-Assumptions!$B$7)/Assumptions!$B$4,"n/a") | C22: =IF($A22>C$21,(SUMPRODUCT(DCF_Base!$C$24:$L$24/(1+$A22/100)^DCF_Base!$C$4:$L$4)+MAX(0,MIN(DCF_Base!$L$24*(1+C$21/100)/(($A22-C$21)/100),Assumptions!$B$8*DCF_Base!$L$24))/(1+$A22/100)^10-Assumptions!$B$7)/Assumptions!$B$4,"n/a") | D22: =IF($A22>D$21,(SUMPRODUCT(DCF_Base!$C$24:$L$24/(1+$A22/100)^DCF_Base!$C$4:$L$4)+MAX(0,MIN(DCF_Base!$L$24*(1+D$21/100)/(($A22-D$21)/100),Assumptions!$B$8*DCF_Base!$L$24))/(1+$A22/100)^10-Assumptions!$B$7)/Assumptions!$B$4,"n/a") | E22: =IF($A22>E$21,(SUMPRODUCT(DCF_Base!$C$24:$L$24/(1+$A22/100)^DCF_Base!$C$4:$L$4)+MAX(0,MIN(DCF_Base!$L$24*(1+E$21/100)/(($A22-E$21)/100),Assumptions!$B$8*DCF_Base!$L$24))/(1+$A22/100)^10-Assumptions!$B$7)/Assumptions!$B$4,"n/a") | F22: =IF($A22>F$21,(SUMPRODUCT(DCF_Base!$C$24:$L$24/(1+$A22/100)^DCF_Base!$C$4:$L$4)+MAX(0,MIN(DCF_Base!$L$24*(1+F$21/100)/(($A22-F$21)/100),Assumptions!$B$8*DCF_Base!$L$24))/(1+$A22/100)^10-Assumptions!$B$7)/Assumptions!$B$4,"n/a")
A23: 15.5 | B23: =IF($A23>B$21,(SUMPRODUCT(DCF_Base!$C$24:$L$24/(1+$A23/100)^DCF_Base!$C$4:$L$4)+MAX(0,MIN(DCF_Base!$L$24*(1+B$21/100)/(($A23-B$21)/100),Assumptions!$B$8*DCF_Base!$L$24))/(1+$A23/100)^10-Assumptions!$B$7)/Assumptions!$B$4,"n/a") | C23: =IF($A23>C$21,(SUMPRODUCT(DCF_Base!$C$24:$L$24/(1+$A23/100)^DCF_Base!$C$4:$L$4)+MAX(0,MIN(DCF_Base!$L$24*(1+C$21/100)/(($A23-C$21)/100),Assumptions!$B$8*DCF_Base!$L$24))/(1+$A23/100)^10-Assumptions!$B$7)/Assumptions!$B$4,"n/a") | D23: =IF($A23>D$21,(SUMPRODUCT(DCF_Base!$C$24:$L$24/(1+$A23/100)^DCF_Base!$C$4:$L$4)+MAX(0,MIN(DCF_Base!$L$24*(1+D$21/100)/(($A23-D$21)/100),Assumptions!$B$8*DCF_Base!$L$24))/(1+$A23/100)^10-Assumptions!$B$7)/Assumptions!$B$4,"n/a") | E23: =IF($A23>E$21,(SUMPRODUCT(DCF_Base!$C$24:$L$24/(1+$A23/100)^DCF_Base!$C$4:$L$4)+MAX(0,MIN(DCF_Base!$L$24*(1+E$21/100)/(($A23-E$21)/100),Assumptions!$B$8*DCF_Base!$L$24))/(1+$A23/100)^10-Assumptions!$B$7)/Assumptions!$B$4,"n/a") | F23: =IF($A23>F$21,(SUMPRODUCT(DCF_Base!$C$24:$L$24/(1+$A23/100)^DCF_Base!$C$4:$L$4)+MAX(0,MIN(DCF_Base!$L$24*(1+F$21/100)/(($A23-F$21)/100),Assumptions!$B$8*DCF_Base!$L$24))/(1+$A23/100)^10-Assumptions!$B$7)/Assumptions!$B$4,"n/a")
A24: 16.5 | B24: =IF($A24>B$21,(SUMPRODUCT(DCF_Base!$C$24:$L$24/(1+$A24/100)^DCF_Base!$C$4:$L$4)+MAX(0,MIN(DCF_Base!$L$24*(1+B$21/100)/(($A24-B$21)/100),Assumptions!$B$8*DCF_Base!$L$24))/(1+$A24/100)^10-Assumptions!$B$7)/Assumptions!$B$4,"n/a") | C24: =IF($A24>C$21,(SUMPRODUCT(DCF_Base!$C$24:$L$24/(1+$A24/100)^DCF_Base!$C$4:$L$4)+MAX(0,MIN(DCF_Base!$L$24*(1+C$21/100)/(($A24-C$21)/100),Assumptions!$B$8*DCF_Base!$L$24))/(1+$A24/100)^10-Assumptions!$B$7)/Assumptions!$B$4,"n/a") | D24: =IF($A24>D$21,(SUMPRODUCT(DCF_Base!$C$24:$L$24/(1+$A24/100)^DCF_Base!$C$4:$L$4)+MAX(0,MIN(DCF_Base!$L$24*(1+D$21/100)/(($A24-D$21)/100),Assumptions!$B$8*DCF_Base!$L$24))/(1+$A24/100)^10-Assumptions!$B$7)/Assumptions!$B$4,"n/a") | E24: =IF($A24>E$21,(SUMPRODUCT(DCF_Base!$C$24:$L$24/(1+$A24/100)^DCF_Base!$C$4:$L$4)+MAX(0,MIN(DCF_Base!$L$24*(1+E$21/100)/(($A24-E$21)/100),Assumptions!$B$8*DCF_Base!$L$24))/(1+$A24/100)^10-Assumptions!$B$7)/Assumptions!$B$4,"n/a") | F24: =IF($A24>F$21,(SUMPRODUCT(DCF_Base!$C$24:$L$24/(1+$A24/100)^DCF_Base!$C$4:$L$4)+MAX(0,MIN(DCF_Base!$L$24*(1+F$21/100)/(($A24-F$21)/100),Assumptions!$B$8*DCF_Base!$L$24))/(1+$A24/100)^10-Assumptions!$B$7)/Assumptions!$B$4,"n/a")
A25: 17.5 | B25: =IF($A25>B$21,(SUMPRODUCT(DCF_Base!$C$24:$L$24/(1+$A25/100)^DCF_Base!$C$4:$L$4)+MAX(0,MIN(DCF_Base!$L$24*(1+B$21/100)/(($A25-B$21)/100),Assumptions!$B$8*DCF_Base!$L$24))/(1+$A25/100)^10-Assumptions!$B$7)/Assumptions!$B$4,"n/a") | C25: =IF($A25>C$21,(SUMPRODUCT(DCF_Base!$C$24:$L$24/(1+$A25/100)^DCF_Base!$C$4:$L$4)+MAX(0,MIN(DCF_Base!$L$24*(1+C$21/100)/(($A25-C$21)/100),Assumptions!$B$8*DCF_Base!$L$24))/(1+$A25/100)^10-Assumptions!$B$7)/Assumptions!$B$4,"n/a") | D25: =IF($A25>D$21,(SUMPRODUCT(DCF_Base!$C$24:$L$24/(1+$A25/100)^DCF_Base!$C$4:$L$4)+MAX(0,MIN(DCF_Base!$L$24*(1+D$21/100)/(($A25-D$21)/100),Assumptions!$B$8*DCF_Base!$L$24))/(1+$A25/100)^10-Assumptions!$B$7)/Assumptions!$B$4,"n/a") | E25: =IF($A25>E$21,(SUMPRODUCT(DCF_Base!$C$24:$L$24/(1+$A25/100)^DCF_Base!$C$4:$L$4)+MAX(0,MIN(DCF_Base!$L$24*(1+E$21/100)/(($A25-E$21)/100),Assumptions!$B$8*DCF_Base!$L$24))/(1+$A25/100)^10-Assumptions!$B$7)/Assumptions!$B$4,"n/a") | F25: =IF($A25>F$21,(SUMPRODUCT(DCF_Base!$C$24:$L$24/(1+$A25/100)^DCF_Base!$C$4:$L$4)+MAX(0,MIN(DCF_Base!$L$24*(1+F$21/100)/(($A25-F$21)/100),Assumptions!$B$8*DCF_Base!$L$24))/(1+$A25/100)^10-Assumptions!$B$7)/Assumptions!$B$4,"n/a")
A26: 18.5 | B26: =IF($A26>B$21,(SUMPRODUCT(DCF_Base!$C$24:$L$24/(1+$A26/100)^DCF_Base!$C$4:$L$4)+MAX(0,MIN(DCF_Base!$L$24*(1+B$21/100)/(($A26-B$21)/100),Assumptions!$B$8*DCF_Base!$L$24))/(1+$A26/100)^10-Assumptions!$B$7)/Assumptions!$B$4,"n/a") | C26: =IF($A26>C$21,(SUMPRODUCT(DCF_Base!$C$24:$L$24/(1+$A26/100)^DCF_Base!$C$4:$L$4)+MAX(0,MIN(DCF_Base!$L$24*(1+C$21/100)/(($A26-C$21)/100),Assumptions!$B$8*DCF_Base!$L$24))/(1+$A26/100)^10-Assumptions!$B$7)/Assumptions!$B$4,"n/a") | D26: =IF($A26>D$21,(SUMPRODUCT(DCF_Base!$C$24:$L$24/(1+$A26/100)^DCF_Base!$C$4:$L$4)+MAX(0,MIN(DCF_Base!$L$24*(1+D$21/100)/(($A26-D$21)/100),Assumptions!$B$8*DCF_Base!$L$24))/(1+$A26/100)^10-Assumptions!$B$7)/Assumptions!$B$4,"n/a") | E26: =IF($A26>E$21,(SUMPRODUCT(DCF_Base!$C$24:$L$24/(1+$A26/100)^DCF_Base!$C$4:$L$4)+MAX(0,MIN(DCF_Base!$L$24*(1+E$21/100)/(($A26-E$21)/100),Assumptions!$B$8*DCF_Base!$L$24))/(1+$A26/100)^10-Assumptions!$B$7)/Assumptions!$B$4,"n/a") | F26: =IF($A26>F$21,(SUMPRODUCT(DCF_Base!$C$24:$L$24/(1+$A26/100)^DCF_Base!$C$4:$L$4)+MAX(0,MIN(DCF_Base!$L$24*(1+F$21/100)/(($A26-F$21)/100),Assumptions!$B$8*DCF_Base!$L$24))/(1+$A26/100)^10-Assumptions!$B$7)/Assumptions!$B$4,"n/a")
A28: Dividend cross-check
A29: Targeted DPS (NZ$) | B29: 0.02
A30: Gross yield at price % | B30: =B29/Assumptions!$B$3*100
A31: Annual cash cost (NZ$m) | B31: =B29*Assumptions!$B$4
A32: DDM value at WACC as cost of equity, g = 2% (NZ$) | B32: =B29/((Assumptions!$B$10-2)/100)
A33: Implied required return at price (yield + 2%) | B33: =B30+2
A34: Base FY27 levered FCF after ~6.5% bank interest (NZ$m) | B34: =DCF_Base!C24-Assumptions!$B$5*0.065
A35: Dividend cover on base levered FCF (x) | B35: =B34/B31
