Workbook

Sheet Base Case Model
A1: MEE.NZ (Me Today Limited) - Path-to-Breakeven Scenario Model
A2: NOT a standard FCF DCF - company has never had positive FCF/continuing profit. Gray cells are INPUTS.
A4: KEY INPUTS
A5: Current Stock Price | B5: 0.052
A6: Shares Outstanding (M, current) | B6: 94.522
A7: Cash (M) | B7: 2.226
A8: Total Debt (M) | B8: 2.25
A9: Net Debt (M) | B9: =B8-B7 -> 0
A10: Warrant Series 1 (M units) | B10: 47.261
A11: Warrant Series 2 (M units) | B11: 47.261
A12: Warrant Strike Price | B12: 0.06
A13: Cost of Equity (Base) | B13: 0.21
A14: Exit EV/EBITDA Multiple (Base) | B14: 9
A16: WARRANT OUTCOME SWITCHES (Base Case)
A17: Series 1 exercises? (1=yes,0=no) | B17: 0
A18: Series 2 exercises? (1=yes,0=no) | B18: 1
A19: FY27 dilutive placement raise (M$) | B19: 1.237
A20: FY27 placement price | B20: 0.045
A21: These switches encode the BASE case narrative: Series 1 (Oct-2026) expires worthless because the price has not cleared the $0.06 strike this early; a discounted placement bridges FY2027; Series 2 (Oct-2027) then exercises as the story de-risks. Change the switches/placement inputs to explore other paths.
A23: REVENUE & EBITDA BUILD
B24: FY2026 | C24: FY2027 | D24: FY2028 | E24: FY2029 | F24: FY2030
A25: Revenue (net, $M) | B25: 7.5 | C25: 9.15 | D25: 10.797 | E25: 12.417 | F25: 13.907
A26: EBITDA margin % | B26: -0.207 | C26: -0.09 | D26: -0.02 | E26: 0.04 | F26: 0.08
A27: EBITDA ($M) | B27: =B25*B26 -> 0 | C27: =C25*C26 -> 0 | D27: =D25*D26 -> 0 | E27: =E25*E26 -> 0 | F27: =F25*F26 -> 0
A28: D&A (% of revenue) | B28: 0.012
A29: D&A ($M) | B29: =B25*$B$28 -> 0 | C29: =C25*$B$28 -> 0 | D29: =D25*$B$28 -> 0 | E29: =E25*$B$28 -> 0 | F29: =F25*$B$28 -> 0
A30: EBIT ($M) | B30: =B27-B29 -> 0 | C30: =C27-C29 -> 0 | D30: =D27-D29 -> 0 | E30: =E27-E29 -> 0 | F30: =F27-F29 -> 0
A31: Cash Tax Rate | B31: 0.28
A32: NOPAT ($M) [no tax benefit on losses] | B32: =IF(B30>0,B30*(1-$B$31),B30) -> 0 | C32: =IF(C30>0,C30*(1-$B$31),C30) -> 0 | D32: =IF(D30>0,D30*(1-$B$31),D30) -> 0 | E32: =IF(E30>0,E30*(1-$B$31),E30) -> 0 | F32: =IF(F30>0,F30*(1-$B$31),F30) -> 0
A33: Capex (% of revenue) | B33: 0.015
A34: Capex ($M) | B34: =B25*$B$33 -> 0 | C34: =C25*$B$33 -> 0 | D34: =D25*$B$33 -> 0 | E34: =E25*$B$33 -> 0 | F34: =F25*$B$33 -> 0
A35: WC capture % of revenue GROWTH | B35: 0.12
A36: Working Capital change ($M) | B36: =$B$35*(B25-6.318449873631002) -> 0 | C36: =$B$35*(C25-B25) -> 0 | D36: =$B$35*(D25-C25) -> 0 | E36: =$B$35*(E25-D25) -> 0 | F36: =$B$35*(F25-E25) -> 0
A37: Owner FCF ($M) | B37: =B32+B29-B34-B36 -> 0 | C37: =C32+C29-C34-C36 -> 0 | D37: =D32+D29-D34-D36 -> 0 | E37: =E32+E29-E34-E36 -> 0 | F37: =F32+F29-F34-F36 -> 0
A39: CASH & SHARE WALK
A40: Cash, opening ($M) | B40: =B7 -> 0 | C40: =B45 -> 0 | D40: =C45 -> 0 | E40: =D45 -> 0 | F40: =E45 -> 0
A41: + Owner FCF | B41: =B37 -> 0 | C41: =C37 -> 0 | D41: =D37 -> 0 | E41: =E37 -> 0 | F41: =F37 -> 0
A42: + Series 1 proceeds (FY2027 only) | C42: =$B$17*$B$10*$B$12 -> 0
A43: + Series 2 proceeds (FY2028 only) | D43: =$B$18*$B$11*$B$12 -> 0
A44: + Discounted placement (FY2027 only) | C44: =IF($B$17=0,$B$19,0) -> 0
...

Sheet Scenario Summary
A1: Scenario Summary (values from JSON - not linked formulas)
A3: Metric | B3: Bull | C3: Base | D3: Bear
A4: Probability | B4: 0.2 | C4: 0.45 | D4: 0.35
A5: Cost of Equity | B5: 0.185 | C5: 0.21 | D5: 0.26
A6: Year-5 Revenue ($M) | B6: 22.937 | C6: 13.907 | D6: 8.377
A7: Year-5 EBITDA ($M) | B7: 2.752 | C7: 1.113 | D7: -0.251
A8: Year-5 Shares (M) | B8: 189.044 | C8: 169.272 | D8: 217.162
A9: Intrinsic Value/Share | B9: 0.0927 | C9: 0.0144 | D9: 0
A10: Upside/(Downside) | B10: 0.783 | C10: -0.723 | D10: -1
A11: Probability-Weighted IV | B11: =B8*0.2+C8*0.45+D8*0.35 -> 0
A12: Current Price | B12: 0.052
A13: Weighted Upside/(Downside) | B13: =(B11-B12)/B12 -> 0
A15: Bear case raw equity value is NEGATIVE (modelled dilution/cash burn exceeds enterprise value). Per-share IV is floored at $0.00 -- a limited-liability equity claim cannot go below zero -- rather than shown as a negative price. This reflects a real, non-trivial probability of near-total loss.

Sheet Sensitivity
A1: Sensitivity Analysis (Base Case)
A2: Intrinsic Value by Cost of Equity & Exit EV/EBITDA Multiple
A4: CoE \ Exit Mult | B4: 7 | C4: 8 | D4: 9 | E4: 10 | F4: 11
A5: 0.17 | B5: =(NPV(0.17,'Base Case Model'!$B$37:$F$37)+('Base Case Model'!$F$27*7.0)/(1+0.17)^5-'Base Case Model'!$B$56)/'Base Case Model'!$B$58 -> 0 | C5: =(NPV(0.17,'Base Case Model'!$B$37:$F$37)+('Base Case Model'!$F$27*8.0)/(1+0.17)^5-'Base Case Model'!$B$56)/'Base Case Model'!$B$58 -> 0 | D5: =(NPV(0.17,'Base Case Model'!$B$37:$F$37)+('Base Case Model'!$F$27*9.0)/(1+0.17)^5-'Base Case Model'!$B$56)/'Base Case Model'!$B$58 -> 0 | E5: =(NPV(0.17,'Base Case Model'!$B$37:$F$37)+('Base Case Model'!$F$27*10.0)/(1+0.17)^5-'Base Case Model'!$B$56)/'Base Case Model'!$B$58 -> 0 | F5: =(NPV(0.17,'Base Case Model'!$B$37:$F$37)+('Base Case Model'!$F$27*11.0)/(1+0.17)^5-'Base Case Model'!$B$56)/'Base Case Model'!$B$58 -> 0
A6: 0.19 | B6: =(NPV(0.19,'Base Case Model'!$B$37:$F$37)+('Base Case Model'!$F$27*7.0)/(1+0.19)^5-'Base Case Model'!$B$56)/'Base Case Model'!$B$58 -> 0 | C6: =(NPV(0.19,'Base Case Model'!$B$37:$F$37)+('Base Case Model'!$F$27*8.0)/(1+0.19)^5-'Base Case Model'!$B$56)/'Base Case Model'!$B$58 -> 0 | D6: =(NPV(0.19,'Base Case Model'!$B$37:$F$37)+('Base Case Model'!$F$27*9.0)/(1+0.19)^5-'Base Case Model'!$B$56)/'Base Case Model'!$B$58 -> 0 | E6: =(NPV(0.19,'Base Case Model'!$B$37:$F$37)+('Base Case Model'!$F$27*10.0)/(1+0.19)^5-'Base Case Model'!$B$56)/'Base Case Model'!$B$58 -> 0 | F6: =(NPV(0.19,'Base Case Model'!$B$37:$F$37)+('Base Case Model'!$F$27*11.0)/(1+0.19)^5-'Base Case Model'!$B$56)/'Base Case Model'!$B$58 -> 0
A7: 0.21 | B7: =(NPV(0.21,'Base Case Model'!$B$37:$F$37)+('Base Case Model'!$F$27*7.0)/(1+0.21)^5-'Base Case Model'!$B$56)/'Base Case Model'!$B$58 -> 0 | C7: =(NPV(0.21,'Base Case Model'!$B$37:$F$37)+('Base Case Model'!$F$27*8.0)/(1+0.21)^5-'Base Case Model'!$B$56)/'Base Case Model'!$B$58 -> 0 | D7: =(NPV(0.21,'Base Case Model'!$B$37:$F$37)+('Base Case Model'!$F$27*9.0)/(1+0.21)^5-'Base Case Model'!$B$56)/'Base Case Model'!$B$58 -> 0 | E7: =(NPV(0.21,'Base Case Model'!$B$37:$F$37)+('Base Case Model'!$F$27*10.0)/(1+0.21)^5-'Base Case Model'!$B$56)/'Base Case Model'!$B$58 -> 0 | F7: =(NPV(0.21,'Base Case Model'!$B$37:$F$37)+('Base Case Model'!$F$27*11.0)/(1+0.21)^5-'Base Case Model'!$B$56)/'Base Case Model'!$B$58 -> 0
A8: 0.23 | B8: =(NPV(0.23,'Base Case Model'!$B$37:$F$37)+('Base Case Model'!$F$27*7.0)/(1+0.23)^5-'Base Case Model'!$B$56)/'Base Case Model'!$B$58 -> 0 | C8: =(NPV(0.23,'Base Case Model'!$B$37:$F$37)+('Base Case Model'!$F$27*8.0)/(1+0.23)^5-'Base Case Model'!$B$56)/'Base Case Model'!$B$58 -> 0 | D8: =(NPV(0.23,'Base Case Model'!$B$37:$F$37)+('Base Case Model'!$F$27*9.0)/(1+0.23)^5-'Base Case Model'!$B$56)/'Base Case Model'!$B$58 -> 0 | E8: =(NPV(0.23,'Base Case Model'!$B$37:$F$37)+('Base Case Model'!$F$27*10.0)/(1+0.23)^5-'Base Case Model'!$B$56)/'Base Case Model'!$B$58 -> 0 | F8: =(NPV(0.23,'Base Case Model'!$B$37:$F$37)+('Base Case Model'!$F$27*11.0)/(1+0.23)^5-'Base Case Model'!$B$56)/'Base Case Model'!$B$58 -> 0
A9: 0.25 | B9: =(NPV(0.25,'Base Case Model'!$B$37:$F$37)+('Base Case Model'!$F$27*7.0)/(1+0.25)^5-'Base Case Model'!$B$56)/'Base Case Model'!$B$58 -> 0 | C9: =(NPV(0.25,'Base Case Model'!$B$37:$F$37)+('Base Case Model'!$F$27*8.0)/(1+0.25)^5-'Base Case Model'!$B$56)/'Base Case Model'!$B$58 -> 0 | D9: =(NPV(0.25,'Base Case Model'!$B$37:$F$37)+('Base Case Model'!$F$27*9.0)/(1+0.25)^5-'Base Case Model'!$B$56)/'Base Case Model'!$B$58 -> 0 | E9: =(NPV(0.25,'Base Case Model'!$B$37:$F$37)+('Base Case Model'!$F$27*10.0)/(1+0.25)^5-'Base Case Model'!$B$56)/'Base Case Model'!$B$58 -> 0 | F9: =(NPV(0.25,'Base Case Model'!$B$37:$F$37)+('Base Case Model'!$F$27*11.0)/(1+0.25)^5-'Base Case Model'!$B$56)/'Base Case Model'!$B$58 -> 0
A11: Gordon-growth terminal value is NOT used in this model (FCF is near zero through most of the projection window, making a growth perpetuity numerically unstable). Terminal value uses an exit EV/EBITDA multiple on Year-5 EBITDA instead.

Sheet FCF Quality
A1: Historical Free Cash Flow (as reported) - ALL NEGATIVE
A2: No period in the historical record has positive FCF or continuing-operations profit. This is the core reason a standard discounted-FCF model is not used for MEE.NZ.
A4: Period | B4: FY2020 | C4: FY2021 | D4: FY2022 | E4: FY2023 | F4: FY2024 | G4: FY2025 | H4: H1-2026
A5: Revenue ($M) | B5: 0.566 | C5: 1.143 | D5: 8.273 | E5: 7.883 | F5: 5.032 | G5: 7.454 | H5: 2.554
A6: Reported FCF ($M) | B6: -1.157 | C6: -3.453 | D6: -12.053 | E6: -5.601 | F6: -3.161 | G6: -0.975 | H6: -1.088
A7: Net Income ($M) [H1-2026 incl. $4.143M one-off King Honey gain] | B7: -4.982 | C7: -2.86 | D7: -19.544 | E7: -12.974 | F7: -11.276 | G7: -6.016 | H7: 3.219
A9: H1-2026 Continuing-Ops Net Income (excl. one-off) | B9: -0.902
A10: H1-2025 Continuing-Ops Net Income | B10: -1.476
A11: H1-2026 Continuing-Ops EBITDA | B11: -0.827
A13: Memo: Accumulated losses ($M) | B13: 54.5
A14: Memo: SBC | B14: Not material / nil in recent periods per CSV

Sheet Model_Info
A1: Model Info / Provenance
A3: Ticker | B3: MEE.NZ (Me Today Limited)
A4: Built by | B4: Claude dcf-analyst agent, per .claude/agents/dcf-analyst.md, with explicit non-standard-DCF instructions from the invoking task
A5: Build date | B5: 2026-08-13
A6: Share price date/source | B6: 0.052 NZD, Yahoo Finance live quote, verified 2026-08-13
A7: Data vintage | B7: MEE.NZ_Metrics.csv and MEE.NZ_Analysis.json as of 13-Aug-2026; H1-2026 (six months to 31-Dec-2025) is the latest reported period; FY2026 (year to 30-Jun-2026) guidance last updated 29-Jul-2026 market update; audited FY2026 results due to NZX before 31-Aug-2026 (NOT YET RELEASED as of this model)
A8: Methodology | B8: NOT a discounted-FCF model. Scenario-weighted path-to-breakeven valuation: revenue/EBITDA margin build to breakeven per scenario, owner FCF from EBITDA-DA-tax-capex-WC, cash-balance walk determines dilution needs, warrants (95.522M units, $0.06 strike) modelled CONDITIONALLY per scenario (exercise with cash-in+shares-out, or expire worthless triggering a discounted placement), terminal value via exit EV/EBITDA multiple (NOT Gordon growth - unstable this close to breakeven), discounted at a scenario-specific cost of equity (18.5%-26%), divided by the Year-5 projected share count.
A9: Why not Gordon growth | B9: FCF and EBITDA are near zero through most of the 5-year window; a growth-perpetuity terminal value on a near-zero base is numerically unstable and small growth-rate changes swing it wildly. An exit EV/EBITDA multiple on Year-5 EBITDA is used instead (bear case, still EBITDA-negative at Year 5, uses 0.3x Year-5 revenue as a distressed floor).
A10: Why no historical CAGRs | B10: Two share consolidations (1-for-5 Apr-2020, 1-for-100 Jan-2024) plus a near-doubling of shares via the Nov-2025 rights issue break the SharesOutstanding series. EPS/equity-per-share CAGRs across these breaks would be meaningless and are not computed.
A11: Key near-term catalysts | B11: Audited FY2026 results (due before 31-Aug-2026); Series 1 warrant window 1-30 Oct-2026 (currently out-of-the-money vs $0.06 strike)
A12: What to refresh after FY2026 results | B12: Actual FY2026 revenue/EBITDA vs guidance; whether continuing-operations losses continue to narrow; updated cash balance and runway; re-assess whether the share price has moved relative to the $0.06 warrant strike ahead of the Oct-2026 window; update all three scenarios and re-run.
A13: Cell colour conventions | B13: Gray fill = input cell (change to explore scenarios). Green fill = key output. Red fill = warning/disclosure. White = formula/computed.
A14: Staleness warning | B14: All figures, especially FY2026 guidance and the warrant moneyness assessment, are time-sensitive and MUST be re-checked against the audited FY2026 result and the then-current share price before being relied upon.
