Workbook

Sheet Model_Info
A1: Workbook | B1: SML.NZ Synlait Milk Limited -- scenario-weighted owner-FCF DCF with equity-impairment bear. Version 1.0 (fresh build, supersedes nothing).
A2: Built by | B2: dcf-analyst agent (Claude, model claude-fable-5-1) on 2026-09-02 at the request of the research-stock orchestrator for Stephen Williams.
A3: Data vintage: price | B3: NZ$0.395 -- 2026-09-02T05:00:13Z (NZX regular close 17:00 NZST; Yahoo regularMarketPrice). Figures go stale: refresh price before use.
A4: Data vintage: balance sheet | B4: 2026-01-31 (H1 FY2026 interim, reviewed by KPMG with a material-uncertainty-related-to-going-concern paragraph); net debt adjusted for the 1-Apr-2026 North Island sale completion and estimated forward to 31-Jul-2026
A5: Data vintage: net debt | B5: ESTIMATED 31-Jul-2026 pro-forma: 472.1 (31-Jan-2026 reported, ex leases) - 283.1 (Abbott proceeds 1-Apr-2026) - 90.0 (seasonal WC unwind to FY-end norm) + 26.0 (H2 FY26 cash burn) = 125.0. Refresh at the FY2026 result (late Sept-2026).
A6: Data vintage: shares | B6: 603,198,098 ordinary shares on issue at 31-Jan-2026 (H1 FY2026 note 12), unchanged since the 1-Oct-2024 recapitalisation placement; PSRs immaterial and anti-dilutive. Held FLAT (no SBC to expense, no raise assumed in the flows).
A7: Data vintage: guidance | B7: FY2026 (year to 31-Jul-2026) underlying net loss after tax NZ$19m-24m, issued 14-Aug-2026. FY2026 results due late Sept-2026 -- refresh net debt, equity and the FY0 revenue base then.
A8: Methodology: model | B8: MODEL CHOICE: probability-weighted owner-FCF DCF (component build, 10-year horizon) with a DISTRESS bear, routed via .claude/skills/dcf-methods/SKILL.md. Synlait straddles two routing rows -- 'operating company, non-US/cyclical' and 'distressed' -- but is NOT in receivership, has forward cash flows, a NZ$307m asset sale just completed, and a 65% controlling shareholder that recapitalised it in 2024, so a pure asset/creditor waterfall would be wrong; equally a plain three-growth-scenario DCF would ignore the live going-concern qualification. The chosen hybrid keeps the house engine (so the dashboard reproduces every scenario) and puts the distress in the bear path and its 40% weight. Read owner-fcf.md in full including section 7.
A9: Methodology: revenue base | B9: REVENUE BASE: TTM continuing-operations revenue to 31-Jan-2026 = FY2025 continuing 1,590.2 (1,827.4 group less 237.3 North Island discontinued) + H1 FY2026 777.6 - H1 FY2025 779.0 = NZ$1,588.7m. The North Island (Pokeno + Auckland) business is EXCLUDED from every forward year because it was sold to Abbott on 1-Apr-2026; it contributed NZ$237m FY2025 revenue and a NZ$23.1m after-tax loss (NZ$8.8m in H1 FY2026), so its removal is earnings-accretive and revenue-dilutive. Y1 = FY2027 (year ending 31-Jul-2027). FY2026 (guided NZ$19-24m underlying loss, results due late Sept-2026) is treated as the FY0 stub and is NOT projected as profitable.
A10: Methodology: leases | B10: LEASE TREATMENT: (B) leases as operating cost. IFRS-16 lease principal (FY2025 NZ$6.0m, TTM NZ$6.2m, ~0.4% of revenue) is charged inside the flows as lease_cost_pct = 0.4 and DEDUCTED from historical owner FCF; lease liabilities (NZ$53.1m at 31-Jan-2026: 6.5 current + 46.6 non-current) are EXCLUDED from net_debt. Nothing is charged twice. The CSV TotalDebt column (557.6) INCLUDES leases; inputs.total_debt here (504.4) does not.
A11: Methodology: SBC | B11: SBC: immaterial and SBC-zero in practice (FY2025 -NZ$0.5m on forfeitures, H1 FY2026 nil, historical max NZ$0.7m = 0.05% of revenue). Kept explicit at 0% in all scenarios; house and street bases coincide, band_position is null.
A12: Methodology: tax | B12: TAX: NZ$330m gross NZ tax losses at 31-Jul-2025 plus FY2026 losses (~NZ$420m+ per the Analysis JSON); the DTA on losses was derecognised at H1 FY2026 (DTA 9.6m -> nil, DTL 1.9m). Cash tax modelled at 0% until cumulative EBIT approaches the pool, then ramped to the 28% statutory rate (base: 14% FY2033, 28% from FY2034; bull from FY2031; bear never). Shareholder-continuity (49%) is preserved by Bright's stable control.
... A19: Verification | B19: Recalculated headless in LibreOffice with zero formula errors; Valuation!B8 (weighted IV) ties to probability_weighted.weighted_iv in the JSON within rounding.

Sheet Actuals
A1: Reported history, NZ$ millions (EPS/prices per share). Source: SML.NZ_Metrics.csv (from annual/interim reports, financial-parser agent), lease principal and interest income from cash-flow statements / finance-income notes; FY-end prices Yahoo monthly close.
A3: Line | B3: FY2016 | C3: FY2017 | D3: FY2018 | E3: FY2019 | F3: FY2020 | G3: FY2021 | H3: FY2022 | I3: FY2023 | J3: FY2024 | K3: FY2025 | L3: H1 FY2025 | M3: H1 FY2026
A4: Revenue | B4: 546.866 | C4: 758.994 | D4: 879.001 | E4: 1024.305 | F4: 1302.025 | G4: 1367.349 | H4: 1660.601 | I4: 1320.758 | J4: 1636.858 | K4: 1827.415 | L4: 916.767 | M4: 777.581
A5: EBITDA (reported) | D5: 138.641 | E5: 152.147 | F5: 166.403 | G5: 32.571 | H5: 112.627 | I5: 68.759 | J5: -126.827 | K5: 44.241 | L5: 59.759 | M5: -31.457
A6: Net income | B6: 34.383 | C6: 38.223 | D6: 74.553 | E6: 82.239 | F6: 75.208 | G6: -28.451 | H6: 38.523 | I6: -4.292 | J6: -182.111 | K6: -39.822 | L6: 4.808 | M6: -80.628
A7: Operating cash flow | B7: 103.903 | C7: 115.175 | D7: 98.39 | E7: 136.698 | F7: 105.54 | G7: 15.868 | H7: 232.92 | I7: 39.037 | J7: -47.191 | K7: 165.522 | L7: -12.038 | M7: -183.371
A8: Capex | B8: -41.038 | C8: -33.283 | D8: -120.289 | E8: -320.441 | F8: -152.474 | G8: -140.368 | H8: -92.908 | I8: -64.895 | J8: -30.902 | K8: -23.663 | L8: -13.083 | M8: -16.392
A9: Free cash flow (reported) | B9: 62.865 | C9: 81.892 | D9: -21.899 | E9: -183.743 | F9: -46.934 | G9: -124.5 | H9: 140.012 | I9: -25.858 | J9: -78.093 | K9: 141.859 | L9: -25.121 | M9: -199.763
A10: SBC | B10: 0.364 | C10: 0.364 | D10: 0.588 | E10: 0.644 | F10: 0.523 | G10: -0.61 | H10: 0.115 | I10: 0.115 | J10: 0.399 | K10: -0.536 | L10: 0.198 | M10: 0
A11: Interest income | B11: 0.018 | C11: 0.018 | D11: 1.023 | E11: 1.232 | F11: 0.134 | G11: 0.044 | H11: 0.17 | I11: 0.281 | J11: 0.585 | K11: 0.842 | L11: 0.484 | M11: 0.198
A12: Lease principal repaid | B12: 0 | C12: 0 | D12: 0 | E12: 0 | F12: 4.185 | G12: 4.499 | H12: 4.079 | I12: 4.4 | J12: 5.916 | K12: 6.012 | L12: 3.111 | M12: 3.255
A13: Shareholders equity | B13: 256.843 | C13: 393.084 | D13: 424.745 | E13: 492.359 | F13: 606.484 | G13: 767.114 | H13: 748.396 | I13: 790.374 | J13: 604.798 | K13: 788.786 | L13: 796.658 | M13: 717.564
A14: Total debt (CSV, incl leases) | B14: 215.454 | C14: 156.085 | D14: 146.386 | E14: 349.108 | F14: 548.851 | G14: 507.935 | H14: 383.528 | I14: 469.618 | J14: 615.035 | K14: 384.072 | L14: 491.958 | M14: 557.553
A15: Cash | B15: 2.045 | C15: 73.827 | D15: 32.129 | E15: 16.007 | F15: 5.887 | G15: 16.02 | H15: 14.493 | I15: 9.29 | J15: 10.273 | K15: 78.277 | L15: 49.041 | M15: 32.305
A16: Shares on issue (m) | B16: 146.341 | C16: 179.223 | D16: 179.223 | E16: 179.223 | F16: 179.307 | G16: 218.582 | H16: 218.582 | I16: 218.582 | J16: 218.582 | K16: 603.198 | L16: 603.198 | M16: 603.198
A17: FY-end price (31-Jul, NZ$) | B17: 3.614 | C17: 4.78 | D17: 12.8 | E17: 9.35 | F17: 6.36 | G17: 3.3 | H17: 3.48 | I17: 1.3 | J17: 0.4 | K17: 0.77
A19: Balance-sheet snapshot 31-Jan-2026 (H1 FY2026, KPMG-reviewed, material uncertainty re going concern): loans & borrowings 504.438 (RCF 273.0, term 72.0, NZD/CNH 29.4, Bright Dairy shareholder loan 130.0; ALL current), cash 32.305, lease liabilities 53.115, assets held for sale (North Island) 296.053, equity 717.564.
A20: Net debt bridge (company definition, ex leases): 472.1 at 31-Jan-2026 -> less 283.1 Abbott proceeds received 1-Apr-2026 = 189.0 pro-forma (seasonal WC peak) -> less ~90 seasonal WC unwind + ~26 H2 cash burn = ~125.0 estimated 31-Jul-2026. Holdback ~14 not credited.
A21: Seasonal working capital (inventories + receivables - payables): 31-Jan-2026 129.9 (ex HFS); FY-ends: FY2022 0.9, FY2023 52.2, FY2024 96.7, FY2025 -1.9.
A22: Continuing-ops revenue: FY2025 1,590.2 (group 1,827.4 less North Island 237.3); H1 FY2026 777.6; H1 FY2025 779.0 -> TTM 1,588.7 (FY0 base on Assumptions!B8).
A23: Segments H1 FY2026 (continuing): Synlait SI revenue 557.5 / EBITDA -45.2 (incl 33.2 tactical raw-milk losses); Dairyworks revenue 220.1 / EBITDA 13.2. FY2025 Dairyworks NPAT 10.3, EBITDA ~23.5 on revenue 324.2.
A24: Guidance 14-Aug-2026: FY2026 underlying net loss after tax NZ$19m-24m. FY26 milk price ~NZ$9.90/kgMS. Formal EBITDA/revenue guidance withdrawn.
A25: Share history: 218,581,661 pre-recap -> 603,198,098 after the 1-Oct-2024 placement (Bright Dairy at NZ$0.60, a2 Milk at NZ$0.43; NZ$212.1m net). Buybacks: none. Ownership Bright Dairy 65.25%, a2 Milk 19.83%.

Sheet Assumptions
A1: Global inputs (blue = hardcoded). Scenario drivers below; narratives at the bottom.
A3: Current price (NZ$) | B3: 0.395 | F3: 2026-09-02T05:00:13Z (NZX regular close 17:00 NZST; Yahoo regularMarketPrice)
A4: Price timestamp | B4: 2026-09-02T05:00:13Z (NZX regular close 17:00 NZST; Yahoo regularMarketPrice) | F4: Yahoo regularMarketTime; NZX regular close
A5: Diluted shares (m) | B5: 603.1981 | F5: 603,198,098 ordinary shares on issue at 31-Jan-2026 (H1 FY2026 note 12), unchanged since the 1-Oct-2024 recapitalisation placement; PSRs immaterial and anti-dilutive. Held FLAT (no SBC to expense, no raise assumed in the flows).
A6: Net debt (NZ$m, ex leases) | B6: 125 | F6: ESTIMATED 31-Jul-2026 pro-forma: 472.1 (31-Jan-2026 reported, ex leases) - 283.1 (Abbott proceeds 1-Apr-2026) - 90.0 (seasonal WC unwind to FY-end norm) + 26.0 (H2 FY26 cash burn) = 125.0. Refresh at the FY2026 result (late Sept-2026).
A7: Balance sheet date | B7: 2026-01-31 (H1 FY2026 interim, reviewed by KPMG with a material-uncertainty-related-to-going-concern paragraph); net debt adjusted for the 1-Apr-2026 North Island sale completion and estimated forward to 31-Jul-2026 | F7: Latest reviewed accounts
A8: FY0 revenue base (NZ$m) | B8: 1588.7 | F8: TTM continuing operations to 31-Jan-2026 (ex North Island)
A9: Discount rate / WACC (%) | B9: 16 | F9: Single rate for all scenarios; see wacc_rationale in the JSON and Model_Info
A10: Hurdle rate for entry price | B10: 0.15 | F10: 15% IRR; TV rebuilt at the hurdle
A11: Lease liabilities excluded (memo) | B11: 53.1 | F11: Treatment B: lease cost charged in flows (row 11 / memo row 25), liabilities excluded from net debt
A12: Horizon (years) | B12: 10 | F12: 10 years: margins still ramping at year 5
A15: Scenario parameters | C15: Bear | D15: Base | E15: Bull
A16: Terminal growth (%) | C16: 0.5 | D16: 1.5 | E16: 2
A17: Terminal cap (x owner FCF) | C17: 8 | D17: 10 | E17: 12
A18: D&A (% revenue) | C18: 2.8 | D18: 2.7 | E18: 2.7
A19: Capex (% revenue) | C19: 1.5 | D19: 1.8 | E19: 2
A20: Lease cost (% revenue) | C20: 0.4 | D20: 0.4 | E20: 0.4
A21: WC capture (% of revenue change) | C21: -3 | D21: -3 | E21: -3
A22: Probability weight | C22: 0.4 | D22: 0.45 | E22: 0.15 | F22: Bear 40% (house default 15%): KPMG's material-uncertainty-related-to-going-concern paragraph is live on the latest reviewed accounts; all core facilities (30-Jun-2026) and the NZ$130m Bright Dairy loan (12-Jul-2026) have matured with Bright's support only 'preliminarily indicated' at the last filing and no refinancing announcement in the corpus; FY2026 is a third consecutive underlying loss (guided -NZ$19m to -24m on 14-Aug-2026); the CEO resigned after 11 months and the Chief Quality Officer has left; and a2 Milk is building alternative capacity. Base 45%: the Abbott sale did complete and did halve bank facilities, Dairyworks and Foodservice are growing and profitable, and the controlling shareholder has funded two rescues -- muddle-through is the modal outcome. Bull 15% (house default 35%): requires Dairyworks, Foodservice, non-a2 nutrition wins AND a normal-terms refinancing AND a stable leadership team to all land within the horizon.
A23: Weights sum (must be 1.00) | C23: =SUM(C22:E22)
A26: Scenario narratives
A27: Bear | B27: Bear -- the going-concern path fails to stabilise and the equity is impaired. The a2 Milk Company shifts China-label and base-powder volumes to Mataura Valley Milk and its ex-Yashili Pokeno plant as minimum-volume obligations under the NPMSA step down, taking Advanced Nutrition -- historically the only high-margin product line -- with it; Ingredients stays a milk-absorption release valve with ~nil gross margin in a weak WMP market; Dairyworks and Foodservice grow but are too small (~31% and ~4% of revenue) to carry a NZ$600m single-site asset base. Revenue shrinks 8%/5%/3%/1% over FY27-FY30 and flat-lines near NZ$1.33bn; group EBITDA margin never exceeds 3.0% (vs FY2025 underlying 5.9%); D&A (2.8%) exceeds a starved 1.5% capex, so FCF is positive only because the plant is being run down. Cash tax is nil throughout (the NZ$420m+ of tax losses are never used). Terminal growth 0.5%, terminal cap 8x owner FCF. Enterprise value (~NZ$71m) does not cover the ~NZ$125m of pro-forma net debt: the equity is under water on this path, and the refinancing that the H1 FY2026 going-concern note depends on resolves by a Bright Dairy-led recapitalisation that leaves minorities with a small slice of a small equity (see rescue_raise_memo). This is the scenario KPMG's material-uncertainty paragraph describes.
A28: Base | B28: Base -- muddle-through, refinanced by the controlling shareholder. Bright Dairy rolls the NZ$130m shareholder loan and the syndicate refinances the halved (~NZ$200m) bank facilities on the strength of the Abbott proceeds; there is no further equity raise. The South-Island-only business (Dunsandel + Dairyworks) returns to a modest profit in FY2027 as the FY25-HY26 'manufacturing plan adjustment' one-offs (NZ$33m tactical raw-milk losses, NZ$43.5m manufacturing costs) wash out, but the structural picture is post-exclusivity: a2 Milk remains the anchor Advanced Nutrition customer at minimum volumes only, so the FY2018-FY2020 12-16% EBITDA margins do not return. Revenue dips 2% in FY2027 (Ingredients volume down, lower FY27 milk price) then grows 2-2.5%/yr on Dairyworks export growth, Foodservice UHT cream and incremental non-a2 nutrition customers; EBITDA margin ramps 3.5% -> 6.5% by FY2032 (FY2025 underlying 5.9%; FY2022 reported 6.8%) and holds. Capex 1.8% vs D&A 2.7% (maintenance on a NZ$600m PP&E base with no growth projects). Cash tax nil through FY2032 as the NZ$420m+ tax-loss pool is consumed, ramping to 28% by FY2034. Terminal growth 1.5%, cap 10x owner FCF; Gordon binds. Leadership: a permanent CEO is appointed and the Stabilise/Simplify horizons deliver, Scale does not.
A29: Bull | B29: Bull -- the reset works and Synlait becomes a diversified, profitable South Island processor. Dairyworks keeps compounding (HY26 revenue +51%, GP +22%) on Australian, SE Asian and US private-label/branded wins plus the Bright Dairy China retail channel; Foodservice UHT cream doubles in FY2027 as management targets and stays profitable; Advanced Nutrition diversifies beyond a2 Milk (white-label supplements, Middle East ELN customer, Nutrabase base powder, Abbott base-powder access, a2's FDA US infant-formula approval adding a new line). Revenue grows 0/4/5/5/4/3.5% then ~2.5-3%; EBITDA margin ramps 4.5% -> 8.5% (still well below the FY2018-2020 a2-exclusivity peak of 12.8-15.8%, above the FY2022 6.8%). Capex 2.0% funds modest growth projects. Tax losses are consumed faster (cash tax 10% by FY2031, 28% from FY2033). Terminal growth 2.0%, cap 12x. Net debt is refinanced on normal terms and the going-concern qualification is lifted at FY2027. The bull case also captures the strategic-value angle behind the (denied) a2 Milk/Fonterra takeover speculation: a clean, SAMR-registered Dunsandel plant with secured Canterbury milk is worth more to a strategic owner than to minority holders of a distressed equity.
A31: Valuation philosophy | B31: SML.NZ is a going-concern-qualified, controlled (85% held by two strategic shareholders) NZ dairy processor 18 months into a second recovery attempt, trading at NZ$0.395 (market cap ~NZ$238m) against ~NZ$690m of book equity and ~NZ$1.59bn of continuing revenue. The standard owner-FCF DCF cannot be applied naively: (1) the historical FCF series is unusable -- the 10-year median owner FCF is NEGATIVE (-NZ$27m) and the two positive peaks (FY2022, FY2025, +NZ$136m each) were working-capital releases, so every scenario is a component build (revenue x margin path -> lease -> D&A -> cash tax -> capex -> WC) from the TTM continuing-operations revenue base, never an FCF extrapolation; (2) the balance sheet in the CSV (31-Jan-2026) predates the completed 1-Apr-2026 Abbott sale and sits at the seasonal working-capital peak, so net debt is a documented pro-forma estimate (NZ$125m) with a sensitivity showing the NZ$189m peak and NZ$85m trough alternatives; (3) the bear case is a genuine equity-impairment path, not a low multiple -- enterprise value fails to cover net debt and the equity is under water, resolved in practice by a controlling-shareholder recapitalisation; (4) scenario weights are 40/45/15 -- the bear is weighted at nearly the base case because the auditor's material-uncertainty paragraph is live, the refinancing outcome is unknown at build, FY2026 is a third consecutive underlying loss, and the CEO seat is empty; the bull is 15% because it needs Dairyworks, Foodservice, non-a2 nutrition AND a normal refinancing to all land. The result -- weighted IV NZ$0.22 vs NZ$0.395 -- says the market is paying for something the DCF does not: the option value of the controlling shareholder's strategic interest (Bright paid NZ$0.60 in Sept-2024, 50% above the then market) and consolidation speculation. That gap is the finding, not an error: a minority holder receives the DCF value only if Bright Dairy and a2 Milk let them, and the model does not assume they will. A negative or near-zero intrinsic value on the bear path is the honest outcome and has not been floored away; a floored-at-zero weighted IV is shown as a memo.

Sheet DCF_Bear
A1: SML.NZ -- BEAR scenario, NZ$ millions. Drivers (yellow): rows 5, 7, 9, 14. Everything else is formula.
A3: Fiscal year (31 July) | B3: FY2026E/TTM | C3: FY2027E | D3: FY2028E | E3: FY2029E | F3: FY2030E | G3: FY2031E | H3: FY2032E | I3: FY2033E | J3: FY2034E | K3: FY2035E | L3: FY2036E
A4: Year index | B4: 0 | C4: 1 | D4: 2 | E4: 3 | F4: 4 | G4: 5 | H4: 6 | I4: 7 | J4: 8 | K4: 9 | L4: 10
A5: Revenue growth YoY (%) | C5: -8 | D5: -5 | E5: -3 | F5: -1 | G5: 0 | H5: 0 | I5: 0.5 | J5: 0.5 | K5: 0.5 | L5: 0.5
A6: Revenue | B6: =Assumptions!$B$8 | C6: =B6*(1+C5/100) | D6: =C6*(1+D5/100) | E6: =D6*(1+E5/100) | F6: =E6*(1+F5/100) | G6: =F6*(1+G5/100) | H6: =G6*(1+H5/100) | I6: =H6*(1+I5/100) | J6: =I6*(1+J5/100) | ... L6: =K6*(1+L5/100)
A7: Adj EBITDA margin (%) | C7: 1.5 | D7: 2 | E7: 2.3 | F7: 2.5 | G7: 2.7 | H7: 2.8 | I7: 3 | J7: 3 | K7: 3 | L7: 3
A8: Adjusted EBITDA | C8: =C6*C7/100 | D8: =D6*D7/100 | E8: =E6*E7/100 | F8: =F6*F7/100 | G8: =G6*G7/100 | H8: =H6*H7/100 | I8: =I6*I7/100 | J8: =J6*J7/100 | ... L8: =L6*L7/100
A9: SBC (% revenue) | C9: 0 | D9: 0 | E9: 0 | F9: 0 | G9: 0 | H9: 0 | I9: 0 | J9: 0 | K9: 0 | L9: 0
A10: SBC (negative) | C10: =-C6*C9/100 | D10: =-D6*D9/100 | E10: =-E6*E9/100 | F10: =-F6*F9/100 | G10: =-G6*G9/100 | H10: =-H6*H9/100 | I10: =-I6*I9/100 | J10: =-J6*J9/100 | ... L10: =-L6*L9/100
A11: Owner EBITDA (after SBC and lease cost) | C11: =C8+C10-C6*Assumptions!$C$20/100 | D11: =D8+D10-D6*Assumptions!$C$20/100 | E11: =E8+E10-E6*Assumptions!$C$20/100 | F11: =F8+F10-F6*Assumptions!$C$20/100 | G11: =G8+G10-G6*Assumptions!$C$20/100 | H11: =H8+H10-H6*Assumptions!$C$20/100 | I11: =I8+I10-I6*Assumptions!$C$20/100 | J11: =J8+J10-J6*Assumptions!$C$20/100 | ... L11: =L8+L10-L6*Assumptions!$C$20/100
A12: D&A (negative) | C12: =-C6*Assumptions!$C$18/100 | D12: =-D6*Assumptions!$C$18/100 | E12: =-E6*Assumptions!$C$18/100 | F12: =-F6*Assumptions!$C$18/100 | G12: =-G6*Assumptions!$C$18/100 | H12: =-H6*Assumptions!$C$18/100 | I12: =-I6*Assumptions!$C$18/100 | J12: =-J6*Assumptions!$C$18/100 | ... L12: =-L6*Assumptions!$C$18/100
A13: EBIT (SBC and lease expensed) | C13: =C11+C12 | D13: =D11+D12 | E13: =E11+E12 | F13: =F11+F12 | G13: =G11+G12 | H13: =H11+H12 | I13: =I11+I12 | J13: =J11+J12 | ... L13: =L11+L12
A14: Cash tax rate (%) -- on positive EBIT only | C14: 0 | D14: 0 | E14: 0 | F14: 0 | G14: 0 | H14: 0 | I14: 0 | J14: 0 | K14: 0 | L14: 0
A15: NOPAT | C15: =C13-MAX(0,C13)*C14/100 | D15: =D13-MAX(0,D13)*D14/100 | E15: =E13-MAX(0,E13)*E14/100 | F15: =F13-MAX(0,F13)*F14/100 | G15: =G13-MAX(0,G13)*G14/100 | H15: =H13-MAX(0,H13)*H14/100 | I15: =I13-MAX(0,I13)*I14/100 | J15: =J13-MAX(0,J13)*J14/100 | ... L15: =L13-MAX(0,L13)*L14/100
A16: add back D&A | C16: =-C12 | D16: =-D12 | E16: =-E12 | F16: =-F12 | G16: =-G12 | H16: =-H12 | I16: =-I12 | J16: =-J12 | ... L16: =-L12
A17: less capex | C17: =-C6*Assumptions!$C$19/100 | D17: =-D6*Assumptions!$C$19/100 | E17: =-E6*Assumptions!$C$19/100 | F17: =-F6*Assumptions!$C$19/100 | G17: =-G6*Assumptions!$C$19/100 | H17: =-H6*Assumptions!$C$19/100 | I17: =-I6*Assumptions!$C$19/100 | J17: =-J6*Assumptions!$C$19/100 | ... L17: =-L6*Assumptions!$C$19/100
A18: add working capital (capture x revenue change) | C18: =Assumptions!$C$21/100*(C6-B6) | D18: =Assumptions!$C$21/100*(D6-C6) | E18: =Assumptions!$C$21/100*(E6-D6) | F18: =Assumptions!$C$21/100*(F6-E6) | G18: =Assumptions!$C$21/100*(G6-F6) | H18: =Assumptions!$C$21/100*(H6-G6) | I18: =Assumptions!$C$21/100*(I6-H6) | J18: =Assumptions!$C$21/100*(J6-I6) | ... L18: =Assumptions!$C$21/100*(L6-K6)
A19: Unlevered owner FCF | C19: =C15+C16+C17+C18 | D19: =D15+D16+D17+D18 | E19: =E15+E16+E17+E18 | F19: =F15+F16+F17+F18 | G19: =G15+G16+G17+G18 | H19: =H15+H16+H17+H18 | I19: =I15+I16+I17+I18 | J19: =J15+J16+J17+J18 | ... L19: =L15+L16+L17+L18
A20: Discount factor | C20: =1/(1+Assumptions!$B$9/100)^C4 | D20: =1/(1+Assumptions!$B$9/100)^D4 | E20: =1/(1+Assumptions!$B$9/100)^E4 | F20: =1/(1+Assumptions!$B$9/100)^F4 | G20: =1/(1+Assumptions!$B$9/100)^G4 | H20: =1/(1+Assumptions!$B$9/100)^H4 | I20: =1/(1+Assumptions!$B$9/100)^I4 | J20: =1/(1+Assumptions!$B$9/100)^J4 | ... L20: =1/(1+Assumptions!$B$9/100)^L4
A21: PV of FCF | C21: =C19*C20 | D21: =D19*D20 | E21: =E19*E20 | F21: =F19*F20 | G21: =G19*G20 | H21: =H19*H20 | I21: =I19*I20 | J21: =J19*J20 | ... L21: =L19*L20
A23: Memo: FCF before SBC (company-style) | C23: =C19-C10 | D23: =D19-D10 | E23: =E19-E10 | F23: =F19-F10 | G23: =G19-G10 | H23: =H19-H10 | I23: =I19-I10 | J23: =J19-J10 | ... L23: =L19-L10
A24: Memo: owner-FCF margin | C24: =C19/C6 | D24: =D19/D6 | E24: =E19/E6 | F24: =F19/F6 | G24: =G19/G6 | H24: =H19/H6 | I24: =I19/I6 | J24: =J19/J6 | ... L24: =L19/L6
A25: Memo: lease cost charged (negative) | C25: =-C6*Assumptions!$C$20/100 | D25: =-D6*Assumptions!$C$20/100 | E25: =-E6*Assumptions!$C$20/100 | F25: =-F6*Assumptions!$C$20/100 | G25: =-G6*Assumptions!$C$20/100 | H25: =-H6*Assumptions!$C$20/100 | I25: =-I6*Assumptions!$C$20/100 | J25: =-J6*Assumptions!$C$20/100 | ... L25: =-L6*Assumptions!$C$20/100
A26: Sum of PV of FCF | B26: =SUM(C21:L21)
A27: Terminal growth (%) | B27: =Assumptions!$C$16
A28: Terminal-year FCF x (1+g) | B28: =L19*(1+B27/100)
A29: Gordon terminal value | B29: =IF(Assumptions!$B$9>B27,B28/((Assumptions!$B$9-B27)/100),0)
A30: Cap terminal value (cap x FCF_10) | B30: =Assumptions!$C$17*L19
A31: Terminal value used = MAX(0,MIN(Gordon,cap)) | B31: =MAX(0,MIN(B29,B30))
A32: Implied exit multiple (TV / FCF_10) | B32: =IF(L19<>0,B31/L19,"n/a")
A33: PV of terminal value | B33: =B31*L20
A34: Enterprise value | B34: =B26+B33
A35: less net debt (add net cash) | B35: =-Assumptions!$B$6
A36: Equity value | B36: =B34+B35
A37: Diluted shares (m) | B37: =Assumptions!$B$5
A38: VALUE PER SHARE (NZ$) | B38: =B36/B37
A39: Upside vs price | B39: =B38/Assumptions!$B$3-1
A41: Street memo: PV of explicit-period SBC | B41: =SUMPRODUCT(-C10:L10/(1+Assumptions!$B$9/100)^C4:L4)
A42: Street memo: PV of terminal SBC | B42: =IF(Assumptions!$B$9>B27,(-L10*(1+B27/100)/((Assumptions!$B$9-B27)/100))*L20,0)
A43: Street value per share (SBC as non-cash) | B43: =(B36+B41+B42)/B37
...

Sheet DCF_Base
A1: SML.NZ -- BASE scenario, NZ$ millions. Drivers (yellow): rows 5, 7, 9, 14. Everything else is formula.
A3: Fiscal year (31 July) | B3: FY2026E/TTM | C3: FY2027E | D3: FY2028E | E3: FY2029E | F3: FY2030E | G3: FY2031E | H3: FY2032E | I3: FY2033E | J3: FY2034E | K3: FY2035E | L3: FY2036E
A4: Year index | B4: 0 | C4: 1 | D4: 2 | E4: 3 | F4: 4 | G4: 5 | H4: 6 | I4: 7 | J4: 8 | K4: 9 | L4: 10
A5: Revenue growth YoY (%) | C5: -2 | D5: 2 | E5: 2.5 | F5: 2.5 | G5: 2 | H5: 2 | I5: 2 | J5: 2 | K5: 2 | L5: 2
A6: Revenue | B6: =Assumptions!$B$8 | C6: =B6*(1+C5/100) | D6: =C6*(1+D5/100) | E6: =D6*(1+E5/100) | F6: =E6*(1+F5/100) | G6: =F6*(1+G5/100) | H6: =G6*(1+H5/100) | I6: =H6*(1+I5/100) | J6: =I6*(1+J5/100) | ... L6: =K6*(1+L5/100)
A7: Adj EBITDA margin (%) | C7: 3.5 | D7: 4.5 | E7: 5.3 | F7: 5.8 | G7: 6.2 | H7: 6.5 | I7: 6.5 | J7: 6.5 | K7: 6.5 | L7: 6.5
A8: Adjusted EBITDA | C8: =C6*C7/100 | D8: =D6*D7/100 | E8: =E6*E7/100 | F8: =F6*F7/100 | G8: =G6*G7/100 | H8: =H6*H7/100 | I8: =I6*I7/100 | J8: =J6*J7/100 | ... L8: =L6*L7/100
A9: SBC (% revenue) | C9: 0 | D9: 0 | E9: 0 | F9: 0 | G9: 0 | H9: 0 | I9: 0 | J9: 0 | K9: 0 | L9: 0
A10: SBC (negative) | C10: =-C6*C9/100 | D10: =-D6*D9/100 | E10: =-E6*E9/100 | F10: =-F6*F9/100 | G10: =-G6*G9/100 | H10: =-H6*H9/100 | I10: =-I6*I9/100 | J10: =-J6*J9/100 | ... L10: =-L6*L9/100
A11: Owner EBITDA (after SBC and lease cost) | C11: =C8+C10-C6*Assumptions!$D$20/100 | D11: =D8+D10-D6*Assumptions!$D$20/100 | E11: =E8+E10-E6*Assumptions!$D$20/100 | F11: =F8+F10-F6*Assumptions!$D$20/100 | G11: =G8+G10-G6*Assumptions!$D$20/100 | H11: =H8+H10-H6*Assumptions!$D$20/100 | I11: =I8+I10-I6*Assumptions!$D$20/100 | J11: =J8+J10-J6*Assumptions!$D$20/100 | ... L11: =L8+L10-L6*Assumptions!$D$20/100
A12: D&A (negative) | C12: =-C6*Assumptions!$D$18/100 | D12: =-D6*Assumptions!$D$18/100 | E12: =-E6*Assumptions!$D$18/100 | F12: =-F6*Assumptions!$D$18/100 | G12: =-G6*Assumptions!$D$18/100 | H12: =-H6*Assumptions!$D$18/100 | I12: =-I6*Assumptions!$D$18/100 | J12: =-J6*Assumptions!$D$18/100 | ... L12: =-L6*Assumptions!$D$18/100
A13: EBIT (SBC and lease expensed) | C13: =C11+C12 | D13: =D11+D12 | E13: =E11+E12 | F13: =F11+F12 | G13: =G11+G12 | H13: =H11+H12 | I13: =I11+I12 | J13: =J11+J12 | ... L13: =L11+L12
A14: Cash tax rate (%) -- on positive EBIT only | C14: 0 | D14: 0 | E14: 0 | F14: 0 | G14: 0 | H14: 0 | I14: 14 | J14: 28 | K14: 28 | L14: 28
A15: NOPAT | C15: =C13-MAX(0,C13)*C14/100 | D15: =D13-MAX(0,D13)*D14/100 | E15: =E13-MAX(0,E13)*E14/100 | F15: =F13-MAX(0,F13)*F14/100 | G15: =G13-MAX(0,G13)*G14/100 | H15: =H13-MAX(0,H13)*H14/100 | I15: =I13-MAX(0,I13)*I14/100 | J15: =J13-MAX(0,J13)*J14/100 | ... L15: =L13-MAX(0,L13)*L14/100
A16: add back D&A | C16: =-C12 | D16: =-D12 | E16: =-E12 | F16: =-F12 | G16: =-G12 | H16: =-H12 | I16: =-I12 | J16: =-J12 | ... L16: =-L12
A17: less capex | C17: =-C6*Assumptions!$D$19/100 | D17: =-D6*Assumptions!$D$19/100 | E17: =-E6*Assumptions!$D$19/100 | F17: =-F6*Assumptions!$D$19/100 | G17: =-G6*Assumptions!$D$19/100 | H17: =-H6*Assumptions!$D$19/100 | I17: =-I6*Assumptions!$D$19/100 | J17: =-J6*Assumptions!$D$19/100 | ... L17: =-L6*Assumptions!$D$19/100
A18: add working capital (capture x revenue change) | C18: =Assumptions!$D$21/100*(C6-B6) | D18: =Assumptions!$D$21/100*(D6-C6) | E18: =Assumptions!$D$21/100*(E6-D6) | F18: =Assumptions!$D$21/100*(F6-E6) | G18: =Assumptions!$D$21/100*(G6-F6) | H18: =Assumptions!$D$21/100*(H6-G6) | I18: =Assumptions!$D$21/100*(I6-H6) | J18: =Assumptions!$D$21/100*(J6-I6) | ... L18: =Assumptions!$D$21/100*(L6-K6)
A19: Unlevered owner FCF | C19: =C15+C16+C17+C18 | D19: =D15+D16+D17+D18 | E19: =E15+E16+E17+E18 | F19: =F15+F16+F17+F18 | G19: =G15+G16+G17+G18 | H19: =H15+H16+H17+H18 | I19: =I15+I16+I17+I18 | J19: =J15+J16+J17+J18 | ... L19: =L15+L16+L17+L18
A20: Discount factor | C20: =1/(1+Assumptions!$B$9/100)^C4 | D20: =1/(1+Assumptions!$B$9/100)^D4 | E20: =1/(1+Assumptions!$B$9/100)^E4 | F20: =1/(1+Assumptions!$B$9/100)^F4 | G20: =1/(1+Assumptions!$B$9/100)^G4 | H20: =1/(1+Assumptions!$B$9/100)^H4 | I20: =1/(1+Assumptions!$B$9/100)^I4 | J20: =1/(1+Assumptions!$B$9/100)^J4 | ... L20: =1/(1+Assumptions!$B$9/100)^L4
A21: PV of FCF | C21: =C19*C20 | D21: =D19*D20 | E21: =E19*E20 | F21: =F19*F20 | G21: =G19*G20 | H21: =H19*H20 | I21: =I19*I20 | J21: =J19*J20 | ... L21: =L19*L20
A23: Memo: FCF before SBC (company-style) | C23: =C19-C10 | D23: =D19-D10 | E23: =E19-E10 | F23: =F19-F10 | G23: =G19-G10 | H23: =H19-H10 | I23: =I19-I10 | J23: =J19-J10 | ... L23: =L19-L10
A24: Memo: owner-FCF margin | C24: =C19/C6 | D24: =D19/D6 | E24: =E19/E6 | F24: =F19/F6 | G24: =G19/G6 | H24: =H19/H6 | I24: =I19/I6 | J24: =J19/J6 | ... L24: =L19/L6
A25: Memo: lease cost charged (negative) | C25: =-C6*Assumptions!$D$20/100 | D25: =-D6*Assumptions!$D$20/100 | E25: =-E6*Assumptions!$D$20/100 | F25: =-F6*Assumptions!$D$20/100 | G25: =-G6*Assumptions!$D$20/100 | H25: =-H6*Assumptions!$D$20/100 | I25: =-I6*Assumptions!$D$20/100 | J25: =-J6*Assumptions!$D$20/100 | ... L25: =-L6*Assumptions!$D$20/100
A26: Sum of PV of FCF | B26: =SUM(C21:L21)
A27: Terminal growth (%) | B27: =Assumptions!$D$16
A28: Terminal-year FCF x (1+g) | B28: =L19*(1+B27/100)
A29: Gordon terminal value | B29: =IF(Assumptions!$B$9>B27,B28/((Assumptions!$B$9-B27)/100),0)
A30: Cap terminal value (cap x FCF_10) | B30: =Assumptions!$D$17*L19
A31: Terminal value used = MAX(0,MIN(Gordon,cap)) | B31: =MAX(0,MIN(B29,B30))
A32: Implied exit multiple (TV / FCF_10) | B32: =IF(L19<>0,B31/L19,"n/a")
A33: PV of terminal value | B33: =B31*L20
A34: Enterprise value | B34: =B26+B33
A35: less net debt (add net cash) | B35: =-Assumptions!$B$6
A36: Equity value | B36: =B34+B35
A37: Diluted shares (m) | B37: =Assumptions!$B$5
A38: VALUE PER SHARE (NZ$) | B38: =B36/B37
A39: Upside vs price | B39: =B38/Assumptions!$B$3-1
A41: Street memo: PV of explicit-period SBC | B41: =SUMPRODUCT(-C10:L10/(1+Assumptions!$B$9/100)^C4:L4)
A42: Street memo: PV of terminal SBC | B42: =IF(Assumptions!$B$9>B27,(-L10*(1+B27/100)/((Assumptions!$B$9-B27)/100))*L20,0)
A43: Street value per share (SBC as non-cash) | B43: =(B36+B41+B42)/B37
...

Sheet DCF_Bull
A1: SML.NZ -- BULL scenario, NZ$ millions. Drivers (yellow): rows 5, 7, 9, 14. Everything else is formula.
A3: Fiscal year (31 July) | B3: FY2026E/TTM | C3: FY2027E | D3: FY2028E | E3: FY2029E | F3: FY2030E | G3: FY2031E | H3: FY2032E | I3: FY2033E | J3: FY2034E | K3: FY2035E | L3: FY2036E
A4: Year index | B4: 0 | C4: 1 | D4: 2 | E4: 3 | F4: 4 | G4: 5 | H4: 6 | I4: 7 | J4: 8 | K4: 9 | L4: 10
A5: Revenue growth YoY (%) | C5: 0 | D5: 4 | E5: 5 | F5: 5 | G5: 4 | H5: 3.5 | I5: 3 | J5: 3 | K5: 2.5 | L5: 2.5
A6: Revenue | B6: =Assumptions!$B$8 | C6: =B6*(1+C5/100) | D6: =C6*(1+D5/100) | E6: =D6*(1+E5/100) | F6: =E6*(1+F5/100) | G6: =F6*(1+G5/100) | H6: =G6*(1+H5/100) | I6: =H6*(1+I5/100) | J6: =I6*(1+J5/100) | ... L6: =K6*(1+L5/100)
A7: Adj EBITDA margin (%) | C7: 4.5 | D7: 6 | E7: 7 | F7: 7.8 | G7: 8.3 | H7: 8.5 | I7: 8.5 | J7: 8.5 | K7: 8.5 | L7: 8.5
A8: Adjusted EBITDA | C8: =C6*C7/100 | D8: =D6*D7/100 | E8: =E6*E7/100 | F8: =F6*F7/100 | G8: =G6*G7/100 | H8: =H6*H7/100 | I8: =I6*I7/100 | J8: =J6*J7/100 | ... L8: =L6*L7/100
A9: SBC (% revenue) | C9: 0 | D9: 0 | E9: 0 | F9: 0 | G9: 0 | H9: 0 | I9: 0 | J9: 0 | K9: 0 | L9: 0
A10: SBC (negative) | C10: =-C6*C9/100 | D10: =-D6*D9/100 | E10: =-E6*E9/100 | F10: =-F6*F9/100 | G10: =-G6*G9/100 | H10: =-H6*H9/100 | I10: =-I6*I9/100 | J10: =-J6*J9/100 | ... L10: =-L6*L9/100
A11: Owner EBITDA (after SBC and lease cost) | C11: =C8+C10-C6*Assumptions!$E$20/100 | D11: =D8+D10-D6*Assumptions!$E$20/100 | E11: =E8+E10-E6*Assumptions!$E$20/100 | F11: =F8+F10-F6*Assumptions!$E$20/100 | G11: =G8+G10-G6*Assumptions!$E$20/100 | H11: =H8+H10-H6*Assumptions!$E$20/100 | I11: =I8+I10-I6*Assumptions!$E$20/100 | J11: =J8+J10-J6*Assumptions!$E$20/100 | ... L11: =L8+L10-L6*Assumptions!$E$20/100
A12: D&A (negative) | C12: =-C6*Assumptions!$E$18/100 | D12: =-D6*Assumptions!$E$18/100 | E12: =-E6*Assumptions!$E$18/100 | F12: =-F6*Assumptions!$E$18/100 | G12: =-G6*Assumptions!$E$18/100 | H12: =-H6*Assumptions!$E$18/100 | I12: =-I6*Assumptions!$E$18/100 | J12: =-J6*Assumptions!$E$18/100 | ... L12: =-L6*Assumptions!$E$18/100
A13: EBIT (SBC and lease expensed) | C13: =C11+C12 | D13: =D11+D12 | E13: =E11+E12 | F13: =F11+F12 | G13: =G11+G12 | H13: =H11+H12 | I13: =I11+I12 | J13: =J11+J12 | ... L13: =L11+L12
A14: Cash tax rate (%) -- on positive EBIT only | C14: 0 | D14: 0 | E14: 0 | F14: 0 | G14: 10 | H14: 20 | I14: 28 | J14: 28 | K14: 28 | L14: 28
A15: NOPAT | C15: =C13-MAX(0,C13)*C14/100 | D15: =D13-MAX(0,D13)*D14/100 | E15: =E13-MAX(0,E13)*E14/100 | F15: =F13-MAX(0,F13)*F14/100 | G15: =G13-MAX(0,G13)*G14/100 | H15: =H13-MAX(0,H13)*H14/100 | I15: =I13-MAX(0,I13)*I14/100 | J15: =J13-MAX(0,J13)*J14/100 | ... L15: =L13-MAX(0,L13)*L14/100
A16: add back D&A | C16: =-C12 | D16: =-D12 | E16: =-E12 | F16: =-F12 | G16: =-G12 | H16: =-H12 | I16: =-I12 | J16: =-J12 | ... L16: =-L12
A17: less capex | C17: =-C6*Assumptions!$E$19/100 | D17: =-D6*Assumptions!$E$19/100 | E17: =-E6*Assumptions!$E$19/100 | F17: =-F6*Assumptions!$E$19/100 | G17: =-G6*Assumptions!$E$19/100 | H17: =-H6*Assumptions!$E$19/100 | I17: =-I6*Assumptions!$E$19/100 | J17: =-J6*Assumptions!$E$19/100 | ... L17: =-L6*Assumptions!$E$19/100
A18: add working capital (capture x revenue change) | C18: =Assumptions!$E$21/100*(C6-B6) | D18: =Assumptions!$E$21/100*(D6-C6) | E18: =Assumptions!$E$21/100*(E6-D6) | F18: =Assumptions!$E$21/100*(F6-E6) | G18: =Assumptions!$E$21/100*(G6-F6) | H18: =Assumptions!$E$21/100*(H6-G6) | I18: =Assumptions!$E$21/100*(I6-H6) | J18: =Assumptions!$E$21/100*(J6-I6) | ... L18: =Assumptions!$E$21/100*(L6-K6)
A19: Unlevered owner FCF | C19: =C15+C16+C17+C18 | D19: =D15+D16+D17+D18 | E19: =E15+E16+E17+E18 | F19: =F15+F16+F17+F18 | G19: =G15+G16+G17+G18 | H19: =H15+H16+H17+H18 | I19: =I15+I16+I17+I18 | J19: =J15+J16+J17+J18 | ... L19: =L15+L16+L17+L18
A20: Discount factor | C20: =1/(1+Assumptions!$B$9/100)^C4 | D20: =1/(1+Assumptions!$B$9/100)^D4 | E20: =1/(1+Assumptions!$B$9/100)^E4 | F20: =1/(1+Assumptions!$B$9/100)^F4 | G20: =1/(1+Assumptions!$B$9/100)^G4 | H20: =1/(1+Assumptions!$B$9/100)^H4 | I20: =1/(1+Assumptions!$B$9/100)^I4 | J20: =1/(1+Assumptions!$B$9/100)^J4 | ... L20: =1/(1+Assumptions!$B$9/100)^L4
A21: PV of FCF | C21: =C19*C20 | D21: =D19*D20 | E21: =E19*E20 | F21: =F19*F20 | G21: =G19*G20 | H21: =H19*H20 | I21: =I19*I20 | J21: =J19*J20 | ... L21: =L19*L20
A23: Memo: FCF before SBC (company-style) | C23: =C19-C10 | D23: =D19-D10 | E23: =E19-E10 | F23: =F19-F10 | G23: =G19-G10 | H23: =H19-H10 | I23: =I19-I10 | J23: =J19-J10 | ... L23: =L19-L10
A24: Memo: owner-FCF margin | C24: =C19/C6 | D24: =D19/D6 | E24: =E19/E6 | F24: =F19/F6 | G24: =G19/G6 | H24: =H19/H6 | I24: =I19/I6 | J24: =J19/J6 | ... L24: =L19/L6
A25: Memo: lease cost charged (negative) | C25: =-C6*Assumptions!$E$20/100 | D25: =-D6*Assumptions!$E$20/100 | E25: =-E6*Assumptions!$E$20/100 | F25: =-F6*Assumptions!$E$20/100 | G25: =-G6*Assumptions!$E$20/100 | H25: =-H6*Assumptions!$E$20/100 | I25: =-I6*Assumptions!$E$20/100 | J25: =-J6*Assumptions!$E$20/100 | ... L25: =-L6*Assumptions!$E$20/100
A26: Sum of PV of FCF | B26: =SUM(C21:L21)
A27: Terminal growth (%) | B27: =Assumptions!$E$16
A28: Terminal-year FCF x (1+g) | B28: =L19*(1+B27/100)
A29: Gordon terminal value | B29: =IF(Assumptions!$B$9>B27,B28/((Assumptions!$B$9-B27)/100),0)
A30: Cap terminal value (cap x FCF_10) | B30: =Assumptions!$E$17*L19
A31: Terminal value used = MAX(0,MIN(Gordon,cap)) | B31: =MAX(0,MIN(B29,B30))
A32: Implied exit multiple (TV / FCF_10) | B32: =IF(L19<>0,B31/L19,"n/a")
A33: PV of terminal value | B33: =B31*L20
A34: Enterprise value | B34: =B26+B33
A35: less net debt (add net cash) | B35: =-Assumptions!$B$6
A36: Equity value | B36: =B34+B35
A37: Diluted shares (m) | B37: =Assumptions!$B$5
A38: VALUE PER SHARE (NZ$) | B38: =B36/B37
A39: Upside vs price | B39: =B38/Assumptions!$B$3-1
A41: Street memo: PV of explicit-period SBC | B41: =SUMPRODUCT(-C10:L10/(1+Assumptions!$B$9/100)^C4:L4)
A42: Street memo: PV of terminal SBC | B42: =IF(Assumptions!$B$9>B27,(-L10*(1+B27/100)/((Assumptions!$B$9-B27)/100))*L20,0)
A43: Street value per share (SBC as non-cash) | B43: =(B36+B41+B42)/B37
...

Sheet FCF_Quality
A1: Reported FCF reconciled to owner FCF (treatment B), NZ$ millions. Links to Actuals.
A3: Line | B3: FY2016 | C3: FY2017 | D3: FY2018 | E3: FY2019 | F3: FY2020 | G3: FY2021 | H3: FY2022 | I3: FY2023 | J3: FY2024 | K3: FY2025
A4: Free cash flow (company definition) | B4: =Actuals!B9 | C4: =Actuals!C9 | D4: =Actuals!D9 | E4: =Actuals!E9 | F4: =Actuals!F9 | G4: =Actuals!G9 | H4: =Actuals!H9 | I4: =Actuals!I9 | ... K4: =Actuals!K9
A5: less: SBC incl. equity-award taxes | B5: =-Actuals!B10 | C5: =-Actuals!C10 | D5: =-Actuals!D10 | E5: =-Actuals!E10 | F5: =-Actuals!F10 | G5: =-Actuals!G10 | H5: =-Actuals!H10 | I5: =-Actuals!I10 | ... K5: =-Actuals!K10
A6: less: interest income | B6: =-Actuals!B11 | C6: =-Actuals!C11 | D6: =-Actuals!D11 | E6: =-Actuals!E11 | F6: =-Actuals!F11 | G6: =-Actuals!G11 | H6: =-Actuals!H11 | I6: =-Actuals!I11 | ... K6: =-Actuals!K11
A7: less: IFRS-16 lease principal | B7: =-Actuals!B12 | C7: =-Actuals!C12 | D7: =-Actuals!D12 | E7: =-Actuals!E12 | F7: =-Actuals!F12 | G7: =-Actuals!G12 | H7: =-Actuals!H12 | I7: =-Actuals!I12 | ... K7: =-Actuals!K12
A8: Owner FCF (sum of the four lines above) | B8: =SUM(B4:B7) | C8: =SUM(C4:C7) | D8: =SUM(D4:D7) | E8: =SUM(E4:E7) | F8: =SUM(F4:F7) | G8: =SUM(G4:G7) | H8: =SUM(H4:H7) | I8: =SUM(I4:I7) | ... K8: =SUM(K4:K7)
A9: Revenue | B9: =Actuals!B4 | C9: =Actuals!C4 | D9: =Actuals!D4 | E9: =Actuals!E4 | F9: =Actuals!F4 | G9: =Actuals!G4 | H9: =Actuals!H4 | I9: =Actuals!I4 | ... K9: =Actuals!K4
A10: Reported FCF margin | B10: =B4/B9 | C10: =C4/C9 | D10: =D4/D9 | E10: =E4/E9 | F10: =F4/F9 | G10: =G4/G9 | H10: =H4/H9 | I10: =I4/I9 | ... K10: =K4/K9
A11: Owner FCF margin | B11: =B8/B9 | C11: =C8/C9 | D11: =D8/D9 | E11: =E8/E9 | F11: =F8/F9 | G11: =G8/G9 | H11: =H8/H9 | I11: =I8/I9 | ... K11: =K8/K9
A12: Memo: capex | B12: =Actuals!B8 | C12: =Actuals!C8 | D12: =Actuals!D8 | E12: =Actuals!E8 | F12: =Actuals!F8 | G12: =Actuals!G8 | H12: =Actuals!H8 | I12: =Actuals!I8 | ... K12: =Actuals!K8
A13: Memo: operating cash flow | B13: =Actuals!B7 | C13: =Actuals!C7 | D13: =Actuals!D7 | E13: =Actuals!E7 | F13: =Actuals!F7 | G13: =Actuals!G7 | H13: =Actuals!H7 | I13: =Actuals!I7 | ... K13: =Actuals!K7
A15: 10-year median owner FCF | B15: =MEDIAN(B8:K8)
A16: Reading | B16: The median owner FCF over FY2016-FY2025 is NEGATIVE. The two positive peaks (FY2022, FY2025) were working-capital releases (FY2025 OCF +165.5 against an EBITDA of 44.2); FY2019 carries -320 of capex for the Pokeno/Dunsandel build. Historical FCF is therefore not a usable projection base; the DCF tabs build FCF from revenue x component margins instead. SBC is immaterial (SBC-zero market).

Sheet Valuation
A1: SML.NZ valuation summary (NZ$ per share). Green = links to DCF tabs.
A3: Scenario | B3: Value / share | C3: Upside vs price | D3: Probability | E3: Street value / share | F3: Entry price @ hurdle | G3: TV bound
A4: Bear | B4: =DCF_Bear!$B$38 | C4: =B4/Assumptions!$B$3-1 | D4: =Assumptions!$C$22 | E4: =DCF_Bear!$B$43 | F4: =IF(Assumptions!$B$10*100>Assumptions!$C$16,(SUMPRODUCT(DCF_Bear!$C$19:$L$19/(1+Assumptions!$B$10*100/100)^DCF_Bear!$C$4:$L$4)+MAX(0,MIN(DCF_Bear!$L$19*(1+Assumptions!$C$16/100)/((Assumptions!$B$10*100-Assumptions!$C$16)/100),Assumptions!$C$17*DCF_Bear!$L$19))/(1+Assumptions!$B$10*100/100)^10-Assumptions!$B$6)/Assumptions!$B$5,"n/a") | G4: =IF(DCF_Bear!$B$31=0,"floor",IF(DCF_Bear!$B$29<=DCF_Bear!$B$30,"gordon","cap"))
A5: Base | B5: =DCF_Base!$B$38 | C5: =B5/Assumptions!$B$3-1 | D5: =Assumptions!$D$22 | E5: =DCF_Base!$B$43 | F5: =IF(Assumptions!$B$10*100>Assumptions!$D$16,(SUMPRODUCT(DCF_Base!$C$19:$L$19/(1+Assumptions!$B$10*100/100)^DCF_Base!$C$4:$L$4)+MAX(0,MIN(DCF_Base!$L$19*(1+Assumptions!$D$16/100)/((Assumptions!$B$10*100-Assumptions!$D$16)/100),Assumptions!$D$17*DCF_Base!$L$19))/(1+Assumptions!$B$10*100/100)^10-Assumptions!$B$6)/Assumptions!$B$5,"n/a") | G5: =IF(DCF_Base!$B$31=0,"floor",IF(DCF_Base!$B$29<=DCF_Base!$B$30,"gordon","cap"))
A6: Bull | B6: =DCF_Bull!$B$38 | C6: =B6/Assumptions!$B$3-1 | D6: =Assumptions!$E$22 | E6: =DCF_Bull!$B$43 | F6: =IF(Assumptions!$B$10*100>Assumptions!$E$16,(SUMPRODUCT(DCF_Bull!$C$19:$L$19/(1+Assumptions!$B$10*100/100)^DCF_Bull!$C$4:$L$4)+MAX(0,MIN(DCF_Bull!$L$19*(1+Assumptions!$E$16/100)/((Assumptions!$B$10*100-Assumptions!$E$16)/100),Assumptions!$E$17*DCF_Bull!$L$19))/(1+Assumptions!$B$10*100/100)^10-Assumptions!$B$6)/Assumptions!$B$5,"n/a") | G6: =IF(DCF_Bull!$B$31=0,"floor",IF(DCF_Bull!$B$29<=DCF_Bull!$B$30,"gordon","cap"))
A8: Probability-weighted value per share | B8: =SUMPRODUCT(B4:B6,D4:D6)
A9: Margin of safety (1 - price / weighted) | B9: =1-Assumptions!$B$3/B8
A10: Street weighted value per share | B10: =SUMPRODUCT(E4:E6,D4:D6)
A11: Band position (0% house, 100% street) | B11: =IF(ABS(B10-B8)<0.0001,"n/a (SBC-zero: band collapsed)",(Assumptions!$B$3-B8)/(B10-B8))
A12: Probability-weighted entry price (15% hurdle) | B12: =SUMPRODUCT(F4:F6,D4:D6)
A13: Weighted value with bear floored at zero (memo) | B13: =SUMPRODUCT(D4:D6,IF(B4:B6>0,B4:B6,0))
A14: Current price | B14: =Assumptions!$B$3
A17: Required-return table (BASE): value per share at r, TV rebuilt at r
A18: Required return (%) | B18: Value / share
A19: 9 | B19: =IF($A$19>Assumptions!$D$16,(SUMPRODUCT(DCF_Base!$C$19:$L$19/(1+$A$19/100)^DCF_Base!$C$4:$L$4)+MAX(0,MIN(DCF_Base!$L$19*(1+Assumptions!$D$16/100)/(($A$19-Assumptions!$D$16)/100),Assumptions!$D$17*DCF_Base!$L$19))/(1+$A$19/100)^10-Assumptions!$B$6)/Assumptions!$B$5,"n/a")
A20: 10 | B20: =IF($A$20>Assumptions!$D$16,(SUMPRODUCT(DCF_Base!$C$19:$L$19/(1+$A$20/100)^DCF_Base!$C$4:$L$4)+MAX(0,MIN(DCF_Base!$L$19*(1+Assumptions!$D$16/100)/(($A$20-Assumptions!$D$16)/100),Assumptions!$D$17*DCF_Base!$L$19))/(1+$A$20/100)^10-Assumptions!$B$6)/Assumptions!$B$5,"n/a")
A21: 11 | B21: =IF($A$21>Assumptions!$D$16,(SUMPRODUCT(DCF_Base!$C$19:$L$19/(1+$A$21/100)^DCF_Base!$C$4:$L$4)+MAX(0,MIN(DCF_Base!$L$19*(1+Assumptions!$D$16/100)/(($A$21-Assumptions!$D$16)/100),Assumptions!$D$17*DCF_Base!$L$19))/(1+$A$21/100)^10-Assumptions!$B$6)/Assumptions!$B$5,"n/a")
A22: 12 | B22: =IF($A$22>Assumptions!$D$16,(SUMPRODUCT(DCF_Base!$C$19:$L$19/(1+$A$22/100)^DCF_Base!$C$4:$L$4)+MAX(0,MIN(DCF_Base!$L$19*(1+Assumptions!$D$16/100)/(($A$22-Assumptions!$D$16)/100),Assumptions!$D$17*DCF_Base!$L$19))/(1+$A$22/100)^10-Assumptions!$B$6)/Assumptions!$B$5,"n/a")
A23: 15 | B23: =IF($A$23>Assumptions!$D$16,(SUMPRODUCT(DCF_Base!$C$19:$L$19/(1+$A$23/100)^DCF_Base!$C$4:$L$4)+MAX(0,MIN(DCF_Base!$L$19*(1+Assumptions!$D$16/100)/(($A$23-Assumptions!$D$16)/100),Assumptions!$D$17*DCF_Base!$L$19))/(1+$A$23/100)^10-Assumptions!$B$6)/Assumptions!$B$5,"n/a") | C23: <- 15% row; must equal the base entry price (F5)
A24: =Assumptions!$B$9 | B24: =IF($A$24>Assumptions!$D$16,(SUMPRODUCT(DCF_Base!$C$19:$L$19/(1+$A$24/100)^DCF_Base!$C$4:$L$4)+MAX(0,MIN(DCF_Base!$L$19*(1+Assumptions!$D$16/100)/(($A$24-Assumptions!$D$16)/100),Assumptions!$D$17*DCF_Base!$L$19))/(1+$A$24/100)^10-Assumptions!$B$6)/Assumptions!$B$5,"n/a") | C24: <- model WACC row; must equal DCF_Base!B38
A27: Sensitivity (BASE): WACC (rows, %) x terminal growth (columns, %)
B28: 0.5 | C28: 1 | D28: 1.5 | E28: 2 | F28: 2.5
A29: 14 | B29: =IF($A$29>B$28,(SUMPRODUCT(DCF_Base!$C$19:$L$19/(1+$A$29/100)^DCF_Base!$C$4:$L$4)+MAX(0,MIN(DCF_Base!$L$19*(1+B$28/100)/(($A$29-B$28)/100),Assumptions!$D$17*DCF_Base!$L$19))/(1+$A$29/100)^10-Assumptions!$B$6)/Assumptions!$B$5,"n/a") | C29: =IF($A$29>C$28,(SUMPRODUCT(DCF_Base!$C$19:$L$19/(1+$A$29/100)^DCF_Base!$C$4:$L$4)+MAX(0,MIN(DCF_Base!$L$19*(1+C$28/100)/(($A$29-C$28)/100),Assumptions!$D$17*DCF_Base!$L$19))/(1+$A$29/100)^10-Assumptions!$B$6)/Assumptions!$B$5,"n/a") | D29: =IF($A$29>D$28,(SUMPRODUCT(DCF_Base!$C$19:$L$19/(1+$A$29/100)^DCF_Base!$C$4:$L$4)+MAX(0,MIN(DCF_Base!$L$19*(1+D$28/100)/(($A$29-D$28)/100),Assumptions!$D$17*DCF_Base!$L$19))/(1+$A$29/100)^10-Assumptions!$B$6)/Assumptions!$B$5,"n/a") | E29: =IF($A$29>E$28,(SUMPRODUCT(DCF_Base!$C$19:$L$19/(1+$A$29/100)^DCF_Base!$C$4:$L$4)+MAX(0,MIN(DCF_Base!$L$19*(1+E$28/100)/(($A$29-E$28)/100),Assumptions!$D$17*DCF_Base!$L$19))/(1+$A$29/100)^10-Assumptions!$B$6)/Assumptions!$B$5,"n/a") | F29: =IF($A$29>F$28,(SUMPRODUCT(DCF_Base!$C$19:$L$19/(1+$A$29/100)^DCF_Base!$C$4:$L$4)+MAX(0,MIN(DCF_Base!$L$19*(1+F$28/100)/(($A$29-F$28)/100),Assumptions!$D$17*DCF_Base!$L$19))/(1+$A$29/100)^10-Assumptions!$B$6)/Assumptions!$B$5,"n/a")
A30: 15 | B30: =IF($A$30>B$28,(SUMPRODUCT(DCF_Base!$C$19:$L$19/(1+$A$30/100)^DCF_Base!$C$4:$L$4)+MAX(0,MIN(DCF_Base!$L$19*(1+B$28/100)/(($A$30-B$28)/100),Assumptions!$D$17*DCF_Base!$L$19))/(1+$A$30/100)^10-Assumptions!$B$6)/Assumptions!$B$5,"n/a") | C30: =IF($A$30>C$28,(SUMPRODUCT(DCF_Base!$C$19:$L$19/(1+$A$30/100)^DCF_Base!$C$4:$L$4)+MAX(0,MIN(DCF_Base!$L$19*(1+C$28/100)/(($A$30-C$28)/100),Assumptions!$D$17*DCF_Base!$L$19))/(1+$A$30/100)^10-Assumptions!$B$6)/Assumptions!$B$5,"n/a") | D30: =IF($A$30>D$28,(SUMPRODUCT(DCF_Base!$C$19:$L$19/(1+$A$30/100)^DCF_Base!$C$4:$L$4)+MAX(0,MIN(DCF_Base!$L$19*(1+D$28/100)/(($A$30-D$28)/100),Assumptions!$D$17*DCF_Base!$L$19))/(1+$A$30/100)^10-Assumptions!$B$6)/Assumptions!$B$5,"n/a") | E30: =IF($A$30>E$28,(SUMPRODUCT(DCF_Base!$C$19:$L$19/(1+$A$30/100)^DCF_Base!$C$4:$L$4)+MAX(0,MIN(DCF_Base!$L$19*(1+E$28/100)/(($A$30-E$28)/100),Assumptions!$D$17*DCF_Base!$L$19))/(1+$A$30/100)^10-Assumptions!$B$6)/Assumptions!$B$5,"n/a") | F30: =IF($A$30>F$28,(SUMPRODUCT(DCF_Base!$C$19:$L$19/(1+$A$30/100)^DCF_Base!$C$4:$L$4)+MAX(0,MIN(DCF_Base!$L$19*(1+F$28/100)/(($A$30-F$28)/100),Assumptions!$D$17*DCF_Base!$L$19))/(1+$A$30/100)^10-Assumptions!$B$6)/Assumptions!$B$5,"n/a")
A31: 16 | B31: =IF($A$31>B$28,(SUMPRODUCT(DCF_Base!$C$19:$L$19/(1+$A$31/100)^DCF_Base!$C$4:$L$4)+MAX(0,MIN(DCF_Base!$L$19*(1+B$28/100)/(($A$31-B$28)/100),Assumptions!$D$17*DCF_Base!$L$19))/(1+$A$31/100)^10-Assumptions!$B$6)/Assumptions!$B$5,"n/a") | C31: =IF($A$31>C$28,(SUMPRODUCT(DCF_Base!$C$19:$L$19/(1+$A$31/100)^DCF_Base!$C$4:$L$4)+MAX(0,MIN(DCF_Base!$L$19*(1+C$28/100)/(($A$31-C$28)/100),Assumptions!$D$17*DCF_Base!$L$19))/(1+$A$31/100)^10-Assumptions!$B$6)/Assumptions!$B$5,"n/a") | D31: =IF($A$31>D$28,(SUMPRODUCT(DCF_Base!$C$19:$L$19/(1+$A$31/100)^DCF_Base!$C$4:$L$4)+MAX(0,MIN(DCF_Base!$L$19*(1+D$28/100)/(($A$31-D$28)/100),Assumptions!$D$17*DCF_Base!$L$19))/(1+$A$31/100)^10-Assumptions!$B$6)/Assumptions!$B$5,"n/a") | E31: =IF($A$31>E$28,(SUMPRODUCT(DCF_Base!$C$19:$L$19/(1+$A$31/100)^DCF_Base!$C$4:$L$4)+MAX(0,MIN(DCF_Base!$L$19*(1+E$28/100)/(($A$31-E$28)/100),Assumptions!$D$17*DCF_Base!$L$19))/(1+$A$31/100)^10-Assumptions!$B$6)/Assumptions!$B$5,"n/a") | F31: =IF($A$31>F$28,(SUMPRODUCT(DCF_Base!$C$19:$L$19/(1+$A$31/100)^DCF_Base!$C$4:$L$4)+MAX(0,MIN(DCF_Base!$L$19*(1+F$28/100)/(($A$31-F$28)/100),Assumptions!$D$17*DCF_Base!$L$19))/(1+$A$31/100)^10-Assumptions!$B$6)/Assumptions!$B$5,"n/a")
A32: 17 | B32: =IF($A$32>B$28,(SUMPRODUCT(DCF_Base!$C$19:$L$19/(1+$A$32/100)^DCF_Base!$C$4:$L$4)+MAX(0,MIN(DCF_Base!$L$19*(1+B$28/100)/(($A$32-B$28)/100),Assumptions!$D$17*DCF_Base!$L$19))/(1+$A$32/100)^10-Assumptions!$B$6)/Assumptions!$B$5,"n/a") | C32: =IF($A$32>C$28,(SUMPRODUCT(DCF_Base!$C$19:$L$19/(1+$A$32/100)^DCF_Base!$C$4:$L$4)+MAX(0,MIN(DCF_Base!$L$19*(1+C$28/100)/(($A$32-C$28)/100),Assumptions!$D$17*DCF_Base!$L$19))/(1+$A$32/100)^10-Assumptions!$B$6)/Assumptions!$B$5,"n/a") | D32: =IF($A$32>D$28,(SUMPRODUCT(DCF_Base!$C$19:$L$19/(1+$A$32/100)^DCF_Base!$C$4:$L$4)+MAX(0,MIN(DCF_Base!$L$19*(1+D$28/100)/(($A$32-D$28)/100),Assumptions!$D$17*DCF_Base!$L$19))/(1+$A$32/100)^10-Assumptions!$B$6)/Assumptions!$B$5,"n/a") | E32: =IF($A$32>E$28,(SUMPRODUCT(DCF_Base!$C$19:$L$19/(1+$A$32/100)^DCF_Base!$C$4:$L$4)+MAX(0,MIN(DCF_Base!$L$19*(1+E$28/100)/(($A$32-E$28)/100),Assumptions!$D$17*DCF_Base!$L$19))/(1+$A$32/100)^10-Assumptions!$B$6)/Assumptions!$B$5,"n/a") | F32: =IF($A$32>F$28,(SUMPRODUCT(DCF_Base!$C$19:$L$19/(1+$A$32/100)^DCF_Base!$C$4:$L$4)+MAX(0,MIN(DCF_Base!$L$19*(1+F$28/100)/(($A$32-F$28)/100),Assumptions!$D$17*DCF_Base!$L$19))/(1+$A$32/100)^10-Assumptions!$B$6)/Assumptions!$B$5,"n/a")
A33: 18 | B33: =IF($A$33>B$28,(SUMPRODUCT(DCF_Base!$C$19:$L$19/(1+$A$33/100)^DCF_Base!$C$4:$L$4)+MAX(0,MIN(DCF_Base!$L$19*(1+B$28/100)/(($A$33-B$28)/100),Assumptions!$D$17*DCF_Base!$L$19))/(1+$A$33/100)^10-Assumptions!$B$6)/Assumptions!$B$5,"n/a") | C33: =IF($A$33>C$28,(SUMPRODUCT(DCF_Base!$C$19:$L$19/(1+$A$33/100)^DCF_Base!$C$4:$L$4)+MAX(0,MIN(DCF_Base!$L$19*(1+C$28/100)/(($A$33-C$28)/100),Assumptions!$D$17*DCF_Base!$L$19))/(1+$A$33/100)^10-Assumptions!$B$6)/Assumptions!$B$5,"n/a") | D33: =IF($A$33>D$28,(SUMPRODUCT(DCF_Base!$C$19:$L$19/(1+$A$33/100)^DCF_Base!$C$4:$L$4)+MAX(0,MIN(DCF_Base!$L$19*(1+D$28/100)/(($A$33-D$28)/100),Assumptions!$D$17*DCF_Base!$L$19))/(1+$A$33/100)^10-Assumptions!$B$6)/Assumptions!$B$5,"n/a") | E33: =IF($A$33>E$28,(SUMPRODUCT(DCF_Base!$C$19:$L$19/(1+$A$33/100)^DCF_Base!$C$4:$L$4)+MAX(0,MIN(DCF_Base!$L$19*(1+E$28/100)/(($A$33-E$28)/100),Assumptions!$D$17*DCF_Base!$L$19))/(1+$A$33/100)^10-Assumptions!$B$6)/Assumptions!$B$5,"n/a") | F33: =IF($A$33>F$28,(SUMPRODUCT(DCF_Base!$C$19:$L$19/(1+$A$33/100)^DCF_Base!$C$4:$L$4)+MAX(0,MIN(DCF_Base!$L$19*(1+F$28/100)/(($A$33-F$28)/100),Assumptions!$D$17*DCF_Base!$L$19))/(1+$A$33/100)^10-Assumptions!$B$6)/Assumptions!$B$5,"n/a")
A35: Net-debt sensitivity (weighted IV, memo from JSON)
A36: 189.0 (31-Jan-26 pro-forma, seasonal WC peak, no unwind) | B36: 0.1119
A37: 125.0 (house estimate, 31-Jul-26) | B37: 0.218
A38: 85.0 (full seasonal unwind to nil net WC) | B38: 0.2843
A40: Bear rescue-raise memo
A41: Bright Dairy-led recapitalisation of NZ$150m at NZ$0.20/share (750m new shares, +124% dilution), proceeds applied to debt | B41: 0.0616
