Workbook

Sheet Model_Info
A1: TWL.NZ -- TradeWindow Holdings Limited -- owner-FCF DCF model
A2: Version | B2: v1 (fresh build 2026-09-19). Supersedes nothing: first valuation of this ticker.
A3: Built by | B3: dcf-analyst agent (Claude Fable 5.1) on 2026-09-19 at the research orchestrator's request.
A4: Price | B4: NZ$0.117 -- 2026-09-18T03:47:52Z (NZX last trade 15:47:51 NZST, regular session; Yahoo regularMarketTime). Figures go stale; refresh price, cash and share count before use.
A5: Balance sheet | B5: 2026-03-31 audited: cash 4.190, debt 0.454 (MBIE R&D loan + insurance premium funding), lease liabilities 0.007 excluded. FY26 Annual Report (audited, auditor's report dated 29-May-2026, re-lodged 17-Jul-2026), notes 10, 16, 17, 18
A6: Share count | B6: fully diluted: 163,605,272 ordinary shares on issue per NZX (2026-09-18; ties to 163,361,489 at 31-Mar-2026 in FY26 AR note 18 + 243,783 options exercised per Capital Change Notice 19-Aug-2026) + 533,216 remaining options = 164,138,488. Held FLAT because SBC is expensed in the flows; the negative early-year FCFs are discounted as if funded at fair value -- see notes on the funding gap for what a raise at the current price does to this figure.
A7: Guidance | B7: FY27 (Mar-2027): trading revenue +13-18%, EBITDA 'approaching breakeven', FreightAI capitalised spend ~NZ$1.5m (FY26 results 29-May-2026; Q1 FY27 update 23-Jul-2026: revenue +18%, ARR NZ$10.4m +17%, retention 90%).
A8: Model | B8: Owner-FCF DCF (dcf-methods routing: operating SaaS). Staged path-to-profitability, 10-year explicit horizon FY2027E-FY2036E, component margins, end-of-year discounting, TV = MAX(0, MIN(Gordon, 15x FCF10)), net cash added, fully diluted flat share count.
A9: Owner FCF | B9: reported FCF less SBC expense, less interest income (net cash is in the bridge), less lease cash (treatment B: leases as operating cost, lease liabilities excluded from net debt). Capitalised development is capex.
A10: EBITDA driver | B10: PRE-SBC. Company EBITDA (-1.242m FY26) is after SBC; the driver starts at -12.6% pre-SBC and SBC is charged on row 10.
A11: Tax | B11: Zero through year 6 (NZ$39.1m unrecognised losses), ramped 10/20/28% years 7-10 for shareholder-continuity risk; tax = MAX(0, EBIT) x rate. Bear: zero throughout.
A12: WACC | B12: NZD-built cost of equity = WACC (no material debt): NZ 10y govt ~4.5% + 5.5% ERP x beta 1.5 (loss-making micro-cap SaaS) = 12.75%, plus ~1.25pp illiquidity/size premium (NZ$19m market cap, sub-NZ$50k daily turnover) = 14.0%. Cross-check: the company's own FY26 impairment test uses a 17.8% PRE-tax discount rate (FY25: 17.0%), i.e. ~13-14% post-tax. Same 14% in all three scenarios; survival, execution and dilution risk are charged in the scenario flows and in the 30% bear weight, not stacked into the rate (owner-fcf.md s7f).
A13: Scenario drivers | B13: Agent judgment set 2026-09-19 from the FY26 Annual Report, FY26 results deck and Q1 FY27 update. Base sits BELOW management guidance (growth at the 13% floor, EBITDA -5% pre-SBC in FY27) because breakeven guidance slipped FY26 -> FY27 -> 'approaching'. Bear 30% / base 50% / bull 20%.
... A18: Units | B18: NZD millions unless stated; per-share figures in NZD.

Sheet Actuals
A1: Metric (NZD m) | B1: FY2021 | C1: FY2022 | D1: FY2023 | E1: FY2024 | F1: FY2025 | G1: FY2026 | H1: Source
A2: Revenue | B2: 1.642 | C2: 3.878 | D2: 4.92 | E2: 6.179 | F2: 8.031 | G2: 9.609 | H2: Metrics.csv FY21-FY25; FY26 Annual Report p.46
A3: EBITDA (company, post-SBC) | B3: -5.864 | C3: -9.547 | D3: -11.69 | E3: -6.626 | F3: -1.526 | G3: -1.242 | H3: op. loss + D&A
A4: Net loss | B4: -6.598 | C4: -10.824 | D4: -9.793 | E4: -8.014 | F4: -3.518 | G4: -2.592
A5: Operating cash flow | B5: -4.576 | C5: -8.496 | D5: -10.833 | E5: -5.754 | F5: -1.525 | G5: -1.308
A6: Capex incl. capitalised dev | B6: 0.118 | C6: 0.34 | D6: 0.148 | E6: 0.012 | F6: 0.059 | G6: 0.703 | H6: FY26: PPE 0.042 + intangibles 0.661
A7: ARR (NZ$m) | D7: 5.2 | E7: 6.3 | F7: 8.7 | G7: 10.1 | H7: kpis; Q1 FY27 10.4
A8: Cash | B8: 1.413 | C8: 5.933 | D8: 6.148 | E8: 0.188 | F8: 0.392 | G8: 4.19
A9: Interest-bearing debt | B9: 1.71 | C9: 3.633 | D9: 2.668 | E9: 1.52 | F9: 1.433 | G9: 0.454 | H9: FY26 note 17
A10: Shares on issue (m, closing) | B10: 5.78 | C10: 86.373 | D10: 117.196 | E10: 130.791 | F10: 130.791 | G10: 163.361 | H10: FY26 note 18; CSV FY25 127.7m is the weighted average. Live 163.605 + 0.533 options
A13: FY27 guidance | B13: Trading revenue +13-18%; EBITDA approaching breakeven; FreightAI capitalised ~NZ$1.5m; avg monthly cash outflow FY26 NZ$184k ex-raises.
A14: Buybacks | B14: None ever. 32.5m shares issued in FY26 (NZ$7.67m gross).

Sheet Assumptions
A1: Global inputs
A3: WACC (cost of equity, NZD) | B3: 0.14 | C3: 14%: NZ rf 4.5% + 5.5% ERP x 1.5 beta + 1.25pp illiquidity; company impairment rate 17.8% pre-tax
A4: D&A % of revenue (ex-ROU) | B4: 0.07 | C4: FY26 13% incl. acquired-intangible amortisation, run-off to ~7%; tax-only effect
A5: Lease cost % of revenue | B5: 0.005 | C5: FY26 principal 0.044 + interest 0.003 = 0.5%
A6: WC capture on revenue change | B6: -0.05 | C6: Negative: receivables outgrow contract liabilities (FY26 -0.084 on +1.58)
A7: Net cash (NZD m) | B7: 3.736 | C7: 31-Mar-2026: cash 4.190 - debt 0.454; ~0.7m lower by Sept-2026 at NZ$184k/month burn
A8: Diluted shares (m) | B8: 164.138 | C8: 163.605 on issue (NZX 18-Sep-2026) + 0.533 options
A9: Share price (NZD) | B9: 0.117 | C9: 2026-09-18T03:47:52Z (NZX last trade 15:47:51 NZST, regular session; Yahoo regularMarketTime)
A10: Terminal value cap (x FCF10) | B10: 15 | C10: 15x for an illiquid micro-cap SaaS
A11: Hurdle rate (entry price) | B11: 0.15 | C11: TV rebuilt at the hurdle
A12: Net debt (NZD m) | B12: =-B7 | C12: formula
A14: Scenario | B14: Tab | C14: Terminal growth | D14: Probability
A15: bear | B15: DCF_Bear | C15: 0.02 | D15: 0.3
A16: base | B16: DCF_Base | C16: 0.03 | D16: 0.5
A17: bull | B17: DCF_Bull | C17: 0.035 | D17: 0.2
A18: Weights sum (must be 1.0) | D18: =SUM(D15:D17)
A20: Scenario narratives
A21: base | B21: Revenue grows 13% in FY27 (floor of guidance; Q1 printed +18%) decelerating to 4% by FY36, driven by ARPC expansion (shipper ARPC +20-22%/yr on re-pricing and module cross-sell) against a flat-to-declining customer count. Pre-SBC EBITDA margin moves from -12.6% to -5% in FY27 -- i.e. management's 'approaching breakeven' slips again by roughly a year -- reaching breakeven in FY28 and 22% by FY36 as the 60-63% gross margin scales over a cost base held near NZ$11m. FreightAI is delivered (capex 15% of revenue in FY27, 11% FY28) but contributes only modestly. Cumulative burn exhausts net cash around FY29, so one more raise or a spend cut is implied.
A22: bull | B22: FreightAI ships on schedule (Sept-2027), lands mid-market freight forwarders currently on WiseTech/legacy systems, and the primary ASX listing brings Australian institutional capital at a premium to today's price. Revenue growth holds 17-18% for three years (ARR already compounding 17%), pre-SBC EBITDA reaches breakeven in FY28 and 28% by FY35 -- still below the 30%+ mature margins of scaled trade-software peers. Terminal growth 3.5%.
A23: bear | B23: Retention slips back toward the 87% seen in FY25 as re-pricing pushes small customers out, FreightAI overruns the Board's cost envelope (the going-concern note's stated trigger), Australian growth stalls against WiseTech, and the company cannot raise on acceptable terms in a thin small-cap market (as in 2023 when it reached 27% of target). Revenue growth fades to 2-3%, EBITDA never clears 3% pre-SBC, owner FCF stays negative every year, the terminal value floors at zero and the equity is worth net cash less the burn -- negative: the business does not survive this path without a rescue raise.
A25: Weights rationale | B25: Bear raised to 30% (house default 15%) because the FY26 audit opinion still carries a going-concern material uncertainty, the base case itself implies another raise, EBITDA-breakeven guidance has slipped twice, and the CEO changed in mid-2026. Bull cut to 20% (default 35%) because it needs three independent things to go right: FreightAI delivered on time and cost, adoption against a far better-capitalised incumbent, and an ASX raise at a premium. Base 50%.

Sheet DCF_Bear
A1: BEAR case -- owner-FCF DCF (NZD m)
A3: Fiscal year | B3: 2026A | C3: 2027E | D3: 2028E | E3: 2029E | F3: 2030E | G3: 2031E | H3: 2032E | I3: 2033E | J3: 2034E | K3: 2035E | L3: 2036E
A4: Year index | B4: 0 | C4: 1 | D4: 2 | E4: 3 | F4: 4 | G4: 5 | H4: 6 | I4: 7 | J4: 8 | K4: 9 | L4: 10
A5: Revenue growth YoY | C5: 0.07 | D5: 0.05 | E5: 0.04 | F5: 0.03 | G5: 0.03 | H5: 0.03 | I5: 0.02 | J5: 0.02 | K5: 0.02 | L5: 0.02
A6: Revenue | B6: 9.609 | C6: =B6*(1+C5) | D6: =C6*(1+D5) | E6: =D6*(1+E5) | F6: =E6*(1+F5) | G6: =F6*(1+G5) | H6: =G6*(1+H5) | I6: =H6*(1+I5) | J6: =I6*(1+J5) | ... L6: =K6*(1+L5)
A7: Adj EBITDA margin (pre-SBC) | B7: =B8/B6 | C7: -0.1 | D7: -0.08 | E7: -0.06 | F7: -0.04 | G7: -0.02 | H7: 0 | I7: 0.01 | J7: 0.02 | K7: 0.03 | L7: 0.03
A8: Adjusted EBITDA | B8: -1.208 | C8: =C6*C7 | D8: =D6*D7 | E8: =E6*E7 | F8: =F6*F7 | G8: =G6*G7 | H8: =H6*H7 | I8: =I6*I7 | J8: =J6*J7 | ... L8: =L6*L7
A9: SBC % of revenue | B9: =-B10/B6 | C9: 0.01 | D9: 0.01 | E9: 0.01 | F9: 0.01 | G9: 0.01 | H9: 0.01 | I9: 0.01 | J9: 0.01 | K9: 0.01 | L9: 0.01
A10: SBC (negative) | B10: -0.0347 | C10: =-C6*C9 | D10: =-D6*D9 | E10: =-E6*E9 | F10: =-F6*F9 | G10: =-G6*G9 | H10: =-H6*H9 | I10: =-I6*I9 | J10: =-J6*J9 | ... L10: =-L6*L9
A11: Owner EBITDA (after SBC and lease) | C11: =C8+C10+C22 | D11: =D8+D10+D22 | E11: =E8+E10+E22 | F11: =F8+F10+F22 | G11: =G8+G10+G22 | H11: =H8+H10+H22 | I11: =I8+I10+I22 | J11: =J8+J10+J22 | ... L11: =L8+L10+L22
A12: D&A | B12: -1.263 | C12: =-C6*Assumptions!$B$4 | D12: =-D6*Assumptions!$B$4 | E12: =-E6*Assumptions!$B$4 | F12: =-F6*Assumptions!$B$4 | G12: =-G6*Assumptions!$B$4 | H12: =-H6*Assumptions!$B$4 | I12: =-I6*Assumptions!$B$4 | J12: =-J6*Assumptions!$B$4 | ... L12: =-L6*Assumptions!$B$4
A13: EBIT, SBC expensed | C13: =C11+C12 | D13: =D11+D12 | E13: =E11+E12 | F13: =F11+F12 | G13: =G11+G12 | H13: =H11+H12 | I13: =I11+I12 | J13: =J11+J12 | ... L13: =L11+L12
A14: Cash tax rate | C14: 0 | D14: 0 | E14: 0 | F14: 0 | G14: 0 | H14: 0 | I14: 0 | J14: 0 | K14: 0 | L14: 0
A15: NOPAT (tax on MAX(0,EBIT)) | C15: =C13-MAX(0,C13)*C14 | D15: =D13-MAX(0,D13)*D14 | E15: =E13-MAX(0,E13)*E14 | F15: =F13-MAX(0,F13)*F14 | G15: =G13-MAX(0,G13)*G14 | H15: =H13-MAX(0,H13)*H14 | I15: =I13-MAX(0,I13)*I14 | J15: =J13-MAX(0,J13)*J14 | ... L15: =L13-MAX(0,L13)*L14
A16: add back D&A | C16: =-C12 | D16: =-D12 | E16: =-E12 | F16: =-F12 | G16: =-G12 | H16: =-H12 | I16: =-I12 | J16: =-J12 | ... L16: =-L12
A17: less capex incl. capitalised dev | B17: -0.703 | C17: =-C6*C25 | D17: =-D6*D25 | E17: =-E6*E25 | F17: =-F6*F25 | G17: =-G6*G25 | H17: =-H6*H25 | I17: =-I6*I25 | J17: =-J6*J25 | ... L17: =-L6*L25
A18: add working capital | C18: =Assumptions!$B$6*(C6-B6) | D18: =Assumptions!$B$6*(D6-C6) | E18: =Assumptions!$B$6*(E6-D6) | F18: =Assumptions!$B$6*(F6-E6) | G18: =Assumptions!$B$6*(G6-F6) | H18: =Assumptions!$B$6*(H6-G6) | I18: =Assumptions!$B$6*(I6-H6) | J18: =Assumptions!$B$6*(J6-I6) | ... L18: =Assumptions!$B$6*(L6-K6)
A19: Unlevered owner FCF | B19: -2.111 | C19: =C15+C16+C17+C18 | D19: =D15+D16+D17+D18 | E19: =E15+E16+E17+E18 | F19: =F15+F16+F17+F18 | G19: =G15+G16+G17+G18 | H19: =H15+H16+H17+H18 | I19: =I15+I16+I17+I18 | J19: =J15+J16+J17+J18 | ... L19: =L15+L16+L17+L18
A20: Discount factor | B20: 1 | C20: =1/(1+Assumptions!$B$3)^C4 | D20: =1/(1+Assumptions!$B$3)^D4 | E20: =1/(1+Assumptions!$B$3)^E4 | F20: =1/(1+Assumptions!$B$3)^F4 | G20: =1/(1+Assumptions!$B$3)^G4 | H20: =1/(1+Assumptions!$B$3)^H4 | I20: =1/(1+Assumptions!$B$3)^I4 | J20: =1/(1+Assumptions!$B$3)^J4 | ... L20: =1/(1+Assumptions!$B$3)^L4
A21: PV of FCF | C21: =C19*C20 | D21: =D19*D20 | E21: =E19*E20 | F21: =F19*F20 | G21: =G19*G20 | H21: =H19*H20 | I21: =I19*I20 | J21: =J19*J20 | ... L21: =L19*L20
A22: Lease cost (negative) | B22: -0.0466 | C22: =-C6*Assumptions!$B$5 | D22: =-D6*Assumptions!$B$5 | E22: =-E6*Assumptions!$B$5 | F22: =-F6*Assumptions!$B$5 | G22: =-G6*Assumptions!$B$5 | H22: =-H6*Assumptions!$B$5 | I22: =-I6*Assumptions!$B$5 | J22: =-J6*Assumptions!$B$5 | ... L22: =-L6*Assumptions!$B$5
A23: Memo: FCF before SBC | C23: =C19-C10 | D23: =D19-D10 | E23: =E19-E10 | F23: =F19-F10 | G23: =G19-G10 | H23: =H19-H10 | I23: =I19-I10 | J23: =J19-J10 | ... L23: =L19-L10
A24: Memo: owner-FCF margin | B24: =B19/B6 | C24: =C19/C6 | D24: =D19/D6 | E24: =E19/E6 | F24: =F19/F6 | G24: =G19/G6 | H24: =H19/H6 | I24: =I19/I6 | ... L24: =L19/L6
A25: Capex % of revenue | B25: =-B17/B6 | C25: 0.15 | D25: 0.11 | E25: 0.08 | F25: 0.06 | G25: 0.05 | H25: 0.05 | I25: 0.05 | J25: 0.05 | K25: 0.05 | L25: 0.05
A26: Sum of PV of FCF | B26: =SUM(C21:L21)
A27: Terminal growth | B27: =Assumptions!$C$15
A28: Terminal-year FCF x (1+g) | B28: =L19*(1+B27)
A29: Gordon terminal value | B29: =B28/(Assumptions!$B$3-B27)
A30: Cap terminal value | B30: =Assumptions!$B$10*L19
A31: Terminal value used = MAX(0, MIN(Gordon, cap)) | B31: =MAX(0,MIN(B29,B30))
A32: Implied exit multiple (TV / FCF10) | B32: =IF(L19>0,B31/L19,"n/a")
A33: PV of terminal value | B33: =B31*L20
A34: Enterprise value | B34: =B26+B33
A35: add net cash | B35: =Assumptions!$B$7
A36: Equity value | B36: =B34+B35
A37: Diluted shares (m) | B37: =Assumptions!$B$8
A38: Value per share (NZD) | B38: =B36/B37
A39: Upside vs price | B39: =B38/Assumptions!$B$9-1
A41: Street memo: PV of explicit SBC | B41: =SUMPRODUCT(-C10:L10/(1+Assumptions!$B$3)^C4:L4)
A42: Street memo: PV of terminal SBC | B42: =(-L10*(1+B27)/(Assumptions!$B$3-B27))*L20
...

Sheet DCF_Base
A1: BASE case -- owner-FCF DCF (NZD m)
A3: Fiscal year | B3: 2026A | C3: 2027E | D3: 2028E | E3: 2029E | F3: 2030E | G3: 2031E | H3: 2032E | I3: 2033E | J3: 2034E | K3: 2035E | L3: 2036E
A4: Year index | B4: 0 | C4: 1 | D4: 2 | E4: 3 | F4: 4 | G4: 5 | H4: 6 | I4: 7 | J4: 8 | K4: 9 | L4: 10
A5: Revenue growth YoY | C5: 0.13 | D5: 0.12 | E5: 0.11 | F5: 0.1 | G5: 0.09 | H5: 0.08 | I5: 0.07 | J5: 0.06 | K5: 0.05 | L5: 0.04
A6: Revenue | B6: 9.609 | C6: =B6*(1+C5) | D6: =C6*(1+D5) | E6: =D6*(1+E5) | F6: =E6*(1+F5) | G6: =F6*(1+G5) | H6: =G6*(1+H5) | I6: =H6*(1+I5) | J6: =I6*(1+J5) | ... L6: =K6*(1+L5)
A7: Adj EBITDA margin (pre-SBC) | B7: =B8/B6 | C7: -0.05 | D7: 0 | E7: 0.05 | F7: 0.09 | G7: 0.13 | H7: 0.16 | I7: 0.18 | J7: 0.2 | K7: 0.21 | L7: 0.22
A8: Adjusted EBITDA | B8: -1.208 | C8: =C6*C7 | D8: =D6*D7 | E8: =E6*E7 | F8: =F6*F7 | G8: =G6*G7 | H8: =H6*H7 | I8: =I6*I7 | J8: =J6*J7 | ... L8: =L6*L7
A9: SBC % of revenue | B9: =-B10/B6 | C9: 0.01 | D9: 0.01 | E9: 0.01 | F9: 0.009 | G9: 0.009 | H9: 0.009 | I9: 0.008 | J9: 0.008 | K9: 0.008 | L9: 0.008
A10: SBC (negative) | B10: -0.0347 | C10: =-C6*C9 | D10: =-D6*D9 | E10: =-E6*E9 | F10: =-F6*F9 | G10: =-G6*G9 | H10: =-H6*H9 | I10: =-I6*I9 | J10: =-J6*J9 | ... L10: =-L6*L9
A11: Owner EBITDA (after SBC and lease) | C11: =C8+C10+C22 | D11: =D8+D10+D22 | E11: =E8+E10+E22 | F11: =F8+F10+F22 | G11: =G8+G10+G22 | H11: =H8+H10+H22 | I11: =I8+I10+I22 | J11: =J8+J10+J22 | ... L11: =L8+L10+L22
A12: D&A | B12: -1.263 | C12: =-C6*Assumptions!$B$4 | D12: =-D6*Assumptions!$B$4 | E12: =-E6*Assumptions!$B$4 | F12: =-F6*Assumptions!$B$4 | G12: =-G6*Assumptions!$B$4 | H12: =-H6*Assumptions!$B$4 | I12: =-I6*Assumptions!$B$4 | J12: =-J6*Assumptions!$B$4 | ... L12: =-L6*Assumptions!$B$4
A13: EBIT, SBC expensed | C13: =C11+C12 | D13: =D11+D12 | E13: =E11+E12 | F13: =F11+F12 | G13: =G11+G12 | H13: =H11+H12 | I13: =I11+I12 | J13: =J11+J12 | ... L13: =L11+L12
A14: Cash tax rate | C14: 0 | D14: 0 | E14: 0 | F14: 0 | G14: 0 | H14: 0 | I14: 0.1 | J14: 0.2 | K14: 0.28 | L14: 0.28
A15: NOPAT (tax on MAX(0,EBIT)) | C15: =C13-MAX(0,C13)*C14 | D15: =D13-MAX(0,D13)*D14 | E15: =E13-MAX(0,E13)*E14 | F15: =F13-MAX(0,F13)*F14 | G15: =G13-MAX(0,G13)*G14 | H15: =H13-MAX(0,H13)*H14 | I15: =I13-MAX(0,I13)*I14 | J15: =J13-MAX(0,J13)*J14 | ... L15: =L13-MAX(0,L13)*L14
A16: add back D&A | C16: =-C12 | D16: =-D12 | E16: =-E12 | F16: =-F12 | G16: =-G12 | H16: =-H12 | I16: =-I12 | J16: =-J12 | ... L16: =-L12
A17: less capex incl. capitalised dev | B17: -0.703 | C17: =-C6*C25 | D17: =-D6*D25 | E17: =-E6*E25 | F17: =-F6*F25 | G17: =-G6*G25 | H17: =-H6*H25 | I17: =-I6*I25 | J17: =-J6*J25 | ... L17: =-L6*L25
A18: add working capital | C18: =Assumptions!$B$6*(C6-B6) | D18: =Assumptions!$B$6*(D6-C6) | E18: =Assumptions!$B$6*(E6-D6) | F18: =Assumptions!$B$6*(F6-E6) | G18: =Assumptions!$B$6*(G6-F6) | H18: =Assumptions!$B$6*(H6-G6) | I18: =Assumptions!$B$6*(I6-H6) | J18: =Assumptions!$B$6*(J6-I6) | ... L18: =Assumptions!$B$6*(L6-K6)
A19: Unlevered owner FCF | B19: -2.111 | C19: =C15+C16+C17+C18 | D19: =D15+D16+D17+D18 | E19: =E15+E16+E17+E18 | F19: =F15+F16+F17+F18 | G19: =G15+G16+G17+G18 | H19: =H15+H16+H17+H18 | I19: =I15+I16+I17+I18 | J19: =J15+J16+J17+J18 | ... L19: =L15+L16+L17+L18
A20: Discount factor | B20: 1 | C20: =1/(1+Assumptions!$B$3)^C4 | D20: =1/(1+Assumptions!$B$3)^D4 | E20: =1/(1+Assumptions!$B$3)^E4 | F20: =1/(1+Assumptions!$B$3)^F4 | G20: =1/(1+Assumptions!$B$3)^G4 | H20: =1/(1+Assumptions!$B$3)^H4 | I20: =1/(1+Assumptions!$B$3)^I4 | J20: =1/(1+Assumptions!$B$3)^J4 | ... L20: =1/(1+Assumptions!$B$3)^L4
A21: PV of FCF | C21: =C19*C20 | D21: =D19*D20 | E21: =E19*E20 | F21: =F19*F20 | G21: =G19*G20 | H21: =H19*H20 | I21: =I19*I20 | J21: =J19*J20 | ... L21: =L19*L20
A22: Lease cost (negative) | B22: -0.0466 | C22: =-C6*Assumptions!$B$5 | D22: =-D6*Assumptions!$B$5 | E22: =-E6*Assumptions!$B$5 | F22: =-F6*Assumptions!$B$5 | G22: =-G6*Assumptions!$B$5 | H22: =-H6*Assumptions!$B$5 | I22: =-I6*Assumptions!$B$5 | J22: =-J6*Assumptions!$B$5 | ... L22: =-L6*Assumptions!$B$5
A23: Memo: FCF before SBC | C23: =C19-C10 | D23: =D19-D10 | E23: =E19-E10 | F23: =F19-F10 | G23: =G19-G10 | H23: =H19-H10 | I23: =I19-I10 | J23: =J19-J10 | ... L23: =L19-L10
A24: Memo: owner-FCF margin | B24: =B19/B6 | C24: =C19/C6 | D24: =D19/D6 | E24: =E19/E6 | F24: =F19/F6 | G24: =G19/G6 | H24: =H19/H6 | I24: =I19/I6 | ... L24: =L19/L6
A25: Capex % of revenue | B25: =-B17/B6 | C25: 0.15 | D25: 0.11 | E25: 0.08 | F25: 0.07 | G25: 0.06 | H25: 0.06 | I25: 0.055 | J25: 0.055 | K25: 0.055 | L25: 0.055
A26: Sum of PV of FCF | B26: =SUM(C21:L21)
A27: Terminal growth | B27: =Assumptions!$C$16
A28: Terminal-year FCF x (1+g) | B28: =L19*(1+B27)
A29: Gordon terminal value | B29: =B28/(Assumptions!$B$3-B27)
A30: Cap terminal value | B30: =Assumptions!$B$10*L19
A31: Terminal value used = MAX(0, MIN(Gordon, cap)) | B31: =MAX(0,MIN(B29,B30))
A32: Implied exit multiple (TV / FCF10) | B32: =IF(L19>0,B31/L19,"n/a")
A33: PV of terminal value | B33: =B31*L20
A34: Enterprise value | B34: =B26+B33
A35: add net cash | B35: =Assumptions!$B$7
A36: Equity value | B36: =B34+B35
A37: Diluted shares (m) | B37: =Assumptions!$B$8
A38: Value per share (NZD) | B38: =B36/B37
A39: Upside vs price | B39: =B38/Assumptions!$B$9-1
A41: Street memo: PV of explicit SBC | B41: =SUMPRODUCT(-C10:L10/(1+Assumptions!$B$3)^C4:L4)
A42: Street memo: PV of terminal SBC | B42: =(-L10*(1+B27)/(Assumptions!$B$3-B27))*L20
...

Sheet DCF_Bull
A1: BULL case -- owner-FCF DCF (NZD m)
A3: Fiscal year | B3: 2026A | C3: 2027E | D3: 2028E | E3: 2029E | F3: 2030E | G3: 2031E | H3: 2032E | I3: 2033E | J3: 2034E | K3: 2035E | L3: 2036E
A4: Year index | B4: 0 | C4: 1 | D4: 2 | E4: 3 | F4: 4 | G4: 5 | H4: 6 | I4: 7 | J4: 8 | K4: 9 | L4: 10
A5: Revenue growth YoY | C5: 0.18 | D5: 0.18 | E5: 0.17 | F5: 0.15 | G5: 0.13 | H5: 0.11 | I5: 0.09 | J5: 0.08 | K5: 0.06 | L5: 0.05
A6: Revenue | B6: 9.609 | C6: =B6*(1+C5) | D6: =C6*(1+D5) | E6: =D6*(1+E5) | F6: =E6*(1+F5) | G6: =F6*(1+G5) | H6: =G6*(1+H5) | I6: =H6*(1+I5) | J6: =I6*(1+J5) | ... L6: =K6*(1+L5)
A7: Adj EBITDA margin (pre-SBC) | B7: =B8/B6 | C7: -0.02 | D7: 0.06 | E7: 0.12 | F7: 0.17 | G7: 0.21 | H7: 0.24 | I7: 0.26 | J7: 0.27 | K7: 0.28 | L7: 0.28
A8: Adjusted EBITDA | B8: -1.208 | C8: =C6*C7 | D8: =D6*D7 | E8: =E6*E7 | F8: =F6*F7 | G8: =G6*G7 | H8: =H6*H7 | I8: =I6*I7 | J8: =J6*J7 | ... L8: =L6*L7
A9: SBC % of revenue | B9: =-B10/B6 | C9: 0.01 | D9: 0.01 | E9: 0.01 | F9: 0.009 | G9: 0.009 | H9: 0.009 | I9: 0.008 | J9: 0.008 | K9: 0.008 | L9: 0.008
A10: SBC (negative) | B10: -0.0347 | C10: =-C6*C9 | D10: =-D6*D9 | E10: =-E6*E9 | F10: =-F6*F9 | G10: =-G6*G9 | H10: =-H6*H9 | I10: =-I6*I9 | J10: =-J6*J9 | ... L10: =-L6*L9
A11: Owner EBITDA (after SBC and lease) | C11: =C8+C10+C22 | D11: =D8+D10+D22 | E11: =E8+E10+E22 | F11: =F8+F10+F22 | G11: =G8+G10+G22 | H11: =H8+H10+H22 | I11: =I8+I10+I22 | J11: =J8+J10+J22 | ... L11: =L8+L10+L22
A12: D&A | B12: -1.263 | C12: =-C6*Assumptions!$B$4 | D12: =-D6*Assumptions!$B$4 | E12: =-E6*Assumptions!$B$4 | F12: =-F6*Assumptions!$B$4 | G12: =-G6*Assumptions!$B$4 | H12: =-H6*Assumptions!$B$4 | I12: =-I6*Assumptions!$B$4 | J12: =-J6*Assumptions!$B$4 | ... L12: =-L6*Assumptions!$B$4
A13: EBIT, SBC expensed | C13: =C11+C12 | D13: =D11+D12 | E13: =E11+E12 | F13: =F11+F12 | G13: =G11+G12 | H13: =H11+H12 | I13: =I11+I12 | J13: =J11+J12 | ... L13: =L11+L12
A14: Cash tax rate | C14: 0 | D14: 0 | E14: 0 | F14: 0 | G14: 0 | H14: 0 | I14: 0.1 | J14: 0.2 | K14: 0.28 | L14: 0.28
A15: NOPAT (tax on MAX(0,EBIT)) | C15: =C13-MAX(0,C13)*C14 | D15: =D13-MAX(0,D13)*D14 | E15: =E13-MAX(0,E13)*E14 | F15: =F13-MAX(0,F13)*F14 | G15: =G13-MAX(0,G13)*G14 | H15: =H13-MAX(0,H13)*H14 | I15: =I13-MAX(0,I13)*I14 | J15: =J13-MAX(0,J13)*J14 | ... L15: =L13-MAX(0,L13)*L14
A16: add back D&A | C16: =-C12 | D16: =-D12 | E16: =-E12 | F16: =-F12 | G16: =-G12 | H16: =-H12 | I16: =-I12 | J16: =-J12 | ... L16: =-L12
A17: less capex incl. capitalised dev | B17: -0.703 | C17: =-C6*C25 | D17: =-D6*D25 | E17: =-E6*E25 | F17: =-F6*F25 | G17: =-G6*G25 | H17: =-H6*H25 | I17: =-I6*I25 | J17: =-J6*J25 | ... L17: =-L6*L25
A18: add working capital | C18: =Assumptions!$B$6*(C6-B6) | D18: =Assumptions!$B$6*(D6-C6) | E18: =Assumptions!$B$6*(E6-D6) | F18: =Assumptions!$B$6*(F6-E6) | G18: =Assumptions!$B$6*(G6-F6) | H18: =Assumptions!$B$6*(H6-G6) | I18: =Assumptions!$B$6*(I6-H6) | J18: =Assumptions!$B$6*(J6-I6) | ... L18: =Assumptions!$B$6*(L6-K6)
A19: Unlevered owner FCF | B19: -2.111 | C19: =C15+C16+C17+C18 | D19: =D15+D16+D17+D18 | E19: =E15+E16+E17+E18 | F19: =F15+F16+F17+F18 | G19: =G15+G16+G17+G18 | H19: =H15+H16+H17+H18 | I19: =I15+I16+I17+I18 | J19: =J15+J16+J17+J18 | ... L19: =L15+L16+L17+L18
A20: Discount factor | B20: 1 | C20: =1/(1+Assumptions!$B$3)^C4 | D20: =1/(1+Assumptions!$B$3)^D4 | E20: =1/(1+Assumptions!$B$3)^E4 | F20: =1/(1+Assumptions!$B$3)^F4 | G20: =1/(1+Assumptions!$B$3)^G4 | H20: =1/(1+Assumptions!$B$3)^H4 | I20: =1/(1+Assumptions!$B$3)^I4 | J20: =1/(1+Assumptions!$B$3)^J4 | ... L20: =1/(1+Assumptions!$B$3)^L4
A21: PV of FCF | C21: =C19*C20 | D21: =D19*D20 | E21: =E19*E20 | F21: =F19*F20 | G21: =G19*G20 | H21: =H19*H20 | I21: =I19*I20 | J21: =J19*J20 | ... L21: =L19*L20
A22: Lease cost (negative) | B22: -0.0466 | C22: =-C6*Assumptions!$B$5 | D22: =-D6*Assumptions!$B$5 | E22: =-E6*Assumptions!$B$5 | F22: =-F6*Assumptions!$B$5 | G22: =-G6*Assumptions!$B$5 | H22: =-H6*Assumptions!$B$5 | I22: =-I6*Assumptions!$B$5 | J22: =-J6*Assumptions!$B$5 | ... L22: =-L6*Assumptions!$B$5
A23: Memo: FCF before SBC | C23: =C19-C10 | D23: =D19-D10 | E23: =E19-E10 | F23: =F19-F10 | G23: =G19-G10 | H23: =H19-H10 | I23: =I19-I10 | J23: =J19-J10 | ... L23: =L19-L10
A24: Memo: owner-FCF margin | B24: =B19/B6 | C24: =C19/C6 | D24: =D19/D6 | E24: =E19/E6 | F24: =F19/F6 | G24: =G19/G6 | H24: =H19/H6 | I24: =I19/I6 | ... L24: =L19/L6
A25: Capex % of revenue | B25: =-B17/B6 | C25: 0.15 | D25: 0.11 | E25: 0.08 | F25: 0.07 | G25: 0.06 | H25: 0.06 | I25: 0.055 | J25: 0.055 | K25: 0.055 | L25: 0.055
A26: Sum of PV of FCF | B26: =SUM(C21:L21)
A27: Terminal growth | B27: =Assumptions!$C$17
A28: Terminal-year FCF x (1+g) | B28: =L19*(1+B27)
A29: Gordon terminal value | B29: =B28/(Assumptions!$B$3-B27)
A30: Cap terminal value | B30: =Assumptions!$B$10*L19
A31: Terminal value used = MAX(0, MIN(Gordon, cap)) | B31: =MAX(0,MIN(B29,B30))
A32: Implied exit multiple (TV / FCF10) | B32: =IF(L19>0,B31/L19,"n/a")
A33: PV of terminal value | B33: =B31*L20
A34: Enterprise value | B34: =B26+B33
A35: add net cash | B35: =Assumptions!$B$7
A36: Equity value | B36: =B34+B35
A37: Diluted shares (m) | B37: =Assumptions!$B$8
A38: Value per share (NZD) | B38: =B36/B37
A39: Upside vs price | B39: =B38/Assumptions!$B$9-1
A41: Street memo: PV of explicit SBC | B41: =SUMPRODUCT(-C10:L10/(1+Assumptions!$B$3)^C4:L4)
A42: Street memo: PV of terminal SBC | B42: =(-L10*(1+B27)/(Assumptions!$B$3-B27))*L20
...

Sheet FCF_Quality
A1: Reported FCF reconciled to owner FCF (NZD m)
A3: Year | B3: FY2021 | C3: FY2022 | D3: FY2023 | E3: FY2024 | F3: FY2025 | G3: FY2026
A4: Revenue | B4: 1.642 | C4: 3.878 | D4: 4.92 | E4: 6.179 | F4: 8.031 | G4: 9.609
A5: Free cash flow (company definition: OCF - PPE - intangibles) | B5: -4.694 | C5: -8.836 | D5: -10.981 | E5: -5.766 | F5: -1.583 | G5: -2.01
A6: less: SBC expense | B6: -0.285 | C6: -0.089 | D6: -0.189 | E6: -0.205 | F6: -0.141 | G6: -0.035
A7: less: interest income | B7: -0.001 | C7: -0.012 | D7: -0.114 | E7: -0.08 | F7: -0.021 | G7: -0.02
A8: less: lease cash (principal + interest) | B8: -0.008 | C8: -0.053 | D8: -0.059 | E8: -0.299 | F8: -0.104 | G8: -0.047
A9: Owner FCF (sum of the four lines above) | B9: =SUM(B5:B8) | C9: =SUM(C5:C8) | D9: =SUM(D5:D8) | E9: =SUM(E5:E8) | F9: =SUM(F5:F8) | G9: =SUM(G5:G8)
A10: Reported FCF margin | B10: =B5/B4 | C10: =C5/C4 | D10: =D5/D4 | E10: =E5/E4 | F10: =F5/F4 | G10: =G5/G4
A11: Owner FCF margin | B11: =B9/B4 | C11: =C9/C4 | D11: =D9/D4 | E11: =E9/E4 | F11: =F9/F4 | G11: =G9/G4
A12: Memo: cash tax | B12: nil (losses) | C12: nil (losses) | D12: nil (losses) | E12: nil (losses) | F12: nil (losses) | G12: nil (losses)
A13: Memo: SBC basis | B13: reserve (CSV) | C13: reserve (CSV) | D13: reserve (CSV) | E13: reserve movement | F13: expense, note 26 | G13: expense, note 26
A15: Note: FY26 R&D-loss cash-out clawback contingency NZ$1.036m (note 9) not in any line. Deferred-revenue movement is negative in FY26 (-0.011) -- no working-capital tailwind inside OCF.

Sheet Valuation
A1: Valuation summary (NZD per share)
A3: Scenario | B3: Value/share | C3: Upside vs price | D3: Probability | E3: Street value/share | F3: Entry price @ hurdle | G3: TV zero-floor?
A4: bear | B4: =DCF_Bear!$B$38 | C4: =B4/Assumptions!$B$9-1 | D4: =Assumptions!$D$15 | E4: =DCF_Bear!$B$43 | F4: =(SUMPRODUCT(DCF_Bear!$C$19:$L$19/(1+Assumptions!$B$11)^DCF_Bear!$C$4:$L$4)+MAX(0,MIN(DCF_Bear!$L$19*(1+Assumptions!$C$15)/(Assumptions!$B$11-Assumptions!$C$15),Assumptions!$B$10*DCF_Bear!$L$19))/(1+Assumptions!$B$11)^10+Assumptions!$B$7)/Assumptions!$B$8 | G4: =DCF_Bear!$B$46
A5: base | B5: =DCF_Base!$B$38 | C5: =B5/Assumptions!$B$9-1 | D5: =Assumptions!$D$16 | E5: =DCF_Base!$B$43 | F5: =(SUMPRODUCT(DCF_Base!$C$19:$L$19/(1+Assumptions!$B$11)^DCF_Base!$C$4:$L$4)+MAX(0,MIN(DCF_Base!$L$19*(1+Assumptions!$C$16)/(Assumptions!$B$11-Assumptions!$C$16),Assumptions!$B$10*DCF_Base!$L$19))/(1+Assumptions!$B$11)^10+Assumptions!$B$7)/Assumptions!$B$8 | G5: =DCF_Base!$B$46
A6: bull | B6: =DCF_Bull!$B$38 | C6: =B6/Assumptions!$B$9-1 | D6: =Assumptions!$D$17 | E6: =DCF_Bull!$B$43 | F6: =(SUMPRODUCT(DCF_Bull!$C$19:$L$19/(1+Assumptions!$B$11)^DCF_Bull!$C$4:$L$4)+MAX(0,MIN(DCF_Bull!$L$19*(1+Assumptions!$C$17)/(Assumptions!$B$11-Assumptions!$C$17),Assumptions!$B$10*DCF_Bull!$L$19))/(1+Assumptions!$B$11)^10+Assumptions!$B$7)/Assumptions!$B$8 | G6: =DCF_Bull!$B$46
A8: Probability-weighted value | B8: =SUMPRODUCT(B4:B6,D4:D6)
A9: Current price | B9: =Assumptions!$B$9
A10: Margin of safety (1 - price/weighted) | B10: =1-B9/B8
A11: Street weighted value | B11: =SUMPRODUCT(E4:E6,D4:D6)
A12: Band position (price-house)/(street-house) | B12: =IF(ABS(B11-B8)<0.001,"n/a (band collapsed)",(B9-B8)/(B11-B8))
A13: Weighted entry price @ hurdle (buy-below) | B13: =SUMPRODUCT(F4:F6,D4:D6)
A14: Weights check | B14: =Assumptions!$D$18
A16: Required-return table (base case; TV rebuilt at each rate)
A17: Required return | B17: Value/share
A18: 0.09 | B18: =(SUMPRODUCT(DCF_Base!$C$19:$L$19/(1+$A$18)^DCF_Base!$C$4:$L$4)+MAX(0,MIN(DCF_Base!$L$19*(1+Assumptions!$C$16)/($A$18-Assumptions!$C$16),Assumptions!$B$10*DCF_Base!$L$19))/(1+$A$18)^10+Assumptions!$B$7)/Assumptions!$B$8
A19: 0.1 | B19: =(SUMPRODUCT(DCF_Base!$C$19:$L$19/(1+$A$19)^DCF_Base!$C$4:$L$4)+MAX(0,MIN(DCF_Base!$L$19*(1+Assumptions!$C$16)/($A$19-Assumptions!$C$16),Assumptions!$B$10*DCF_Base!$L$19))/(1+$A$19)^10+Assumptions!$B$7)/Assumptions!$B$8
A20: 0.11 | B20: =(SUMPRODUCT(DCF_Base!$C$19:$L$19/(1+$A$20)^DCF_Base!$C$4:$L$4)+MAX(0,MIN(DCF_Base!$L$19*(1+Assumptions!$C$16)/($A$20-Assumptions!$C$16),Assumptions!$B$10*DCF_Base!$L$19))/(1+$A$20)^10+Assumptions!$B$7)/Assumptions!$B$8
A21: 0.12 | B21: =(SUMPRODUCT(DCF_Base!$C$19:$L$19/(1+$A$21)^DCF_Base!$C$4:$L$4)+MAX(0,MIN(DCF_Base!$L$19*(1+Assumptions!$C$16)/($A$21-Assumptions!$C$16),Assumptions!$B$10*DCF_Base!$L$19))/(1+$A$21)^10+Assumptions!$B$7)/Assumptions!$B$8
A22: =Assumptions!$B$3 | B22: =(SUMPRODUCT(DCF_Base!$C$19:$L$19/(1+$A$22)^DCF_Base!$C$4:$L$4)+MAX(0,MIN(DCF_Base!$L$19*(1+Assumptions!$C$16)/($A$22-Assumptions!$C$16),Assumptions!$B$10*DCF_Base!$L$19))/(1+$A$22)^10+Assumptions!$B$7)/Assumptions!$B$8
A23: 0.15 | B23: =(SUMPRODUCT(DCF_Base!$C$19:$L$19/(1+$A$23)^DCF_Base!$C$4:$L$4)+MAX(0,MIN(DCF_Base!$L$19*(1+Assumptions!$C$16)/($A$23-Assumptions!$C$16),Assumptions!$B$10*DCF_Base!$L$19))/(1+$A$23)^10+Assumptions!$B$7)/Assumptions!$B$8
A26: Sensitivity: base value/share, WACC (rows) x terminal growth (columns)
B27: 0.02 | C27: 0.025 | D27: 0.03 | E27: 0.035 | F27: 0.04
A28: 0.12 | B28: =IF($A28>B$27,(SUMPRODUCT(DCF_Base!$C$19:$L$19/(1+$A28)^DCF_Base!$C$4:$L$4)+MAX(0,MIN(DCF_Base!$L$19*(1+B$27)/($A28-B$27),Assumptions!$B$10*DCF_Base!$L$19))/(1+$A28)^10+Assumptions!$B$7)/Assumptions!$B$8,"n/a") | C28: =IF($A28>C$27,(SUMPRODUCT(DCF_Base!$C$19:$L$19/(1+$A28)^DCF_Base!$C$4:$L$4)+MAX(0,MIN(DCF_Base!$L$19*(1+C$27)/($A28-C$27),Assumptions!$B$10*DCF_Base!$L$19))/(1+$A28)^10+Assumptions!$B$7)/Assumptions!$B$8,"n/a") | D28: =IF($A28>D$27,(SUMPRODUCT(DCF_Base!$C$19:$L$19/(1+$A28)^DCF_Base!$C$4:$L$4)+MAX(0,MIN(DCF_Base!$L$19*(1+D$27)/($A28-D$27),Assumptions!$B$10*DCF_Base!$L$19))/(1+$A28)^10+Assumptions!$B$7)/Assumptions!$B$8,"n/a") | E28: =IF($A28>E$27,(SUMPRODUCT(DCF_Base!$C$19:$L$19/(1+$A28)^DCF_Base!$C$4:$L$4)+MAX(0,MIN(DCF_Base!$L$19*(1+E$27)/($A28-E$27),Assumptions!$B$10*DCF_Base!$L$19))/(1+$A28)^10+Assumptions!$B$7)/Assumptions!$B$8,"n/a") | F28: =IF($A28>F$27,(SUMPRODUCT(DCF_Base!$C$19:$L$19/(1+$A28)^DCF_Base!$C$4:$L$4)+MAX(0,MIN(DCF_Base!$L$19*(1+F$27)/($A28-F$27),Assumptions!$B$10*DCF_Base!$L$19))/(1+$A28)^10+Assumptions!$B$7)/Assumptions!$B$8,"n/a")
A29: 0.13 | B29: =IF($A29>B$27,(SUMPRODUCT(DCF_Base!$C$19:$L$19/(1+$A29)^DCF_Base!$C$4:$L$4)+MAX(0,MIN(DCF_Base!$L$19*(1+B$27)/($A29-B$27),Assumptions!$B$10*DCF_Base!$L$19))/(1+$A29)^10+Assumptions!$B$7)/Assumptions!$B$8,"n/a") | C29: =IF($A29>C$27,(SUMPRODUCT(DCF_Base!$C$19:$L$19/(1+$A29)^DCF_Base!$C$4:$L$4)+MAX(0,MIN(DCF_Base!$L$19*(1+C$27)/($A29-C$27),Assumptions!$B$10*DCF_Base!$L$19))/(1+$A29)^10+Assumptions!$B$7)/Assumptions!$B$8,"n/a") | D29: =IF($A29>D$27,(SUMPRODUCT(DCF_Base!$C$19:$L$19/(1+$A29)^DCF_Base!$C$4:$L$4)+MAX(0,MIN(DCF_Base!$L$19*(1+D$27)/($A29-D$27),Assumptions!$B$10*DCF_Base!$L$19))/(1+$A29)^10+Assumptions!$B$7)/Assumptions!$B$8,"n/a") | E29: =IF($A29>E$27,(SUMPRODUCT(DCF_Base!$C$19:$L$19/(1+$A29)^DCF_Base!$C$4:$L$4)+MAX(0,MIN(DCF_Base!$L$19*(1+E$27)/($A29-E$27),Assumptions!$B$10*DCF_Base!$L$19))/(1+$A29)^10+Assumptions!$B$7)/Assumptions!$B$8,"n/a") | F29: =IF($A29>F$27,(SUMPRODUCT(DCF_Base!$C$19:$L$19/(1+$A29)^DCF_Base!$C$4:$L$4)+MAX(0,MIN(DCF_Base!$L$19*(1+F$27)/($A29-F$27),Assumptions!$B$10*DCF_Base!$L$19))/(1+$A29)^10+Assumptions!$B$7)/Assumptions!$B$8,"n/a")
A30: 0.14 | B30: =IF($A30>B$27,(SUMPRODUCT(DCF_Base!$C$19:$L$19/(1+$A30)^DCF_Base!$C$4:$L$4)+MAX(0,MIN(DCF_Base!$L$19*(1+B$27)/($A30-B$27),Assumptions!$B$10*DCF_Base!$L$19))/(1+$A30)^10+Assumptions!$B$7)/Assumptions!$B$8,"n/a") | C30: =IF($A30>C$27,(SUMPRODUCT(DCF_Base!$C$19:$L$19/(1+$A30)^DCF_Base!$C$4:$L$4)+MAX(0,MIN(DCF_Base!$L$19*(1+C$27)/($A30-C$27),Assumptions!$B$10*DCF_Base!$L$19))/(1+$A30)^10+Assumptions!$B$7)/Assumptions!$B$8,"n/a") | D30: =IF($A30>D$27,(SUMPRODUCT(DCF_Base!$C$19:$L$19/(1+$A30)^DCF_Base!$C$4:$L$4)+MAX(0,MIN(DCF_Base!$L$19*(1+D$27)/($A30-D$27),Assumptions!$B$10*DCF_Base!$L$19))/(1+$A30)^10+Assumptions!$B$7)/Assumptions!$B$8,"n/a") | E30: =IF($A30>E$27,(SUMPRODUCT(DCF_Base!$C$19:$L$19/(1+$A30)^DCF_Base!$C$4:$L$4)+MAX(0,MIN(DCF_Base!$L$19*(1+E$27)/($A30-E$27),Assumptions!$B$10*DCF_Base!$L$19))/(1+$A30)^10+Assumptions!$B$7)/Assumptions!$B$8,"n/a") | F30: =IF($A30>F$27,(SUMPRODUCT(DCF_Base!$C$19:$L$19/(1+$A30)^DCF_Base!$C$4:$L$4)+MAX(0,MIN(DCF_Base!$L$19*(1+F$27)/($A30-F$27),Assumptions!$B$10*DCF_Base!$L$19))/(1+$A30)^10+Assumptions!$B$7)/Assumptions!$B$8,"n/a")
A31: 0.15 | B31: =IF($A31>B$27,(SUMPRODUCT(DCF_Base!$C$19:$L$19/(1+$A31)^DCF_Base!$C$4:$L$4)+MAX(0,MIN(DCF_Base!$L$19*(1+B$27)/($A31-B$27),Assumptions!$B$10*DCF_Base!$L$19))/(1+$A31)^10+Assumptions!$B$7)/Assumptions!$B$8,"n/a") | C31: =IF($A31>C$27,(SUMPRODUCT(DCF_Base!$C$19:$L$19/(1+$A31)^DCF_Base!$C$4:$L$4)+MAX(0,MIN(DCF_Base!$L$19*(1+C$27)/($A31-C$27),Assumptions!$B$10*DCF_Base!$L$19))/(1+$A31)^10+Assumptions!$B$7)/Assumptions!$B$8,"n/a") | D31: =IF($A31>D$27,(SUMPRODUCT(DCF_Base!$C$19:$L$19/(1+$A31)^DCF_Base!$C$4:$L$4)+MAX(0,MIN(DCF_Base!$L$19*(1+D$27)/($A31-D$27),Assumptions!$B$10*DCF_Base!$L$19))/(1+$A31)^10+Assumptions!$B$7)/Assumptions!$B$8,"n/a") | E31: =IF($A31>E$27,(SUMPRODUCT(DCF_Base!$C$19:$L$19/(1+$A31)^DCF_Base!$C$4:$L$4)+MAX(0,MIN(DCF_Base!$L$19*(1+E$27)/($A31-E$27),Assumptions!$B$10*DCF_Base!$L$19))/(1+$A31)^10+Assumptions!$B$7)/Assumptions!$B$8,"n/a") | F31: =IF($A31>F$27,(SUMPRODUCT(DCF_Base!$C$19:$L$19/(1+$A31)^DCF_Base!$C$4:$L$4)+MAX(0,MIN(DCF_Base!$L$19*(1+F$27)/($A31-F$27),Assumptions!$B$10*DCF_Base!$L$19))/(1+$A31)^10+Assumptions!$B$7)/Assumptions!$B$8,"n/a")
A32: 0.16 | B32: =IF($A32>B$27,(SUMPRODUCT(DCF_Base!$C$19:$L$19/(1+$A32)^DCF_Base!$C$4:$L$4)+MAX(0,MIN(DCF_Base!$L$19*(1+B$27)/($A32-B$27),Assumptions!$B$10*DCF_Base!$L$19))/(1+$A32)^10+Assumptions!$B$7)/Assumptions!$B$8,"n/a") | C32: =IF($A32>C$27,(SUMPRODUCT(DCF_Base!$C$19:$L$19/(1+$A32)^DCF_Base!$C$4:$L$4)+MAX(0,MIN(DCF_Base!$L$19*(1+C$27)/($A32-C$27),Assumptions!$B$10*DCF_Base!$L$19))/(1+$A32)^10+Assumptions!$B$7)/Assumptions!$B$8,"n/a") | D32: =IF($A32>D$27,(SUMPRODUCT(DCF_Base!$C$19:$L$19/(1+$A32)^DCF_Base!$C$4:$L$4)+MAX(0,MIN(DCF_Base!$L$19*(1+D$27)/($A32-D$27),Assumptions!$B$10*DCF_Base!$L$19))/(1+$A32)^10+Assumptions!$B$7)/Assumptions!$B$8,"n/a") | E32: =IF($A32>E$27,(SUMPRODUCT(DCF_Base!$C$19:$L$19/(1+$A32)^DCF_Base!$C$4:$L$4)+MAX(0,MIN(DCF_Base!$L$19*(1+E$27)/($A32-E$27),Assumptions!$B$10*DCF_Base!$L$19))/(1+$A32)^10+Assumptions!$B$7)/Assumptions!$B$8,"n/a") | F32: =IF($A32>F$27,(SUMPRODUCT(DCF_Base!$C$19:$L$19/(1+$A32)^DCF_Base!$C$4:$L$4)+MAX(0,MIN(DCF_Base!$L$19*(1+F$27)/($A32-F$27),Assumptions!$B$10*DCF_Base!$L$19))/(1+$A32)^10+Assumptions!$B$7)/Assumptions!$B$8,"n/a")
A35: Cash runway memo (base case, no new equity): net cash after each year's owner FCF
A36: Year | B36: =DCF_Base!C3 | C36: =DCF_Base!D3 | D36: =DCF_Base!E3 | E36: =DCF_Base!F3 | F36: =DCF_Base!G3 | G36: =DCF_Base!H3 | H36: =DCF_Base!I3 | I36: =DCF_Base!J3 | ... K36: =DCF_Base!L3
A37: Net cash end of year | B37: =Assumptions!$B$7+DCF_Base!C19 | C37: =B37+DCF_Base!D19 | D37: =C37+DCF_Base!E19 | E37: =D37+DCF_Base!F19 | F37: =E37+DCF_Base!G19 | G37: =F37+DCF_Base!H19 | H37: =G37+DCF_Base!I19 | I37: =H37+DCF_Base!J19 | J37: =I37+DCF_Base!K19 | K37: =J37+DCF_Base!L19
A38: Trough | B38: =MIN(B37:K37)
A39: Raise needed at current price to fund trough + NZ$1m buffer (NZD m) | B39: =MAX(0,-B38)+1
A40: New shares at current price (m) | B40: =B39/Assumptions!$B$9
A41: Base value/share AFTER such a raise | B41: =(DCF_Base!$B$36+B39)/(Assumptions!$B$8+B40)
A43: EV/ARR memo
A44: Market cap (basic shares) | B44: =Assumptions!$B$9*163.605
A45: EV at market | B45: =B44-Assumptions!$B$7
A46: ARR (NZ$m, Jun-2026) | B46: 10.4
A47: EV/ARR at market | B47: =B45/B46
A48: EV/ARR implied by base DCF | B48: =DCF_Base!$B$34/B46
