Workbook

Sheet Model_Info
A1: APA Group (APA.AX) owner-FCF component DCF
A2: Version 1.0, 2026-09-21. First valuation of this ticker; supersedes nothing.
A3: Built by the dcf-analyst agent (Claude Fable 5.1) on 2026-09-21 at the research-stock orchestrator's request.
A5: DATA VINTAGE (all figures go stale -- refresh after the next print)
A6: Price: A$10.87, Yahoo Finance APA.AX regular close 2026-09-21T06:10:31Z.
A7: Balance sheet: 30 June 2026 (FY26 Annual Report). Drawn debt 14,230 (face), leases 65, cash 1,636 -> net debt 12,659.
A8: Share count: 1,323.75m on issue 30-Jun-2026 + ~6m performance rights = 1,330m diluted; held flat (DRP issuance funds capex already in the flows).
A9: Guidance: FY26 results 20-Aug-2026 -- FY27 Underlying EBITDA $2,260-2,340m, FY27 DPS 59.0c, FY27-29 growth capex pipeline ~$3.5bn.
A10: History: APA.AX_Metrics.csv (core_metrics), FY2016-FY2026, AUD millions, 30 June year end.
A12: METHODOLOGY
A13: Model: unlevered owner-FCF DCF built from components (revenue x EBITDA margin - SBC - D&A -> tax on EBIT -> + D&A - capex + WC), 10-year horizon, end-of-year discounting at a 7.0% AUD WACC.
A14: Terminal value: MAX(0, MIN(Gordon, 18x terminal FCF)). Cap 18x (house default 20x) because APA is a structurally slow grower; the cap binds in base and bull. The market price sits at the UNCAPPED Gordon value.
... A29: CELL COLOURS: blue = hardcoded input; yellow fill = key lever; black = formula; green = cross-sheet link. Sheet names contain no spaces. No text cell begins with '='.

Sheet Actuals
A1: Reported history, AUD millions (source: APA.AX_Metrics.csv from core_metrics; FY26 AR for capex split, SBC, cash tax)
A3: Line | B3: FY2021 | C3: FY2022 | D3: FY2023 | E3: FY2024 | F3: FY2025 | G3: FY2026
A4: Revenue (statutory, incl. pass-through) | B4: 2605.3 | C4: 2705.04 | D4: 2890 | E4: 3039 | F4: 3179 | G4: 2977
A5: Revenue ex pass-through | B5: 2144.5 | C5: 2236.6 | D5: 2401 | E5: 2591 | F5: 2716 | G5: 2803
A6: Underlying EBITDA | B6: 1628.8 | C6: 1692.3 | D6: 1725 | E6: 1893 | F6: 2015 | G6: 2183
A7: Reported EBITDA | B7: 1638.8 | C7: 1630.2 | D7: 1686 | E7: 1736 | F7: 1894 | G7: 2095
A8: D&A | B8: 674.4 | C8: 735.178 | D8: 750 | E8: 919 | F8: 990 | G8: 1042
A9: Net interest expense | B9: 483 | C9: 459 | D9: 579 | E9: 657 | F9: 657 | G9: 653
A10: Statutory NPAT | B10: 0.7 | C10: 259.7 | D10: 287 | E10: 998 | F10: 129 | G10: 234
A11: Operating cash flow | B11: 1050.958 | C11: 1197.268 | D11: 1206 | E11: 1156 | F11: 1284 | G11: 1252
A12: Capex (total, PPE + intangibles) | B12: 432.928 | C12: 689.045 | D12: 1180 | E12: 1096 | F12: 964 | G12: 845
A13: Company FCF (OCF - SIB capex, post-interest) | B13: 901.9 | C13: 1080.6 | D13: 1070 | E13: 1073 | F13: 1083 | G13: 1118
A14: Equity settled LTI (SBC) | B14: 2 | C14: 3 | D14: 3 | E14: 2 | F14: 4 | G14: 4
A15: Cash taxes paid | C15: 42.715 | D15: 22 | E15: 52 | F15: 74 | G15: 158
A16: Total debt (carrying) | B16: 9924.038 | C16: 10904.32 | D16: 11523 | E16: 12922 | F16: 13977 | G16: 14087
A17: Cash | B17: 652.352 | C17: 940.129 | D17: 513 | E17: 676 | F17: 800 | G17: 1636
A18: Shareholders equity | B18: 2950.978 | C18: 2628.445 | D18: 1910 | E18: 3248 | F18: 2668 | G18: 2699
A19: Securities (m) | B19: 1179.894 | C19: 1179.894 | D19: 1180 | E19: 1265 | F19: 1295 | G19: 1316
A20: DPS (cents) | B20: 51 | C20: 53 | D20: 55 | E20: 56 | F20: 57 | G20: 58
A23: Balance sheet snapshot 30-Jun-2026
A24: Total drawn debt (face, AR KPI table) | B24: 14230
A25: Lease liabilities (note 17) | B25: 65
A26: Cash and equivalents | B26: 1636
A27: Net debt used in model | B27: 12659
A28: Securities on issue 30-Jun-2026 (m) | B28: 1323.751
A29: Diluted count used (m) | B29: 1330
A30: FY26 capex split: SIB / growth / foundation | B30: 210 / 546 / 89
A31: FY26 DRP issuance ($m) | B31: 162
A32: Buybacks | B32: 0
A33: FY27 guidance: Underlying EBITDA ($m) | B33: 2,260 - 2,340
A34: FY27 guidance: DPS (cents) | B34: 59
A35: FY27-29 organic growth capex pipeline ($bn) | B35: 3.5
A36: Average interest rate on drawn debt FY26 | B36: 0.0532

Sheet Assumptions
A1: Global assumptions (blue = input, yellow = key lever)
A4: WACC (AUD-built) | B4: 0.07 | C4: rf 4.4% + 0.9 x 5.5% ERP = 9.35% CoE; Kd 5.6% pre-tax; 53/47 E/D at market -> 6.8%, house 7.0%
A5: Working-capital capture (% of revenue change) | B5: 0 | C5: APA WC movements are small and non-directional
A6: Net debt (AUD m, 30-Jun-2026) | B6: 12659 | C6: drawn debt 14,230 + leases 65 - cash 1,636
A7: Diluted securities (m) | B7: 1330 | C7: 1,323.75m on issue + ~6m performance rights; held flat
A8: Price (AUD) | B8: 10.87 | C8: 2026-09-21T06:10:31Z regular close (ASX)
A9: Terminal value cap (x terminal FCF) | B9: 18 | C9: below house 20x for a structurally slow grower; equals ~18.5x the market pays on FY26 pre-growth-capex unlevered FCF
A10: Hurdle rate for entry price | B10: 0.15 | C10: house standard
A12: Scenario | B12: Terminal growth | C12: Probability | D12: Rationale
A13: bear | B13: 0.01 | C13: 0.25 | D13: 25%: leverage 5.8x turns a modest EV miss into a large equity miss; gas-transition and regulatory-reset risk are structural
A14: base | B14: 0.025 | C14: 0.5 | D14: 50%
A15: bull | B15: 0.03 | C15: 0.25 | D15: 25%: needs Beetaloo, ECGG 4-5, GPG and data-centre load all to convert; pipeline historically spent slower than announced
A16: Weights check (must be 100%) | C16: =SUM(C13:C15)
A18: BASE: FY27 at the guidance midpoint; CPI-linked tariffs plus Sturt Plateau, ECGG Stage 3 and Brigalow hold revenue growth at 4% through FY30, fading to 2.5%. Margin 72.4% to 73.5% on statutory revenue; $60m/yr recurring leakage. Growth capex ~$650-700m/yr FY27-29 then tapers to replacement level. 18x cap binds.
A19: BULL: ECGG 3-5, Beetaloo/NEAP, Pilbara and GPG firming convert at >150bp above WACC; data-centre load adds contracted growth. 5% growth through FY30, margin to 75%, capex higher early (33%), terminal growth 3.0%. 18x cap binds.
A20: BEAR: gas demand declines early, AER tightens allowed returns at the next resets, reservation/price-cap policy hits shippers. Growth fades to 1%, margin to 69%, capex stays 20% of revenue, terminal growth 1.0%. Gordon (16.8x) binds. Equity falls 53% on a 24% EV miss because of leverage.

Sheet DCF_Bear
A1: DCF_Bear: unlevered owner-FCF build, AUD millions. Drivers (blue/yellow) in rows 5, 7, 9, 14, 45, 46.
A3: Year | B3: 2026A | C3: 2027E | D3: 2028E | E3: 2029E | F3: 2030E | G3: 2031E | H3: 2032E | I3: 2033E | J3: 2034E | K3: 2035E | L3: 2036E
A4: Index | B4: 0 | C4: 1 | D4: 2 | E4: 3 | F4: 4 | G4: 5 | H4: 6 | I4: 7 | J4: 8 | K4: 9 | L4: 10
A5: Revenue growth YoY | C5: 0.025 | D5: 0.02 | E5: 0.02 | F5: 0.015 | G5: 0.015 | H5: 0.01 | I5: 0.01 | J5: 0.01 | K5: 0.01 | L5: 0.01
A6: Revenue | B6: 2977 | C6: =B6*(1+C5) | D6: =C6*(1+D5) | E6: =D6*(1+E5) | F6: =E6*(1+F5) | G6: =F6*(1+G5) | H6: =G6*(1+H5) | I6: =H6*(1+I5) | J6: =I6*(1+J5) | ... L6: =K6*(1+L5)
A7: Adj EBITDA margin | C7: 0.715 | D7: 0.71 | E7: 0.705 | F7: 0.7 | G7: 0.7 | H7: 0.695 | I7: 0.69 | J7: 0.69 | K7: 0.69 | L7: 0.69
A8: Adjusted EBITDA | B8: 2123 | C8: =C6*C7 | D8: =D6*D7 | E8: =E6*E7 | F8: =F6*F7 | G8: =G6*G7 | H8: =H6*H7 | I8: =I6*I7 | J8: =J6*J7 | ... L8: =L6*L7
A9: SBC % of revenue | C9: 0.00134 | D9: 0.00134 | E9: 0.00134 | F9: 0.00134 | G9: 0.00134 | H9: 0.00134 | I9: 0.00134 | J9: 0.00134 | K9: 0.00134 | L9: 0.00134
A10: SBC (negative) | B10: -4 | C10: =-C6*C9 | D10: =-D6*D9 | E10: =-E6*E9 | F10: =-F6*F9 | G10: =-G6*G9 | H10: =-H6*H9 | I10: =-I6*I9 | J10: =-J6*J9 | ... L10: =-L6*L9
A11: Owner EBITDA | C11: =C8+C10 | D11: =D8+D10 | E11: =E8+E10 | F11: =F8+F10 | G11: =G8+G10 | H11: =H8+H10 | I11: =I8+I10 | J11: =J8+J10 | ... L11: =L8+L10
A12: D&A (negative) | B12: -1042 | C12: =-C6*C45 | D12: =-D6*D45 | E12: =-E6*E45 | F12: =-F6*F45 | G12: =-G6*G45 | H12: =-H6*H45 | I12: =-I6*I45 | J12: =-J6*J45 | ... L12: =-L6*L45
A13: EBIT (SBC expensed) | C13: =C11+C12 | D13: =D11+D12 | E13: =E11+E12 | F13: =F11+F12 | G13: =G11+G12 | H13: =H11+H12 | I13: =I11+I12 | J13: =J11+J12 | ... L13: =L11+L12
A14: Cash tax rate on EBIT | C14: 0.33 | D14: 0.33 | E14: 0.33 | F14: 0.33 | G14: 0.33 | H14: 0.32 | I14: 0.32 | J14: 0.32 | K14: 0.31 | L14: 0.31
A15: NOPAT | C15: =C13-MAX(0,C13)*C14 | D15: =D13-MAX(0,D13)*D14 | E15: =E13-MAX(0,E13)*E14 | F15: =F13-MAX(0,F13)*F14 | G15: =G13-MAX(0,G13)*G14 | H15: =H13-MAX(0,H13)*H14 | I15: =I13-MAX(0,I13)*I14 | J15: =J13-MAX(0,J13)*J14 | ... L15: =L13-MAX(0,L13)*L14
A16: Add back D&A | C16: =-C12 | D16: =-D12 | E16: =-E12 | F16: =-F12 | G16: =-G12 | H16: =-H12 | I16: =-I12 | J16: =-J12 | ... L16: =-L12
A17: Less capex | B17: -845 | C17: =-C6*C46 | D17: =-D6*D46 | E17: =-E6*E46 | F17: =-F6*F46 | G17: =-G6*G46 | H17: =-H6*H46 | I17: =-I6*I46 | J17: =-J6*J46 | ... L17: =-L6*L46
A18: Add working capital | C18: =Assumptions!$B$5*(C6-B6) | D18: =Assumptions!$B$5*(D6-C6) | E18: =Assumptions!$B$5*(E6-D6) | F18: =Assumptions!$B$5*(F6-E6) | G18: =Assumptions!$B$5*(G6-F6) | H18: =Assumptions!$B$5*(H6-G6) | I18: =Assumptions!$B$5*(I6-H6) | J18: =Assumptions!$B$5*(J6-I6) | ... L18: =Assumptions!$B$5*(L6-K6)
A19: Unlevered owner FCF | C19: =C15+C16+C17+C18 | D19: =D15+D16+D17+D18 | E19: =E15+E16+E17+E18 | F19: =F15+F16+F17+F18 | G19: =G15+G16+G17+G18 | H19: =H15+H16+H17+H18 | I19: =I15+I16+I17+I18 | J19: =J15+J16+J17+J18 | ... L19: =L15+L16+L17+L18
A20: Discount factor | C20: =1/(1+Assumptions!$B$4)^C4 | D20: =1/(1+Assumptions!$B$4)^D4 | E20: =1/(1+Assumptions!$B$4)^E4 | F20: =1/(1+Assumptions!$B$4)^F4 | G20: =1/(1+Assumptions!$B$4)^G4 | H20: =1/(1+Assumptions!$B$4)^H4 | I20: =1/(1+Assumptions!$B$4)^I4 | J20: =1/(1+Assumptions!$B$4)^J4 | ... L20: =1/(1+Assumptions!$B$4)^L4
A21: PV of FCF | C21: =C19*C20 | D21: =D19*D20 | E21: =E19*E20 | F21: =F19*F20 | G21: =G19*G20 | H21: =H19*H20 | I21: =I19*I20 | J21: =J19*J20 | ... L21: =L19*L20
A23: Memo: FCF before SBC (company-style) | C23: =C19-C10 | D23: =D19-D10 | E23: =E19-E10 | F23: =F19-F10 | G23: =G19-G10 | H23: =H19-H10 | I23: =I19-I10 | J23: =J19-J10 | ... L23: =L19-L10
A24: Memo: owner-FCF margin | C24: =C19/C6 | D24: =D19/D6 | E24: =E19/E6 | F24: =F19/F6 | G24: =G19/G6 | H24: =H19/H6 | I24: =I19/I6 | J24: =J19/J6 | ... L24: =L19/L6
A26: Sum of PV (explicit years) | B26: =SUM(C21:L21)
A27: Terminal growth | B27: =Assumptions!$B$13
A28: Terminal-year FCF x (1+g) | B28: =L19*(1+B27)
A29: Gordon terminal value | B29: =IF(Assumptions!$B$4>B27,B28/(Assumptions!$B$4-B27),1E+12)
A30: Cap terminal value | B30: =Assumptions!$B$9*L19
A31: Terminal value used | B31: =MAX(0,MIN(B29,B30))
A32: Implied exit multiple (x FCF) | B32: =IF(L19<>0,B31/L19,0)
A33: PV of terminal value | B33: =B31*L20
A34: Enterprise value | B34: =B26+B33
A35: Less net debt | B35: =-Assumptions!$B$6
A36: Equity value | B36: =B34+B35
A37: Diluted securities (m) | B37: =Assumptions!$B$7
A38: VALUE PER SECURITY (AUD) | B38: =B36/B37
A39: Upside vs price | B39: =B38/Assumptions!$B$8-1
A41: Street memo: PV of explicit SBC | B41: =SUMPRODUCT(-C10:L10/(1+Assumptions!$B$4)^C4:L4)
A42: Street memo: PV of terminal SBC | B42: =IF(Assumptions!$B$4>B27,(-L10*(1+B27)/(Assumptions!$B$4-B27))*L20,0)
A43: Street value per security | B43: =(B36+B41+B42)/B37
A45: D&A % of revenue (driver) | C45: 0.34 | D45: 0.335 | E45: 0.33 | F45: 0.32 | G45: 0.31 | H45: 0.3 | I45: 0.28 | J45: 0.26 | K45: 0.24 | L45: 0.23
...

Sheet DCF_Base
A1: DCF_Base: unlevered owner-FCF build, AUD millions. Drivers (blue/yellow) in rows 5, 7, 9, 14, 45, 46.
A3: Year | B3: 2026A | C3: 2027E | D3: 2028E | E3: 2029E | F3: 2030E | G3: 2031E | H3: 2032E | I3: 2033E | J3: 2034E | K3: 2035E | L3: 2036E
A4: Index | B4: 0 | C4: 1 | D4: 2 | E4: 3 | F4: 4 | G4: 5 | H4: 6 | I4: 7 | J4: 8 | K4: 9 | L4: 10
A5: Revenue growth YoY | C5: 0.04 | D5: 0.04 | E5: 0.04 | F5: 0.04 | G5: 0.035 | H5: 0.03 | I5: 0.025 | J5: 0.025 | K5: 0.025 | L5: 0.025
A6: Revenue | B6: 2977 | C6: =B6*(1+C5) | D6: =C6*(1+D5) | E6: =D6*(1+E5) | F6: =E6*(1+F5) | G6: =F6*(1+G5) | H6: =G6*(1+H5) | I6: =H6*(1+I5) | J6: =I6*(1+J5) | ... L6: =K6*(1+L5)
A7: Adj EBITDA margin | C7: 0.724 | D7: 0.728 | E7: 0.73 | F7: 0.732 | G7: 0.734 | H7: 0.735 | I7: 0.735 | J7: 0.735 | K7: 0.735 | L7: 0.735
A8: Adjusted EBITDA | B8: 2123 | C8: =C6*C7 | D8: =D6*D7 | E8: =E6*E7 | F8: =F6*F7 | G8: =G6*G7 | H8: =H6*H7 | I8: =I6*I7 | J8: =J6*J7 | ... L8: =L6*L7
A9: SBC % of revenue | C9: 0.00134 | D9: 0.00134 | E9: 0.00134 | F9: 0.00134 | G9: 0.00134 | H9: 0.00134 | I9: 0.00134 | J9: 0.00134 | K9: 0.00134 | L9: 0.00134
A10: SBC (negative) | B10: -4 | C10: =-C6*C9 | D10: =-D6*D9 | E10: =-E6*E9 | F10: =-F6*F9 | G10: =-G6*G9 | H10: =-H6*H9 | I10: =-I6*I9 | J10: =-J6*J9 | ... L10: =-L6*L9
A11: Owner EBITDA | C11: =C8+C10 | D11: =D8+D10 | E11: =E8+E10 | F11: =F8+F10 | G11: =G8+G10 | H11: =H8+H10 | I11: =I8+I10 | J11: =J8+J10 | ... L11: =L8+L10
A12: D&A (negative) | B12: -1042 | C12: =-C6*C45 | D12: =-D6*D45 | E12: =-E6*E45 | F12: =-F6*F45 | G12: =-G6*G45 | H12: =-H6*H45 | I12: =-I6*I45 | J12: =-J6*J45 | ... L12: =-L6*L45
A13: EBIT (SBC expensed) | C13: =C11+C12 | D13: =D11+D12 | E13: =E11+E12 | F13: =F11+F12 | G13: =G11+G12 | H13: =H11+H12 | I13: =I11+I12 | J13: =J11+J12 | ... L13: =L11+L12
A14: Cash tax rate on EBIT | C14: 0.33 | D14: 0.33 | E14: 0.33 | F14: 0.33 | G14: 0.33 | H14: 0.32 | I14: 0.32 | J14: 0.32 | K14: 0.31 | L14: 0.31
A15: NOPAT | C15: =C13-MAX(0,C13)*C14 | D15: =D13-MAX(0,D13)*D14 | E15: =E13-MAX(0,E13)*E14 | F15: =F13-MAX(0,F13)*F14 | G15: =G13-MAX(0,G13)*G14 | H15: =H13-MAX(0,H13)*H14 | I15: =I13-MAX(0,I13)*I14 | J15: =J13-MAX(0,J13)*J14 | ... L15: =L13-MAX(0,L13)*L14
A16: Add back D&A | C16: =-C12 | D16: =-D12 | E16: =-E12 | F16: =-F12 | G16: =-G12 | H16: =-H12 | I16: =-I12 | J16: =-J12 | ... L16: =-L12
A17: Less capex | B17: -845 | C17: =-C6*C46 | D17: =-D6*D46 | E17: =-E6*E46 | F17: =-F6*F46 | G17: =-G6*G46 | H17: =-H6*H46 | I17: =-I6*I46 | J17: =-J6*J46 | ... L17: =-L6*L46
A18: Add working capital | C18: =Assumptions!$B$5*(C6-B6) | D18: =Assumptions!$B$5*(D6-C6) | E18: =Assumptions!$B$5*(E6-D6) | F18: =Assumptions!$B$5*(F6-E6) | G18: =Assumptions!$B$5*(G6-F6) | H18: =Assumptions!$B$5*(H6-G6) | I18: =Assumptions!$B$5*(I6-H6) | J18: =Assumptions!$B$5*(J6-I6) | ... L18: =Assumptions!$B$5*(L6-K6)
A19: Unlevered owner FCF | C19: =C15+C16+C17+C18 | D19: =D15+D16+D17+D18 | E19: =E15+E16+E17+E18 | F19: =F15+F16+F17+F18 | G19: =G15+G16+G17+G18 | H19: =H15+H16+H17+H18 | I19: =I15+I16+I17+I18 | J19: =J15+J16+J17+J18 | ... L19: =L15+L16+L17+L18
A20: Discount factor | C20: =1/(1+Assumptions!$B$4)^C4 | D20: =1/(1+Assumptions!$B$4)^D4 | E20: =1/(1+Assumptions!$B$4)^E4 | F20: =1/(1+Assumptions!$B$4)^F4 | G20: =1/(1+Assumptions!$B$4)^G4 | H20: =1/(1+Assumptions!$B$4)^H4 | I20: =1/(1+Assumptions!$B$4)^I4 | J20: =1/(1+Assumptions!$B$4)^J4 | ... L20: =1/(1+Assumptions!$B$4)^L4
A21: PV of FCF | C21: =C19*C20 | D21: =D19*D20 | E21: =E19*E20 | F21: =F19*F20 | G21: =G19*G20 | H21: =H19*H20 | I21: =I19*I20 | J21: =J19*J20 | ... L21: =L19*L20
A23: Memo: FCF before SBC (company-style) | C23: =C19-C10 | D23: =D19-D10 | E23: =E19-E10 | F23: =F19-F10 | G23: =G19-G10 | H23: =H19-H10 | I23: =I19-I10 | J23: =J19-J10 | ... L23: =L19-L10
A24: Memo: owner-FCF margin | C24: =C19/C6 | D24: =D19/D6 | E24: =E19/E6 | F24: =F19/F6 | G24: =G19/G6 | H24: =H19/H6 | I24: =I19/I6 | J24: =J19/J6 | ... L24: =L19/L6
A26: Sum of PV (explicit years) | B26: =SUM(C21:L21)
A27: Terminal growth | B27: =Assumptions!$B$14
A28: Terminal-year FCF x (1+g) | B28: =L19*(1+B27)
A29: Gordon terminal value | B29: =IF(Assumptions!$B$4>B27,B28/(Assumptions!$B$4-B27),1E+12)
A30: Cap terminal value | B30: =Assumptions!$B$9*L19
A31: Terminal value used | B31: =MAX(0,MIN(B29,B30))
A32: Implied exit multiple (x FCF) | B32: =IF(L19<>0,B31/L19,0)
A33: PV of terminal value | B33: =B31*L20
A34: Enterprise value | B34: =B26+B33
A35: Less net debt | B35: =-Assumptions!$B$6
A36: Equity value | B36: =B34+B35
A37: Diluted securities (m) | B37: =Assumptions!$B$7
A38: VALUE PER SECURITY (AUD) | B38: =B36/B37
A39: Upside vs price | B39: =B38/Assumptions!$B$8-1
A41: Street memo: PV of explicit SBC | B41: =SUMPRODUCT(-C10:L10/(1+Assumptions!$B$4)^C4:L4)
A42: Street memo: PV of terminal SBC | B42: =IF(Assumptions!$B$4>B27,(-L10*(1+B27)/(Assumptions!$B$4-B27))*L20,0)
A43: Street value per security | B43: =(B36+B41+B42)/B37
A45: D&A % of revenue (driver) | C45: 0.34 | D45: 0.33 | E45: 0.32 | F45: 0.31 | G45: 0.3 | H45: 0.28 | I45: 0.26 | J45: 0.24 | K45: 0.22 | L45: 0.21
...

Sheet DCF_Bull
A1: DCF_Bull: unlevered owner-FCF build, AUD millions. Drivers (blue/yellow) in rows 5, 7, 9, 14, 45, 46.
A3: Year | B3: 2026A | C3: 2027E | D3: 2028E | E3: 2029E | F3: 2030E | G3: 2031E | H3: 2032E | I3: 2033E | J3: 2034E | K3: 2035E | L3: 2036E
A4: Index | B4: 0 | C4: 1 | D4: 2 | E4: 3 | F4: 4 | G4: 5 | H4: 6 | I4: 7 | J4: 8 | K4: 9 | L4: 10
A5: Revenue growth YoY | C5: 0.05 | D5: 0.05 | E5: 0.05 | F5: 0.05 | G5: 0.045 | H5: 0.04 | I5: 0.035 | J5: 0.03 | K5: 0.03 | L5: 0.03
A6: Revenue | B6: 2977 | C6: =B6*(1+C5) | D6: =C6*(1+D5) | E6: =D6*(1+E5) | F6: =E6*(1+F5) | G6: =F6*(1+G5) | H6: =G6*(1+H5) | I6: =H6*(1+I5) | J6: =I6*(1+J5) | ... L6: =K6*(1+L5)
A7: Adj EBITDA margin | C7: 0.73 | D7: 0.735 | E7: 0.74 | F7: 0.743 | G7: 0.746 | H7: 0.748 | I7: 0.75 | J7: 0.75 | K7: 0.75 | L7: 0.75
A8: Adjusted EBITDA | B8: 2123 | C8: =C6*C7 | D8: =D6*D7 | E8: =E6*E7 | F8: =F6*F7 | G8: =G6*G7 | H8: =H6*H7 | I8: =I6*I7 | J8: =J6*J7 | ... L8: =L6*L7
A9: SBC % of revenue | C9: 0.00134 | D9: 0.00134 | E9: 0.00134 | F9: 0.00134 | G9: 0.00134 | H9: 0.00134 | I9: 0.00134 | J9: 0.00134 | K9: 0.00134 | L9: 0.00134
A10: SBC (negative) | B10: -4 | C10: =-C6*C9 | D10: =-D6*D9 | E10: =-E6*E9 | F10: =-F6*F9 | G10: =-G6*G9 | H10: =-H6*H9 | I10: =-I6*I9 | J10: =-J6*J9 | ... L10: =-L6*L9
A11: Owner EBITDA | C11: =C8+C10 | D11: =D8+D10 | E11: =E8+E10 | F11: =F8+F10 | G11: =G8+G10 | H11: =H8+H10 | I11: =I8+I10 | J11: =J8+J10 | ... L11: =L8+L10
A12: D&A (negative) | B12: -1042 | C12: =-C6*C45 | D12: =-D6*D45 | E12: =-E6*E45 | F12: =-F6*F45 | G12: =-G6*G45 | H12: =-H6*H45 | I12: =-I6*I45 | J12: =-J6*J45 | ... L12: =-L6*L45
A13: EBIT (SBC expensed) | C13: =C11+C12 | D13: =D11+D12 | E13: =E11+E12 | F13: =F11+F12 | G13: =G11+G12 | H13: =H11+H12 | I13: =I11+I12 | J13: =J11+J12 | ... L13: =L11+L12
A14: Cash tax rate on EBIT | C14: 0.33 | D14: 0.33 | E14: 0.33 | F14: 0.33 | G14: 0.33 | H14: 0.32 | I14: 0.32 | J14: 0.32 | K14: 0.31 | L14: 0.31
A15: NOPAT | C15: =C13-MAX(0,C13)*C14 | D15: =D13-MAX(0,D13)*D14 | E15: =E13-MAX(0,E13)*E14 | F15: =F13-MAX(0,F13)*F14 | G15: =G13-MAX(0,G13)*G14 | H15: =H13-MAX(0,H13)*H14 | I15: =I13-MAX(0,I13)*I14 | J15: =J13-MAX(0,J13)*J14 | ... L15: =L13-MAX(0,L13)*L14
A16: Add back D&A | C16: =-C12 | D16: =-D12 | E16: =-E12 | F16: =-F12 | G16: =-G12 | H16: =-H12 | I16: =-I12 | J16: =-J12 | ... L16: =-L12
A17: Less capex | B17: -845 | C17: =-C6*C46 | D17: =-D6*D46 | E17: =-E6*E46 | F17: =-F6*F46 | G17: =-G6*G46 | H17: =-H6*H46 | I17: =-I6*I46 | J17: =-J6*J46 | ... L17: =-L6*L46
A18: Add working capital | C18: =Assumptions!$B$5*(C6-B6) | D18: =Assumptions!$B$5*(D6-C6) | E18: =Assumptions!$B$5*(E6-D6) | F18: =Assumptions!$B$5*(F6-E6) | G18: =Assumptions!$B$5*(G6-F6) | H18: =Assumptions!$B$5*(H6-G6) | I18: =Assumptions!$B$5*(I6-H6) | J18: =Assumptions!$B$5*(J6-I6) | ... L18: =Assumptions!$B$5*(L6-K6)
A19: Unlevered owner FCF | C19: =C15+C16+C17+C18 | D19: =D15+D16+D17+D18 | E19: =E15+E16+E17+E18 | F19: =F15+F16+F17+F18 | G19: =G15+G16+G17+G18 | H19: =H15+H16+H17+H18 | I19: =I15+I16+I17+I18 | J19: =J15+J16+J17+J18 | ... L19: =L15+L16+L17+L18
A20: Discount factor | C20: =1/(1+Assumptions!$B$4)^C4 | D20: =1/(1+Assumptions!$B$4)^D4 | E20: =1/(1+Assumptions!$B$4)^E4 | F20: =1/(1+Assumptions!$B$4)^F4 | G20: =1/(1+Assumptions!$B$4)^G4 | H20: =1/(1+Assumptions!$B$4)^H4 | I20: =1/(1+Assumptions!$B$4)^I4 | J20: =1/(1+Assumptions!$B$4)^J4 | ... L20: =1/(1+Assumptions!$B$4)^L4
A21: PV of FCF | C21: =C19*C20 | D21: =D19*D20 | E21: =E19*E20 | F21: =F19*F20 | G21: =G19*G20 | H21: =H19*H20 | I21: =I19*I20 | J21: =J19*J20 | ... L21: =L19*L20
A23: Memo: FCF before SBC (company-style) | C23: =C19-C10 | D23: =D19-D10 | E23: =E19-E10 | F23: =F19-F10 | G23: =G19-G10 | H23: =H19-H10 | I23: =I19-I10 | J23: =J19-J10 | ... L23: =L19-L10
A24: Memo: owner-FCF margin | C24: =C19/C6 | D24: =D19/D6 | E24: =E19/E6 | F24: =F19/F6 | G24: =G19/G6 | H24: =H19/H6 | I24: =I19/I6 | J24: =J19/J6 | ... L24: =L19/L6
A26: Sum of PV (explicit years) | B26: =SUM(C21:L21)
A27: Terminal growth | B27: =Assumptions!$B$15
A28: Terminal-year FCF x (1+g) | B28: =L19*(1+B27)
A29: Gordon terminal value | B29: =IF(Assumptions!$B$4>B27,B28/(Assumptions!$B$4-B27),1E+12)
A30: Cap terminal value | B30: =Assumptions!$B$9*L19
A31: Terminal value used | B31: =MAX(0,MIN(B29,B30))
A32: Implied exit multiple (x FCF) | B32: =IF(L19<>0,B31/L19,0)
A33: PV of terminal value | B33: =B31*L20
A34: Enterprise value | B34: =B26+B33
A35: Less net debt | B35: =-Assumptions!$B$6
A36: Equity value | B36: =B34+B35
A37: Diluted securities (m) | B37: =Assumptions!$B$7
A38: VALUE PER SECURITY (AUD) | B38: =B36/B37
A39: Upside vs price | B39: =B38/Assumptions!$B$8-1
A41: Street memo: PV of explicit SBC | B41: =SUMPRODUCT(-C10:L10/(1+Assumptions!$B$4)^C4:L4)
A42: Street memo: PV of terminal SBC | B42: =IF(Assumptions!$B$4>B27,(-L10*(1+B27)/(Assumptions!$B$4-B27))*L20,0)
A43: Street value per security | B43: =(B36+B41+B42)/B37
A45: D&A % of revenue (driver) | C45: 0.34 | D45: 0.33 | E45: 0.32 | F45: 0.31 | G45: 0.3 | H45: 0.28 | I45: 0.26 | J45: 0.24 | K45: 0.22 | L45: 0.21
...

Sheet FCF_Quality
A1: Reported FCF reconciled to owner FCF (AUD m). APA's own 'Free Cash Flow' deducts SIB capex only and is post-interest; the owner series deducts ALL capex.
B3: FY2021 | C3: FY2022 | D3: FY2023 | E3: FY2024 | F3: FY2025 | G3: FY2026
A4: Operating cash flow | B4: 1050.958 | C4: 1197.268 | D4: 1206 | E4: 1156 | F4: 1284 | G4: 1252
A5: Less: total capex | B5: -432.928 | C5: -689.045 | D5: -1180 | E5: -1096 | F5: -964 | G5: -845
A6: Reported FCF (OCF - total capex) | B6: =B4+B5 | C6: =C4+C5 | D6: =D4+D5 | E6: =E4+E5 | F6: =F4+F5 | G6: =G4+G5
A7: Less: SBC incl. equity-award taxes | B7: -2 | C7: -3 | D7: -3 | E7: -2 | F7: -4 | G7: -4
A8: Less: interest income (not stripped -- net-debt company) | B8: 0 | C8: 0 | D8: 0 | E8: 0 | F8: 0 | G8: 0
A9: Owner FCF | B9: =B6+B7+B8 | C9: =C6+C7+C8 | D9: =D6+D7+D8 | E9: =E6+E7+E8 | F9: =F6+F7+F8 | G9: =G6+G7+G8
A10: Memo: company-definition FCF (SIB capex only) | B10: 901.9 | C10: 1080.6 | D10: 1070 | E10: 1073 | F10: 1083 | G10: 1118
A11: Memo: growth + foundation capex funded by debt/DRP | B11: =B10-B9 | C11: =C10-C9 | D11: =D10-D9 | E11: =E10-E9 | F11: =F10-F9 | G11: =G10-G9
A12: Revenue | B12: 2605.3 | C12: 2705.04 | D12: 2890 | E12: 3039 | F12: 3179 | G12: 2977
A13: Reported FCF margin | B13: =B6/B12 | C13: =C6/C12 | D13: =D6/D12 | E13: =E6/E12 | F13: =F6/F12 | G13: =G6/G12
A14: Owner FCF margin | B14: =B9/B12 | C14: =C9/C12 | D14: =D9/D12 | E14: =E9/E12 | F14: =F9/F12 | G14: =G9/G12
A15: Memo: cash taxes paid | C15: 42.715 | D15: 22 | E15: 52 | F15: 74 | G15: 158
A16: Memo: cash tax / PBT (flag: FY26 39.5% incl. FY25 catch-up) | B16: n/a | C16: =C15/440.09 | D16: =D15/477 | E16: =E15/1073 | F16: =F15/247 | G16: =G15/400
A18: Reading: owner FCF after all capex fell from 614 (FY21) to 22-56 (FY23-24) during the capex supercycle and recovered to 403 in FY26; distributions of ~766m/yr exceed it and are funded by DRP (~160m) and net debt. SBC is immaterial.

Sheet Valuation
A1: Valuation summary (AUD per security). Live links; every closed-form cell rebuilds its own terminal value at that rate.
A3: Scenario | B3: Value per security | C3: Upside vs price | D3: Probability | E3: Street value per security | F3: TV bound | G3: Terminal % of EV | H3: Implied exit multiple
A4: bear | B4: =DCF_Bear!B38 | C4: =B4/Assumptions!$B$8-1 | D4: =Assumptions!C13 | E4: =DCF_Bear!B43 | F4: =IF(DCF_Bear!B31=0,"floor",IF(DCF_Bear!B29<=DCF_Bear!B30,"gordon","cap")) | G4: =DCF_Bear!B33/DCF_Bear!B34 | H4: =DCF_Bear!B32
A5: base | B5: =DCF_Base!B38 | C5: =B5/Assumptions!$B$8-1 | D5: =Assumptions!C14 | E5: =DCF_Base!B43 | F5: =IF(DCF_Base!B31=0,"floor",IF(DCF_Base!B29<=DCF_Base!B30,"gordon","cap")) | G5: =DCF_Base!B33/DCF_Base!B34 | H5: =DCF_Base!B32
A6: bull | B6: =DCF_Bull!B38 | C6: =B6/Assumptions!$B$8-1 | D6: =Assumptions!C15 | E6: =DCF_Bull!B43 | F6: =IF(DCF_Bull!B31=0,"floor",IF(DCF_Bull!B29<=DCF_Bull!B30,"gordon","cap")) | G6: =DCF_Bull!B33/DCF_Bull!B34 | H6: =DCF_Bull!B32
A8: Probability-weighted value | B8: =SUMPRODUCT(B4:B6,D4:D6)
A9: Margin of safety vs price | B9: =1-Assumptions!B8/B8
A10: Street weighted value | B10: =SUMPRODUCT(E4:E6,D4:D6)
A11: Band position (price - house)/(street - house) | B11: =IF(ABS(B10-B8)<0.25,"n/a: SBC-zero, band collapsed",(Assumptions!B8-B8)/(B10-B8))
A12: Current price | B12: =Assumptions!B8
A14: Required-return table (base case; TV rebuilt at each rate)
A15: Required return | B15: Value per security
A16: 0.07 | B16: =(SUMPRODUCT(DCF_Base!$C$19:$L$19/(1+$A$16)^DCF_Base!$C$4:$L$4)+MAX(0,MIN(IF($A$16>Assumptions!$B$14,DCF_Base!$L$19*(1+Assumptions!$B$14)/($A$16-Assumptions!$B$14),1E+12),Assumptions!$B$9*DCF_Base!$L$19))/(1+$A$16)^10-Assumptions!$B$6)/Assumptions!$B$7 | C16: equals DCF_Base!B38 (house WACC)
A17: 0.09 | B17: =(SUMPRODUCT(DCF_Base!$C$19:$L$19/(1+$A$17)^DCF_Base!$C$4:$L$4)+MAX(0,MIN(IF($A$17>Assumptions!$B$14,DCF_Base!$L$19*(1+Assumptions!$B$14)/($A$17-Assumptions!$B$14),1E+12),Assumptions!$B$9*DCF_Base!$L$19))/(1+$A$17)^10-Assumptions!$B$6)/Assumptions!$B$7
A18: 0.1 | B18: =(SUMPRODUCT(DCF_Base!$C$19:$L$19/(1+$A$18)^DCF_Base!$C$4:$L$4)+MAX(0,MIN(IF($A$18>Assumptions!$B$14,DCF_Base!$L$19*(1+Assumptions!$B$14)/($A$18-Assumptions!$B$14),1E+12),Assumptions!$B$9*DCF_Base!$L$19))/(1+$A$18)^10-Assumptions!$B$6)/Assumptions!$B$7
A19: 0.11 | B19: =(SUMPRODUCT(DCF_Base!$C$19:$L$19/(1+$A$19)^DCF_Base!$C$4:$L$4)+MAX(0,MIN(IF($A$19>Assumptions!$B$14,DCF_Base!$L$19*(1+Assumptions!$B$14)/($A$19-Assumptions!$B$14),1E+12),Assumptions!$B$9*DCF_Base!$L$19))/(1+$A$19)^10-Assumptions!$B$6)/Assumptions!$B$7
A20: 0.12 | B20: =(SUMPRODUCT(DCF_Base!$C$19:$L$19/(1+$A$20)^DCF_Base!$C$4:$L$4)+MAX(0,MIN(IF($A$20>Assumptions!$B$14,DCF_Base!$L$19*(1+Assumptions!$B$14)/($A$20-Assumptions!$B$14),1E+12),Assumptions!$B$9*DCF_Base!$L$19))/(1+$A$20)^10-Assumptions!$B$6)/Assumptions!$B$7
A21: 0.15 | B21: =(SUMPRODUCT(DCF_Base!$C$19:$L$19/(1+$A$21)^DCF_Base!$C$4:$L$4)+MAX(0,MIN(IF($A$21>Assumptions!$B$14,DCF_Base!$L$19*(1+Assumptions!$B$14)/($A$21-Assumptions!$B$14),1E+12),Assumptions!$B$9*DCF_Base!$L$19))/(1+$A$21)^10-Assumptions!$B$6)/Assumptions!$B$7 | C21: equals the base-case 15% entry price
A23: 15%-hurdle entry prices (TV rebuilt at the hurdle)
A24: Scenario | B24: Entry price | C24: Probability | D24: Street entry price
A25: bear | B25: =(SUMPRODUCT(DCF_Bear!$C$19:$L$19/(1+Assumptions!$B$10)^DCF_Bear!$C$4:$L$4)+MAX(0,MIN(IF(Assumptions!$B$10>Assumptions!$B$13,DCF_Bear!$L$19*(1+Assumptions!$B$13)/(Assumptions!$B$10-Assumptions!$B$13),1E+12),Assumptions!$B$9*DCF_Bear!$L$19))/(1+Assumptions!$B$10)^10-Assumptions!$B$6)/Assumptions!$B$7 | C25: =Assumptions!C13 | D25: =B25+(SUMPRODUCT(-DCF_Bear!$C$10:$L$10/(1+Assumptions!$B$10)^DCF_Bear!$C$4:$L$4)+IF(Assumptions!$B$10>Assumptions!$B$13,(-DCF_Bear!$L$10*(1+Assumptions!$B$13)/(Assumptions!$B$10-Assumptions!$B$13))/(1+Assumptions!$B$10)^10,0))/Assumptions!$B$7
A26: base | B26: =(SUMPRODUCT(DCF_Base!$C$19:$L$19/(1+Assumptions!$B$10)^DCF_Base!$C$4:$L$4)+MAX(0,MIN(IF(Assumptions!$B$10>Assumptions!$B$14,DCF_Base!$L$19*(1+Assumptions!$B$14)/(Assumptions!$B$10-Assumptions!$B$14),1E+12),Assumptions!$B$9*DCF_Base!$L$19))/(1+Assumptions!$B$10)^10-Assumptions!$B$6)/Assumptions!$B$7 | C26: =Assumptions!C14 | D26: =B26+(SUMPRODUCT(-DCF_Base!$C$10:$L$10/(1+Assumptions!$B$10)^DCF_Base!$C$4:$L$4)+IF(Assumptions!$B$10>Assumptions!$B$14,(-DCF_Base!$L$10*(1+Assumptions!$B$14)/(Assumptions!$B$10-Assumptions!$B$14))/(1+Assumptions!$B$10)^10,0))/Assumptions!$B$7
A27: bull | B27: =(SUMPRODUCT(DCF_Bull!$C$19:$L$19/(1+Assumptions!$B$10)^DCF_Bull!$C$4:$L$4)+MAX(0,MIN(IF(Assumptions!$B$10>Assumptions!$B$15,DCF_Bull!$L$19*(1+Assumptions!$B$15)/(Assumptions!$B$10-Assumptions!$B$15),1E+12),Assumptions!$B$9*DCF_Bull!$L$19))/(1+Assumptions!$B$10)^10-Assumptions!$B$6)/Assumptions!$B$7 | C27: =Assumptions!C15 | D27: =B27+(SUMPRODUCT(-DCF_Bull!$C$10:$L$10/(1+Assumptions!$B$10)^DCF_Bull!$C$4:$L$4)+IF(Assumptions!$B$10>Assumptions!$B$15,(-DCF_Bull!$L$10*(1+Assumptions!$B$15)/(Assumptions!$B$10-Assumptions!$B$15))/(1+Assumptions!$B$10)^10,0))/Assumptions!$B$7
A28: Probability-weighted entry price (buy-below) | B28: =SUMPRODUCT(B25:B27,C25:C27)
A29: Reading: negative in every scenario -- at a 15% discount rate the enterprise is worth less than its 12.66bn of net debt. No price delivers 15% on a 5.8x-levered BBB utility; use the 9-10% rows above.
A31: Sensitivity: base-case value per security, WACC (rows) x terminal growth (columns); TV rebuilt at each pair
B32: 0.015 | C32: 0.02 | D32: 0.025 | E32: 0.03 | F32: 0.035
A33: 0.05 | B33: =(SUMPRODUCT(DCF_Base!$C$19:$L$19/(1+$A$33)^DCF_Base!$C$4:$L$4)+MAX(0,MIN(IF($A$33>B$32,DCF_Base!$L$19*(1+B$32)/($A$33-B$32),1E+12),Assumptions!$B$9*DCF_Base!$L$19))/(1+$A$33)^10-Assumptions!$B$6)/Assumptions!$B$7 | C33: =(SUMPRODUCT(DCF_Base!$C$19:$L$19/(1+$A$33)^DCF_Base!$C$4:$L$4)+MAX(0,MIN(IF($A$33>C$32,DCF_Base!$L$19*(1+C$32)/($A$33-C$32),1E+12),Assumptions!$B$9*DCF_Base!$L$19))/(1+$A$33)^10-Assumptions!$B$6)/Assumptions!$B$7 | D33: =(SUMPRODUCT(DCF_Base!$C$19:$L$19/(1+$A$33)^DCF_Base!$C$4:$L$4)+MAX(0,MIN(IF($A$33>D$32,DCF_Base!$L$19*(1+D$32)/($A$33-D$32),1E+12),Assumptions!$B$9*DCF_Base!$L$19))/(1+$A$33)^10-Assumptions!$B$6)/Assumptions!$B$7 | E33: =(SUMPRODUCT(DCF_Base!$C$19:$L$19/(1+$A$33)^DCF_Base!$C$4:$L$4)+MAX(0,MIN(IF($A$33>E$32,DCF_Base!$L$19*(1+E$32)/($A$33-E$32),1E+12),Assumptions!$B$9*DCF_Base!$L$19))/(1+$A$33)^10-Assumptions!$B$6)/Assumptions!$B$7 | F33: =(SUMPRODUCT(DCF_Base!$C$19:$L$19/(1+$A$33)^DCF_Base!$C$4:$L$4)+MAX(0,MIN(IF($A$33>F$32,DCF_Base!$L$19*(1+F$32)/($A$33-F$32),1E+12),Assumptions!$B$9*DCF_Base!$L$19))/(1+$A$33)^10-Assumptions!$B$6)/Assumptions!$B$7
A34: 0.06 | B34: =(SUMPRODUCT(DCF_Base!$C$19:$L$19/(1+$A$34)^DCF_Base!$C$4:$L$4)+MAX(0,MIN(IF($A$34>B$32,DCF_Base!$L$19*(1+B$32)/($A$34-B$32),1E+12),Assumptions!$B$9*DCF_Base!$L$19))/(1+$A$34)^10-Assumptions!$B$6)/Assumptions!$B$7 | C34: =(SUMPRODUCT(DCF_Base!$C$19:$L$19/(1+$A$34)^DCF_Base!$C$4:$L$4)+MAX(0,MIN(IF($A$34>C$32,DCF_Base!$L$19*(1+C$32)/($A$34-C$32),1E+12),Assumptions!$B$9*DCF_Base!$L$19))/(1+$A$34)^10-Assumptions!$B$6)/Assumptions!$B$7 | D34: =(SUMPRODUCT(DCF_Base!$C$19:$L$19/(1+$A$34)^DCF_Base!$C$4:$L$4)+MAX(0,MIN(IF($A$34>D$32,DCF_Base!$L$19*(1+D$32)/($A$34-D$32),1E+12),Assumptions!$B$9*DCF_Base!$L$19))/(1+$A$34)^10-Assumptions!$B$6)/Assumptions!$B$7 | E34: =(SUMPRODUCT(DCF_Base!$C$19:$L$19/(1+$A$34)^DCF_Base!$C$4:$L$4)+MAX(0,MIN(IF($A$34>E$32,DCF_Base!$L$19*(1+E$32)/($A$34-E$32),1E+12),Assumptions!$B$9*DCF_Base!$L$19))/(1+$A$34)^10-Assumptions!$B$6)/Assumptions!$B$7 | F34: =(SUMPRODUCT(DCF_Base!$C$19:$L$19/(1+$A$34)^DCF_Base!$C$4:$L$4)+MAX(0,MIN(IF($A$34>F$32,DCF_Base!$L$19*(1+F$32)/($A$34-F$32),1E+12),Assumptions!$B$9*DCF_Base!$L$19))/(1+$A$34)^10-Assumptions!$B$6)/Assumptions!$B$7
A35: 0.07 | B35: =(SUMPRODUCT(DCF_Base!$C$19:$L$19/(1+$A$35)^DCF_Base!$C$4:$L$4)+MAX(0,MIN(IF($A$35>B$32,DCF_Base!$L$19*(1+B$32)/($A$35-B$32),1E+12),Assumptions!$B$9*DCF_Base!$L$19))/(1+$A$35)^10-Assumptions!$B$6)/Assumptions!$B$7 | C35: =(SUMPRODUCT(DCF_Base!$C$19:$L$19/(1+$A$35)^DCF_Base!$C$4:$L$4)+MAX(0,MIN(IF($A$35>C$32,DCF_Base!$L$19*(1+C$32)/($A$35-C$32),1E+12),Assumptions!$B$9*DCF_Base!$L$19))/(1+$A$35)^10-Assumptions!$B$6)/Assumptions!$B$7 | D35: =(SUMPRODUCT(DCF_Base!$C$19:$L$19/(1+$A$35)^DCF_Base!$C$4:$L$4)+MAX(0,MIN(IF($A$35>D$32,DCF_Base!$L$19*(1+D$32)/($A$35-D$32),1E+12),Assumptions!$B$9*DCF_Base!$L$19))/(1+$A$35)^10-Assumptions!$B$6)/Assumptions!$B$7 | E35: =(SUMPRODUCT(DCF_Base!$C$19:$L$19/(1+$A$35)^DCF_Base!$C$4:$L$4)+MAX(0,MIN(IF($A$35>E$32,DCF_Base!$L$19*(1+E$32)/($A$35-E$32),1E+12),Assumptions!$B$9*DCF_Base!$L$19))/(1+$A$35)^10-Assumptions!$B$6)/Assumptions!$B$7 | F35: =(SUMPRODUCT(DCF_Base!$C$19:$L$19/(1+$A$35)^DCF_Base!$C$4:$L$4)+MAX(0,MIN(IF($A$35>F$32,DCF_Base!$L$19*(1+F$32)/($A$35-F$32),1E+12),Assumptions!$B$9*DCF_Base!$L$19))/(1+$A$35)^10-Assumptions!$B$6)/Assumptions!$B$7
A36: 0.08 | B36: =(SUMPRODUCT(DCF_Base!$C$19:$L$19/(1+$A$36)^DCF_Base!$C$4:$L$4)+MAX(0,MIN(IF($A$36>B$32,DCF_Base!$L$19*(1+B$32)/($A$36-B$32),1E+12),Assumptions!$B$9*DCF_Base!$L$19))/(1+$A$36)^10-Assumptions!$B$6)/Assumptions!$B$7 | C36: =(SUMPRODUCT(DCF_Base!$C$19:$L$19/(1+$A$36)^DCF_Base!$C$4:$L$4)+MAX(0,MIN(IF($A$36>C$32,DCF_Base!$L$19*(1+C$32)/($A$36-C$32),1E+12),Assumptions!$B$9*DCF_Base!$L$19))/(1+$A$36)^10-Assumptions!$B$6)/Assumptions!$B$7 | D36: =(SUMPRODUCT(DCF_Base!$C$19:$L$19/(1+$A$36)^DCF_Base!$C$4:$L$4)+MAX(0,MIN(IF($A$36>D$32,DCF_Base!$L$19*(1+D$32)/($A$36-D$32),1E+12),Assumptions!$B$9*DCF_Base!$L$19))/(1+$A$36)^10-Assumptions!$B$6)/Assumptions!$B$7 | E36: =(SUMPRODUCT(DCF_Base!$C$19:$L$19/(1+$A$36)^DCF_Base!$C$4:$L$4)+MAX(0,MIN(IF($A$36>E$32,DCF_Base!$L$19*(1+E$32)/($A$36-E$32),1E+12),Assumptions!$B$9*DCF_Base!$L$19))/(1+$A$36)^10-Assumptions!$B$6)/Assumptions!$B$7 | F36: =(SUMPRODUCT(DCF_Base!$C$19:$L$19/(1+$A$36)^DCF_Base!$C$4:$L$4)+MAX(0,MIN(IF($A$36>F$32,DCF_Base!$L$19*(1+F$32)/($A$36-F$32),1E+12),Assumptions!$B$9*DCF_Base!$L$19))/(1+$A$36)^10-Assumptions!$B$6)/Assumptions!$B$7
A37: 0.09 | B37: =(SUMPRODUCT(DCF_Base!$C$19:$L$19/(1+$A$37)^DCF_Base!$C$4:$L$4)+MAX(0,MIN(IF($A$37>B$32,DCF_Base!$L$19*(1+B$32)/($A$37-B$32),1E+12),Assumptions!$B$9*DCF_Base!$L$19))/(1+$A$37)^10-Assumptions!$B$6)/Assumptions!$B$7 | C37: =(SUMPRODUCT(DCF_Base!$C$19:$L$19/(1+$A$37)^DCF_Base!$C$4:$L$4)+MAX(0,MIN(IF($A$37>C$32,DCF_Base!$L$19*(1+C$32)/($A$37-C$32),1E+12),Assumptions!$B$9*DCF_Base!$L$19))/(1+$A$37)^10-Assumptions!$B$6)/Assumptions!$B$7 | D37: =(SUMPRODUCT(DCF_Base!$C$19:$L$19/(1+$A$37)^DCF_Base!$C$4:$L$4)+MAX(0,MIN(IF($A$37>D$32,DCF_Base!$L$19*(1+D$32)/($A$37-D$32),1E+12),Assumptions!$B$9*DCF_Base!$L$19))/(1+$A$37)^10-Assumptions!$B$6)/Assumptions!$B$7 | E37: =(SUMPRODUCT(DCF_Base!$C$19:$L$19/(1+$A$37)^DCF_Base!$C$4:$L$4)+MAX(0,MIN(IF($A$37>E$32,DCF_Base!$L$19*(1+E$32)/($A$37-E$32),1E+12),Assumptions!$B$9*DCF_Base!$L$19))/(1+$A$37)^10-Assumptions!$B$6)/Assumptions!$B$7 | F37: =(SUMPRODUCT(DCF_Base!$C$19:$L$19/(1+$A$37)^DCF_Base!$C$4:$L$4)+MAX(0,MIN(IF($A$37>F$32,DCF_Base!$L$19*(1+F$32)/($A$37-F$32),1E+12),Assumptions!$B$9*DCF_Base!$L$19))/(1+$A$37)^10-Assumptions!$B$6)/Assumptions!$B$7
A39: Memo: base value with the cap at 20x and uncapped Gordon (7%/2.5%)
A40: Cap 20x | B40: =(SUMPRODUCT(DCF_Base!$C$19:$L$19/(1+Assumptions!$B$4)^DCF_Base!$C$4:$L$4)+MAX(0,MIN(DCF_Base!$B$29,20*DCF_Base!$L$19))/(1+Assumptions!$B$4)^10-Assumptions!$B$6)/Assumptions!$B$7
A41: Uncapped Gordon | B41: =(SUMPRODUCT(DCF_Base!$C$19:$L$19/(1+Assumptions!$B$4)^DCF_Base!$C$4:$L$4)+MAX(0,DCF_Base!$B$29)/(1+Assumptions!$B$4)^10-Assumptions!$B$6)/Assumptions!$B$7
A42: Reading: the market price is within 2% of the uncapped Gordon value -- the whole gap to the house base is the 18x cap.
