Workbook

Sheet Model_Info
A1: APX.AX -- Appen Limited -- owner-FCF DCF model
A2: Version 1.0, fresh build dated 2026-09-21. Supersedes: nothing (first APX.AX valuation in this folder).
A3: Built by the dcf-analyst agent (Claude Fable 5.1) on 2026-09-21 at the research-stock orchestrator's request.
A5: DATA VINTAGE (figures go stale -- refresh after every print)
A6: Price: A$1.05, 2026-09-21T06:10:31Z ASX regular close (Yahoo regularMarketTime); 52wk A$0.65-1.975; 25 days after the 27-Aug-2026 H1 result (-14% on the day)
A7: Balance sheet: 30-Jun-2026 H1 FY2026 report. Cash US$44.705m; lease liabilities US$7.426m; no borrowings.
A8: Share count: fully diluted: 268,523,648 shares on issue at 30-Jun-2026 (H1 FY2026 note 12) + 18,842,259 unvested performance rights (21,755,268 at 31-Dec-2025 per FY2025 note on share-based payments, less 2,913,009 exercised in H1 FY2026; the EPS note reports rights as antidilutive only because the company is loss-making). Held FLAT because forward SBC is fully expensed; the 2024 grant of 21.7m rights was struck at trough prices so the P&L expense understates its cost -- including the unvested rights in the divisor is the charge for those past grants.
A9: Guidance: Revenue US$270-300m; underlying EBITDA before FX margin 5-10% (reaffirmed 27-Aug-2026). Base case takes US$275m (H1 US$119.9m, so H2 must grow ~21% YoY just to reach the floor) at 6.0% statutory EBITDA (~7% underlying before FX, lower-middle of the guide: H1 was 4.5% underlying / 3.0% statutory but the business is H2-weighted -- H2 FY2025 ran ~11% underlying before FX).
A10: FX: Statements and flows in USD (presentation currency changed from AUD on 1-Jan-2021, retrospectively restated); ASX quote in AUD. All per-share values computed in USD then converted at USD/AUD 1.4019 (AUDUSD=X 0.7133, Yahoo, 2026-09-21T11:10:08Z). Parity check on the OTC line: APPEF US$0.7123 (stale print, 2026-09-18) vs A$1.05 x 0.7133 = US$0.749 -- a 5% gap on a frozen OTC quote that traded when APX.AX was ~A$1.00, so direction and basis are confirmed. A 5% AUD rally cuts every AUD value here by ~5%.
A12: METHODOLOGY
A13: MODEL: owner-FCF DCF (dcf-methods SKILL routing: operating company, non-US + cyclical -> owner-fcf.md incl. section 7), 10-year explicit horizon because margins and capex intensity are still ramping, component-built margins, scenario-weighted. Fresh build -- no prior APX.AX DCF and no MEMORY.md entry. Not routed to the distressed/asset-waterfall model: the company has no debt, US$44.7m cash, positive and guided EBITDA, and a going-concern audit opinion; the distress is in the history, not the balance sheet.
A14: OWNER FCF (FY2025, US$m): reported FCF 6.329 (OCF 22.966 - capex 16.637) - SBC 1.299 - interest income 0.773 - lease payments 4.848 = -0.591. Interest income is stripped because net cash (US$44.7m) is many times the FCF base and is added back in the bridge. TTM to Jun-2026 owner FCF is -20.5 (H1 FY2026 OCF -4.1 on a US$12.8m contract-asset build).
... A29: CELL COLOURS: blue = hardcoded input; yellow fill = key lever; black = formula; green = cross-sheet link.

Sheet Actuals
A1: Reported history, USD millions (presentation currency USD from FY2021; FY2014-FY2020 AUD rows deliberately omitted)
A3: Metric | B3: FY2021 | C3: FY2022 | D3: FY2023 | E3: FY2024 | F3: FY2025 | G3: H1 FY2025 | H3: H1 FY2026 | I3: Source
A4: Revenue | B4: 447.154 | C4: 388.133 | D4: 273.012 | E4: 234.285 | F4: 230.774 | G4: 102.072 | H4: 119.915 | I4: Metrics.csv / annual + half-year reports
A5: Statutory EBITDA | B5: 72.932 | C5: -195.901 | D5: -88.643 | E5: 3.662 | F5: 9.476 | G5: -3.806 | H5: 3.604 | I5: FY2022 incl. US$204.3m impairment; FY2023 incl. US$69.2m
A6: Net income | B6: 28.519 | C6: -239.068 | D6: -118.079 | E6: -20.009 | F6: -21.818 | G6: -19.263 | H6: -4.454
A7: Operating cash flow | B7: 53.923 | C7: 18.228 | D7: -22.939 | E7: -0.664 | F7: 22.966 | G7: 13.153 | H7: -4.146 | I7: cash flow statements
A8: Capex (PPE + intangibles) | B8: 23.095 | C8: 27.931 | D8: 19.853 | E8: 12.847 | F8: 16.637 | G8: 7.306 | H8: 9.22
A9: Reported FCF | B9: 30.828 | C9: -9.703 | D9: -42.792 | E9: -13.511 | F9: 6.329 | G9: 5.847 | H9: -13.366 | I9: OCF - capex
A10: SBC expense | B10: 0.516 | C10: 1.492 | D10: 5.691 | E10: 4.077 | F10: 1.299 | G10: 0.259 | H10: 0.799 | I10: note 5
A11: Interest income | B11: 0.01 | C11: 0.183 | D11: 0.371 | E11: 0.482 | F11: 0.773 | G11: 0.4 | H11: 0.281 | I11: cash flow: interest received
A12: Lease payments (principal + interest) | C12: 4.508 | D12: 4.763 | E12: 4.398 | F12: 4.848 | G12: 2.397 | H12: 2.678 | I12: financing activities; FY2021 not extracted
A13: Equity raised (net) | B13: 0 | C13: 0 | D13: 57.437 | E13: 42.137 | F13: 0 | G13: 0 | H13: 0 | I13: financing activities
A14: Cash | B14: 47.878 | C14: 23.429 | D14: 32.152 | E14: 54.809 | F14: 59.824 | G14: 60.865 | H14: 44.705
A15: Lease liabilities (= total_debt in DB) | B15: 15.06 | C15: 10.177 | D15: 12.434 | E15: 11.04 | F15: 9.403 | G15: 9.893 | H15: 7.426 | I15: no bank debt since FY2020
A16: Shareholders' equity | B16: 391.872 | C16: 147.986 | D16: 92.797 | E16: 114.316 | F16: 94.604 | G16: 96.851 | H16: 93.011
A17: Weighted avg shares (m) | B17: 124.814 | C17: 123.372 | D17: 142.088 | E17: 228.917 | F17: 264.352 | G17: 263.345 | H17: 267.346 | I17: EPS note
A18: Appen Global revenue | E18: 175.407 | F18: 127.874 | G18: 59.827 | H18: 43.719 | I18: segment note (restated FY2024)
A19: Appen China revenue | E19: 58.883 | F19: 102.9 | G19: 42.245 | H19: 76.196
A20: Appen Global EBITDA | E20: 9.2 | F20: 5.8 | G20: -3.6 | H20: -4.5 | I20: OFR
A21: Appen China EBITDA | E21: 1.4 | F21: 10.6 | G21: 2.9 | H21: 12.1 | I21: OFR
A24: FY2026 guidance (27-Aug-2026): revenue US$270-300m; underlying EBITDA before FX margin 5-10%.
A25: Shares on issue 30-Jun-2026: 268,523,648; unvested performance rights ~18.84m; buybacks: none.

Sheet Assumptions
A1: Global assumptions (blue = input)
A3: WACC (USD-built) | B3: 0.12 | C3: US 10y 5.0% + 5.0% ERP x beta 1.4; same in all scenarios
A4: Terminal value cap (x FCF_10) | B4: 15 | C4: 15x: cyclical, thin-margin business
A5: Lease cost % of revenue | B5: 0.017 | C5: treatment B: full lease payment in flows; FY2025 was 2.1%
A6: Net cash US$m (30-Jun-2026) | B6: 44.705 | C6: lease liabilities excluded (treatment B); no borrowings
A7: Diluted shares (m) | B7: 287.366 | C7: 268.524 on issue + 18.842 unvested rights; held flat
A8: Current price A$ | B8: 1.05 | C8: 2026-09-21T06:10:31Z ASX regular close (Yahoo regularMarketTime); 52wk A$0.65-1.975; 25 days after the 27-Aug-2026 H1 result (-14% on the day)
A9: AUDUSD | B9: 0.7133 | C9: Yahoo AUDUSD=X 2026-09-21
A10: USD -> AUD multiplier | B10: =1/B9 | C10: formula
A11: Hurdle rate | B11: 0.15 | C11: entry-price IRR
A12: FY2025 revenue US$m | B12: 230.774 | C12: FY0 base
A14: Scenario | B14: Terminal growth | C14: Probability | D14: WC capture % of revenue change
A15: bear | B15: 0.02 | C15: 0.3 | D15: -0.15
A16: base | B16: 0.03 | C16: 0.5 | D16: -0.12
A17: bull | B17: 0.035 | C17: 0.2 | D17: -0.1
A18: Weights check | C18: =SUM(C15:C17)
A20: Scenario narratives
A21: base: FY2026 revenue US$275m (+19%, low end of the US$270-300m guide: H1 was US$119.9m, H2 needs +21% YoY) at a 6.0% statutory EBITDA margin (~7% underlying before FX; H1 was 4.5%/3.0% but H2 FY2025 ran ~11%, so the year is H2-weighted). Appen China (+80% H1) decelerates to +30%/+20%/+12% and reaches ~80% of group revenue by FY2029 while Appen Global (-27% H1) shrinks a further ~30% then stabilises on foundation-model/RLHF work outside its largest client, giving group growth of 16/13/10/8% in FY2027-30 and a 3.5% exit. Group EBITDA margin climbs ~1pp/yr to 11% by FY2032 as China's 16% segment margin dominates the mix and Global reaches breakeven. Capex (capitalised product development) falls from 6.5% to 3.5% of revenue now that CrowdGen/Mercury replatforming is done; working capital consumes 12% of every revenue dollar added. Owner FCF is negative through FY2028 (-13/-8/-3) and only reaches a 2.7% margin at maturity: the cash the business generates at an 11% EBITDA margin is thin once leases, capex, China tax and receivables growth are paid for.
A22: bull: The Meta-Scale AI neutrality shock converts into durable share gains at Google, Microsoft, OpenAI and xAI, Appen Global returns to growth on RLHF/agentic-environment work, and Appen China sustains 40%+ growth on Chinese labs' international expansion: revenue US$286m (+24%) in FY2026 compounding at 22/18/14/11% to ~US$860m by FY2035. Operating leverage on a 40%+ gross margin takes group EBITDA to 15% by FY2033 (China 18%, Global 5%, corporate 1%). Working-capital drag eases to 10% as hyperscaler terms improve. Terminal growth 3.5%. This is the analyst-target (A$2.35) world and needs four things to go right at once: Scale share shift, Global stabilisation, China deceleration only gradual, and no large-client loss.
A23: bear: FY2026 lands just under the guidance floor (US$258m, +12%) at a 3.5% margin, then a top-5 client cuts volumes in FY2027 -- the Google FY2024 pattern repeated with a Chinese lab or hyperscaler -- and revenue falls 12% and 2% before creeping back at 2-3%. Margins collapse to 1% in the loss year and recover only to 5% because the crowd-based model has no pricing power against in-house RLHF pipelines and offshore niche vendors. At a 5% EBITDA margin the business never generates owner FCF (year-10 FCF -US$5m), so the terminal value sits on the ZERO FLOOR and the equity is worth the cash pile less a decade of burn: A$0.03/share. The bear case is a slow liquidation, not a bankruptcy -- no debt, and US$44.7m cash covers the ~US$30m cumulative burn without a raise.
A25: Weights rationale: Bear 30% / base 50% / bull 20%, against the 15/50/35 house default. Bear is doubled because the thesis rests on an unproven pivot with a single-customer-dependency history (Google walked in FY2024 and took ~US$60m of revenue with it; top-5 clients are still 68-74% of revenue), Appen Global is still shrinking 27%, and TTM owner FCF is -US$20m. Bull is cut because it needs the Scale-AI share shift, Global stabilisation, only gradual China deceleration and no client loss to all hold at once.

Sheet DCF_Bear
A1: BEAR scenario -- USD millions; drivers in blue (rows 5, 7, 9, 14, 17, 21)
A3: Year | B3: FY2025A | C3: FY2026E | D3: FY2027E | E3: FY2028E | F3: FY2029E | G3: FY2030E | H3: FY2031E | I3: FY2032E | J3: FY2033E | K3: FY2034E | L3: FY2035E
A4: Index | B4: 0 | C4: 1 | D4: 2 | E4: 3 | F4: 4 | G4: 5 | H4: 6 | I4: 7 | J4: 8 | K4: 9 | L4: 10
A5: Revenue growth | C5: 0.12 | D5: -0.12 | E5: -0.02 | F5: 0.02 | G5: 0.03 | H5: 0.03 | I5: 0.03 | J5: 0.03 | K5: 0.03 | L5: 0.03
A6: Revenue | B6: =Assumptions!B12 | C6: =B6*(1+C5) | D6: =C6*(1+D5) | E6: =D6*(1+E5) | F6: =E6*(1+F5) | G6: =F6*(1+G5) | H6: =G6*(1+H5) | I6: =H6*(1+I5) | J6: =I6*(1+J5) | ... L6: =K6*(1+L5)
A7: Adj EBITDA margin (post-AASB16, statutory) | C7: 0.035 | D7: 0.01 | E7: 0.025 | F7: 0.035 | G7: 0.04 | H7: 0.045 | I7: 0.05 | J7: 0.05 | K7: 0.05 | L7: 0.05
A8: Adjusted EBITDA | C8: =C6*C7 | D8: =D6*D7 | E8: =E6*E7 | F8: =F6*F7 | G8: =G6*G7 | H8: =H6*H7 | I8: =I6*I7 | J8: =J6*J7 | ... L8: =L6*L7
A9: SBC % revenue | C9: 0.007 | D9: 0.007 | E9: 0.007 | F9: 0.007 | G9: 0.007 | H9: 0.007 | I9: 0.007 | J9: 0.007 | K9: 0.007 | L9: 0.007
A10: SBC (expensed) | C10: =-C6*C9 | D10: =-D6*D9 | E10: =-E6*E9 | F10: =-F6*F9 | G10: =-G6*G9 | H10: =-H6*H9 | I10: =-I6*I9 | J10: =-J6*J9 | ... L10: =-L6*L9
A11: Lease cost % revenue | C11: =Assumptions!$B$5 | D11: =Assumptions!$B$5 | E11: =Assumptions!$B$5 | F11: =Assumptions!$B$5 | G11: =Assumptions!$B$5 | H11: =Assumptions!$B$5 | I11: =Assumptions!$B$5 | J11: =Assumptions!$B$5 | ... L11: =Assumptions!$B$5
A12: Lease payments (principal + interest) | C12: =-C6*C11 | D12: =-D6*D11 | E12: =-E6*E11 | F12: =-F6*F11 | G12: =-G6*G11 | H12: =-H6*H11 | I12: =-I6*I11 | J12: =-J6*J11 | ... L12: =-L6*L11
A13: Owner EBITDA (after SBC and leases) | C13: =C8+C10+C12 | D13: =D8+D10+D12 | E13: =E8+E10+E12 | F13: =F8+F10+F12 | G13: =G8+G10+G12 | H13: =H8+H10+H12 | I13: =I8+I10+I12 | J13: =J8+J10+J12 | ... L13: =L8+L10+L12
A14: D&A % revenue (ex ROU, ex acquired intangibles) | C14: 0.065 | D14: 0.06 | E14: 0.055 | F14: 0.05 | G14: 0.045 | H14: 0.04 | I14: 0.0375 | J14: 0.035 | K14: 0.035 | L14: 0.035
A15: D&A | C15: =-C6*C14 | D15: =-D6*D14 | E15: =-E6*E14 | F15: =-F6*F14 | G15: =-G6*G14 | H15: =-H6*H14 | I15: =-I6*I14 | J15: =-J6*J14 | ... L15: =-L6*L14
A16: EBIT (SBC and leases expensed) | C16: =C13+C15 | D16: =D13+D15 | E16: =E13+E15 | F16: =F13+F15 | G16: =G13+G15 | H16: =H13+H15 | I16: =I13+I15 | J16: =J13+J15 | ... L16: =L13+L15
A17: Cash tax rate (on positive EBIT) | C17: 0.3 | D17: 0.3 | E17: 0.28 | F17: 0.27 | G17: 0.26 | H17: 0.25 | I17: 0.25 | J17: 0.25 | K17: 0.25 | L17: 0.25
A18: Cash tax | C18: =-MAX(0,C16)*C17 | D18: =-MAX(0,D16)*D17 | E18: =-MAX(0,E16)*E17 | F18: =-MAX(0,F16)*F17 | G18: =-MAX(0,G16)*G17 | H18: =-MAX(0,H16)*H17 | I18: =-MAX(0,I16)*I17 | J18: =-MAX(0,J16)*J17 | ... L18: =-MAX(0,L16)*L17
A19: NOPAT | C19: =C16+C18 | D19: =D16+D18 | E19: =E16+E18 | F19: =F16+F18 | G19: =G16+G18 | H19: =H16+H18 | I19: =I16+I18 | J19: =J16+J18 | ... L19: =L16+L18
A20: add back D&A | C20: =-C15 | D20: =-D15 | E20: =-E15 | F20: =-F15 | G20: =-G15 | H20: =-H15 | I20: =-I15 | J20: =-J15 | ... L20: =-L15
A21: Capex % revenue | C21: 0.065 | D21: 0.06 | E21: 0.055 | F21: 0.05 | G21: 0.045 | H21: 0.04 | I21: 0.0375 | J21: 0.035 | K21: 0.035 | L21: 0.035
A22: Capex | C22: =-C6*C21 | D22: =-D6*D21 | E22: =-E6*E21 | F22: =-F6*F21 | G22: =-G6*G21 | H22: =-H6*H21 | I22: =-I6*I21 | J22: =-J6*J21 | ... L22: =-L6*L21
A23: Working capital (capture x revenue change) | C23: =Assumptions!$D$15*(C6-B6) | D23: =Assumptions!$D$15*(D6-C6) | E23: =Assumptions!$D$15*(E6-D6) | F23: =Assumptions!$D$15*(F6-E6) | G23: =Assumptions!$D$15*(G6-F6) | H23: =Assumptions!$D$15*(H6-G6) | I23: =Assumptions!$D$15*(I6-H6) | J23: =Assumptions!$D$15*(J6-I6) | ... L23: =Assumptions!$D$15*(L6-K6)
A24: Unlevered owner FCF | C24: =C19+C20+C22+C23 | D24: =D19+D20+D22+D23 | E24: =E19+E20+E22+E23 | F24: =F19+F20+F22+F23 | G24: =G19+G20+G22+G23 | H24: =H19+H20+H22+H23 | I24: =I19+I20+I22+I23 | J24: =J19+J20+J22+J23 | ... L24: =L19+L20+L22+L23
A25: Discount factor | C25: =1/(1+Assumptions!$B$3)^C4 | D25: =1/(1+Assumptions!$B$3)^D4 | E25: =1/(1+Assumptions!$B$3)^E4 | F25: =1/(1+Assumptions!$B$3)^F4 | G25: =1/(1+Assumptions!$B$3)^G4 | H25: =1/(1+Assumptions!$B$3)^H4 | I25: =1/(1+Assumptions!$B$3)^I4 | J25: =1/(1+Assumptions!$B$3)^J4 | ... L25: =1/(1+Assumptions!$B$3)^L4
A26: PV of FCF | C26: =C24*C25 | D26: =D24*D25 | E26: =E24*E25 | F26: =F24*F25 | G26: =G24*G25 | H26: =H24*H25 | I26: =I24*I25 | J26: =J24*J25 | ... L26: =L24*L25
A28: Memo: FCF before SBC (company-style) | C28: =C24-C10 | D28: =D24-D10 | E28: =E24-E10 | F28: =F24-F10 | G28: =G24-G10 | H28: =H24-H10 | I28: =I24-I10 | J28: =J24-J10 | ... L28: =L24-L10
A29: Memo: owner-FCF margin | C29: =C24/C6 | D29: =D24/D6 | E29: =E24/E6 | F29: =F24/F6 | G29: =G24/G6 | H29: =H24/H6 | I29: =I24/I6 | J29: =J24/J6 | ... L29: =L24/L6
A31: Sum of PV of FCF | B31: =SUM(C26:L26)
A32: Terminal growth | B32: =Assumptions!B15
A33: Terminal FCF (FCF_10 x (1+g)) | B33: =L24*(1+B32)
A34: Gordon TV | B34: =IF(Assumptions!B3>B32,B33/(Assumptions!B3-B32),"n/a")
A35: Cap TV (cap x FCF_10) | B35: =Assumptions!B4*L24
A36: TV used = MAX(0, MIN(Gordon, cap)) | B36: =MAX(0,MIN(IF(ISNUMBER(B34),B34,B35),B35))
A37: Implied exit multiple (TV / FCF_10) | B37: =IF(L24>0,B36/L24,"n/a")
A38: PV of TV | B38: =B36*L25
A39: Enterprise value | B39: =B31+B38
A40: add net cash | B40: =Assumptions!B6
A41: Equity value US$m | B41: =B39+B40
A42: Diluted shares (m) | B42: =Assumptions!B7
A43: Value per share US$ | B43: =B41/B42
...

Sheet DCF_Base
A1: BASE scenario -- USD millions; drivers in blue (rows 5, 7, 9, 14, 17, 21)
A3: Year | B3: FY2025A | C3: FY2026E | D3: FY2027E | E3: FY2028E | F3: FY2029E | G3: FY2030E | H3: FY2031E | I3: FY2032E | J3: FY2033E | K3: FY2034E | L3: FY2035E
A4: Index | B4: 0 | C4: 1 | D4: 2 | E4: 3 | F4: 4 | G4: 5 | H4: 6 | I4: 7 | J4: 8 | K4: 9 | L4: 10
A5: Revenue growth | C5: 0.19 | D5: 0.16 | E5: 0.13 | F5: 0.1 | G5: 0.08 | H5: 0.065 | I5: 0.055 | J5: 0.045 | K5: 0.04 | L5: 0.035
A6: Revenue | B6: =Assumptions!B12 | C6: =B6*(1+C5) | D6: =C6*(1+D5) | E6: =D6*(1+E5) | F6: =E6*(1+F5) | G6: =F6*(1+G5) | H6: =G6*(1+H5) | I6: =H6*(1+I5) | J6: =I6*(1+J5) | ... L6: =K6*(1+L5)
A7: Adj EBITDA margin (post-AASB16, statutory) | C7: 0.06 | D7: 0.075 | E7: 0.085 | F7: 0.095 | G7: 0.1 | H7: 0.105 | I7: 0.11 | J7: 0.11 | K7: 0.11 | L7: 0.11
A8: Adjusted EBITDA | C8: =C6*C7 | D8: =D6*D7 | E8: =E6*E7 | F8: =F6*F7 | G8: =G6*G7 | H8: =H6*H7 | I8: =I6*I7 | J8: =J6*J7 | ... L8: =L6*L7
A9: SBC % revenue | C9: 0.007 | D9: 0.007 | E9: 0.007 | F9: 0.0065 | G9: 0.0065 | H9: 0.006 | I9: 0.006 | J9: 0.006 | K9: 0.006 | L9: 0.006
A10: SBC (expensed) | C10: =-C6*C9 | D10: =-D6*D9 | E10: =-E6*E9 | F10: =-F6*F9 | G10: =-G6*G9 | H10: =-H6*H9 | I10: =-I6*I9 | J10: =-J6*J9 | ... L10: =-L6*L9
A11: Lease cost % revenue | C11: =Assumptions!$B$5 | D11: =Assumptions!$B$5 | E11: =Assumptions!$B$5 | F11: =Assumptions!$B$5 | G11: =Assumptions!$B$5 | H11: =Assumptions!$B$5 | I11: =Assumptions!$B$5 | J11: =Assumptions!$B$5 | ... L11: =Assumptions!$B$5
A12: Lease payments (principal + interest) | C12: =-C6*C11 | D12: =-D6*D11 | E12: =-E6*E11 | F12: =-F6*F11 | G12: =-G6*G11 | H12: =-H6*H11 | I12: =-I6*I11 | J12: =-J6*J11 | ... L12: =-L6*L11
A13: Owner EBITDA (after SBC and leases) | C13: =C8+C10+C12 | D13: =D8+D10+D12 | E13: =E8+E10+E12 | F13: =F8+F10+F12 | G13: =G8+G10+G12 | H13: =H8+H10+H12 | I13: =I8+I10+I12 | J13: =J8+J10+J12 | ... L13: =L8+L10+L12
A14: D&A % revenue (ex ROU, ex acquired intangibles) | C14: 0.065 | D14: 0.06 | E14: 0.055 | F14: 0.05 | G14: 0.045 | H14: 0.04 | I14: 0.0375 | J14: 0.035 | K14: 0.035 | L14: 0.035
A15: D&A | C15: =-C6*C14 | D15: =-D6*D14 | E15: =-E6*E14 | F15: =-F6*F14 | G15: =-G6*G14 | H15: =-H6*H14 | I15: =-I6*I14 | J15: =-J6*J14 | ... L15: =-L6*L14
A16: EBIT (SBC and leases expensed) | C16: =C13+C15 | D16: =D13+D15 | E16: =E13+E15 | F16: =F13+F15 | G16: =G13+G15 | H16: =H13+H15 | I16: =I13+I15 | J16: =J13+J15 | ... L16: =L13+L15
A17: Cash tax rate (on positive EBIT) | C17: 0.3 | D17: 0.3 | E17: 0.28 | F17: 0.27 | G17: 0.26 | H17: 0.25 | I17: 0.25 | J17: 0.25 | K17: 0.25 | L17: 0.25
A18: Cash tax | C18: =-MAX(0,C16)*C17 | D18: =-MAX(0,D16)*D17 | E18: =-MAX(0,E16)*E17 | F18: =-MAX(0,F16)*F17 | G18: =-MAX(0,G16)*G17 | H18: =-MAX(0,H16)*H17 | I18: =-MAX(0,I16)*I17 | J18: =-MAX(0,J16)*J17 | ... L18: =-MAX(0,L16)*L17
A19: NOPAT | C19: =C16+C18 | D19: =D16+D18 | E19: =E16+E18 | F19: =F16+F18 | G19: =G16+G18 | H19: =H16+H18 | I19: =I16+I18 | J19: =J16+J18 | ... L19: =L16+L18
A20: add back D&A | C20: =-C15 | D20: =-D15 | E20: =-E15 | F20: =-F15 | G20: =-G15 | H20: =-H15 | I20: =-I15 | J20: =-J15 | ... L20: =-L15
A21: Capex % revenue | C21: 0.065 | D21: 0.06 | E21: 0.055 | F21: 0.05 | G21: 0.045 | H21: 0.04 | I21: 0.0375 | J21: 0.035 | K21: 0.035 | L21: 0.035
A22: Capex | C22: =-C6*C21 | D22: =-D6*D21 | E22: =-E6*E21 | F22: =-F6*F21 | G22: =-G6*G21 | H22: =-H6*H21 | I22: =-I6*I21 | J22: =-J6*J21 | ... L22: =-L6*L21
A23: Working capital (capture x revenue change) | C23: =Assumptions!$D$16*(C6-B6) | D23: =Assumptions!$D$16*(D6-C6) | E23: =Assumptions!$D$16*(E6-D6) | F23: =Assumptions!$D$16*(F6-E6) | G23: =Assumptions!$D$16*(G6-F6) | H23: =Assumptions!$D$16*(H6-G6) | I23: =Assumptions!$D$16*(I6-H6) | J23: =Assumptions!$D$16*(J6-I6) | ... L23: =Assumptions!$D$16*(L6-K6)
A24: Unlevered owner FCF | C24: =C19+C20+C22+C23 | D24: =D19+D20+D22+D23 | E24: =E19+E20+E22+E23 | F24: =F19+F20+F22+F23 | G24: =G19+G20+G22+G23 | H24: =H19+H20+H22+H23 | I24: =I19+I20+I22+I23 | J24: =J19+J20+J22+J23 | ... L24: =L19+L20+L22+L23
A25: Discount factor | C25: =1/(1+Assumptions!$B$3)^C4 | D25: =1/(1+Assumptions!$B$3)^D4 | E25: =1/(1+Assumptions!$B$3)^E4 | F25: =1/(1+Assumptions!$B$3)^F4 | G25: =1/(1+Assumptions!$B$3)^G4 | H25: =1/(1+Assumptions!$B$3)^H4 | I25: =1/(1+Assumptions!$B$3)^I4 | J25: =1/(1+Assumptions!$B$3)^J4 | ... L25: =1/(1+Assumptions!$B$3)^L4
A26: PV of FCF | C26: =C24*C25 | D26: =D24*D25 | E26: =E24*E25 | F26: =F24*F25 | G26: =G24*G25 | H26: =H24*H25 | I26: =I24*I25 | J26: =J24*J25 | ... L26: =L24*L25
A28: Memo: FCF before SBC (company-style) | C28: =C24-C10 | D28: =D24-D10 | E28: =E24-E10 | F28: =F24-F10 | G28: =G24-G10 | H28: =H24-H10 | I28: =I24-I10 | J28: =J24-J10 | ... L28: =L24-L10
A29: Memo: owner-FCF margin | C29: =C24/C6 | D29: =D24/D6 | E29: =E24/E6 | F29: =F24/F6 | G29: =G24/G6 | H29: =H24/H6 | I29: =I24/I6 | J29: =J24/J6 | ... L29: =L24/L6
A31: Sum of PV of FCF | B31: =SUM(C26:L26)
A32: Terminal growth | B32: =Assumptions!B16
A33: Terminal FCF (FCF_10 x (1+g)) | B33: =L24*(1+B32)
A34: Gordon TV | B34: =IF(Assumptions!B3>B32,B33/(Assumptions!B3-B32),"n/a")
A35: Cap TV (cap x FCF_10) | B35: =Assumptions!B4*L24
A36: TV used = MAX(0, MIN(Gordon, cap)) | B36: =MAX(0,MIN(IF(ISNUMBER(B34),B34,B35),B35))
A37: Implied exit multiple (TV / FCF_10) | B37: =IF(L24>0,B36/L24,"n/a")
A38: PV of TV | B38: =B36*L25
A39: Enterprise value | B39: =B31+B38
A40: add net cash | B40: =Assumptions!B6
A41: Equity value US$m | B41: =B39+B40
A42: Diluted shares (m) | B42: =Assumptions!B7
A43: Value per share US$ | B43: =B41/B42
...

Sheet DCF_Bull
A1: BULL scenario -- USD millions; drivers in blue (rows 5, 7, 9, 14, 17, 21)
A3: Year | B3: FY2025A | C3: FY2026E | D3: FY2027E | E3: FY2028E | F3: FY2029E | G3: FY2030E | H3: FY2031E | I3: FY2032E | J3: FY2033E | K3: FY2034E | L3: FY2035E
A4: Index | B4: 0 | C4: 1 | D4: 2 | E4: 3 | F4: 4 | G4: 5 | H4: 6 | I4: 7 | J4: 8 | K4: 9 | L4: 10
A5: Revenue growth | C5: 0.24 | D5: 0.22 | E5: 0.18 | F5: 0.14 | G5: 0.11 | H5: 0.09 | I5: 0.07 | J5: 0.06 | K5: 0.05 | L5: 0.04
A6: Revenue | B6: =Assumptions!B12 | C6: =B6*(1+C5) | D6: =C6*(1+D5) | E6: =D6*(1+E5) | F6: =E6*(1+F5) | G6: =F6*(1+G5) | H6: =G6*(1+H5) | I6: =H6*(1+I5) | J6: =I6*(1+J5) | ... L6: =K6*(1+L5)
A7: Adj EBITDA margin (post-AASB16, statutory) | C7: 0.07 | D7: 0.09 | E7: 0.11 | F7: 0.125 | G7: 0.135 | H7: 0.14 | I7: 0.145 | J7: 0.15 | K7: 0.15 | L7: 0.15
A8: Adjusted EBITDA | C8: =C6*C7 | D8: =D6*D7 | E8: =E6*E7 | F8: =F6*F7 | G8: =G6*G7 | H8: =H6*H7 | I8: =I6*I7 | J8: =J6*J7 | ... L8: =L6*L7
A9: SBC % revenue | C9: 0.007 | D9: 0.007 | E9: 0.007 | F9: 0.0065 | G9: 0.0065 | H9: 0.006 | I9: 0.006 | J9: 0.006 | K9: 0.006 | L9: 0.006
A10: SBC (expensed) | C10: =-C6*C9 | D10: =-D6*D9 | E10: =-E6*E9 | F10: =-F6*F9 | G10: =-G6*G9 | H10: =-H6*H9 | I10: =-I6*I9 | J10: =-J6*J9 | ... L10: =-L6*L9
A11: Lease cost % revenue | C11: =Assumptions!$B$5 | D11: =Assumptions!$B$5 | E11: =Assumptions!$B$5 | F11: =Assumptions!$B$5 | G11: =Assumptions!$B$5 | H11: =Assumptions!$B$5 | I11: =Assumptions!$B$5 | J11: =Assumptions!$B$5 | ... L11: =Assumptions!$B$5
A12: Lease payments (principal + interest) | C12: =-C6*C11 | D12: =-D6*D11 | E12: =-E6*E11 | F12: =-F6*F11 | G12: =-G6*G11 | H12: =-H6*H11 | I12: =-I6*I11 | J12: =-J6*J11 | ... L12: =-L6*L11
A13: Owner EBITDA (after SBC and leases) | C13: =C8+C10+C12 | D13: =D8+D10+D12 | E13: =E8+E10+E12 | F13: =F8+F10+F12 | G13: =G8+G10+G12 | H13: =H8+H10+H12 | I13: =I8+I10+I12 | J13: =J8+J10+J12 | ... L13: =L8+L10+L12
A14: D&A % revenue (ex ROU, ex acquired intangibles) | C14: 0.065 | D14: 0.06 | E14: 0.055 | F14: 0.05 | G14: 0.045 | H14: 0.04 | I14: 0.0375 | J14: 0.035 | K14: 0.035 | L14: 0.035
A15: D&A | C15: =-C6*C14 | D15: =-D6*D14 | E15: =-E6*E14 | F15: =-F6*F14 | G15: =-G6*G14 | H15: =-H6*H14 | I15: =-I6*I14 | J15: =-J6*J14 | ... L15: =-L6*L14
A16: EBIT (SBC and leases expensed) | C16: =C13+C15 | D16: =D13+D15 | E16: =E13+E15 | F16: =F13+F15 | G16: =G13+G15 | H16: =H13+H15 | I16: =I13+I15 | J16: =J13+J15 | ... L16: =L13+L15
A17: Cash tax rate (on positive EBIT) | C17: 0.3 | D17: 0.3 | E17: 0.28 | F17: 0.27 | G17: 0.26 | H17: 0.25 | I17: 0.25 | J17: 0.25 | K17: 0.25 | L17: 0.25
A18: Cash tax | C18: =-MAX(0,C16)*C17 | D18: =-MAX(0,D16)*D17 | E18: =-MAX(0,E16)*E17 | F18: =-MAX(0,F16)*F17 | G18: =-MAX(0,G16)*G17 | H18: =-MAX(0,H16)*H17 | I18: =-MAX(0,I16)*I17 | J18: =-MAX(0,J16)*J17 | ... L18: =-MAX(0,L16)*L17
A19: NOPAT | C19: =C16+C18 | D19: =D16+D18 | E19: =E16+E18 | F19: =F16+F18 | G19: =G16+G18 | H19: =H16+H18 | I19: =I16+I18 | J19: =J16+J18 | ... L19: =L16+L18
A20: add back D&A | C20: =-C15 | D20: =-D15 | E20: =-E15 | F20: =-F15 | G20: =-G15 | H20: =-H15 | I20: =-I15 | J20: =-J15 | ... L20: =-L15
A21: Capex % revenue | C21: 0.065 | D21: 0.06 | E21: 0.055 | F21: 0.05 | G21: 0.045 | H21: 0.04 | I21: 0.0375 | J21: 0.035 | K21: 0.035 | L21: 0.035
A22: Capex | C22: =-C6*C21 | D22: =-D6*D21 | E22: =-E6*E21 | F22: =-F6*F21 | G22: =-G6*G21 | H22: =-H6*H21 | I22: =-I6*I21 | J22: =-J6*J21 | ... L22: =-L6*L21
A23: Working capital (capture x revenue change) | C23: =Assumptions!$D$17*(C6-B6) | D23: =Assumptions!$D$17*(D6-C6) | E23: =Assumptions!$D$17*(E6-D6) | F23: =Assumptions!$D$17*(F6-E6) | G23: =Assumptions!$D$17*(G6-F6) | H23: =Assumptions!$D$17*(H6-G6) | I23: =Assumptions!$D$17*(I6-H6) | J23: =Assumptions!$D$17*(J6-I6) | ... L23: =Assumptions!$D$17*(L6-K6)
A24: Unlevered owner FCF | C24: =C19+C20+C22+C23 | D24: =D19+D20+D22+D23 | E24: =E19+E20+E22+E23 | F24: =F19+F20+F22+F23 | G24: =G19+G20+G22+G23 | H24: =H19+H20+H22+H23 | I24: =I19+I20+I22+I23 | J24: =J19+J20+J22+J23 | ... L24: =L19+L20+L22+L23
A25: Discount factor | C25: =1/(1+Assumptions!$B$3)^C4 | D25: =1/(1+Assumptions!$B$3)^D4 | E25: =1/(1+Assumptions!$B$3)^E4 | F25: =1/(1+Assumptions!$B$3)^F4 | G25: =1/(1+Assumptions!$B$3)^G4 | H25: =1/(1+Assumptions!$B$3)^H4 | I25: =1/(1+Assumptions!$B$3)^I4 | J25: =1/(1+Assumptions!$B$3)^J4 | ... L25: =1/(1+Assumptions!$B$3)^L4
A26: PV of FCF | C26: =C24*C25 | D26: =D24*D25 | E26: =E24*E25 | F26: =F24*F25 | G26: =G24*G25 | H26: =H24*H25 | I26: =I24*I25 | J26: =J24*J25 | ... L26: =L24*L25
A28: Memo: FCF before SBC (company-style) | C28: =C24-C10 | D28: =D24-D10 | E28: =E24-E10 | F28: =F24-F10 | G28: =G24-G10 | H28: =H24-H10 | I28: =I24-I10 | J28: =J24-J10 | ... L28: =L24-L10
A29: Memo: owner-FCF margin | C29: =C24/C6 | D29: =D24/D6 | E29: =E24/E6 | F29: =F24/F6 | G29: =G24/G6 | H29: =H24/H6 | I29: =I24/I6 | J29: =J24/J6 | ... L29: =L24/L6
A31: Sum of PV of FCF | B31: =SUM(C26:L26)
A32: Terminal growth | B32: =Assumptions!B17
A33: Terminal FCF (FCF_10 x (1+g)) | B33: =L24*(1+B32)
A34: Gordon TV | B34: =IF(Assumptions!B3>B32,B33/(Assumptions!B3-B32),"n/a")
A35: Cap TV (cap x FCF_10) | B35: =Assumptions!B4*L24
A36: TV used = MAX(0, MIN(Gordon, cap)) | B36: =MAX(0,MIN(IF(ISNUMBER(B34),B34,B35),B35))
A37: Implied exit multiple (TV / FCF_10) | B37: =IF(L24>0,B36/L24,"n/a")
A38: PV of TV | B38: =B36*L25
A39: Enterprise value | B39: =B31+B38
A40: add net cash | B40: =Assumptions!B6
A41: Equity value US$m | B41: =B39+B40
A42: Diluted shares (m) | B42: =Assumptions!B7
A43: Value per share US$ | B43: =B41/B42
...

Sheet FCF_Quality
A1: Reported FCF reconciled to owner FCF (USD millions, USD era only)
A3: Line | B3: FY2022 | C3: FY2023 | D3: FY2024 | E3: FY2025 | F3: TTM Jun-26
A4: Revenue | B4: 388.133 | C4: 273.012 | D4: 234.285 | E4: 230.774 | F4: 248.617
A5: Free cash flow (company definition: OCF - capex) | B5: -9.703 | C5: -42.792 | D5: -13.511 | E5: 6.329 | F5: -12.87
A6: less: SBC (no equity-award cash taxes disclosed) | B6: 1.492 | C6: 5.691 | D6: 4.077 | E6: 1.299 | F6: 1.839
A7: less: interest income | B7: 0.183 | C7: 0.371 | D7: 0.482 | E7: 0.773 | F7: 0.654
A8: less: lease payments (principal + interest) | B8: 4.508 | C8: 4.763 | D8: 4.398 | E8: 4.848 | F8: 5.129
A9: Owner FCF (equals FCF less the three deductions) | B9: =B5-B6-B7-B8 | C9: =C5-C6-C7-C8 | D9: =D5-D6-D7-D8 | E9: =E5-E6-E7-E8 | F9: =F5-F6-F7-F8
A10: Reported FCF margin | B10: =B5/B4 | C10: =C5/C4 | D10: =D5/D4 | E10: =E5/E4 | F10: =F5/F4
A11: Owner FCF margin | B11: =B9/B4 | C11: =C9/C4 | D11: =D9/D4 | E11: =E9/E4 | F11: =F9/F4
A12: Memo: receivables + contract assets change inside OCF (US$m, + = release) | D12: 0.967 | E12: 12.005 | F12: -0.8
A13: Memo: cash tax paid | D13: 0.068 | E13: 0.222 | F13: 1.79
A15: Cash tax is near zero because US$104m of US and US$20m of China tax losses are unrecognised; the FY2025 near-breakeven owner FCF rests on a US$12.0m receivables release that reversed in H1 FY2026 (contract assets +US$12.8m). TTM columns are FY2025 + H1 FY2026 - H1 FY2025.

Sheet Valuation
A1: Valuation summary (per-share values in A$ unless marked)
A3: Scenario | B3: Value/share A$ | C3: Upside vs price | D3: Probability | E3: Street value/share A$ | F3: Value/share US$ | G3: TV bound
A4: bear | B4: =DCF_Bear!B44 | C4: =DCF_Bear!B45 | D4: =Assumptions!C15 | E4: =DCF_Bear!B49 | F4: =DCF_Bear!B43 | G4: =IF(DCF_Bear!B36=0,"floor",IF(DCF_Bear!B35<IF(ISNUMBER(DCF_Bear!B34),DCF_Bear!B34,DCF_Bear!B35),"cap","gordon"))
A5: base | B5: =DCF_Base!B44 | C5: =DCF_Base!B45 | D5: =Assumptions!C16 | E5: =DCF_Base!B49 | F5: =DCF_Base!B43 | G5: =IF(DCF_Base!B36=0,"floor",IF(DCF_Base!B35<IF(ISNUMBER(DCF_Base!B34),DCF_Base!B34,DCF_Base!B35),"cap","gordon"))
A6: bull | B6: =DCF_Bull!B44 | C6: =DCF_Bull!B45 | D6: =Assumptions!C17 | E6: =DCF_Bull!B49 | F6: =DCF_Bull!B43 | G6: =IF(DCF_Bull!B36=0,"floor",IF(DCF_Bull!B35<IF(ISNUMBER(DCF_Bull!B34),DCF_Bull!B34,DCF_Bull!B35),"cap","gordon"))
A8: Probability-weighted value A$ | B8: =SUMPRODUCT(B4:B6,D4:D6)
A9: Margin of safety (1 - price/weighted) | B9: =1-Assumptions!B8/B8
A10: Street weighted value A$ | B10: =SUMPRODUCT(E4:E6,D4:D6)
A11: Band position (price - house)/(street - house) | B11: =IF(ABS(B10-B8)<0.0001,"n/a",(Assumptions!B8-B8)/(B10-B8))
A12: Current price A$ | B12: =Assumptions!B8
A14: Required-return table (base case; TV rebuilt at each rate)
A15: Required return | B15: Value/share A$
A16: 0.09 | B16: =(SUMPRODUCT(DCF_Base!$C$24:$L$24/(1+$A16)^DCF_Base!$C$4:$L$4)+MAX(0,MIN(IF($A16>Assumptions!$B$16,DCF_Base!$L$24*(1+Assumptions!$B$16)/($A16-Assumptions!$B$16),Assumptions!$B$4*DCF_Base!$L$24),Assumptions!$B$4*DCF_Base!$L$24))/(1+$A16)^10+Assumptions!$B$6)/Assumptions!$B$7*Assumptions!$B$10
A17: 0.1 | B17: =(SUMPRODUCT(DCF_Base!$C$24:$L$24/(1+$A17)^DCF_Base!$C$4:$L$4)+MAX(0,MIN(IF($A17>Assumptions!$B$16,DCF_Base!$L$24*(1+Assumptions!$B$16)/($A17-Assumptions!$B$16),Assumptions!$B$4*DCF_Base!$L$24),Assumptions!$B$4*DCF_Base!$L$24))/(1+$A17)^10+Assumptions!$B$6)/Assumptions!$B$7*Assumptions!$B$10
A18: 0.11 | B18: =(SUMPRODUCT(DCF_Base!$C$24:$L$24/(1+$A18)^DCF_Base!$C$4:$L$4)+MAX(0,MIN(IF($A18>Assumptions!$B$16,DCF_Base!$L$24*(1+Assumptions!$B$16)/($A18-Assumptions!$B$16),Assumptions!$B$4*DCF_Base!$L$24),Assumptions!$B$4*DCF_Base!$L$24))/(1+$A18)^10+Assumptions!$B$6)/Assumptions!$B$7*Assumptions!$B$10
A19: 0.12 | B19: =(SUMPRODUCT(DCF_Base!$C$24:$L$24/(1+$A19)^DCF_Base!$C$4:$L$4)+MAX(0,MIN(IF($A19>Assumptions!$B$16,DCF_Base!$L$24*(1+Assumptions!$B$16)/($A19-Assumptions!$B$16),Assumptions!$B$4*DCF_Base!$L$24),Assumptions!$B$4*DCF_Base!$L$24))/(1+$A19)^10+Assumptions!$B$6)/Assumptions!$B$7*Assumptions!$B$10 | C19: WACC row: must equal DCF_Base!B44
A20: 0.15 | B20: =(SUMPRODUCT(DCF_Base!$C$24:$L$24/(1+$A20)^DCF_Base!$C$4:$L$4)+MAX(0,MIN(IF($A20>Assumptions!$B$16,DCF_Base!$L$24*(1+Assumptions!$B$16)/($A20-Assumptions!$B$16),Assumptions!$B$4*DCF_Base!$L$24),Assumptions!$B$4*DCF_Base!$L$24))/(1+$A20)^10+Assumptions!$B$6)/Assumptions!$B$7*Assumptions!$B$10 | C20: Hurdle row (15%): must equal base entry price below
A23: 15%-hurdle entry prices (TV rebuilt at the hurdle rate)
A24: Scenario | B24: Entry price A$ | C24: Probability | D24: Discount vs price
A25: bear | B25: =(SUMPRODUCT(DCF_Bear!$C$24:$L$24/(1+Assumptions!$B$11)^DCF_Bear!$C$4:$L$4)+MAX(0,MIN(IF(Assumptions!$B$11>Assumptions!$B$15,DCF_Bear!$L$24*(1+Assumptions!$B$15)/(Assumptions!$B$11-Assumptions!$B$15),Assumptions!$B$4*DCF_Bear!$L$24),Assumptions!$B$4*DCF_Bear!$L$24))/(1+Assumptions!$B$11)^10+Assumptions!$B$6)/Assumptions!$B$7*Assumptions!$B$10 | C25: =Assumptions!C15 | D25: =B25/Assumptions!$B$8-1
A26: base | B26: =(SUMPRODUCT(DCF_Base!$C$24:$L$24/(1+Assumptions!$B$11)^DCF_Base!$C$4:$L$4)+MAX(0,MIN(IF(Assumptions!$B$11>Assumptions!$B$16,DCF_Base!$L$24*(1+Assumptions!$B$16)/(Assumptions!$B$11-Assumptions!$B$16),Assumptions!$B$4*DCF_Base!$L$24),Assumptions!$B$4*DCF_Base!$L$24))/(1+Assumptions!$B$11)^10+Assumptions!$B$6)/Assumptions!$B$7*Assumptions!$B$10 | C26: =Assumptions!C16 | D26: =B26/Assumptions!$B$8-1
A27: bull | B27: =(SUMPRODUCT(DCF_Bull!$C$24:$L$24/(1+Assumptions!$B$11)^DCF_Bull!$C$4:$L$4)+MAX(0,MIN(IF(Assumptions!$B$11>Assumptions!$B$17,DCF_Bull!$L$24*(1+Assumptions!$B$17)/(Assumptions!$B$11-Assumptions!$B$17),Assumptions!$B$4*DCF_Bull!$L$24),Assumptions!$B$4*DCF_Bull!$L$24))/(1+Assumptions!$B$11)^10+Assumptions!$B$6)/Assumptions!$B$7*Assumptions!$B$10 | C27: =Assumptions!C17 | D27: =B27/Assumptions!$B$8-1
A28: Probability-weighted entry price A$ (buy-below) | B28: =SUMPRODUCT(B25:B27,C25:C27)
A31: Sensitivity: base-case value/share A$ -- rows WACC, columns terminal growth (TV re-capped at every cell)
B32: 0.02 | C32: 0.025 | D32: 0.03 | E32: 0.035 | F32: 0.04
A33: 0.1 | B33: =(SUMPRODUCT(DCF_Base!$C$24:$L$24/(1+$A33)^DCF_Base!$C$4:$L$4)+MAX(0,MIN(IF($A33>B$32,DCF_Base!$L$24*(1+B$32)/($A33-B$32),Assumptions!$B$4*DCF_Base!$L$24),Assumptions!$B$4*DCF_Base!$L$24))/(1+$A33)^10+Assumptions!$B$6)/Assumptions!$B$7*Assumptions!$B$10 | C33: =(SUMPRODUCT(DCF_Base!$C$24:$L$24/(1+$A33)^DCF_Base!$C$4:$L$4)+MAX(0,MIN(IF($A33>C$32,DCF_Base!$L$24*(1+C$32)/($A33-C$32),Assumptions!$B$4*DCF_Base!$L$24),Assumptions!$B$4*DCF_Base!$L$24))/(1+$A33)^10+Assumptions!$B$6)/Assumptions!$B$7*Assumptions!$B$10 | D33: =(SUMPRODUCT(DCF_Base!$C$24:$L$24/(1+$A33)^DCF_Base!$C$4:$L$4)+MAX(0,MIN(IF($A33>D$32,DCF_Base!$L$24*(1+D$32)/($A33-D$32),Assumptions!$B$4*DCF_Base!$L$24),Assumptions!$B$4*DCF_Base!$L$24))/(1+$A33)^10+Assumptions!$B$6)/Assumptions!$B$7*Assumptions!$B$10 | E33: =(SUMPRODUCT(DCF_Base!$C$24:$L$24/(1+$A33)^DCF_Base!$C$4:$L$4)+MAX(0,MIN(IF($A33>E$32,DCF_Base!$L$24*(1+E$32)/($A33-E$32),Assumptions!$B$4*DCF_Base!$L$24),Assumptions!$B$4*DCF_Base!$L$24))/(1+$A33)^10+Assumptions!$B$6)/Assumptions!$B$7*Assumptions!$B$10 | F33: =(SUMPRODUCT(DCF_Base!$C$24:$L$24/(1+$A33)^DCF_Base!$C$4:$L$4)+MAX(0,MIN(IF($A33>F$32,DCF_Base!$L$24*(1+F$32)/($A33-F$32),Assumptions!$B$4*DCF_Base!$L$24),Assumptions!$B$4*DCF_Base!$L$24))/(1+$A33)^10+Assumptions!$B$6)/Assumptions!$B$7*Assumptions!$B$10
A34: 0.11 | B34: =(SUMPRODUCT(DCF_Base!$C$24:$L$24/(1+$A34)^DCF_Base!$C$4:$L$4)+MAX(0,MIN(IF($A34>B$32,DCF_Base!$L$24*(1+B$32)/($A34-B$32),Assumptions!$B$4*DCF_Base!$L$24),Assumptions!$B$4*DCF_Base!$L$24))/(1+$A34)^10+Assumptions!$B$6)/Assumptions!$B$7*Assumptions!$B$10 | C34: =(SUMPRODUCT(DCF_Base!$C$24:$L$24/(1+$A34)^DCF_Base!$C$4:$L$4)+MAX(0,MIN(IF($A34>C$32,DCF_Base!$L$24*(1+C$32)/($A34-C$32),Assumptions!$B$4*DCF_Base!$L$24),Assumptions!$B$4*DCF_Base!$L$24))/(1+$A34)^10+Assumptions!$B$6)/Assumptions!$B$7*Assumptions!$B$10 | D34: =(SUMPRODUCT(DCF_Base!$C$24:$L$24/(1+$A34)^DCF_Base!$C$4:$L$4)+MAX(0,MIN(IF($A34>D$32,DCF_Base!$L$24*(1+D$32)/($A34-D$32),Assumptions!$B$4*DCF_Base!$L$24),Assumptions!$B$4*DCF_Base!$L$24))/(1+$A34)^10+Assumptions!$B$6)/Assumptions!$B$7*Assumptions!$B$10 | E34: =(SUMPRODUCT(DCF_Base!$C$24:$L$24/(1+$A34)^DCF_Base!$C$4:$L$4)+MAX(0,MIN(IF($A34>E$32,DCF_Base!$L$24*(1+E$32)/($A34-E$32),Assumptions!$B$4*DCF_Base!$L$24),Assumptions!$B$4*DCF_Base!$L$24))/(1+$A34)^10+Assumptions!$B$6)/Assumptions!$B$7*Assumptions!$B$10 | F34: =(SUMPRODUCT(DCF_Base!$C$24:$L$24/(1+$A34)^DCF_Base!$C$4:$L$4)+MAX(0,MIN(IF($A34>F$32,DCF_Base!$L$24*(1+F$32)/($A34-F$32),Assumptions!$B$4*DCF_Base!$L$24),Assumptions!$B$4*DCF_Base!$L$24))/(1+$A34)^10+Assumptions!$B$6)/Assumptions!$B$7*Assumptions!$B$10
A35: 0.12 | B35: =(SUMPRODUCT(DCF_Base!$C$24:$L$24/(1+$A35)^DCF_Base!$C$4:$L$4)+MAX(0,MIN(IF($A35>B$32,DCF_Base!$L$24*(1+B$32)/($A35-B$32),Assumptions!$B$4*DCF_Base!$L$24),Assumptions!$B$4*DCF_Base!$L$24))/(1+$A35)^10+Assumptions!$B$6)/Assumptions!$B$7*Assumptions!$B$10 | C35: =(SUMPRODUCT(DCF_Base!$C$24:$L$24/(1+$A35)^DCF_Base!$C$4:$L$4)+MAX(0,MIN(IF($A35>C$32,DCF_Base!$L$24*(1+C$32)/($A35-C$32),Assumptions!$B$4*DCF_Base!$L$24),Assumptions!$B$4*DCF_Base!$L$24))/(1+$A35)^10+Assumptions!$B$6)/Assumptions!$B$7*Assumptions!$B$10 | D35: =(SUMPRODUCT(DCF_Base!$C$24:$L$24/(1+$A35)^DCF_Base!$C$4:$L$4)+MAX(0,MIN(IF($A35>D$32,DCF_Base!$L$24*(1+D$32)/($A35-D$32),Assumptions!$B$4*DCF_Base!$L$24),Assumptions!$B$4*DCF_Base!$L$24))/(1+$A35)^10+Assumptions!$B$6)/Assumptions!$B$7*Assumptions!$B$10 | E35: =(SUMPRODUCT(DCF_Base!$C$24:$L$24/(1+$A35)^DCF_Base!$C$4:$L$4)+MAX(0,MIN(IF($A35>E$32,DCF_Base!$L$24*(1+E$32)/($A35-E$32),Assumptions!$B$4*DCF_Base!$L$24),Assumptions!$B$4*DCF_Base!$L$24))/(1+$A35)^10+Assumptions!$B$6)/Assumptions!$B$7*Assumptions!$B$10 | F35: =(SUMPRODUCT(DCF_Base!$C$24:$L$24/(1+$A35)^DCF_Base!$C$4:$L$4)+MAX(0,MIN(IF($A35>F$32,DCF_Base!$L$24*(1+F$32)/($A35-F$32),Assumptions!$B$4*DCF_Base!$L$24),Assumptions!$B$4*DCF_Base!$L$24))/(1+$A35)^10+Assumptions!$B$6)/Assumptions!$B$7*Assumptions!$B$10
A36: 0.13 | B36: =(SUMPRODUCT(DCF_Base!$C$24:$L$24/(1+$A36)^DCF_Base!$C$4:$L$4)+MAX(0,MIN(IF($A36>B$32,DCF_Base!$L$24*(1+B$32)/($A36-B$32),Assumptions!$B$4*DCF_Base!$L$24),Assumptions!$B$4*DCF_Base!$L$24))/(1+$A36)^10+Assumptions!$B$6)/Assumptions!$B$7*Assumptions!$B$10 | C36: =(SUMPRODUCT(DCF_Base!$C$24:$L$24/(1+$A36)^DCF_Base!$C$4:$L$4)+MAX(0,MIN(IF($A36>C$32,DCF_Base!$L$24*(1+C$32)/($A36-C$32),Assumptions!$B$4*DCF_Base!$L$24),Assumptions!$B$4*DCF_Base!$L$24))/(1+$A36)^10+Assumptions!$B$6)/Assumptions!$B$7*Assumptions!$B$10 | D36: =(SUMPRODUCT(DCF_Base!$C$24:$L$24/(1+$A36)^DCF_Base!$C$4:$L$4)+MAX(0,MIN(IF($A36>D$32,DCF_Base!$L$24*(1+D$32)/($A36-D$32),Assumptions!$B$4*DCF_Base!$L$24),Assumptions!$B$4*DCF_Base!$L$24))/(1+$A36)^10+Assumptions!$B$6)/Assumptions!$B$7*Assumptions!$B$10 | E36: =(SUMPRODUCT(DCF_Base!$C$24:$L$24/(1+$A36)^DCF_Base!$C$4:$L$4)+MAX(0,MIN(IF($A36>E$32,DCF_Base!$L$24*(1+E$32)/($A36-E$32),Assumptions!$B$4*DCF_Base!$L$24),Assumptions!$B$4*DCF_Base!$L$24))/(1+$A36)^10+Assumptions!$B$6)/Assumptions!$B$7*Assumptions!$B$10 | F36: =(SUMPRODUCT(DCF_Base!$C$24:$L$24/(1+$A36)^DCF_Base!$C$4:$L$4)+MAX(0,MIN(IF($A36>F$32,DCF_Base!$L$24*(1+F$32)/($A36-F$32),Assumptions!$B$4*DCF_Base!$L$24),Assumptions!$B$4*DCF_Base!$L$24))/(1+$A36)^10+Assumptions!$B$6)/Assumptions!$B$7*Assumptions!$B$10
A37: 0.14 | B37: =(SUMPRODUCT(DCF_Base!$C$24:$L$24/(1+$A37)^DCF_Base!$C$4:$L$4)+MAX(0,MIN(IF($A37>B$32,DCF_Base!$L$24*(1+B$32)/($A37-B$32),Assumptions!$B$4*DCF_Base!$L$24),Assumptions!$B$4*DCF_Base!$L$24))/(1+$A37)^10+Assumptions!$B$6)/Assumptions!$B$7*Assumptions!$B$10 | C37: =(SUMPRODUCT(DCF_Base!$C$24:$L$24/(1+$A37)^DCF_Base!$C$4:$L$4)+MAX(0,MIN(IF($A37>C$32,DCF_Base!$L$24*(1+C$32)/($A37-C$32),Assumptions!$B$4*DCF_Base!$L$24),Assumptions!$B$4*DCF_Base!$L$24))/(1+$A37)^10+Assumptions!$B$6)/Assumptions!$B$7*Assumptions!$B$10 | D37: =(SUMPRODUCT(DCF_Base!$C$24:$L$24/(1+$A37)^DCF_Base!$C$4:$L$4)+MAX(0,MIN(IF($A37>D$32,DCF_Base!$L$24*(1+D$32)/($A37-D$32),Assumptions!$B$4*DCF_Base!$L$24),Assumptions!$B$4*DCF_Base!$L$24))/(1+$A37)^10+Assumptions!$B$6)/Assumptions!$B$7*Assumptions!$B$10 | E37: =(SUMPRODUCT(DCF_Base!$C$24:$L$24/(1+$A37)^DCF_Base!$C$4:$L$4)+MAX(0,MIN(IF($A37>E$32,DCF_Base!$L$24*(1+E$32)/($A37-E$32),Assumptions!$B$4*DCF_Base!$L$24),Assumptions!$B$4*DCF_Base!$L$24))/(1+$A37)^10+Assumptions!$B$6)/Assumptions!$B$7*Assumptions!$B$10 | F37: =(SUMPRODUCT(DCF_Base!$C$24:$L$24/(1+$A37)^DCF_Base!$C$4:$L$4)+MAX(0,MIN(IF($A37>F$32,DCF_Base!$L$24*(1+F$32)/($A37-F$32),Assumptions!$B$4*DCF_Base!$L$24),Assumptions!$B$4*DCF_Base!$L$24))/(1+$A37)^10+Assumptions!$B$6)/Assumptions!$B$7*Assumptions!$B$10
