Workbook

Sheet NAV Model
A1: KFL.NZ (Kingfish Limited) NAV Compounding Valuation Model
A2: NOT an FCF DCF -- closed-end LIC valued on NAV/share compounding x exit price-to-NAV. Gray cells are INPUTS.
A4: KEY INPUTS
A5: Current Share Price | B5: 1.2
A6: Shares Outstanding (M) | B6: 358.84419
A7: Starting NAV per Share (FY2026) | B7: 1.2
A8: Net Assets (M) | B8: 431.37
A9: Cash & Equivalents (M) | B9: 7.016
A10: Total Debt (M) | B10: 0
A11: Net Debt (M) | B11: =B10-B9 -> 0 | C11: <- always ~0/negative; Kingfish carries no debt and NAV already nets this
A13: Cost of Equity (WACC field) | B13: 0.1
A15: SCENARIO ASSUMPTIONS (BASE CASE ACTIVE BELOW)
B16: Bear | C16: Base | D16: Bull
A18: Gross Portfolio Return % | B18: 0.03 | C18: 0.065 | D18: 0.095
A19: Fee Drag % | B19: 0.012 | C19: 0.011 | D19: 0.0115
A20: Net Return % (=Gross-Fee) | B20: 0.018 | C20: 0.054 | D20: 0.0835
A21: Distribution Rate % of NAV | B21: 0.08 | C21: 0.08 | D21: 0.08
A22: Implied NAV/Share Growth % | B22: -0.062 | C22: -0.026 | D22: 0.0035
A23: Exit Price-to-NAV (Yr 5) | B23: 0.9 | C23: 0.95 | D23: 1
A24: Cost of Equity % | B24: 0.105 | C24: 0.1 | D24: 0.095
A25: Active scenario used in projection below: | B25: Base | C25: <- type Bear / Base / Bull to switch (drives column C above via manual copy; formulas below reference Base directly for simplicity)
A27: ACTIVE: Net Return % | B27: =C20 -> 0
A28: ACTIVE: Distribution Rate % of NAV | B28: =C21 -> 0
A29: ACTIVE: Exit Price-to-NAV | B29: =C23 -> 0
A30: ACTIVE: Cost of Equity % | B30: =C24 -> 0
A31: ACTIVE: Implied NAV/Share Growth % (=NetReturn-Distribution) | B31: =B27-B28 -> 0
A33: PROJECTIONS (Active Scenario)
B34: FY2027 | C34: FY2028 | D34: FY2029 | E34: FY2030 | F34: FY2031
A35: NAV per Share | B35: =B7*(1+$B$31) -> 0 | C35: =B35*(1+$B$31) -> 0 | D35: =C35*(1+$B$31) -> 0 | E35: =D35*(1+$B$31) -> 0 | F35: =E35*(1+$B$31) -> 0
A36: Dividend per Share | B36: =B7*$B$28 -> 0 | C36: =B35*$B$28 -> 0 | D36: =C35*$B$28 -> 0 | E36: =D35*$B$28 -> 0 | F36: =E35*$B$28 -> 0
A37: Discount Factor (Cost of Equity) | B37: =1/(1+$B$30)^1 -> 0 | C37: =1/(1+$B$30)^2 -> 0 | D37: =1/(1+$B$30)^3 -> 0 | E37: =1/(1+$B$30)^4 -> 0 | F37: =1/(1+$B$30)^5 -> 0
A38: PV of Dividend | B38: =B36*B37 -> 0 | C38: =C36*C37 -> 0 | D38: =D36*D37 -> 0 | E38: =E36*E37 -> 0 | F38: =F36*F37 -> 0
A40: VALUATION
A41: Sum of PV of Dividends | B41: =SUM(B38:F38) -> 0
A42: Year-5 NAV per Share | B42: =F35 -> 0
A43: Exit Value (Yr5 NAV x Exit P/NAV) | B43: =B42*$B$29 -> 0
A44: PV of Exit Value | B44: =B43*F37 -> 0
A45: INTRINSIC VALUE/SHARE | B45: =B41+B44 -> 0
A46: Upside/(Downside) vs Current Price | B46: =(B45-B5)/B5 -> 0
A47: Implied Price-to-NAV (Base IV / Starting NAV) | B47: =B45/B7 -> 0
...

Sheet Sensitivity
A1: Sensitivity Analysis
A2: Intrinsic Value by Cost of Equity & Exit Price-to-NAV (base-case NAV/dividend path)
A3: NOTE: for a closed-end fund the 2nd axis is EXIT PRICE-TO-NAV, not terminal growth.
A5: CoE \ Exit P/NAV | B5: 0.85 | C5: 0.9 | D5: 0.95 | E5: 1 | F5: 1.05
A6: 0.08 | B6: =('NAV Model'!$B$36/(1+0.08)^1 + 'NAV Model'!$C$36/(1+0.08)^2 + 'NAV Model'!$D$36/(1+0.08)^3 + 'NAV Model'!$E$36/(1+0.08)^4 + 'NAV Model'!$F$36/(1+0.08)^5) + ('NAV Model'!$F$35*0.85)/(1+0.08)^5 -> 0 | C6: =('NAV Model'!$B$36/(1+0.08)^1 + 'NAV Model'!$C$36/(1+0.08)^2 + 'NAV Model'!$D$36/(1+0.08)^3 + 'NAV Model'!$E$36/(1+0.08)^4 + 'NAV Model'!$F$36/(1+0.08)^5) + ('NAV Model'!$F$35*0.9)/(1+0.08)^5 -> 0 | D6: =('NAV Model'!$B$36/(1+0.08)^1 + 'NAV Model'!$C$36/(1+0.08)^2 + 'NAV Model'!$D$36/(1+0.08)^3 + 'NAV Model'!$E$36/(1+0.08)^4 + 'NAV Model'!$F$36/(1+0.08)^5) + ('NAV Model'!$F$35*0.95)/(1+0.08)^5 -> 0 | E6: =('NAV Model'!$B$36/(1+0.08)^1 + 'NAV Model'!$C$36/(1+0.08)^2 + 'NAV Model'!$D$36/(1+0.08)^3 + 'NAV Model'!$E$36/(1+0.08)^4 + 'NAV Model'!$F$36/(1+0.08)^5) + ('NAV Model'!$F$35*1.0)/(1+0.08)^5 -> 0 | F6: =('NAV Model'!$B$36/(1+0.08)^1 + 'NAV Model'!$C$36/(1+0.08)^2 + 'NAV Model'!$D$36/(1+0.08)^3 + 'NAV Model'!$E$36/(1+0.08)^4 + 'NAV Model'!$F$36/(1+0.08)^5) + ('NAV Model'!$F$35*1.05)/(1+0.08)^5 -> 0
A7: 0.09 | B7: =('NAV Model'!$B$36/(1+0.09)^1 + 'NAV Model'!$C$36/(1+0.09)^2 + 'NAV Model'!$D$36/(1+0.09)^3 + 'NAV Model'!$E$36/(1+0.09)^4 + 'NAV Model'!$F$36/(1+0.09)^5) + ('NAV Model'!$F$35*0.85)/(1+0.09)^5 -> 0 | C7: =('NAV Model'!$B$36/(1+0.09)^1 + 'NAV Model'!$C$36/(1+0.09)^2 + 'NAV Model'!$D$36/(1+0.09)^3 + 'NAV Model'!$E$36/(1+0.09)^4 + 'NAV Model'!$F$36/(1+0.09)^5) + ('NAV Model'!$F$35*0.9)/(1+0.09)^5 -> 0 | D7: =('NAV Model'!$B$36/(1+0.09)^1 + 'NAV Model'!$C$36/(1+0.09)^2 + 'NAV Model'!$D$36/(1+0.09)^3 + 'NAV Model'!$E$36/(1+0.09)^4 + 'NAV Model'!$F$36/(1+0.09)^5) + ('NAV Model'!$F$35*0.95)/(1+0.09)^5 -> 0 | E7: =('NAV Model'!$B$36/(1+0.09)^1 + 'NAV Model'!$C$36/(1+0.09)^2 + 'NAV Model'!$D$36/(1+0.09)^3 + 'NAV Model'!$E$36/(1+0.09)^4 + 'NAV Model'!$F$36/(1+0.09)^5) + ('NAV Model'!$F$35*1.0)/(1+0.09)^5 -> 0 | F7: =('NAV Model'!$B$36/(1+0.09)^1 + 'NAV Model'!$C$36/(1+0.09)^2 + 'NAV Model'!$D$36/(1+0.09)^3 + 'NAV Model'!$E$36/(1+0.09)^4 + 'NAV Model'!$F$36/(1+0.09)^5) + ('NAV Model'!$F$35*1.05)/(1+0.09)^5 -> 0
A8: 0.1 | B8: =('NAV Model'!$B$36/(1+0.1)^1 + 'NAV Model'!$C$36/(1+0.1)^2 + 'NAV Model'!$D$36/(1+0.1)^3 + 'NAV Model'!$E$36/(1+0.1)^4 + 'NAV Model'!$F$36/(1+0.1)^5) + ('NAV Model'!$F$35*0.85)/(1+0.1)^5 -> 0 | C8: =('NAV Model'!$B$36/(1+0.1)^1 + 'NAV Model'!$C$36/(1+0.1)^2 + 'NAV Model'!$D$36/(1+0.1)^3 + 'NAV Model'!$E$36/(1+0.1)^4 + 'NAV Model'!$F$36/(1+0.1)^5) + ('NAV Model'!$F$35*0.9)/(1+0.1)^5 -> 0 | D8: =('NAV Model'!$B$36/(1+0.1)^1 + 'NAV Model'!$C$36/(1+0.1)^2 + 'NAV Model'!$D$36/(1+0.1)^3 + 'NAV Model'!$E$36/(1+0.1)^4 + 'NAV Model'!$F$36/(1+0.1)^5) + ('NAV Model'!$F$35*0.95)/(1+0.1)^5 -> 0 | E8: =('NAV Model'!$B$36/(1+0.1)^1 + 'NAV Model'!$C$36/(1+0.1)^2 + 'NAV Model'!$D$36/(1+0.1)^3 + 'NAV Model'!$E$36/(1+0.1)^4 + 'NAV Model'!$F$36/(1+0.1)^5) + ('NAV Model'!$F$35*1.0)/(1+0.1)^5 -> 0 | F8: =('NAV Model'!$B$36/(1+0.1)^1 + 'NAV Model'!$C$36/(1+0.1)^2 + 'NAV Model'!$D$36/(1+0.1)^3 + 'NAV Model'!$E$36/(1+0.1)^4 + 'NAV Model'!$F$36/(1+0.1)^5) + ('NAV Model'!$F$35*1.05)/(1+0.1)^5 -> 0
A9: 0.11 | B9: =('NAV Model'!$B$36/(1+0.11)^1 + 'NAV Model'!$C$36/(1+0.11)^2 + 'NAV Model'!$D$36/(1+0.11)^3 + 'NAV Model'!$E$36/(1+0.11)^4 + 'NAV Model'!$F$36/(1+0.11)^5) + ('NAV Model'!$F$35*0.85)/(1+0.11)^5 -> 0 | C9: =('NAV Model'!$B$36/(1+0.11)^1 + 'NAV Model'!$C$36/(1+0.11)^2 + 'NAV Model'!$D$36/(1+0.11)^3 + 'NAV Model'!$E$36/(1+0.11)^4 + 'NAV Model'!$F$36/(1+0.11)^5) + ('NAV Model'!$F$35*0.9)/(1+0.11)^5 -> 0 | D9: =('NAV Model'!$B$36/(1+0.11)^1 + 'NAV Model'!$C$36/(1+0.11)^2 + 'NAV Model'!$D$36/(1+0.11)^3 + 'NAV Model'!$E$36/(1+0.11)^4 + 'NAV Model'!$F$36/(1+0.11)^5) + ('NAV Model'!$F$35*0.95)/(1+0.11)^5 -> 0 | E9: =('NAV Model'!$B$36/(1+0.11)^1 + 'NAV Model'!$C$36/(1+0.11)^2 + 'NAV Model'!$D$36/(1+0.11)^3 + 'NAV Model'!$E$36/(1+0.11)^4 + 'NAV Model'!$F$36/(1+0.11)^5) + ('NAV Model'!$F$35*1.0)/(1+0.11)^5 -> 0 | F9: =('NAV Model'!$B$36/(1+0.11)^1 + 'NAV Model'!$C$36/(1+0.11)^2 + 'NAV Model'!$D$36/(1+0.11)^3 + 'NAV Model'!$E$36/(1+0.11)^4 + 'NAV Model'!$F$36/(1+0.11)^5) + ('NAV Model'!$F$35*1.05)/(1+0.11)^5 -> 0
A10: 0.12 | B10: =('NAV Model'!$B$36/(1+0.12)^1 + 'NAV Model'!$C$36/(1+0.12)^2 + 'NAV Model'!$D$36/(1+0.12)^3 + 'NAV Model'!$E$36/(1+0.12)^4 + 'NAV Model'!$F$36/(1+0.12)^5) + ('NAV Model'!$F$35*0.85)/(1+0.12)^5 -> 0 | C10: =('NAV Model'!$B$36/(1+0.12)^1 + 'NAV Model'!$C$36/(1+0.12)^2 + 'NAV Model'!$D$36/(1+0.12)^3 + 'NAV Model'!$E$36/(1+0.12)^4 + 'NAV Model'!$F$36/(1+0.12)^5) + ('NAV Model'!$F$35*0.9)/(1+0.12)^5 -> 0 | D10: =('NAV Model'!$B$36/(1+0.12)^1 + 'NAV Model'!$C$36/(1+0.12)^2 + 'NAV Model'!$D$36/(1+0.12)^3 + 'NAV Model'!$E$36/(1+0.12)^4 + 'NAV Model'!$F$36/(1+0.12)^5) + ('NAV Model'!$F$35*0.95)/(1+0.12)^5 -> 0 | E10: =('NAV Model'!$B$36/(1+0.12)^1 + 'NAV Model'!$C$36/(1+0.12)^2 + 'NAV Model'!$D$36/(1+0.12)^3 + 'NAV Model'!$E$36/(1+0.12)^4 + 'NAV Model'!$F$36/(1+0.12)^5) + ('NAV Model'!$F$35*1.0)/(1+0.12)^5 -> 0 | F10: =('NAV Model'!$B$36/(1+0.12)^1 + 'NAV Model'!$C$36/(1+0.12)^2 + 'NAV Model'!$D$36/(1+0.12)^3 + 'NAV Model'!$E$36/(1+0.12)^4 + 'NAV Model'!$F$36/(1+0.12)^5) + ('NAV Model'!$F$35*1.05)/(1+0.12)^5 -> 0

Sheet Historical
A1: Historical NAV, Share Price & Discount/Premium
A3: Fiscal Year End 31-Mar | B3: FY2018 | C3: FY2019 | D3: FY2020 | E3: FY2021 | F3: FY2022 | G3: FY2023 | H3: FY2024 | I3: FY2025 | J3: FY2026
A4: NAV per Share ($) | B4: 1.45 | C4: 1.57 | D4: 1.39 | E4: 1.77 | F4: 1.58 | G4: 1.4 | H4: 1.34 | I4: 1.35 | J4: 1.2
A6: Share Price vs Adjusted NAV (company-published table)
B7: FY2022 | C7: FY2023 | D7: FY2024 | E7: FY2025 | F7: FY2026
A8: Adjusted NAV ($) | B8: 1.58 | C8: 1.4 | D8: 1.34 | E8: 1.35 | F8: 1.2
A9: Share Price ($) | B9: 1.75 | C9: 1.32 | D9: 1.25 | E9: 1.28 | F9: 1.19
A10: Discount/(Premium) to NAV | B10: -0.116 | C10: 0.057 | D10: 0.065 | E10: 0.052 | F10: 0.01
A12: Adjusted NAV Return (annual, %)
B13: FY2022 | C13: FY2023 | D13: FY2024 | E13: FY2025 | F13: FY2026
A14: Kingfish | B14: -0.035 | C14: -0.036 | D14: 0.046 | E14: 0.089 | F14: -0.032
A17: Selected Growth Rate (NAV/share 7yr CAGR): | B17: -0.0377
A18: Source: | B18: nav_per_share_7yr_cagr
A19: 5yr CAGR: | B19: -0.0748
A20: 3yr CAGR: | B20: -0.0501

Sheet Model_Info
A1: KFL.NZ (Kingfish Limited) NAV Valuation Model -- Provenance & Methodology
A3: BUILT BY: Claude (dcf-analyst workflow), 2026-08-12.
A5: DATA VINTAGE:
A6: - Share price: $1.20 NZD, live Yahoo Finance quote, 12-Aug-2026 (52wk range $1.17-$1.36).
A7: - NAV/financials: FY2026 Annual Report (year ended 31-Mar-2026, released 22-Jun-2026).
A8: - Shares outstanding: 358,844,193 at 31-Mar-2026 (a further 1,218,425 issued 6-May-2026 from the 1.40% KFLWI warrant take-up; ~85.7m warrants lapsed).
A9: - Most recent weekly NAV disclosure referenced: 29-Jul-2026 ($1.2977 undiluted) -- NOT used as the projection anchor; the lower, audited FY2026 statutory NAV ($1.20) is used conservatively.
A11: METHODOLOGY -- THIS IS NOT AN FCF DCF:
A12: Kingfish is a closed-end listed investment company (LIC): no revenue, no EBITDA, no free cash flow in any
A13: meaningful sense. The model instead compounds NAV per share forward using:
A14: NAV growth %/yr = (gross portfolio return - management fee drag) - distribution rate (% of NAV paid out)
A15: then values the shares as PV(5 years of dividends per share) + PV(year-5 NAV/share x an exit price-to-NAV
... A49: must be re-checked before being relied upon.
