Workbook

Sheet DCF Model
A1: SOFI Earnings-Based Valuation Model (Base Case)
A2: Gray cells are INPUTS - adjust to see valuation change. NOT an FCF DCF -- SoFi is a bank holding company; see Model_Info.
A3: net_debt = 0 throughout: deposits/bank debt are operating funding for a bank, not financing debt netted against equity value.
A5: KEY INPUTS
A6: Current Stock Price | B6: 18.03
A7: Shares Outstanding, base (M, diluted wavg) | B7: 1378.011
A8: Net Debt (M) -- bank, always 0 | B8: 0
A9: TTM Net Income, base year (M) | B9: 636.67
A10: TTM Revenue, base year (M) | B10: 4283.94
A11: TTM Net Margin, base year | B11: =B9/B10 -> 0
A12: Annual Share Growth (SBC + convert dilution) | B12: 0.0275
A14: Cost of Equity (CoE) | B14: 0.12
A15: Terminal Growth Rate | B15: 0.0225
A16: Exit P/E Cap (terminal multiple ceiling) | B16: 20
A18: GROWTH & MARGIN ASSUMPTIONS
C19: Year 1 | D19: Year 2 | E19: Year 3 | F19: Year 4 | G19: Year 5
A20: Revenue Growth Rate | C20: 0.3 | D20: 0.25 | E20: 0.2 | F20: 0.16 | G20: 0.13
A21: Net Margin | C21: 0.16 | D21: 0.175 | E21: 0.19 | F21: 0.205 | G21: 0.22
A23: PROJECTIONS
B24: Base (TTM) | C24: Year 1 | D24: Year 2 | E24: Year 3 | F24: Year 4 | G24: Year 5
A25: Revenue ($M) | B25: =B10 -> 0 | C25: =B25*(1+C20) -> 0 | D25: =C25*(1+D20) -> 0 | E25: =D25*(1+E20) -> 0 | F25: =E25*(1+F20) -> 0 | G25: =F25*(1+G20) -> 0
A26: Net Income ($M) | C26: =C25*C21 -> 0 | D26: =D25*D21 -> 0 | E26: =E25*E21 -> 0 | F26: =F25*F21 -> 0 | G26: =G25*G21 -> 0
A27: Shares Outstanding (M) | B27: =B7 -> 0 | C27: =B27*(1+$B$12) -> 0 | D27: =C27*(1+$B$12) -> 0 | E27: =D27*(1+$B$12) -> 0 | F27: =E27*(1+$B$12) -> 0 | G27: =F27*(1+$B$12) -> 0
A28: EPS ($) | C28: =C26/C27 -> 0 | D28: =D26/D27 -> 0 | E28: =E26/E27 -> 0 | F28: =F26/F27 -> 0 | G28: =G26/G27 -> 0
A29: Discount Factor (at CoE) | C29: =1/(1+$B$14)^1 -> 0 | D29: =1/(1+$B$14)^2 -> 0 | E29: =1/(1+$B$14)^3 -> 0 | F29: =1/(1+$B$14)^4 -> 0 | G29: =1/(1+$B$14)^5 -> 0
A30: PV of EPS ($) | C30: =C28*C29 -> 0 | D30: =D28*D29 -> 0 | E30: =E28*E29 -> 0 | F30: =F28*F29 -> 0 | G30: =G28*G29 -> 0
A32: VALUATION
A33: Sum of PV of EPS ($) | B33: =SUM(C30:G30) -> 0
A34: Year-5 EPS ($) | B34: =G28 -> 0
A35: Gordon Implied P/E ((1+g)/(CoE-g)) | B35: =(1+$B$15)/($B$14-$B$15) -> 0
A36: Gordon Terminal Value / share ($) | B36: =B34*B35 -> 0
A37: Exit P/E Cap Value / share ($) | B37: =B34*B16 -> 0
A38: Terminal Value / share used ($) [= MIN of the two] | B38: =MIN(B36,B37) -> 0
A39: PV of Terminal Value / share ($) | B39: =B38*G29 -> 0
A40: Less: Net Debt / share ($) -- always 0 for a bank | B40: =B8/G27 -> 0
A41: INTRINSIC VALUE/SHARE | B41: =B33+B39-B40 -> 0
A43: ENTRY PRICE (15% IRR Target)
A44: PV of Yrs 1-5 EPS @15% | B44: =NPV(0.15,C28:G28) -> 0
A45: PV of Terminal Value @15% | B45: =B38/(1.15^5) -> 0
A46: Less: Net Debt / share | B46: =B40 -> 0
...

Sheet Sensitivity
A1: Sensitivity Analysis
A2: Intrinsic Value by Cost of Equity & Terminal Growth (base scenario growth/margin path, 20x exit P/E cap)
A4: CoE \ Term Growth | B4: 0.0125 | C4: 0.0175 | D4: 0.0225 | E4: 0.0275 | F4: 0.0325
A5: 0.1 | B5: =NPV(0.1,'DCF Model'!$C$28:$G$28)+MIN('DCF Model'!$G$28*(1+0.0125)/(0.1-0.0125),'DCF Model'!$G$28*'DCF Model'!$B$16)/(1+0.1)^5 -> 0 | C5: =NPV(0.1,'DCF Model'!$C$28:$G$28)+MIN('DCF Model'!$G$28*(1+0.0175)/(0.1-0.0175),'DCF Model'!$G$28*'DCF Model'!$B$16)/(1+0.1)^5 -> 0 | D5: =NPV(0.1,'DCF Model'!$C$28:$G$28)+MIN('DCF Model'!$G$28*(1+0.0225)/(0.1-0.0225),'DCF Model'!$G$28*'DCF Model'!$B$16)/(1+0.1)^5 -> 0 | E5: =NPV(0.1,'DCF Model'!$C$28:$G$28)+MIN('DCF Model'!$G$28*(1+0.0275)/(0.1-0.0275),'DCF Model'!$G$28*'DCF Model'!$B$16)/(1+0.1)^5 -> 0 | F5: =NPV(0.1,'DCF Model'!$C$28:$G$28)+MIN('DCF Model'!$G$28*(1+0.0325)/(0.1-0.0325),'DCF Model'!$G$28*'DCF Model'!$B$16)/(1+0.1)^5 -> 0
A6: 0.11 | B6: =NPV(0.11,'DCF Model'!$C$28:$G$28)+MIN('DCF Model'!$G$28*(1+0.0125)/(0.11-0.0125),'DCF Model'!$G$28*'DCF Model'!$B$16)/(1+0.11)^5 -> 0 | C6: =NPV(0.11,'DCF Model'!$C$28:$G$28)+MIN('DCF Model'!$G$28*(1+0.0175)/(0.11-0.0175),'DCF Model'!$G$28*'DCF Model'!$B$16)/(1+0.11)^5 -> 0 | D6: =NPV(0.11,'DCF Model'!$C$28:$G$28)+MIN('DCF Model'!$G$28*(1+0.0225)/(0.11-0.0225),'DCF Model'!$G$28*'DCF Model'!$B$16)/(1+0.11)^5 -> 0 | E6: =NPV(0.11,'DCF Model'!$C$28:$G$28)+MIN('DCF Model'!$G$28*(1+0.0275)/(0.11-0.0275),'DCF Model'!$G$28*'DCF Model'!$B$16)/(1+0.11)^5 -> 0 | F6: =NPV(0.11,'DCF Model'!$C$28:$G$28)+MIN('DCF Model'!$G$28*(1+0.0325)/(0.11-0.0325),'DCF Model'!$G$28*'DCF Model'!$B$16)/(1+0.11)^5 -> 0
A7: 0.12 | B7: =NPV(0.12,'DCF Model'!$C$28:$G$28)+MIN('DCF Model'!$G$28*(1+0.0125)/(0.12-0.0125),'DCF Model'!$G$28*'DCF Model'!$B$16)/(1+0.12)^5 -> 0 | C7: =NPV(0.12,'DCF Model'!$C$28:$G$28)+MIN('DCF Model'!$G$28*(1+0.0175)/(0.12-0.0175),'DCF Model'!$G$28*'DCF Model'!$B$16)/(1+0.12)^5 -> 0 | D7: =NPV(0.12,'DCF Model'!$C$28:$G$28)+MIN('DCF Model'!$G$28*(1+0.0225)/(0.12-0.0225),'DCF Model'!$G$28*'DCF Model'!$B$16)/(1+0.12)^5 -> 0 | E7: =NPV(0.12,'DCF Model'!$C$28:$G$28)+MIN('DCF Model'!$G$28*(1+0.0275)/(0.12-0.0275),'DCF Model'!$G$28*'DCF Model'!$B$16)/(1+0.12)^5 -> 0 | F7: =NPV(0.12,'DCF Model'!$C$28:$G$28)+MIN('DCF Model'!$G$28*(1+0.0325)/(0.12-0.0325),'DCF Model'!$G$28*'DCF Model'!$B$16)/(1+0.12)^5 -> 0
A8: 0.13 | B8: =NPV(0.13,'DCF Model'!$C$28:$G$28)+MIN('DCF Model'!$G$28*(1+0.0125)/(0.13-0.0125),'DCF Model'!$G$28*'DCF Model'!$B$16)/(1+0.13)^5 -> 0 | C8: =NPV(0.13,'DCF Model'!$C$28:$G$28)+MIN('DCF Model'!$G$28*(1+0.0175)/(0.13-0.0175),'DCF Model'!$G$28*'DCF Model'!$B$16)/(1+0.13)^5 -> 0 | D8: =NPV(0.13,'DCF Model'!$C$28:$G$28)+MIN('DCF Model'!$G$28*(1+0.0225)/(0.13-0.0225),'DCF Model'!$G$28*'DCF Model'!$B$16)/(1+0.13)^5 -> 0 | E8: =NPV(0.13,'DCF Model'!$C$28:$G$28)+MIN('DCF Model'!$G$28*(1+0.0275)/(0.13-0.0275),'DCF Model'!$G$28*'DCF Model'!$B$16)/(1+0.13)^5 -> 0 | F8: =NPV(0.13,'DCF Model'!$C$28:$G$28)+MIN('DCF Model'!$G$28*(1+0.0325)/(0.13-0.0325),'DCF Model'!$G$28*'DCF Model'!$B$16)/(1+0.13)^5 -> 0
A9: 0.14 | B9: =NPV(0.14,'DCF Model'!$C$28:$G$28)+MIN('DCF Model'!$G$28*(1+0.0125)/(0.14-0.0125),'DCF Model'!$G$28*'DCF Model'!$B$16)/(1+0.14)^5 -> 0 | C9: =NPV(0.14,'DCF Model'!$C$28:$G$28)+MIN('DCF Model'!$G$28*(1+0.0175)/(0.14-0.0175),'DCF Model'!$G$28*'DCF Model'!$B$16)/(1+0.14)^5 -> 0 | D9: =NPV(0.14,'DCF Model'!$C$28:$G$28)+MIN('DCF Model'!$G$28*(1+0.0225)/(0.14-0.0225),'DCF Model'!$G$28*'DCF Model'!$B$16)/(1+0.14)^5 -> 0 | E9: =NPV(0.14,'DCF Model'!$C$28:$G$28)+MIN('DCF Model'!$G$28*(1+0.0275)/(0.14-0.0275),'DCF Model'!$G$28*'DCF Model'!$B$16)/(1+0.14)^5 -> 0 | F9: =NPV(0.14,'DCF Model'!$C$28:$G$28)+MIN('DCF Model'!$G$28*(1+0.0325)/(0.14-0.0325),'DCF Model'!$G$28*'DCF Model'!$B$16)/(1+0.14)^5 -> 0
A11: Note: shares outstanding/EPS path held at the DCF Model sheet base-case values; only CoE and terminal growth vary here.

Sheet Scenarios
A1: Scenario Comparison
A4: BEAR
A5: Revenue growth path (%) | B5: 0.2 | C5: 0.14 | D5: 0.1 | E5: 0.08 | F5: 0.06
A6: Net margin path (%) | B6: 0.13 | C6: 0.135 | D6: 0.145 | E6: 0.155 | F6: 0.165
A7: Revenue ($M) | B7: 5140.7 | C7: 5860.4 | D7: 6446.5 | E7: 6962.2 | F7: 7379.9
A8: Net Income ($M) | B8: 668.3 | C8: 791.2 | D8: 934.7 | E8: 1079.1 | F8: 1217.7
A9: EPS ($) | B9: 0.472 | C9: 0.544 | D9: 0.625 | E9: 0.703 | F9: 0.772
A10: Cost of Equity | B10: 0.13
A11: Terminal Growth | B11: 0.02
A12: Exit P/E Cap | B12: 15
A13: Implied Exit Multiple | B13: 9.27
A14: Terminal Value Capped by Exit P/E? | B14: False
A15: INTRINSIC VALUE/SHARE | B15: 6.01
A16: Upside vs Current Price | B16: -0.667
A18: BASE
A19: Revenue growth path (%) | B19: 0.3 | C19: 0.25 | D19: 0.2 | E19: 0.16 | F19: 0.13
A20: Net margin path (%) | B20: 0.16 | C20: 0.175 | D20: 0.19 | E20: 0.205 | F20: 0.22
A21: Revenue ($M) | B21: 5569.1 | C21: 6961.4 | D21: 8353.7 | E21: 9690.3 | F21: 10950
A22: Net Income ($M) | B22: 891.1 | C22: 1218.2 | D22: 1587.2 | E22: 1986.5 | F22: 2409
A23: EPS ($) | B23: 0.629 | C23: 0.837 | D23: 1.062 | E23: 1.293 | F23: 1.526
A24: Cost of Equity | B24: 0.12
A25: Terminal Growth | B25: 0.0225
A26: Exit P/E Cap | B26: 20
A27: Implied Exit Multiple | B27: 10.49
A28: Terminal Value Capped by Exit P/E? | B28: False
A29: INTRINSIC VALUE/SHARE | B29: 12.76
A30: Upside vs Current Price | B30: -0.292
A32: BULL
A33: Revenue growth path (%) | B33: 0.35 | C33: 0.3 | D33: 0.25 | E33: 0.2 | F33: 0.17
A34: Net margin path (%) | B34: 0.17 | C34: 0.19 | D34: 0.21 | E34: 0.23 | F34: 0.25
A35: Revenue ($M) | B35: 5783.3 | C35: 7518.3 | D35: 9397.9 | E35: 11277.5 | F35: 13194.6
A36: Net Income ($M) | B36: 983.2 | C36: 1428.5 | D36: 1973.6 | E36: 2593.8 | F36: 3298.7
A37: EPS ($) | B37: 0.694 | C37: 0.982 | D37: 1.32 | E37: 1.689 | F37: 2.09
A38: Cost of Equity | B38: 0.11
A39: Terminal Growth | B39: 0.025
A40: Exit P/E Cap | B40: 25
A41: Implied Exit Multiple | B41: 12.06
A42: Terminal Value Capped by Exit P/E? | B42: False
A43: INTRINSIC VALUE/SHARE | B43: 19.7
A44: Upside vs Current Price | B44: 0.093
...

Sheet Historical
A1: Historical Growth Rates & Multiples
A3: Metric | B3: 3-Year CAGR | C3: 5-Year CAGR
A4: Revenue | B4: 0.319 | C4: 0.449
A5: Equity (Book Value) | B5: 0.263
A7: FCF CAGR: not applicable (bank; OCF dominated by loan/deposit flows). See valuation_philosophy.
A9: Historical FY-End Multiples (SPAC-era FY2021-2022 noted as outliers)
A10: Year | B10: FY-End Price | C10: P/E | D10: P/B | E10: P/S
A11: FY2021 (SPAC-era) | B11: 15.81 | C11: n/m (loss) | D11: 1.9 | E11: 8.46
A12: FY2022 (SPAC-era) | B12: 4.61 | C12: n/m (loss) | D12: 0.8 | E12: 2.64
A13: FY2023 | B13: 9.95 | C13: n/m (loss) | D13: 1.8 | E13: 4.43
A14: FY2024 | B14: 15.4 | C14: 34 | D14: 2.6 | E14: 6.34
A15: FY2025 | B15: 26.18 | C15: 68.1 | D15: 3.12 | E15: 9.07
A17: Implied multiples on base-case IV ($12.76)
A18: Implied P/E | B18: 25.7
A19: Implied P/B | B19: 1.51
A20: Implied P/S | B20: 3.82

Sheet Model_Info
A1: SOFI DCF Model -- Provenance & Methodology
A3: BUILT BY: Claude (dcf-analyst agent), 2026-08-04, per user-specified adaptations for a bank holding company.
A5: DATA VINTAGE:
A6: - Share price: $18.03, Yahoo Finance close, 2026-08-04.
A7: - Metrics: SOFI_Metrics.csv (FY2019-Q1 2026, USD millions).
A8: - Qualitative/guidance: SOFI_Analysis.json (as of Q2 2026 earnings call, 2026-07-29).
A9: - Q2 2026 net income (~$157M) and revenue growth (+40% YoY) are sourced from Analysis.json recent_developments,
A10: NOT the Metrics.csv (which only has actuals through Q1 2026 at time of writing).
A12: METHODOLOGY -- WHY NOT A STANDARD FCF DCF:
A13: SoFi is a national bank holding company (SoFi Bank, N.A.). Reported operating cash flow is dominated by loan
A14: origination/sale volume and deposit flows (FY2025 OCF -$3,742M despite $481M of GAAP net income; FY2023 OCF
A15: -$7,227M). A conventional unlevered FCF DCF would show the company perpetually burning cash and is not a valid
... A65: TTM actuals will go stale after the next earnings release -- re-verify before relying on this model.
