Workbook

Sheet DCF Model
A1: PANW DCF Valuation Model
A2: Valuation Date: 2026-02-17 | All figures in USD millions unless noted
A3: Gray cells are INPUTS - adjust to see valuation change automatically
A5: KEY INPUTS
A6: Current Stock Price ($) | B6: 167
A7: Shares Outstanding (M, diluted) | B7: 710
A8: Cash & Equivalents (M) | B8: 2903.2
A9: Total Debt (M) | B9: 0
A10: Net Debt (M) [Debt - Cash] | B10: =B9-B8 -> 0
A11: Base Year FCF (M) | B11: 3469.8
A13: WACC | B13: 0.105 | C13: Tip: 10.5% base | range 8.5%-12.5% for high-growth tech
A14: Terminal Growth Rate | B14: 0.03 | C14: Tip: 3%-3.5% reflects secular cybersecurity tailwinds
A16: FCF GROWTH ASSUMPTIONS (BASE CASE)
A17: FCF Growth Rate | B17: Year 1 | C17: Year 2 | D17: Year 3 | E17: Year 4 | F17: Year 5 | G17: Historical FCF CAGRs:
B18: 0.18 | C18: 0.16 | D18: 0.14 | E18: 0.12 | F18: 0.1 | G18: 3yr: 24.64% | 5yr: 33.4%
A20: PROJECTIONS
B21: FY2025 (Base) | C21: Year 1 | D21: Year 2 | E21: Year 3 | F21: Year 4 | G21: Year 5
A22: Free Cash Flow (M) | B22: =B11 -> 0 | C22: =B22*(1+B18) -> 0 | D22: =C22*(1+C18) -> 0 | E22: =D22*(1+D18) -> 0 | F22: =E22*(1+E18) -> 0 | G22: =F22*(1+F18) -> 0
A23: Discount Factor | B23: 1 | C23: =1/(1+$B$13)^1 -> 0 | D23: =1/(1+$B$13)^2 -> 0 | E23: =1/(1+$B$13)^3 -> 0 | F23: =1/(1+$B$13)^4 -> 0 | G23: =1/(1+$B$13)^5 -> 0
A24: PV of FCF (M) | C24: =C22*C23 -> 0 | D24: =D22*D23 -> 0 | E24: =E22*E23 -> 0 | F24: =F22*F23 -> 0 | G24: =G22*G23 -> 0
A26: VALUATION
A27: Sum of PV of FCF (M) | B27: =SUM(C24:G24) -> 0
A28: Terminal FCF [Y5 FCF x (1+g)] | B28: =G22*(1+$B$14) -> 0
A29: Terminal Value [TV FCF / (WACC - g)] | B29: =B28/($B$13-$B$14) -> 0
A30: PV of Terminal Value | B30: =B29*G23 -> 0
A31: Enterprise Value (M) | B31: =B27+B30 -> 0
A32: Less: Net Debt (M) [negative = net cash] | B32: =B10 -> 0
A33: Equity Value (M) | B33: =B31-B32 -> 0
A34: INTRINSIC VALUE PER SHARE | B34: =B33/B7 -> 0
A35: Upside / (Downside) to IV | B35: =(B34-B6)/B6 -> 0
A37: ENTRY PRICE (15% CAGR TARGET)
A38: Terminal Value per Share | B38: =B29/B7 -> 0 | C38: Entry price = price to pay today to earn 15% annualised return to terminal value
A39: Entry Price (15% CAGR over 5 years) | B39: =B38/(1.15^5) -> 0
A40: Entry Discount from Current Price | B40: =(B6-B39)/B6 -> 0
A42: SCENARIO COMPARISON
B43: BEAR | C43: BASE | D43: BULL | E43: PROBABILITY WEIGHTED
A44: Intrinsic Value/Share | B44: 66.96 | C44: 110.19 | D44: 160.92 | E44: 112.06
A45: Upside / (Downside) | B45: -0.599 | C45: -0.34 | D45: -0.036 | E45: -0.32898204
A46: FCF Growth Y1 -> Y5 | B46: 10% -> 4% | C46: 18% -> 10% | D46: 25% -> 12%
A47: WACC | B47: 0.12 | C47: 0.105 | D47: 0.095
...

Sheet Sensitivity
A1: Sensitivity Analysis - Base Case Intrinsic Value per Share
A2: Base FCF growth: 18%, 16%, 14%, 12%, 10% | Base year FCF: $3,469.8M
A3: Shares: 710M diluted | Net Cash: $2,903M | Updates automatically when you change DCF Model inputs
A5: WACC \ Term Growth | B5: 0.02 | C5: 0.025 | D5: 0.03 | E5: 0.035 | F5: 0.04
A6: 0.08 | B6: =('DCF Model'!$B$11*(1+'DCF Model'!$B$18)/(1+0.08)^1+'DCF Model'!$B$11*(1+'DCF Model'!$B$18)*(1+'DCF Model'!$C$18)/(1+0.08)^2+'DCF Model'!$B$11*(1+'DCF Model'!$B$18)*(1+'DCF Model'!$C$18)*(1+'DCF Model'!$D$18)/(1+0.08)^3+'DCF Model'!$B$11*(1+'DCF Model'!$B$18)*(1+'DCF Model'!$C$18)*(1+'DCF Model'!$D$18)*(1+'DCF Model'!$E$18)/(1+0.08)^4+'DCF Model'!$B$11*(1+'DCF Model'!$B$18)*(1+'DCF Model'!$C$18)*(1+'DCF Model'!$D$18)*(1+'DCF Model'!$E$18)*(1+'DCF Model'!$F$18)/(1+0.08)^5+'DCF Model'!$B$11*(1+'DCF Model'!$B$18)*(1+'DCF Model'!$C$18)*(1+'DCF Model'!$D$18)*(1+'DCF Model'!$E$18)*(1+'DCF Model'!$F$18)*(1+0.02)/(0.08-0.02)/(1+0.08)^5-'DCF Model'!$B$10)/'DCF Model'!$B$7 -> 0 | C6: =('DCF Model'!$B$11*(1+'DCF Model'!$B$18)/(1+0.08)^1+'DCF Model'!$B$11*(1+'DCF Model'!$B$18)*(1+'DCF Model'!$C$18)/(1+0.08)^2+'DCF Model'!$B$11*(1+'DCF Model'!$B$18)*(1+'DCF Model'!$C$18)*(1+'DCF Model'!$D$18)/(1+0.08)^3+'DCF Model'!$B$11*(1+'DCF Model'!$B$18)*(1+'DCF Model'!$C$18)*(1+'DCF Model'!$D$18)*(1+'DCF Model'!$E$18)/(1+0.08)^4+'DCF Model'!$B$11*(1+'DCF Model'!$B$18)*(1+'DCF Model'!$C$18)*(1+'DCF Model'!$D$18)*(1+'DCF Model'!$E$18)*(1+'DCF Model'!$F$18)/(1+0.08)^5+'DCF Model'!$B$11*(1+'DCF Model'!$B$18)*(1+'DCF Model'!$C$18)*(1+'DCF Model'!$D$18)*(1+'DCF Model'!$E$18)*(1+'DCF Model'!$F$18)*(1+0.025)/(0.08-0.025)/(1+0.08)^5-'DCF Model'!$B$10)/'DCF Model'!$B$7 -> 0 | D6: =('DCF Model'!$B$11*(1+'DCF Model'!$B$18)/(1+0.08)^1+'DCF Model'!$B$11*(1+'DCF Model'!$B$18)*(1+'DCF Model'!$C$18)/(1+0.08)^2+'DCF Model'!$B$11*(1+'DCF Model'!$B$18)*(1+'DCF Model'!$C$18)*(1+'DCF Model'!$D$18)/(1+0.08)^3+'DCF Model'!$B$11*(1+'DCF Model'!$B$18)*(1+'DCF Model'!$C$18)*(1+'DCF Model'!$D$18)*(1+'DCF Model'!$E$18)/(1+0.08)^4+'DCF Model'!$B$11*(1+'DCF Model'!$B$18)*(1+'DCF Model'!$C$18)*(1+'DCF Model'!$D$18)*(1+'DCF Model'!$E$18)*(1+'DCF Model'!$F$18)/(1+0.08)^5+'DCF Model'!$B$11*(1+'DCF Model'!$B$18)*(1+'DCF Model'!$C$18)*(1+'DCF Model'!$D$18)*(1+'DCF Model'!$E$18)*(1+'DCF Model'!$F$18)*(1+0.03)/(0.08-0.03)/(1+0.08)^5-'DCF Model'!$B$10)/'DCF Model'!$B$7 -> 0 | E6: =('DCF Model'!$B$11*(1+'DCF Model'!$B$18)/(1+0.08)^1+'DCF Model'!$B$11*(1+'DCF Model'!$B$18)*(1+'DCF Model'!$C$18)/(1+0.08)^2+'DCF Model'!$B$11*(1+'DCF Model'!$B$18)*(1+'DCF Model'!$C$18)*(1+'DCF Model'!$D$18)/(1+0.08)^3+'DCF Model'!$B$11*(1+'DCF Model'!$B$18)*(1+'DCF Model'!$C$18)*(1+'DCF Model'!$D$18)*(1+'DCF Model'!$E$18)/(1+0.08)^4+'DCF Model'!$B$11*(1+'DCF Model'!$B$18)*(1+'DCF Model'!$C$18)*(1+'DCF Model'!$D$18)*(1+'DCF Model'!$E$18)*(1+'DCF Model'!$F$18)/(1+0.08)^5+'DCF Model'!$B$11*(1+'DCF Model'!$B$18)*(1+'DCF Model'!$C$18)*(1+'DCF Model'!$D$18)*(1+'DCF Model'!$E$18)*(1+'DCF Model'!$F$18)*(1+0.035)/(0.08-0.035)/(1+0.08)^5-'DCF Model'!$B$10)/'DCF Model'!$B$7 -> 0 | F6: =('DCF Model'!$B$11*(1+'DCF Model'!$B$18)/(1+0.08)^1+'DCF Model'!$B$11*(1+'DCF Model'!$B$18)*(1+'DCF Model'!$C$18)/(1+0.08)^2+'DCF Model'!$B$11*(1+'DCF Model'!$B$18)*(1+'DCF Model'!$C$18)*(1+'DCF Model'!$D$18)/(1+0.08)^3+'DCF Model'!$B$11*(1+'DCF Model'!$B$18)*(1+'DCF Model'!$C$18)*(1+'DCF Model'!$D$18)*(1+'DCF Model'!$E$18)/(1+0.08)^4+'DCF Model'!$B$11*(1+'DCF Model'!$B$18)*(1+'DCF Model'!$C$18)*(1+'DCF Model'!$D$18)*(1+'DCF Model'!$E$18)*(1+'DCF Model'!$F$18)/(1+0.08)^5+'DCF Model'!$B$11*(1+'DCF Model'!$B$18)*(1+'DCF Model'!$C$18)*(1+'DCF Model'!$D$18)*(1+'DCF Model'!$E$18)*(1+'DCF Model'!$F$18)*(1+0.04)/(0.08-0.04)/(1+0.08)^5-'DCF Model'!$B$10)/'DCF Model'!$B$7 -> 0
A7: 0.09 | B7: =('DCF Model'!$B$11*(1+'DCF Model'!$B$18)/(1+0.09)^1+'DCF Model'!$B$11*(1+'DCF Model'!$B$18)*(1+'DCF Model'!$C$18)/(1+0.09)^2+'DCF Model'!$B$11*(1+'DCF Model'!$B$18)*(1+'DCF Model'!$C$18)*(1+'DCF Model'!$D$18)/(1+0.09)^3+'DCF Model'!$B$11*(1+'DCF Model'!$B$18)*(1+'DCF Model'!$C$18)*(1+'DCF Model'!$D$18)*(1+'DCF Model'!$E$18)/(1+0.09)^4+'DCF Model'!$B$11*(1+'DCF Model'!$B$18)*(1+'DCF Model'!$C$18)*(1+'DCF Model'!$D$18)*(1+'DCF Model'!$E$18)*(1+'DCF Model'!$F$18)/(1+0.09)^5+'DCF Model'!$B$11*(1+'DCF Model'!$B$18)*(1+'DCF Model'!$C$18)*(1+'DCF Model'!$D$18)*(1+'DCF Model'!$E$18)*(1+'DCF Model'!$F$18)*(1+0.02)/(0.09-0.02)/(1+0.09)^5-'DCF Model'!$B$10)/'DCF Model'!$B$7 -> 0 | C7: =('DCF Model'!$B$11*(1+'DCF Model'!$B$18)/(1+0.09)^1+'DCF Model'!$B$11*(1+'DCF Model'!$B$18)*(1+'DCF Model'!$C$18)/(1+0.09)^2+'DCF Model'!$B$11*(1+'DCF Model'!$B$18)*(1+'DCF Model'!$C$18)*(1+'DCF Model'!$D$18)/(1+0.09)^3+'DCF Model'!$B$11*(1+'DCF Model'!$B$18)*(1+'DCF Model'!$C$18)*(1+'DCF Model'!$D$18)*(1+'DCF Model'!$E$18)/(1+0.09)^4+'DCF Model'!$B$11*(1+'DCF Model'!$B$18)*(1+'DCF Model'!$C$18)*(1+'DCF Model'!$D$18)*(1+'DCF Model'!$E$18)*(1+'DCF Model'!$F$18)/(1+0.09)^5+'DCF Model'!$B$11*(1+'DCF Model'!$B$18)*(1+'DCF Model'!$C$18)*(1+'DCF Model'!$D$18)*(1+'DCF Model'!$E$18)*(1+'DCF Model'!$F$18)*(1+0.025)/(0.09-0.025)/(1+0.09)^5-'DCF Model'!$B$10)/'DCF Model'!$B$7 -> 0 | D7: =('DCF Model'!$B$11*(1+'DCF Model'!$B$18)/(1+0.09)^1+'DCF Model'!$B$11*(1+'DCF Model'!$B$18)*(1+'DCF Model'!$C$18)/(1+0.09)^2+'DCF Model'!$B$11*(1+'DCF Model'!$B$18)*(1+'DCF Model'!$C$18)*(1+'DCF Model'!$D$18)/(1+0.09)^3+'DCF Model'!$B$11*(1+'DCF Model'!$B$18)*(1+'DCF Model'!$C$18)*(1+'DCF Model'!$D$18)*(1+'DCF Model'!$E$18)/(1+0.09)^4+'DCF Model'!$B$11*(1+'DCF Model'!$B$18)*(1+'DCF Model'!$C$18)*(1+'DCF Model'!$D$18)*(1+'DCF Model'!$E$18)*(1+'DCF Model'!$F$18)/(1+0.09)^5+'DCF Model'!$B$11*(1+'DCF Model'!$B$18)*(1+'DCF Model'!$C$18)*(1+'DCF Model'!$D$18)*(1+'DCF Model'!$E$18)*(1+'DCF Model'!$F$18)*(1+0.03)/(0.09-0.03)/(1+0.09)^5-'DCF Model'!$B$10)/'DCF Model'!$B$7 -> 0 | E7: =('DCF Model'!$B$11*(1+'DCF Model'!$B$18)/(1+0.09)^1+'DCF Model'!$B$11*(1+'DCF Model'!$B$18)*(1+'DCF Model'!$C$18)/(1+0.09)^2+'DCF Model'!$B$11*(1+'DCF Model'!$B$18)*(1+'DCF Model'!$C$18)*(1+'DCF Model'!$D$18)/(1+0.09)^3+'DCF Model'!$B$11*(1+'DCF Model'!$B$18)*(1+'DCF Model'!$C$18)*(1+'DCF Model'!$D$18)*(1+'DCF Model'!$E$18)/(1+0.09)^4+'DCF Model'!$B$11*(1+'DCF Model'!$B$18)*(1+'DCF Model'!$C$18)*(1+'DCF Model'!$D$18)*(1+'DCF Model'!$E$18)*(1+'DCF Model'!$F$18)/(1+0.09)^5+'DCF Model'!$B$11*(1+'DCF Model'!$B$18)*(1+'DCF Model'!$C$18)*(1+'DCF Model'!$D$18)*(1+'DCF Model'!$E$18)*(1+'DCF Model'!$F$18)*(1+0.035)/(0.09-0.035)/(1+0.09)^5-'DCF Model'!$B$10)/'DCF Model'!$B$7 -> 0 | F7: =('DCF Model'!$B$11*(1+'DCF Model'!$B$18)/(1+0.09)^1+'DCF Model'!$B$11*(1+'DCF Model'!$B$18)*(1+'DCF Model'!$C$18)/(1+0.09)^2+'DCF Model'!$B$11*(1+'DCF Model'!$B$18)*(1+'DCF Model'!$C$18)*(1+'DCF Model'!$D$18)/(1+0.09)^3+'DCF Model'!$B$11*(1+'DCF Model'!$B$18)*(1+'DCF Model'!$C$18)*(1+'DCF Model'!$D$18)*(1+'DCF Model'!$E$18)/(1+0.09)^4+'DCF Model'!$B$11*(1+'DCF Model'!$B$18)*(1+'DCF Model'!$C$18)*(1+'DCF Model'!$D$18)*(1+'DCF Model'!$E$18)*(1+'DCF Model'!$F$18)/(1+0.09)^5+'DCF Model'!$B$11*(1+'DCF Model'!$B$18)*(1+'DCF Model'!$C$18)*(1+'DCF Model'!$D$18)*(1+'DCF Model'!$E$18)*(1+'DCF Model'!$F$18)*(1+0.04)/(0.09-0.04)/(1+0.09)^5-'DCF Model'!$B$10)/'DCF Model'!$B$7 -> 0
A8: 0.1 | B8: =('DCF Model'!$B$11*(1+'DCF Model'!$B$18)/(1+0.1)^1+'DCF Model'!$B$11*(1+'DCF Model'!$B$18)*(1+'DCF Model'!$C$18)/(1+0.1)^2+'DCF Model'!$B$11*(1+'DCF Model'!$B$18)*(1+'DCF Model'!$C$18)*(1+'DCF Model'!$D$18)/(1+0.1)^3+'DCF Model'!$B$11*(1+'DCF Model'!$B$18)*(1+'DCF Model'!$C$18)*(1+'DCF Model'!$D$18)*(1+'DCF Model'!$E$18)/(1+0.1)^4+'DCF Model'!$B$11*(1+'DCF Model'!$B$18)*(1+'DCF Model'!$C$18)*(1+'DCF Model'!$D$18)*(1+'DCF Model'!$E$18)*(1+'DCF Model'!$F$18)/(1+0.1)^5+'DCF Model'!$B$11*(1+'DCF Model'!$B$18)*(1+'DCF Model'!$C$18)*(1+'DCF Model'!$D$18)*(1+'DCF Model'!$E$18)*(1+'DCF Model'!$F$18)*(1+0.02)/(0.1-0.02)/(1+0.1)^5-'DCF Model'!$B$10)/'DCF Model'!$B$7 -> 0 | C8: =('DCF Model'!$B$11*(1+'DCF Model'!$B$18)/(1+0.1)^1+'DCF Model'!$B$11*(1+'DCF Model'!$B$18)*(1+'DCF Model'!$C$18)/(1+0.1)^2+'DCF Model'!$B$11*(1+'DCF Model'!$B$18)*(1+'DCF Model'!$C$18)*(1+'DCF Model'!$D$18)/(1+0.1)^3+'DCF Model'!$B$11*(1+'DCF Model'!$B$18)*(1+'DCF Model'!$C$18)*(1+'DCF Model'!$D$18)*(1+'DCF Model'!$E$18)/(1+0.1)^4+'DCF Model'!$B$11*(1+'DCF Model'!$B$18)*(1+'DCF Model'!$C$18)*(1+'DCF Model'!$D$18)*(1+'DCF Model'!$E$18)*(1+'DCF Model'!$F$18)/(1+0.1)^5+'DCF Model'!$B$11*(1+'DCF Model'!$B$18)*(1+'DCF Model'!$C$18)*(1+'DCF Model'!$D$18)*(1+'DCF Model'!$E$18)*(1+'DCF Model'!$F$18)*(1+0.025)/(0.1-0.025)/(1+0.1)^5-'DCF Model'!$B$10)/'DCF Model'!$B$7 -> 0 | D8: =('DCF Model'!$B$11*(1+'DCF Model'!$B$18)/(1+0.1)^1+'DCF Model'!$B$11*(1+'DCF Model'!$B$18)*(1+'DCF Model'!$C$18)/(1+0.1)^2+'DCF Model'!$B$11*(1+'DCF Model'!$B$18)*(1+'DCF Model'!$C$18)*(1+'DCF Model'!$D$18)/(1+0.1)^3+'DCF Model'!$B$11*(1+'DCF Model'!$B$18)*(1+'DCF Model'!$C$18)*(1+'DCF Model'!$D$18)*(1+'DCF Model'!$E$18)/(1+0.1)^4+'DCF Model'!$B$11*(1+'DCF Model'!$B$18)*(1+'DCF Model'!$C$18)*(1+'DCF Model'!$D$18)*(1+'DCF Model'!$E$18)*(1+'DCF Model'!$F$18)/(1+0.1)^5+'DCF Model'!$B$11*(1+'DCF Model'!$B$18)*(1+'DCF Model'!$C$18)*(1+'DCF Model'!$D$18)*(1+'DCF Model'!$E$18)*(1+'DCF Model'!$F$18)*(1+0.03)/(0.1-0.03)/(1+0.1)^5-'DCF Model'!$B$10)/'DCF Model'!$B$7 -> 0 | E8: =('DCF Model'!$B$11*(1+'DCF Model'!$B$18)/(1+0.1)^1+'DCF Model'!$B$11*(1+'DCF Model'!$B$18)*(1+'DCF Model'!$C$18)/(1+0.1)^2+'DCF Model'!$B$11*(1+'DCF Model'!$B$18)*(1+'DCF Model'!$C$18)*(1+'DCF Model'!$D$18)/(1+0.1)^3+'DCF Model'!$B$11*(1+'DCF Model'!$B$18)*(1+'DCF Model'!$C$18)*(1+'DCF Model'!$D$18)*(1+'DCF Model'!$E$18)/(1+0.1)^4+'DCF Model'!$B$11*(1+'DCF Model'!$B$18)*(1+'DCF Model'!$C$18)*(1+'DCF Model'!$D$18)*(1+'DCF Model'!$E$18)*(1+'DCF Model'!$F$18)/(1+0.1)^5+'DCF Model'!$B$11*(1+'DCF Model'!$B$18)*(1+'DCF Model'!$C$18)*(1+'DCF Model'!$D$18)*(1+'DCF Model'!$E$18)*(1+'DCF Model'!$F$18)*(1+0.035)/(0.1-0.035)/(1+0.1)^5-'DCF Model'!$B$10)/'DCF Model'!$B$7 -> 0 | F8: =('DCF Model'!$B$11*(1+'DCF Model'!$B$18)/(1+0.1)^1+'DCF Model'!$B$11*(1+'DCF Model'!$B$18)*(1+'DCF Model'!$C$18)/(1+0.1)^2+'DCF Model'!$B$11*(1+'DCF Model'!$B$18)*(1+'DCF Model'!$C$18)*(1+'DCF Model'!$D$18)/(1+0.1)^3+'DCF Model'!$B$11*(1+'DCF Model'!$B$18)*(1+'DCF Model'!$C$18)*(1+'DCF Model'!$D$18)*(1+'DCF Model'!$E$18)/(1+0.1)^4+'DCF Model'!$B$11*(1+'DCF Model'!$B$18)*(1+'DCF Model'!$C$18)*(1+'DCF Model'!$D$18)*(1+'DCF Model'!$E$18)*(1+'DCF Model'!$F$18)/(1+0.1)^5+'DCF Model'!$B$11*(1+'DCF Model'!$B$18)*(1+'DCF Model'!$C$18)*(1+'DCF Model'!$D$18)*(1+'DCF Model'!$E$18)*(1+'DCF Model'!$F$18)*(1+0.04)/(0.1-0.04)/(1+0.1)^5-'DCF Model'!$B$10)/'DCF Model'!$B$7 -> 0
A9: 0.105 | B9: =('DCF Model'!$B$11*(1+'DCF Model'!$B$18)/(1+0.105)^1+'DCF Model'!$B$11*(1+'DCF Model'!$B$18)*(1+'DCF Model'!$C$18)/(1+0.105)^2+'DCF Model'!$B$11*(1+'DCF Model'!$B$18)*(1+'DCF Model'!$C$18)*(1+'DCF Model'!$D$18)/(1+0.105)^3+'DCF Model'!$B$11*(1+'DCF Model'!$B$18)*(1+'DCF Model'!$C$18)*(1+'DCF Model'!$D$18)*(1+'DCF Model'!$E$18)/(1+0.105)^4+'DCF Model'!$B$11*(1+'DCF Model'!$B$18)*(1+'DCF Model'!$C$18)*(1+'DCF Model'!$D$18)*(1+'DCF Model'!$E$18)*(1+'DCF Model'!$F$18)/(1+0.105)^5+'DCF Model'!$B$11*(1+'DCF Model'!$B$18)*(1+'DCF Model'!$C$18)*(1+'DCF Model'!$D$18)*(1+'DCF Model'!$E$18)*(1+'DCF Model'!$F$18)*(1+0.02)/(0.105-0.02)/(1+0.105)^5-'DCF Model'!$B$10)/'DCF Model'!$B$7 -> 0 | C9: =('DCF Model'!$B$11*(1+'DCF Model'!$B$18)/(1+0.105)^1+'DCF Model'!$B$11*(1+'DCF Model'!$B$18)*(1+'DCF Model'!$C$18)/(1+0.105)^2+'DCF Model'!$B$11*(1+'DCF Model'!$B$18)*(1+'DCF Model'!$C$18)*(1+'DCF Model'!$D$18)/(1+0.105)^3+'DCF Model'!$B$11*(1+'DCF Model'!$B$18)*(1+'DCF Model'!$C$18)*(1+'DCF Model'!$D$18)*(1+'DCF Model'!$E$18)/(1+0.105)^4+'DCF Model'!$B$11*(1+'DCF Model'!$B$18)*(1+'DCF Model'!$C$18)*(1+'DCF Model'!$D$18)*(1+'DCF Model'!$E$18)*(1+'DCF Model'!$F$18)/(1+0.105)^5+'DCF Model'!$B$11*(1+'DCF Model'!$B$18)*(1+'DCF Model'!$C$18)*(1+'DCF Model'!$D$18)*(1+'DCF Model'!$E$18)*(1+'DCF Model'!$F$18)*(1+0.025)/(0.105-0.025)/(1+0.105)^5-'DCF Model'!$B$10)/'DCF Model'!$B$7 -> 0 | D9: =('DCF Model'!$B$11*(1+'DCF Model'!$B$18)/(1+0.105)^1+'DCF Model'!$B$11*(1+'DCF Model'!$B$18)*(1+'DCF Model'!$C$18)/(1+0.105)^2+'DCF Model'!$B$11*(1+'DCF Model'!$B$18)*(1+'DCF Model'!$C$18)*(1+'DCF Model'!$D$18)/(1+0.105)^3+'DCF Model'!$B$11*(1+'DCF Model'!$B$18)*(1+'DCF Model'!$C$18)*(1+'DCF Model'!$D$18)*(1+'DCF Model'!$E$18)/(1+0.105)^4+'DCF Model'!$B$11*(1+'DCF Model'!$B$18)*(1+'DCF Model'!$C$18)*(1+'DCF Model'!$D$18)*(1+'DCF Model'!$E$18)*(1+'DCF Model'!$F$18)/(1+0.105)^5+'DCF Model'!$B$11*(1+'DCF Model'!$B$18)*(1+'DCF Model'!$C$18)*(1+'DCF Model'!$D$18)*(1+'DCF Model'!$E$18)*(1+'DCF Model'!$F$18)*(1+0.03)/(0.105-0.03)/(1+0.105)^5-'DCF Model'!$B$10)/'DCF Model'!$B$7 -> 0 | E9: =('DCF Model'!$B$11*(1+'DCF Model'!$B$18)/(1+0.105)^1+'DCF Model'!$B$11*(1+'DCF Model'!$B$18)*(1+'DCF Model'!$C$18)/(1+0.105)^2+'DCF Model'!$B$11*(1+'DCF Model'!$B$18)*(1+'DCF Model'!$C$18)*(1+'DCF Model'!$D$18)/(1+0.105)^3+'DCF Model'!$B$11*(1+'DCF Model'!$B$18)*(1+'DCF Model'!$C$18)*(1+'DCF Model'!$D$18)*(1+'DCF Model'!$E$18)/(1+0.105)^4+'DCF Model'!$B$11*(1+'DCF Model'!$B$18)*(1+'DCF Model'!$C$18)*(1+'DCF Model'!$D$18)*(1+'DCF Model'!$E$18)*(1+'DCF Model'!$F$18)/(1+0.105)^5+'DCF Model'!$B$11*(1+'DCF Model'!$B$18)*(1+'DCF Model'!$C$18)*(1+'DCF Model'!$D$18)*(1+'DCF Model'!$E$18)*(1+'DCF Model'!$F$18)*(1+0.035)/(0.105-0.035)/(1+0.105)^5-'DCF Model'!$B$10)/'DCF Model'!$B$7 -> 0 | F9: =('DCF Model'!$B$11*(1+'DCF Model'!$B$18)/(1+0.105)^1+'DCF Model'!$B$11*(1+'DCF Model'!$B$18)*(1+'DCF Model'!$C$18)/(1+0.105)^2+'DCF Model'!$B$11*(1+'DCF Model'!$B$18)*(1+'DCF Model'!$C$18)*(1+'DCF Model'!$D$18)/(1+0.105)^3+'DCF Model'!$B$11*(1+'DCF Model'!$B$18)*(1+'DCF Model'!$C$18)*(1+'DCF Model'!$D$18)*(1+'DCF Model'!$E$18)/(1+0.105)^4+'DCF Model'!$B$11*(1+'DCF Model'!$B$18)*(1+'DCF Model'!$C$18)*(1+'DCF Model'!$D$18)*(1+'DCF Model'!$E$18)*(1+'DCF Model'!$F$18)/(1+0.105)^5+'DCF Model'!$B$11*(1+'DCF Model'!$B$18)*(1+'DCF Model'!$C$18)*(1+'DCF Model'!$D$18)*(1+'DCF Model'!$E$18)*(1+'DCF Model'!$F$18)*(1+0.04)/(0.105-0.04)/(1+0.105)^5-'DCF Model'!$B$10)/'DCF Model'!$B$7 -> 0
A10: 0.11 | B10: =('DCF Model'!$B$11*(1+'DCF Model'!$B$18)/(1+0.11)^1+'DCF Model'!$B$11*(1+'DCF Model'!$B$18)*(1+'DCF Model'!$C$18)/(1+0.11)^2+'DCF Model'!$B$11*(1+'DCF Model'!$B$18)*(1+'DCF Model'!$C$18)*(1+'DCF Model'!$D$18)/(1+0.11)^3+'DCF Model'!$B$11*(1+'DCF Model'!$B$18)*(1+'DCF Model'!$C$18)*(1+'DCF Model'!$D$18)*(1+'DCF Model'!$E$18)/(1+0.11)^4+'DCF Model'!$B$11*(1+'DCF Model'!$B$18)*(1+'DCF Model'!$C$18)*(1+'DCF Model'!$D$18)*(1+'DCF Model'!$E$18)*(1+'DCF Model'!$F$18)/(1+0.11)^5+'DCF Model'!$B$11*(1+'DCF Model'!$B$18)*(1+'DCF Model'!$C$18)*(1+'DCF Model'!$D$18)*(1+'DCF Model'!$E$18)*(1+'DCF Model'!$F$18)*(1+0.02)/(0.11-0.02)/(1+0.11)^5-'DCF Model'!$B$10)/'DCF Model'!$B$7 -> 0 | C10: =('DCF Model'!$B$11*(1+'DCF Model'!$B$18)/(1+0.11)^1+'DCF Model'!$B$11*(1+'DCF Model'!$B$18)*(1+'DCF Model'!$C$18)/(1+0.11)^2+'DCF Model'!$B$11*(1+'DCF Model'!$B$18)*(1+'DCF Model'!$C$18)*(1+'DCF Model'!$D$18)/(1+0.11)^3+'DCF Model'!$B$11*(1+'DCF Model'!$B$18)*(1+'DCF Model'!$C$18)*(1+'DCF Model'!$D$18)*(1+'DCF Model'!$E$18)/(1+0.11)^4+'DCF Model'!$B$11*(1+'DCF Model'!$B$18)*(1+'DCF Model'!$C$18)*(1+'DCF Model'!$D$18)*(1+'DCF Model'!$E$18)*(1+'DCF Model'!$F$18)/(1+0.11)^5+'DCF Model'!$B$11*(1+'DCF Model'!$B$18)*(1+'DCF Model'!$C$18)*(1+'DCF Model'!$D$18)*(1+'DCF Model'!$E$18)*(1+'DCF Model'!$F$18)*(1+0.025)/(0.11-0.025)/(1+0.11)^5-'DCF Model'!$B$10)/'DCF Model'!$B$7 -> 0 | D10: =('DCF Model'!$B$11*(1+'DCF Model'!$B$18)/(1+0.11)^1+'DCF Model'!$B$11*(1+'DCF Model'!$B$18)*(1+'DCF Model'!$C$18)/(1+0.11)^2+'DCF Model'!$B$11*(1+'DCF Model'!$B$18)*(1+'DCF Model'!$C$18)*(1+'DCF Model'!$D$18)/(1+0.11)^3+'DCF Model'!$B$11*(1+'DCF Model'!$B$18)*(1+'DCF Model'!$C$18)*(1+'DCF Model'!$D$18)*(1+'DCF Model'!$E$18)/(1+0.11)^4+'DCF Model'!$B$11*(1+'DCF Model'!$B$18)*(1+'DCF Model'!$C$18)*(1+'DCF Model'!$D$18)*(1+'DCF Model'!$E$18)*(1+'DCF Model'!$F$18)/(1+0.11)^5+'DCF Model'!$B$11*(1+'DCF Model'!$B$18)*(1+'DCF Model'!$C$18)*(1+'DCF Model'!$D$18)*(1+'DCF Model'!$E$18)*(1+'DCF Model'!$F$18)*(1+0.03)/(0.11-0.03)/(1+0.11)^5-'DCF Model'!$B$10)/'DCF Model'!$B$7 -> 0 | E10: =('DCF Model'!$B$11*(1+'DCF Model'!$B$18)/(1+0.11)^1+'DCF Model'!$B$11*(1+'DCF Model'!$B$18)*(1+'DCF Model'!$C$18)/(1+0.11)^2+'DCF Model'!$B$11*(1+'DCF Model'!$B$18)*(1+'DCF Model'!$C$18)*(1+'DCF Model'!$D$18)/(1+0.11)^3+'DCF Model'!$B$11*(1+'DCF Model'!$B$18)*(1+'DCF Model'!$C$18)*(1+'DCF Model'!$D$18)*(1+'DCF Model'!$E$18)/(1+0.11)^4+'DCF Model'!$B$11*(1+'DCF Model'!$B$18)*(1+'DCF Model'!$C$18)*(1+'DCF Model'!$D$18)*(1+'DCF Model'!$E$18)*(1+'DCF Model'!$F$18)/(1+0.11)^5+'DCF Model'!$B$11*(1+'DCF Model'!$B$18)*(1+'DCF Model'!$C$18)*(1+'DCF Model'!$D$18)*(1+'DCF Model'!$E$18)*(1+'DCF Model'!$F$18)*(1+0.035)/(0.11-0.035)/(1+0.11)^5-'DCF Model'!$B$10)/'DCF Model'!$B$7 -> 0 | F10: =('DCF Model'!$B$11*(1+'DCF Model'!$B$18)/(1+0.11)^1+'DCF Model'!$B$11*(1+'DCF Model'!$B$18)*(1+'DCF Model'!$C$18)/(1+0.11)^2+'DCF Model'!$B$11*(1+'DCF Model'!$B$18)*(1+'DCF Model'!$C$18)*(1+'DCF Model'!$D$18)/(1+0.11)^3+'DCF Model'!$B$11*(1+'DCF Model'!$B$18)*(1+'DCF Model'!$C$18)*(1+'DCF Model'!$D$18)*(1+'DCF Model'!$E$18)/(1+0.11)^4+'DCF Model'!$B$11*(1+'DCF Model'!$B$18)*(1+'DCF Model'!$C$18)*(1+'DCF Model'!$D$18)*(1+'DCF Model'!$E$18)*(1+'DCF Model'!$F$18)/(1+0.11)^5+'DCF Model'!$B$11*(1+'DCF Model'!$B$18)*(1+'DCF Model'!$C$18)*(1+'DCF Model'!$D$18)*(1+'DCF Model'!$E$18)*(1+'DCF Model'!$F$18)*(1+0.04)/(0.11-0.04)/(1+0.11)^5-'DCF Model'!$B$10)/'DCF Model'!$B$7 -> 0
A11: 0.12 | B11: =('DCF Model'!$B$11*(1+'DCF Model'!$B$18)/(1+0.12)^1+'DCF Model'!$B$11*(1+'DCF Model'!$B$18)*(1+'DCF Model'!$C$18)/(1+0.12)^2+'DCF Model'!$B$11*(1+'DCF Model'!$B$18)*(1+'DCF Model'!$C$18)*(1+'DCF Model'!$D$18)/(1+0.12)^3+'DCF Model'!$B$11*(1+'DCF Model'!$B$18)*(1+'DCF Model'!$C$18)*(1+'DCF Model'!$D$18)*(1+'DCF Model'!$E$18)/(1+0.12)^4+'DCF Model'!$B$11*(1+'DCF Model'!$B$18)*(1+'DCF Model'!$C$18)*(1+'DCF Model'!$D$18)*(1+'DCF Model'!$E$18)*(1+'DCF Model'!$F$18)/(1+0.12)^5+'DCF Model'!$B$11*(1+'DCF Model'!$B$18)*(1+'DCF Model'!$C$18)*(1+'DCF Model'!$D$18)*(1+'DCF Model'!$E$18)*(1+'DCF Model'!$F$18)*(1+0.02)/(0.12-0.02)/(1+0.12)^5-'DCF Model'!$B$10)/'DCF Model'!$B$7 -> 0 | C11: =('DCF Model'!$B$11*(1+'DCF Model'!$B$18)/(1+0.12)^1+'DCF Model'!$B$11*(1+'DCF Model'!$B$18)*(1+'DCF Model'!$C$18)/(1+0.12)^2+'DCF Model'!$B$11*(1+'DCF Model'!$B$18)*(1+'DCF Model'!$C$18)*(1+'DCF Model'!$D$18)/(1+0.12)^3+'DCF Model'!$B$11*(1+'DCF Model'!$B$18)*(1+'DCF Model'!$C$18)*(1+'DCF Model'!$D$18)*(1+'DCF Model'!$E$18)/(1+0.12)^4+'DCF Model'!$B$11*(1+'DCF Model'!$B$18)*(1+'DCF Model'!$C$18)*(1+'DCF Model'!$D$18)*(1+'DCF Model'!$E$18)*(1+'DCF Model'!$F$18)/(1+0.12)^5+'DCF Model'!$B$11*(1+'DCF Model'!$B$18)*(1+'DCF Model'!$C$18)*(1+'DCF Model'!$D$18)*(1+'DCF Model'!$E$18)*(1+'DCF Model'!$F$18)*(1+0.025)/(0.12-0.025)/(1+0.12)^5-'DCF Model'!$B$10)/'DCF Model'!$B$7 -> 0 | D11: =('DCF Model'!$B$11*(1+'DCF Model'!$B$18)/(1+0.12)^1+'DCF Model'!$B$11*(1+'DCF Model'!$B$18)*(1+'DCF Model'!$C$18)/(1+0.12)^2+'DCF Model'!$B$11*(1+'DCF Model'!$B$18)*(1+'DCF Model'!$C$18)*(1+'DCF Model'!$D$18)/(1+0.12)^3+'DCF Model'!$B$11*(1+'DCF Model'!$B$18)*(1+'DCF Model'!$C$18)*(1+'DCF Model'!$D$18)*(1+'DCF Model'!$E$18)/(1+0.12)^4+'DCF Model'!$B$11*(1+'DCF Model'!$B$18)*(1+'DCF Model'!$C$18)*(1+'DCF Model'!$D$18)*(1+'DCF Model'!$E$18)*(1+'DCF Model'!$F$18)/(1+0.12)^5+'DCF Model'!$B$11*(1+'DCF Model'!$B$18)*(1+'DCF Model'!$C$18)*(1+'DCF Model'!$D$18)*(1+'DCF Model'!$E$18)*(1+'DCF Model'!$F$18)*(1+0.03)/(0.12-0.03)/(1+0.12)^5-'DCF Model'!$B$10)/'DCF Model'!$B$7 -> 0 | E11: =('DCF Model'!$B$11*(1+'DCF Model'!$B$18)/(1+0.12)^1+'DCF Model'!$B$11*(1+'DCF Model'!$B$18)*(1+'DCF Model'!$C$18)/(1+0.12)^2+'DCF Model'!$B$11*(1+'DCF Model'!$B$18)*(1+'DCF Model'!$C$18)*(1+'DCF Model'!$D$18)/(1+0.12)^3+'DCF Model'!$B$11*(1+'DCF Model'!$B$18)*(1+'DCF Model'!$C$18)*(1+'DCF Model'!$D$18)*(1+'DCF Model'!$E$18)/(1+0.12)^4+'DCF Model'!$B$11*(1+'DCF Model'!$B$18)*(1+'DCF Model'!$C$18)*(1+'DCF Model'!$D$18)*(1+'DCF Model'!$E$18)*(1+'DCF Model'!$F$18)/(1+0.12)^5+'DCF Model'!$B$11*(1+'DCF Model'!$B$18)*(1+'DCF Model'!$C$18)*(1+'DCF Model'!$D$18)*(1+'DCF Model'!$E$18)*(1+'DCF Model'!$F$18)*(1+0.035)/(0.12-0.035)/(1+0.12)^5-'DCF Model'!$B$10)/'DCF Model'!$B$7 -> 0 | F11: =('DCF Model'!$B$11*(1+'DCF Model'!$B$18)/(1+0.12)^1+'DCF Model'!$B$11*(1+'DCF Model'!$B$18)*(1+'DCF Model'!$C$18)/(1+0.12)^2+'DCF Model'!$B$11*(1+'DCF Model'!$B$18)*(1+'DCF Model'!$C$18)*(1+'DCF Model'!$D$18)/(1+0.12)^3+'DCF Model'!$B$11*(1+'DCF Model'!$B$18)*(1+'DCF Model'!$C$18)*(1+'DCF Model'!$D$18)*(1+'DCF Model'!$E$18)/(1+0.12)^4+'DCF Model'!$B$11*(1+'DCF Model'!$B$18)*(1+'DCF Model'!$C$18)*(1+'DCF Model'!$D$18)*(1+'DCF Model'!$E$18)*(1+'DCF Model'!$F$18)/(1+0.12)^5+'DCF Model'!$B$11*(1+'DCF Model'!$B$18)*(1+'DCF Model'!$C$18)*(1+'DCF Model'!$D$18)*(1+'DCF Model'!$E$18)*(1+'DCF Model'!$F$18)*(1+0.04)/(0.12-0.04)/(1+0.12)^5-'DCF Model'!$B$10)/'DCF Model'!$B$7 -> 0
A12: Yellow highlighted cell = Base Case assumptions (WACC 10.5%, Terminal Growth 3.0%)
A13: Matrix recalculates automatically when you change growth rates or FCF base in the DCF Model sheet.

Sheet Scenarios
A1: PANW - Full Scenario Workings
A2: All figures in USD millions | Shares: 710M diluted | Net Cash: $2,903M
A5: BASE CASE | B5: FY2025 (Base) | C5: Y1 (FY2026) | D5: Y2 (FY2027) | E5: Y3 (FY2028) | F5: Y4 (FY2029) | G5: Y5 (FY2030)
A6: FCF Growth Rate | B6: - | C6: 0.18 | D6: 0.16 | E6: 0.14 | F6: 0.12 | G6: 0.1
A7: Free Cash Flow (M) | B7: 3469.8 | C7: 4094.4 | D7: 4749.5 | E7: 5414.4 | F7: 6064.1 | G7: 6670.5
A8: Discount Factor | B8: 1 | C8: 0.905 | D8: 0.819 | E8: 0.7412 | F8: 0.6707 | G8: 0.607
A9: PV of FCF (M) | C9: 3705.4 | D9: 3889.8 | E9: 4013.2 | F9: 4067.2 | G9: 4049
A11: Sum PV of FCF (M) | B11: 19724.6 | C11: WACC = 10.5%
A12: Terminal Value (M) | B12: 91608.2 | C12: Terminal g = 3.0% | TV = Y5 FCF x (1+g) / (WACC - g)
A13: PV of Terminal Value (M) | B13: 55606.2
A14: Enterprise Value (M) | B14: 75330.8
A15: Less: Net Debt (M) | B15: -2903.2 | C15: Negative = Net Cash ($2,903M cash, zero debt)
A16: Equity Value (M) | B16: 78234
A17: Intrinsic Value per Share | B17: 110.19
A18: Upside / (Downside) | B18: -0.34
A19: Entry Price (15% CAGR target) | B19: 64.15 | C19: TV/share $129.03 discounted at 15% for 5 years
A25: BULL CASE | B25: FY2025 (Base) | C25: Y1 (FY2026) | D25: Y2 (FY2027) | E25: Y3 (FY2028) | F25: Y4 (FY2029) | G25: Y5 (FY2030)
A26: FCF Growth Rate | B26: - | C26: 0.25 | D26: 0.22 | E26: 0.18 | F26: 0.15 | G26: 0.12
A27: Free Cash Flow (M) | B27: 3469.8 | C27: 4337.2 | D27: 5291.4 | E27: 6243.9 | F27: 7180.5 | G27: 8042.1
A28: Discount Factor | B28: 1 | C28: 0.9132 | D28: 0.834 | E28: 0.7617 | F28: 0.6956 | G28: 0.6352
A29: PV of FCF (M) | C29: 3960.7 | D29: 4413 | E29: 4756 | F29: 4994.8 | G29: 5108.3
A31: Sum PV of FCF (M) | B31: 23232.8 | C31: WACC = 9.5%
A32: Terminal Value (M) | B32: 138726.2 | C32: Terminal g = 3.5% | TV = Y5 FCF x (1+g) / (WACC - g)
A33: PV of Terminal Value (M) | B33: 88118.9
A34: Enterprise Value (M) | B34: 111351.7
A35: Less: Net Debt (M) | B35: -2903.2 | C35: Negative = Net Cash ($2,903M cash, zero debt)
A36: Equity Value (M) | B36: 114254.9
A37: Intrinsic Value per Share | B37: 160.92
A38: Upside / (Downside) | B38: -0.036
A39: Entry Price (15% CAGR target) | B39: 97.14 | C39: TV/share $195.39 discounted at 15% for 5 years
A45: BEAR CASE | B45: FY2025 (Base) | C45: Y1 (FY2026) | D45: Y2 (FY2027) | E45: Y3 (FY2028) | F45: Y4 (FY2029) | G45: Y5 (FY2030)
A46: FCF Growth Rate | B46: - | C46: 0.1 | D46: 0.08 | E46: 0.06 | F46: 0.05 | G46: 0.04
A47: Free Cash Flow (M) | B47: 3469.8 | C47: 3816.8 | D47: 4122.1 | E47: 4369.4 | F47: 4587.9 | G47: 4771.4
A48: Discount Factor | B48: 1 | C48: 0.8929 | D48: 0.7972 | E48: 0.7118 | F48: 0.6355 | G48: 0.5674
A49: PV of FCF (M) | C49: 3408 | D49: 3286.1 | E49: 3110.1 | F49: 2915.6 | G49: 2707.3
A51: Sum PV of FCF (M) | B51: 15427.1 | C51: WACC = 12.0%
A52: Terminal Value (M) | B52: 51480.9 | C52: Terminal g = 2.5% | TV = Y5 FCF x (1+g) / (WACC - g)
A53: PV of Terminal Value (M) | B53: 29210.3
A54: Enterprise Value (M) | B54: 44637.4
A55: Less: Net Debt (M) | B55: -2903.2 | C55: Negative = Net Cash ($2,903M cash, zero debt)
...

Sheet Historical Data
A1: PANW Historical Financial Data (FY2015 - FY2025)
A2: USD millions | EPS is split-adjusted (3-for-1 Sep 2022 + 2-for-1 Dec 2024)
A4: Period | B4: Revenue | C4: Gross Profit | D4: Gross Margin | E4: Op. Income | F4: Net Income | G4: EPS (Diluted) | H4: Free Cash Flow | I4: Equity | J4: Shares (M)
A5: FY2015 | B5: 928.1 | C5: 676.6 | D5: 0.729 | E5: -133.5 | F5: -165 | G5: -0.32 | H5: 316.5 | I5: 487.9 | J5: 508.8
A6: FY2016 | B6: 1378.5 | C6: 1008.5 | D6: 0.732 | E6: -190.1 | F6: -225.9 | G6: -0.43 | H6: 585.6 | I6: 789.9 | J6: 543
A7: FY2017 | B7: 1761.6 | C7: 1285 | D7: 0.729 | E7: -179.8 | F7: -216.6 | G7: -0.4 | H7: 705.1 | I7: 759.6 | J7: 549
A8: FY2018 | B8: 2273.1 | C8: 1627.8 | D8: 0.716 | E8: -129.1 | F8: -147.9 | G8: -0.27 | H8: 925 | I8: 966.4 | J8: 561.6
A9: FY2019 | B9: 2899.6 | C9: 2091.2 | D9: 0.721 | E9: -54.1 | F9: -81.9 | G9: -0.14 | H9: 924.4 | I9: 1586.3 | J9: 580.8
A10: FY2020 | B10: 3408.4 | C10: 2408.9 | D10: 0.707 | E10: -179 | F10: -267 | G10: -0.46 | H10: 821.3 | I10: 1101.8 | J10: 577.8
A11: FY2021 | B11: 4256.1 | C11: 2981.2 | D11: 0.701 | E11: -304.1 | F11: -498.9 | G11: -0.86 | H11: 1387 | I11: 634.5 | J11: 583.8
A12: FY2022 | B12: 5501.5 | C12: 3782.8 | D12: 0.688 | E12: -188.8 | F12: -267 | G12: -0.45 | H12: 1791.9 | I12: 210 | J12: 597.6
A13: FY2023 | B13: 6892.7 | C13: 4983 | D13: 0.723 | E13: 387.3 | F13: 439.7 | G13: 0.64 | H13: 2631.2 | I13: 1748.4 | J13: 616.6
A14: FY2024 | B14: 8027.5 | C14: 5968.3 | D14: 0.743 | E14: 683.9 | F14: 2577.6 | G14: 3.64 | H14: 3100.8 | I14: 5169.7 | J14: 650.2
A15: FY2025 | B15: 9221.5 | C15: 6769.9 | D15: 0.734 | E15: 1242.9 | F15: 1133.9 | G15: 1.6 | H15: 3469.8 | I15: 7824.4 | J15: 667.9
A17: GROWTH RATE SUMMARY
A18: Metric | B18: 3-Year CAGR | C18: 5-Year CAGR | D18: Period | E18: Notes
A19: Revenue | B19: 0.1879 | C19: 0.2203 | D19: FY2022->FY2025 | FY2020->FY2025 | E19: Growing at ~22% 5yr; deceleration to ~14% guided FY2026
A20: Free Cash Flow | B20: 0.2464 | C20: 0.334 | D20: FY2022->FY2025 | FY2020->FY2025 | E20: SELECTED PRIMARY METRIC. Strong and consistent FCF generation
A21: Shareholders Equity | B21: 2.34 | C21: 0.48 | D21: FY2022->FY2025 | FY2020->FY2025 | E21: UNRELIABLE. FY2022 near-zero base ($210M) distorts both CAGRs
A22: EPS (Diluted) | B22: N/A | C22: N/A | D22: N/A - negative base | E22: Undefined. GAAP losses through FY2022. FY2024 EPS inflated by one-time tax benefit.
A23: Selected Primary Metric: | B23: FCF 5yr CAGR | C23: 0.334
A24: Divergence Warning:
B25: Equity CAGR (48% 5yr, 234% 3yr) is unreliable due to FY2022 near-zero equity base ($210M trough from heavy buybacks and goodwill). EPS CAGRs are undefined due to negative earnings through FY2022. FCF CAGR is used as primary metric per Visa-precedent logic. Historical FCF 5yr CAGR of 33.4% is used as anchor but projected growth rates are set conservatively (18% to 10% base case) given revenue growth deceleration to ~14% guided for FY2026 and CyberArk acquisition integration uncertainty.
