Workbook

Sheet DCF Model
A1: AGL.NZ DCF Valuation Model (Accordant Group) - BASE CASE
A2: Gray cells are INPUTS - adjust to see valuation change. Distressed cyclical: net debt often exceeds enterprise value under base/bear.
A4: KEY INPUTS
A5: Current Stock Price (NZD) | B5: 0.166
A6: Shares Outstanding (M, post-raise) | B6: 67.6589
A7: Pro-forma Net Bank Debt (M) | B7: 24
A8: WACC (Base) | B8: 0.17
A9: Terminal Growth Rate | B9: 0.018
A10: Terminal EV/EBITDA Cap Multiple | B10: 8.29
A11: Cash Tax Rate | B11: 0.28
A12: Capex % of Revenue | B12: 0.0035
A13: Lease Principal % of Revenue | B13: 0.011
A14: Working Capital Capture % (of revenue CHANGE) | B14: 0.12
A15: SBC % of Revenue (immaterial) | B15: 0.00047
A16: FY26 Base Revenue (M) | B16: 165.1
A18: GROWTH & MARGIN ASSUMPTIONS (10yr, gray = inputs)
B19: FY2027 | C19: FY2028 | D19: FY2029 | E19: FY2030 | F19: FY2031 | G19: FY2032 | H19: FY2033 | I19: FY2034 | J19: FY2035 | K19: FY2036
A20: Revenue Growth % | B20: 0.03 | C20: 0.045 | D20: 0.05 | E20: 0.045 | F20: 0.04 | G20: 0.035 | H20: 0.03 | I20: 0.028 | J20: 0.025 | K20: 0.025
A21: EBITDA Margin % | B21: 0.0273 | C21: 0.0298 | D21: 0.0324 | E21: 0.0349 | F21: 0.0374 | G21: 0.04 | H21: 0.0425 | I21: 0.045 | J21: 0.045 | K21: 0.045
A22: D&A % of Revenue | B22: 0.023 | C22: 0.0238 | D22: 0.0247 | E22: 0.0255 | F22: 0.0263 | G22: 0.0272 | H22: 0.028 | I22: 0.023 | J22: 0.023 | K22: 0.018
A24: PROJECTIONS (base case, formula-driven)
A25: Revenue | B25: =$B$16*(1+B20) -> 0 | C25: =B25*(1+C20) -> 0 | D25: =C25*(1+D20) -> 0 | E25: =D25*(1+E20) -> 0 | F25: =E25*(1+F20) -> 0 | G25: =F25*(1+G20) -> 0 | H25: =G25*(1+H20) -> 0 | I25: =H25*(1+I20) -> 0 | J25: =I25*(1+J20) -> 0 | K25: =J25*(1+K20) -> 0
A26: EBITDA | B26: =B25*B21 -> 0 | C26: =C25*C21 -> 0 | D26: =D25*D21 -> 0 | E26: =E25*E21 -> 0 | F26: =F25*F21 -> 0 | G26: =G25*G21 -> 0 | H26: =H25*H21 -> 0 | I26: =I25*I21 -> 0 | ... K26: =K25*K21 -> 0
A27: Less: SBC | B27: =B25*$B$15 -> 0 | C27: =C25*$B$15 -> 0 | D27: =D25*$B$15 -> 0 | E27: =E25*$B$15 -> 0 | F27: =F25*$B$15 -> 0 | G27: =G25*$B$15 -> 0 | H27: =H25*$B$15 -> 0 | I27: =I25*$B$15 -> 0 | ... K27: =K25*$B$15 -> 0
A28: Owner EBITDA | B28: =B26-B27 -> 0 | C28: =C26-C27 -> 0 | D28: =D26-D27 -> 0 | E28: =E26-E27 -> 0 | F28: =F26-F27 -> 0 | G28: =G26-G27 -> 0 | H28: =H26-H27 -> 0 | I28: =I26-I27 -> 0 | ... K28: =K26-K27 -> 0
A29: Less: D&A | B29: =B25*B22 -> 0 | C29: =C25*C22 -> 0 | D29: =D25*D22 -> 0 | E29: =E25*E22 -> 0 | F29: =F25*F22 -> 0 | G29: =G25*G22 -> 0 | H29: =H25*H22 -> 0 | I29: =I25*I22 -> 0 | ... K29: =K25*K22 -> 0
A30: EBIT | B30: =B28-B29 -> 0 | C30: =C28-C29 -> 0 | D30: =D28-D29 -> 0 | E30: =E28-E29 -> 0 | F30: =F28-F29 -> 0 | G30: =G28-G29 -> 0 | H30: =H28-H29 -> 0 | I30: =I28-I29 -> 0 | ... K30: =K28-K29 -> 0
A31: NOPAT (tax only if EBIT>0) | B31: =IF(B30>0,B30*(1-$B$11),B30) -> 0 | C31: =IF(C30>0,C30*(1-$B$11),C30) -> 0 | D31: =IF(D30>0,D30*(1-$B$11),D30) -> 0 | E31: =IF(E30>0,E30*(1-$B$11),E30) -> 0 | F31: =IF(F30>0,F30*(1-$B$11),F30) -> 0 | G31: =IF(G30>0,G30*(1-$B$11),G30) -> 0 | H31: =IF(H30>0,H30*(1-$B$11),H30) -> 0 | I31: =IF(I30>0,I30*(1-$B$11),I30) -> 0 | ... K31: =IF(K30>0,K30*(1-$B$11),K30) -> 0
A32: Add back: D&A | B32: =B29 -> 0 | C32: =C29 -> 0 | D32: =D29 -> 0 | E32: =E29 -> 0 | F32: =F29 -> 0 | G32: =G29 -> 0 | H32: =H29 -> 0 | I32: =I29 -> 0 | ... K32: =K29 -> 0
A33: Less: Capex | B33: =B25*$B$12 -> 0 | C33: =C25*$B$12 -> 0 | D33: =D25*$B$12 -> 0 | E33: =E25*$B$12 -> 0 | F33: =F25*$B$12 -> 0 | G33: =G25*$B$12 -> 0 | H33: =H25*$B$12 -> 0 | I33: =I25*$B$12 -> 0 | ... K33: =K25*$B$12 -> 0
A34: Less: Lease Principal Paid | B34: =B25*$B$13 -> 0 | C34: =C25*$B$13 -> 0 | D34: =D25*$B$13 -> 0 | E34: =E25*$B$13 -> 0 | F34: =F25*$B$13 -> 0 | G34: =G25*$B$13 -> 0 | H34: =H25*$B$13 -> 0 | I34: =I25*$B$13 -> 0 | ... K34: =K25*$B$13 -> 0
A35: Less: Working Capital (on rev change) | B35: =$B$14*(B25-$B$16) -> 0 | C35: =$B$14*(C25-B25) -> 0 | D35: =$B$14*(D25-C25) -> 0 | E35: =$B$14*(E25-D25) -> 0 | F35: =$B$14*(F25-E25) -> 0 | G35: =$B$14*(G25-F25) -> 0 | H35: =$B$14*(H25-G25) -> 0 | I35: =$B$14*(I25-H25) -> 0 | J35: =$B$14*(J25-I25) -> 0 | K35: =$B$14*(K25-J25) -> 0
A36: Owner FCF | B36: =B31+B32-B33-B34-B35 -> 0 | C36: =C31+C32-C33-C34-C35 -> 0 | D36: =D31+D32-D33-D34-D35 -> 0 | E36: =E31+E32-E33-E34-E35 -> 0 | F36: =F31+F32-F33-F34-F35 -> 0 | G36: =G31+G32-G33-G34-G35 -> 0 | H36: =H31+H32-H33-H34-H35 -> 0 | I36: =I31+I32-I33-I34-I35 -> 0 | ... K36: =K31+K32-K33-K34-K35 -> 0
A37: Owner FCF Margin % | B37: =B36/B25 -> 0 | C37: =C36/C25 -> 0 | D37: =D36/D25 -> 0 | E37: =E36/E25 -> 0 | F37: =F36/F25 -> 0 | G37: =G36/G25 -> 0 | H37: =H36/H25 -> 0 | I37: =I36/I25 -> 0 | ... K37: =K36/K25 -> 0
A38: Discount Factor | B38: =1/(1+$B$8)^1 -> 0 | C38: =1/(1+$B$8)^2 -> 0 | D38: =1/(1+$B$8)^3 -> 0 | E38: =1/(1+$B$8)^4 -> 0 | F38: =1/(1+$B$8)^5 -> 0 | G38: =1/(1+$B$8)^6 -> 0 | H38: =1/(1+$B$8)^7 -> 0 | I38: =1/(1+$B$8)^8 -> 0 | J38: =1/(1+$B$8)^9 -> 0 | K38: =1/(1+$B$8)^10 -> 0
A39: PV of FCF | B39: =B36*B38 -> 0 | C39: =C36*C38 -> 0 | D39: =D36*D38 -> 0 | E39: =E36*E38 -> 0 | F39: =F36*F38 -> 0 | G39: =G36*G38 -> 0 | H39: =H36*H38 -> 0 | I39: =I36*I38 -> 0 | ... K39: =K36*K38 -> 0
A41: VALUATION
A42: Sum of PV of FCF (Yrs 1-10) | B42: =SUM(B39:K39) -> 0
A43: Terminal FCF x (1+g) | B43: =K36*(1+$B$9) -> 0
A44: Terminal Value - Gordon Growth | B44: =B43/($B$8-$B$9) -> 0
...

Sheet Scenarios
A1: Scenario Comparison
A3: Metric | B3: Bear | C3: Base | D3: Bull
A4: WACC | B4: 0.19 | C4: 0.17 | D4: 0.155
A5: Terminal Growth | B5: 0.015 | C5: 0.018 | D5: 0.02
A6: Terminal Cap Multiple (x) | B6: 3.61 | C6: 8.29 | D6: 9.58
A7: TV Bound | B7: gordon | C7: gordon | D7: gordon
A8: Sum PV FCF (M) | B8: 7.38 | C8: 11.057 | D8: 16.654
A9: PV Terminal Value (M) | B9: 2.215 | C9: 6.393 | D9: 13.057
A10: Enterprise Value (M) | B10: 9.594 | C10: 17.451 | D10: 29.711
A11: Equity Value (M) | B11: -14.406 | C11: -6.549 | D11: 5.711
A12: Intrinsic Value/Share | B12: -0.2129 | C12: -0.0968 | D12: 0.0844
A13: Upside/Downside % | B13: -2.283 | C13: -1.583 | D13: -0.491
A14: Terminal % of EV | B14: 0.231 | C14: 0.366 | D14: 0.439
A15: Implied Exit Multiple (x) | B15: 5.8 | C15: 6.7 | D15: 7.56
A17: Probability Weights
A18: Bear weight | B18: 0.35
A19: Base weight | B19: 0.45
A20: Bull weight | B20: 0.2
A21: Weighted Intrinsic Value/Share | B21: -0.1012
A22: Weighted Upside % | B22: -1.61

Sheet Sensitivity
A1: Sensitivity Analysis - Base Case
A2: Intrinsic Value/Share by WACC & Terminal Growth (TV = MIN(Gordon, EV/EBITDA cap))
A4: WACC \ Term G | B4: 0.008 | C4: 0.013 | D4: 0.018 | E4: 0.023 | F4: 0.028
A5: 0.15 | B5: =('DCF Model'!$B$36/(1+0.15)^1+'DCF Model'!$C$36/(1+0.15)^2+'DCF Model'!$D$36/(1+0.15)^3+'DCF Model'!$E$36/(1+0.15)^4+'DCF Model'!$F$36/(1+0.15)^5+'DCF Model'!$G$36/(1+0.15)^6+'DCF Model'!$H$36/(1+0.15)^7+'DCF Model'!$I$36/(1+0.15)^8+'DCF Model'!$J$36/(1+0.15)^9+'DCF Model'!$K$36/(1+0.15)^10+MIN('DCF Model'!$K$36*(1+0.008)/(0.15-0.008),'DCF Model'!$B$10*'DCF Model'!$K$26)/(1+0.15)^10-'DCF Model'!$B$7)/'DCF Model'!$B$6 -> 0 | C5: =('DCF Model'!$B$36/(1+0.15)^1+'DCF Model'!$C$36/(1+0.15)^2+'DCF Model'!$D$36/(1+0.15)^3+'DCF Model'!$E$36/(1+0.15)^4+'DCF Model'!$F$36/(1+0.15)^5+'DCF Model'!$G$36/(1+0.15)^6+'DCF Model'!$H$36/(1+0.15)^7+'DCF Model'!$I$36/(1+0.15)^8+'DCF Model'!$J$36/(1+0.15)^9+'DCF Model'!$K$36/(1+0.15)^10+MIN('DCF Model'!$K$36*(1+0.013000000000000001)/(0.15-0.013000000000000001),'DCF Model'!$B$10*'DCF Model'!$K$26)/(1+0.15)^10-'DCF Model'!$B$7)/'DCF Model'!$B$6 -> 0 | D5: =('DCF Model'!$B$36/(1+0.15)^1+'DCF Model'!$C$36/(1+0.15)^2+'DCF Model'!$D$36/(1+0.15)^3+'DCF Model'!$E$36/(1+0.15)^4+'DCF Model'!$F$36/(1+0.15)^5+'DCF Model'!$G$36/(1+0.15)^6+'DCF Model'!$H$36/(1+0.15)^7+'DCF Model'!$I$36/(1+0.15)^8+'DCF Model'!$J$36/(1+0.15)^9+'DCF Model'!$K$36/(1+0.15)^10+MIN('DCF Model'!$K$36*(1+0.018000000000000002)/(0.15-0.018000000000000002),'DCF Model'!$B$10*'DCF Model'!$K$26)/(1+0.15)^10-'DCF Model'!$B$7)/'DCF Model'!$B$6 -> 0 | E5: =('DCF Model'!$B$36/(1+0.15)^1+'DCF Model'!$C$36/(1+0.15)^2+'DCF Model'!$D$36/(1+0.15)^3+'DCF Model'!$E$36/(1+0.15)^4+'DCF Model'!$F$36/(1+0.15)^5+'DCF Model'!$G$36/(1+0.15)^6+'DCF Model'!$H$36/(1+0.15)^7+'DCF Model'!$I$36/(1+0.15)^8+'DCF Model'!$J$36/(1+0.15)^9+'DCF Model'!$K$36/(1+0.15)^10+MIN('DCF Model'!$K$36*(1+0.023)/(0.15-0.023),'DCF Model'!$B$10*'DCF Model'!$K$26)/(1+0.15)^10-'DCF Model'!$B$7)/'DCF Model'!$B$6 -> 0 | F5: =('DCF Model'!$B$36/(1+0.15)^1+'DCF Model'!$C$36/(1+0.15)^2+'DCF Model'!$D$36/(1+0.15)^3+'DCF Model'!$E$36/(1+0.15)^4+'DCF Model'!$F$36/(1+0.15)^5+'DCF Model'!$G$36/(1+0.15)^6+'DCF Model'!$H$36/(1+0.15)^7+'DCF Model'!$I$36/(1+0.15)^8+'DCF Model'!$J$36/(1+0.15)^9+'DCF Model'!$K$36/(1+0.15)^10+MIN('DCF Model'!$K$36*(1+0.027999999999999997)/(0.15-0.027999999999999997),'DCF Model'!$B$10*'DCF Model'!$K$26)/(1+0.15)^10-'DCF Model'!$B$7)/'DCF Model'!$B$6 -> 0
A6: 0.16 | B6: =('DCF Model'!$B$36/(1+0.16)^1+'DCF Model'!$C$36/(1+0.16)^2+'DCF Model'!$D$36/(1+0.16)^3+'DCF Model'!$E$36/(1+0.16)^4+'DCF Model'!$F$36/(1+0.16)^5+'DCF Model'!$G$36/(1+0.16)^6+'DCF Model'!$H$36/(1+0.16)^7+'DCF Model'!$I$36/(1+0.16)^8+'DCF Model'!$J$36/(1+0.16)^9+'DCF Model'!$K$36/(1+0.16)^10+MIN('DCF Model'!$K$36*(1+0.008)/(0.16-0.008),'DCF Model'!$B$10*'DCF Model'!$K$26)/(1+0.16)^10-'DCF Model'!$B$7)/'DCF Model'!$B$6 -> 0 | C6: =('DCF Model'!$B$36/(1+0.16)^1+'DCF Model'!$C$36/(1+0.16)^2+'DCF Model'!$D$36/(1+0.16)^3+'DCF Model'!$E$36/(1+0.16)^4+'DCF Model'!$F$36/(1+0.16)^5+'DCF Model'!$G$36/(1+0.16)^6+'DCF Model'!$H$36/(1+0.16)^7+'DCF Model'!$I$36/(1+0.16)^8+'DCF Model'!$J$36/(1+0.16)^9+'DCF Model'!$K$36/(1+0.16)^10+MIN('DCF Model'!$K$36*(1+0.013000000000000001)/(0.16-0.013000000000000001),'DCF Model'!$B$10*'DCF Model'!$K$26)/(1+0.16)^10-'DCF Model'!$B$7)/'DCF Model'!$B$6 -> 0 | D6: =('DCF Model'!$B$36/(1+0.16)^1+'DCF Model'!$C$36/(1+0.16)^2+'DCF Model'!$D$36/(1+0.16)^3+'DCF Model'!$E$36/(1+0.16)^4+'DCF Model'!$F$36/(1+0.16)^5+'DCF Model'!$G$36/(1+0.16)^6+'DCF Model'!$H$36/(1+0.16)^7+'DCF Model'!$I$36/(1+0.16)^8+'DCF Model'!$J$36/(1+0.16)^9+'DCF Model'!$K$36/(1+0.16)^10+MIN('DCF Model'!$K$36*(1+0.018000000000000002)/(0.16-0.018000000000000002),'DCF Model'!$B$10*'DCF Model'!$K$26)/(1+0.16)^10-'DCF Model'!$B$7)/'DCF Model'!$B$6 -> 0 | E6: =('DCF Model'!$B$36/(1+0.16)^1+'DCF Model'!$C$36/(1+0.16)^2+'DCF Model'!$D$36/(1+0.16)^3+'DCF Model'!$E$36/(1+0.16)^4+'DCF Model'!$F$36/(1+0.16)^5+'DCF Model'!$G$36/(1+0.16)^6+'DCF Model'!$H$36/(1+0.16)^7+'DCF Model'!$I$36/(1+0.16)^8+'DCF Model'!$J$36/(1+0.16)^9+'DCF Model'!$K$36/(1+0.16)^10+MIN('DCF Model'!$K$36*(1+0.023)/(0.16-0.023),'DCF Model'!$B$10*'DCF Model'!$K$26)/(1+0.16)^10-'DCF Model'!$B$7)/'DCF Model'!$B$6 -> 0 | F6: =('DCF Model'!$B$36/(1+0.16)^1+'DCF Model'!$C$36/(1+0.16)^2+'DCF Model'!$D$36/(1+0.16)^3+'DCF Model'!$E$36/(1+0.16)^4+'DCF Model'!$F$36/(1+0.16)^5+'DCF Model'!$G$36/(1+0.16)^6+'DCF Model'!$H$36/(1+0.16)^7+'DCF Model'!$I$36/(1+0.16)^8+'DCF Model'!$J$36/(1+0.16)^9+'DCF Model'!$K$36/(1+0.16)^10+MIN('DCF Model'!$K$36*(1+0.027999999999999997)/(0.16-0.027999999999999997),'DCF Model'!$B$10*'DCF Model'!$K$26)/(1+0.16)^10-'DCF Model'!$B$7)/'DCF Model'!$B$6 -> 0
A7: 0.17 | B7: =('DCF Model'!$B$36/(1+0.17)^1+'DCF Model'!$C$36/(1+0.17)^2+'DCF Model'!$D$36/(1+0.17)^3+'DCF Model'!$E$36/(1+0.17)^4+'DCF Model'!$F$36/(1+0.17)^5+'DCF Model'!$G$36/(1+0.17)^6+'DCF Model'!$H$36/(1+0.17)^7+'DCF Model'!$I$36/(1+0.17)^8+'DCF Model'!$J$36/(1+0.17)^9+'DCF Model'!$K$36/(1+0.17)^10+MIN('DCF Model'!$K$36*(1+0.008)/(0.17-0.008),'DCF Model'!$B$10*'DCF Model'!$K$26)/(1+0.17)^10-'DCF Model'!$B$7)/'DCF Model'!$B$6 -> 0 | C7: =('DCF Model'!$B$36/(1+0.17)^1+'DCF Model'!$C$36/(1+0.17)^2+'DCF Model'!$D$36/(1+0.17)^3+'DCF Model'!$E$36/(1+0.17)^4+'DCF Model'!$F$36/(1+0.17)^5+'DCF Model'!$G$36/(1+0.17)^6+'DCF Model'!$H$36/(1+0.17)^7+'DCF Model'!$I$36/(1+0.17)^8+'DCF Model'!$J$36/(1+0.17)^9+'DCF Model'!$K$36/(1+0.17)^10+MIN('DCF Model'!$K$36*(1+0.013000000000000001)/(0.17-0.013000000000000001),'DCF Model'!$B$10*'DCF Model'!$K$26)/(1+0.17)^10-'DCF Model'!$B$7)/'DCF Model'!$B$6 -> 0 | D7: =('DCF Model'!$B$36/(1+0.17)^1+'DCF Model'!$C$36/(1+0.17)^2+'DCF Model'!$D$36/(1+0.17)^3+'DCF Model'!$E$36/(1+0.17)^4+'DCF Model'!$F$36/(1+0.17)^5+'DCF Model'!$G$36/(1+0.17)^6+'DCF Model'!$H$36/(1+0.17)^7+'DCF Model'!$I$36/(1+0.17)^8+'DCF Model'!$J$36/(1+0.17)^9+'DCF Model'!$K$36/(1+0.17)^10+MIN('DCF Model'!$K$36*(1+0.018000000000000002)/(0.17-0.018000000000000002),'DCF Model'!$B$10*'DCF Model'!$K$26)/(1+0.17)^10-'DCF Model'!$B$7)/'DCF Model'!$B$6 -> 0 | E7: =('DCF Model'!$B$36/(1+0.17)^1+'DCF Model'!$C$36/(1+0.17)^2+'DCF Model'!$D$36/(1+0.17)^3+'DCF Model'!$E$36/(1+0.17)^4+'DCF Model'!$F$36/(1+0.17)^5+'DCF Model'!$G$36/(1+0.17)^6+'DCF Model'!$H$36/(1+0.17)^7+'DCF Model'!$I$36/(1+0.17)^8+'DCF Model'!$J$36/(1+0.17)^9+'DCF Model'!$K$36/(1+0.17)^10+MIN('DCF Model'!$K$36*(1+0.023)/(0.17-0.023),'DCF Model'!$B$10*'DCF Model'!$K$26)/(1+0.17)^10-'DCF Model'!$B$7)/'DCF Model'!$B$6 -> 0 | F7: =('DCF Model'!$B$36/(1+0.17)^1+'DCF Model'!$C$36/(1+0.17)^2+'DCF Model'!$D$36/(1+0.17)^3+'DCF Model'!$E$36/(1+0.17)^4+'DCF Model'!$F$36/(1+0.17)^5+'DCF Model'!$G$36/(1+0.17)^6+'DCF Model'!$H$36/(1+0.17)^7+'DCF Model'!$I$36/(1+0.17)^8+'DCF Model'!$J$36/(1+0.17)^9+'DCF Model'!$K$36/(1+0.17)^10+MIN('DCF Model'!$K$36*(1+0.027999999999999997)/(0.17-0.027999999999999997),'DCF Model'!$B$10*'DCF Model'!$K$26)/(1+0.17)^10-'DCF Model'!$B$7)/'DCF Model'!$B$6 -> 0
A8: 0.18 | B8: =('DCF Model'!$B$36/(1+0.18)^1+'DCF Model'!$C$36/(1+0.18)^2+'DCF Model'!$D$36/(1+0.18)^3+'DCF Model'!$E$36/(1+0.18)^4+'DCF Model'!$F$36/(1+0.18)^5+'DCF Model'!$G$36/(1+0.18)^6+'DCF Model'!$H$36/(1+0.18)^7+'DCF Model'!$I$36/(1+0.18)^8+'DCF Model'!$J$36/(1+0.18)^9+'DCF Model'!$K$36/(1+0.18)^10+MIN('DCF Model'!$K$36*(1+0.008)/(0.18-0.008),'DCF Model'!$B$10*'DCF Model'!$K$26)/(1+0.18)^10-'DCF Model'!$B$7)/'DCF Model'!$B$6 -> 0 | C8: =('DCF Model'!$B$36/(1+0.18)^1+'DCF Model'!$C$36/(1+0.18)^2+'DCF Model'!$D$36/(1+0.18)^3+'DCF Model'!$E$36/(1+0.18)^4+'DCF Model'!$F$36/(1+0.18)^5+'DCF Model'!$G$36/(1+0.18)^6+'DCF Model'!$H$36/(1+0.18)^7+'DCF Model'!$I$36/(1+0.18)^8+'DCF Model'!$J$36/(1+0.18)^9+'DCF Model'!$K$36/(1+0.18)^10+MIN('DCF Model'!$K$36*(1+0.013000000000000001)/(0.18-0.013000000000000001),'DCF Model'!$B$10*'DCF Model'!$K$26)/(1+0.18)^10-'DCF Model'!$B$7)/'DCF Model'!$B$6 -> 0 | D8: =('DCF Model'!$B$36/(1+0.18)^1+'DCF Model'!$C$36/(1+0.18)^2+'DCF Model'!$D$36/(1+0.18)^3+'DCF Model'!$E$36/(1+0.18)^4+'DCF Model'!$F$36/(1+0.18)^5+'DCF Model'!$G$36/(1+0.18)^6+'DCF Model'!$H$36/(1+0.18)^7+'DCF Model'!$I$36/(1+0.18)^8+'DCF Model'!$J$36/(1+0.18)^9+'DCF Model'!$K$36/(1+0.18)^10+MIN('DCF Model'!$K$36*(1+0.018000000000000002)/(0.18-0.018000000000000002),'DCF Model'!$B$10*'DCF Model'!$K$26)/(1+0.18)^10-'DCF Model'!$B$7)/'DCF Model'!$B$6 -> 0 | E8: =('DCF Model'!$B$36/(1+0.18)^1+'DCF Model'!$C$36/(1+0.18)^2+'DCF Model'!$D$36/(1+0.18)^3+'DCF Model'!$E$36/(1+0.18)^4+'DCF Model'!$F$36/(1+0.18)^5+'DCF Model'!$G$36/(1+0.18)^6+'DCF Model'!$H$36/(1+0.18)^7+'DCF Model'!$I$36/(1+0.18)^8+'DCF Model'!$J$36/(1+0.18)^9+'DCF Model'!$K$36/(1+0.18)^10+MIN('DCF Model'!$K$36*(1+0.023)/(0.18-0.023),'DCF Model'!$B$10*'DCF Model'!$K$26)/(1+0.18)^10-'DCF Model'!$B$7)/'DCF Model'!$B$6 -> 0 | F8: =('DCF Model'!$B$36/(1+0.18)^1+'DCF Model'!$C$36/(1+0.18)^2+'DCF Model'!$D$36/(1+0.18)^3+'DCF Model'!$E$36/(1+0.18)^4+'DCF Model'!$F$36/(1+0.18)^5+'DCF Model'!$G$36/(1+0.18)^6+'DCF Model'!$H$36/(1+0.18)^7+'DCF Model'!$I$36/(1+0.18)^8+'DCF Model'!$J$36/(1+0.18)^9+'DCF Model'!$K$36/(1+0.18)^10+MIN('DCF Model'!$K$36*(1+0.027999999999999997)/(0.18-0.027999999999999997),'DCF Model'!$B$10*'DCF Model'!$K$26)/(1+0.18)^10-'DCF Model'!$B$7)/'DCF Model'!$B$6 -> 0
A9: 0.19 | B9: =('DCF Model'!$B$36/(1+0.19)^1+'DCF Model'!$C$36/(1+0.19)^2+'DCF Model'!$D$36/(1+0.19)^3+'DCF Model'!$E$36/(1+0.19)^4+'DCF Model'!$F$36/(1+0.19)^5+'DCF Model'!$G$36/(1+0.19)^6+'DCF Model'!$H$36/(1+0.19)^7+'DCF Model'!$I$36/(1+0.19)^8+'DCF Model'!$J$36/(1+0.19)^9+'DCF Model'!$K$36/(1+0.19)^10+MIN('DCF Model'!$K$36*(1+0.008)/(0.19-0.008),'DCF Model'!$B$10*'DCF Model'!$K$26)/(1+0.19)^10-'DCF Model'!$B$7)/'DCF Model'!$B$6 -> 0 | C9: =('DCF Model'!$B$36/(1+0.19)^1+'DCF Model'!$C$36/(1+0.19)^2+'DCF Model'!$D$36/(1+0.19)^3+'DCF Model'!$E$36/(1+0.19)^4+'DCF Model'!$F$36/(1+0.19)^5+'DCF Model'!$G$36/(1+0.19)^6+'DCF Model'!$H$36/(1+0.19)^7+'DCF Model'!$I$36/(1+0.19)^8+'DCF Model'!$J$36/(1+0.19)^9+'DCF Model'!$K$36/(1+0.19)^10+MIN('DCF Model'!$K$36*(1+0.013000000000000001)/(0.19-0.013000000000000001),'DCF Model'!$B$10*'DCF Model'!$K$26)/(1+0.19)^10-'DCF Model'!$B$7)/'DCF Model'!$B$6 -> 0 | D9: =('DCF Model'!$B$36/(1+0.19)^1+'DCF Model'!$C$36/(1+0.19)^2+'DCF Model'!$D$36/(1+0.19)^3+'DCF Model'!$E$36/(1+0.19)^4+'DCF Model'!$F$36/(1+0.19)^5+'DCF Model'!$G$36/(1+0.19)^6+'DCF Model'!$H$36/(1+0.19)^7+'DCF Model'!$I$36/(1+0.19)^8+'DCF Model'!$J$36/(1+0.19)^9+'DCF Model'!$K$36/(1+0.19)^10+MIN('DCF Model'!$K$36*(1+0.018000000000000002)/(0.19-0.018000000000000002),'DCF Model'!$B$10*'DCF Model'!$K$26)/(1+0.19)^10-'DCF Model'!$B$7)/'DCF Model'!$B$6 -> 0 | E9: =('DCF Model'!$B$36/(1+0.19)^1+'DCF Model'!$C$36/(1+0.19)^2+'DCF Model'!$D$36/(1+0.19)^3+'DCF Model'!$E$36/(1+0.19)^4+'DCF Model'!$F$36/(1+0.19)^5+'DCF Model'!$G$36/(1+0.19)^6+'DCF Model'!$H$36/(1+0.19)^7+'DCF Model'!$I$36/(1+0.19)^8+'DCF Model'!$J$36/(1+0.19)^9+'DCF Model'!$K$36/(1+0.19)^10+MIN('DCF Model'!$K$36*(1+0.023)/(0.19-0.023),'DCF Model'!$B$10*'DCF Model'!$K$26)/(1+0.19)^10-'DCF Model'!$B$7)/'DCF Model'!$B$6 -> 0 | F9: =('DCF Model'!$B$36/(1+0.19)^1+'DCF Model'!$C$36/(1+0.19)^2+'DCF Model'!$D$36/(1+0.19)^3+'DCF Model'!$E$36/(1+0.19)^4+'DCF Model'!$F$36/(1+0.19)^5+'DCF Model'!$G$36/(1+0.19)^6+'DCF Model'!$H$36/(1+0.19)^7+'DCF Model'!$I$36/(1+0.19)^8+'DCF Model'!$J$36/(1+0.19)^9+'DCF Model'!$K$36/(1+0.19)^10+MIN('DCF Model'!$K$36*(1+0.027999999999999997)/(0.19-0.027999999999999997),'DCF Model'!$B$10*'DCF Model'!$K$26)/(1+0.19)^10-'DCF Model'!$B$7)/'DCF Model'!$B$6 -> 0
A11: Note: matrix recalculates from DCF Model sheet base-case FCF/EBITDA path; changing base-case
A12: growth/margin inputs on the DCF Model sheet will flow through to this table automatically.

Sheet FCF Quality
A1: FCF Quality - Reported vs Owner FCF Reconciliation (FY2018-FY2026)
B3: FY2018 | C3: FY2019 | D3: FY2020 | E3: FY2021 | F3: FY2022 | G3: FY2023 | H3: FY2024 | I3: FY2025 | J3: FY2026
A4: Revenue | B4: 279.3 | C4: 267.8 | D4: 263.5 | E4: 205.5 | F4: 221.5 | G4: 227.4 | H4: 212.4 | I4: 165.2 | J4: 165.1
A5: Operating Cash Flow | B5: 11.5 | C5: 9.5 | D5: 9.9 | E5: 21.9 | F5: 10.5 | G5: 4.7 | H5: 2.3 | I5: -0.6 | J5: 1.6
A6: Less: Capex | B6: 0.6 | C6: 2.6 | D6: 1 | E6: 1.4 | F6: 0.6 | G6: 0.7 | H6: 0.2 | I6: 0.2 | J6: 0.2
A7: Less: Lease Principal Paid | B7: 0 | C7: 0 | D7: 2.4 | E7: 2.5 | F7: 2.4 | G7: 2.5 | H7: 2.8 | I7: 2.9 | J7: 2.1
A8: Less: SBC | B8: 0 | C8: 0.16 | D8: 0.12 | E8: 0.08 | F8: 0.02 | G8: 0.22 | H8: 0.21 | I8: 0.19 | J8: 0.08
A9: = Owner FCF | B9: 10.9 | C9: 6.74 | D9: 6.38 | E9: 17.92 | F9: 7.48 | G9: 1.28 | H9: -0.91 | I9: -3.89 | J9: -0.78
A10: Owner FCF Margin % | B10: 0.039 | C10: 0.0252 | D10: 0.0242 | E10: 0.0872 | F10: 0.0338 | G10: 0.0056 | H10: -0.0043 | I10: -0.0235 | J10: -0.0047
A11: Reported FCF (company definition) | B11: 10.9 | C11: 6.8 | D11: 8.9 | E11: 20.5 | F11: 9.9 | G11: 4 | H11: 2.1 | I11: -0.8 | J11: 1.4
A13: Memo: Reported FCF margin % | B13: 0.039026137 | C13: 0.025392084 | D13: 0.033776091 | E13: 0.099756691 | F13: 0.04469526 | G13: 0.01759015 | H13: 0.0098870056 | I13: -0.004842615 | J13: 0.0084797093
A14: Memo: cash tax rate flag
A15: FY26 effective tax rate 22.7%, FY25 33.0% - no valuation allowance release identified; 28% NZ statutory used flat in projections

Sheet Historical
A1: Historical Growth Rates & Multiples
A3: Metric | B3: 3-Year CAGR | C3: 5-Year CAGR
A4: Revenue | B4: -0.1012 | C4: -0.0428
A5: Shareholders Equity | B5: -0.1972 | C5: -0.1486
A7: Note: EPS and FCF CAGRs not computable (negative in multiple years).
A8: Revenue and equity CAGRs are both deeply negative (three-year revenue -10.1%/yr, equity -19.7%/yr) reflecting the FY23-26 downturn and FY24 goodwill impairment. EPS and owner-FCF CAGRs are not computable (negative/near-zero values in multiple years). Historical CAGRs are NOT used as the growth driver; projections are built bottom-up from a cyclical mid-cycle revenue recovery path anchored to FY19-23 pre-downturn levels (component build per Step 1c), not extrapolated from trailing CAGRs, because this is a post-trough cyclical recovery situation not a compounding growth trend.
A10: Historical Multiples (pre-raise share count)
A11: Year | B11: Price | C11: P/E | D11: P/B | E11: EV/EBITDA | F11: P/S
A12: FY2018 | B12: 1.9 | C12: 14.67 | D12: 1.99 | E12: 8.73 | F12: 0.26
A13: FY2019 | B13: 1.65 | C13: 32.42 | D13: 1.86 | E13: 11.88 | F13: 0.24
A14: FY2020 | B14: 1.29 | C14: 21.55 | D14: 1.73 | E14: 7.21 | F14: 0.22
A15: FY2021 | B15: 1.3 | C15: 7.99 | D15: 1.24 | E15: 3.61 | F15: 0.24
A16: FY2022 | B16: 2.02 | C16: 25.65 | D16: 2.1 | E16: 8.41 | F16: 0.35
A17: FY2023 | B17: 1.61 | C17: 34.29 | D17: 1.98 | E17: 9.58 | F17: 0.3
A18: FY2024 | B18: 0.56 | C18: n/a | D18: 0.78 | E18: n/a | F18: 0.08
A19: FY2025 | B19: 0.38 | C19: n/a | D19: 0.6 | E19: 11.77 | F19: 0.07
A20: FY2026 | B20: 0.145 | C20: n/a | D20: 0.26 | E20: 8.07 | F20: 0.03

Sheet Model_Info
A3: BUILT BY: dcf-analyst agent (Claude), within the Stocks/Research project.
A4: VALUATION DATE: 2026-07-31
A5: SHARE PRICE VINTAGE: NZ$0.166, live Yahoo Finance quote fetched 2026-07-31.
A7: DATA VINTAGE:
A8: - FY2026 Annual Report (year ended 31-Mar-2026), authorised 28-May-2026: revenue $165.1m, net loss $2.1m,
A9: net bank debt $28.5m at balance date, shareholders' equity $17.9m, goodwill $31.6m.
A10: - Post-balance-date event: renounceable rights offer completed 13-May-2026, 33,333,334 new shares at $0.15,
A11: $5.0m gross proceeds applied to bank debt repayment, taking shares on issue to 67,658,876 and pro-forma
A12: net bank debt to approximately $24.0m. Bank facilities extended to 30-Apr-2028.
A13: - Historical FY2018-FY2026 metrics from AGL.NZ_Metrics.csv, cross-checked against Extracted/ 10-K/Annual
A14: Report text (share-based payments note F1, depreciation note, effective tax rate note).
A16: METHODOLOGY CHOICES:
... A66: decision, and do not extrapolate the 'valuation_date' price or FY2026 actuals beyond one reporting cycle.
