Workbook

Sheet NTA Model
A1: AFI.NZ - AFIC NTA-Compounding Valuation Model
A2: LIC valuation: NTA total-return compounding + exit discount/premium (NOT a standard FCF DCF). Gray cells are INPUTS.
A4: KEY INPUTS
A5: Current Price - NZX (NZ$, AFI.NZ) | B5: 8.27
A6: Current Price - ASX (A$, AFI.AX) | B6: 6.86
A7: AUDNZD FX rate | B7: 1.19807
A8: Pre-tax NTA per share (A$, latest) | B8: 7.93
A9: Shares Outstanding (M) | B9: 1253
A10: Net Cash (A$M) | B10: 131.6
A11: Current Price / NTA discount (A$ basis) | B11: =B6/B8-1 -> 0
A13: Cost of Equity (CoE) | B13: 0.0875
A14: Dividend payout yield (all scenarios) | B14: 0.04
A16: SCENARIO ASSUMPTIONS
B17: Bear | C17: Base | D17: Bull
A18: NTA Total Return p.a. | B18: 0.05 | C18: 0.075 | D18: 0.095
A19: Implied NTA/share growth (= total return - div yield) | B19: =B18-$B$14 -> 0 | C19: =C18-$B$14 -> 0 | D19: =D18-$B$14 -> 0
A20: Exit discount/(premium) to NTA, Yr5 | B20: -0.13 | C20: -0.06 | D20: 0
A22: NTA & DIVIDEND PROJECTIONS (A$ per share)
A24: BEAR | C24: FY2027 | D24: FY2028 | E24: FY2029 | F24: FY2030 | G24: FY2031
B25: NTA/share | C25: =$B$8*(1+$B$19) -> 0 | D25: =C25*(1+$B$19) -> 0 | E25: =D25*(1+$B$19) -> 0 | F25: =E25*(1+$B$19) -> 0 | G25: =F25*(1+$B$19) -> 0
B26: Dividend/share | C26: =$B$8*$B$14 -> 0 | D26: =C25*$B$14 -> 0 | E26: =D25*$B$14 -> 0 | F26: =E25*$B$14 -> 0 | G26: =F25*$B$14 -> 0
A28: BASE | C28: FY2027 | D28: FY2028 | E28: FY2029 | F28: FY2030 | G28: FY2031
B29: NTA/share | C29: =$B$8*(1+$C$19) -> 0 | D29: =C29*(1+$C$19) -> 0 | E29: =D29*(1+$C$19) -> 0 | F29: =E29*(1+$C$19) -> 0 | G29: =F29*(1+$C$19) -> 0
B30: Dividend/share | C30: =$B$8*$B$14 -> 0 | D30: =C29*$B$14 -> 0 | E30: =D29*$B$14 -> 0 | F30: =E29*$B$14 -> 0 | G30: =F29*$B$14 -> 0
A32: BULL | C32: FY2027 | D32: FY2028 | E32: FY2029 | F32: FY2030 | G32: FY2031
B33: NTA/share | C33: =$B$8*(1+$D$19) -> 0 | D33: =C33*(1+$D$19) -> 0 | E33: =D33*(1+$D$19) -> 0 | F33: =E33*(1+$D$19) -> 0 | G33: =F33*(1+$D$19) -> 0
B34: Dividend/share | C34: =$B$8*$B$14 -> 0 | D34: =C33*$B$14 -> 0 | E34: =D33*$B$14 -> 0 | F34: =E33*$B$14 -> 0 | G34: =F33*$B$14 -> 0
A36: HEADLINE VALUATION (current NTA x fair exit discount)
B37: Bear | C37: Base | D37: Bull
A38: Intrinsic Value (A$) | B38: =$B$8*(1+B20) -> 0 | C38: =$B$8*(1+C20) -> 0 | D38: =$B$8*(1+D20) -> 0
A39: Intrinsic Value (NZ$) | B39: =B38*$B$7 -> 0 | C39: =C38*$B$7 -> 0 | D39: =D38*$B$7 -> 0
A40: Upside vs current NZX price | B40: =B39/$B$5-1 -> 0 | C40: =C39/$B$5-1 -> 0 | D40: =D39/$B$5-1 -> 0
A41: Implied P/NTA | B41: =B20 -> 0 | C41: =C20 -> 0 | D41: =D20 -> 0
A43: 5-YEAR IRR BUILD (memo, discounted at CoE)
B44: Bear | C44: Base | D44: Bull
A45: Year-5 NTA/share (A$) | B45: =G25 -> 0 | C45: =G29 -> 0 | D45: =G33 -> 0
A46: Year-5 exit price (A$) = Y5 NTA x (1+exit disc) | B46: =B45*(1+B20) -> 0 | C46: =C45*(1+C20) -> 0 | D46: =D45*(1+D20) -> 0
A47: PV of dividends @ CoE (NPV yrs1-5) | B47: =NPV($B$13,C26:G26) -> 0 | C47: =NPV($B$13,C30:G30) -> 0 | D47: =NPV($B$13,C34:G34) -> 0
A48: PV of exit value @ CoE | B48: =B46/(1+$B$13)^5 -> 0 | C48: =C46/(1+$B$13)^5 -> 0 | D48: =D46/(1+$B$13)^5 -> 0
A49: 5yr-build Fair Value (A$) | B49: =B47+B48 -> 0 | C49: =C47+C48 -> 0 | D49: =D47+D48 -> 0
...

Sheet Sensitivity
A1: Sensitivity Analysis
A2: 5yr-build Fair Value (A$) by Exit Discount (rows) x NTA Total Return (cols)
A4: Discount \ Return | B4: 0.05 | C4: 0.065 | D4: 0.075 | E4: 0.085 | F4: 0.095
A5: -0.13 | B5: =('NTA Model'!$B$8*(1+(0.05-'NTA Model'!$B$14))*0.04*(1/(1+'NTA Model'!$B$13)^1)+'NTA Model'!$B$8*(1+(0.05-'NTA Model'!$B$14))^2*0.04*(1/(1+'NTA Model'!$B$13)^2)+'NTA Model'!$B$8*(1+(0.05-'NTA Model'!$B$14))^3*0.04*(1/(1+'NTA Model'!$B$13)^3)+'NTA Model'!$B$8*(1+(0.05-'NTA Model'!$B$14))^4*0.04*(1/(1+'NTA Model'!$B$13)^4)+'NTA Model'!$B$8*(1+(0.05-'NTA Model'!$B$14))^5*0.04*(1/(1+'NTA Model'!$B$13)^5)+('NTA Model'!$B$8*(1+(0.05-'NTA Model'!$B$14))^5*(1+-0.13))/(1+'NTA Model'!$B$13)^5) -> 0 | C5: =('NTA Model'!$B$8*(1+(0.065-'NTA Model'!$B$14))*0.04*(1/(1+'NTA Model'!$B$13)^1)+'NTA Model'!$B$8*(1+(0.065-'NTA Model'!$B$14))^2*0.04*(1/(1+'NTA Model'!$B$13)^2)+'NTA Model'!$B$8*(1+(0.065-'NTA Model'!$B$14))^3*0.04*(1/(1+'NTA Model'!$B$13)^3)+'NTA Model'!$B$8*(1+(0.065-'NTA Model'!$B$14))^4*0.04*(1/(1+'NTA Model'!$B$13)^4)+'NTA Model'!$B$8*(1+(0.065-'NTA Model'!$B$14))^5*0.04*(1/(1+'NTA Model'!$B$13)^5)+('NTA Model'!$B$8*(1+(0.065-'NTA Model'!$B$14))^5*(1+-0.13))/(1+'NTA Model'!$B$13)^5) -> 0 | D5: =('NTA Model'!$B$8*(1+(0.075-'NTA Model'!$B$14))*0.04*(1/(1+'NTA Model'!$B$13)^1)+'NTA Model'!$B$8*(1+(0.075-'NTA Model'!$B$14))^2*0.04*(1/(1+'NTA Model'!$B$13)^2)+'NTA Model'!$B$8*(1+(0.075-'NTA Model'!$B$14))^3*0.04*(1/(1+'NTA Model'!$B$13)^3)+'NTA Model'!$B$8*(1+(0.075-'NTA Model'!$B$14))^4*0.04*(1/(1+'NTA Model'!$B$13)^4)+'NTA Model'!$B$8*(1+(0.075-'NTA Model'!$B$14))^5*0.04*(1/(1+'NTA Model'!$B$13)^5)+('NTA Model'!$B$8*(1+(0.075-'NTA Model'!$B$14))^5*(1+-0.13))/(1+'NTA Model'!$B$13)^5) -> 0 | E5: =('NTA Model'!$B$8*(1+(0.085-'NTA Model'!$B$14))*0.04*(1/(1+'NTA Model'!$B$13)^1)+'NTA Model'!$B$8*(1+(0.085-'NTA Model'!$B$14))^2*0.04*(1/(1+'NTA Model'!$B$13)^2)+'NTA Model'!$B$8*(1+(0.085-'NTA Model'!$B$14))^3*0.04*(1/(1+'NTA Model'!$B$13)^3)+'NTA Model'!$B$8*(1+(0.085-'NTA Model'!$B$14))^4*0.04*(1/(1+'NTA Model'!$B$13)^4)+'NTA Model'!$B$8*(1+(0.085-'NTA Model'!$B$14))^5*0.04*(1/(1+'NTA Model'!$B$13)^5)+('NTA Model'!$B$8*(1+(0.085-'NTA Model'!$B$14))^5*(1+-0.13))/(1+'NTA Model'!$B$13)^5) -> 0 | F5: =('NTA Model'!$B$8*(1+(0.095-'NTA Model'!$B$14))*0.04*(1/(1+'NTA Model'!$B$13)^1)+'NTA Model'!$B$8*(1+(0.095-'NTA Model'!$B$14))^2*0.04*(1/(1+'NTA Model'!$B$13)^2)+'NTA Model'!$B$8*(1+(0.095-'NTA Model'!$B$14))^3*0.04*(1/(1+'NTA Model'!$B$13)^3)+'NTA Model'!$B$8*(1+(0.095-'NTA Model'!$B$14))^4*0.04*(1/(1+'NTA Model'!$B$13)^4)+'NTA Model'!$B$8*(1+(0.095-'NTA Model'!$B$14))^5*0.04*(1/(1+'NTA Model'!$B$13)^5)+('NTA Model'!$B$8*(1+(0.095-'NTA Model'!$B$14))^5*(1+-0.13))/(1+'NTA Model'!$B$13)^5) -> 0
A6: -0.09 | B6: =('NTA Model'!$B$8*(1+(0.05-'NTA Model'!$B$14))*0.04*(1/(1+'NTA Model'!$B$13)^1)+'NTA Model'!$B$8*(1+(0.05-'NTA Model'!$B$14))^2*0.04*(1/(1+'NTA Model'!$B$13)^2)+'NTA Model'!$B$8*(1+(0.05-'NTA Model'!$B$14))^3*0.04*(1/(1+'NTA Model'!$B$13)^3)+'NTA Model'!$B$8*(1+(0.05-'NTA Model'!$B$14))^4*0.04*(1/(1+'NTA Model'!$B$13)^4)+'NTA Model'!$B$8*(1+(0.05-'NTA Model'!$B$14))^5*0.04*(1/(1+'NTA Model'!$B$13)^5)+('NTA Model'!$B$8*(1+(0.05-'NTA Model'!$B$14))^5*(1+-0.09))/(1+'NTA Model'!$B$13)^5) -> 0 | C6: =('NTA Model'!$B$8*(1+(0.065-'NTA Model'!$B$14))*0.04*(1/(1+'NTA Model'!$B$13)^1)+'NTA Model'!$B$8*(1+(0.065-'NTA Model'!$B$14))^2*0.04*(1/(1+'NTA Model'!$B$13)^2)+'NTA Model'!$B$8*(1+(0.065-'NTA Model'!$B$14))^3*0.04*(1/(1+'NTA Model'!$B$13)^3)+'NTA Model'!$B$8*(1+(0.065-'NTA Model'!$B$14))^4*0.04*(1/(1+'NTA Model'!$B$13)^4)+'NTA Model'!$B$8*(1+(0.065-'NTA Model'!$B$14))^5*0.04*(1/(1+'NTA Model'!$B$13)^5)+('NTA Model'!$B$8*(1+(0.065-'NTA Model'!$B$14))^5*(1+-0.09))/(1+'NTA Model'!$B$13)^5) -> 0 | D6: =('NTA Model'!$B$8*(1+(0.075-'NTA Model'!$B$14))*0.04*(1/(1+'NTA Model'!$B$13)^1)+'NTA Model'!$B$8*(1+(0.075-'NTA Model'!$B$14))^2*0.04*(1/(1+'NTA Model'!$B$13)^2)+'NTA Model'!$B$8*(1+(0.075-'NTA Model'!$B$14))^3*0.04*(1/(1+'NTA Model'!$B$13)^3)+'NTA Model'!$B$8*(1+(0.075-'NTA Model'!$B$14))^4*0.04*(1/(1+'NTA Model'!$B$13)^4)+'NTA Model'!$B$8*(1+(0.075-'NTA Model'!$B$14))^5*0.04*(1/(1+'NTA Model'!$B$13)^5)+('NTA Model'!$B$8*(1+(0.075-'NTA Model'!$B$14))^5*(1+-0.09))/(1+'NTA Model'!$B$13)^5) -> 0 | E6: =('NTA Model'!$B$8*(1+(0.085-'NTA Model'!$B$14))*0.04*(1/(1+'NTA Model'!$B$13)^1)+'NTA Model'!$B$8*(1+(0.085-'NTA Model'!$B$14))^2*0.04*(1/(1+'NTA Model'!$B$13)^2)+'NTA Model'!$B$8*(1+(0.085-'NTA Model'!$B$14))^3*0.04*(1/(1+'NTA Model'!$B$13)^3)+'NTA Model'!$B$8*(1+(0.085-'NTA Model'!$B$14))^4*0.04*(1/(1+'NTA Model'!$B$13)^4)+'NTA Model'!$B$8*(1+(0.085-'NTA Model'!$B$14))^5*0.04*(1/(1+'NTA Model'!$B$13)^5)+('NTA Model'!$B$8*(1+(0.085-'NTA Model'!$B$14))^5*(1+-0.09))/(1+'NTA Model'!$B$13)^5) -> 0 | F6: =('NTA Model'!$B$8*(1+(0.095-'NTA Model'!$B$14))*0.04*(1/(1+'NTA Model'!$B$13)^1)+'NTA Model'!$B$8*(1+(0.095-'NTA Model'!$B$14))^2*0.04*(1/(1+'NTA Model'!$B$13)^2)+'NTA Model'!$B$8*(1+(0.095-'NTA Model'!$B$14))^3*0.04*(1/(1+'NTA Model'!$B$13)^3)+'NTA Model'!$B$8*(1+(0.095-'NTA Model'!$B$14))^4*0.04*(1/(1+'NTA Model'!$B$13)^4)+'NTA Model'!$B$8*(1+(0.095-'NTA Model'!$B$14))^5*0.04*(1/(1+'NTA Model'!$B$13)^5)+('NTA Model'!$B$8*(1+(0.095-'NTA Model'!$B$14))^5*(1+-0.09))/(1+'NTA Model'!$B$13)^5) -> 0
A7: -0.06 | B7: =('NTA Model'!$B$8*(1+(0.05-'NTA Model'!$B$14))*0.04*(1/(1+'NTA Model'!$B$13)^1)+'NTA Model'!$B$8*(1+(0.05-'NTA Model'!$B$14))^2*0.04*(1/(1+'NTA Model'!$B$13)^2)+'NTA Model'!$B$8*(1+(0.05-'NTA Model'!$B$14))^3*0.04*(1/(1+'NTA Model'!$B$13)^3)+'NTA Model'!$B$8*(1+(0.05-'NTA Model'!$B$14))^4*0.04*(1/(1+'NTA Model'!$B$13)^4)+'NTA Model'!$B$8*(1+(0.05-'NTA Model'!$B$14))^5*0.04*(1/(1+'NTA Model'!$B$13)^5)+('NTA Model'!$B$8*(1+(0.05-'NTA Model'!$B$14))^5*(1+-0.06))/(1+'NTA Model'!$B$13)^5) -> 0 | C7: =('NTA Model'!$B$8*(1+(0.065-'NTA Model'!$B$14))*0.04*(1/(1+'NTA Model'!$B$13)^1)+'NTA Model'!$B$8*(1+(0.065-'NTA Model'!$B$14))^2*0.04*(1/(1+'NTA Model'!$B$13)^2)+'NTA Model'!$B$8*(1+(0.065-'NTA Model'!$B$14))^3*0.04*(1/(1+'NTA Model'!$B$13)^3)+'NTA Model'!$B$8*(1+(0.065-'NTA Model'!$B$14))^4*0.04*(1/(1+'NTA Model'!$B$13)^4)+'NTA Model'!$B$8*(1+(0.065-'NTA Model'!$B$14))^5*0.04*(1/(1+'NTA Model'!$B$13)^5)+('NTA Model'!$B$8*(1+(0.065-'NTA Model'!$B$14))^5*(1+-0.06))/(1+'NTA Model'!$B$13)^5) -> 0 | D7: =('NTA Model'!$B$8*(1+(0.075-'NTA Model'!$B$14))*0.04*(1/(1+'NTA Model'!$B$13)^1)+'NTA Model'!$B$8*(1+(0.075-'NTA Model'!$B$14))^2*0.04*(1/(1+'NTA Model'!$B$13)^2)+'NTA Model'!$B$8*(1+(0.075-'NTA Model'!$B$14))^3*0.04*(1/(1+'NTA Model'!$B$13)^3)+'NTA Model'!$B$8*(1+(0.075-'NTA Model'!$B$14))^4*0.04*(1/(1+'NTA Model'!$B$13)^4)+'NTA Model'!$B$8*(1+(0.075-'NTA Model'!$B$14))^5*0.04*(1/(1+'NTA Model'!$B$13)^5)+('NTA Model'!$B$8*(1+(0.075-'NTA Model'!$B$14))^5*(1+-0.06))/(1+'NTA Model'!$B$13)^5) -> 0 | E7: =('NTA Model'!$B$8*(1+(0.085-'NTA Model'!$B$14))*0.04*(1/(1+'NTA Model'!$B$13)^1)+'NTA Model'!$B$8*(1+(0.085-'NTA Model'!$B$14))^2*0.04*(1/(1+'NTA Model'!$B$13)^2)+'NTA Model'!$B$8*(1+(0.085-'NTA Model'!$B$14))^3*0.04*(1/(1+'NTA Model'!$B$13)^3)+'NTA Model'!$B$8*(1+(0.085-'NTA Model'!$B$14))^4*0.04*(1/(1+'NTA Model'!$B$13)^4)+'NTA Model'!$B$8*(1+(0.085-'NTA Model'!$B$14))^5*0.04*(1/(1+'NTA Model'!$B$13)^5)+('NTA Model'!$B$8*(1+(0.085-'NTA Model'!$B$14))^5*(1+-0.06))/(1+'NTA Model'!$B$13)^5) -> 0 | F7: =('NTA Model'!$B$8*(1+(0.095-'NTA Model'!$B$14))*0.04*(1/(1+'NTA Model'!$B$13)^1)+'NTA Model'!$B$8*(1+(0.095-'NTA Model'!$B$14))^2*0.04*(1/(1+'NTA Model'!$B$13)^2)+'NTA Model'!$B$8*(1+(0.095-'NTA Model'!$B$14))^3*0.04*(1/(1+'NTA Model'!$B$13)^3)+'NTA Model'!$B$8*(1+(0.095-'NTA Model'!$B$14))^4*0.04*(1/(1+'NTA Model'!$B$13)^4)+'NTA Model'!$B$8*(1+(0.095-'NTA Model'!$B$14))^5*0.04*(1/(1+'NTA Model'!$B$13)^5)+('NTA Model'!$B$8*(1+(0.095-'NTA Model'!$B$14))^5*(1+-0.06))/(1+'NTA Model'!$B$13)^5) -> 0
A8: -0.03 | B8: =('NTA Model'!$B$8*(1+(0.05-'NTA Model'!$B$14))*0.04*(1/(1+'NTA Model'!$B$13)^1)+'NTA Model'!$B$8*(1+(0.05-'NTA Model'!$B$14))^2*0.04*(1/(1+'NTA Model'!$B$13)^2)+'NTA Model'!$B$8*(1+(0.05-'NTA Model'!$B$14))^3*0.04*(1/(1+'NTA Model'!$B$13)^3)+'NTA Model'!$B$8*(1+(0.05-'NTA Model'!$B$14))^4*0.04*(1/(1+'NTA Model'!$B$13)^4)+'NTA Model'!$B$8*(1+(0.05-'NTA Model'!$B$14))^5*0.04*(1/(1+'NTA Model'!$B$13)^5)+('NTA Model'!$B$8*(1+(0.05-'NTA Model'!$B$14))^5*(1+-0.03))/(1+'NTA Model'!$B$13)^5) -> 0 | C8: =('NTA Model'!$B$8*(1+(0.065-'NTA Model'!$B$14))*0.04*(1/(1+'NTA Model'!$B$13)^1)+'NTA Model'!$B$8*(1+(0.065-'NTA Model'!$B$14))^2*0.04*(1/(1+'NTA Model'!$B$13)^2)+'NTA Model'!$B$8*(1+(0.065-'NTA Model'!$B$14))^3*0.04*(1/(1+'NTA Model'!$B$13)^3)+'NTA Model'!$B$8*(1+(0.065-'NTA Model'!$B$14))^4*0.04*(1/(1+'NTA Model'!$B$13)^4)+'NTA Model'!$B$8*(1+(0.065-'NTA Model'!$B$14))^5*0.04*(1/(1+'NTA Model'!$B$13)^5)+('NTA Model'!$B$8*(1+(0.065-'NTA Model'!$B$14))^5*(1+-0.03))/(1+'NTA Model'!$B$13)^5) -> 0 | D8: =('NTA Model'!$B$8*(1+(0.075-'NTA Model'!$B$14))*0.04*(1/(1+'NTA Model'!$B$13)^1)+'NTA Model'!$B$8*(1+(0.075-'NTA Model'!$B$14))^2*0.04*(1/(1+'NTA Model'!$B$13)^2)+'NTA Model'!$B$8*(1+(0.075-'NTA Model'!$B$14))^3*0.04*(1/(1+'NTA Model'!$B$13)^3)+'NTA Model'!$B$8*(1+(0.075-'NTA Model'!$B$14))^4*0.04*(1/(1+'NTA Model'!$B$13)^4)+'NTA Model'!$B$8*(1+(0.075-'NTA Model'!$B$14))^5*0.04*(1/(1+'NTA Model'!$B$13)^5)+('NTA Model'!$B$8*(1+(0.075-'NTA Model'!$B$14))^5*(1+-0.03))/(1+'NTA Model'!$B$13)^5) -> 0 | E8: =('NTA Model'!$B$8*(1+(0.085-'NTA Model'!$B$14))*0.04*(1/(1+'NTA Model'!$B$13)^1)+'NTA Model'!$B$8*(1+(0.085-'NTA Model'!$B$14))^2*0.04*(1/(1+'NTA Model'!$B$13)^2)+'NTA Model'!$B$8*(1+(0.085-'NTA Model'!$B$14))^3*0.04*(1/(1+'NTA Model'!$B$13)^3)+'NTA Model'!$B$8*(1+(0.085-'NTA Model'!$B$14))^4*0.04*(1/(1+'NTA Model'!$B$13)^4)+'NTA Model'!$B$8*(1+(0.085-'NTA Model'!$B$14))^5*0.04*(1/(1+'NTA Model'!$B$13)^5)+('NTA Model'!$B$8*(1+(0.085-'NTA Model'!$B$14))^5*(1+-0.03))/(1+'NTA Model'!$B$13)^5) -> 0 | F8: =('NTA Model'!$B$8*(1+(0.095-'NTA Model'!$B$14))*0.04*(1/(1+'NTA Model'!$B$13)^1)+'NTA Model'!$B$8*(1+(0.095-'NTA Model'!$B$14))^2*0.04*(1/(1+'NTA Model'!$B$13)^2)+'NTA Model'!$B$8*(1+(0.095-'NTA Model'!$B$14))^3*0.04*(1/(1+'NTA Model'!$B$13)^3)+'NTA Model'!$B$8*(1+(0.095-'NTA Model'!$B$14))^4*0.04*(1/(1+'NTA Model'!$B$13)^4)+'NTA Model'!$B$8*(1+(0.095-'NTA Model'!$B$14))^5*0.04*(1/(1+'NTA Model'!$B$13)^5)+('NTA Model'!$B$8*(1+(0.095-'NTA Model'!$B$14))^5*(1+-0.03))/(1+'NTA Model'!$B$13)^5) -> 0
A9: 0 | B9: =('NTA Model'!$B$8*(1+(0.05-'NTA Model'!$B$14))*0.04*(1/(1+'NTA Model'!$B$13)^1)+'NTA Model'!$B$8*(1+(0.05-'NTA Model'!$B$14))^2*0.04*(1/(1+'NTA Model'!$B$13)^2)+'NTA Model'!$B$8*(1+(0.05-'NTA Model'!$B$14))^3*0.04*(1/(1+'NTA Model'!$B$13)^3)+'NTA Model'!$B$8*(1+(0.05-'NTA Model'!$B$14))^4*0.04*(1/(1+'NTA Model'!$B$13)^4)+'NTA Model'!$B$8*(1+(0.05-'NTA Model'!$B$14))^5*0.04*(1/(1+'NTA Model'!$B$13)^5)+('NTA Model'!$B$8*(1+(0.05-'NTA Model'!$B$14))^5*(1+0.0))/(1+'NTA Model'!$B$13)^5) -> 0 | C9: =('NTA Model'!$B$8*(1+(0.065-'NTA Model'!$B$14))*0.04*(1/(1+'NTA Model'!$B$13)^1)+'NTA Model'!$B$8*(1+(0.065-'NTA Model'!$B$14))^2*0.04*(1/(1+'NTA Model'!$B$13)^2)+'NTA Model'!$B$8*(1+(0.065-'NTA Model'!$B$14))^3*0.04*(1/(1+'NTA Model'!$B$13)^3)+'NTA Model'!$B$8*(1+(0.065-'NTA Model'!$B$14))^4*0.04*(1/(1+'NTA Model'!$B$13)^4)+'NTA Model'!$B$8*(1+(0.065-'NTA Model'!$B$14))^5*0.04*(1/(1+'NTA Model'!$B$13)^5)+('NTA Model'!$B$8*(1+(0.065-'NTA Model'!$B$14))^5*(1+0.0))/(1+'NTA Model'!$B$13)^5) -> 0 | D9: =('NTA Model'!$B$8*(1+(0.075-'NTA Model'!$B$14))*0.04*(1/(1+'NTA Model'!$B$13)^1)+'NTA Model'!$B$8*(1+(0.075-'NTA Model'!$B$14))^2*0.04*(1/(1+'NTA Model'!$B$13)^2)+'NTA Model'!$B$8*(1+(0.075-'NTA Model'!$B$14))^3*0.04*(1/(1+'NTA Model'!$B$13)^3)+'NTA Model'!$B$8*(1+(0.075-'NTA Model'!$B$14))^4*0.04*(1/(1+'NTA Model'!$B$13)^4)+'NTA Model'!$B$8*(1+(0.075-'NTA Model'!$B$14))^5*0.04*(1/(1+'NTA Model'!$B$13)^5)+('NTA Model'!$B$8*(1+(0.075-'NTA Model'!$B$14))^5*(1+0.0))/(1+'NTA Model'!$B$13)^5) -> 0 | E9: =('NTA Model'!$B$8*(1+(0.085-'NTA Model'!$B$14))*0.04*(1/(1+'NTA Model'!$B$13)^1)+'NTA Model'!$B$8*(1+(0.085-'NTA Model'!$B$14))^2*0.04*(1/(1+'NTA Model'!$B$13)^2)+'NTA Model'!$B$8*(1+(0.085-'NTA Model'!$B$14))^3*0.04*(1/(1+'NTA Model'!$B$13)^3)+'NTA Model'!$B$8*(1+(0.085-'NTA Model'!$B$14))^4*0.04*(1/(1+'NTA Model'!$B$13)^4)+'NTA Model'!$B$8*(1+(0.085-'NTA Model'!$B$14))^5*0.04*(1/(1+'NTA Model'!$B$13)^5)+('NTA Model'!$B$8*(1+(0.085-'NTA Model'!$B$14))^5*(1+0.0))/(1+'NTA Model'!$B$13)^5) -> 0 | F9: =('NTA Model'!$B$8*(1+(0.095-'NTA Model'!$B$14))*0.04*(1/(1+'NTA Model'!$B$13)^1)+'NTA Model'!$B$8*(1+(0.095-'NTA Model'!$B$14))^2*0.04*(1/(1+'NTA Model'!$B$13)^2)+'NTA Model'!$B$8*(1+(0.095-'NTA Model'!$B$14))^3*0.04*(1/(1+'NTA Model'!$B$13)^3)+'NTA Model'!$B$8*(1+(0.095-'NTA Model'!$B$14))^4*0.04*(1/(1+'NTA Model'!$B$13)^4)+'NTA Model'!$B$8*(1+(0.095-'NTA Model'!$B$14))^5*0.04*(1/(1+'NTA Model'!$B$13)^5)+('NTA Model'!$B$8*(1+(0.095-'NTA Model'!$B$14))^5*(1+0.0))/(1+'NTA Model'!$B$13)^5) -> 0
A11: Note: uses 4.0% dividend payout yield for all cells (matches base assumption). Discount row -6% / return column 7.5% = base case.

Sheet Historical
A1: AFIC Historical NTA & Dividend Data (A$)
A3: Period | B3: Pre-tax NTA/sh | C3: After-tax NTA/sh | D3: DPS (c) | E3: NPAT (A$m) | F3: Shares (M) | G3: MER
A4: FY2015 | B4: 5.85 | C4: 5 | D4: 23 | E4: 293.6 | F4: 1089.8 | G4: 0.16
A5: FY2016 | B5: 5.5 | C5: 4.79 | D5: 24 | E5: 265.8 | F5: 1130.3 | G5: 0.16
A6: FY2017 | B6: 5.89 | C6: 5.07 | D6: 24 | E6: 245.3 | F6: 1176.1 | G6: 0.14
A7: FY2018 | B7: 6.27 | C7: 5.34 | D7: 24 | E7: 279 | F7: 1186.1 | G7: 0.14
A8: FY2019 | B8: 6.49 | C8: 5.52 | D8: 24 | E8: 406.4 | F8: 1200.1 | G8: 0.13
A9: FY2020 | B9: 5.96 | C9: 5.16 | D9: 24 | E9: 240.4 | F9: 1210.4 | G9: 0.13
A10: FY2021 | B10: 7.45 | C10: 6.19 | D10: 24 | E10: 235.1 | F10: 1220.8 | G10: 0.14
A11: FY2022 | B11: 6.63 | C11: 5.68 | D11: 24 | E11: 360.6 | F11: 1229.9 | G11: 0.16
A12: FY2023 | B12: 7.19 | C12: 6.09 | D12: 25 | E12: 310.2 | F12: 1240.3 | G12: 0.14
A13: FY2024 | B13: 7.88 | C13: 6.6 | D13: 26 | E13: 296.4 | F13: 1251.6 | G13: 0.15
A14: FY2025 | B14: 8.33 | C14: 6.97 | D14: 26.5 | E14: 285 | F14: 1254.1 | G14: 0.16
A15: FY2026 | B15: 7.93 | D15: 31.5 | E15: 293.5 | F15: 1253 | G15: 0.14
A17: Historical NTA Total-Return CAGRs
A18: 5yr (FY21-FY26) | B18: 0.0445
A19: 10yr (FY16-FY26) | B19: 0.0664
A20: Company-reported 10yr investment return | B20: 0.089
A21: Company-reported 10yr benchmark return | B21: 0.084
A22: Selected base-case total return assumption | B22: 0.075

Sheet Model_Info
A1: Model Provenance & Methodology Notes
A4: Ticker | B4: AFI.NZ (NZX) / AFI.AX (ASX) - Australian Foundation Investment Company Limited
A5: Built by | B5: Claude (dcf-analyst agent), adapted per user instruction for LIC/closed-end fund valuation
A6: Build date | B6: 2026-07-31
A7: Price data vintage | B7: NZX AFI.NZ live quote NZ$8.27, ASX AFI.AX live quote A$6.86, AUDNZD=X 1.19807 - all fetched from Yahoo Finance at build time (2026-07-31). RE-FETCH before relying on this model after any elapsed time; FX and prices move daily.
A8: Fundamental data vintage | B8: FY2026 headline results released 2026-07-27 (NPAT A$293.5m, pre-tax NTA/share A$7.93 at 30-Jun-2026, DPS 31.5c fully franked, portfolio return 0.9% vs ASX200 Accum 7.2%) per AFI.NZ_Analysis.json. Full FY2026 annual report text was not yet available in Extracted/ at build time (only H1-2026 to Dec-2025 was extracted, NTA $7.90). The FY2026 pre-tax NTA of $7.93 from the results announcement was used as the anchor in place of the H1 figure.
A9: Methodology | B9: NTA (net tangible assets) total-return compounding + exit discount/premium model - the standard approach for closed-end LICs/holdcos in this research folder (see also FIH.U Fairfax India, FRFHF Fairfax). NOT a standard FCF DCF: AFIC is an internally-managed investment company holding a ~A$9.8bn ASX-listed equity portfolio; "free cash flow" would just be dividend pass-through with no productive-asset reinvestment dynamic, and SBC/dilution mechanics do not apply.
A10: Value driver | B10: Pre-tax NTA per share TOTAL RETURN = NTA/share growth + dividends paid (since AFIC distributes nearly all income). Historical 5yr/10yr computed at 4.45%/6.64% (net of franking, per-share, non-grossed-up - appropriate for NZX holders who get no franking benefit). Cross-checked against AFIC-reported grossed-up 10yr investment return of 10.4% vs 9.5% benchmark (gross of expenses/tax, includes franking).
A11: Headline IV formula | B11: Intrinsic value = current pre-tax NTA/share x (1 + scenario fair P/NTA discount). This is the "simpler framing" specified in the build instructions: what today's known NTA is worth at a fair (rather than currently depressed) discount, converted to NZD at the live AUDNZD rate.
A12: 5yr IRR build (memo) | B12: Separate cross-check: PV of 5 years of projected dividends + PV of year-5 exit value (year-5 compounded NTA x scenario exit discount), both discounted at the 8.75% cost of equity. Shown on the NTA Model sheet rows 43-50 and used as the basis for the Sensitivity sheet matrix.
A13: Exit discount assumptions | B13: Bear -13% (current wide discount persists), Base -6% (AFIC long-run average, supported by A$243m FY2026 buyback), Bull 0% / par (buybacks + new CEO Alison Gibson restore demand). Historical range is roughly -13% to +15%.
A14: Cost of equity / "WACC" | B14: 8.75% (midpoint of 8.5-9%) - large-cap, ultra-liquid, ungeared (net cash), diversified blue-chip portfolio; explicitly NOT a small-cap risk premium.
A15: Entry price | B15: 15% IRR hurdle applied to base-case dividends + year-5 exit value. Produces A$5.53/NZ$6.63 (~-30% implied P/NTA), deliberately far below AFIC's historical discount range and current price - this is the expected, correct output given AFIC's ~7.5% total-return profile cannot organically clear a 15% hurdle except at an implausibly deep discount. See entry_price.memo in the JSON.
... A20: Staleness warning | B20: All prices, FX rates and the NTA figure are point-in-time. AFIC publishes NTA weekly - this model will go stale quickly relative to most DCF models. Always re-check the current NTA and price/NTA discount before using this model to make a decision.
