Workbook
Name pubhtml: 'MKT CAP - Price'!$A$1

Sheet Template
S1: input cells
B2: Name | C2: LINK TO RESEARCH | S2: result cells
B3: STOCK PRICE | C3: ='COMPARATIVE TABLE'!C39 -> 226.79 | F3: DIVIDEND PAYOUT RATIO | I3: 0
B4: COMPARATIVE TABLE'!A1 | N4: Terminal Value | O4: Growth rate
B5: Scenario 1 | C5: Earnings per share | D5: 2025 | E5: =D5+1 -> 2026 | F5: =E5+1 -> 2027 | G5: =F5+1 -> 2028 | H5: =G5+1 -> 2029 | I5: =H5+1 -> 2030 | J5: =I5+1 -> 2031 | K5: =J5+1 -> 2032 | L5: =K5+1 -> 2033 | M5: =L5+1 -> 2034 | N5: 2034 | O5: 0 | P5: next 5 years
B6: normal case | C6: 0 | D6: =C6*(1+$O$5) -> 0 | E6: =D6*(1+$O$5) -> 0 | F6: =E6*(1+$O$5) -> 0 | G6: =F6*(1+$O$5) -> 0 | H6: =G6*(1+$O$5) -> 0 | I6: =H6*(1+$O$6) -> 0 | J6: =I6*(1+$O$6) -> 0 | K6: =J6*(1+$O$6) -> 0 | L6: =K6*(1+$O$6) -> 0 | M6: =L6*(1+$O$6) -> 0 | N6: =L6*O8 -> 0 | O6: 0 | P6: 5 to 10 years
C7: =CONCATENATE(R8,O7*100,S8) -> PV(10%) | D7: =D6*(1+$O$7)^($D$5-D5-1)*$I$3 -> 0 | E7: =E6*(1+$O$7)^($D$5-E5-1)*$I$3 -> 0 | F7: =F6*(1+$O$7)^($D$5-F5-1)*$I$3 -> 0 | G7: =G6*(1+$O$7)^($D$5-G5-1)*$I$3 -> 0 | H7: =H6*(1+$O$7)^($D$5-H5-1)*$I$3 -> 0 | I7: =I6*(1+$O$7)^($D$5-I5-1)*$I$3 -> 0 | J7: =J6*(1+$O$7)^($D$5-J5-1)*$I$3 -> 0 | K7: =K6*(1+$O$7)^($D$5-K5-1)*$I$3 -> 0 | ... M7: =M6*(1+$O$7)^($D$5-M5-1)*$I$3 -> 0 | N7: =N6*(1+$O$7)^($D$5-N5-1) -> 0 | O7: 0.1 | P7: Discount rate
C8: INTRINSIC VALUE | D8: =SUM(D7:N7) -> 0 | O8: 15 | P8: Terminal multiple | R8: PV( | S8: %)
N10: Terminal Value | O10: Growth rate
B11: Scenario 2 | C11: =C5 -> Earnings per share | D11: =D5 -> 2025 | E11: =D11+1 -> 2026 | F11: =E11+1 -> 2027 | G11: =F11+1 -> 2028 | H11: =G11+1 -> 2029 | I11: =H11+1 -> 2030 | J11: =I11+1 -> 2031 | K11: =J11+1 -> 2032 | L11: =K11+1 -> 2033 | M11: =L11+1 -> 2034 | N11: =N5 -> 2034 | O11: 0 | P11: next 5 years
B12: best case | C12: =C6 -> 0 | D12: =C12*(1+$O$11) -> 0 | E12: =D12*(1+$O$11) -> 0 | F12: =E12*(1+$O$11) -> 0 | G12: =F12*(1+$O$11) -> 0 | H12: =G12*(1+$O$11) -> 0 | I12: =H12*(1+$O$12) -> 0 | J12: =I12*(1+$O$12) -> 0 | K12: =J12*(1+$O$12) -> 0 | L12: =K12*(1+$O$12) -> 0 | M12: =L12*(1+$O$12) -> 0 | N12: =L12*O14 -> 0 | O12: 0 | P12: 5 to 10 years
B13: =B7 -> 0 | C13: =C7 -> PV(10%) | D13: =D12*(1+$O$13)^($D$11-D11-1)*$I$3 -> 0 | E13: =E12*(1+$O$13)^($D$11-E11-1)*$I$3 -> 0 | F13: =F12*(1+$O$13)^($D$11-F11-1)*$I$3 -> 0 | G13: =G12*(1+$O$13)^($D$11-G11-1)*$I$3 -> 0 | H13: =H12*(1+$O$13)^($D$11-H11-1)*$I$3 -> 0 | I13: =I12*(1+$O$13)^($D$11-I11-1)*$I$3 -> 0 | J13: =J12*(1+$O$13)^($D$11-J11-1)*$I$3 -> 0 | K13: =K12*(1+$O$13)^($D$11-K11-1)*$I$3 -> 0 | ... M13: =M12*(1+$O$13)^($D$11-M11-1)*$I$3 -> 0 | N13: =N12*(1+$O$7)^($D$5-N11-1) -> 0 | O13: =O7 -> 0.1 | P13: Discount rate
C14: Present value sum | D14: =SUM(D13:N13) -> 0 | O14: 20 | P14: Terminal multiple
N16: Terminal Value | O16: Growth rate
B17: Scenario 3 | C17: =C11 -> Earnings per share | D17: =D11 -> 2025 | E17: =D17+1 -> 2026 | F17: =E17+1 -> 2027 | G17: =F17+1 -> 2028 | H17: =G17+1 -> 2029 | I17: =H17+1 -> 2030 | J17: =I17+1 -> 2031 | K17: =J17+1 -> 2032 | L17: =K17+1 -> 2033 | M17: =L17+1 -> 2034 | N17: =N11 -> 2034 | O17: 0 | P17: next 5 years
B18: worst case | C18: =C12 -> 0 | D18: =C18*(1+$O$17) -> 0 | E18: =D18*(1+$O$17) -> 0 | F18: =E18*(1+$O$17) -> 0 | G18: =F18*(1+$O$17) -> 0 | H18: =G18*(1+$O$17) -> 0 | I18: =H18*(1+$O$18) -> 0 | J18: =I18*(1+$O$18) -> 0 | K18: =J18*(1+$O$18) -> 0 | L18: =K18*(1+$O$18) -> 0 | M18: =L18*(1+$O$18) -> 0 | N18: =L18*O20 -> 0 | O18: 0 | P18: 5 to 10 years
B19: MARGIN OF | C19: =C13 -> PV(10%) | D19: =D18*(1+$O$19)^($D$17-D17-1)*$I$3 -> 0 | E19: =E18*(1+$O$19)^($D$17-E17-1)*$I$3 -> 0 | F19: =F18*(1+$O$19)^($D$17-F17-1)*$I$3 -> 0 | G19: =G18*(1+$O$19)^($D$17-G17-1)*$I$3 -> 0 | H19: =H18*(1+$O$19)^($D$17-H17-1)*$I$3 -> 0 | I19: =I18*(1+$O$19)^($D$17-I17-1)*$I$3 -> 0 | J19: =J18*(1+$O$19)^($D$17-J17-1)*$I$3 -> 0 | K19: =K18*(1+$O$19)^($D$17-K17-1)*$I$3 -> 0 | ... M19: =M18*(1+$O$19)^($D$17-M17-1)*$I$3 -> 0 | N19: =N18*(1+$O$19)^($D$17-N17-1) -> 0 | O19: =O13 -> 0.1 | P19: Discount rate
B20: SAFETY | C20: Present value sum | D20: =SUM(D19:N19) -> 0 | O20: 10 | P20: Terminal multiple
C22: Scenario | D22: Probability | E22: PV | F22: Part
C23: Scenario 1 (normal case) | D23: 0.34 | E23: =D8 -> 0 | F23: =E23*D23 -> 0
C24: Scenario 2 (best case) | D24: 0.33 | E24: =D14 -> 0 | F24: =E24*D24 -> 0
C25: Scenario 3 (worst case) | D25: 0.33 | E25: =D20 -> 0 | F25: =E25*D25 -> 0
C26: STOCK PRICE NOW | D26: =C3 -> 226.79 | E26: Sum | F26: =SUM(F23:F25) -> 0
B28: Disclaimer: This is just for educational purposes and not for investing advice!
B30: MADE BY | C30: STOCK MARKET RESEARCH PLATFORM

Sheet COMPARATIVE TABLE
A1: STOCK | B1: TICKER | C1: Stock Price/MKT Cap | D1: 10% RETURN | E1: Ratio | F1: LINK to RESEARCH | G1: INTRINSIC | H1: UPDATED | I1: TYPE | J1: Comment | K1: MAIN RISK & MARGIN OF SAFETY (MOS) REQUIREMENT FOR RISKS (MOS IS ALWAYS LOW PRICE - if BUY, ok) | L1: Strategy | M1: WOULD I BUY THIS AT A CERTAIN PRICE (what to think about deeper in such a case)
A2: THIS IS JUST AN OVERVIEW, NOT INVESTMENT ADVICE! THIS IS JUST FOR EDUCATIONAL PURPOSES TO SHOW WHAT IS PRICED IN BY THE MARKET AND WHAT GROWTH OR DIVIDENDS SHOULD BE REACHED FOR A IMMAGINARY RETURN - IN THIS CASE 10%
A3: AHOLD | B3: AMS:AD | C3: ='MKT CAP - Price'!D4 -> 34.42 | D3: =Ahold!F26 -> 23.937824 | E3: =D3/C3 -> 0.69546262 | F3: https://sven-carlin-research-platform.teachable.com/courses/335443/lectures/45225403 | G3: Ahold!A1 | H3: 45839 | I3: Slow growth | J3: A good US/Dutch retailer but pricy | K3: Retail, recessions in US and Europe
A4: Alibaba | B4: BABA | C4: ='MKT CAP - Price'!C98 -> 143.93 | D4: =BABA!F26 -> 95.030015 | E4: =D4/C4 -> 0.66025162 | F4: https://sven-carlin-research-platform.teachable.com/courses/335443/lectures/43880623 | G4: BABA!A1 | H4: 45901 | I4: Growth | J4: China e-commerce/fintech/cloud with global scaling ambitions | K4: China
A5: ACOMO | B5: ACOMO | C5: ='MKT CAP - Price'!C99 -> 22.9 | D5: =ACOMO!F26 -> 22.436316 | E5: =D5/C5 -> 0.97975179 | F5: https://sven-carlin-research-platform.teachable.com/courses/335443/lectures/44136947 | G5: ACOMO!A1 | H5: 45901 | I5: Food | J5: European spice trader | K5: Dutch stock market
A6: Archer Daniels | B6: ADM | C6: ='MKT CAP - Price'!E91 -> 61.41 | D6: =ADM!F26 -> 38.188779 | E6: =D6/C6 -> 0.6218658 | F6: https://sven-carlin-research-platform.teachable.com/courses/335443/lectures/59274915 | G6: ADM!A1 | H6: 45901 | I6: Food | J6: Cyclical, global food processing company
A7: AKER BP | C7: ='MKT CAP - Price'!C127 -> 25.11 | D7: =AKER!F26 -> 27.784211 | E7: =D7/C7 -> 1.1064998 | G7: AKER!A1 | H7: 45901 | I7: Oil | J7: Low cost producer
A8: ABF | B8: LSE: ABF | C8: ='MKT CAP - Price'!C100 -> 1997 | D8: =ABF!F26 -> 1275.3724 | E8: =D8/C8 -> 0.63864414 | F8: https://sven-carlin-research-platform.teachable.com/courses/335443/lectures/47872443 | G8: ABF!A1 | H8: 45901 | I8: food-other | J8: Food and Primark
A9: Berkshire | B9: BRK | C9: ='MKT CAP - Price'!J6 -> 1061.6746 | D9: =BRK.B!F26 -> 460.39879 | E9: =D9/C9 -> 0.43365341 | F9: https://sven-carlin-research-platform.teachable.com/courses/335443/lectures/44788692 | G9: BRK.B!A1 | H9: 45901 | I9: Buffett | J9: The fortress…
A10: Brasilagro | B10: LND | C10: ='MKT CAP - Price'!C101 -> 3.88 | D10: =LND!F26 -> 3.3544476 | E10: =D10/C10 -> 0.86454836 | F10: https://sven-carlin-research-platform.teachable.com/courses/335443/lectures/58576359 | G10: LND!A1 | H10: 45901 | I10: Land | J10: Land ownership in Brazil
A11: Cembre | B11: BIT:CMB | C11: ='MKT CAP - Price'!C102 -> 60.2 | D11: =CEMBRE!F26 -> 31.276446 | E11: =D11/C11 -> 0.51954229 | F11: https://sven-carlin-research-platform.teachable.com/courses/335443/lectures/45991763 | G11: CEMBRE!A1 | H11: 45901 | I11: Ita industrial | J11: Italy industrial
A12: China Mobile | B12: 941 | C12: ='MKT CAP - Price'!C103 -> 87.5 | D12: =CHM!F26 -> 88.630037 | E12: =D12/C12 -> 1.0129147 | F12: https://sven-carlin-research-platform.teachable.com/courses/335443/lectures/45806485 | G12: CHM!A1 | H12: 45901 | I12: telco | J12: China government owned telco, US SANCTIONED
A13: CK Hutchison | B13: 0001 | C13: ='MKT CAP - Price'!C104 -> 52.1 | D13: =CK!F26 -> 41.476928 | E13: =D13/C13 -> 0.79610226 | F13: https://sven-carlin-research-platform.teachable.com/courses/335443/lectures/51704170 | G13: CK!A1 | H13: 45901 | I13: mix | J13: Global conglomerate listed in HK
A14: Clarksons | B14: LON:CKN | C14: ='MKT CAP - Price'!C105 -> 3455 | D14: =Clarks!F26 -> 2297.8594 | E14: =D14/C14 -> 0.66508231 | F14: https://sven-carlin-research-platform.teachable.com/courses/335443/lectures/49464822 | G14: Clarks!A1 | H14: 45901 | I14: Shipping | J14: shipping broker, no ships
A15: First Pacific | B15: 142 | C15: ='MKT CAP - Price'!C106 -> 6.67 | D15: =FP!F26 -> 4.2143239 | E15: =D15/C15 -> 0.63183268 | F15: https://sven-carlin-research-platform.teachable.com/courses/335443/lectures/54079430 | G15: FP!A1 | H15: 45901 | I15: Phillipines | J15: Conglomerate
A16: Flow Traders | B16: AMS:FLOW | C16: ='MKT CAP - Price'!C107 -> 24.92 | D16: =FLOW!F26 -> 39.828939 | E16: =D16/C16 -> 1.598272 | F16: https://sven-carlin-research-platform.teachable.com/courses/335443/lectures/45447020 | G16: FLOW!A1 | H16: 45901 | I16: Operator | J16: Flow operators, liquidity provider and trading
A17: Glencore | B17: LON:GLEN | C17: ='MKT CAP - Price'!C124/1000000000 -> 35.194536 | D17: =GLEN!D8 -> 39.462855 | E17: =D17/C17 -> 1.1212779 | F17: https://sven-carlin-research-platform.teachable.com/courses/335443/lectures/60682625 | G17: GLEN!A1 | H17: 45901 | I17: Cyclical | J17: Cyclical commodities
A18: ICL Group | B18: ICL | C18: ='MKT CAP - Price'!C108 -> 6.25 | D18: =ICL!F26 -> 4.505649 | E18: =D18/C18 -> 0.72090383 | F18: https://sven-carlin-research-platform.teachable.com/courses/335443/lectures/57859152 | G18: ICL!A1 | H18: 45901 | I18: fertilizer | J18: Fertilizer
A19: Lanxess | C19: ='MKT CAP - Price'!C128 -> 23 | D19: =LXS!F26 -> 27.412555 | E19: =D19/C19 -> 1.1918502 | G19: LXS!A1 | H19: 45901 | I19: Chemical | J19: Cycle
A20: Liberty Global | B20: LBTYK | C20: ='MKT CAP - Price'!C109 -> 11.71 | D20: =LBTYK!F26 -> 12.740721 | E20: =D20/C20 -> 1.0880206 | F20: https://sven-carlin-research-platform.teachable.com/courses/335443/lectures/45722067 | G20: LBTYK!A1 | H20: 45901 | I20: EU/UK Telco | J20: Telco UK, Netherlands, Belgium
A21: Lundin | B21: LUNMF | C21: ='MKT CAP - Price'!C110 -> 11.76 | D21: =LUNDIN!F26 -> 5.8796968 | E21: =D21/C21 -> 0.49997422 | F21: https://sven-carlin-research-platform.teachable.com/courses/335443/lectures/52353280 | G21: LUNDIN!A1 | H21: 45901 | I21: copper | J21: Copper miner
A22: Maersk | B22: AMKBY | C22: ='MKT CAP - Price'!C111 -> 10.26 | D22: =Maersk!F26 -> 7.6169348 | E22: =D22/C22 -> 0.74239131 | F22: https://sven-carlin-research-platform.teachable.com/courses/335443/lectures/50403317 | G22: Maersk!A1 | H22: 45901 | I22: shipping | J22: Global shipping
A23: Nine Dragons | B23: 2689 | C23: ='MKT CAP - Price'!C112 -> 5.95 | D23: ='Nine D'!F26 -> 6.4341068 | E23: =D23/C23 -> 1.0813625 | F23: https://sven-carlin-research-platform.teachable.com/courses/335443/lectures/17571825 | G23: Nine D'!A1 | H23: 45901 | I23: Paper China | J23: Largest paper in China
A24: Nutrien | B24: NTR | C24: ='MKT CAP - Price'!C113 -> 57.41 | D24: =NTR!F26 -> 42.801656 | E24: =D24/C24 -> 0.74554356 | F24: https://sven-carlin-research-platform.teachable.com/courses/335443/lectures/54527058 | G24: NTR!A1 | H24: 45901 | I24: fertilizer | J24: Fertilizer
A25: Mosaic | B25: MOS | C25: ='MKT CAP - Price'!C114 -> 33.41 | D25: =MOS!F26 -> 18.826609 | E25: =D25/C25 -> 0.56350222 | F25: https://sven-carlin-research-platform.teachable.com/courses/335443/lectures/54527058 | G25: MOS!A1 | H25: 45901 | I25: fertilizer | J25: Fertilizer
A26: RHI Magnesita | B26: LON:RHIM | C26: ='MKT CAP - Price'!C115 -> 2085 | D26: =RHIM!F26 -> 2594.4344 | E26: =D26/C26 -> 1.2443331 | F26: https://sven-carlin-research-platform.teachable.com/courses/335443/lectures/49610686 | G26: RHIM!A1 | H26: 45901 | I26: refraction | J26: Global refraction
A27: Rubis | B27: EPA: RUI | C27: ='MKT CAP - Price'!C116 -> 28.16 | D27: =RUI!F26 -> 26.367784 | E27: =D27/C27 -> 0.93635596 | F27: https://sven-carlin-research-platform.teachable.com/courses/335443/lectures/54002769 | G27: RUI!A1 | H27: 45901 | I27: oil distribution | J27: Africa Carribean oil distribution, French solar
A28: Signify | B28: AMS: LIGHT | C28: ='MKT CAP - Price'!M5 -> 23.06 | D28: =LIGHT!F26 -> 25.404899 | E28: =D28/C28 -> 1.1016869 | F28: https://sven-carlin-research-platform.teachable.com/courses/335443/lectures/59805978 | G28: LIGHT!A1 | H28: 45901 | I28: Lighting | J28: cyclical downturn, but can get worse
A29: SiriusXM | B29: SIRI | C29: ='MKT CAP - Price'!C117 -> 23.81 | D29: =SIRI!F26 -> 27.632941 | E29: =D29/C29 -> 1.1605603 | F29: https://sven-carlin-research-platform.teachable.com/courses/335443/lectures/53497824 | G29: SIRI!A1 | H29: 45901 | I29: Radio | J29: US radio
A30: Sunrise | B30: SNRE | C30: ='MKT CAP - Price'!C118 -> 48.98 | D30: =SNRE!F26 -> 47.797386 | E30: =D30/C30 -> 0.97585516 | F30: https://sven-carlin-research-platform.teachable.com/courses/335443/lectures/57072847 | G30: SNRE!A1 | H30: 45901 | I30: CHF telco | J30: Swiss telco, recent spin from Liberty
A31: TITLIS | B31: TIBN | C31: ='MKT CAP - Price'!M6 -> 43.1 | D31: =TIBN!F26 -> 57.831493 | E31: =D31/C31 -> 1.341798 | F31: https://sven-carlin-research-platform.teachable.com/courses/335443/lectures/45664225 | G31: TIBN!A1 | H31: 45901 | I31: Asset | J31: Swiss Asset with growth
A32: Wilmar | B32: F34 | C32: 2.95 | D32: =Wilmar!F26 -> 2.8504033 | E32: =D32/C32 -> 0.96623839 | F32: https://sven-carlin-research-platform.teachable.com/courses/335443/lectures/45064788 | G32: Wilmar!A1 | H32: 45901 | I32: FoodAsia | J32: Asia food owned 22.5% by ADM
E33: =D33/C33 -> #DIV/0!
E34: =D34/C34 -> #DIV/0!
E35: =D35/C35 -> #DIV/0!
A38: some from the YouTube analyses I made, just for reference
A39: Apple | B39: AAPL | C39: ='MKT CAP - Price'!C45 -> 226.79 | D39: =APPLE!F26 -> 85.489249 | E39: =D39/C39 -> 0.37695335 | G39: APPLE!A1 | H39: 45658 | I39: Stalwarth | J39: Good growth stock with a strong position. | K39: As always: competition, slower than expected growth and valuation contraction based on higher interest rates - iphone cycle
A40: S&P 500 | B40: SPY | C40: ='MKT CAP - Price'!C13 -> 6522.1 | D40: ='S&P 500'!F26 -> 3351.9049 | E40: =D40/C40 -> 0.51393031 | G40: S&P 500'!A1 | H40: 45658 | I40: INDEX | J40: US index fund - good businesses but risky valuations | K40: US economy, interest rates, valuation, tech profitability etc. taxes
A41: Van Eck Gold Miners | B41: GDX | C41: ='MKT CAP - Price'!C92 -> 68.5 | D41: =GDX!F26 -> 15.79298 | E41: =D41/C41 -> 0.23055445 | F41: Gold miner vid | G41: GDX!A1 | H41: 45658 | I41: GOLD
A42: Amazon | B42: AMZN | C42: =AMZN!C3 -> 2456.4487 | D42: =AMZN!F26 -> 1261.2997 | E42: =D42/C42 -> 0.51346471 | F42: Amazon | G42: AMZN!A1 | H42: 45658 | I42: Growth
...

Sheet MKT CAP - Price
A1: INTRINSIC MARKET CAPS : Sheet1
B3: KROGER | C3: 44317272466 | E3: ASML | F3: 678.1 | G3: 1.1689344 | L3: Kraft Heinz | M3: 26.65
B4: AHOLD | C4: 31247565451 | D4: 34.42 | E4: Siemens | F4: 228.8 | L4: Jdepeets | M4: 31.26
B5: MELCO RESORTS | C5: 3798660904 | E5: ADYEN | F5: 1355.4 | L5: Signify | M5: 23.06
B6: BRK | C6: 490.08 | E6: Deutsche Borse | F6: 242.6 | H6: brk market cap | I6: 1061674568342 | J6: 1061.6746 | L6: Titlis | M6: 43.1
B7: Fresenius | C7: 26663649133 | E7: Aedifica | F7: 62.15 | L7: CNH Industria | M7: 11.24
B8: FRE MED | C8: 12490612605 | E8: Akzo Nobel | F8: 60.48
B9: Google | C9: 239.56 | E9: Alfen | F9: 9.27 | H9: Google mkcap | I9: 2894200931242
B10: MSFT | C10: 3719333735495 | E10: Facebook | F10: 41.1
B11: APPLE | C11: 3365651948463 | E11: APAM | F11: 26.98
B12: NIO | C12: 96323410562 | E12: BYND | F12: 190848839
B13: S&P 500 | C13: 6522.1 | E13: ArcelorMittal | F13: 25235175553 | G13: 25.235176
B14: Tencent | C14: 5774355028500 | E14: 629.5 | F14: 17.96 | I14: 7.7867672 | J14: 741559995623
B15: TSM | C15: 260.44 | E15: B&S | F15: 496646196
B16: Kroger | C16: 44317272466 | E16: CCEP | F16: 40507719806 | G16: 40.50772
B17: SFM | C17: 13105556048 | E17: CRBN | F17: 998409763
B18: Norsk Hydro | C18: 13096476776 | E18: CTP | F18: 8627117400 | G18: 9.9349262 | H18: 130112530642
B19: BABA | C19: 143.93 | E19: KMI | F19: 27.38
B20: Tesla | C20: 1089789558075 | E20: DSM | F20: #N/A
B21: Amazon | C21: 2456448739828 | E21: Berry | F21: #N/A | G21: AMZN | H21: 347.79 | L21: da
B22: AT&T | C22: 208791218255 | E22: Bjs wholesale | F22: 97.44
B23: Ahold | C23: 31247565451 | F23: 63.2
B24: Wiener | C24: 28.6 | F24: 793.14
B25: WBA | C25: 10369413195 | F25: 793.14
B26: Nestle | C26: 189631868068 | F26: 793.14 | G26: NESN | H26: 73.6
B27: STOR CAPITAL | C27: #N/A | F27: 793.14
B28: Douglas Emmet | C28: 2747793757 | F28: 793.14
B29: Smart Centres | C29: #N/A | F29: 793.14
B30: Abbvie | C30: 211.64 | F30: 793.14
B31: BMY | C31: 47.15 | E31: ASML | F31: 793.14
B32: Merck | C32: 84.03 | E32: ASML | F32: 793.14
B33: VZ | C33: 43.49 | E33: ASML | F33: 793.14
B34: Nutrien | C34: 38710385357 | E34: ASML | F34: 793.14
B35: Chebron | C35: 323058127724 | E35: ASML | F35: 793.14
B36: Lukoil | C36: #N/A | D36: #N/A | E36: ASML | F36: 793.14
B37: Barrick Gold | C37: 356401384 | E37: ASML | F37: 793.14
B38: AngloGold | C38: 469490393524 | E38: ASML | F38: 793.14
B39: CYCP | C39: data not available to google finance | E39: ASML | F39: 793.14 | G39: 85.292648
B40: USDCNY | C40: 7.1212492 | E40: ASML | F40: 793.14
B41: baidu | C41: 291340894228 | E41: ASML | F41: 793.14
...

Sheet LXS
S1: input cells
B2: Name | C2: LINK TO RESEARCH | S2: result cells
B3: STOCK PRICE | C3: ='COMPARATIVE TABLE'!C39 -> 226.79 | F3: DIVIDEND PAYOUT RATIO | I3: 0.6
B4: COMPARATIVE TABLE'!A1 | N4: Terminal Value | O4: Growth rate
B5: Scenario 1 | C5: FCF | D5: 2025 | E5: =D5+1 -> 2026 | F5: =E5+1 -> 2027 | G5: =F5+1 -> 2028 | H5: =G5+1 -> 2029 | I5: =H5+1 -> 2030 | J5: =I5+1 -> 2031 | K5: =J5+1 -> 2032 | L5: =K5+1 -> 2033 | M5: =L5+1 -> 2034 | N5: 2034 | O5: 0.04 | P5: next 5 years
B6: normal case | C6: 2.5 | D6: =C6*(1+$O$5) -> 2.6 | E6: =D6*(1+$O$5) -> 2.704 | F6: =E6*(1+$O$5) -> 2.81216 | G6: =F6*(1+$O$5) -> 2.9246464 | H6: =G6*(1+$O$5) -> 3.0416323 | I6: =H6*(1+$O$6) -> 3.1328812 | J6: =I6*(1+$O$6) -> 3.2268677 | K6: =J6*(1+$O$6) -> 3.3236737 | L6: =K6*(1+$O$6) -> 3.4233839 | M6: =L6*(1+$O$6) -> 3.5260854 | N6: =L6*O8 -> 68.467678 | O6: 0.03 | P6: 5 to 10 years
C7: =CONCATENATE(R8,O7*100,S8) -> PV(10%) | F7: =F6*(1+$O$7)^($D$5-F5-1)*$I$3 -> 1.2676905 | G7: =G6*(1+$O$7)^($D$5-G5-1)*$I$3 -> 1.1985437 | H7: =H6*(1+$O$7)^($D$5-H5-1)*$I$3 -> 1.1331686 | I7: =I6*(1+$O$7)^($D$5-I5-1)*$I$3 -> 1.0610579 | J7: =J6*(1+$O$7)^($D$5-J5-1)*$I$3 -> 0.993536 | K7: =K6*(1+$O$7)^($D$5-K5-1)*$I$3 -> 0.93031098 | L7: =L6*(1+$O$7)^($D$5-L5-1)*$I$3 -> 0.87110938 | M7: =M6*(1+$O$7)^($D$5-M5-1)*$I$3 -> 0.81567514 | N7: =N6*(1+$O$7)^($D$5-N5-1) -> 26.397254 | O7: 0.1 | P7: Discount rate
C8: INTRINSIC VALUE | D8: =SUM(D7:N7) -> 34.668346 | O8: 20 | P8: Terminal multiple | R8: PV( | S8: %)
N10: Terminal Value | O10: Growth rate
B11: Scenario 2 | C11: =C5 -> FCF | D11: =D5 -> 2025 | E11: =D11+1 -> 2026 | F11: =E11+1 -> 2027 | G11: =F11+1 -> 2028 | H11: =G11+1 -> 2029 | I11: =H11+1 -> 2030 | J11: =I11+1 -> 2031 | K11: =J11+1 -> 2032 | L11: =K11+1 -> 2033 | M11: =L11+1 -> 2034 | N11: =N5 -> 2034 | O11: 0 | P11: next 5 years
B12: best case | C12: =C6 -> 2.5 | D12: =C12*(1+$O$11) -> 2.5 | E12: =D12*(1+$O$11) -> 2.5 | F12: =E12*(1+$O$11) -> 2.5 | G12: =F12*(1+$O$11) -> 2.5 | H12: =G12*(1+$O$11) -> 2.5 | I12: =H12*(1+$O$12) -> 2.5 | J12: =I12*(1+$O$12) -> 2.5 | K12: =J12*(1+$O$12) -> 2.5 | L12: =K12*(1+$O$12) -> 2.5 | M12: =L12*(1+$O$12) -> 2.5 | N12: =L12*O14 -> 50 | O12: 0 | P12: 5 to 10 years
B13: =B7 -> 0 | C13: =C7 -> PV(10%) | D13: =D12*(1+$O$13)^($D$11-D11-1)*$I$3 -> 1.3636364 | E13: =E12*(1+$O$13)^($D$11-E11-1)*$I$3 -> 1.2396694 | F13: =F12*(1+$O$13)^($D$11-F11-1)*$I$3 -> 1.1269722 | G13: =G12*(1+$O$13)^($D$11-G11-1)*$I$3 -> 1.0245202 | H13: =H12*(1+$O$13)^($D$11-H11-1)*$I$3 -> 0.93138198 | I13: =I12*(1+$O$13)^($D$11-I11-1)*$I$3 -> 0.8467109 | J13: =J12*(1+$O$13)^($D$11-J11-1)*$I$3 -> 0.76973718 | K13: =K12*(1+$O$13)^($D$11-K11-1)*$I$3 -> 0.69976107 | ... M13: =M12*(1+$O$13)^($D$11-M11-1)*$I$3 -> 0.57831493 | N13: =N12*(1+$O$7)^($D$5-N11-1) -> 19.277164 | O13: =O7 -> 0.1 | P13: Discount rate
C14: Present value sum | D14: =SUM(D13:N13) -> 28.494015 | O14: 20 | P14: Terminal multiple
N16: Terminal Value | O16: Growth rate
B17: Scenario 3 | C17: =C11 -> FCF | D17: =D11 -> 2025 | E17: =D17+1 -> 2026 | F17: =E17+1 -> 2027 | G17: =F17+1 -> 2028 | H17: =G17+1 -> 2029 | I17: =H17+1 -> 2030 | J17: =I17+1 -> 2031 | K17: =J17+1 -> 2032 | L17: =K17+1 -> 2033 | M17: =L17+1 -> 2034 | N17: =N11 -> 2034 | O17: 0 | P17: next 5 years
B18: worst case | C18: =C12 -> 2.5 | D18: =C18*(1+$O$17) -> 2.5 | E18: =D18*(1+$O$17) -> 2.5 | F18: =E18*(1+$O$17) -> 2.5 | G18: =F18*(1+$O$17) -> 2.5 | H18: =G18*(1+$O$17) -> 2.5 | I18: =H18*(1+$O$18) -> 2.5 | J18: =I18*(1+$O$18) -> 2.5 | K18: =J18*(1+$O$18) -> 2.5 | L18: =K18*(1+$O$18) -> 2.5 | M18: =L18*(1+$O$18) -> 2.5 | N18: =L18*O20 -> 25 | O18: 0 | P18: 5 to 10 years
B19: MARGIN OF | C19: =C13 -> PV(10%) | D19: =D18*(1+$O$19)^($D$17-D17-1)*$I$3 -> 1.3636364 | E19: =E18*(1+$O$19)^($D$17-E17-1)*$I$3 -> 1.2396694 | F19: =F18*(1+$O$19)^($D$17-F17-1)*$I$3 -> 1.1269722 | G19: =G18*(1+$O$19)^($D$17-G17-1)*$I$3 -> 1.0245202 | H19: =H18*(1+$O$19)^($D$17-H17-1)*$I$3 -> 0.93138198 | I19: =I18*(1+$O$19)^($D$17-I17-1)*$I$3 -> 0.8467109 | J19: =J18*(1+$O$19)^($D$17-J17-1)*$I$3 -> 0.76973718 | K19: =K18*(1+$O$19)^($D$17-K17-1)*$I$3 -> 0.69976107 | ... M19: =M18*(1+$O$19)^($D$17-M17-1)*$I$3 -> 0.57831493 | N19: =N18*(1+$O$19)^($D$17-N17-1) -> 9.6385822 | O19: =O13 -> 0.1 | P19: Discount rate
B20: SAFETY | C20: Present value sum | D20: =SUM(D19:N19) -> 18.855433 | O20: 10 | P20: Terminal multiple
C22: Scenario | D22: Probability | E22: PV | F22: Part
C23: Scenario 1 (normal case) | D23: 0.34 | E23: =D8 -> 34.668346 | F23: =E23*D23 -> 11.787238
C24: Scenario 2 (best case) | D24: 0.33 | E24: =D14 -> 28.494015 | F24: =E24*D24 -> 9.403025
C25: Scenario 3 (worst case) | D25: 0.33 | E25: =D20 -> 18.855433 | F25: =E25*D25 -> 6.2222929
C26: STOCK PRICE NOW | D26: =C3 -> 226.79 | E26: Sum | F26: =SUM(F23:F25) -> 27.412555
B28: Disclaimer: This is just for educational purposes and not for investing advice!
B30: MADE BY | C30: STOCK MARKET RESEARCH PLATFORM

Sheet AKER
S1: input cells
B2: AKER | C2: LINK TO RESEARCH | S2: result cells
B3: STOCK PRICE | F3: DIVIDEND PAYOUT RATIO | I3: 0.75 | J3: Norway tax
B4: COMPARATIVE TABLE'!A1 | N4: Terminal Value | O4: Growth rate
B5: Scenario 1 | C5: Dividend | D5: 2025 | E5: =D5+1 -> 2026 | F5: =E5+1 -> 2027 | G5: =F5+1 -> 2028 | H5: =G5+1 -> 2029 | I5: =H5+1 -> 2030 | J5: =I5+1 -> 2031 | K5: =J5+1 -> 2032 | L5: =K5+1 -> 2033 | M5: =L5+1 -> 2034 | N5: 2034 | O5: 0.05 | P5: next 5 years
B6: normal case | C6: 2.52 | D6: =C6*(1+$O$5) -> 2.646 | E6: =D6*(1+$O$5) -> 2.7783 | F6: =E6*(1+$O$5) -> 2.917215 | G6: =F6*(1+$O$5) -> 3.0630758 | H6: =G6*(1+$O$5) -> 3.2162295 | I6: =H6*(1+$O$6) -> 3.2162295 | J6: =I6*(1+$O$6) -> 3.2162295 | K6: =J6*(1+$O$6) -> 3.2162295 | L6: =K6*(1+$O$6) -> 3.2162295 | M6: =L6*(1+$O$6) -> 3.2162295 | N6: =L6*O8 -> 32.162295 | O6: 0 | P6: 5 to 10 years
C7: =CONCATENATE(R8,O7*100,S8) -> PV(10%) | D7: =D6*(1+$O$7)^($D$5-D5-1)*$I$3 -> 1.8040909 | E7: =E6*(1+$O$7)^($D$5-E5-1)*$I$3 -> 1.7220868 | F7: =F6*(1+$O$7)^($D$5-F5-1)*$I$3 -> 1.6438101 | G7: =G6*(1+$O$7)^($D$5-G5-1)*$I$3 -> 1.5690915 | H7: =H6*(1+$O$7)^($D$5-H5-1)*$I$3 -> 1.4977691 | I7: =I6*(1+$O$7)^($D$5-I5-1)*$I$3 -> 1.3616083 | J7: =J6*(1+$O$7)^($D$5-J5-1)*$I$3 -> 1.2378257 | K7: =K6*(1+$O$7)^($D$5-K5-1)*$I$3 -> 1.1252961 | ... M7: =M6*(1+$O$7)^($D$5-M5-1)*$I$3 -> 0.92999679 | N7: =N6*(1+$O$7)^($D$5-N5-1) -> 12.399957 | O7: 0.1 | P7: Discount rate
C8: INTRINSIC VALUE | D8: =SUM(D7:N7) -> 26.314529 | O8: 10 | P8: Terminal multiple | R8: PV( | S8: %)
N10: Terminal Value | O10: Growth rate
B11: Scenario 2 | C11: =C5 -> Dividend | D11: =D5 -> 2025 | E11: =D11+1 -> 2026 | F11: =E11+1 -> 2027 | G11: =F11+1 -> 2028 | H11: =G11+1 -> 2029 | I11: =H11+1 -> 2030 | J11: =I11+1 -> 2031 | K11: =J11+1 -> 2032 | L11: =K11+1 -> 2033 | M11: =L11+1 -> 2034 | N11: =N5 -> 2034 | O11: 0.07 | P11: next 5 years
B12: best case | C12: =C6 -> 2.52 | D12: =C12*(1+$O$11) -> 2.6964 | E12: =D12*(1+$O$11) -> 2.885148 | F12: =E12*(1+$O$11) -> 3.0871084 | G12: =F12*(1+$O$11) -> 3.3032059 | H12: =G12*(1+$O$11) -> 3.5344304 | I12: =H12*(1+$O$12) -> 3.7111519 | J12: =I12*(1+$O$12) -> 3.8967095 | K12: =J12*(1+$O$12) -> 4.0915449 | L12: =K12*(1+$O$12) -> 4.2961222 | M12: =L12*(1+$O$12) -> 4.5109283 | N12: =L12*O14 -> 51.553466 | O12: 0.05 | P12: 5 to 10 years
B13: =B7 -> 0 | C13: =C7 -> PV(10%) | D13: =D12*(1+$O$13)^($D$11-D11-1)*$I$3 -> 1.8384545 | E13: =E12*(1+$O$13)^($D$11-E11-1)*$I$3 -> 1.7883149 | F13: =F12*(1+$O$13)^($D$11-F11-1)*$I$3 -> 1.7395427 | G13: =G12*(1+$O$13)^($D$11-G11-1)*$I$3 -> 1.6921006 | H13: =H12*(1+$O$13)^($D$11-H11-1)*$I$3 -> 1.6459524 | I13: =I12*(1+$O$13)^($D$11-I11-1)*$I$3 -> 1.5711364 | J13: =J12*(1+$O$13)^($D$11-J11-1)*$I$3 -> 1.4997211 | K13: =K12*(1+$O$13)^($D$11-K11-1)*$I$3 -> 1.4315519 | ... M13: =M12*(1+$O$13)^($D$11-M11-1)*$I$3 -> 1.3043686 | N13: =N12*(1+$O$7)^($D$5-N11-1) -> 19.876093 | O13: =O7 -> 0.1 | P13: Discount rate
C14: Present value sum | D14: =SUM(D13:N13) -> 35.753717 | O14: 12 | P14: Terminal multiple
N16: Terminal Value | O16: Growth rate
B17: Scenario 3 | C17: =C11 -> Dividend | D17: =D11 -> 2025 | E17: =D17+1 -> 2026 | F17: =E17+1 -> 2027 | G17: =F17+1 -> 2028 | H17: =G17+1 -> 2029 | I17: =H17+1 -> 2030 | J17: =I17+1 -> 2031 | K17: =J17+1 -> 2032 | L17: =K17+1 -> 2033 | M17: =L17+1 -> 2034 | N17: =N11 -> 2034 | O17: 0 | P17: next 5 years
B18: worst case | C18: =C12 -> 2.52 | D18: =C18*(1+$O$17) -> 2.52 | E18: =D18*(1+$O$17) -> 2.52 | F18: =E18*(1+$O$17) -> 2.52 | G18: =F18*(1+$O$17) -> 2.52 | H18: =G18*(1+$O$17) -> 2.52 | I18: =H18*(1+$O$18) -> 2.52 | J18: =I18*(1+$O$18) -> 2.52 | K18: =J18*(1+$O$18) -> 2.52 | L18: =K18*(1+$O$18) -> 2.52 | M18: =L18*(1+$O$18) -> 2.52 | N18: =L18*O20 -> 25.2 | O18: 0 | P18: 5 to 10 years
B19: MARGIN OF | C19: =C13 -> PV(10%) | D19: =D18*(1+$O$19)^($D$17-D17-1)*$I$3 -> 1.7181818 | E19: =E18*(1+$O$19)^($D$17-E17-1)*$I$3 -> 1.5619835 | F19: =F18*(1+$O$19)^($D$17-F17-1)*$I$3 -> 1.419985 | G19: =G18*(1+$O$19)^($D$17-G17-1)*$I$3 -> 1.2908954 | H19: =H18*(1+$O$19)^($D$17-H17-1)*$I$3 -> 1.1735413 | I19: =I18*(1+$O$19)^($D$17-I17-1)*$I$3 -> 1.0668557 | J19: =J18*(1+$O$19)^($D$17-J17-1)*$I$3 -> 0.96986884 | K19: =K18*(1+$O$19)^($D$17-K17-1)*$I$3 -> 0.88169895 | ... M19: =M18*(1+$O$19)^($D$17-M17-1)*$I$3 -> 0.72867682 | N19: =N18*(1+$O$19)^($D$17-N17-1) -> 9.7156909 | O19: =O13 -> 0.1 | P19: Discount rate
B20: SAFETY | C20: Present value sum | D20: =SUM(D19:N19) -> 21.328923 | O20: 10 | P20: Terminal multiple
C22: Scenario | D22: Probability | E22: PV | F22: Part
C23: Scenario 1 (normal case) | D23: 0.34 | E23: =D8 -> 26.314529 | F23: =E23*D23 -> 8.9469398
C24: Scenario 2 (best case) | D24: 0.33 | E24: =D14 -> 35.753717 | F24: =E24*D24 -> 11.798727
C25: Scenario 3 (worst case) | D25: 0.33 | E25: =D20 -> 21.328923 | F25: =E25*D25 -> 7.0385445
C26: STOCK PRICE NOW | D26: =C3 -> 0 | E26: Sum | F26: =SUM(F23:F25) -> 27.784211
B28: Disclaimer: This is just for educational purposes and not for investing advice!
B30: MADE BY | C30: STOCK MARKET RESEARCH PLATFORM

Sheet Ahold
S1: input cells
B2: Ahold | C2: LINK TO RESEARCH | S2: result cells
B3: STOCK PRICE | C3: ='COMPARATIVE TABLE'!C3 -> 34.42 | F3: DIVIDEND PAYOUT RATIO | I3: 1
B4: COMPARATIVE TABLE'!A1 | N4: Terminal Value | O4: Growth rate
B5: Scenario 1 | C5: Dividend | D5: 2025 | E5: =D5+1 -> 2026 | F5: =E5+1 -> 2027 | G5: =F5+1 -> 2028 | H5: =G5+1 -> 2029 | I5: =H5+1 -> 2030 | J5: =I5+1 -> 2031 | K5: =J5+1 -> 2032 | L5: =K5+1 -> 2033 | M5: =L5+1 -> 2034 | N5: 2034 | O5: 0.05 | P5: next 5 years
B6: normal case | C6: 1.17 | D6: =C6*(1+$O$5) -> 1.2285 | E6: =D6*(1+$O$5) -> 1.289925 | F6: =E6*(1+$O$5) -> 1.3544213 | G6: =F6*(1+$O$5) -> 1.4221423 | H6: =G6*(1+$O$5) -> 1.4932494 | I6: =H6*(1+$O$6) -> 1.5679119 | J6: =I6*(1+$O$6) -> 1.6463075 | K6: =J6*(1+$O$6) -> 1.7286229 | L6: =K6*(1+$O$6) -> 1.815054 | M6: =L6*(1+$O$6) -> 1.9058067 | N6: =L6*O8 -> 36.30108 | O6: 0.05 | P6: 5 to 10 years
C7: =CONCATENATE(R8,O7*100,S8) -> PV(10%) | D7: =D6*(1+$O$7)^($D$5-D5-1)*$I$3 -> 1.1168182 | E7: =E6*(1+$O$7)^($D$5-E5-1)*$I$3 -> 1.0660537 | F7: =F6*(1+$O$7)^($D$5-F5-1)*$I$3 -> 1.0175967 | G7: =G6*(1+$O$7)^($D$5-G5-1)*$I$3 -> 0.97134233 | H7: =H6*(1+$O$7)^($D$5-H5-1)*$I$3 -> 0.92719041 | I7: =I6*(1+$O$7)^($D$5-I5-1)*$I$3 -> 0.88504539 | J7: =J6*(1+$O$7)^($D$5-J5-1)*$I$3 -> 0.84481606 | K7: =K6*(1+$O$7)^($D$5-K5-1)*$I$3 -> 0.80641533 | ... M7: =M6*(1+$O$7)^($D$5-M5-1)*$I$3 -> 0.73477099 | N7: =N6*(1+$O$7)^($D$5-N5-1) -> 13.995638 | O7: 0.1 | P7: Discount rate
C8: INTRINSIC VALUE | D8: =SUM(D7:N7) -> 23.135447 | O8: 20 | P8: Terminal multiple | R8: PV( | S8: %)
N10: Terminal Value | O10: Growth rate
B11: Scenario 2 | C11: =C5 -> Dividend | D11: =D5 -> 2025 | E11: =D11+1 -> 2026 | F11: =E11+1 -> 2027 | G11: =F11+1 -> 2028 | H11: =G11+1 -> 2029 | I11: =H11+1 -> 2030 | J11: =I11+1 -> 2031 | K11: =J11+1 -> 2032 | L11: =K11+1 -> 2033 | M11: =L11+1 -> 2034 | N11: =N5 -> 2034 | O11: 0.06 | P11: next 5 years
B12: best case | C12: =C6 -> 1.17 | D12: =C12*(1+$O$11) -> 1.2402 | E12: =D12*(1+$O$11) -> 1.314612 | F12: =E12*(1+$O$11) -> 1.3934887 | G12: =F12*(1+$O$11) -> 1.477098 | H12: =G12*(1+$O$11) -> 1.5657239 | I12: =H12*(1+$O$12) -> 1.6596674 | J12: =I12*(1+$O$12) -> 1.7592474 | K12: =J12*(1+$O$12) -> 1.8648022 | L12: =K12*(1+$O$12) -> 1.9766904 | M12: =L12*(1+$O$12) -> 2.0952918 | N12: =L12*O14 -> 65.230783 | O12: 0.06 | P12: 5 to 10 years
B13: =B7 -> 0 | C13: =C7 -> PV(10%) | D13: =D12*(1+$O$13)^($D$11-D11-1)*$I$3 -> 1.1274545 | E13: =E12*(1+$O$13)^($D$11-E11-1)*$I$3 -> 1.0864562 | F13: =F12*(1+$O$13)^($D$11-F11-1)*$I$3 -> 1.0469487 | G13: =G12*(1+$O$13)^($D$11-G11-1)*$I$3 -> 1.0088778 | H13: =H12*(1+$O$13)^($D$11-H11-1)*$I$3 -> 0.97219137 | I13: =I12*(1+$O$13)^($D$11-I11-1)*$I$3 -> 0.93683896 | J13: =J12*(1+$O$13)^($D$11-J11-1)*$I$3 -> 0.90277209 | K13: =K12*(1+$O$13)^($D$11-K11-1)*$I$3 -> 0.86994401 | ... M13: =M12*(1+$O$13)^($D$11-M11-1)*$I$3 -> 0.80782569 | N13: =N12*(1+$O$7)^($D$5-N11-1) -> 25.14929 | O13: =O7 -> 0.1 | P13: Discount rate
C14: Present value sum | D14: =SUM(D13:N13) -> 34.74691 | O14: 33 | P14: Terminal multiple
N16: Terminal Value | O16: Growth rate
B17: Scenario 3 | C17: =C11 -> Dividend | D17: =D11 -> 2025 | E17: =D17+1 -> 2026 | F17: =E17+1 -> 2027 | G17: =F17+1 -> 2028 | H17: =G17+1 -> 2029 | I17: =H17+1 -> 2030 | J17: =I17+1 -> 2031 | K17: =J17+1 -> 2032 | L17: =K17+1 -> 2033 | M17: =L17+1 -> 2034 | N17: =N11 -> 2034 | O17: 0 | P17: next 5 years
B18: worst case | C18: =C12 -> 1.17 | D18: =C18*(1+$O$17) -> 1.17 | E18: =D18*(1+$O$17) -> 1.17 | F18: =E18*(1+$O$17) -> 1.17 | G18: =F18*(1+$O$17) -> 1.17 | H18: =G18*(1+$O$17) -> 1.17 | I18: =H18*(1+$O$18) -> 1.17 | J18: =I18*(1+$O$18) -> 1.17 | K18: =J18*(1+$O$18) -> 1.17 | L18: =K18*(1+$O$18) -> 1.17 | M18: =L18*(1+$O$18) -> 1.17 | N18: =L18*O20 -> 17.55 | O18: 0 | P18: 5 to 10 years
B19: MARGIN OF | C19: =C13 -> PV(10%) | D19: =D18*(1+$O$19)^($D$17-D17-1)*$I$3 -> 1.0636364 | E19: =E18*(1+$O$19)^($D$17-E17-1)*$I$3 -> 0.96694215 | F19: =F18*(1+$O$19)^($D$17-F17-1)*$I$3 -> 0.87903832 | G19: =G18*(1+$O$19)^($D$17-G17-1)*$I$3 -> 0.79912574 | H19: =H18*(1+$O$19)^($D$17-H17-1)*$I$3 -> 0.72647795 | I19: =I18*(1+$O$19)^($D$17-I17-1)*$I$3 -> 0.6604345 | J19: =J18*(1+$O$19)^($D$17-J17-1)*$I$3 -> 0.600395 | K19: =K18*(1+$O$19)^($D$17-K17-1)*$I$3 -> 0.54581363 | ... M19: =M18*(1+$O$19)^($D$17-M17-1)*$I$3 -> 0.45108565 | N19: =N18*(1+$O$19)^($D$17-N17-1) -> 6.7662847 | O19: =O13 -> 0.1 | P19: Discount rate
B20: SAFETY | C20: Present value sum | D20: =SUM(D19:N19) -> 13.955428 | O20: 15 | P20: Terminal multiple
C22: Scenario | D22: Probability | E22: PV | F22: Part
C23: Scenario 1 (normal case) | D23: 0.34 | E23: =D8 -> 23.135447 | F23: =E23*D23 -> 7.866052
C24: Scenario 2 (best case) | D24: 0.33 | E24: =D14 -> 34.74691 | F24: =E24*D24 -> 11.46648
C25: Scenario 3 (worst case) | D25: 0.33 | E25: =D20 -> 13.955428 | F25: =E25*D25 -> 4.6052913
C26: STOCK PRICE NOW | D26: =C3 -> 34.42 | E26: Sum | F26: =SUM(F23:F25) -> 23.937824
B28: Disclaimer: This is just for educational purposes and not for investing advice!
B30: MADE BY | C30: STOCK MARKET RESEARCH PLATFORM

Sheet BABA
S1: input cells
B2: Alibaba | C2: LINK TO RESEARCH | S2: result cells
B3: STOCK PRICE | C3: ='COMPARATIVE TABLE'!C4 -> 143.93 | F3: DIVIDEND PAYOUT RATIO | I3: 0.2
B4: COMPARATIVE TABLE'!A1 | N4: Terminal Value | O4: Growth rate
B5: Scenario 1 | C5: FCF | D5: 2026 | E5: =D5+1 -> 2027 | F5: =E5+1 -> 2028 | G5: =F5+1 -> 2029 | H5: =G5+1 -> 2030 | I5: =H5+1 -> 2031 | J5: =I5+1 -> 2032 | K5: =J5+1 -> 2033 | L5: =K5+1 -> 2034 | M5: =L5+1 -> 2035 | N5: 2035 | O5: 0.07 | P5: next 5 years
B6: normal case | C6: 8 | D6: =C6*(1+$O$5) -> 8.56 | E6: =D6*(1+$O$5) -> 9.1592 | F6: =E6*(1+$O$5) -> 9.800344 | G6: =F6*(1+$O$5) -> 10.486368 | H6: =G6*(1+$O$5) -> 11.220414 | I6: =H6*(1+$O$6) -> 11.781435 | J6: =I6*(1+$O$6) -> 12.370506 | K6: =J6*(1+$O$6) -> 12.989032 | L6: =K6*(1+$O$6) -> 13.638483 | M6: =L6*(1+$O$6) -> 14.320407 | N6: =L6*O8 -> 204.57725 | O6: 0.05 | P6: 5 to 10 years
C7: =CONCATENATE(R8,O7*100,S8) -> PV(10%) | D7: =D6*(1+$O$7)^($D$5-D5-1)*$I$3 -> 1.5563636 | E7: =E6*(1+$O$7)^($D$5-E5-1)*$I$3 -> 1.5139174 | F7: =F6*(1+$O$7)^($D$5-F5-1)*$I$3 -> 1.4726287 | G7: =G6*(1+$O$7)^($D$5-G5-1)*$I$3 -> 1.4324661 | H7: =H6*(1+$O$7)^($D$5-H5-1)*$I$3 -> 1.3933988 | I7: =I6*(1+$O$7)^($D$5-I5-1)*$I$3 -> 1.3300625 | J7: =J6*(1+$O$7)^($D$5-J5-1)*$I$3 -> 1.2696051 | K7: =K6*(1+$O$7)^($D$5-K5-1)*$I$3 -> 1.2118958 | ... M7: =M6*(1+$O$7)^($D$5-M5-1)*$I$3 -> 1.1042274 | N7: =N6*(1+$O$7)^($D$5-N5-1) -> 78.873385 | O7: 0.1 | P7: Discount rate
C8: INTRINSIC VALUE | D8: =SUM(D7:N7) -> 92.31476 | O8: 15 | P8: Terminal multiple | R8: PV( | S8: %)
N10: Terminal Value | O10: Growth rate
B11: Scenario 2 | C11: =C5 -> FCF | D11: =D5 -> 2026 | E11: =D11+1 -> 2027 | F11: =E11+1 -> 2028 | G11: =F11+1 -> 2029 | H11: =G11+1 -> 2030 | I11: =H11+1 -> 2031 | J11: =I11+1 -> 2032 | K11: =J11+1 -> 2033 | L11: =K11+1 -> 2034 | M11: =L11+1 -> 2035 | N11: =N5 -> 2035 | O11: 0.09 | P11: next 5 years
B12: best case | C12: =C6 -> 8 | D12: =C12*(1+$O$11) -> 8.72 | E12: =D12*(1+$O$11) -> 9.5048 | F12: =E12*(1+$O$11) -> 10.360232 | G12: =F12*(1+$O$11) -> 11.292653 | H12: =G12*(1+$O$11) -> 12.308992 | I12: =H12*(1+$O$12) -> 13.047531 | J12: =I12*(1+$O$12) -> 13.830383 | K12: =J12*(1+$O$12) -> 14.660206 | L12: =K12*(1+$O$12) -> 15.539818 | M12: =L12*(1+$O$12) -> 16.472207 | N12: =L12*O14 -> 310.79637 | O12: 0.06 | P12: 5 to 10 years
B13: =B7 -> 0 | C13: =C7 -> PV(10%) | D13: =D12*(1+$O$13)^($D$11-D11-1)*$I$3 -> 1.5854545 | E13: =E12*(1+$O$13)^($D$11-E11-1)*$I$3 -> 1.5710413 | F13: =F12*(1+$O$13)^($D$11-F11-1)*$I$3 -> 1.5567591 | G13: =G12*(1+$O$13)^($D$11-G11-1)*$I$3 -> 1.5426068 | H13: =H12*(1+$O$13)^($D$11-H11-1)*$I$3 -> 1.5285831 | I13: =I12*(1+$O$13)^($D$11-I11-1)*$I$3 -> 1.4729982 | J13: =J12*(1+$O$13)^($D$11-J11-1)*$I$3 -> 1.4194347 | K13: =K12*(1+$O$13)^($D$11-K11-1)*$I$3 -> 1.3678189 | ... M13: =M12*(1+$O$13)^($D$11-M11-1)*$I$3 -> 1.2701498 | N13: =N12*(1+$O$7)^($D$5-N11-1) -> 119.82545 | O13: =O7 -> 0.1 | P13: Discount rate
C14: Present value sum | D14: =SUM(D13:N13) -> 134.45838 | O14: 20 | P14: Terminal multiple
N16: Terminal Value | O16: Growth rate
B17: Scenario 3 | C17: =C11 -> FCF | D17: =D11 -> 2026 | E17: =D17+1 -> 2027 | F17: =E17+1 -> 2028 | G17: =F17+1 -> 2029 | H17: =G17+1 -> 2030 | I17: =H17+1 -> 2031 | J17: =I17+1 -> 2032 | K17: =J17+1 -> 2033 | L17: =K17+1 -> 2034 | M17: =L17+1 -> 2035 | N17: =N11 -> 2035 | O17: 0.05 | P17: next 5 years
B18: worst case | C18: =C12 -> 8 | D18: =C18*(1+$O$17) -> 8.4 | E18: =D18*(1+$O$17) -> 8.82 | F18: =E18*(1+$O$17) -> 9.261 | G18: =F18*(1+$O$17) -> 9.72405 | H18: =G18*(1+$O$17) -> 10.210253 | I18: =H18*(1+$O$18) -> 10.618663 | J18: =I18*(1+$O$18) -> 11.043409 | K18: =J18*(1+$O$18) -> 11.485145 | L18: =K18*(1+$O$18) -> 11.944551 | M18: =L18*(1+$O$18) -> 12.422333 | N18: =L18*O20 -> 119.44551 | O18: 0.04 | P18: 5 to 10 years
B19: MARGIN OF | C19: =C13 -> PV(10%) | D19: =D18*(1+$O$19)^($D$17-D17-1)*$I$3 -> 1.5272727 | E19: =E18*(1+$O$19)^($D$17-E17-1)*$I$3 -> 1.4578512 | F19: =F18*(1+$O$19)^($D$17-F17-1)*$I$3 -> 1.3915853 | G19: =G18*(1+$O$19)^($D$17-G17-1)*$I$3 -> 1.3283314 | H19: =H18*(1+$O$19)^($D$17-H17-1)*$I$3 -> 1.2679527 | I19: =I18*(1+$O$19)^($D$17-I17-1)*$I$3 -> 1.1987916 | J19: =J18*(1+$O$19)^($D$17-J17-1)*$I$3 -> 1.133403 | K19: =K18*(1+$O$19)^($D$17-K17-1)*$I$3 -> 1.071581 | ... M19: =M18*(1+$O$19)^($D$17-M17-1)*$I$3 -> 0.95786945 | N19: =N18*(1+$O$19)^($D$17-N17-1) -> 46.051416 | O19: =O13 -> 0.1 | P19: Discount rate
B20: SAFETY | C20: Present value sum | D20: =SUM(D19:N19) -> 58.399186 | O20: 10 | P20: Terminal multiple
C22: Scenario | D22: Probability | E22: PV | F22: Part
C23: Scenario 1 (normal case) | D23: 0.34 | E23: =D8 -> 92.31476 | F23: =E23*D23 -> 31.387018
C24: Scenario 2 (best case) | D24: 0.33 | E24: =D14 -> 134.45838 | F24: =E24*D24 -> 44.371265
C25: Scenario 3 (worst case) | D25: 0.33 | E25: =D20 -> 58.399186 | F25: =E25*D25 -> 19.271731
C26: STOCK PRICE NOW | D26: =C3 -> 143.93 | E26: Sum | F26: =SUM(F23:F25) -> 95.030015
B28: Disclaimer: This is just for educational purposes and not for investing advice!
B30: MADE BY | C30: STOCK MARKET RESEARCH PLATFORM

Sheet ACOMO
S1: input cells
B2: ACOMO | C2: LINK TO RESEARCH | S2: result cells
B3: STOCK PRICE | C3: ='COMPARATIVE TABLE'!C5 -> 22.9 | F3: DIVIDEND PAYOUT RATIO | I3: 1
B4: COMPARATIVE TABLE'!A1 | N4: Terminal Value | O4: Growth rate
B5: Scenario 1 | C5: DIVIDEND PER SHARE | D5: 2026 | E5: =D5+1 -> 2027 | F5: =E5+1 -> 2028 | G5: =F5+1 -> 2029 | H5: =G5+1 -> 2030 | I5: =H5+1 -> 2031 | J5: =I5+1 -> 2032 | K5: =J5+1 -> 2033 | L5: =K5+1 -> 2034 | M5: =L5+1 -> 2035 | N5: 2035 | O5: 0.05 | P5: next 5 years
B6: normal case | C6: 1.3 | D6: =C6*(1+$O$5) -> 1.365 | E6: =D6*(1+$O$5) -> 1.43325 | F6: =E6*(1+$O$5) -> 1.5049125 | G6: =F6*(1+$O$5) -> 1.5801581 | H6: =G6*(1+$O$5) -> 1.659166 | I6: =H6*(1+$O$6) -> 1.7421243 | J6: =I6*(1+$O$6) -> 1.8292305 | K6: =J6*(1+$O$6) -> 1.9206921 | L6: =K6*(1+$O$6) -> 2.0167267 | M6: =L6*(1+$O$6) -> 2.117563 | N6: =L6*O8 -> 30.2509 | O6: 0.05 | P6: 5 to 10 years
C7: =CONCATENATE(R8,O7*100,S8) -> PV(10%) | D7: =D6*(1+$O$7)^($D$5-D5-1)*$I$3 -> 1.2409091 | E7: =E6*(1+$O$7)^($D$5-E5-1)*$I$3 -> 1.1845041 | F7: =F6*(1+$O$7)^($D$5-F5-1)*$I$3 -> 1.130663 | G7: =G6*(1+$O$7)^($D$5-G5-1)*$I$3 -> 1.0792693 | H7: =H6*(1+$O$7)^($D$5-H5-1)*$I$3 -> 1.0302116 | I7: =I6*(1+$O$7)^($D$5-I5-1)*$I$3 -> 0.98338377 | J7: =J6*(1+$O$7)^($D$5-J5-1)*$I$3 -> 0.93868451 | K7: =K6*(1+$O$7)^($D$5-K5-1)*$I$3 -> 0.89601703 | ... M7: =M6*(1+$O$7)^($D$5-M5-1)*$I$3 -> 0.81641221 | N7: =N6*(1+$O$7)^($D$5-N5-1) -> 11.663032 | O7: 0.1 | P7: Discount rate
C8: INTRINSIC VALUE | D8: =SUM(D7:N7) -> 21.818375 | O8: 15 | P8: Terminal multiple | R8: PV( | S8: %)
N10: Terminal Value | O10: Growth rate
B11: Scenario 2 | C11: =C5 -> DIVIDEND PER SHARE | D11: =D5 -> 2026 | E11: =D11+1 -> 2027 | F11: =E11+1 -> 2028 | G11: =F11+1 -> 2029 | H11: =G11+1 -> 2030 | I11: =H11+1 -> 2031 | J11: =I11+1 -> 2032 | K11: =J11+1 -> 2033 | L11: =K11+1 -> 2034 | M11: =L11+1 -> 2035 | N11: =N5 -> 2035 | O11: 0.07 | P11: next 5 years
B12: best case | C12: =C6 -> 1.3 | D12: =C12*(1+$O$11) -> 1.391 | E12: =D12*(1+$O$11) -> 1.48837 | F12: =E12*(1+$O$11) -> 1.5925559 | G12: =F12*(1+$O$11) -> 1.7040348 | H12: =G12*(1+$O$11) -> 1.8233172 | I12: =H12*(1+$O$12) -> 1.9509495 | J12: =I12*(1+$O$12) -> 2.0875159 | K12: =J12*(1+$O$12) -> 2.233642 | L12: =K12*(1+$O$12) -> 2.389997 | M12: =L12*(1+$O$12) -> 2.5572968 | N12: =L12*O14 -> 47.79994 | O12: 0.07 | P12: 5 to 10 years
B13: =B7 -> 0 | C13: =C7 -> PV(10%) | D13: =D12*(1+$O$13)^($D$11-D11-1)*$I$3 -> 1.2645455 | E13: =E12*(1+$O$13)^($D$11-E11-1)*$I$3 -> 1.2300579 | F13: =F12*(1+$O$13)^($D$11-F11-1)*$I$3 -> 1.1965108 | G13: =G12*(1+$O$13)^($D$11-G11-1)*$I$3 -> 1.1638787 | H13: =H12*(1+$O$13)^($D$11-H11-1)*$I$3 -> 1.1321366 | I13: =I12*(1+$O$13)^($D$11-I11-1)*$I$3 -> 1.1012601 | J13: =J12*(1+$O$13)^($D$11-J11-1)*$I$3 -> 1.0712257 | K13: =K12*(1+$O$13)^($D$11-K11-1)*$I$3 -> 1.0420105 | ... M13: =M12*(1+$O$13)^($D$11-M11-1)*$I$3 -> 0.98594861 | N13: =N12*(1+$O$7)^($D$5-N11-1) -> 18.428946 | O13: =O7 -> 0.1 | P13: Discount rate
C14: Present value sum | D14: =SUM(D13:N13) -> 29.630112 | O14: 20 | P14: Terminal multiple
N16: Terminal Value | O16: Growth rate
B17: Scenario 3 | C17: =C11 -> DIVIDEND PER SHARE | D17: =D11 -> 2026 | E17: =D17+1 -> 2027 | F17: =E17+1 -> 2028 | G17: =F17+1 -> 2029 | H17: =G17+1 -> 2030 | I17: =H17+1 -> 2031 | J17: =I17+1 -> 2032 | K17: =J17+1 -> 2033 | L17: =K17+1 -> 2034 | M17: =L17+1 -> 2035 | N17: =N11 -> 2035 | O17: 0.03 | P17: next 5 years
B18: worst case | C18: =C12 -> 1.3 | D18: =C18*(1+$O$17) -> 1.339 | E18: =D18*(1+$O$17) -> 1.37917 | F18: =E18*(1+$O$17) -> 1.4205451 | G18: =F18*(1+$O$17) -> 1.4631615 | H18: =G18*(1+$O$17) -> 1.5070563 | I18: =H18*(1+$O$18) -> 1.5070563 | J18: =I18*(1+$O$18) -> 1.5070563 | K18: =J18*(1+$O$18) -> 1.5070563 | L18: =K18*(1+$O$18) -> 1.5070563 | M18: =L18*(1+$O$18) -> 1.5070563 | N18: =L18*O20 -> 18.084676 | O18: 0 | P18: 5 to 10 years
B19: MARGIN OF | C19: =C13 -> PV(10%) | D19: =D18*(1+$O$19)^($D$17-D17-1)*$I$3 -> 1.2172727 | E19: =E18*(1+$O$19)^($D$17-E17-1)*$I$3 -> 1.1398099 | F19: =F18*(1+$O$19)^($D$17-F17-1)*$I$3 -> 1.0672766 | G19: =G18*(1+$O$19)^($D$17-G17-1)*$I$3 -> 0.99935896 | H19: =H18*(1+$O$19)^($D$17-H17-1)*$I$3 -> 0.93576339 | I19: =I18*(1+$O$19)^($D$17-I17-1)*$I$3 -> 0.85069399 | J19: =J18*(1+$O$19)^($D$17-J17-1)*$I$3 -> 0.77335817 | K19: =K18*(1+$O$19)^($D$17-K17-1)*$I$3 -> 0.70305288 | ... M19: =M18*(1+$O$19)^($D$17-M17-1)*$I$3 -> 0.58103544 | N19: =N18*(1+$O$19)^($D$17-N17-1) -> 6.9724253 | O19: =O13 -> 0.1 | P19: Discount rate
B20: SAFETY | C20: Present value sum | D20: =SUM(D19:N19) -> 15.879186 | O20: 12 | P20: Terminal multiple
C22: Scenario | D22: Probability | E22: PV | F22: Part
C23: Scenario 1 (normal case) | D23: 0.34 | E23: =D8 -> 21.818375 | F23: =E23*D23 -> 7.4182476
C24: Scenario 2 (best case) | D24: 0.33 | E24: =D14 -> 29.630112 | F24: =E24*D24 -> 9.7779371
C25: Scenario 3 (worst case) | D25: 0.33 | E25: =D20 -> 15.879186 | F25: =E25*D25 -> 5.2401315
C26: STOCK PRICE NOW | D26: =C3 -> 22.9 | E26: Sum | F26: =SUM(F23:F25) -> 22.436316
B28: Disclaimer: This is just for educational purposes and not for investing advice!
B30: MADE BY | C30: STOCK MARKET RESEARCH PLATFORM

Sheet ADM
S1: input cells
B2: ADM | C2: LINK TO RESEARCH | S2: result cells
B3: STOCK PRICE | C3: ='MKT CAP - Price'!E91 -> 61.41 | F3: DIVIDEND PAYOUT RATIO | I3: 1
B4: COMPARATIVE TABLE'!A1 | N4: Terminal Value | O4: Growth rate
B5: Scenario 1 | C5: Dividend per share | D5: 2025 | E5: =D5+1 -> 2026 | F5: =E5+1 -> 2027 | G5: =F5+1 -> 2028 | H5: =G5+1 -> 2029 | I5: =H5+1 -> 2030 | J5: =I5+1 -> 2031 | K5: =J5+1 -> 2032 | L5: =K5+1 -> 2033 | M5: =L5+1 -> 2034 | N5: 2034 | O5: 0.02 | P5: next 5 years
B6: normal case | C6: 2.04 | D6: =C6*(1+$O$5) -> 2.0808 | E6: =D6*(1+$O$5) -> 2.122416 | F6: =E6*(1+$O$5) -> 2.1648643 | G6: =F6*(1+$O$5) -> 2.2081616 | H6: =G6*(1+$O$5) -> 2.2523248 | I6: =H6*(1+$O$6) -> 2.3874643 | J6: =I6*(1+$O$6) -> 2.5307122 | K6: =J6*(1+$O$6) -> 2.6825549 | L6: =K6*(1+$O$6) -> 2.8435082 | M6: =L6*(1+$O$6) -> 3.0141187 | N6: =L6*O8 -> 56.870164 | O6: 0.06 | P6: 5 to 10 years
C7: =CONCATENATE(R8,O7*100,S8) -> PV(10%) | D7: =D6*(1+$O$7)^($D$5-D5-1)*$I$3 -> 1.8916364 | E7: =E6*(1+$O$7)^($D$5-E5-1)*$I$3 -> 1.7540628 | F7: =F6*(1+$O$7)^($D$5-F5-1)*$I$3 -> 1.6264946 | G7: =G6*(1+$O$7)^($D$5-G5-1)*$I$3 -> 1.5082041 | H7: =H6*(1+$O$7)^($D$5-H5-1)*$I$3 -> 1.3985165 | I7: =I6*(1+$O$7)^($D$5-I5-1)*$I$3 -> 1.3476614 | J7: =J6*(1+$O$7)^($D$5-J5-1)*$I$3 -> 1.2986555 | K7: =K6*(1+$O$7)^($D$5-K5-1)*$I$3 -> 1.2514317 | ... M7: =M6*(1+$O$7)^($D$5-M5-1)*$I$3 -> 1.1620732 | N7: =N6*(1+$O$7)^($D$5-N5-1) -> 21.92591 | O7: 0.1 | P7: Discount rate
C8: INTRINSIC VALUE | D8: =SUM(D7:N7) -> 36.370571 | O8: 20 | P8: Terminal multiple | R8: PV( | S8: %)
N10: Terminal Value | O10: Growth rate
B11: Scenario 2 | C11: =C5 -> Dividend per share | D11: =D5 -> 2025 | E11: =D11+1 -> 2026 | F11: =E11+1 -> 2027 | G11: =F11+1 -> 2028 | H11: =G11+1 -> 2029 | I11: =H11+1 -> 2030 | J11: =I11+1 -> 2031 | K11: =J11+1 -> 2032 | L11: =K11+1 -> 2033 | M11: =L11+1 -> 2034 | N11: =N5 -> 2034 | O11: 0.06 | P11: next 5 years
B12: best case | C12: =C6 -> 2.04 | D12: =C12*(1+$O$11) -> 2.1624 | E12: =D12*(1+$O$11) -> 2.292144 | F12: =E12*(1+$O$11) -> 2.4296726 | G12: =F12*(1+$O$11) -> 2.575453 | H12: =G12*(1+$O$11) -> 2.7299802 | I12: =H12*(1+$O$12) -> 2.893779 | J12: =I12*(1+$O$12) -> 3.0674057 | K12: =J12*(1+$O$12) -> 3.2514501 | L12: =K12*(1+$O$12) -> 3.4465371 | M12: =L12*(1+$O$12) -> 3.6533293 | N12: =L12*O14 -> 86.163427 | O12: 0.06 | P12: 5 to 10 years
B13: =B7 -> 0 | C13: =C7 -> PV(10%) | D13: =D12*(1+$O$13)^($D$11-D11-1) -> 1.9658182 | E13: =E12*(1+$O$13)^($D$11-E11-1) -> 1.8943339 | F13: =F12*(1+$O$13)^($D$11-F11-1) -> 1.825449 | G13: =G12*(1+$O$13)^($D$11-G11-1) -> 1.7590691 | H13: =H12*(1+$O$13)^($D$11-H11-1) -> 1.6951029 | I13: =I12*(1+$O$13)^($D$11-I11-1) -> 1.6334628 | J13: =J12*(1+$O$13)^($D$11-J11-1) -> 1.5740642 | K13: =K12*(1+$O$13)^($D$11-K11-1) -> 1.5168255 | ... M13: =M12*(1+$O$13)^($D$11-M11-1) -> 1.4085166 | N13: =N12*(1+$O$7)^($D$5-N11-1) -> 33.219731 | O13: =O7 -> 0.1 | P13: Discount rate
C14: Present value sum | D14: =SUM(D13:N13) -> 49.954041 | O14: 25 | P14: Terminal multiple
N16: Terminal Value | O16: Growth rate
B17: Scenario 3 | C17: =C11 -> Dividend per share | D17: =D11 -> 2025 | E17: =D17+1 -> 2026 | F17: =E17+1 -> 2027 | G17: =F17+1 -> 2028 | H17: =G17+1 -> 2029 | I17: =H17+1 -> 2030 | J17: =I17+1 -> 2031 | K17: =J17+1 -> 2032 | L17: =K17+1 -> 2033 | M17: =L17+1 -> 2034 | N17: =N11 -> 2034 | O17: 0.02 | P17: next 5 years
B18: worst case | C18: =C12 -> 2.04 | D18: =C18*(1+$O$17) -> 2.0808 | E18: =D18*(1+$O$17) -> 2.122416 | F18: =E18*(1+$O$17) -> 2.1648643 | G18: =F18*(1+$O$17) -> 2.2081616 | H18: =G18*(1+$O$17) -> 2.2523248 | I18: =H18*(1+$O$18) -> 2.2973713 | J18: =I18*(1+$O$18) -> 2.3433188 | K18: =J18*(1+$O$18) -> 2.3901851 | L18: =K18*(1+$O$18) -> 2.4379888 | M18: =L18*(1+$O$18) -> 2.4867486 | N18: =L18*O20 -> 36.569833 | O18: 0.02 | P18: 5 to 10 years
B19: MARGIN OF | C19: =C13 -> PV(10%) | D19: =D18*(1+$O$19)^($D$17-D17-1)*$I$3 -> 1.8916364 | E19: =E18*(1+$O$19)^($D$17-E17-1)*$I$3 -> 1.7540628 | F19: =F18*(1+$O$19)^($D$17-F17-1)*$I$3 -> 1.6264946 | G19: =G18*(1+$O$19)^($D$17-G17-1)*$I$3 -> 1.5082041 | H19: =H18*(1+$O$19)^($D$17-H17-1)*$I$3 -> 1.3985165 | I19: =I18*(1+$O$19)^($D$17-I17-1)*$I$3 -> 1.2968062 | J19: =J18*(1+$O$19)^($D$17-J17-1)*$I$3 -> 1.202493 | K19: =K18*(1+$O$19)^($D$17-K17-1)*$I$3 -> 1.115039 | ... M19: =M18*(1+$O$19)^($D$17-M17-1)*$I$3 -> 0.95874924 | N19: =N18*(1+$O$19)^($D$17-N17-1) -> 14.099254 | O19: =O13 -> 0.1 | P19: Discount rate
B20: SAFETY | C20: Present value sum | D20: =SUM(D19:N19) -> 27.885201 | O20: 15 | P20: Terminal multiple
C22: Scenario | D22: Probability | E22: PV | F22: Part
C23: Scenario 1 (normal case) | D23: 0.33 | E23: =D8 -> 36.370571 | F23: =E23*D23 -> 12.002289
C24: Scenario 2 (best case) | D24: 0.34 | E24: =D14 -> 49.954041 | F24: =E24*D24 -> 16.984374
C25: Scenario 3 (worst case) | D25: 0.33 | E25: =D20 -> 27.885201 | F25: =E25*D25 -> 9.2021162
C26: STOCK PRICE NOW | D26: =C3 -> 61.41 | E26: Sum | F26: =SUM(F23:F25) -> 38.188779
B28: Disclaimer: This is just for educational purposes and not for investing advice!
B30: MADE BY | C30: STOCK MARKET RESEARCH PLATFORM

Sheet ABF
S1: input cells
B2: ABF | C2: LINK TO RESEARCH | S2: result cells
B3: STOCK PRICE | C3: ='MKT CAP - Price'!C100 -> 1997 | F3: DIVIDEND PAYOUT RATIO | I3: 1
B4: COMPARATIVE TABLE'!A1 | N4: Terminal Value | O4: Growth rate
B5: Scenario 1 | C5: Dividend per share | D5: 2025 | E5: =D5+1 -> 2026 | F5: =E5+1 -> 2027 | G5: =F5+1 -> 2028 | H5: =G5+1 -> 2029 | I5: =H5+1 -> 2030 | J5: =I5+1 -> 2031 | K5: =J5+1 -> 2032 | L5: =K5+1 -> 2033 | M5: =L5+1 -> 2034 | N5: 2034 | O5: 0.05 | P5: next 5 years
B6: normal case | C6: 63 | D6: =C6*(1+$O$5) -> 66.15 | E6: =D6*(1+$O$5) -> 69.4575 | F6: =E6*(1+$O$5) -> 72.930375 | G6: =F6*(1+$O$5) -> 76.576894 | H6: =G6*(1+$O$5) -> 80.405738 | I6: =H6*(1+$O$6) -> 84.426025 | J6: =I6*(1+$O$6) -> 88.647327 | K6: =J6*(1+$O$6) -> 93.079693 | L6: =K6*(1+$O$6) -> 97.733678 | M6: =L6*(1+$O$6) -> 102.62036 | N6: =L6*O8 -> 1954.6736 | O6: 0.05 | P6: 5 to 10 years
C7: =CONCATENATE(R8,O7*100,S8) -> PV(10%) | D7: =D6*(1+$O$7)^($D$5-D5-1)*$I$3 -> 60.136364 | E7: =E6*(1+$O$7)^($D$5-E5-1)*$I$3 -> 57.402893 | F7: =F6*(1+$O$7)^($D$5-F5-1)*$I$3 -> 54.79367 | G7: =G6*(1+$O$7)^($D$5-G5-1)*$I$3 -> 52.303049 | H7: =H6*(1+$O$7)^($D$5-H5-1)*$I$3 -> 49.925637 | I7: =I6*(1+$O$7)^($D$5-I5-1)*$I$3 -> 47.65629 | J7: =J6*(1+$O$7)^($D$5-J5-1)*$I$3 -> 45.490095 | K7: =K6*(1+$O$7)^($D$5-K5-1)*$I$3 -> 43.422364 | ... M7: =M6*(1+$O$7)^($D$5-M5-1)*$I$3 -> 39.564592 | N7: =N6*(1+$O$7)^($D$5-N5-1) -> 753.61127 | O7: 0.1 | P7: Discount rate
C8: INTRINSIC VALUE | D8: =SUM(D7:N7) -> 1245.7548 | O8: 20 | P8: Terminal multiple | R8: PV( | S8: %)
N10: Terminal Value | O10: Growth rate
B11: Scenario 2 | C11: =C5 -> Dividend per share | D11: =D5 -> 2025 | E11: =D11+1 -> 2026 | F11: =E11+1 -> 2027 | G11: =F11+1 -> 2028 | H11: =G11+1 -> 2029 | I11: =H11+1 -> 2030 | J11: =I11+1 -> 2031 | K11: =J11+1 -> 2032 | L11: =K11+1 -> 2033 | M11: =L11+1 -> 2034 | N11: =N5 -> 2034 | O11: 0.07 | P11: next 5 years
B12: best case | C12: =C6 -> 63 | D12: =C12*(1+$O$11) -> 67.41 | E12: =D12*(1+$O$11) -> 72.1287 | F12: =E12*(1+$O$11) -> 77.177709 | G12: =F12*(1+$O$11) -> 82.580149 | H12: =G12*(1+$O$11) -> 88.360759 | I12: =H12*(1+$O$12) -> 94.546012 | J12: =I12*(1+$O$12) -> 101.16423 | K12: =J12*(1+$O$12) -> 108.24573 | L12: =K12*(1+$O$12) -> 115.82293 | M12: =L12*(1+$O$12) -> 123.93054 | N12: =L12*O14 -> 2895.5733 | O12: 0.07 | P12: 5 to 10 years
B13: =B7 -> 0 | C13: =C7 -> PV(10%) | D13: =D12*(1+$O$13)^($D$11-D11-1)*$I$3 -> 61.281818 | E13: =E12*(1+$O$13)^($D$11-E11-1)*$I$3 -> 59.610496 | F13: =F12*(1+$O$13)^($D$11-F11-1)*$I$3 -> 57.984755 | G13: =G12*(1+$O$13)^($D$11-G11-1)*$I$3 -> 56.403353 | H13: =H12*(1+$O$13)^($D$11-H11-1)*$I$3 -> 54.865079 | I13: =I12*(1+$O$13)^($D$11-I11-1)*$I$3 -> 53.368759 | J13: =J12*(1+$O$13)^($D$11-J11-1)*$I$3 -> 51.913247 | K13: =K12*(1+$O$13)^($D$11-K11-1)*$I$3 -> 50.497432 | ... M13: =M12*(1+$O$13)^($D$11-M11-1)*$I$3 -> 47.780586 | N13: =N12*(1+$O$7)^($D$5-N11-1) -> 1116.3688 | O13: =O7 -> 0.1 | P13: Discount rate
C14: Present value sum | D14: =SUM(D13:N13) -> 1659.1946 | O14: 25 | P14: Terminal multiple
N16: Terminal Value | O16: Growth rate
B17: Scenario 3 | C17: =C11 -> Dividend per share | D17: =D11 -> 2025 | E17: =D17+1 -> 2026 | F17: =E17+1 -> 2027 | G17: =F17+1 -> 2028 | H17: =G17+1 -> 2029 | I17: =H17+1 -> 2030 | J17: =I17+1 -> 2031 | K17: =J17+1 -> 2032 | L17: =K17+1 -> 2033 | M17: =L17+1 -> 2034 | N17: =N11 -> 2034 | O17: 0.03 | P17: next 5 years
B18: worst case | C18: =C12 -> 63 | D18: =C18*(1+$O$17) -> 64.89 | E18: =D18*(1+$O$17) -> 66.8367 | F18: =E18*(1+$O$17) -> 68.841801 | G18: =F18*(1+$O$17) -> 70.907055 | H18: =G18*(1+$O$17) -> 73.034267 | I18: =H18*(1+$O$18) -> 75.225295 | J18: =I18*(1+$O$18) -> 77.482054 | K18: =J18*(1+$O$18) -> 79.806515 | L18: =K18*(1+$O$18) -> 82.200711 | M18: =L18*(1+$O$18) -> 84.666732 | N18: =L18*O20 -> 1233.0107 | O18: 0.03 | P18: 5 to 10 years
B19: MARGIN OF | C19: =C13 -> PV(10%) | D19: =D18*(1+$O$19)^($D$17-D17-1)*$I$3 -> 58.990909 | E19: =E18*(1+$O$19)^($D$17-E17-1)*$I$3 -> 55.236942 | F19: =F18*(1+$O$19)^($D$17-F17-1)*$I$3 -> 51.721864 | G19: =G18*(1+$O$19)^($D$17-G17-1)*$I$3 -> 48.430473 | H19: =H18*(1+$O$19)^($D$17-H17-1)*$I$3 -> 45.348533 | I19: =I18*(1+$O$19)^($D$17-I17-1)*$I$3 -> 42.462718 | J19: =J18*(1+$O$19)^($D$17-J17-1)*$I$3 -> 39.760545 | K19: =K18*(1+$O$19)^($D$17-K17-1)*$I$3 -> 37.230328 | ... M19: =M18*(1+$O$19)^($D$17-M17-1)*$I$3 -> 32.64269 | N19: =N18*(1+$O$19)^($D$17-N17-1) -> 475.37899 | O19: =O13 -> 0.1 | P19: Discount rate
B20: SAFETY | C20: Present value sum | D20: =SUM(D19:N19) -> 922.06511 | O20: 15 | P20: Terminal multiple
C22: Scenario | D22: Probability | E22: PV | F22: Part
C23: Scenario 1 (normal case) | D23: 0.34 | E23: =D8 -> 1245.7548 | F23: =E23*D23 -> 423.55665
C24: Scenario 2 (best case) | D24: 0.33 | E24: =D14 -> 1659.1946 | F24: =E24*D24 -> 547.53422
C25: Scenario 3 (worst case) | D25: 0.33 | E25: =D20 -> 922.06511 | F25: =E25*D25 -> 304.28149
C26: STOCK PRICE NOW | D26: =C3 -> 1997 | E26: Sum | F26: =SUM(F23:F25) -> 1275.3724
B28: Disclaimer: This is just for educational purposes and not for investing advice!
B30: MADE BY | C30: STOCK MARKET RESEARCH PLATFORM

Sheet BRK.B
S1: input cells
B2: BRK.B | C2: LINK TO RESEARCH | S2: result cells
B3: STOCK PRICE | C3: ='COMPARATIVE TABLE'!C9 -> 1061.6746 | F3: DIVIDEND PAYOUT RATIO | I3: 0
B4: COMPARATIVE TABLE'!A1 | N4: Terminal Value | O4: Growth rate
B5: Scenario 1 | C5: EARNINGS IN BILLIONS | D5: 2026 | E5: =D5+1 -> 2027 | F5: =E5+1 -> 2028 | G5: =F5+1 -> 2029 | H5: =G5+1 -> 2030 | I5: =H5+1 -> 2031 | J5: =I5+1 -> 2032 | K5: =J5+1 -> 2033 | L5: =K5+1 -> 2034 | M5: =L5+1 -> 2035 | N5: 2035 | O5: 0.07 | P5: next 5 years
B6: normal case | C6: 40 | D6: =C6*(1+$O$5) -> 42.8 | E6: =D6*(1+$O$5) -> 45.796 | F6: =E6*(1+$O$5) -> 49.00172 | G6: =F6*(1+$O$5) -> 52.43184 | H6: =G6*(1+$O$5) -> 56.102069 | I6: =H6*(1+$O$6) -> 60.029214 | J6: =I6*(1+$O$6) -> 64.231259 | K6: =J6*(1+$O$6) -> 68.727447 | L6: =K6*(1+$O$6) -> 73.538368 | M6: =L6*(1+$O$6) -> 78.686054 | N6: =L6*O8 -> 1103.0755 | O6: 0.07 | P6: 5 to 10 years
C7: =CONCATENATE(R8,O7*100,S8) -> PV(10%) | D7: =D6*(1+$O$7)^($D$5-D5-1)*$I$3 -> 0 | E7: =E6*(1+$O$7)^($D$5-E5-1)*$I$3 -> 0 | F7: =F6*(1+$O$7)^($D$5-F5-1)*$I$3 -> 0 | G7: =G6*(1+$O$7)^($D$5-G5-1)*$I$3 -> 0 | H7: =H6*(1+$O$7)^($D$5-H5-1)*$I$3 -> 0 | I7: =I6*(1+$O$7)^($D$5-I5-1)*$I$3 -> 0 | J7: =J6*(1+$O$7)^($D$5-J5-1)*$I$3 -> 0 | K7: =K6*(1+$O$7)^($D$5-K5-1)*$I$3 -> 0 | ... M7: =M6*(1+$O$7)^($D$5-M5-1)*$I$3 -> 0 | N7: =N6*(1+$O$7)^($D$5-N5-1) -> 425.28337 | O7: 0.1 | P7: Discount rate
C8: INTRINSIC VALUE | D8: =SUM(D7:N7) -> 425.28337 | O8: 15 | P8: Terminal multiple | R8: PV( | S8: %)
N10: Terminal Value | O10: Growth rate
B11: Scenario 2 | C11: =C5 -> EARNINGS IN BILLIONS | D11: =D5 -> 2026 | E11: =D11+1 -> 2027 | F11: =E11+1 -> 2028 | G11: =F11+1 -> 2029 | H11: =G11+1 -> 2030 | I11: =H11+1 -> 2031 | J11: =I11+1 -> 2032 | K11: =J11+1 -> 2033 | L11: =K11+1 -> 2034 | M11: =L11+1 -> 2035 | N11: =N5 -> 2035 | O11: 0.09 | P11: next 5 years
B12: best case | C12: =C6 -> 40 | D12: =C12*(1+$O$11) -> 43.6 | E12: =D12*(1+$O$11) -> 47.524 | F12: =E12*(1+$O$11) -> 51.80116 | G12: =F12*(1+$O$11) -> 56.463264 | H12: =G12*(1+$O$11) -> 61.544958 | I12: =H12*(1+$O$12) -> 67.084004 | J12: =I12*(1+$O$12) -> 73.121565 | K12: =J12*(1+$O$12) -> 79.702506 | L12: =K12*(1+$O$12) -> 86.875731 | M12: =L12*(1+$O$12) -> 94.694547 | N12: =L12*O14 -> 1737.5146 | O12: 0.09 | P12: 5 to 10 years
B13: =B7 -> 0 | C13: =C7 -> PV(10%) | D13: =D12*(1+$O$13)^($D$11-D11-1)*$I$3 -> 0 | E13: =E12*(1+$O$13)^($D$11-E11-1)*$I$3 -> 0 | F13: =F12*(1+$O$13)^($D$11-F11-1)*$I$3 -> 0 | G13: =G12*(1+$O$13)^($D$11-G11-1)*$I$3 -> 0 | H13: =H12*(1+$O$13)^($D$11-H11-1)*$I$3 -> 0 | I13: =I12*(1+$O$13)^($D$11-I11-1)*$I$3 -> 0 | J13: =J12*(1+$O$13)^($D$11-J11-1)*$I$3 -> 0 | K13: =K12*(1+$O$13)^($D$11-K11-1)*$I$3 -> 0 | ... M13: =M12*(1+$O$13)^($D$11-M11-1)*$I$3 -> 0 | N13: =N12*(1+$O$7)^($D$5-N11-1) -> 669.8871 | O13: =O7 -> 0.1 | P13: Discount rate
C14: Present value sum | D14: =SUM(D13:N13) -> 669.8871 | O14: 20 | P14: Terminal multiple
N16: Terminal Value | O16: Growth rate
B17: Scenario 3 | C17: =C11 -> EARNINGS IN BILLIONS | D17: =D11 -> 2026 | E17: =D17+1 -> 2027 | F17: =E17+1 -> 2028 | G17: =F17+1 -> 2029 | H17: =G17+1 -> 2030 | I17: =H17+1 -> 2031 | J17: =I17+1 -> 2032 | K17: =J17+1 -> 2033 | L17: =K17+1 -> 2034 | M17: =L17+1 -> 2035 | N17: =N11 -> 2035 | O17: 0.05 | P17: next 5 years
B18: worst case | C18: =C12 -> 40 | D18: =C18*(1+$O$17) -> 42 | E18: =D18*(1+$O$17) -> 44.1 | F18: =E18*(1+$O$17) -> 46.305 | G18: =F18*(1+$O$17) -> 48.62025 | H18: =G18*(1+$O$17) -> 51.051263 | I18: =H18*(1+$O$18) -> 53.603826 | J18: =I18*(1+$O$18) -> 56.284017 | K18: =J18*(1+$O$18) -> 59.098218 | L18: =K18*(1+$O$18) -> 62.053129 | M18: =L18*(1+$O$18) -> 65.155785 | N18: =L18*O20 -> 744.63754 | O18: 0.05 | P18: 5 to 10 years
B19: MARGIN OF | C19: =C13 -> PV(10%) | D19: =D18*(1+$O$19)^($D$17-D17-1)*$I$3 -> 0 | E19: =E18*(1+$O$19)^($D$17-E17-1)*$I$3 -> 0 | F19: =F18*(1+$O$19)^($D$17-F17-1)*$I$3 -> 0 | G19: =G18*(1+$O$19)^($D$17-G17-1)*$I$3 -> 0 | H19: =H18*(1+$O$19)^($D$17-H17-1)*$I$3 -> 0 | I19: =I18*(1+$O$19)^($D$17-I17-1)*$I$3 -> 0 | J19: =J18*(1+$O$19)^($D$17-J17-1)*$I$3 -> 0 | K19: =K18*(1+$O$19)^($D$17-K17-1)*$I$3 -> 0 | ... M19: =M18*(1+$O$19)^($D$17-M17-1)*$I$3 -> 0 | N19: =N18*(1+$O$19)^($D$17-N17-1) -> 287.09001 | O19: =O13 -> 0.1 | P19: Discount rate
B20: SAFETY | C20: Present value sum | D20: =SUM(D19:N19) -> 287.09001 | O20: 12 | P20: Terminal multiple
C22: Scenario | D22: Probability | E22: PV | F22: Part
C23: Scenario 1 (normal case) | D23: 0.34 | E23: =D8 -> 425.28337 | F23: =E23*D23 -> 144.59634
C24: Scenario 2 (best case) | D24: 0.33 | E24: =D14 -> 669.8871 | F24: =E24*D24 -> 221.06274
C25: Scenario 3 (worst case) | D25: 0.33 | E25: =D20 -> 287.09001 | F25: =E25*D25 -> 94.739703
C26: STOCK PRICE NOW | D26: =C3 -> 1061.6746 | E26: Sum | F26: =SUM(F23:F25) -> 460.39879
B28: Disclaimer: This is just for educational purposes and not for investing advice!
B30: MADE BY | C30: STOCK MARKET RESEARCH PLATFORM

Sheet LND
S1: input cells
B2: Brasilagro | C2: LINK TO RESEARCH | S2: result cells
B3: STOCK PRICE | C3: ='COMPARATIVE TABLE'!C10 -> 3.88 | F3: DIVIDEND PAYOUT RATIO | I3: 0.5
B4: COMPARATIVE TABLE'!A1 | N4: Terminal Value | O4: Growth rate
B5: Scenario 1 | C5: Earnings per share | D5: 2025 | E5: =D5+1 -> 2026 | F5: =E5+1 -> 2027 | G5: =F5+1 -> 2028 | H5: =G5+1 -> 2029 | I5: =H5+1 -> 2030 | J5: =I5+1 -> 2031 | K5: =J5+1 -> 2032 | L5: =K5+1 -> 2033 | M5: =L5+1 -> 2034 | N5: 2034 | O5: 0.05 | P5: next 5 years
B6: normal case | C6: 0.25 | D6: =C6*(1+$O$5) -> 0.2625 | E6: =D6*(1+$O$5) -> 0.275625 | F6: =E6*(1+$O$5) -> 0.28940625 | G6: =F6*(1+$O$5) -> 0.30387656 | H6: =G6*(1+$O$5) -> 0.31907039 | I6: =H6*(1+$O$6) -> 0.33502391 | J6: =I6*(1+$O$6) -> 0.35177511 | K6: =J6*(1+$O$6) -> 0.36936386 | L6: =K6*(1+$O$6) -> 0.38783205 | M6: =L6*(1+$O$6) -> 0.40722366 | N6: =L6*O8 -> 5.8174808 | O6: 0.05 | P6: 5 to 10 years
C7: =CONCATENATE(R8,O7*100,S8) -> PV(10%) | D7: =D6*(1+$O$7)^($D$5-D5-1)*$I$3 -> 0.11931818 | E7: =E6*(1+$O$7)^($D$5-E5-1)*$I$3 -> 0.11389463 | F7: =F6*(1+$O$7)^($D$5-F5-1)*$I$3 -> 0.1087176 | G7: =G6*(1+$O$7)^($D$5-G5-1)*$I$3 -> 0.10377589 | H7: =H6*(1+$O$7)^($D$5-H5-1)*$I$3 -> 0.099058805 | I7: =I6*(1+$O$7)^($D$5-I5-1)*$I$3 -> 0.094556132 | J7: =J6*(1+$O$7)^($D$5-J5-1)*$I$3 -> 0.090258126 | K7: =K6*(1+$O$7)^($D$5-K5-1)*$I$3 -> 0.086155484 | ... M7: =M6*(1+$O$7)^($D$5-M5-1)*$I$3 -> 0.078501174 | N7: =N6*(1+$O$7)^($D$5-N5-1) -> 2.2428907 | O7: 0.1 | P7: Discount rate
C8: INTRINSIC VALUE | D8: =SUM(D7:N7) -> 3.219366 | O8: 15 | P8: Terminal multiple | R8: PV( | S8: %)
N10: Terminal Value | O10: Growth rate
