Workbook

Sheet DCF Model
A1: MFB.NZ DCF Valuation Model - My Food Bag Group Limited
A2: Gray cells are INPUTS - adjust to see valuation change. Base case = standalone, no takeover premium.
A4: KEY INPUTS
A5: Current Stock Price (NZ$) | B5: 0.29
A6: Shares Outstanding FY26 (M) | B6: 254.956
A7: Cash & Equivalents (NZ$M) | B7: 0.623
A8: Total Debt (NZ$M, excl. lease liabilities) | B8: 2.5
A9: Net Debt (NZ$M) | B9: =B8-B7 -> 0
A10: Reported FCF FY26 (NZ$M, already lease-adjusted) | B10: 8.539
A11: Less: Stock-Based Comp (NZ$M) | B11: 0.514
A12: Base Year Owner FCF (NZ$M) | B12: =B10-B11 -> 0
A13: Annual Share Growth (uncovered SBC dilution) | B13: 0.00695
A15: WACC (base case) | B15: 0.17
A16: Terminal Growth Rate | B16: 0.017
A17: Terminal Cap Multiple (x owner FCF) | B17: 5
A19: GROWTH ASSUMPTIONS (Base Case) | B19: FY2027 | C19: FY2028 | D19: FY2029 | E19: FY2030 | F19: FY2031
A20: Revenue Growth Rate | B20: 0.03 | C20: 0.025 | D20: 0.02 | E20: 0.018 | F20: 0.015
A21: EBITDA Margin | B21: 0.098 | C21: 0.099 | D21: 0.1 | E21: 0.1 | F21: 0.1
A22: SBC % of Revenue | B22: 0.003 | C22: 0.003 | D22: 0.0029 | E22: 0.0028 | F22: 0.0028
A23: D&A % of Revenue | B23: 0.036 | C23: 0.036 | D23: 0.036 | E23: 0.036 | F23: 0.036
A24: CapEx % of Revenue | B24: 0.018 | C24: 0.018 | D24: 0.018 | E24: 0.018 | F24: 0.018
A25: Lease Principal % of Revenue | B25: 0.0135 | C25: 0.013 | D25: 0.0125 | E25: 0.0125 | F25: 0.0125
A26: Working Capital Capture % (of rev change) | B26: 0.06 | C26: 0.06 | D26: 0.06 | E26: 0.06 | F26: 0.06
A27: Cash Tax Rate | B27: 0.28 | C27: 0.28 | D27: 0.28 | E27: 0.28 | F27: 0.28
A29: PROJECTIONS (Component Build)
B30: FY26 Base | C30: FY2027 | D30: FY2028 | E30: FY2029 | F30: FY2030 | G30: FY2031
A31: Revenue | B31: =170.221 -> 0 | C31: =B31*(1+B20) -> 0 | D31: =C31*(1+C20) -> 0 | E31: =D31*(1+D20) -> 0 | F31: =E31*(1+E20) -> 0 | G31: =F31*(1+F20) -> 0
A32: Adj. EBITDA | C32: =C31*C21 -> 0 | D32: =D31*D21 -> 0 | E32: =E31*E21 -> 0 | F32: =F31*F21 -> 0 | G32: =G31*G21 -> 0
A33: Less: SBC | C33: =C31*C22 -> 0 | D33: =D31*D22 -> 0 | E33: =E31*E22 -> 0 | F33: =F31*F22 -> 0 | G33: =G31*G22 -> 0
A34: Owner EBITDA | C34: =C32-C33 -> 0 | D34: =D32-D33 -> 0 | E34: =E32-E33 -> 0 | F34: =F32-F33 -> 0 | G34: =G32-G33 -> 0
A35: Less: D&A | C35: =C31*C23 -> 0 | D35: =D31*D23 -> 0 | E35: =E31*E23 -> 0 | F35: =F31*F23 -> 0 | G35: =G31*G23 -> 0
A36: EBIT | C36: =C34-C35 -> 0 | D36: =D34-D35 -> 0 | E36: =E34-E35 -> 0 | F36: =F34-F35 -> 0 | G36: =G34-G35 -> 0
A37: NOPAT | C37: =C36*(1-C27) -> 0 | D37: =D36*(1-D27) -> 0 | E37: =E36*(1-E27) -> 0 | F37: =F36*(1-F27) -> 0 | G37: =G36*(1-G27) -> 0
A38: Add back: D&A | C38: =C35 -> 0 | D38: =D35 -> 0 | E38: =E35 -> 0 | F38: =F35 -> 0 | G38: =G35 -> 0
A39: Less: CapEx | C39: =C31*C24 -> 0 | D39: =D31*D24 -> 0 | E39: =E31*E24 -> 0 | F39: =F31*F24 -> 0 | G39: =G31*G24 -> 0
A40: Less: Lease Principal Repayment | C40: =C31*C25 -> 0 | D40: =D31*D25 -> 0 | E40: =E31*E25 -> 0 | F40: =F31*F25 -> 0 | G40: =G31*G25 -> 0
A41: +/- Working Capital (on rev change) | C41: =(C31-B31)*C26 -> 0 | D41: =(D31-C31)*D26 -> 0 | E41: =(E31-D31)*E26 -> 0 | F41: =(F31-E31)*F26 -> 0 | G41: =(G31-F31)*G26 -> 0
A42: Owner FCF | C42: =C37+C38-C39-C40+C41 -> 0 | D42: =D37+D38-D39-D40+D41 -> 0 | E42: =E37+E38-E39-E40+E41 -> 0 | F42: =F37+F38-F39-F40+F41 -> 0 | G42: =G37+G38-G39-G40+G41 -> 0
A43: Owner FCF Margin % | C43: =C42/C31 -> 0 | D43: =D42/D31 -> 0 | E43: =E42/E31 -> 0 | F43: =F42/F31 -> 0 | G43: =G42/G31 -> 0
A44: Shares Outstanding (M) | B44: =B6 -> 0 | C44: =B44*(1+$B$13) -> 0 | D44: =C44*(1+$B$13) -> 0 | E44: =D44*(1+$B$13) -> 0 | F44: =E44*(1+$B$13) -> 0 | G44: =F44*(1+$B$13) -> 0
...

Sheet Sensitivity
A1: Sensitivity Analysis
A2: Intrinsic Value by WACC & Terminal Growth (base case; terminal cap usually binds)
A4: WACC \ Term G | B4: 0.007 | C4: 0.012 | D4: 0.017 | E4: 0.022 | F4: 0.027
A5: 0.15 | B5: {=(SUMPRODUCT('DCF Model'!$C$42:$G$42,1/(1+0.15)^{1,2,3,4,5})+MIN('DCF Model'!$G$42*(1+0.007)/(0.15-0.007),'DCF Model'!$B$17*'DCF Model'!$G$42)/(1+0.15)^5-'DCF Model'!$B$9)/'DCF Model'!$G$44} -> 0 | C5: {=(SUMPRODUCT('DCF Model'!$C$42:$G$42,1/(1+0.15)^{1,2,3,4,5})+MIN('DCF Model'!$G$42*(1+0.012)/(0.15-0.012),'DCF Model'!$B$17*'DCF Model'!$G$42)/(1+0.15)^5-'DCF Model'!$B$9)/'DCF Model'!$G$44} -> 0 | D5: {=(SUMPRODUCT('DCF Model'!$C$42:$G$42,1/(1+0.15)^{1,2,3,4,5})+MIN('DCF Model'!$G$42*(1+0.017)/(0.15-0.017),'DCF Model'!$B$17*'DCF Model'!$G$42)/(1+0.15)^5-'DCF Model'!$B$9)/'DCF Model'!$G$44} -> 0 | E5: {=(SUMPRODUCT('DCF Model'!$C$42:$G$42,1/(1+0.15)^{1,2,3,4,5})+MIN('DCF Model'!$G$42*(1+0.022)/(0.15-0.022),'DCF Model'!$B$17*'DCF Model'!$G$42)/(1+0.15)^5-'DCF Model'!$B$9)/'DCF Model'!$G$44} -> 0 | F5: {=(SUMPRODUCT('DCF Model'!$C$42:$G$42,1/(1+0.15)^{1,2,3,4,5})+MIN('DCF Model'!$G$42*(1+0.027)/(0.15-0.027),'DCF Model'!$B$17*'DCF Model'!$G$42)/(1+0.15)^5-'DCF Model'!$B$9)/'DCF Model'!$G$44} -> 0
A6: 0.16 | B6: {=(SUMPRODUCT('DCF Model'!$C$42:$G$42,1/(1+0.16)^{1,2,3,4,5})+MIN('DCF Model'!$G$42*(1+0.007)/(0.16-0.007),'DCF Model'!$B$17*'DCF Model'!$G$42)/(1+0.16)^5-'DCF Model'!$B$9)/'DCF Model'!$G$44} -> 0 | C6: {=(SUMPRODUCT('DCF Model'!$C$42:$G$42,1/(1+0.16)^{1,2,3,4,5})+MIN('DCF Model'!$G$42*(1+0.012)/(0.16-0.012),'DCF Model'!$B$17*'DCF Model'!$G$42)/(1+0.16)^5-'DCF Model'!$B$9)/'DCF Model'!$G$44} -> 0 | D6: {=(SUMPRODUCT('DCF Model'!$C$42:$G$42,1/(1+0.16)^{1,2,3,4,5})+MIN('DCF Model'!$G$42*(1+0.017)/(0.16-0.017),'DCF Model'!$B$17*'DCF Model'!$G$42)/(1+0.16)^5-'DCF Model'!$B$9)/'DCF Model'!$G$44} -> 0 | E6: {=(SUMPRODUCT('DCF Model'!$C$42:$G$42,1/(1+0.16)^{1,2,3,4,5})+MIN('DCF Model'!$G$42*(1+0.022)/(0.16-0.022),'DCF Model'!$B$17*'DCF Model'!$G$42)/(1+0.16)^5-'DCF Model'!$B$9)/'DCF Model'!$G$44} -> 0 | F6: {=(SUMPRODUCT('DCF Model'!$C$42:$G$42,1/(1+0.16)^{1,2,3,4,5})+MIN('DCF Model'!$G$42*(1+0.027)/(0.16-0.027),'DCF Model'!$B$17*'DCF Model'!$G$42)/(1+0.16)^5-'DCF Model'!$B$9)/'DCF Model'!$G$44} -> 0
A7: 0.17 | B7: {=(SUMPRODUCT('DCF Model'!$C$42:$G$42,1/(1+0.17)^{1,2,3,4,5})+MIN('DCF Model'!$G$42*(1+0.007)/(0.17-0.007),'DCF Model'!$B$17*'DCF Model'!$G$42)/(1+0.17)^5-'DCF Model'!$B$9)/'DCF Model'!$G$44} -> 0 | C7: {=(SUMPRODUCT('DCF Model'!$C$42:$G$42,1/(1+0.17)^{1,2,3,4,5})+MIN('DCF Model'!$G$42*(1+0.012)/(0.17-0.012),'DCF Model'!$B$17*'DCF Model'!$G$42)/(1+0.17)^5-'DCF Model'!$B$9)/'DCF Model'!$G$44} -> 0 | D7: {=(SUMPRODUCT('DCF Model'!$C$42:$G$42,1/(1+0.17)^{1,2,3,4,5})+MIN('DCF Model'!$G$42*(1+0.017)/(0.17-0.017),'DCF Model'!$B$17*'DCF Model'!$G$42)/(1+0.17)^5-'DCF Model'!$B$9)/'DCF Model'!$G$44} -> 0 | E7: {=(SUMPRODUCT('DCF Model'!$C$42:$G$42,1/(1+0.17)^{1,2,3,4,5})+MIN('DCF Model'!$G$42*(1+0.022)/(0.17-0.022),'DCF Model'!$B$17*'DCF Model'!$G$42)/(1+0.17)^5-'DCF Model'!$B$9)/'DCF Model'!$G$44} -> 0 | F7: {=(SUMPRODUCT('DCF Model'!$C$42:$G$42,1/(1+0.17)^{1,2,3,4,5})+MIN('DCF Model'!$G$42*(1+0.027)/(0.17-0.027),'DCF Model'!$B$17*'DCF Model'!$G$42)/(1+0.17)^5-'DCF Model'!$B$9)/'DCF Model'!$G$44} -> 0
A8: 0.18 | B8: {=(SUMPRODUCT('DCF Model'!$C$42:$G$42,1/(1+0.18)^{1,2,3,4,5})+MIN('DCF Model'!$G$42*(1+0.007)/(0.18-0.007),'DCF Model'!$B$17*'DCF Model'!$G$42)/(1+0.18)^5-'DCF Model'!$B$9)/'DCF Model'!$G$44} -> 0 | C8: {=(SUMPRODUCT('DCF Model'!$C$42:$G$42,1/(1+0.18)^{1,2,3,4,5})+MIN('DCF Model'!$G$42*(1+0.012)/(0.18-0.012),'DCF Model'!$B$17*'DCF Model'!$G$42)/(1+0.18)^5-'DCF Model'!$B$9)/'DCF Model'!$G$44} -> 0 | D8: {=(SUMPRODUCT('DCF Model'!$C$42:$G$42,1/(1+0.18)^{1,2,3,4,5})+MIN('DCF Model'!$G$42*(1+0.017)/(0.18-0.017),'DCF Model'!$B$17*'DCF Model'!$G$42)/(1+0.18)^5-'DCF Model'!$B$9)/'DCF Model'!$G$44} -> 0 | E8: {=(SUMPRODUCT('DCF Model'!$C$42:$G$42,1/(1+0.18)^{1,2,3,4,5})+MIN('DCF Model'!$G$42*(1+0.022)/(0.18-0.022),'DCF Model'!$B$17*'DCF Model'!$G$42)/(1+0.18)^5-'DCF Model'!$B$9)/'DCF Model'!$G$44} -> 0 | F8: {=(SUMPRODUCT('DCF Model'!$C$42:$G$42,1/(1+0.18)^{1,2,3,4,5})+MIN('DCF Model'!$G$42*(1+0.027)/(0.18-0.027),'DCF Model'!$B$17*'DCF Model'!$G$42)/(1+0.18)^5-'DCF Model'!$B$9)/'DCF Model'!$G$44} -> 0
A9: 0.19 | B9: {=(SUMPRODUCT('DCF Model'!$C$42:$G$42,1/(1+0.19)^{1,2,3,4,5})+MIN('DCF Model'!$G$42*(1+0.007)/(0.19-0.007),'DCF Model'!$B$17*'DCF Model'!$G$42)/(1+0.19)^5-'DCF Model'!$B$9)/'DCF Model'!$G$44} -> 0 | C9: {=(SUMPRODUCT('DCF Model'!$C$42:$G$42,1/(1+0.19)^{1,2,3,4,5})+MIN('DCF Model'!$G$42*(1+0.012)/(0.19-0.012),'DCF Model'!$B$17*'DCF Model'!$G$42)/(1+0.19)^5-'DCF Model'!$B$9)/'DCF Model'!$G$44} -> 0 | D9: {=(SUMPRODUCT('DCF Model'!$C$42:$G$42,1/(1+0.19)^{1,2,3,4,5})+MIN('DCF Model'!$G$42*(1+0.017)/(0.19-0.017),'DCF Model'!$B$17*'DCF Model'!$G$42)/(1+0.19)^5-'DCF Model'!$B$9)/'DCF Model'!$G$44} -> 0 | E9: {=(SUMPRODUCT('DCF Model'!$C$42:$G$42,1/(1+0.19)^{1,2,3,4,5})+MIN('DCF Model'!$G$42*(1+0.022)/(0.19-0.022),'DCF Model'!$B$17*'DCF Model'!$G$42)/(1+0.19)^5-'DCF Model'!$B$9)/'DCF Model'!$G$44} -> 0 | F9: {=(SUMPRODUCT('DCF Model'!$C$42:$G$42,1/(1+0.19)^{1,2,3,4,5})+MIN('DCF Model'!$G$42*(1+0.027)/(0.19-0.027),'DCF Model'!$B$17*'DCF Model'!$G$42)/(1+0.19)^5-'DCF Model'!$B$9)/'DCF Model'!$G$44} -> 0
A11: Note: FCF path (C42:G42) held at base-case assumptions; only WACC and
A12: terminal growth vary here. Terminal cap multiple stays at base $B$17=5.0x.

Sheet Historical
A1: Historical Growth Rates & Multiples
A3: Metric | B3: 3-Year CAGR | C3: 5-Year CAGR
A4: Revenue | B4: -0.0105 | C4: -0.0225
A5: Equity (Book Value) | B5: 0.0769 | C5: 0.0597
A6: FCF (owner basis) | B6: 0.655 | C6: -0.1739
A7: Net Income | B7: -0.0521 | C7: 0.2232
A9: Selected Growth Rate: | B9: 0.0243
A10: Source: | B10: revenue_fy24_fy26_cagr (post-COVID stabilisation trend)
A11: Warning:
A12: Standard 3yr/5yr CAGRs computed from FY2021 or FY2022 start-years are NEGATIVE or wildly distorted (FCF 5yr -17.4%, NI 5yr +22.3% from a depressed FY2021 base, revenue 5yr -2.25%) because FY2021-22 was a COVID-lockdown demand spike (EBITDA $34.2m FY22 vs $16.4m FY26, ~2.1x). None of these headline CAGRs are used as the growth driver. Instead the model anchors to the FY2024->FY2026 stabilisation/recovery revenue CAGR of 2.43% as the starting point, fading further toward a 1.5% terminal rate given structural category headwinds (HelloFresh NZ reach 72%->84% of population, active customers still ~20-25% below 2021 peak, supermarket duopoly encroachment). Equity CAGR (7.69% 3yr / 5.97% 5yr) is NOT used as the primary growth driver here because the equity build reflects retained-earnings/dividend-payout mechanics on a shrunken FY2023 base, not underlying revenue-generating capacity in a competitively squeezed category.
A14: Historical Trading Multiples (FY-end price, post-COVID FY23-26)
A16: FY | B16: Price | C16: EV/EBITDA | D16: P/E | E16: P/B | F16: P/S
A18: FY2023 | B18: 0.23 | C18: 3.91 | D18: 7.11 | E18: 0.96 | F18: 0.32
A19: FY2024 | B19: 0.132 | C19: 2.76 | D19: 5.38 | E19: 0.5 | F19: 0.2
A20: FY2025 | B20: 0.189 | C20: 3.38 | D20: 7.47 | E20: 0.69 | F20: 0.29
A21: FY2026 | B21: 0.21 | C21: 3.39 | D21: 8.01 | E21: 0.74 | F21: 0.31
A22: FY2022 (excluded - COVID/IPO bubble) | B22: 0.93 | C22: 6.52 | D22: 11.27 | E22: 3.37 | F22: 1.16
A24: Current (13-Aug-2026) | B24: 0.29 | C24: 4.63 | D24: 11.06 | E24: 1.02 | F24: 0.43
A26: Sanity Check Verdict: | B26: PASS
A27: PASS - no fix required. Every multiple implied by the base intrinsic value ($0.1854) falls inside or immediately adjacent to the post-COVID (FY23-26) historical trading range: implied P/E 7.07x vs historical 5.38x-8.01x; implied P/B 0.65x vs historical 0.50x-0.96x; implied P/S 0.28x vs historical 0.20x-0.32x; implied EV/EBITDA 3.00x vs historical 2.76x-3.91x. The base case values MFB at a multiple the market has actually paid for the standalone business post-COVID, not at an unprecedented re-rating and not at the IPO-hype multiples. The gap between the base IV and the current $0.29 price is explained by the current price sitting ABOVE the historical multiple range (P/E 11.06x, EV/EBITDA 4.63x, EV/OwnerFCF 9.45x), consistent with an unresolved M&A speculation premium rather than a standalone fundamentals re-rating.

Sheet FCF Quality
A1: FCF Quality - Reported vs Owner FCF Reconciliation
A2: FreeCashFlow in the Metrics CSV is already IFRS16 lease-adjusted (OCF - CapEx - lease principal)
A4: NZ$ millions | B4: FY2021 | C4: FY2022 | D4: FY2023 | E4: FY2024 | F4: FY2025 | G4: FY2026
A5: Operating Cash Flow | B5: 24.064 | C5: 29.534 | D5: 9.758 | E5: 9.799 | F5: 13.227 | G5: 13.532
A6: Less: CapEx | B6: 0.674 | C6: 2.879 | D6: 7.747 | E6: 3.848 | F6: 3.17 | G6: 2.872
A7: Less: Lease Principal Repayment | E7: 2.451 | F7: 2.404 | G7: 2.121
A8: = Reported (Owner) FCF per CSV | B8: 21.164 | C8: 24.098 | D8: -0.592 | E8: 3.5 | F8: 7.653 | G8: 8.539
A9: Less: Stock-Based Comp | B9: 0.305 | C9: 0 | D9: 0.266 | E9: 0.57 | F9: 0.52 | G9: 0.514
A10: = Owner FCF (SBC-adjusted) | B10: 20.859 | C10: 24.098 | D10: -0.858 | E10: 2.93 | F10: 7.133 | G10: 8.025
A12: Reported FCF Margin % | B12: 0.11097478 | C12: 0.12424596 | D12: -0.0033694947 | E12: 0.021573643 | F12: 0.047211015 | G12: 0.050164198
A13: Owner FCF Margin % | B13: 0.10937549 | C13: 0.12424596 | D13: -0.0048834906 | E13: 0.018060221 | F13: 0.044003159 | G13: 0.047144594
A15: Memo: EBITDA (NZ$M) | B15: 15.5 | C15: 34.2 | D15: 18.166 | E15: 16.031 | F15: 16.073 | G15: 16.367
A16: Memo: EBITDA Margin % | B16: 0.081275235 | C16: 0.17633047 | D16: 0.10339568 | E16: 0.09881345 | F16: 0.099153619 | G16: 0.096151474
A18: Memo: Cash Tax Rate (effective) | G18: 0.256
A19: FY2026 effective tax rate 25.6% vs 28% NZ statutory - no abnormal one-off, no ramp needed.
A21: IMPORTANT NOTES
A22: FY2022 EBITDA ($34.2m) is a verified COVID-lockdown demand spike, ~2.1x the current run-rate.
A23: Never used as a growth, margin, or exit-multiple anchor anywhere in this model.
A25: Lease principal repayment (~1.3-1.5% of revenue) is deducted as a real cash cost in the
A26: owner FCF definition used throughout - this ties exactly to the company reported FCF
A27: (verified for FY2024, FY2025 and FY2026 cash flow statements).
A29: SBC is small (~0.3% of revenue) but real; deducted separately since it is a non-cash
A30: add-back inside OCF, not already stripped from the lease-adjusted reported FCF figure.
A32: Interest income (FY26: $0.088m) is immaterial given MFB holds net DEBT (not net cash)
A33: of $1.877m, so no interest-income strip is required.

Sheet Model_Info
A1: Model Provenance & Methodology Notes
A3: Ticker | B3: MFB.NZ - My Food Bag Group Limited
A4: Built by | B4: Claude (DCF valuation agent), research-stock workflow
A5: Valuation date | B5: 2026-08-13
A6: Share price date/source | B6: 13-Aug-2026, live Yahoo Finance quote (regularMarketTime confirmed same-day, actively trading)
A7: Data vintage | B7: FY2026 Annual Report (year ended 31-Mar-2026), published ~20-May-2026; H1 FY2026 interim (30-Sep-2025)
A8: Fiscal year end | B8: 31 March
A9: Currency / units | B9: NZD, millions
A11: METHODOLOGY CHOICES
A12: Base FCF | B12: FreeCashFlow per Metrics CSV (OCF - CapEx - IFRS16 lease principal repayment) less SBC = owner FCF. Verified to tie exactly to FY2024/25/26 cash flow statements.
A13: Net debt definition | B13: Total Debt (2.5) - Cash (0.623) = 1.877, EXCLUDING capitalised lease liabilities (matches company-reported "$1.9m net debt"). Deliberate: owner FCF already deducts the annual lease principal as a cash cost, so adding the lease liability to net debt would double-count the same obligation.
A14: SBC treatment | B14: Deducted once from FCF (0.514 FY26, ~0.3% of revenue). No buybacks exist, so 100% of SBC is uncovered dilution; shares grow ~0.70%/yr through the projection.
A15: Growth driver | B15: FY2024->FY2026 revenue stabilisation CAGR (2.43%), NOT the 3yr/5yr headline CAGRs, which are negative/distorted by the FY2021-22 COVID-era peak. Base case fades further to 1.5% terminal.
A16: FY2022 exclusion | B16: FY2022 EBITDA ($34.2m, ~2.1x normal run-rate) is a verified real but non-repeatable COVID lockdown demand spike. Excluded from all growth, margin and multiple anchors throughout this model.
A17: WACC build (base 17.0%) | B17: NZ small-cap base 11.5% + micro-cap illiquidity 2.25% + single-country/category concentration 1.25% + competitive/no-moat/churn 1.75%. See DCF JSON assumptions.base.wacc_rationale for full detail.
A18: Terminal value | B18: Lower of Gordon Growth and a 5.0x (base) / 6.0x (bull) / 3.5x (bear) cap on EV/owner-FCF, anchored to the post-COVID (FY23-26) historical EV/EBITDA trading range of 2.76x-3.91x (average 3.36x), excluding the FY2021-22 IPO-bubble years. The cap binds in ALL three scenarios across the full sensitivity range tested.
A19: Strategic review handling | B19: Base case = standalone DCF, NO takeover premium. Bull case reflects a modest trade-sale exit multiple uplift. Bear case explicitly models the review concluding with no transaction and the ~17% announcement-driven share price premium unwinding. Probability weights: 25% bull / 45% base / 30% bear - deliberately not presuming a deal.
A20: Sanity check | B20: PASS - base-case implied P/E (7.07x), P/B (0.65x), P/S (0.28x) and EV/EBITDA (3.00x) all fall within the post-COVID historical trading range. Current market multiples sit above this range, consistent with an unresolved M&A speculation premium.
A22: WHAT TO REFRESH NEXT
A23: After H1 FY2027 results (~Nov-2026) | B23: Update revenue/EBITDA trajectory, active customer count, and any strategic review update. Re-check whether the review has concluded (deal or no-deal) and re-weight scenarios accordingly.
A24: After any strategic review outcome | B24: If a transaction is announced, re-base the valuation entirely around deal terms rather than a standalone DCF. If the review concludes with no transaction, re-check whether the share price gives back the speculation premium toward $0.21-0.24 as the bear case anticipates.
A25: Ongoing | B25: Re-verify SBC, lease principal and net debt inputs each year from the cash flow statement; re-run the FY-end EV/EBITDA history with the new year added and the oldest excluded year re-assessed.
A27: CELL COLOUR CONVENTIONS
A28: Gray cells | B28: Direct inputs - safe to overtype/adjust; all downstream cells are formulas that recalculate automatically.
A29: Green cells | B29: Key output results (Intrinsic Value/Share, Entry Price).
A30: White/unshaded cells | B30: Formulas - do not hardcode over these without understanding the dependency chain.
A32: STALENESS WARNING | B32: All figures in this model reflect data available as of 13-Aug-2026. Share prices, financial results, and especially the strategic review status WILL change. Do not rely on this file without checking for newer filings/announcements first.
