Workbook

Sheet DCF Model
A1: NetEase, Inc. (NTES) - Discounted Cash Flow Model
A2: As of December 15, 2025 | Currency: USD (millions unless noted)
A4: COMPANY OVERVIEW
A5: Company: | B5: NetEase, Inc. | C5: Ticker: | D5: NTES
A6: Exchange: | B6: NASDAQ | C6: Industry: | D6: Gaming / Technology
A7: Headquarters: | B7: Hangzhou, China | C7: Fiscal Year End: | D7: December
A9: KEY ASSUMPTIONS
A10: Risk-Free Rate: | B10: 0.0425 | C10: 10-Year US Treasury
A11: Equity Risk Premium: | B11: 0.055 | C11: Historical market premium
A12: Beta (Levered): | B12: 0.85 | C12: Industry average adjusted
A13: Cost of Equity: | B13: =B10+B11*B12 -> 0.08925 | C13: CAPM Formula
A14: Pre-Tax Cost of Debt: | B14: 0.045 | C14: Estimated borrowing rate
A15: Tax Rate: | B15: 0.15 | C15: China effective rate
A16: After-Tax Cost of Debt: | B16: =B14*(1-B15) -> 0.03825 | C16: Post-tax debt cost
A17: Debt Weight: | B17: 0.12 | C17: Target capital structure
A18: Equity Weight: | B18: =1-B17 -> 0.88 | C18: Target capital structure
A19: WACC: | B19: =B13*B18+B16*B17 -> 0.08313 | C19: Weighted Average Cost of Capital
A20: Terminal Growth Rate: | B20: 0.025 | C20: Long-term GDP growth
A23: HISTORICAL FINANCIALS
B24: 2020 | C24: 2021 | D24: 2022 | E24: 2023 | F24: 2024 | G24: CAGR
A25: Revenue | B25: 11260 | C25: 13690 | D25: 13840 | E25: 14573 | F25: 14425 | G25: =POWER(F25/B25,1/4)-1 -> 0.063884197
A26: YoY Growth | C26: =C25/B25-1 -> 0.21580817 | D26: =D25/C25-1 -> 0.010956903 | E26: =E25/D25-1 -> 0.052962428 | F26: =F25/E25-1 -> -0.010155768
A27: Gross Profit | B27: 5975 | C27: 7371 | D27: 7650 | E27: 8882 | F27: 9040
A28: Gross Margin | B28: =B27/B25 -> 0.53063943 | C28: =C27/C25 -> 0.53842221 | D28: =D27/D25 -> 0.55274566 | E28: =E27/E25 -> 0.60948329 | F28: =F27/F25 -> 0.62668977
A29: Operating Income | B29: 2420 | C29: 2850 | D29: 2915 | E29: 3985 | F29: 4150
A30: Operating Margin | B30: =B29/B25 -> 0.21492007 | C30: =C29/C25 -> 0.20818115 | D30: =D29/D25 -> 0.21062139 | E30: =E29/E25 -> 0.2734509 | F30: =F29/F25 -> 0.28769497
A31: Net Income | B31: 1837 | C31: 2646 | D31: 2949 | E31: 4143 | F31: 4520
A32: Net Margin | B32: =B31/B25 -> 0.16314387 | C32: =C31/C25 -> 0.19327977 | D32: =D31/D25 -> 0.21307803 | E32: =E31/E25 -> 0.28429287 | F32: =F31/F25 -> 0.31334489
A33: Free Cash Flow | B33: 3655 | C33: 3671 | D33: 3719 | E33: 4654 | F33: 4800 | G33: =POWER(F33/B33,1/4)-1 -> 0.070504418
A34: FCF Margin | B34: =B33/B25 -> 0.32460036 | C34: =C33/C25 -> 0.26815194 | D34: =D33/D25 -> 0.26871387 | E34: =E33/E25 -> 0.31935772 | F34: =F33/F25 -> 0.33275563
A37: REVENUE & FCF PROJECTIONS
B38: 2024A | C38: 2025E | D38: 2026E | E38: 2027E | F38: 2028E | G38: 2029E | H38: 2030E | I38: 2031E | J38: 2032E | K38: 2033E
A39: Revenue Growth Rate | B39: 14425 | C39: 0.08 | D39: 0.075 | E39: 0.07 | F39: 0.065 | G39: 0.06 | H39: 0.055 | I39: 0.05 | J39: 0.045 | K39: 0.04
A40: Revenue | B40: 14425 | C40: =B40*(1+C39) -> 15579 | D40: =C40*(1+D39) -> 16747.425 | E40: =D40*(1+E39) -> 17919.745 | F40: =E40*(1+F39) -> 19084.528 | G40: =F40*(1+G39) -> 20229.6 | H40: =G40*(1+H39) -> 21342.228 | I40: =H40*(1+I39) -> 22409.339 | J40: =I40*(1+J39) -> 23417.759 | K40: =J40*(1+K39) -> 24354.47
A41: FCF Margin | B41: =F33/F25 -> 0.33275563 | C41: 0.335 | D41: 0.34 | E41: 0.345 | F41: 0.35 | G41: 0.355 | H41: 0.36 | I41: 0.36 | J41: 0.36 | K41: 0.36
A42: Free Cash Flow | B42: 4800 | C42: =C40*C41 -> 5218.965 | D42: =D40*D41 -> 5694.1245 | E42: =E40*E41 -> 6182.3119 | F42: =F40*F41 -> 6679.5849 | G42: =G40*G41 -> 7181.5079 | H42: =H40*H41 -> 7683.202 | I42: =I40*I41 -> 8067.3621 | J42: =J40*J41 -> 8430.3934 | K42: =K40*K41 -> 8767.6092
A45: DCF VALUATION
A46: Year | C46: 1 | D46: 2 | E46: 3 | F46: 4 | G46: 5 | H46: 6 | I46: 7 | J46: 8 | K46: 9
A47: Discount Factor | B47: WACC: | C47: =1/POWER(1+$B$19,1) -> 0.92325021 | D47: =1/POWER(1+$B$19,2) -> 0.85239095 | E47: =1/POWER(1+$B$19,3) -> 0.78697012 | F47: =1/POWER(1+$B$19,4) -> 0.72657033 | G47: =1/POWER(1+$B$19,5) -> 0.67080621 | H47: =1/POWER(1+$B$19,6) -> 0.61932198 | I47: =1/POWER(1+$B$19,7) -> 0.57178914 | J47: =1/POWER(1+$B$19,8) -> 0.52790445 | K47: =1/POWER(1+$B$19,9) -> 0.48738789
A48: PV of FCF | C48: =C42*C47 -> 4818.4105 | D48: =D42*D47 -> 4853.6202 | E48: =E42*E47 -> 4865.2948 | F48: =F42*F47 -> 4853.1882 | G48: =G42*G47 -> 4817.4001 | H48: =H42*H47 -> 4758.3759 | I48: =I42*I47 -> 4612.8301 | J48: =J42*J47 -> 4450.4422 | K48: =K42*K47 -> 4273.2265
...

Sheet Sensitivity Analysis
A1: SENSITIVITY ANALYSIS - IMPLIED SHARE PRICE
A3: WACC vs Terminal Growth Rate
A4: WACC → | B4: 0.065 | C4: 0.07 | D4: 0.075 | E4: 0.08 | F4: 0.085 | G4: 0.09 | H4: 0.095
A5: 0.015 | B5: =('DCF Model'!B50+'DCF Model'!K42*(1+A5)/(B4-A5)*'DCF Model'!K47+'DCF Model'!B62+'DCF Model'!B63)/'DCF Model'!B65 -> 270.7536 | C5: =('DCF Model'!B50+'DCF Model'!K42*(1+A5)/(C4-A5)*'DCF Model'!K47+'DCF Model'!B62+'DCF Model'!B63)/'DCF Model'!B65 -> 258.35415 | D5: =('DCF Model'!B50+'DCF Model'!K42*(1+A5)/(D4-A5)*'DCF Model'!K47+'DCF Model'!B62+'DCF Model'!B63)/'DCF Model'!B65 -> 248.02129 | E5: =('DCF Model'!B50+'DCF Model'!K42*(1+A5)/(E4-A5)*'DCF Model'!K47+'DCF Model'!B62+'DCF Model'!B63)/'DCF Model'!B65 -> 239.27809 | F5: =('DCF Model'!B50+'DCF Model'!K42*(1+A5)/(F4-A5)*'DCF Model'!K47+'DCF Model'!B62+'DCF Model'!B63)/'DCF Model'!B65 -> 231.78392 | G5: =('DCF Model'!B50+'DCF Model'!K42*(1+A5)/(G4-A5)*'DCF Model'!K47+'DCF Model'!B62+'DCF Model'!B63)/'DCF Model'!B65 -> 225.28897 | H5: =('DCF Model'!B50+'DCF Model'!K42*(1+A5)/(H4-A5)*'DCF Model'!K47+'DCF Model'!B62+'DCF Model'!B63)/'DCF Model'!B65 -> 219.6059
A6: 0.02 | B6: =('DCF Model'!B50+'DCF Model'!K42*(1+A6)/(B4-A6)*'DCF Model'!K47+'DCF Model'!B62+'DCF Model'!B63)/'DCF Model'!B65 -> 286.65502 | C6: =('DCF Model'!B50+'DCF Model'!K42*(1+A6)/(C4-A6)*'DCF Model'!K47+'DCF Model'!B62+'DCF Model'!B63)/'DCF Model'!B65 -> 271.42549 | D6: =('DCF Model'!B50+'DCF Model'!K42*(1+A6)/(D4-A6)*'DCF Model'!K47+'DCF Model'!B62+'DCF Model'!B63)/'DCF Model'!B65 -> 258.96496 | E6: =('DCF Model'!B50+'DCF Model'!K42*(1+A6)/(E4-A6)*'DCF Model'!K47+'DCF Model'!B62+'DCF Model'!B63)/'DCF Model'!B65 -> 248.58119 | F6: =('DCF Model'!B50+'DCF Model'!K42*(1+A6)/(F4-A6)*'DCF Model'!K47+'DCF Model'!B62+'DCF Model'!B63)/'DCF Model'!B65 -> 239.79493 | G6: =('DCF Model'!B50+'DCF Model'!K42*(1+A6)/(G4-A6)*'DCF Model'!K47+'DCF Model'!B62+'DCF Model'!B63)/'DCF Model'!B65 -> 232.26384 | H6: =('DCF Model'!B50+'DCF Model'!K42*(1+A6)/(H4-A6)*'DCF Model'!K47+'DCF Model'!B62+'DCF Model'!B63)/'DCF Model'!B65 -> 225.7369
A7: 0.025 | B7: =('DCF Model'!B50+'DCF Model'!K42*(1+A7)/(B4-A7)*'DCF Model'!K47+'DCF Model'!B62+'DCF Model'!B63)/'DCF Model'!B65 -> 306.53179 | C7: =('DCF Model'!B50+'DCF Model'!K42*(1+A7)/(C4-A7)*'DCF Model'!K47+'DCF Model'!B62+'DCF Model'!B63)/'DCF Model'!B65 -> 287.40156 | D7: =('DCF Model'!B50+'DCF Model'!K42*(1+A7)/(D4-A7)*'DCF Model'!K47+'DCF Model'!B62+'DCF Model'!B63)/'DCF Model'!B65 -> 272.09738 | E7: =('DCF Model'!B50+'DCF Model'!K42*(1+A7)/(E4-A7)*'DCF Model'!K47+'DCF Model'!B62+'DCF Model'!B63)/'DCF Model'!B65 -> 259.57577 | F7: =('DCF Model'!B50+'DCF Model'!K42*(1+A7)/(F4-A7)*'DCF Model'!K47+'DCF Model'!B62+'DCF Model'!B63)/'DCF Model'!B65 -> 249.1411 | G7: =('DCF Model'!B50+'DCF Model'!K42*(1+A7)/(G4-A7)*'DCF Model'!K47+'DCF Model'!B62+'DCF Model'!B63)/'DCF Model'!B65 -> 240.31177 | H7: =('DCF Model'!B50+'DCF Model'!K42*(1+A7)/(H4-A7)*'DCF Model'!K47+'DCF Model'!B62+'DCF Model'!B63)/'DCF Model'!B65 -> 232.74376
A8: 0.03 | B8: =('DCF Model'!B50+'DCF Model'!K42*(1+A8)/(B4-A8)*'DCF Model'!K47+'DCF Model'!B62+'DCF Model'!B63)/'DCF Model'!B65 -> 332.08764 | C8: =('DCF Model'!B50+'DCF Model'!K42*(1+A8)/(C4-A8)*'DCF Model'!K47+'DCF Model'!B62+'DCF Model'!B63)/'DCF Model'!B65 -> 307.37165 | D8: =('DCF Model'!B50+'DCF Model'!K42*(1+A8)/(D4-A8)*'DCF Model'!K47+'DCF Model'!B62+'DCF Model'!B63)/'DCF Model'!B65 -> 288.14811 | E8: =('DCF Model'!B50+'DCF Model'!K42*(1+A8)/(E4-A8)*'DCF Model'!K47+'DCF Model'!B62+'DCF Model'!B63)/'DCF Model'!B65 -> 272.76927 | F8: =('DCF Model'!B50+'DCF Model'!K42*(1+A8)/(F4-A8)*'DCF Model'!K47+'DCF Model'!B62+'DCF Model'!B63)/'DCF Model'!B65 -> 260.18658 | G8: =('DCF Model'!B50+'DCF Model'!K42*(1+A8)/(G4-A8)*'DCF Model'!K47+'DCF Model'!B62+'DCF Model'!B63)/'DCF Model'!B65 -> 249.70101 | H8: =('DCF Model'!B50+'DCF Model'!K42*(1+A8)/(H4-A8)*'DCF Model'!K47+'DCF Model'!B62+'DCF Model'!B63)/'DCF Model'!B65 -> 240.82861
A9: 0.035 | B9: =('DCF Model'!B50+'DCF Model'!K42*(1+A9)/(B4-A9)*'DCF Model'!K47+'DCF Model'!B62+'DCF Model'!B63)/'DCF Model'!B65 -> 366.16211 | C9: =('DCF Model'!B50+'DCF Model'!K42*(1+A9)/(C4-A9)*'DCF Model'!K47+'DCF Model'!B62+'DCF Model'!B63)/'DCF Model'!B65 -> 333.04749 | D9: =('DCF Model'!B50+'DCF Model'!K42*(1+A9)/(D4-A9)*'DCF Model'!K47+'DCF Model'!B62+'DCF Model'!B63)/'DCF Model'!B65 -> 308.21152 | E9: =('DCF Model'!B50+'DCF Model'!K42*(1+A9)/(E4-A9)*'DCF Model'!K47+'DCF Model'!B62+'DCF Model'!B63)/'DCF Model'!B65 -> 288.89465 | F9: =('DCF Model'!B50+'DCF Model'!K42*(1+A9)/(F4-A9)*'DCF Model'!K47+'DCF Model'!B62+'DCF Model'!B63)/'DCF Model'!B65 -> 273.44116 | G9: =('DCF Model'!B50+'DCF Model'!K42*(1+A9)/(G4-A9)*'DCF Model'!K47+'DCF Model'!B62+'DCF Model'!B63)/'DCF Model'!B65 -> 260.79739 | H9: =('DCF Model'!B50+'DCF Model'!K42*(1+A9)/(H4-A9)*'DCF Model'!K47+'DCF Model'!B62+'DCF Model'!B63)/'DCF Model'!B65 -> 250.26092
A12: Revenue Growth Rate Sensitivity
A14: Base Case Implied Price: | B14: ='DCF Model'!B66 -> 252.83354
A16: Bear Case (-2% growth)
A17: Base Case
A18: Bull Case (+2% growth)

Sheet Business Overview
A1: NetEase, Inc. (NTES) - Business Overview
A3: BUSINESS SEGMENTS
A4: Segment | B4: 2024 Revenue | C4: % of Total | D4: YoY Growth | E4: Key Products
A5: Games & Related Services | B5: 11450 | C5: 0.794 | D5: 0.015 | E5: Marvel Rivals, Fantasy Westward Journey, Identity V
A6: Youdao (Education) | B6: 770 | C6: 0.053 | D6: -0.095 | E6: AI learning services, Youdao Dictionary
A7: Cloud Music | B7: 1100 | C7: 0.076 | D7: -0.053 | E7: NetEase Cloud Music streaming platform
A8: Innovative Businesses | B8: 1105 | C8: 0.077 | D8: -0.17 | E8: E-commerce (Yanxuan), advertising
A11: KEY INVESTMENT HIGHLIGHTS
A12: 1. Dominant position in China's gaming market with strong IP portfolio
A13: 2. Marvel Rivals success (40M+ users) demonstrates global expansion capability
A14: 3. Strong cash position ($54B+) with low debt provides financial flexibility
A15: 4. Consistent profitability with 31%+ net margins
A16: 5. Active shareholder returns through dividends (~2% yield) and buybacks ($1.9B program)
A17: 6. Blizzard partnership restored (World of Warcraft, Hearthstone)
A18: 7. R&D intensity of 17%+ supports future game pipeline
A21: KEY RISKS
A22: 1. Regulatory environment in China (gaming restrictions, content review)
A23: 2. Competition from Tencent and global gaming companies
A24: 3. Currency risk (RMB/USD exposure)
... A27: 6. Slowing growth in non-gaming segments (Youdao, Cloud Music)

Sheet Stress Test
A1: NTES DCF STRESS TEST - REVISED WITH REALISTIC ASSUMPTIONS
A2: Terminal growth of 2.5% assumes a dying company. Gaming industry grows 3-10% annually.
A4: INDUSTRY GROWTH CONTEXT
A5: Gaming Industry CAGR (2025-2030) | B5: 8-10% | C5: Mordor Intelligence, Grand View Research
A6: Nominal GDP Growth (US/Global) | B6: 4-5% | C6: Inflation + Real GDP
A7: Mature Tech Companies (MSFT, AAPL) | B7: 5-15% | C7: Even 'mature' tech grows faster than GDP
A8: NetEase 5-Year Revenue CAGR | B8: 9% | C8: Strong historical performer
A9: A 2.5% terminal growth implies: | B9: Company in secular decline | C9: Unrealistic for healthy gaming co.
A12: REVISED SCENARIO DEFINITIONS (Realistic Terminal Growth)
A13: Scenario | B13: Revenue CAGR | C13: Terminal FCF Margin | D13: WACC | E13: Terminal Growth | F13: China Risk Premium | G13: Description
A14: Bull Case | B14: 0.075 | C14: 0.38 | D14: 0.075 | E14: 0.06 | F14: 0 | G14: Strong execution, gains market share
A15: Base Case | B15: 0.055 | C15: 0.36 | D15: 0.083 | E15: 0.05 | F15: 0 | G15: Maintains position, grows with industry
A16: Conservative | B16: 0.04 | C16: 0.34 | D16: 0.09 | E16: 0.04 | F16: 0.01 | G16: Slower growth, modest China premium
A17: Bear Case | B17: 0.03 | C17: 0.32 | D17: 0.1 | E17: 0.035 | F17: 0.02 | G17: Regulatory pressure, loses some share
A18: China Crisis | B18: 0.02 | C18: 0.3 | D18: 0.12 | E18: 0.03 | F18: 0.04 | G18: Severe geopolitical impact
A19: Distressed (Original) | B19: 0.02 | C19: 0.28 | D19: 0.12 | E19: 0.025 | F19: 0.04 | G19: Company in decline - UNREALISTIC
A21: REVISED SCENARIO VALUATIONS
A22: Scenario | B22: Sum PV FCF | C22: Terminal Value | D22: PV Terminal | E22: Enterprise Value | F22: Equity Value | G22: Share Price | H22: vs Current | I22: Rating
A23: Bull Case | B23: 46621.6 | C23: 742660.29 | D23: 387359.33 | E23: 433980.93 | F23: 477130.93 | G23: 750.20587 | H23: 4.391734 | I23: Strong Buy
A24: Base Case | B24: 39664.021 | C24: 267525.89 | D24: 130529.81 | E24: 170193.83 | F24: 213343.83 | G24: 335.44628 | H24: 1.4108544 | I24: Strong Buy
A25: Conservative | B25: 33359.49 | C25: 120997.63 | D25: 51314.809 | E25: 84674.298 | F25: 127824.3 | G25: 200.9816 | H25: 0.44445595 | I25: Buy
A26: Bear Case | B26: 28546.32 | C26: 73336.849 | D26: 26446.003 | E26: 54992.323 | F26: 98142.323 | G26: 154.31183 | H26: 0.10904002 | I26: Hold
A27: China Crisis | B27: 22899.504 | C27: 40976.277 | D27: 10774.834 | E27: 33674.338 | F27: 76824.338 | G27: 120.79298 | H27: -0.13186011 | I27: Sell
A28: Distressed (Original) | B28: 22233.047 | C28: 36649.284 | D28: 9637.0385 | E28: 31870.085 | F28: 75020.085 | G28: 117.95611 | H28: -0.15224875 | I28: Sell
A31: 2-WAY SENSITIVITY: WACC vs TERMINAL GROWTH (Realistic Range)
A32: WACC → | B32: 0.07 | C32: 0.08 | D32: 0.09 | E32: 0.1 | F32: 0.11 | G32: 0.12 | H32: 0.13 | I32: 0.14
A33: 0.03 | B33: 319.19498 | C33: 267.29721 | D33: 232.77912 | E33: 208.18727 | F33: 189.7953 | G33: 175.5333 | H33: 164.15959 | I33: 154.88419
A34: 0.035 | B34: 346.67424 | C34: 283.16918 | D34: 242.8317 | E34: 214.96447 | F34: 194.57574 | G34: 179.02308 | H34: 166.77688 | I34: 156.89043
A35: 0.04 | B35: 383.31326 | C35: 303.00914 | D35: 254.89479 | E35: 222.87121 | F35: 200.03911 | G35: 182.94908 | H35: 169.68499 | I35: 159.09729
A36: 0.045 | B36: 434.60789 | C36: 328.51766 | D36: 269.63857 | E36: 232.21553 | F36: 206.34299 | G36: 187.39855 | H36: 172.93522 | I36: 161.53645
A37: 0.05 | B37: 511.54982 | C37: 362.52902 | D37: 288.0683 | E37: 243.42872 | F37: 213.69752 | G37: 192.48365 | H37: 176.59173 | I37: 164.24663
A38: 0.055 | B38: 639.78639 | C38: 410.14492 | D38: 311.76366 | E38: 257.13373 | F38: 222.38924 | G38: 198.35108 | H38: 180.73578 | I38: 167.27566
A39: 0.06 | B39: 896.25952 | C39: 481.56878 | D39: 343.35747 | E39: 274.26499 | F39: 232.8193 | G39: 205.19641 | H39: 185.47183 | I39: 170.68332
A42: PROBABILITY-WEIGHTED VALUATION (Revised)
A43: Scenario | B43: Probability | C43: Share Price | D43: Weighted Price
A44: Bull Case | B44: 0.15 | C44: 750.20587 | D44: 112.53088
A45: Base Case | B45: 0.4 | C45: 335.44628 | D45: 134.17851
A46: Conservative | B46: 0.25 | C46: 200.9816 | D46: 50.2454
A47: Bear Case | B47: 0.15 | C47: 154.31183 | D47: 23.146774
A48: China Crisis | B48: 0.05 | C48: 120.79298 | D48: 6.0396492
...
