Workbook

Sheet DCF Model
A1: FRW.NZ (Freightways Group) DCF Valuation Model
A2: Gray cells are INPUTS - adjust to see valuation change
A3: LEASE CONVENTION (Option A): lease principal is deducted from FCF (row 13) AND the IFRS16 lease liability is EXCLUDED from Net Debt (row 10 = bank debt only, row 15 shows the excluded liability for reference). Each lease dollar is charged EXACTLY ONCE - do not add the lease liability back into Net Debt or the same obligation is double-counted.
A6: KEY INPUTS
A7: Current Stock Price (NZD) | B7: 13.97
A8: Shares Outstanding (M) | B8: 178.789
A9: Cash & Equivalents (M) | B9: 43.261
A10: Bank Borrowings ONLY, excl. IFRS16 leases (M) | B10: 258.48
A11: Net Debt (M) - bank debt only (Option A) | B11: =B10-B9 -> 0
A12: Reported FCF, FY2025 (OCF - Capex) (M) | B12: 147.74
A13: Less: Stock-Based Comp (M) | B13: 1.213
A14: Less: Lease Principal Repayments (M) | B14: 57.698 | C14: financing outflow excluded from OCF but real cash cost of the leased fleet - expensed here so the lease liability (row 15) is NOT also subtracted in Net Debt
A15: MEMO ONLY: IFRS16 Lease Liability, FY2025 (M) | B15: 373.689 | C15: NOT part of Net Debt (row 11) under Option A - reference/reconciliation only. Do NOT add to B11.
A16: Base Year Owner FCF (M) | B16: =B12-B13-B14 -> 0
A18: Annual Share Growth (residual dilution) | B18: 0.003
A20: WACC | B20: 0.1
A21: Terminal Growth Rate | B21: 0.0225
A22: Terminal EV/EBITDA Exit Cap (ex-lease-liability EV basis) | B22: 11.1
A24: COMPONENT ASSUMPTIONS (BASE CASE)
B25: Year 1 | C25: Year 2 | D25: Year 3 | E25: Year 4 | F25: Year 5
A26: Revenue Growth Rate | B26: 0.08 | C26: 0.065 | D26: 0.055 | E26: 0.05 | F26: 0.045
A27: EBITDA Margin | B27: 0.195 | C27: 0.197 | D27: 0.199 | E27: 0.2 | F27: 0.201
A28: SBC % of Revenue | B28: 0.001 | C28: 0.001 | D28: 0.001 | E28: 0.001 | F28: 0.001
A29: D&A % of Revenue (flat) | B29: 0.079
A30: Capex % of Revenue (flat) | B30: 0.022
A31: Lease Principal % of Revenue | B31: 0.045 | C31: 0.045 | D31: 0.045 | E31: 0.044 | F31: 0.044
A32: Cash Tax Rate | B32: 0.285 | C32: 0.285 | D32: 0.285 | E32: 0.285 | F32: 0.285
A33: Working Capital Capture % (of rev change) | B33: 0.35
A35: PROJECTIONS (component build)
B36: FY2025A | C36: Year 1 | D36: Year 2 | E36: Year 3 | F36: Year 4 | G36: Year 5
A37: Revenue | B37: =1289.559 -> 0 | C37: =B37*(1+C26) -> 0 | D37: =C37*(1+D26) -> 0 | E37: =D37*(1+E26) -> 0 | F37: =E37*(1+F26) -> 0 | G37: =F37*(1+G26) -> 0
A38: EBITDA (post-IFRS16) | C38: =C37*C27 -> 0 | D38: =D37*D27 -> 0 | E38: =E37*E27 -> 0 | F38: =F37*F27 -> 0 | G38: =G37*G27 -> 0
A39: Less: SBC | C39: =C37*C28 -> 0 | D39: =D37*D28 -> 0 | E39: =E37*E28 -> 0 | F39: =F37*F28 -> 0 | G39: =G37*G28 -> 0
A40: Less: D&A (incl. lease D&A, non-cash) | C40: =C37*$B$29 -> 0 | D40: =D37*$B$29 -> 0 | E40: =E37*$B$29 -> 0 | F40: =F37*$B$29 -> 0 | G40: =G37*$B$29 -> 0
A41: EBIT | C41: =C38-C39-C40 -> 0 | D41: =D38-D39-D40 -> 0 | E41: =E38-E39-E40 -> 0 | F41: =F38-F39-F40 -> 0 | G41: =G38-G39-G40 -> 0
A42: NOPAT (EBIT x (1-tax)) | C42: =C41*(1-C32) -> 0 | D42: =D41*(1-D32) -> 0 | E42: =E41*(1-E32) -> 0 | F42: =F41*(1-F32) -> 0 | G42: =G41*(1-G32) -> 0
A43: Add back: D&A | C43: =C40 -> 0 | D43: =D40 -> 0 | E43: =E40 -> 0 | F43: =F40 -> 0 | G43: =G40 -> 0
A44: Less: Capex | C44: =C37*$B$30 -> 0 | D44: =D37*$B$30 -> 0 | E44: =E37*$B$30 -> 0 | F44: =F37*$B$30 -> 0 | G44: =G37*$B$30 -> 0
A45: Less: Lease Principal Repayment | C45: =C37*C31 -> 0 | D45: =D37*D31 -> 0 | E45: =E37*E31 -> 0 | F45: =F37*F31 -> 0 | G45: =G37*G31 -> 0
A46: Less: Working Capital Investment | C46: =-$B$33*(C37-B37) -> 0 | D46: =-$B$33*(D37-C37) -> 0 | E46: =-$B$33*(E37-D37) -> 0 | F46: =-$B$33*(F37-E37) -> 0 | G46: =-$B$33*(G37-F37) -> 0
...

Sheet Sensitivity
A1: Sensitivity Analysis
A2: Intrinsic Value by WACC & Terminal Growth (Gordon vs 11.1x EV/EBITDA cap, lower of the two; Net Debt = bank debt only per Option A)
A4: WACC \ Term G | B4: 0.0125 | C4: 0.0175 | D4: 0.0225 | E4: 0.0275 | F4: 0.0325
A5: 0.08 | B5: =('DCF Model'!$C$47/(1+0.08)^1+'DCF Model'!$D$47/(1+0.08)^2+'DCF Model'!$E$47/(1+0.08)^3+'DCF Model'!$F$47/(1+0.08)^4+'DCF Model'!$G$47/(1+0.08)^5+MIN(('DCF Model'!$G$47*(1+0.0125))/(0.08-0.0125),'DCF Model'!$B$22*'DCF Model'!$G$38)/(1+0.08)^5-'DCF Model'!$B$11)/'DCF Model'!$G$50 -> 0 | C5: =('DCF Model'!$C$47/(1+0.08)^1+'DCF Model'!$D$47/(1+0.08)^2+'DCF Model'!$E$47/(1+0.08)^3+'DCF Model'!$F$47/(1+0.08)^4+'DCF Model'!$G$47/(1+0.08)^5+MIN(('DCF Model'!$G$47*(1+0.0175))/(0.08-0.0175),'DCF Model'!$B$22*'DCF Model'!$G$38)/(1+0.08)^5-'DCF Model'!$B$11)/'DCF Model'!$G$50 -> 0 | D5: =('DCF Model'!$C$47/(1+0.08)^1+'DCF Model'!$D$47/(1+0.08)^2+'DCF Model'!$E$47/(1+0.08)^3+'DCF Model'!$F$47/(1+0.08)^4+'DCF Model'!$G$47/(1+0.08)^5+MIN(('DCF Model'!$G$47*(1+0.0225))/(0.08-0.0225),'DCF Model'!$B$22*'DCF Model'!$G$38)/(1+0.08)^5-'DCF Model'!$B$11)/'DCF Model'!$G$50 -> 0 | E5: =('DCF Model'!$C$47/(1+0.08)^1+'DCF Model'!$D$47/(1+0.08)^2+'DCF Model'!$E$47/(1+0.08)^3+'DCF Model'!$F$47/(1+0.08)^4+'DCF Model'!$G$47/(1+0.08)^5+MIN(('DCF Model'!$G$47*(1+0.0275))/(0.08-0.0275),'DCF Model'!$B$22*'DCF Model'!$G$38)/(1+0.08)^5-'DCF Model'!$B$11)/'DCF Model'!$G$50 -> 0 | F5: =('DCF Model'!$C$47/(1+0.08)^1+'DCF Model'!$D$47/(1+0.08)^2+'DCF Model'!$E$47/(1+0.08)^3+'DCF Model'!$F$47/(1+0.08)^4+'DCF Model'!$G$47/(1+0.08)^5+MIN(('DCF Model'!$G$47*(1+0.0325))/(0.08-0.0325),'DCF Model'!$B$22*'DCF Model'!$G$38)/(1+0.08)^5-'DCF Model'!$B$11)/'DCF Model'!$G$50 -> 0
A6: 0.09 | B6: =('DCF Model'!$C$47/(1+0.09)^1+'DCF Model'!$D$47/(1+0.09)^2+'DCF Model'!$E$47/(1+0.09)^3+'DCF Model'!$F$47/(1+0.09)^4+'DCF Model'!$G$47/(1+0.09)^5+MIN(('DCF Model'!$G$47*(1+0.0125))/(0.09-0.0125),'DCF Model'!$B$22*'DCF Model'!$G$38)/(1+0.09)^5-'DCF Model'!$B$11)/'DCF Model'!$G$50 -> 0 | C6: =('DCF Model'!$C$47/(1+0.09)^1+'DCF Model'!$D$47/(1+0.09)^2+'DCF Model'!$E$47/(1+0.09)^3+'DCF Model'!$F$47/(1+0.09)^4+'DCF Model'!$G$47/(1+0.09)^5+MIN(('DCF Model'!$G$47*(1+0.0175))/(0.09-0.0175),'DCF Model'!$B$22*'DCF Model'!$G$38)/(1+0.09)^5-'DCF Model'!$B$11)/'DCF Model'!$G$50 -> 0 | D6: =('DCF Model'!$C$47/(1+0.09)^1+'DCF Model'!$D$47/(1+0.09)^2+'DCF Model'!$E$47/(1+0.09)^3+'DCF Model'!$F$47/(1+0.09)^4+'DCF Model'!$G$47/(1+0.09)^5+MIN(('DCF Model'!$G$47*(1+0.0225))/(0.09-0.0225),'DCF Model'!$B$22*'DCF Model'!$G$38)/(1+0.09)^5-'DCF Model'!$B$11)/'DCF Model'!$G$50 -> 0 | E6: =('DCF Model'!$C$47/(1+0.09)^1+'DCF Model'!$D$47/(1+0.09)^2+'DCF Model'!$E$47/(1+0.09)^3+'DCF Model'!$F$47/(1+0.09)^4+'DCF Model'!$G$47/(1+0.09)^5+MIN(('DCF Model'!$G$47*(1+0.0275))/(0.09-0.0275),'DCF Model'!$B$22*'DCF Model'!$G$38)/(1+0.09)^5-'DCF Model'!$B$11)/'DCF Model'!$G$50 -> 0 | F6: =('DCF Model'!$C$47/(1+0.09)^1+'DCF Model'!$D$47/(1+0.09)^2+'DCF Model'!$E$47/(1+0.09)^3+'DCF Model'!$F$47/(1+0.09)^4+'DCF Model'!$G$47/(1+0.09)^5+MIN(('DCF Model'!$G$47*(1+0.0325))/(0.09-0.0325),'DCF Model'!$B$22*'DCF Model'!$G$38)/(1+0.09)^5-'DCF Model'!$B$11)/'DCF Model'!$G$50 -> 0
A7: 0.1 | B7: =('DCF Model'!$C$47/(1+0.1)^1+'DCF Model'!$D$47/(1+0.1)^2+'DCF Model'!$E$47/(1+0.1)^3+'DCF Model'!$F$47/(1+0.1)^4+'DCF Model'!$G$47/(1+0.1)^5+MIN(('DCF Model'!$G$47*(1+0.0125))/(0.1-0.0125),'DCF Model'!$B$22*'DCF Model'!$G$38)/(1+0.1)^5-'DCF Model'!$B$11)/'DCF Model'!$G$50 -> 0 | C7: =('DCF Model'!$C$47/(1+0.1)^1+'DCF Model'!$D$47/(1+0.1)^2+'DCF Model'!$E$47/(1+0.1)^3+'DCF Model'!$F$47/(1+0.1)^4+'DCF Model'!$G$47/(1+0.1)^5+MIN(('DCF Model'!$G$47*(1+0.0175))/(0.1-0.0175),'DCF Model'!$B$22*'DCF Model'!$G$38)/(1+0.1)^5-'DCF Model'!$B$11)/'DCF Model'!$G$50 -> 0 | D7: =('DCF Model'!$C$47/(1+0.1)^1+'DCF Model'!$D$47/(1+0.1)^2+'DCF Model'!$E$47/(1+0.1)^3+'DCF Model'!$F$47/(1+0.1)^4+'DCF Model'!$G$47/(1+0.1)^5+MIN(('DCF Model'!$G$47*(1+0.0225))/(0.1-0.0225),'DCF Model'!$B$22*'DCF Model'!$G$38)/(1+0.1)^5-'DCF Model'!$B$11)/'DCF Model'!$G$50 -> 0 | E7: =('DCF Model'!$C$47/(1+0.1)^1+'DCF Model'!$D$47/(1+0.1)^2+'DCF Model'!$E$47/(1+0.1)^3+'DCF Model'!$F$47/(1+0.1)^4+'DCF Model'!$G$47/(1+0.1)^5+MIN(('DCF Model'!$G$47*(1+0.0275))/(0.1-0.0275),'DCF Model'!$B$22*'DCF Model'!$G$38)/(1+0.1)^5-'DCF Model'!$B$11)/'DCF Model'!$G$50 -> 0 | F7: =('DCF Model'!$C$47/(1+0.1)^1+'DCF Model'!$D$47/(1+0.1)^2+'DCF Model'!$E$47/(1+0.1)^3+'DCF Model'!$F$47/(1+0.1)^4+'DCF Model'!$G$47/(1+0.1)^5+MIN(('DCF Model'!$G$47*(1+0.0325))/(0.1-0.0325),'DCF Model'!$B$22*'DCF Model'!$G$38)/(1+0.1)^5-'DCF Model'!$B$11)/'DCF Model'!$G$50 -> 0
A8: 0.11 | B8: =('DCF Model'!$C$47/(1+0.11)^1+'DCF Model'!$D$47/(1+0.11)^2+'DCF Model'!$E$47/(1+0.11)^3+'DCF Model'!$F$47/(1+0.11)^4+'DCF Model'!$G$47/(1+0.11)^5+MIN(('DCF Model'!$G$47*(1+0.0125))/(0.11-0.0125),'DCF Model'!$B$22*'DCF Model'!$G$38)/(1+0.11)^5-'DCF Model'!$B$11)/'DCF Model'!$G$50 -> 0 | C8: =('DCF Model'!$C$47/(1+0.11)^1+'DCF Model'!$D$47/(1+0.11)^2+'DCF Model'!$E$47/(1+0.11)^3+'DCF Model'!$F$47/(1+0.11)^4+'DCF Model'!$G$47/(1+0.11)^5+MIN(('DCF Model'!$G$47*(1+0.0175))/(0.11-0.0175),'DCF Model'!$B$22*'DCF Model'!$G$38)/(1+0.11)^5-'DCF Model'!$B$11)/'DCF Model'!$G$50 -> 0 | D8: =('DCF Model'!$C$47/(1+0.11)^1+'DCF Model'!$D$47/(1+0.11)^2+'DCF Model'!$E$47/(1+0.11)^3+'DCF Model'!$F$47/(1+0.11)^4+'DCF Model'!$G$47/(1+0.11)^5+MIN(('DCF Model'!$G$47*(1+0.0225))/(0.11-0.0225),'DCF Model'!$B$22*'DCF Model'!$G$38)/(1+0.11)^5-'DCF Model'!$B$11)/'DCF Model'!$G$50 -> 0 | E8: =('DCF Model'!$C$47/(1+0.11)^1+'DCF Model'!$D$47/(1+0.11)^2+'DCF Model'!$E$47/(1+0.11)^3+'DCF Model'!$F$47/(1+0.11)^4+'DCF Model'!$G$47/(1+0.11)^5+MIN(('DCF Model'!$G$47*(1+0.0275))/(0.11-0.0275),'DCF Model'!$B$22*'DCF Model'!$G$38)/(1+0.11)^5-'DCF Model'!$B$11)/'DCF Model'!$G$50 -> 0 | F8: =('DCF Model'!$C$47/(1+0.11)^1+'DCF Model'!$D$47/(1+0.11)^2+'DCF Model'!$E$47/(1+0.11)^3+'DCF Model'!$F$47/(1+0.11)^4+'DCF Model'!$G$47/(1+0.11)^5+MIN(('DCF Model'!$G$47*(1+0.0325))/(0.11-0.0325),'DCF Model'!$B$22*'DCF Model'!$G$38)/(1+0.11)^5-'DCF Model'!$B$11)/'DCF Model'!$G$50 -> 0
A9: 0.12 | B9: =('DCF Model'!$C$47/(1+0.12)^1+'DCF Model'!$D$47/(1+0.12)^2+'DCF Model'!$E$47/(1+0.12)^3+'DCF Model'!$F$47/(1+0.12)^4+'DCF Model'!$G$47/(1+0.12)^5+MIN(('DCF Model'!$G$47*(1+0.0125))/(0.12-0.0125),'DCF Model'!$B$22*'DCF Model'!$G$38)/(1+0.12)^5-'DCF Model'!$B$11)/'DCF Model'!$G$50 -> 0 | C9: =('DCF Model'!$C$47/(1+0.12)^1+'DCF Model'!$D$47/(1+0.12)^2+'DCF Model'!$E$47/(1+0.12)^3+'DCF Model'!$F$47/(1+0.12)^4+'DCF Model'!$G$47/(1+0.12)^5+MIN(('DCF Model'!$G$47*(1+0.0175))/(0.12-0.0175),'DCF Model'!$B$22*'DCF Model'!$G$38)/(1+0.12)^5-'DCF Model'!$B$11)/'DCF Model'!$G$50 -> 0 | D9: =('DCF Model'!$C$47/(1+0.12)^1+'DCF Model'!$D$47/(1+0.12)^2+'DCF Model'!$E$47/(1+0.12)^3+'DCF Model'!$F$47/(1+0.12)^4+'DCF Model'!$G$47/(1+0.12)^5+MIN(('DCF Model'!$G$47*(1+0.0225))/(0.12-0.0225),'DCF Model'!$B$22*'DCF Model'!$G$38)/(1+0.12)^5-'DCF Model'!$B$11)/'DCF Model'!$G$50 -> 0 | E9: =('DCF Model'!$C$47/(1+0.12)^1+'DCF Model'!$D$47/(1+0.12)^2+'DCF Model'!$E$47/(1+0.12)^3+'DCF Model'!$F$47/(1+0.12)^4+'DCF Model'!$G$47/(1+0.12)^5+MIN(('DCF Model'!$G$47*(1+0.0275))/(0.12-0.0275),'DCF Model'!$B$22*'DCF Model'!$G$38)/(1+0.12)^5-'DCF Model'!$B$11)/'DCF Model'!$G$50 -> 0 | F9: =('DCF Model'!$C$47/(1+0.12)^1+'DCF Model'!$D$47/(1+0.12)^2+'DCF Model'!$E$47/(1+0.12)^3+'DCF Model'!$F$47/(1+0.12)^4+'DCF Model'!$G$47/(1+0.12)^5+MIN(('DCF Model'!$G$47*(1+0.0325))/(0.12-0.0325),'DCF Model'!$B$22*'DCF Model'!$G$38)/(1+0.12)^5-'DCF Model'!$B$11)/'DCF Model'!$G$50 -> 0

Sheet FCF Quality
A1: FCF Quality - Reported vs Owner FCF Reconciliation
A2: CRITICAL: Freightways is IFRS16 lease-heavy. Lease principal repayments sit in FINANCING
A3: activities and are excluded from OCF, but are the real cash cost that offsets the leased
A4: fleet/depot D&A already added back inside post-IFRS16 EBITDA. Having deducted this cost from
A5: FCF, the lease LIABILITY must be excluded from Net Debt (see DCF Model sheet, Option A) to
A6: avoid charging the same lease obligation twice.
B8: FY2022 | C8: FY2023 | D8: FY2024 | E8: FY2025
A9: Operating Cash Flow | B9: 123.684 | C9: 155.808 | D9: 156.663 | E9: 173.647
A10: Less: Capex | B10: 23.02 | C10: 34.19 | D10: 28.919 | E10: 25.907
A11: Reported FCF (company definition) | B11: 100.664 | C11: 121.618 | D11: 127.744 | E11: 147.74
A12: Less: SBC | B12: 1.031 | C12: 1.016 | D12: 0.886 | E12: 1.213
A13: Less: Lease Principal Repayments (financing outflow) | B13: 34.008 | C13: 41.734 | D13: 50.204 | E13: 57.698
A14: Owner FCF | B14: =B11-B12-B13 -> 0 | C14: =C11-C12-C13 -> 0 | D14: =D11-D12-D13 -> 0 | E14: =E11-E12-E13 -> 0
A16: Reported FCF Margin | B16: =B11/873.094 -> 0 | C16: =C11/1121.62 -> 0 | D16: =D11/1209.151 -> 0 | E16: =E11/1289.559 -> 0
A17: Owner FCF Margin | B17: =B14/873.094 -> 0 | C17: =C14/1121.62 -> 0 | D17: =D14/1209.151 -> 0 | E17: =E14/1289.559 -> 0
A19: Memo: Lease Principal as % of Reported FCF | B19: =B13/B11 -> 0 | C19: =C13/C11 -> 0 | D19: =D13/D11 -> 0 | E19: =E13/E11 -> 0
A21: Memo: Bank Borrowings Only (Net Debt basis, Option A) | B21: 176.21 | C21: 297.194 | D21: 265.674 | E21: 258.48
A22: Memo: IFRS16 Lease Liability (EXCLUDED from Net Debt) | D22: 383.067 | E22: 373.689
A24: Memo: Cash Tax Rate (FY2025 = 28.5%, in line with NZ statutory 28% - no ramp needed)

Sheet Historical
A1: Historical Growth Rates
A3: Metric | B3: 3-Year CAGR | C3: 5-Year CAGR
A4: Revenue (acquisitive - see warning) | B4: 0.1388 | C4: 0.1537
A5: EPS | B5: 0.0186 | C5: 0.083
A6: Equity | B6: 0.1192 | C6: 0.0956
A7: FCF (reported) | B7: 0.1364 | C7: 0.063
A8: FCF (owner, SBC-only adj.) | B8: 0.1372 | C8: 0.0621
A10: Selected Growth Approach: | B10: revenue-driven component build (NOT equity or blended CAGR)
A11: Warning:
A12: Revenue 3yr/5yr CAGR (13.9%/15.4%) is INFLATED by the August-2022 Allied Express acquisition (FY2022->FY2023 revenue +28.5%) and is NOT organic. EPS 3yr CAGR (1.9%) is depressed by FY2024's cyclical NZ-macro trough. Equity CAGR is distorted by ~13m shares of Allied Express acquisition scrip issued in FY2023. None of the standard CAGR anchors (revenue, EPS, equity) is reliable in isolation for this ticker - the DCF instead uses a revenue-driven component build with an explicit organic-growth-plus-bolt-on-M&A assumption (base case Y1 8.0% decelerating to 4.5% by Y5), calibrated against underlying organic revenue growth (FY2019 +6.0%, FY2020 +2.5%, FY2022 +9.1%, FY2024 +7.8%, FY2025 +6.6% - i.e. non-acquisition years only) rather than the acquisition-inflated blended CAGR.
A14: Historical Multiples (SBC-adjusted, ex-FY2021 outlier, LEASE-INCLUSIVE EV basis)
A15: Metric | B15: Ex-Outlier Avg/Max
A16: P/E average | B16: 21.6
A17: P/B max | B17: 4.79
A18: EV/EBITDA max (lease-inclusive) | B18: 12.8
A19: EV/EBITDA min (lease-inclusive) | B19: 8.7
A20: EV/EBITDA range, ex-lease-restated | B20: ~7.0x - 9.0x (FY2022-25, bank-debt-only EV)

Sheet Model_Info
A1: Model Provenance
A4: Ticker | B4: FRW.NZ - Freightways Group Limited
A5: Built by | B5: Claude agent (DCF valuation skill), per instructions in .claude/CLAUDE.md. Corrected on coordinator review to fix an IFRS16 lease double-count (see below).
A6: Valuation date | B6: 2026-08-10
A7: Share price date/source | B7: NZ$13.97, Yahoo Finance live quote, 10-Aug-2026
A8: Data vintage | B8: FY2025 (year to 30-Jun-2025) is the latest COMPLETE fiscal year. H1-2026 (six months to 31-Dec-2025) is the latest reported period. FY2026 full-year results are due 17-Aug-2026 and are NOT reflected in this model.
A9: LEASE ACCOUNTING CONVENTION (Option A - IMPORTANT) | B9: Lease principal repayments AND lease interest are fully expensed through the projected owner FCF (lease principal deducted explicitly each year; lease interest sits inside EBIT via the post-IFRS16 income statement). Because the full economic cost of the leased fleet is charged through the cash flows, the IFRS16 lease LIABILITY ($373.689m FY2025) is EXCLUDED from Net Debt in the equity-value bridge. Net Debt = bank borrowings only ($258.48m) less cash ($43.261m) = $215.22m. A PRIOR VERSION of this model incorrectly included the full $632.17m lease-inclusive debt in Net Debt on top of deducting lease principal from FCF - that double-counted the same lease obligation (once as the discounted PV of future payments via the liability, once again as the future payments themselves via the FCF deduction) and understated base-case intrinsic value by $2.06/share (~36%). CORRECTED here: each lease dollar is now charged exactly once.
A10: Working capital calibration | B10: wc_capture_pct (35% base case) was calibrated to the historical FY2022-25 gap between a bottom-up NOPAT+D&A-capex-lease-SBC build and the actual reported-OCF-based owner FCF, which averaged ~38-41% of YoY revenue change in non-acquisition years. This is NOT a generic SaaS-style deferred-revenue assumption; Freightways negative working capital is small (~$45.6m FY2025) relative to a subscription business.
A11: Revenue growth approach | B11: Revenue-driven component build, NOT equity/EPS/revenue CAGR extrapolation. Blended revenue CAGRs (13.9%/15.4% 3yr/5yr) are inflated by the August-2022 Allied Express acquisition step (FY2022->FY2023 revenue +28.5%). Base case uses organic-growth-plus-bolt-on-M&A assumption (8.0% Y1 decelerating to 4.5% Y5), calibrated against non-acquisition-year organic growth (2.5%-9.1% historically).
A12: WACC | B12: 10.0% base (9.0% bull / 11.5% bear), built from CAPM (rf 4.5%, ERP 6.0%, beta 0.95) plus a modest premium for contractor-classification regulatory risk (NZ Employment Relations Amendment Act 2026). Capital weights now use bank-debt-only leverage (~7% debt / 93% equity) consistent with the Option A convention - leases are treated as an operating cost inside FCF, not as financial leverage. See wacc_rationale in the JSON for the full component breakdown.
A13: Terminal value | B13: Lower of Gordon Growth (FCF-based) vs. an EV/EBITDA exit-multiple cap (11.1x base, applied to an ex-lease-liability EV, from the 8-year ex-FY2021-outlier average). Gordon binds in all three scenarios. IMPORTANT: the historical 8.7-12.8x multiple range quoted in the research brief is computed on a LEASE-INCLUSIVE EV basis - see the Sensitivity/Historical sheets and the JSON valuation.base.implied_exit_multiple_ev_ebitda_lease_inclusive_equivalent field for a like-for-like comparison.
A14: Result summary (post-fix) | B14: Base case intrinsic value NZ$7.85/share (-43.8% vs $13.97 current price); bull $12.45 (-10.9%), bear $4.73 (-66.1%), probability-weighted $8.22 (-41.2%). Entry price for 15% IRR: $6.24. Even after the lease-double-count fix, the DCF implied exit EV/EBITDA (5.54x ex-lease, ~6.2x lease-inclusive-equivalent) remains below the 10-year historical floor (~7.0-8.7x) - investigated and confirmed as a genuine structural finding (thin owner-FCF base relative to EBITDA, Gordon growth mechanically produces a lower multiple than the market has paid), not a residual modelling artifact. See sanity_check.diagnosis in the JSON for the full investigation, including a WACC stress test showing ~7.2% WACC (below the specified 9.5-11% range) would be needed to close the gap.
A15: What to refresh after FY2026 results (17-Aug-2026) | B15: Update FY2025->FY2026 actuals: revenue, EBITDA, EBIT, D&A, lease principal repayment, bank borrowings, lease liability, capex, SBC, shares outstanding, cash tax rate. Re-run the organic-vs-acquisitive growth decomposition (VT Freight Express will be in FY2026 for a full year for the first time). Re-check the EBITDA margin band (18.6%-21.4%) still holds. Re-verify the current price and 52-week/10-year percentile.
... A17: Staleness warning | B17: All figures in this model will go stale after the FY2026 results release (17-Aug-2026) and after any future market price move. Do not treat this file as current without re-checking the valuation_date field and re-running the live price fetch.
