Workbook

Sheet Assumptions
A1: DUOLINGO (DUOL) - DCF VALUATION MODEL
A2: Model Date: November 28, 2025
A3: Source: Company filings, investor relations, web search
A5: COMPANY OVERVIEW
A6: Current Stock Price ($) | B6: 188.43 | C6: Source: Morningstar, Nov 26, 2025
A7: Shares Outstanding (M) | B7: 46.23 | C7: Source: StockAnalysis
A8: Diluted Shares Outstanding (M) | B8: 49.2 | C8: Source: GuruFocus
A9: Market Cap ($M) | B9: =B6*B7 -> 8711.1189
A10: Cash & Investments ($M) | B10: 865 | C10: Estimate based on filings
A11: Total Debt ($M) | B11: 62.5 | C11: Source: GuruFocus
A12: Enterprise Value ($M) | B12: =B9-B10+B11 -> 7908.6189
A14: HISTORICAL FINANCIALS ($M)
A15: Year | B15: 2022 | C15: 2023 | D15: 2024 | E15: TTM Q3 2025
A16: Revenue | B16: 369 | C16: 531 | D16: 748 | E16: 964.27
A17: Revenue Growth % | B17: 0.4734 | C17: =(C16-B16)/B16 -> 0.43902439 | D17: =(D16-C16)/C16 -> 0.4086629 | E17: =(E16-D16)/D16 -> 0.28913102
A18: Net Income | B18: -59.57 | C18: 16.07 | D18: 88.57 | E18: 386.02
A19: Free Cash Flow | B19: 48.09 | C19: 144.3 | D19: 274.9 | E19: 354.56
A20: FCF Margin % | B20: =B19/B16 -> 0.1303252 | C20: =C19/C16 -> 0.27175141 | D20: =D19/D16 -> 0.36751337 | E20: =E19/E16 -> 0.36769784
A21: D&A | B21: 4.87 | C21: 7.1 | D21: 10.85 | E21: 14.24
A22: CapEx + Intangibles | B22: 10.12 | C22: 13.58 | D22: 21.14 | E22: 16.29
A24: DCF ASSUMPTIONS
A25: Risk-Free Rate | B25: 0.043 | C25: 10-Year Treasury
A26: Equity Risk Premium | B26: 0.055 | C26: Market consensus
A27: Beta (Levered) | B27: 0.85 | C27: Source: Various (0.74-1.3 range)
A28: Cost of Equity | B28: =B25+B27*B26 -> 0.08975 | C28: CAPM: Rf + Beta * ERP
A29: Cost of Debt (Pre-Tax) | B29: 0.05
A30: Tax Rate | B30: 0.21
A31: Cost of Debt (After-Tax) | B31: =B29*(1-B30) -> 0.0395
A32: Debt Weight | B32: 0.005 | C32: Minimal debt
A33: Equity Weight | B33: =1-B32 -> 0.995
A34: WACC | B34: =B28*B33+B31*B32 -> 0.08949875
A35: Terminal Growth Rate | B35: 0.03 | C35: Long-term GDP growth
A37: PROJECTION ASSUMPTIONS
A38: FY 2025E Revenue ($M) | B38: 1030 | C38: Company guidance midpoint: $1.0275-$1.0315B
A39: Revenue Growth Y1 (2026) | B39: 0.28
A40: Revenue Growth Y2 (2027) | B40: 0.24
A41: Revenue Growth Y3 (2028) | B41: 0.2
A42: Revenue Growth Y4 (2029) | B42: 0.16
A43: Revenue Growth Y5 (2030) | B43: 0.12
A44: Terminal FCF Margin | B44: 0.35 | C44: Mature SaaS company target
...

Sheet DCF Model
A1: DUOLINGO DCF VALUATION
A3: Projection Period
B4: 2025E | C4: 2026E | D4: 2027E | E4: 2028E | F4: 2029E | G4: 2030E | H4: Terminal
A5: Year # | B5: 0 | C5: 1 | D5: 2 | E5: 3 | F5: 4 | G5: 5 | H5: TV
A7: REVENUE PROJECTIONS
A8: Revenue Growth % | B8: =Assumptions!B38/Assumptions!D16-1 -> 0.37700535 | C8: =Assumptions!B39 -> 0.28 | D8: =Assumptions!B40 -> 0.24 | E8: =Assumptions!B41 -> 0.2 | F8: =Assumptions!B42 -> 0.16 | G8: =Assumptions!B43 -> 0.12 | H8: =Assumptions!B35 -> 0.03
A9: Revenue ($M) | B9: =Assumptions!B38 -> 1030 | C9: =B9*(1+C8) -> 1318.4 | D9: =C9*(1+D8) -> 1634.816 | E9: =D9*(1+E8) -> 1961.7792 | F9: =E9*(1+F8) -> 2275.6639 | G9: =F9*(1+G8) -> 2548.7435
A11: FREE CASH FLOW PROJECTIONS
A12: FCF Margin % | B12: =Assumptions!B45 -> 0.3 | C12: =B12+Assumptions!B46 -> 0.31 | D12: =C12+Assumptions!B46 -> 0.32 | E12: =D12+Assumptions!B46 -> 0.33 | F12: =E12+Assumptions!B46 -> 0.34 | G12: =MIN(F12+Assumptions!B46,Assumptions!B44) -> 0.35
A13: Free Cash Flow ($M) | B13: =B9*B12 -> 309 | C13: =C9*C12 -> 408.704 | D13: =D9*D12 -> 523.14112 | E13: =E9*E12 -> 647.38714 | F13: =F9*F12 -> 773.72572 | G13: =G9*G12 -> 892.06024
A15: TERMINAL VALUE CALCULATION
A16: Terminal FCF (Year 5 FCF) | G16: =G13 -> 892.06024
A17: Terminal Growth Rate | G17: =Assumptions!B35 -> 0.03
A18: WACC | G18: =Assumptions!B34 -> 0.08949875
A19: Terminal Value (Gordon Growth) | G19: =G16*(1+G17)/(G18-G17) -> 15442.712 | H19: TV = FCF*(1+g)/(WACC-g)
A21: DISCOUNTED CASH FLOWS
A22: Discount Factor | B22: =1/(1+Assumptions!B34)^1 -> 0.91785328 | C22: =1/(1+Assumptions!B34)^2 -> 0.84245464 | D22: =1/(1+Assumptions!B34)^3 -> 0.77324976 | E22: =1/(1+Assumptions!B34)^4 -> 0.70972982 | F22: =1/(1+Assumptions!B34)^5 -> 0.65142785 | G22: =1/(1+Assumptions!B34)^5 -> 0.65142785
A23: PV of FCF ($M) | B23: =B13*B22 -> 283.61666 | C23: =C13*C22 -> 344.31458 | D23: =D13*D22 -> 404.51874 | E23: =E13*E22 -> 459.46996 | F23: =F13*F22 -> 504.02648 | G23: =G13*G22 -> 581.11288
A24: PV of Terminal Value ($M) | G24: =G19*G22 -> 10059.812
A26: VALUATION SUMMARY
A27: Sum of PV of FCFs ($M) | B27: =SUM(B23:G23) -> 2577.0593
A28: PV of Terminal Value ($M) | B28: =G24 -> 10059.812
A29: Enterprise Value ($M) | B29: =B27+B28 -> 12636.872
A30: Plus: Cash ($M) | B30: =Assumptions!B10 -> 865
A31: Less: Debt ($M) | B31: =Assumptions!B11 -> 62.5
A32: Equity Value ($M) | B32: =B29+B30-B31 -> 13439.372
A33: Diluted Shares Outstanding (M) | B33: =Assumptions!B8 -> 49.2
A34: Implied Share Price | B34: =B32/B33 -> 273.15796
A35: Current Share Price | B35: =Assumptions!B6 -> 188.43
A36: Upside / (Downside) | B36: =(B34-B35)/B35 -> 0.44965219
A38: VALUE ATTRIBUTION
A39: % from FCF Period | B39: =B27/B29 -> 0.20393174
A40: % from Terminal Value | B40: =B28/B29 -> 0.79606826

Sheet Sensitivity
A1: SENSITIVITY ANALYSIS
A3: Share Price Sensitivity: WACC vs Terminal Growth Rate
A5: WACC \ Term Growth | B5: 2.0% | C5: 2.5% | D5: 3.0% | E5: 3.5% | F5: 4.0%
A6: 7.0% | B6: =(($B$23*(1+$B$13)/($B$18-$B$13))*(1/(1+$B$18)^5)+$B$24+$B$25-$B$26)/$B$27 -> 332.40858 | C6: =(($B$23*(1+$B$14)/($B$18-$B$14))*(1/(1+$B$18)^5)+$B$24+$B$25-$B$26)/$B$27 -> 363.147 | D6: =(($B$23*(1+$B$15)/($B$18-$B$15))*(1/(1+$B$18)^5)+$B$24+$B$25-$B$26)/$B$27 -> 401.57002 | E6: =(($B$23*(1+$B$16)/($B$18-$B$16))*(1/(1+$B$18)^5)+$B$24+$B$25-$B$26)/$B$27 -> 450.97104 | F6: =(($B$23*(1+$B$17)/($B$18-$B$17))*(1/(1+$B$18)^5)+$B$24+$B$25-$B$26)/$B$27 -> 516.83907
A7: 8.0% | B7: =(($B$23*(1+$B$13)/($B$19-$B$13))*(1/(1+$B$19)^5)+$B$24+$B$25-$B$26)/$B$27 -> 278.46788 | C7: =(($B$23*(1+$B$14)/($B$19-$B$14))*(1/(1+$B$19)^5)+$B$24+$B$25-$B$26)/$B$27 -> 298.66038 | D7: =(($B$23*(1+$B$15)/($B$19-$B$15))*(1/(1+$B$19)^5)+$B$24+$B$25-$B$26)/$B$27 -> 322.89139 | E7: =(($B$23*(1+$B$16)/($B$19-$B$16))*(1/(1+$B$19)^5)+$B$24+$B$25-$B$26)/$B$27 -> 352.50705 | F7: =(($B$23*(1+$B$17)/($B$19-$B$17))*(1/(1+$B$19)^5)+$B$24+$B$25-$B$26)/$B$27 -> 389.52664
A8: 9.0% | B8: =(($B$23*(1+$B$13)/($B$20-$B$13))*(1/(1+$B$20)^5)+$B$24+$B$25-$B$26)/$B$27 -> 240.40147 | C8: =(($B$23*(1+$B$14)/($B$20-$B$14))*(1/(1+$B$20)^5)+$B$24+$B$25-$B$26)/$B$27 -> 254.51649 | D8: =(($B$23*(1+$B$15)/($B$20-$B$15))*(1/(1+$B$20)^5)+$B$24+$B$25-$B$26)/$B$27 -> 270.98403 | E8: =(($B$23*(1+$B$16)/($B$20-$B$16))*(1/(1+$B$20)^5)+$B$24+$B$25-$B$26)/$B$27 -> 290.44565 | F8: =(($B$23*(1+$B$17)/($B$20-$B$17))*(1/(1+$B$20)^5)+$B$24+$B$25-$B$26)/$B$27 -> 313.79961
A9: 10.0% | B9: =(($B$23*(1+$B$13)/($B$21-$B$13))*(1/(1+$B$21)^5)+$B$24+$B$25-$B$26)/$B$27 -> 212.23119 | C9: =(($B$23*(1+$B$14)/($B$21-$B$14))*(1/(1+$B$21)^5)+$B$24+$B$25-$B$26)/$B$27 -> 222.55112 | D9: =(($B$23*(1+$B$15)/($B$21-$B$15))*(1/(1+$B$21)^5)+$B$24+$B$25-$B$26)/$B$27 -> 234.34534 | E9: =(($B$23*(1+$B$16)/($B$21-$B$16))*(1/(1+$B$21)^5)+$B$24+$B$25-$B$26)/$B$27 -> 247.95405 | F9: =(($B$23*(1+$B$17)/($B$21-$B$17))*(1/(1+$B$21)^5)+$B$24+$B$25-$B$26)/$B$27 -> 263.83088
A10: 11.0% | B10: =(($B$23*(1+$B$13)/($B$22-$B$13))*(1/(1+$B$22)^5)+$B$24+$B$25-$B$26)/$B$27 -> 190.63743 | C10: =(($B$23*(1+$B$14)/($B$22-$B$14))*(1/(1+$B$22)^5)+$B$24+$B$25-$B$26)/$B$27 -> 198.44374 | D10: =(($B$23*(1+$B$15)/($B$22-$B$15))*(1/(1+$B$22)^5)+$B$24+$B$25-$B$26)/$B$27 -> 207.22584 | E10: =(($B$23*(1+$B$16)/($B$22-$B$16))*(1/(1+$B$22)^5)+$B$24+$B$25-$B$26)/$B$27 -> 217.17888 | F10: =(($B$23*(1+$B$17)/($B$22-$B$17))*(1/(1+$B$22)^5)+$B$24+$B$25-$B$26)/$B$27 -> 228.55379
A12: Helper Values (for formulas)
A13: TG1 | B13: 0.02
A14: TG2 | B14: 0.025
A15: TG3 | B15: 0.03
A16: TG4 | B16: 0.035
A17: TG5 | B17: 0.04
A18: W1 | B18: 0.07
A19: W2 | B19: 0.08
A20: W3 | B20: 0.09
A21: W4 | B21: 0.1
A22: W5 | B22: 0.11
A23: Y5 FCF | B23: ='DCF Model'!G13 -> 892.06024
A24: PV FCFs | B24: ='DCF Model'!B27 -> 2577.0593
A25: Cash | B25: =Assumptions!B10 -> 865
A26: Debt | B26: =Assumptions!B11 -> 62.5
A27: Shares | B27: =Assumptions!B8 -> 49.2

Sheet Summary
A1: DUOLINGO (DUOL) - VALUATION SUMMARY
A3: KEY METRICS
A4: Current Price | B4: =Assumptions!B6 -> 188.43
A5: DCF Fair Value | B5: ='DCF Model'!B34 -> 273.15796
A6: Upside / (Downside) | B6: ='DCF Model'!B36 -> 0.44965219
A7: Market Cap ($M) | B7: =Assumptions!B9 -> 8711.1189
A8: Enterprise Value - DCF ($M) | B8: ='DCF Model'!B29 -> 12636.872
A10: KEY ASSUMPTIONS
A11: WACC | B11: =Assumptions!B34 -> 0.08949875
A12: Terminal Growth Rate | B12: =Assumptions!B35 -> 0.03
A13: Terminal FCF Margin | B13: =Assumptions!B44 -> 0.35
A14: 5-Year Revenue CAGR | B14: =(('DCF Model'!G9/Assumptions!B38)^(1/5))-1 -> 0.19866488
A16: PROJECTED FINANCIALS ($M)
A17: 2025E Revenue | B17: =Assumptions!B38 -> 1030
A18: 2030E Revenue | B18: ='DCF Model'!G9 -> 2548.7435
A19: 2030E FCF | B19: ='DCF Model'!G13 -> 892.06024
A21: INVESTMENT THESIS
A22: • Market leader in language learning with 100M+ MAUs
A23: • Strong subscription growth (40%+ paid subscriber growth)
A24: • High engagement with gamified learning approach
A25: • AI-powered features driving premium tier adoption
A26: • Expanding into Math, Music, and other subjects
A27: • Asset-light business model with high FCF conversion
A29: KEY RISKS
A30: • Slowing DAU growth as base scales
A31: • Competition from AI-native language tools
A32: • Platform dependency (App Store fees)
A33: • Monetization vs. user growth tradeoff
A34: • Execution risk on new subject expansion
