Workbook

Sheet Model_Info
A1: Ticker | B1: SGRO.L
A2: Company | B2: SEGRO plc
A3: Valuation date | B3: 2026-10-10
A4: Current price | B4: 919.2
A5: Price as of | B5: 2026-10-09T16:35:59Z (LSE regular close; Yahoo v8 chart meta; 52-week range 632.2-997.4)
A6: Balance sheet date | B6: 2026-06-30
A7: Model | B7: REIT AFFO capitalisation at cost of equity (engine route) with deal-completes vs deal-breaks scenario weighting
A8: Currency (model) | B8: GBP
A9: Currency (quote) | B9: GBp
A10: Units | B10: millions
A11: Engine | B11: dcf_engine v1
A12: Built at | B12: 2026-10-10T01:28:58Z
A13: Drivers file | B13: SGRO.L_Drivers.json
A14: Convention | B14: Percents stored as percents; formulas divide by 100. Blue = input, green = link, black = formula.
A15: Methodology | B15: summary: SEGRO is valued as a merger-arbitrage position, not as a going-concern REIT, because a shareholder-approved Prologis scheme sets the near-term outcome. Base and bull are the scheme receipts (blended stock-plus-capped-cash consideration plus permitted dividends) discounted at an 8% arbitrage return over a year; bear is the standalone business valued the house way for a REIT -- adjusted (EPRA) earnings less refurbishment spend, i.e. AFFO, capitalised at an 8% GBP cost of equity with no net-debt deduction because the flow is post-interest. Statutory earnings, book-value growth and reported free cash flow are set aside as IAS 40 revaluation noise and development-capex timing. The finding is that the price already embeds near-certain completion: the probability-weighted value lands below the price because a 15% break probability against a ~40% fall to the house standalone value outweighs a 2-4% spread to the consideration. The investment question is therefore not SEGRO's intrinsic value but whether a sub-8% annualised, 85%-probability arbitrage with that asymmetry is worth holding; for a new buyer it is not, and for an existing holder the case for selling into the spread is strong unless they want to own Prologis. key_risks_to_valuation: Consideration mark: 75% of the deal value is PLD stock. Each USD 1 on PLD moves the base ~0.68p (~0.7%); a 10% PLD fall to USD 116 takes the blended consideration to ~866p, below the current price. refresh_price.py does not refresh PLD or GBPUSD.; Break probability and break price: the weighted value is most sensitive to the 15% break weight and to whether the break price is the house standalone (~565p) or the undisturbed level (~742p); at 742p the weighted value rises ~27p.; Timing: each extra quarter of regulatory delay costs ~2% of the base value at an 8% arbitrage rate; CMA Phase 2 or EC Phase II would push completion into H2 2027.; Permitted dividends: the ~22p FY2026 final is assumed received; completion before the record date or a stricter scheme term removes it (~2% of base).; Standalone floor: the bear capitalises FY2026E AFFO at 8% with a 17x exit; at the market's own ~7% pre-bid cost of equity the standalone value is ~700p, so the floor is itself a judgment, and capitalised development interest (c.GBP 70m/yr) left inside adjusted earnings flatters it by ~5p/share of AFFO.
A16: Data sources | B16: price: Yahoo Finance v8 chart API at inputs.price_as_of (LSE regular close); 52-week range 632.2-997.4. PLD and GBPUSD marks from the same API at the timestamps in deal_analysis. financials: SGRO.L Metrics CSV / core_metrics and kpis (adjusted/EPRA earnings and EPS, EPRA NTA, LTV, gross and net rental income, dividends, share counts) adjudicated from the FY2021-FY2025 annual reports and the H1 2026 results presentation (30-Jul-2026: adjusted income statement, net debt, LTV, cost of debt, EBITDA), the 8-Jul-2026 H1 trading update (905p pro forma NAV, capex guidance) and the H1 2026 property analysis report. FY2025 AR: adjusted earnings table and diluted share count (lines 10465-10482), capital expenditure paragraph with spend on existing completed properties and capitalised interest (lines 2884-2900), net debt table (lines 10592-10606). qualitative: SGRO.L_Analysis.json (2026-10-10): scheme terms and timetable, regulatory conditions, guidance, risk register, bull/bear points.
... A19: Scenario narrative: bull | B19: The deal completes and the stock leg is worth more at completion than today: PLD recovers to ~USD 145, where the exchange ratio was struck at parity with the cash in July 2026 (52-week high USD 153), or sterling weakens, lifting the blended consideration to ~1,014p; plus the permitted final dividend, ~1,036p of receipts worth ~959p today. A competing bid is the alternative route to the same number: Prologis's 'Best and Final' statement caps its own terms, and the GBP 14bn size and pan-European antitrust footprint make an interloper (Blackstone, GIC, Goodman) unlikely but not impossible. There is no bull case for SEGRO's own operations inside a one-year horizon.

Sheet Actuals
A1: Period | B1: Revenue | C1: CostOfRevenue | D1: GrossProfit | E1: GrossMargin | F1: OperatingIncome | G1: OperatingMargin | H1: EBITDA | I1: NetIncome | J1: NetMargin | K1: EPS | L1: OperatingCashFlow | M1: CapEx | N1: FreeCashFlow | O1: ShareholdersEquity | P1: TotalAssets | Q1: TotalLiabilities | R1: TotalDebt | S1: CashAndEquivalents | T1: SharesOutstanding | U1: StockBasedComp | V1: DividendPerShare | W1: EBITDABeforeSignificant | X1: RevenueContinuing | Y1: EBITDAContinuingBeforeSignificant | Z1: EBITContinuingBeforeSignificant | AA1: Units | AB1: Currency | AC1: DividendPerShareDeclared | AD1: EPRAEPS | AE1: EPRAEarnings | AF1: GrossRentalIncome | AG1: InterestPaid | AH1: LTV | AI1: NAVPerShare | AJ1: NTAPerShare | AK1: NetDebtToEBITDA | AL1: NetRentalIncome | AM1: Occupancy | AN1: ProfitAfterTaxTotal | AO1: ShareIssuanceProceeds | AP1: ShareOfJVProfit | AQ1: TotalCashCapex | AR1: TotalEquityInclNCI
A2: FY2020 | B2: 432 | C2: 104 | D2: 328 | E2: 75.9 | F2: 1501 | G2: 347.5 | I2: 1427 | J2: 330.3 | K2: 1.236 | L2: 199 | M2: 5 | N2: 194 | O2: 9659 | P2: 12667 | Q2: 2996 | R2: 2414 | S2: 89 | T2: 1154.5 | U2: 10 | AA2: millions | AB2: GBP | AD2: 25.4 | AE2: 292 | AG2: 94 | AI2: 809 | AJ2: 814 | AN2: 1429 | AO2: 672 | AP2: 236 | AQ2: 1221 | AR2: 9671
A3: FY2021 | B3: 546 | C3: 140 | D3: 406 | E3: 74.4 | F3: 4477 | G3: 820 | I3: 4060 | J3: 743.6 | K3: 3.381 | L3: 327 | M3: 7 | N3: 320 | O3: 13436 | P3: 17783 | Q3: 4347 | R3: 3406 | S3: 85 | T3: 1201 | U3: 13 | AA3: millions | AB3: GBP | AD3: 29.1 | AE3: 348 | AG3: 100 | AH3: 24.6 | AI3: 1115 | AJ3: 1137 | AN3: 4067 | AO3: 1 | AP3: 461 | AQ3: 1713
A4: FY2022 | B4: 669 | C4: 214 | D4: 455 | E4: 68 | F4: -1694 | G4: -253.2 | I4: -1927 | J4: -288 | K4: -1.597 | L4: 213 | M4: 9 | N4: 204 | O4: 11373 | P4: 17348 | Q4: 5975 | R4: 4884 | S4: 162 | T4: 1210 | U4: 9 | AA4: millions | AB4: GBP | AD4: 31 | AE4: 374 | AF4: 488 | AG4: 131 | AH4: 34.2 | AI4: 938 | AJ4: 966 | AL4: 412 | AN4: -1930 | AO4: 0 | AP4: -144 | AQ4: 1481
A5: FY2023 | B5: 749 | C5: 161 | D5: 588 | E5: 78.5 | F5: -180 | G5: -24 | I5: -253 | J5: -33.8 | K5: -0.207 | L5: 431 | M5: 29 | N5: 402 | O5: 10904 | P5: 17306 | Q5: 6402 | R5: 5348 | S5: 376 | T5: 1223.4 | U5: 10 | AA5: millions | AB5: GBP | AD5: 33.9 | AE5: 413 | AF5: 547 | AG5: 199 | AH5: 36.9 | AI5: 886 | AJ5: 907 | AL5: 462 | AO5: 0 | AP5: -76 | AQ5: 868
A6: FY2024 | B6: 675 | C6: 144 | D6: 531 | E6: 78.7 | F6: 703 | G6: 104.1 | I6: 594 | J6: 88 | K6: 0.446 | L6: 330 | M6: 24 | N6: 306 | O6: 12049 | P6: 17574 | Q6: 5525 | R6: 4607 | S6: 363 | T6: 1332 | U6: 7 | AA6: millions | AB6: GBP | AD6: 34.5 | AE6: 458 | AF6: 592 | AG6: 209 | AH6: 30.6 | AI6: 889 | AJ6: 907 | AL6: 500 | AO6: 889 | AP6: 53 | AQ6: 1024
A7: FY2025 | B7: 726 | C7: 154 | D7: 572 | E7: 78.8 | F7: 663 | G7: 91.3 | H7: 579 | I7: 551 | J7: 75.9 | K7: 0.407 | L7: 396 | M7: 29 | N7: 367 | O7: 12273 | P7: 18181 | Q7: 5908 | R7: 4951 | S7: 111 | T7: 1355.3 | U7: 5 | AA7: millions | AB7: GBP | AD7: 36.6 | AE7: 495 | AF7: 637 | AG7: 172 | AH7: 33.6 | AI7: 906 | AJ7: 925 | AL7: 543 | AO7: 0 | AP7: 109 | AQ7: 473

Sheet Assumptions
A1: Input | B1: Value
A2: Current price (quote currency) | B2: 919.2
A3: Shares, final projected (m) | B3: 1355.3
A4: Net debt (m, model currency) | B4: 0
A5: Equity bridge total (m, + adds) | B5: 0
A6: Hurdle rate (%) | B6: 15
A7: Base revenue FY0 (m) | B7: 726
A8: FY0 | B8: FY2025
A9: Currency / units | B9: GBP millions
A10: FX rate (model -> quote) | B10: 100
A12: BEAR | C12: FY2026
A13: Revenue growth (%) | C13: 6
A14: EBITDA margin (%) | C14: 68.2
A15: SBC (% of revenue) | C15: 0
A16: Lease cost (% of revenue) | C16: 0
A17: D&A (% of revenue) | C17: 0
A18: Capex (% of revenue) | C18: 8.4
A19: Cash tax rate (%) | C19: 0
A20: WACC (%) | B20: 8
A21: Terminal growth (%) | B21: 2.5
A22: Terminal cap multiple (x FCF) | B22: 17
A23: Working-capital capture (% of revenue change) | B23: 0
A24: Scenario weight | B24: 0.15
A26: BASE | C26: FY2026
A27: Revenue growth (%) | C27: 6
A28: EBITDA margin (%) | C28: 68.2
A29: SBC (% of revenue) | C29: 0
A30: Lease cost (% of revenue) | C30: 0
A31: D&A (% of revenue) | C31: 0
A32: Capex (% of revenue) | C32: 8.4
A33: Cash tax rate (%) | C33: 0
A34: WACC (%) | B34: 8
A35: Terminal growth (%) | B35: 4.5
A36: Terminal cap multiple (x FCF) | B36: 27.13
A37: Working-capital capture (% of revenue change) | B37: 0
A38: Scenario weight | B38: 0.65
A40: BULL | C40: FY2026
A41: Revenue growth (%) | C41: 6
A42: EBITDA margin (%) | C42: 68.2
A43: SBC (% of revenue) | C43: 0
...

Sheet DCF_Bear
A1: SGRO.L owner-FCF component DCF: bear case (millions, GBP)
A3: Line | B3: FY2025 | C3: FY2026
A4: Year index (discount exponent) | B4: 0 | C4: =B4+1 -> 1
A5: Revenue growth (%) | C5: =Assumptions!C13 -> 6
A6: Revenue | B6: 726 | C6: =B6*(1+C5/100) -> 769.56
A7: EBITDA margin (%) | C7: =Assumptions!C14 -> 68.2
A8: EBITDA | C8: =C6*C7/100 -> 524.83992
A9: SBC (% of revenue) | C9: =Assumptions!C15 -> 0
A10: SBC charge | C10: =-C6*C9/100 -> 0
A11: Owner EBITDA (after SBC and leases) | C11: =C8+C10+C24 -> 524.83992
A12: D&A | C12: =-C6*Assumptions!C17/100 -> 0
A13: EBIT | C13: =C11+C12 -> 524.83992
A14: Cash tax rate (%) | C14: =Assumptions!C19 -> 0
A15: NOPAT | C15: =C13-MAX(0,C13)*C14/100 -> 524.83992
A16: D&A add-back | C16: =-C12 -> 0
A17: Capex | C17: =-C6*Assumptions!C18/100 -> -64.64304
A18: Working capital | C18: =(C6-B6)*Assumptions!$B$23/100 -> 0
A19: Unlevered owner FCF | C19: =C15+C16+C17+C18 -> 460.19688
A20: Discount factor | C20: =1/(1+$B$27/100)^C4 -> 0.92592593
A21: PV of FCF | C21: =C19*C20 -> 426.10822
A23: Lease cost (% of revenue) | C23: =Assumptions!C16 -> 0
A24: Lease cost | C24: =-C6*C23/100 -> 0
A26: Valuation
A27: WACC (%) | B27: =Assumptions!$B$20 -> 8
A28: Terminal growth (%) | B28: =Assumptions!$B$21 -> 2.5
A29: Terminal cap multiple (x FCF) | B29: =Assumptions!$B$22 -> 17
A30: Sum of PV of FCF | B30: =SUM(C21) -> 426.10822
A31: Terminal-year FCF | B31: =C19 -> 460.19688
A32: Gordon terminal value | B32: =IF(B27>B28,B31*(1+B28/100)/((B27-B28)/100),B31*B29) -> 8576.3964
A33: Cap terminal value | B33: =B31*B29 -> 7823.347
A34: Terminal value used: MAX(0,MIN(Gordon,cap)) | B34: =MAX(0,MIN(B32,B33)) -> 7823.347
A35: PV of terminal value | B35: =B34/(1+B27/100)^C4 -> 7243.8398
A36: Enterprise value | B36: =B30+B35 -> 7669.948
A37: Equity value (EV + bridge - net debt) | B37: =B36+Assumptions!$B$5-Assumptions!$B$4 -> 7669.948
A38: Value per share (quote currency) | B38: =B37/Assumptions!$B$3*Assumptions!$B$10 -> 565.92253
A39: Upside vs price | B39: =B38/Assumptions!$B$2-1 -> -0.38433146
A41: Street memo: PV of explicit-period SBC | B41: =SUMPRODUCT(-C10/(1+$B$27/100)^C4) -> 0
A42: Street memo: PV of terminal SBC (Gordon) | B42: =IF(B27>B28,-C10*(1+B28/100)/((B27-B28)/100),-C10*20)/(1+B27/100)^C4 -> 0
A43: Street value per share | B43: =(B37+B41+B42)/Assumptions!$B$3*Assumptions!$B$10 -> 565.92253
A45: Hurdle rate (%) | B45: =Assumptions!$B$6 -> 15
...

Sheet DCF_Base
A1: SGRO.L owner-FCF component DCF: base case (millions, GBP)
A3: Line | B3: FY2025 | C3: FY2026
A4: Year index (discount exponent) | B4: 0 | C4: =B4+1 -> 1
A5: Revenue growth (%) | C5: =Assumptions!C27 -> 6
A6: Revenue | B6: 726 | C6: =B6*(1+C5/100) -> 769.56
A7: EBITDA margin (%) | C7: =Assumptions!C28 -> 68.2
A8: EBITDA | C8: =C6*C7/100 -> 524.83992
A9: SBC (% of revenue) | C9: =Assumptions!C29 -> 0
A10: SBC charge | C10: =-C6*C9/100 -> 0
A11: Owner EBITDA (after SBC and leases) | C11: =C8+C10+C24 -> 524.83992
A12: D&A | C12: =-C6*Assumptions!C31/100 -> 0
A13: EBIT | C13: =C11+C12 -> 524.83992
A14: Cash tax rate (%) | C14: =Assumptions!C33 -> 0
A15: NOPAT | C15: =C13-MAX(0,C13)*C14/100 -> 524.83992
A16: D&A add-back | C16: =-C12 -> 0
A17: Capex | C17: =-C6*Assumptions!C32/100 -> -64.64304
A18: Working capital | C18: =(C6-B6)*Assumptions!$B$37/100 -> 0
A19: Unlevered owner FCF | C19: =C15+C16+C17+C18 -> 460.19688
A20: Discount factor | C20: =1/(1+$B$27/100)^C4 -> 0.92592593
A21: PV of FCF | C21: =C19*C20 -> 426.10822
A23: Lease cost (% of revenue) | C23: =Assumptions!C30 -> 0
A24: Lease cost | C24: =-C6*C23/100 -> 0
A26: Valuation
A27: WACC (%) | B27: =Assumptions!$B$34 -> 8
A28: Terminal growth (%) | B28: =Assumptions!$B$35 -> 4.5
A29: Terminal cap multiple (x FCF) | B29: =Assumptions!$B$36 -> 27.13
A30: Sum of PV of FCF | B30: =SUM(C21) -> 426.10822
A31: Terminal-year FCF | B31: =C19 -> 460.19688
A32: Gordon terminal value | B32: =IF(B27>B28,B31*(1+B28/100)/((B27-B28)/100),B31*B29) -> 13740.164
A33: Cap terminal value | B33: =B31*B29 -> 12485.141
A34: Terminal value used: MAX(0,MIN(Gordon,cap)) | B34: =MAX(0,MIN(B32,B33)) -> 12485.141
A35: PV of terminal value | B35: =B34/(1+B27/100)^C4 -> 11560.316
A36: Enterprise value | B36: =B30+B35 -> 11986.424
A37: Equity value (EV + bridge - net debt) | B37: =B36+Assumptions!$B$5-Assumptions!$B$4 -> 11986.424
A38: Value per share (quote currency) | B38: =B37/Assumptions!$B$3*Assumptions!$B$10 -> 884.41115
A39: Upside vs price | B39: =B38/Assumptions!$B$2-1 -> -0.03784688
A41: Street memo: PV of explicit-period SBC | B41: =SUMPRODUCT(-C10/(1+$B$27/100)^C4) -> 0
A42: Street memo: PV of terminal SBC (Gordon) | B42: =IF(B27>B28,-C10*(1+B28/100)/((B27-B28)/100),-C10*20)/(1+B27/100)^C4 -> 0
A43: Street value per share | B43: =(B37+B41+B42)/Assumptions!$B$3*Assumptions!$B$10 -> 884.41115
A45: Hurdle rate (%) | B45: =Assumptions!$B$6 -> 15
...

Sheet DCF_Bull
A1: SGRO.L owner-FCF component DCF: bull case (millions, GBP)
A3: Line | B3: FY2025 | C3: FY2026
A4: Year index (discount exponent) | B4: 0 | C4: =B4+1 -> 1
A5: Revenue growth (%) | C5: =Assumptions!C41 -> 6
A6: Revenue | B6: 726 | C6: =B6*(1+C5/100) -> 769.56
A7: EBITDA margin (%) | C7: =Assumptions!C42 -> 68.2
A8: EBITDA | C8: =C6*C7/100 -> 524.83992
A9: SBC (% of revenue) | C9: =Assumptions!C43 -> 0
A10: SBC charge | C10: =-C6*C9/100 -> 0
A11: Owner EBITDA (after SBC and leases) | C11: =C8+C10+C24 -> 524.83992
A12: D&A | C12: =-C6*Assumptions!C45/100 -> 0
A13: EBIT | C13: =C11+C12 -> 524.83992
A14: Cash tax rate (%) | C14: =Assumptions!C47 -> 0
A15: NOPAT | C15: =C13-MAX(0,C13)*C14/100 -> 524.83992
A16: D&A add-back | C16: =-C12 -> 0
A17: Capex | C17: =-C6*Assumptions!C46/100 -> -64.64304
A18: Working capital | C18: =(C6-B6)*Assumptions!$B$51/100 -> 0
A19: Unlevered owner FCF | C19: =C15+C16+C17+C18 -> 460.19688
A20: Discount factor | C20: =1/(1+$B$27/100)^C4 -> 0.92592593
A21: PV of FCF | C21: =C19*C20 -> 426.10822
A23: Lease cost (% of revenue) | C23: =Assumptions!C44 -> 0
A24: Lease cost | C24: =-C6*C23/100 -> 0
A26: Valuation
A27: WACC (%) | B27: =Assumptions!$B$48 -> 8
A28: Terminal growth (%) | B28: =Assumptions!$B$49 -> 4.5
A29: Terminal cap multiple (x FCF) | B29: =Assumptions!$B$50 -> 29.52
A30: Sum of PV of FCF | B30: =SUM(C21) -> 426.10822
A31: Terminal-year FCF | B31: =C19 -> 460.19688
A32: Gordon terminal value | B32: =IF(B27>B28,B31*(1+B28/100)/((B27-B28)/100),B31*B29) -> 13740.164
A33: Cap terminal value | B33: =B31*B29 -> 13585.012
A34: Terminal value used: MAX(0,MIN(Gordon,cap)) | B34: =MAX(0,MIN(B32,B33)) -> 13585.012
A35: PV of terminal value | B35: =B34/(1+B27/100)^C4 -> 12578.715
A36: Enterprise value | B36: =B30+B35 -> 13004.823
A37: Equity value (EV + bridge - net debt) | B37: =B36+Assumptions!$B$5-Assumptions!$B$4 -> 13004.823
A38: Value per share (quote currency) | B38: =B37/Assumptions!$B$3*Assumptions!$B$10 -> 959.55308
A39: Upside vs price | B39: =B38/Assumptions!$B$2-1 -> 0.043900222
A41: Street memo: PV of explicit-period SBC | B41: =SUMPRODUCT(-C10/(1+$B$27/100)^C4) -> 0
A42: Street memo: PV of terminal SBC (Gordon) | B42: =IF(B27>B28,-C10*(1+B28/100)/((B27-B28)/100),-C10*20)/(1+B27/100)^C4 -> 0
A43: Street value per share | B43: =(B37+B41+B42)/Assumptions!$B$3*Assumptions!$B$10 -> 959.55308
A45: Hurdle rate (%) | B45: =Assumptions!$B$6 -> 15
...

Sheet Valuation
A1: SGRO.L valuation summary
A3: Scenario | B3: Value per share | C3: Upside vs price | D3: Weight | E3: Street value per share | F3: Hurdle entry price
A4: Bear | B4: =DCF_Bear!$B$38 -> 565.92253 | C4: =B4/Assumptions!$B$2-1 -> -0.38433146 | D4: =Assumptions!$B$24 -> 0.15 | E4: =DCF_Bear!$B$43 -> 565.92253 | F4: =DCF_Bear!$B$47 -> 271.64281
A5: Base | B5: =DCF_Base!$B$38 -> 884.41115 | C5: =B5/Assumptions!$B$2-1 -> -0.03784688 | D5: =Assumptions!$B$38 -> 0.65 | E5: =DCF_Base!$B$43 -> 884.41115 | F5: =DCF_Base!$B$47 -> 323.3843
A6: Bull | B6: =DCF_Bull!$B$38 -> 959.55308 | C6: =B6/Assumptions!$B$2-1 -> 0.043900222 | D6: =Assumptions!$B$52 -> 0.2 | E6: =DCF_Bull!$B$43 -> 959.55308 | F6: =DCF_Bull!$B$47 -> 323.3843
A8: Probability-weighted value per share | B8: =SUMPRODUCT(B4:B6,D4:D6) -> 851.66624
A9: Street weighted value per share | B9: =SUMPRODUCT(E4:E6,D4:D6) -> 851.66624
A10: Margin of safety (1 - price/weighted) | B10: =1-Assumptions!$B$2/B8 -> -0.079296037
A11: Band position (%; 0 = house, 100 = street) | B11: =IF(ABS(B9-B8)>0.01*ABS(B8),(Assumptions!$B$2-B8)/(B9-B8)*100,"n/a") -> n/a
A12: Weighted 15% hurdle entry price | B12: =SUMPRODUCT(F4:F6,D4:D6) -> 315.62308
A14: Required-return table (base case; each row rebuilds its own terminal value) | C14: Rate (%)
A15: Value per share at 8% (WACC) | B15: =(SUMPRODUCT(DCF_Base!$C$19/(1+$C$15/100)^DCF_Base!$C$4)+MAX(0,MIN(IF($C$15>DCF_Base!$B$28,DCF_Base!$C$19*(1+DCF_Base!$B$28/100)/(($C$15-DCF_Base!$B$28)/100),DCF_Base!$C$19*DCF_Base!$B$29),DCF_Base!$C$19*DCF_Base!$B$29))/(1+$C$15/100)^DCF_Base!$C$4+Assumptions!$B$5-Assumptions!$B$4)/Assumptions!$B$3*Assumptions!$B$10 -> 884.41115 | C15: 8
A16: Value per share at 9% | B16: =(SUMPRODUCT(DCF_Base!$C$19/(1+$C$16/100)^DCF_Base!$C$4)+MAX(0,MIN(IF($C$16>DCF_Base!$B$28,DCF_Base!$C$19*(1+DCF_Base!$B$28/100)/(($C$16-DCF_Base!$B$28)/100),DCF_Base!$C$19*DCF_Base!$B$29),DCF_Base!$C$19*DCF_Base!$B$29))/(1+$C$16/100)^DCF_Base!$C$4+Assumptions!$B$5-Assumptions!$B$4)/Assumptions!$B$3*Assumptions!$B$10 -> 754.56337 | C16: 9
A17: Value per share at 10% | B17: =(SUMPRODUCT(DCF_Base!$C$19/(1+$C$17/100)^DCF_Base!$C$4)+MAX(0,MIN(IF($C$17>DCF_Base!$B$28,DCF_Base!$C$19*(1+DCF_Base!$B$28/100)/(($C$17-DCF_Base!$B$28)/100),DCF_Base!$C$19*DCF_Base!$B$29),DCF_Base!$C$19*DCF_Base!$B$29))/(1+$C$17/100)^DCF_Base!$C$4+Assumptions!$B$5-Assumptions!$B$4)/Assumptions!$B$3*Assumptions!$B$10 -> 617.37003 | C17: 10
A18: Value per share at 11% | B18: =(SUMPRODUCT(DCF_Base!$C$19/(1+$C$18/100)^DCF_Base!$C$4)+MAX(0,MIN(IF($C$18>DCF_Base!$B$28,DCF_Base!$C$19*(1+DCF_Base!$B$28/100)/(($C$18-DCF_Base!$B$28)/100),DCF_Base!$C$19*DCF_Base!$B$29),DCF_Base!$C$19*DCF_Base!$B$29))/(1+$C$18/100)^DCF_Base!$C$4+Assumptions!$B$5-Assumptions!$B$4)/Assumptions!$B$3*Assumptions!$B$10 -> 522.39002 | C18: 11
A19: Value per share at 12% | B19: =(SUMPRODUCT(DCF_Base!$C$19/(1+$C$19/100)^DCF_Base!$C$4)+MAX(0,MIN(IF($C$19>DCF_Base!$B$28,DCF_Base!$C$19*(1+DCF_Base!$B$28/100)/(($C$19-DCF_Base!$B$28)/100),DCF_Base!$C$19*DCF_Base!$B$29),DCF_Base!$C$19*DCF_Base!$B$29))/(1+$C$19/100)^DCF_Base!$C$4+Assumptions!$B$5-Assumptions!$B$4)/Assumptions!$B$3*Assumptions!$B$10 -> 452.73802 | C19: 12
A20: Value per share at 15% | B20: =(SUMPRODUCT(DCF_Base!$C$19/(1+$C$20/100)^DCF_Base!$C$4)+MAX(0,MIN(IF($C$20>DCF_Base!$B$28,DCF_Base!$C$19*(1+DCF_Base!$B$28/100)/(($C$20-DCF_Base!$B$28)/100),DCF_Base!$C$19*DCF_Base!$B$29),DCF_Base!$C$19*DCF_Base!$B$29))/(1+$C$20/100)^DCF_Base!$C$4+Assumptions!$B$5-Assumptions!$B$4)/Assumptions!$B$3*Assumptions!$B$10 -> 323.3843 | C20: 15
A22: Sensitivity: value per share, rows WACC (%) x columns terminal growth (%)
B23: 3.5 | C23: 4 | D23: 4.5 | E23: 5 | F23: 5.5
A24: 6 | B24: =(SUMPRODUCT(DCF_Base!$C$19/(1+$A$24/100)^DCF_Base!$C$4)+MAX(0,MIN(IF($A$24>$B$23,DCF_Base!$C$19*(1+$B$23/100)/(($A$24-$B$23)/100),DCF_Base!$C$19*DCF_Base!$B$29),DCF_Base!$C$19*DCF_Base!$B$29))/(1+$A$24/100)^DCF_Base!$C$4+Assumptions!$B$5-Assumptions!$B$4)/Assumptions!$B$3*Assumptions!$B$10 -> 901.09815 | C24: =(SUMPRODUCT(DCF_Base!$C$19/(1+$A$24/100)^DCF_Base!$C$4)+MAX(0,MIN(IF($A$24>$C$23,DCF_Base!$C$19*(1+$C$23/100)/(($A$24-$C$23)/100),DCF_Base!$C$19*DCF_Base!$B$29),DCF_Base!$C$19*DCF_Base!$B$29))/(1+$A$24/100)^DCF_Base!$C$4+Assumptions!$B$5-Assumptions!$B$4)/Assumptions!$B$3*Assumptions!$B$10 -> 901.09815 | D24: =(SUMPRODUCT(DCF_Base!$C$19/(1+$A$24/100)^DCF_Base!$C$4)+MAX(0,MIN(IF($A$24>$D$23,DCF_Base!$C$19*(1+$D$23/100)/(($A$24-$D$23)/100),DCF_Base!$C$19*DCF_Base!$B$29),DCF_Base!$C$19*DCF_Base!$B$29))/(1+$A$24/100)^DCF_Base!$C$4+Assumptions!$B$5-Assumptions!$B$4)/Assumptions!$B$3*Assumptions!$B$10 -> 901.09815 | E24: =(SUMPRODUCT(DCF_Base!$C$19/(1+$A$24/100)^DCF_Base!$C$4)+MAX(0,MIN(IF($A$24>$E$23,DCF_Base!$C$19*(1+$E$23/100)/(($A$24-$E$23)/100),DCF_Base!$C$19*DCF_Base!$B$29),DCF_Base!$C$19*DCF_Base!$B$29))/(1+$A$24/100)^DCF_Base!$C$4+Assumptions!$B$5-Assumptions!$B$4)/Assumptions!$B$3*Assumptions!$B$10 -> 901.09815 | F24: =(SUMPRODUCT(DCF_Base!$C$19/(1+$A$24/100)^DCF_Base!$C$4)+MAX(0,MIN(IF($A$24>$F$23,DCF_Base!$C$19*(1+$F$23/100)/(($A$24-$F$23)/100),DCF_Base!$C$19*DCF_Base!$B$29),DCF_Base!$C$19*DCF_Base!$B$29))/(1+$A$24/100)^DCF_Base!$C$4+Assumptions!$B$5-Assumptions!$B$4)/Assumptions!$B$3*Assumptions!$B$10 -> 901.09815
A25: 7 | B25: =(SUMPRODUCT(DCF_Base!$C$19/(1+$A$25/100)^DCF_Base!$C$4)+MAX(0,MIN(IF($A$25>$B$23,DCF_Base!$C$19*(1+$B$23/100)/(($A$25-$B$23)/100),DCF_Base!$C$19*DCF_Base!$B$29),DCF_Base!$C$19*DCF_Base!$B$29))/(1+$A$25/100)^DCF_Base!$C$4+Assumptions!$B$5-Assumptions!$B$4)/Assumptions!$B$3*Assumptions!$B$10 -> 892.67667 | C25: =(SUMPRODUCT(DCF_Base!$C$19/(1+$A$25/100)^DCF_Base!$C$4)+MAX(0,MIN(IF($A$25>$C$23,DCF_Base!$C$19*(1+$C$23/100)/(($A$25-$C$23)/100),DCF_Base!$C$19*DCF_Base!$B$29),DCF_Base!$C$19*DCF_Base!$B$29))/(1+$A$25/100)^DCF_Base!$C$4+Assumptions!$B$5-Assumptions!$B$4)/Assumptions!$B$3*Assumptions!$B$10 -> 892.67667 | D25: =(SUMPRODUCT(DCF_Base!$C$19/(1+$A$25/100)^DCF_Base!$C$4)+MAX(0,MIN(IF($A$25>$D$23,DCF_Base!$C$19*(1+$D$23/100)/(($A$25-$D$23)/100),DCF_Base!$C$19*DCF_Base!$B$29),DCF_Base!$C$19*DCF_Base!$B$29))/(1+$A$25/100)^DCF_Base!$C$4+Assumptions!$B$5-Assumptions!$B$4)/Assumptions!$B$3*Assumptions!$B$10 -> 892.67667 | E25: =(SUMPRODUCT(DCF_Base!$C$19/(1+$A$25/100)^DCF_Base!$C$4)+MAX(0,MIN(IF($A$25>$E$23,DCF_Base!$C$19*(1+$E$23/100)/(($A$25-$E$23)/100),DCF_Base!$C$19*DCF_Base!$B$29),DCF_Base!$C$19*DCF_Base!$B$29))/(1+$A$25/100)^DCF_Base!$C$4+Assumptions!$B$5-Assumptions!$B$4)/Assumptions!$B$3*Assumptions!$B$10 -> 892.67667 | F25: =(SUMPRODUCT(DCF_Base!$C$19/(1+$A$25/100)^DCF_Base!$C$4)+MAX(0,MIN(IF($A$25>$F$23,DCF_Base!$C$19*(1+$F$23/100)/(($A$25-$F$23)/100),DCF_Base!$C$19*DCF_Base!$B$29),DCF_Base!$C$19*DCF_Base!$B$29))/(1+$A$25/100)^DCF_Base!$C$4+Assumptions!$B$5-Assumptions!$B$4)/Assumptions!$B$3*Assumptions!$B$10 -> 892.67667
A26: 8 | B26: =(SUMPRODUCT(DCF_Base!$C$19/(1+$A$26/100)^DCF_Base!$C$4)+MAX(0,MIN(IF($A$26>$B$23,DCF_Base!$C$19*(1+$B$23/100)/(($A$26-$B$23)/100),DCF_Base!$C$19*DCF_Base!$B$29),DCF_Base!$C$19*DCF_Base!$B$29))/(1+$A$26/100)^DCF_Base!$C$4+Assumptions!$B$5-Assumptions!$B$4)/Assumptions!$B$3*Assumptions!$B$10 -> 754.56337 | C26: =(SUMPRODUCT(DCF_Base!$C$19/(1+$A$26/100)^DCF_Base!$C$4)+MAX(0,MIN(IF($A$26>$C$23,DCF_Base!$C$19*(1+$C$23/100)/(($A$26-$C$23)/100),DCF_Base!$C$19*DCF_Base!$B$29),DCF_Base!$C$19*DCF_Base!$B$29))/(1+$A$26/100)^DCF_Base!$C$4+Assumptions!$B$5-Assumptions!$B$4)/Assumptions!$B$3*Assumptions!$B$10 -> 848.88379 | D26: =(SUMPRODUCT(DCF_Base!$C$19/(1+$A$26/100)^DCF_Base!$C$4)+MAX(0,MIN(IF($A$26>$D$23,DCF_Base!$C$19*(1+$D$23/100)/(($A$26-$D$23)/100),DCF_Base!$C$19*DCF_Base!$B$29),DCF_Base!$C$19*DCF_Base!$B$29))/(1+$A$26/100)^DCF_Base!$C$4+Assumptions!$B$5-Assumptions!$B$4)/Assumptions!$B$3*Assumptions!$B$10 -> 884.41115 | E26: =(SUMPRODUCT(DCF_Base!$C$19/(1+$A$26/100)^DCF_Base!$C$4)+MAX(0,MIN(IF($A$26>$E$23,DCF_Base!$C$19*(1+$E$23/100)/(($A$26-$E$23)/100),DCF_Base!$C$19*DCF_Base!$B$29),DCF_Base!$C$19*DCF_Base!$B$29))/(1+$A$26/100)^DCF_Base!$C$4+Assumptions!$B$5-Assumptions!$B$4)/Assumptions!$B$3*Assumptions!$B$10 -> 884.41115 | F26: =(SUMPRODUCT(DCF_Base!$C$19/(1+$A$26/100)^DCF_Base!$C$4)+MAX(0,MIN(IF($A$26>$F$23,DCF_Base!$C$19*(1+$F$23/100)/(($A$26-$F$23)/100),DCF_Base!$C$19*DCF_Base!$B$29),DCF_Base!$C$19*DCF_Base!$B$29))/(1+$A$26/100)^DCF_Base!$C$4+Assumptions!$B$5-Assumptions!$B$4)/Assumptions!$B$3*Assumptions!$B$10 -> 884.41115
A27: 9 | B27: =(SUMPRODUCT(DCF_Base!$C$19/(1+$A$27/100)^DCF_Base!$C$4)+MAX(0,MIN(IF($A$27>$B$23,DCF_Base!$C$19*(1+$B$23/100)/(($A$27-$B$23)/100),DCF_Base!$C$19*DCF_Base!$B$29),DCF_Base!$C$19*DCF_Base!$B$29))/(1+$A$27/100)^DCF_Base!$C$4+Assumptions!$B$5-Assumptions!$B$4)/Assumptions!$B$3*Assumptions!$B$10 -> 617.37003 | C27: =(SUMPRODUCT(DCF_Base!$C$19/(1+$A$27/100)^DCF_Base!$C$4)+MAX(0,MIN(IF($A$27>$C$23,DCF_Base!$C$19*(1+$C$23/100)/(($A$27-$C$23)/100),DCF_Base!$C$19*DCF_Base!$B$29),DCF_Base!$C$19*DCF_Base!$B$29))/(1+$A$27/100)^DCF_Base!$C$4+Assumptions!$B$5-Assumptions!$B$4)/Assumptions!$B$3*Assumptions!$B$10 -> 679.10703 | D27: =(SUMPRODUCT(DCF_Base!$C$19/(1+$A$27/100)^DCF_Base!$C$4)+MAX(0,MIN(IF($A$27>$D$23,DCF_Base!$C$19*(1+$D$23/100)/(($A$27-$D$23)/100),DCF_Base!$C$19*DCF_Base!$B$29),DCF_Base!$C$19*DCF_Base!$B$29))/(1+$A$27/100)^DCF_Base!$C$4+Assumptions!$B$5-Assumptions!$B$4)/Assumptions!$B$3*Assumptions!$B$10 -> 754.56337 | E27: =(SUMPRODUCT(DCF_Base!$C$19/(1+$A$27/100)^DCF_Base!$C$4)+MAX(0,MIN(IF($A$27>$E$23,DCF_Base!$C$19*(1+$E$23/100)/(($A$27-$E$23)/100),DCF_Base!$C$19*DCF_Base!$B$29),DCF_Base!$C$19*DCF_Base!$B$29))/(1+$A$27/100)^DCF_Base!$C$4+Assumptions!$B$5-Assumptions!$B$4)/Assumptions!$B$3*Assumptions!$B$10 -> 848.88379 | F27: =(SUMPRODUCT(DCF_Base!$C$19/(1+$A$27/100)^DCF_Base!$C$4)+MAX(0,MIN(IF($A$27>$F$23,DCF_Base!$C$19*(1+$F$23/100)/(($A$27-$F$23)/100),DCF_Base!$C$19*DCF_Base!$B$29),DCF_Base!$C$19*DCF_Base!$B$29))/(1+$A$27/100)^DCF_Base!$C$4+Assumptions!$B$5-Assumptions!$B$4)/Assumptions!$B$3*Assumptions!$B$10 -> 876.29728
A28: 10 | B28: =(SUMPRODUCT(DCF_Base!$C$19/(1+$A$28/100)^DCF_Base!$C$4)+MAX(0,MIN(IF($A$28>$B$23,DCF_Base!$C$19*(1+$B$23/100)/(($A$28-$B$23)/100),DCF_Base!$C$19*DCF_Base!$B$29),DCF_Base!$C$19*DCF_Base!$B$29))/(1+$A$28/100)^DCF_Base!$C$4+Assumptions!$B$5-Assumptions!$B$4)/Assumptions!$B$3*Assumptions!$B$10 -> 522.39002 | C28: =(SUMPRODUCT(DCF_Base!$C$19/(1+$A$28/100)^DCF_Base!$C$4)+MAX(0,MIN(IF($A$28>$C$23,DCF_Base!$C$19*(1+$C$23/100)/(($A$28-$C$23)/100),DCF_Base!$C$19*DCF_Base!$B$29),DCF_Base!$C$19*DCF_Base!$B$29))/(1+$A$28/100)^DCF_Base!$C$4+Assumptions!$B$5-Assumptions!$B$4)/Assumptions!$B$3*Assumptions!$B$10 -> 565.92253 | D28: =(SUMPRODUCT(DCF_Base!$C$19/(1+$A$28/100)^DCF_Base!$C$4)+MAX(0,MIN(IF($A$28>$D$23,DCF_Base!$C$19*(1+$D$23/100)/(($A$28-$D$23)/100),DCF_Base!$C$19*DCF_Base!$B$29),DCF_Base!$C$19*DCF_Base!$B$29))/(1+$A$28/100)^DCF_Base!$C$4+Assumptions!$B$5-Assumptions!$B$4)/Assumptions!$B$3*Assumptions!$B$10 -> 617.37003 | E28: =(SUMPRODUCT(DCF_Base!$C$19/(1+$A$28/100)^DCF_Base!$C$4)+MAX(0,MIN(IF($A$28>$E$23,DCF_Base!$C$19*(1+$E$23/100)/(($A$28-$E$23)/100),DCF_Base!$C$19*DCF_Base!$B$29),DCF_Base!$C$19*DCF_Base!$B$29))/(1+$A$28/100)^DCF_Base!$C$4+Assumptions!$B$5-Assumptions!$B$4)/Assumptions!$B$3*Assumptions!$B$10 -> 679.10703 | F28: =(SUMPRODUCT(DCF_Base!$C$19/(1+$A$28/100)^DCF_Base!$C$4)+MAX(0,MIN(IF($A$28>$F$23,DCF_Base!$C$19*(1+$F$23/100)/(($A$28-$F$23)/100),DCF_Base!$C$19*DCF_Base!$B$29),DCF_Base!$C$19*DCF_Base!$B$29))/(1+$A$28/100)^DCF_Base!$C$4+Assumptions!$B$5-Assumptions!$B$4)/Assumptions!$B$3*Assumptions!$B$10 -> 754.56337
