Workbook

Sheet DCF Model
A1: TAH.NZ — Third Age Health Services DCF Valuation
A2: Base Case | NZD 000s | Shaded grey cells are INPUTS — change them to see results update
A3: Valuation date: 2026-06-25 | Current Price: NZD $4.40 | Shares: 9,954k
A6: KEY INPUTS
A7: Current Stock Price (NZD) | B7: 4.4
A8: Shares Outstanding (000s) | B8: 9954
A9: Cash & Equivalents (NZD 000s) | B9: 1650
A10: Bank Debt (NZD 000s) | B10: 1150
A11: Net Financial Debt (000s) [=Debt - Cash] | B11: =B10-B9 -> 0
A12: Lease Liabilities (IFRS16, note only) | B12: 2428
A13: Base Year FCF (NZD 000s) [FY26E normalised] | B13: 3200
A15: DISCOUNT RATE ASSUMPTIONS
A16: WACC | B16: 0.145
A17: Terminal Growth Rate | B17: 0.03
A19: YEAR 1-5 FCF GROWTH RATES
B20: Year 1 | C20: Year 2 | D20: Year 3 | E20: Year 4 | F20: Year 5
A21: FCF Growth Rate (adjust here) | B21: 0.1 | C21: 0.09 | D21: 0.07 | E21: 0.05 | F21: 0.04
A23: FREE CASH FLOW PROJECTIONS
A24: Beginning FCF (NZD 000s) | B24: Base FCF | C24: Year 1 | D24: Year 2 | E24: Year 3 | F24: Year 4 | G24: Year 5
A25: Projected FCF (NZD 000s) | B25: =$B$13 -> 0 | C25: =$B$13*(1+C$21) -> 0 | D25: =C25*(1+D$21) -> 0 | E25: =D25*(1+E$21) -> 0 | F25: =E25*(1+F$21) -> 0 | G25: =F25*(1+G$21) -> 0
A26: Discount Factor | C26: =1/(1+$B$16)^1 -> 0 | D26: =1/(1+$B$16)^2 -> 0 | E26: =1/(1+$B$16)^3 -> 0 | F26: =1/(1+$B$16)^4 -> 0 | G26: =1/(1+$B$16)^5 -> 0
A27: PV of FCF (NZD 000s) | C27: =C25*C26 -> 0 | D27: =D25*D26 -> 0 | E27: =E25*E26 -> 0 | F27: =F25*F26 -> 0 | G27: =G25*G26 -> 0
A29: TERMINAL VALUE & EQUITY VALUATION
A30: Sum of PV of FCF (NZD 000s) | B30: =SUM(C27:G27) -> 0
A31: Terminal Year FCF x (1+g) | B31: =G25*(1+$B$17) -> 0
A32: Terminal Value (NZD 000s) | B32: =B31/($B$16-$B$17) -> 0
A33: PV of Terminal Value (NZD 000s) | B33: =B32*G26 -> 0
A34: Enterprise Value (NZD 000s) | B34: =B30+B33 -> 0
A35: Less: Net Financial Debt (000s) | B35: =B11 -> 0
A36: Equity Value (NZD 000s) | B36: =B34-B35 -> 0
A37: INTRINSIC VALUE PER SHARE (NZD) | B37: =B36/$B$8 -> 0
A38: Upside / (Downside) vs $4.40 | B38: =(B37-$B$7)/$B$7 -> 0
A40: ENTRY PRICE FOR 15% CAGR TARGET
A41: Terminal Value per Share (NZD) | B41: =B32/$B$8 -> 0
A42: Entry Price (15% CAGR over 5 years) | B42: =B41/(1.15^5) -> 0
A43: Entry Price vs Current ($4.40) | B43: =($B$7-B42)/$B$7 -> 0
A45: NOTES
A46: - All figures in NZD thousands (000s) except per-share amounts and percentages
A47: - WACC 14.5% includes premiums: NZ small-cap base (11.5%) + single-payer +1% + workforce +0.5% + illiquidity +1% + integration +0.5%
A48: - Base FCF $3,200k = FY26E normalised (~15% FCF margin on $21.5M revenue). FY25 FCF $3,549k excluded as peak-cycle.
...

Sheet Scenarios
A1: TAH.NZ — Bear / Base / Bull Scenario Comparison
A2: NZD 000s where noted. Static values from DCF model. See DCF Model sheet for interactive base case.
A4: Scenario | B4: BEAR | C4: BASE | D4: BULL
A5: WACC | B5: 16.0% | C5: 14.5% | D5: 13.0%
A6: Terminal Growth Rate | B6: 2.0% | C6: 3.0% | D6: 3.5%
A7: Y1 FCF Growth | B7: 5.0% | C7: 10.0% | D7: 15.0%
A8: Y2 FCF Growth | B8: 4.0% | C8: 9.0% | D8: 13.0%
A9: Y3 FCF Growth | B9: 3.0% | C9: 7.0% | D9: 11.0%
A10: Y4 FCF Growth | B10: 2.0% | C10: 5.0% | D10: 9.0%
A11: Y5 FCF Growth | B11: 1.0% | C11: 4.0% | D11: 7.0%
A12: FCF Margin (approx.) | B12: 13% | C12: 15% | D12: 17%
A13: Description | B13: Funding freeze + workforce collapse | C13: Organic growth + modest M&A | D13: Capitation reweighting + M&A success
A15: Y1 Projected FCF ($000s) | B15: 3,360 | C15: 3,520 | D15: 3,680
A16: Y2 Projected FCF ($000s) | B16: 3,494 | C16: 3,837 | D16: 4,158
... A34: Probability Weight | B34: 25% | C34: 50% | D34: 25%
A35: Probability-Weighted IV | C35: $3.56

Sheet Sensitivity
A1: TAH.NZ — Sensitivity: Intrinsic Value (NZD/share) by WACC & Terminal Growth
A2: Base FCF $3,200k | Growth rates: Y1 10%, Y2 9%, Y3 7%, Y4 5%, Y5 4% | Net cash $500k | Shares 9,954k
A4: WACC \ Term. Growth | B4: 2.0% | C4: 2.5% | D4: 3.0% | E4: 3.5% | F4: 4.0%
A5: 11.0% | B5: 4.56 | C5: 4.76 | D5: 4.98 | E5: 5.22 | F5: 5.51
A6: 12.0% | B6: 4.1 | C6: 4.25 | D6: 4.42 | E6: 4.61 | F6: 4.82
A7: 13.0% | B7: 3.73 | C7: 3.85 | D7: 3.98 | E7: 4.12 | F7: 4.29
A8: 14.5% | B8: 3.28 | C8: 3.36 | D8: 3.46 | E8: 3.56 | F8: 3.68
A9: 16.0% | B9: 2.92 | C9: 2.99 | D9: 3.06 | E9: 3.13 | F9: 3.22
A11: Green = above current price ($4.40) | Blue = between $3.00 and $4.40 | Red = below $3.00 | Bold green = base case
A12: Sensitivity uses static formula values. For live sensitivity, adjust WACC and Terminal Growth in DCF Model sheet.
A15: LIVE SENSITIVITY — linked to DCF Model inputs
A16: Note: These values use the base-case growth rates from the DCF Model sheet but vary WACC and terminal growth statically.
A18: WACC \ Term. Growth | B18: 2.0% | C18: 2.5% | D18: 3.0% | E18: 3.5% | F18: 4.0%
A19: 11.0% | B19: =('DCF Model'!$B$13*(1+'DCF Model'!C$21)/(1+0.11)^1 + 'DCF Model'!$B$13*(1+'DCF Model'!C$21)*(1+'DCF Model'!D$21)/(1+0.11)^2 + 'DCF Model'!$B$13*(1+'DCF Model'!C$21)*(1+'DCF Model'!D$21)*(1+'DCF Model'!E$21)/(1+0.11)^3 + 'DCF Model'!$B$13*(1+'DCF Model'!C$21)*(1+'DCF Model'!D$21)*(1+'DCF Model'!E$21)*(1+'DCF Model'!F$21)/(1+0.11)^4 + 'DCF Model'!$B$13*(1+'DCF Model'!C$21)*(1+'DCF Model'!D$21)*(1+'DCF Model'!E$21)*(1+'DCF Model'!F$21)*(1+'DCF Model'!G$21)/(1+0.11)^5 + ('DCF Model'!$B$13*(1+'DCF Model'!C$21)*(1+'DCF Model'!D$21)*(1+'DCF Model'!E$21)*(1+'DCF Model'!F$21)*(1+'DCF Model'!G$21)*(1+0.02)/(0.11-0.02))/(1+0.11)^5-'DCF Model'!$B$11)/'DCF Model'!$B$8 -> 0 | C19: =('DCF Model'!$B$13*(1+'DCF Model'!C$21)/(1+0.11)^1 + 'DCF Model'!$B$13*(1+'DCF Model'!C$21)*(1+'DCF Model'!D$21)/(1+0.11)^2 + 'DCF Model'!$B$13*(1+'DCF Model'!C$21)*(1+'DCF Model'!D$21)*(1+'DCF Model'!E$21)/(1+0.11)^3 + 'DCF Model'!$B$13*(1+'DCF Model'!C$21)*(1+'DCF Model'!D$21)*(1+'DCF Model'!E$21)*(1+'DCF Model'!F$21)/(1+0.11)^4 + 'DCF Model'!$B$13*(1+'DCF Model'!C$21)*(1+'DCF Model'!D$21)*(1+'DCF Model'!E$21)*(1+'DCF Model'!F$21)*(1+'DCF Model'!G$21)/(1+0.11)^5 + ('DCF Model'!$B$13*(1+'DCF Model'!C$21)*(1+'DCF Model'!D$21)*(1+'DCF Model'!E$21)*(1+'DCF Model'!F$21)*(1+'DCF Model'!G$21)*(1+0.025)/(0.11-0.025))/(1+0.11)^5-'DCF Model'!$B$11)/'DCF Model'!$B$8 -> 0 | D19: =('DCF Model'!$B$13*(1+'DCF Model'!C$21)/(1+0.11)^1 + 'DCF Model'!$B$13*(1+'DCF Model'!C$21)*(1+'DCF Model'!D$21)/(1+0.11)^2 + 'DCF Model'!$B$13*(1+'DCF Model'!C$21)*(1+'DCF Model'!D$21)*(1+'DCF Model'!E$21)/(1+0.11)^3 + 'DCF Model'!$B$13*(1+'DCF Model'!C$21)*(1+'DCF Model'!D$21)*(1+'DCF Model'!E$21)*(1+'DCF Model'!F$21)/(1+0.11)^4 + 'DCF Model'!$B$13*(1+'DCF Model'!C$21)*(1+'DCF Model'!D$21)*(1+'DCF Model'!E$21)*(1+'DCF Model'!F$21)*(1+'DCF Model'!G$21)/(1+0.11)^5 + ('DCF Model'!$B$13*(1+'DCF Model'!C$21)*(1+'DCF Model'!D$21)*(1+'DCF Model'!E$21)*(1+'DCF Model'!F$21)*(1+'DCF Model'!G$21)*(1+0.03)/(0.11-0.03))/(1+0.11)^5-'DCF Model'!$B$11)/'DCF Model'!$B$8 -> 0 | E19: =('DCF Model'!$B$13*(1+'DCF Model'!C$21)/(1+0.11)^1 + 'DCF Model'!$B$13*(1+'DCF Model'!C$21)*(1+'DCF Model'!D$21)/(1+0.11)^2 + 'DCF Model'!$B$13*(1+'DCF Model'!C$21)*(1+'DCF Model'!D$21)*(1+'DCF Model'!E$21)/(1+0.11)^3 + 'DCF Model'!$B$13*(1+'DCF Model'!C$21)*(1+'DCF Model'!D$21)*(1+'DCF Model'!E$21)*(1+'DCF Model'!F$21)/(1+0.11)^4 + 'DCF Model'!$B$13*(1+'DCF Model'!C$21)*(1+'DCF Model'!D$21)*(1+'DCF Model'!E$21)*(1+'DCF Model'!F$21)*(1+'DCF Model'!G$21)/(1+0.11)^5 + ('DCF Model'!$B$13*(1+'DCF Model'!C$21)*(1+'DCF Model'!D$21)*(1+'DCF Model'!E$21)*(1+'DCF Model'!F$21)*(1+'DCF Model'!G$21)*(1+0.035)/(0.11-0.035))/(1+0.11)^5-'DCF Model'!$B$11)/'DCF Model'!$B$8 -> 0 | F19: =('DCF Model'!$B$13*(1+'DCF Model'!C$21)/(1+0.11)^1 + 'DCF Model'!$B$13*(1+'DCF Model'!C$21)*(1+'DCF Model'!D$21)/(1+0.11)^2 + 'DCF Model'!$B$13*(1+'DCF Model'!C$21)*(1+'DCF Model'!D$21)*(1+'DCF Model'!E$21)/(1+0.11)^3 + 'DCF Model'!$B$13*(1+'DCF Model'!C$21)*(1+'DCF Model'!D$21)*(1+'DCF Model'!E$21)*(1+'DCF Model'!F$21)/(1+0.11)^4 + 'DCF Model'!$B$13*(1+'DCF Model'!C$21)*(1+'DCF Model'!D$21)*(1+'DCF Model'!E$21)*(1+'DCF Model'!F$21)*(1+'DCF Model'!G$21)/(1+0.11)^5 + ('DCF Model'!$B$13*(1+'DCF Model'!C$21)*(1+'DCF Model'!D$21)*(1+'DCF Model'!E$21)*(1+'DCF Model'!F$21)*(1+'DCF Model'!G$21)*(1+0.04)/(0.11-0.04))/(1+0.11)^5-'DCF Model'!$B$11)/'DCF Model'!$B$8 -> 0
A20: 12.0% | B20: =('DCF Model'!$B$13*(1+'DCF Model'!C$21)/(1+0.12)^1 + 'DCF Model'!$B$13*(1+'DCF Model'!C$21)*(1+'DCF Model'!D$21)/(1+0.12)^2 + 'DCF Model'!$B$13*(1+'DCF Model'!C$21)*(1+'DCF Model'!D$21)*(1+'DCF Model'!E$21)/(1+0.12)^3 + 'DCF Model'!$B$13*(1+'DCF Model'!C$21)*(1+'DCF Model'!D$21)*(1+'DCF Model'!E$21)*(1+'DCF Model'!F$21)/(1+0.12)^4 + 'DCF Model'!$B$13*(1+'DCF Model'!C$21)*(1+'DCF Model'!D$21)*(1+'DCF Model'!E$21)*(1+'DCF Model'!F$21)*(1+'DCF Model'!G$21)/(1+0.12)^5 + ('DCF Model'!$B$13*(1+'DCF Model'!C$21)*(1+'DCF Model'!D$21)*(1+'DCF Model'!E$21)*(1+'DCF Model'!F$21)*(1+'DCF Model'!G$21)*(1+0.02)/(0.12-0.02))/(1+0.12)^5-'DCF Model'!$B$11)/'DCF Model'!$B$8 -> 0 | C20: =('DCF Model'!$B$13*(1+'DCF Model'!C$21)/(1+0.12)^1 + 'DCF Model'!$B$13*(1+'DCF Model'!C$21)*(1+'DCF Model'!D$21)/(1+0.12)^2 + 'DCF Model'!$B$13*(1+'DCF Model'!C$21)*(1+'DCF Model'!D$21)*(1+'DCF Model'!E$21)/(1+0.12)^3 + 'DCF Model'!$B$13*(1+'DCF Model'!C$21)*(1+'DCF Model'!D$21)*(1+'DCF Model'!E$21)*(1+'DCF Model'!F$21)/(1+0.12)^4 + 'DCF Model'!$B$13*(1+'DCF Model'!C$21)*(1+'DCF Model'!D$21)*(1+'DCF Model'!E$21)*(1+'DCF Model'!F$21)*(1+'DCF Model'!G$21)/(1+0.12)^5 + ('DCF Model'!$B$13*(1+'DCF Model'!C$21)*(1+'DCF Model'!D$21)*(1+'DCF Model'!E$21)*(1+'DCF Model'!F$21)*(1+'DCF Model'!G$21)*(1+0.025)/(0.12-0.025))/(1+0.12)^5-'DCF Model'!$B$11)/'DCF Model'!$B$8 -> 0 | D20: =('DCF Model'!$B$13*(1+'DCF Model'!C$21)/(1+0.12)^1 + 'DCF Model'!$B$13*(1+'DCF Model'!C$21)*(1+'DCF Model'!D$21)/(1+0.12)^2 + 'DCF Model'!$B$13*(1+'DCF Model'!C$21)*(1+'DCF Model'!D$21)*(1+'DCF Model'!E$21)/(1+0.12)^3 + 'DCF Model'!$B$13*(1+'DCF Model'!C$21)*(1+'DCF Model'!D$21)*(1+'DCF Model'!E$21)*(1+'DCF Model'!F$21)/(1+0.12)^4 + 'DCF Model'!$B$13*(1+'DCF Model'!C$21)*(1+'DCF Model'!D$21)*(1+'DCF Model'!E$21)*(1+'DCF Model'!F$21)*(1+'DCF Model'!G$21)/(1+0.12)^5 + ('DCF Model'!$B$13*(1+'DCF Model'!C$21)*(1+'DCF Model'!D$21)*(1+'DCF Model'!E$21)*(1+'DCF Model'!F$21)*(1+'DCF Model'!G$21)*(1+0.03)/(0.12-0.03))/(1+0.12)^5-'DCF Model'!$B$11)/'DCF Model'!$B$8 -> 0 | E20: =('DCF Model'!$B$13*(1+'DCF Model'!C$21)/(1+0.12)^1 + 'DCF Model'!$B$13*(1+'DCF Model'!C$21)*(1+'DCF Model'!D$21)/(1+0.12)^2 + 'DCF Model'!$B$13*(1+'DCF Model'!C$21)*(1+'DCF Model'!D$21)*(1+'DCF Model'!E$21)/(1+0.12)^3 + 'DCF Model'!$B$13*(1+'DCF Model'!C$21)*(1+'DCF Model'!D$21)*(1+'DCF Model'!E$21)*(1+'DCF Model'!F$21)/(1+0.12)^4 + 'DCF Model'!$B$13*(1+'DCF Model'!C$21)*(1+'DCF Model'!D$21)*(1+'DCF Model'!E$21)*(1+'DCF Model'!F$21)*(1+'DCF Model'!G$21)/(1+0.12)^5 + ('DCF Model'!$B$13*(1+'DCF Model'!C$21)*(1+'DCF Model'!D$21)*(1+'DCF Model'!E$21)*(1+'DCF Model'!F$21)*(1+'DCF Model'!G$21)*(1+0.035)/(0.12-0.035))/(1+0.12)^5-'DCF Model'!$B$11)/'DCF Model'!$B$8 -> 0 | F20: =('DCF Model'!$B$13*(1+'DCF Model'!C$21)/(1+0.12)^1 + 'DCF Model'!$B$13*(1+'DCF Model'!C$21)*(1+'DCF Model'!D$21)/(1+0.12)^2 + 'DCF Model'!$B$13*(1+'DCF Model'!C$21)*(1+'DCF Model'!D$21)*(1+'DCF Model'!E$21)/(1+0.12)^3 + 'DCF Model'!$B$13*(1+'DCF Model'!C$21)*(1+'DCF Model'!D$21)*(1+'DCF Model'!E$21)*(1+'DCF Model'!F$21)/(1+0.12)^4 + 'DCF Model'!$B$13*(1+'DCF Model'!C$21)*(1+'DCF Model'!D$21)*(1+'DCF Model'!E$21)*(1+'DCF Model'!F$21)*(1+'DCF Model'!G$21)/(1+0.12)^5 + ('DCF Model'!$B$13*(1+'DCF Model'!C$21)*(1+'DCF Model'!D$21)*(1+'DCF Model'!E$21)*(1+'DCF Model'!F$21)*(1+'DCF Model'!G$21)*(1+0.04)/(0.12-0.04))/(1+0.12)^5-'DCF Model'!$B$11)/'DCF Model'!$B$8 -> 0
A21: 13.0% | B21: =('DCF Model'!$B$13*(1+'DCF Model'!C$21)/(1+0.13)^1 + 'DCF Model'!$B$13*(1+'DCF Model'!C$21)*(1+'DCF Model'!D$21)/(1+0.13)^2 + 'DCF Model'!$B$13*(1+'DCF Model'!C$21)*(1+'DCF Model'!D$21)*(1+'DCF Model'!E$21)/(1+0.13)^3 + 'DCF Model'!$B$13*(1+'DCF Model'!C$21)*(1+'DCF Model'!D$21)*(1+'DCF Model'!E$21)*(1+'DCF Model'!F$21)/(1+0.13)^4 + 'DCF Model'!$B$13*(1+'DCF Model'!C$21)*(1+'DCF Model'!D$21)*(1+'DCF Model'!E$21)*(1+'DCF Model'!F$21)*(1+'DCF Model'!G$21)/(1+0.13)^5 + ('DCF Model'!$B$13*(1+'DCF Model'!C$21)*(1+'DCF Model'!D$21)*(1+'DCF Model'!E$21)*(1+'DCF Model'!F$21)*(1+'DCF Model'!G$21)*(1+0.02)/(0.13-0.02))/(1+0.13)^5-'DCF Model'!$B$11)/'DCF Model'!$B$8 -> 0 | C21: =('DCF Model'!$B$13*(1+'DCF Model'!C$21)/(1+0.13)^1 + 'DCF Model'!$B$13*(1+'DCF Model'!C$21)*(1+'DCF Model'!D$21)/(1+0.13)^2 + 'DCF Model'!$B$13*(1+'DCF Model'!C$21)*(1+'DCF Model'!D$21)*(1+'DCF Model'!E$21)/(1+0.13)^3 + 'DCF Model'!$B$13*(1+'DCF Model'!C$21)*(1+'DCF Model'!D$21)*(1+'DCF Model'!E$21)*(1+'DCF Model'!F$21)/(1+0.13)^4 + 'DCF Model'!$B$13*(1+'DCF Model'!C$21)*(1+'DCF Model'!D$21)*(1+'DCF Model'!E$21)*(1+'DCF Model'!F$21)*(1+'DCF Model'!G$21)/(1+0.13)^5 + ('DCF Model'!$B$13*(1+'DCF Model'!C$21)*(1+'DCF Model'!D$21)*(1+'DCF Model'!E$21)*(1+'DCF Model'!F$21)*(1+'DCF Model'!G$21)*(1+0.025)/(0.13-0.025))/(1+0.13)^5-'DCF Model'!$B$11)/'DCF Model'!$B$8 -> 0 | D21: =('DCF Model'!$B$13*(1+'DCF Model'!C$21)/(1+0.13)^1 + 'DCF Model'!$B$13*(1+'DCF Model'!C$21)*(1+'DCF Model'!D$21)/(1+0.13)^2 + 'DCF Model'!$B$13*(1+'DCF Model'!C$21)*(1+'DCF Model'!D$21)*(1+'DCF Model'!E$21)/(1+0.13)^3 + 'DCF Model'!$B$13*(1+'DCF Model'!C$21)*(1+'DCF Model'!D$21)*(1+'DCF Model'!E$21)*(1+'DCF Model'!F$21)/(1+0.13)^4 + 'DCF Model'!$B$13*(1+'DCF Model'!C$21)*(1+'DCF Model'!D$21)*(1+'DCF Model'!E$21)*(1+'DCF Model'!F$21)*(1+'DCF Model'!G$21)/(1+0.13)^5 + ('DCF Model'!$B$13*(1+'DCF Model'!C$21)*(1+'DCF Model'!D$21)*(1+'DCF Model'!E$21)*(1+'DCF Model'!F$21)*(1+'DCF Model'!G$21)*(1+0.03)/(0.13-0.03))/(1+0.13)^5-'DCF Model'!$B$11)/'DCF Model'!$B$8 -> 0 | E21: =('DCF Model'!$B$13*(1+'DCF Model'!C$21)/(1+0.13)^1 + 'DCF Model'!$B$13*(1+'DCF Model'!C$21)*(1+'DCF Model'!D$21)/(1+0.13)^2 + 'DCF Model'!$B$13*(1+'DCF Model'!C$21)*(1+'DCF Model'!D$21)*(1+'DCF Model'!E$21)/(1+0.13)^3 + 'DCF Model'!$B$13*(1+'DCF Model'!C$21)*(1+'DCF Model'!D$21)*(1+'DCF Model'!E$21)*(1+'DCF Model'!F$21)/(1+0.13)^4 + 'DCF Model'!$B$13*(1+'DCF Model'!C$21)*(1+'DCF Model'!D$21)*(1+'DCF Model'!E$21)*(1+'DCF Model'!F$21)*(1+'DCF Model'!G$21)/(1+0.13)^5 + ('DCF Model'!$B$13*(1+'DCF Model'!C$21)*(1+'DCF Model'!D$21)*(1+'DCF Model'!E$21)*(1+'DCF Model'!F$21)*(1+'DCF Model'!G$21)*(1+0.035)/(0.13-0.035))/(1+0.13)^5-'DCF Model'!$B$11)/'DCF Model'!$B$8 -> 0 | F21: =('DCF Model'!$B$13*(1+'DCF Model'!C$21)/(1+0.13)^1 + 'DCF Model'!$B$13*(1+'DCF Model'!C$21)*(1+'DCF Model'!D$21)/(1+0.13)^2 + 'DCF Model'!$B$13*(1+'DCF Model'!C$21)*(1+'DCF Model'!D$21)*(1+'DCF Model'!E$21)/(1+0.13)^3 + 'DCF Model'!$B$13*(1+'DCF Model'!C$21)*(1+'DCF Model'!D$21)*(1+'DCF Model'!E$21)*(1+'DCF Model'!F$21)/(1+0.13)^4 + 'DCF Model'!$B$13*(1+'DCF Model'!C$21)*(1+'DCF Model'!D$21)*(1+'DCF Model'!E$21)*(1+'DCF Model'!F$21)*(1+'DCF Model'!G$21)/(1+0.13)^5 + ('DCF Model'!$B$13*(1+'DCF Model'!C$21)*(1+'DCF Model'!D$21)*(1+'DCF Model'!E$21)*(1+'DCF Model'!F$21)*(1+'DCF Model'!G$21)*(1+0.04)/(0.13-0.04))/(1+0.13)^5-'DCF Model'!$B$11)/'DCF Model'!$B$8 -> 0
A22: 14.5% | B22: =('DCF Model'!$B$13*(1+'DCF Model'!C$21)/(1+0.145)^1 + 'DCF Model'!$B$13*(1+'DCF Model'!C$21)*(1+'DCF Model'!D$21)/(1+0.145)^2 + 'DCF Model'!$B$13*(1+'DCF Model'!C$21)*(1+'DCF Model'!D$21)*(1+'DCF Model'!E$21)/(1+0.145)^3 + 'DCF Model'!$B$13*(1+'DCF Model'!C$21)*(1+'DCF Model'!D$21)*(1+'DCF Model'!E$21)*(1+'DCF Model'!F$21)/(1+0.145)^4 + 'DCF Model'!$B$13*(1+'DCF Model'!C$21)*(1+'DCF Model'!D$21)*(1+'DCF Model'!E$21)*(1+'DCF Model'!F$21)*(1+'DCF Model'!G$21)/(1+0.145)^5 + ('DCF Model'!$B$13*(1+'DCF Model'!C$21)*(1+'DCF Model'!D$21)*(1+'DCF Model'!E$21)*(1+'DCF Model'!F$21)*(1+'DCF Model'!G$21)*(1+0.02)/(0.145-0.02))/(1+0.145)^5-'DCF Model'!$B$11)/'DCF Model'!$B$8 -> 0 | C22: =('DCF Model'!$B$13*(1+'DCF Model'!C$21)/(1+0.145)^1 + 'DCF Model'!$B$13*(1+'DCF Model'!C$21)*(1+'DCF Model'!D$21)/(1+0.145)^2 + 'DCF Model'!$B$13*(1+'DCF Model'!C$21)*(1+'DCF Model'!D$21)*(1+'DCF Model'!E$21)/(1+0.145)^3 + 'DCF Model'!$B$13*(1+'DCF Model'!C$21)*(1+'DCF Model'!D$21)*(1+'DCF Model'!E$21)*(1+'DCF Model'!F$21)/(1+0.145)^4 + 'DCF Model'!$B$13*(1+'DCF Model'!C$21)*(1+'DCF Model'!D$21)*(1+'DCF Model'!E$21)*(1+'DCF Model'!F$21)*(1+'DCF Model'!G$21)/(1+0.145)^5 + ('DCF Model'!$B$13*(1+'DCF Model'!C$21)*(1+'DCF Model'!D$21)*(1+'DCF Model'!E$21)*(1+'DCF Model'!F$21)*(1+'DCF Model'!G$21)*(1+0.025)/(0.145-0.025))/(1+0.145)^5-'DCF Model'!$B$11)/'DCF Model'!$B$8 -> 0 | D22: =('DCF Model'!$B$13*(1+'DCF Model'!C$21)/(1+0.145)^1 + 'DCF Model'!$B$13*(1+'DCF Model'!C$21)*(1+'DCF Model'!D$21)/(1+0.145)^2 + 'DCF Model'!$B$13*(1+'DCF Model'!C$21)*(1+'DCF Model'!D$21)*(1+'DCF Model'!E$21)/(1+0.145)^3 + 'DCF Model'!$B$13*(1+'DCF Model'!C$21)*(1+'DCF Model'!D$21)*(1+'DCF Model'!E$21)*(1+'DCF Model'!F$21)/(1+0.145)^4 + 'DCF Model'!$B$13*(1+'DCF Model'!C$21)*(1+'DCF Model'!D$21)*(1+'DCF Model'!E$21)*(1+'DCF Model'!F$21)*(1+'DCF Model'!G$21)/(1+0.145)^5 + ('DCF Model'!$B$13*(1+'DCF Model'!C$21)*(1+'DCF Model'!D$21)*(1+'DCF Model'!E$21)*(1+'DCF Model'!F$21)*(1+'DCF Model'!G$21)*(1+0.03)/(0.145-0.03))/(1+0.145)^5-'DCF Model'!$B$11)/'DCF Model'!$B$8 -> 0 | E22: =('DCF Model'!$B$13*(1+'DCF Model'!C$21)/(1+0.145)^1 + 'DCF Model'!$B$13*(1+'DCF Model'!C$21)*(1+'DCF Model'!D$21)/(1+0.145)^2 + 'DCF Model'!$B$13*(1+'DCF Model'!C$21)*(1+'DCF Model'!D$21)*(1+'DCF Model'!E$21)/(1+0.145)^3 + 'DCF Model'!$B$13*(1+'DCF Model'!C$21)*(1+'DCF Model'!D$21)*(1+'DCF Model'!E$21)*(1+'DCF Model'!F$21)/(1+0.145)^4 + 'DCF Model'!$B$13*(1+'DCF Model'!C$21)*(1+'DCF Model'!D$21)*(1+'DCF Model'!E$21)*(1+'DCF Model'!F$21)*(1+'DCF Model'!G$21)/(1+0.145)^5 + ('DCF Model'!$B$13*(1+'DCF Model'!C$21)*(1+'DCF Model'!D$21)*(1+'DCF Model'!E$21)*(1+'DCF Model'!F$21)*(1+'DCF Model'!G$21)*(1+0.035)/(0.145-0.035))/(1+0.145)^5-'DCF Model'!$B$11)/'DCF Model'!$B$8 -> 0 | F22: =('DCF Model'!$B$13*(1+'DCF Model'!C$21)/(1+0.145)^1 + 'DCF Model'!$B$13*(1+'DCF Model'!C$21)*(1+'DCF Model'!D$21)/(1+0.145)^2 + 'DCF Model'!$B$13*(1+'DCF Model'!C$21)*(1+'DCF Model'!D$21)*(1+'DCF Model'!E$21)/(1+0.145)^3 + 'DCF Model'!$B$13*(1+'DCF Model'!C$21)*(1+'DCF Model'!D$21)*(1+'DCF Model'!E$21)*(1+'DCF Model'!F$21)/(1+0.145)^4 + 'DCF Model'!$B$13*(1+'DCF Model'!C$21)*(1+'DCF Model'!D$21)*(1+'DCF Model'!E$21)*(1+'DCF Model'!F$21)*(1+'DCF Model'!G$21)/(1+0.145)^5 + ('DCF Model'!$B$13*(1+'DCF Model'!C$21)*(1+'DCF Model'!D$21)*(1+'DCF Model'!E$21)*(1+'DCF Model'!F$21)*(1+'DCF Model'!G$21)*(1+0.04)/(0.145-0.04))/(1+0.145)^5-'DCF Model'!$B$11)/'DCF Model'!$B$8 -> 0
A23: 16.0% | B23: =('DCF Model'!$B$13*(1+'DCF Model'!C$21)/(1+0.16)^1 + 'DCF Model'!$B$13*(1+'DCF Model'!C$21)*(1+'DCF Model'!D$21)/(1+0.16)^2 + 'DCF Model'!$B$13*(1+'DCF Model'!C$21)*(1+'DCF Model'!D$21)*(1+'DCF Model'!E$21)/(1+0.16)^3 + 'DCF Model'!$B$13*(1+'DCF Model'!C$21)*(1+'DCF Model'!D$21)*(1+'DCF Model'!E$21)*(1+'DCF Model'!F$21)/(1+0.16)^4 + 'DCF Model'!$B$13*(1+'DCF Model'!C$21)*(1+'DCF Model'!D$21)*(1+'DCF Model'!E$21)*(1+'DCF Model'!F$21)*(1+'DCF Model'!G$21)/(1+0.16)^5 + ('DCF Model'!$B$13*(1+'DCF Model'!C$21)*(1+'DCF Model'!D$21)*(1+'DCF Model'!E$21)*(1+'DCF Model'!F$21)*(1+'DCF Model'!G$21)*(1+0.02)/(0.16-0.02))/(1+0.16)^5-'DCF Model'!$B$11)/'DCF Model'!$B$8 -> 0 | C23: =('DCF Model'!$B$13*(1+'DCF Model'!C$21)/(1+0.16)^1 + 'DCF Model'!$B$13*(1+'DCF Model'!C$21)*(1+'DCF Model'!D$21)/(1+0.16)^2 + 'DCF Model'!$B$13*(1+'DCF Model'!C$21)*(1+'DCF Model'!D$21)*(1+'DCF Model'!E$21)/(1+0.16)^3 + 'DCF Model'!$B$13*(1+'DCF Model'!C$21)*(1+'DCF Model'!D$21)*(1+'DCF Model'!E$21)*(1+'DCF Model'!F$21)/(1+0.16)^4 + 'DCF Model'!$B$13*(1+'DCF Model'!C$21)*(1+'DCF Model'!D$21)*(1+'DCF Model'!E$21)*(1+'DCF Model'!F$21)*(1+'DCF Model'!G$21)/(1+0.16)^5 + ('DCF Model'!$B$13*(1+'DCF Model'!C$21)*(1+'DCF Model'!D$21)*(1+'DCF Model'!E$21)*(1+'DCF Model'!F$21)*(1+'DCF Model'!G$21)*(1+0.025)/(0.16-0.025))/(1+0.16)^5-'DCF Model'!$B$11)/'DCF Model'!$B$8 -> 0 | D23: =('DCF Model'!$B$13*(1+'DCF Model'!C$21)/(1+0.16)^1 + 'DCF Model'!$B$13*(1+'DCF Model'!C$21)*(1+'DCF Model'!D$21)/(1+0.16)^2 + 'DCF Model'!$B$13*(1+'DCF Model'!C$21)*(1+'DCF Model'!D$21)*(1+'DCF Model'!E$21)/(1+0.16)^3 + 'DCF Model'!$B$13*(1+'DCF Model'!C$21)*(1+'DCF Model'!D$21)*(1+'DCF Model'!E$21)*(1+'DCF Model'!F$21)/(1+0.16)^4 + 'DCF Model'!$B$13*(1+'DCF Model'!C$21)*(1+'DCF Model'!D$21)*(1+'DCF Model'!E$21)*(1+'DCF Model'!F$21)*(1+'DCF Model'!G$21)/(1+0.16)^5 + ('DCF Model'!$B$13*(1+'DCF Model'!C$21)*(1+'DCF Model'!D$21)*(1+'DCF Model'!E$21)*(1+'DCF Model'!F$21)*(1+'DCF Model'!G$21)*(1+0.03)/(0.16-0.03))/(1+0.16)^5-'DCF Model'!$B$11)/'DCF Model'!$B$8 -> 0 | E23: =('DCF Model'!$B$13*(1+'DCF Model'!C$21)/(1+0.16)^1 + 'DCF Model'!$B$13*(1+'DCF Model'!C$21)*(1+'DCF Model'!D$21)/(1+0.16)^2 + 'DCF Model'!$B$13*(1+'DCF Model'!C$21)*(1+'DCF Model'!D$21)*(1+'DCF Model'!E$21)/(1+0.16)^3 + 'DCF Model'!$B$13*(1+'DCF Model'!C$21)*(1+'DCF Model'!D$21)*(1+'DCF Model'!E$21)*(1+'DCF Model'!F$21)/(1+0.16)^4 + 'DCF Model'!$B$13*(1+'DCF Model'!C$21)*(1+'DCF Model'!D$21)*(1+'DCF Model'!E$21)*(1+'DCF Model'!F$21)*(1+'DCF Model'!G$21)/(1+0.16)^5 + ('DCF Model'!$B$13*(1+'DCF Model'!C$21)*(1+'DCF Model'!D$21)*(1+'DCF Model'!E$21)*(1+'DCF Model'!F$21)*(1+'DCF Model'!G$21)*(1+0.035)/(0.16-0.035))/(1+0.16)^5-'DCF Model'!$B$11)/'DCF Model'!$B$8 -> 0 | F23: =('DCF Model'!$B$13*(1+'DCF Model'!C$21)/(1+0.16)^1 + 'DCF Model'!$B$13*(1+'DCF Model'!C$21)*(1+'DCF Model'!D$21)/(1+0.16)^2 + 'DCF Model'!$B$13*(1+'DCF Model'!C$21)*(1+'DCF Model'!D$21)*(1+'DCF Model'!E$21)/(1+0.16)^3 + 'DCF Model'!$B$13*(1+'DCF Model'!C$21)*(1+'DCF Model'!D$21)*(1+'DCF Model'!E$21)*(1+'DCF Model'!F$21)/(1+0.16)^4 + 'DCF Model'!$B$13*(1+'DCF Model'!C$21)*(1+'DCF Model'!D$21)*(1+'DCF Model'!E$21)*(1+'DCF Model'!F$21)*(1+'DCF Model'!G$21)/(1+0.16)^5 + ('DCF Model'!$B$13*(1+'DCF Model'!C$21)*(1+'DCF Model'!D$21)*(1+'DCF Model'!E$21)*(1+'DCF Model'!F$21)*(1+'DCF Model'!G$21)*(1+0.04)/(0.16-0.04))/(1+0.16)^5-'DCF Model'!$B$11)/'DCF Model'!$B$8 -> 0
A25: Live sensitivity updates when you change FCF growth rates in the DCF Model sheet.

Sheet Historical
A1: TAH.NZ — Historical Financial Data & Valuation Multiples
A2: Figures in NZD 000s unless noted. Source: Annual Reports FY2017-FY2025 + H1 FY2026.
A4: Metric | B4: FY2017 | C4: FY2018 | D4: FY2019 | E4: FY2020 | F4: FY2021 | G4: FY2022 | H4: FY2023 | I4: FY2024 | J4: FY2025 | K4: H1 FY26
A5: Revenue ($000s) | B5: 3764.5 | C5: 4574.9 | D5: 5671.8 | E5: 5260.4 | F5: 5490.4 | G5: 5900 | H5: 11217 | I5: 15151 | J5: 19081 | K5: 10653
A6: EBITDA ($000s) | B6: 345.5 | C6: 620.7 | D6: 1407.8 | E6: 1573.5 | F6: 1709.6 | G6: 1726 | H6: 1558 | I6: 2996 | J6: 4678 | K6: 2759
A7: Net Income ($000s) | B7: 110.3 | C7: 333.6 | D7: 1050.3 | E7: 1322.6 | F7: 1041.5 | G7: 1173 | H7: 439 | I7: 1400 | J7: 2339 | K7: 1415
A8: Free Cash Flow ($000s) | B8: 350.4 | C8: 403.9 | D8: 1046.4 | E8: 1336 | F8: 1550.3 | G8: 1037 | H8: 734 | I8: 2528 | J8: 3549 | K8: 1380
A9: Shareholders Equity ($000s) | B9: -1206.3 | C9: -1242.4 | D9: -29.6 | E9: 861 | F9: 1976 | G9: 2696 | H9: 2544 | I9: 2913 | J9: 3967 | K9: 4815
A10: FCF Margin (%) | B10: 0.093 | C10: 0.088 | D10: 0.185 | E10: 0.254 | F10: 0.282 | G10: 0.176 | H10: 0.065 | I10: 0.167 | J10: 0.186 | K10: 0.13
A11: EBITDA Margin (%) | B11: 0.092 | C11: 0.136 | D11: 0.248 | E11: 0.299 | F11: 0.311 | G11: 0.293 | H11: 0.139 | I11: 0.198 | J11: 0.245 | K11: 0.259
A12: Net Margin (%) | B12: 0.029 | C12: 0.073 | D12: 0.185 | E12: 0.251 | F12: 0.19 | G12: 0.199 | H12: 0.039 | I12: 0.092 | J12: 0.123 | K12: 0.133
A15: HISTORICAL GROWTH RATES
A16: Metric | B16: 3-Year CAGR | C16: 5-Year CAGR | D16: Note
A17: Revenue | B17: 0.479 | C17: 0.294 | D17: ACQUISITION-DISTORTED — cannot use for organic growth forecasting
A18: EPS | B18: 0.253 | C18: 0.096 | D18: Diluted by acquisition costs in FY23; improving FY24-25
A19: Shareholders Equity | B19: 0.137 | C19: 0.357 | D19: 5yr inflated by negative equity base in FY2020 ($861k); use cautiously
A20: Free Cash Flow | B20: 0.507 | C20: 0.216 | D20: FY22 and FY23 depressed (deal costs); high base effect in FY25
A21: SELECTED ORGANIC GROWTH | B21: 0.06 | D21: Custom estimate: organic ARC patient growth + capitation uplift, ex-M&A
A24: HISTORICAL TRADING MULTIPLES (NZX FY-end prices)
A25: Period | B25: FY-End Price | C25: P/E | D25: EV/EBITDA | E25: P/Sales | F25: P/Book
A26: FY2021 | B26: 1.82 | C26: 16.4x | D26: 9.5x | E26: 3.3x | F26: 9.2x
A27: FY2022 | B27: 2.31 | C27: 19.4x | D27: 12.7x | E27: 3.9x | F27: 8.5x
A28: FY2023 | B28: 1.34 | C28: 30.5x | D28: 9.2x | E28: 1.19x | F28: 5.2x
A29: FY2024 | B29: 1.51 | C29: 10.8x | D29: 4.9x | E29: 0.99x | F29: 5.1x
A30: FY2025 | B30: 3.12 | C30: 13.3x | D30: 6.3x | E30: 1.63x | F30: 7.8x
A31: Current $4.40 (FY26E) | B31: 4.4 | C31: 14.1x | D31: 8.0x | E31: 2.04x | F31: 8.1x
A33: FY23 P/E of 30.5x is outlier (EastMed/DFM acquisition costs depressed earnings). FY24 P/Sales 0.99x anomalously low.
A34: Sanity check: Base IV $3.46 implies EV/EBITDA 6.3x, P/E 11.1x, P/Sales 1.6x — all within historical ranges. PASS.

Sheet WACC & Assumptions
A1: TAH.NZ — WACC Construction & Scenario Assumptions
A2: Rationale for discount rate and growth rate selection.
A4: WACC CONSTRUCTION (BASE CASE)
A5: Component | B5: Rate | C5: Rationale
A6: NZ Small-Cap Base WACC | B6: 11.5% | C6: Midpoint of 11-12% NZ small-cap equity risk range
A7: + Single-payer funding concentration | B7: +1.0% | C7: 100% revenue from Health NZ/PHOs; under Commissioner control; price-taker
A8: + Clinical workforce constraint | B8: +0.5% | C8: GP shortage structural; growth ceiling constrained; wage inflation structural
A9: + Micro-cap illiquidity premium | B9: +1.0% | C9: Market cap ~NZD 44M (vs $300M threshold); thin NZX trading; limited inst. coverage
A10: + Acquisition integration complexity | B10: +0.5% | C10: 4 acquisitions in 18 months; 67-80% minority structures; EastMed loss-making at NCI
A11: =BASE CASE WACC -> 0 | B11: 14.5% | C11: Applied to Base scenario DCF
A12: Bull Case WACC | B12: 13.0% | C12: Partial premium compression: capitation success + scale growth toward $50M+ revenue
A13: Bear Case WACC | B13: 16.0% | C13: Escalated: funding deterioration or workforce crisis materialises
A16: FCF NORMALISATION RATIONALE
A17: FCF Measure | B17: Amount | C17: Note
A18: FY2025 FCF (peak) | B18: $3,549k | C18: FCF margin 18.6% — near-peak after sharp margin expansion; not sustainable as perpetual base
A19: H1 FY26 FCF (annualised) | B19: $2,760k | C19: FCF margin 13.0% — partly seasonal; H2 typically stronger; captures FY26 start of "difficult" year
A20: FY26E Prelim NPAT | B20: $3,100k | C20: Prelim unaudited; implies strong FCF conversion similar to FY25 ~95%
A21: SELECTED BASE FCF | B21: $3,200k | C21: FY26E estimate; FCF margin ~15% on ~$21.5M revenue; mid-cycle between peak and H1 run-rate
A22: Mid-cycle avg FY21-FY25 | B22: $1,880k | C22: Simple average; understates current scale but confirms conservative approach appropriate
A25: GROWTH RATE SELECTION RATIONALE
A26: Why standard CAGRs cannot be used:
A27: - Revenue 3yr CAGR 47.9%, FCF 3yr CAGR 50.7%: acquisition-dominated (DFM/EastMed FY23, Hub FY24, ARC Health/Cicada FY26)
A28: - Revenue 5yr CAGR 29.4%: includes same inorganic bolts; diverges 71% from Equity CAGR -> FLAGGED
A29: - Equity CAGR distorted by negative equity base (FY17-FY19) and rapid retained earnings in post-listing years
A31: Selected growth framework:
A32: Organic ARC patient growth ~3.7% (H1 FY26) + capitation uplift 9.69% (FY26) = combined ~10-13% near term
A33: Through-cycle organic estimate 6-8% pa (demographics + partial capitation formula benefit)
A34: Bolt-on M&A adds ~2pp in active acquisition years (modelled conservatively)
A35: FY27 management guidance explicitly "difficult" -> decelerate quickly from Y1 10% toward 4% by Y5
A36: Terminal growth 3%: NZ demographic tailwind (~2-3% population growth in 65+ cohort) moderating at maturity
