Workbook

Sheet Model_Info
A1: TRA.NZ Turners Automotive Group - distributable-earnings (FCFE) DCF
A2: Version | B2: v1 2026-09-13. Fresh build; supersedes nothing (first TRA.NZ valuation).
A3: Built by | B3: dcf-analyst agent (Claude Fable 5.1) on 2026-09-13 at the orchestrator's request.
A4: Price | B4: NZ$7.50 NZX regular close Fri 11-Sep-2026 (Yahoo regularMarketTime 2026-09-11T04:59:51Z). Goes stale daily.
A5: Balance sheet | B5: 31-Mar-2026 FY2026 annual report (authorised 25-Jun-2026): borrowings 586.322, cash 20.243, lease liabilities 20.065, equity 317.866, finance receivables 566.023.
A6: Share count | B6: 91,025,265 shares on issue 31-Mar-2026 (note 10.1); option dilution 36k shares immaterial. Held flat. July-2026 DRP issuance (~0.5-0.9m) not yet in a filing.
A7: Guidance | B7: FY28 NPBT target NZ$65m expected in FY27; FY31 NPBT NZ$100m (March-2026 investor day). FY26 normalised NPBT 63.224 (ex 7.474 EC Credit goodwill write-down).
A8: Model choice | B8: Post-interest earnings at 11% NZD cost of equity, net debt = 0 (borrowings fund the loan book/property and all interest is inside the flows). Reason: retailer + NZ$566m finance book + insurer share one syndicated facility; an EV/WACC DCF or a debt split by segment cannot be done without inventing an allocation.
A9: Margin driver | B9: Row 7 'adj margin' = (NPBT + D&A + SBC)/revenue - post-interest, pre-D&A EARNINGS margin, not EBITDA. FY26 normalised 16.70%.
A10: Leases | B10: Treatment B: lease principal (1.543% of revenue) charged in row 11; lease interest already inside NPBT; ROU depreciation inside D&A; lease liabilities excluded from any bridge.
A11: Capital retention | B11: Row 20 'WC' uses a NEGATIVE capture rate: equity retained to fund finance-receivables growth, scaled to the change in revenue (base -15%, bull -12%, bear -20%).
A12: Capex | B12: Row 18 per-year driver: Auto Retail branch/property programme 7.5% of revenue tapering to 3.0% (maintenance) by FY36. Largest single lever (~NZ$0.65/share if held at 4.5%).
A13: Terminal value | B13: MAX(0, MIN(Gordon, 15 x FCF_10)); 15x rather than 20x because used-car and consumer-credit cycles are in the flows. Gordon binds at 11%.
... A17: Warning | B17: All figures go stale. The workbook and TRA.NZ_DCF.json were verified to agree at build time; the workbook is authoritative once drivers are edited.

Sheet Actuals
A1: Metric (NZ$m) | B1: FY2020 | C1: FY2021 | D1: FY2022 | E1: FY2023 | F1: FY2024 | G1: FY2025 | H1: FY2026 | I1: Source
A2: Revenue | B2: 332.174 | C2: 296.512 | D2: 342.029 | E2: 389.027 | F2: 416.145 | G2: 412.904 | H2: 450.171 | I2: core_metrics / annual reports
A3: Profit before tax (reported) | B3: 29.065 | C3: 37.375 | D3: 43.12 | E3: 45.545 | F3: 49.139 | G3: 54.274 | H3: 55.75 | I3: kpis ProfitBeforeTax
A4: Profit before tax (normalised) | B4: 29.065 | C4: 37.375 | D4: 43.12 | E4: 45.545 | F4: 49.139 | G4: 54.274 | H4: 63.224 | I4: FY26 ex EC Credit goodwill write-down 7.474
A5: Net profit (reported) | B5: 20.953 | C5: 26.864 | D5: 31.281 | E5: 32.566 | F5: 32.966 | G5: 38.587 | H5: 38.172 | I5: core_metrics
A6: Net profit (normalised) | B6: 20.953 | C6: 26.864 | D6: 31.281 | E6: 32.566 | F6: 32.966 | G6: 38.587 | H6: 45.6 | I6: FY26 AR p.10
A7: Depreciation & amortisation | B7: 11.919 | C7: 11.418 | D7: 10.702 | E7: 11.478 | F7: 11.968 | G7: 11.651 | H7: 11.097 | I7: kpis Depreciation
A8: Capex (PP&E + intangibles) | B8: 19.245 | C8: 8.641 | D8: 16.121 | E8: 44.177 | F8: 18.641 | G8: 32.136 | H8: 41.7 | I8: cash flow statements
A9: Lease principal paid | B9: 6.998 | C9: 6.346 | D9: 5.563 | E9: 7.501 | F9: 6.303 | G9: 6.676 | H9: 6.944 | I9: cash flow statements
A10: Stock-based comp | G10: 0.993 | H10: 0.862 | I10: kpis StockBasedComp
A11: Interest expense | B11: 14.853 | D11: 10.932 | E11: 19.933 | F11: 27.842 | G11: 27.451 | H11: 28.067 | I11: kpis InterestExpense
A12: Cash taxes paid | B12: 11.46 | C12: 8.166 | D12: 9.326 | E12: 10.394 | F12: 15.259 | G12: 14.451 | H12: 17.512 | I12: kpis CashTaxesPaid
A13: Finance receivables | C13: 377 | D13: 422.87 | E13: 424.621 | F13: 430.299 | G13: 447.218 | H13: 566.023 | I13: kpis FinanceReceivables
A14: Shareholders' equity | B14: 223.055 | C14: 233.57 | D14: 252.397 | E14: 270.413 | F14: 278.224 | G14: 298.493 | H14: 317.866 | I14: core_metrics
A15: Total borrowings | B15: 350.364 | C15: 339.611 | D15: 412.761 | E15: 412.035 | F15: 425.318 | G15: 446.059 | H15: 586.322 | I15: core_metrics
A16: Shares outstanding (m, period end) | B16: 86.0555 | C16: 85.5514 | D16: 85.9686 | E16: 86.5183 | F16: 87.4233 | G16: 89.8938 | H16: 91.0253 | I16: FY26 note 10.1 for FY25/26
A17: EPS reported (cents) | B17: 24.35 | C17: 31.4 | D17: 36.39 | E17: 37.64 | F17: 37.71 | G17: 43.37 | H17: 42.17 | I17: core_metrics
A18: DPS (cents) | B18: 14 | C18: 20 | D18: 23 | E18: 23 | F18: 25.5 | G18: 29 | H18: 33 | I18: H1 FY26 presentation p.14 / FY26 AR
A19: Segment NPBT FY26: Auto Retail 32.567 / Finance 19.245 / Insurance 17.290 / Credit Mgmt 1.840 norm (-5.634 rep) / Corporate -7.498 / JV -0.220 | I19: FY26 AR note 2
A20: Guidance: FY27 NPBT target NZ$65m (was FY28); FY31 NPBT NZ$100m | I20: FY26 AR p.12, p.20

Sheet Assumptions
A1: Global inputs
A3: Current price (NZ$) | B3: 7.5 | C3: NZX close 11-Sep-2026
A4: Diluted shares (m) | B4: 91.025265 | C4: 31-Mar-2026 shares on issue; flat
A5: Net debt (NZ$m) | B5: 0 | C5: Zero by construction: post-interest flows at cost of equity
A6: Cost of equity | B6: 0.11 | C6: NZ 10yr ~4.5% + 1.1 x 5.5% ERP + 0.4% size; same in all scenarios
A7: D&A % revenue | B7: 0.024650633 | C7: FY26 11.097 / 450.171, incl. ROU depreciation
A8: Lease principal % revenue | B8: 0.01542525 | C8: FY26 6.944 / 450.171 (treatment B)
A9: Cash tax rate | B9: 0.28 | C9: NZ statutory; FY26 normalised effective 27.8%
A10: Terminal cap multiple (x FCF_10) | B10: 15 | C10: Cyclical: 15x not 20x
A11: Hurdle rate | B11: 0.15 | C11: Entry price IRR
A12: SBC % revenue | B12: 0.0019148279 | C12: FY26 0.862 / 450.171; flat
A14: Scenario | B14: Terminal growth | C14: Probability | D14: Capital retention (% of revenue change, negative)
A15: Bear | B15: 0.02 | C15: 0.2 | D15: -0.2
A16: Base | B16: 0.03 | C16: 0.5 | D16: -0.15
A17: Bull | B17: 0.035 | C17: 0.3 | D17: -0.12
A18: Weights sum | C18: =SUM(C15:C17)
A20: Scenario narratives
A21: Bear | B21: Narrative: The late-March 2026 demand shock persists into a NZ recession: used-car margins compress, a NZ$566m book grown 27% in one year seasons badly (impairments double), NIM is squeezed as hedges roll, and the branch programme is slowed. NPBT troughs at ~NZ$53m in FY28 and only regains FY26's normalised level by FY31; mature margin 15.5%, retention 20% of revenue growth, terminal growth 2%. Note the bear case distributes MORE cash in years 1-2 than base because growth capex and loan-book retention stop: the loss is in the terminal, not the interim flows.
A22: Base | B22: Narrative: Auto Retail keeps its wholesale-to-retail and lower-price-point mix, opens the FY28 branch cohort and grows mid-single digits with owned-stock margins holding; Oxford Finance grows the book low-double digits on stable 5.7% NIM with arrears at 2.5-3%; Autosure compounds premium mid-single digits with MBI loss ratios near 58%; corporate interest keeps falling after the securitisation term-out. NPBT reaches ~NZ$97m by FY31 (target NZ$100m), then growth fades to 3%. Property capex tapers from 7.5% to 3.0% of revenue by FY36; 15% of each revenue dollar added is retained as loan-book equity.
A23: Bull | B23: Narrative: The NZ consumer recovery arrives: used-car prices lift, lease-unit and import volumes recover, the 15-branch programme delivers Christchurch-style +22% local sourcing gains, Oxford Finance keeps taking share with the term-out structure requiring only 1.4% capital, and direct-to-consumer insurance scales. NPBT NZ$114m by FY31 (target beaten a year early, as every prior target has been), mature post-interest margin 19.5%, retention 12% of revenue growth, terminal growth 3.5%.

Sheet DCF_Bear
A1: Bear case - distributable earnings (NZ$m)
A3: Year | B3: 2026A | C3: FY2027E | D3: FY2028E | E3: FY2029E | F3: FY2030E | G3: FY2031E | H3: FY2032E | I3: FY2033E | J3: FY2034E | K3: FY2035E | L3: FY2036E
A4: Index | B4: 0 | C4: 1 | D4: 2 | E4: 3 | F4: 4 | G4: 5 | H4: 6 | I4: 7 | J4: 8 | K4: 9 | L4: 10
A5: Revenue growth | C5: 0.02 | D5: 0.01 | E5: 0.03 | F5: 0.03 | G5: 0.03 | H5: 0.03 | I5: 0.03 | J5: 0.03 | K5: 0.03 | L5: 0.03
A6: Revenue | B6: 450.171 | C6: =B6*(1+C5) | D6: =C6*(1+D5) | E6: =D6*(1+E5) | F6: =E6*(1+F5) | G6: =F6*(1+G5) | H6: =G6*(1+H5) | I6: =H6*(1+I5) | J6: =I6*(1+J5) | ... L6: =K6*(1+L5)
A7: Adj margin (NPBT+D&A+SBC)/rev | C7: 0.15 | D7: 0.14 | E7: 0.143 | F7: 0.148 | G7: 0.152 | H7: 0.155 | I7: 0.155 | J7: 0.155 | K7: 0.155 | L7: 0.155
A8: Adj earnings pre-D&A | C8: =C6*C7 | D8: =D6*D7 | E8: =E6*E7 | F8: =F6*F7 | G8: =G6*G7 | H8: =H6*H7 | I8: =I6*I7 | J8: =J6*J7 | ... L8: =L6*L7
A9: SBC % revenue | C9: =Assumptions!$B$12 | D9: =Assumptions!$B$12 | E9: =Assumptions!$B$12 | F9: =Assumptions!$B$12 | G9: =Assumptions!$B$12 | H9: =Assumptions!$B$12 | I9: =Assumptions!$B$12 | J9: =Assumptions!$B$12 | ... L9: =Assumptions!$B$12
A10: SBC | C10: =-C6*C9 | D10: =-D6*D9 | E10: =-E6*E9 | F10: =-F6*F9 | G10: =-G6*G9 | H10: =-H6*H9 | I10: =-I6*I9 | J10: =-J6*J9 | ... L10: =-L6*L9
A11: Lease principal | C11: =-C6*Assumptions!$B$8 | D11: =-D6*Assumptions!$B$8 | E11: =-E6*Assumptions!$B$8 | F11: =-F6*Assumptions!$B$8 | G11: =-G6*Assumptions!$B$8 | H11: =-H6*Assumptions!$B$8 | I11: =-I6*Assumptions!$B$8 | J11: =-J6*Assumptions!$B$8 | ... L11: =-L6*Assumptions!$B$8
A12: Owner earnings pre-D&A | C12: =C8+C10+C11 | D12: =D8+D10+D11 | E12: =E8+E10+E11 | F12: =F8+F10+F11 | G12: =G8+G10+G11 | H12: =H8+H10+H11 | I12: =I8+I10+I11 | J12: =J8+J10+J11 | ... L12: =L8+L10+L11
A13: D&A | C13: =-C6*Assumptions!$B$7 | D13: =-D6*Assumptions!$B$7 | E13: =-E6*Assumptions!$B$7 | F13: =-F6*Assumptions!$B$7 | G13: =-G6*Assumptions!$B$7 | H13: =-H6*Assumptions!$B$7 | I13: =-I6*Assumptions!$B$7 | J13: =-J6*Assumptions!$B$7 | ... L13: =-L6*Assumptions!$B$7
A14: EBIT (pre-tax profit after lease principal) | C14: =C12+C13 | D14: =D12+D13 | E14: =E12+E13 | F14: =F12+F13 | G14: =G12+G13 | H14: =H12+H13 | I14: =I12+I13 | J14: =J12+J13 | ... L14: =L12+L13
A15: Cash tax rate | C15: =Assumptions!$B$9 | D15: =Assumptions!$B$9 | E15: =Assumptions!$B$9 | F15: =Assumptions!$B$9 | G15: =Assumptions!$B$9 | H15: =Assumptions!$B$9 | I15: =Assumptions!$B$9 | J15: =Assumptions!$B$9 | ... L15: =Assumptions!$B$9
A16: NOPAT | C16: =C14*(1-C15) | D16: =D14*(1-D15) | E16: =E14*(1-E15) | F16: =F14*(1-F15) | G16: =G14*(1-G15) | H16: =H14*(1-H15) | I16: =I14*(1-I15) | J16: =J14*(1-J15) | ... L16: =L14*(1-L15)
A17: add back D&A | C17: =-C13 | D17: =-D13 | E17: =-E13 | F17: =-F13 | G17: =-G13 | H17: =-H13 | I17: =-I13 | J17: =-J13 | ... L17: =-L13
A18: Capex % revenue | C18: 0.065 | D18: 0.055 | E18: 0.05 | F18: 0.045 | G18: 0.04 | H18: 0.035 | I18: 0.035 | J18: 0.03 | K18: 0.03 | L18: 0.03
A19: Capex | C19: =-C6*C18 | D19: =-D6*D18 | E19: =-E6*E18 | F19: =-F6*F18 | G19: =-G6*G18 | H19: =-H6*H18 | I19: =-I6*I18 | J19: =-J6*J18 | ... L19: =-L6*L18
A20: Capital retained for loan-book growth (WC) | C20: =Assumptions!$D$15*(C6-B6) | D20: =Assumptions!$D$15*(D6-C6) | E20: =Assumptions!$D$15*(E6-D6) | F20: =Assumptions!$D$15*(F6-E6) | G20: =Assumptions!$D$15*(G6-F6) | H20: =Assumptions!$D$15*(H6-G6) | I20: =Assumptions!$D$15*(I6-H6) | J20: =Assumptions!$D$15*(J6-I6) | ... L20: =Assumptions!$D$15*(L6-K6)
A21: Distributable FCF | C21: =C16+C17+C19+C20 | D21: =D16+D17+D19+D20 | E21: =E16+E17+E19+E20 | F21: =F16+F17+F19+F20 | G21: =G16+G17+G19+G20 | H21: =H16+H17+H19+H20 | I21: =I16+I17+I19+I20 | J21: =J16+J17+J19+J20 | ... L21: =L16+L17+L19+L20
A22: Discount factor | C22: =1/(1+Assumptions!$B$6)^C4 | D22: =1/(1+Assumptions!$B$6)^D4 | E22: =1/(1+Assumptions!$B$6)^E4 | F22: =1/(1+Assumptions!$B$6)^F4 | G22: =1/(1+Assumptions!$B$6)^G4 | H22: =1/(1+Assumptions!$B$6)^H4 | I22: =1/(1+Assumptions!$B$6)^I4 | J22: =1/(1+Assumptions!$B$6)^J4 | ... L22: =1/(1+Assumptions!$B$6)^L4
A23: PV of FCF | C23: =C21*C22 | D23: =D21*D22 | E23: =E21*E22 | F23: =F21*F22 | G23: =G21*G22 | H23: =H21*H22 | I23: =I21*I22 | J23: =J21*J22 | ... L23: =L21*L22
A25: Memo: FCF before SBC | C25: =C21-C10 | D25: =D21-D10 | E25: =E21-E10 | F25: =F21-F10 | G25: =G21-G10 | H25: =H21-H10 | I25: =I21-I10 | J25: =J21-J10 | ... L25: =L21-L10
A26: Memo: distributable FCF margin | C26: =C21/C6 | D26: =D21/D6 | E26: =E21/E6 | F26: =F21/F6 | G26: =G21/G6 | H26: =H21/H6 | I26: =I21/I6 | J26: =J21/J6 | ... L26: =L21/L6
A27: Memo: NPBT-equivalent | C27: =C8+C10+C13 | D27: =D8+D10+D13 | E27: =E8+E10+E13 | F27: =F8+F10+F13 | G27: =G8+G10+G13 | H27: =H8+H10+H13 | I27: =I8+I10+I13 | J27: =J8+J10+J13 | ... L27: =L8+L10+L13
A28: Memo: NPAT-equivalent | C28: =C27*(1-C15) | D28: =D27*(1-D15) | E28: =E27*(1-E15) | F28: =F27*(1-F15) | G28: =G27*(1-G15) | H28: =H27*(1-H15) | I28: =I27*(1-I15) | J28: =J27*(1-J15) | ... L28: =L27*(1-L15)
A30: Sum of PV of FCF | B30: =SUM(C23:L23)
A31: Terminal growth | B31: =Assumptions!$B$15
A32: Terminal FCF (yr 11) | B32: =L21*(1+B31)
A33: Gordon TV | B33: =IF(Assumptions!$B$6>B31,B32/(Assumptions!$B$6-B31),0)
A34: Cap TV | B34: =Assumptions!$B$10*L21
A35: TV used | B35: =MAX(0,MIN(B33,B34))
A36: Implied exit multiple (x FCF_10) | B36: =IF(L21<>0,B35/L21,0)
A37: PV of TV | B37: =B35*L22
A38: Equity value (EV; no bridge) | B38: =B30+B37
A39: less net debt | B39: =-Assumptions!$B$5
A40: Equity value | B40: =B38+B39
A41: Diluted shares (m) | B41: =Assumptions!$B$4
A42: Value per share (NZ$) | B42: =B40/B41
A43: Upside vs price | B43: =B42/Assumptions!$B$3-1
...

Sheet DCF_Base
A1: Base case - distributable earnings (NZ$m)
A3: Year | B3: 2026A | C3: FY2027E | D3: FY2028E | E3: FY2029E | F3: FY2030E | G3: FY2031E | H3: FY2032E | I3: FY2033E | J3: FY2034E | K3: FY2035E | L3: FY2036E
A4: Index | B4: 0 | C4: 1 | D4: 2 | E4: 3 | F4: 4 | G4: 5 | H4: 6 | I4: 7 | J4: 8 | K4: 9 | L4: 10
A5: Revenue growth | C5: 0.07 | D5: 0.08 | E5: 0.08 | F5: 0.07 | G5: 0.06 | H5: 0.05 | I5: 0.045 | J5: 0.04 | K5: 0.035 | L5: 0.03
A6: Revenue | B6: 450.171 | C6: =B6*(1+C5) | D6: =C6*(1+D5) | E6: =D6*(1+E5) | F6: =E6*(1+F5) | G6: =F6*(1+G5) | H6: =G6*(1+H5) | I6: =H6*(1+I5) | J6: =I6*(1+J5) | ... L6: =K6*(1+L5)
A7: Adj margin (NPBT+D&A+SBC)/rev | C7: 0.165 | D7: 0.169 | E7: 0.173 | F7: 0.176 | G7: 0.179 | H7: 0.18 | I7: 0.18 | J7: 0.18 | K7: 0.18 | L7: 0.18
A8: Adj earnings pre-D&A | C8: =C6*C7 | D8: =D6*D7 | E8: =E6*E7 | F8: =F6*F7 | G8: =G6*G7 | H8: =H6*H7 | I8: =I6*I7 | J8: =J6*J7 | ... L8: =L6*L7
A9: SBC % revenue | C9: =Assumptions!$B$12 | D9: =Assumptions!$B$12 | E9: =Assumptions!$B$12 | F9: =Assumptions!$B$12 | G9: =Assumptions!$B$12 | H9: =Assumptions!$B$12 | I9: =Assumptions!$B$12 | J9: =Assumptions!$B$12 | ... L9: =Assumptions!$B$12
A10: SBC | C10: =-C6*C9 | D10: =-D6*D9 | E10: =-E6*E9 | F10: =-F6*F9 | G10: =-G6*G9 | H10: =-H6*H9 | I10: =-I6*I9 | J10: =-J6*J9 | ... L10: =-L6*L9
A11: Lease principal | C11: =-C6*Assumptions!$B$8 | D11: =-D6*Assumptions!$B$8 | E11: =-E6*Assumptions!$B$8 | F11: =-F6*Assumptions!$B$8 | G11: =-G6*Assumptions!$B$8 | H11: =-H6*Assumptions!$B$8 | I11: =-I6*Assumptions!$B$8 | J11: =-J6*Assumptions!$B$8 | ... L11: =-L6*Assumptions!$B$8
A12: Owner earnings pre-D&A | C12: =C8+C10+C11 | D12: =D8+D10+D11 | E12: =E8+E10+E11 | F12: =F8+F10+F11 | G12: =G8+G10+G11 | H12: =H8+H10+H11 | I12: =I8+I10+I11 | J12: =J8+J10+J11 | ... L12: =L8+L10+L11
A13: D&A | C13: =-C6*Assumptions!$B$7 | D13: =-D6*Assumptions!$B$7 | E13: =-E6*Assumptions!$B$7 | F13: =-F6*Assumptions!$B$7 | G13: =-G6*Assumptions!$B$7 | H13: =-H6*Assumptions!$B$7 | I13: =-I6*Assumptions!$B$7 | J13: =-J6*Assumptions!$B$7 | ... L13: =-L6*Assumptions!$B$7
A14: EBIT (pre-tax profit after lease principal) | C14: =C12+C13 | D14: =D12+D13 | E14: =E12+E13 | F14: =F12+F13 | G14: =G12+G13 | H14: =H12+H13 | I14: =I12+I13 | J14: =J12+J13 | ... L14: =L12+L13
A15: Cash tax rate | C15: =Assumptions!$B$9 | D15: =Assumptions!$B$9 | E15: =Assumptions!$B$9 | F15: =Assumptions!$B$9 | G15: =Assumptions!$B$9 | H15: =Assumptions!$B$9 | I15: =Assumptions!$B$9 | J15: =Assumptions!$B$9 | ... L15: =Assumptions!$B$9
A16: NOPAT | C16: =C14*(1-C15) | D16: =D14*(1-D15) | E16: =E14*(1-E15) | F16: =F14*(1-F15) | G16: =G14*(1-G15) | H16: =H14*(1-H15) | I16: =I14*(1-I15) | J16: =J14*(1-J15) | ... L16: =L14*(1-L15)
A17: add back D&A | C17: =-C13 | D17: =-D13 | E17: =-E13 | F17: =-F13 | G17: =-G13 | H17: =-H13 | I17: =-I13 | J17: =-J13 | ... L17: =-L13
A18: Capex % revenue | C18: 0.075 | D18: 0.075 | E18: 0.07 | F18: 0.065 | G18: 0.06 | H18: 0.05 | I18: 0.045 | J18: 0.04 | K18: 0.035 | L18: 0.03
A19: Capex | C19: =-C6*C18 | D19: =-D6*D18 | E19: =-E6*E18 | F19: =-F6*F18 | G19: =-G6*G18 | H19: =-H6*H18 | I19: =-I6*I18 | J19: =-J6*J18 | ... L19: =-L6*L18
A20: Capital retained for loan-book growth (WC) | C20: =Assumptions!$D$16*(C6-B6) | D20: =Assumptions!$D$16*(D6-C6) | E20: =Assumptions!$D$16*(E6-D6) | F20: =Assumptions!$D$16*(F6-E6) | G20: =Assumptions!$D$16*(G6-F6) | H20: =Assumptions!$D$16*(H6-G6) | I20: =Assumptions!$D$16*(I6-H6) | J20: =Assumptions!$D$16*(J6-I6) | ... L20: =Assumptions!$D$16*(L6-K6)
A21: Distributable FCF | C21: =C16+C17+C19+C20 | D21: =D16+D17+D19+D20 | E21: =E16+E17+E19+E20 | F21: =F16+F17+F19+F20 | G21: =G16+G17+G19+G20 | H21: =H16+H17+H19+H20 | I21: =I16+I17+I19+I20 | J21: =J16+J17+J19+J20 | ... L21: =L16+L17+L19+L20
A22: Discount factor | C22: =1/(1+Assumptions!$B$6)^C4 | D22: =1/(1+Assumptions!$B$6)^D4 | E22: =1/(1+Assumptions!$B$6)^E4 | F22: =1/(1+Assumptions!$B$6)^F4 | G22: =1/(1+Assumptions!$B$6)^G4 | H22: =1/(1+Assumptions!$B$6)^H4 | I22: =1/(1+Assumptions!$B$6)^I4 | J22: =1/(1+Assumptions!$B$6)^J4 | ... L22: =1/(1+Assumptions!$B$6)^L4
A23: PV of FCF | C23: =C21*C22 | D23: =D21*D22 | E23: =E21*E22 | F23: =F21*F22 | G23: =G21*G22 | H23: =H21*H22 | I23: =I21*I22 | J23: =J21*J22 | ... L23: =L21*L22
A25: Memo: FCF before SBC | C25: =C21-C10 | D25: =D21-D10 | E25: =E21-E10 | F25: =F21-F10 | G25: =G21-G10 | H25: =H21-H10 | I25: =I21-I10 | J25: =J21-J10 | ... L25: =L21-L10
A26: Memo: distributable FCF margin | C26: =C21/C6 | D26: =D21/D6 | E26: =E21/E6 | F26: =F21/F6 | G26: =G21/G6 | H26: =H21/H6 | I26: =I21/I6 | J26: =J21/J6 | ... L26: =L21/L6
A27: Memo: NPBT-equivalent | C27: =C8+C10+C13 | D27: =D8+D10+D13 | E27: =E8+E10+E13 | F27: =F8+F10+F13 | G27: =G8+G10+G13 | H27: =H8+H10+H13 | I27: =I8+I10+I13 | J27: =J8+J10+J13 | ... L27: =L8+L10+L13
A28: Memo: NPAT-equivalent | C28: =C27*(1-C15) | D28: =D27*(1-D15) | E28: =E27*(1-E15) | F28: =F27*(1-F15) | G28: =G27*(1-G15) | H28: =H27*(1-H15) | I28: =I27*(1-I15) | J28: =J27*(1-J15) | ... L28: =L27*(1-L15)
A30: Sum of PV of FCF | B30: =SUM(C23:L23)
A31: Terminal growth | B31: =Assumptions!$B$16
A32: Terminal FCF (yr 11) | B32: =L21*(1+B31)
A33: Gordon TV | B33: =IF(Assumptions!$B$6>B31,B32/(Assumptions!$B$6-B31),0)
A34: Cap TV | B34: =Assumptions!$B$10*L21
A35: TV used | B35: =MAX(0,MIN(B33,B34))
A36: Implied exit multiple (x FCF_10) | B36: =IF(L21<>0,B35/L21,0)
A37: PV of TV | B37: =B35*L22
A38: Equity value (EV; no bridge) | B38: =B30+B37
A39: less net debt | B39: =-Assumptions!$B$5
A40: Equity value | B40: =B38+B39
A41: Diluted shares (m) | B41: =Assumptions!$B$4
A42: Value per share (NZ$) | B42: =B40/B41
A43: Upside vs price | B43: =B42/Assumptions!$B$3-1
...

Sheet DCF_Bull
A1: Bull case - distributable earnings (NZ$m)
A3: Year | B3: 2026A | C3: FY2027E | D3: FY2028E | E3: FY2029E | F3: FY2030E | G3: FY2031E | H3: FY2032E | I3: FY2033E | J3: FY2034E | K3: FY2035E | L3: FY2036E
A4: Index | B4: 0 | C4: 1 | D4: 2 | E4: 3 | F4: 4 | G4: 5 | H4: 6 | I4: 7 | J4: 8 | K4: 9 | L4: 10
A5: Revenue growth | C5: 0.09 | D5: 0.1 | E5: 0.1 | F5: 0.09 | G5: 0.08 | H5: 0.065 | I5: 0.055 | J5: 0.045 | K5: 0.04 | L5: 0.035
A6: Revenue | B6: 450.171 | C6: =B6*(1+C5) | D6: =C6*(1+D5) | E6: =D6*(1+E5) | F6: =E6*(1+F5) | G6: =F6*(1+G5) | H6: =G6*(1+H5) | I6: =H6*(1+I5) | J6: =I6*(1+J5) | ... L6: =K6*(1+L5)
A7: Adj margin (NPBT+D&A+SBC)/rev | C7: 0.168 | D7: 0.174 | E7: 0.18 | F7: 0.185 | G7: 0.19 | H7: 0.193 | I7: 0.195 | J7: 0.195 | K7: 0.195 | L7: 0.195
A8: Adj earnings pre-D&A | C8: =C6*C7 | D8: =D6*D7 | E8: =E6*E7 | F8: =F6*F7 | G8: =G6*G7 | H8: =H6*H7 | I8: =I6*I7 | J8: =J6*J7 | ... L8: =L6*L7
A9: SBC % revenue | C9: =Assumptions!$B$12 | D9: =Assumptions!$B$12 | E9: =Assumptions!$B$12 | F9: =Assumptions!$B$12 | G9: =Assumptions!$B$12 | H9: =Assumptions!$B$12 | I9: =Assumptions!$B$12 | J9: =Assumptions!$B$12 | ... L9: =Assumptions!$B$12
A10: SBC | C10: =-C6*C9 | D10: =-D6*D9 | E10: =-E6*E9 | F10: =-F6*F9 | G10: =-G6*G9 | H10: =-H6*H9 | I10: =-I6*I9 | J10: =-J6*J9 | ... L10: =-L6*L9
A11: Lease principal | C11: =-C6*Assumptions!$B$8 | D11: =-D6*Assumptions!$B$8 | E11: =-E6*Assumptions!$B$8 | F11: =-F6*Assumptions!$B$8 | G11: =-G6*Assumptions!$B$8 | H11: =-H6*Assumptions!$B$8 | I11: =-I6*Assumptions!$B$8 | J11: =-J6*Assumptions!$B$8 | ... L11: =-L6*Assumptions!$B$8
A12: Owner earnings pre-D&A | C12: =C8+C10+C11 | D12: =D8+D10+D11 | E12: =E8+E10+E11 | F12: =F8+F10+F11 | G12: =G8+G10+G11 | H12: =H8+H10+H11 | I12: =I8+I10+I11 | J12: =J8+J10+J11 | ... L12: =L8+L10+L11
A13: D&A | C13: =-C6*Assumptions!$B$7 | D13: =-D6*Assumptions!$B$7 | E13: =-E6*Assumptions!$B$7 | F13: =-F6*Assumptions!$B$7 | G13: =-G6*Assumptions!$B$7 | H13: =-H6*Assumptions!$B$7 | I13: =-I6*Assumptions!$B$7 | J13: =-J6*Assumptions!$B$7 | ... L13: =-L6*Assumptions!$B$7
A14: EBIT (pre-tax profit after lease principal) | C14: =C12+C13 | D14: =D12+D13 | E14: =E12+E13 | F14: =F12+F13 | G14: =G12+G13 | H14: =H12+H13 | I14: =I12+I13 | J14: =J12+J13 | ... L14: =L12+L13
A15: Cash tax rate | C15: =Assumptions!$B$9 | D15: =Assumptions!$B$9 | E15: =Assumptions!$B$9 | F15: =Assumptions!$B$9 | G15: =Assumptions!$B$9 | H15: =Assumptions!$B$9 | I15: =Assumptions!$B$9 | J15: =Assumptions!$B$9 | ... L15: =Assumptions!$B$9
A16: NOPAT | C16: =C14*(1-C15) | D16: =D14*(1-D15) | E16: =E14*(1-E15) | F16: =F14*(1-F15) | G16: =G14*(1-G15) | H16: =H14*(1-H15) | I16: =I14*(1-I15) | J16: =J14*(1-J15) | ... L16: =L14*(1-L15)
A17: add back D&A | C17: =-C13 | D17: =-D13 | E17: =-E13 | F17: =-F13 | G17: =-G13 | H17: =-H13 | I17: =-I13 | J17: =-J13 | ... L17: =-L13
A18: Capex % revenue | C18: 0.08 | D18: 0.08 | E18: 0.075 | F18: 0.07 | G18: 0.06 | H18: 0.05 | I18: 0.045 | J18: 0.04 | K18: 0.035 | L18: 0.03
A19: Capex | C19: =-C6*C18 | D19: =-D6*D18 | E19: =-E6*E18 | F19: =-F6*F18 | G19: =-G6*G18 | H19: =-H6*H18 | I19: =-I6*I18 | J19: =-J6*J18 | ... L19: =-L6*L18
A20: Capital retained for loan-book growth (WC) | C20: =Assumptions!$D$17*(C6-B6) | D20: =Assumptions!$D$17*(D6-C6) | E20: =Assumptions!$D$17*(E6-D6) | F20: =Assumptions!$D$17*(F6-E6) | G20: =Assumptions!$D$17*(G6-F6) | H20: =Assumptions!$D$17*(H6-G6) | I20: =Assumptions!$D$17*(I6-H6) | J20: =Assumptions!$D$17*(J6-I6) | ... L20: =Assumptions!$D$17*(L6-K6)
A21: Distributable FCF | C21: =C16+C17+C19+C20 | D21: =D16+D17+D19+D20 | E21: =E16+E17+E19+E20 | F21: =F16+F17+F19+F20 | G21: =G16+G17+G19+G20 | H21: =H16+H17+H19+H20 | I21: =I16+I17+I19+I20 | J21: =J16+J17+J19+J20 | ... L21: =L16+L17+L19+L20
A22: Discount factor | C22: =1/(1+Assumptions!$B$6)^C4 | D22: =1/(1+Assumptions!$B$6)^D4 | E22: =1/(1+Assumptions!$B$6)^E4 | F22: =1/(1+Assumptions!$B$6)^F4 | G22: =1/(1+Assumptions!$B$6)^G4 | H22: =1/(1+Assumptions!$B$6)^H4 | I22: =1/(1+Assumptions!$B$6)^I4 | J22: =1/(1+Assumptions!$B$6)^J4 | ... L22: =1/(1+Assumptions!$B$6)^L4
A23: PV of FCF | C23: =C21*C22 | D23: =D21*D22 | E23: =E21*E22 | F23: =F21*F22 | G23: =G21*G22 | H23: =H21*H22 | I23: =I21*I22 | J23: =J21*J22 | ... L23: =L21*L22
A25: Memo: FCF before SBC | C25: =C21-C10 | D25: =D21-D10 | E25: =E21-E10 | F25: =F21-F10 | G25: =G21-G10 | H25: =H21-H10 | I25: =I21-I10 | J25: =J21-J10 | ... L25: =L21-L10
A26: Memo: distributable FCF margin | C26: =C21/C6 | D26: =D21/D6 | E26: =E21/E6 | F26: =F21/F6 | G26: =G21/G6 | H26: =H21/H6 | I26: =I21/I6 | J26: =J21/J6 | ... L26: =L21/L6
A27: Memo: NPBT-equivalent | C27: =C8+C10+C13 | D27: =D8+D10+D13 | E27: =E8+E10+E13 | F27: =F8+F10+F13 | G27: =G8+G10+G13 | H27: =H8+H10+H13 | I27: =I8+I10+I13 | J27: =J8+J10+J13 | ... L27: =L8+L10+L13
A28: Memo: NPAT-equivalent | C28: =C27*(1-C15) | D28: =D27*(1-D15) | E28: =E27*(1-E15) | F28: =F27*(1-F15) | G28: =G27*(1-G15) | H28: =H27*(1-H15) | I28: =I27*(1-I15) | J28: =J27*(1-J15) | ... L28: =L27*(1-L15)
A30: Sum of PV of FCF | B30: =SUM(C23:L23)
A31: Terminal growth | B31: =Assumptions!$B$17
A32: Terminal FCF (yr 11) | B32: =L21*(1+B31)
A33: Gordon TV | B33: =IF(Assumptions!$B$6>B31,B32/(Assumptions!$B$6-B31),0)
A34: Cap TV | B34: =Assumptions!$B$10*L21
A35: TV used | B35: =MAX(0,MIN(B33,B34))
A36: Implied exit multiple (x FCF_10) | B36: =IF(L21<>0,B35/L21,0)
A37: PV of TV | B37: =B35*L22
A38: Equity value (EV; no bridge) | B38: =B30+B37
A39: less net debt | B39: =-Assumptions!$B$5
A40: Equity value | B40: =B38+B39
A41: Diluted shares (m) | B41: =Assumptions!$B$4
A42: Value per share (NZ$) | B42: =B40/B41
A43: Upside vs price | B43: =B42/Assumptions!$B$3-1
...

Sheet FCF_Quality
A1: Reported FCF reconciled to distributable owner FCF (NZ$m)
B2: FY2021 | C2: FY2022 | D2: FY2023 | E2: FY2024 | F2: FY2025 | G2: FY2026
A3: Operating cash flow (reported) | B3: 10.878 | C3: -43.941 | D3: 68.317 | E3: 29.671 | F3: 33.457 | G3: -74.981
A4: less capex | B4: -8.641 | C4: -16.121 | D4: -44.177 | E4: -18.641 | F4: -32.136 | G4: -41.7
A5: Equals: Reported FCF | B5: =B3+B4 | C5: =C3+C4 | D5: =D3+D4 | E5: =E3+E4 | F5: =F3+F4 | G5: =G3+G4
A6: of which: net increase in finance receivables (loan-book growth, debt-funded) | F6: -20.062 | G6: -116.121
A7: Normalised NPAT | B7: 26.864 | C7: 31.281 | D7: 32.566 | E7: 32.966 | F7: 38.587 | G7: 45.6
A8: add D&A | B8: 11.418 | C8: 10.702 | D8: 11.478 | E8: 11.968 | F8: 11.651 | G8: 11.097
A9: less capex | B9: -8.641 | C9: -16.121 | D9: -44.177 | E9: -18.641 | F9: -32.136 | G9: -41.7
A10: add PP&E disposal proceeds | B10: 0 | C10: 0 | D10: 0 | E10: 0 | F10: 6.456 | G10: 3.304
A11: less lease principal | B11: -6.346 | C11: -5.563 | D11: -7.501 | E11: -6.303 | F11: -6.676 | G11: -6.944
A12: Equals: Distributable owner FCF (before loan-book equity retention) | B12: =SUM(B7:B11) | C12: =SUM(C7:C11) | D12: =SUM(D7:D11) | E12: =SUM(E7:E11) | F12: =SUM(F7:F11) | G12: =SUM(G7:G11)
A13: Reported FCF margin | B13: =B5/B16 | C13: =C5/C16 | D13: =D5/D16 | E13: =E5/E16 | F13: =F5/F16 | G13: =G5/G16
A14: Distributable FCF margin | B14: =B12/B16 | C14: =C12/C16 | D14: =D12/D16 | E14: =E12/E16 | F14: =F12/F16 | G14: =G12/G16
A15: Cash tax rate (paid / normalised PBT) | B15: =8.166/37.375 | C15: =9.326/43.12 | D15: =10.394/45.545 | E15: =15.259/49.139 | F15: =14.451/54.274 | G15: =17.512/63.224
A16: Revenue | B16: 296.512 | C16: 342.029 | D16: 389.027 | E16: 416.145 | F16: 412.904 | G16: 450.171
A18: Note: FY2026 NPAT normalised for the 7.474 EC Credit goodwill write-down. FY2023 and FY2026 distributable FCF are depressed by branch-property capex peaks; the model's year-1 FCF is component-built (see DCF tabs), not a carry-forward.

Sheet Valuation
A1: Valuation summary (NZ$ per share)
A3: Scenario | B3: Value/share | C3: Upside vs price | D3: Probability | E3: Street value/share | F3: Entry price @ hurdle
A4: Bear | B4: =DCF_Bear!B42 | C4: =B4/Assumptions!$B$3-1 | D4: =Assumptions!C15 | E4: =DCF_Bear!B47 | F4: =(SUMPRODUCT(DCF_Bear!$C$21:$L$21/(1+Assumptions!$B$11)^DCF_Bear!$C$4:$L$4)+MAX(0,MIN(IF(Assumptions!$B$11>Assumptions!$B$15,DCF_Bear!$L$21*(1+Assumptions!$B$15)/(Assumptions!$B$11-Assumptions!$B$15),0),Assumptions!$B$10*DCF_Bear!$L$21))/(1+Assumptions!$B$11)^10-Assumptions!$B$5)/Assumptions!$B$4
A5: Base | B5: =DCF_Base!B42 | C5: =B5/Assumptions!$B$3-1 | D5: =Assumptions!C16 | E5: =DCF_Base!B47 | F5: =(SUMPRODUCT(DCF_Base!$C$21:$L$21/(1+Assumptions!$B$11)^DCF_Base!$C$4:$L$4)+MAX(0,MIN(IF(Assumptions!$B$11>Assumptions!$B$16,DCF_Base!$L$21*(1+Assumptions!$B$16)/(Assumptions!$B$11-Assumptions!$B$16),0),Assumptions!$B$10*DCF_Base!$L$21))/(1+Assumptions!$B$11)^10-Assumptions!$B$5)/Assumptions!$B$4
A6: Bull | B6: =DCF_Bull!B42 | C6: =B6/Assumptions!$B$3-1 | D6: =Assumptions!C17 | E6: =DCF_Bull!B47 | F6: =(SUMPRODUCT(DCF_Bull!$C$21:$L$21/(1+Assumptions!$B$11)^DCF_Bull!$C$4:$L$4)+MAX(0,MIN(IF(Assumptions!$B$11>Assumptions!$B$17,DCF_Bull!$L$21*(1+Assumptions!$B$17)/(Assumptions!$B$11-Assumptions!$B$17),0),Assumptions!$B$10*DCF_Bull!$L$21))/(1+Assumptions!$B$11)^10-Assumptions!$B$5)/Assumptions!$B$4
A8: Probability-weighted value | B8: =SUMPRODUCT(B4:B6,D4:D6)
A9: Current price | B9: =Assumptions!B3
A10: Margin of safety | B10: =1-B9/B8
A11: Street weighted value | B11: =SUMPRODUCT(E4:E6,D4:D6)
A12: Band position (0%=house,100%=street) | B12: =IF(ABS(B11-B8)<0.0001,"n/a",(B9-B8)/(B11-B8))
A13: Weighted entry price (15% hurdle) | B13: =SUMPRODUCT(F4:F6,D4:D6)
A15: Required-return table (base case, TV rebuilt at each rate)
A16: Required return | B16: Value/share
A17: 0.09 | B17: =(SUMPRODUCT(DCF_Base!$C$21:$L$21/(1+$A17)^DCF_Base!$C$4:$L$4)+MAX(0,MIN(IF($A17>Assumptions!$B$16,DCF_Base!$L$21*(1+Assumptions!$B$16)/($A17-Assumptions!$B$16),0),Assumptions!$B$10*DCF_Base!$L$21))/(1+$A17)^10-Assumptions!$B$5)/Assumptions!$B$4
A18: 0.1 | B18: =(SUMPRODUCT(DCF_Base!$C$21:$L$21/(1+$A18)^DCF_Base!$C$4:$L$4)+MAX(0,MIN(IF($A18>Assumptions!$B$16,DCF_Base!$L$21*(1+Assumptions!$B$16)/($A18-Assumptions!$B$16),0),Assumptions!$B$10*DCF_Base!$L$21))/(1+$A18)^10-Assumptions!$B$5)/Assumptions!$B$4
A19: 0.11 | B19: =(SUMPRODUCT(DCF_Base!$C$21:$L$21/(1+$A19)^DCF_Base!$C$4:$L$4)+MAX(0,MIN(IF($A19>Assumptions!$B$16,DCF_Base!$L$21*(1+Assumptions!$B$16)/($A19-Assumptions!$B$16),0),Assumptions!$B$10*DCF_Base!$L$21))/(1+$A19)^10-Assumptions!$B$5)/Assumptions!$B$4
A20: 0.12 | B20: =(SUMPRODUCT(DCF_Base!$C$21:$L$21/(1+$A20)^DCF_Base!$C$4:$L$4)+MAX(0,MIN(IF($A20>Assumptions!$B$16,DCF_Base!$L$21*(1+Assumptions!$B$16)/($A20-Assumptions!$B$16),0),Assumptions!$B$10*DCF_Base!$L$21))/(1+$A20)^10-Assumptions!$B$5)/Assumptions!$B$4
A21: 0.15 | B21: =(SUMPRODUCT(DCF_Base!$C$21:$L$21/(1+$A21)^DCF_Base!$C$4:$L$4)+MAX(0,MIN(IF($A21>Assumptions!$B$16,DCF_Base!$L$21*(1+Assumptions!$B$16)/($A21-Assumptions!$B$16),0),Assumptions!$B$10*DCF_Base!$L$21))/(1+$A21)^10-Assumptions!$B$5)/Assumptions!$B$4
A22: =Assumptions!B6 | B22: =(SUMPRODUCT(DCF_Base!$C$21:$L$21/(1+$A22)^DCF_Base!$C$4:$L$4)+MAX(0,MIN(IF($A22>Assumptions!$B$16,DCF_Base!$L$21*(1+Assumptions!$B$16)/($A22-Assumptions!$B$16),0),Assumptions!$B$10*DCF_Base!$L$21))/(1+$A22)^10-Assumptions!$B$5)/Assumptions!$B$4 | C22: model cost of equity (must equal DCF_Base!B42)
A24: Sensitivity: cost of equity (rows) x terminal growth (cols), base case
B25: 0.02 | C25: 0.025 | D25: 0.03 | E25: 0.035 | F25: 0.04
A26: 0.09 | B26: =IF($A26>B$25,(SUMPRODUCT(DCF_Base!$C$21:$L$21/(1+$A26)^DCF_Base!$C$4:$L$4)+MAX(0,MIN(IF($A26>B$25,DCF_Base!$L$21*(1+B$25)/($A26-B$25),0),Assumptions!$B$10*DCF_Base!$L$21))/(1+$A26)^10-Assumptions!$B$5)/Assumptions!$B$4,"n/a") | C26: =IF($A26>C$25,(SUMPRODUCT(DCF_Base!$C$21:$L$21/(1+$A26)^DCF_Base!$C$4:$L$4)+MAX(0,MIN(IF($A26>C$25,DCF_Base!$L$21*(1+C$25)/($A26-C$25),0),Assumptions!$B$10*DCF_Base!$L$21))/(1+$A26)^10-Assumptions!$B$5)/Assumptions!$B$4,"n/a") | D26: =IF($A26>D$25,(SUMPRODUCT(DCF_Base!$C$21:$L$21/(1+$A26)^DCF_Base!$C$4:$L$4)+MAX(0,MIN(IF($A26>D$25,DCF_Base!$L$21*(1+D$25)/($A26-D$25),0),Assumptions!$B$10*DCF_Base!$L$21))/(1+$A26)^10-Assumptions!$B$5)/Assumptions!$B$4,"n/a") | E26: =IF($A26>E$25,(SUMPRODUCT(DCF_Base!$C$21:$L$21/(1+$A26)^DCF_Base!$C$4:$L$4)+MAX(0,MIN(IF($A26>E$25,DCF_Base!$L$21*(1+E$25)/($A26-E$25),0),Assumptions!$B$10*DCF_Base!$L$21))/(1+$A26)^10-Assumptions!$B$5)/Assumptions!$B$4,"n/a") | F26: =IF($A26>F$25,(SUMPRODUCT(DCF_Base!$C$21:$L$21/(1+$A26)^DCF_Base!$C$4:$L$4)+MAX(0,MIN(IF($A26>F$25,DCF_Base!$L$21*(1+F$25)/($A26-F$25),0),Assumptions!$B$10*DCF_Base!$L$21))/(1+$A26)^10-Assumptions!$B$5)/Assumptions!$B$4,"n/a")
A27: 0.1 | B27: =IF($A27>B$25,(SUMPRODUCT(DCF_Base!$C$21:$L$21/(1+$A27)^DCF_Base!$C$4:$L$4)+MAX(0,MIN(IF($A27>B$25,DCF_Base!$L$21*(1+B$25)/($A27-B$25),0),Assumptions!$B$10*DCF_Base!$L$21))/(1+$A27)^10-Assumptions!$B$5)/Assumptions!$B$4,"n/a") | C27: =IF($A27>C$25,(SUMPRODUCT(DCF_Base!$C$21:$L$21/(1+$A27)^DCF_Base!$C$4:$L$4)+MAX(0,MIN(IF($A27>C$25,DCF_Base!$L$21*(1+C$25)/($A27-C$25),0),Assumptions!$B$10*DCF_Base!$L$21))/(1+$A27)^10-Assumptions!$B$5)/Assumptions!$B$4,"n/a") | D27: =IF($A27>D$25,(SUMPRODUCT(DCF_Base!$C$21:$L$21/(1+$A27)^DCF_Base!$C$4:$L$4)+MAX(0,MIN(IF($A27>D$25,DCF_Base!$L$21*(1+D$25)/($A27-D$25),0),Assumptions!$B$10*DCF_Base!$L$21))/(1+$A27)^10-Assumptions!$B$5)/Assumptions!$B$4,"n/a") | E27: =IF($A27>E$25,(SUMPRODUCT(DCF_Base!$C$21:$L$21/(1+$A27)^DCF_Base!$C$4:$L$4)+MAX(0,MIN(IF($A27>E$25,DCF_Base!$L$21*(1+E$25)/($A27-E$25),0),Assumptions!$B$10*DCF_Base!$L$21))/(1+$A27)^10-Assumptions!$B$5)/Assumptions!$B$4,"n/a") | F27: =IF($A27>F$25,(SUMPRODUCT(DCF_Base!$C$21:$L$21/(1+$A27)^DCF_Base!$C$4:$L$4)+MAX(0,MIN(IF($A27>F$25,DCF_Base!$L$21*(1+F$25)/($A27-F$25),0),Assumptions!$B$10*DCF_Base!$L$21))/(1+$A27)^10-Assumptions!$B$5)/Assumptions!$B$4,"n/a")
A28: 0.11 | B28: =IF($A28>B$25,(SUMPRODUCT(DCF_Base!$C$21:$L$21/(1+$A28)^DCF_Base!$C$4:$L$4)+MAX(0,MIN(IF($A28>B$25,DCF_Base!$L$21*(1+B$25)/($A28-B$25),0),Assumptions!$B$10*DCF_Base!$L$21))/(1+$A28)^10-Assumptions!$B$5)/Assumptions!$B$4,"n/a") | C28: =IF($A28>C$25,(SUMPRODUCT(DCF_Base!$C$21:$L$21/(1+$A28)^DCF_Base!$C$4:$L$4)+MAX(0,MIN(IF($A28>C$25,DCF_Base!$L$21*(1+C$25)/($A28-C$25),0),Assumptions!$B$10*DCF_Base!$L$21))/(1+$A28)^10-Assumptions!$B$5)/Assumptions!$B$4,"n/a") | D28: =IF($A28>D$25,(SUMPRODUCT(DCF_Base!$C$21:$L$21/(1+$A28)^DCF_Base!$C$4:$L$4)+MAX(0,MIN(IF($A28>D$25,DCF_Base!$L$21*(1+D$25)/($A28-D$25),0),Assumptions!$B$10*DCF_Base!$L$21))/(1+$A28)^10-Assumptions!$B$5)/Assumptions!$B$4,"n/a") | E28: =IF($A28>E$25,(SUMPRODUCT(DCF_Base!$C$21:$L$21/(1+$A28)^DCF_Base!$C$4:$L$4)+MAX(0,MIN(IF($A28>E$25,DCF_Base!$L$21*(1+E$25)/($A28-E$25),0),Assumptions!$B$10*DCF_Base!$L$21))/(1+$A28)^10-Assumptions!$B$5)/Assumptions!$B$4,"n/a") | F28: =IF($A28>F$25,(SUMPRODUCT(DCF_Base!$C$21:$L$21/(1+$A28)^DCF_Base!$C$4:$L$4)+MAX(0,MIN(IF($A28>F$25,DCF_Base!$L$21*(1+F$25)/($A28-F$25),0),Assumptions!$B$10*DCF_Base!$L$21))/(1+$A28)^10-Assumptions!$B$5)/Assumptions!$B$4,"n/a")
A29: 0.12 | B29: =IF($A29>B$25,(SUMPRODUCT(DCF_Base!$C$21:$L$21/(1+$A29)^DCF_Base!$C$4:$L$4)+MAX(0,MIN(IF($A29>B$25,DCF_Base!$L$21*(1+B$25)/($A29-B$25),0),Assumptions!$B$10*DCF_Base!$L$21))/(1+$A29)^10-Assumptions!$B$5)/Assumptions!$B$4,"n/a") | C29: =IF($A29>C$25,(SUMPRODUCT(DCF_Base!$C$21:$L$21/(1+$A29)^DCF_Base!$C$4:$L$4)+MAX(0,MIN(IF($A29>C$25,DCF_Base!$L$21*(1+C$25)/($A29-C$25),0),Assumptions!$B$10*DCF_Base!$L$21))/(1+$A29)^10-Assumptions!$B$5)/Assumptions!$B$4,"n/a") | D29: =IF($A29>D$25,(SUMPRODUCT(DCF_Base!$C$21:$L$21/(1+$A29)^DCF_Base!$C$4:$L$4)+MAX(0,MIN(IF($A29>D$25,DCF_Base!$L$21*(1+D$25)/($A29-D$25),0),Assumptions!$B$10*DCF_Base!$L$21))/(1+$A29)^10-Assumptions!$B$5)/Assumptions!$B$4,"n/a") | E29: =IF($A29>E$25,(SUMPRODUCT(DCF_Base!$C$21:$L$21/(1+$A29)^DCF_Base!$C$4:$L$4)+MAX(0,MIN(IF($A29>E$25,DCF_Base!$L$21*(1+E$25)/($A29-E$25),0),Assumptions!$B$10*DCF_Base!$L$21))/(1+$A29)^10-Assumptions!$B$5)/Assumptions!$B$4,"n/a") | F29: =IF($A29>F$25,(SUMPRODUCT(DCF_Base!$C$21:$L$21/(1+$A29)^DCF_Base!$C$4:$L$4)+MAX(0,MIN(IF($A29>F$25,DCF_Base!$L$21*(1+F$25)/($A29-F$25),0),Assumptions!$B$10*DCF_Base!$L$21))/(1+$A29)^10-Assumptions!$B$5)/Assumptions!$B$4,"n/a")
A30: 0.13 | B30: =IF($A30>B$25,(SUMPRODUCT(DCF_Base!$C$21:$L$21/(1+$A30)^DCF_Base!$C$4:$L$4)+MAX(0,MIN(IF($A30>B$25,DCF_Base!$L$21*(1+B$25)/($A30-B$25),0),Assumptions!$B$10*DCF_Base!$L$21))/(1+$A30)^10-Assumptions!$B$5)/Assumptions!$B$4,"n/a") | C30: =IF($A30>C$25,(SUMPRODUCT(DCF_Base!$C$21:$L$21/(1+$A30)^DCF_Base!$C$4:$L$4)+MAX(0,MIN(IF($A30>C$25,DCF_Base!$L$21*(1+C$25)/($A30-C$25),0),Assumptions!$B$10*DCF_Base!$L$21))/(1+$A30)^10-Assumptions!$B$5)/Assumptions!$B$4,"n/a") | D30: =IF($A30>D$25,(SUMPRODUCT(DCF_Base!$C$21:$L$21/(1+$A30)^DCF_Base!$C$4:$L$4)+MAX(0,MIN(IF($A30>D$25,DCF_Base!$L$21*(1+D$25)/($A30-D$25),0),Assumptions!$B$10*DCF_Base!$L$21))/(1+$A30)^10-Assumptions!$B$5)/Assumptions!$B$4,"n/a") | E30: =IF($A30>E$25,(SUMPRODUCT(DCF_Base!$C$21:$L$21/(1+$A30)^DCF_Base!$C$4:$L$4)+MAX(0,MIN(IF($A30>E$25,DCF_Base!$L$21*(1+E$25)/($A30-E$25),0),Assumptions!$B$10*DCF_Base!$L$21))/(1+$A30)^10-Assumptions!$B$5)/Assumptions!$B$4,"n/a") | F30: =IF($A30>F$25,(SUMPRODUCT(DCF_Base!$C$21:$L$21/(1+$A30)^DCF_Base!$C$4:$L$4)+MAX(0,MIN(IF($A30>F$25,DCF_Base!$L$21*(1+F$25)/($A30-F$25),0),Assumptions!$B$10*DCF_Base!$L$21))/(1+$A30)^10-Assumptions!$B$5)/Assumptions!$B$4,"n/a")
