Workbook

Sheet DCF Model
A1: 6995.T (TOKAI RIKA) DCF Valuation Model - 10yr Component Build
A2: Gray cells are INPUTS - adjust to see valuation change. JPY millions except per-share/shares.
A4: KEY INPUTS
A5: Current Stock Price (JPY) | B5: 3040
A6: Shares Outstanding (M) - current | B6: 85.0997
A7: Cash & Equivalents (JPYm) | B7: 93757
A8: Total Debt (JPYm) | B8: 10000
A9: Net Debt (JPYm) [negative = net cash] | B9: =B8-B7 -> 0
A10: Reported FCF, FY2026 (JPYm) | B10: 8522
A11: Less: SBC (JPYm) - verified NIL | B11: 0
A12: Less: Interest & Dividend Income (JPYm) | B12: 1889 | C12: Stripped: net cash >1x FCF base (avoids double count vs net-cash addback)
A13: Owner FCF base, FY2026 actual (JPYm) | B13: =B10-B11-B12 -> 0
A15: Revenue, FY2026 actual (JPYm) | B15: 644701
A17: WACC (Base) | B17: 0.095
A18: Terminal Growth Rate | B18: 0.015
A19: Terminal EV/EBITDA Cap (10yr avg) | B19: 2.66 | C19: Historical range 1.67x-3.12x; caps Gordon growth in every scenario
A20: Annual Share Count Growth (buyback) | B20: -0.005
A22: PROJECTIONS (10yr component build)
B24: FY2027 | C24: FY2028 | D24: FY2029 | E24: FY2030 | F24: FY2031 | G24: FY2032 | H24: FY2033 | I24: FY2034 | J24: FY2035 | K24: FY2036
A25: Revenue Growth % | B25: 0.008 | C25: 0.018 | D25: 0.022 | E25: 0.023 | F25: 0.022 | G25: 0.02 | H25: 0.018 | I25: 0.017 | J25: 0.016 | K25: 0.015
A26: Revenue | B26: =B15*(1+B25) -> 0 | C26: =B26*(1+C25) -> 0 | D26: =C26*(1+D25) -> 0 | E26: =D26*(1+E25) -> 0 | F26: =E26*(1+F25) -> 0 | G26: =F26*(1+G25) -> 0 | H26: =G26*(1+H25) -> 0 | I26: =H26*(1+I25) -> 0 | J26: =I26*(1+J25) -> 0 | K26: =J26*(1+K25) -> 0
A27: Operating Margin % | B27: 0.04615 | C27: 0.048 | D27: 0.05 | E27: 0.052 | F27: 0.054 | G27: 0.055 | H27: 0.056 | I27: 0.057 | J27: 0.058 | K27: 0.06
A28: D&A % of Revenue | B28: 0.039 | C28: 0.0385 | D28: 0.038 | E28: 0.0375 | F28: 0.037 | G28: 0.0365 | H28: 0.036 | I28: 0.0355 | J28: 0.035 | K28: 0.035
A29: EBITDA Margin % (=OpMgn+D&A%) | B29: =B27+B28 -> 0 | C29: =C27+C28 -> 0 | D29: =D27+D28 -> 0 | E29: =E27+E28 -> 0 | F29: =F27+F28 -> 0 | G29: =G27+G28 -> 0 | H29: =H27+H28 -> 0 | I29: =I27+I28 -> 0 | ... K29: =K27+K28 -> 0
A30: EBITDA | B30: =B26*B29 -> 0 | C30: =C26*C29 -> 0 | D30: =D26*D29 -> 0 | E30: =E26*E29 -> 0 | F30: =F26*F29 -> 0 | G30: =G26*G29 -> 0 | H30: =H26*H29 -> 0 | I30: =I26*I29 -> 0 | ... K30: =K26*K29 -> 0
A31: Less: SBC (verified nil) | B31: 0 | C31: 0 | D31: 0 | E31: 0 | F31: 0 | G31: 0 | H31: 0 | I31: 0 | J31: 0 | K31: 0
A32: Less: D&A | B32: =B26*B28 -> 0 | C32: =C26*C28 -> 0 | D32: =D26*D28 -> 0 | E32: =E26*E28 -> 0 | F32: =F26*F28 -> 0 | G32: =G26*G28 -> 0 | H32: =H26*H28 -> 0 | I32: =I26*I28 -> 0 | ... K32: =K26*K28 -> 0
A33: EBIT (Owner EBITDA - SBC - D&A) | B33: =B30-B31-B32 -> 0 | C33: =C30-C31-C32 -> 0 | D33: =D30-D31-D32 -> 0 | E33: =E30-E31-E32 -> 0 | F33: =F30-F31-F32 -> 0 | G33: =G30-G31-G32 -> 0 | H33: =H30-H31-H32 -> 0 | I33: =I30-I31-I32 -> 0 | ... K33: =K30-K31-K32 -> 0
A34: Cash Tax Rate % | B34: 0.305 | C34: 0.305 | D34: 0.305 | E34: 0.305 | F34: 0.305 | G34: 0.305 | H34: 0.305 | I34: 0.305 | J34: 0.305 | K34: 0.305
A35: NOPAT (EBIT x (1-tax)) | B35: =B33*(1-B34) -> 0 | C35: =C33*(1-C34) -> 0 | D35: =D33*(1-D34) -> 0 | E35: =E33*(1-E34) -> 0 | F35: =F33*(1-F34) -> 0 | G35: =G33*(1-G34) -> 0 | H35: =H33*(1-H34) -> 0 | I35: =I33*(1-I34) -> 0 | ... K35: =K33*(1-K34) -> 0
A36: Capex % of Revenue | B36: 0.05077 | C36: 0.05 | D36: 0.048 | E36: 0.046 | F36: 0.044 | G36: 0.042 | H36: 0.041 | I36: 0.04 | J36: 0.04 | K36: 0.04
A37: Less: Capex | B37: =B26*B36 -> 0 | C37: =C26*C36 -> 0 | D37: =D26*D36 -> 0 | E37: =E26*E36 -> 0 | F37: =F26*F36 -> 0 | G37: =G26*G36 -> 0 | H37: =H26*H36 -> 0 | I37: =I26*I36 -> 0 | ... K37: =K26*K36 -> 0
A38: WC Capture % of Revenue Change | B38: 0.08 | C38: (applied to all years vs prior-year revenue)
A39: Less: Working Capital (WC% x DeltaRev) | B39: =$B$38*(B26-B15) -> 0 | C39: =$B$38*(C26-B26) -> 0 | D39: =$B$38*(D26-C26) -> 0 | E39: =$B$38*(E26-D26) -> 0 | F39: =$B$38*(F26-E26) -> 0 | G39: =$B$38*(G26-F26) -> 0 | H39: =$B$38*(H26-G26) -> 0 | I39: =$B$38*(I26-H26) -> 0 | J39: =$B$38*(J26-I26) -> 0 | K39: =$B$38*(K26-J26) -> 0
A40: OWNER FCF (NOPAT+D&A-Capex-WC) | B40: =B35+B32-B37-B39 -> 0 | C40: =C35+C32-C37-C39 -> 0 | D40: =D35+D32-D37-D39 -> 0 | E40: =E35+E32-E37-E39 -> 0 | F40: =F35+F32-F37-F39 -> 0 | G40: =G35+G32-G37-G39 -> 0 | H40: =H35+H32-H37-H39 -> 0 | I40: =I35+I32-I37-I39 -> 0 | ... K40: =K35+K32-K37-K39 -> 0
A41: Owner FCF Margin % | B41: =B40/B26 -> 0 | C41: =C40/C26 -> 0 | D41: =D40/D26 -> 0 | E41: =E40/E26 -> 0 | F41: =F40/F26 -> 0 | G41: =G40/G26 -> 0 | H41: =H40/H26 -> 0 | I41: =I40/I26 -> 0 | ... K41: =K40/K26 -> 0
A42: Discount Factor | B42: =1/(1+$B$17)^1 -> 0 | C42: =1/(1+$B$17)^2 -> 0 | D42: =1/(1+$B$17)^3 -> 0 | E42: =1/(1+$B$17)^4 -> 0 | F42: =1/(1+$B$17)^5 -> 0 | G42: =1/(1+$B$17)^6 -> 0 | H42: =1/(1+$B$17)^7 -> 0 | I42: =1/(1+$B$17)^8 -> 0 | J42: =1/(1+$B$17)^9 -> 0 | K42: =1/(1+$B$17)^10 -> 0
A43: PV of Owner FCF | B43: =B40*B42 -> 0 | C43: =C40*C42 -> 0 | D43: =D40*D42 -> 0 | E43: =E40*E42 -> 0 | F43: =F40*F42 -> 0 | G43: =G40*G42 -> 0 | H43: =H40*H42 -> 0 | I43: =I40*I42 -> 0 | ... K43: =K40*K42 -> 0
A44: Projected Shares Outstanding (M) | B44: =$B$6*(1+$B$20) -> 0 | C44: =B44*(1+$B$20) -> 0 | D44: =C44*(1+$B$20) -> 0 | E44: =D44*(1+$B$20) -> 0 | F44: =E44*(1+$B$20) -> 0 | G44: =F44*(1+$B$20) -> 0 | H44: =G44*(1+$B$20) -> 0 | I44: =H44*(1+$B$20) -> 0 | J44: =I44*(1+$B$20) -> 0 | K44: =J44*(1+$B$20) -> 0
A46: VALUATION
...

Sheet Sensitivity
A1: Sensitivity Analysis
A2: Intrinsic Value by WACC & Exit EV/EBITDA Multiple (the multiple, not terminal growth, is the binding driver here)
A4: WACC \ Exit Mult | B4: 1.67 | C4: 2.16 | D4: 2.66 | E4: 3.12 | F4: 3.6
A5: 0.075 | B5: =(SUMPRODUCT('DCF Model'!$B$40:'DCF Model'!$K$40,(1+0.075)^-{1,2,3,4,5,6,7,8,9,10})+(1.67*'DCF Model'!$B$49)*(1+0.075)^-10-'DCF Model'!$B$55)/'DCF Model'!$K$44 -> 0 | C5: =(SUMPRODUCT('DCF Model'!$B$40:'DCF Model'!$K$40,(1+0.075)^-{1,2,3,4,5,6,7,8,9,10})+(2.16*'DCF Model'!$B$49)*(1+0.075)^-10-'DCF Model'!$B$55)/'DCF Model'!$K$44 -> 0 | D5: =(SUMPRODUCT('DCF Model'!$B$40:'DCF Model'!$K$40,(1+0.075)^-{1,2,3,4,5,6,7,8,9,10})+(2.66*'DCF Model'!$B$49)*(1+0.075)^-10-'DCF Model'!$B$55)/'DCF Model'!$K$44 -> 0 | E5: =(SUMPRODUCT('DCF Model'!$B$40:'DCF Model'!$K$40,(1+0.075)^-{1,2,3,4,5,6,7,8,9,10})+(3.12*'DCF Model'!$B$49)*(1+0.075)^-10-'DCF Model'!$B$55)/'DCF Model'!$K$44 -> 0 | F5: =(SUMPRODUCT('DCF Model'!$B$40:'DCF Model'!$K$40,(1+0.075)^-{1,2,3,4,5,6,7,8,9,10})+(3.6*'DCF Model'!$B$49)*(1+0.075)^-10-'DCF Model'!$B$55)/'DCF Model'!$K$44 -> 0
A6: 0.085 | B6: =(SUMPRODUCT('DCF Model'!$B$40:'DCF Model'!$K$40,(1+0.085)^-{1,2,3,4,5,6,7,8,9,10})+(1.67*'DCF Model'!$B$49)*(1+0.085)^-10-'DCF Model'!$B$55)/'DCF Model'!$K$44 -> 0 | C6: =(SUMPRODUCT('DCF Model'!$B$40:'DCF Model'!$K$40,(1+0.085)^-{1,2,3,4,5,6,7,8,9,10})+(2.16*'DCF Model'!$B$49)*(1+0.085)^-10-'DCF Model'!$B$55)/'DCF Model'!$K$44 -> 0 | D6: =(SUMPRODUCT('DCF Model'!$B$40:'DCF Model'!$K$40,(1+0.085)^-{1,2,3,4,5,6,7,8,9,10})+(2.66*'DCF Model'!$B$49)*(1+0.085)^-10-'DCF Model'!$B$55)/'DCF Model'!$K$44 -> 0 | E6: =(SUMPRODUCT('DCF Model'!$B$40:'DCF Model'!$K$40,(1+0.085)^-{1,2,3,4,5,6,7,8,9,10})+(3.12*'DCF Model'!$B$49)*(1+0.085)^-10-'DCF Model'!$B$55)/'DCF Model'!$K$44 -> 0 | F6: =(SUMPRODUCT('DCF Model'!$B$40:'DCF Model'!$K$40,(1+0.085)^-{1,2,3,4,5,6,7,8,9,10})+(3.6*'DCF Model'!$B$49)*(1+0.085)^-10-'DCF Model'!$B$55)/'DCF Model'!$K$44 -> 0
A7: 0.095 | B7: =(SUMPRODUCT('DCF Model'!$B$40:'DCF Model'!$K$40,(1+0.095)^-{1,2,3,4,5,6,7,8,9,10})+(1.67*'DCF Model'!$B$49)*(1+0.095)^-10-'DCF Model'!$B$55)/'DCF Model'!$K$44 -> 0 | C7: =(SUMPRODUCT('DCF Model'!$B$40:'DCF Model'!$K$40,(1+0.095)^-{1,2,3,4,5,6,7,8,9,10})+(2.16*'DCF Model'!$B$49)*(1+0.095)^-10-'DCF Model'!$B$55)/'DCF Model'!$K$44 -> 0 | D7: =(SUMPRODUCT('DCF Model'!$B$40:'DCF Model'!$K$40,(1+0.095)^-{1,2,3,4,5,6,7,8,9,10})+(2.66*'DCF Model'!$B$49)*(1+0.095)^-10-'DCF Model'!$B$55)/'DCF Model'!$K$44 -> 0 | E7: =(SUMPRODUCT('DCF Model'!$B$40:'DCF Model'!$K$40,(1+0.095)^-{1,2,3,4,5,6,7,8,9,10})+(3.12*'DCF Model'!$B$49)*(1+0.095)^-10-'DCF Model'!$B$55)/'DCF Model'!$K$44 -> 0 | F7: =(SUMPRODUCT('DCF Model'!$B$40:'DCF Model'!$K$40,(1+0.095)^-{1,2,3,4,5,6,7,8,9,10})+(3.6*'DCF Model'!$B$49)*(1+0.095)^-10-'DCF Model'!$B$55)/'DCF Model'!$K$44 -> 0
A8: 0.105 | B8: =(SUMPRODUCT('DCF Model'!$B$40:'DCF Model'!$K$40,(1+0.105)^-{1,2,3,4,5,6,7,8,9,10})+(1.67*'DCF Model'!$B$49)*(1+0.105)^-10-'DCF Model'!$B$55)/'DCF Model'!$K$44 -> 0 | C8: =(SUMPRODUCT('DCF Model'!$B$40:'DCF Model'!$K$40,(1+0.105)^-{1,2,3,4,5,6,7,8,9,10})+(2.16*'DCF Model'!$B$49)*(1+0.105)^-10-'DCF Model'!$B$55)/'DCF Model'!$K$44 -> 0 | D8: =(SUMPRODUCT('DCF Model'!$B$40:'DCF Model'!$K$40,(1+0.105)^-{1,2,3,4,5,6,7,8,9,10})+(2.66*'DCF Model'!$B$49)*(1+0.105)^-10-'DCF Model'!$B$55)/'DCF Model'!$K$44 -> 0 | E8: =(SUMPRODUCT('DCF Model'!$B$40:'DCF Model'!$K$40,(1+0.105)^-{1,2,3,4,5,6,7,8,9,10})+(3.12*'DCF Model'!$B$49)*(1+0.105)^-10-'DCF Model'!$B$55)/'DCF Model'!$K$44 -> 0 | F8: =(SUMPRODUCT('DCF Model'!$B$40:'DCF Model'!$K$40,(1+0.105)^-{1,2,3,4,5,6,7,8,9,10})+(3.6*'DCF Model'!$B$49)*(1+0.105)^-10-'DCF Model'!$B$55)/'DCF Model'!$K$44 -> 0
A9: 0.115 | B9: =(SUMPRODUCT('DCF Model'!$B$40:'DCF Model'!$K$40,(1+0.115)^-{1,2,3,4,5,6,7,8,9,10})+(1.67*'DCF Model'!$B$49)*(1+0.115)^-10-'DCF Model'!$B$55)/'DCF Model'!$K$44 -> 0 | C9: =(SUMPRODUCT('DCF Model'!$B$40:'DCF Model'!$K$40,(1+0.115)^-{1,2,3,4,5,6,7,8,9,10})+(2.16*'DCF Model'!$B$49)*(1+0.115)^-10-'DCF Model'!$B$55)/'DCF Model'!$K$44 -> 0 | D9: =(SUMPRODUCT('DCF Model'!$B$40:'DCF Model'!$K$40,(1+0.115)^-{1,2,3,4,5,6,7,8,9,10})+(2.66*'DCF Model'!$B$49)*(1+0.115)^-10-'DCF Model'!$B$55)/'DCF Model'!$K$44 -> 0 | E9: =(SUMPRODUCT('DCF Model'!$B$40:'DCF Model'!$K$40,(1+0.115)^-{1,2,3,4,5,6,7,8,9,10})+(3.12*'DCF Model'!$B$49)*(1+0.115)^-10-'DCF Model'!$B$55)/'DCF Model'!$K$44 -> 0 | F9: =(SUMPRODUCT('DCF Model'!$B$40:'DCF Model'!$K$40,(1+0.115)^-{1,2,3,4,5,6,7,8,9,10})+(3.6*'DCF Model'!$B$49)*(1+0.115)^-10-'DCF Model'!$B$55)/'DCF Model'!$K$44 -> 0
A11: Standard WACC x Terminal Growth matrix (mostly flat - cap binds at all these growth rates)
A13: WACC \ Term G | B13: 0.005 | C13: 0.01 | D13: 0.015 | E13: 0.02 | F13: 0.025
A14: 0.075 | B14: 3850.36 | C14: 3850.36 | D14: 3850.36 | E14: 3850.36 | F14: 3850.36
A15: 0.085 | B15: 3663.91 | C15: 3663.91 | D15: 3663.91 | E15: 3663.91 | F15: 3663.91
A16: 0.095 | B16: 3493.31 | C16: 3493.31 | D16: 3493.31 | E16: 3493.31 | F16: 3493.31
A17: 0.105 | B17: 3337.02 | C17: 3337.02 | D17: 3337.02 | E17: 3337.02 | F17: 3337.02
A18: 0.115 | B18: 3193.67 | C18: 3193.67 | D18: 3193.67 | E18: 3193.67 | F18: 3193.67

Sheet FCF Quality
A1: FCF Quality - Reported vs Owner FCF Reconciliation
A2: SBC verified NIL throughout FY2017-FY2026; only adjustment is stripping interest/dividend income (net cash >1x FCF base)
B4: FY2017 | C4: FY2018 | D4: FY2019 | E4: FY2020 | F4: FY2021 | G4: FY2022 | H4: FY2023 | I4: FY2024 | J4: FY2025 | K4: FY2026
A5: Reported FCF (company definition) | B5: 11198 | C5: 687 | D5: 12612 | E5: 17281 | F5: 22472 | G5: 276 | H5: 8677 | I5: 26397 | J5: 8575 | K5: 8522
A6: Less: SBC (verified nil) | B6: 0 | C6: 0 | D6: 0 | E6: 0 | F6: 0 | G6: 0 | H6: 0 | I6: 0 | J6: 0 | K6: 0
A7: Less: Interest & Dividend Income | B7: 790 | C7: 839 | D7: 918 | E7: 969 | F7: 936 | G7: 666 | H7: 754 | I7: 1125 | J7: 1843 | K7: 1889
A8: = Owner FCF | B8: 10408 | C8: -152 | D8: 11694 | E8: 16312 | F8: 21536 | G8: -390 | H8: 7923 | I8: 25272 | J8: 6732 | K8: 6633
A10: Reported FCF Margin % | B10: 0.024392794 | C10: 0.0014254739 | D10: 0.024844133 | E10: 0.034561862 | F10: 0.051065648 | G10: 0.00056638272 | H10: 0.01568726 | I10: 0.04233287 | J10: 0.013883042 | K10: 0.013218531
A11: Owner FCF Margin % | B11: 0.022671924 | C11: -0.00031538869 | D11: 0.023035783 | E11: 0.03262387 | F11: 0.04893867 | G11: -0.00080032341 | H11: 0.014324094 | I11: 0.040528708 | J11: 0.0108992 | K11: 0.01028849
A13: Memo: Capex (JPYm) | B13: 22299 | C13: 20139 | D13: 25307 | E13: 23065 | F13: 12210 | G13: 14401 | H13: 18078 | I13: 26869 | J13: 30621 | K13: 35232
A14: Memo: Capex % of Revenue | B14: 0.048574292 | C14: 0.041786926 | D14: 0.049851766 | E14: 0.046129815 | F14: 0.027746153 | G14: 0.029552455 | H14: 0.032683449 | I14: 0.043089817 | J14: 0.049575818 | K14: 0.054648589
A16: Memo: Cash Tax Rate % (FY2026 only disclosed) | K16: 0.31
A18: Note: FCF is structurally volatile across the capex cycle (10yr range JPY0.3bn-JPY26.4bn, mean JPY11.7bn, median JPY9.9bn).
A19: FY2026 owner FCF (JPY6.6bn) is BELOW the median despite record operating profit (JPY35.6bn) - the gap is a heavy capex cycle (5.46% of revenue).
A20: DCF projections are built bottom-up from EBITDA/D&A/tax/capex/WC components, not extrapolated from any single historical FCF year.

Sheet Historical
A1: Historical Growth Rates & Multiples
A3: Metric | B3: 3-Year CAGR | C3: 5-Year CAGR
A4: Revenue | B4: 0.0524 | C4: 0.0794
A5: EPS | B5: 0.4535 | C5: 0.2241
A6: Equity (Book Value) | B6: 0.0623 | C6: 0.0558
A7: Reported FCF | B7: -0.006 | C7: -0.1763
A8: Owner FCF | B8: -0.0575 | C8: -0.2099
A10: Selected Growth Rate: | B10: 0.0558
A11: Source: | B11: equity_5yr_cagr
A12: Divergence Warning:
A13: EPS 5yr CAGR (22.41%) diverges 75.1% from equity 5yr CAGR (5.58%), and EPS 3yr CAGR (45.35%) is even more extreme -- both are artifacts of the FY2022 trough base (EPS JPY31.77, an operating-profit trough year at 1.8% margin) rather than a genuine step-change in earnings power. Reported and owner FCF CAGRs are both NEGATIVE (-0.6%/-17.6% and -5.8%/-21.0% respectively) purely because FY2021 (a low-capex COVID-recovery year, FCF JPY22.5bn) and FY2024 (a working-capital-favorable year, FCF JPY26.4bn) are unusually high starting/ending points against a capex-heavy FY2026 (FCF JPY8.5bn) -- FCF CAGR is NOT used as the growth driver for this reason; equity CAGR (the most stable, least distorted series) is used instead, consistent with the Growth Rate Selection Logic primary rule.
A16: Historical Multiples (FY-end, March close)
B18: FY2017 | C18: FY2018 | D18: FY2019 | E18: FY2020 | F18: FY2021 | G18: FY2022 | H18: FY2023 | I18: FY2024 | J18: FY2025 | K18: FY2026
A19: Price (JPY) | B19: 2071 | C19: 2190 | D19: 1929 | E19: 1385 | F19: 1766 | G19: 1370 | H19: 1868 | I19: 2150 | J19: 2129 | K19: 2891
A20: P/E | C20: 9.1 | D20: 9.7 | E20: 8.4 | F20: 14 | G20: 43.1 | H20: 16.6 | I20: 7.8 | J20: 6.9 | K20: 8.3
A21: P/B | B21: 0.89 | C21: 0.86 | D21: 0.73 | E21: 0.52 | F21: 0.61 | G21: 0.45 | H21: 0.59 | I21: 0.58 | J21: 0.59 | K21: 0.71
A22: EV/EBITDA | B22: 2.67 | C22: 2.93 | D22: 2.55 | E22: 1.67 | F22: 3.11 | G22: 2.99 | H22: 3.12 | I22: 2.74 | J22: 2.07 | K22: 2.75
A24: Current EV/EBITDA: | B24: 2.97
A25: 10yr avg EV/EBITDA: | B25: 2.66
A26: Current P/B: | B26: 0.74
A27: 10yr avg P/B: | B27: 0.65

Sheet Model_Info
A1: Model Provenance & Methodology
A3: Ticker | B3: 6995.T (TOKAI RIKA CO., LTD.)
A4: Built by | B4: Claude dcf-analyst agent, per .claude/agents/dcf-analyst.md workflow
A5: Valuation date | B5: 2026-08-14
A6: Share price vintage | B6: JPY3040 - live Yahoo Finance quote fetched 2026-08-14
A7: Filing vintage | B7: FY2026 (year ended 31-Mar-2026) Kessan Tanshin, released 15-May-2026 (delayed from normal schedule due to FY2021-2025 restatement); FY2027 guidance issued same date
A8: Horizon | B8: 10-year explicit component build (not 5) because FY2027 guided op margin (4.62%) is still well below the assumed mature level (6.0% base case Y10) -- a 5yr horizon would capitalize an immature margin
A9: SBC treatment | B9: Verified NIL across all 10 historical fiscal years -- no adjustment needed, no dilution modeled
A10: Interest income treatment | B10: Interest+dividend income (~JPY1.9bn/yr) stripped from FCF base because net cash (JPY83.8bn) is ~10x FY2026 reported FCF -- avoids double-counting the cash pile (once in FCF, once in the net-debt addback)
A11: Terminal value method | B11: MIN(Gordon growth, EV/EBITDA cap) in every scenario -- the cap BINDS in all three scenarios. Caps are set to the stocks own 10-year historical EV/EBITDA range (bear=1.67x min, base=2.66x avg, bull=3.12x max), not the workflow default 20x, because this is a low-multiple, cyclical, keiretsu-embedded Tier-1 supplier the market has never priced above ~3.1x EV/EBITDA in a decade
A12: WACC construction | B12: CAPM (JGB 1.7% + beta 0.85 x ERP 5.0%) + explicit premiums: +2.0pp Toyota concentration (~74% of sales), +1.0pp extreme cyclicality (3.9x peak-to-trough op profit), +0.5pp governance (Apr-2026 multi-year ICFR material weakness/restatement) = 9.5% base WACC. No small-cap premium (market cap ~USD1.7bn, TSE Prime).
A13: Growth rate selection | B13: Equity 5yr CAGR (5.58%) selected as primary driver per Growth Rate Selection Logic -- EPS CAGR (22-45%) is a trough-base artifact of FY2022 and excluded as unrepresentative
A14: Key judgment calls | B14: Base case assumes PARTIAL (not full) progress toward TRV2030 (op margin recovers to 6.0% by Y10 vs the 7% FY2031 stretch target) given the companys own disclosed persistent net price-down drag. Working capital modeled on the CHANGE in revenue (8% capture rate), not a fixed % of revenue, per methodology.
... A17: Staleness warning | B17: All figures are current as of the valuation date above. Share price, guidance, and multiples WILL go stale -- re-verify before relying on this model for a live investment decision.
