Workbook

Sheet SOTP Model
A1: GXH.NZ Sum-of-Parts Valuation Model
A2: Gray cells are INPUTS. Post-Medical-divestment sum-of-parts: PV(Pharmacy DCF) + Net Proceeds + Existing Net Cash
A4: KEY INPUTS
A5: Current Stock Price | B5: 1.95
A6: Shares Outstanding (M) | B6: 143.83415
A7: Existing Group Net Cash (M) - pre proceeds | B7: 8.58
A8: Gross Medical Sale Proceeds (M) | B8: 270
A9: Net Proceeds - Mid Case (M) | B9: 223.3
A10: Capital Allocation Discount (Base) | B10: 0.15
A11: Effective Net Proceeds (Base) | B11: =B9*(1-B10) -> 0
A13: Pharmacy Segment Revenue FY2026 (M) | B13: 380.21
A14: Corporate Cost FY2026 (M) | B14: 3.026
A15: Corporate Cost Allocated to Pharmacy (%) | B15: 0.8
A16: NCI % of Pharmacy Profit | B16: 0.212
A17: Cash Tax Rate | B17: 0.28
A19: WACC (Pharmacy operating business) | B19: 0.145
A20: Terminal Growth Rate | B20: 0.02
A21: Terminal Cap Multiple (EV/EBITDA) | B21: 5.7
A23: PHARMACY GROWTH & MARGIN ASSUMPTIONS (BASE)
B24: Year 1 | C24: Year 2 | D24: Year 3 | E24: Year 4 | F24: Year 5
A25: Revenue Growth Rate | B25: 0.03 | C25: 0.03 | D25: 0.025 | E25: 0.025 | F25: 0.02
A26: EBITDA Margin (net of stranded corp cost) | B26: 0.085 | C26: 0.086 | D26: 0.087 | E26: 0.088 | F26: 0.089
A27: D&A % of Revenue | B27: 0.0336 | C27: 0.0336 | D27: 0.0336 | E27: 0.0336 | F27: 0.0336
A28: CapEx % of Revenue | B28: 0.0176 | C28: 0.0176 | D28: 0.0176 | E28: 0.0176 | F28: 0.0176
A29: Lease Principal % of Revenue | B29: 0.0222 | C29: 0.0222 | D29: 0.0222 | E29: 0.0222 | F29: 0.0222
A30: Working Capital Capture % (of rev change) | B30: 0.15 | C30: 0.15 | D30: 0.15 | E30: 0.15 | F30: 0.15
A32: PHARMACY PROJECTIONS (component build)
B33: Year 1 | C33: Year 2 | D33: Year 3 | E33: Year 4 | F33: Year 5
A34: Revenue | B34: =$B$13*(1+B25) -> 0 | C34: =B34*(1+C25) -> 0 | D34: =C34*(1+D25) -> 0 | E34: =D34*(1+E25) -> 0 | F34: =E34*(1+F25) -> 0
A35: EBITDA (net of stranded corp cost) | B35: =B34*B26 -> 0 | C35: =C34*C26 -> 0 | D35: =D34*D26 -> 0 | E35: =E34*E26 -> 0 | F35: =F34*F26 -> 0
A36: D&A (incl. lease depreciation) | B36: =B34*B27 -> 0 | C36: =C34*C27 -> 0 | D36: =D34*D27 -> 0 | E36: =E34*E27 -> 0 | F36: =F34*F27 -> 0
A37: EBIT | B37: =B35-B36 -> 0 | C37: =C35-C36 -> 0 | D37: =D35-D36 -> 0 | E37: =E35-E36 -> 0 | F37: =F35-F36 -> 0
A38: NOPAT | B38: =B37*(1-$B$17) -> 0 | C38: =C37*(1-$B$17) -> 0 | D38: =D37*(1-$B$17) -> 0 | E38: =E37*(1-$B$17) -> 0 | F38: =F37*(1-$B$17) -> 0
A39: CapEx | B39: =B34*B28 -> 0 | C39: =C34*C28 -> 0 | D39: =D34*D28 -> 0 | E39: =E34*E28 -> 0 | F39: =F34*F28 -> 0
A40: Lease Principal Repayment | B40: =B34*B29 -> 0 | C40: =C34*C29 -> 0 | D40: =D34*D29 -> 0 | E40: =E34*E29 -> 0 | F40: =F34*F29 -> 0
A41: Working Capital (use of cash) | B41: 0 | C41: =(C34-B34)*C30 -> 0 | D41: =(D34-C34)*D30 -> 0 | E41: =(E34-D34)*E30 -> 0 | F41: =(F34-E34)*F30 -> 0
A42: Owner FCF (pre-NCI) | B42: =B38+B36-B39-B40-B41 -> 0 | C42: =C38+C36-C39-C40-C41 -> 0 | D42: =D38+D36-D39-D40-D41 -> 0 | E42: =E38+E36-E39-E40-E41 -> 0 | F42: =F38+F36-F39-F40-F41 -> 0
A43: Owner FCF (post-NCI, to GXH shareholders) | B43: =B42*(1-$B$16) -> 0 | C43: =C42*(1-$B$16) -> 0 | D43: =D42*(1-$B$16) -> 0 | E43: =E42*(1-$B$16) -> 0 | F43: =F42*(1-$B$16) -> 0
A44: Discount Factor | B44: =1/(1+$B$19)^1 -> 0 | C44: =1/(1+$B$19)^2 -> 0 | D44: =1/(1+$B$19)^3 -> 0 | E44: =1/(1+$B$19)^4 -> 0 | F44: =1/(1+$B$19)^5 -> 0
A45: PV of Owner FCF | B45: =B43*B44 -> 0 | C45: =C43*C44 -> 0 | D45: =D43*D44 -> 0 | E45: =E43*E44 -> 0 | F45: =F43*F44 -> 0
...

Sheet Scenarios
A1: Scenario Comparison
A2: Static summary of Bull/Base/Bear (see SOTP Model sheet for live Base-case formulas)
B4: Bear | C4: Base | D4: Bull
A6: WACC | B6: 0.16 | C6: 0.145 | D6: 0.13
A7: Terminal Growth | B7: 0.015 | C7: 0.02 | D7: 0.025
A8: Terminal Cap Multiple (EV/EBITDA) | B8: 3.7 | C8: 5.7 | D8: 9.2
A9: Net Proceeds Case (M) | B9: 199.2 | C9: 223.3 | D9: 252.2
A10: Capital Allocation Discount | B10: 0.35 | C10: 0.15 | D10: 0
A11: Pharmacy Enterprise Value (M) | B11: 40.549 | C11: 74.356 | D11: 113.27
A12: Equity Value (M) | B12: 178.609 | C12: 272.741 | D12: 374.05
A13: Intrinsic Value / Share | B13: 1.242 | C13: 1.896 | D13: 2.601
A14: Upside / (Downside) | B14: -0.3632 | C14: -0.0276 | D14: 0.3336
A15: Terminal Value % of EV | B15: 0.464 | C15: 0.584 | D15: 0.659
A18: Probability Weights | B18: 0.3 | C18: 0.45 | D18: 0.25
A19: Probability-Weighted IV | B19: 1.878
A20: Weighted Upside | B20: -0.037

Sheet Sensitivity
A1: Sensitivity Analysis (Base Case)
A2: Intrinsic Value by WACC & Terminal Growth
A4: WACC \ Term G | B4: 0.01 | C4: 0.015 | D4: 0.02 | E4: 0.025 | F4: 0.03
A5: 0.125 | B5: =(NPV(0.125,'SOTP Model'!$B$43:$F$43)+MIN('SOTP Model'!$F$43*(1+0.01)/(0.125-0.01),'SOTP Model'!$F$35*'SOTP Model'!$B$21)/(1+0.125)^5+'SOTP Model'!$B$7+'SOTP Model'!$B$11)/'SOTP Model'!$B$6 -> 0 | C5: =(NPV(0.125,'SOTP Model'!$B$43:$F$43)+MIN('SOTP Model'!$F$43*(1+0.015)/(0.125-0.015),'SOTP Model'!$F$35*'SOTP Model'!$B$21)/(1+0.125)^5+'SOTP Model'!$B$7+'SOTP Model'!$B$11)/'SOTP Model'!$B$6 -> 0 | D5: =(NPV(0.125,'SOTP Model'!$B$43:$F$43)+MIN('SOTP Model'!$F$43*(1+0.02)/(0.125-0.02),'SOTP Model'!$F$35*'SOTP Model'!$B$21)/(1+0.125)^5+'SOTP Model'!$B$7+'SOTP Model'!$B$11)/'SOTP Model'!$B$6 -> 0 | E5: =(NPV(0.125,'SOTP Model'!$B$43:$F$43)+MIN('SOTP Model'!$F$43*(1+0.025)/(0.125-0.025),'SOTP Model'!$F$35*'SOTP Model'!$B$21)/(1+0.125)^5+'SOTP Model'!$B$7+'SOTP Model'!$B$11)/'SOTP Model'!$B$6 -> 0 | F5: =(NPV(0.125,'SOTP Model'!$B$43:$F$43)+MIN('SOTP Model'!$F$43*(1+0.03)/(0.125-0.03),'SOTP Model'!$F$35*'SOTP Model'!$B$21)/(1+0.125)^5+'SOTP Model'!$B$7+'SOTP Model'!$B$11)/'SOTP Model'!$B$6 -> 0
A6: 0.135 | B6: =(NPV(0.135,'SOTP Model'!$B$43:$F$43)+MIN('SOTP Model'!$F$43*(1+0.01)/(0.135-0.01),'SOTP Model'!$F$35*'SOTP Model'!$B$21)/(1+0.135)^5+'SOTP Model'!$B$7+'SOTP Model'!$B$11)/'SOTP Model'!$B$6 -> 0 | C6: =(NPV(0.135,'SOTP Model'!$B$43:$F$43)+MIN('SOTP Model'!$F$43*(1+0.015)/(0.135-0.015),'SOTP Model'!$F$35*'SOTP Model'!$B$21)/(1+0.135)^5+'SOTP Model'!$B$7+'SOTP Model'!$B$11)/'SOTP Model'!$B$6 -> 0 | D6: =(NPV(0.135,'SOTP Model'!$B$43:$F$43)+MIN('SOTP Model'!$F$43*(1+0.02)/(0.135-0.02),'SOTP Model'!$F$35*'SOTP Model'!$B$21)/(1+0.135)^5+'SOTP Model'!$B$7+'SOTP Model'!$B$11)/'SOTP Model'!$B$6 -> 0 | E6: =(NPV(0.135,'SOTP Model'!$B$43:$F$43)+MIN('SOTP Model'!$F$43*(1+0.025)/(0.135-0.025),'SOTP Model'!$F$35*'SOTP Model'!$B$21)/(1+0.135)^5+'SOTP Model'!$B$7+'SOTP Model'!$B$11)/'SOTP Model'!$B$6 -> 0 | F6: =(NPV(0.135,'SOTP Model'!$B$43:$F$43)+MIN('SOTP Model'!$F$43*(1+0.03)/(0.135-0.03),'SOTP Model'!$F$35*'SOTP Model'!$B$21)/(1+0.135)^5+'SOTP Model'!$B$7+'SOTP Model'!$B$11)/'SOTP Model'!$B$6 -> 0
A7: 0.145 | B7: =(NPV(0.145,'SOTP Model'!$B$43:$F$43)+MIN('SOTP Model'!$F$43*(1+0.01)/(0.145-0.01),'SOTP Model'!$F$35*'SOTP Model'!$B$21)/(1+0.145)^5+'SOTP Model'!$B$7+'SOTP Model'!$B$11)/'SOTP Model'!$B$6 -> 0 | C7: =(NPV(0.145,'SOTP Model'!$B$43:$F$43)+MIN('SOTP Model'!$F$43*(1+0.015)/(0.145-0.015),'SOTP Model'!$F$35*'SOTP Model'!$B$21)/(1+0.145)^5+'SOTP Model'!$B$7+'SOTP Model'!$B$11)/'SOTP Model'!$B$6 -> 0 | D7: =(NPV(0.145,'SOTP Model'!$B$43:$F$43)+MIN('SOTP Model'!$F$43*(1+0.02)/(0.145-0.02),'SOTP Model'!$F$35*'SOTP Model'!$B$21)/(1+0.145)^5+'SOTP Model'!$B$7+'SOTP Model'!$B$11)/'SOTP Model'!$B$6 -> 0 | E7: =(NPV(0.145,'SOTP Model'!$B$43:$F$43)+MIN('SOTP Model'!$F$43*(1+0.025)/(0.145-0.025),'SOTP Model'!$F$35*'SOTP Model'!$B$21)/(1+0.145)^5+'SOTP Model'!$B$7+'SOTP Model'!$B$11)/'SOTP Model'!$B$6 -> 0 | F7: =(NPV(0.145,'SOTP Model'!$B$43:$F$43)+MIN('SOTP Model'!$F$43*(1+0.03)/(0.145-0.03),'SOTP Model'!$F$35*'SOTP Model'!$B$21)/(1+0.145)^5+'SOTP Model'!$B$7+'SOTP Model'!$B$11)/'SOTP Model'!$B$6 -> 0
A8: 0.155 | B8: =(NPV(0.155,'SOTP Model'!$B$43:$F$43)+MIN('SOTP Model'!$F$43*(1+0.01)/(0.155-0.01),'SOTP Model'!$F$35*'SOTP Model'!$B$21)/(1+0.155)^5+'SOTP Model'!$B$7+'SOTP Model'!$B$11)/'SOTP Model'!$B$6 -> 0 | C8: =(NPV(0.155,'SOTP Model'!$B$43:$F$43)+MIN('SOTP Model'!$F$43*(1+0.015)/(0.155-0.015),'SOTP Model'!$F$35*'SOTP Model'!$B$21)/(1+0.155)^5+'SOTP Model'!$B$7+'SOTP Model'!$B$11)/'SOTP Model'!$B$6 -> 0 | D8: =(NPV(0.155,'SOTP Model'!$B$43:$F$43)+MIN('SOTP Model'!$F$43*(1+0.02)/(0.155-0.02),'SOTP Model'!$F$35*'SOTP Model'!$B$21)/(1+0.155)^5+'SOTP Model'!$B$7+'SOTP Model'!$B$11)/'SOTP Model'!$B$6 -> 0 | E8: =(NPV(0.155,'SOTP Model'!$B$43:$F$43)+MIN('SOTP Model'!$F$43*(1+0.025)/(0.155-0.025),'SOTP Model'!$F$35*'SOTP Model'!$B$21)/(1+0.155)^5+'SOTP Model'!$B$7+'SOTP Model'!$B$11)/'SOTP Model'!$B$6 -> 0 | F8: =(NPV(0.155,'SOTP Model'!$B$43:$F$43)+MIN('SOTP Model'!$F$43*(1+0.03)/(0.155-0.03),'SOTP Model'!$F$35*'SOTP Model'!$B$21)/(1+0.155)^5+'SOTP Model'!$B$7+'SOTP Model'!$B$11)/'SOTP Model'!$B$6 -> 0
A9: 0.165 | B9: =(NPV(0.165,'SOTP Model'!$B$43:$F$43)+MIN('SOTP Model'!$F$43*(1+0.01)/(0.165-0.01),'SOTP Model'!$F$35*'SOTP Model'!$B$21)/(1+0.165)^5+'SOTP Model'!$B$7+'SOTP Model'!$B$11)/'SOTP Model'!$B$6 -> 0 | C9: =(NPV(0.165,'SOTP Model'!$B$43:$F$43)+MIN('SOTP Model'!$F$43*(1+0.015)/(0.165-0.015),'SOTP Model'!$F$35*'SOTP Model'!$B$21)/(1+0.165)^5+'SOTP Model'!$B$7+'SOTP Model'!$B$11)/'SOTP Model'!$B$6 -> 0 | D9: =(NPV(0.165,'SOTP Model'!$B$43:$F$43)+MIN('SOTP Model'!$F$43*(1+0.02)/(0.165-0.02),'SOTP Model'!$F$35*'SOTP Model'!$B$21)/(1+0.165)^5+'SOTP Model'!$B$7+'SOTP Model'!$B$11)/'SOTP Model'!$B$6 -> 0 | E9: =(NPV(0.165,'SOTP Model'!$B$43:$F$43)+MIN('SOTP Model'!$F$43*(1+0.025)/(0.165-0.025),'SOTP Model'!$F$35*'SOTP Model'!$B$21)/(1+0.165)^5+'SOTP Model'!$B$7+'SOTP Model'!$B$11)/'SOTP Model'!$B$6 -> 0 | F9: =(NPV(0.165,'SOTP Model'!$B$43:$F$43)+MIN('SOTP Model'!$F$43*(1+0.03)/(0.165-0.03),'SOTP Model'!$F$35*'SOTP Model'!$B$21)/(1+0.165)^5+'SOTP Model'!$B$7+'SOTP Model'!$B$11)/'SOTP Model'!$B$6 -> 0

Sheet FCF Quality
A1: FCF Quality Reconciliation (Group-Level, Historical Reference Only)
A2: NOTE: These are CONSOLIDATED figures including the now-divested Medical division. NOT the DCF driver.
B4: FY2025 | C4: FY2026
A6: Revenue (Group, incl. Medical) | B6: 523.758 | C6: 545.976
A7: Operating Cash Flow | B7: 52.641 | C7: 54.613
A8: CapEx | B8: 5.838 | C8: 9.608
A9: Reported FCF (company definition) | B9: 46.803 | C9: 45.005
A10: Less: Stock-Based Comp | B10: 0.174 | C10: 0.192
A11: Less: Lease Principal Repayment | B11: 12.577 | C11: 13.752
A12: Owner FCF (Group, historical basis) | B12: 34.052 | C12: 31.061
A13: Reported FCF Margin | B13: 0.0894 | C13: 0.0824
A14: Owner FCF Margin | B14: 0.065 | C14: 0.0569
A16: Memo: Pharmacy-only (retained business) owner FCF build
A17: Pharmacy Segment Revenue FY2026 | C17: 380.21
A18: Pharmacy Segment Profit (EBIT-like) FY2026 | C18: 22.245
A19: Less: 80% of stranded Corporate Cost | C19: 2.4208
A20: NOPAT (post-corp, pre-NCI) | C20: 14.273424
A21: + D&A (incl. lease depreciation) | C21: 12.76
A22: - CapEx (revenue-share allocated) | C22: 6.691
A23: - Lease Principal (allocated) | C23: 8.456
A24: = Owner FCF pre-NCI | C24: 11.887
A25: x (1 - NCI% 21.2%) | C25: 9.366956
A26: = Owner FCF post-NCI (to GXH shareholders) - Year 0 base | C26: 9.366956
A28: Memo: Cash tax rate FY2026 (tax expense / PBT) | C28: 0.27699911
A29: Note: close to NZ statutory 28% - no ramp required

Sheet Historical
A1: Historical Group Financials (Consolidated - includes now-divested Medical)
A2: FY2022 (COVID spike) and FY2023 (Community Health divestment gain) are OUTLIERS - excluded from trend analysis
A4: Period | B4: Revenue (M) | C4: Net Income (M) | D4: Shares (M) | E4: FY-End Price ($)
A6: FY2018 | B6: 522.909 | C6: 16.784 | D6: 143.153 | E6: 2.22
A7: FY2020 | B7: 568.5 | C7: 13.5 | E7: 1.14
A8: FY2021 | B8: 570.4 | C8: 16.8 | E8: 1.03
A9: FY2022 (COVID - excl.) | B9: 670.3 | C9: 24.6 | E9: 1.33
A10: FY2023 (divestment - excl.) | B10: 493.6 | C10: 45.2 | E10: 1.35
A11: FY2024 | B11: 503.9 | C11: 12 | E11: 1.02
A12: FY2025 | B12: 523.758 | C12: 15.975 | D12: 143.603 | E12: 0.75
A13: FY2026 | B13: 545.976 | C13: 20.395 | D13: 143.834 | E13: 1.2
A15: Selected Growth Rate (Pharmacy revenue FY25->FY26) | B15: 0.0266
A16: Source | B16: pharmacy_segment_revenue_growth_fy2025_to_fy2026 (only clean, business-comparable growth data point available; used as the anchor for Base-case Year-1 growth)

Sheet Model_Info
A1: Model Provenance & Notes
A4: Ticker | B4: GXH.NZ (Green Cross Health Limited, NZX)
A5: Model type | B5: Sum-of-parts, post-divestment. NOT a standard consolidated-growth DCF.
A6: Built by | B6: Claude agent (DCF valuation skill), per /Users/swilliams/Stocks/Research/.claude/CLAUDE.md pipeline
A7: Valuation date | B7: 2026-08-11
A8: Share price used | B8: NZ$1.95 (live quote, 11-Aug-2026)
A9: Shares outstanding | B9: 143.834147m (per company register)
A10: Data vintage | B10: FY2026 Annual Report (year ended 31-Mar-2026), Medical division sale completion announcement (31-Jul-2026), shareholder approval (14-Jul-2026)
A11: Key event | B11: GXH sold its Medical division (The Doctors, 65 clinics) to Tend Health for gross NZ$270m, completed 31-Jul-2026. GXH is now a pure-play NZ pharmacy retailer.
A12: Methodology - Pharmacy value | B12: Component-built owner-FCF DCF (5yr explicit + Gordon/exit-multiple-cap terminal value) on the Pharmacy SEGMENT ONLY (FY2026 revenue $380.210m), net of an 80%-allocated share of stranded corporate cost and NCI (~21.2% of profit).
A13: Methodology - Sale proceeds | B13: Net proceeds estimated in a conservative/mid/optimistic range ($199.2m/$223.3m/$252.2m) from the $270m gross headline, since exact net proceeds are NOT company-disclosed. A capital-allocation discount (0%/15%/35% by scenario) is applied to reflect the undisclosed Board decision on use of proceeds.
A14: Methodology - Existing cash | B14: FY2026 year-end (pre-sale) net cash of $8.58m (bank debt basis) added at face value.
A15: Key judgment calls | B15: (1) 80% corporate-cost stranding assumption; (2) lease liability/principal allocation to Pharmacy via its 61.5% share of group lease depreciation; (3) net-proceeds deduction range is an ESTIMATE, not disclosed; (4) capital-allocation discount by scenario is a modelling judgment.
... A18: Staleness warning | B18: All figures in this model reference a specific point in time (11-Aug-2026) and a specific, still-evolving corporate event (the Medical sale and its proceeds). This model WILL go stale quickly and must be re-checked against any Board capital-allocation announcement before being relied upon.
