Workbook

Sheet DCF Model
A2: SANITY CHECK: Stock priced at premium to base-case DCF. At $499, MA trades at 30x P/E near bull-case fair value ($547). Base-case IV $365 implies 27% downside. Limited margin of safety at current price.
A3: MA - Mastercard DCF Valuation Model
A4: Valuation Date: 2026-06-29 | All figures in USD millions unless shown per share | Gray cells = INPUTS
A6: KEY INPUTS
A7: Current Stock Price ($) | B7: 499.02
A8: Shares Outstanding (M) | B8: 906
A9: Cash & Equivalents (M) | B9: 10566
A10: Total Debt (M) | B10: 19000
A11: Net Debt (M) [Debt - Cash] | B11: =B10-B9 -> 0
A12: Base Year FCF (M) [FY2025] | B12: 16433
A14: DISCOUNT RATE INPUTS
A15: WACC | B15: 0.1
A16: Terminal Growth Rate | B16: 0.03
A18: FCF GROWTH ASSUMPTIONS (adjust these cells) | B18: Year 1 | C18: Year 2 | D18: Year 3 | E18: Year 4 | F18: Year 5 | G18: Source / Rationale
A19: FCF Growth Rate | B19: 0.14 | C19: 0.13 | D19: 0.11 | E19: 0.09 | F19: 0.08 | G19: Base case: FY2026 guidance ~12% CN + FX. Decelerates from 14% to 8% over 5 years.
A21: FCF PROJECTIONS | B21: Year 1 | C21: Year 2 | D21: Year 3 | E21: Year 4 | F21: Year 5 | G21: Formula
A22: Free Cash Flow (M) | B22: =B12*(1+B19) -> 0 | C22: =B22*(1+C19) -> 0 | D22: =C22*(1+D19) -> 0 | E22: =D22*(1+E19) -> 0 | F22: =E22*(1+F19) -> 0 | G22: Each year = prior year FCF * (1 + growth rate)
A23: Discount Factor (1/(1+WACC)^n) | B23: =1/(1+B14)^1 -> 0 | C23: =1/(1+B14)^2 -> 0 | D23: =1/(1+B14)^3 -> 0 | E23: =1/(1+B14)^4 -> 0 | F23: =1/(1+B14)^5 -> 0 | G23: =1/(1+WACC)^n where WACC from cell B14 -> 0
A24: PV of FCF (M) | B24: =B22*B23 -> 0 | C24: =C22*C23 -> 0 | D24: =D22*D23 -> 0 | E24: =E22*E23 -> 0 | F24: =F22*F23 -> 0 | G24: PV = FCF * Discount Factor
A26: VALUATION (BASE CASE) | B26: Value ($M) | C26: Notes
A27: Sum of PV of FCF | B27: =SUM(B24:F24) -> 0 | C27: Sum of 5 discounted annual FCFs
A28: Terminal FCF (Year 5 FCF × (1+g)) | B28: =F22*(1+B15) -> 0
A29: Terminal Value (TV = Terminal FCF / (WACC - g)) | B29: =B28/(B14-B15) -> 0 | C29: Gordon Growth / perpetuity model
A30: PV of Terminal Value | B30: =B29*F23 -> 0 | C30: TV discounted at Year 5 discount factor
A31: Enterprise Value | B31: =B27+B30 -> 0
A32: Less: Net Debt (Debt - Cash) | B32: =B11 -> 0
A33: Equity Value | B33: =B31-B32 -> 0
A34: INTRINSIC VALUE PER SHARE | B34: =B33/B8 -> 0 | C34: Equity Value / Shares Outstanding
A35: Upside / Downside to Current Price | B35: =(B34-B7)/B7 -> 0 | C35: (IV - Current Price) / Current Price
A37: ENTRY PRICE (15% CAGR Target, 5-Year Horizon) | B37: Value
A38: Terminal Value per Share | B38: =B29/B8 -> 0 | C38: TV / Shares Outstanding
A39: Entry Price (15% CAGR to TV) | B39: =B38/(1.15^5) -> 0 | C39: TV per Share / (1.15)^5 — price to achieve 15% CAGR to terminal value
A40: Discount to Current Price | B40: =(B39-B7)/B7 -> 0
A42: SCENARIO SUMMARY | B42: Bear | C42: Base | D42: Bull | E42: Probability Weighted
A43: FCF Growth Y1-Y5 | B43: 9/7/5/4/3% | C43: 14/13/11/9/8% | D43: 19/17/15/13/11%
A44: WACC | B44: 11.5% | C44: 10.0% | D44: 9.0%
A45: Terminal Growth | B45: 2.5% | C45: 3.0% | D45: 3.5%
A46: Intrinsic Value | B46: $227.47 | C46: $365.49 | D46: $546.57 | E46: $376.26
A47: Upside / Downside | B47: -54.4% | C47: -26.8% | D47: 9.5% | E47: -24.6%
A48: Probability Weight | B48: 25% | C48: 50% | D48: 25% | E48: 100%
...

Sheet Sensitivity
A1: Sensitivity Analysis - Intrinsic Value per Share
A2: Base case FCF projections held constant. Only WACC and Terminal Growth Rate vary.
A3: Current price $499.02 shown as reference. Green = above current price, Red = below.
A5: WACC \ Terminal Growth | B5: 0.02 | C5: 0.025 | D5: 0.03 | E5: 0.035 | F5: 0.04
A6: 0.08 | B6: 445 | C6: 479 | D6: 520 | E6: 570 | F6: 632
A7: 0.09 | B7: 378 | C7: 402 | D7: 430 | E7: 463 | F7: 502
A8: 0.1 | B8: 328 | C8: 346 | D8: 366 | E8: 388 | F8: 415
A9: 0.11 | B9: 289 | C9: 302 | D9: 317 | E9: 334 | F9: 353
A10: 0.12 | B10: 258 | C10: 268 | D10: 280 | E10: 292 | F10: 307
A11: Color Legend: | B11: Blue = Base Case | C11: Green = Above current price ($499) | D11: Amber = Above base IV, below current | E11: Red = Below base IV ($365)
A14: FORMULA-BASED SENSITIVITY (updates with DCF Model inputs)
A15: Uses live FCF projections from DCF Model sheet. Adjust growth rates/WACC there and this table updates.
A17: WACC \ Terminal Growth | B17: 0.02 | C17: 0.025 | D17: 0.03 | E17: 0.035 | F17: 0.04
A18: 0.08 | B18: =(SUM('DCF Model'!B22/(1+0.08)^1,'DCF Model'!C22/(1+0.08)^2,'DCF Model'!D22/(1+0.08)^3,'DCF Model'!E22/(1+0.08)^4,'DCF Model'!F22/(1+0.08)^5)+'DCF Model'!F22*(1+0.02)/(0.08-0.02)/(1+0.08)^5-'DCF Model'!B11)/'DCF Model'!B8 -> 0 | C18: =(SUM('DCF Model'!B22/(1+0.08)^1,'DCF Model'!C22/(1+0.08)^2,'DCF Model'!D22/(1+0.08)^3,'DCF Model'!E22/(1+0.08)^4,'DCF Model'!F22/(1+0.08)^5)+'DCF Model'!F22*(1+0.025)/(0.08-0.025)/(1+0.08)^5-'DCF Model'!B11)/'DCF Model'!B8 -> 0 | D18: =(SUM('DCF Model'!B22/(1+0.08)^1,'DCF Model'!C22/(1+0.08)^2,'DCF Model'!D22/(1+0.08)^3,'DCF Model'!E22/(1+0.08)^4,'DCF Model'!F22/(1+0.08)^5)+'DCF Model'!F22*(1+0.03)/(0.08-0.03)/(1+0.08)^5-'DCF Model'!B11)/'DCF Model'!B8 -> 0 | E18: =(SUM('DCF Model'!B22/(1+0.08)^1,'DCF Model'!C22/(1+0.08)^2,'DCF Model'!D22/(1+0.08)^3,'DCF Model'!E22/(1+0.08)^4,'DCF Model'!F22/(1+0.08)^5)+'DCF Model'!F22*(1+0.035)/(0.08-0.035)/(1+0.08)^5-'DCF Model'!B11)/'DCF Model'!B8 -> 0 | F18: =(SUM('DCF Model'!B22/(1+0.08)^1,'DCF Model'!C22/(1+0.08)^2,'DCF Model'!D22/(1+0.08)^3,'DCF Model'!E22/(1+0.08)^4,'DCF Model'!F22/(1+0.08)^5)+'DCF Model'!F22*(1+0.04)/(0.08-0.04)/(1+0.08)^5-'DCF Model'!B11)/'DCF Model'!B8 -> 0
A19: 0.09 | B19: =(SUM('DCF Model'!B22/(1+0.09)^1,'DCF Model'!C22/(1+0.09)^2,'DCF Model'!D22/(1+0.09)^3,'DCF Model'!E22/(1+0.09)^4,'DCF Model'!F22/(1+0.09)^5)+'DCF Model'!F22*(1+0.02)/(0.09-0.02)/(1+0.09)^5-'DCF Model'!B11)/'DCF Model'!B8 -> 0 | C19: =(SUM('DCF Model'!B22/(1+0.09)^1,'DCF Model'!C22/(1+0.09)^2,'DCF Model'!D22/(1+0.09)^3,'DCF Model'!E22/(1+0.09)^4,'DCF Model'!F22/(1+0.09)^5)+'DCF Model'!F22*(1+0.025)/(0.09-0.025)/(1+0.09)^5-'DCF Model'!B11)/'DCF Model'!B8 -> 0 | D19: =(SUM('DCF Model'!B22/(1+0.09)^1,'DCF Model'!C22/(1+0.09)^2,'DCF Model'!D22/(1+0.09)^3,'DCF Model'!E22/(1+0.09)^4,'DCF Model'!F22/(1+0.09)^5)+'DCF Model'!F22*(1+0.03)/(0.09-0.03)/(1+0.09)^5-'DCF Model'!B11)/'DCF Model'!B8 -> 0 | E19: =(SUM('DCF Model'!B22/(1+0.09)^1,'DCF Model'!C22/(1+0.09)^2,'DCF Model'!D22/(1+0.09)^3,'DCF Model'!E22/(1+0.09)^4,'DCF Model'!F22/(1+0.09)^5)+'DCF Model'!F22*(1+0.035)/(0.09-0.035)/(1+0.09)^5-'DCF Model'!B11)/'DCF Model'!B8 -> 0 | F19: =(SUM('DCF Model'!B22/(1+0.09)^1,'DCF Model'!C22/(1+0.09)^2,'DCF Model'!D22/(1+0.09)^3,'DCF Model'!E22/(1+0.09)^4,'DCF Model'!F22/(1+0.09)^5)+'DCF Model'!F22*(1+0.04)/(0.09-0.04)/(1+0.09)^5-'DCF Model'!B11)/'DCF Model'!B8 -> 0
A20: 0.1 | B20: =(SUM('DCF Model'!B22/(1+0.1)^1,'DCF Model'!C22/(1+0.1)^2,'DCF Model'!D22/(1+0.1)^3,'DCF Model'!E22/(1+0.1)^4,'DCF Model'!F22/(1+0.1)^5)+'DCF Model'!F22*(1+0.02)/(0.1-0.02)/(1+0.1)^5-'DCF Model'!B11)/'DCF Model'!B8 -> 0 | C20: =(SUM('DCF Model'!B22/(1+0.1)^1,'DCF Model'!C22/(1+0.1)^2,'DCF Model'!D22/(1+0.1)^3,'DCF Model'!E22/(1+0.1)^4,'DCF Model'!F22/(1+0.1)^5)+'DCF Model'!F22*(1+0.025)/(0.1-0.025)/(1+0.1)^5-'DCF Model'!B11)/'DCF Model'!B8 -> 0 | D20: =(SUM('DCF Model'!B22/(1+0.1)^1,'DCF Model'!C22/(1+0.1)^2,'DCF Model'!D22/(1+0.1)^3,'DCF Model'!E22/(1+0.1)^4,'DCF Model'!F22/(1+0.1)^5)+'DCF Model'!F22*(1+0.03)/(0.1-0.03)/(1+0.1)^5-'DCF Model'!B11)/'DCF Model'!B8 -> 0 | E20: =(SUM('DCF Model'!B22/(1+0.1)^1,'DCF Model'!C22/(1+0.1)^2,'DCF Model'!D22/(1+0.1)^3,'DCF Model'!E22/(1+0.1)^4,'DCF Model'!F22/(1+0.1)^5)+'DCF Model'!F22*(1+0.035)/(0.1-0.035)/(1+0.1)^5-'DCF Model'!B11)/'DCF Model'!B8 -> 0 | F20: =(SUM('DCF Model'!B22/(1+0.1)^1,'DCF Model'!C22/(1+0.1)^2,'DCF Model'!D22/(1+0.1)^3,'DCF Model'!E22/(1+0.1)^4,'DCF Model'!F22/(1+0.1)^5)+'DCF Model'!F22*(1+0.04)/(0.1-0.04)/(1+0.1)^5-'DCF Model'!B11)/'DCF Model'!B8 -> 0
A21: 0.11 | B21: =(SUM('DCF Model'!B22/(1+0.11)^1,'DCF Model'!C22/(1+0.11)^2,'DCF Model'!D22/(1+0.11)^3,'DCF Model'!E22/(1+0.11)^4,'DCF Model'!F22/(1+0.11)^5)+'DCF Model'!F22*(1+0.02)/(0.11-0.02)/(1+0.11)^5-'DCF Model'!B11)/'DCF Model'!B8 -> 0 | C21: =(SUM('DCF Model'!B22/(1+0.11)^1,'DCF Model'!C22/(1+0.11)^2,'DCF Model'!D22/(1+0.11)^3,'DCF Model'!E22/(1+0.11)^4,'DCF Model'!F22/(1+0.11)^5)+'DCF Model'!F22*(1+0.025)/(0.11-0.025)/(1+0.11)^5-'DCF Model'!B11)/'DCF Model'!B8 -> 0 | D21: =(SUM('DCF Model'!B22/(1+0.11)^1,'DCF Model'!C22/(1+0.11)^2,'DCF Model'!D22/(1+0.11)^3,'DCF Model'!E22/(1+0.11)^4,'DCF Model'!F22/(1+0.11)^5)+'DCF Model'!F22*(1+0.03)/(0.11-0.03)/(1+0.11)^5-'DCF Model'!B11)/'DCF Model'!B8 -> 0 | E21: =(SUM('DCF Model'!B22/(1+0.11)^1,'DCF Model'!C22/(1+0.11)^2,'DCF Model'!D22/(1+0.11)^3,'DCF Model'!E22/(1+0.11)^4,'DCF Model'!F22/(1+0.11)^5)+'DCF Model'!F22*(1+0.035)/(0.11-0.035)/(1+0.11)^5-'DCF Model'!B11)/'DCF Model'!B8 -> 0 | F21: =(SUM('DCF Model'!B22/(1+0.11)^1,'DCF Model'!C22/(1+0.11)^2,'DCF Model'!D22/(1+0.11)^3,'DCF Model'!E22/(1+0.11)^4,'DCF Model'!F22/(1+0.11)^5)+'DCF Model'!F22*(1+0.04)/(0.11-0.04)/(1+0.11)^5-'DCF Model'!B11)/'DCF Model'!B8 -> 0
A22: 0.12 | B22: =(SUM('DCF Model'!B22/(1+0.12)^1,'DCF Model'!C22/(1+0.12)^2,'DCF Model'!D22/(1+0.12)^3,'DCF Model'!E22/(1+0.12)^4,'DCF Model'!F22/(1+0.12)^5)+'DCF Model'!F22*(1+0.02)/(0.12-0.02)/(1+0.12)^5-'DCF Model'!B11)/'DCF Model'!B8 -> 0 | C22: =(SUM('DCF Model'!B22/(1+0.12)^1,'DCF Model'!C22/(1+0.12)^2,'DCF Model'!D22/(1+0.12)^3,'DCF Model'!E22/(1+0.12)^4,'DCF Model'!F22/(1+0.12)^5)+'DCF Model'!F22*(1+0.025)/(0.12-0.025)/(1+0.12)^5-'DCF Model'!B11)/'DCF Model'!B8 -> 0 | D22: =(SUM('DCF Model'!B22/(1+0.12)^1,'DCF Model'!C22/(1+0.12)^2,'DCF Model'!D22/(1+0.12)^3,'DCF Model'!E22/(1+0.12)^4,'DCF Model'!F22/(1+0.12)^5)+'DCF Model'!F22*(1+0.03)/(0.12-0.03)/(1+0.12)^5-'DCF Model'!B11)/'DCF Model'!B8 -> 0 | E22: =(SUM('DCF Model'!B22/(1+0.12)^1,'DCF Model'!C22/(1+0.12)^2,'DCF Model'!D22/(1+0.12)^3,'DCF Model'!E22/(1+0.12)^4,'DCF Model'!F22/(1+0.12)^5)+'DCF Model'!F22*(1+0.035)/(0.12-0.035)/(1+0.12)^5-'DCF Model'!B11)/'DCF Model'!B8 -> 0 | F22: =(SUM('DCF Model'!B22/(1+0.12)^1,'DCF Model'!C22/(1+0.12)^2,'DCF Model'!D22/(1+0.12)^3,'DCF Model'!E22/(1+0.12)^4,'DCF Model'!F22/(1+0.12)^5)+'DCF Model'!F22*(1+0.04)/(0.12-0.04)/(1+0.12)^5-'DCF Model'!B11)/'DCF Model'!B8 -> 0

Sheet Scenarios
A1: Mastercard DCF - All Three Scenarios
A2: Current Price: $499.02 | Valuation Date: 2026-06-29
A4: SANITY CHECK TRIPPED: Base case ($365, 22x P/E) is below MA historical 30-38x range. Current price ($499, 30x P/E) is near bull-case fair value ($547, 33x P/E). Investors at current price are implicitly pricing in bull-case execution.
A6: Metric | B6: Bear Case | E6: Base Case | H6: Bull Case
A7: FCF Growth Y1-Y5 | B7: 9%/7%/5%/4%/3% | E7: 14%/13%/11%/9%/8% | H7: 19%/17%/15%/13%/11%
A8: FCF Margin (%) | B8: 47 | E8: 50.5 | H8: 52
A9: WACC | B9: 11.5% | E9: 10.0% | H9: 9.0%
A10: Terminal Growth | B10: 2.5% | E10: 3.0% | H10: 3.5%
A12: Year 1 FCF | B12: 17912 | E12: 18734 | H12: 19555
A13: Year 2 FCF | B13: 19166 | E13: 21169 | H13: 22879
A14: Year 3 FCF | B14: 20124 | E14: 23498 | H14: 26311
A15: Year 4 FCF | B15: 20929 | E15: 25613 | H15: 29731
A16: Year 5 FCF | B16: 21557 | E16: 27662 | H16: 33001
A18: Sum PV FCF | B18: 72050 | E18: 86848 | H18: 100022
A19: Terminal FCF | B19: 22096 | E19: 28492 | H19: 34156
A20: Terminal Value | B20: 245511 | E20: 407029 | H20: 621018
A21: PV Terminal | B21: 142470 | E21: 252724 | H21: 403600
A22: Enterprise Value | B22: 214520 | E22: 339572 | H22: 503622
A23: Net Debt | B23: 8434 | E23: 8434 | H23: 8434
A24: Equity Value | B24: 206086 | E24: 331138 | H24: 495188
A25: Intrinsic Value / Share | B25: $227.47 | E25: $365.49 | H25: $546.57
A26: Upside / Downside | B26: -54.4% | E26: -26.8% | H26: 9.5%
A28: Entry Price (15% CAGR) | B28: $134.72 | E28: $223.36 | H28: $340.79
A29: Discount to Current | B29: -73.0% | E29: -55.2% | H29: -31.7%

Sheet Historical
A1: Historical Growth Rates - Mastercard
A2: NOTE: Equity/Book Value CAGR is distorted by buybacks and is excluded from valuation anchoring.
A4: Metric | B4: 3-Year CAGR (FY2022-FY2025) | C4: 5-Year CAGR (FY2020-FY2025)
A5: Revenue | B5: 0.138 | C5: 0.165
A6: EPS (Diluted) | B6: 0.174 | C6: 0.21
A7: Free Cash Flow | B7: 0.176 | C7: 0.203
A8: Shareholders Equity * | B8: 0.071 | C8: 0.039
A9: * Equity CAGR is EXCLUDED from valuation anchoring
A10: Mastercard returned $14.5B to shareholders in FY2025 (buybacks $11.7B + dividends $2.8B),
A11: which mechanically suppresses reported book equity. FCF and EPS CAGRs are the valid anchors.
A13: SELECTED GROWTH RATE FOR DCF | B13: 0.176 | C13: fcf_3yr_cagr
A15: KEY FY2025 ACTUALS
A16: Revenue ($M) | B16: 32791
A17: Operating Income ($M) | B17: 18897
A18: Operating Margin | B18: 57.6%
A19: Net Income ($M) | B19: 14968
A20: Diluted EPS | B20: $16.52
A21: Diluted Shares (M) | B21: 906
A22: Operating Cash Flow ($M) | B22: 17648
A23: CapEx ($M) | B23: 1215
A24: Free Cash Flow ($M) | B24: 16433
A25: FCF Margin | B25: 50.1%
A26: Cash & Equivalents ($M) | B26: 10566
A27: Total Debt ($M) | B27: 19000
A28: Net Debt ($M) | B28: 8434
A29: Shareholders Equity ($M) | B29: 7737
A30: Share Buybacks ($M) | B30: 11727
A31: Dividends ($M) | B31: 2756
A32: Total Capital Returned ($M) | B32: 14483
