Workbook

Sheet Model_Info
A1: ADYEN.AS DCF Model
A3: Version | B3: v2 (28-Aug-2026), post-H1-2026
A4: Supersedes | B4: ADYEN.AS_DCF.json of 9-Aug-2026 (5-year horizon, weighted EUR769.52) and the pre-H1 model of record ADYEN_DCF_v1_preH1FY26.xlsx (weighted EUR1,118.31 SBC-corrected).
A5: Built by | B5: dcf-analyst agent (Claude Opus 5), at Stephen Williams request, 28-Aug-2026.
A7: DATA VINTAGE
A8: Price | B8: EUR1,079.60, Yahoo Finance ADYEN.AS regularMarketPrice, 2026-08-27T15:35:02Z regular close.
A9: EURUSD | B9: 1.1656 at 2026-08-27T22:23:03Z. ADR cross-check: 1079.60 x 1.1656 / 100 = $12.58 vs ADYEY traded $12.59.
A10: Balance sheet | B10: 30-Jun-2026, from the H1 2026 Shareholder Letter (13-Aug-2026).
A11: Share count | B11: 31.567m ordinary shares at 30-Jun-2026.
A12: Guidance | B12: H1 2026 letter, 13-Aug-2026: FY2026 net revenue growth 21-23% CC (incl. ~1pp acquisitions); EBITDA margin ~1pp below 2025 in 2026, above 55% by 2028; CapEx 7% of net revenue in 2026, ~5% thereafter.
A14: METHODOLOGY CHOICES
A15: Model | B15: Owner-FCF DCF, routed via dcf-methods/SKILL.md as an operating company (payments platform).
A16: Horizon | B16: 10 years. The year-5 owner-FCF margin is still climbing toward maturity, so a 5-year build would capitalize an immature margin. This is the correction that reconciles the 9-Aug DCF to the model of record.
A17: Margin basis | B17: Row 7 is the REPORTED (post-SBC) EBITDA margin. Adyen IFRS opex ALREADY contains SBC, so EBIT = EBITDA - D&A and SBC is NOT deducted again. NOTE this differs from the model of record, whose row 7 is PRE-SBC. The two are not interchangeable.
A18: SBC | B18: Carried as an explicit visible memo line (row 9/10) used only for the street-basis add-back. SBC is 1.85% of net revenue, genuinely small. Share count held FLAT (charge dilution once).
A19: Net cash | B19: EUR4,190m = own cash 4,600 (company-stated post-acquisition figure) less lease liabilities 409.4. Headline cash of EUR12,392.8m is mostly MERCHANT FLOAT and is not shareholders money.
A20: Merchant float | B20: Valued separately per scenario (bear 988.0 / base 1,910.5 / bull 2,761.3), inherited from the model of record. Not double-counted with the stripped Finance income.
A21: Interest | B21: Finance income (interest on Adyen own cash, TTM EUR272.1m) is STRIPPED. Net interest income (embedded finance, inside net revenue) is KEPT.
A22: Leases | B22: Treatment (A): lease liabilities deducted once in the net-debt bridge; lease principal NOT deducted from the flows.
A23: WACC | B23: 10.5% for ALL THREE scenarios, EUR-denominated. Risk is charged once, in the flows.
A24: Working capital | B24: A net USE of cash, SUBTRACTED, at 5% of the YoY net revenue increase.
A26: SCENARIO DRIVERS | B26: Driver paths are the agent judgment of 28-Aug-2026, anchored to the 13-Aug-2026 guidance and reconciled against Stephen model of record. Weights 15/50/35 restored to house default.
A28: REFRESH AFTER NEXT PRINT | B28: FY2026 results (Feb-2027): take rate (must hold near/above 16bps), H2 CapEx intensity vs the 7% full-year guide, EBITDA margin path toward 55% by 2028, Digital pillar growth, permanent CFO appointment, Talon.One/Orb purchase price allocation.
A30: THESE FIGURES GO STALE | B30: Price, EURUSD, net cash and the share count are point-in-time anchors. Re-verify every one of them before acting on this workbook.
A32: COLOUR LEGEND
A33: Blue bold | B33: Hardcoded input.
A34: Yellow fill | B34: Key driver / lever.
A35: Black | B35: Formula.
A36: Green | B36: Cross-sheet link.

Sheet Reconciliation
A1: Reconciliation vs prior version
A3: Prior published DCF 9-Aug-2026 (price EUR916.80 refreshed, 5-year horizon, weights 25/50/25)
A4: Bear | B4: 510.16
A5: Base | B5: 749.38
A6: Bull | B6: 1069.17
A7: Weighted | B7: 769.52
A9: Model of record ADYEN_DCF_v1_preH1FY26.xlsx (price EUR933.20, SBC-corrected)
A10: Weighted | B10: 1118.31
A11: Stephen H1-updated reference point | B11: 1144.87
A13: Bridge to new weighted IV (approximate attributions of a simultaneous re-solve)
A14: Prior published weighted IV (9-Aug-2026, 5-year horizon) | B14: 769.52
A15: Horizon 5yr -> 10yr: the year-5 owner-FCF margin was still climbing, so the prior model capitalized an immature margin in perpetuity. This is the single largest correction and reconciles the prior DCF to the model of record. | B15: 305.31
A16: Weights 25/50/25 -> 15/50/35 (house default restored; the H1 print resolved the uncertainty the extra bear weight insured against) | B16: 63
A17: Single 10.5% WACC replaces 9.0/10.0/11.5 by scenario (risk charged once, in the flows, not again in the discount rate) | B17: -38
A18: Base revenue rolled forward FY2025 (2,364.2) -> TTM to 30-Jun-2026 (2,573.6) | B18: 41
A19: FY2026 growth raised to 20% base / 22% bull / 18% bear on the 13-Aug guidance raise to 21-23% CC | B19: 22
A20: CapEx 7% in year 1 per guidance, reverting to 5% (bear: stays elevated at 5.5-6%) | B20: -14
A21: Margin path re-anchored to guidance on a reported post-SBC basis: ~1pp below FY2025 in 2026, >55% by 2028, maturing ~57% | B21: 29
A22: Net cash 4,735.2 -> 4,190.0 (own cash marked to the post-acquisition EUR4.6bn the company states, less EUR409.4m leases) | B22: -17
A23: Shares 31.5 -> 31.567m and other rounding | B23: -8.14
A24: New weighted IV | B24: 1152.69
A26: Live weighted IV (authoritative) | B26: =Valuation!B10
A28: Bridge figures are approximate; the live linked cells above and on Valuation are authoritative.

Sheet Actuals
A3: Metric | B3: FY2023 | C3: FY2024 | D3: FY2025 | E3: H1 2026 | F3: TTM Jun-26 | G3: Source
A4: Net revenue | B4: 1626.1 | C4: 1996.1 | D4: 2364.2 | E4: 1302.9 | F4: 2573.6 | G4: Metrics CSV NetRevenue; TTM = FY25 + H1-26 - H1-25
A5: EBITDA (reported, post-SBC) | B5: 743 | C5: 992.3 | D5: 1245.7 | E5: 641.5 | F5: 1343.5 | G5: Metrics CSV EBITDA
A6: EBITDA margin % | B6: 45.7 | C6: 49.7 | D6: 52.7 | E6: 49.2 | F6: 52.2 | G6: H1-26 is 50.0% excl. one-time transaction costs
A7: Net income | B7: 698.3 | C7: 925.2 | D7: 1062.5 | E7: 544.1 | F7: 1125.6 | G7: Metrics CSV NetIncome
A8: Reported FCF | B8: 639.5 | C8: 859.8 | D8: 1081.3 | E8: 553.4 | F8: 1160.2 | G8: Company definition: EBITDA less CapEx
A9: CapEx | B9: 69.7 | C9: 91.1 | D9: 116.8 | E9: 64.1 | F9: 133.6 | G9: Metrics CSV CapEx; H1-26 = 5% of net revenue
A10: SBC | B10: 38.6 | C10: 37.4 | D10: 43.5 | E10: 29.1 | G10: FY25 annual report; H1-26 equity-settled 29,596k
A11: Finance income (own-cash interest) | B11: 246 | C11: 349.9 | D11: 267.6 | E11: 143.2 | F11: 272.1 | G11: STRIPPED from owner FCF; note 9
A12: Owner FCF (ex finance income, ex SBC) | B12: 354.9 | C12: 472.5 | D12: 770.3 | F12: 888.1 | G12: reported_fcf - SBC - finance income
A13: Processed volume (EUR bn) | B13: 970.1 | C13: 1285.9 | D13: 1394.3 | E13: 803.8 | F13: 1549.1 | G13: Metrics CSV ProcessedVolume
A14: Take rate (bps) | B14: 16.8 | C14: 15.5 | D14: 17 | E14: 16.2 | G14: H1-26 down from 16.8; management calls it volume tiering
A15: Shareholders equity | B15: 3159.6 | C15: 4231.5 | D15: 5285.4 | E15: 5908.8 | G15: Metrics CSV
A16: FTE | B16: 4196 | C16: 4345 | D16: 4771 | E16: 5020 | G16: Metrics CSV
A18: BALANCE SHEET 30-Jun-2026 (EUR m)
A19: Cash and cash equivalents (headline) | B19: 12392.8 | G19: Line 687 - MOSTLY MERCHANT FLOAT, not shareholders money
A20: less Payables to merchants and FI | B20: -8097.4 | G20: Line 717
A21: plus Receivables from merchants and FI | B21: 602.8 | G21: Line 677
A22: Own cash | B22: 4898.2 | G22: Ties to letter line 524: our cash stood at EUR4.9 billion
A23: Own cash net of Talon.One and Orb | B23: 4600 | G23: Letter line 525: would have been approximately EUR4.6 billion
A24: less Lease liabilities | B24: -409.4 | G24: 338,307k non-current + 71,056k current
A25: NET CASH used in model | B25: 4190 | G25: Own cash post-acquisition less leases
A27: Diluted shares (m) | B27: 31.567 | G27: 30-Jun-2026; held FLAT in the model
A28: Buybacks / dividends | B28: 0 | G28: ZERO of both. 100% earnings retention; flat count is a convention, not cash-funded.
A30: FY2026 GUIDANCE (13-Aug-2026)
A31: Net revenue growth CC | B31: 21-23% incl. ~1pp from acquisitions
A32: EBITDA margin | B32: ~1pp below 2025 in 2026; above 55% by 2028
A33: CapEx | B33: 7% of net revenue in 2026, ~5% thereafter
A34: Medium-term growth | B34: ~20% annually (Nov-2025 Investor Day, maintained)

Sheet Assumptions
A1: Global assumptions
A3: WACC (all scenarios) | B3: 0.105 | C3: Single rate, EUR-denominated. Risk charged once, in the flows.
A4: D&A % of net revenue | B4: 0.06 | C4: H1-26 D&A 77.2 on 1302.9 annualizes to 5.9%.
A5: Working capital capture | B5: 0.05 | C5: Applied to the YoY revenue INCREASE and SUBTRACTED (net use of cash).
A6: Terminal cap multiple | B6: 20 | C6: TV capped at 20x terminal FCF.
A7: Net cash (EUR m) | B7: 4190 | C7: Own cash 4,600 less leases 409.4.
A8: Diluted shares (m) | B8: 31.567 | C8: 30-Jun-2026, held flat.
A9: Current price (EUR) | B9: 1079.6 | C9: 2026-08-27T15:35:02Z regular close.
A10: Base net revenue TTM (EUR m) | B10: 2573.6 | C10: TTM to 30-Jun-2026.
A11: EURUSD | B11: 1.1656 | C11: For the ADR cross-reference.
A12: Hurdle rate | B12: 0.15 | C12: For the entry-price calculation.
A14: Per-scenario
A15: Scenario | B15: Terminal growth | C15: Weight | D15: Merchant float (EUR m)
A16: bear | B16: 0.02 | C16: 0.15 | D16: 988
A17: base | B17: 0.03 | C17: 0.5 | D17: 1910.5
A18: bull | B18: 0.035 | C18: 0.35 | D18: 2761.3
A19: Weights check | C19: =SUM(C16:C18)
A21: Scenario narratives
A22: BEAR | C22: 'Expected volume tiering' turns out to be competitive repricing: the June-2026 large-merchant pricing revision is the first of several, take rate keeps sliding below 16bps, and net revenue growth decouples downward from volume growth. Digital -- still ~55% of revenue -- stalls again after one good half against Stripe and Braintree's enterprise in-store push. The 7% CapEx step-up proves permanent rather than a one-year pull-forward, because AI-era infrastructure competition genuinely raised capital intensity; CapEx stays 5.5-6%. Margin expansion stalls far short of the 55% 2028 target. First-ever M&A integration risk crystallizes at exactly the moment the CFO departs and a Co-CEO has only recently returned to a visible operating role.
A23: BASE | C23: Take-rate decline at 16.2bps is treated as MOSTLY benign volume tiering: net revenue keeps compounding with volume at a lower unit price, and unit economics hold, but a modest permanent drag is carried by letting growth decelerate slightly faster than volume through the decade. FY2026 growth of 20% reported sits just below the 21-23% CC guide (FX drag; the guide includes ~1pp of acquisition contribution). Margin follows management's own shape: ~1pp below FY2025 in 2026 on acquisition dilution and transaction costs, crossing the >55% 2028 target in year 3, then maturing near 57%. CapEx is 7% in year 1 exactly as guided, reverting to the historical 5% thereafter. Platforms (+37%) and Unified Commerce (+25%) keep mixing up against a slower Digital pillar.
A24: BULL | C24: Digital's H1 improvement (+13%/+15% CC off a record-low Q1 +9%) proves to be a genuine structural reacceleration rather than a bounce; Platforms and Unified Commerce continue compounding in the 25-40% range and lift group growth toward the ~20% medium-term ambition for longer. Take-rate stabilizes at/above 16bps, confirming volume tiering over competitive discounting. The Talon.One/Orb pivot cross-sells successfully into Unified Commerce and Platforms, widening wallet share (disclosed <20% in years 3-7 rising to >40% after year 12), and further disciplined capital deployment extends the roadmap. Margin pulls the 55%+ target forward and matures near 59.6% on operating leverage over a fixed single-platform stack.
A26: Weights rationale | C26: House default 15/50/35, restored deliberately from the 25/50/25 used on 9-Aug-2026 and matching the model of record. The 9-Aug run raised bear weight to 25% ahead of an uncertain H1 print; that print (13-Aug) landed clearly ahead -- 21% CC net revenue growth, 24% volume growth, guidance RAISED to 21-23% CC, Digital reaccelerating from its record-low Q1 -- which resolved the specific uncertainty the extra bear weight was insuring against. Bear stays at 15% and not lower because the take-rate question is genuinely unresolved (management's 'volume tiering' framing cannot yet be independently verified against competitive discounting) and because the balance sheet carries no solvency or refinancing risk at all -- the bear case is margin and growth compression, never distress. Bull at 35% because the bull path needs only the already-observed Platforms/Unified Commerce trajectory to persist, not several independent things to go right.
A27: WACC rationale | C27: 10.5% for ALL THREE scenarios, in the flows' own currency (EUR). Built from a ~2.6% 10-year Bund/EUR risk-free rate plus an equity risk premium of ~5.5% on a beta modestly above 1.0 for a high-multiple, long-duration growth asset, with a small increment for single-country listing and payments-competition dynamics. This matches the model of record's 10.5% exactly and is denominated consistently with Adyen's EUR reporting and EUR quote -- no USD-derived rate is used anywhere. Adyen carries no financial debt (only IFRS-16 leases), so WACC is effectively cost of equity. Crucially, the SAME rate is applied to bear, base and bull: risk is charged ONCE, in the probability-weighted flows. The 9-Aug-2026 DCF used 9.0/10.0/11.5% by scenario, which charged competition and governance risk twice (once in the bear driver paths, again in a higher bear discount rate) and materially widened the scenario spread for no economic reason. Governance risk (CFO departure, Co-CEO step-back) is expressed in the bear case's execution assumptions, NOT as a WACC premium.

Sheet DCF_Bear
A1: Adyen DCF - BEAR (EUR m)
A3: Year | B3: 2026 TTM A | C3: 2027E | D3: 2028E | E3: 2029E | F3: 2030E | G3: 2031E | H3: 2032E | I3: 2033E | J3: 2034E | K3: 2035E | L3: 2036E
A4: Index | B4: 0 | C4: 1 | D4: 2 | E4: 3 | F4: 4 | G4: 5 | H4: 6 | I4: 7 | J4: 8 | K4: 9 | L4: 10
A5: Revenue growth YoY | C5: 0.18 | D5: 0.11 | E5: 0.09 | F5: 0.075 | G5: 0.065 | H5: 0.055 | I5: 0.05 | J5: 0.045 | K5: 0.04 | L5: 0.035
A6: Net revenue | B6: =Assumptions!$B$10 | C6: =B6*(1+C5) | D6: =C6*(1+D5) | E6: =D6*(1+E5) | F6: =E6*(1+F5) | G6: =F6*(1+G5) | H6: =G6*(1+H5) | I6: =H6*(1+I5) | J6: =I6*(1+J5) | ... L6: =K6*(1+L5)
A7: EBITDA margin (REPORTED, post-SBC) | C7: 0.505 | D7: 0.51 | E7: 0.515 | F7: 0.518 | G7: 0.52 | H7: 0.522 | I7: 0.524 | J7: 0.525 | K7: 0.526 | L7: 0.527
A8: EBITDA (post-SBC) | C8: =C6*C7 | D8: =D6*D7 | E8: =E6*E7 | F8: =F6*F7 | G8: =G6*G7 | H8: =H6*H7 | I8: =I6*I7 | J8: =J6*J7 | ... L8: =L6*L7
A9: SBC % of revenue (memo) | C9: 0.019 | D9: 0.019 | E9: 0.0185 | F9: 0.0185 | G9: 0.018 | H9: 0.018 | I9: 0.0175 | J9: 0.0175 | K9: 0.017 | L9: 0.017
A10: SBC (memo, already in EBITDA) | C10: =-C6*C9 | D10: =-D6*D9 | E10: =-E6*E9 | F10: =-F6*F9 | G10: =-G6*G9 | H10: =-H6*H9 | I10: =-I6*I9 | J10: =-J6*J9 | ... L10: =-L6*L9
A11: D&A | C11: =-C6*Assumptions!$B$4 | D11: =-D6*Assumptions!$B$4 | E11: =-E6*Assumptions!$B$4 | F11: =-F6*Assumptions!$B$4 | G11: =-G6*Assumptions!$B$4 | H11: =-H6*Assumptions!$B$4 | I11: =-I6*Assumptions!$B$4 | J11: =-J6*Assumptions!$B$4 | ... L11: =-L6*Assumptions!$B$4
A12: EBIT | C12: =C8+C11 | D12: =D8+D11 | E12: =E8+E11 | F12: =F8+F11 | G12: =G8+G11 | H12: =H8+H11 | I12: =I8+I11 | J12: =J8+J11 | ... L12: =L8+L11
A13: Cash tax rate | C13: 0.25 | D13: 0.255 | E13: 0.258 | F13: 0.258 | G13: 0.258 | H13: 0.258 | I13: 0.258 | J13: 0.258 | K13: 0.258 | L13: 0.258
A14: NOPAT | C14: =C12*(1-C13) | D14: =D12*(1-D13) | E14: =E12*(1-E13) | F14: =F12*(1-F13) | G14: =G12*(1-G13) | H14: =H12*(1-H13) | I14: =I12*(1-I13) | J14: =J12*(1-J13) | ... L14: =L12*(1-L13)
A15: add back D&A | C15: =-C11 | D15: =-D11 | E15: =-E11 | F15: =-F11 | G15: =-G11 | H15: =-H11 | I15: =-I11 | J15: =-J11 | ... L15: =-L11
A16: CapEx % of revenue | C16: 0.07 | D16: 0.06 | E16: 0.058 | F16: 0.057 | G16: 0.056 | H16: 0.055 | I16: 0.055 | J16: 0.055 | K16: 0.055 | L16: 0.055
A17: less CapEx | C17: =-C6*C16 | D17: =-D6*D16 | E17: =-E6*E16 | F17: =-F6*F16 | G17: =-G6*G16 | H17: =-H6*H16 | I17: =-I6*I16 | J17: =-J6*J16 | ... L17: =-L6*L16
A18: less working capital (net use) | C18: =-Assumptions!$B$5*(C6-B6) | D18: =-Assumptions!$B$5*(D6-C6) | E18: =-Assumptions!$B$5*(E6-D6) | F18: =-Assumptions!$B$5*(F6-E6) | G18: =-Assumptions!$B$5*(G6-F6) | H18: =-Assumptions!$B$5*(H6-G6) | I18: =-Assumptions!$B$5*(I6-H6) | J18: =-Assumptions!$B$5*(J6-I6) | ... L18: =-Assumptions!$B$5*(L6-K6)
A19: Unlevered owner FCF | C19: =C14+C15+C17+C18 | D19: =D14+D15+D17+D18 | E19: =E14+E15+E17+E18 | F19: =F14+F15+F17+F18 | G19: =G14+G15+G17+G18 | H19: =H14+H15+H17+H18 | I19: =I14+I15+I17+I18 | J19: =J14+J15+J17+J18 | ... L19: =L14+L15+L17+L18
A20: Discount factor | C20: =1/(1+Assumptions!$B$3)^C4 | D20: =1/(1+Assumptions!$B$3)^D4 | E20: =1/(1+Assumptions!$B$3)^E4 | F20: =1/(1+Assumptions!$B$3)^F4 | G20: =1/(1+Assumptions!$B$3)^G4 | H20: =1/(1+Assumptions!$B$3)^H4 | I20: =1/(1+Assumptions!$B$3)^I4 | J20: =1/(1+Assumptions!$B$3)^J4 | ... L20: =1/(1+Assumptions!$B$3)^L4
A21: PV of FCF | C21: =C19*C20 | D21: =D19*D20 | E21: =E19*E20 | F21: =F19*F20 | G21: =G19*G20 | H21: =H19*H20 | I21: =I19*I20 | J21: =J19*J20 | ... L21: =L19*L20
A23: Memo: FCF before SBC (company style) | C23: =C19-C10 | D23: =D19-D10 | E23: =E19-E10 | F23: =F19-F10 | G23: =G19-G10 | H23: =H19-H10 | I23: =I19-I10 | J23: =J19-J10 | ... L23: =L19-L10
A24: Memo: owner FCF margin | C24: =C19/C6 | D24: =D19/D6 | E24: =E19/E6 | F24: =F19/F6 | G24: =G19/G6 | H24: =H19/H6 | I24: =I19/I6 | J24: =J19/J6 | ... L24: =L19/L6
A26: Sum PV of FCF | B26: =SUM(C21:L21)
A27: Terminal growth | B27: =Assumptions!$B$16
A28: Terminal FCF (year N+1) | B28: =L19*(1+B27)
A29: Gordon TV | B29: =B28/(Assumptions!$B$3-B27)
A30: Cap TV | B30: =Assumptions!$B$6*L19
A31: TV used | B31: =MAX(0,MIN(B29,B30))
A32: Implied exit multiple | B32: =B31/L19
A33: PV of TV | B33: =B31*L20
A34: Operating EV | B34: =B26+B33
A35: add merchant float | B35: =Assumptions!$D$16
A36: add net cash | B36: =Assumptions!$B$7
A37: Equity value | B37: =B34+B35+B36
A38: Diluted shares | B38: =Assumptions!$B$8
A39: VALUE PER SHARE (EUR) | B39: =B37/B38
A40: Upside vs price | B40: =B39/Assumptions!$B$9-1
A41: Street basis memo (SBC added back)
A42: PV of explicit-period SBC | B42: =SUMPRODUCT(-C10:L10,1/(1+Assumptions!$B$3)^C4:L4)
A43: PV of terminal SBC | B43: =(-L10*(1+B27)/(Assumptions!$B$3-B27))*L20
...

Sheet DCF_Base
A1: Adyen DCF - BASE (EUR m)
A3: Year | B3: 2026 TTM A | C3: 2027E | D3: 2028E | E3: 2029E | F3: 2030E | G3: 2031E | H3: 2032E | I3: 2033E | J3: 2034E | K3: 2035E | L3: 2036E
A4: Index | B4: 0 | C4: 1 | D4: 2 | E4: 3 | F4: 4 | G4: 5 | H4: 6 | I4: 7 | J4: 8 | K4: 9 | L4: 10
A5: Revenue growth YoY | C5: 0.2 | D5: 0.17 | E5: 0.155 | F5: 0.14 | G5: 0.125 | H5: 0.115 | I5: 0.105 | J5: 0.095 | K5: 0.085 | L5: 0.075
A6: Net revenue | B6: =Assumptions!$B$10 | C6: =B6*(1+C5) | D6: =C6*(1+D5) | E6: =D6*(1+E5) | F6: =E6*(1+F5) | G6: =F6*(1+G5) | H6: =G6*(1+H5) | I6: =H6*(1+I5) | J6: =I6*(1+J5) | ... L6: =K6*(1+L5)
A7: EBITDA margin (REPORTED, post-SBC) | C7: 0.517 | D7: 0.538 | E7: 0.552 | F7: 0.558 | G7: 0.563 | H7: 0.566 | I7: 0.568 | J7: 0.569 | K7: 0.57 | L7: 0.57
A8: EBITDA (post-SBC) | C8: =C6*C7 | D8: =D6*D7 | E8: =E6*E7 | F8: =F6*F7 | G8: =G6*G7 | H8: =H6*H7 | I8: =I6*I7 | J8: =J6*J7 | ... L8: =L6*L7
A9: SBC % of revenue (memo) | C9: 0.0185 | D9: 0.018 | E9: 0.0175 | F9: 0.017 | G9: 0.0165 | H9: 0.016 | I9: 0.0155 | J9: 0.015 | K9: 0.0145 | L9: 0.014
A10: SBC (memo, already in EBITDA) | C10: =-C6*C9 | D10: =-D6*D9 | E10: =-E6*E9 | F10: =-F6*F9 | G10: =-G6*G9 | H10: =-H6*H9 | I10: =-I6*I9 | J10: =-J6*J9 | ... L10: =-L6*L9
A11: D&A | C11: =-C6*Assumptions!$B$4 | D11: =-D6*Assumptions!$B$4 | E11: =-E6*Assumptions!$B$4 | F11: =-F6*Assumptions!$B$4 | G11: =-G6*Assumptions!$B$4 | H11: =-H6*Assumptions!$B$4 | I11: =-I6*Assumptions!$B$4 | J11: =-J6*Assumptions!$B$4 | ... L11: =-L6*Assumptions!$B$4
A12: EBIT | C12: =C8+C11 | D12: =D8+D11 | E12: =E8+E11 | F12: =F8+F11 | G12: =G8+G11 | H12: =H8+H11 | I12: =I8+I11 | J12: =J8+J11 | ... L12: =L8+L11
A13: Cash tax rate | C13: 0.245 | D13: 0.248 | E13: 0.25 | F13: 0.252 | G13: 0.255 | H13: 0.256 | I13: 0.258 | J13: 0.258 | K13: 0.258 | L13: 0.258
A14: NOPAT | C14: =C12*(1-C13) | D14: =D12*(1-D13) | E14: =E12*(1-E13) | F14: =F12*(1-F13) | G14: =G12*(1-G13) | H14: =H12*(1-H13) | I14: =I12*(1-I13) | J14: =J12*(1-J13) | ... L14: =L12*(1-L13)
A15: add back D&A | C15: =-C11 | D15: =-D11 | E15: =-E11 | F15: =-F11 | G15: =-G11 | H15: =-H11 | I15: =-I11 | J15: =-J11 | ... L15: =-L11
A16: CapEx % of revenue | C16: 0.07 | D16: 0.05 | E16: 0.05 | F16: 0.05 | G16: 0.05 | H16: 0.05 | I16: 0.05 | J16: 0.05 | K16: 0.05 | L16: 0.05
A17: less CapEx | C17: =-C6*C16 | D17: =-D6*D16 | E17: =-E6*E16 | F17: =-F6*F16 | G17: =-G6*G16 | H17: =-H6*H16 | I17: =-I6*I16 | J17: =-J6*J16 | ... L17: =-L6*L16
A18: less working capital (net use) | C18: =-Assumptions!$B$5*(C6-B6) | D18: =-Assumptions!$B$5*(D6-C6) | E18: =-Assumptions!$B$5*(E6-D6) | F18: =-Assumptions!$B$5*(F6-E6) | G18: =-Assumptions!$B$5*(G6-F6) | H18: =-Assumptions!$B$5*(H6-G6) | I18: =-Assumptions!$B$5*(I6-H6) | J18: =-Assumptions!$B$5*(J6-I6) | ... L18: =-Assumptions!$B$5*(L6-K6)
A19: Unlevered owner FCF | C19: =C14+C15+C17+C18 | D19: =D14+D15+D17+D18 | E19: =E14+E15+E17+E18 | F19: =F14+F15+F17+F18 | G19: =G14+G15+G17+G18 | H19: =H14+H15+H17+H18 | I19: =I14+I15+I17+I18 | J19: =J14+J15+J17+J18 | ... L19: =L14+L15+L17+L18
A20: Discount factor | C20: =1/(1+Assumptions!$B$3)^C4 | D20: =1/(1+Assumptions!$B$3)^D4 | E20: =1/(1+Assumptions!$B$3)^E4 | F20: =1/(1+Assumptions!$B$3)^F4 | G20: =1/(1+Assumptions!$B$3)^G4 | H20: =1/(1+Assumptions!$B$3)^H4 | I20: =1/(1+Assumptions!$B$3)^I4 | J20: =1/(1+Assumptions!$B$3)^J4 | ... L20: =1/(1+Assumptions!$B$3)^L4
A21: PV of FCF | C21: =C19*C20 | D21: =D19*D20 | E21: =E19*E20 | F21: =F19*F20 | G21: =G19*G20 | H21: =H19*H20 | I21: =I19*I20 | J21: =J19*J20 | ... L21: =L19*L20
A23: Memo: FCF before SBC (company style) | C23: =C19-C10 | D23: =D19-D10 | E23: =E19-E10 | F23: =F19-F10 | G23: =G19-G10 | H23: =H19-H10 | I23: =I19-I10 | J23: =J19-J10 | ... L23: =L19-L10
A24: Memo: owner FCF margin | C24: =C19/C6 | D24: =D19/D6 | E24: =E19/E6 | F24: =F19/F6 | G24: =G19/G6 | H24: =H19/H6 | I24: =I19/I6 | J24: =J19/J6 | ... L24: =L19/L6
A26: Sum PV of FCF | B26: =SUM(C21:L21)
A27: Terminal growth | B27: =Assumptions!$B$17
A28: Terminal FCF (year N+1) | B28: =L19*(1+B27)
A29: Gordon TV | B29: =B28/(Assumptions!$B$3-B27)
A30: Cap TV | B30: =Assumptions!$B$6*L19
A31: TV used | B31: =MAX(0,MIN(B29,B30))
A32: Implied exit multiple | B32: =B31/L19
A33: PV of TV | B33: =B31*L20
A34: Operating EV | B34: =B26+B33
A35: add merchant float | B35: =Assumptions!$D$17
A36: add net cash | B36: =Assumptions!$B$7
A37: Equity value | B37: =B34+B35+B36
A38: Diluted shares | B38: =Assumptions!$B$8
A39: VALUE PER SHARE (EUR) | B39: =B37/B38
A40: Upside vs price | B40: =B39/Assumptions!$B$9-1
A41: Street basis memo (SBC added back)
A42: PV of explicit-period SBC | B42: =SUMPRODUCT(-C10:L10,1/(1+Assumptions!$B$3)^C4:L4)
A43: PV of terminal SBC | B43: =(-L10*(1+B27)/(Assumptions!$B$3-B27))*L20
...

Sheet DCF_Bull
A1: Adyen DCF - BULL (EUR m)
A3: Year | B3: 2026 TTM A | C3: 2027E | D3: 2028E | E3: 2029E | F3: 2030E | G3: 2031E | H3: 2032E | I3: 2033E | J3: 2034E | K3: 2035E | L3: 2036E
A4: Index | B4: 0 | C4: 1 | D4: 2 | E4: 3 | F4: 4 | G4: 5 | H4: 6 | I4: 7 | J4: 8 | K4: 9 | L4: 10
A5: Revenue growth YoY | C5: 0.22 | D5: 0.205 | E5: 0.19 | F5: 0.175 | G5: 0.16 | H5: 0.15 | I5: 0.135 | J5: 0.125 | K5: 0.115 | L5: 0.105
A6: Net revenue | B6: =Assumptions!$B$10 | C6: =B6*(1+C5) | D6: =C6*(1+D5) | E6: =D6*(1+E5) | F6: =E6*(1+F5) | G6: =F6*(1+G5) | H6: =G6*(1+H5) | I6: =H6*(1+I5) | J6: =I6*(1+J5) | ... L6: =K6*(1+L5)
A7: EBITDA margin (REPORTED, post-SBC) | C7: 0.522 | D7: 0.548 | E7: 0.567 | F7: 0.578 | G7: 0.585 | H7: 0.59 | I7: 0.593 | J7: 0.595 | K7: 0.596 | L7: 0.596
A8: EBITDA (post-SBC) | C8: =C6*C7 | D8: =D6*D7 | E8: =E6*E7 | F8: =F6*F7 | G8: =G6*G7 | H8: =H6*H7 | I8: =I6*I7 | J8: =J6*J7 | ... L8: =L6*L7
A9: SBC % of revenue (memo) | C9: 0.018 | D9: 0.017 | E9: 0.016 | F9: 0.015 | G9: 0.0145 | H9: 0.014 | I9: 0.0135 | J9: 0.013 | K9: 0.0125 | L9: 0.012
A10: SBC (memo, already in EBITDA) | C10: =-C6*C9 | D10: =-D6*D9 | E10: =-E6*E9 | F10: =-F6*F9 | G10: =-G6*G9 | H10: =-H6*H9 | I10: =-I6*I9 | J10: =-J6*J9 | ... L10: =-L6*L9
A11: D&A | C11: =-C6*Assumptions!$B$4 | D11: =-D6*Assumptions!$B$4 | E11: =-E6*Assumptions!$B$4 | F11: =-F6*Assumptions!$B$4 | G11: =-G6*Assumptions!$B$4 | H11: =-H6*Assumptions!$B$4 | I11: =-I6*Assumptions!$B$4 | J11: =-J6*Assumptions!$B$4 | ... L11: =-L6*Assumptions!$B$4
A12: EBIT | C12: =C8+C11 | D12: =D8+D11 | E12: =E8+E11 | F12: =F8+F11 | G12: =G8+G11 | H12: =H8+H11 | I12: =I8+I11 | J12: =J8+J11 | ... L12: =L8+L11
A13: Cash tax rate | C13: 0.24 | D13: 0.243 | E13: 0.245 | F13: 0.248 | G13: 0.25 | H13: 0.252 | I13: 0.255 | J13: 0.258 | K13: 0.258 | L13: 0.258
A14: NOPAT | C14: =C12*(1-C13) | D14: =D12*(1-D13) | E14: =E12*(1-E13) | F14: =F12*(1-F13) | G14: =G12*(1-G13) | H14: =H12*(1-H13) | I14: =I12*(1-I13) | J14: =J12*(1-J13) | ... L14: =L12*(1-L13)
A15: add back D&A | C15: =-C11 | D15: =-D11 | E15: =-E11 | F15: =-F11 | G15: =-G11 | H15: =-H11 | I15: =-I11 | J15: =-J11 | ... L15: =-L11
A16: CapEx % of revenue | C16: 0.07 | D16: 0.05 | E16: 0.05 | F16: 0.05 | G16: 0.049 | H16: 0.048 | I16: 0.048 | J16: 0.048 | K16: 0.048 | L16: 0.048
A17: less CapEx | C17: =-C6*C16 | D17: =-D6*D16 | E17: =-E6*E16 | F17: =-F6*F16 | G17: =-G6*G16 | H17: =-H6*H16 | I17: =-I6*I16 | J17: =-J6*J16 | ... L17: =-L6*L16
A18: less working capital (net use) | C18: =-Assumptions!$B$5*(C6-B6) | D18: =-Assumptions!$B$5*(D6-C6) | E18: =-Assumptions!$B$5*(E6-D6) | F18: =-Assumptions!$B$5*(F6-E6) | G18: =-Assumptions!$B$5*(G6-F6) | H18: =-Assumptions!$B$5*(H6-G6) | I18: =-Assumptions!$B$5*(I6-H6) | J18: =-Assumptions!$B$5*(J6-I6) | ... L18: =-Assumptions!$B$5*(L6-K6)
A19: Unlevered owner FCF | C19: =C14+C15+C17+C18 | D19: =D14+D15+D17+D18 | E19: =E14+E15+E17+E18 | F19: =F14+F15+F17+F18 | G19: =G14+G15+G17+G18 | H19: =H14+H15+H17+H18 | I19: =I14+I15+I17+I18 | J19: =J14+J15+J17+J18 | ... L19: =L14+L15+L17+L18
A20: Discount factor | C20: =1/(1+Assumptions!$B$3)^C4 | D20: =1/(1+Assumptions!$B$3)^D4 | E20: =1/(1+Assumptions!$B$3)^E4 | F20: =1/(1+Assumptions!$B$3)^F4 | G20: =1/(1+Assumptions!$B$3)^G4 | H20: =1/(1+Assumptions!$B$3)^H4 | I20: =1/(1+Assumptions!$B$3)^I4 | J20: =1/(1+Assumptions!$B$3)^J4 | ... L20: =1/(1+Assumptions!$B$3)^L4
A21: PV of FCF | C21: =C19*C20 | D21: =D19*D20 | E21: =E19*E20 | F21: =F19*F20 | G21: =G19*G20 | H21: =H19*H20 | I21: =I19*I20 | J21: =J19*J20 | ... L21: =L19*L20
A23: Memo: FCF before SBC (company style) | C23: =C19-C10 | D23: =D19-D10 | E23: =E19-E10 | F23: =F19-F10 | G23: =G19-G10 | H23: =H19-H10 | I23: =I19-I10 | J23: =J19-J10 | ... L23: =L19-L10
A24: Memo: owner FCF margin | C24: =C19/C6 | D24: =D19/D6 | E24: =E19/E6 | F24: =F19/F6 | G24: =G19/G6 | H24: =H19/H6 | I24: =I19/I6 | J24: =J19/J6 | ... L24: =L19/L6
A26: Sum PV of FCF | B26: =SUM(C21:L21)
A27: Terminal growth | B27: =Assumptions!$B$18
A28: Terminal FCF (year N+1) | B28: =L19*(1+B27)
A29: Gordon TV | B29: =B28/(Assumptions!$B$3-B27)
A30: Cap TV | B30: =Assumptions!$B$6*L19
A31: TV used | B31: =MAX(0,MIN(B29,B30))
A32: Implied exit multiple | B32: =B31/L19
A33: PV of TV | B33: =B31*L20
A34: Operating EV | B34: =B26+B33
A35: add merchant float | B35: =Assumptions!$D$18
A36: add net cash | B36: =Assumptions!$B$7
A37: Equity value | B37: =B34+B35+B36
A38: Diluted shares | B38: =Assumptions!$B$8
A39: VALUE PER SHARE (EUR) | B39: =B37/B38
A40: Upside vs price | B40: =B39/Assumptions!$B$9-1
A41: Street basis memo (SBC added back)
A42: PV of explicit-period SBC | B42: =SUMPRODUCT(-C10:L10,1/(1+Assumptions!$B$3)^C4:L4)
A43: PV of terminal SBC | B43: =(-L10*(1+B27)/(Assumptions!$B$3-B27))*L20
...

Sheet FCF_Quality
A1: Reported FCF reconciled to owner FCF
B3: FY2020 | C3: FY2021 | D3: FY2022 | E3: FY2023 | F3: FY2024 | G3: FY2025 | H3: TTM Jun-26
A4: Net revenue | B4: 684.2 | C4: 1001.5 | D4: 1330.2 | E4: 1626.1 | F4: 1996.1 | G4: 2364.2 | H4: 2573.6
A5: Free cash flow (company definition) | B5: 346.3 | C5: 544.6 | D5: 607.1 | E5: 639.5 | F5: 859.8 | G5: 1081.3 | H5: 1160.2
A6: less SBC incl. equity-award taxes | B6: -10.085 | C6: -12.008 | D6: -10.499 | E6: -38.609 | F6: -37.368 | G6: -43.457 | H6: -54
A7: less Finance income (own-cash interest) | B7: -6.9 | C7: -4.5 | D7: -29.3 | E7: -246 | F7: -349.9 | G7: -267.55 | H7: -272.1
A8: Owner FCF | B8: =B5+B6+B7 | C8: =C5+C6+C7 | D8: =D5+D6+D7 | E8: =E5+E6+E7 | F8: =F5+F6+F7 | G8: =G5+G6+G7 | H8: =H5+H6+H7
A9: Reported FCF margin | B9: =B5/B4 | C9: =C5/C4 | D9: =D5/D4 | E9: =E5/E4 | F9: =F5/F4 | G9: =G5/G4 | H9: =H5/H4
A10: Owner FCF margin | B10: =B8/B4 | C10: =C8/C4 | D10: =D8/D4 | E10: =E8/E4 | F10: =F8/F4 | G10: =G8/G4 | H10: =H8/H4
A12: Memo: Finance income as % of reported FCF | B12: =-B7/B5 | C12: =-C7/C5 | D12: =-D7/D5 | E12: =-E7/E5 | F12: =-F7/F5 | G12: =-G7/G5 | H12: =-H7/H5
A14: Note | B14: Adyen has no deferred-revenue tailwind; working capital is a net USE of cash as receivables from merchants grow. Finance income rose from 2% of reported FCF in FY2020-22 to 25-41% in FY2023-25 as policy rates rose - a rate-cycle windfall on the cash pile, not operating performance, and the reason owner-FCF CAGR (10.7% 3yr) is far below reported (21.2%).
A16: Memo: cash tax rate FY2025 | B16: 0.238
A17: Not flagged as abnormal; close to the 25.8% Dutch statutory rate and ramped there in the model.

Sheet Valuation
A1: Valuation summary
A3: Scenario | B3: Value/share | C3: Upside | D3: Weight | E3: Street value | F3: Exit mult | G3: TV % of EV
A4: bear | B4: =DCF_Bear!B39 | C4: =B4/Assumptions!$B$9-1 | D4: =Assumptions!C16 | E4: =DCF_Bear!B44 | F4: =DCF_Bear!B32 | G4: =DCF_Bear!B33/DCF_Bear!B34
A5: base | B5: =DCF_Base!B39 | C5: =B5/Assumptions!$B$9-1 | D5: =Assumptions!C17 | E5: =DCF_Base!B44 | F5: =DCF_Base!B32 | G5: =DCF_Base!B33/DCF_Base!B34
A6: bull | B6: =DCF_Bull!B39 | C6: =B6/Assumptions!$B$9-1 | D6: =Assumptions!C18 | E6: =DCF_Bull!B44 | F6: =DCF_Bull!B32 | G6: =DCF_Bull!B33/DCF_Bull!B34
A8: Current price | B8: =Assumptions!B9
A10: PROBABILITY-WEIGHTED IV | B10: =SUMPRODUCT(B4:B6,D4:D6)
A11: Weighted upside | B11: =B10/B8-1
A12: Margin of safety | B12: =1-B8/B10
A13: Street weighted IV | B13: =SUMPRODUCT(E4:E6,D4:D6)
A14: Band position | B14: n/a - see note
A15: Band note | B15: House/street spread is only ~3% because SBC is 1.85% of revenue. The price sits BELOW both bounds, so band position is degenerate and is reported as null.
A17: Weighted IV per ADR (USD) | B17: =B10*Assumptions!B11/100
A18: ADYEY 1 ADR = 1/100 ordinary share.
A20: Required return table (base case)
A21: Required return | B21: Value/share
A22: 0.09 | B22: =(SUMPRODUCT(DCF_Base!C19:L19,1/(1+A22)^DCF_Base!C4:L4)+DCF_Base!B31/(1+A22)^10+Assumptions!$D$17+Assumptions!$B$7)/Assumptions!$B$8
A23: 0.1 | B23: =(SUMPRODUCT(DCF_Base!C19:L19,1/(1+A23)^DCF_Base!C4:L4)+DCF_Base!B31/(1+A23)^10+Assumptions!$D$17+Assumptions!$B$7)/Assumptions!$B$8
A24: 0.105 | B24: =(SUMPRODUCT(DCF_Base!C19:L19,1/(1+A24)^DCF_Base!C4:L4)+DCF_Base!B31/(1+A24)^10+Assumptions!$D$17+Assumptions!$B$7)/Assumptions!$B$8
A25: 0.11 | B25: =(SUMPRODUCT(DCF_Base!C19:L19,1/(1+A25)^DCF_Base!C4:L4)+DCF_Base!B31/(1+A25)^10+Assumptions!$D$17+Assumptions!$B$7)/Assumptions!$B$8
A26: 0.12 | B26: =(SUMPRODUCT(DCF_Base!C19:L19,1/(1+A26)^DCF_Base!C4:L4)+DCF_Base!B31/(1+A26)^10+Assumptions!$D$17+Assumptions!$B$7)/Assumptions!$B$8
A27: 0.15 | B27: =(SUMPRODUCT(DCF_Base!C19:L19,1/(1+A27)^DCF_Base!C4:L4)+DCF_Base!B31/(1+A27)^10+Assumptions!$D$17+Assumptions!$B$7)/Assumptions!$B$8
A28: At the current price the base case implies roughly a 10.6% expected return.
A30: 15% hurdle entry price
A31: Scenario | B31: Entry price | C31: vs price | D31: Weight
A32: bear | B32: =(SUMPRODUCT(DCF_Bear!C19:L19,1/(1+Assumptions!$B$12)^DCF_Bear!C4:L4)+DCF_Bear!B31/(1+Assumptions!$B$12)^10+Assumptions!$D$16+Assumptions!$B$7)/Assumptions!$B$8 | C32: =B32/Assumptions!$B$9-1 | D32: =Assumptions!C16
A33: base | B33: =(SUMPRODUCT(DCF_Base!C19:L19,1/(1+Assumptions!$B$12)^DCF_Base!C4:L4)+DCF_Base!B31/(1+Assumptions!$B$12)^10+Assumptions!$D$17+Assumptions!$B$7)/Assumptions!$B$8 | C33: =B33/Assumptions!$B$9-1 | D33: =Assumptions!C17
A34: bull | B34: =(SUMPRODUCT(DCF_Bull!C19:L19,1/(1+Assumptions!$B$12)^DCF_Bull!C4:L4)+DCF_Bull!B31/(1+Assumptions!$B$12)^10+Assumptions!$D$18+Assumptions!$B$7)/Assumptions!$B$8 | C34: =B34/Assumptions!$B$9-1 | D34: =Assumptions!C18
A35: WEIGHTED ENTRY PRICE | B35: =SUMPRODUCT(B32:B34,D32:D34)
A36: vs current price | B36: =B35/Assumptions!B9-1
A37: A 15% IRR is not available at the current price on these drivers.
A39: Sensitivity: WACC x terminal growth (base case)
A40: WACC \ g | B40: 0.02 | C40: 0.025 | D40: 0.03 | E40: 0.035 | F40: 0.04
A41: 0.085 | B41: =IF($A41>B$40,(SUMPRODUCT(DCF_Base!C19:L19,1/(1+$A41)^DCF_Base!C4:L4)+MAX(0,MIN(DCF_Base!L19*(1+B$40)/($A41-B$40),Assumptions!$B$6*DCF_Base!L19))/(1+$A41)^10+Assumptions!$D$17+Assumptions!$B$7)/Assumptions!$B$8,"n/a") | C41: =IF($A41>C$40,(SUMPRODUCT(DCF_Base!C19:L19,1/(1+$A41)^DCF_Base!C4:L4)+MAX(0,MIN(DCF_Base!L19*(1+C$40)/($A41-C$40),Assumptions!$B$6*DCF_Base!L19))/(1+$A41)^10+Assumptions!$D$17+Assumptions!$B$7)/Assumptions!$B$8,"n/a") | D41: =IF($A41>D$40,(SUMPRODUCT(DCF_Base!C19:L19,1/(1+$A41)^DCF_Base!C4:L4)+MAX(0,MIN(DCF_Base!L19*(1+D$40)/($A41-D$40),Assumptions!$B$6*DCF_Base!L19))/(1+$A41)^10+Assumptions!$D$17+Assumptions!$B$7)/Assumptions!$B$8,"n/a") | E41: =IF($A41>E$40,(SUMPRODUCT(DCF_Base!C19:L19,1/(1+$A41)^DCF_Base!C4:L4)+MAX(0,MIN(DCF_Base!L19*(1+E$40)/($A41-E$40),Assumptions!$B$6*DCF_Base!L19))/(1+$A41)^10+Assumptions!$D$17+Assumptions!$B$7)/Assumptions!$B$8,"n/a") | F41: =IF($A41>F$40,(SUMPRODUCT(DCF_Base!C19:L19,1/(1+$A41)^DCF_Base!C4:L4)+MAX(0,MIN(DCF_Base!L19*(1+F$40)/($A41-F$40),Assumptions!$B$6*DCF_Base!L19))/(1+$A41)^10+Assumptions!$D$17+Assumptions!$B$7)/Assumptions!$B$8,"n/a")
A42: 0.095 | B42: =IF($A42>B$40,(SUMPRODUCT(DCF_Base!C19:L19,1/(1+$A42)^DCF_Base!C4:L4)+MAX(0,MIN(DCF_Base!L19*(1+B$40)/($A42-B$40),Assumptions!$B$6*DCF_Base!L19))/(1+$A42)^10+Assumptions!$D$17+Assumptions!$B$7)/Assumptions!$B$8,"n/a") | C42: =IF($A42>C$40,(SUMPRODUCT(DCF_Base!C19:L19,1/(1+$A42)^DCF_Base!C4:L4)+MAX(0,MIN(DCF_Base!L19*(1+C$40)/($A42-C$40),Assumptions!$B$6*DCF_Base!L19))/(1+$A42)^10+Assumptions!$D$17+Assumptions!$B$7)/Assumptions!$B$8,"n/a") | D42: =IF($A42>D$40,(SUMPRODUCT(DCF_Base!C19:L19,1/(1+$A42)^DCF_Base!C4:L4)+MAX(0,MIN(DCF_Base!L19*(1+D$40)/($A42-D$40),Assumptions!$B$6*DCF_Base!L19))/(1+$A42)^10+Assumptions!$D$17+Assumptions!$B$7)/Assumptions!$B$8,"n/a") | E42: =IF($A42>E$40,(SUMPRODUCT(DCF_Base!C19:L19,1/(1+$A42)^DCF_Base!C4:L4)+MAX(0,MIN(DCF_Base!L19*(1+E$40)/($A42-E$40),Assumptions!$B$6*DCF_Base!L19))/(1+$A42)^10+Assumptions!$D$17+Assumptions!$B$7)/Assumptions!$B$8,"n/a") | F42: =IF($A42>F$40,(SUMPRODUCT(DCF_Base!C19:L19,1/(1+$A42)^DCF_Base!C4:L4)+MAX(0,MIN(DCF_Base!L19*(1+F$40)/($A42-F$40),Assumptions!$B$6*DCF_Base!L19))/(1+$A42)^10+Assumptions!$D$17+Assumptions!$B$7)/Assumptions!$B$8,"n/a")
A43: 0.105 | B43: =IF($A43>B$40,(SUMPRODUCT(DCF_Base!C19:L19,1/(1+$A43)^DCF_Base!C4:L4)+MAX(0,MIN(DCF_Base!L19*(1+B$40)/($A43-B$40),Assumptions!$B$6*DCF_Base!L19))/(1+$A43)^10+Assumptions!$D$17+Assumptions!$B$7)/Assumptions!$B$8,"n/a") | C43: =IF($A43>C$40,(SUMPRODUCT(DCF_Base!C19:L19,1/(1+$A43)^DCF_Base!C4:L4)+MAX(0,MIN(DCF_Base!L19*(1+C$40)/($A43-C$40),Assumptions!$B$6*DCF_Base!L19))/(1+$A43)^10+Assumptions!$D$17+Assumptions!$B$7)/Assumptions!$B$8,"n/a") | D43: =IF($A43>D$40,(SUMPRODUCT(DCF_Base!C19:L19,1/(1+$A43)^DCF_Base!C4:L4)+MAX(0,MIN(DCF_Base!L19*(1+D$40)/($A43-D$40),Assumptions!$B$6*DCF_Base!L19))/(1+$A43)^10+Assumptions!$D$17+Assumptions!$B$7)/Assumptions!$B$8,"n/a") | E43: =IF($A43>E$40,(SUMPRODUCT(DCF_Base!C19:L19,1/(1+$A43)^DCF_Base!C4:L4)+MAX(0,MIN(DCF_Base!L19*(1+E$40)/($A43-E$40),Assumptions!$B$6*DCF_Base!L19))/(1+$A43)^10+Assumptions!$D$17+Assumptions!$B$7)/Assumptions!$B$8,"n/a") | F43: =IF($A43>F$40,(SUMPRODUCT(DCF_Base!C19:L19,1/(1+$A43)^DCF_Base!C4:L4)+MAX(0,MIN(DCF_Base!L19*(1+F$40)/($A43-F$40),Assumptions!$B$6*DCF_Base!L19))/(1+$A43)^10+Assumptions!$D$17+Assumptions!$B$7)/Assumptions!$B$8,"n/a")
A44: 0.115 | B44: =IF($A44>B$40,(SUMPRODUCT(DCF_Base!C19:L19,1/(1+$A44)^DCF_Base!C4:L4)+MAX(0,MIN(DCF_Base!L19*(1+B$40)/($A44-B$40),Assumptions!$B$6*DCF_Base!L19))/(1+$A44)^10+Assumptions!$D$17+Assumptions!$B$7)/Assumptions!$B$8,"n/a") | C44: =IF($A44>C$40,(SUMPRODUCT(DCF_Base!C19:L19,1/(1+$A44)^DCF_Base!C4:L4)+MAX(0,MIN(DCF_Base!L19*(1+C$40)/($A44-C$40),Assumptions!$B$6*DCF_Base!L19))/(1+$A44)^10+Assumptions!$D$17+Assumptions!$B$7)/Assumptions!$B$8,"n/a") | D44: =IF($A44>D$40,(SUMPRODUCT(DCF_Base!C19:L19,1/(1+$A44)^DCF_Base!C4:L4)+MAX(0,MIN(DCF_Base!L19*(1+D$40)/($A44-D$40),Assumptions!$B$6*DCF_Base!L19))/(1+$A44)^10+Assumptions!$D$17+Assumptions!$B$7)/Assumptions!$B$8,"n/a") | E44: =IF($A44>E$40,(SUMPRODUCT(DCF_Base!C19:L19,1/(1+$A44)^DCF_Base!C4:L4)+MAX(0,MIN(DCF_Base!L19*(1+E$40)/($A44-E$40),Assumptions!$B$6*DCF_Base!L19))/(1+$A44)^10+Assumptions!$D$17+Assumptions!$B$7)/Assumptions!$B$8,"n/a") | F44: =IF($A44>F$40,(SUMPRODUCT(DCF_Base!C19:L19,1/(1+$A44)^DCF_Base!C4:L4)+MAX(0,MIN(DCF_Base!L19*(1+F$40)/($A44-F$40),Assumptions!$B$6*DCF_Base!L19))/(1+$A44)^10+Assumptions!$D$17+Assumptions!$B$7)/Assumptions!$B$8,"n/a")
A45: 0.125 | B45: =IF($A45>B$40,(SUMPRODUCT(DCF_Base!C19:L19,1/(1+$A45)^DCF_Base!C4:L4)+MAX(0,MIN(DCF_Base!L19*(1+B$40)/($A45-B$40),Assumptions!$B$6*DCF_Base!L19))/(1+$A45)^10+Assumptions!$D$17+Assumptions!$B$7)/Assumptions!$B$8,"n/a") | C45: =IF($A45>C$40,(SUMPRODUCT(DCF_Base!C19:L19,1/(1+$A45)^DCF_Base!C4:L4)+MAX(0,MIN(DCF_Base!L19*(1+C$40)/($A45-C$40),Assumptions!$B$6*DCF_Base!L19))/(1+$A45)^10+Assumptions!$D$17+Assumptions!$B$7)/Assumptions!$B$8,"n/a") | D45: =IF($A45>D$40,(SUMPRODUCT(DCF_Base!C19:L19,1/(1+$A45)^DCF_Base!C4:L4)+MAX(0,MIN(DCF_Base!L19*(1+D$40)/($A45-D$40),Assumptions!$B$6*DCF_Base!L19))/(1+$A45)^10+Assumptions!$D$17+Assumptions!$B$7)/Assumptions!$B$8,"n/a") | E45: =IF($A45>E$40,(SUMPRODUCT(DCF_Base!C19:L19,1/(1+$A45)^DCF_Base!C4:L4)+MAX(0,MIN(DCF_Base!L19*(1+E$40)/($A45-E$40),Assumptions!$B$6*DCF_Base!L19))/(1+$A45)^10+Assumptions!$D$17+Assumptions!$B$7)/Assumptions!$B$8,"n/a") | F45: =IF($A45>F$40,(SUMPRODUCT(DCF_Base!C19:L19,1/(1+$A45)^DCF_Base!C4:L4)+MAX(0,MIN(DCF_Base!L19*(1+F$40)/($A45-F$40),Assumptions!$B$6*DCF_Base!L19))/(1+$A45)^10+Assumptions!$D$17+Assumptions!$B$7)/Assumptions!$B$8,"n/a")
A47: House pair WACC 10.5% / g 3.0% highlighted. Top-right cells are bound by the 20x terminal cap.
