Workbook

Sheet DCF Model
A1: MELI — MercadoLibre DCF Valuation Model
A2: Valuation Date: 2026-06-30 | Current Price: $1,683.13 | Units: USD Millions (per-share in USD)
A3: Gray cells are INPUTS — change them to instantly recalculate intrinsic value, upside, and entry price.
A5: KEY INPUTS
A6: Current Stock Price ($) | B6: 1683.13
A7: Shares Outstanding (M) | B7: 50.697
A8: Cash & Equivalents (M) | B8: 3677
A9: Total Debt (M) | B9: 12345
A10: Net Debt (M) [= Total Debt - Cash] | B10: =B9-B8 -> 0
A11: Base Year FCF (M) [FY2025] | B11: 1327
A12: Base Year Revenue (M) [FY2025] | B12: 28893
A13: WACC — Base Case | B13: 0.11
A14: Terminal Growth Rate — Base | B14: 0.035
A15: Target CAGR for Entry Price | B15: 0.15
A17: FCF GROWTH RATE & MARGIN ASSUMPTIONS — edit gray cells
A18: Scenario / Year | B18: Year 1 | C18: Year 2 | D18: Year 3 | E18: Year 4 | F18: Year 5
A19: Base Revenue Growth | B19: 0.3 | C19: 0.27 | D19: 0.22 | E19: 0.18 | F19: 0.15
A20: Base FCF Margin | B20: 0.048 | C20: 0.052 | D20: 0.055 | E20: 0.058 | F20: 0.06
A21: Bull Revenue Growth | B21: 0.4 | C21: 0.33 | D21: 0.28 | E21: 0.22 | F21: 0.18
A22: Bull FCF Margin | B22: 0.055 | C22: 0.065 | D22: 0.075 | E22: 0.08 | F22: 0.085
A23: Bear Revenue Growth | B23: 0.18 | C23: 0.15 | D23: 0.12 | E23: 0.08 | F23: 0.06
A24: Bear FCF Margin | B24: 0.035 | C24: 0.038 | D24: 0.04 | E24: 0.04 | F24: 0.042
A25: Bull: WACC | Terminal Growth | B25: 0.1 | C25: 0.04
A26: Bear: WACC | Terminal Growth | B26: 0.13 | C26: 0.025
A28: BASE CASE — PROJECTIONS & DISCOUNTED CASH FLOWS
B29: Base Year | C29: Year 1 | D29: Year 2 | E29: Year 3 | F29: Year 4 | G29: Year 5
A30: Revenue (M) | B30: =B12 -> 0 | C30: =B30*(1+B19) -> 0 | D30: =C30*(1+C19) -> 0 | E30: =D30*(1+D19) -> 0 | F30: =E30*(1+E19) -> 0 | G30: =F30*(1+F19) -> 0
A31: Free Cash Flow (M) | B31: =B11 -> 0 | C31: =C30*B20 -> 0 | D31: =D30*C20 -> 0 | E31: =E30*D20 -> 0 | F31: =F30*E20 -> 0 | G31: =G30*F20 -> 0
A32: Discount Factor (1/(1+WACC)^n) | B32: — | C32: =1/(1+$B$13)^1 -> 0 | D32: =1/(1+$B$13)^2 -> 0 | E32: =1/(1+$B$13)^3 -> 0 | F32: =1/(1+$B$13)^4 -> 0 | G32: =1/(1+$B$13)^5 -> 0
A33: PV of FCF (M) | B33: — | C33: =C31*C32 -> 0 | D33: =D31*D32 -> 0 | E33: =E31*E32 -> 0 | F33: =F31*F32 -> 0 | G33: =G31*G32 -> 0
A35: BASE CASE — VALUATION SUMMARY
A36: Sum of PV of FCF (M) | B36: =SUM(C33:G33) -> 0
A37: Terminal FCF [Y5 FCF × (1+g)] | B37: =G31*(1+$B$14) -> 0
A38: Terminal Value (M) | B38: =B37/($B$13-$B$14) -> 0
A39: PV of Terminal Value (M) | B39: =B38*G32 -> 0
A40: Enterprise Value (M) | B40: =B36+B39 -> 0
A41: Less: Net Debt (M) | B41: =B10 -> 0
A42: Equity Value (M) | B42: =B40-B41 -> 0
A43: BASE INTRINSIC VALUE / SHARE | B43: =B42/B7 -> 0
A44: Upside / Downside vs Current Price | B44: =(B43-B6)/B6 -> 0
...

Sheet Bull & Bear
A1: MELI — Bull & Bear DCF Scenarios
A2: Inputs pull from 'DCF Model' sheet — change inputs there to update all scenarios.
A4: BULL CASE PROJECTIONS
A5: Scenario | B5: Base Year | C5: Year 1 | D5: Year 2 | E5: Year 3 | F5: Year 4 | G5: Year 5
A6: Revenue (M) | B6: ='DCF Model'!B12 -> 0 | C6: =B6*(1+'DCF Model'!B21) -> 0 | D6: =C6*(1+'DCF Model'!C21) -> 0 | E6: =D6*(1+'DCF Model'!D21) -> 0 | F6: =E6*(1+'DCF Model'!E21) -> 0 | G6: =F6*(1+'DCF Model'!F21) -> 0
A7: Free Cash Flow (M) | B7: ='DCF Model'!B11 -> 0 | C7: =C6*'DCF Model'!B22 -> 0 | D7: =D6*'DCF Model'!C22 -> 0 | E7: =E6*'DCF Model'!D22 -> 0 | F7: =F6*'DCF Model'!E22 -> 0 | G7: =G6*'DCF Model'!F22 -> 0
A8: Discount Factor (Bull WACC) | B8: — | C8: =1/(1+'DCF Model'!B25)^1 -> 0 | D8: =1/(1+'DCF Model'!B25)^2 -> 0 | E8: =1/(1+'DCF Model'!B25)^3 -> 0 | F8: =1/(1+'DCF Model'!B25)^4 -> 0 | G8: =1/(1+'DCF Model'!B25)^5 -> 0
A9: PV of FCF (M) | B9: — | C9: =C7*C8 -> 0 | D9: =D7*D8 -> 0 | E9: =E7*E8 -> 0 | F9: =F7*F8 -> 0 | G9: =G7*G8 -> 0
A11: BULL CASE — VALUATION
A12: Sum of PV of FCF (M) | B12: =SUM(C9:G9) -> 0
A13: Terminal FCF (Y5 FCF × (1+g_bull)) | B13: =G7*(1+'DCF Model'!C25) -> 0
A14: Terminal Value (M) | B14: =B13/('DCF Model'!B25-'DCF Model'!C25) -> 0
A15: PV of Terminal Value (M) | B15: =B14*G8 -> 0
A16: Enterprise Value (M) | B16: =B12+B15 -> 0
A17: Equity Value (M) | B17: =B16-'DCF Model'!B10 -> 0
A18: BULL INTRINSIC VALUE / SHARE | B18: =B17/'DCF Model'!B7 -> 0
A19: Upside / Downside vs Current Price | B19: =(B18-'DCF Model'!B6)/'DCF Model'!B6 -> 0
A20: Bull Entry Price (15% CAGR) | B20: =(B14/'DCF Model'!B7)/(1+'DCF Model'!B15)^5 -> 0
A22: BEAR CASE PROJECTIONS
A23: Scenario | B23: Base Year | C23: Year 1 | D23: Year 2 | E23: Year 3 | F23: Year 4 | G23: Year 5
A24: Revenue (M) | B24: ='DCF Model'!B12 -> 0 | C24: =B24*(1+'DCF Model'!B23) -> 0 | D24: =C24*(1+'DCF Model'!C23) -> 0 | E24: =D24*(1+'DCF Model'!D23) -> 0 | F24: =E24*(1+'DCF Model'!E23) -> 0 | G24: =F24*(1+'DCF Model'!F23) -> 0
A25: Free Cash Flow (M) | B25: ='DCF Model'!B11 -> 0 | C25: =C24*'DCF Model'!B24 -> 0 | D25: =D24*'DCF Model'!C24 -> 0 | E25: =E24*'DCF Model'!D24 -> 0 | F25: =F24*'DCF Model'!E24 -> 0 | G25: =G24*'DCF Model'!F24 -> 0
A26: Discount Factor (Bear WACC) | B26: — | C26: =1/(1+'DCF Model'!B26)^1 -> 0 | D26: =1/(1+'DCF Model'!B26)^2 -> 0 | E26: =1/(1+'DCF Model'!B26)^3 -> 0 | F26: =1/(1+'DCF Model'!B26)^4 -> 0 | G26: =1/(1+'DCF Model'!B26)^5 -> 0
A27: PV of FCF (M) | B27: — | C27: =C25*C26 -> 0 | D27: =D25*D26 -> 0 | E27: =E25*E26 -> 0 | F27: =F25*F26 -> 0 | G27: =G25*G26 -> 0
A29: BEAR CASE — VALUATION
A30: Sum of PV of FCF (M) | B30: =SUM(C27:G27) -> 0
A31: Terminal FCF (Y5 FCF × (1+g_bear)) | B31: =G25*(1+'DCF Model'!C26) -> 0
A32: Terminal Value (M) | B32: =B31/('DCF Model'!B26-'DCF Model'!C26) -> 0
A33: PV of Terminal Value (M) | B33: =B32*G26 -> 0
A34: Enterprise Value (M) | B34: =B30+B33 -> 0
A35: Equity Value (M) | B35: =B34-'DCF Model'!B10 -> 0
A36: BEAR INTRINSIC VALUE / SHARE | B36: =B35/'DCF Model'!B7 -> 0
A37: Upside / Downside vs Current Price | B37: =(B36-'DCF Model'!B6)/'DCF Model'!B6 -> 0
A38: Bear Entry Price (15% CAGR) | B38: =(B32/'DCF Model'!B7)/(1+'DCF Model'!B15)^5 -> 0
A40: PROBABILITY-WEIGHTED INTRINSIC VALUE
A41: Bull Weight | B41: 0.25
A42: Base Weight | B42: 0.5
A43: Bear Weight | B43: 0.25
A44: PROBABILITY-WEIGHTED IV / SHARE | B44: =B18*B41+'DCF Model'!B43*B42+B36*B43 -> 0
A45: Weighted Upside vs Current Price | B45: =(B44-'DCF Model'!B6)/'DCF Model'!B6 -> 0

Sheet Sensitivity
A1: MELI Base Case — Sensitivity: Intrinsic Value per Share
A2: Rows = WACC | Columns = Terminal Growth Rate | Current price: $1,683.13
A3: Green = above current price | Yellow = within 20% of current | Red = below current
A5: WACC \ Term G | B5: 0.025 | C5: 0.03 | D5: 0.035 | E5: 0.04 | F5: 0.045
A6: 0.09 | B6: 1025.72 | C6: 1110.64 | D6: 1211.04 | E6: 1331.48 | F6: 1478.41
A7: 0.1 | B7: 853.88 | C7: 914.71 | D7: 984.91 | E7: 1066.81 | F7: 1163.38
A8: 0.11 | B8: 722.94 | C8: 768.27 | D8: 819.61 | E8: 878.3 | F8: 945.84
A9: 0.12 | B9: 619.76 | C9: 654.54 | D9: 693.39 | E9: 737.1 | F9: 786.5
A10: 0.13 | B10: 536.66 | C10: 564 | D10: 594.2 | E10: 627.77 | F10: 665.13
A12: Notes:
A13: Base assumptions: WACC 11.0%, Terminal Growth 3.5% -> IV $819.61 (51% below current $1683.13)
A14: Bull IV $1,984.93 requires strong FCF margin expansion (5.5-8.5% over 5yr) at WACC 10% / terminal 4.0%.
A15: Current price $1,683 is NOT supported in the base case sensitivity matrix; requires bull case FCF assumptions.

Sheet Historical
A1: MELI — Historical Growth Rates & Revenue History
A3: Metric | B3: 3yr CAGR | C3: 2yr CAGR | D3: Notes
A4: Revenue | B4: 0.399 | C4: 0.383 | D4: FY2022-FY2025; Q1'26 +49.0% YoY re-acceleration
A5: EPS | B5: 0.601 | C5: 0.416 | D5: FY2022-FY2025; FY2025 compressed by credit provisioning surge
A6: Shareholders Eq. | B6: 0.546 | C6: 0.482 | D6: FY2022-FY2025; driven by retained earnings
A7: FCF | B7: N/A | C7: N/A | D7: FY2024 $1,315M -> FY2025 $1,327M (+0.9%); 2 years only
A9: Selected Growth Rate Source: | B9: revenue_3yr_cagr
A10: Selected Rate: | B10: 0.399
A12: Revenue & FCF History
A13: Period | B13: Revenue (M) | C13: YoY Growth | D13: FCF (M)
A14: FY2022 | B14: 10545 | C14: — | D14: —
A15: FY2023 | B15: 15107 | C15: 0.4326221 | D15: —
A16: FY2024 | B16: 20777 | C16: 0.3753227 | D16: 1315
A17: FY2025 | B17: 28893 | C17: 0.39062425 | D17: 1327
A18: Q1 2026 | B18: 8845 | C18: 0.49031171 | D18: 271
