Workbook

Sheet DCF Model
A1: CPNG DCF Valuation Model (Base Case)
A2: Gray cells are INPUTS - adjust to see valuation change
A4: KEY INPUTS
A5: Current Stock Price | B5: 15.5
A6: Shares Outstanding (M) | B6: 1809
A7: Cash & Equivalents (M) | B7: 6301
A8: Total Debt (M) | B8: 2289
A9: Net Debt (M) [negative = net cash] | B9: =B8-B7 -> 0
A10: Base Year Revenue - FY2025 (M) | B10: 34534
A12: WACC | B12: 0.115
A13: Terminal Growth Rate | B13: 0.025
A15: GROWTH & MARGIN ASSUMPTIONS | B15: Year 1 | C15: Year 2 | D15: Year 3 | E15: Year 4 | F15: Year 5
A16: Revenue Growth Rate | B16: 0.105 | C16: 0.095 | D16: 0.085 | E16: 0.075 | F16: 0.065
A17: FCF Margin (% of Revenue) | B17: 0.02 | C17: 0.028 | D17: 0.033 | E17: 0.035 | F17: 0.035
A19: PROJECTIONS
B20: Year 1 | C20: Year 2 | D20: Year 3 | E20: Year 4 | F20: Year 5
A21: Revenue | B21: =B10*(1+B16) -> 0 | C21: =B21*(1+C16) -> 0 | D21: =C21*(1+D16) -> 0 | E21: =D21*(1+E16) -> 0 | F21: =E21*(1+F16) -> 0
A22: Free Cash Flow | B22: =B21*B17 -> 0 | C22: =C21*C17 -> 0 | D22: =D21*D17 -> 0 | E22: =E21*E17 -> 0 | F22: =F21*F17 -> 0
A23: Discount Factor | B23: =1/(1+$B$12)^1 -> 0 | C23: =1/(1+$B$12)^2 -> 0 | D23: =1/(1+$B$12)^3 -> 0 | E23: =1/(1+$B$12)^4 -> 0 | F23: =1/(1+$B$12)^5 -> 0
A24: PV of FCF | B24: =B22*B23 -> 0 | C24: =C22*C23 -> 0 | D24: =D22*D23 -> 0 | E24: =E22*E23 -> 0 | F24: =F22*F23 -> 0
A26: VALUATION
A27: Sum of PV of FCF | B27: =SUM(B24:F24) -> 0
A28: Terminal FCF (Year 5 * (1+g)) | B28: =F22*(1+$B$13) -> 0
A29: Terminal Value | B29: =B28/($B$12-$B$13) -> 0
A30: PV of Terminal Value | B30: =B29*F23 -> 0
A31: Enterprise Value | B31: =B27+B30 -> 0
A32: Less: Net Debt | B32: =B9 -> 0
A33: Equity Value | B33: =B31-B32 -> 0
A34: INTRINSIC VALUE/SHARE | B34: =B33/B6 -> 0
A35: Terminal Value % of EV | B35: =B30/B31 -> 0
A36: Implied Exit Multiple (TV/FCF5) | B36: =B29/F22 -> 0
A38: ENTRY PRICE (15% IRR Target)
A39: PV of Yrs 1-5 FCF @15% | B39: =NPV(0.15,B22:F22) -> 0
A40: PV of Terminal Value @15% | B40: =B29/(1.15^5) -> 0
A41: Less: Net Debt | B41: =B9 -> 0
A42: Entry Price (15% CAGR) | B42: =(B39+B40-B41)/B6 -> 0
A44: Upside to Intrinsic Value | B44: =(B34-B5)/B5 -> 0
A45: Upside to Entry Price | B45: =(B5-B42)/B5 -> 0
A47: Note: FCF base year is FY2025 revenue ($34,534M); FY2025 FCF margin was
A48: trough-depressed at 1.5% due to Taiwan/automation capex ramp and the Nov-2025
...

Sheet Scenarios
A1: Bull / Base / Bear Scenario Comparison
A3: Assumption | B3: Bull | C3: Base | D3: Bear
A4: WACC | B4: 0.105 | C4: 0.115 | D4: 0.125
A5: Terminal Growth | B5: 0.03 | C5: 0.025 | D5: 0.02
A6: Year 5 FCF Margin | B6: 0.05 | C6: 0.035 | D6: 0.02
A8: Year | B8: Y1 | C8: Y2 | D8: Y3 | E8: Y4 | F8: Y5
A9: Bull Revenue Growth | B9: 0.135 | C9: 0.12 | D9: 0.11 | E9: 0.1 | F9: 0.09
A10: Base Revenue Growth | B10: 0.105 | C10: 0.095 | D10: 0.085 | E10: 0.075 | F10: 0.065
A11: Bear Revenue Growth | B11: 0.06 | C11: 0.05 | D11: 0.045 | E11: 0.035 | F11: 0.03
A13: Scenario Results
B14: Intrinsic Value | C14: Upside/Downside | D14: Terminal % of EV | E14: Implied Exit Mult
A15: Bull | B15: 19.72 | C15: 0.272 | D15: 0.769 | E15: 13.7
A16: Base | B16: 11.54 | C16: -0.255 | D16: 0.712 | E16: 11.4
A17: Bear | B17: 6.21 | C17: -0.6 | D17: 0.64 | E17: 9.7
A19: Probability-Weighted IV | B19: 12.25
A20: Weights (Bull/Base/Bear) | B20: 25% / 50% / 25%

Sheet Sensitivity
A1: Sensitivity Analysis (Base Case)
A2: Intrinsic Value by WACC & Terminal Growth
A4: WACC \ Term G | B4: 0.015 | C4: 0.02 | D4: 0.025 | E4: 0.03 | F4: 0.035
A5: 0.095 | B5: =('DCF Model'!$B$10*(1+'DCF Model'!$B$16)*(1+'DCF Model'!$B$17)*(1+0.095)^-1 + 'DCF Model'!$B$10*(1+'DCF Model'!$B$16)*(1+'DCF Model'!$C$16)*(1+'DCF Model'!$C$17)*(1+0.095)^-2 + 'DCF Model'!$B$10*(1+'DCF Model'!$B$16)*(1+'DCF Model'!$C$16)*(1+'DCF Model'!$D$16)*(1+'DCF Model'!$D$17)*(1+0.095)^-3 + 'DCF Model'!$B$10*(1+'DCF Model'!$B$16)*(1+'DCF Model'!$C$16)*(1+'DCF Model'!$D$16)*(1+'DCF Model'!$E$16)*(1+'DCF Model'!$E$17)*(1+0.095)^-4 + 'DCF Model'!$B$10*(1+'DCF Model'!$B$16)*(1+'DCF Model'!$C$16)*(1+'DCF Model'!$D$16)*(1+'DCF Model'!$E$16)*(1+'DCF Model'!$F$16)*'DCF Model'!$F$17*(1+0.095)^-5 + ('DCF Model'!$B$10*(1+'DCF Model'!$B$16)*(1+'DCF Model'!$C$16)*(1+'DCF Model'!$D$16)*(1+'DCF Model'!$E$16)*(1+'DCF Model'!$F$16)*'DCF Model'!$F$17*(1+0.015)/(0.095-0.015))*(1+0.095)^-5 - 'DCF Model'!$B$9)/'DCF Model'!$B$6 -> 0 | C5: =('DCF Model'!$B$10*(1+'DCF Model'!$B$16)*(1+'DCF Model'!$B$17)*(1+0.095)^-1 + 'DCF Model'!$B$10*(1+'DCF Model'!$B$16)*(1+'DCF Model'!$C$16)*(1+'DCF Model'!$C$17)*(1+0.095)^-2 + 'DCF Model'!$B$10*(1+'DCF Model'!$B$16)*(1+'DCF Model'!$C$16)*(1+'DCF Model'!$D$16)*(1+'DCF Model'!$D$17)*(1+0.095)^-3 + 'DCF Model'!$B$10*(1+'DCF Model'!$B$16)*(1+'DCF Model'!$C$16)*(1+'DCF Model'!$D$16)*(1+'DCF Model'!$E$16)*(1+'DCF Model'!$E$17)*(1+0.095)^-4 + 'DCF Model'!$B$10*(1+'DCF Model'!$B$16)*(1+'DCF Model'!$C$16)*(1+'DCF Model'!$D$16)*(1+'DCF Model'!$E$16)*(1+'DCF Model'!$F$16)*'DCF Model'!$F$17*(1+0.095)^-5 + ('DCF Model'!$B$10*(1+'DCF Model'!$B$16)*(1+'DCF Model'!$C$16)*(1+'DCF Model'!$D$16)*(1+'DCF Model'!$E$16)*(1+'DCF Model'!$F$16)*'DCF Model'!$F$17*(1+0.02)/(0.095-0.02))*(1+0.095)^-5 - 'DCF Model'!$B$9)/'DCF Model'!$B$6 -> 0 | D5: =('DCF Model'!$B$10*(1+'DCF Model'!$B$16)*(1+'DCF Model'!$B$17)*(1+0.095)^-1 + 'DCF Model'!$B$10*(1+'DCF Model'!$B$16)*(1+'DCF Model'!$C$16)*(1+'DCF Model'!$C$17)*(1+0.095)^-2 + 'DCF Model'!$B$10*(1+'DCF Model'!$B$16)*(1+'DCF Model'!$C$16)*(1+'DCF Model'!$D$16)*(1+'DCF Model'!$D$17)*(1+0.095)^-3 + 'DCF Model'!$B$10*(1+'DCF Model'!$B$16)*(1+'DCF Model'!$C$16)*(1+'DCF Model'!$D$16)*(1+'DCF Model'!$E$16)*(1+'DCF Model'!$E$17)*(1+0.095)^-4 + 'DCF Model'!$B$10*(1+'DCF Model'!$B$16)*(1+'DCF Model'!$C$16)*(1+'DCF Model'!$D$16)*(1+'DCF Model'!$E$16)*(1+'DCF Model'!$F$16)*'DCF Model'!$F$17*(1+0.095)^-5 + ('DCF Model'!$B$10*(1+'DCF Model'!$B$16)*(1+'DCF Model'!$C$16)*(1+'DCF Model'!$D$16)*(1+'DCF Model'!$E$16)*(1+'DCF Model'!$F$16)*'DCF Model'!$F$17*(1+0.025)/(0.095-0.025))*(1+0.095)^-5 - 'DCF Model'!$B$9)/'DCF Model'!$B$6 -> 0 | E5: =('DCF Model'!$B$10*(1+'DCF Model'!$B$16)*(1+'DCF Model'!$B$17)*(1+0.095)^-1 + 'DCF Model'!$B$10*(1+'DCF Model'!$B$16)*(1+'DCF Model'!$C$16)*(1+'DCF Model'!$C$17)*(1+0.095)^-2 + 'DCF Model'!$B$10*(1+'DCF Model'!$B$16)*(1+'DCF Model'!$C$16)*(1+'DCF Model'!$D$16)*(1+'DCF Model'!$D$17)*(1+0.095)^-3 + 'DCF Model'!$B$10*(1+'DCF Model'!$B$16)*(1+'DCF Model'!$C$16)*(1+'DCF Model'!$D$16)*(1+'DCF Model'!$E$16)*(1+'DCF Model'!$E$17)*(1+0.095)^-4 + 'DCF Model'!$B$10*(1+'DCF Model'!$B$16)*(1+'DCF Model'!$C$16)*(1+'DCF Model'!$D$16)*(1+'DCF Model'!$E$16)*(1+'DCF Model'!$F$16)*'DCF Model'!$F$17*(1+0.095)^-5 + ('DCF Model'!$B$10*(1+'DCF Model'!$B$16)*(1+'DCF Model'!$C$16)*(1+'DCF Model'!$D$16)*(1+'DCF Model'!$E$16)*(1+'DCF Model'!$F$16)*'DCF Model'!$F$17*(1+0.03)/(0.095-0.03))*(1+0.095)^-5 - 'DCF Model'!$B$9)/'DCF Model'!$B$6 -> 0 | F5: =('DCF Model'!$B$10*(1+'DCF Model'!$B$16)*(1+'DCF Model'!$B$17)*(1+0.095)^-1 + 'DCF Model'!$B$10*(1+'DCF Model'!$B$16)*(1+'DCF Model'!$C$16)*(1+'DCF Model'!$C$17)*(1+0.095)^-2 + 'DCF Model'!$B$10*(1+'DCF Model'!$B$16)*(1+'DCF Model'!$C$16)*(1+'DCF Model'!$D$16)*(1+'DCF Model'!$D$17)*(1+0.095)^-3 + 'DCF Model'!$B$10*(1+'DCF Model'!$B$16)*(1+'DCF Model'!$C$16)*(1+'DCF Model'!$D$16)*(1+'DCF Model'!$E$16)*(1+'DCF Model'!$E$17)*(1+0.095)^-4 + 'DCF Model'!$B$10*(1+'DCF Model'!$B$16)*(1+'DCF Model'!$C$16)*(1+'DCF Model'!$D$16)*(1+'DCF Model'!$E$16)*(1+'DCF Model'!$F$16)*'DCF Model'!$F$17*(1+0.095)^-5 + ('DCF Model'!$B$10*(1+'DCF Model'!$B$16)*(1+'DCF Model'!$C$16)*(1+'DCF Model'!$D$16)*(1+'DCF Model'!$E$16)*(1+'DCF Model'!$F$16)*'DCF Model'!$F$17*(1+0.035)/(0.095-0.035))*(1+0.095)^-5 - 'DCF Model'!$B$9)/'DCF Model'!$B$6 -> 0
A6: 0.105 | B6: =('DCF Model'!$B$10*(1+'DCF Model'!$B$16)*(1+'DCF Model'!$B$17)*(1+0.105)^-1 + 'DCF Model'!$B$10*(1+'DCF Model'!$B$16)*(1+'DCF Model'!$C$16)*(1+'DCF Model'!$C$17)*(1+0.105)^-2 + 'DCF Model'!$B$10*(1+'DCF Model'!$B$16)*(1+'DCF Model'!$C$16)*(1+'DCF Model'!$D$16)*(1+'DCF Model'!$D$17)*(1+0.105)^-3 + 'DCF Model'!$B$10*(1+'DCF Model'!$B$16)*(1+'DCF Model'!$C$16)*(1+'DCF Model'!$D$16)*(1+'DCF Model'!$E$16)*(1+'DCF Model'!$E$17)*(1+0.105)^-4 + 'DCF Model'!$B$10*(1+'DCF Model'!$B$16)*(1+'DCF Model'!$C$16)*(1+'DCF Model'!$D$16)*(1+'DCF Model'!$E$16)*(1+'DCF Model'!$F$16)*'DCF Model'!$F$17*(1+0.105)^-5 + ('DCF Model'!$B$10*(1+'DCF Model'!$B$16)*(1+'DCF Model'!$C$16)*(1+'DCF Model'!$D$16)*(1+'DCF Model'!$E$16)*(1+'DCF Model'!$F$16)*'DCF Model'!$F$17*(1+0.015)/(0.105-0.015))*(1+0.105)^-5 - 'DCF Model'!$B$9)/'DCF Model'!$B$6 -> 0 | C6: =('DCF Model'!$B$10*(1+'DCF Model'!$B$16)*(1+'DCF Model'!$B$17)*(1+0.105)^-1 + 'DCF Model'!$B$10*(1+'DCF Model'!$B$16)*(1+'DCF Model'!$C$16)*(1+'DCF Model'!$C$17)*(1+0.105)^-2 + 'DCF Model'!$B$10*(1+'DCF Model'!$B$16)*(1+'DCF Model'!$C$16)*(1+'DCF Model'!$D$16)*(1+'DCF Model'!$D$17)*(1+0.105)^-3 + 'DCF Model'!$B$10*(1+'DCF Model'!$B$16)*(1+'DCF Model'!$C$16)*(1+'DCF Model'!$D$16)*(1+'DCF Model'!$E$16)*(1+'DCF Model'!$E$17)*(1+0.105)^-4 + 'DCF Model'!$B$10*(1+'DCF Model'!$B$16)*(1+'DCF Model'!$C$16)*(1+'DCF Model'!$D$16)*(1+'DCF Model'!$E$16)*(1+'DCF Model'!$F$16)*'DCF Model'!$F$17*(1+0.105)^-5 + ('DCF Model'!$B$10*(1+'DCF Model'!$B$16)*(1+'DCF Model'!$C$16)*(1+'DCF Model'!$D$16)*(1+'DCF Model'!$E$16)*(1+'DCF Model'!$F$16)*'DCF Model'!$F$17*(1+0.02)/(0.105-0.02))*(1+0.105)^-5 - 'DCF Model'!$B$9)/'DCF Model'!$B$6 -> 0 | D6: =('DCF Model'!$B$10*(1+'DCF Model'!$B$16)*(1+'DCF Model'!$B$17)*(1+0.105)^-1 + 'DCF Model'!$B$10*(1+'DCF Model'!$B$16)*(1+'DCF Model'!$C$16)*(1+'DCF Model'!$C$17)*(1+0.105)^-2 + 'DCF Model'!$B$10*(1+'DCF Model'!$B$16)*(1+'DCF Model'!$C$16)*(1+'DCF Model'!$D$16)*(1+'DCF Model'!$D$17)*(1+0.105)^-3 + 'DCF Model'!$B$10*(1+'DCF Model'!$B$16)*(1+'DCF Model'!$C$16)*(1+'DCF Model'!$D$16)*(1+'DCF Model'!$E$16)*(1+'DCF Model'!$E$17)*(1+0.105)^-4 + 'DCF Model'!$B$10*(1+'DCF Model'!$B$16)*(1+'DCF Model'!$C$16)*(1+'DCF Model'!$D$16)*(1+'DCF Model'!$E$16)*(1+'DCF Model'!$F$16)*'DCF Model'!$F$17*(1+0.105)^-5 + ('DCF Model'!$B$10*(1+'DCF Model'!$B$16)*(1+'DCF Model'!$C$16)*(1+'DCF Model'!$D$16)*(1+'DCF Model'!$E$16)*(1+'DCF Model'!$F$16)*'DCF Model'!$F$17*(1+0.025)/(0.105-0.025))*(1+0.105)^-5 - 'DCF Model'!$B$9)/'DCF Model'!$B$6 -> 0 | E6: =('DCF Model'!$B$10*(1+'DCF Model'!$B$16)*(1+'DCF Model'!$B$17)*(1+0.105)^-1 + 'DCF Model'!$B$10*(1+'DCF Model'!$B$16)*(1+'DCF Model'!$C$16)*(1+'DCF Model'!$C$17)*(1+0.105)^-2 + 'DCF Model'!$B$10*(1+'DCF Model'!$B$16)*(1+'DCF Model'!$C$16)*(1+'DCF Model'!$D$16)*(1+'DCF Model'!$D$17)*(1+0.105)^-3 + 'DCF Model'!$B$10*(1+'DCF Model'!$B$16)*(1+'DCF Model'!$C$16)*(1+'DCF Model'!$D$16)*(1+'DCF Model'!$E$16)*(1+'DCF Model'!$E$17)*(1+0.105)^-4 + 'DCF Model'!$B$10*(1+'DCF Model'!$B$16)*(1+'DCF Model'!$C$16)*(1+'DCF Model'!$D$16)*(1+'DCF Model'!$E$16)*(1+'DCF Model'!$F$16)*'DCF Model'!$F$17*(1+0.105)^-5 + ('DCF Model'!$B$10*(1+'DCF Model'!$B$16)*(1+'DCF Model'!$C$16)*(1+'DCF Model'!$D$16)*(1+'DCF Model'!$E$16)*(1+'DCF Model'!$F$16)*'DCF Model'!$F$17*(1+0.03)/(0.105-0.03))*(1+0.105)^-5 - 'DCF Model'!$B$9)/'DCF Model'!$B$6 -> 0 | F6: =('DCF Model'!$B$10*(1+'DCF Model'!$B$16)*(1+'DCF Model'!$B$17)*(1+0.105)^-1 + 'DCF Model'!$B$10*(1+'DCF Model'!$B$16)*(1+'DCF Model'!$C$16)*(1+'DCF Model'!$C$17)*(1+0.105)^-2 + 'DCF Model'!$B$10*(1+'DCF Model'!$B$16)*(1+'DCF Model'!$C$16)*(1+'DCF Model'!$D$16)*(1+'DCF Model'!$D$17)*(1+0.105)^-3 + 'DCF Model'!$B$10*(1+'DCF Model'!$B$16)*(1+'DCF Model'!$C$16)*(1+'DCF Model'!$D$16)*(1+'DCF Model'!$E$16)*(1+'DCF Model'!$E$17)*(1+0.105)^-4 + 'DCF Model'!$B$10*(1+'DCF Model'!$B$16)*(1+'DCF Model'!$C$16)*(1+'DCF Model'!$D$16)*(1+'DCF Model'!$E$16)*(1+'DCF Model'!$F$16)*'DCF Model'!$F$17*(1+0.105)^-5 + ('DCF Model'!$B$10*(1+'DCF Model'!$B$16)*(1+'DCF Model'!$C$16)*(1+'DCF Model'!$D$16)*(1+'DCF Model'!$E$16)*(1+'DCF Model'!$F$16)*'DCF Model'!$F$17*(1+0.035)/(0.105-0.035))*(1+0.105)^-5 - 'DCF Model'!$B$9)/'DCF Model'!$B$6 -> 0
A7: 0.115 | B7: =('DCF Model'!$B$10*(1+'DCF Model'!$B$16)*(1+'DCF Model'!$B$17)*(1+0.115)^-1 + 'DCF Model'!$B$10*(1+'DCF Model'!$B$16)*(1+'DCF Model'!$C$16)*(1+'DCF Model'!$C$17)*(1+0.115)^-2 + 'DCF Model'!$B$10*(1+'DCF Model'!$B$16)*(1+'DCF Model'!$C$16)*(1+'DCF Model'!$D$16)*(1+'DCF Model'!$D$17)*(1+0.115)^-3 + 'DCF Model'!$B$10*(1+'DCF Model'!$B$16)*(1+'DCF Model'!$C$16)*(1+'DCF Model'!$D$16)*(1+'DCF Model'!$E$16)*(1+'DCF Model'!$E$17)*(1+0.115)^-4 + 'DCF Model'!$B$10*(1+'DCF Model'!$B$16)*(1+'DCF Model'!$C$16)*(1+'DCF Model'!$D$16)*(1+'DCF Model'!$E$16)*(1+'DCF Model'!$F$16)*'DCF Model'!$F$17*(1+0.115)^-5 + ('DCF Model'!$B$10*(1+'DCF Model'!$B$16)*(1+'DCF Model'!$C$16)*(1+'DCF Model'!$D$16)*(1+'DCF Model'!$E$16)*(1+'DCF Model'!$F$16)*'DCF Model'!$F$17*(1+0.015)/(0.115-0.015))*(1+0.115)^-5 - 'DCF Model'!$B$9)/'DCF Model'!$B$6 -> 0 | C7: =('DCF Model'!$B$10*(1+'DCF Model'!$B$16)*(1+'DCF Model'!$B$17)*(1+0.115)^-1 + 'DCF Model'!$B$10*(1+'DCF Model'!$B$16)*(1+'DCF Model'!$C$16)*(1+'DCF Model'!$C$17)*(1+0.115)^-2 + 'DCF Model'!$B$10*(1+'DCF Model'!$B$16)*(1+'DCF Model'!$C$16)*(1+'DCF Model'!$D$16)*(1+'DCF Model'!$D$17)*(1+0.115)^-3 + 'DCF Model'!$B$10*(1+'DCF Model'!$B$16)*(1+'DCF Model'!$C$16)*(1+'DCF Model'!$D$16)*(1+'DCF Model'!$E$16)*(1+'DCF Model'!$E$17)*(1+0.115)^-4 + 'DCF Model'!$B$10*(1+'DCF Model'!$B$16)*(1+'DCF Model'!$C$16)*(1+'DCF Model'!$D$16)*(1+'DCF Model'!$E$16)*(1+'DCF Model'!$F$16)*'DCF Model'!$F$17*(1+0.115)^-5 + ('DCF Model'!$B$10*(1+'DCF Model'!$B$16)*(1+'DCF Model'!$C$16)*(1+'DCF Model'!$D$16)*(1+'DCF Model'!$E$16)*(1+'DCF Model'!$F$16)*'DCF Model'!$F$17*(1+0.02)/(0.115-0.02))*(1+0.115)^-5 - 'DCF Model'!$B$9)/'DCF Model'!$B$6 -> 0 | D7: =('DCF Model'!$B$10*(1+'DCF Model'!$B$16)*(1+'DCF Model'!$B$17)*(1+0.115)^-1 + 'DCF Model'!$B$10*(1+'DCF Model'!$B$16)*(1+'DCF Model'!$C$16)*(1+'DCF Model'!$C$17)*(1+0.115)^-2 + 'DCF Model'!$B$10*(1+'DCF Model'!$B$16)*(1+'DCF Model'!$C$16)*(1+'DCF Model'!$D$16)*(1+'DCF Model'!$D$17)*(1+0.115)^-3 + 'DCF Model'!$B$10*(1+'DCF Model'!$B$16)*(1+'DCF Model'!$C$16)*(1+'DCF Model'!$D$16)*(1+'DCF Model'!$E$16)*(1+'DCF Model'!$E$17)*(1+0.115)^-4 + 'DCF Model'!$B$10*(1+'DCF Model'!$B$16)*(1+'DCF Model'!$C$16)*(1+'DCF Model'!$D$16)*(1+'DCF Model'!$E$16)*(1+'DCF Model'!$F$16)*'DCF Model'!$F$17*(1+0.115)^-5 + ('DCF Model'!$B$10*(1+'DCF Model'!$B$16)*(1+'DCF Model'!$C$16)*(1+'DCF Model'!$D$16)*(1+'DCF Model'!$E$16)*(1+'DCF Model'!$F$16)*'DCF Model'!$F$17*(1+0.025)/(0.115-0.025))*(1+0.115)^-5 - 'DCF Model'!$B$9)/'DCF Model'!$B$6 -> 0 | E7: =('DCF Model'!$B$10*(1+'DCF Model'!$B$16)*(1+'DCF Model'!$B$17)*(1+0.115)^-1 + 'DCF Model'!$B$10*(1+'DCF Model'!$B$16)*(1+'DCF Model'!$C$16)*(1+'DCF Model'!$C$17)*(1+0.115)^-2 + 'DCF Model'!$B$10*(1+'DCF Model'!$B$16)*(1+'DCF Model'!$C$16)*(1+'DCF Model'!$D$16)*(1+'DCF Model'!$D$17)*(1+0.115)^-3 + 'DCF Model'!$B$10*(1+'DCF Model'!$B$16)*(1+'DCF Model'!$C$16)*(1+'DCF Model'!$D$16)*(1+'DCF Model'!$E$16)*(1+'DCF Model'!$E$17)*(1+0.115)^-4 + 'DCF Model'!$B$10*(1+'DCF Model'!$B$16)*(1+'DCF Model'!$C$16)*(1+'DCF Model'!$D$16)*(1+'DCF Model'!$E$16)*(1+'DCF Model'!$F$16)*'DCF Model'!$F$17*(1+0.115)^-5 + ('DCF Model'!$B$10*(1+'DCF Model'!$B$16)*(1+'DCF Model'!$C$16)*(1+'DCF Model'!$D$16)*(1+'DCF Model'!$E$16)*(1+'DCF Model'!$F$16)*'DCF Model'!$F$17*(1+0.03)/(0.115-0.03))*(1+0.115)^-5 - 'DCF Model'!$B$9)/'DCF Model'!$B$6 -> 0 | F7: =('DCF Model'!$B$10*(1+'DCF Model'!$B$16)*(1+'DCF Model'!$B$17)*(1+0.115)^-1 + 'DCF Model'!$B$10*(1+'DCF Model'!$B$16)*(1+'DCF Model'!$C$16)*(1+'DCF Model'!$C$17)*(1+0.115)^-2 + 'DCF Model'!$B$10*(1+'DCF Model'!$B$16)*(1+'DCF Model'!$C$16)*(1+'DCF Model'!$D$16)*(1+'DCF Model'!$D$17)*(1+0.115)^-3 + 'DCF Model'!$B$10*(1+'DCF Model'!$B$16)*(1+'DCF Model'!$C$16)*(1+'DCF Model'!$D$16)*(1+'DCF Model'!$E$16)*(1+'DCF Model'!$E$17)*(1+0.115)^-4 + 'DCF Model'!$B$10*(1+'DCF Model'!$B$16)*(1+'DCF Model'!$C$16)*(1+'DCF Model'!$D$16)*(1+'DCF Model'!$E$16)*(1+'DCF Model'!$F$16)*'DCF Model'!$F$17*(1+0.115)^-5 + ('DCF Model'!$B$10*(1+'DCF Model'!$B$16)*(1+'DCF Model'!$C$16)*(1+'DCF Model'!$D$16)*(1+'DCF Model'!$E$16)*(1+'DCF Model'!$F$16)*'DCF Model'!$F$17*(1+0.035)/(0.115-0.035))*(1+0.115)^-5 - 'DCF Model'!$B$9)/'DCF Model'!$B$6 -> 0
A8: 0.125 | B8: =('DCF Model'!$B$10*(1+'DCF Model'!$B$16)*(1+'DCF Model'!$B$17)*(1+0.125)^-1 + 'DCF Model'!$B$10*(1+'DCF Model'!$B$16)*(1+'DCF Model'!$C$16)*(1+'DCF Model'!$C$17)*(1+0.125)^-2 + 'DCF Model'!$B$10*(1+'DCF Model'!$B$16)*(1+'DCF Model'!$C$16)*(1+'DCF Model'!$D$16)*(1+'DCF Model'!$D$17)*(1+0.125)^-3 + 'DCF Model'!$B$10*(1+'DCF Model'!$B$16)*(1+'DCF Model'!$C$16)*(1+'DCF Model'!$D$16)*(1+'DCF Model'!$E$16)*(1+'DCF Model'!$E$17)*(1+0.125)^-4 + 'DCF Model'!$B$10*(1+'DCF Model'!$B$16)*(1+'DCF Model'!$C$16)*(1+'DCF Model'!$D$16)*(1+'DCF Model'!$E$16)*(1+'DCF Model'!$F$16)*'DCF Model'!$F$17*(1+0.125)^-5 + ('DCF Model'!$B$10*(1+'DCF Model'!$B$16)*(1+'DCF Model'!$C$16)*(1+'DCF Model'!$D$16)*(1+'DCF Model'!$E$16)*(1+'DCF Model'!$F$16)*'DCF Model'!$F$17*(1+0.015)/(0.125-0.015))*(1+0.125)^-5 - 'DCF Model'!$B$9)/'DCF Model'!$B$6 -> 0 | C8: =('DCF Model'!$B$10*(1+'DCF Model'!$B$16)*(1+'DCF Model'!$B$17)*(1+0.125)^-1 + 'DCF Model'!$B$10*(1+'DCF Model'!$B$16)*(1+'DCF Model'!$C$16)*(1+'DCF Model'!$C$17)*(1+0.125)^-2 + 'DCF Model'!$B$10*(1+'DCF Model'!$B$16)*(1+'DCF Model'!$C$16)*(1+'DCF Model'!$D$16)*(1+'DCF Model'!$D$17)*(1+0.125)^-3 + 'DCF Model'!$B$10*(1+'DCF Model'!$B$16)*(1+'DCF Model'!$C$16)*(1+'DCF Model'!$D$16)*(1+'DCF Model'!$E$16)*(1+'DCF Model'!$E$17)*(1+0.125)^-4 + 'DCF Model'!$B$10*(1+'DCF Model'!$B$16)*(1+'DCF Model'!$C$16)*(1+'DCF Model'!$D$16)*(1+'DCF Model'!$E$16)*(1+'DCF Model'!$F$16)*'DCF Model'!$F$17*(1+0.125)^-5 + ('DCF Model'!$B$10*(1+'DCF Model'!$B$16)*(1+'DCF Model'!$C$16)*(1+'DCF Model'!$D$16)*(1+'DCF Model'!$E$16)*(1+'DCF Model'!$F$16)*'DCF Model'!$F$17*(1+0.02)/(0.125-0.02))*(1+0.125)^-5 - 'DCF Model'!$B$9)/'DCF Model'!$B$6 -> 0 | D8: =('DCF Model'!$B$10*(1+'DCF Model'!$B$16)*(1+'DCF Model'!$B$17)*(1+0.125)^-1 + 'DCF Model'!$B$10*(1+'DCF Model'!$B$16)*(1+'DCF Model'!$C$16)*(1+'DCF Model'!$C$17)*(1+0.125)^-2 + 'DCF Model'!$B$10*(1+'DCF Model'!$B$16)*(1+'DCF Model'!$C$16)*(1+'DCF Model'!$D$16)*(1+'DCF Model'!$D$17)*(1+0.125)^-3 + 'DCF Model'!$B$10*(1+'DCF Model'!$B$16)*(1+'DCF Model'!$C$16)*(1+'DCF Model'!$D$16)*(1+'DCF Model'!$E$16)*(1+'DCF Model'!$E$17)*(1+0.125)^-4 + 'DCF Model'!$B$10*(1+'DCF Model'!$B$16)*(1+'DCF Model'!$C$16)*(1+'DCF Model'!$D$16)*(1+'DCF Model'!$E$16)*(1+'DCF Model'!$F$16)*'DCF Model'!$F$17*(1+0.125)^-5 + ('DCF Model'!$B$10*(1+'DCF Model'!$B$16)*(1+'DCF Model'!$C$16)*(1+'DCF Model'!$D$16)*(1+'DCF Model'!$E$16)*(1+'DCF Model'!$F$16)*'DCF Model'!$F$17*(1+0.025)/(0.125-0.025))*(1+0.125)^-5 - 'DCF Model'!$B$9)/'DCF Model'!$B$6 -> 0 | E8: =('DCF Model'!$B$10*(1+'DCF Model'!$B$16)*(1+'DCF Model'!$B$17)*(1+0.125)^-1 + 'DCF Model'!$B$10*(1+'DCF Model'!$B$16)*(1+'DCF Model'!$C$16)*(1+'DCF Model'!$C$17)*(1+0.125)^-2 + 'DCF Model'!$B$10*(1+'DCF Model'!$B$16)*(1+'DCF Model'!$C$16)*(1+'DCF Model'!$D$16)*(1+'DCF Model'!$D$17)*(1+0.125)^-3 + 'DCF Model'!$B$10*(1+'DCF Model'!$B$16)*(1+'DCF Model'!$C$16)*(1+'DCF Model'!$D$16)*(1+'DCF Model'!$E$16)*(1+'DCF Model'!$E$17)*(1+0.125)^-4 + 'DCF Model'!$B$10*(1+'DCF Model'!$B$16)*(1+'DCF Model'!$C$16)*(1+'DCF Model'!$D$16)*(1+'DCF Model'!$E$16)*(1+'DCF Model'!$F$16)*'DCF Model'!$F$17*(1+0.125)^-5 + ('DCF Model'!$B$10*(1+'DCF Model'!$B$16)*(1+'DCF Model'!$C$16)*(1+'DCF Model'!$D$16)*(1+'DCF Model'!$E$16)*(1+'DCF Model'!$F$16)*'DCF Model'!$F$17*(1+0.03)/(0.125-0.03))*(1+0.125)^-5 - 'DCF Model'!$B$9)/'DCF Model'!$B$6 -> 0 | F8: =('DCF Model'!$B$10*(1+'DCF Model'!$B$16)*(1+'DCF Model'!$B$17)*(1+0.125)^-1 + 'DCF Model'!$B$10*(1+'DCF Model'!$B$16)*(1+'DCF Model'!$C$16)*(1+'DCF Model'!$C$17)*(1+0.125)^-2 + 'DCF Model'!$B$10*(1+'DCF Model'!$B$16)*(1+'DCF Model'!$C$16)*(1+'DCF Model'!$D$16)*(1+'DCF Model'!$D$17)*(1+0.125)^-3 + 'DCF Model'!$B$10*(1+'DCF Model'!$B$16)*(1+'DCF Model'!$C$16)*(1+'DCF Model'!$D$16)*(1+'DCF Model'!$E$16)*(1+'DCF Model'!$E$17)*(1+0.125)^-4 + 'DCF Model'!$B$10*(1+'DCF Model'!$B$16)*(1+'DCF Model'!$C$16)*(1+'DCF Model'!$D$16)*(1+'DCF Model'!$E$16)*(1+'DCF Model'!$F$16)*'DCF Model'!$F$17*(1+0.125)^-5 + ('DCF Model'!$B$10*(1+'DCF Model'!$B$16)*(1+'DCF Model'!$C$16)*(1+'DCF Model'!$D$16)*(1+'DCF Model'!$E$16)*(1+'DCF Model'!$F$16)*'DCF Model'!$F$17*(1+0.035)/(0.125-0.035))*(1+0.125)^-5 - 'DCF Model'!$B$9)/'DCF Model'!$B$6 -> 0
A9: 0.135 | B9: =('DCF Model'!$B$10*(1+'DCF Model'!$B$16)*(1+'DCF Model'!$B$17)*(1+0.135)^-1 + 'DCF Model'!$B$10*(1+'DCF Model'!$B$16)*(1+'DCF Model'!$C$16)*(1+'DCF Model'!$C$17)*(1+0.135)^-2 + 'DCF Model'!$B$10*(1+'DCF Model'!$B$16)*(1+'DCF Model'!$C$16)*(1+'DCF Model'!$D$16)*(1+'DCF Model'!$D$17)*(1+0.135)^-3 + 'DCF Model'!$B$10*(1+'DCF Model'!$B$16)*(1+'DCF Model'!$C$16)*(1+'DCF Model'!$D$16)*(1+'DCF Model'!$E$16)*(1+'DCF Model'!$E$17)*(1+0.135)^-4 + 'DCF Model'!$B$10*(1+'DCF Model'!$B$16)*(1+'DCF Model'!$C$16)*(1+'DCF Model'!$D$16)*(1+'DCF Model'!$E$16)*(1+'DCF Model'!$F$16)*'DCF Model'!$F$17*(1+0.135)^-5 + ('DCF Model'!$B$10*(1+'DCF Model'!$B$16)*(1+'DCF Model'!$C$16)*(1+'DCF Model'!$D$16)*(1+'DCF Model'!$E$16)*(1+'DCF Model'!$F$16)*'DCF Model'!$F$17*(1+0.015)/(0.135-0.015))*(1+0.135)^-5 - 'DCF Model'!$B$9)/'DCF Model'!$B$6 -> 0 | C9: =('DCF Model'!$B$10*(1+'DCF Model'!$B$16)*(1+'DCF Model'!$B$17)*(1+0.135)^-1 + 'DCF Model'!$B$10*(1+'DCF Model'!$B$16)*(1+'DCF Model'!$C$16)*(1+'DCF Model'!$C$17)*(1+0.135)^-2 + 'DCF Model'!$B$10*(1+'DCF Model'!$B$16)*(1+'DCF Model'!$C$16)*(1+'DCF Model'!$D$16)*(1+'DCF Model'!$D$17)*(1+0.135)^-3 + 'DCF Model'!$B$10*(1+'DCF Model'!$B$16)*(1+'DCF Model'!$C$16)*(1+'DCF Model'!$D$16)*(1+'DCF Model'!$E$16)*(1+'DCF Model'!$E$17)*(1+0.135)^-4 + 'DCF Model'!$B$10*(1+'DCF Model'!$B$16)*(1+'DCF Model'!$C$16)*(1+'DCF Model'!$D$16)*(1+'DCF Model'!$E$16)*(1+'DCF Model'!$F$16)*'DCF Model'!$F$17*(1+0.135)^-5 + ('DCF Model'!$B$10*(1+'DCF Model'!$B$16)*(1+'DCF Model'!$C$16)*(1+'DCF Model'!$D$16)*(1+'DCF Model'!$E$16)*(1+'DCF Model'!$F$16)*'DCF Model'!$F$17*(1+0.02)/(0.135-0.02))*(1+0.135)^-5 - 'DCF Model'!$B$9)/'DCF Model'!$B$6 -> 0 | D9: =('DCF Model'!$B$10*(1+'DCF Model'!$B$16)*(1+'DCF Model'!$B$17)*(1+0.135)^-1 + 'DCF Model'!$B$10*(1+'DCF Model'!$B$16)*(1+'DCF Model'!$C$16)*(1+'DCF Model'!$C$17)*(1+0.135)^-2 + 'DCF Model'!$B$10*(1+'DCF Model'!$B$16)*(1+'DCF Model'!$C$16)*(1+'DCF Model'!$D$16)*(1+'DCF Model'!$D$17)*(1+0.135)^-3 + 'DCF Model'!$B$10*(1+'DCF Model'!$B$16)*(1+'DCF Model'!$C$16)*(1+'DCF Model'!$D$16)*(1+'DCF Model'!$E$16)*(1+'DCF Model'!$E$17)*(1+0.135)^-4 + 'DCF Model'!$B$10*(1+'DCF Model'!$B$16)*(1+'DCF Model'!$C$16)*(1+'DCF Model'!$D$16)*(1+'DCF Model'!$E$16)*(1+'DCF Model'!$F$16)*'DCF Model'!$F$17*(1+0.135)^-5 + ('DCF Model'!$B$10*(1+'DCF Model'!$B$16)*(1+'DCF Model'!$C$16)*(1+'DCF Model'!$D$16)*(1+'DCF Model'!$E$16)*(1+'DCF Model'!$F$16)*'DCF Model'!$F$17*(1+0.025)/(0.135-0.025))*(1+0.135)^-5 - 'DCF Model'!$B$9)/'DCF Model'!$B$6 -> 0 | E9: =('DCF Model'!$B$10*(1+'DCF Model'!$B$16)*(1+'DCF Model'!$B$17)*(1+0.135)^-1 + 'DCF Model'!$B$10*(1+'DCF Model'!$B$16)*(1+'DCF Model'!$C$16)*(1+'DCF Model'!$C$17)*(1+0.135)^-2 + 'DCF Model'!$B$10*(1+'DCF Model'!$B$16)*(1+'DCF Model'!$C$16)*(1+'DCF Model'!$D$16)*(1+'DCF Model'!$D$17)*(1+0.135)^-3 + 'DCF Model'!$B$10*(1+'DCF Model'!$B$16)*(1+'DCF Model'!$C$16)*(1+'DCF Model'!$D$16)*(1+'DCF Model'!$E$16)*(1+'DCF Model'!$E$17)*(1+0.135)^-4 + 'DCF Model'!$B$10*(1+'DCF Model'!$B$16)*(1+'DCF Model'!$C$16)*(1+'DCF Model'!$D$16)*(1+'DCF Model'!$E$16)*(1+'DCF Model'!$F$16)*'DCF Model'!$F$17*(1+0.135)^-5 + ('DCF Model'!$B$10*(1+'DCF Model'!$B$16)*(1+'DCF Model'!$C$16)*(1+'DCF Model'!$D$16)*(1+'DCF Model'!$E$16)*(1+'DCF Model'!$F$16)*'DCF Model'!$F$17*(1+0.03)/(0.135-0.03))*(1+0.135)^-5 - 'DCF Model'!$B$9)/'DCF Model'!$B$6 -> 0 | F9: =('DCF Model'!$B$10*(1+'DCF Model'!$B$16)*(1+'DCF Model'!$B$17)*(1+0.135)^-1 + 'DCF Model'!$B$10*(1+'DCF Model'!$B$16)*(1+'DCF Model'!$C$16)*(1+'DCF Model'!$C$17)*(1+0.135)^-2 + 'DCF Model'!$B$10*(1+'DCF Model'!$B$16)*(1+'DCF Model'!$C$16)*(1+'DCF Model'!$D$16)*(1+'DCF Model'!$D$17)*(1+0.135)^-3 + 'DCF Model'!$B$10*(1+'DCF Model'!$B$16)*(1+'DCF Model'!$C$16)*(1+'DCF Model'!$D$16)*(1+'DCF Model'!$E$16)*(1+'DCF Model'!$E$17)*(1+0.135)^-4 + 'DCF Model'!$B$10*(1+'DCF Model'!$B$16)*(1+'DCF Model'!$C$16)*(1+'DCF Model'!$D$16)*(1+'DCF Model'!$E$16)*(1+'DCF Model'!$F$16)*'DCF Model'!$F$17*(1+0.135)^-5 + ('DCF Model'!$B$10*(1+'DCF Model'!$B$16)*(1+'DCF Model'!$C$16)*(1+'DCF Model'!$D$16)*(1+'DCF Model'!$E$16)*(1+'DCF Model'!$F$16)*'DCF Model'!$F$17*(1+0.035)/(0.135-0.035))*(1+0.135)^-5 - 'DCF Model'!$B$9)/'DCF Model'!$B$6 -> 0
A11: Note: matrix recalculates using Base case revenue growth & FCF margin
A12: path from the DCF Model sheet, varying only WACC and terminal growth.

Sheet Historical
A1: Historical Growth Rates
A3: Metric | B3: 3-Year CAGR | C3: 5-Year CAGR
A4: Revenue | B4: 0.188 | C4: 0.236
A5: EPS | B5: n/a | C5: n/a
A6: Equity | B6: 0.242 | C6: n/a
A7: FCF | B7: n/a | C7: n/a
A9: Selected Growth Driver: | B9: 0.105
A10: Source: | B10: revenue_driven_decelerating (management guide + FY2025 actual +14%, Q1-2026 +8% breach-impacted, Q2-2026 guide +9-10% cc)
A12: Growth Divergence Warning:
A13: Equity CAGR (24.2%, 3yr) and revenue CAGR (18.8%, 3yr) are not meaningful as growth drivers here: FY2020 equity was negative (post-IPO recap distortion) so a clean 5yr equity CAGR cannot be computed, EPS CAGR is not meaningful given a 2023 net-income spike from a one-off tax benefit followed by declines, and FCF CAGR is negative/not meaningful because FCF swung from -$1,082M (FY2021) to a $1,775M peak (FY2023, inflated by working-capital tailwinds) down to $527M (FY2025) and -$110M (Q1-2026, data-breach compensation). Given this volatility, the model uses a revenue-driven, decelerating growth path (FY2025 revenue +14%, Q1-2026 +8%, Q2-2026 guided +9-10% cc) combined with an FCF margin that normalizes from the FY2025 trough (1.5%) toward 3.5% mid-term, rather than compounding any single historical CAGR.
A22: Year | B22: Revenue ($M) | C22: FCF ($M) | D22: FCF Margin
A24: FY2021 | B24: 18406.4 | C24: -1082.4 | D24: =C24/B24 -> 0
A25: FY2022 | B25: 20582.6 | C25: -245.6 | D25: =C25/B25 -> 0
A26: FY2023 | B26: 24383 | C26: 1775 | D26: =C26/B26 -> 0
A27: FY2024 | B27: 30268 | C27: 1016 | D27: =C27/B27 -> 0
A28: FY2025 | B28: 34534 | C28: 527 | D28: =C28/B28 -> 0
A29: Q1-2026 | B29: 8504 | C29: -110 | D29: =C29/B29 -> 0
