Workbook

Sheet Deal weighting
A1: Intertek / EQT scheme - deal-weighted valuation (GBp per share)
A2: Headline offer (GBp) | B2: 6107.7
A3: FY2025 final dividend already paid (GBp) | B3: 107.7
A4: Remaining cash consideration (GBp) | B4: =B2-B3
A5: Years to completion (2027-01-31 midpoint) | B5: 0.31
A6: Deal-leg discount rate | B6: 0.05
A7: Hurdle rate | B7: 0.15
A8: PV of consideration at deal rate | B8: =B4/(1+B6)^B5
A9: PV of consideration at hurdle | B9: =B4/(1+B7)^B5
A10: Standalone base IV (engine) | B10: 4626.12
A11: Standalone bear IV (engine) | B11: 3212.28
A12: Standalone bull IV (engine, reference only) | B12: 5347.49
A13: Standalone base entry @ hurdle (engine) | B13: 1442.11
A14: Standalone bear entry @ hurdle (engine) | B14: 1016.99
A15: P(deal completes) | B15: 0.9
A16: Weight base (deal breaks) | B16: 0.07
A17: Weight bear (deal breaks) | B17: 0.03
A18: Weights sum | B18: =B15+B16+B17
A19: DEAL-WEIGHTED IV (GBp) | B19: =B15*B8+B16*B10+B17*B11
A20: Deal-weighted entry price (GBp) | B20: =B15*B9+B16*B13+B17*B14
A21: Current price (GBp) | B21: 5890
A22: Upside vs price | B22: =B19/B21-1
A23: Break value (0.7 base + 0.3 bear) | B23: =0.7*B10+0.3*B11
A24: PV offer at ~4% risk-free | B24: =B4/(1+0.04)^B5
A25: Market-implied completion probability | B25: =(B21-B23)/(B24-B23)
A26: Gross spread to remaining consideration | B26: =B4/B21-1
A27: Annualised spread | B27: =(B4/B21)^(1/B5)-1

Sheet Model_Info
A1: Ticker | B1: ITRK.L
A2: Company | B2: Intertek Group plc
A3: Valuation date | B3: 2026-10-10
A4: Current price | B4: 5890
A5: Price as of | B5: 2026-10-09T16:15:00Z regular close (Yahoo chart API); not an after-hours print
A6: Balance sheet date | B6: 2026-06-30
A7: Model | B7: owner_fcf_dcf_component
A8: Currency (model) | B8: GBP
A9: Currency (quote) | B9: GBp
A10: Units | B10: millions
A11: Engine | B11: dcf_engine v1
A12: Built at | B12: 2026-10-10T00:44:54Z
A13: Drivers file | B13: ITRK.L_Drivers.json
A14: Convention | B14: Percents stored as percents; formulas divide by 100. Blue = input, green = link, black = formula.
A15: Methodology | B15: summary: Standalone owner-FCF DCF leg of a deal-weighted valuation. See ITRK.L_DCF.json valuation_philosophy for the full approach. key_risks_to_valuation: Scheme lapses on regulatory grounds; Consumer-goods sourcing volumes under tariffs; World of Energy cyclicality; Rising leverage (1.4x net debt/EBITDA after the FY2025 buyback)
A16: Data sources | B16: price: Yahoo Finance chart API at inputs.price_as_of; 52-week range 3519-5900 GBp financials: ITRK.L_Metrics.csv (FY2019-FY2025 + half-years) from the FY2019-FY2025 annual reports and the H1 FY2026 half-year report; component lines cited by file:line in inputs.* qualitative: ITRK.L_Analysis.json (2026-10-10); H1 FY2026 half-year report EQT Transaction Update and outlook
... A19: Scenario narrative: bull | B19: Standalone bull, reference leg only (superseded in the shipped DCF by the deal-completes scenario).

Sheet Actuals
A1: Period | B1: Revenue | C1: CostOfRevenue | D1: GrossProfit | E1: GrossMargin | F1: OperatingIncome | G1: OperatingMargin | H1: EBITDA | I1: NetIncome | J1: NetMargin | K1: EPS | L1: OperatingCashFlow | M1: CapEx | N1: FreeCashFlow | O1: ShareholdersEquity | P1: TotalAssets | Q1: TotalLiabilities | R1: TotalDebt | S1: CashAndEquivalents | T1: SharesOutstanding | U1: StockBasedComp | V1: DividendPerShare | W1: EBITDABeforeSignificant | X1: RevenueContinuing | Y1: EBITDAContinuingBeforeSignificant | Z1: EBITContinuingBeforeSignificant | AA1: Units | AB1: Currency | AC1: AdjustedNetIncome | AD1: TotalEquityInclNCI
A2: FY2019 | B2: 2987 | F2: 485.8 | G2: 16.3 | H2: 686.4 | I2: 313.1 | J2: 10.5 | K2: 1.926 | L2: 562.8 | M2: 116.8 | N2: 380 | O2: 955.9 | P2: 2818.4 | Q2: 1833.1 | R2: 856.8 | S2: 227.4 | T2: 162.6 | U2: 21.9 | Z2: 524.2 | AA2: millions | AB2: GBP | AC2: 345.5 | AD2: 985.3
A3: FY2020 | B3: 2741.7 | F3: 378.2 | G3: 13.8 | H3: 580.3 | I3: 247.3 | J3: 9 | K3: 1.524 | L3: 558.8 | M3: 79.8 | N3: 415.7 | O3: 975 | P3: 2615.1 | Q3: 1612.1 | R3: 623.8 | S3: 203.9 | T3: 162.3 | U3: 17.7 | Z3: 427.7 | AA3: millions | AB3: GBP | AC3: 277.3 | AD3: 1003
A4: FY2021 | B4: 2786.3 | F4: 433.2 | G4: 15.5 | H4: 631.8 | I4: 288.1 | J4: 10.3 | K4: 1.779 | L4: 550.2 | M4: 97.1 | N4: 385.2 | O4: 1082 | P4: 3249.7 | Q4: 2135.4 | R4: 999.2 | S4: 265.9 | T4: 161.9 | U4: 18.6 | Z4: 473.9 | AA4: millions | AB4: GBP | AC4: 308.9 | AD4: 1114.3
A5: FY2022 | B5: 3192.9 | F5: 452.4 | G5: 14.2 | H5: 667.7 | I5: 288.8 | J5: 9 | K5: 1.784 | L5: 559.9 | M5: 116.5 | N5: 368.4 | O5: 1284 | P5: 3660.3 | Q5: 2342.3 | R5: 1059.5 | S5: 321.6 | T5: 161.9 | U5: 17.5 | Z5: 520.1 | AA5: millions | AB5: GBP | AC5: 341.8 | AD5: 1318
A6: FY2023 | B6: 3328.7 | F6: 486.2 | G6: 14.6 | H6: 695.7 | I6: 297.4 | J6: 8.9 | K6: 1.834 | L6: 535 | M6: 116.9 | N6: 355.3 | O6: 1323.4 | P6: 3537.9 | Q6: 2177.8 | R6: 909.9 | S6: 299.3 | T6: 162.2 | U6: 21.2 | Z6: 551.1 | AA6: millions | AB6: GBP | AC6: 361.7 | AD6: 1360.1
A7: FY2024 | B7: 3393.2 | F7: 535.7 | G7: 15.8 | H7: 729.7 | I7: 345.4 | J7: 10.2 | K7: 2.127 | L7: 597.1 | M7: 135 | N7: 395.4 | O7: 1401.9 | P7: 3599.3 | Q7: 2154.4 | R7: 842.8 | S7: 343 | T7: 162.4 | U7: 24.4 | Z7: 590.1 | AA7: millions | AB7: GBP | AC7: 390.8 | AD7: 1444.9
A8: FY2025 | B8: 3431.6 | F8: 542.3 | G8: 15.8 | H8: 745.2 | I8: 343.5 | J8: 10 | K8: 2.16 | L8: 536.5 | M8: 144.5 | N8: 327 | O8: 1082.9 | P8: 3761.5 | Q8: 2634 | R8: 1326 | S8: 329.2 | T8: 159 | U8: 24.3 | Z8: 619.6 | AA8: millions | AB8: GBP | AC8: 403.1 | AD8: 1127.5

Sheet Assumptions
A1: Input | B1: Value
A2: Current price (quote currency) | B2: 5890
A3: Shares, final projected (m) | B3: 154.8
A4: Net debt (m, model currency) | B4: 1145.5
A5: Equity bridge total (m, + adds) | B5: -300
A6: Hurdle rate (%) | B6: 15
A7: Base revenue FY0 (m) | B7: 3431.6
A8: FY0 | B8: FY2025
A9: Currency / units | B9: GBP millions
A10: FX rate (model -> quote) | B10: 100
A12: BEAR | C12: FY2026 | D12: FY2027 | E12: FY2028 | F12: FY2029 | G12: FY2030 | H12: FY2031 | I12: FY2032 | J12: FY2033 | K12: FY2034 | L12: FY2035
A13: Revenue growth (%) | C13: 4 | D13: 2 | E13: 2.5 | F13: 3 | G13: 3 | H13: 3 | I13: 2.5 | J13: 2.5 | K13: 2.5 | L13: 2
A14: EBITDA margin (%) | C14: 22.8 | D14: 22.4 | E14: 22.4 | F14: 22.6 | G14: 22.8 | H14: 23 | I14: 23 | J14: 23 | K14: 23 | L14: 23
A15: SBC (% of revenue) | C15: 1 | D15: 1 | E15: 1 | F15: 1 | G15: 1 | H15: 1 | I15: 1 | J15: 1 | K15: 1 | L15: 1
A16: Lease cost (% of revenue) | C16: 2.6 | D16: 2.6 | E16: 2.6 | F16: 2.6 | G16: 2.6 | H16: 2.6 | I16: 2.6 | J16: 2.6 | K16: 2.6 | L16: 2.6
A17: D&A (% of revenue) | C17: 2.6 | D17: 2.6 | E17: 2.6 | F17: 2.6 | G17: 2.6 | H17: 2.6 | I17: 2.6 | J17: 2.6 | K17: 2.6 | L17: 2.6
A18: Capex (% of revenue) | C18: 4.3 | D18: 4.2 | E18: 4.2 | F18: 4.2 | G18: 4.2 | H18: 4.2 | I18: 4.2 | J18: 4.2 | K18: 4.2 | L18: 4.2
A19: Cash tax rate (%) | C19: 26 | D19: 26 | E19: 26 | F19: 26 | G19: 26 | H19: 26 | I19: 26 | J19: 26 | K19: 26 | L19: 26
A20: WACC (%) | B20: 8
A21: Terminal growth (%) | B21: 2
A22: Terminal cap multiple (x FCF) | B22: 16
A23: Working-capital capture (% of revenue change) | B23: 0
A24: Scenario weight | B24: 0.15
A26: BASE | C26: FY2026 | D26: FY2027 | E26: FY2028 | F26: FY2029 | G26: FY2030 | H26: FY2031 | I26: FY2032 | J26: FY2033 | K26: FY2034 | L26: FY2035
A27: Revenue growth (%) | C27: 5.5 | D27: 5 | E27: 5 | F27: 4.5 | G27: 4.5 | H27: 4 | I27: 3.5 | J27: 3 | K27: 3 | L27: 2.5
A28: EBITDA margin (%) | C28: 23.2 | D28: 23.5 | E28: 23.8 | F28: 24 | G28: 24.2 | H28: 24.3 | I28: 24.4 | J28: 24.5 | K28: 24.5 | L28: 24.5
A29: SBC (% of revenue) | C29: 1 | D29: 1 | E29: 1 | F29: 1 | G29: 1 | H29: 1 | I29: 1 | J29: 1 | K29: 1 | L29: 1
A30: Lease cost (% of revenue) | C30: 2.6 | D30: 2.6 | E30: 2.6 | F30: 2.6 | G30: 2.6 | H30: 2.6 | I30: 2.6 | J30: 2.6 | K30: 2.6 | L30: 2.6
A31: D&A (% of revenue) | C31: 2.6 | D31: 2.6 | E31: 2.6 | F31: 2.6 | G31: 2.6 | H31: 2.6 | I31: 2.6 | J31: 2.6 | K31: 2.6 | L31: 2.6
A32: Capex (% of revenue) | C32: 4.3 | D32: 4.2 | E32: 4.2 | F32: 4.2 | G32: 4.2 | H32: 4.2 | I32: 4.2 | J32: 4.2 | K32: 4.2 | L32: 4.2
A33: Cash tax rate (%) | C33: 26 | D33: 26 | E33: 26 | F33: 26 | G33: 26 | H33: 26 | I33: 26 | J33: 26 | K33: 26 | L33: 26
A34: WACC (%) | B34: 8
A35: Terminal growth (%) | B35: 2.5
A36: Terminal cap multiple (x FCF) | B36: 20
A37: Working-capital capture (% of revenue change) | B37: 0
A38: Scenario weight | B38: 0.5
A40: BULL | C40: FY2026 | D40: FY2027 | E40: FY2028 | F40: FY2029 | G40: FY2030 | H40: FY2031 | I40: FY2032 | J40: FY2033 | K40: FY2034 | L40: FY2035
A41: Revenue growth (%) | C41: 6 | D41: 6 | E41: 5.5 | F41: 5.5 | G41: 5 | H41: 4.5 | I41: 4 | J41: 3.5 | K41: 3 | L41: 3
A42: EBITDA margin (%) | C42: 23.4 | D42: 23.9 | E42: 24.4 | F42: 24.8 | G42: 25.2 | H42: 25.5 | I42: 25.7 | J42: 25.9 | K42: 26 | L42: 26
A43: SBC (% of revenue) | C43: 1 | D43: 1 | E43: 1 | F43: 1 | G43: 1 | H43: 1 | I43: 1 | J43: 1 | K43: 1 | L43: 1
...

Sheet DCF_Bear
A1: ITRK.L owner-FCF component DCF: bear case (millions, GBP)
A3: Line | B3: FY2025 | C3: FY2026 | D3: FY2027 | E3: FY2028 | F3: FY2029 | G3: FY2030 | H3: FY2031 | I3: FY2032 | J3: FY2033 | K3: FY2034 | L3: FY2035
A4: Year index (discount exponent) | B4: 0 | C4: =B4+1 | D4: =C4+1 | E4: =D4+1 | F4: =E4+1 | G4: =F4+1 | H4: =G4+1 | I4: =H4+1 | J4: =I4+1 | ... L4: =K4+1
A5: Revenue growth (%) | C5: =Assumptions!C13 | D5: =Assumptions!D13 | E5: =Assumptions!E13 | F5: =Assumptions!F13 | G5: =Assumptions!G13 | H5: =Assumptions!H13 | I5: =Assumptions!I13 | J5: =Assumptions!J13 | ... L5: =Assumptions!L13
A6: Revenue | B6: 3431.6 | C6: =B6*(1+C5/100) | D6: =C6*(1+D5/100) | E6: =D6*(1+E5/100) | F6: =E6*(1+F5/100) | G6: =F6*(1+G5/100) | H6: =G6*(1+H5/100) | I6: =H6*(1+I5/100) | J6: =I6*(1+J5/100) | ... L6: =K6*(1+L5/100)
A7: EBITDA margin (%) | C7: =Assumptions!C14 | D7: =Assumptions!D14 | E7: =Assumptions!E14 | F7: =Assumptions!F14 | G7: =Assumptions!G14 | H7: =Assumptions!H14 | I7: =Assumptions!I14 | J7: =Assumptions!J14 | ... L7: =Assumptions!L14
A8: EBITDA | C8: =C6*C7/100 | D8: =D6*D7/100 | E8: =E6*E7/100 | F8: =F6*F7/100 | G8: =G6*G7/100 | H8: =H6*H7/100 | I8: =I6*I7/100 | J8: =J6*J7/100 | ... L8: =L6*L7/100
A9: SBC (% of revenue) | C9: =Assumptions!C15 | D9: =Assumptions!D15 | E9: =Assumptions!E15 | F9: =Assumptions!F15 | G9: =Assumptions!G15 | H9: =Assumptions!H15 | I9: =Assumptions!I15 | J9: =Assumptions!J15 | ... L9: =Assumptions!L15
A10: SBC charge | C10: =-C6*C9/100 | D10: =-D6*D9/100 | E10: =-E6*E9/100 | F10: =-F6*F9/100 | G10: =-G6*G9/100 | H10: =-H6*H9/100 | I10: =-I6*I9/100 | J10: =-J6*J9/100 | ... L10: =-L6*L9/100
A11: Owner EBITDA (after SBC and leases) | C11: =C8+C10+C24 | D11: =D8+D10+D24 | E11: =E8+E10+E24 | F11: =F8+F10+F24 | G11: =G8+G10+G24 | H11: =H8+H10+H24 | I11: =I8+I10+I24 | J11: =J8+J10+J24 | ... L11: =L8+L10+L24
A12: D&A | C12: =-C6*Assumptions!C17/100 | D12: =-D6*Assumptions!D17/100 | E12: =-E6*Assumptions!E17/100 | F12: =-F6*Assumptions!F17/100 | G12: =-G6*Assumptions!G17/100 | H12: =-H6*Assumptions!H17/100 | I12: =-I6*Assumptions!I17/100 | J12: =-J6*Assumptions!J17/100 | ... L12: =-L6*Assumptions!L17/100
A13: EBIT | C13: =C11+C12 | D13: =D11+D12 | E13: =E11+E12 | F13: =F11+F12 | G13: =G11+G12 | H13: =H11+H12 | I13: =I11+I12 | J13: =J11+J12 | ... L13: =L11+L12
A14: Cash tax rate (%) | C14: =Assumptions!C19 | D14: =Assumptions!D19 | E14: =Assumptions!E19 | F14: =Assumptions!F19 | G14: =Assumptions!G19 | H14: =Assumptions!H19 | I14: =Assumptions!I19 | J14: =Assumptions!J19 | ... L14: =Assumptions!L19
A15: NOPAT | C15: =C13-MAX(0,C13)*C14/100 | D15: =D13-MAX(0,D13)*D14/100 | E15: =E13-MAX(0,E13)*E14/100 | F15: =F13-MAX(0,F13)*F14/100 | G15: =G13-MAX(0,G13)*G14/100 | H15: =H13-MAX(0,H13)*H14/100 | I15: =I13-MAX(0,I13)*I14/100 | J15: =J13-MAX(0,J13)*J14/100 | ... L15: =L13-MAX(0,L13)*L14/100
A16: D&A add-back | C16: =-C12 | D16: =-D12 | E16: =-E12 | F16: =-F12 | G16: =-G12 | H16: =-H12 | I16: =-I12 | J16: =-J12 | ... L16: =-L12
A17: Capex | C17: =-C6*Assumptions!C18/100 | D17: =-D6*Assumptions!D18/100 | E17: =-E6*Assumptions!E18/100 | F17: =-F6*Assumptions!F18/100 | G17: =-G6*Assumptions!G18/100 | H17: =-H6*Assumptions!H18/100 | I17: =-I6*Assumptions!I18/100 | J17: =-J6*Assumptions!J18/100 | ... L17: =-L6*Assumptions!L18/100
A18: Working capital | C18: =(C6-B6)*Assumptions!$B$23/100 | D18: =(D6-C6)*Assumptions!$B$23/100 | E18: =(E6-D6)*Assumptions!$B$23/100 | F18: =(F6-E6)*Assumptions!$B$23/100 | G18: =(G6-F6)*Assumptions!$B$23/100 | H18: =(H6-G6)*Assumptions!$B$23/100 | I18: =(I6-H6)*Assumptions!$B$23/100 | J18: =(J6-I6)*Assumptions!$B$23/100 | ... L18: =(L6-K6)*Assumptions!$B$23/100
A19: Unlevered owner FCF | C19: =C15+C16+C17+C18 | D19: =D15+D16+D17+D18 | E19: =E15+E16+E17+E18 | F19: =F15+F16+F17+F18 | G19: =G15+G16+G17+G18 | H19: =H15+H16+H17+H18 | I19: =I15+I16+I17+I18 | J19: =J15+J16+J17+J18 | ... L19: =L15+L16+L17+L18
A20: Discount factor | C20: =1/(1+$B$27/100)^C4 | D20: =1/(1+$B$27/100)^D4 | E20: =1/(1+$B$27/100)^E4 | F20: =1/(1+$B$27/100)^F4 | G20: =1/(1+$B$27/100)^G4 | H20: =1/(1+$B$27/100)^H4 | I20: =1/(1+$B$27/100)^I4 | J20: =1/(1+$B$27/100)^J4 | ... L20: =1/(1+$B$27/100)^L4
A21: PV of FCF | C21: =C19*C20 | D21: =D19*D20 | E21: =E19*E20 | F21: =F19*F20 | G21: =G19*G20 | H21: =H19*H20 | I21: =I19*I20 | J21: =J19*J20 | ... L21: =L19*L20
A23: Lease cost (% of revenue) | C23: =Assumptions!C16 | D23: =Assumptions!D16 | E23: =Assumptions!E16 | F23: =Assumptions!F16 | G23: =Assumptions!G16 | H23: =Assumptions!H16 | I23: =Assumptions!I16 | J23: =Assumptions!J16 | ... L23: =Assumptions!L16
A24: Lease cost | C24: =-C6*C23/100 | D24: =-D6*D23/100 | E24: =-E6*E23/100 | F24: =-F6*F23/100 | G24: =-G6*G23/100 | H24: =-H6*H23/100 | I24: =-I6*I23/100 | J24: =-J6*J23/100 | ... L24: =-L6*L23/100
A26: Valuation
A27: WACC (%) | B27: =Assumptions!$B$20
A28: Terminal growth (%) | B28: =Assumptions!$B$21
A29: Terminal cap multiple (x FCF) | B29: =Assumptions!$B$22
A30: Sum of PV of FCF | B30: =SUM(C21:L21)
A31: Terminal-year FCF | B31: =L19
A32: Gordon terminal value | B32: =IF(B27>B28,B31*(1+B28/100)/((B27-B28)/100),B31*B29)
A33: Cap terminal value | B33: =B31*B29
A34: Terminal value used: MAX(0,MIN(Gordon,cap)) | B34: =MAX(0,MIN(B32,B33))
A35: PV of terminal value | B35: =B34/(1+B27/100)^L4
A36: Enterprise value | B36: =B30+B35
A37: Equity value (EV + bridge - net debt) | B37: =B36+Assumptions!$B$5-Assumptions!$B$4
A38: Value per share (quote currency) | B38: =B37/Assumptions!$B$3*Assumptions!$B$10
A39: Upside vs price | B39: =B38/Assumptions!$B$2-1
A41: Street memo: PV of explicit-period SBC | B41: =SUMPRODUCT(-C10:L10/(1+$B$27/100)^C4:L4)
A42: Street memo: PV of terminal SBC (Gordon) | B42: =IF(B27>B28,-L10*(1+B28/100)/((B27-B28)/100),-L10*20)/(1+B27/100)^L4
A43: Street value per share | B43: =(B37+B41+B42)/Assumptions!$B$3*Assumptions!$B$10
A45: Hurdle rate (%) | B45: =Assumptions!$B$6
...

Sheet DCF_Base
A1: ITRK.L owner-FCF component DCF: base case (millions, GBP)
A3: Line | B3: FY2025 | C3: FY2026 | D3: FY2027 | E3: FY2028 | F3: FY2029 | G3: FY2030 | H3: FY2031 | I3: FY2032 | J3: FY2033 | K3: FY2034 | L3: FY2035
A4: Year index (discount exponent) | B4: 0 | C4: =B4+1 | D4: =C4+1 | E4: =D4+1 | F4: =E4+1 | G4: =F4+1 | H4: =G4+1 | I4: =H4+1 | J4: =I4+1 | ... L4: =K4+1
A5: Revenue growth (%) | C5: =Assumptions!C27 | D5: =Assumptions!D27 | E5: =Assumptions!E27 | F5: =Assumptions!F27 | G5: =Assumptions!G27 | H5: =Assumptions!H27 | I5: =Assumptions!I27 | J5: =Assumptions!J27 | ... L5: =Assumptions!L27
A6: Revenue | B6: 3431.6 | C6: =B6*(1+C5/100) | D6: =C6*(1+D5/100) | E6: =D6*(1+E5/100) | F6: =E6*(1+F5/100) | G6: =F6*(1+G5/100) | H6: =G6*(1+H5/100) | I6: =H6*(1+I5/100) | J6: =I6*(1+J5/100) | ... L6: =K6*(1+L5/100)
A7: EBITDA margin (%) | C7: =Assumptions!C28 | D7: =Assumptions!D28 | E7: =Assumptions!E28 | F7: =Assumptions!F28 | G7: =Assumptions!G28 | H7: =Assumptions!H28 | I7: =Assumptions!I28 | J7: =Assumptions!J28 | ... L7: =Assumptions!L28
A8: EBITDA | C8: =C6*C7/100 | D8: =D6*D7/100 | E8: =E6*E7/100 | F8: =F6*F7/100 | G8: =G6*G7/100 | H8: =H6*H7/100 | I8: =I6*I7/100 | J8: =J6*J7/100 | ... L8: =L6*L7/100
A9: SBC (% of revenue) | C9: =Assumptions!C29 | D9: =Assumptions!D29 | E9: =Assumptions!E29 | F9: =Assumptions!F29 | G9: =Assumptions!G29 | H9: =Assumptions!H29 | I9: =Assumptions!I29 | J9: =Assumptions!J29 | ... L9: =Assumptions!L29
A10: SBC charge | C10: =-C6*C9/100 | D10: =-D6*D9/100 | E10: =-E6*E9/100 | F10: =-F6*F9/100 | G10: =-G6*G9/100 | H10: =-H6*H9/100 | I10: =-I6*I9/100 | J10: =-J6*J9/100 | ... L10: =-L6*L9/100
A11: Owner EBITDA (after SBC and leases) | C11: =C8+C10+C24 | D11: =D8+D10+D24 | E11: =E8+E10+E24 | F11: =F8+F10+F24 | G11: =G8+G10+G24 | H11: =H8+H10+H24 | I11: =I8+I10+I24 | J11: =J8+J10+J24 | ... L11: =L8+L10+L24
A12: D&A | C12: =-C6*Assumptions!C31/100 | D12: =-D6*Assumptions!D31/100 | E12: =-E6*Assumptions!E31/100 | F12: =-F6*Assumptions!F31/100 | G12: =-G6*Assumptions!G31/100 | H12: =-H6*Assumptions!H31/100 | I12: =-I6*Assumptions!I31/100 | J12: =-J6*Assumptions!J31/100 | ... L12: =-L6*Assumptions!L31/100
A13: EBIT | C13: =C11+C12 | D13: =D11+D12 | E13: =E11+E12 | F13: =F11+F12 | G13: =G11+G12 | H13: =H11+H12 | I13: =I11+I12 | J13: =J11+J12 | ... L13: =L11+L12
A14: Cash tax rate (%) | C14: =Assumptions!C33 | D14: =Assumptions!D33 | E14: =Assumptions!E33 | F14: =Assumptions!F33 | G14: =Assumptions!G33 | H14: =Assumptions!H33 | I14: =Assumptions!I33 | J14: =Assumptions!J33 | ... L14: =Assumptions!L33
A15: NOPAT | C15: =C13-MAX(0,C13)*C14/100 | D15: =D13-MAX(0,D13)*D14/100 | E15: =E13-MAX(0,E13)*E14/100 | F15: =F13-MAX(0,F13)*F14/100 | G15: =G13-MAX(0,G13)*G14/100 | H15: =H13-MAX(0,H13)*H14/100 | I15: =I13-MAX(0,I13)*I14/100 | J15: =J13-MAX(0,J13)*J14/100 | ... L15: =L13-MAX(0,L13)*L14/100
A16: D&A add-back | C16: =-C12 | D16: =-D12 | E16: =-E12 | F16: =-F12 | G16: =-G12 | H16: =-H12 | I16: =-I12 | J16: =-J12 | ... L16: =-L12
A17: Capex | C17: =-C6*Assumptions!C32/100 | D17: =-D6*Assumptions!D32/100 | E17: =-E6*Assumptions!E32/100 | F17: =-F6*Assumptions!F32/100 | G17: =-G6*Assumptions!G32/100 | H17: =-H6*Assumptions!H32/100 | I17: =-I6*Assumptions!I32/100 | J17: =-J6*Assumptions!J32/100 | ... L17: =-L6*Assumptions!L32/100
A18: Working capital | C18: =(C6-B6)*Assumptions!$B$37/100 | D18: =(D6-C6)*Assumptions!$B$37/100 | E18: =(E6-D6)*Assumptions!$B$37/100 | F18: =(F6-E6)*Assumptions!$B$37/100 | G18: =(G6-F6)*Assumptions!$B$37/100 | H18: =(H6-G6)*Assumptions!$B$37/100 | I18: =(I6-H6)*Assumptions!$B$37/100 | J18: =(J6-I6)*Assumptions!$B$37/100 | ... L18: =(L6-K6)*Assumptions!$B$37/100
A19: Unlevered owner FCF | C19: =C15+C16+C17+C18 | D19: =D15+D16+D17+D18 | E19: =E15+E16+E17+E18 | F19: =F15+F16+F17+F18 | G19: =G15+G16+G17+G18 | H19: =H15+H16+H17+H18 | I19: =I15+I16+I17+I18 | J19: =J15+J16+J17+J18 | ... L19: =L15+L16+L17+L18
A20: Discount factor | C20: =1/(1+$B$27/100)^C4 | D20: =1/(1+$B$27/100)^D4 | E20: =1/(1+$B$27/100)^E4 | F20: =1/(1+$B$27/100)^F4 | G20: =1/(1+$B$27/100)^G4 | H20: =1/(1+$B$27/100)^H4 | I20: =1/(1+$B$27/100)^I4 | J20: =1/(1+$B$27/100)^J4 | ... L20: =1/(1+$B$27/100)^L4
A21: PV of FCF | C21: =C19*C20 | D21: =D19*D20 | E21: =E19*E20 | F21: =F19*F20 | G21: =G19*G20 | H21: =H19*H20 | I21: =I19*I20 | J21: =J19*J20 | ... L21: =L19*L20
A23: Lease cost (% of revenue) | C23: =Assumptions!C30 | D23: =Assumptions!D30 | E23: =Assumptions!E30 | F23: =Assumptions!F30 | G23: =Assumptions!G30 | H23: =Assumptions!H30 | I23: =Assumptions!I30 | J23: =Assumptions!J30 | ... L23: =Assumptions!L30
A24: Lease cost | C24: =-C6*C23/100 | D24: =-D6*D23/100 | E24: =-E6*E23/100 | F24: =-F6*F23/100 | G24: =-G6*G23/100 | H24: =-H6*H23/100 | I24: =-I6*I23/100 | J24: =-J6*J23/100 | ... L24: =-L6*L23/100
A26: Valuation
A27: WACC (%) | B27: =Assumptions!$B$34
A28: Terminal growth (%) | B28: =Assumptions!$B$35
A29: Terminal cap multiple (x FCF) | B29: =Assumptions!$B$36
A30: Sum of PV of FCF | B30: =SUM(C21:L21)
A31: Terminal-year FCF | B31: =L19
A32: Gordon terminal value | B32: =IF(B27>B28,B31*(1+B28/100)/((B27-B28)/100),B31*B29)
A33: Cap terminal value | B33: =B31*B29
A34: Terminal value used: MAX(0,MIN(Gordon,cap)) | B34: =MAX(0,MIN(B32,B33))
A35: PV of terminal value | B35: =B34/(1+B27/100)^L4
A36: Enterprise value | B36: =B30+B35
A37: Equity value (EV + bridge - net debt) | B37: =B36+Assumptions!$B$5-Assumptions!$B$4
A38: Value per share (quote currency) | B38: =B37/Assumptions!$B$3*Assumptions!$B$10
A39: Upside vs price | B39: =B38/Assumptions!$B$2-1
A41: Street memo: PV of explicit-period SBC | B41: =SUMPRODUCT(-C10:L10/(1+$B$27/100)^C4:L4)
A42: Street memo: PV of terminal SBC (Gordon) | B42: =IF(B27>B28,-L10*(1+B28/100)/((B27-B28)/100),-L10*20)/(1+B27/100)^L4
A43: Street value per share | B43: =(B37+B41+B42)/Assumptions!$B$3*Assumptions!$B$10
A45: Hurdle rate (%) | B45: =Assumptions!$B$6
...

Sheet DCF_Bull
A1: ITRK.L owner-FCF component DCF: bull case (millions, GBP)
A3: Line | B3: FY2025 | C3: FY2026 | D3: FY2027 | E3: FY2028 | F3: FY2029 | G3: FY2030 | H3: FY2031 | I3: FY2032 | J3: FY2033 | K3: FY2034 | L3: FY2035
A4: Year index (discount exponent) | B4: 0 | C4: =B4+1 | D4: =C4+1 | E4: =D4+1 | F4: =E4+1 | G4: =F4+1 | H4: =G4+1 | I4: =H4+1 | J4: =I4+1 | ... L4: =K4+1
A5: Revenue growth (%) | C5: =Assumptions!C41 | D5: =Assumptions!D41 | E5: =Assumptions!E41 | F5: =Assumptions!F41 | G5: =Assumptions!G41 | H5: =Assumptions!H41 | I5: =Assumptions!I41 | J5: =Assumptions!J41 | ... L5: =Assumptions!L41
A6: Revenue | B6: 3431.6 | C6: =B6*(1+C5/100) | D6: =C6*(1+D5/100) | E6: =D6*(1+E5/100) | F6: =E6*(1+F5/100) | G6: =F6*(1+G5/100) | H6: =G6*(1+H5/100) | I6: =H6*(1+I5/100) | J6: =I6*(1+J5/100) | ... L6: =K6*(1+L5/100)
A7: EBITDA margin (%) | C7: =Assumptions!C42 | D7: =Assumptions!D42 | E7: =Assumptions!E42 | F7: =Assumptions!F42 | G7: =Assumptions!G42 | H7: =Assumptions!H42 | I7: =Assumptions!I42 | J7: =Assumptions!J42 | ... L7: =Assumptions!L42
A8: EBITDA | C8: =C6*C7/100 | D8: =D6*D7/100 | E8: =E6*E7/100 | F8: =F6*F7/100 | G8: =G6*G7/100 | H8: =H6*H7/100 | I8: =I6*I7/100 | J8: =J6*J7/100 | ... L8: =L6*L7/100
A9: SBC (% of revenue) | C9: =Assumptions!C43 | D9: =Assumptions!D43 | E9: =Assumptions!E43 | F9: =Assumptions!F43 | G9: =Assumptions!G43 | H9: =Assumptions!H43 | I9: =Assumptions!I43 | J9: =Assumptions!J43 | ... L9: =Assumptions!L43
A10: SBC charge | C10: =-C6*C9/100 | D10: =-D6*D9/100 | E10: =-E6*E9/100 | F10: =-F6*F9/100 | G10: =-G6*G9/100 | H10: =-H6*H9/100 | I10: =-I6*I9/100 | J10: =-J6*J9/100 | ... L10: =-L6*L9/100
A11: Owner EBITDA (after SBC and leases) | C11: =C8+C10+C24 | D11: =D8+D10+D24 | E11: =E8+E10+E24 | F11: =F8+F10+F24 | G11: =G8+G10+G24 | H11: =H8+H10+H24 | I11: =I8+I10+I24 | J11: =J8+J10+J24 | ... L11: =L8+L10+L24
A12: D&A | C12: =-C6*Assumptions!C45/100 | D12: =-D6*Assumptions!D45/100 | E12: =-E6*Assumptions!E45/100 | F12: =-F6*Assumptions!F45/100 | G12: =-G6*Assumptions!G45/100 | H12: =-H6*Assumptions!H45/100 | I12: =-I6*Assumptions!I45/100 | J12: =-J6*Assumptions!J45/100 | ... L12: =-L6*Assumptions!L45/100
A13: EBIT | C13: =C11+C12 | D13: =D11+D12 | E13: =E11+E12 | F13: =F11+F12 | G13: =G11+G12 | H13: =H11+H12 | I13: =I11+I12 | J13: =J11+J12 | ... L13: =L11+L12
A14: Cash tax rate (%) | C14: =Assumptions!C47 | D14: =Assumptions!D47 | E14: =Assumptions!E47 | F14: =Assumptions!F47 | G14: =Assumptions!G47 | H14: =Assumptions!H47 | I14: =Assumptions!I47 | J14: =Assumptions!J47 | ... L14: =Assumptions!L47
A15: NOPAT | C15: =C13-MAX(0,C13)*C14/100 | D15: =D13-MAX(0,D13)*D14/100 | E15: =E13-MAX(0,E13)*E14/100 | F15: =F13-MAX(0,F13)*F14/100 | G15: =G13-MAX(0,G13)*G14/100 | H15: =H13-MAX(0,H13)*H14/100 | I15: =I13-MAX(0,I13)*I14/100 | J15: =J13-MAX(0,J13)*J14/100 | ... L15: =L13-MAX(0,L13)*L14/100
A16: D&A add-back | C16: =-C12 | D16: =-D12 | E16: =-E12 | F16: =-F12 | G16: =-G12 | H16: =-H12 | I16: =-I12 | J16: =-J12 | ... L16: =-L12
A17: Capex | C17: =-C6*Assumptions!C46/100 | D17: =-D6*Assumptions!D46/100 | E17: =-E6*Assumptions!E46/100 | F17: =-F6*Assumptions!F46/100 | G17: =-G6*Assumptions!G46/100 | H17: =-H6*Assumptions!H46/100 | I17: =-I6*Assumptions!I46/100 | J17: =-J6*Assumptions!J46/100 | ... L17: =-L6*Assumptions!L46/100
A18: Working capital | C18: =(C6-B6)*Assumptions!$B$51/100 | D18: =(D6-C6)*Assumptions!$B$51/100 | E18: =(E6-D6)*Assumptions!$B$51/100 | F18: =(F6-E6)*Assumptions!$B$51/100 | G18: =(G6-F6)*Assumptions!$B$51/100 | H18: =(H6-G6)*Assumptions!$B$51/100 | I18: =(I6-H6)*Assumptions!$B$51/100 | J18: =(J6-I6)*Assumptions!$B$51/100 | ... L18: =(L6-K6)*Assumptions!$B$51/100
A19: Unlevered owner FCF | C19: =C15+C16+C17+C18 | D19: =D15+D16+D17+D18 | E19: =E15+E16+E17+E18 | F19: =F15+F16+F17+F18 | G19: =G15+G16+G17+G18 | H19: =H15+H16+H17+H18 | I19: =I15+I16+I17+I18 | J19: =J15+J16+J17+J18 | ... L19: =L15+L16+L17+L18
A20: Discount factor | C20: =1/(1+$B$27/100)^C4 | D20: =1/(1+$B$27/100)^D4 | E20: =1/(1+$B$27/100)^E4 | F20: =1/(1+$B$27/100)^F4 | G20: =1/(1+$B$27/100)^G4 | H20: =1/(1+$B$27/100)^H4 | I20: =1/(1+$B$27/100)^I4 | J20: =1/(1+$B$27/100)^J4 | ... L20: =1/(1+$B$27/100)^L4
A21: PV of FCF | C21: =C19*C20 | D21: =D19*D20 | E21: =E19*E20 | F21: =F19*F20 | G21: =G19*G20 | H21: =H19*H20 | I21: =I19*I20 | J21: =J19*J20 | ... L21: =L19*L20
A23: Lease cost (% of revenue) | C23: =Assumptions!C44 | D23: =Assumptions!D44 | E23: =Assumptions!E44 | F23: =Assumptions!F44 | G23: =Assumptions!G44 | H23: =Assumptions!H44 | I23: =Assumptions!I44 | J23: =Assumptions!J44 | ... L23: =Assumptions!L44
A24: Lease cost | C24: =-C6*C23/100 | D24: =-D6*D23/100 | E24: =-E6*E23/100 | F24: =-F6*F23/100 | G24: =-G6*G23/100 | H24: =-H6*H23/100 | I24: =-I6*I23/100 | J24: =-J6*J23/100 | ... L24: =-L6*L23/100
A26: Valuation
A27: WACC (%) | B27: =Assumptions!$B$48
A28: Terminal growth (%) | B28: =Assumptions!$B$49
A29: Terminal cap multiple (x FCF) | B29: =Assumptions!$B$50
A30: Sum of PV of FCF | B30: =SUM(C21:L21)
A31: Terminal-year FCF | B31: =L19
A32: Gordon terminal value | B32: =IF(B27>B28,B31*(1+B28/100)/((B27-B28)/100),B31*B29)
A33: Cap terminal value | B33: =B31*B29
A34: Terminal value used: MAX(0,MIN(Gordon,cap)) | B34: =MAX(0,MIN(B32,B33))
A35: PV of terminal value | B35: =B34/(1+B27/100)^L4
A36: Enterprise value | B36: =B30+B35
A37: Equity value (EV + bridge - net debt) | B37: =B36+Assumptions!$B$5-Assumptions!$B$4
A38: Value per share (quote currency) | B38: =B37/Assumptions!$B$3*Assumptions!$B$10
A39: Upside vs price | B39: =B38/Assumptions!$B$2-1
A41: Street memo: PV of explicit-period SBC | B41: =SUMPRODUCT(-C10:L10/(1+$B$27/100)^C4:L4)
A42: Street memo: PV of terminal SBC (Gordon) | B42: =IF(B27>B28,-L10*(1+B28/100)/((B27-B28)/100),-L10*20)/(1+B27/100)^L4
A43: Street value per share | B43: =(B37+B41+B42)/Assumptions!$B$3*Assumptions!$B$10
A45: Hurdle rate (%) | B45: =Assumptions!$B$6
...

Sheet Valuation
A1: ITRK.L valuation summary
A3: Scenario | B3: Value per share | C3: Upside vs price | D3: Weight | E3: Street value per share | F3: Hurdle entry price
A4: Bear | B4: =DCF_Bear!$B$38 | C4: =B4/Assumptions!$B$2-1 | D4: =Assumptions!$B$24 | E4: =DCF_Bear!$B$43 | F4: =DCF_Bear!$B$47
A5: Base | B5: =DCF_Base!$B$38 | C5: =B5/Assumptions!$B$2-1 | D5: =Assumptions!$B$38 | E5: =DCF_Base!$B$43 | F5: =DCF_Base!$B$47
A6: Bull | B6: =DCF_Bull!$B$38 | C6: =B6/Assumptions!$B$2-1 | D6: =Assumptions!$B$52 | E6: =DCF_Bull!$B$43 | F6: =DCF_Bull!$B$47
A8: Probability-weighted value per share | B8: =SUMPRODUCT(B4:B6,D4:D6)
A9: Street weighted value per share | B9: =SUMPRODUCT(E4:E6,D4:D6)
A10: Margin of safety (1 - price/weighted) | B10: =1-Assumptions!$B$2/B8
A11: Band position (%; 0 = house, 100 = street) | B11: =IF(ABS(B9-B8)>0.01*ABS(B8),(Assumptions!$B$2-B8)/(B9-B8)*100,"n/a")
A12: Weighted 15% hurdle entry price | B12: =SUMPRODUCT(F4:F6,D4:D6)
A14: Required-return table (base case; each row rebuilds its own terminal value) | C14: Rate (%)
A15: Value per share at 8% (WACC) | B15: =(SUMPRODUCT(DCF_Base!$C$19:$L$19/(1+$C$15/100)^DCF_Base!$C$4:$L$4)+MAX(0,MIN(IF($C$15>DCF_Base!$B$28,DCF_Base!$L$19*(1+DCF_Base!$B$28/100)/(($C$15-DCF_Base!$B$28)/100),DCF_Base!$L$19*DCF_Base!$B$29),DCF_Base!$L$19*DCF_Base!$B$29))/(1+$C$15/100)^DCF_Base!$L$4+Assumptions!$B$5-Assumptions!$B$4)/Assumptions!$B$3*Assumptions!$B$10 | C15: 8
A16: Value per share at 9% | B16: =(SUMPRODUCT(DCF_Base!$C$19:$L$19/(1+$C$16/100)^DCF_Base!$C$4:$L$4)+MAX(0,MIN(IF($C$16>DCF_Base!$B$28,DCF_Base!$L$19*(1+DCF_Base!$B$28/100)/(($C$16-DCF_Base!$B$28)/100),DCF_Base!$L$19*DCF_Base!$B$29),DCF_Base!$L$19*DCF_Base!$B$29))/(1+$C$16/100)^DCF_Base!$L$4+Assumptions!$B$5-Assumptions!$B$4)/Assumptions!$B$3*Assumptions!$B$10 | C16: 9
A17: Value per share at 10% | B17: =(SUMPRODUCT(DCF_Base!$C$19:$L$19/(1+$C$17/100)^DCF_Base!$C$4:$L$4)+MAX(0,MIN(IF($C$17>DCF_Base!$B$28,DCF_Base!$L$19*(1+DCF_Base!$B$28/100)/(($C$17-DCF_Base!$B$28)/100),DCF_Base!$L$19*DCF_Base!$B$29),DCF_Base!$L$19*DCF_Base!$B$29))/(1+$C$17/100)^DCF_Base!$L$4+Assumptions!$B$5-Assumptions!$B$4)/Assumptions!$B$3*Assumptions!$B$10 | C17: 10
A18: Value per share at 11% | B18: =(SUMPRODUCT(DCF_Base!$C$19:$L$19/(1+$C$18/100)^DCF_Base!$C$4:$L$4)+MAX(0,MIN(IF($C$18>DCF_Base!$B$28,DCF_Base!$L$19*(1+DCF_Base!$B$28/100)/(($C$18-DCF_Base!$B$28)/100),DCF_Base!$L$19*DCF_Base!$B$29),DCF_Base!$L$19*DCF_Base!$B$29))/(1+$C$18/100)^DCF_Base!$L$4+Assumptions!$B$5-Assumptions!$B$4)/Assumptions!$B$3*Assumptions!$B$10 | C18: 11
A19: Value per share at 12% | B19: =(SUMPRODUCT(DCF_Base!$C$19:$L$19/(1+$C$19/100)^DCF_Base!$C$4:$L$4)+MAX(0,MIN(IF($C$19>DCF_Base!$B$28,DCF_Base!$L$19*(1+DCF_Base!$B$28/100)/(($C$19-DCF_Base!$B$28)/100),DCF_Base!$L$19*DCF_Base!$B$29),DCF_Base!$L$19*DCF_Base!$B$29))/(1+$C$19/100)^DCF_Base!$L$4+Assumptions!$B$5-Assumptions!$B$4)/Assumptions!$B$3*Assumptions!$B$10 | C19: 12
A20: Value per share at 15% | B20: =(SUMPRODUCT(DCF_Base!$C$19:$L$19/(1+$C$20/100)^DCF_Base!$C$4:$L$4)+MAX(0,MIN(IF($C$20>DCF_Base!$B$28,DCF_Base!$L$19*(1+DCF_Base!$B$28/100)/(($C$20-DCF_Base!$B$28)/100),DCF_Base!$L$19*DCF_Base!$B$29),DCF_Base!$L$19*DCF_Base!$B$29))/(1+$C$20/100)^DCF_Base!$L$4+Assumptions!$B$5-Assumptions!$B$4)/Assumptions!$B$3*Assumptions!$B$10 | C20: 15
A22: Sensitivity: value per share, rows WACC (%) x columns terminal growth (%)
B23: 1.5 | C23: 2 | D23: 2.5 | E23: 3 | F23: 3.5
A24: 6 | B24: =(SUMPRODUCT(DCF_Base!$C$19:$L$19/(1+$A$24/100)^DCF_Base!$C$4:$L$4)+MAX(0,MIN(IF($A$24>$B$23,DCF_Base!$L$19*(1+$B$23/100)/(($A$24-$B$23)/100),DCF_Base!$L$19*DCF_Base!$B$29),DCF_Base!$L$19*DCF_Base!$B$29))/(1+$A$24/100)^DCF_Base!$L$4+Assumptions!$B$5-Assumptions!$B$4)/Assumptions!$B$3*Assumptions!$B$10 | C24: =(SUMPRODUCT(DCF_Base!$C$19:$L$19/(1+$A$24/100)^DCF_Base!$C$4:$L$4)+MAX(0,MIN(IF($A$24>$C$23,DCF_Base!$L$19*(1+$C$23/100)/(($A$24-$C$23)/100),DCF_Base!$L$19*DCF_Base!$B$29),DCF_Base!$L$19*DCF_Base!$B$29))/(1+$A$24/100)^DCF_Base!$L$4+Assumptions!$B$5-Assumptions!$B$4)/Assumptions!$B$3*Assumptions!$B$10 | D24: =(SUMPRODUCT(DCF_Base!$C$19:$L$19/(1+$A$24/100)^DCF_Base!$C$4:$L$4)+MAX(0,MIN(IF($A$24>$D$23,DCF_Base!$L$19*(1+$D$23/100)/(($A$24-$D$23)/100),DCF_Base!$L$19*DCF_Base!$B$29),DCF_Base!$L$19*DCF_Base!$B$29))/(1+$A$24/100)^DCF_Base!$L$4+Assumptions!$B$5-Assumptions!$B$4)/Assumptions!$B$3*Assumptions!$B$10 | E24: =(SUMPRODUCT(DCF_Base!$C$19:$L$19/(1+$A$24/100)^DCF_Base!$C$4:$L$4)+MAX(0,MIN(IF($A$24>$E$23,DCF_Base!$L$19*(1+$E$23/100)/(($A$24-$E$23)/100),DCF_Base!$L$19*DCF_Base!$B$29),DCF_Base!$L$19*DCF_Base!$B$29))/(1+$A$24/100)^DCF_Base!$L$4+Assumptions!$B$5-Assumptions!$B$4)/Assumptions!$B$3*Assumptions!$B$10 | F24: =(SUMPRODUCT(DCF_Base!$C$19:$L$19/(1+$A$24/100)^DCF_Base!$C$4:$L$4)+MAX(0,MIN(IF($A$24>$F$23,DCF_Base!$L$19*(1+$F$23/100)/(($A$24-$F$23)/100),DCF_Base!$L$19*DCF_Base!$B$29),DCF_Base!$L$19*DCF_Base!$B$29))/(1+$A$24/100)^DCF_Base!$L$4+Assumptions!$B$5-Assumptions!$B$4)/Assumptions!$B$3*Assumptions!$B$10
A25: 7 | B25: =(SUMPRODUCT(DCF_Base!$C$19:$L$19/(1+$A$25/100)^DCF_Base!$C$4:$L$4)+MAX(0,MIN(IF($A$25>$B$23,DCF_Base!$L$19*(1+$B$23/100)/(($A$25-$B$23)/100),DCF_Base!$L$19*DCF_Base!$B$29),DCF_Base!$L$19*DCF_Base!$B$29))/(1+$A$25/100)^DCF_Base!$L$4+Assumptions!$B$5-Assumptions!$B$4)/Assumptions!$B$3*Assumptions!$B$10 | C25: =(SUMPRODUCT(DCF_Base!$C$19:$L$19/(1+$A$25/100)^DCF_Base!$C$4:$L$4)+MAX(0,MIN(IF($A$25>$C$23,DCF_Base!$L$19*(1+$C$23/100)/(($A$25-$C$23)/100),DCF_Base!$L$19*DCF_Base!$B$29),DCF_Base!$L$19*DCF_Base!$B$29))/(1+$A$25/100)^DCF_Base!$L$4+Assumptions!$B$5-Assumptions!$B$4)/Assumptions!$B$3*Assumptions!$B$10 | D25: =(SUMPRODUCT(DCF_Base!$C$19:$L$19/(1+$A$25/100)^DCF_Base!$C$4:$L$4)+MAX(0,MIN(IF($A$25>$D$23,DCF_Base!$L$19*(1+$D$23/100)/(($A$25-$D$23)/100),DCF_Base!$L$19*DCF_Base!$B$29),DCF_Base!$L$19*DCF_Base!$B$29))/(1+$A$25/100)^DCF_Base!$L$4+Assumptions!$B$5-Assumptions!$B$4)/Assumptions!$B$3*Assumptions!$B$10 | E25: =(SUMPRODUCT(DCF_Base!$C$19:$L$19/(1+$A$25/100)^DCF_Base!$C$4:$L$4)+MAX(0,MIN(IF($A$25>$E$23,DCF_Base!$L$19*(1+$E$23/100)/(($A$25-$E$23)/100),DCF_Base!$L$19*DCF_Base!$B$29),DCF_Base!$L$19*DCF_Base!$B$29))/(1+$A$25/100)^DCF_Base!$L$4+Assumptions!$B$5-Assumptions!$B$4)/Assumptions!$B$3*Assumptions!$B$10 | F25: =(SUMPRODUCT(DCF_Base!$C$19:$L$19/(1+$A$25/100)^DCF_Base!$C$4:$L$4)+MAX(0,MIN(IF($A$25>$F$23,DCF_Base!$L$19*(1+$F$23/100)/(($A$25-$F$23)/100),DCF_Base!$L$19*DCF_Base!$B$29),DCF_Base!$L$19*DCF_Base!$B$29))/(1+$A$25/100)^DCF_Base!$L$4+Assumptions!$B$5-Assumptions!$B$4)/Assumptions!$B$3*Assumptions!$B$10
A26: 8 | B26: =(SUMPRODUCT(DCF_Base!$C$19:$L$19/(1+$A$26/100)^DCF_Base!$C$4:$L$4)+MAX(0,MIN(IF($A$26>$B$23,DCF_Base!$L$19*(1+$B$23/100)/(($A$26-$B$23)/100),DCF_Base!$L$19*DCF_Base!$B$29),DCF_Base!$L$19*DCF_Base!$B$29))/(1+$A$26/100)^DCF_Base!$L$4+Assumptions!$B$5-Assumptions!$B$4)/Assumptions!$B$3*Assumptions!$B$10 | C26: =(SUMPRODUCT(DCF_Base!$C$19:$L$19/(1+$A$26/100)^DCF_Base!$C$4:$L$4)+MAX(0,MIN(IF($A$26>$C$23,DCF_Base!$L$19*(1+$C$23/100)/(($A$26-$C$23)/100),DCF_Base!$L$19*DCF_Base!$B$29),DCF_Base!$L$19*DCF_Base!$B$29))/(1+$A$26/100)^DCF_Base!$L$4+Assumptions!$B$5-Assumptions!$B$4)/Assumptions!$B$3*Assumptions!$B$10 | D26: =(SUMPRODUCT(DCF_Base!$C$19:$L$19/(1+$A$26/100)^DCF_Base!$C$4:$L$4)+MAX(0,MIN(IF($A$26>$D$23,DCF_Base!$L$19*(1+$D$23/100)/(($A$26-$D$23)/100),DCF_Base!$L$19*DCF_Base!$B$29),DCF_Base!$L$19*DCF_Base!$B$29))/(1+$A$26/100)^DCF_Base!$L$4+Assumptions!$B$5-Assumptions!$B$4)/Assumptions!$B$3*Assumptions!$B$10 | E26: =(SUMPRODUCT(DCF_Base!$C$19:$L$19/(1+$A$26/100)^DCF_Base!$C$4:$L$4)+MAX(0,MIN(IF($A$26>$E$23,DCF_Base!$L$19*(1+$E$23/100)/(($A$26-$E$23)/100),DCF_Base!$L$19*DCF_Base!$B$29),DCF_Base!$L$19*DCF_Base!$B$29))/(1+$A$26/100)^DCF_Base!$L$4+Assumptions!$B$5-Assumptions!$B$4)/Assumptions!$B$3*Assumptions!$B$10 | F26: =(SUMPRODUCT(DCF_Base!$C$19:$L$19/(1+$A$26/100)^DCF_Base!$C$4:$L$4)+MAX(0,MIN(IF($A$26>$F$23,DCF_Base!$L$19*(1+$F$23/100)/(($A$26-$F$23)/100),DCF_Base!$L$19*DCF_Base!$B$29),DCF_Base!$L$19*DCF_Base!$B$29))/(1+$A$26/100)^DCF_Base!$L$4+Assumptions!$B$5-Assumptions!$B$4)/Assumptions!$B$3*Assumptions!$B$10
A27: 9 | B27: =(SUMPRODUCT(DCF_Base!$C$19:$L$19/(1+$A$27/100)^DCF_Base!$C$4:$L$4)+MAX(0,MIN(IF($A$27>$B$23,DCF_Base!$L$19*(1+$B$23/100)/(($A$27-$B$23)/100),DCF_Base!$L$19*DCF_Base!$B$29),DCF_Base!$L$19*DCF_Base!$B$29))/(1+$A$27/100)^DCF_Base!$L$4+Assumptions!$B$5-Assumptions!$B$4)/Assumptions!$B$3*Assumptions!$B$10 | C27: =(SUMPRODUCT(DCF_Base!$C$19:$L$19/(1+$A$27/100)^DCF_Base!$C$4:$L$4)+MAX(0,MIN(IF($A$27>$C$23,DCF_Base!$L$19*(1+$C$23/100)/(($A$27-$C$23)/100),DCF_Base!$L$19*DCF_Base!$B$29),DCF_Base!$L$19*DCF_Base!$B$29))/(1+$A$27/100)^DCF_Base!$L$4+Assumptions!$B$5-Assumptions!$B$4)/Assumptions!$B$3*Assumptions!$B$10 | D27: =(SUMPRODUCT(DCF_Base!$C$19:$L$19/(1+$A$27/100)^DCF_Base!$C$4:$L$4)+MAX(0,MIN(IF($A$27>$D$23,DCF_Base!$L$19*(1+$D$23/100)/(($A$27-$D$23)/100),DCF_Base!$L$19*DCF_Base!$B$29),DCF_Base!$L$19*DCF_Base!$B$29))/(1+$A$27/100)^DCF_Base!$L$4+Assumptions!$B$5-Assumptions!$B$4)/Assumptions!$B$3*Assumptions!$B$10 | E27: =(SUMPRODUCT(DCF_Base!$C$19:$L$19/(1+$A$27/100)^DCF_Base!$C$4:$L$4)+MAX(0,MIN(IF($A$27>$E$23,DCF_Base!$L$19*(1+$E$23/100)/(($A$27-$E$23)/100),DCF_Base!$L$19*DCF_Base!$B$29),DCF_Base!$L$19*DCF_Base!$B$29))/(1+$A$27/100)^DCF_Base!$L$4+Assumptions!$B$5-Assumptions!$B$4)/Assumptions!$B$3*Assumptions!$B$10 | F27: =(SUMPRODUCT(DCF_Base!$C$19:$L$19/(1+$A$27/100)^DCF_Base!$C$4:$L$4)+MAX(0,MIN(IF($A$27>$F$23,DCF_Base!$L$19*(1+$F$23/100)/(($A$27-$F$23)/100),DCF_Base!$L$19*DCF_Base!$B$29),DCF_Base!$L$19*DCF_Base!$B$29))/(1+$A$27/100)^DCF_Base!$L$4+Assumptions!$B$5-Assumptions!$B$4)/Assumptions!$B$3*Assumptions!$B$10
A28: 10 | B28: =(SUMPRODUCT(DCF_Base!$C$19:$L$19/(1+$A$28/100)^DCF_Base!$C$4:$L$4)+MAX(0,MIN(IF($A$28>$B$23,DCF_Base!$L$19*(1+$B$23/100)/(($A$28-$B$23)/100),DCF_Base!$L$19*DCF_Base!$B$29),DCF_Base!$L$19*DCF_Base!$B$29))/(1+$A$28/100)^DCF_Base!$L$4+Assumptions!$B$5-Assumptions!$B$4)/Assumptions!$B$3*Assumptions!$B$10 | C28: =(SUMPRODUCT(DCF_Base!$C$19:$L$19/(1+$A$28/100)^DCF_Base!$C$4:$L$4)+MAX(0,MIN(IF($A$28>$C$23,DCF_Base!$L$19*(1+$C$23/100)/(($A$28-$C$23)/100),DCF_Base!$L$19*DCF_Base!$B$29),DCF_Base!$L$19*DCF_Base!$B$29))/(1+$A$28/100)^DCF_Base!$L$4+Assumptions!$B$5-Assumptions!$B$4)/Assumptions!$B$3*Assumptions!$B$10 | D28: =(SUMPRODUCT(DCF_Base!$C$19:$L$19/(1+$A$28/100)^DCF_Base!$C$4:$L$4)+MAX(0,MIN(IF($A$28>$D$23,DCF_Base!$L$19*(1+$D$23/100)/(($A$28-$D$23)/100),DCF_Base!$L$19*DCF_Base!$B$29),DCF_Base!$L$19*DCF_Base!$B$29))/(1+$A$28/100)^DCF_Base!$L$4+Assumptions!$B$5-Assumptions!$B$4)/Assumptions!$B$3*Assumptions!$B$10 | E28: =(SUMPRODUCT(DCF_Base!$C$19:$L$19/(1+$A$28/100)^DCF_Base!$C$4:$L$4)+MAX(0,MIN(IF($A$28>$E$23,DCF_Base!$L$19*(1+$E$23/100)/(($A$28-$E$23)/100),DCF_Base!$L$19*DCF_Base!$B$29),DCF_Base!$L$19*DCF_Base!$B$29))/(1+$A$28/100)^DCF_Base!$L$4+Assumptions!$B$5-Assumptions!$B$4)/Assumptions!$B$3*Assumptions!$B$10 | F28: =(SUMPRODUCT(DCF_Base!$C$19:$L$19/(1+$A$28/100)^DCF_Base!$C$4:$L$4)+MAX(0,MIN(IF($A$28>$F$23,DCF_Base!$L$19*(1+$F$23/100)/(($A$28-$F$23)/100),DCF_Base!$L$19*DCF_Base!$B$29),DCF_Base!$L$19*DCF_Base!$B$29))/(1+$A$28/100)^DCF_Base!$L$4+Assumptions!$B$5-Assumptions!$B$4)/Assumptions!$B$3*Assumptions!$B$10
