Workbook

Sheet Model_Info
A1: AD.AS - Koninklijke Ahold Delhaize N.V. - DCF model
A2: Version | B2: v1.0 (fresh build, no prior version superseded)
A3: Built by | B3: dcf-analyst agent (Claude Fable 5), 2026-08-30, at the user's request
A4: Price anchor | B4: EUR 30.57, Yahoo regular close 2026-08-28 (verified 2026-08-30); figures go stale - refresh after each quarterly print
A5: Balance sheet | B5: FY2025, 52 weeks ended 2025-12-28 (annual report)
A6: Share count | B6: 887M period-end common shares FY2025; held FLAT (SBC fully expensed; EUR 1bn/yr buyback treated as value-neutral capital return)
A7: Guidance anchor | B7: FY2026 (reiterated Q2 2026, 5-Aug-2026): ~4% underlying operating margin, FCF >= EUR 2.3bn, gross capex ~EUR 2.7bn, EUR 1bn buyback, 53-week year
A8: Model | B8: Owner-FCF DCF, component build, 10-year horizon, three probability-weighted scenarios
A9: Owner FCF basis | B9: Company-defined FCF 2,600 + 261 interest paid (add-back) - 130 interest received - 70 SBC = EUR 2,661m FY2025
A10: Lease treatment | B10: Treatment B: full lease payments (principal+interest, one combined filing line) net of sublease receipts charged in flows (1.96% of revenue); lease liabilities (EUR 11,974m) EXCLUDED from net debt
A11: Net debt | B11: EUR 2,725m ex-lease = company net debt 14,699 - lease liabilities 11,974. Never pair 14,699 with this lease-deducted FCF
A12: Terminal value | B12: Capped at 11-14x owner FCF (binds in all scenarios); Gordon at 6.8%/1.75% would imply 20x, a multiple grocers never fetch
A13: WACC | B13: 6.8% all scenarios: rf 3.59% (57.5% UST 4.25% + 42.5% Bund 2.70%), ERP 5.5%, beta 0.75, CoE 7.72%; Kd 3.7% pre-tax; E 80.8%/D 19.2%. Risk is charged once, in the flows
... A16: Cell legend | B16: BLUE font = hardcoded input; YELLOW fill = key driver row; black = formula; GREEN = cross-sheet link

Sheet Actuals
A1: Reported history, EUR millions (source: annual reports; FY2016 merger stub excluded; FY2017-18 pre-IFRS-16)
A2: Metric | B2: FY2017 | C2: FY2018 | D2: FY2019 | E2: FY2020 | F2: FY2021 | G2: FY2022 | H2: FY2023 | I2: FY2024 | J2: FY2025
A3: Revenue | B3: 62890 | C3: 62791 | D3: 66260 | E3: 74736 | F3: 75601 | G3: 86984 | H3: 88734 | I3: 89356 | J3: 92352
A4: EBITDA | B4: 4082 | C4: 4439 | D4: 5510 | E4: 5083 | F4: 6388 | G4: 7436 | H4: 6690 | I4: 6490 | J4: 7275
A5: OperatingIncome | B5: 2225 | C5: 2623 | D5: 2662 | E5: 2191 | F5: 3320 | G5: 3768 | H5: 2846 | I5: 2784 | J5: 3542
A6: NetIncome | B6: 1817 | C6: 1780 | D6: 1766 | E6: 1397 | F6: 2246 | G6: 2546 | H6: 1874 | I6: 1764 | J6: 2264
A7: EPS | B7: 1.45 | C7: 1.51 | D7: 1.6 | E7: 1.31 | F7: 2.18 | G7: 2.56 | H7: 1.95 | I7: 1.9 | J7: 2.51
A8: OperatingCashFlow | B8: 3695 | C8: 4323 | D8: 5449 | E8: 6343 | F8: 5468 | G8: 6110 | H8: 6466 | I8: 6224 | J8: 6989
A9: GrossCapex | B9: 1698 | C9: 1780 | D9: 2218 | E9: 2659 | F9: 2371 | G9: 2490 | H9: 2434 | I9: 2299 | J9: 2564
A10: ReportedFCF | B10: 1926 | C10: 2165 | D10: 1843 | E10: 2199 | F10: 1618 | G10: 2188 | H10: 2425 | I10: 2545 | J10: 2600
A11: InterestPaid | B11: 320 | C11: 324 | D11: 189 | E11: 149 | F11: 138 | G11: 174 | H11: 226 | I11: 230 | J11: 261
A12: InterestReceived | B12: 32 | C12: 74 | D12: 56 | E12: 24 | F12: 16 | G12: 56 | H12: 160 | I12: 196 | J12: 130
A13: SBC | B13: 79 | C13: 60 | D13: 51 | E13: 59 | F13: 48 | G13: 65 | H13: 53 | I13: 42 | J13: 70
A14: SharesOutstanding | B14: 1228 | C14: 1130 | D14: 1088 | E14: 1047 | F14: 1011 | G14: 977 | H14: 946 | I14: 914 | J14: 887
... A16: DividendsPaid | B16: 720 | C16: 757 | D16: 1114 | E16: 1026 | F16: 856 | G16: 979 | H16: 1044 | I16: 1037 | J16: 1070
A18: Balance-sheet snapshot FY2025 (2025-12-28)
A19: Cash & equivalents | B19: 3605
A20: Financial debt ex-lease | B20: 6430
A21: Lease liabilities (curr+non-curr) | B21: 11974
A22: Company net debt (incl leases) | B22: 14699
A23: Net debt EX-lease (bridge) | B23: 2725
A24: Shareholders equity | B24: 14195
A25: Period-end shares (M) | B25: 887
A26: Weighted diluted shares FY2025 (M) | B26: 905.6
A28: FY2026 guidance (reiterated 5-Aug-2026): underlying operating margin ~4%; FCF >= EUR 2.3bn; gross capex ~EUR 2.7bn; mid-to-high-single-digit underlying EPS growth cc; EUR 1bn buyback; dividend payout 40-50%; 53-week year

Sheet Assumptions
A1: Globals
A2: Price (EUR, 2026-08-28 close) | B2: 30.57
A3: Diluted shares (M, period-end FY2025) | B3: 887
A4: Net debt ex-lease (EUR m) | B4: 2725
A5: WACC % | B5: 6.8
A6: D&A % of revenue (ex-ROU) | B6: 1.95
A7: WC capture % of revenue change | B7: 5
A8: Hurdle rate % | B8: 15
A10: Per scenario
A11: Scenario | B11: Terminal growth % | C11: TV cap (x owner FCF) | D11: Probability
A12: Bear | B12: 1.25 | C12: 11 | D12: 0.2
A13: Base | B13: 1.75 | C13: 13 | D13: 0.5
A14: Bull | B14: 2 | C14: 14 | D14: 0.3
A15: Weights sum (must equal 1.0) | B15: =SUM(D12:D14)
A17: Narratives
A18: Bear | B18: US price war + SNAP cut (5.3M fewer enrollees, ~5.3% of US sales) + IRA pharmacy deflation; EBITDA margin 7.9->7.0%; growth ~1%; Stop & Shop closures accelerate; CEO handover resets strategy; exit de-rates to 11x owner FCF.
A19: Base | B19: FY2026 guidance delivered and sustained: ~4% underlying margin (EBITDA 7.9% flat), company FCF >= EUR 2.3bn, +3.0% in 53-wk 2026 then ~2-2.5%/yr nominal; no FX drift; exit 13x owner FCF.
A20: Bull | B20: Growing Together over-delivers: retail media/complementary income (~EUR 3bn by 2028) lift EBITDA margin to 8.4% by Y6; S&S turnaround holds; ~3%/yr growth; exit 14x owner FCF.

Sheet DCF_Bear
A1: Bear scenario - component owner-FCF build, EUR millions
A3: Year | B3: 2025A | C3: 2026E | D3: 2027E | E3: 2028E | F3: 2029E | G3: 2030E | H3: 2031E | I3: 2032E | J3: 2033E | K3: 2034E | L3: 2035E
A4: Index | B4: 0 | C4: 1 | D4: 2 | E4: 3 | F4: 4 | G4: 5 | H4: 6 | I4: 7 | J4: 8 | K4: 9 | L4: 10
A5: Revenue growth % | C5: 1.5 | D5: 0 | E5: 0.5 | F5: 1 | G5: 1 | H5: 1.25 | I5: 1.25 | J5: 1.5 | K5: 1.5 | L5: 1.5
A6: Revenue | B6: 92352 | C6: =B6*(1+C5/100) | D6: =C6*(1+D5/100) | E6: =D6*(1+E5/100) | F6: =E6*(1+F5/100) | G6: =F6*(1+G5/100) | H6: =G6*(1+H5/100) | I6: =H6*(1+I5/100) | J6: =I6*(1+J5/100) | ... L6: =K6*(1+L5/100)
A7: Adj EBITDA margin % | C7: 7.7 | D7: 7.4 | E7: 7.2 | F7: 7 | G7: 7 | H7: 7 | I7: 7 | J7: 7 | K7: 7 | L7: 7
A8: Adjusted EBITDA | C8: =C6*C7/100 | D8: =D6*D7/100 | E8: =E6*E7/100 | F8: =F6*F7/100 | G8: =G6*G7/100 | H8: =H6*H7/100 | I8: =I6*I7/100 | J8: =J6*J7/100 | ... L8: =L6*L7/100
A9: SBC % of revenue | C9: 0.08 | D9: 0.08 | E9: 0.08 | F9: 0.08 | G9: 0.08 | H9: 0.08 | I9: 0.08 | J9: 0.08 | K9: 0.08 | L9: 0.08
A10: SBC (EUR) | C10: =-C6*C9/100 | D10: =-D6*D9/100 | E10: =-E6*E9/100 | F10: =-F6*F9/100 | G10: =-G6*G9/100 | H10: =-H6*H9/100 | I10: =-I6*I9/100 | J10: =-J6*J9/100 | ... L10: =-L6*L9/100
A11: Lease cost % of revenue (net pmts) | C11: 1.96 | D11: 1.96 | E11: 1.96 | F11: 1.96 | G11: 1.96 | H11: 1.96 | I11: 1.96 | J11: 1.96 | K11: 1.96 | L11: 1.96
A12: Lease cost (EUR) | C12: =-C6*C11/100 | D12: =-D6*D11/100 | E12: =-E6*E11/100 | F12: =-F6*F11/100 | G12: =-G6*G11/100 | H12: =-H6*H11/100 | I12: =-I6*I11/100 | J12: =-J6*J11/100 | ... L12: =-L6*L11/100
A13: D&A % (link) | C13: =Assumptions!$B$6 | D13: =Assumptions!$B$6 | E13: =Assumptions!$B$6 | F13: =Assumptions!$B$6 | G13: =Assumptions!$B$6 | H13: =Assumptions!$B$6 | I13: =Assumptions!$B$6 | J13: =Assumptions!$B$6 | ... L13: =Assumptions!$B$6
A14: D&A (EUR) | C14: =-C6*C13/100 | D14: =-D6*D13/100 | E14: =-E6*E13/100 | F14: =-F6*F13/100 | G14: =-G6*G13/100 | H14: =-H6*H13/100 | I14: =-I6*I13/100 | J14: =-J6*J13/100 | ... L14: =-L6*L13/100
A15: EBIT (SBC+lease charged) | C15: =C8+C10+C12+C14 | D15: =D8+D10+D12+D14 | E15: =E8+E10+E12+E14 | F15: =F8+F10+F12+F14 | G15: =G8+G10+G12+G14 | H15: =H8+H10+H12+H14 | I15: =I8+I10+I12+I14 | J15: =J8+J10+J12+J14 | ... L15: =L8+L10+L12+L14
A16: Cash tax rate % | C16: 18 | D16: 19 | E16: 20 | F16: 21 | G16: 22 | H16: 22 | I16: 22 | J16: 22 | K16: 22 | L16: 22
A17: NOPAT | C17: =C15-MAX(0,C15)*C16/100 | D17: =D15-MAX(0,D15)*D16/100 | E17: =E15-MAX(0,E15)*E16/100 | F17: =F15-MAX(0,F15)*F16/100 | G17: =G15-MAX(0,G15)*G16/100 | H17: =H15-MAX(0,H15)*H16/100 | I17: =I15-MAX(0,I15)*I16/100 | J17: =J15-MAX(0,J15)*J16/100 | ... L17: =L15-MAX(0,L15)*L16/100
A18: add back D&A | C18: =-C14 | D18: =-D14 | E18: =-E14 | F18: =-F14 | G18: =-G14 | H18: =-H14 | I18: =-I14 | J18: =-J14 | ... L18: =-L14
A19: Capex % of revenue | C19: 2.8 | D19: 2.8 | E19: 2.8 | F19: 2.8 | G19: 2.8 | H19: 2.8 | I19: 2.8 | J19: 2.8 | K19: 2.8 | L19: 2.8
A20: Capex (EUR) | C20: =-C6*C19/100 | D20: =-D6*D19/100 | E20: =-E6*E19/100 | F20: =-F6*F19/100 | G20: =-G6*G19/100 | H20: =-H6*H19/100 | I20: =-I6*I19/100 | J20: =-J6*J19/100 | ... L20: =-L6*L19/100
A21: WC (capture x rev change) | C21: =Assumptions!$B$7/100*(C6-B6) | D21: =Assumptions!$B$7/100*(D6-C6) | E21: =Assumptions!$B$7/100*(E6-D6) | F21: =Assumptions!$B$7/100*(F6-E6) | G21: =Assumptions!$B$7/100*(G6-F6) | H21: =Assumptions!$B$7/100*(H6-G6) | I21: =Assumptions!$B$7/100*(I6-H6) | J21: =Assumptions!$B$7/100*(J6-I6) | ... L21: =Assumptions!$B$7/100*(L6-K6)
A22: Owner FCF | C22: =C17+C18+C20+C21 | D22: =D17+D18+D20+D21 | E22: =E17+E18+E20+E21 | F22: =F17+F18+F20+F21 | G22: =G17+G18+G20+G21 | H22: =H17+H18+H20+H21 | I22: =I17+I18+I20+I21 | J22: =J17+J18+J20+J21 | ... L22: =L17+L18+L20+L21
A23: Discount factor | C23: =1/(1+Assumptions!$B$5/100)^C4 | D23: =1/(1+Assumptions!$B$5/100)^D4 | E23: =1/(1+Assumptions!$B$5/100)^E4 | F23: =1/(1+Assumptions!$B$5/100)^F4 | G23: =1/(1+Assumptions!$B$5/100)^G4 | H23: =1/(1+Assumptions!$B$5/100)^H4 | I23: =1/(1+Assumptions!$B$5/100)^I4 | J23: =1/(1+Assumptions!$B$5/100)^J4 | ... L23: =1/(1+Assumptions!$B$5/100)^L4
A24: PV of FCF | C24: =C22*C23 | D24: =D22*D23 | E24: =E22*E23 | F24: =F22*F23 | G24: =G22*G23 | H24: =H22*H23 | I24: =I22*I23 | J24: =J22*J23 | ... L24: =L22*L23
A26: Memo: owner-FCF margin % | C26: =C22/C6*100 | D26: =D22/D6*100 | E26: =E22/E6*100 | F26: =F22/F6*100 | G26: =G22/G6*100 | H26: =H22/H6*100 | I26: =I22/I6*100 | J26: =J22/J6*100 | ... L26: =L22/L6*100
A28: Sum PV of FCF | B28: =SUM(C24:L24)
A29: Terminal growth % (link) | B29: =Assumptions!$B$12
A30: Terminal FCF | B30: =L22*(1+B29/100)
A31: Gordon TV | B31: =IF(Assumptions!$B$5>B29, B30/((Assumptions!$B$5-B29)/100), "n/a")
A32: Cap TV (cap x FCF10) | B32: =Assumptions!$C$12*L22
A33: TV used | B33: =MAX(0,MIN(B31,B32))
A34: Implied exit multiple (x owner FCF) | B34: =B33/L22
A35: PV of TV | B35: =B33*L23
A36: Enterprise value | B36: =B28+B35
A37: less net debt (ex-lease) | B37: =-Assumptions!$B$4
A38: Equity value | B38: =B36+B37
A39: Diluted shares (M) | B39: =Assumptions!$B$3
A40: VALUE PER SHARE (EUR) | B40: =B38/B39
A41: Upside vs price | B41: =B40/Assumptions!$B$2-1
A43: Street memo: PV explicit SBC | B43: =SUMPRODUCT(-C10:L10/(1+Assumptions!$B$5/100)^C4:L4)
A44: PV terminal SBC | B44: =-L10*(1+B29/100)/((Assumptions!$B$5-B29)/100)*L23
...

Sheet DCF_Base
A1: Base scenario - component owner-FCF build, EUR millions
A3: Year | B3: 2025A | C3: 2026E | D3: 2027E | E3: 2028E | F3: 2029E | G3: 2030E | H3: 2031E | I3: 2032E | J3: 2033E | K3: 2034E | L3: 2035E
A4: Index | B4: 0 | C4: 1 | D4: 2 | E4: 3 | F4: 4 | G4: 5 | H4: 6 | I4: 7 | J4: 8 | K4: 9 | L4: 10
A5: Revenue growth % | C5: 3 | D5: 1.7 | E5: 2.5 | F5: 2.5 | G5: 2.25 | H5: 2.25 | I5: 2 | J5: 2 | K5: 2 | L5: 2
A6: Revenue | B6: 92352 | C6: =B6*(1+C5/100) | D6: =C6*(1+D5/100) | E6: =D6*(1+E5/100) | F6: =E6*(1+F5/100) | G6: =F6*(1+G5/100) | H6: =G6*(1+H5/100) | I6: =H6*(1+I5/100) | J6: =I6*(1+J5/100) | ... L6: =K6*(1+L5/100)
A7: Adj EBITDA margin % | C7: 7.9 | D7: 7.9 | E7: 7.9 | F7: 7.9 | G7: 7.9 | H7: 7.9 | I7: 7.9 | J7: 7.9 | K7: 7.9 | L7: 7.9
A8: Adjusted EBITDA | C8: =C6*C7/100 | D8: =D6*D7/100 | E8: =E6*E7/100 | F8: =F6*F7/100 | G8: =G6*G7/100 | H8: =H6*H7/100 | I8: =I6*I7/100 | J8: =J6*J7/100 | ... L8: =L6*L7/100
A9: SBC % of revenue | C9: 0.08 | D9: 0.08 | E9: 0.08 | F9: 0.08 | G9: 0.08 | H9: 0.08 | I9: 0.08 | J9: 0.08 | K9: 0.08 | L9: 0.08
A10: SBC (EUR) | C10: =-C6*C9/100 | D10: =-D6*D9/100 | E10: =-E6*E9/100 | F10: =-F6*F9/100 | G10: =-G6*G9/100 | H10: =-H6*H9/100 | I10: =-I6*I9/100 | J10: =-J6*J9/100 | ... L10: =-L6*L9/100
A11: Lease cost % of revenue (net pmts) | C11: 1.96 | D11: 1.96 | E11: 1.96 | F11: 1.96 | G11: 1.96 | H11: 1.96 | I11: 1.96 | J11: 1.96 | K11: 1.96 | L11: 1.96
A12: Lease cost (EUR) | C12: =-C6*C11/100 | D12: =-D6*D11/100 | E12: =-E6*E11/100 | F12: =-F6*F11/100 | G12: =-G6*G11/100 | H12: =-H6*H11/100 | I12: =-I6*I11/100 | J12: =-J6*J11/100 | ... L12: =-L6*L11/100
A13: D&A % (link) | C13: =Assumptions!$B$6 | D13: =Assumptions!$B$6 | E13: =Assumptions!$B$6 | F13: =Assumptions!$B$6 | G13: =Assumptions!$B$6 | H13: =Assumptions!$B$6 | I13: =Assumptions!$B$6 | J13: =Assumptions!$B$6 | ... L13: =Assumptions!$B$6
A14: D&A (EUR) | C14: =-C6*C13/100 | D14: =-D6*D13/100 | E14: =-E6*E13/100 | F14: =-F6*F13/100 | G14: =-G6*G13/100 | H14: =-H6*H13/100 | I14: =-I6*I13/100 | J14: =-J6*J13/100 | ... L14: =-L6*L13/100
A15: EBIT (SBC+lease charged) | C15: =C8+C10+C12+C14 | D15: =D8+D10+D12+D14 | E15: =E8+E10+E12+E14 | F15: =F8+F10+F12+F14 | G15: =G8+G10+G12+G14 | H15: =H8+H10+H12+H14 | I15: =I8+I10+I12+I14 | J15: =J8+J10+J12+J14 | ... L15: =L8+L10+L12+L14
A16: Cash tax rate % | C16: 18 | D16: 19 | E16: 20 | F16: 21 | G16: 22 | H16: 22 | I16: 22 | J16: 22 | K16: 22 | L16: 22
A17: NOPAT | C17: =C15-MAX(0,C15)*C16/100 | D17: =D15-MAX(0,D15)*D16/100 | E17: =E15-MAX(0,E15)*E16/100 | F17: =F15-MAX(0,F15)*F16/100 | G17: =G15-MAX(0,G15)*G16/100 | H17: =H15-MAX(0,H15)*H16/100 | I17: =I15-MAX(0,I15)*I16/100 | J17: =J15-MAX(0,J15)*J16/100 | ... L17: =L15-MAX(0,L15)*L16/100
A18: add back D&A | C18: =-C14 | D18: =-D14 | E18: =-E14 | F18: =-F14 | G18: =-G14 | H18: =-H14 | I18: =-I14 | J18: =-J14 | ... L18: =-L14
A19: Capex % of revenue | C19: 2.7 | D19: 2.7 | E19: 2.7 | F19: 2.7 | G19: 2.7 | H19: 2.7 | I19: 2.7 | J19: 2.7 | K19: 2.7 | L19: 2.7
A20: Capex (EUR) | C20: =-C6*C19/100 | D20: =-D6*D19/100 | E20: =-E6*E19/100 | F20: =-F6*F19/100 | G20: =-G6*G19/100 | H20: =-H6*H19/100 | I20: =-I6*I19/100 | J20: =-J6*J19/100 | ... L20: =-L6*L19/100
A21: WC (capture x rev change) | C21: =Assumptions!$B$7/100*(C6-B6) | D21: =Assumptions!$B$7/100*(D6-C6) | E21: =Assumptions!$B$7/100*(E6-D6) | F21: =Assumptions!$B$7/100*(F6-E6) | G21: =Assumptions!$B$7/100*(G6-F6) | H21: =Assumptions!$B$7/100*(H6-G6) | I21: =Assumptions!$B$7/100*(I6-H6) | J21: =Assumptions!$B$7/100*(J6-I6) | ... L21: =Assumptions!$B$7/100*(L6-K6)
A22: Owner FCF | C22: =C17+C18+C20+C21 | D22: =D17+D18+D20+D21 | E22: =E17+E18+E20+E21 | F22: =F17+F18+F20+F21 | G22: =G17+G18+G20+G21 | H22: =H17+H18+H20+H21 | I22: =I17+I18+I20+I21 | J22: =J17+J18+J20+J21 | ... L22: =L17+L18+L20+L21
A23: Discount factor | C23: =1/(1+Assumptions!$B$5/100)^C4 | D23: =1/(1+Assumptions!$B$5/100)^D4 | E23: =1/(1+Assumptions!$B$5/100)^E4 | F23: =1/(1+Assumptions!$B$5/100)^F4 | G23: =1/(1+Assumptions!$B$5/100)^G4 | H23: =1/(1+Assumptions!$B$5/100)^H4 | I23: =1/(1+Assumptions!$B$5/100)^I4 | J23: =1/(1+Assumptions!$B$5/100)^J4 | ... L23: =1/(1+Assumptions!$B$5/100)^L4
A24: PV of FCF | C24: =C22*C23 | D24: =D22*D23 | E24: =E22*E23 | F24: =F22*F23 | G24: =G22*G23 | H24: =H22*H23 | I24: =I22*I23 | J24: =J22*J23 | ... L24: =L22*L23
A26: Memo: owner-FCF margin % | C26: =C22/C6*100 | D26: =D22/D6*100 | E26: =E22/E6*100 | F26: =F22/F6*100 | G26: =G22/G6*100 | H26: =H22/H6*100 | I26: =I22/I6*100 | J26: =J22/J6*100 | ... L26: =L22/L6*100
A28: Sum PV of FCF | B28: =SUM(C24:L24)
A29: Terminal growth % (link) | B29: =Assumptions!$B$13
A30: Terminal FCF | B30: =L22*(1+B29/100)
A31: Gordon TV | B31: =IF(Assumptions!$B$5>B29, B30/((Assumptions!$B$5-B29)/100), "n/a")
A32: Cap TV (cap x FCF10) | B32: =Assumptions!$C$13*L22
A33: TV used | B33: =MAX(0,MIN(B31,B32))
A34: Implied exit multiple (x owner FCF) | B34: =B33/L22
A35: PV of TV | B35: =B33*L23
A36: Enterprise value | B36: =B28+B35
A37: less net debt (ex-lease) | B37: =-Assumptions!$B$4
A38: Equity value | B38: =B36+B37
A39: Diluted shares (M) | B39: =Assumptions!$B$3
A40: VALUE PER SHARE (EUR) | B40: =B38/B39
A41: Upside vs price | B41: =B40/Assumptions!$B$2-1
A43: Street memo: PV explicit SBC | B43: =SUMPRODUCT(-C10:L10/(1+Assumptions!$B$5/100)^C4:L4)
A44: PV terminal SBC | B44: =-L10*(1+B29/100)/((Assumptions!$B$5-B29)/100)*L23
...

Sheet DCF_Bull
A1: Bull scenario - component owner-FCF build, EUR millions
A3: Year | B3: 2025A | C3: 2026E | D3: 2027E | E3: 2028E | F3: 2029E | G3: 2030E | H3: 2031E | I3: 2032E | J3: 2033E | K3: 2034E | L3: 2035E
A4: Index | B4: 0 | C4: 1 | D4: 2 | E4: 3 | F4: 4 | G4: 5 | H4: 6 | I4: 7 | J4: 8 | K4: 9 | L4: 10
A5: Revenue growth % | C5: 3.5 | D5: 2.5 | E5: 3.25 | F5: 3.25 | G5: 3 | H5: 3 | I5: 2.75 | J5: 2.75 | K5: 2.5 | L5: 2.5
A6: Revenue | B6: 92352 | C6: =B6*(1+C5/100) | D6: =C6*(1+D5/100) | E6: =D6*(1+E5/100) | F6: =E6*(1+F5/100) | G6: =F6*(1+G5/100) | H6: =G6*(1+H5/100) | I6: =H6*(1+I5/100) | J6: =I6*(1+J5/100) | ... L6: =K6*(1+L5/100)
A7: Adj EBITDA margin % | C7: 7.9 | D7: 8 | E7: 8.1 | F7: 8.2 | G7: 8.3 | H7: 8.4 | I7: 8.4 | J7: 8.4 | K7: 8.4 | L7: 8.4
A8: Adjusted EBITDA | C8: =C6*C7/100 | D8: =D6*D7/100 | E8: =E6*E7/100 | F8: =F6*F7/100 | G8: =G6*G7/100 | H8: =H6*H7/100 | I8: =I6*I7/100 | J8: =J6*J7/100 | ... L8: =L6*L7/100
A9: SBC % of revenue | C9: 0.08 | D9: 0.08 | E9: 0.08 | F9: 0.08 | G9: 0.08 | H9: 0.08 | I9: 0.08 | J9: 0.08 | K9: 0.08 | L9: 0.08
A10: SBC (EUR) | C10: =-C6*C9/100 | D10: =-D6*D9/100 | E10: =-E6*E9/100 | F10: =-F6*F9/100 | G10: =-G6*G9/100 | H10: =-H6*H9/100 | I10: =-I6*I9/100 | J10: =-J6*J9/100 | ... L10: =-L6*L9/100
A11: Lease cost % of revenue (net pmts) | C11: 1.96 | D11: 1.96 | E11: 1.96 | F11: 1.96 | G11: 1.96 | H11: 1.96 | I11: 1.96 | J11: 1.96 | K11: 1.96 | L11: 1.96
A12: Lease cost (EUR) | C12: =-C6*C11/100 | D12: =-D6*D11/100 | E12: =-E6*E11/100 | F12: =-F6*F11/100 | G12: =-G6*G11/100 | H12: =-H6*H11/100 | I12: =-I6*I11/100 | J12: =-J6*J11/100 | ... L12: =-L6*L11/100
A13: D&A % (link) | C13: =Assumptions!$B$6 | D13: =Assumptions!$B$6 | E13: =Assumptions!$B$6 | F13: =Assumptions!$B$6 | G13: =Assumptions!$B$6 | H13: =Assumptions!$B$6 | I13: =Assumptions!$B$6 | J13: =Assumptions!$B$6 | ... L13: =Assumptions!$B$6
A14: D&A (EUR) | C14: =-C6*C13/100 | D14: =-D6*D13/100 | E14: =-E6*E13/100 | F14: =-F6*F13/100 | G14: =-G6*G13/100 | H14: =-H6*H13/100 | I14: =-I6*I13/100 | J14: =-J6*J13/100 | ... L14: =-L6*L13/100
A15: EBIT (SBC+lease charged) | C15: =C8+C10+C12+C14 | D15: =D8+D10+D12+D14 | E15: =E8+E10+E12+E14 | F15: =F8+F10+F12+F14 | G15: =G8+G10+G12+G14 | H15: =H8+H10+H12+H14 | I15: =I8+I10+I12+I14 | J15: =J8+J10+J12+J14 | ... L15: =L8+L10+L12+L14
A16: Cash tax rate % | C16: 18 | D16: 19 | E16: 20 | F16: 21 | G16: 22 | H16: 22 | I16: 22 | J16: 22 | K16: 22 | L16: 22
A17: NOPAT | C17: =C15-MAX(0,C15)*C16/100 | D17: =D15-MAX(0,D15)*D16/100 | E17: =E15-MAX(0,E15)*E16/100 | F17: =F15-MAX(0,F15)*F16/100 | G17: =G15-MAX(0,G15)*G16/100 | H17: =H15-MAX(0,H15)*H16/100 | I17: =I15-MAX(0,I15)*I16/100 | J17: =J15-MAX(0,J15)*J16/100 | ... L17: =L15-MAX(0,L15)*L16/100
A18: add back D&A | C18: =-C14 | D18: =-D14 | E18: =-E14 | F18: =-F14 | G18: =-G14 | H18: =-H14 | I18: =-I14 | J18: =-J14 | ... L18: =-L14
A19: Capex % of revenue | C19: 2.7 | D19: 2.7 | E19: 2.7 | F19: 2.7 | G19: 2.7 | H19: 2.7 | I19: 2.7 | J19: 2.7 | K19: 2.7 | L19: 2.7
A20: Capex (EUR) | C20: =-C6*C19/100 | D20: =-D6*D19/100 | E20: =-E6*E19/100 | F20: =-F6*F19/100 | G20: =-G6*G19/100 | H20: =-H6*H19/100 | I20: =-I6*I19/100 | J20: =-J6*J19/100 | ... L20: =-L6*L19/100
A21: WC (capture x rev change) | C21: =Assumptions!$B$7/100*(C6-B6) | D21: =Assumptions!$B$7/100*(D6-C6) | E21: =Assumptions!$B$7/100*(E6-D6) | F21: =Assumptions!$B$7/100*(F6-E6) | G21: =Assumptions!$B$7/100*(G6-F6) | H21: =Assumptions!$B$7/100*(H6-G6) | I21: =Assumptions!$B$7/100*(I6-H6) | J21: =Assumptions!$B$7/100*(J6-I6) | ... L21: =Assumptions!$B$7/100*(L6-K6)
A22: Owner FCF | C22: =C17+C18+C20+C21 | D22: =D17+D18+D20+D21 | E22: =E17+E18+E20+E21 | F22: =F17+F18+F20+F21 | G22: =G17+G18+G20+G21 | H22: =H17+H18+H20+H21 | I22: =I17+I18+I20+I21 | J22: =J17+J18+J20+J21 | ... L22: =L17+L18+L20+L21
A23: Discount factor | C23: =1/(1+Assumptions!$B$5/100)^C4 | D23: =1/(1+Assumptions!$B$5/100)^D4 | E23: =1/(1+Assumptions!$B$5/100)^E4 | F23: =1/(1+Assumptions!$B$5/100)^F4 | G23: =1/(1+Assumptions!$B$5/100)^G4 | H23: =1/(1+Assumptions!$B$5/100)^H4 | I23: =1/(1+Assumptions!$B$5/100)^I4 | J23: =1/(1+Assumptions!$B$5/100)^J4 | ... L23: =1/(1+Assumptions!$B$5/100)^L4
A24: PV of FCF | C24: =C22*C23 | D24: =D22*D23 | E24: =E22*E23 | F24: =F22*F23 | G24: =G22*G23 | H24: =H22*H23 | I24: =I22*I23 | J24: =J22*J23 | ... L24: =L22*L23
A26: Memo: owner-FCF margin % | C26: =C22/C6*100 | D26: =D22/D6*100 | E26: =E22/E6*100 | F26: =F22/F6*100 | G26: =G22/G6*100 | H26: =H22/H6*100 | I26: =I22/I6*100 | J26: =J22/J6*100 | ... L26: =L22/L6*100
A28: Sum PV of FCF | B28: =SUM(C24:L24)
A29: Terminal growth % (link) | B29: =Assumptions!$B$14
A30: Terminal FCF | B30: =L22*(1+B29/100)
A31: Gordon TV | B31: =IF(Assumptions!$B$5>B29, B30/((Assumptions!$B$5-B29)/100), "n/a")
A32: Cap TV (cap x FCF10) | B32: =Assumptions!$C$14*L22
A33: TV used | B33: =MAX(0,MIN(B31,B32))
A34: Implied exit multiple (x owner FCF) | B34: =B33/L22
A35: PV of TV | B35: =B33*L23
A36: Enterprise value | B36: =B28+B35
A37: less net debt (ex-lease) | B37: =-Assumptions!$B$4
A38: Equity value | B38: =B36+B37
A39: Diluted shares (M) | B39: =Assumptions!$B$3
A40: VALUE PER SHARE (EUR) | B40: =B38/B39
A41: Upside vs price | B41: =B40/Assumptions!$B$2-1
A43: Street memo: PV explicit SBC | B43: =SUMPRODUCT(-C10:L10/(1+Assumptions!$B$5/100)^C4:L4)
A44: PV terminal SBC | B44: =-L10*(1+B29/100)/((Assumptions!$B$5-B29)/100)*L23
...

Sheet FCF_Quality
A1: Reported FCF (company definition: OCF - gross capex + divestments + JV divs + interest recd + lease receipts - interest paid - lease repayments) reconciled to owner FCF
A2: Metric | B2: FY2017 | C2: FY2018 | D2: FY2019 | E2: FY2020 | F2: FY2021 | G2: FY2022 | H2: FY2023 | I2: FY2024 | J2: FY2025
A3: Reported FCF (company) | B3: 1926 | C3: 2165 | D3: 1843 | E3: 2199 | F3: 1618 | G3: 2188 | H3: 2425 | I3: 2545 | J3: 2600
A4: add: interest paid | B4: 320 | C4: 324 | D4: 189 | E4: 149 | F4: 138 | G4: 174 | H4: 226 | I4: 230 | J4: 261
A5: less: interest received | B5: -32 | C5: -74 | D5: -56 | E5: -24 | F5: -16 | G5: -56 | H5: -160 | I5: -196 | J5: -130
A6: less: SBC | B6: -79 | C6: -60 | D6: -51 | E6: -59 | F6: -48 | G6: -65 | H6: -53 | I6: -42 | J6: -70
A7: Owner FCF (sum of above) | B7: =SUM(B3:B6) | C7: =SUM(C3:C6) | D7: =SUM(D3:D6) | E7: =SUM(E3:E6) | F7: =SUM(F3:F6) | G7: =SUM(G3:G6) | H7: =SUM(H3:H6) | I7: =SUM(I3:I6) | J7: =SUM(J3:J6)
A8: Reported FCF margin % | B8: =B3/62890*100 | C8: =C3/62791*100 | D8: =D3/66260*100 | E8: =E3/74736*100 | F8: =F3/75601*100 | G8: =G3/86984*100 | H8: =H3/88734*100 | I8: =I3/89356*100 | J8: =J3/92352*100
A9: Owner FCF margin % | B9: =B7/62890*100 | C9: =C7/62791*100 | D9: =D7/66260*100 | E9: =E7/74736*100 | F9: =F7/75601*100 | G9: =G7/86984*100 | H9: =H7/88734*100 | I9: =I7/89356*100 | J9: =J7/92352*100
A10: Memo: cash taxes paid | B10: 480 | C10: 280 | D10: 358 | E10: 486 | F10: 931 | G10: 397 | H10: 200 | I10: 470 | J10: 499
A11: Memo: lease repayments (in reported FCF) | B11: 0 | C11: 0 | D11: 1530 | E11: 1584 | F11: 1569 | G11: 1755 | H11: 1815 | I11: 1743 | J11: 1944
A13: Notes: FY2017-18 are pre-IFRS-16 (leases were rent inside OCF - economically comparable, mechanically different). FY2021 cash taxes EUR 931m include a catch-up payment; FY2023's EUR 200m was unusually low - the DCF ramps the cash rate 18->22%. FY2025 owner FCF EUR 2,661m is 1.15x the FY2018-25 median (EUR 2,310m) - not a peak base.

Sheet Valuation
A1: Scenario summary
A2: Scenario | B2: Value/share | C2: Upside vs price | D2: Probability | E2: Street value/share | F2: Entry price @15% IRR
A3: Bear | B3: =DCF_Bear!$B$40 | C3: =B3/Assumptions!$B$2-1 | D3: =Assumptions!$D$12 | E3: =DCF_Bear!$B$45 | F3: =(SUMPRODUCT(DCF_Bear!$C$22:$L$22/(1.15)^DCF_Bear!$C$4:$L$4)+DCF_Bear!$B$33/(1.15)^10-Assumptions!$B$4)/Assumptions!$B$3
A4: Base | B4: =DCF_Base!$B$40 | C4: =B4/Assumptions!$B$2-1 | D4: =Assumptions!$D$13 | E4: =DCF_Base!$B$45 | F4: =(SUMPRODUCT(DCF_Base!$C$22:$L$22/(1.15)^DCF_Base!$C$4:$L$4)+DCF_Base!$B$33/(1.15)^10-Assumptions!$B$4)/Assumptions!$B$3
A5: Bull | B5: =DCF_Bull!$B$40 | C5: =B5/Assumptions!$B$2-1 | D5: =Assumptions!$D$14 | E5: =DCF_Bull!$B$45 | F5: =(SUMPRODUCT(DCF_Bull!$C$22:$L$22/(1.15)^DCF_Bull!$C$4:$L$4)+DCF_Bull!$B$33/(1.15)^10-Assumptions!$B$4)/Assumptions!$B$3
A7: Probability-weighted IV | B7: =SUMPRODUCT(B3:B5,D3:D5)
A8: Margin of safety | B8: =1-Assumptions!$B$2/B7
A9: Street weighted IV | B9: =SUMPRODUCT(E3:E5,D3:D5)
A10: Weighted entry price @15% | B10: =SUMPRODUCT(F3:F5,D3:D5)
A11: Band position | B11: n/a - SBC is 0.08% of revenue; house/street band ~EUR 1.7 wide, collapsed
A13: Required-return table (base case): value per share at r
A14: r (%) | B14: 6.8 | C14: 9 | D14: 10 | E14: 11 | F14: 12 | G14: 15
A15: Value/share | B15: =IF(6.8>Assumptions!$B$13,(SUMPRODUCT(DCF_Base!$C$22:$L$22/(1+6.8/100)^DCF_Base!$C$4:$L$4)+MAX(0,MIN(DCF_Base!$L$22*(1+Assumptions!$B$13/100)/((6.8-Assumptions!$B$13)/100),Assumptions!$C$13*DCF_Base!$L$22))/(1+6.8/100)^10-Assumptions!$B$4)/Assumptions!$B$3,"n/a") | C15: =IF(9>Assumptions!$B$13,(SUMPRODUCT(DCF_Base!$C$22:$L$22/(1+9/100)^DCF_Base!$C$4:$L$4)+MAX(0,MIN(DCF_Base!$L$22*(1+Assumptions!$B$13/100)/((9-Assumptions!$B$13)/100),Assumptions!$C$13*DCF_Base!$L$22))/(1+9/100)^10-Assumptions!$B$4)/Assumptions!$B$3,"n/a") | D15: =IF(10>Assumptions!$B$13,(SUMPRODUCT(DCF_Base!$C$22:$L$22/(1+10/100)^DCF_Base!$C$4:$L$4)+MAX(0,MIN(DCF_Base!$L$22*(1+Assumptions!$B$13/100)/((10-Assumptions!$B$13)/100),Assumptions!$C$13*DCF_Base!$L$22))/(1+10/100)^10-Assumptions!$B$4)/Assumptions!$B$3,"n/a") | E15: =IF(11>Assumptions!$B$13,(SUMPRODUCT(DCF_Base!$C$22:$L$22/(1+11/100)^DCF_Base!$C$4:$L$4)+MAX(0,MIN(DCF_Base!$L$22*(1+Assumptions!$B$13/100)/((11-Assumptions!$B$13)/100),Assumptions!$C$13*DCF_Base!$L$22))/(1+11/100)^10-Assumptions!$B$4)/Assumptions!$B$3,"n/a") | F15: =IF(12>Assumptions!$B$13,(SUMPRODUCT(DCF_Base!$C$22:$L$22/(1+12/100)^DCF_Base!$C$4:$L$4)+MAX(0,MIN(DCF_Base!$L$22*(1+Assumptions!$B$13/100)/((12-Assumptions!$B$13)/100),Assumptions!$C$13*DCF_Base!$L$22))/(1+12/100)^10-Assumptions!$B$4)/Assumptions!$B$3,"n/a") | G15: =IF(15>Assumptions!$B$13,(SUMPRODUCT(DCF_Base!$C$22:$L$22/(1+15/100)^DCF_Base!$C$4:$L$4)+MAX(0,MIN(DCF_Base!$L$22*(1+Assumptions!$B$13/100)/((15-Assumptions!$B$13)/100),Assumptions!$C$13*DCF_Base!$L$22))/(1+15/100)^10-Assumptions!$B$4)/Assumptions!$B$3,"n/a")
A17: Sensitivity: WACC (rows) x terminal growth (cols), base case
B18: 0.75 | C18: 1.25 | D18: 1.75 | E18: 2.25 | F18: 2.75
A19: 4.8 | B19: =IF(4.8>0.75,(SUMPRODUCT(DCF_Base!$C$22:$L$22/(1+4.8/100)^DCF_Base!$C$4:$L$4)+MAX(0,MIN(DCF_Base!$L$22*(1+0.75/100)/((4.8-0.75)/100),Assumptions!$C$13*DCF_Base!$L$22))/(1+4.8/100)^10-Assumptions!$B$4)/Assumptions!$B$3,"n/a") | C19: =IF(4.8>1.25,(SUMPRODUCT(DCF_Base!$C$22:$L$22/(1+4.8/100)^DCF_Base!$C$4:$L$4)+MAX(0,MIN(DCF_Base!$L$22*(1+1.25/100)/((4.8-1.25)/100),Assumptions!$C$13*DCF_Base!$L$22))/(1+4.8/100)^10-Assumptions!$B$4)/Assumptions!$B$3,"n/a") | D19: =IF(4.8>1.75,(SUMPRODUCT(DCF_Base!$C$22:$L$22/(1+4.8/100)^DCF_Base!$C$4:$L$4)+MAX(0,MIN(DCF_Base!$L$22*(1+1.75/100)/((4.8-1.75)/100),Assumptions!$C$13*DCF_Base!$L$22))/(1+4.8/100)^10-Assumptions!$B$4)/Assumptions!$B$3,"n/a") | E19: =IF(4.8>2.25,(SUMPRODUCT(DCF_Base!$C$22:$L$22/(1+4.8/100)^DCF_Base!$C$4:$L$4)+MAX(0,MIN(DCF_Base!$L$22*(1+2.25/100)/((4.8-2.25)/100),Assumptions!$C$13*DCF_Base!$L$22))/(1+4.8/100)^10-Assumptions!$B$4)/Assumptions!$B$3,"n/a") | F19: =IF(4.8>2.75,(SUMPRODUCT(DCF_Base!$C$22:$L$22/(1+4.8/100)^DCF_Base!$C$4:$L$4)+MAX(0,MIN(DCF_Base!$L$22*(1+2.75/100)/((4.8-2.75)/100),Assumptions!$C$13*DCF_Base!$L$22))/(1+4.8/100)^10-Assumptions!$B$4)/Assumptions!$B$3,"n/a")
A20: 5.8 | B20: =IF(5.8>0.75,(SUMPRODUCT(DCF_Base!$C$22:$L$22/(1+5.8/100)^DCF_Base!$C$4:$L$4)+MAX(0,MIN(DCF_Base!$L$22*(1+0.75/100)/((5.8-0.75)/100),Assumptions!$C$13*DCF_Base!$L$22))/(1+5.8/100)^10-Assumptions!$B$4)/Assumptions!$B$3,"n/a") | C20: =IF(5.8>1.25,(SUMPRODUCT(DCF_Base!$C$22:$L$22/(1+5.8/100)^DCF_Base!$C$4:$L$4)+MAX(0,MIN(DCF_Base!$L$22*(1+1.25/100)/((5.8-1.25)/100),Assumptions!$C$13*DCF_Base!$L$22))/(1+5.8/100)^10-Assumptions!$B$4)/Assumptions!$B$3,"n/a") | D20: =IF(5.8>1.75,(SUMPRODUCT(DCF_Base!$C$22:$L$22/(1+5.8/100)^DCF_Base!$C$4:$L$4)+MAX(0,MIN(DCF_Base!$L$22*(1+1.75/100)/((5.8-1.75)/100),Assumptions!$C$13*DCF_Base!$L$22))/(1+5.8/100)^10-Assumptions!$B$4)/Assumptions!$B$3,"n/a") | E20: =IF(5.8>2.25,(SUMPRODUCT(DCF_Base!$C$22:$L$22/(1+5.8/100)^DCF_Base!$C$4:$L$4)+MAX(0,MIN(DCF_Base!$L$22*(1+2.25/100)/((5.8-2.25)/100),Assumptions!$C$13*DCF_Base!$L$22))/(1+5.8/100)^10-Assumptions!$B$4)/Assumptions!$B$3,"n/a") | F20: =IF(5.8>2.75,(SUMPRODUCT(DCF_Base!$C$22:$L$22/(1+5.8/100)^DCF_Base!$C$4:$L$4)+MAX(0,MIN(DCF_Base!$L$22*(1+2.75/100)/((5.8-2.75)/100),Assumptions!$C$13*DCF_Base!$L$22))/(1+5.8/100)^10-Assumptions!$B$4)/Assumptions!$B$3,"n/a")
A21: 6.8 | B21: =IF(6.8>0.75,(SUMPRODUCT(DCF_Base!$C$22:$L$22/(1+6.8/100)^DCF_Base!$C$4:$L$4)+MAX(0,MIN(DCF_Base!$L$22*(1+0.75/100)/((6.8-0.75)/100),Assumptions!$C$13*DCF_Base!$L$22))/(1+6.8/100)^10-Assumptions!$B$4)/Assumptions!$B$3,"n/a") | C21: =IF(6.8>1.25,(SUMPRODUCT(DCF_Base!$C$22:$L$22/(1+6.8/100)^DCF_Base!$C$4:$L$4)+MAX(0,MIN(DCF_Base!$L$22*(1+1.25/100)/((6.8-1.25)/100),Assumptions!$C$13*DCF_Base!$L$22))/(1+6.8/100)^10-Assumptions!$B$4)/Assumptions!$B$3,"n/a") | D21: =IF(6.8>1.75,(SUMPRODUCT(DCF_Base!$C$22:$L$22/(1+6.8/100)^DCF_Base!$C$4:$L$4)+MAX(0,MIN(DCF_Base!$L$22*(1+1.75/100)/((6.8-1.75)/100),Assumptions!$C$13*DCF_Base!$L$22))/(1+6.8/100)^10-Assumptions!$B$4)/Assumptions!$B$3,"n/a") | E21: =IF(6.8>2.25,(SUMPRODUCT(DCF_Base!$C$22:$L$22/(1+6.8/100)^DCF_Base!$C$4:$L$4)+MAX(0,MIN(DCF_Base!$L$22*(1+2.25/100)/((6.8-2.25)/100),Assumptions!$C$13*DCF_Base!$L$22))/(1+6.8/100)^10-Assumptions!$B$4)/Assumptions!$B$3,"n/a") | F21: =IF(6.8>2.75,(SUMPRODUCT(DCF_Base!$C$22:$L$22/(1+6.8/100)^DCF_Base!$C$4:$L$4)+MAX(0,MIN(DCF_Base!$L$22*(1+2.75/100)/((6.8-2.75)/100),Assumptions!$C$13*DCF_Base!$L$22))/(1+6.8/100)^10-Assumptions!$B$4)/Assumptions!$B$3,"n/a")
A22: 7.8 | B22: =IF(7.8>0.75,(SUMPRODUCT(DCF_Base!$C$22:$L$22/(1+7.8/100)^DCF_Base!$C$4:$L$4)+MAX(0,MIN(DCF_Base!$L$22*(1+0.75/100)/((7.8-0.75)/100),Assumptions!$C$13*DCF_Base!$L$22))/(1+7.8/100)^10-Assumptions!$B$4)/Assumptions!$B$3,"n/a") | C22: =IF(7.8>1.25,(SUMPRODUCT(DCF_Base!$C$22:$L$22/(1+7.8/100)^DCF_Base!$C$4:$L$4)+MAX(0,MIN(DCF_Base!$L$22*(1+1.25/100)/((7.8-1.25)/100),Assumptions!$C$13*DCF_Base!$L$22))/(1+7.8/100)^10-Assumptions!$B$4)/Assumptions!$B$3,"n/a") | D22: =IF(7.8>1.75,(SUMPRODUCT(DCF_Base!$C$22:$L$22/(1+7.8/100)^DCF_Base!$C$4:$L$4)+MAX(0,MIN(DCF_Base!$L$22*(1+1.75/100)/((7.8-1.75)/100),Assumptions!$C$13*DCF_Base!$L$22))/(1+7.8/100)^10-Assumptions!$B$4)/Assumptions!$B$3,"n/a") | E22: =IF(7.8>2.25,(SUMPRODUCT(DCF_Base!$C$22:$L$22/(1+7.8/100)^DCF_Base!$C$4:$L$4)+MAX(0,MIN(DCF_Base!$L$22*(1+2.25/100)/((7.8-2.25)/100),Assumptions!$C$13*DCF_Base!$L$22))/(1+7.8/100)^10-Assumptions!$B$4)/Assumptions!$B$3,"n/a") | F22: =IF(7.8>2.75,(SUMPRODUCT(DCF_Base!$C$22:$L$22/(1+7.8/100)^DCF_Base!$C$4:$L$4)+MAX(0,MIN(DCF_Base!$L$22*(1+2.75/100)/((7.8-2.75)/100),Assumptions!$C$13*DCF_Base!$L$22))/(1+7.8/100)^10-Assumptions!$B$4)/Assumptions!$B$3,"n/a")
A23: 8.8 | B23: =IF(8.8>0.75,(SUMPRODUCT(DCF_Base!$C$22:$L$22/(1+8.8/100)^DCF_Base!$C$4:$L$4)+MAX(0,MIN(DCF_Base!$L$22*(1+0.75/100)/((8.8-0.75)/100),Assumptions!$C$13*DCF_Base!$L$22))/(1+8.8/100)^10-Assumptions!$B$4)/Assumptions!$B$3,"n/a") | C23: =IF(8.8>1.25,(SUMPRODUCT(DCF_Base!$C$22:$L$22/(1+8.8/100)^DCF_Base!$C$4:$L$4)+MAX(0,MIN(DCF_Base!$L$22*(1+1.25/100)/((8.8-1.25)/100),Assumptions!$C$13*DCF_Base!$L$22))/(1+8.8/100)^10-Assumptions!$B$4)/Assumptions!$B$3,"n/a") | D23: =IF(8.8>1.75,(SUMPRODUCT(DCF_Base!$C$22:$L$22/(1+8.8/100)^DCF_Base!$C$4:$L$4)+MAX(0,MIN(DCF_Base!$L$22*(1+1.75/100)/((8.8-1.75)/100),Assumptions!$C$13*DCF_Base!$L$22))/(1+8.8/100)^10-Assumptions!$B$4)/Assumptions!$B$3,"n/a") | E23: =IF(8.8>2.25,(SUMPRODUCT(DCF_Base!$C$22:$L$22/(1+8.8/100)^DCF_Base!$C$4:$L$4)+MAX(0,MIN(DCF_Base!$L$22*(1+2.25/100)/((8.8-2.25)/100),Assumptions!$C$13*DCF_Base!$L$22))/(1+8.8/100)^10-Assumptions!$B$4)/Assumptions!$B$3,"n/a") | F23: =IF(8.8>2.75,(SUMPRODUCT(DCF_Base!$C$22:$L$22/(1+8.8/100)^DCF_Base!$C$4:$L$4)+MAX(0,MIN(DCF_Base!$L$22*(1+2.75/100)/((8.8-2.75)/100),Assumptions!$C$13*DCF_Base!$L$22))/(1+8.8/100)^10-Assumptions!$B$4)/Assumptions!$B$3,"n/a")
A25: Note: the TV cap (11-14x owner FCF) binds at nearly every cell, so terminal-growth sensitivity is deliberately nil; WACC and the cap are the levers.
