Workbook

Sheet Model_Info
A1: UCB SA (UCB.BR) -- DCF Model: provenance and how to use
A3: Version | B3: v1.0 -- first DCF for this ticker. Supersedes nothing; no prior UCB.BR_DCF.json existed.
A4: Built by | B4: dcf-analyst agent (Claude Opus 5), 2026-08-29, at the user request to value UCB.BR.
A5: Model | B5: Owner-FCF DCF, 10-year explicit component build, three scenarios, probability-weighted.
A6: Routing | B6: Routed via .claude/skills/dcf-methods/SKILL.md. UCB is a conventional branded-pharma operating company, so row 1/2 (owner-FCF DCF) applies. Not a bank/REIT/trust/shell.
A7: Authority | B7: This workbook and UCB.BR_DCF.json implement the SAME model and agree to the cent. If they ever diverge, one is wrong -- do not paper over it.
A9: DATA VINTAGE -- all figures go stale
A10: Price | B10: EUR 216.5 as of 2026-08-28T15:35:27Z regular close (Yahoo regularMarketTime). Source Yahoo Finance chart API. 52wk 191.2-289.5.
A11: Balance sheet | B11: 2026-06-30 -- UCB H1-2026 Half-Year Financial Report. Net financial debt EUR 2,821m. NOT the FY2025 near-net-cash position, which the June-2026 acquisitions ended.
A12: Share count | B12: Fully diluted 193,954,539 -- H1-2026 interim report, EPS note 3. Basic 190,597,758.
A13: Guidance | B13: FY2026, raised at H1-2026 results 30-Jul-2026: revenue growth low-teens to mid-teens % CER; adjusted EBITDA growth mid-teens to low-twenties % CER; tax rate 15%; FX drag approx -2pt revenue and -6pt EBITDA. Guidance EXCLUDES US tariffs and MFN pricing.
A14: Last actuals | B14: FY2025 annual report (revenue 7,741; adj EBITDA 2,636; FCF 1,842; SBC 188) and H1-2026 interim (revenue 4,270; adj EBITDA 1,736; OCF 369; capex 446).
A16: METHODOLOGY CHOICES
A17: Base FCF | B17: Owner FCF 1,608 = reported 1,842 - SBC 188 - interest income 46. Interest income stripped because net cash was material at FY2025; its source asset sits in the bridge.
A18: FY2025 not mid-cycled | B18: FY2025 FCF is 2.7x the FY2015-24 median, but that median describes the pre-Bimzelx company. Built off a normalized FORWARD base instead. Terminal MARGIN is mid-cycled instead (base fades 37.5% to 36.0%; bear to 27%).
A19: H1-2026 negative FCF | B19: EUR -77m is not the run-rate: OCF was +369m; the swing is a -623m working-capital outflow from growth plus a capex spike (446m in one half vs 449m for all FY2025). The -2,227m for Candid/Neurona is investing, below the FCF line.
A20: Horizon | B20: 10 years. Year-5 base owner-FCF margin is 22.8% and still rising, so a 5-year Gordon would capitalize an immature margin.
A21: WACC | B21: 8.0%, built in EUR (the flows own currency). Bund ~2.8% + EUR ERP 5.0% x beta ~1.0 = 7.8% CoE; CAPM WACC ~7.7%, rounded up to 8.0% for Bimzelx single-asset concentration and the MFN/tariff risk management excludes from guidance. SAME WACC in all three scenarios -- risk charged once.
A22: Leases | B22: Treatment (A), leases as debt. Lease principal NOT deducted from flows; lease liabilities of EUR 209m ARE inside the 3,588m total debt. Charged once. lease_cost_pct = 0.
A23: Minority interests | B23: Nil -- UCB reports NCI of EUR 0m FY2022-FY2025. No adjustment either side.
A24: Working capital | B24: wc_capture NEGATIVE (-12% base). Pharma growth consumes cash into receivables and inventory; this is not a prepaid-subscription deferred-revenue tailwind.
A25: SBC | B25: EUR 188m, 2.43% of revenue, fully expensed in the flows AND share count held flat. Charged once.
A26: Terminal value | B26: max(0, min(Gordon, cap x FCF10)). Cap 18x base/bull, 14x bear -- below the 20x house default because branded pharma carries patent-cliff risk.
A28: SCENARIO DRIVERS | B28: Set by the dcf-analyst agent on 2026-08-29 from FY2025 actuals, H1-2026 actuals and FY2026 guidance. They are judgments, not facts. Weights 25/50/25 bear/base/bull.
A29: REFRESH AFTER NEXT PRINT | B29: After FY2026 results (approx Feb-2027): reset the FY0 revenue and EBITDA anchors, refresh net debt and the diluted count from the Dec-2026 balance sheet, and re-judge the year-1 growth and margin against actual FY2026. Later-year paths should stay put unless specific evidence moves them, and a reconciliation bridge is required.
A31: CELL COLOUR LEGEND
A32: Blue bold | B32: Hardcoded input -- safe to change.
A33: Yellow fill | B33: Key lever -- the drivers most worth flexing.
A34: Black | B34: Formula -- do not overwrite.
A35: Green | B35: Cross-sheet link, or the highlighted answer cell.

Sheet Actuals
A1: Reported history and current guidance -- all hardcoded
B3: FY2020 | C3: FY2021 | D3: FY2022 | E3: FY2023 | F3: FY2024 | G3: FY2025 | H3: H1 2026 | I3: Source
A4: Revenue | B4: 5347 | C4: 5777 | D4: 5517 | E4: 5252 | F4: 6152 | G4: 7741 | H4: 4270 | I4: UCB.BR_Metrics.csv, from annual/interim reports
A5: Adjusted EBITDA | B5: 1441 | C5: 1641 | D5: 1260 | E5: 1349 | F5: 1476 | G5: 2636 | H5: 1736 | I5: Company adjusted EBITDA (non-IFRS), results releases
A6: Adj EBITDA margin % | B6: 26.9 | C6: 28.4 | D6: 22.8 | E6: 25.7 | F6: 24 | G6: 34.1 | H6: 40.7 | I6: Derived
A7: Net income | B7: 732 | C7: 1058 | D7: 418 | E7: 343 | F7: 1065 | G7: 1558 | H7: 1111 | I7: Consolidated income statement
A8: Operating cash flow | B8: 1081 | C8: 1553 | D8: 1119 | E8: 761 | F8: 1242 | G8: 2291 | H8: 369 | I8: Consolidated cash flow statement
A9: Capex | B9: 349 | C9: 493 | D9: 371 | E9: 316 | F9: 322 | G9: 449 | H9: 446 | I9: PP&E + intangible acquisitions
A10: Reported free cash flow | B10: 732 | C10: 1060 | D10: 748 | E10: 445 | F10: 920 | G10: 1842 | H10: -77 | I10: OCF less capex
A11: Stock-based compensation | B11: 81 | C11: 109 | D11: 81 | E11: 104 | F11: 183 | G11: 188 | I11: Share-based payments to employees and directors; H1 not disclosed
A12: Interest income | B12: 20 | C12: 17 | D12: 20 | E12: 20 | F12: 29 | G12: 46 | H12: 18 | I12: Interest received, cash flow statement
A13: Owner FCF | B13: 631 | C13: 934 | D13: 647 | E13: 321 | F13: 708 | G13: 1608 | I13: Reported FCF less SBC less interest income
A14: Shareholders equity | B14: 7272 | C14: 8386 | D14: 9064 | E14: 8975 | F14: 10029 | G14: 10867 | H14: 11654 | I14: Balance sheet
A15: Total debt | B15: 2747 | C15: 2123 | D15: 2900 | E15: 3038 | F15: 3026 | G15: 2245 | H15: 3588 | I15: Bonds + borrowings + lease liabilities
A16: Cash and equivalents | B16: 1336 | C16: 1263 | D16: 899 | E16: 861 | F16: 1573 | G16: 2251 | H16: 766 | I16: Balance sheet
A17: Net financial debt | B17: 1411 | C17: 860 | D17: 2000 | E17: 2177 | F17: 1454 | G17: -7 | H17: 2821 | I17: Company-stated; H1-2026 is 0.8x adj EBITDA
A18: Non-controlling interests | C18: 0 | D18: 0 | E18: 0 | F18: 0 | G18: 0 | H18: 0 | I18: NIL -- no NCI adjustment needed anywhere
A19: Treasury shares acquired | F19: 162 | G19: 121 | H19: 127 | I19: Financing activities -- funds the flat share count
A20: Dividends paid | B20: 235 | C20: 240 | D20: 247 | E20: 252 | F20: 259 | G20: 264 | H20: 276 | I20: Dividend paid to UCB shareholders
A22: BALANCE SHEET SNAPSHOT at 2026-06-30
A23: Bonds | B23: 1425 | I23: Note 3.25: Eurobond 476, EMTN 145, retail 305, Eurobond 499
A24: Bank borrowings | B24: 1804 | I24: Note 3.24 non-current 1,805 + current -1
A25: Debentures and short-term loans | B25: 150 | I25: Note 3.24 current
A26: Lease liabilities | B26: 209 | I26: Note 3.24: non-current 141 + current 68 -- INSIDE net debt, treatment A
A27: Total debt | B27: 3588 | I27: Sum of the above
A28: Less cash | B28: -766 | I28: Net cash and cash equivalents at 30-Jun-2026
A29: Net financial debt | B29: 2821 | I29: Agrees with company-stated EUR 2,821m
A31: DILUTED SHARE COUNT
A32: Basic weighted average (m) | B32: 190.598 | I32: H1-2026 EPS note 2
A33: Fully diluted (m) | B33: 193.955 | I33: H1-2026 EPS note 3 -- THIS is the valuation divisor
A34: Assumed annual share growth % | B34: 0 | I34: Zero: SBC is expensed, so the count is held flat
A36: FY2026 GUIDANCE (raised 30-Jul-2026)
A37: Revenue growth | B37: Low-teens to mid-teens % CER
A38: Adjusted EBITDA growth | B38: Mid-teens to low-twenties % CER
A39: Tax rate | B39: 15%
A40: FX drag | B40: approx -2pt revenue, -6pt adjusted EBITDA at 30-Jun-2026 rates
A41: BIMZELX peak sales | B41: At least EUR 7 billion
A42: Excluded from guidance | B42: US tariffs and any Most-Favoured-Nation pricing arrangement

Sheet Assumptions
A1: Global assumptions, scenario terminals and narratives
A3: GLOBALS
A4: WACC % | B4: 8 | C4: EUR-built: Bund 2.8% + ERP 5.0% x beta 1.0 = 7.8% CoE, CAPM WACC 7.7%, rounded to 8.0% for Bimzelx concentration and excluded MFN/tariff risk. SAME in all scenarios.
A5: Diluted shares (m) | B5: 193.955 | C5: H1-2026 EPS note 3. Held flat -- SBC expensed instead.
A6: Net debt (EUR m) | B6: 2821 | C6: At 2026-06-30, post Candid and Neurona. Positive = debt.
A7: Current price (EUR) | B7: 216.5 | C7: Yahoo close 2026-08-28T15:35:27Z.
A8: FY2025 revenue (EUR m) | B8: 7741 | C8: FY0 anchor for every scenario.
A9: Entry hurdle rate % | B9: 15 | C9: IRR required for the entry-price calculation.
A10: FY2025 owner FCF (EUR m) | B10: 1608 | C10: 1,842 reported - 188 SBC - 46 interest income.
A12: PER-SCENARIO TERMINALS AND WEIGHTS
B13: Bear | C13: Base | D13: Bull
A14: Terminal growth % | B14: 1 | C14: 2 | D14: 2.5
A15: Terminal FCF cap multiple | B15: 14 | C15: 18 | D15: 18
A16: Probability weight | B16: 0.25 | C16: 0.5 | D16: 0.25
A17: Working capital capture % | B17: -13 | C17: -12 | D17: -11
A18: Weights check (must be 100%) | B18: =SUM(B16:D16)
A20: SCENARIO NARRATIVES
A21: BEAR | C21: BEAR (25%). The three live adverse paths land together. Cimzia biosimilars finally arrive -- the molecule has been biosimilar-free for over two years past LOE on manufacturing difficulty alone, which is a reprieve rather than a moat, and roughly EUR 1.9bn/yr is exposed. US MFN reference pricing and pharma tariffs land; management explicitly excludes both from guidance, so the guided numbers carry no allowance for them whatsoever. And Bimzelx growth is bought with price: management itself flags net pricing erosion as access widens, and Cosentyx, Taltz, Skyrizi and Tremfya are all well-capitalized defenders. Meanwhile the legacy epilepsy base keeps shrinking -- Briviact lost US exclusivity Feb-2026 with the EU following in Aug-2026, and Vimpat fell 41% in H1 on Japanese generics. Revenue rolls over from FY2028 and the adjusted EBITDA margin retraces from 40.7% to 27%, i.e. the H1-2026 margin proves to be the cycle peak.
A22: BASE | C22: BASE (50%). Bimzelx keeps compounding but decelerates as it approaches the guided EUR 7bn+ peak, and the gMG duo plus Fintepla and the Evenity profit-share more than cover the epilepsy and Cimzia decline. Revenue grows 14% in FY2026 -- inside guidance once the -2pt FX drag is applied, and deliberately BELOW the H1-2026 run-rate, which annualizes closer to 20%. Adjusted EBITDA margin improves from 34.5% to a 37.5% peak on operating leverage, then FADES to 36.0% as pricing erosion and the R&D step-up from Candid and Neurona bite. Capex starts elevated at 8% of revenue for the Georgia biologics campus before tapering to 5.5%. Cash tax ramps 17% to 21% as the R&D incentives and recognized deferred tax assets are used up.
A23: BULL | C23: BULL (25%). Bimzelx reaches and passes the EUR 7bn peak guidance, helped by pediatric, PPP and further indication expansion, and it holds price while doing so -- the four head-to-head superiority wins (vs secukinumab, ustekinumab, adalimumab and now risankizumab on ACR50) translate into durable share rather than discounting. Rystiggo and Zilbrysq scale as the only dual-mechanism gMG portfolio against argenx Vyvgart, Fintepla broadens into CDKL5 and Rett, and the Candid T-cell-engager platform and Neurona cell therapy start to look like a second growth wave rather than a cash cost. Margin reaches 41.5% and holds. Note this case requires SEVERAL independent things to go right at once, which is why it carries 25% and not the house 35%.
A25: Weights rationale | C25: 25 bear / 50 base / 25 bull, moved off the 15/50/35 house default by taking 10pp from the bull and giving it to the bear. Bear raised to 25% because three independent adverse paths are live and none is remote: (1) US MFN pricing and pharma tariffs, which management explicitly excludes from guidance so the guided numbers carry no allowance for them at all; (2) Cimzia, ~EUR 1.9bn/yr, has been biosimilar-free for over two years past LOE on manufacturing difficulty alone -- that is a reprieve, not a moat, and it can end in any quarter; (3) Briviact lost US exclusivity Feb-2026 with EU to follow Aug-2026 while Vimpat fell 41% in H1. Bull cut to 25% because it needs several independent things to go right together -- Bimzelx reaching EUR 7bn+ peak AND holding price as access widens (management itself flags net pricing erosion) AND the gMG duo scaling against argenx's Vyvgart AND the Candid/Neurona pipeline paying off. Base at 50%.

Sheet DCF_Bear
A1: UCB.BR -- BEAR case, 10-year owner-FCF build
A3: Year | B3: 2025A | C3: 2026E | D3: 2027E | E3: 2028E | F3: 2029E | G3: 2030E | H3: 2031E | I3: 2032E | J3: 2033E | K3: 2034E | L3: 2035E
A4: Year index | B4: 0 | C4: 1 | D4: 2 | E4: 3 | F4: 4 | G4: 5 | H4: 6 | I4: 7 | J4: 8 | K4: 9 | L4: 10
A5: Revenue growth % (driver) | C5: 10 | D5: 4 | E5: 1 | F5: -1 | G5: -2 | H5: -1 | I5: 0 | J5: 1 | K5: 1.5 | L5: 1.5
A6: Revenue | B6: 7741 | C6: =B6*(1+C5/100) | D6: =C6*(1+D5/100) | E6: =D6*(1+E5/100) | F6: =E6*(1+F5/100) | G6: =F6*(1+G5/100) | H6: =G6*(1+H5/100) | I6: =H6*(1+I5/100) | J6: =I6*(1+J5/100) | ... L6: =K6*(1+L5/100)
A7: Adj EBITDA margin % (driver) | C7: 32.5 | D7: 31.5 | E7: 30 | F7: 28.5 | G7: 27.5 | H7: 27 | I7: 27 | J7: 27 | K7: 27 | L7: 27
A8: Adjusted EBITDA | C8: =C6*C7/100 | D8: =D6*D7/100 | E8: =E6*E7/100 | F8: =F6*F7/100 | G8: =G6*G7/100 | H8: =H6*H7/100 | I8: =I6*I7/100 | J8: =J6*J7/100 | ... L8: =L6*L7/100
A9: SBC % of revenue (driver) | C9: 2.5 | D9: 2.5 | E9: 2.5 | F9: 2.5 | G9: 2.5 | H9: 2.5 | I9: 2.5 | J9: 2.5 | K9: 2.5 | L9: 2.5
A10: SBC (negative) | C10: =-C6*C9/100 | D10: =-D6*D9/100 | E10: =-E6*E9/100 | F10: =-F6*F9/100 | G10: =-G6*G9/100 | H10: =-H6*H9/100 | I10: =-I6*I9/100 | J10: =-J6*J9/100 | ... L10: =-L6*L9/100
A11: Owner EBITDA (SBC expensed) | C11: =C8+C10 | D11: =D8+D10 | E11: =E8+E10 | F11: =F8+F10 | G11: =G8+G10 | H11: =H8+H10 | I11: =I8+I10 | J11: =J8+J10 | ... L11: =L8+L10
A12: D&A % of revenue (driver) | C12: 7.8 | D12: 7.8 | E12: 7.7 | F12: 7.6 | G12: 7.5 | H12: 7.5 | I12: 7.5 | J12: 7.5 | K12: 7.5 | L12: 7.5
A13: D&A (negative) | C13: =-C6*C12/100 | D13: =-D6*D12/100 | E13: =-E6*E12/100 | F13: =-F6*F12/100 | G13: =-G6*G12/100 | H13: =-H6*H12/100 | I13: =-I6*I12/100 | J13: =-J6*J12/100 | ... L13: =-L6*L12/100
A14: EBIT, SBC expensed | C14: =C11+C13 | D14: =D11+D13 | E14: =E11+E13 | F14: =F11+F13 | G14: =G11+G13 | H14: =H11+H13 | I14: =I11+I13 | J14: =J11+J13 | ... L14: =L11+L13
A15: Cash tax rate % (driver) | C15: 18 | D15: 20 | E15: 22 | F15: 23 | G15: 24 | H15: 24 | I15: 24 | J15: 24 | K15: 24 | L15: 24
A16: NOPAT | C16: =C14*(1-C15/100) | D16: =D14*(1-D15/100) | E16: =E14*(1-E15/100) | F16: =F14*(1-F15/100) | G16: =G14*(1-G15/100) | H16: =H14*(1-H15/100) | I16: =I14*(1-I15/100) | J16: =J14*(1-J15/100) | ... L16: =L14*(1-L15/100)
A17: add back D&A | C17: =-C13 | D17: =-D13 | E17: =-E13 | F17: =-F13 | G17: =-G13 | H17: =-H13 | I17: =-I13 | J17: =-J13 | ... L17: =-L13
A18: Capex % of revenue (driver) | C18: 8.2 | D18: 7.5 | E18: 7 | F18: 6.5 | G18: 6.2 | H18: 6 | I18: 6 | J18: 6 | K18: 6 | L18: 6
A19: less capex | C19: =-C6*C18/100 | D19: =-D6*D18/100 | E19: =-E6*E18/100 | F19: =-F6*F18/100 | G19: =-G6*G18/100 | H19: =-H6*H18/100 | I19: =-I6*I18/100 | J19: =-J6*J18/100 | ... L19: =-L6*L18/100
A20: Working capital (on revenue CHANGE) | C20: =Assumptions!$B$17/100*(C6-B6) | D20: =Assumptions!$B$17/100*(D6-C6) | E20: =Assumptions!$B$17/100*(E6-D6) | F20: =Assumptions!$B$17/100*(F6-E6) | G20: =Assumptions!$B$17/100*(G6-F6) | H20: =Assumptions!$B$17/100*(H6-G6) | I20: =Assumptions!$B$17/100*(I6-H6) | J20: =Assumptions!$B$17/100*(J6-I6) | ... L20: =Assumptions!$B$17/100*(L6-K6)
A21: UNLEVERED OWNER FCF | C21: =C16+C17+C19+C20 | D21: =D16+D17+D19+D20 | E21: =E16+E17+E19+E20 | F21: =F16+F17+F19+F20 | G21: =G16+G17+G19+G20 | H21: =H16+H17+H19+H20 | I21: =I16+I17+I19+I20 | J21: =J16+J17+J19+J20 | ... L21: =L16+L17+L19+L20
A22: Discount factor | C22: =1/(1+Assumptions!$B$4/100)^C4 | D22: =1/(1+Assumptions!$B$4/100)^D4 | E22: =1/(1+Assumptions!$B$4/100)^E4 | F22: =1/(1+Assumptions!$B$4/100)^F4 | G22: =1/(1+Assumptions!$B$4/100)^G4 | H22: =1/(1+Assumptions!$B$4/100)^H4 | I22: =1/(1+Assumptions!$B$4/100)^I4 | J22: =1/(1+Assumptions!$B$4/100)^J4 | ... L22: =1/(1+Assumptions!$B$4/100)^L4
A23: PV of FCF | C23: =C21*C22 | D23: =D21*D22 | E23: =E21*E22 | F23: =F21*F22 | G23: =G21*G22 | H23: =H21*H22 | I23: =I21*I22 | J23: =J21*J22 | ... L23: =L21*L22
A25: Memo: FCF before SBC (company style) | C25: =C21-C10 | D25: =D21-D10 | E25: =E21-E10 | F25: =F21-F10 | G25: =G21-G10 | H25: =H21-H10 | I25: =I21-I10 | J25: =J21-J10 | ... L25: =L21-L10
A26: Memo: owner FCF margin % | C26: =C21/C6*100 | D26: =D21/D6*100 | E26: =E21/E6*100 | F26: =F21/F6*100 | G26: =G21/G6*100 | H26: =H21/H6*100 | I26: =I21/I6*100 | J26: =J21/J6*100 | ... L26: =L21/L6*100
A28: VALUATION
A29: Sum of PV of FCF | B29: =SUM(C23:L23)
A30: Terminal growth % | B30: =Assumptions!$B$14
A31: Terminal FCF cap multiple | B31: =Assumptions!$B$15
A32: Terminal-year FCF grown one year | B32: =L21*(1+B30/100)
A33: Gordon terminal value | B33: =L21*(1+B30/100)/((Assumptions!$B$4-B30)/100)
A34: Cap terminal value | B34: =B31*L21
A35: Terminal value used | B35: =MAX(0,MIN(B33,B34))
A36: Which bound | B36: =IF(B34<B33,"cap","gordon")
A37: Implied exit multiple | B37: =B35/L21
A38: PV of terminal value | B38: =B35*L22
A39: Enterprise value | B39: =B29+B38
A40: Terminal % of EV | B40: =B38/B39*100
A41: less net debt | B41: =-Assumptions!$B$6
A42: Equity value | B42: =B39+B41
A43: Diluted shares (m) | B43: =Assumptions!$B$5
...

Sheet DCF_Base
A1: UCB.BR -- BASE case, 10-year owner-FCF build
A3: Year | B3: 2025A | C3: 2026E | D3: 2027E | E3: 2028E | F3: 2029E | G3: 2030E | H3: 2031E | I3: 2032E | J3: 2033E | K3: 2034E | L3: 2035E
A4: Year index | B4: 0 | C4: 1 | D4: 2 | E4: 3 | F4: 4 | G4: 5 | H4: 6 | I4: 7 | J4: 8 | K4: 9 | L4: 10
A5: Revenue growth % (driver) | C5: 14 | D5: 11 | E5: 9 | F5: 7.5 | G5: 6 | H5: 5 | I5: 4 | J5: 3.5 | K5: 3 | L5: 2.5
A6: Revenue | B6: 7741 | C6: =B6*(1+C5/100) | D6: =C6*(1+D5/100) | E6: =D6*(1+E5/100) | F6: =E6*(1+F5/100) | G6: =F6*(1+G5/100) | H6: =G6*(1+H5/100) | I6: =H6*(1+I5/100) | J6: =I6*(1+J5/100) | ... L6: =K6*(1+L5/100)
A7: Adj EBITDA margin % (driver) | C7: 34.5 | D7: 36 | E7: 36.8 | F7: 37.3 | G7: 37.5 | H7: 37.3 | I7: 37 | J7: 36.5 | K7: 36 | L7: 36
A8: Adjusted EBITDA | C8: =C6*C7/100 | D8: =D6*D7/100 | E8: =E6*E7/100 | F8: =F6*F7/100 | G8: =G6*G7/100 | H8: =H6*H7/100 | I8: =I6*I7/100 | J8: =J6*J7/100 | ... L8: =L6*L7/100
A9: SBC % of revenue (driver) | C9: 2.4 | D9: 2.4 | E9: 2.3 | F9: 2.3 | G9: 2.2 | H9: 2.2 | I9: 2.1 | J9: 2.1 | K9: 2 | L9: 2
A10: SBC (negative) | C10: =-C6*C9/100 | D10: =-D6*D9/100 | E10: =-E6*E9/100 | F10: =-F6*F9/100 | G10: =-G6*G9/100 | H10: =-H6*H9/100 | I10: =-I6*I9/100 | J10: =-J6*J9/100 | ... L10: =-L6*L9/100
A11: Owner EBITDA (SBC expensed) | C11: =C8+C10 | D11: =D8+D10 | E11: =E8+E10 | F11: =F8+F10 | G11: =G8+G10 | H11: =H8+H10 | I11: =I8+I10 | J11: =J8+J10 | ... L11: =L8+L10
A12: D&A % of revenue (driver) | C12: 7.5 | D12: 7.2 | E12: 7 | F12: 6.8 | G12: 6.6 | H12: 6.5 | I12: 6.5 | J12: 6.5 | K12: 6.5 | L12: 6.5
A13: D&A (negative) | C13: =-C6*C12/100 | D13: =-D6*D12/100 | E13: =-E6*E12/100 | F13: =-F6*F12/100 | G13: =-G6*G12/100 | H13: =-H6*H12/100 | I13: =-I6*I12/100 | J13: =-J6*J12/100 | ... L13: =-L6*L12/100
A14: EBIT, SBC expensed | C14: =C11+C13 | D14: =D11+D13 | E14: =E11+E13 | F14: =F11+F13 | G14: =G11+G13 | H14: =H11+H13 | I14: =I11+I13 | J14: =J11+J13 | ... L14: =L11+L13
A15: Cash tax rate % (driver) | C15: 17 | D15: 18 | E15: 19 | F15: 20 | G15: 21 | H15: 21 | I15: 21 | J15: 21 | K15: 21 | L15: 21
A16: NOPAT | C16: =C14*(1-C15/100) | D16: =D14*(1-D15/100) | E16: =E14*(1-E15/100) | F16: =F14*(1-F15/100) | G16: =G14*(1-G15/100) | H16: =H14*(1-H15/100) | I16: =I14*(1-I15/100) | J16: =J14*(1-J15/100) | ... L16: =L14*(1-L15/100)
A17: add back D&A | C17: =-C13 | D17: =-D13 | E17: =-E13 | F17: =-F13 | G17: =-G13 | H17: =-H13 | I17: =-I13 | J17: =-J13 | ... L17: =-L13
A18: Capex % of revenue (driver) | C18: 8 | D18: 7 | E18: 6.5 | F18: 6 | G18: 5.8 | H18: 5.5 | I18: 5.5 | J18: 5.5 | K18: 5.5 | L18: 5.5
A19: less capex | C19: =-C6*C18/100 | D19: =-D6*D18/100 | E19: =-E6*E18/100 | F19: =-F6*F18/100 | G19: =-G6*G18/100 | H19: =-H6*H18/100 | I19: =-I6*I18/100 | J19: =-J6*J18/100 | ... L19: =-L6*L18/100
A20: Working capital (on revenue CHANGE) | C20: =Assumptions!$C$17/100*(C6-B6) | D20: =Assumptions!$C$17/100*(D6-C6) | E20: =Assumptions!$C$17/100*(E6-D6) | F20: =Assumptions!$C$17/100*(F6-E6) | G20: =Assumptions!$C$17/100*(G6-F6) | H20: =Assumptions!$C$17/100*(H6-G6) | I20: =Assumptions!$C$17/100*(I6-H6) | J20: =Assumptions!$C$17/100*(J6-I6) | ... L20: =Assumptions!$C$17/100*(L6-K6)
A21: UNLEVERED OWNER FCF | C21: =C16+C17+C19+C20 | D21: =D16+D17+D19+D20 | E21: =E16+E17+E19+E20 | F21: =F16+F17+F19+F20 | G21: =G16+G17+G19+G20 | H21: =H16+H17+H19+H20 | I21: =I16+I17+I19+I20 | J21: =J16+J17+J19+J20 | ... L21: =L16+L17+L19+L20
A22: Discount factor | C22: =1/(1+Assumptions!$B$4/100)^C4 | D22: =1/(1+Assumptions!$B$4/100)^D4 | E22: =1/(1+Assumptions!$B$4/100)^E4 | F22: =1/(1+Assumptions!$B$4/100)^F4 | G22: =1/(1+Assumptions!$B$4/100)^G4 | H22: =1/(1+Assumptions!$B$4/100)^H4 | I22: =1/(1+Assumptions!$B$4/100)^I4 | J22: =1/(1+Assumptions!$B$4/100)^J4 | ... L22: =1/(1+Assumptions!$B$4/100)^L4
A23: PV of FCF | C23: =C21*C22 | D23: =D21*D22 | E23: =E21*E22 | F23: =F21*F22 | G23: =G21*G22 | H23: =H21*H22 | I23: =I21*I22 | J23: =J21*J22 | ... L23: =L21*L22
A25: Memo: FCF before SBC (company style) | C25: =C21-C10 | D25: =D21-D10 | E25: =E21-E10 | F25: =F21-F10 | G25: =G21-G10 | H25: =H21-H10 | I25: =I21-I10 | J25: =J21-J10 | ... L25: =L21-L10
A26: Memo: owner FCF margin % | C26: =C21/C6*100 | D26: =D21/D6*100 | E26: =E21/E6*100 | F26: =F21/F6*100 | G26: =G21/G6*100 | H26: =H21/H6*100 | I26: =I21/I6*100 | J26: =J21/J6*100 | ... L26: =L21/L6*100
A28: VALUATION
A29: Sum of PV of FCF | B29: =SUM(C23:L23)
A30: Terminal growth % | B30: =Assumptions!$C$14
A31: Terminal FCF cap multiple | B31: =Assumptions!$C$15
A32: Terminal-year FCF grown one year | B32: =L21*(1+B30/100)
A33: Gordon terminal value | B33: =L21*(1+B30/100)/((Assumptions!$B$4-B30)/100)
A34: Cap terminal value | B34: =B31*L21
A35: Terminal value used | B35: =MAX(0,MIN(B33,B34))
A36: Which bound | B36: =IF(B34<B33,"cap","gordon")
A37: Implied exit multiple | B37: =B35/L21
A38: PV of terminal value | B38: =B35*L22
A39: Enterprise value | B39: =B29+B38
A40: Terminal % of EV | B40: =B38/B39*100
A41: less net debt | B41: =-Assumptions!$B$6
A42: Equity value | B42: =B39+B41
A43: Diluted shares (m) | B43: =Assumptions!$B$5
...

Sheet DCF_Bull
A1: UCB.BR -- BULL case, 10-year owner-FCF build
A3: Year | B3: 2025A | C3: 2026E | D3: 2027E | E3: 2028E | F3: 2029E | G3: 2030E | H3: 2031E | I3: 2032E | J3: 2033E | K3: 2034E | L3: 2035E
A4: Year index | B4: 0 | C4: 1 | D4: 2 | E4: 3 | F4: 4 | G4: 5 | H4: 6 | I4: 7 | J4: 8 | K4: 9 | L4: 10
A5: Revenue growth % (driver) | C5: 18 | D5: 15 | E5: 13 | F5: 11 | G5: 9 | H5: 7.5 | I5: 6 | J5: 5 | K5: 4 | L5: 3.5
A6: Revenue | B6: 7741 | C6: =B6*(1+C5/100) | D6: =C6*(1+D5/100) | E6: =D6*(1+E5/100) | F6: =E6*(1+F5/100) | G6: =F6*(1+G5/100) | H6: =G6*(1+H5/100) | I6: =H6*(1+I5/100) | J6: =I6*(1+J5/100) | ... L6: =K6*(1+L5/100)
A7: Adj EBITDA margin % (driver) | C7: 36.5 | D7: 38.5 | E7: 40 | F7: 41 | G7: 41.5 | H7: 41.5 | I7: 41 | J7: 40.5 | K7: 40 | L7: 40
A8: Adjusted EBITDA | C8: =C6*C7/100 | D8: =D6*D7/100 | E8: =E6*E7/100 | F8: =F6*F7/100 | G8: =G6*G7/100 | H8: =H6*H7/100 | I8: =I6*I7/100 | J8: =J6*J7/100 | ... L8: =L6*L7/100
A9: SBC % of revenue (driver) | C9: 2.4 | D9: 2.3 | E9: 2.2 | F9: 2.1 | G9: 2 | H9: 2 | I9: 1.9 | J9: 1.9 | K9: 1.8 | L9: 1.8
A10: SBC (negative) | C10: =-C6*C9/100 | D10: =-D6*D9/100 | E10: =-E6*E9/100 | F10: =-F6*F9/100 | G10: =-G6*G9/100 | H10: =-H6*H9/100 | I10: =-I6*I9/100 | J10: =-J6*J9/100 | ... L10: =-L6*L9/100
A11: Owner EBITDA (SBC expensed) | C11: =C8+C10 | D11: =D8+D10 | E11: =E8+E10 | F11: =F8+F10 | G11: =G8+G10 | H11: =H8+H10 | I11: =I8+I10 | J11: =J8+J10 | ... L11: =L8+L10
A12: D&A % of revenue (driver) | C12: 7.3 | D12: 6.9 | E12: 6.6 | F12: 6.3 | G12: 6 | H12: 5.8 | I12: 5.8 | J12: 5.8 | K12: 5.8 | L12: 5.8
A13: D&A (negative) | C13: =-C6*C12/100 | D13: =-D6*D12/100 | E13: =-E6*E12/100 | F13: =-F6*F12/100 | G13: =-G6*G12/100 | H13: =-H6*H12/100 | I13: =-I6*I12/100 | J13: =-J6*J12/100 | ... L13: =-L6*L12/100
A14: EBIT, SBC expensed | C14: =C11+C13 | D14: =D11+D13 | E14: =E11+E13 | F14: =F11+F13 | G14: =G11+G13 | H14: =H11+H13 | I14: =I11+I13 | J14: =J11+J13 | ... L14: =L11+L13
A15: Cash tax rate % (driver) | C15: 16 | D15: 17 | E15: 18 | F15: 18.5 | G15: 19 | H15: 19 | I15: 19 | J15: 19 | K15: 19 | L15: 19
A16: NOPAT | C16: =C14*(1-C15/100) | D16: =D14*(1-D15/100) | E16: =E14*(1-E15/100) | F16: =F14*(1-F15/100) | G16: =G14*(1-G15/100) | H16: =H14*(1-H15/100) | I16: =I14*(1-I15/100) | J16: =J14*(1-J15/100) | ... L16: =L14*(1-L15/100)
A17: add back D&A | C17: =-C13 | D17: =-D13 | E17: =-E13 | F17: =-F13 | G17: =-G13 | H17: =-H13 | I17: =-I13 | J17: =-J13 | ... L17: =-L13
A18: Capex % of revenue (driver) | C18: 8 | D18: 6.8 | E18: 6.2 | F18: 5.8 | G18: 5.5 | H18: 5.2 | I18: 5.2 | J18: 5.2 | K18: 5.2 | L18: 5.2
A19: less capex | C19: =-C6*C18/100 | D19: =-D6*D18/100 | E19: =-E6*E18/100 | F19: =-F6*F18/100 | G19: =-G6*G18/100 | H19: =-H6*H18/100 | I19: =-I6*I18/100 | J19: =-J6*J18/100 | ... L19: =-L6*L18/100
A20: Working capital (on revenue CHANGE) | C20: =Assumptions!$D$17/100*(C6-B6) | D20: =Assumptions!$D$17/100*(D6-C6) | E20: =Assumptions!$D$17/100*(E6-D6) | F20: =Assumptions!$D$17/100*(F6-E6) | G20: =Assumptions!$D$17/100*(G6-F6) | H20: =Assumptions!$D$17/100*(H6-G6) | I20: =Assumptions!$D$17/100*(I6-H6) | J20: =Assumptions!$D$17/100*(J6-I6) | ... L20: =Assumptions!$D$17/100*(L6-K6)
A21: UNLEVERED OWNER FCF | C21: =C16+C17+C19+C20 | D21: =D16+D17+D19+D20 | E21: =E16+E17+E19+E20 | F21: =F16+F17+F19+F20 | G21: =G16+G17+G19+G20 | H21: =H16+H17+H19+H20 | I21: =I16+I17+I19+I20 | J21: =J16+J17+J19+J20 | ... L21: =L16+L17+L19+L20
A22: Discount factor | C22: =1/(1+Assumptions!$B$4/100)^C4 | D22: =1/(1+Assumptions!$B$4/100)^D4 | E22: =1/(1+Assumptions!$B$4/100)^E4 | F22: =1/(1+Assumptions!$B$4/100)^F4 | G22: =1/(1+Assumptions!$B$4/100)^G4 | H22: =1/(1+Assumptions!$B$4/100)^H4 | I22: =1/(1+Assumptions!$B$4/100)^I4 | J22: =1/(1+Assumptions!$B$4/100)^J4 | ... L22: =1/(1+Assumptions!$B$4/100)^L4
A23: PV of FCF | C23: =C21*C22 | D23: =D21*D22 | E23: =E21*E22 | F23: =F21*F22 | G23: =G21*G22 | H23: =H21*H22 | I23: =I21*I22 | J23: =J21*J22 | ... L23: =L21*L22
A25: Memo: FCF before SBC (company style) | C25: =C21-C10 | D25: =D21-D10 | E25: =E21-E10 | F25: =F21-F10 | G25: =G21-G10 | H25: =H21-H10 | I25: =I21-I10 | J25: =J21-J10 | ... L25: =L21-L10
A26: Memo: owner FCF margin % | C26: =C21/C6*100 | D26: =D21/D6*100 | E26: =E21/E6*100 | F26: =F21/F6*100 | G26: =G21/G6*100 | H26: =H21/H6*100 | I26: =I21/I6*100 | J26: =J21/J6*100 | ... L26: =L21/L6*100
A28: VALUATION
A29: Sum of PV of FCF | B29: =SUM(C23:L23)
A30: Terminal growth % | B30: =Assumptions!$D$14
A31: Terminal FCF cap multiple | B31: =Assumptions!$D$15
A32: Terminal-year FCF grown one year | B32: =L21*(1+B30/100)
A33: Gordon terminal value | B33: =L21*(1+B30/100)/((Assumptions!$B$4-B30)/100)
A34: Cap terminal value | B34: =B31*L21
A35: Terminal value used | B35: =MAX(0,MIN(B33,B34))
A36: Which bound | B36: =IF(B34<B33,"cap","gordon")
A37: Implied exit multiple | B37: =B35/L21
A38: PV of terminal value | B38: =B35*L22
A39: Enterprise value | B39: =B29+B38
A40: Terminal % of EV | B40: =B38/B39*100
A41: less net debt | B41: =-Assumptions!$B$6
A42: Equity value | B42: =B39+B41
A43: Diluted shares (m) | B43: =Assumptions!$B$5
...

Sheet FCF_Quality
A1: Reported FCF reconciled to owner FCF -- every historical year
B3: FY2019 | C3: FY2020 | D3: FY2021 | E3: FY2022 | F3: FY2023 | G3: FY2024 | H3: FY2025
A4: Revenue | B4: 4913 | C4: 5347 | D4: 5777 | E4: 5517 | F4: 5252 | G4: 6152 | H4: 7741
A5: Free cash flow (company definition) | B5: 599 | C5: 732 | D5: 1060 | E5: 748 | F5: 445 | G5: 920 | H5: 1842
A6: less: SBC incl. equity-award taxes | B6: -69 | C6: -81 | D6: -109 | E6: -81 | F6: -104 | G6: -183 | H6: -188
A7: less: interest income | B7: -20 | C7: -20 | D7: -17 | E7: -20 | F7: -20 | G7: -29 | H7: -46
A8: Owner FCF (equals sum above) | B8: =SUM(B5:B7) | C8: =SUM(C5:C7) | D8: =SUM(D5:D7) | E8: =SUM(E5:E7) | F8: =SUM(F5:F7) | G8: =SUM(G5:G7) | H8: =SUM(H5:H7)
A9: Reported FCF margin % | B9: =B5/B4*100 | C9: =C5/C4*100 | D9: =D5/D4*100 | E9: =E5/E4*100 | F9: =F5/F4*100 | G9: =G5/G4*100 | H9: =H5/H4*100
A10: Owner FCF margin % | B10: =B8/B4*100 | C10: =C8/C4*100 | D10: =D8/D4*100 | E10: =E8/E4*100 | F10: =F8/F4*100 | G10: =G8/G4*100 | H10: =H8/H4*100
A12: MEMO: working capital inside OCF
A13: Change in working capital (EUR m) | G13: 168 | H13: 303 | J13: FY2025 +303 was an INFLOW; H1-2026 was -623, an outflow. Growth consumes WC -- hence the negative capture rate.
A14: Cash taxes paid (EUR m) | C14: -72 | D14: -126 | G14: -215 | H14: -582 | J14: FY2025 cash tax 582 on PBT 1,822 = 31.9% cash rate, well above the 15% guided book rate -- the model ramps 17% to 21%.
A16: MEMO: the FY2025 step-change
A17: Owner FCF median FY2015-FY2024 | B17: 605 | D17: NOT used as the base. That median describes the pre-Bimzelx company -- see Model_Info.
A18: FY2025 owner FCF | B18: 1608 | D18: 2.7x the median. A genuine product-cycle inflection, confirmed by H1-2026 (+22% revenue, 40.7% margin).

Sheet Valuation
A1: UCB.BR -- valuation summary, entry prices and sensitivity
B3: Bear | C3: Base | D3: Bull
A4: Value per share (EUR) | B4: =DCF_Bear!$B$44 | C4: =DCF_Base!$B$44 | D4: =DCF_Bull!$B$44
A5: Street value per share (EUR) | B5: =DCF_Bear!$B$50 | C5: =DCF_Base!$B$50 | D5: =DCF_Bull!$B$50
A6: Entry price at 15% (EUR) | B6: =DCF_Bear!$B$55 | C6: =DCF_Base!$B$55 | D6: =DCF_Bull!$B$55
A7: Upside vs price % | B7: =(B4/Assumptions!$B$7-1)*100 | C7: =(C4/Assumptions!$B$7-1)*100 | D7: =(D4/Assumptions!$B$7-1)*100
A8: Probability weight | B8: =Assumptions!$B$16 | C8: =Assumptions!$C$16 | D8: =Assumptions!$D$16
A10: PROBABILITY-WEIGHTED VALUE (EUR) | B10: =SUMPRODUCT(B4:D4,B8:D8)
A11: Street weighted value (EUR) | B11: =SUMPRODUCT(B5:D5,B8:D8)
A12: Weighted entry price at 15% (EUR) | B12: =SUMPRODUCT(B6:D6,B8:D8)
A13: Current price (EUR) | B13: =Assumptions!$B$7
A14: Upside vs weighted % | B14: =(B10/Assumptions!$B$7-1)*100
A15: Margin of safety | B15: =1-Assumptions!$B$7/B10
A16: Band position (0% house, 100% street) | B16: =(Assumptions!$B$7-B10)/(B11-B10)*100 | D16: Not collapsed -- UCB has real SBC (2.4% of revenue), so this is a meaningful number, not n/a.
A18: REQUIRED-RETURN TABLE (base case)
A19: Required return % | B19: Value per share (EUR)
A20: 7 | B20: =IF(7/100>DCF_Base!$B$30/100,(SUMPRODUCT(DCF_Base!$C$21:$L$21,1/(1+7/100)^DCF_Base!$C$4:$L$4)+MAX(0,MIN(DCF_Base!$L$21*(1+DCF_Base!$B$30/100)/((7-DCF_Base!$B$30)/100),DCF_Base!$B$31*DCF_Base!$L$21))/(1+7/100)^10+DCF_Base!$B$41)/DCF_Base!$B$43,"n/a")
A21: 8 | B21: =IF(8/100>DCF_Base!$B$30/100,(SUMPRODUCT(DCF_Base!$C$21:$L$21,1/(1+8/100)^DCF_Base!$C$4:$L$4)+MAX(0,MIN(DCF_Base!$L$21*(1+DCF_Base!$B$30/100)/((8-DCF_Base!$B$30)/100),DCF_Base!$B$31*DCF_Base!$L$21))/(1+8/100)^10+DCF_Base!$B$41)/DCF_Base!$B$43,"n/a")
A22: 9 | B22: =IF(9/100>DCF_Base!$B$30/100,(SUMPRODUCT(DCF_Base!$C$21:$L$21,1/(1+9/100)^DCF_Base!$C$4:$L$4)+MAX(0,MIN(DCF_Base!$L$21*(1+DCF_Base!$B$30/100)/((9-DCF_Base!$B$30)/100),DCF_Base!$B$31*DCF_Base!$L$21))/(1+9/100)^10+DCF_Base!$B$41)/DCF_Base!$B$43,"n/a")
A23: 10 | B23: =IF(10/100>DCF_Base!$B$30/100,(SUMPRODUCT(DCF_Base!$C$21:$L$21,1/(1+10/100)^DCF_Base!$C$4:$L$4)+MAX(0,MIN(DCF_Base!$L$21*(1+DCF_Base!$B$30/100)/((10-DCF_Base!$B$30)/100),DCF_Base!$B$31*DCF_Base!$L$21))/(1+10/100)^10+DCF_Base!$B$41)/DCF_Base!$B$43,"n/a")
A24: 11 | B24: =IF(11/100>DCF_Base!$B$30/100,(SUMPRODUCT(DCF_Base!$C$21:$L$21,1/(1+11/100)^DCF_Base!$C$4:$L$4)+MAX(0,MIN(DCF_Base!$L$21*(1+DCF_Base!$B$30/100)/((11-DCF_Base!$B$30)/100),DCF_Base!$B$31*DCF_Base!$L$21))/(1+11/100)^10+DCF_Base!$B$41)/DCF_Base!$B$43,"n/a")
A25: 12 | B25: =IF(12/100>DCF_Base!$B$30/100,(SUMPRODUCT(DCF_Base!$C$21:$L$21,1/(1+12/100)^DCF_Base!$C$4:$L$4)+MAX(0,MIN(DCF_Base!$L$21*(1+DCF_Base!$B$30/100)/((12-DCF_Base!$B$30)/100),DCF_Base!$B$31*DCF_Base!$L$21))/(1+12/100)^10+DCF_Base!$B$41)/DCF_Base!$B$43,"n/a")
A26: 15 | B26: =IF(15/100>DCF_Base!$B$30/100,(SUMPRODUCT(DCF_Base!$C$21:$L$21,1/(1+15/100)^DCF_Base!$C$4:$L$4)+MAX(0,MIN(DCF_Base!$L$21*(1+DCF_Base!$B$30/100)/((15-DCF_Base!$B$30)/100),DCF_Base!$B$31*DCF_Base!$L$21))/(1+15/100)^10+DCF_Base!$B$41)/DCF_Base!$B$43,"n/a")
A27: Note: the market price sits between the 7% and 8% rows, so EUR 216.50 implies a required return of roughly 7.5%.
A29: SENSITIVITY -- base case, WACC (rows) x terminal growth (cols)
A30: WACC % \ g % | B30: 1 | C30: 1.5 | D30: 2 | E30: 2.5 | F30: 3
A31: 6 | B31: =IF(6.0>1.0,(SUMPRODUCT(DCF_Base!$C$21:$L$21,1/(1+6.0/100)^DCF_Base!$C$4:$L$4)+MAX(0,MIN(DCF_Base!$L$21*(1+1.0/100)/((6.0-1.0)/100),DCF_Base!$B$31*DCF_Base!$L$21))/(1+6.0/100)^10+DCF_Base!$B$41)/DCF_Base!$B$43,"n/a") | C31: =IF(6.0>1.5,(SUMPRODUCT(DCF_Base!$C$21:$L$21,1/(1+6.0/100)^DCF_Base!$C$4:$L$4)+MAX(0,MIN(DCF_Base!$L$21*(1+1.5/100)/((6.0-1.5)/100),DCF_Base!$B$31*DCF_Base!$L$21))/(1+6.0/100)^10+DCF_Base!$B$41)/DCF_Base!$B$43,"n/a") | D31: =IF(6.0>2.0,(SUMPRODUCT(DCF_Base!$C$21:$L$21,1/(1+6.0/100)^DCF_Base!$C$4:$L$4)+MAX(0,MIN(DCF_Base!$L$21*(1+2.0/100)/((6.0-2.0)/100),DCF_Base!$B$31*DCF_Base!$L$21))/(1+6.0/100)^10+DCF_Base!$B$41)/DCF_Base!$B$43,"n/a") | E31: =IF(6.0>2.5,(SUMPRODUCT(DCF_Base!$C$21:$L$21,1/(1+6.0/100)^DCF_Base!$C$4:$L$4)+MAX(0,MIN(DCF_Base!$L$21*(1+2.5/100)/((6.0-2.5)/100),DCF_Base!$B$31*DCF_Base!$L$21))/(1+6.0/100)^10+DCF_Base!$B$41)/DCF_Base!$B$43,"n/a") | F31: =IF(6.0>3.0,(SUMPRODUCT(DCF_Base!$C$21:$L$21,1/(1+6.0/100)^DCF_Base!$C$4:$L$4)+MAX(0,MIN(DCF_Base!$L$21*(1+3.0/100)/((6.0-3.0)/100),DCF_Base!$B$31*DCF_Base!$L$21))/(1+6.0/100)^10+DCF_Base!$B$41)/DCF_Base!$B$43,"n/a")
A32: 7 | B32: =IF(7.0>1.0,(SUMPRODUCT(DCF_Base!$C$21:$L$21,1/(1+7.0/100)^DCF_Base!$C$4:$L$4)+MAX(0,MIN(DCF_Base!$L$21*(1+1.0/100)/((7.0-1.0)/100),DCF_Base!$B$31*DCF_Base!$L$21))/(1+7.0/100)^10+DCF_Base!$B$41)/DCF_Base!$B$43,"n/a") | C32: =IF(7.0>1.5,(SUMPRODUCT(DCF_Base!$C$21:$L$21,1/(1+7.0/100)^DCF_Base!$C$4:$L$4)+MAX(0,MIN(DCF_Base!$L$21*(1+1.5/100)/((7.0-1.5)/100),DCF_Base!$B$31*DCF_Base!$L$21))/(1+7.0/100)^10+DCF_Base!$B$41)/DCF_Base!$B$43,"n/a") | D32: =IF(7.0>2.0,(SUMPRODUCT(DCF_Base!$C$21:$L$21,1/(1+7.0/100)^DCF_Base!$C$4:$L$4)+MAX(0,MIN(DCF_Base!$L$21*(1+2.0/100)/((7.0-2.0)/100),DCF_Base!$B$31*DCF_Base!$L$21))/(1+7.0/100)^10+DCF_Base!$B$41)/DCF_Base!$B$43,"n/a") | E32: =IF(7.0>2.5,(SUMPRODUCT(DCF_Base!$C$21:$L$21,1/(1+7.0/100)^DCF_Base!$C$4:$L$4)+MAX(0,MIN(DCF_Base!$L$21*(1+2.5/100)/((7.0-2.5)/100),DCF_Base!$B$31*DCF_Base!$L$21))/(1+7.0/100)^10+DCF_Base!$B$41)/DCF_Base!$B$43,"n/a") | F32: =IF(7.0>3.0,(SUMPRODUCT(DCF_Base!$C$21:$L$21,1/(1+7.0/100)^DCF_Base!$C$4:$L$4)+MAX(0,MIN(DCF_Base!$L$21*(1+3.0/100)/((7.0-3.0)/100),DCF_Base!$B$31*DCF_Base!$L$21))/(1+7.0/100)^10+DCF_Base!$B$41)/DCF_Base!$B$43,"n/a")
A33: 8 | B33: =IF(8.0>1.0,(SUMPRODUCT(DCF_Base!$C$21:$L$21,1/(1+8.0/100)^DCF_Base!$C$4:$L$4)+MAX(0,MIN(DCF_Base!$L$21*(1+1.0/100)/((8.0-1.0)/100),DCF_Base!$B$31*DCF_Base!$L$21))/(1+8.0/100)^10+DCF_Base!$B$41)/DCF_Base!$B$43,"n/a") | C33: =IF(8.0>1.5,(SUMPRODUCT(DCF_Base!$C$21:$L$21,1/(1+8.0/100)^DCF_Base!$C$4:$L$4)+MAX(0,MIN(DCF_Base!$L$21*(1+1.5/100)/((8.0-1.5)/100),DCF_Base!$B$31*DCF_Base!$L$21))/(1+8.0/100)^10+DCF_Base!$B$41)/DCF_Base!$B$43,"n/a") | D33: =IF(8.0>2.0,(SUMPRODUCT(DCF_Base!$C$21:$L$21,1/(1+8.0/100)^DCF_Base!$C$4:$L$4)+MAX(0,MIN(DCF_Base!$L$21*(1+2.0/100)/((8.0-2.0)/100),DCF_Base!$B$31*DCF_Base!$L$21))/(1+8.0/100)^10+DCF_Base!$B$41)/DCF_Base!$B$43,"n/a") | E33: =IF(8.0>2.5,(SUMPRODUCT(DCF_Base!$C$21:$L$21,1/(1+8.0/100)^DCF_Base!$C$4:$L$4)+MAX(0,MIN(DCF_Base!$L$21*(1+2.5/100)/((8.0-2.5)/100),DCF_Base!$B$31*DCF_Base!$L$21))/(1+8.0/100)^10+DCF_Base!$B$41)/DCF_Base!$B$43,"n/a") | F33: =IF(8.0>3.0,(SUMPRODUCT(DCF_Base!$C$21:$L$21,1/(1+8.0/100)^DCF_Base!$C$4:$L$4)+MAX(0,MIN(DCF_Base!$L$21*(1+3.0/100)/((8.0-3.0)/100),DCF_Base!$B$31*DCF_Base!$L$21))/(1+8.0/100)^10+DCF_Base!$B$41)/DCF_Base!$B$43,"n/a")
A34: 9 | B34: =IF(9.0>1.0,(SUMPRODUCT(DCF_Base!$C$21:$L$21,1/(1+9.0/100)^DCF_Base!$C$4:$L$4)+MAX(0,MIN(DCF_Base!$L$21*(1+1.0/100)/((9.0-1.0)/100),DCF_Base!$B$31*DCF_Base!$L$21))/(1+9.0/100)^10+DCF_Base!$B$41)/DCF_Base!$B$43,"n/a") | C34: =IF(9.0>1.5,(SUMPRODUCT(DCF_Base!$C$21:$L$21,1/(1+9.0/100)^DCF_Base!$C$4:$L$4)+MAX(0,MIN(DCF_Base!$L$21*(1+1.5/100)/((9.0-1.5)/100),DCF_Base!$B$31*DCF_Base!$L$21))/(1+9.0/100)^10+DCF_Base!$B$41)/DCF_Base!$B$43,"n/a") | D34: =IF(9.0>2.0,(SUMPRODUCT(DCF_Base!$C$21:$L$21,1/(1+9.0/100)^DCF_Base!$C$4:$L$4)+MAX(0,MIN(DCF_Base!$L$21*(1+2.0/100)/((9.0-2.0)/100),DCF_Base!$B$31*DCF_Base!$L$21))/(1+9.0/100)^10+DCF_Base!$B$41)/DCF_Base!$B$43,"n/a") | E34: =IF(9.0>2.5,(SUMPRODUCT(DCF_Base!$C$21:$L$21,1/(1+9.0/100)^DCF_Base!$C$4:$L$4)+MAX(0,MIN(DCF_Base!$L$21*(1+2.5/100)/((9.0-2.5)/100),DCF_Base!$B$31*DCF_Base!$L$21))/(1+9.0/100)^10+DCF_Base!$B$41)/DCF_Base!$B$43,"n/a") | F34: =IF(9.0>3.0,(SUMPRODUCT(DCF_Base!$C$21:$L$21,1/(1+9.0/100)^DCF_Base!$C$4:$L$4)+MAX(0,MIN(DCF_Base!$L$21*(1+3.0/100)/((9.0-3.0)/100),DCF_Base!$B$31*DCF_Base!$L$21))/(1+9.0/100)^10+DCF_Base!$B$41)/DCF_Base!$B$43,"n/a")
A35: 10 | B35: =IF(10.0>1.0,(SUMPRODUCT(DCF_Base!$C$21:$L$21,1/(1+10.0/100)^DCF_Base!$C$4:$L$4)+MAX(0,MIN(DCF_Base!$L$21*(1+1.0/100)/((10.0-1.0)/100),DCF_Base!$B$31*DCF_Base!$L$21))/(1+10.0/100)^10+DCF_Base!$B$41)/DCF_Base!$B$43,"n/a") | C35: =IF(10.0>1.5,(SUMPRODUCT(DCF_Base!$C$21:$L$21,1/(1+10.0/100)^DCF_Base!$C$4:$L$4)+MAX(0,MIN(DCF_Base!$L$21*(1+1.5/100)/((10.0-1.5)/100),DCF_Base!$B$31*DCF_Base!$L$21))/(1+10.0/100)^10+DCF_Base!$B$41)/DCF_Base!$B$43,"n/a") | D35: =IF(10.0>2.0,(SUMPRODUCT(DCF_Base!$C$21:$L$21,1/(1+10.0/100)^DCF_Base!$C$4:$L$4)+MAX(0,MIN(DCF_Base!$L$21*(1+2.0/100)/((10.0-2.0)/100),DCF_Base!$B$31*DCF_Base!$L$21))/(1+10.0/100)^10+DCF_Base!$B$41)/DCF_Base!$B$43,"n/a") | E35: =IF(10.0>2.5,(SUMPRODUCT(DCF_Base!$C$21:$L$21,1/(1+10.0/100)^DCF_Base!$C$4:$L$4)+MAX(0,MIN(DCF_Base!$L$21*(1+2.5/100)/((10.0-2.5)/100),DCF_Base!$B$31*DCF_Base!$L$21))/(1+10.0/100)^10+DCF_Base!$B$41)/DCF_Base!$B$43,"n/a") | F35: =IF(10.0>3.0,(SUMPRODUCT(DCF_Base!$C$21:$L$21,1/(1+10.0/100)^DCF_Base!$C$4:$L$4)+MAX(0,MIN(DCF_Base!$L$21*(1+3.0/100)/((10.0-3.0)/100),DCF_Base!$B$31*DCF_Base!$L$21))/(1+10.0/100)^10+DCF_Base!$B$41)/DCF_Base!$B$43,"n/a")
A36: Note: flat cells at low WACC are the 18x terminal cap binding -- Gordon there implies an exit multiple no buyer has to grant.
A38: SANITY CHECK vs 10-year historical multiples
A39: TTM EV/EBITDA at current price | B39: 13.4x vs 10y median 12.3x, range 10.0-25.2x -- inside the band
A40: TTM P/E at current price | B40: 19.1x vs 10y median 22.6x, range 15.7-48.4x -- BELOW the median
A41: TTM EV/Sales at current price | B41: 5.26x vs 10y median 3.14x, range 3.0-6.3x -- FLAG, near the top
A42: Model weighted IV implies | B42: 12.5x EV/EBITDA and 17.8x P/E -- both inside the historical bands
A43: Verdict | B43: PASS with one flag. EBITDA and P/E look benign only because margin went from ~24% to ~40%. If that margin is the cycle peak rather than the new normal, EV/Sales is the honest multiple and the stock is expensive -- which is precisely the bear case.
A45: CONCLUSION | B45: The honest answer is that UCB is FULLY VALUED to modestly overvalued at EUR 216.50. The probability-weighted intrinsic value is EUR 201.33, about 7% BELOW the market price, and the base case alone at EUR 206.80 is still below it. The bull case at EUR 317.34 shows there is real upside if Bimzelx reaches its guided peak with margins intact -- but the market is already paying for a meaningful share of that: the price implies a required return of only ~7.5%, and a 15% hurdle would need an entry around EUR 117. This is not a call that the business is bad. It is a very good business at a price that has already re-rated to reflect it, which is exactly what the Analysis JSON's own high-severity 'valuation / expectations risk' flags. The margin for error is thin: the bear case, which requires nothing more exotic than Cimzia biosimilars arriving, MFN pricing landing, and the 40.7% margin proving to be a peak, produces EUR 74.37.
