Workbook

Sheet Inputs
A1: AIG - BVPS Compounding x Exit P/B Model
A2: Valuation date | B2: 2026-09-26
A3: Current price (USD) | B3: 74.13
A4: Price as of | B4: 2026-09-25T16:05:43Z regular close
A5: Shares outstanding (m) | B5: 522.89
A6: Shares basis | B6: cover-page, 10-Q filed 2026-07-31
A7: Shareholders' equity (m, 2026-06-30) | B7: 40606
A8: Book value per share (BVPS0) | B8: =B7/B5
A9: P/B at current price | B9: =B3/B8
A10: Net debt treatment | B10: N/A -- insurer model, no net debt deduction (see notes)
A11: Goodwill (m) | B11: 3400
A12: Tangible BVPS | B12: =(B7-B11)/B5
A14: Model | B14: BVPS compounding x exit P/B (residual-income-style insurer model, cost of equity discount)
A15: Routing | B15: dcf-methods SKILL.md: Insurer, holdco, compounder-of-book -> BVPS compounding x exit P/B

Sheet Scenarios
A1: Scenario assumptions and 5-year BVPS / dividend projection
A3: BASE | B3: Y1 | C3: Y2 | D3: Y3 | E3: Y4 | F3: Y5 | G3: Terminal / Exit
A4: ROE % (core operating) | B4: 0.095 | C4: 0.105 | D4: 0.11 | E4: 0.115 | F4: 0.115
A5: Payout ratio % | B5: 0.22 | C5: 0.24 | D5: 0.26 | E5: 0.28 | F5: 0.3
A6: BVPS (start of year) | B6: =Inputs!$B$8 | C6: =B6+B7-B8 | D6: =C6+C7-C8 | E6: =D6+D7-D8 | F6: =E6+E7-E8
A7: Earnings per share (BVPS x ROE) | B7: =B6*B4 | C7: =C6*C4 | D7: =D6*D4 | E7: =E6*E4 | F7: =F6*F4
A8: Dividend per share | B8: =B7*B5 | C8: =C7*C5 | D8: =D7*D5 | E8: =E7*E5 | F8: =F7*F5
A9: Retained earnings per share | B9: =B7-B8 | C9: =C7-C8 | D9: =D7-D8 | E9: =E7-E8 | F9: =F7-F8
A10: BVPS (end of year) | B10: =B6+B9 | C10: =C6+C9 | D10: =D6+D9 | E10: =E6+E9 | F10: =F6+F9
A11: Exit P/B multiple | G11: 1.05
A12: Terminal value per share | G12: =F10*G11
A13: Cost of equity | G13: 0.095
A14: PV of dividends | B14: =B8/(1+$G$13)^1+C8/(1+$G$13)^2+D8/(1+$G$13)^3+E8/(1+$G$13)^4+F8/(1+$G$13)^5
A15: PV of terminal value | B15: =G12/(1+$G$13)^5
A16: Intrinsic value per share | B16: =B14+B15
A18: BULL | B18: Y1 | C18: Y2 | D18: Y3 | E18: Y4 | F18: Y5 | G18: Terminal / Exit
A19: ROE % (core operating) | B19: 0.105 | C19: 0.12 | D19: 0.13 | E19: 0.13 | F19: 0.13
A20: Payout ratio % | B20: 0.2 | C20: 0.22 | D20: 0.24 | E20: 0.26 | F20: 0.28
A21: BVPS (start of year) | B21: =Inputs!$B$8 | C21: =B21+B22-B23 | D21: =C21+C22-C23 | E21: =D21+D22-D23 | F21: =E21+E22-E23
A22: Earnings per share (BVPS x ROE) | B22: =B21*B19 | C22: =C21*C19 | D22: =D21*D19 | E22: =E21*E19 | F22: =F21*F19
A23: Dividend per share | B23: =B22*B20 | C23: =C22*C20 | D23: =D22*D20 | E23: =E22*E20 | F23: =F22*F20
A24: Retained earnings per share | B24: =B22-B23 | C24: =C22-C23 | D24: =D22-D23 | E24: =E22-E23 | F24: =F22-F23
A25: BVPS (end of year) | B25: =B21+B24 | C25: =C21+C24 | D25: =D21+D24 | E25: =E21+E24 | F25: =F21+F24
A26: Exit P/B multiple | G26: 1.3
A27: Terminal value per share | G27: =F25*G26
A28: Cost of equity | G28: 0.09
A29: PV of dividends | B29: =B23/(1+$G$28)^1+C23/(1+$G$28)^2+D23/(1+$G$28)^3+E23/(1+$G$28)^4+F23/(1+$G$28)^5
A30: PV of terminal value | B30: =G27/(1+$G$28)^5
A31: Intrinsic value per share | B31: =B29+B30
A33: BEAR | B33: Y1 | C33: Y2 | D33: Y3 | E33: Y4 | F33: Y5 | G33: Terminal / Exit
A34: ROE % (core operating) | B34: 0.07 | C34: 0.075 | D34: 0.08 | E34: 0.08 | F34: 0.08
A35: Payout ratio % | B35: 0.25 | C35: 0.28 | D35: 0.3 | E35: 0.32 | F35: 0.32
A36: BVPS (start of year) | B36: =Inputs!$B$8 | C36: =B36+B37-B38 | D36: =C36+C37-C38 | E36: =D36+D37-D38 | F36: =E36+E37-E38
A37: Earnings per share (BVPS x ROE) | B37: =B36*B34 | C37: =C36*C34 | D37: =D36*D34 | E37: =E36*E34 | F37: =F36*F34
A38: Dividend per share | B38: =B37*B35 | C38: =C37*C35 | D38: =D37*D35 | E38: =E37*E35 | F38: =F37*F35
A39: Retained earnings per share | B39: =B37-B38 | C39: =C37-C38 | D39: =D37-D38 | E39: =E37-E38 | F39: =F37-F38
A40: BVPS (end of year) | B40: =B36+B39 | C40: =C36+C39 | D40: =D36+D39 | E40: =E36+E39 | F40: =F36+F39
A41: Exit P/B multiple | G41: 0.85
A42: Terminal value per share | G42: =F40*G41
A43: Cost of equity | G43: 0.105
...

Sheet Valuation Summary
A1: AIG Valuation Summary
A3: Scenario | B3: Weight | C3: Terminal BVPS | D3: Exit P/B | E3: Terminal Value/Share | F3: PV Dividends | G3: PV Terminal | H3: Intrinsic Value | I3: Upside vs Current
A4: Bear | B4: 0.25 | C4: ='Scenarios'!F40 | D4: ='Scenarios'!G41 | E4: ='Scenarios'!G42 | F4: ='Scenarios'!B44 | G4: ='Scenarios'!B45 | H4: ='Scenarios'!B46 | I4: =H4/Inputs!$B$3-1
A5: Base | B5: 0.5 | C5: ='Scenarios'!F10 | D5: ='Scenarios'!G11 | E5: ='Scenarios'!G12 | F5: ='Scenarios'!B14 | G5: ='Scenarios'!B15 | H5: ='Scenarios'!B16 | I5: =H5/Inputs!$B$3-1
A6: Bull | B6: 0.25 | C6: ='Scenarios'!F25 | D6: ='Scenarios'!G26 | E6: ='Scenarios'!G27 | F6: ='Scenarios'!B29 | G6: ='Scenarios'!B30 | H6: ='Scenarios'!B31 | I6: =H6/Inputs!$B$3-1
A7: Weighted | H7: =SUMPRODUCT(B4:B6,H4:H6) | I7: =H7/Inputs!$B$3-1
A9: Current price | B9: =Inputs!B3
A10: Current BVPS | B10: =Inputs!B8
A12: Entry price @ 15% hurdle (weighted) | B12: 68.01
A13: Entry price base | B13: 67.79

Sheet Sensitivity
A1: Base-case sensitivity: Cost of Equity x Exit P/B
A3: Exit P/B \ CoE | B3: 0.08 | C3: 0.085 | D3: 0.095 | E3: 0.105 | F3: 0.11
A4: 0.85 | B4: 76.1 | C4: 74.4 | D4: 71.2 | E4: 68.2 | F4: 66.8
A5: 0.95 | B5: 83.8 | C5: 82 | D5: 78.5 | E5: 75.1 | F5: 73.5
A6: 1.05 | B6: 91.6 | C6: 89.6 | D6: 85.7 | E6: 82 | F6: 80.3
A7: 1.15 | B7: 99.3 | C7: 97.1 | D7: 92.9 | E7: 89 | F7: 87.1
A8: 1.25 | B8: 107.1 | C8: 104.7 | D8: 100.2 | E8: 95.9 | F8: 93.8

Sheet Notes
A1: Methodology Notes
A3: Model: BVPS compounding x exit price-to-book, discounted at cost of equity.
A4: Rationale: AIG is a pure-play P&C insurer post-Corebridge/Validus divestiture. Reported operating cash flow reflects investment-portfolio
A5: and reserve timing, not a distributable owner-FCF stream -- an owner-FCF DCF would be meaningless. Net debt is not subtracted: the ~$9.2bn
A6: of holding-company debt funds investable float backing policy liabilities and is already embedded in the book-value base being compounded;
A7: subtracting it again would double-count exactly as owner-fcf-adaptations.md warns against for a bank/insurer.
A9: Anchor: book value per share = $77.66 (equity $40,606m / 522.89m shares), equity as of 2026-06-30 (10-Q), shares as of 2026-07-31 (10-Q cover page).
A11: Historical growth: BVPS 3yr CAGR (FY2022->FY2025) = 6.8%, used as selected_growth_rate. Total equity CAGR is negative and NOT used --
A12: it mixes ~$20bn+ of Corebridge/Validus divestiture proceeds paid out as buybacks/dividends with organic book growth; share count fell
A13: from 870m (FY2019) to 523m (current), ~40%, more than offsetting the equity-base shrinkage from the payout.
A15: Scenario construction: ROE path (core operating basis) x payout ratio compounds BVPS per share each year; buyback accretion is captured
A16: implicitly (not as a separate line) because ROE is already applied to equity-per-share on a shrinking share count -- charging it twice
... A20: the external first-time-CEO transition, and a turning commercial pricing cycle, none of which are solvency risk but all bear on earnings quality.
