Workbook

Sheet DCF Model
A1: DGL.NZ (Delegat Group) DCF Valuation Model
A2: Gray cells are INPUTS - adjust to see valuation change. Base case shown; SBC verified nil (no adjustment needed).
A4: KEY INPUTS
A5: Current Stock Price (NZD) | B5: 4.2
A6: Shares Outstanding (M) | B6: 101.13
A7: Cash (M) | B7: 16.397
A8: Bank Debt (M) | B8: 323.426
A9: IFRS-16 Lease Liability (M) | B9: 101.153
A10: Net Debt incl. Leases (M) | B10: =B8+B9-B7 -> 0
A11: FY2025 Base Revenue (M) | B11: 349.556
A12: SBC (verified NIL) | B12: 0
A14: WACC (Base) | B14: 0.128
A15: Terminal Growth Rate | B15: 0.02
A16: Terminal FCF-Multiple Cap | B16: 14
A17: EV/EBITDA Anchor Multiple (hist avg ex-FY24) | B17: 12.69
A19: COMPONENT ASSUMPTIONS (Base Case)
B20: Year 1 FY2027 | C20: Year 2 FY2028 | D20: Year 3 FY2029 | E20: Year 4 FY2030 | F20: Year 5 FY2031
A21: Revenue Growth % | B21: 0.03 | C21: 0.035 | D21: 0.03 | E21: 0.025 | F21: 0.02
A22: EBITDA Margin % | B22: 0.325 | C22: 0.33 | D22: 0.335 | E22: 0.34 | F22: 0.34
A23: D&A % of Revenue | B23: 0.079 | C23: 0.078 | D23: 0.077 | E23: 0.076 | F23: 0.075
A24: Capex % of Revenue | B24: 0.085 | C24: 0.083 | D24: 0.082 | E24: 0.082 | F24: 0.082
A25: Lease Principal % of Revenue | B25: 0.02 | C25: 0.019 | D25: 0.018 | E25: 0.017 | F25: 0.017
A26: Cash Tax Rate % | B26: 0.28 | C26: 0.28 | D26: 0.28 | E26: 0.28 | F26: 0.28
A27: WC Capture % of Rev Increase | B27: 0.25
A29: PROJECTIONS (Component Build)
B30: Year 1 FY2027 | C30: Year 2 FY2028 | D30: Year 3 FY2029 | E30: Year 4 FY2030 | F30: Year 5 FY2031
A31: Revenue | B31: =$B$11*(1+B21) -> 0 | C31: =B31*(1+C21) -> 0 | D31: =C31*(1+D21) -> 0 | E31: =D31*(1+E21) -> 0 | F31: =E31*(1+F21) -> 0
A32: EBITDA | B32: =B31*B22 -> 0 | C32: =C31*C22 -> 0 | D32: =D31*D22 -> 0 | E32: =E31*E22 -> 0 | F32: =F31*F22 -> 0
A33: D&A | B33: =B31*B23 -> 0 | C33: =C31*C23 -> 0 | D33: =D31*D23 -> 0 | E33: =E31*E23 -> 0 | F33: =F31*F23 -> 0
A34: EBIT | B34: =B32-B33 -> 0 | C34: =C32-C33 -> 0 | D34: =D32-D33 -> 0 | E34: =E32-E33 -> 0 | F34: =F32-F33 -> 0
A35: NOPAT | B35: =B34*(1-B26) -> 0 | C35: =C34*(1-C26) -> 0 | D35: =D34*(1-D26) -> 0 | E35: =E34*(1-E26) -> 0 | F35: =F34*(1-F26) -> 0
A36: Capex | B36: =B31*B24 -> 0 | C36: =C31*C24 -> 0 | D36: =D31*D24 -> 0 | E36: =E31*E24 -> 0 | F36: =F31*F24 -> 0
A37: Lease Principal Repayment | B37: =B31*B25 -> 0 | C37: =C31*C25 -> 0 | D37: =D31*D25 -> 0 | E37: =E31*E25 -> 0 | F37: =F31*F25 -> 0
A38: Working Capital (use of cash) | B38: =$B$27*(B31-$B$11) -> 0 | C38: =$B$27*(C31-B31) -> 0 | D38: =$B$27*(D31-C31) -> 0 | E38: =$B$27*(E31-D31) -> 0 | F38: =$B$27*(F31-E31) -> 0
A39: Free Cash Flow (Owner FCF) | B39: =B35+B33-B36-B37-B38 -> 0 | C39: =C35+C33-C36-C37-C38 -> 0 | D39: =D35+D33-D36-D37-D38 -> 0 | E39: =E35+E33-E36-E37-E38 -> 0 | F39: =F35+F33-F36-F37-F38 -> 0
A40: FCF Margin % | B40: =B39/B31 -> 0 | C40: =C39/C31 -> 0 | D40: =D39/D31 -> 0 | E40: =E39/E31 -> 0 | F40: =F39/F31 -> 0
A41: Discount Factor | B41: =1/(1+$B$14)^1 -> 0 | C41: =1/(1+$B$14)^2 -> 0 | D41: =1/(1+$B$14)^3 -> 0 | E41: =1/(1+$B$14)^4 -> 0 | F41: =1/(1+$B$14)^5 -> 0
A42: PV of FCF | B42: =B39*B41 -> 0 | C42: =C39*C41 -> 0 | D42: =D39*D41 -> 0 | E42: =E39*E41 -> 0 | F42: =F39*F41 -> 0
A44: VALUATION
A45: Sum of PV of FCF | B45: =SUM(B42:F42) -> 0
...

Sheet Sensitivity
A1: Sensitivity Analysis (Gordon-Growth Basis)
A2: Intrinsic Value by WACC & Terminal Growth - uncapped Gordon, for directional sensitivity only.
A3: Headline valuation uses the capped EV/EBITDA-anchor methodology (see DCF Model tab) which is largely insensitive to terminal growth.
A5: WACC \ Term G | B5: 0.01 | C5: 0.015 | D5: 0.02 | E5: 0.025 | F5: 0.03
A6: 0.108 | B6: =('DCF Model'!$F$39*(1+0.01)/(0.10800000000000001-0.01)/(1+0.10800000000000001)^5 + SUMPRODUCT('DCF Model'!$B$39:$F$39,1/(1+0.10800000000000001)^{1,2,3,4,5}) - 'DCF Model'!$B$10)/'DCF Model'!$B$6 -> 0 | C6: =('DCF Model'!$F$39*(1+0.015)/(0.10800000000000001-0.015)/(1+0.10800000000000001)^5 + SUMPRODUCT('DCF Model'!$B$39:$F$39,1/(1+0.10800000000000001)^{1,2,3,4,5}) - 'DCF Model'!$B$10)/'DCF Model'!$B$6 -> 0 | D6: =('DCF Model'!$F$39*(1+0.02)/(0.10800000000000001-0.02)/(1+0.10800000000000001)^5 + SUMPRODUCT('DCF Model'!$B$39:$F$39,1/(1+0.10800000000000001)^{1,2,3,4,5}) - 'DCF Model'!$B$10)/'DCF Model'!$B$6 -> 0 | E6: =('DCF Model'!$F$39*(1+0.025)/(0.10800000000000001-0.025)/(1+0.10800000000000001)^5 + SUMPRODUCT('DCF Model'!$B$39:$F$39,1/(1+0.10800000000000001)^{1,2,3,4,5}) - 'DCF Model'!$B$10)/'DCF Model'!$B$6 -> 0 | F6: =('DCF Model'!$F$39*(1+0.03)/(0.10800000000000001-0.03)/(1+0.10800000000000001)^5 + SUMPRODUCT('DCF Model'!$B$39:$F$39,1/(1+0.10800000000000001)^{1,2,3,4,5}) - 'DCF Model'!$B$10)/'DCF Model'!$B$6 -> 0
A7: 0.118 | B7: =('DCF Model'!$F$39*(1+0.01)/(0.11800000000000001-0.01)/(1+0.11800000000000001)^5 + SUMPRODUCT('DCF Model'!$B$39:$F$39,1/(1+0.11800000000000001)^{1,2,3,4,5}) - 'DCF Model'!$B$10)/'DCF Model'!$B$6 -> 0 | C7: =('DCF Model'!$F$39*(1+0.015)/(0.11800000000000001-0.015)/(1+0.11800000000000001)^5 + SUMPRODUCT('DCF Model'!$B$39:$F$39,1/(1+0.11800000000000001)^{1,2,3,4,5}) - 'DCF Model'!$B$10)/'DCF Model'!$B$6 -> 0 | D7: =('DCF Model'!$F$39*(1+0.02)/(0.11800000000000001-0.02)/(1+0.11800000000000001)^5 + SUMPRODUCT('DCF Model'!$B$39:$F$39,1/(1+0.11800000000000001)^{1,2,3,4,5}) - 'DCF Model'!$B$10)/'DCF Model'!$B$6 -> 0 | E7: =('DCF Model'!$F$39*(1+0.025)/(0.11800000000000001-0.025)/(1+0.11800000000000001)^5 + SUMPRODUCT('DCF Model'!$B$39:$F$39,1/(1+0.11800000000000001)^{1,2,3,4,5}) - 'DCF Model'!$B$10)/'DCF Model'!$B$6 -> 0 | F7: =('DCF Model'!$F$39*(1+0.03)/(0.11800000000000001-0.03)/(1+0.11800000000000001)^5 + SUMPRODUCT('DCF Model'!$B$39:$F$39,1/(1+0.11800000000000001)^{1,2,3,4,5}) - 'DCF Model'!$B$10)/'DCF Model'!$B$6 -> 0
A8: 0.128 | B8: =('DCF Model'!$F$39*(1+0.01)/(0.128-0.01)/(1+0.128)^5 + SUMPRODUCT('DCF Model'!$B$39:$F$39,1/(1+0.128)^{1,2,3,4,5}) - 'DCF Model'!$B$10)/'DCF Model'!$B$6 -> 0 | C8: =('DCF Model'!$F$39*(1+0.015)/(0.128-0.015)/(1+0.128)^5 + SUMPRODUCT('DCF Model'!$B$39:$F$39,1/(1+0.128)^{1,2,3,4,5}) - 'DCF Model'!$B$10)/'DCF Model'!$B$6 -> 0 | D8: =('DCF Model'!$F$39*(1+0.02)/(0.128-0.02)/(1+0.128)^5 + SUMPRODUCT('DCF Model'!$B$39:$F$39,1/(1+0.128)^{1,2,3,4,5}) - 'DCF Model'!$B$10)/'DCF Model'!$B$6 -> 0 | E8: =('DCF Model'!$F$39*(1+0.025)/(0.128-0.025)/(1+0.128)^5 + SUMPRODUCT('DCF Model'!$B$39:$F$39,1/(1+0.128)^{1,2,3,4,5}) - 'DCF Model'!$B$10)/'DCF Model'!$B$6 -> 0 | F8: =('DCF Model'!$F$39*(1+0.03)/(0.128-0.03)/(1+0.128)^5 + SUMPRODUCT('DCF Model'!$B$39:$F$39,1/(1+0.128)^{1,2,3,4,5}) - 'DCF Model'!$B$10)/'DCF Model'!$B$6 -> 0
A9: 0.138 | B9: =('DCF Model'!$F$39*(1+0.01)/(0.138-0.01)/(1+0.138)^5 + SUMPRODUCT('DCF Model'!$B$39:$F$39,1/(1+0.138)^{1,2,3,4,5}) - 'DCF Model'!$B$10)/'DCF Model'!$B$6 -> 0 | C9: =('DCF Model'!$F$39*(1+0.015)/(0.138-0.015)/(1+0.138)^5 + SUMPRODUCT('DCF Model'!$B$39:$F$39,1/(1+0.138)^{1,2,3,4,5}) - 'DCF Model'!$B$10)/'DCF Model'!$B$6 -> 0 | D9: =('DCF Model'!$F$39*(1+0.02)/(0.138-0.02)/(1+0.138)^5 + SUMPRODUCT('DCF Model'!$B$39:$F$39,1/(1+0.138)^{1,2,3,4,5}) - 'DCF Model'!$B$10)/'DCF Model'!$B$6 -> 0 | E9: =('DCF Model'!$F$39*(1+0.025)/(0.138-0.025)/(1+0.138)^5 + SUMPRODUCT('DCF Model'!$B$39:$F$39,1/(1+0.138)^{1,2,3,4,5}) - 'DCF Model'!$B$10)/'DCF Model'!$B$6 -> 0 | F9: =('DCF Model'!$F$39*(1+0.03)/(0.138-0.03)/(1+0.138)^5 + SUMPRODUCT('DCF Model'!$B$39:$F$39,1/(1+0.138)^{1,2,3,4,5}) - 'DCF Model'!$B$10)/'DCF Model'!$B$6 -> 0
A10: 0.148 | B10: =('DCF Model'!$F$39*(1+0.01)/(0.14800000000000002-0.01)/(1+0.14800000000000002)^5 + SUMPRODUCT('DCF Model'!$B$39:$F$39,1/(1+0.14800000000000002)^{1,2,3,4,5}) - 'DCF Model'!$B$10)/'DCF Model'!$B$6 -> 0 | C10: =('DCF Model'!$F$39*(1+0.015)/(0.14800000000000002-0.015)/(1+0.14800000000000002)^5 + SUMPRODUCT('DCF Model'!$B$39:$F$39,1/(1+0.14800000000000002)^{1,2,3,4,5}) - 'DCF Model'!$B$10)/'DCF Model'!$B$6 -> 0 | D10: =('DCF Model'!$F$39*(1+0.02)/(0.14800000000000002-0.02)/(1+0.14800000000000002)^5 + SUMPRODUCT('DCF Model'!$B$39:$F$39,1/(1+0.14800000000000002)^{1,2,3,4,5}) - 'DCF Model'!$B$10)/'DCF Model'!$B$6 -> 0 | E10: =('DCF Model'!$F$39*(1+0.025)/(0.14800000000000002-0.025)/(1+0.14800000000000002)^5 + SUMPRODUCT('DCF Model'!$B$39:$F$39,1/(1+0.14800000000000002)^{1,2,3,4,5}) - 'DCF Model'!$B$10)/'DCF Model'!$B$6 -> 0 | F10: =('DCF Model'!$F$39*(1+0.03)/(0.14800000000000002-0.03)/(1+0.14800000000000002)^5 + SUMPRODUCT('DCF Model'!$B$39:$F$39,1/(1+0.14800000000000002)^{1,2,3,4,5}) - 'DCF Model'!$B$10)/'DCF Model'!$B$6 -> 0

Sheet Historical
A1: Historical Financials & Multiples
A3: FY | B3: Revenue | C3: EBITDA | D3: Net Income | E3: Reported FCF | F3: Capex | G3: Equity | H3: Bank Debt | I3: Lease Liab | J3: Cash | K3: June Price
A4: FY2018 | B4: 255.8 | C4: 92.2 | D4: 46.8 | E4: 11.873 | F4: 45.896 | G4: 325.961 | H4: 285.754 | J4: 4.264 | K4: 9.15
A5: FY2019 | B5: 277.974 | C5: 98.1 | D5: 46.795 | E5: 29.172 | F5: 30.393 | G5: 356.696 | H5: 275.989 | I5: 86.429 | J5: 5.647 | K5: 12.4
A6: FY2020 | B6: 304.181 | C6: 117.4 | D6: 65.427 | E6: 57.137 | F6: 27.176 | G6: 404.58 | H6: 254.296 | I6: 84.062 | J6: 14.755 | K6: 13
A7: FY2021 | B7: 305.376 | C7: 117.8 | D7: 61.923 | E7: 14.464 | F7: 59.816 | G7: 453.85 | H7: 258.001 | I7: 98.703 | J7: 8.943 | K7: 13.6
A8: FY2022 | B8: 325.566 | C8: 119 | D8: 63.014 | E8: 29.181 | F8: 36.462 | G8: 499.466 | H8: 253.777 | I8: 124.323 | J8: 5.117 | K8: 11.5
A9: FY2023 | B9: 381.442 | C9: 128.1 | D9: 64.825 | E9: -3.141 | F9: 62.857 | G9: 544.771 | H9: 326.008 | I9: 93.559 | J9: 6.61 | K9: 9.22
A10: FY2024 | B10: 378.346 | C10: 107.2 | D10: 31.377 | E10: -9.117 | F10: 65.978 | G10: 555.999 | H10: 369.478 | I10: 94.613 | J10: 9.384 | K10: 5.07
A11: FY2025 | B11: 349.556 | C11: 113.6 | D11: 49.038 | E11: 59.273 | F11: 46.389 | G11: 586.115 | H11: 337.179 | I11: 103.948 | J11: 8.625 | K11: 3.9
A13: Implied Multiples (EV incl. lease liabilities in net debt)
A14: FY | B14: P/E | C14: P/B | D14: EV/EBITDA | E14: P/S
A15: FY2018 | B15: 19.8 | C15: 2.84 | D15: 13.1 | E15: 3.62
A16: FY2019 | B16: 26.8 | C16: 3.52 | D16: 16.4 | E16: 4.51
A17: FY2020 | B17: 20.1 | C17: 3.25 | D17: 14 | E17: 4.32
A18: FY2021 | B18: 22.2 | C18: 3.03 | D18: 14.6 | E18: 4.5
A19: FY2022 | B19: 18.5 | C19: 2.33 | D19: 12.9 | E19: 3.57
A20: FY2023 | B20: 14.4 | C20: 1.71 | D20: 10.5 | E20: 2.44
A21: FY2024 | B21: 16.3 | C21: 0.92 | D21: 9 | E21: 1.36
A22: FY2025 | B22: 8 | C22: 0.67 | D22: 7.3 | E22: 1.13
A24: Average ex-FY2024 (tariff/vintage outlier) | B24: 18.5 | C24: 2.48 | D24: 12.69 | E24: 3.5
A26: Growth Rates
A28: Metric | B28: 3-Year CAGR | C28: 5-Year CAGR
A29: Revenue | B29: 0.024 | C29: 0.0282
A30: EPS | B30: -0.0802 | C30: -0.056
A31: Equity (Book Value) | B31: 0.0548 | C31: 0.077
A33: Selected Growth Rate: | B33: 0.028
A34: Source: | B34: revenue_5yr_cagr (FY2020-FY2025), NOT equity_5yr_cagr
A36: Note: Equity CAGR diverges >30% above Revenue/EPS CAGR - NOT used as growth driver.
A37: See growth_divergence_warning in JSON for full explanation.

Sheet FCF Quality
A1: FCF Quality - Reported to Owner FCF Reconciliation
A3: SBC is verified NIL throughout - no SBC/interest-income adjustment needed.
A4: The only adjustment applied is deducting IFRS-16 lease PRINCIPAL repayment (financing cash flow) from reported FCF,
A5: since reported FCF (OCF - capex) already includes the ROU D&A add-back inside OCF without the offsetting lease cash cost.
A7: FY | B7: Reported FCF | C7: SBC | D7: Interest Income | E7: Lease Principal Repaid | F7: Owner FCF (adj) | G7: Reported FCF Margin | H7: Owner FCF Margin
A8: FY2019 | B8: 29.172 | C8: 0 | D8: 0 | E8: pre-IFRS16 | F8: 29.172 | G8: 0.10494507 | H8: 0.10494507
A9: FY2020 | B9: 57.137 | C9: 0 | D9: 0 | E9: pre-IFRS16 | F9: 57.137 | G9: 0.18783882 | H9: 0.18783882
A10: FY2021 | B10: 14.464 | C10: 0 | D10: 0 | E10: 4.179 | F10: 10.285 | G10: 0.04736456 | H10: 0.033679791
A11: FY2022 | B11: 29.181 | C11: 0 | D11: 0 | E11: 5.133 | F11: 24.048 | G11: 0.089631595 | H11: 0.073865207
A12: FY2023 | B12: -3.141 | C12: 0 | D12: 0 | E12: 45.053 | F12: -48.194 | G12: -0.0082345416 | H12: -0.12634686
A13: FY2024 | B13: -9.117 | C13: 0 | D13: 0 | E13: 5.188 | F13: -14.305 | G13: -0.024096991 | H13: -0.037809307
A14: FY2025 | B14: 59.273 | C14: 0 | D14: 0 | E14: 10.435 | F14: 48.838 | G14: 0.16956654 | H14: 0.13971438
A16: Memo: FY2023 lease repayment ($45.1m) is a ONE-OFF - Dashwood vineyard land purchase
A17: (buying out a previously-leased vineyard), not a recurring lease amortization cost.
A18: Normalized lease principal run-rate is ~$5-10.4m/yr; projections use ~1.7-2.0% of revenue.
A20: Memo: Effective cash tax rate FY2025 = 19.326/(86.118-17.754) = 28.3% - matches NZ statutory
A21: rate of 28%. No ramp needed (unlike companies with valuation-allowance releases).

Sheet Model_Info
A1: Model Provenance & Notes
A3: Built by | B3: Claude agent (DCF valuation skill), Stocks Research project
A4: Data vintage | B4: Share price NZ$4.20 fetched live from Yahoo Finance 2026-08-10 (regularMarketTime fresh). Financials from Metrics.csv (FY2018-FY2025 annual + H1 FY2019-H1 FY2026 half-year, NZD millions). Lease liabilities queried from DGL.NZ.duckdb kpis table.
A5: Latest filing basis | B5: H1 FY2026 (six months to 31 Dec 2025) is the latest balance sheet date used for net debt/shares. FY2025 (year to 30 Jun 2025) is the latest full audited income statement used as the FCF projection base year. FY2026 full-year results are due late Aug 2026 and were NOT yet published as of valuation date - guidance ($60-62m Operating NPAT) is a forecast, not an actual.
A6: SBC treatment | B6: Verified NIL throughout FY2018-H1FY2026 - family-controlled (~66% Delegat/Douglas families), no option/LTI scheme. No owner-FCF SBC adjustment needed; reported FCF == owner FCF before the lease adjustment below. Shares flat at 101.13m, zero dilution, zero buybacks.
A7: Lease liability treatment | B7: TotalDebt column = bank borrowings ONLY. IFRS-16 lease liabilities (vineyard land leases) held separately, included in net debt alongside bank debt (net debt = bank debt + lease liability - cash = $408.2m at H1 FY2026). Lease PRINCIPAL repayment (not the full liability) is deducted from owner FCF each projected year as a % of revenue, offsetting the ROU depreciation added back in the D&A step. FY2023 lease repayment spike ($45.1m, Dashwood vineyard purchase) is a one-off excluded from the normalized path.
A8: Horizon | B8: 5-year explicit projection (FY2027-FY2031). Base-case FCF margin matures by Year 4-5 (16.1% -> 16.2%), confirming 5yr is sufficient (does not need the 10yr extension reserved for still-ramping margins).
A9: Terminal value methodology - IMPORTANT | B9: Terminal value = MIN(EV/EBITDA-anchored TV using 12.69x [8yr historical average ex-FY2024], FCF-multiple cap of 12-15x by scenario). Pure Gordon growth on FCF was tested first and FAILED the Step 8c sanity check: it produced a negative base-case intrinsic value at an 18% WACC, because DGL's owner-FCF/EBITDA conversion (~45-50%, driven by heavy vineyard capex/D&A/lease drag) means a Gordon FCF-multiple implies a much lower EV/EBITDA multiple (~3.5-4.5x) than the market has EVER paid for this stock, even at its FY2025 trading trough (7.3x). WACC was also recalibrated down from an initial 18% to a base of 12.8% for the same reason - see wacc_rationale and sanity_check blocks in the JSON for the full diagnosis. Gordon growth is retained in the model for disclosure only (row 49 on the DCF Model tab) and used for the Sensitivity tab (uncapped), which will therefore show LOWER values than the headline scenarios at matching WACC/g - this is expected and documented.
A10: WACC | B10: Base 12.8% = 9.5% NZ small-cap floor + 3.3% stacked premium (illiquidity/thin free float +1.0%, family/founder governance +0.5%, single-brand concentration +0.5%, vintage/weather cyclicality +0.5%, US tariff/trade policy +0.8%). Bull 11.8%, Bear 14.8%. Still above the ~8.6% WACC the market's own $4.20 price implicitly assumes on the base-case FCF path (solved by bisection) - the model remains conservative relative to market pricing.
A11: Growth driver | B11: Revenue 5yr CAGR (2.8%), NOT equity CAGR (7.7%) - equity CAGR is inflated by retained-earnings compounding even as revenue has stagnated/declined since the FY2023 peak ($381.4m -> FY2025 $349.6m) and EPS CAGR is negative. See growth_divergence_warning in JSON.
A12: What to refresh after next earnings | B12: FY2026 full-year results (due late Aug 2026): update base-year revenue/EBITDA/FCF from FY2025 to FY2026 actuals, re-verify the $60-62m Operating NPAT guidance against the reported figure, refresh net debt and lease liability from the FY2026 balance sheet, and re-check the Section 301 tariff impact (effective 24-Jul-2026, ~17% total on NZ wine into the US) once it shows up in a full reporting period.
A13: Cell colour conventions | B13: Gray-shaded cells (light blue-gray, #dfe6e9) are INPUTS - safe to edit. White cells with borders are FORMULAS - do not hand-edit, they recalculate automatically. Green cells are headline OUTPUTS (intrinsic value, entry price).
A14: Staleness warning | B14: All figures (price, financials, guidance) are dated 2026-08-10 or the FY2025/H1FY2026 filings. Re-verify before relying on this model beyond the next earnings release or major tariff development.
