Workbook

Sheet DCF Model
A1: DELL Technologies - DCF Valuation Model
A2: Valuation date: 2026-06-27 | Yellow cells are INPUTS - adjust to see valuation update automatically
A3: Live price fetched from Yahoo Finance: $399.49 | Sanity check: CONDITIONAL_PASS
A4: CAUTION: Current price ($399.49) requires bull-case assumptions to be supported by DCF. Base case intrinsic value is $232 (-42%). Market multiples (P/E 23x, EV/EBIT 21x) are not stretched for the growth trajectory, but the DCF margin of safety is negative at current price. Only the bull scenario ($424) implies meaningful upside. Key risk: AI server FCF margins staying compressed at 4-5% would make current price difficult to justify.
A6: KEY INPUTS
A7: Current Stock Price ($) | B7: 399.49 | C7: Live from Yahoo Finance
A8: Shares Outstanding (M) | B8: 656 | C8: Q1 FY2027 diluted shares
A9: Cash & Equivalents ($M) | B9: 11528 | C9: FY2026 year-end (Jan 30 2026)
A10: Total Debt ($M) | B10: 31503 | C10: FY2026 year-end
A11: Net Debt ($M) | B11: =B10-B9 -> 0 | C11: Formula: Total Debt minus Cash
A12: Base Year FCF ($M) | B12: 8552 | C12: FY2026 actual FCF ($8,552M = OCF $11,185M - CapEx $2,633M)
A13: Base Year Revenue ($M) | B13: 113538 | C13: FY2026 actual revenue
A14: WACC | B14: 0.1 | C14: Base case; adjust for sensitivity
A15: Terminal Growth Rate | B15: 0.03 | C15: Base case (long-run nominal GDP)
A16: FCF Margin (% of Revenue) | B16: 0.055 | C16: Base: 5.5% (FY2026 actual was 7.5%; reduced for AI mix compression)
A18: REVENUE GROWTH RATES (Yellow = editable)
A19: Growth Rate | B19: FY2026 Base | C19: Year 1 | D19: Year 2 | E19: Year 3 | F19: Year 4 | G19: Year 5
C20: 0.47 | D20: 0.2 | E20: 0.12 | F20: 0.08 | G20: 0.05
A22: PROJECTIONS (All formula-driven)
A23: Revenue ($M) | B23: =B13 -> 0 | C23: =B23*(1+C20) -> 0 | D23: =C23*(1+D20) -> 0 | E23: =D23*(1+E20) -> 0 | F23: =E23*(1+F20) -> 0 | G23: =F23*(1+G20) -> 0
A24: FCF ($M) | B24: =B12 -> 0 | C24: =C23*$B$16 -> 0 | D24: =D23*$B$16 -> 0 | E24: =E23*$B$16 -> 0 | F24: =F23*$B$16 -> 0 | G24: =G23*$B$16 -> 0
A25: Discount Factor (1/(1+WACC)^t) | C25: =1/(1+$B$14)^1 -> 0 | D25: =1/(1+$B$14)^2 -> 0 | E25: =1/(1+$B$14)^3 -> 0 | F25: =1/(1+$B$14)^4 -> 0 | G25: =1/(1+$B$14)^5 -> 0
A26: PV of FCF ($M) | C26: =C24*C25 -> 0 | D26: =D24*D25 -> 0 | E26: =E24*E25 -> 0 | F26: =F24*F25 -> 0 | G26: =G24*G25 -> 0
A27: FCF Growth YoY (%) | C27: =(C24-B24)/B24 -> 0 | D27: =(D24-C24)/C24 -> 0 | E27: =(E24-D24)/D24 -> 0 | F27: =(F24-E24)/E24 -> 0 | G27: =(G24-F24)/F24 -> 0
A29: VALUATION BRIDGE
A30: Sum of PV of FCF ($M) | B30: =SUM(C26:G26) -> 0
A31: Terminal FCF = Year 5 FCF x (1 + Terminal Growth) | B31: =G24*(1+$B$15) -> 0
A32: Terminal Value = Terminal FCF / (WACC - Terminal Growth) | B32: =B31/($B$14-$B$15) -> 0
A33: PV of Terminal Value | B33: =B32*G25 -> 0
A34: Enterprise Value ($M) | B34: =B30+B33 -> 0
A35: Less: Net Debt ($M) | B35: =B11 -> 0
A36: Equity Value ($M) | B36: =B34-B35 -> 0
A37: INTRINSIC VALUE PER SHARE | B37: =IF(B36>0,B36/B8,0) -> 0
A38: Current Price | B38: =B7 -> 0
A39: Upside / (Downside) | B39: =(B37-B7)/B7 -> 0
A41: ENTRY PRICE FOR 15% CAGR TARGET
A42: Terminal Value per Share ($) | B42: =B32/B8 -> 0
A43: Entry Price (15% CAGR over 5 years) | B43: =B37/(1.15^5) -> 0
A44: Premium/(Discount) to Entry Price | B44: =(B7-B43)/B43 -> 0
A46: VALUATION MULTIPLES (Sanity Check)
...

Sheet Scenarios
A1: DELL - Scenario Comparison: Base / Bull / Bear
A2: Current price: $399.49 | Valuation date: 2026-06-27
A4: Assumption / Output | B4: BASE CASE | C4: BULL CASE | D4: BEAR CASE
A6: ASSUMPTIONS
A7: WACC | B7: 0.1 | C7: 0.09 | D7: 0.12
A8: Terminal Growth Rate | B8: 0.03 | C8: 0.035 | D8: 0.02
A9: FCF Margin | B9: 0.055 | C9: 0.065 | D9: 0.04
A10: Year 1 Revenue Growth | B10: 0.47 | C10: 0.54 | D10: 0.23
A11: Year 5 Revenue Growth | B11: 0.05 | C11: 0.07 | D11: 0.02
A12: REVENUE PROJECTIONS ($M)
A13: Year 1 (FY2027) | B13: 167000 | C13: 175000 | D13: 140000
A14: Year 2 (FY2028) | B14: 200400 | C14: 218750 | D14: 148400
A15: Year 3 (FY2029) | B15: 224448 | C15: 252563 | D15: 153854
A16: Year 4 (FY2030) | B16: 242404 | C16: 278219 | D16: 157316
A17: Year 5 (FY2031) | B17: 254524 | C17: 299085 | D17: 159777
A18: FREE CASH FLOW PROJECTIONS ($M)
A19: Year 1 (FY2027) | B19: 9185 | C19: 11375 | D19: 5600
A20: Year 2 (FY2028) | B20: 11022 | C20: 14219 | D20: 5936
A21: Year 3 (FY2029) | B21: 12345 | C21: 16417 | D21: 6154
A22: Year 4 (FY2030) | B22: 13332 | C22: 18084 | D22: 6293
A23: Year 5 (FY2031) | B23: 13999 | C23: 19441 | D23: 6391
A24: VALUATION OUTPUTS
A25: Sum of PV FCF ($M) | B25: 44532 | C25: 60527 | D25: 21737
A26: Terminal Value ($M) | B26: 205983 | C26: 365835 | D26: 65189
A27: PV of Terminal Value ($M) | B27: 127899 | C27: 237768 | D27: 36990
A28: Enterprise Value ($M) | B28: 172431 | C28: 298295 | D28: 58727
A29: Less: Net Debt ($M) | B29: 19975 | C29: 19975 | D29: 19975
A30: Equity Value ($M) | B30: 152456 | C30: 278320 | D30: 38752
A31: INTRINSIC VALUE PER SHARE | B31: 232.4 | C31: 424.27 | D31: 59.07
A32: Current Price | B32: 399.49 | C32: 399.49 | D32: 399.49
A33: Upside / (Downside) to Current | B33: -0.418 | C33: 0.062 | D33: -0.852
A34: Entry Price (15% CAGR) | B34: 115.55 | C34: 210.94 | D34: 29.37
A36: PROBABILITY WEIGHTED
A37: Bull Weight | B37: 0.25
A38: Base Weight | B38: 0.5
A39: Bear Weight | B39: 0.25
A40: Weighted Intrinsic Value | B40: =B37*424.27+B38*232.4+B39*59.07 -> 0
A41: Weighted Upside / (Downside) | B41: =(B40-399.49)/399.49 -> 0

Sheet Sensitivity
A1: Sensitivity Analysis - Intrinsic Value per Share (Base Case FCF)
A2: WACC (rows) vs Terminal Growth Rate (columns) | Shares=656M, Net Debt=$19,975M
A3: Values calculated using base case revenue projections x 5.5% FCF margin
A5: Live matrix (recalculates from DCF Model inputs):
A7: WACC \ TG | B7: 2.0% | C7: 2.5% | D7: 3.0% | E7: 3.5% | F7: 4.0%
A8: 8% | B8: =((167000*'DCF Model'!$B$16/(1+0.08)^1+200400*'DCF Model'!$B$16/(1+0.08)^2+224448*'DCF Model'!$B$16/(1+0.08)^3+242404*'DCF Model'!$B$16/(1+0.08)^4+254524*'DCF Model'!$B$16/(1+0.08)^5+254524*'DCF Model'!$B$16*(1+0.02)/(0.08-0.02)/(1+0.08)^5)-'DCF Model'!$B$11)/'DCF Model'!$B$8 -> 0 | C8: =((167000*'DCF Model'!$B$16/(1+0.08)^1+200400*'DCF Model'!$B$16/(1+0.08)^2+224448*'DCF Model'!$B$16/(1+0.08)^3+242404*'DCF Model'!$B$16/(1+0.08)^4+254524*'DCF Model'!$B$16/(1+0.08)^5+254524*'DCF Model'!$B$16*(1+0.025)/(0.08-0.025)/(1+0.08)^5)-'DCF Model'!$B$11)/'DCF Model'!$B$8 -> 0 | D8: =((167000*'DCF Model'!$B$16/(1+0.08)^1+200400*'DCF Model'!$B$16/(1+0.08)^2+224448*'DCF Model'!$B$16/(1+0.08)^3+242404*'DCF Model'!$B$16/(1+0.08)^4+254524*'DCF Model'!$B$16/(1+0.08)^5+254524*'DCF Model'!$B$16*(1+0.03)/(0.08-0.03)/(1+0.08)^5)-'DCF Model'!$B$11)/'DCF Model'!$B$8 -> 0 | E8: =((167000*'DCF Model'!$B$16/(1+0.08)^1+200400*'DCF Model'!$B$16/(1+0.08)^2+224448*'DCF Model'!$B$16/(1+0.08)^3+242404*'DCF Model'!$B$16/(1+0.08)^4+254524*'DCF Model'!$B$16/(1+0.08)^5+254524*'DCF Model'!$B$16*(1+0.035)/(0.08-0.035)/(1+0.08)^5)-'DCF Model'!$B$11)/'DCF Model'!$B$8 -> 0 | F8: =((167000*'DCF Model'!$B$16/(1+0.08)^1+200400*'DCF Model'!$B$16/(1+0.08)^2+224448*'DCF Model'!$B$16/(1+0.08)^3+242404*'DCF Model'!$B$16/(1+0.08)^4+254524*'DCF Model'!$B$16/(1+0.08)^5+254524*'DCF Model'!$B$16*(1+0.04)/(0.08-0.04)/(1+0.08)^5)-'DCF Model'!$B$11)/'DCF Model'!$B$8 -> 0
A9: 9% | B9: =((167000*'DCF Model'!$B$16/(1+0.09)^1+200400*'DCF Model'!$B$16/(1+0.09)^2+224448*'DCF Model'!$B$16/(1+0.09)^3+242404*'DCF Model'!$B$16/(1+0.09)^4+254524*'DCF Model'!$B$16/(1+0.09)^5+254524*'DCF Model'!$B$16*(1+0.02)/(0.09-0.02)/(1+0.09)^5)-'DCF Model'!$B$11)/'DCF Model'!$B$8 -> 0 | C9: =((167000*'DCF Model'!$B$16/(1+0.09)^1+200400*'DCF Model'!$B$16/(1+0.09)^2+224448*'DCF Model'!$B$16/(1+0.09)^3+242404*'DCF Model'!$B$16/(1+0.09)^4+254524*'DCF Model'!$B$16/(1+0.09)^5+254524*'DCF Model'!$B$16*(1+0.025)/(0.09-0.025)/(1+0.09)^5)-'DCF Model'!$B$11)/'DCF Model'!$B$8 -> 0 | D9: =((167000*'DCF Model'!$B$16/(1+0.09)^1+200400*'DCF Model'!$B$16/(1+0.09)^2+224448*'DCF Model'!$B$16/(1+0.09)^3+242404*'DCF Model'!$B$16/(1+0.09)^4+254524*'DCF Model'!$B$16/(1+0.09)^5+254524*'DCF Model'!$B$16*(1+0.03)/(0.09-0.03)/(1+0.09)^5)-'DCF Model'!$B$11)/'DCF Model'!$B$8 -> 0 | E9: =((167000*'DCF Model'!$B$16/(1+0.09)^1+200400*'DCF Model'!$B$16/(1+0.09)^2+224448*'DCF Model'!$B$16/(1+0.09)^3+242404*'DCF Model'!$B$16/(1+0.09)^4+254524*'DCF Model'!$B$16/(1+0.09)^5+254524*'DCF Model'!$B$16*(1+0.035)/(0.09-0.035)/(1+0.09)^5)-'DCF Model'!$B$11)/'DCF Model'!$B$8 -> 0 | F9: =((167000*'DCF Model'!$B$16/(1+0.09)^1+200400*'DCF Model'!$B$16/(1+0.09)^2+224448*'DCF Model'!$B$16/(1+0.09)^3+242404*'DCF Model'!$B$16/(1+0.09)^4+254524*'DCF Model'!$B$16/(1+0.09)^5+254524*'DCF Model'!$B$16*(1+0.04)/(0.09-0.04)/(1+0.09)^5)-'DCF Model'!$B$11)/'DCF Model'!$B$8 -> 0
A10: 10% | B10: =((167000*'DCF Model'!$B$16/(1+0.1)^1+200400*'DCF Model'!$B$16/(1+0.1)^2+224448*'DCF Model'!$B$16/(1+0.1)^3+242404*'DCF Model'!$B$16/(1+0.1)^4+254524*'DCF Model'!$B$16/(1+0.1)^5+254524*'DCF Model'!$B$16*(1+0.02)/(0.1-0.02)/(1+0.1)^5)-'DCF Model'!$B$11)/'DCF Model'!$B$8 -> 0 | C10: =((167000*'DCF Model'!$B$16/(1+0.1)^1+200400*'DCF Model'!$B$16/(1+0.1)^2+224448*'DCF Model'!$B$16/(1+0.1)^3+242404*'DCF Model'!$B$16/(1+0.1)^4+254524*'DCF Model'!$B$16/(1+0.1)^5+254524*'DCF Model'!$B$16*(1+0.025)/(0.1-0.025)/(1+0.1)^5)-'DCF Model'!$B$11)/'DCF Model'!$B$8 -> 0 | D10: =((167000*'DCF Model'!$B$16/(1+0.1)^1+200400*'DCF Model'!$B$16/(1+0.1)^2+224448*'DCF Model'!$B$16/(1+0.1)^3+242404*'DCF Model'!$B$16/(1+0.1)^4+254524*'DCF Model'!$B$16/(1+0.1)^5+254524*'DCF Model'!$B$16*(1+0.03)/(0.1-0.03)/(1+0.1)^5)-'DCF Model'!$B$11)/'DCF Model'!$B$8 -> 0 | E10: =((167000*'DCF Model'!$B$16/(1+0.1)^1+200400*'DCF Model'!$B$16/(1+0.1)^2+224448*'DCF Model'!$B$16/(1+0.1)^3+242404*'DCF Model'!$B$16/(1+0.1)^4+254524*'DCF Model'!$B$16/(1+0.1)^5+254524*'DCF Model'!$B$16*(1+0.035)/(0.1-0.035)/(1+0.1)^5)-'DCF Model'!$B$11)/'DCF Model'!$B$8 -> 0 | F10: =((167000*'DCF Model'!$B$16/(1+0.1)^1+200400*'DCF Model'!$B$16/(1+0.1)^2+224448*'DCF Model'!$B$16/(1+0.1)^3+242404*'DCF Model'!$B$16/(1+0.1)^4+254524*'DCF Model'!$B$16/(1+0.1)^5+254524*'DCF Model'!$B$16*(1+0.04)/(0.1-0.04)/(1+0.1)^5)-'DCF Model'!$B$11)/'DCF Model'!$B$8 -> 0
A11: 11% | B11: =((167000*'DCF Model'!$B$16/(1+0.11)^1+200400*'DCF Model'!$B$16/(1+0.11)^2+224448*'DCF Model'!$B$16/(1+0.11)^3+242404*'DCF Model'!$B$16/(1+0.11)^4+254524*'DCF Model'!$B$16/(1+0.11)^5+254524*'DCF Model'!$B$16*(1+0.02)/(0.11-0.02)/(1+0.11)^5)-'DCF Model'!$B$11)/'DCF Model'!$B$8 -> 0 | C11: =((167000*'DCF Model'!$B$16/(1+0.11)^1+200400*'DCF Model'!$B$16/(1+0.11)^2+224448*'DCF Model'!$B$16/(1+0.11)^3+242404*'DCF Model'!$B$16/(1+0.11)^4+254524*'DCF Model'!$B$16/(1+0.11)^5+254524*'DCF Model'!$B$16*(1+0.025)/(0.11-0.025)/(1+0.11)^5)-'DCF Model'!$B$11)/'DCF Model'!$B$8 -> 0 | D11: =((167000*'DCF Model'!$B$16/(1+0.11)^1+200400*'DCF Model'!$B$16/(1+0.11)^2+224448*'DCF Model'!$B$16/(1+0.11)^3+242404*'DCF Model'!$B$16/(1+0.11)^4+254524*'DCF Model'!$B$16/(1+0.11)^5+254524*'DCF Model'!$B$16*(1+0.03)/(0.11-0.03)/(1+0.11)^5)-'DCF Model'!$B$11)/'DCF Model'!$B$8 -> 0 | E11: =((167000*'DCF Model'!$B$16/(1+0.11)^1+200400*'DCF Model'!$B$16/(1+0.11)^2+224448*'DCF Model'!$B$16/(1+0.11)^3+242404*'DCF Model'!$B$16/(1+0.11)^4+254524*'DCF Model'!$B$16/(1+0.11)^5+254524*'DCF Model'!$B$16*(1+0.035)/(0.11-0.035)/(1+0.11)^5)-'DCF Model'!$B$11)/'DCF Model'!$B$8 -> 0 | F11: =((167000*'DCF Model'!$B$16/(1+0.11)^1+200400*'DCF Model'!$B$16/(1+0.11)^2+224448*'DCF Model'!$B$16/(1+0.11)^3+242404*'DCF Model'!$B$16/(1+0.11)^4+254524*'DCF Model'!$B$16/(1+0.11)^5+254524*'DCF Model'!$B$16*(1+0.04)/(0.11-0.04)/(1+0.11)^5)-'DCF Model'!$B$11)/'DCF Model'!$B$8 -> 0
A12: 12% | B12: =((167000*'DCF Model'!$B$16/(1+0.12)^1+200400*'DCF Model'!$B$16/(1+0.12)^2+224448*'DCF Model'!$B$16/(1+0.12)^3+242404*'DCF Model'!$B$16/(1+0.12)^4+254524*'DCF Model'!$B$16/(1+0.12)^5+254524*'DCF Model'!$B$16*(1+0.02)/(0.12-0.02)/(1+0.12)^5)-'DCF Model'!$B$11)/'DCF Model'!$B$8 -> 0 | C12: =((167000*'DCF Model'!$B$16/(1+0.12)^1+200400*'DCF Model'!$B$16/(1+0.12)^2+224448*'DCF Model'!$B$16/(1+0.12)^3+242404*'DCF Model'!$B$16/(1+0.12)^4+254524*'DCF Model'!$B$16/(1+0.12)^5+254524*'DCF Model'!$B$16*(1+0.025)/(0.12-0.025)/(1+0.12)^5)-'DCF Model'!$B$11)/'DCF Model'!$B$8 -> 0 | D12: =((167000*'DCF Model'!$B$16/(1+0.12)^1+200400*'DCF Model'!$B$16/(1+0.12)^2+224448*'DCF Model'!$B$16/(1+0.12)^3+242404*'DCF Model'!$B$16/(1+0.12)^4+254524*'DCF Model'!$B$16/(1+0.12)^5+254524*'DCF Model'!$B$16*(1+0.03)/(0.12-0.03)/(1+0.12)^5)-'DCF Model'!$B$11)/'DCF Model'!$B$8 -> 0 | E12: =((167000*'DCF Model'!$B$16/(1+0.12)^1+200400*'DCF Model'!$B$16/(1+0.12)^2+224448*'DCF Model'!$B$16/(1+0.12)^3+242404*'DCF Model'!$B$16/(1+0.12)^4+254524*'DCF Model'!$B$16/(1+0.12)^5+254524*'DCF Model'!$B$16*(1+0.035)/(0.12-0.035)/(1+0.12)^5)-'DCF Model'!$B$11)/'DCF Model'!$B$8 -> 0 | F12: =((167000*'DCF Model'!$B$16/(1+0.12)^1+200400*'DCF Model'!$B$16/(1+0.12)^2+224448*'DCF Model'!$B$16/(1+0.12)^3+242404*'DCF Model'!$B$16/(1+0.12)^4+254524*'DCF Model'!$B$16/(1+0.12)^5+254524*'DCF Model'!$B$16*(1+0.04)/(0.12-0.04)/(1+0.12)^5)-'DCF Model'!$B$11)/'DCF Model'!$B$8 -> 0
A14: Legend: | B14: Green = IV >= current price ($399.49) | C14: Yellow = IV within 15% of current price | D14: White = IV more than 15% below current price
A16: Current Price (reference): | B16: ='DCF Model'!B7 -> 0
A17: Base case (WACC=10%, TG=3%): highlighted row/col
A18: Note: FCF margin is live from DCF Model sheet (cell B16, currently 5.5%). Change it there and this table updates.

Sheet Historical Data
A1: DELL - Historical Financial Data (Post-VMware Spinoff)
A2: VMware spun off Nov 1 2021. FY2022+ is the clean post-spinoff comparison base.
A4: Period | B4: Revenue ($M) | C4: Gross Margin | D4: Oper. Margin | E4: Net Income ($M) | F4: GAAP EPS | G4: OCF ($M) | H4: FCF ($M) | I4: FCF Margin
A5: FY2022 | B5: 101197 | C5: 0.216 | D5: 0.046 | E5: 5563 | F5: 7.02 | G5: 10307 | H5: 7511 | I5: 0.074
A6: FY2023 | B6: 102301 | C6: 0.222 | D6: 0.056 | E6: 2442 | F6: 3.24 | G6: 3565 | H6: 562 | I6: 0.005
A7: FY2024 | B7: 88425 | C7: 0.238 | D7: 0.061 | E7: 3388 | F7: 4.6 | G7: 8676 | H7: 5920 | I7: 0.067
A8: FY2025 | B8: 95567 | C8: 0.222 | D8: 0.065 | E8: 4592 | F8: 6.38 | G8: 4521 | H8: 1869 | I8: 0.02
A9: FY2026 | B9: 113538 | C9: 0.2 | D9: 0.072 | E9: 5936 | F9: 8.68 | G9: 11185 | H9: 8552 | I9: 0.075
A10: Q1 FY2027 | B10: 43842 | C10: 0.178 | D10: 0.083 | E10: 3438 | F10: 5.24 | G10: 4081 | H10: 3118 | I10: 0.071
A12: HISTORICAL GROWTH RATES
A13: Metric | B13: 3yr CAGR (FY23-FY26) | C13: 4yr CAGR (FY22-FY26) | D13: Note
A14: Revenue | B14: 3.5% | C14: 2.9% | D14: Suppressed by PC market weakness in FY2024; pre-spinoff comparable issues
A15: GAAP EPS | B15: 38.9% | C15: 5.4% | D15: FY2023 depressed by restructuring; FY2026 record earnings
A16: FCF | B16: 20.2% (2yr) | C16: N/A | D16: FY2023 ($562M) distorted; 2yr FY2024-FY2026 CAGR most reliable
A17: Equity/Book Value | B17: N/A | C17: N/A | D17: UNUSABLE: Dell has sustained negative shareholders equity since 2016 EMC acquisition
A18: Selected Rate | B18: forward_revenue_guidance_fy2027 | C18: FY2027 guidance: +47% | D18: Forward-anchored to mgmt guidance; AI supercycle inflection
A20: Q1 FY2027 KEY METRICS (Quarter ended May 1 2026)
A21: Total Revenue | B21: $43.8B | C21: +88% YoY, beat consensus by $8.1B
A22: ISG Revenue | B22: $29.0B | C22: +181% YoY; AI-optimized servers $16.1B (+757% YoY)
A23: CSG Revenue | B23: $14.6B | C23: +17% YoY; commercial record $13B; AI PCs driving ASP expansion
A24: AI Server Orders | B24: $24.4B booked in Q1 | C24: AI backlog reached record $51.3B
A25: GAAP EPS | B25: $5.24 | C25: +282% YoY; Q1 alone represents 30% of full FY2026 GAAP EPS
A26: Operating Cash Flow | B26: $4.1B | C26: Q1 FCF $3.1B (7.1% margin); annualizes to $12.5B
A27: FY2027 Guidance Raised | B27: Revenue $165-169B | C27: AI servers ~$60B; non-GAAP EPS ~$17.90
