Workbook

Sheet Model_Info
A1: SKC.NZ - SkyCity Entertainment Group - DCF Model
A3: Version | B3: 1.0 - initial build. Supersedes nothing; no prior SKC.NZ_DCF.json existed.
A4: Built by | B4: dcf-analyst agent (Claude Opus 5), 2026-08-28, at the user request to value SKC.NZ.
A5: Model | B5: Owner-FCF DCF, 10-year explicit horizon, unlevered, 3 scenarios probability-weighted, plus a non-operating asset bridge and a book-value cross-check.
A6: Currency / units | B6: NZD, millions. Quote and financials are both NZD - no currency layer.
A7: Price anchor | B7: NZ$0.67, Yahoo NZX regular close 2026-08-28T04:59:59Z. 52-week range 0.46-0.99. Figures go stale - refresh before use.
A8: Balance sheet anchor | B8: 30 June 2026 (FY2026 annual report).
A9: Share count | B9: 1,103,055,047 ACTUAL shares on issue at 1 Aug 2026. NOT the 1,037,141,618 FY2026 weighted average (understates by 6.4%).
A10: Guidance vintage | B10: FY2026 annual result, 20-21 August 2026. FY27 capex guidance $80-100m; cost-out $30m FY27 -> $70m FY28; net debt/EBITDA target <2.0x.
A11: Lease treatment | B11: Treatment A - leases are DEBT. Lease principal NOT deducted from flows; lease liabilities 154.228 ARE in net debt. Charged once.
A12: Interest | B12: SkyCity reports interest in FINANCING, not operating. The model is therefore UNLEVERED: interest is not in the flows, debt is deducted in the bridge.
A13: WACC | B13: 11.5% NZD. Rf 4.3% + beta 1.30 x ERP 6.0% = 12.1% base CoE, plus 1.5pp regulatory, 0.8pp illiquidity, 0.7pp leverage. Same WACC in all scenarios (risk charged once).
A14: Mid-cycle base | B14: Clean FY2026 EBITDA of 152.6, NOT reported 120.5 and NOT company underlying 181.6. See the Mid_Cycle tab.
... A19: Caution | B19: All figures go stale. Re-verify the price, balance sheet and share count before relying on this workbook.

Sheet Actuals
A1: Reported history (NZD m) - source: SKC.NZ_Metrics.csv, from the annual reports
B2: FY2016 | C2: FY2017 | D2: FY2018 | E2: FY2019 | F2: FY2020 | G2: FY2021 | H2: FY2022 | I2: FY2023 | J2: FY2024 | K2: FY2025 | L2: FY2026
A3: Revenue | B3: 998.7 | C3: 927.3 | D3: 994.6 | E3: 802.3 | F3: 641.7 | G3: 713.2 | H3: 553.5 | I3: 855.8 | J3: 861 | K3: 821.3 | L3: 813.651
A4: EBITDA (reported) | B4: 333.9 | C4: 307 | D4: 338.7 | E4: 297.8 | F4: 348.3 | G4: 317.3 | H4: 96.9 | I4: 165.9 | J4: 138.2 | K4: 216.1 | L4: 120.474
A5: EBITDA margin % | B5: 33.4 | C5: 33.1 | D5: 34.1 | E5: 37.1 | F5: 54.3 | G5: 44.5 | H5: 17.5 | I5: 19.4 | J5: 16 | K5: 26.3 | L5: 14.8
A6: Operating cash flow | B6: 305.2 | C6: 279.5 | D6: 289.1 | E6: 252.3 | F6: 120.2 | G6: 288.2 | H6: 91.1 | I6: 280.1 | J6: 203.6 | K6: 45.2 | L6: 121.676
A7: Capex | B7: 156.5 | C7: 158.6 | D7: 215.1 | E7: 332.8 | F7: 345.1 | G7: 177.5 | H7: 111.5 | I7: 262.9 | J7: 310.7 | K7: 163.8 | L7: 113.627
A8: Free cash flow | B8: 148.6 | C8: 120.9 | D8: 74 | E8: -80.5 | F8: -225 | G8: 110.7 | H8: -20.4 | I8: 17.2 | J8: -107.2 | K8: -118.7 | L8: 8.049
A9: Shareholders equity | B9: 1113 | C9: 1070.9 | D9: 1158 | E9: 1156 | F9: 1434.6 | G9: 1651 | H9: 1571.3 | I9: 1530.2 | J9: 1303.9 | K9: 1330.4 | L9: 1545.034
A10: Total debt (incl leases) | B10: 427.1 | C10: 391.8 | D10: 508.5 | E10: 545 | F10: 637.9 | G10: 607.8 | H10: 650.5 | I10: 691.4 | J10: 730.9 | K10: 803.4 | L10: 719.336
A11: Cash | B11: 90.3 | C11: 56.7 | D11: 76 | E11: 41.6 | F11: 54.2 | G11: 49.9 | H11: 48.7 | I11: 245 | J11: 60.5 | K11: 51.5 | L11: 84.415
A12: Shares (m, period end) | B12: 598.5 | C12: 662.2 | D12: 669.1 | E12: 675.8 | F12: 664.9 | G12: 759.7 | H12: 757.5 | I12: 758.1 | J12: 758.7 | K12: 759.2 | L12: 1103.055
A14: Balance sheet and share count at 30 June 2026 / 1 August 2026
A15: Borrowings (ex leases) | B15: 565.108 | D15: Total debt 719.336 less lease liabilities 154.228
A16: Lease liabilities | B16: 154.228 | D16: FY2026 note 22; treated as DEBT (Treatment A)
A17: Cash | B17: 84.415 | D17: FY2026 balance sheet
A18: NET DEBT | B18: 634.921 | D18: 565.108 + 154.228 - 84.415
A19: Shares on issue | B19: 1103.055 | D19: ACTUAL at 1 Aug 2026 - not the 1037.1m weighted average
A20: Assets held for sale | B20: 74.056 | D20: 99 Albert St / Victoria St, UNCONDITIONAL, settles Sep-2026
A21: Investment properties | B21: 20.75 | D21: FY2026 note 18, at fair value
A22: SBC expense | B22: 0.76 | D22: Note 29 - immaterial, 0.09% of revenue
A23: Interest income | B23: 2.351 | D23: Note 8 - not stripped; company is net DEBT
A24: Buyback cash | B24: 0 | D24: None. Dividend also suspended since FY2025

Sheet Mid_Cycle
A1: Bridge from reported FY2026 EBITDA to the clean mid-cycle base
A2: Reported FY2026 EBITDA | B2: 120.474
A3: add back: impairment_adelaide_cgu_non_cash | B3: 62.443
A4: add back: regulatory_penalty_provision_cbs | B4: 23.94
A5: add back: fair_value_loss_investment_property_non_cash | B5: 7.389
A6: strip out: fx_translation_reserve_release_non_cash | B6: -56.197
A7: strip out: settlement_and_litigation_recoveries | B7: -5.46
A8: CLEAN FY2026 EBITDA | B8: =SUM(B2:B7)
A10: Company-stated underlying EBITDA | B10: 181.6 | C10: Company additionally adds back 23.5m of B3 Adelaide costs. This model does not: the annual report states B3 costs INCREASE in FY27, they were 17.6m in FY25 and 23.5m in FY26, and the programme completes only in early FY28.
A12: Critical finding | C12: The 56.197 foreign currency translation reserve release is a PURE NON-CASH accounting reclassification from equity to P&L on deregistration of Australian and Hong Kong subsidiaries (NZ IAS 21). It creates no cash and no value, yet it sits INSIDE reported EBITDA of 120.5. Adding back only the impairment/penalty/FV-loss without stripping this gain would overstate the clean base by 56.2m.
A14: Bottom-up mid-cycle bridge (informs the margin path)
A15: Clean FY2026 EBITDA | B15: 152.6 | C15: starting point
A16: Cost-out programme, annualised FY28 target | B16: 70 | C16: management target
A17: B3 Adelaide costs roll off after early FY28 | B17: 23.5 | C17: genuinely ends
A18: Execution haircut applied to the above | B18: -42.1 | C18: 45% haircut for slippage
A19: NZICC annualising (opened Feb-2026) | B19: 6 | C19: 10m gross, 60% credited
A20: Carded play recovery | B20: 0 | C20: assumed ZERO - permanent reset
A21: Consumer recovery | B21: 0 | C21: assumed ZERO in base
A22: Mid-cycle EBITDA implied | B22: =SUM(B15:B21) | C22: The base-case margin path reaches roughly this level by year 4 (24% of revenue).

Sheet Assumptions
A1: Global assumptions
A2: WACC (all scenarios) | B2: 0.115 | F2: NZD-built. Risk charged ONCE - same rate in every scenario.
A3: D&A % of revenue | B3: 0.129 | F3: FY2026 D&A 96.015 + RoU 9.044 = 105.1 on revenue 813.7
A4: Net debt | B4: 634.921 | F4: Borrowings 565.108 + leases 154.228 - cash 84.415
A5: Shares on issue (m) | B5: 1103.055 | F5: ACTUAL at 1 Aug 2026
A6: Current price | B6: 0.67 | F6: Yahoo NZX close 2026-08-28
A7: Book value per share | B7: 1.401 | F7: Equity 1545.034 / 1103.055m shares
A8: Clean FY2026 EBITDA | B8: 152.6 | F8: See the Mid_Cycle tab
A9: Hurdle rate for entry price | B9: 0.15 | F9: House standard
A11: Per-scenario assumptions
B12: BEAR | C12: BASE | D12: BULL
A13: Terminal growth | B13: 0.015 | C13: 0.025 | D13: 0.03
A14: Terminal FCF cap multiple | B14: 11 | C14: 14 | D14: 15
A15: Non-operating assets credited | B15: 60 | C15: 91.7 | D15: 200
A16: Probability weight | B16: 0.3 | C16: 0.45 | D16: 0.25
A17: Weights sum (must be 1.0) | B17: =SUM(B16:D16)
A19: Scenario narratives
A20: BEAR | B20: Carded play proves a permanent reset and bites further; the cost-out programme slips against a rising compliance base; the Adelaide strategic review concludes in a further write-down; consumer weakness persists; the unsigned share of the asset-monetisation target does not complete, as the failed Auckland car park concession process already foreshadowed. No re-bid emerges and the price reverts toward the un-bid 0.46-0.60 range. Revenue declines before stabilising and the EBITDA margin holds near 19%.
A21: BASE | B21: Cost-out delivers roughly half its $70m target after execution slippage; B3 Adelaide costs roll off from FY28; the NZICC annualises but converts visitation to precinct spend only gradually; carded play is NOT recovered and no consumer recovery is assumed. Revenue grows with inflation only, and the EBITDA margin recovers from 19.5% to a mature 24% - reaching the bottom-up mid-cycle level of roughly $211m by year 4, well short of the $330m the company earned pre-2019.
A22: BULL | B22: The cost-out programme delivers in full, the NZICC drives genuine precinct-wide operating leverage, SkyCity wins an online casino licence at the 2027 auction, the consumer recovers, and the full $275-300m monetisation completes and takes net debt/EBITDA below 2.0x, reopening the dividend. A bidder returns with a binding offer at or above the rejected $0.75. Margin recovers to 28%, still below the 33-34% of FY2016-18.

Sheet DCF_Bear
A1: SKC.NZ DCF - BEAR case
A2: All rows are formulas except the blue driver rows 5, 7, 9, 14 and the FY0 revenue in B6.
A3: Year | B3: FY2026A | C3: FY2027E | D3: FY2028E | E3: FY2029E | F3: FY2030E | G3: FY2031E | H3: FY2032E | I3: FY2033E | J3: FY2034E | K3: FY2035E | L3: FY2036E
A4: Year index | B4: 0 | C4: 1 | D4: 2 | E4: 3 | F4: 4 | G4: 5 | H4: 6 | I4: 7 | J4: 8 | K4: 9 | L4: 10
A5: Revenue growth YoY | C5: -0.03 | D5: -0.015 | E5: 0 | F5: 0.01 | G5: 0.01 | H5: 0.015 | I5: 0.015 | J5: 0.015 | K5: 0.015 | L5: 0.015
A6: Revenue | B6: 813.651 | C6: =B6*(1+C5) | D6: =C6*(1+D5) | E6: =D6*(1+E5) | F6: =E6*(1+F5) | G6: =F6*(1+G5) | H6: =G6*(1+H5) | I6: =H6*(1+I5) | J6: =I6*(1+J5) | ... L6: =K6*(1+L5)
A7: Adj EBITDA margin | C7: 0.17 | D7: 0.175 | E7: 0.185 | F7: 0.19 | G7: 0.19 | H7: 0.19 | I7: 0.19 | J7: 0.19 | K7: 0.19 | L7: 0.19
A8: Adjusted EBITDA | C8: =C6*C7 | D8: =D6*D7 | E8: =E6*E7 | F8: =F6*F7 | G8: =G6*G7 | H8: =H6*H7 | I8: =I6*I7 | J8: =J6*J7 | ... L8: =L6*L7
A9: SBC % of revenue | C9: 0.001 | D9: 0.001 | E9: 0.001 | F9: 0.001 | G9: 0.001 | H9: 0.001 | I9: 0.001 | J9: 0.001 | K9: 0.001 | L9: 0.001
A10: SBC (negative) | C10: =-C6*C9 | D10: =-D6*D9 | E10: =-E6*E9 | F10: =-F6*F9 | G10: =-G6*G9 | H10: =-H6*H9 | I10: =-I6*I9 | J10: =-J6*J9 | ... L10: =-L6*L9
A11: Owner EBITDA | C11: =C8+C10 | D11: =D8+D10 | E11: =E8+E10 | F11: =F8+F10 | G11: =G8+G10 | H11: =H8+H10 | I11: =I8+I10 | J11: =J8+J10 | ... L11: =L8+L10
A12: D&A (negative) | C12: =-C6*Assumptions!$B$3 | D12: =-D6*Assumptions!$B$3 | E12: =-E6*Assumptions!$B$3 | F12: =-F6*Assumptions!$B$3 | G12: =-G6*Assumptions!$B$3 | H12: =-H6*Assumptions!$B$3 | I12: =-I6*Assumptions!$B$3 | J12: =-J6*Assumptions!$B$3 | ... L12: =-L6*Assumptions!$B$3
A13: EBIT | C13: =C11+C12 | D13: =D11+D12 | E13: =E11+E12 | F13: =F11+F12 | G13: =G11+G12 | H13: =H11+H12 | I13: =I11+I12 | J13: =J11+J12 | ... L13: =L11+L12
A14: Cash tax rate | C14: 0.12 | D14: 0.2 | E14: 0.26 | F14: 0.28 | G14: 0.28 | H14: 0.28 | I14: 0.28 | J14: 0.28 | K14: 0.28 | L14: 0.28
A15: NOPAT | C15: =C13*(1-C14) | D15: =D13*(1-D14) | E15: =E13*(1-E14) | F15: =F13*(1-F14) | G15: =G13*(1-G14) | H15: =H13*(1-H14) | I15: =I13*(1-I14) | J15: =J13*(1-J14) | ... L15: =L13*(1-L14)
A16: add back D&A | C16: =-C12 | D16: =-D12 | E16: =-E12 | F16: =-F12 | G16: =-G12 | H16: =-H12 | I16: =-I12 | J16: =-J12 | ... L16: =-L12
A17: less capex | C17: =-C6*0.115 | D17: =-D6*0.11 | E17: =-E6*0.11 | F17: =-F6*0.105 | G17: =-G6*0.105 | H17: =-H6*0.105 | I17: =-I6*0.105 | J17: =-J6*0.105 | K17: =-K6*0.105 | L17: =-L6*0.105
A18: Working capital | C18: 0 | D18: 0 | E18: 0 | F18: 0 | G18: 0 | H18: 0 | I18: 0 | J18: 0 | K18: 0 | L18: 0
A19: UNLEVERED OWNER FCF | C19: =C15+C16+C17+C18 | D19: =D15+D16+D17+D18 | E19: =E15+E16+E17+E18 | F19: =F15+F16+F17+F18 | G19: =G15+G16+G17+G18 | H19: =H15+H16+H17+H18 | I19: =I15+I16+I17+I18 | J19: =J15+J16+J17+J18 | ... L19: =L15+L16+L17+L18
A20: Discount factor | C20: =1/(1+Assumptions!$B$2)^C4 | D20: =1/(1+Assumptions!$B$2)^D4 | E20: =1/(1+Assumptions!$B$2)^E4 | F20: =1/(1+Assumptions!$B$2)^F4 | G20: =1/(1+Assumptions!$B$2)^G4 | H20: =1/(1+Assumptions!$B$2)^H4 | I20: =1/(1+Assumptions!$B$2)^I4 | J20: =1/(1+Assumptions!$B$2)^J4 | ... L20: =1/(1+Assumptions!$B$2)^L4
A21: PV of FCF | C21: =C19*C20 | D21: =D19*D20 | E21: =E19*E20 | F21: =F19*F20 | G21: =G19*G20 | H21: =H19*H20 | I21: =I19*I20 | J21: =J19*J20 | ... L21: =L19*L20
A23: Memo: FCF before SBC | C23: =C19-C10 | D23: =D19-D10 | E23: =E19-E10 | F23: =F19-F10 | G23: =G19-G10 | H23: =H19-H10 | I23: =I19-I10 | J23: =J19-J10 | ... L23: =L19-L10
A24: Memo: owner-FCF margin | C24: =C19/C6 | D24: =D19/D6 | E24: =E19/E6 | F24: =F19/F6 | G24: =G19/G6 | H24: =H19/H6 | I24: =I19/I6 | J24: =J19/J6 | ... L24: =L19/L6
A26: Sum of PV of FCF | B26: =SUM(C21:L21)
A27: Terminal growth | B27: =Assumptions!$B$13
A28: Terminal-year FCF | B28: =L19*(1+B27)
A29: Gordon terminal value | B29: =B28/(Assumptions!$B$2-B27)
A30: Cap terminal value | B30: =Assumptions!$B$14*L19
A31: Terminal value used | B31: =MAX(0,MIN(B29,B30))
A32: Implied exit multiple | B32: =B31/L19
A33: PV of terminal value | B33: =B31*L20
A34: Enterprise value | B34: =B26+B33
A35: less net debt | B35: =-Assumptions!$B$4
A36: add non-operating assets | B36: =Assumptions!$B$15
A37: Equity value | B37: =B34+B35+B36
A38: Shares on issue (m) | B38: =Assumptions!$B$5
A39: VALUE PER SHARE | B39: =B37/B38
A40: Upside vs current price | B40: =B39/Assumptions!$B$6-1
A41: Implied EV / clean FY26 EBITDA | B41: =B34/Assumptions!$B$8
A42: Implied price / book | B42: =B39/Assumptions!$B$7
...

Sheet DCF_Base
A1: SKC.NZ DCF - BASE case
A2: All rows are formulas except the blue driver rows 5, 7, 9, 14 and the FY0 revenue in B6.
A3: Year | B3: FY2026A | C3: FY2027E | D3: FY2028E | E3: FY2029E | F3: FY2030E | G3: FY2031E | H3: FY2032E | I3: FY2033E | J3: FY2034E | K3: FY2035E | L3: FY2036E
A4: Year index | B4: 0 | C4: 1 | D4: 2 | E4: 3 | F4: 4 | G4: 5 | H4: 6 | I4: 7 | J4: 8 | K4: 9 | L4: 10
A5: Revenue growth YoY | C5: 0.01 | D5: 0.02 | E5: 0.025 | F5: 0.025 | G5: 0.02 | H5: 0.02 | I5: 0.02 | J5: 0.02 | K5: 0.02 | L5: 0.02
A6: Revenue | B6: 813.651 | C6: =B6*(1+C5) | D6: =C6*(1+D5) | E6: =D6*(1+E5) | F6: =E6*(1+F5) | G6: =F6*(1+G5) | H6: =G6*(1+H5) | I6: =H6*(1+I5) | J6: =I6*(1+J5) | ... L6: =K6*(1+L5)
A7: Adj EBITDA margin | C7: 0.195 | D7: 0.215 | E7: 0.235 | F7: 0.24 | G7: 0.24 | H7: 0.24 | I7: 0.24 | J7: 0.24 | K7: 0.24 | L7: 0.24
A8: Adjusted EBITDA | C8: =C6*C7 | D8: =D6*D7 | E8: =E6*E7 | F8: =F6*F7 | G8: =G6*G7 | H8: =H6*H7 | I8: =I6*I7 | J8: =J6*J7 | ... L8: =L6*L7
A9: SBC % of revenue | C9: 0.001 | D9: 0.001 | E9: 0.001 | F9: 0.001 | G9: 0.001 | H9: 0.001 | I9: 0.001 | J9: 0.001 | K9: 0.001 | L9: 0.001
A10: SBC (negative) | C10: =-C6*C9 | D10: =-D6*D9 | E10: =-E6*E9 | F10: =-F6*F9 | G10: =-G6*G9 | H10: =-H6*H9 | I10: =-I6*I9 | J10: =-J6*J9 | ... L10: =-L6*L9
A11: Owner EBITDA | C11: =C8+C10 | D11: =D8+D10 | E11: =E8+E10 | F11: =F8+F10 | G11: =G8+G10 | H11: =H8+H10 | I11: =I8+I10 | J11: =J8+J10 | ... L11: =L8+L10
A12: D&A (negative) | C12: =-C6*Assumptions!$B$3 | D12: =-D6*Assumptions!$B$3 | E12: =-E6*Assumptions!$B$3 | F12: =-F6*Assumptions!$B$3 | G12: =-G6*Assumptions!$B$3 | H12: =-H6*Assumptions!$B$3 | I12: =-I6*Assumptions!$B$3 | J12: =-J6*Assumptions!$B$3 | ... L12: =-L6*Assumptions!$B$3
A13: EBIT | C13: =C11+C12 | D13: =D11+D12 | E13: =E11+E12 | F13: =F11+F12 | G13: =G11+G12 | H13: =H11+H12 | I13: =I11+I12 | J13: =J11+J12 | ... L13: =L11+L12
A14: Cash tax rate | C14: 0.1 | D14: 0.18 | E14: 0.24 | F14: 0.28 | G14: 0.28 | H14: 0.28 | I14: 0.28 | J14: 0.28 | K14: 0.28 | L14: 0.28
A15: NOPAT | C15: =C13*(1-C14) | D15: =D13*(1-D14) | E15: =E13*(1-E14) | F15: =F13*(1-F14) | G15: =G13*(1-G14) | H15: =H13*(1-H14) | I15: =I13*(1-I14) | J15: =J13*(1-J14) | ... L15: =L13*(1-L14)
A16: add back D&A | C16: =-C12 | D16: =-D12 | E16: =-E12 | F16: =-F12 | G16: =-G12 | H16: =-H12 | I16: =-I12 | J16: =-J12 | ... L16: =-L12
A17: less capex | C17: =-C6*0.11 | D17: =-D6*0.105 | E17: =-E6*0.1 | F17: =-F6*0.1 | G17: =-G6*0.1 | H17: =-H6*0.1 | I17: =-I6*0.1 | J17: =-J6*0.1 | K17: =-K6*0.1 | L17: =-L6*0.1
A18: Working capital | C18: 0 | D18: 0 | E18: 0 | F18: 0 | G18: 0 | H18: 0 | I18: 0 | J18: 0 | K18: 0 | L18: 0
A19: UNLEVERED OWNER FCF | C19: =C15+C16+C17+C18 | D19: =D15+D16+D17+D18 | E19: =E15+E16+E17+E18 | F19: =F15+F16+F17+F18 | G19: =G15+G16+G17+G18 | H19: =H15+H16+H17+H18 | I19: =I15+I16+I17+I18 | J19: =J15+J16+J17+J18 | ... L19: =L15+L16+L17+L18
A20: Discount factor | C20: =1/(1+Assumptions!$B$2)^C4 | D20: =1/(1+Assumptions!$B$2)^D4 | E20: =1/(1+Assumptions!$B$2)^E4 | F20: =1/(1+Assumptions!$B$2)^F4 | G20: =1/(1+Assumptions!$B$2)^G4 | H20: =1/(1+Assumptions!$B$2)^H4 | I20: =1/(1+Assumptions!$B$2)^I4 | J20: =1/(1+Assumptions!$B$2)^J4 | ... L20: =1/(1+Assumptions!$B$2)^L4
A21: PV of FCF | C21: =C19*C20 | D21: =D19*D20 | E21: =E19*E20 | F21: =F19*F20 | G21: =G19*G20 | H21: =H19*H20 | I21: =I19*I20 | J21: =J19*J20 | ... L21: =L19*L20
A23: Memo: FCF before SBC | C23: =C19-C10 | D23: =D19-D10 | E23: =E19-E10 | F23: =F19-F10 | G23: =G19-G10 | H23: =H19-H10 | I23: =I19-I10 | J23: =J19-J10 | ... L23: =L19-L10
A24: Memo: owner-FCF margin | C24: =C19/C6 | D24: =D19/D6 | E24: =E19/E6 | F24: =F19/F6 | G24: =G19/G6 | H24: =H19/H6 | I24: =I19/I6 | J24: =J19/J6 | ... L24: =L19/L6
A26: Sum of PV of FCF | B26: =SUM(C21:L21)
A27: Terminal growth | B27: =Assumptions!$C$13
A28: Terminal-year FCF | B28: =L19*(1+B27)
A29: Gordon terminal value | B29: =B28/(Assumptions!$B$2-B27)
A30: Cap terminal value | B30: =Assumptions!$C$14*L19
A31: Terminal value used | B31: =MAX(0,MIN(B29,B30))
A32: Implied exit multiple | B32: =B31/L19
A33: PV of terminal value | B33: =B31*L20
A34: Enterprise value | B34: =B26+B33
A35: less net debt | B35: =-Assumptions!$B$4
A36: add non-operating assets | B36: =Assumptions!$C$15
A37: Equity value | B37: =B34+B35+B36
A38: Shares on issue (m) | B38: =Assumptions!$B$5
A39: VALUE PER SHARE | B39: =B37/B38
A40: Upside vs current price | B40: =B39/Assumptions!$B$6-1
A41: Implied EV / clean FY26 EBITDA | B41: =B34/Assumptions!$B$8
A42: Implied price / book | B42: =B39/Assumptions!$B$7
...

Sheet DCF_Bull
A1: SKC.NZ DCF - BULL case
A2: All rows are formulas except the blue driver rows 5, 7, 9, 14 and the FY0 revenue in B6.
A3: Year | B3: FY2026A | C3: FY2027E | D3: FY2028E | E3: FY2029E | F3: FY2030E | G3: FY2031E | H3: FY2032E | I3: FY2033E | J3: FY2034E | K3: FY2035E | L3: FY2036E
A4: Year index | B4: 0 | C4: 1 | D4: 2 | E4: 3 | F4: 4 | G4: 5 | H4: 6 | I4: 7 | J4: 8 | K4: 9 | L4: 10
A5: Revenue growth YoY | C5: 0.03 | D5: 0.045 | E5: 0.045 | F5: 0.04 | G5: 0.035 | H5: 0.03 | I5: 0.03 | J5: 0.025 | K5: 0.025 | L5: 0.025
A6: Revenue | B6: 813.651 | C6: =B6*(1+C5) | D6: =C6*(1+D5) | E6: =D6*(1+E5) | F6: =E6*(1+F5) | G6: =F6*(1+G5) | H6: =G6*(1+H5) | I6: =H6*(1+I5) | J6: =I6*(1+J5) | ... L6: =K6*(1+L5)
A7: Adj EBITDA margin | C7: 0.21 | D7: 0.24 | E7: 0.265 | F7: 0.275 | G7: 0.28 | H7: 0.28 | I7: 0.28 | J7: 0.28 | K7: 0.28 | L7: 0.28
A8: Adjusted EBITDA | C8: =C6*C7 | D8: =D6*D7 | E8: =E6*E7 | F8: =F6*F7 | G8: =G6*G7 | H8: =H6*H7 | I8: =I6*I7 | J8: =J6*J7 | ... L8: =L6*L7
A9: SBC % of revenue | C9: 0.001 | D9: 0.001 | E9: 0.001 | F9: 0.001 | G9: 0.001 | H9: 0.001 | I9: 0.001 | J9: 0.001 | K9: 0.001 | L9: 0.001
A10: SBC (negative) | C10: =-C6*C9 | D10: =-D6*D9 | E10: =-E6*E9 | F10: =-F6*F9 | G10: =-G6*G9 | H10: =-H6*H9 | I10: =-I6*I9 | J10: =-J6*J9 | ... L10: =-L6*L9
A11: Owner EBITDA | C11: =C8+C10 | D11: =D8+D10 | E11: =E8+E10 | F11: =F8+F10 | G11: =G8+G10 | H11: =H8+H10 | I11: =I8+I10 | J11: =J8+J10 | ... L11: =L8+L10
A12: D&A (negative) | C12: =-C6*Assumptions!$B$3 | D12: =-D6*Assumptions!$B$3 | E12: =-E6*Assumptions!$B$3 | F12: =-F6*Assumptions!$B$3 | G12: =-G6*Assumptions!$B$3 | H12: =-H6*Assumptions!$B$3 | I12: =-I6*Assumptions!$B$3 | J12: =-J6*Assumptions!$B$3 | ... L12: =-L6*Assumptions!$B$3
A13: EBIT | C13: =C11+C12 | D13: =D11+D12 | E13: =E11+E12 | F13: =F11+F12 | G13: =G11+G12 | H13: =H11+H12 | I13: =I11+I12 | J13: =J11+J12 | ... L13: =L11+L12
A14: Cash tax rate | C14: 0.08 | D14: 0.16 | E14: 0.22 | F14: 0.28 | G14: 0.28 | H14: 0.28 | I14: 0.28 | J14: 0.28 | K14: 0.28 | L14: 0.28
A15: NOPAT | C15: =C13*(1-C14) | D15: =D13*(1-D14) | E15: =E13*(1-E14) | F15: =F13*(1-F14) | G15: =G13*(1-G14) | H15: =H13*(1-H14) | I15: =I13*(1-I14) | J15: =J13*(1-J14) | ... L15: =L13*(1-L14)
A16: add back D&A | C16: =-C12 | D16: =-D12 | E16: =-E12 | F16: =-F12 | G16: =-G12 | H16: =-H12 | I16: =-I12 | J16: =-J12 | ... L16: =-L12
A17: less capex | C17: =-C6*0.105 | D17: =-D6*0.1 | E17: =-E6*0.095 | F17: =-F6*0.095 | G17: =-G6*0.095 | H17: =-H6*0.095 | I17: =-I6*0.095 | J17: =-J6*0.095 | K17: =-K6*0.095 | L17: =-L6*0.095
A18: Working capital | C18: 0 | D18: 0 | E18: 0 | F18: 0 | G18: 0 | H18: 0 | I18: 0 | J18: 0 | K18: 0 | L18: 0
A19: UNLEVERED OWNER FCF | C19: =C15+C16+C17+C18 | D19: =D15+D16+D17+D18 | E19: =E15+E16+E17+E18 | F19: =F15+F16+F17+F18 | G19: =G15+G16+G17+G18 | H19: =H15+H16+H17+H18 | I19: =I15+I16+I17+I18 | J19: =J15+J16+J17+J18 | ... L19: =L15+L16+L17+L18
A20: Discount factor | C20: =1/(1+Assumptions!$B$2)^C4 | D20: =1/(1+Assumptions!$B$2)^D4 | E20: =1/(1+Assumptions!$B$2)^E4 | F20: =1/(1+Assumptions!$B$2)^F4 | G20: =1/(1+Assumptions!$B$2)^G4 | H20: =1/(1+Assumptions!$B$2)^H4 | I20: =1/(1+Assumptions!$B$2)^I4 | J20: =1/(1+Assumptions!$B$2)^J4 | ... L20: =1/(1+Assumptions!$B$2)^L4
A21: PV of FCF | C21: =C19*C20 | D21: =D19*D20 | E21: =E19*E20 | F21: =F19*F20 | G21: =G19*G20 | H21: =H19*H20 | I21: =I19*I20 | J21: =J19*J20 | ... L21: =L19*L20
A23: Memo: FCF before SBC | C23: =C19-C10 | D23: =D19-D10 | E23: =E19-E10 | F23: =F19-F10 | G23: =G19-G10 | H23: =H19-H10 | I23: =I19-I10 | J23: =J19-J10 | ... L23: =L19-L10
A24: Memo: owner-FCF margin | C24: =C19/C6 | D24: =D19/D6 | E24: =E19/E6 | F24: =F19/F6 | G24: =G19/G6 | H24: =H19/H6 | I24: =I19/I6 | J24: =J19/J6 | ... L24: =L19/L6
A26: Sum of PV of FCF | B26: =SUM(C21:L21)
A27: Terminal growth | B27: =Assumptions!$D$13
A28: Terminal-year FCF | B28: =L19*(1+B27)
A29: Gordon terminal value | B29: =B28/(Assumptions!$B$2-B27)
A30: Cap terminal value | B30: =Assumptions!$D$14*L19
A31: Terminal value used | B31: =MAX(0,MIN(B29,B30))
A32: Implied exit multiple | B32: =B31/L19
A33: PV of terminal value | B33: =B31*L20
A34: Enterprise value | B34: =B26+B33
A35: less net debt | B35: =-Assumptions!$B$4
A36: add non-operating assets | B36: =Assumptions!$D$15
A37: Equity value | B37: =B34+B35+B36
A38: Shares on issue (m) | B38: =Assumptions!$B$5
A39: VALUE PER SHARE | B39: =B37/B38
A40: Upside vs current price | B40: =B39/Assumptions!$B$6-1
A41: Implied EV / clean FY26 EBITDA | B41: =B34/Assumptions!$B$8
A42: Implied price / book | B42: =B39/Assumptions!$B$7
...

Sheet FCF_Quality
A1: Reported FCF reconciled to owner FCF (NZD m)
B2: FY2016 | C2: FY2017 | D2: FY2018 | E2: FY2019 | F2: FY2020 | G2: FY2021 | H2: FY2022 | I2: FY2023 | J2: FY2024 | K2: FY2025 | L2: FY2026
A3: Operating cash flow | B3: 305.2 | C3: 279.5 | D3: 289.1 | E3: 252.3 | F3: 120.2 | G3: 288.2 | H3: 91.1 | I3: 280.1 | J3: 203.6 | K3: 45.2 | L3: 121.676
A4: less capex | B4: -156.5 | C4: -158.6 | D4: -215.1 | E4: -332.8 | F4: -345.1 | G4: -177.5 | H4: -111.5 | I4: -262.9 | J4: -310.7 | K4: -163.8 | L4: -113.627
A5: Free cash flow (company definition) | B5: =B3+B4 | C5: =C3+C4 | D5: =D3+D4 | E5: =E3+E4 | F5: =F3+F4 | G5: =G3+G4 | H5: =H3+H4 | I5: =I3+I4 | ... L5: =L3+L4
A6: less SBC incl equity-award taxes | B6: 0 | C6: 0 | D6: 0 | E6: 0 | F6: 0 | G6: 0 | H6: 0 | I6: 0 | J6: 0 | K6: -1.247 | L6: -0.76
A7: less interest income (not stripped - net DEBT) | B7: 0 | C7: 0 | D7: 0 | E7: 0 | F7: 0 | G7: 0 | H7: 0 | I7: 0 | J7: 0 | K7: 0 | L7: 0
A8: OWNER FCF | B8: =B5+B6+B7 | C8: =C5+C6+C7 | D8: =D5+D6+D7 | E8: =E5+E6+E7 | F8: =F5+F6+F7 | G8: =G5+G6+G7 | H8: =H5+H6+H7 | I8: =I5+I6+I7 | ... L8: =L5+L6+L7
A10: Memo: SkyCity reports interest paid in FINANCING, so operating cash flow is a PRE-INTEREST figure. FY2026 interest paid was 32.326 plus 8.212 on leases. The DCF is unlevered to match: interest is excluded from the flows and debt is deducted in the bridge.
A11: Memo: FCF was NEGATIVE in FY2019, FY2020, FY2022, FY2024 and FY2025, so no FCF CAGR can be computed. FY2026 FCF of 8.049 is only marginally positive.
A12: Memo: FY2026 cash tax is abnormal. Pre-tax was a LOSS of 12.071 and a 30.304 tax BENEFIT produced the positive NPAT of 18.233. The model ramps the cash tax rate to 28% by year 4.
A13: Memo: SBC is immaterial (0.760 in FY2026, 0.09% of revenue), so the house and street bases coincide.

Sheet Valuation
A1: Scenario summary
B2: BEAR | C2: BASE | D2: BULL
A3: Value per share | B3: =DCF_Bear!$B$39 | C3: =DCF_Base!$B$39 | D3: =DCF_Bull!$B$39
A4: Upside vs price | B4: =DCF_Bear!$B$40 | C4: =DCF_Base!$B$40 | D4: =DCF_Bull!$B$40
A5: Implied EV/clean EBITDA | B5: =DCF_Bear!$B$41 | C5: =DCF_Base!$B$41 | D5: =DCF_Bull!$B$41
A6: Implied P/B | B6: =DCF_Bear!$B$42 | C6: =DCF_Base!$B$42 | D6: =DCF_Bull!$B$42
A7: Street value per share | B7: =DCF_Bear!$B$44 | C7: =DCF_Base!$B$44 | D7: =DCF_Bull!$B$44
A8: Probability weight | B8: =Assumptions!B16 | C8: =Assumptions!C16 | D8: =Assumptions!D16
A10: PROBABILITY-WEIGHTED VALUE | B10: =SUMPRODUCT(B3:D3,B8:D8)
A11: Current price | B11: =Assumptions!$B$6
A12: Upside vs weighted value | B12: =B10/B11-1
A13: Margin of safety | B13: =1-B11/B10
A14: Band position (house vs street) | B14: n/a - SBC immaterial, house and street coincide
A16: 15% hurdle entry price
B17: BEAR | C17: BASE | D17: BULL
A18: Entry price at 15% hurdle | B18: =(SUMPRODUCT(DCF_Bear!C19:L19,1/(1.15)^DCF_Bear!C4:L4)+DCF_Bear!B31/1.15^10-Assumptions!$B$4+Assumptions!B15)/Assumptions!$B$5 | C18: =(SUMPRODUCT(DCF_Base!C19:L19,1/(1.15)^DCF_Base!C4:L4)+DCF_Base!B31/1.15^10-Assumptions!$B$4+Assumptions!C15)/Assumptions!$B$5 | D18: =(SUMPRODUCT(DCF_Bull!C19:L19,1/(1.15)^DCF_Bull!C4:L4)+DCF_Bull!B31/1.15^10-Assumptions!$B$4+Assumptions!D15)/Assumptions!$B$5
A19: WEIGHTED ENTRY PRICE | B19: =SUMPRODUCT(B18:D18,B8:D8)
A21: Required-return table (base case)
A22: Required return | B22: 0.09 | C22: 0.1 | D22: 0.11 | E22: 0.115 | F22: 0.12 | G22: 0.15
A23: Value per share | B23: =(SUMPRODUCT(DCF_Base!C19:L19,1/(1+0.09)^DCF_Base!C4:L4)+MAX(0,MIN(DCF_Base!L19*(1+DCF_Base!B27)/(0.09-DCF_Base!B27),DCF_Base!B30))/(1+0.09)^10-Assumptions!$B$4+Assumptions!C15)/Assumptions!$B$5 | C23: =(SUMPRODUCT(DCF_Base!C19:L19,1/(1+0.1)^DCF_Base!C4:L4)+MAX(0,MIN(DCF_Base!L19*(1+DCF_Base!B27)/(0.1-DCF_Base!B27),DCF_Base!B30))/(1+0.1)^10-Assumptions!$B$4+Assumptions!C15)/Assumptions!$B$5 | D23: =(SUMPRODUCT(DCF_Base!C19:L19,1/(1+0.11)^DCF_Base!C4:L4)+MAX(0,MIN(DCF_Base!L19*(1+DCF_Base!B27)/(0.11-DCF_Base!B27),DCF_Base!B30))/(1+0.11)^10-Assumptions!$B$4+Assumptions!C15)/Assumptions!$B$5 | E23: =(SUMPRODUCT(DCF_Base!C19:L19,1/(1+0.115)^DCF_Base!C4:L4)+MAX(0,MIN(DCF_Base!L19*(1+DCF_Base!B27)/(0.115-DCF_Base!B27),DCF_Base!B30))/(1+0.115)^10-Assumptions!$B$4+Assumptions!C15)/Assumptions!$B$5 | F23: =(SUMPRODUCT(DCF_Base!C19:L19,1/(1+0.12)^DCF_Base!C4:L4)+MAX(0,MIN(DCF_Base!L19*(1+DCF_Base!B27)/(0.12-DCF_Base!B27),DCF_Base!B30))/(1+0.12)^10-Assumptions!$B$4+Assumptions!C15)/Assumptions!$B$5 | G23: =(SUMPRODUCT(DCF_Base!C19:L19,1/(1+0.15)^DCF_Base!C4:L4)+MAX(0,MIN(DCF_Base!L19*(1+DCF_Base!B27)/(0.15-DCF_Base!B27),DCF_Base!B30))/(1+0.15)^10-Assumptions!$B$4+Assumptions!C15)/Assumptions!$B$5
A25: Sensitivity: WACC (rows) x terminal growth (cols), base case
B26: 0.015 | C26: 0.02 | D26: 0.025 | E26: 0.03 | F26: 0.035
A27: 0.095 | B27: =IF(0.095<=0.015,"n/a",(SUMPRODUCT(DCF_Base!C19:L19,1/(1+0.095)^DCF_Base!C4:L4)+MAX(0,MIN(DCF_Base!L19*(1+0.015)/(0.095-0.015),DCF_Base!B30))/(1+0.095)^10-Assumptions!$B$4+Assumptions!C15)/Assumptions!$B$5) | C27: =IF(0.095<=0.02,"n/a",(SUMPRODUCT(DCF_Base!C19:L19,1/(1+0.095)^DCF_Base!C4:L4)+MAX(0,MIN(DCF_Base!L19*(1+0.02)/(0.095-0.02),DCF_Base!B30))/(1+0.095)^10-Assumptions!$B$4+Assumptions!C15)/Assumptions!$B$5) | D27: =IF(0.095<=0.025,"n/a",(SUMPRODUCT(DCF_Base!C19:L19,1/(1+0.095)^DCF_Base!C4:L4)+MAX(0,MIN(DCF_Base!L19*(1+0.025)/(0.095-0.025),DCF_Base!B30))/(1+0.095)^10-Assumptions!$B$4+Assumptions!C15)/Assumptions!$B$5) | E27: =IF(0.095<=0.03,"n/a",(SUMPRODUCT(DCF_Base!C19:L19,1/(1+0.095)^DCF_Base!C4:L4)+MAX(0,MIN(DCF_Base!L19*(1+0.03)/(0.095-0.03),DCF_Base!B30))/(1+0.095)^10-Assumptions!$B$4+Assumptions!C15)/Assumptions!$B$5) | F27: =IF(0.095<=0.035,"n/a",(SUMPRODUCT(DCF_Base!C19:L19,1/(1+0.095)^DCF_Base!C4:L4)+MAX(0,MIN(DCF_Base!L19*(1+0.035)/(0.095-0.035),DCF_Base!B30))/(1+0.095)^10-Assumptions!$B$4+Assumptions!C15)/Assumptions!$B$5)
A28: 0.105 | B28: =IF(0.105<=0.015,"n/a",(SUMPRODUCT(DCF_Base!C19:L19,1/(1+0.105)^DCF_Base!C4:L4)+MAX(0,MIN(DCF_Base!L19*(1+0.015)/(0.105-0.015),DCF_Base!B30))/(1+0.105)^10-Assumptions!$B$4+Assumptions!C15)/Assumptions!$B$5) | C28: =IF(0.105<=0.02,"n/a",(SUMPRODUCT(DCF_Base!C19:L19,1/(1+0.105)^DCF_Base!C4:L4)+MAX(0,MIN(DCF_Base!L19*(1+0.02)/(0.105-0.02),DCF_Base!B30))/(1+0.105)^10-Assumptions!$B$4+Assumptions!C15)/Assumptions!$B$5) | D28: =IF(0.105<=0.025,"n/a",(SUMPRODUCT(DCF_Base!C19:L19,1/(1+0.105)^DCF_Base!C4:L4)+MAX(0,MIN(DCF_Base!L19*(1+0.025)/(0.105-0.025),DCF_Base!B30))/(1+0.105)^10-Assumptions!$B$4+Assumptions!C15)/Assumptions!$B$5) | E28: =IF(0.105<=0.03,"n/a",(SUMPRODUCT(DCF_Base!C19:L19,1/(1+0.105)^DCF_Base!C4:L4)+MAX(0,MIN(DCF_Base!L19*(1+0.03)/(0.105-0.03),DCF_Base!B30))/(1+0.105)^10-Assumptions!$B$4+Assumptions!C15)/Assumptions!$B$5) | F28: =IF(0.105<=0.035,"n/a",(SUMPRODUCT(DCF_Base!C19:L19,1/(1+0.105)^DCF_Base!C4:L4)+MAX(0,MIN(DCF_Base!L19*(1+0.035)/(0.105-0.035),DCF_Base!B30))/(1+0.105)^10-Assumptions!$B$4+Assumptions!C15)/Assumptions!$B$5)
A29: 0.115 | B29: =IF(0.115<=0.015,"n/a",(SUMPRODUCT(DCF_Base!C19:L19,1/(1+0.115)^DCF_Base!C4:L4)+MAX(0,MIN(DCF_Base!L19*(1+0.015)/(0.115-0.015),DCF_Base!B30))/(1+0.115)^10-Assumptions!$B$4+Assumptions!C15)/Assumptions!$B$5) | C29: =IF(0.115<=0.02,"n/a",(SUMPRODUCT(DCF_Base!C19:L19,1/(1+0.115)^DCF_Base!C4:L4)+MAX(0,MIN(DCF_Base!L19*(1+0.02)/(0.115-0.02),DCF_Base!B30))/(1+0.115)^10-Assumptions!$B$4+Assumptions!C15)/Assumptions!$B$5) | D29: =IF(0.115<=0.025,"n/a",(SUMPRODUCT(DCF_Base!C19:L19,1/(1+0.115)^DCF_Base!C4:L4)+MAX(0,MIN(DCF_Base!L19*(1+0.025)/(0.115-0.025),DCF_Base!B30))/(1+0.115)^10-Assumptions!$B$4+Assumptions!C15)/Assumptions!$B$5) | E29: =IF(0.115<=0.03,"n/a",(SUMPRODUCT(DCF_Base!C19:L19,1/(1+0.115)^DCF_Base!C4:L4)+MAX(0,MIN(DCF_Base!L19*(1+0.03)/(0.115-0.03),DCF_Base!B30))/(1+0.115)^10-Assumptions!$B$4+Assumptions!C15)/Assumptions!$B$5) | F29: =IF(0.115<=0.035,"n/a",(SUMPRODUCT(DCF_Base!C19:L19,1/(1+0.115)^DCF_Base!C4:L4)+MAX(0,MIN(DCF_Base!L19*(1+0.035)/(0.115-0.035),DCF_Base!B30))/(1+0.115)^10-Assumptions!$B$4+Assumptions!C15)/Assumptions!$B$5)
A30: 0.125 | B30: =IF(0.125<=0.015,"n/a",(SUMPRODUCT(DCF_Base!C19:L19,1/(1+0.125)^DCF_Base!C4:L4)+MAX(0,MIN(DCF_Base!L19*(1+0.015)/(0.125-0.015),DCF_Base!B30))/(1+0.125)^10-Assumptions!$B$4+Assumptions!C15)/Assumptions!$B$5) | C30: =IF(0.125<=0.02,"n/a",(SUMPRODUCT(DCF_Base!C19:L19,1/(1+0.125)^DCF_Base!C4:L4)+MAX(0,MIN(DCF_Base!L19*(1+0.02)/(0.125-0.02),DCF_Base!B30))/(1+0.125)^10-Assumptions!$B$4+Assumptions!C15)/Assumptions!$B$5) | D30: =IF(0.125<=0.025,"n/a",(SUMPRODUCT(DCF_Base!C19:L19,1/(1+0.125)^DCF_Base!C4:L4)+MAX(0,MIN(DCF_Base!L19*(1+0.025)/(0.125-0.025),DCF_Base!B30))/(1+0.125)^10-Assumptions!$B$4+Assumptions!C15)/Assumptions!$B$5) | E30: =IF(0.125<=0.03,"n/a",(SUMPRODUCT(DCF_Base!C19:L19,1/(1+0.125)^DCF_Base!C4:L4)+MAX(0,MIN(DCF_Base!L19*(1+0.03)/(0.125-0.03),DCF_Base!B30))/(1+0.125)^10-Assumptions!$B$4+Assumptions!C15)/Assumptions!$B$5) | F30: =IF(0.125<=0.035,"n/a",(SUMPRODUCT(DCF_Base!C19:L19,1/(1+0.125)^DCF_Base!C4:L4)+MAX(0,MIN(DCF_Base!L19*(1+0.035)/(0.125-0.035),DCF_Base!B30))/(1+0.125)^10-Assumptions!$B$4+Assumptions!C15)/Assumptions!$B$5)
A31: 0.135 | B31: =IF(0.135<=0.015,"n/a",(SUMPRODUCT(DCF_Base!C19:L19,1/(1+0.135)^DCF_Base!C4:L4)+MAX(0,MIN(DCF_Base!L19*(1+0.015)/(0.135-0.015),DCF_Base!B30))/(1+0.135)^10-Assumptions!$B$4+Assumptions!C15)/Assumptions!$B$5) | C31: =IF(0.135<=0.02,"n/a",(SUMPRODUCT(DCF_Base!C19:L19,1/(1+0.135)^DCF_Base!C4:L4)+MAX(0,MIN(DCF_Base!L19*(1+0.02)/(0.135-0.02),DCF_Base!B30))/(1+0.135)^10-Assumptions!$B$4+Assumptions!C15)/Assumptions!$B$5) | D31: =IF(0.135<=0.025,"n/a",(SUMPRODUCT(DCF_Base!C19:L19,1/(1+0.135)^DCF_Base!C4:L4)+MAX(0,MIN(DCF_Base!L19*(1+0.025)/(0.135-0.025),DCF_Base!B30))/(1+0.135)^10-Assumptions!$B$4+Assumptions!C15)/Assumptions!$B$5) | E31: =IF(0.135<=0.03,"n/a",(SUMPRODUCT(DCF_Base!C19:L19,1/(1+0.135)^DCF_Base!C4:L4)+MAX(0,MIN(DCF_Base!L19*(1+0.03)/(0.135-0.03),DCF_Base!B30))/(1+0.135)^10-Assumptions!$B$4+Assumptions!C15)/Assumptions!$B$5) | F31: =IF(0.135<=0.035,"n/a",(SUMPRODUCT(DCF_Base!C19:L19,1/(1+0.135)^DCF_Base!C4:L4)+MAX(0,MIN(DCF_Base!L19*(1+0.035)/(0.135-0.035),DCF_Base!B30))/(1+0.135)^10-Assumptions!$B$4+Assumptions!C15)/Assumptions!$B$5)

Sheet Sanity_Check
A1: Step 8c sanity check - historical multiples vs implied multiples
A2: ran | B2: True
A3: passed | B3: False
A4: method | B4: Ten years of Yahoo monthly closes aligned to the 30 June fiscal year end, converted to EV using each year's reported net debt and share count, versus implied multiples at the base-case IV.
A5: primary_anchors | B5: EV/EBITDA and P/B
A6: why_not_pe | B6: P/E is deliberately EXCLUDED as an anchor. FY2026 pre-tax was a LOSS of 12.071 and reported NPAT of 18.233 exists only because of a 30.304 tax benefit, so any implied P/E is an artefact of a distorted denominator rather than information about value.
A8: Historical (10 years, June-aligned)
A9: ev_ebitda_10yr_mean | B9: 11.75
A10: ev_ebitda_10yr_median | B10: 10.18
A11: ev_ebitda_ex_fy26_median | B11: 9.76
A12: ev_ebitda_trough | B12: 6.43
A13: ev_ebitda_trough_year | B13: FY2020 (COVID)
A14: pb_10yr_mean | B14: 1.41
A15: pb_10yr_median | B15: 1.24
A16: pb_min | B16: 0.42
A18: Implied at base-case IV
A19: ev_ebitda_on_clean_fy26 | B19: 6.13
A20: ev_ebitda_on_company_underlying | B20: 5.15
A21: price_to_book | B21: 0.25
A23: Market reference
A24: ev_ebitda_at_current_price | B24: 9
A25: pb_at_current_price | B25: 0.48
A26: ev_ebitda_at_070_bid | B26: 9.22
A27: ev_ebitda_at_075_bid | B27: 9.58
A29: Trip reasons
B30: Base-case implied EV/EBITDA of 6.13x sits BELOW the stock's own decade trough of 6.43x (FY2020 COVID) and far below the 9.76x ex-FY26 median.
B31: Base-case implied P/B of 0.25x is below the 0.42x all-time low set this year.
B32: Base-case IV of 0.355 is roughly half the 0.70/0.75 at which two independent sophisticated buyers bid.
A34: diagnosis | B34: Two distinct causes, one a genuine model error and one a real economic conclusion. (1) ERROR, now fixed: the DCF valued only operating cash flows while deducting GROSS net debt, silently discarding the non-operating assets being sold to retire that debt. Under section 7(d) an asset producing no income inside the flows must be credited in the bridge, or its value is simply lost. (2) NOT an error: after fixing that, the model still implies a multiple well below history, and testing shows that even at an 8% WACC with 3% terminal growth - rates that would ignore every documented regulatory, leverage and liquidity risk - the historic 9.76x is unreachable on these cash flows. The historic multiple was earned by a monopoly with growth, dividends, an investment-grade balance sheet and no regulatory scandal; today's SkyCity has the monopoly but none of the rest. A structurally DERATED multiple is the correct conclusion, not a modelling artefact.
A35: fix_applied | B35: Added a scenario-differentiated non-operating asset bridge (base 91.7m: the 74.056m unconditional property sale at full value plus remaining investment property at a 15% haircut; bear 60m; bull 200m reflecting fuller delivery of the 275-300m monetisation target). Raised base terminal growth from 2.0% to 2.5% (NZ long-run inflation plus modest real pricing power on an inflation-linked monopoly asset) and the terminal FCF cap from 12x to 14x. Together these lift base IV from 0.251 to 0.355 and implied EV/EBITDA from 5.97x to 6.13x. The residual gap to history is retained deliberately and is the model's central finding.
A36: residual_disagreement_is_the_thesis | B36: The model says 0.355, the market says 0.67 and two bidders said 0.70-0.75. The gap is almost entirely the terminal multiple: the bids underwrite a return to a ~9.5x historic multiple, this model does not. A buyer of SKC.NZ at 0.67 is paying for a multiple recovery and for balance-sheet value, not for the discounted operating cash flows.
