Workbook

Sheet DCF Model
A1: ATM.NZ (The a2 Milk Company) DCF Valuation Model
A2: Gray cells are INPUTS - adjust to see valuation change. FY ends 30 June.
A4: KEY INPUTS
A5: Current Stock Price (NZD) | B5: 8.25
A6: Shares Outstanding (M) | B6: 729
A7: Cash & Term Deposits (M) | B7: 896.9
A8: Total Debt (M) | B8: 0
A9: Less: Pending Special Dividend (M) | B9: 300
A10: Net Debt / (Net Cash) (M) | B10: =B8-B7+B9 -> 0
A11: FY2025 Reported FCF (M) | B11: 197.5
A12: Less: Stock-Based Comp (M) | B12: 13.54
A13: Less: Interest Income (M) | B13: 45.5
A14: FY2025 Owner FCF (M) | B14: =B11-B12-B13 -> 0
A15: Annual Share Growth (dilution) | B15: 0
A17: WACC (Base) | B17: 0.105
A18: Terminal Growth Rate (Base) | B18: 0.0225
A19: FY2025 Continuing-Ops Revenue base (M) | B19: 1757
A21: GROWTH & MARGIN ASSUMPTIONS (BASE CASE)
B22: FY2027 | C22: FY2028 | D22: FY2029 | E22: FY2030 | F22: FY2031
A23: Revenue Growth % | B23: 0.145 | C23: 0.1 | D23: 0.07 | E23: 0.05 | F23: 0.035
A24: Adj. EBITDA Margin % | B24: 0.158 | C24: 0.165 | D24: 0.17 | E24: 0.172 | F24: 0.173
A25: SBC % of Revenue | B25: 0.007 | C25: 0.007 | D25: 0.0065 | E25: 0.0065 | F25: 0.006
A26: D&A % of Revenue | B26: 0.016 | C26: 0.017 | D26: 0.016 | E26: 0.015 | F26: 0.0145
A27: CapEx % of Revenue | B27: 0.03 | C27: 0.028 | D27: 0.024 | E27: 0.022 | F27: 0.021
A28: Cash Tax Rate % | B28: 0.24 | C28: 0.26 | D28: 0.28 | E28: 0.28 | F28: 0.28
A29: Working Capital Capture % (of rev increase) | B29: 0.15
A31: PROJECTIONS (COMPONENT BUILD)
B32: FY2027 | C32: FY2028 | D32: FY2029 | E32: FY2030 | F32: FY2031
A33: Revenue | B33: =$B$19*(1+B23) -> 0 | C33: =B33*(1+C23) -> 0 | D33: =C33*(1+D23) -> 0 | E33: =D33*(1+E23) -> 0 | F33: =E33*(1+F23) -> 0
A34: Adj. EBITDA | B34: =B33*B24 -> 0 | C34: =C33*C24 -> 0 | D34: =D33*D24 -> 0 | E34: =E33*E24 -> 0 | F34: =F33*F24 -> 0
A35: Less: SBC | B35: =B33*B25 -> 0 | C35: =C33*C25 -> 0 | D35: =D33*D25 -> 0 | E35: =E33*E25 -> 0 | F35: =F33*F25 -> 0
A36: Owner EBITDA | B36: =B34-B35 -> 0 | C36: =C34-C35 -> 0 | D36: =D34-D35 -> 0 | E36: =E34-E35 -> 0 | F36: =F34-F35 -> 0
A37: Less: D&A | B37: =B33*B26 -> 0 | C37: =C33*C26 -> 0 | D37: =D33*D26 -> 0 | E37: =E33*E26 -> 0 | F37: =F33*F26 -> 0
A38: EBIT | B38: =B36-B37 -> 0 | C38: =C36-C37 -> 0 | D38: =D36-D37 -> 0 | E38: =E36-E37 -> 0 | F38: =F36-F37 -> 0
A39: NOPAT | B39: =B38*(1-B28) -> 0 | C39: =C38*(1-C28) -> 0 | D39: =D38*(1-D28) -> 0 | E39: =E38*(1-E28) -> 0 | F39: =F38*(1-F28) -> 0
A40: Add back: D&A | B40: =B37 -> 0 | C40: =C37 -> 0 | D40: =D37 -> 0 | E40: =E37 -> 0 | F40: =F37 -> 0
A41: Less: CapEx | B41: =B33*B27 -> 0 | C41: =C33*C27 -> 0 | D41: =D33*D27 -> 0 | E41: =E33*E27 -> 0 | F41: =F33*F27 -> 0
A42: Less: Working Capital | B42: =$B$29*(B33-$B$19) -> 0 | C42: =$B$29*(C33-B33) -> 0 | D42: =$B$29*(D33-C33) -> 0 | E42: =$B$29*(E33-D33) -> 0 | F42: =$B$29*(F33-E33) -> 0
A43: Owner FCF | B43: =B39+B40-B41-B42 -> 0 | C43: =C39+C40-C41-C42 -> 0 | D43: =D39+D40-D41-D42 -> 0 | E43: =E39+E40-E41-E42 -> 0 | F43: =F39+F40-F41-F42 -> 0
A44: Owner FCF Margin % | B44: =B43/B33 -> 0 | C44: =C43/C33 -> 0 | D44: =D43/D33 -> 0 | E44: =E43/E33 -> 0 | F44: =F43/F33 -> 0
...

Sheet Sensitivity
A1: Sensitivity Analysis
A2: Intrinsic Value by WACC & Terminal Growth (Base Case)
A4: WACC \ Term G | B4: 0.0125 | C4: 0.0175 | D4: 0.0225 | E4: 0.0275 | F4: 0.0325
A5: 0.085 | B5: =('DCF Model'!$F$43*(1+0.0125)/(0.085-0.0125))/(1+0.085)^5+'DCF Model'!$B$49 -> 0 | C5: =('DCF Model'!$F$43*(1+0.0175)/(0.085-0.0175))/(1+0.085)^5+'DCF Model'!$B$49 -> 0 | D5: =('DCF Model'!$F$43*(1+0.0225)/(0.085-0.0225))/(1+0.085)^5+'DCF Model'!$B$49 -> 0 | E5: =('DCF Model'!$F$43*(1+0.0275)/(0.085-0.0275))/(1+0.085)^5+'DCF Model'!$B$49 -> 0 | F5: =('DCF Model'!$F$43*(1+0.0325)/(0.085-0.0325))/(1+0.085)^5+'DCF Model'!$B$49 -> 0
A6: 0.095 | B6: =('DCF Model'!$F$43*(1+0.0125)/(0.095-0.0125))/(1+0.095)^5+'DCF Model'!$B$49 -> 0 | C6: =('DCF Model'!$F$43*(1+0.0175)/(0.095-0.0175))/(1+0.095)^5+'DCF Model'!$B$49 -> 0 | D6: =('DCF Model'!$F$43*(1+0.0225)/(0.095-0.0225))/(1+0.095)^5+'DCF Model'!$B$49 -> 0 | E6: =('DCF Model'!$F$43*(1+0.0275)/(0.095-0.0275))/(1+0.095)^5+'DCF Model'!$B$49 -> 0 | F6: =('DCF Model'!$F$43*(1+0.0325)/(0.095-0.0325))/(1+0.095)^5+'DCF Model'!$B$49 -> 0
A7: 0.105 | B7: =('DCF Model'!$F$43*(1+0.0125)/(0.105-0.0125))/(1+0.105)^5+'DCF Model'!$B$49 -> 0 | C7: =('DCF Model'!$F$43*(1+0.0175)/(0.105-0.0175))/(1+0.105)^5+'DCF Model'!$B$49 -> 0 | D7: =('DCF Model'!$F$43*(1+0.0225)/(0.105-0.0225))/(1+0.105)^5+'DCF Model'!$B$49 -> 0 | E7: =('DCF Model'!$F$43*(1+0.0275)/(0.105-0.0275))/(1+0.105)^5+'DCF Model'!$B$49 -> 0 | F7: =('DCF Model'!$F$43*(1+0.0325)/(0.105-0.0325))/(1+0.105)^5+'DCF Model'!$B$49 -> 0
A8: 0.115 | B8: =('DCF Model'!$F$43*(1+0.0125)/(0.115-0.0125))/(1+0.115)^5+'DCF Model'!$B$49 -> 0 | C8: =('DCF Model'!$F$43*(1+0.0175)/(0.115-0.0175))/(1+0.115)^5+'DCF Model'!$B$49 -> 0 | D8: =('DCF Model'!$F$43*(1+0.0225)/(0.115-0.0225))/(1+0.115)^5+'DCF Model'!$B$49 -> 0 | E8: =('DCF Model'!$F$43*(1+0.0275)/(0.115-0.0275))/(1+0.115)^5+'DCF Model'!$B$49 -> 0 | F8: =('DCF Model'!$F$43*(1+0.0325)/(0.115-0.0325))/(1+0.115)^5+'DCF Model'!$B$49 -> 0
A9: 0.125 | B9: =('DCF Model'!$F$43*(1+0.0125)/(0.125-0.0125))/(1+0.125)^5+'DCF Model'!$B$49 -> 0 | C9: =('DCF Model'!$F$43*(1+0.0175)/(0.125-0.0175))/(1+0.125)^5+'DCF Model'!$B$49 -> 0 | D9: =('DCF Model'!$F$43*(1+0.0225)/(0.125-0.0225))/(1+0.125)^5+'DCF Model'!$B$49 -> 0 | E9: =('DCF Model'!$F$43*(1+0.0275)/(0.125-0.0275))/(1+0.125)^5+'DCF Model'!$B$49 -> 0 | F9: =('DCF Model'!$F$43*(1+0.0325)/(0.125-0.0325))/(1+0.125)^5+'DCF Model'!$B$49 -> 0
A11: Note: terminal value uses fixed Year-5 Owner FCF and Sum of PV FCF from the Base
A12: case sheet (undiscounted PV of interim years is WACC-invariant here for simplicity;
A13: for full WACC-consistent re-discounting of interim years, use the JSON matrix values below).
A15: JSON-COMPUTED SENSITIVITY MATRIX (fully re-discounted, authoritative)
A16: WACC \ Term G | B16: 0.0125 | C16: 0.0175 | D16: 0.0225 | E16: 0.0275 | F16: 0.0325
A17: 0.085 | B17: 5.11 | C17: 5.36 | D17: 5.66 | E17: 6.01 | F17: 6.42
A18: 0.095 | B18: 4.56 | C18: 4.75 | D18: 4.96 | E18: 5.21 | F18: 5.5
A19: 0.105 | B19: 4.13 | C19: 4.28 | D19: 4.44 | E19: 4.62 | F19: 4.83
A20: 0.115 | B20: 3.79 | C20: 3.9 | D20: 4.03 | E20: 4.16 | F20: 4.32
A21: 0.125 | B21: 3.51 | C21: 3.6 | D21: 3.69 | E21: 3.8 | F21: 3.92

Sheet Historical
A1: Historical Growth Rates
A3: Metric | B3: 3-Year CAGR | C3: 5-Year CAGR
A4: Revenue | B4: 0.093 | C4: 0.019
A5: EPS | B5: 0.149 | C5: -0.118
A6: Equity | B6: 0.116 | C6: 0.048
A7: FCF (owner) | B7: 0.559
A9: Selected Growth Rate: | B9: 0.093
A10: Source: | B10: revenue_3yr_cagr (FY2023-FY2025, post-daigou-collapse recovery base)
A12: Divergence Warning:
A13: FY2020 (peak, pre-daigou-collapse) and FY2021-2022 (daigou/China-channel collapse trough, ~$200m inventory write-downs) are structural outliers excluded from all CAGR baselines per company guidance. 5-year revenue CAGR (1.9%, FY2020-2025) is distorted by starting at the pre-collapse peak; 3-year CAGR (9.3%, FY2023-2025) is the cleaner post-recovery trend and is used as the historical anchor, though the FY26 explicit forecast is guidance-driven (mid-double-digit %) rather than a mechanical CAGR extrapolation. Reported FCF 3yr CAGR (39.9%) is far above owner FCF 3yr CAGR (55.8% off a very depressed FY2023 base distorted by a $26.7m interest income spike and inventory rebuild) - neither is a reliable growth-rate input; revenue and EBITDA-margin components drive the projection instead. Equity CAGR is distorted by the FY25 dividend policy inception and pending special dividend and is not used as the growth driver.
A15: Notes:
A16: SBC is small for ATM.NZ (~0.6-1.6% of revenue historically, well below the FCF base) so SBC-driven dilution is not a material growth-rate distortion here, unlike SBC-heavy tech names. The dominant adjustment for ATM.NZ is the interest income strip: FY2025 interest income of $45.5m equals 23% of reported FCF ($197.5m) and would double-count the $896.9m cash pile if left inside FCF while cash is also added to EV.
A19: Historical Owner FCF Build (FY, NZD millions)
B21: FY2016 | C21: FY2017 | D21: FY2018 | E21: FY2019 | F21: FY2020 | G21: FY2021 | H21: FY2022 | I21: FY2023 | J21: FY2024 | K21: FY2025
A22: Reported FCF | B22: 20.3 | C22: 97.5 | D22: 226.3 | E22: 285.7 | F22: 420.2 | G22: 82.1 | H22: 198.6 | I22: 100.9 | J22: 235.2 | K22: 197.5
A23: Less: SBC | B23: 3.109 | C23: 2.528 | D23: 2.612 | E23: 8.184 | F23: 8.331 | G23: 1.835 | H23: 11.609 | I23: 17.132 | J23: 10.727 | K23: 13.545
A24: Less: Interest Income | B24: 0.502 | C24: 0.887 | D24: 2.369 | E24: 4.277 | F24: 6.129 | G24: 3.989 | H24: 6.569 | I24: 26.733 | J24: 40.396 | K24: 45.457
A25: Owner FCF | B25: =B22-B23-B24 -> 0 | C25: =C22-C23-C24 -> 0 | D25: =D22-D23-D24 -> 0 | E25: =E22-E23-E24 -> 0 | F25: =F22-F23-F24 -> 0 | G25: =G22-G23-G24 -> 0 | H25: =H22-H23-H24 -> 0 | I25: =I22-I23-I24 -> 0 | ... K25: =K22-K23-K24 -> 0
A26: Owner FCF Margin % | B26: =B25/352.502 -> 0 | C26: =C25/549.247 -> 0 | D26: =D25/922.354 -> 0 | E26: =E25/1304.336 -> 0 | F26: =F25/1730.696 -> 0 | G26: =G25/1205.034 -> 0 | H26: =H25/1443.74 -> 0 | I26: =I25/1591.088 -> 0 | J26: =J25/1673.323 -> 0 | K26: =K25/1899.273 -> 0

Sheet FCF Quality
A1: FCF Quality Reconciliation
A2: Reported FCF (company definition) reconciled to Owner FCF, FY2016-FY2025
B4: FY2016 | C4: FY2017 | D4: FY2018 | E4: FY2019 | F4: FY2020 | G4: FY2021 | H4: FY2022 | I4: FY2023 | J4: FY2024 | K4: FY2025
A5: Reported Revenue | B5: 352.502 | C5: 549.247 | D5: 922.354 | E5: 1304.336 | F5: 1730.696 | G5: 1205.034 | H5: 1443.74 | I5: 1591.088 | J5: 1673.323 | K5: 1899.273
A6: Reported FCF (company definition) | B6: 20.3 | C6: 97.5 | D6: 226.3 | E6: 285.7 | F6: 420.2 | G6: 82.1 | H6: 198.6 | I6: 100.9 | J6: 235.2 | K6: 197.5
A7: Reported FCF Margin % | B7: =B6/B5 -> 0 | C7: =C6/C5 -> 0 | D7: =D6/D5 -> 0 | E7: =E6/E5 -> 0 | F7: =F6/F5 -> 0 | G7: =G6/G5 -> 0 | H7: =H6/H5 -> 0 | I7: =I6/I5 -> 0 | ... K7: =K6/K5 -> 0
A8: Less: SBC (incl. equity-award taxes, nil) | B8: 3.109 | C8: 2.528 | D8: 2.612 | E8: 8.184 | F8: 8.331 | G8: 1.835 | H8: 11.609 | I8: 17.132 | J8: 10.727 | K8: 13.545
A9: Less: Interest Income | B9: 0.502 | C9: 0.887 | D9: 2.369 | E9: 4.277 | F9: 6.129 | G9: 3.989 | H9: 6.569 | I9: 26.733 | J9: 40.396 | K9: 45.457
A10: Owner FCF | B10: =B6-B8-B9 -> 0 | C10: =C6-C8-C9 -> 0 | D10: =D6-D8-D9 -> 0 | E10: =E6-E8-E9 -> 0 | F10: =F6-F8-F9 -> 0 | G10: =G6-G8-G9 -> 0 | H10: =H6-H8-H9 -> 0 | I10: =I6-I8-I9 -> 0 | ... K10: =K6-K8-K9 -> 0
A11: Owner FCF Margin % | B11: =B10/B5 -> 0 | C11: =C10/C5 -> 0 | D11: =D10/D5 -> 0 | E11: =E10/E5 -> 0 | F11: =F10/F5 -> 0 | G11: =G10/G5 -> 0 | H11: =H10/H5 -> 0 | I11: =I10/I5 -> 0 | ... K11: =K10/K5 -> 0
A13: Memo: cash tax rate flag
A14: FY2023 interest income spike ($26.7m, +307% YoY) reflects rising global rates on a growing cash pile
A15: post FY2020-22 cash build; FY2021-22 daigou-collapse trough years have depressed reported FCF unrelated
A16: to tax; NZ statutory corporate tax rate is 28% flat (no valuation-allowance/one-off releases identified
A17: in ATM.NZ filings) so no tax-rate ramp adjustment was required for the historical series.
A19: Memo: FY2025 interest income as % of reported FCF | B19: =J9/J6 -> 0
A20: This is the core reason net cash must be netted from FCF - at 23% of reported FCF, leaving
A21: interest income inside FCF while also adding the $896.9m cash pile to enterprise value would
A22: double-count roughly $45m/yr of value.

Sheet Model_Info
A1: Model Provenance & Methodology
A3: Ticker | B3: ATM.NZ (The a2 Milk Company Limited)
A4: Built by | B4: Claude dcf-analyst agent, per .claude/agents/dcf-analyst.md and project CLAUDE.md conventions
A5: Valuation date | B5: 2026-08-08
A6: Current price data vintage | B6: NZ$8.25, fetched live from Yahoo Finance chart API on 2026-08-08
A7: Financial data vintage | B7: H1-FY2026 interim result (31 Dec 2025, released 16 Feb 2026) is the latest balance sheet; FY2025 Annual Report (30 Jun 2025, released 18 Aug 2025) is the latest full-year P&L/cash flow used to anchor SBC%, D&A%, and owner-FCF margin ratios
A8: Fiscal year | B8: FY ends 30 June. H1 = 1 Jul-31 Dec.
A9: Horizon | B9: 5-year explicit projection (FY2027-FY2031); Year-5 owner-FCF margin (9.8% base) verified analytically equal to the steady-state margin implied by terminal-year component assumptions (mature, not still ramping) - see Quality Checklist in dcf-analyst.md for the maturity test.
A10: Owner FCF adjustment | B10: last_fcf = reported_fcf - SBC - interest_income. EquityAwardTaxes confirmed NIL in kpis table (no net-share-settlement cash tax withholding disclosed). Interest income strip is the dominant adjustment: FY2025 interest income of $45.5m = 23% of reported FCF, and the company holds ~$897m of net cash (>1x the FCF base) so leaving interest income inside FCF while separately adding net cash to EV would double-count value.
A11: SBC treatment | B11: Immaterial for ATM.NZ (~0.6-1.6% of revenue historically, vs 15%+ for SBC-heavy tech comps). Projected as a declining % of revenue (0.7% -> 0.6% base case) per policy, but the base-vs-non-cash-SBC IV spread is only ~$0.17/share - SBC is NOT a material driver of this valuation, unlike the reference DUOL model.
A12: Share count | B12: Held flat at 729.05M (H1-2026 actual) across the projection. Buybacks have historically kept the share count in a tight 700-745M band for a decade (FY2020-23 cumulative buybacks ~$175M against modest annual SBC of $2-17M/yr), so uncovered_dilution = 0 is a defensible simplification rather than a mechanical max(0, sbc-buyback) computation per year.
A13: Net debt treatment | B13: Net cash of $896.9M (H1-2026, zero debt) LESS the pending $300M special dividend (Board-announced, subject to SAMR regulatory approval for China-label registration transfer + MVM divestment completion - both substantially achieved by early FY26 per company commentary, but not yet paid as of H1-2026) = $596.9M net cash used in the EV-to-equity bridge. Rationale: the special dividend is an already-committed economic distribution to today's shareholders and should not inflate the going-forward intrinsic value of the enterprise. If delayed/cancelled, add back up to $0.41/share (300/729).
A14: Component margin build | B14: Revenue -> Adj. EBITDA (ramping margin) -> less SBC% -> less D&A% -> EBIT -> x(1-tax) -> NOPAT -> +D&A -> less CapEx% -> less Working Capital (15% of the YoY revenue INCREASE, not a flat % of revenue) -> Owner FCF. CapEx is temporarily elevated (~3.0% of revenue in FY27, tapering to ~2.1% by FY31) reflecting the multi-year Pokeno/Yashili insourcing capital programme (company-guided $50-70M for FY26 vs $4-33M historical run-rate).
... A24: Staleness warning | B24: All figures in this workbook reflect data as of the valuation date above. Financial data, guidance, and the special-dividend status will go stale after each new filing (H1/FY results) and MUST be re-checked before reuse - do not treat this file as evergreen.
