Workbook

Sheet Base Case
A1: BABA DCF Model - Base Case
A2: Gray cells are INPUTS - adjust to see valuation change. All RMB figures in millions unless noted.
A4: KEY INPUTS
A5: Current Stock Price (USD/ADS) | B5: 112.14
A6: Ordinary Shares Outstanding (M) | B6: 19235
A7: ADS per Ordinary Share | B7: 8
A8: Cash & Equivalents (RMB M) | B8: 131530
A9: Unrestricted Short-Term Investments (RMB M) | B9: 155236
A10: Unrestricted Other Treasury Investments (RMB M) | B10: 234058
A11: Total Debt (RMB M) | B11: 259996
A12: Net Debt / (Net Cash) (RMB M) | B12: =B11-B8-B9-B10
A13: Positive = net debt (subtracted from EV). Negative = net cash (added to EV).
A14: USD/CNY FX Rate (RMB per USD) | B14: 6.7617
A16: Base Year Normalized FCF (RMB M) | B16: 120000
A17: WACC | B17: 0.115
A18: Terminal Growth Rate | B18: 0.03
A19: Exit EV/EBITDA Multiple (cap) | B19: 7
A20: Normalized EBITDA Basis (avg FY23-25, RMB M) | B20: 189901
A21: EBITDA Growth Factor (% of FCF growth rate) | B21: 0.6
A23: GROWTH ASSUMPTIONS | B23: Year 1 | C23: Year 2 | D23: Year 3 | E23: Year 4 | F23: Year 5
A24: FCF Growth Rate | B24: 0.22 | C24: 0.18 | D24: 0.14 | E24: 0.1 | F24: 0.07
A26: PROJECTIONS (RMB Millions)
B27: Year 1 | C27: Year 2 | D27: Year 3 | E27: Year 4 | F27: Year 5
A28: Free Cash Flow | B28: =B16*(1+B24) | C28: =B28*(1+C24) | D28: =C28*(1+D24) | E28: =D28*(1+E24) | F28: =E28*(1+F24)
A29: Discount Factor | B29: =1/(1+$B$17)^1 | C29: =1/(1+$B$17)^2 | D29: =1/(1+$B$17)^3 | E29: =1/(1+$B$17)^4 | F29: =1/(1+$B$17)^5
A30: PV of FCF | B30: =B28*B29 | C30: =C28*C29 | D30: =D28*D29 | E30: =E28*E29 | F30: =F28*F29
A31: Normalized EBITDA (for exit multiple) | B31: =B20*(1+B24*$B$21) | C31: =B31*(1+C24*$B$21) | D31: =C31*(1+D24*$B$21) | E31: =D31*(1+E24*$B$21) | F31: =E31*(1+F24*$B$21)
A33: VALUATION (RMB Millions)
A34: Sum of PV of FCF | B34: =SUM(B30:F30)
A35: Terminal FCF (Year 5 x (1+g)) | B35: =F28*(1+$B$18)
A36: Terminal Value - Gordon Growth | B36: =B35/($B$17-$B$18)
A37: Terminal Value - Exit Multiple (EBITDA Y5 x cap) | B37: =F31*$B$19
A38: Terminal Value Used (MIN of the two) | B38: =MIN(B36,B37)
A39: PV of Terminal Value | B39: =B38*F29
A40: Enterprise Value | B40: =B34+B39
A41: Less: Net Debt / (Net Cash) | B41: =B12
A42: Equity Value (RMB M) | B42: =B40-B41
A43: Equity Value per Ordinary Share (RMB) | B43: =B42/B6
A44: INTRINSIC VALUE / ADS (USD) | B44: =B43*B7/B14
A46: Upside / (Downside) vs Current Price | B46: =(B44-B5)/B5
...

Sheet Bull Case
A1: BABA DCF Model - Bull Case
A2: Gray cells are INPUTS - adjust to see valuation change. All RMB figures in millions unless noted.
A4: KEY INPUTS
A5: Current Stock Price (USD/ADS) | B5: 112.14
A6: Ordinary Shares Outstanding (M) | B6: 19235
A7: ADS per Ordinary Share | B7: 8
A8: Cash & Equivalents (RMB M) | B8: 131530
A9: Unrestricted Short-Term Investments (RMB M) | B9: 155236
A10: Unrestricted Other Treasury Investments (RMB M) | B10: 234058
A11: Total Debt (RMB M) | B11: 259996
A12: Net Debt / (Net Cash) (RMB M) | B12: =B11-B8-B9-B10
A13: Positive = net debt (subtracted from EV). Negative = net cash (added to EV).
A14: USD/CNY FX Rate (RMB per USD) | B14: 6.7617
A16: Base Year Normalized FCF (RMB M) | B16: 138000
A17: WACC | B17: 0.105
A18: Terminal Growth Rate | B18: 0.035
A19: Exit EV/EBITDA Multiple (cap) | B19: 9.5
A20: Normalized EBITDA Basis (avg FY23-25, RMB M) | B20: 189901
A21: EBITDA Growth Factor (% of FCF growth rate) | B21: 0.6
A23: GROWTH ASSUMPTIONS | B23: Year 1 | C23: Year 2 | D23: Year 3 | E23: Year 4 | F23: Year 5
A24: FCF Growth Rate | B24: 0.28 | C24: 0.23 | D24: 0.18 | E24: 0.14 | F24: 0.1
A26: PROJECTIONS (RMB Millions)
B27: Year 1 | C27: Year 2 | D27: Year 3 | E27: Year 4 | F27: Year 5
A28: Free Cash Flow | B28: =B16*(1+B24) | C28: =B28*(1+C24) | D28: =C28*(1+D24) | E28: =D28*(1+E24) | F28: =E28*(1+F24)
A29: Discount Factor | B29: =1/(1+$B$17)^1 | C29: =1/(1+$B$17)^2 | D29: =1/(1+$B$17)^3 | E29: =1/(1+$B$17)^4 | F29: =1/(1+$B$17)^5
A30: PV of FCF | B30: =B28*B29 | C30: =C28*C29 | D30: =D28*D29 | E30: =E28*E29 | F30: =F28*F29
A31: Normalized EBITDA (for exit multiple) | B31: =B20*(1+B24*$B$21) | C31: =B31*(1+C24*$B$21) | D31: =C31*(1+D24*$B$21) | E31: =D31*(1+E24*$B$21) | F31: =E31*(1+F24*$B$21)
A33: VALUATION (RMB Millions)
A34: Sum of PV of FCF | B34: =SUM(B30:F30)
A35: Terminal FCF (Year 5 x (1+g)) | B35: =F28*(1+$B$18)
A36: Terminal Value - Gordon Growth | B36: =B35/($B$17-$B$18)
A37: Terminal Value - Exit Multiple (EBITDA Y5 x cap) | B37: =F31*$B$19
A38: Terminal Value Used (MIN of the two) | B38: =MIN(B36,B37)
A39: PV of Terminal Value | B39: =B38*F29
A40: Enterprise Value | B40: =B34+B39
A41: Less: Net Debt / (Net Cash) | B41: =B12
A42: Equity Value (RMB M) | B42: =B40-B41
A43: Equity Value per Ordinary Share (RMB) | B43: =B42/B6
A44: INTRINSIC VALUE / ADS (USD) | B44: =B43*B7/B14
A46: Upside / (Downside) vs Current Price | B46: =(B44-B5)/B5
...

Sheet Bear Case
A1: BABA DCF Model - Bear Case
A2: Gray cells are INPUTS - adjust to see valuation change. All RMB figures in millions unless noted.
A4: KEY INPUTS
A5: Current Stock Price (USD/ADS) | B5: 112.14
A6: Ordinary Shares Outstanding (M) | B6: 19235
A7: ADS per Ordinary Share | B7: 8
A8: Cash & Equivalents (RMB M) | B8: 131530
A9: Unrestricted Short-Term Investments (RMB M) | B9: 155236
A10: Unrestricted Other Treasury Investments (RMB M) | B10: 234058
A11: Total Debt (RMB M) | B11: 259996
A12: Net Debt / (Net Cash) (RMB M) | B12: =B11-B8-B9-B10
A13: Positive = net debt (subtracted from EV). Negative = net cash (added to EV).
A14: USD/CNY FX Rate (RMB per USD) | B14: 6.7617
A16: Base Year Normalized FCF (RMB M) | B16: 68000
A17: WACC | B17: 0.13
A18: Terminal Growth Rate | B18: 0.025
A19: Exit EV/EBITDA Multiple (cap) | B19: 4.5
A20: Normalized EBITDA Basis (avg FY23-25, RMB M) | B20: 189901
A21: EBITDA Growth Factor (% of FCF growth rate) | B21: 0.6
A23: GROWTH ASSUMPTIONS | B23: Year 1 | C23: Year 2 | D23: Year 3 | E23: Year 4 | F23: Year 5
A24: FCF Growth Rate | B24: 0.06 | C24: 0.05 | D24: 0.04 | E24: 0.03 | F24: 0.02
A26: PROJECTIONS (RMB Millions)
B27: Year 1 | C27: Year 2 | D27: Year 3 | E27: Year 4 | F27: Year 5
A28: Free Cash Flow | B28: =B16*(1+B24) | C28: =B28*(1+C24) | D28: =C28*(1+D24) | E28: =D28*(1+E24) | F28: =E28*(1+F24)
A29: Discount Factor | B29: =1/(1+$B$17)^1 | C29: =1/(1+$B$17)^2 | D29: =1/(1+$B$17)^3 | E29: =1/(1+$B$17)^4 | F29: =1/(1+$B$17)^5
A30: PV of FCF | B30: =B28*B29 | C30: =C28*C29 | D30: =D28*D29 | E30: =E28*E29 | F30: =F28*F29
A31: Normalized EBITDA (for exit multiple) | B31: =B20*(1+B24*$B$21) | C31: =B31*(1+C24*$B$21) | D31: =C31*(1+D24*$B$21) | E31: =D31*(1+E24*$B$21) | F31: =E31*(1+F24*$B$21)
A33: VALUATION (RMB Millions)
A34: Sum of PV of FCF | B34: =SUM(B30:F30)
A35: Terminal FCF (Year 5 x (1+g)) | B35: =F28*(1+$B$18)
A36: Terminal Value - Gordon Growth | B36: =B35/($B$17-$B$18)
A37: Terminal Value - Exit Multiple (EBITDA Y5 x cap) | B37: =F31*$B$19
A38: Terminal Value Used (MIN of the two) | B38: =MIN(B36,B37)
A39: PV of Terminal Value | B39: =B38*F29
A40: Enterprise Value | B40: =B34+B39
A41: Less: Net Debt / (Net Cash) | B41: =B12
A42: Equity Value (RMB M) | B42: =B40-B41
A43: Equity Value per Ordinary Share (RMB) | B43: =B42/B6
A44: INTRINSIC VALUE / ADS (USD) | B44: =B43*B7/B14
A46: Upside / (Downside) vs Current Price | B46: =(B44-B5)/B5
...

Sheet Summary
A1: BABA DCF Valuation Summary
A2: Valuation date: 2026-07-26 (REVISED - net debt corrected) | Current price: $112.14/ADS | FX: 6.7617 RMB/USD
B4: Bear | C4: Base | D4: Bull
A5: Intrinsic Value / ADS (USD) | B5: ='Bear Case'!B44 | C5: ='Base Case'!B44 | D5: ='Bull Case'!B44
A6: Upside / (Downside) vs Current | B6: ='Bear Case'!B46 | C6: ='Base Case'!B46 | D6: ='Bull Case'!B46
A7: Entry Price (15% IRR), USD/ADS | B7: ='Bear Case'!B56 | C7: ='Base Case'!B56 | D7: ='Bull Case'!B56
A8: Entry Price Discount from Current | B8: ='Bear Case'!B57 | C8: ='Base Case'!B57 | D8: ='Bull Case'!B57
A9: Terminal Value % of EV | B9: ='Bear Case'!B47 | C9: ='Base Case'!B47 | D9: ='Bull Case'!B47
A10: Implied Exit Multiple | B10: ='Bear Case'!B48 | C10: ='Base Case'!B48 | D10: ='Bull Case'!B48
A12: PROBABILITY-WEIGHTED VALUATION
A13: Weight - Bear | B13: 0.25
A14: Weight - Base | B14: 0.5
A15: Weight - Bull | B15: 0.25
A16: Weighted Intrinsic Value / ADS (USD) | B16: =B5*B13+C5*B14+D5*B15
A17: Upside vs Current (weighted) | B17: =(B16-'Base Case'!B5)/'Base Case'!B5
A19: KEY INPUTS (shared across scenarios)
A20: Ordinary Shares Outstanding (M) | B20: ='Base Case'!B6
A21: Cash (RMB M) | B21: ='Base Case'!B8
A22: Unrestricted Short-Term Investments (RMB M) | B22: ='Base Case'!B9
A23: Unrestricted Other Treasury Investments (RMB M) | B23: ='Base Case'!B10
A24: Total Debt (RMB M) | B24: ='Base Case'!B11
A25: Net Debt / (Net Cash) (RMB M) | B25: ='Base Case'!B12
A26: FX Rate (RMB per USD) | B26: ='Base Case'!B14
A28: Data Revision Note (2026-07-26)
A29: REVISED 2026-07-26: Corrected a material net-debt error. The prior same-day model netted only cash against total debt (net debt of RMB 128,466M), omitting Alibaba's unrestricted short-term investments (RMB 155,236M) and other treasury investments (RMB 234,058M), per the FY2026 20-F MD&A. Correctly netting the full RMB 520,824M unrestricted liquid/near-liquid asset base against RMB 259,996M total debt gives a NET CASH position of RMB 260,828M, added to (not subtracted from) enterprise value in the equity bridge. The historical EV/EBITDA series and exit-multiple caps were also re-derived on the same fully-netted basis for internal consistency (caps came down from 9.0/11.5/6.0x to 7.0/9.5/4.5x), since the prior caps were calibrated on the same cash-only-overstated EV. Net result: intrinsic values rose in all three scenarios because the net-cash addition outweighs the lower exit-multiple caps.
A31: Valuation Philosophy
A32: Trough-FCF Mid-Cycle Normalization with Exit-Multiple Cap. FY2026 is an intentional investment trough -- not structural demand decline. Alibaba deployed RMB 126B in AI/cloud capex (part of a stated RMB 380B+ three-year programme) and poured subsidies into Taobao Instant Commerce to compete with Meituan, collapsing FCF to a RMB 46,609M outflow. July 2026 developments (quick-commerce loss-per-order roughly halved from peak, guided ~50% cut in FY2027 quick-commerce investment, SAMR's June 2026 anti-subsidy rules, AIDC EBITA loss narrowing 96% YoY, Cloud external revenue +40% turbocharged by the Apple Intelligence/Qwen partnership) support a faster-than-previously-modeled recovery path. The model retains a NORMALIZED (mid-cycle) FCF base of RMB 120,000M for the base case (~10.5% discount to the FY2020-2025 average of RMB 134,032M). Bull case RMB 138,000M; bear case RMB 68,000M. An exit-multiple cap (MIN of Gordon Growth TV vs EV/EBITDA cap on normalized EBITDA) prevents any scenario from implying multiples the market has never sustainably paid for BABA, net of its full investment portfolio.

Sheet Sensitivity
A1: Sensitivity Analysis - Base Case
A2: Intrinsic Value (USD/ADS) by WACC & Terminal Growth (REVISED: 7.0x exit cap, net cash)
A4: WACC \ Term Growth | B4: 0.02 | C4: 0.025 | D4: 0.03 | E4: 0.035 | F4: 0.04
A5: 0.095 | B5: =('Base Case'!$B$28/(1+0.095)^1+'Base Case'!$C$28/(1+0.095)^2+'Base Case'!$D$28/(1+0.095)^3+'Base Case'!$E$28/(1+0.095)^4+'Base Case'!$F$28/(1+0.095)^5+MIN('Base Case'!$F$28*(1+0.02)/(0.095-0.02),'Base Case'!$F$31*'Base Case'!$B$19)/(1+0.095)^5-'Base Case'!$B$12)/'Base Case'!$B$6*'Base Case'!$B$7/'Base Case'!$B$14 | C5: =('Base Case'!$B$28/(1+0.095)^1+'Base Case'!$C$28/(1+0.095)^2+'Base Case'!$D$28/(1+0.095)^3+'Base Case'!$E$28/(1+0.095)^4+'Base Case'!$F$28/(1+0.095)^5+MIN('Base Case'!$F$28*(1+0.025)/(0.095-0.025),'Base Case'!$F$31*'Base Case'!$B$19)/(1+0.095)^5-'Base Case'!$B$12)/'Base Case'!$B$6*'Base Case'!$B$7/'Base Case'!$B$14 | D5: =('Base Case'!$B$28/(1+0.095)^1+'Base Case'!$C$28/(1+0.095)^2+'Base Case'!$D$28/(1+0.095)^3+'Base Case'!$E$28/(1+0.095)^4+'Base Case'!$F$28/(1+0.095)^5+MIN('Base Case'!$F$28*(1+0.03)/(0.095-0.03),'Base Case'!$F$31*'Base Case'!$B$19)/(1+0.095)^5-'Base Case'!$B$12)/'Base Case'!$B$6*'Base Case'!$B$7/'Base Case'!$B$14 | E5: =('Base Case'!$B$28/(1+0.095)^1+'Base Case'!$C$28/(1+0.095)^2+'Base Case'!$D$28/(1+0.095)^3+'Base Case'!$E$28/(1+0.095)^4+'Base Case'!$F$28/(1+0.095)^5+MIN('Base Case'!$F$28*(1+0.035)/(0.095-0.035),'Base Case'!$F$31*'Base Case'!$B$19)/(1+0.095)^5-'Base Case'!$B$12)/'Base Case'!$B$6*'Base Case'!$B$7/'Base Case'!$B$14 | F5: =('Base Case'!$B$28/(1+0.095)^1+'Base Case'!$C$28/(1+0.095)^2+'Base Case'!$D$28/(1+0.095)^3+'Base Case'!$E$28/(1+0.095)^4+'Base Case'!$F$28/(1+0.095)^5+MIN('Base Case'!$F$28*(1+0.04)/(0.095-0.04),'Base Case'!$F$31*'Base Case'!$B$19)/(1+0.095)^5-'Base Case'!$B$12)/'Base Case'!$B$6*'Base Case'!$B$7/'Base Case'!$B$14
A6: 0.105 | B6: =('Base Case'!$B$28/(1+0.105)^1+'Base Case'!$C$28/(1+0.105)^2+'Base Case'!$D$28/(1+0.105)^3+'Base Case'!$E$28/(1+0.105)^4+'Base Case'!$F$28/(1+0.105)^5+MIN('Base Case'!$F$28*(1+0.02)/(0.105-0.02),'Base Case'!$F$31*'Base Case'!$B$19)/(1+0.105)^5-'Base Case'!$B$12)/'Base Case'!$B$6*'Base Case'!$B$7/'Base Case'!$B$14 | C6: =('Base Case'!$B$28/(1+0.105)^1+'Base Case'!$C$28/(1+0.105)^2+'Base Case'!$D$28/(1+0.105)^3+'Base Case'!$E$28/(1+0.105)^4+'Base Case'!$F$28/(1+0.105)^5+MIN('Base Case'!$F$28*(1+0.025)/(0.105-0.025),'Base Case'!$F$31*'Base Case'!$B$19)/(1+0.105)^5-'Base Case'!$B$12)/'Base Case'!$B$6*'Base Case'!$B$7/'Base Case'!$B$14 | D6: =('Base Case'!$B$28/(1+0.105)^1+'Base Case'!$C$28/(1+0.105)^2+'Base Case'!$D$28/(1+0.105)^3+'Base Case'!$E$28/(1+0.105)^4+'Base Case'!$F$28/(1+0.105)^5+MIN('Base Case'!$F$28*(1+0.03)/(0.105-0.03),'Base Case'!$F$31*'Base Case'!$B$19)/(1+0.105)^5-'Base Case'!$B$12)/'Base Case'!$B$6*'Base Case'!$B$7/'Base Case'!$B$14 | E6: =('Base Case'!$B$28/(1+0.105)^1+'Base Case'!$C$28/(1+0.105)^2+'Base Case'!$D$28/(1+0.105)^3+'Base Case'!$E$28/(1+0.105)^4+'Base Case'!$F$28/(1+0.105)^5+MIN('Base Case'!$F$28*(1+0.035)/(0.105-0.035),'Base Case'!$F$31*'Base Case'!$B$19)/(1+0.105)^5-'Base Case'!$B$12)/'Base Case'!$B$6*'Base Case'!$B$7/'Base Case'!$B$14 | F6: =('Base Case'!$B$28/(1+0.105)^1+'Base Case'!$C$28/(1+0.105)^2+'Base Case'!$D$28/(1+0.105)^3+'Base Case'!$E$28/(1+0.105)^4+'Base Case'!$F$28/(1+0.105)^5+MIN('Base Case'!$F$28*(1+0.04)/(0.105-0.04),'Base Case'!$F$31*'Base Case'!$B$19)/(1+0.105)^5-'Base Case'!$B$12)/'Base Case'!$B$6*'Base Case'!$B$7/'Base Case'!$B$14
A7: 0.115 | B7: =('Base Case'!$B$28/(1+0.115)^1+'Base Case'!$C$28/(1+0.115)^2+'Base Case'!$D$28/(1+0.115)^3+'Base Case'!$E$28/(1+0.115)^4+'Base Case'!$F$28/(1+0.115)^5+MIN('Base Case'!$F$28*(1+0.02)/(0.115-0.02),'Base Case'!$F$31*'Base Case'!$B$19)/(1+0.115)^5-'Base Case'!$B$12)/'Base Case'!$B$6*'Base Case'!$B$7/'Base Case'!$B$14 | C7: =('Base Case'!$B$28/(1+0.115)^1+'Base Case'!$C$28/(1+0.115)^2+'Base Case'!$D$28/(1+0.115)^3+'Base Case'!$E$28/(1+0.115)^4+'Base Case'!$F$28/(1+0.115)^5+MIN('Base Case'!$F$28*(1+0.025)/(0.115-0.025),'Base Case'!$F$31*'Base Case'!$B$19)/(1+0.115)^5-'Base Case'!$B$12)/'Base Case'!$B$6*'Base Case'!$B$7/'Base Case'!$B$14 | D7: =('Base Case'!$B$28/(1+0.115)^1+'Base Case'!$C$28/(1+0.115)^2+'Base Case'!$D$28/(1+0.115)^3+'Base Case'!$E$28/(1+0.115)^4+'Base Case'!$F$28/(1+0.115)^5+MIN('Base Case'!$F$28*(1+0.03)/(0.115-0.03),'Base Case'!$F$31*'Base Case'!$B$19)/(1+0.115)^5-'Base Case'!$B$12)/'Base Case'!$B$6*'Base Case'!$B$7/'Base Case'!$B$14 | E7: =('Base Case'!$B$28/(1+0.115)^1+'Base Case'!$C$28/(1+0.115)^2+'Base Case'!$D$28/(1+0.115)^3+'Base Case'!$E$28/(1+0.115)^4+'Base Case'!$F$28/(1+0.115)^5+MIN('Base Case'!$F$28*(1+0.035)/(0.115-0.035),'Base Case'!$F$31*'Base Case'!$B$19)/(1+0.115)^5-'Base Case'!$B$12)/'Base Case'!$B$6*'Base Case'!$B$7/'Base Case'!$B$14 | F7: =('Base Case'!$B$28/(1+0.115)^1+'Base Case'!$C$28/(1+0.115)^2+'Base Case'!$D$28/(1+0.115)^3+'Base Case'!$E$28/(1+0.115)^4+'Base Case'!$F$28/(1+0.115)^5+MIN('Base Case'!$F$28*(1+0.04)/(0.115-0.04),'Base Case'!$F$31*'Base Case'!$B$19)/(1+0.115)^5-'Base Case'!$B$12)/'Base Case'!$B$6*'Base Case'!$B$7/'Base Case'!$B$14
A8: 0.125 | B8: =('Base Case'!$B$28/(1+0.125)^1+'Base Case'!$C$28/(1+0.125)^2+'Base Case'!$D$28/(1+0.125)^3+'Base Case'!$E$28/(1+0.125)^4+'Base Case'!$F$28/(1+0.125)^5+MIN('Base Case'!$F$28*(1+0.02)/(0.125-0.02),'Base Case'!$F$31*'Base Case'!$B$19)/(1+0.125)^5-'Base Case'!$B$12)/'Base Case'!$B$6*'Base Case'!$B$7/'Base Case'!$B$14 | C8: =('Base Case'!$B$28/(1+0.125)^1+'Base Case'!$C$28/(1+0.125)^2+'Base Case'!$D$28/(1+0.125)^3+'Base Case'!$E$28/(1+0.125)^4+'Base Case'!$F$28/(1+0.125)^5+MIN('Base Case'!$F$28*(1+0.025)/(0.125-0.025),'Base Case'!$F$31*'Base Case'!$B$19)/(1+0.125)^5-'Base Case'!$B$12)/'Base Case'!$B$6*'Base Case'!$B$7/'Base Case'!$B$14 | D8: =('Base Case'!$B$28/(1+0.125)^1+'Base Case'!$C$28/(1+0.125)^2+'Base Case'!$D$28/(1+0.125)^3+'Base Case'!$E$28/(1+0.125)^4+'Base Case'!$F$28/(1+0.125)^5+MIN('Base Case'!$F$28*(1+0.03)/(0.125-0.03),'Base Case'!$F$31*'Base Case'!$B$19)/(1+0.125)^5-'Base Case'!$B$12)/'Base Case'!$B$6*'Base Case'!$B$7/'Base Case'!$B$14 | E8: =('Base Case'!$B$28/(1+0.125)^1+'Base Case'!$C$28/(1+0.125)^2+'Base Case'!$D$28/(1+0.125)^3+'Base Case'!$E$28/(1+0.125)^4+'Base Case'!$F$28/(1+0.125)^5+MIN('Base Case'!$F$28*(1+0.035)/(0.125-0.035),'Base Case'!$F$31*'Base Case'!$B$19)/(1+0.125)^5-'Base Case'!$B$12)/'Base Case'!$B$6*'Base Case'!$B$7/'Base Case'!$B$14 | F8: =('Base Case'!$B$28/(1+0.125)^1+'Base Case'!$C$28/(1+0.125)^2+'Base Case'!$D$28/(1+0.125)^3+'Base Case'!$E$28/(1+0.125)^4+'Base Case'!$F$28/(1+0.125)^5+MIN('Base Case'!$F$28*(1+0.04)/(0.125-0.04),'Base Case'!$F$31*'Base Case'!$B$19)/(1+0.125)^5-'Base Case'!$B$12)/'Base Case'!$B$6*'Base Case'!$B$7/'Base Case'!$B$14
A9: 0.135 | B9: =('Base Case'!$B$28/(1+0.135)^1+'Base Case'!$C$28/(1+0.135)^2+'Base Case'!$D$28/(1+0.135)^3+'Base Case'!$E$28/(1+0.135)^4+'Base Case'!$F$28/(1+0.135)^5+MIN('Base Case'!$F$28*(1+0.02)/(0.135-0.02),'Base Case'!$F$31*'Base Case'!$B$19)/(1+0.135)^5-'Base Case'!$B$12)/'Base Case'!$B$6*'Base Case'!$B$7/'Base Case'!$B$14 | C9: =('Base Case'!$B$28/(1+0.135)^1+'Base Case'!$C$28/(1+0.135)^2+'Base Case'!$D$28/(1+0.135)^3+'Base Case'!$E$28/(1+0.135)^4+'Base Case'!$F$28/(1+0.135)^5+MIN('Base Case'!$F$28*(1+0.025)/(0.135-0.025),'Base Case'!$F$31*'Base Case'!$B$19)/(1+0.135)^5-'Base Case'!$B$12)/'Base Case'!$B$6*'Base Case'!$B$7/'Base Case'!$B$14 | D9: =('Base Case'!$B$28/(1+0.135)^1+'Base Case'!$C$28/(1+0.135)^2+'Base Case'!$D$28/(1+0.135)^3+'Base Case'!$E$28/(1+0.135)^4+'Base Case'!$F$28/(1+0.135)^5+MIN('Base Case'!$F$28*(1+0.03)/(0.135-0.03),'Base Case'!$F$31*'Base Case'!$B$19)/(1+0.135)^5-'Base Case'!$B$12)/'Base Case'!$B$6*'Base Case'!$B$7/'Base Case'!$B$14 | E9: =('Base Case'!$B$28/(1+0.135)^1+'Base Case'!$C$28/(1+0.135)^2+'Base Case'!$D$28/(1+0.135)^3+'Base Case'!$E$28/(1+0.135)^4+'Base Case'!$F$28/(1+0.135)^5+MIN('Base Case'!$F$28*(1+0.035)/(0.135-0.035),'Base Case'!$F$31*'Base Case'!$B$19)/(1+0.135)^5-'Base Case'!$B$12)/'Base Case'!$B$6*'Base Case'!$B$7/'Base Case'!$B$14 | F9: =('Base Case'!$B$28/(1+0.135)^1+'Base Case'!$C$28/(1+0.135)^2+'Base Case'!$D$28/(1+0.135)^3+'Base Case'!$E$28/(1+0.135)^4+'Base Case'!$F$28/(1+0.135)^5+MIN('Base Case'!$F$28*(1+0.04)/(0.135-0.04),'Base Case'!$F$31*'Base Case'!$B$19)/(1+0.135)^5-'Base Case'!$B$12)/'Base Case'!$B$6*'Base Case'!$B$7/'Base Case'!$B$14
A11: Note: recalculates Base Case FCF/EBITDA paths (fixed) at each WACC/terminal-growth
A12: combination, applying the same exit-multiple cap logic (MIN of Gordon TV vs exit TV).
A13: Net Debt cell (Base Case!B12) is negative (net cash), so "-Net Debt" ADDS RMB 260,828M.
A14: With the 7.0x cap, exit-multiple TV is binding across the full WACC/terminal-growth range
A15: tested, so each row is flat across terminal growth (see BABA_DCF.json sensitivity.matrix_note).

Sheet Historical
A1: Historical Growth Rates & Multiples
A3: Metric | B3: 3-Year CAGR | C3: 5-Year CAGR
A4: Revenue | B4: 0.0562 | C4: 0.0737
A5: EPS (ADS, diluted) | B5: 0.1684 | C5: -0.0524
A6: Equity / Book Value | B6: 0.0234 | C6: 0.025
A7: FCF CAGR: N/A (FY2026 negative)
A8: Selected Growth Rate: | B8: 0.025
A9: Source: | B9: equity_5yr_cagr
A11: Historical Multiples by Fiscal Year-End (REVISED: EV/EBITDA nets full investment portfolio)
A12: Fiscal Year | B12: ADS Price (USD) | C12: P/E | D12: P/B | E12: EV/EBITDA (corrected)
A14: FY2017 | B14: 107.83 | C14: 43.83 | D14: 6.85 | E14: 24.96
A15: FY2018 | B15: 183.54 | C15: 47.06 | D15: 8.21 | E15: 27.69
A16: FY2019 | B16: 182.45 | C16: 36.71 | D16: 6.52 | E16: 25.84
A17: FY2020 | B17: 194.48 | C17: 24.62 | D17: 4.86 | E17: 21.8
A18: FY2021 | B18: 226.73 | C18: 27.15 | D18: 4.35 | E18: 19.07
A19: FY2022 | B19: 108.8 | C19: 30.39 | D19: 1.98 | E19: 9.94
A20: FY2023 | B20: 102.18 | C20: 25.55 | D20: 1.87 | E20: 8.26
A21: FY2024 | B21: 72.36 | C21: 16.71 | D21: 1.35 | E21: 4.62
A22: FY2025 | B22: 132.23 | C22: 17.89 | D22: 2.3 | E22: 9.64
A23: FY2026 | B23: 125.46 | C23: 19.66 | D23: 1.96 | E23: 16.02
A24: Current | B24: 112.14
A26: Recent Normal Years (FY2022-FY2025) Averages -- REVISED
A27: P/E Average | B27: 22.64
A28: P/B Average | B28: 1.88
A29: EV/EBITDA Average (corrected, was 10.09x) | B29: 8.12
A30: EV/EBITDA Range (corrected, was 6.53x-11.88x) | B30: 4.62x - 9.94x
A32: Note: FY2021 (bubble peak) and FY2026 (capex/subsidy trough) excluded
A33: from "recent normal years" averages as outliers. FY2017-2018 EV/EBITDA computed
A34: on a cash-only net-debt basis (short-term investment data unavailable in our
A35: extracts for those years); both fall outside the FY2022-2025 calibration window.

Sheet Sanity Check
A1: Sanity Check - Implied Multiples at Base IV (REVISED 2026-07-26)
A3: Passed: | B3: YES
A5: Implied Multiples at Base Intrinsic Value ($129.55)
A6: P/B | B6: 1.99
A7: EV/EBITDA (trough FY2026 EBITDA) | B7: 16.26
A8: EV/EBITDA (normalized avg FY23-25) | B8: 9.72
A9: P/S | B9: 2.06
A10: P/E (trough FY2026 EPS) | B10: 20.31
A12: Historical Range Comparison (Recent Normal Years FY22-25, REVISED)
A13: P/E range | B13: 16.71x - 30.39x
A14: P/B range | B14: 1.35x - 2.30x
A15: EV/EBITDA range (corrected, was 6.53x-11.88x) | B15: 4.62x - 9.94x
A17: Diagnosis
A18: No hard sanity trip on normalized multiples. P/B 1.99x at base IV is within the recent-normal-years (FY2022-FY2025) range of 1.35x-2.30x. Normalized EV/EBITDA 9.72x at base IV is now WITHIN (not near the top of) the corrected recent-normal-years range of 4.62x-9.94x, an improvement versus the pre-revision 11.46x which sat near the (higher, overstated) prior ceiling of 11.9x. P/E 20.31x (on trough FY2026 EPS, understating true earnings power) sits below the recent-years average of 22.6x. P/S 2.06x is within the recent range. Base case upside (15.5% on IV; 12.7% probability-weighted) does not trigger any 'excessive upside at elevated price' trip. Net effect of the net-debt correction: intrinsic value rose in all three scenarios (base +2.8%, bull roughly flat, bear +66.9% in dollar terms / +21.4 points of upside) because the RMB 260,828M net-cash addition to the equity bridge outweighs the reduction in exit-multiple-implied terminal value from the lower, corrected caps (7.0/9.5/4.5x vs 9.0/11.5/6.0x) in every scenario.
A26: Fix Applied
A27: Exit multiple cap applied as a precautionary discipline even though no hard trip was triggered. REVISED 2026-07-26: caps recalibrated to 7.0x/9.5x/4.5x (base/bull/bear) from 9.0x/11.5x/6.0x, following the corrected (lower) historical EV/EBITDA range once the investment portfolio is properly netted out of EV. Base case 7.0x exit multiple on normalized EBITDA constrains base IV to $129.55 (up from the pre-revision capped figure of $125.97, because the net-cash correction more than offsets the lower cap). Bull case 9.5x cap constrains bull IV to $186.55 (essentially unchanged from $186.60 pre-revision). The cap ensures no scenario implies EV/EBITDA meaningfully above what the market has paid in normal (non-bubble, non-trough) years, now measured on a fully-netted EV basis. Adjusted base used throughout (sensitivity, entry price, probability-weighted IV).
A30: Data Revision Note
A31: Prior same-day model netted only cash (net debt of RMB 128,466M). Corrected to net the full unrestricted war chest of RMB 520,824M (cash RMB 131,530M + unrestricted short-term investments RMB 155,236M + unrestricted other treasury investments RMB 234,058M) per the FY2026 20-F MD&A, giving a NET CASH position of RMB 260,828M against total debt of RMB 259,996M. Historical EV/EBITDA series and exit-multiple caps re-derived on the same basis for consistency.
