Workbook

Sheet Model_Info
A1: SCL.NZ - Scales Corporation Limited - owner-FCF DCF model, version 1 (fresh build, supersedes nothing)
A2: Built by the dcf-analyst agent (Claude, model claude-fable-5) on 2026-08-28 at the user's request via /research-stock.
A3: DATA VINTAGE (figures go stale - refresh after each result):
A4: Price NZ$7.10, Yahoo Finance NZX regular close 2026-08-27 (04:59:43Z). 52w range 4.90-7.20; top of range post H1-2026 result.
A5: Balance sheet: net debt NZ$84.1m (mgmt, borrowings less cash, EXCLUDING leases) at 31-Dec-2025 (FY2025 Annual Report);
A6: plus NZ$36.7m deferred acquisition consideration (AUD 7.3m p.a. Sep-2026..Sep-2030). Jun-2026 mgmt net debt $106.7m is a seasonal peak
A7: and matches year-1 flows only if H1 WC build were excluded - Dec-25 anchor avoids double-counting the FY2026 WC build charged in year 1.
A8: Shares: 144.820m at 30-Jun-2026 (H1-2026 interim). Held FLAT: SBC fully expensed in flows (charge once).
A9: Guidance: FY2026 Underlying NPATAS $55-60m (raised 26-Aug-2026), implied Underlying EBITDA $135-142m, Underlying NPAT $72-78m.
A10: METHODOLOGY CHOICES:
A11: Earnings basis UNDERLYING not reported: FY2025 reported NPATAS $101.0m includes ~$26.4m one-off non-cash IFRS 3 step-acquisition gains;
A12: Underlying NPATAS $61.8m / Underlying EBITDA $137.6m are the base. Year 1 ties to FY2026 guidance.
... A22: CELL COLOURS: blue = hardcoded input; yellow fill = key driver row; black = formula; green = cross-sheet link. Sheet names contain no spaces.

Sheet Actuals
A1: Metric (NZ$m) | B1: FY2019 | C1: FY2020 | D1: FY2021 | E1: FY2022 | F1: FY2023 | G1: FY2024 | H1: FY2025 | I1: Source
A2: Revenue | B2: 484.609 | C2: 470.709 | D2: 514.551 | E2: 619.173 | F2: 565.356 | G2: 584.627 | H2: 899.949 | I2: Metrics.csv / annual reports
A3: EBITDA (reported) | B3: 79.853 | C3: 56.74 | D3: 71.619 | E3: 68.516 | F3: 53.675 | G3: 88.093 | H3: 169.862 | I3: Metrics.csv; FY2025 incl $40.6m one-off gains
A4: Underlying EBITDA | G4: 91.704 | H4: 137.628 | I4: FY2025 AR underlying reconciliation
A5: NPAT attributable (reported) | B5: 118.002 | C5: 21.025 | D5: 26.925 | E5: 19.412 | F5: 5.235 | G5: 30.726 | H5: 100.988 | I5: FY2019 incl divestment gains; FY2023 cyclone; FY2025 incl step-acq gains
A6: Underlying NPATAS | G6: 34.058 | H6: 61.834 | I6: FY2025 AR; FY2026 guidance 55-60
A7: NCI share of profit | B7: 3.575 | C7: 5.556 | D7: 10.025 | E7: 18.819 | F7: 19.439 | G7: 19.311 | H7: 16.71 | I7: annual reports; underlying NCI FY2025 15.8
A8: Reported FCF (OCF - capex) | B8: 39.786 | C8: 28.987 | D8: 24.017 | E8: 30.273 | F8: 47.892 | G8: 43.124 | H8: 74.862 | I8: Metrics.csv
A9: Owner FCF (see FCF_Quality) | B9: 29.252 | C9: 18.008 | D9: 12.488 | E9: 18.43 | F9: 35.872 | G9: 29.565 | H9: 60.489 | I9: reported FCF - SBC - full lease payments
A10: Mgmt net debt (ex-lease) | G10: -12.5 | H10: 84.1 | I10: FY2025 AR / H1-2026 presentation (FY2024 = net cash)
A11: Shares outstanding (m) | B11: 140.591 | C11: 140.87 | D11: 141.252 | E11: 141.716 | F11: 141.948 | G11: 142.617 | H11: 143.92 | I11: Metrics.csv; 144.820 at 30-Jun-2026
A13: FY2026 guidance (26-Aug-2026): Underlying EBITDA 135-142; Underlying NPAT 72-78; Underlying NPATAS 55-60. H1-2026 actual: revenue 762.1, U-EBITDA 102.2, U-NPATAS 52.0.
A14: Buybacks: none - Scales issues via DRP; SBC immaterial (~0.1% of revenue).

Sheet Assumptions
A1: Global inputs
A3: Current price (NZ$, 27-Aug-2026 close) | B3: 7.1 | F3: Yahoo NZX close; post-result print at top of 52w range
A4: Diluted shares (m, 30-Jun-2026) | B4: 144.82 | F4: held flat - SBC expensed in flows
A5: Mgmt net debt ex-lease (31-Dec-2025) | B5: 84.1 | F5: borrowings less cash; leases excluded (treatment B)
A6: Deferred consideration (31-Dec-2025) | B6: 36.7 | F6: AUD 7.3m p.a. to Sep-2030, amortised cost
A7: Net debt used in bridge | B7: =B5+B6 | F7: core net debt + deferred consideration
A8: WACC (all scenarios) | B8: 0.115 | F8: NZD build: 4.4 rf + 0.95x5.5 ERP + 0.5 size + 0.75 weather/cyclicality + 0.5 integration/Esro + 0.25 FX = ~11.6 CoE; ~10.7 blended; adopted 11.5
A9: Hurdle rate (entry price) | B9: 0.15 | F9: house standard 15% IRR
A10: Terminal cap multiple (x year-10 FCF) | B10: 12 | F10: cyclical agribusiness - low cap; Gordon binds anyway
A11: Base revenue FY2025 (NZ$m) | B11: 899.949 | F11: FY2025 actual
A13: Per-scenario
B14: Bear | C14: Base | D14: Bull
A15: D&A ex-ROU, % of revenue | B15: 0.019 | C15: 0.0185 | D15: 0.0185 | F15: FY2025 ex-ROU D&A 18.4 = 2.05%; ~1.85% on enlarged trading-heavy base
A16: Capex, % of revenue | B16: 0.02 | C16: 0.02 | D16: 0.021 | F16: FY2025 capex 20.9 (2.3%); orchard redevelopment + GP capacity; bull adds growth capex
A17: WC capture, % of revenue CHANGE | B17: -0.03 | C17: -0.04 | D17: -0.04 | F17: trading + horticulture CONSUME WC as they grow (negative capture)
A18: Terminal growth | B18: 0.02 | C18: 0.02 | D18: 0.025 | F18: mature agribusiness in a small economy; capped 2.0-2.5%
A19: Probability weight | B19: 0.25 | C19: 0.5 | D19: 0.25 | F19: bear raised for LIVE Esro distress + weather concentration; bull needs several independent wins
A20: Weight sum check (must be 1.00) | B20: =SUM(B19:D19)
A22: Scenario narratives
A23: Base: | B23: FY2026 lands at guidance (crop 93% sold); organic 4.5% fading to 2.5%; margin 9.9->10.5% as GP FY27 $85m target broadly met and Esro drag stabilised; ~23% NCI leakage, ~17% cash tax drifting up; no credit for future M&A.
A24: Bull: | B24: Premium apple mix accelerates; GP beats $85m FY27 target; Esro stabilised/exited cleanly; organic 7% fading to 3%; margin to 11.5%; NCI buyouts trim leakage to 35%; terminal 2.5%.
A25: Bear: | B25: Esro losses deepen and exit costs mount; Gabrielle-class Hawke's Bay event hits FY2027 (year-2 revenue -6%, margin 7.8%, leakage spikes to 42% because the weather loss is 100% parent); recovery only to 9.3% margin; CPI growth thereafter.

Sheet DCF_Bear
A1: Bear scenario - all NZ$m; drivers (yellow) in rows 5,7,9,11,16
A3: Year | B3: 2025A | C3: 2026E | D3: 2027E | E3: 2028E | F3: 2029E | G3: 2030E | H3: 2031E | I3: 2032E | J3: 2033E | K3: 2034E | L3: 2035E
A4: Year index | B4: 0 | C4: 1 | D4: 2 | E4: 3 | F4: 4 | G4: 5 | H4: 6 | I4: 7 | J4: 8 | K4: 9 | L4: 10
A5: Revenue growth YoY % | C5: 0.539 | D5: -0.06 | E5: 0.05 | F5: 0.02 | G5: 0.02 | H5: 0.02 | I5: 0.02 | J5: 0.02 | K5: 0.02 | L5: 0.02
A6: Revenue | B6: 899.949 | C6: =B6*(1+C5) | D6: =C6*(1+D5) | E6: =D6*(1+E5) | F6: =E6*(1+F5) | G6: =F6*(1+G5) | H6: =G6*(1+H5) | I6: =H6*(1+I5) | J6: =I6*(1+J5) | ... L6: =K6*(1+L5)
A7: Adj (Underlying) EBITDA margin % | C7: 0.096 | D7: 0.078 | E7: 0.088 | F7: 0.09 | G7: 0.092 | H7: 0.093 | I7: 0.093 | J7: 0.093 | K7: 0.093 | L7: 0.093
A8: Adjusted EBITDA | C8: =C6*C7 | D8: =D6*D7 | E8: =E6*E7 | F8: =F6*F7 | G8: =G6*G7 | H8: =H6*H7 | I8: =I6*I7 | J8: =J6*J7 | ... L8: =L6*L7
A9: SBC % of revenue | C9: 0.001 | D9: 0.001 | E9: 0.001 | F9: 0.001 | G9: 0.001 | H9: 0.001 | I9: 0.001 | J9: 0.001 | K9: 0.001 | L9: 0.001
A10: SBC $ (negative) | C10: =-C6*C9 | D10: =-D6*D9 | E10: =-E6*E9 | F10: =-F6*F9 | G10: =-G6*G9 | H10: =-H6*H9 | I10: =-I6*I9 | J10: =-J6*J9 | ... L10: =-L6*L9
A11: Lease cost % of revenue (principal+interest) | C11: 0.0115 | D11: 0.012 | E11: 0.0115 | F11: 0.0115 | G11: 0.011 | H11: 0.011 | I11: 0.011 | J11: 0.011 | K11: 0.011 | L11: 0.011
A12: Lease payments $ (negative) | C12: =-C6*C11 | D12: =-D6*D11 | E12: =-E6*E11 | F12: =-F6*F11 | G12: =-G6*G11 | H12: =-H6*H11 | I12: =-I6*I11 | J12: =-J6*J11 | ... L12: =-L6*L11
A13: Owner EBITDA after SBC and leases | C13: =C8+C10+C12 | D13: =D8+D10+D12 | E13: =E8+E10+E12 | F13: =F8+F10+F12 | G13: =G8+G10+G12 | H13: =H8+H10+H12 | I13: =I8+I10+I12 | J13: =J8+J10+J12 | ... L13: =L8+L10+L12
A14: D&A ex-ROU (negative) | C14: =-C6*Assumptions!$B$15 | D14: =-D6*Assumptions!$B$15 | E14: =-E6*Assumptions!$B$15 | F14: =-F6*Assumptions!$B$15 | G14: =-G6*Assumptions!$B$15 | H14: =-H6*Assumptions!$B$15 | I14: =-I6*Assumptions!$B$15 | J14: =-J6*Assumptions!$B$15 | ... L14: =-L6*Assumptions!$B$15
A15: EBIT (SBC and leases expensed) | C15: =C13+C14 | D15: =D13+D14 | E15: =E13+E14 | F15: =F13+F14 | G15: =G13+G14 | H15: =H13+H14 | I15: =I13+I14 | J15: =J13+J14 | ... L15: =L13+L14
A16: Combined cash-tax + NCI leakage % of EBIT | C16: 0.37 | D16: 0.42 | E16: 0.39 | F16: 0.385 | G16: 0.38 | H16: 0.38 | I16: 0.38 | J16: 0.38 | K16: 0.38 | L16: 0.38
A17: Attributable NOPAT (unlevered) | C17: =C15-MAX(0,C15)*C16 | D17: =D15-MAX(0,D15)*D16 | E17: =E15-MAX(0,E15)*E16 | F17: =F15-MAX(0,F15)*F16 | G17: =G15-MAX(0,G15)*G16 | H17: =H15-MAX(0,H15)*H16 | I17: =I15-MAX(0,I15)*I16 | J17: =J15-MAX(0,J15)*J16 | ... L17: =L15-MAX(0,L15)*L16
A18: Add back D&A | C18: =-C14 | D18: =-D14 | E18: =-E14 | F18: =-F14 | G18: =-G14 | H18: =-H14 | I18: =-I14 | J18: =-J14 | ... L18: =-L14
A19: Less capex | C19: =-C6*Assumptions!$B$16 | D19: =-D6*Assumptions!$B$16 | E19: =-E6*Assumptions!$B$16 | F19: =-F6*Assumptions!$B$16 | G19: =-G6*Assumptions!$B$16 | H19: =-H6*Assumptions!$B$16 | I19: =-I6*Assumptions!$B$16 | J19: =-J6*Assumptions!$B$16 | ... L19: =-L6*Assumptions!$B$16
A20: Add working capital (on revenue change) | C20: =(C6-B6)*Assumptions!$B$17 | D20: =(D6-C6)*Assumptions!$B$17 | E20: =(E6-D6)*Assumptions!$B$17 | F20: =(F6-E6)*Assumptions!$B$17 | G20: =(G6-F6)*Assumptions!$B$17 | H20: =(H6-G6)*Assumptions!$B$17 | I20: =(I6-H6)*Assumptions!$B$17 | J20: =(J6-I6)*Assumptions!$B$17 | ... L20: =(L6-K6)*Assumptions!$B$17
A21: Unlevered attributable owner FCF | C21: =C17+C18+C19+C20 | D21: =D17+D18+D19+D20 | E21: =E17+E18+E19+E20 | F21: =F17+F18+F19+F20 | G21: =G17+G18+G19+G20 | H21: =H17+H18+H19+H20 | I21: =I17+I18+I19+I20 | J21: =J17+J18+J19+J20 | ... L21: =L17+L18+L19+L20
A22: Discount factor | C22: =1/(1+Assumptions!$B$8)^C4 | D22: =1/(1+Assumptions!$B$8)^D4 | E22: =1/(1+Assumptions!$B$8)^E4 | F22: =1/(1+Assumptions!$B$8)^F4 | G22: =1/(1+Assumptions!$B$8)^G4 | H22: =1/(1+Assumptions!$B$8)^H4 | I22: =1/(1+Assumptions!$B$8)^I4 | J22: =1/(1+Assumptions!$B$8)^J4 | ... L22: =1/(1+Assumptions!$B$8)^L4
A23: PV of FCF | C23: =C21*C22 | D23: =D21*D22 | E23: =E21*E22 | F23: =F21*F22 | G23: =G21*G22 | H23: =H21*H22 | I23: =I21*I22 | J23: =J21*J22 | ... L23: =L21*L22
A25: Memo: FCF before SBC (company-style) | C25: =C21-C10 | D25: =D21-D10 | E25: =E21-E10 | F25: =F21-F10 | G25: =G21-G10 | H25: =H21-H10 | I25: =I21-I10 | J25: =J21-J10 | ... L25: =L21-L10
A26: Memo: implied owner-FCF margin | C26: =C21/C6 | D26: =D21/D6 | E26: =E21/E6 | F26: =F21/F6 | G26: =G21/G6 | H26: =H21/H6 | I26: =I21/I6 | J26: =J21/J6 | ... L26: =L21/L6
A28: Sum of PV of FCF (years 1-10) | B28: =SUM(C23:L23)
A29: Terminal growth | B29: =Assumptions!$B$18
A30: Terminal-year FCF x (1+g) | B30: =L21*(1+B29)
A31: Gordon terminal value | B31: =B30/(Assumptions!$B$8-B29)
A32: Cap terminal value (12x year-10 FCF) | B32: =Assumptions!$B$10*L21
A33: Terminal value used | B33: =MAX(0,MIN(B31,B32))
A34: Implied exit multiple (TV / year-10 FCF) | B34: =B33/L21
A35: PV of terminal value | B35: =B33*L22
A36: Enterprise value | B36: =B28+B35
A37: Less net debt (incl deferred consideration) | B37: =Assumptions!$B$7
A38: Equity value (parent share) | B38: =B36-B37
A39: Diluted shares (m) | B39: =Assumptions!$B$4
A40: VALUE PER SHARE (NZ$) | B40: =B38/B39
A41: Upside vs current price | B41: =B40/Assumptions!$B$3-1
A43: Street memo: PV of explicit-period SBC | B43: =SUMPRODUCT(-C10:L10/(1+Assumptions!$B$8)^C4:L4)
A44: Street memo: PV of terminal SBC | B44: =(-L10)*(1+B29)/(Assumptions!$B$8-B29)*L22
...

Sheet DCF_Base
A1: Base scenario - all NZ$m; drivers (yellow) in rows 5,7,9,11,16
A3: Year | B3: 2025A | C3: 2026E | D3: 2027E | E3: 2028E | F3: 2029E | G3: 2030E | H3: 2031E | I3: 2032E | J3: 2033E | K3: 2034E | L3: 2035E
A4: Year index | B4: 0 | C4: 1 | D4: 2 | E4: 3 | F4: 4 | G4: 5 | H4: 6 | I4: 7 | J4: 8 | K4: 9 | L4: 10
A5: Revenue growth YoY % | C5: 0.556 | D5: 0.045 | E5: 0.04 | F5: 0.04 | G5: 0.035 | H5: 0.03 | I5: 0.03 | J5: 0.025 | K5: 0.025 | L5: 0.025
A6: Revenue | B6: 899.949 | C6: =B6*(1+C5) | D6: =C6*(1+D5) | E6: =D6*(1+E5) | F6: =E6*(1+F5) | G6: =F6*(1+G5) | H6: =G6*(1+H5) | I6: =H6*(1+I5) | J6: =I6*(1+J5) | ... L6: =K6*(1+L5)
A7: Adj (Underlying) EBITDA margin % | C7: 0.099 | D7: 0.101 | E7: 0.1025 | F7: 0.104 | G7: 0.105 | H7: 0.105 | I7: 0.105 | J7: 0.105 | K7: 0.105 | L7: 0.105
A8: Adjusted EBITDA | C8: =C6*C7 | D8: =D6*D7 | E8: =E6*E7 | F8: =F6*F7 | G8: =G6*G7 | H8: =H6*H7 | I8: =I6*I7 | J8: =J6*J7 | ... L8: =L6*L7
A9: SBC % of revenue | C9: 0.001 | D9: 0.001 | E9: 0.001 | F9: 0.001 | G9: 0.001 | H9: 0.001 | I9: 0.001 | J9: 0.001 | K9: 0.001 | L9: 0.001
A10: SBC $ (negative) | C10: =-C6*C9 | D10: =-D6*D9 | E10: =-E6*E9 | F10: =-F6*F9 | G10: =-G6*G9 | H10: =-H6*H9 | I10: =-I6*I9 | J10: =-J6*J9 | ... L10: =-L6*L9
A11: Lease cost % of revenue (principal+interest) | C11: 0.011 | D11: 0.011 | E11: 0.011 | F11: 0.01 | G11: 0.01 | H11: 0.01 | I11: 0.01 | J11: 0.01 | K11: 0.01 | L11: 0.01
A12: Lease payments $ (negative) | C12: =-C6*C11 | D12: =-D6*D11 | E12: =-E6*E11 | F12: =-F6*F11 | G12: =-G6*G11 | H12: =-H6*H11 | I12: =-I6*I11 | J12: =-J6*J11 | ... L12: =-L6*L11
A13: Owner EBITDA after SBC and leases | C13: =C8+C10+C12 | D13: =D8+D10+D12 | E13: =E8+E10+E12 | F13: =F8+F10+F12 | G13: =G8+G10+G12 | H13: =H8+H10+H12 | I13: =I8+I10+I12 | J13: =J8+J10+J12 | ... L13: =L8+L10+L12
A14: D&A ex-ROU (negative) | C14: =-C6*Assumptions!$C$15 | D14: =-D6*Assumptions!$C$15 | E14: =-E6*Assumptions!$C$15 | F14: =-F6*Assumptions!$C$15 | G14: =-G6*Assumptions!$C$15 | H14: =-H6*Assumptions!$C$15 | I14: =-I6*Assumptions!$C$15 | J14: =-J6*Assumptions!$C$15 | ... L14: =-L6*Assumptions!$C$15
A15: EBIT (SBC and leases expensed) | C15: =C13+C14 | D15: =D13+D14 | E15: =E13+E14 | F15: =F13+F14 | G15: =G13+G14 | H15: =H13+H14 | I15: =I13+I14 | J15: =J13+J14 | ... L15: =L13+L14
A16: Combined cash-tax + NCI leakage % of EBIT | C16: 0.363 | D16: 0.365 | E16: 0.365 | F16: 0.365 | G16: 0.37 | H16: 0.37 | I16: 0.37 | J16: 0.37 | K16: 0.37 | L16: 0.37
A17: Attributable NOPAT (unlevered) | C17: =C15-MAX(0,C15)*C16 | D17: =D15-MAX(0,D15)*D16 | E17: =E15-MAX(0,E15)*E16 | F17: =F15-MAX(0,F15)*F16 | G17: =G15-MAX(0,G15)*G16 | H17: =H15-MAX(0,H15)*H16 | I17: =I15-MAX(0,I15)*I16 | J17: =J15-MAX(0,J15)*J16 | ... L17: =L15-MAX(0,L15)*L16
A18: Add back D&A | C18: =-C14 | D18: =-D14 | E18: =-E14 | F18: =-F14 | G18: =-G14 | H18: =-H14 | I18: =-I14 | J18: =-J14 | ... L18: =-L14
A19: Less capex | C19: =-C6*Assumptions!$C$16 | D19: =-D6*Assumptions!$C$16 | E19: =-E6*Assumptions!$C$16 | F19: =-F6*Assumptions!$C$16 | G19: =-G6*Assumptions!$C$16 | H19: =-H6*Assumptions!$C$16 | I19: =-I6*Assumptions!$C$16 | J19: =-J6*Assumptions!$C$16 | ... L19: =-L6*Assumptions!$C$16
A20: Add working capital (on revenue change) | C20: =(C6-B6)*Assumptions!$C$17 | D20: =(D6-C6)*Assumptions!$C$17 | E20: =(E6-D6)*Assumptions!$C$17 | F20: =(F6-E6)*Assumptions!$C$17 | G20: =(G6-F6)*Assumptions!$C$17 | H20: =(H6-G6)*Assumptions!$C$17 | I20: =(I6-H6)*Assumptions!$C$17 | J20: =(J6-I6)*Assumptions!$C$17 | ... L20: =(L6-K6)*Assumptions!$C$17
A21: Unlevered attributable owner FCF | C21: =C17+C18+C19+C20 | D21: =D17+D18+D19+D20 | E21: =E17+E18+E19+E20 | F21: =F17+F18+F19+F20 | G21: =G17+G18+G19+G20 | H21: =H17+H18+H19+H20 | I21: =I17+I18+I19+I20 | J21: =J17+J18+J19+J20 | ... L21: =L17+L18+L19+L20
A22: Discount factor | C22: =1/(1+Assumptions!$B$8)^C4 | D22: =1/(1+Assumptions!$B$8)^D4 | E22: =1/(1+Assumptions!$B$8)^E4 | F22: =1/(1+Assumptions!$B$8)^F4 | G22: =1/(1+Assumptions!$B$8)^G4 | H22: =1/(1+Assumptions!$B$8)^H4 | I22: =1/(1+Assumptions!$B$8)^I4 | J22: =1/(1+Assumptions!$B$8)^J4 | ... L22: =1/(1+Assumptions!$B$8)^L4
A23: PV of FCF | C23: =C21*C22 | D23: =D21*D22 | E23: =E21*E22 | F23: =F21*F22 | G23: =G21*G22 | H23: =H21*H22 | I23: =I21*I22 | J23: =J21*J22 | ... L23: =L21*L22
A25: Memo: FCF before SBC (company-style) | C25: =C21-C10 | D25: =D21-D10 | E25: =E21-E10 | F25: =F21-F10 | G25: =G21-G10 | H25: =H21-H10 | I25: =I21-I10 | J25: =J21-J10 | ... L25: =L21-L10
A26: Memo: implied owner-FCF margin | C26: =C21/C6 | D26: =D21/D6 | E26: =E21/E6 | F26: =F21/F6 | G26: =G21/G6 | H26: =H21/H6 | I26: =I21/I6 | J26: =J21/J6 | ... L26: =L21/L6
A28: Sum of PV of FCF (years 1-10) | B28: =SUM(C23:L23)
A29: Terminal growth | B29: =Assumptions!$C$18
A30: Terminal-year FCF x (1+g) | B30: =L21*(1+B29)
A31: Gordon terminal value | B31: =B30/(Assumptions!$B$8-B29)
A32: Cap terminal value (12x year-10 FCF) | B32: =Assumptions!$B$10*L21
A33: Terminal value used | B33: =MAX(0,MIN(B31,B32))
A34: Implied exit multiple (TV / year-10 FCF) | B34: =B33/L21
A35: PV of terminal value | B35: =B33*L22
A36: Enterprise value | B36: =B28+B35
A37: Less net debt (incl deferred consideration) | B37: =Assumptions!$B$7
A38: Equity value (parent share) | B38: =B36-B37
A39: Diluted shares (m) | B39: =Assumptions!$B$4
A40: VALUE PER SHARE (NZ$) | B40: =B38/B39
A41: Upside vs current price | B41: =B40/Assumptions!$B$3-1
A43: Street memo: PV of explicit-period SBC | B43: =SUMPRODUCT(-C10:L10/(1+Assumptions!$B$8)^C4:L4)
A44: Street memo: PV of terminal SBC | B44: =(-L10)*(1+B29)/(Assumptions!$B$8-B29)*L22
...

Sheet DCF_Bull
A1: Bull scenario - all NZ$m; drivers (yellow) in rows 5,7,9,11,16
A3: Year | B3: 2025A | C3: 2026E | D3: 2027E | E3: 2028E | F3: 2029E | G3: 2030E | H3: 2031E | I3: 2032E | J3: 2033E | K3: 2034E | L3: 2035E
A4: Year index | B4: 0 | C4: 1 | D4: 2 | E4: 3 | F4: 4 | G4: 5 | H4: 6 | I4: 7 | J4: 8 | K4: 9 | L4: 10
A5: Revenue growth YoY % | C5: 0.578 | D5: 0.07 | E5: 0.065 | F5: 0.06 | G5: 0.055 | H5: 0.05 | I5: 0.045 | J5: 0.04 | K5: 0.035 | L5: 0.03
A6: Revenue | B6: 899.949 | C6: =B6*(1+C5) | D6: =C6*(1+D5) | E6: =D6*(1+E5) | F6: =E6*(1+F5) | G6: =F6*(1+G5) | H6: =G6*(1+H5) | I6: =H6*(1+I5) | J6: =I6*(1+J5) | ... L6: =K6*(1+L5)
A7: Adj (Underlying) EBITDA margin % | C7: 0.101 | D7: 0.105 | E7: 0.109 | F7: 0.112 | G7: 0.114 | H7: 0.115 | I7: 0.115 | J7: 0.115 | K7: 0.115 | L7: 0.115
A8: Adjusted EBITDA | C8: =C6*C7 | D8: =D6*D7 | E8: =E6*E7 | F8: =F6*F7 | G8: =G6*G7 | H8: =H6*H7 | I8: =I6*I7 | J8: =J6*J7 | ... L8: =L6*L7
A9: SBC % of revenue | C9: 0.001 | D9: 0.001 | E9: 0.001 | F9: 0.001 | G9: 0.001 | H9: 0.001 | I9: 0.001 | J9: 0.001 | K9: 0.001 | L9: 0.001
A10: SBC $ (negative) | C10: =-C6*C9 | D10: =-D6*D9 | E10: =-E6*E9 | F10: =-F6*F9 | G10: =-G6*G9 | H10: =-H6*H9 | I10: =-I6*I9 | J10: =-J6*J9 | ... L10: =-L6*L9
A11: Lease cost % of revenue (principal+interest) | C11: 0.011 | D11: 0.0105 | E11: 0.01 | F11: 0.01 | G11: 0.01 | H11: 0.01 | I11: 0.01 | J11: 0.01 | K11: 0.01 | L11: 0.01
A12: Lease payments $ (negative) | C12: =-C6*C11 | D12: =-D6*D11 | E12: =-E6*E11 | F12: =-F6*F11 | G12: =-G6*G11 | H12: =-H6*H11 | I12: =-I6*I11 | J12: =-J6*J11 | ... L12: =-L6*L11
A13: Owner EBITDA after SBC and leases | C13: =C8+C10+C12 | D13: =D8+D10+D12 | E13: =E8+E10+E12 | F13: =F8+F10+F12 | G13: =G8+G10+G12 | H13: =H8+H10+H12 | I13: =I8+I10+I12 | J13: =J8+J10+J12 | ... L13: =L8+L10+L12
A14: D&A ex-ROU (negative) | C14: =-C6*Assumptions!$D$15 | D14: =-D6*Assumptions!$D$15 | E14: =-E6*Assumptions!$D$15 | F14: =-F6*Assumptions!$D$15 | G14: =-G6*Assumptions!$D$15 | H14: =-H6*Assumptions!$D$15 | I14: =-I6*Assumptions!$D$15 | J14: =-J6*Assumptions!$D$15 | ... L14: =-L6*Assumptions!$D$15
A15: EBIT (SBC and leases expensed) | C15: =C13+C14 | D15: =D13+D14 | E15: =E13+E14 | F15: =F13+F14 | G15: =G13+G14 | H15: =H13+H14 | I15: =I13+I14 | J15: =J13+J14 | ... L15: =L13+L14
A16: Combined cash-tax + NCI leakage % of EBIT | C16: 0.36 | D16: 0.355 | E16: 0.355 | F16: 0.35 | G16: 0.35 | H16: 0.35 | I16: 0.35 | J16: 0.35 | K16: 0.35 | L16: 0.35
A17: Attributable NOPAT (unlevered) | C17: =C15-MAX(0,C15)*C16 | D17: =D15-MAX(0,D15)*D16 | E17: =E15-MAX(0,E15)*E16 | F17: =F15-MAX(0,F15)*F16 | G17: =G15-MAX(0,G15)*G16 | H17: =H15-MAX(0,H15)*H16 | I17: =I15-MAX(0,I15)*I16 | J17: =J15-MAX(0,J15)*J16 | ... L17: =L15-MAX(0,L15)*L16
A18: Add back D&A | C18: =-C14 | D18: =-D14 | E18: =-E14 | F18: =-F14 | G18: =-G14 | H18: =-H14 | I18: =-I14 | J18: =-J14 | ... L18: =-L14
A19: Less capex | C19: =-C6*Assumptions!$D$16 | D19: =-D6*Assumptions!$D$16 | E19: =-E6*Assumptions!$D$16 | F19: =-F6*Assumptions!$D$16 | G19: =-G6*Assumptions!$D$16 | H19: =-H6*Assumptions!$D$16 | I19: =-I6*Assumptions!$D$16 | J19: =-J6*Assumptions!$D$16 | ... L19: =-L6*Assumptions!$D$16
A20: Add working capital (on revenue change) | C20: =(C6-B6)*Assumptions!$D$17 | D20: =(D6-C6)*Assumptions!$D$17 | E20: =(E6-D6)*Assumptions!$D$17 | F20: =(F6-E6)*Assumptions!$D$17 | G20: =(G6-F6)*Assumptions!$D$17 | H20: =(H6-G6)*Assumptions!$D$17 | I20: =(I6-H6)*Assumptions!$D$17 | J20: =(J6-I6)*Assumptions!$D$17 | ... L20: =(L6-K6)*Assumptions!$D$17
A21: Unlevered attributable owner FCF | C21: =C17+C18+C19+C20 | D21: =D17+D18+D19+D20 | E21: =E17+E18+E19+E20 | F21: =F17+F18+F19+F20 | G21: =G17+G18+G19+G20 | H21: =H17+H18+H19+H20 | I21: =I17+I18+I19+I20 | J21: =J17+J18+J19+J20 | ... L21: =L17+L18+L19+L20
A22: Discount factor | C22: =1/(1+Assumptions!$B$8)^C4 | D22: =1/(1+Assumptions!$B$8)^D4 | E22: =1/(1+Assumptions!$B$8)^E4 | F22: =1/(1+Assumptions!$B$8)^F4 | G22: =1/(1+Assumptions!$B$8)^G4 | H22: =1/(1+Assumptions!$B$8)^H4 | I22: =1/(1+Assumptions!$B$8)^I4 | J22: =1/(1+Assumptions!$B$8)^J4 | ... L22: =1/(1+Assumptions!$B$8)^L4
A23: PV of FCF | C23: =C21*C22 | D23: =D21*D22 | E23: =E21*E22 | F23: =F21*F22 | G23: =G21*G22 | H23: =H21*H22 | I23: =I21*I22 | J23: =J21*J22 | ... L23: =L21*L22
A25: Memo: FCF before SBC (company-style) | C25: =C21-C10 | D25: =D21-D10 | E25: =E21-E10 | F25: =F21-F10 | G25: =G21-G10 | H25: =H21-H10 | I25: =I21-I10 | J25: =J21-J10 | ... L25: =L21-L10
A26: Memo: implied owner-FCF margin | C26: =C21/C6 | D26: =D21/D6 | E26: =E21/E6 | F26: =F21/F6 | G26: =G21/G6 | H26: =H21/H6 | I26: =I21/I6 | J26: =J21/J6 | ... L26: =L21/L6
A28: Sum of PV of FCF (years 1-10) | B28: =SUM(C23:L23)
A29: Terminal growth | B29: =Assumptions!$D$18
A30: Terminal-year FCF x (1+g) | B30: =L21*(1+B29)
A31: Gordon terminal value | B31: =B30/(Assumptions!$B$8-B29)
A32: Cap terminal value (12x year-10 FCF) | B32: =Assumptions!$B$10*L21
A33: Terminal value used | B33: =MAX(0,MIN(B31,B32))
A34: Implied exit multiple (TV / year-10 FCF) | B34: =B33/L21
A35: PV of terminal value | B35: =B33*L22
A36: Enterprise value | B36: =B28+B35
A37: Less net debt (incl deferred consideration) | B37: =Assumptions!$B$7
A38: Equity value (parent share) | B38: =B36-B37
A39: Diluted shares (m) | B39: =Assumptions!$B$4
A40: VALUE PER SHARE (NZ$) | B40: =B38/B39
A41: Upside vs current price | B41: =B40/Assumptions!$B$3-1
A43: Street memo: PV of explicit-period SBC | B43: =SUMPRODUCT(-C10:L10/(1+Assumptions!$B$8)^C4:L4)
A44: Street memo: PV of terminal SBC | B44: =(-L10)*(1+B29)/(Assumptions!$B$8-B29)*L22
...

Sheet FCF_Quality
A1: Reported FCF reconciled to owner FCF (NZ$m). Lease treatment B: full lease payment deducted; lease liabilities excluded from net debt.
A3: Line | B3: FY2019 | C3: FY2020 | D3: FY2021 | E3: FY2022 | F3: FY2023 | G3: FY2024 | H3: FY2025
A4: Free cash flow (company definition: OCF - capex) | B4: 39.786 | C4: 28.987 | D4: 24.017 | E4: 30.273 | F4: 47.892 | G4: 43.124 | H4: 74.862
A5: less: SBC (cash-flow add-back; no equity-tax line disclosed) | B5: 1 | C5: 0.698 | D5: 0.726 | E5: 0.609 | F5: 0.456 | G5: 0.71 | H5: 1.169
A6: less: lease principal repayments | B6: 6.459 | C6: 7.3 | D6: 7.839 | E6: 8.281 | F6: 8.42 | G6: 9.075 | H6: 8.464
A7: less: interest on lease liabilities | B7: 3.075 | C7: 2.981 | D7: 2.964 | E7: 2.953 | F7: 3.144 | G7: 3.774 | H7: 4.74
A8: Owner FCF | B8: =B4-B5-B6-B7 | C8: =C4-C5-C6-C7 | D8: =D4-D5-D6-D7 | E8: =E4-E5-E6-E7 | F8: =F4-F5-F6-F7 | G8: =G4-G5-G6-G7 | H8: =H4-H5-H6-H7
A9: Revenue | B9: 484.609 | C9: 470.709 | D9: 514.551 | E9: 619.173 | F9: 565.356 | G9: 584.627 | H9: 899.949
A10: Reported FCF margin | B10: =B4/B9 | C10: =C4/C9 | D10: =D4/D9 | E10: =E4/E9 | F10: =F4/F9 | G10: =G4/G9 | H10: =H4/H9
A11: Owner FCF margin | B11: =B8/B9 | C11: =C8/C9 | D11: =D8/D9 | E11: =E8/E9 | F11: =F8/F9 | G11: =G8/G9 | H11: =H8/H9
A13: Memo: interest income NOT stripped (company carries net debt; flows are unlevered). FY2025 interest received 2.602.
A14: Memo: FY2025 income tax paid 10.113 on 137.6 underlying EBITDA - low effective cash tax reflects flow-through US LLC (Shelby) and imputation structures; leakage driver ramps it up 1pt over the horizon.
A15: Memo: FY2024 capex 54.4 includes the Bostock orchard purchase; FY2025 capex 20.9 is the cleaner maintenance+growth base.

Sheet Valuation
A1: Valuation summary (NZ$ per share)
A3: Scenario | B3: Bear | C3: Base | D3: Bull
A4: Value per share (house basis) | B4: =DCF_Bear!$B$40 | C4: =DCF_Base!$B$40 | D4: =DCF_Bull!$B$40
A5: Upside vs price | B5: =DCF_Bear!$B$40/Assumptions!$B$3-1 | C5: =DCF_Base!$B$40/Assumptions!$B$3-1 | D5: =DCF_Bull!$B$40/Assumptions!$B$3-1
A6: Probability weight | B6: =Assumptions!$B$19 | C6: =Assumptions!$C$19 | D6: =Assumptions!$D$19
A7: Street value per share (SBC non-cash) | B7: =DCF_Bear!$B$45 | C7: =DCF_Base!$B$45 | D7: =DCF_Bull!$B$45
A9: Probability-weighted value | B9: =SUMPRODUCT(B4:D4,B6:D6)
A10: Margin of safety at current price | B10: =1-Assumptions!$B$3/B9
A11: Street probability-weighted value | B11: =SUMPRODUCT(B7:D7,B6:D6)
A12: Band position note: house/street band collapses (SBC ~0.1% of revenue); band position not meaningful (n/a).
A14: Entry price at 15% hurdle (TV at WACC, discounted at hurdle)
A15: Entry price per scenario | B15: =(SUMPRODUCT(DCF_Bear!C21:L21/(1+Assumptions!$B$9)^DCF_Bear!C4:L4)+DCF_Bear!$B$33/(1+Assumptions!$B$9)^10-Assumptions!$B$7)/Assumptions!$B$4 | C15: =(SUMPRODUCT(DCF_Base!C21:L21/(1+Assumptions!$B$9)^DCF_Base!C4:L4)+DCF_Base!$B$33/(1+Assumptions!$B$9)^10-Assumptions!$B$7)/Assumptions!$B$4 | D15: =(SUMPRODUCT(DCF_Bull!C21:L21/(1+Assumptions!$B$9)^DCF_Bull!C4:L4)+DCF_Bull!$B$33/(1+Assumptions!$B$9)^10-Assumptions!$B$7)/Assumptions!$B$4
A16: Probability-weighted entry price | B16: =SUMPRODUCT(B15:D15,B6:D6)
A18: Required-return table (base case; Gordon TV at r, cap 12x)
A19: Required return | B19: 0.09 | C19: 0.1 | D19: 0.11 | E19: 0.115 | F19: 0.12 | G19: 0.15
A20: Value per share | B20: =(SUMPRODUCT(DCF_Base!C21:L21/(1+B19)^DCF_Base!C4:L4)+MAX(0,MIN(DCF_Base!L21*(1+DCF_Base!$B$29)/(B19-DCF_Base!$B$29),Assumptions!$B$10*DCF_Base!L21))/(1+B19)^10-Assumptions!$B$7)/Assumptions!$B$4 | C20: =(SUMPRODUCT(DCF_Base!C21:L21/(1+C19)^DCF_Base!C4:L4)+MAX(0,MIN(DCF_Base!L21*(1+DCF_Base!$B$29)/(C19-DCF_Base!$B$29),Assumptions!$B$10*DCF_Base!L21))/(1+C19)^10-Assumptions!$B$7)/Assumptions!$B$4 | D20: =(SUMPRODUCT(DCF_Base!C21:L21/(1+D19)^DCF_Base!C4:L4)+MAX(0,MIN(DCF_Base!L21*(1+DCF_Base!$B$29)/(D19-DCF_Base!$B$29),Assumptions!$B$10*DCF_Base!L21))/(1+D19)^10-Assumptions!$B$7)/Assumptions!$B$4 | E20: =(SUMPRODUCT(DCF_Base!C21:L21/(1+E19)^DCF_Base!C4:L4)+MAX(0,MIN(DCF_Base!L21*(1+DCF_Base!$B$29)/(E19-DCF_Base!$B$29),Assumptions!$B$10*DCF_Base!L21))/(1+E19)^10-Assumptions!$B$7)/Assumptions!$B$4 | F20: =(SUMPRODUCT(DCF_Base!C21:L21/(1+F19)^DCF_Base!C4:L4)+MAX(0,MIN(DCF_Base!L21*(1+DCF_Base!$B$29)/(F19-DCF_Base!$B$29),Assumptions!$B$10*DCF_Base!L21))/(1+F19)^10-Assumptions!$B$7)/Assumptions!$B$4 | G20: =(SUMPRODUCT(DCF_Base!C21:L21/(1+G19)^DCF_Base!C4:L4)+MAX(0,MIN(DCF_Base!L21*(1+DCF_Base!$B$29)/(G19-DCF_Base!$B$29),Assumptions!$B$10*DCF_Base!L21))/(1+G19)^10-Assumptions!$B$7)/Assumptions!$B$4
A21: Note: 11.5% column is the model WACC; the current NZ$7.10 price implies a required return of ~7.5% on base-case flows.
A23: Sensitivity: value per share, WACC (rows) x terminal growth (cols), base case
B24: 0.01 | C24: 0.015 | D24: 0.02 | E24: 0.025 | F24: 0.03
A25: 0.095 | B25: =IF($A25>B$24,(SUMPRODUCT(DCF_Base!C21:L21/(1+$A25)^DCF_Base!C4:L4)+MAX(0,MIN(DCF_Base!L21*(1+B$24)/($A25-B$24),Assumptions!$B$10*DCF_Base!L21))/(1+$A25)^10-Assumptions!$B$7)/Assumptions!$B$4,"n/a") | C25: =IF($A25>C$24,(SUMPRODUCT(DCF_Base!C21:L21/(1+$A25)^DCF_Base!C4:L4)+MAX(0,MIN(DCF_Base!L21*(1+C$24)/($A25-C$24),Assumptions!$B$10*DCF_Base!L21))/(1+$A25)^10-Assumptions!$B$7)/Assumptions!$B$4,"n/a") | D25: =IF($A25>D$24,(SUMPRODUCT(DCF_Base!C21:L21/(1+$A25)^DCF_Base!C4:L4)+MAX(0,MIN(DCF_Base!L21*(1+D$24)/($A25-D$24),Assumptions!$B$10*DCF_Base!L21))/(1+$A25)^10-Assumptions!$B$7)/Assumptions!$B$4,"n/a") | E25: =IF($A25>E$24,(SUMPRODUCT(DCF_Base!C21:L21/(1+$A25)^DCF_Base!C4:L4)+MAX(0,MIN(DCF_Base!L21*(1+E$24)/($A25-E$24),Assumptions!$B$10*DCF_Base!L21))/(1+$A25)^10-Assumptions!$B$7)/Assumptions!$B$4,"n/a") | F25: =IF($A25>F$24,(SUMPRODUCT(DCF_Base!C21:L21/(1+$A25)^DCF_Base!C4:L4)+MAX(0,MIN(DCF_Base!L21*(1+F$24)/($A25-F$24),Assumptions!$B$10*DCF_Base!L21))/(1+$A25)^10-Assumptions!$B$7)/Assumptions!$B$4,"n/a")
A26: 0.105 | B26: =IF($A26>B$24,(SUMPRODUCT(DCF_Base!C21:L21/(1+$A26)^DCF_Base!C4:L4)+MAX(0,MIN(DCF_Base!L21*(1+B$24)/($A26-B$24),Assumptions!$B$10*DCF_Base!L21))/(1+$A26)^10-Assumptions!$B$7)/Assumptions!$B$4,"n/a") | C26: =IF($A26>C$24,(SUMPRODUCT(DCF_Base!C21:L21/(1+$A26)^DCF_Base!C4:L4)+MAX(0,MIN(DCF_Base!L21*(1+C$24)/($A26-C$24),Assumptions!$B$10*DCF_Base!L21))/(1+$A26)^10-Assumptions!$B$7)/Assumptions!$B$4,"n/a") | D26: =IF($A26>D$24,(SUMPRODUCT(DCF_Base!C21:L21/(1+$A26)^DCF_Base!C4:L4)+MAX(0,MIN(DCF_Base!L21*(1+D$24)/($A26-D$24),Assumptions!$B$10*DCF_Base!L21))/(1+$A26)^10-Assumptions!$B$7)/Assumptions!$B$4,"n/a") | E26: =IF($A26>E$24,(SUMPRODUCT(DCF_Base!C21:L21/(1+$A26)^DCF_Base!C4:L4)+MAX(0,MIN(DCF_Base!L21*(1+E$24)/($A26-E$24),Assumptions!$B$10*DCF_Base!L21))/(1+$A26)^10-Assumptions!$B$7)/Assumptions!$B$4,"n/a") | F26: =IF($A26>F$24,(SUMPRODUCT(DCF_Base!C21:L21/(1+$A26)^DCF_Base!C4:L4)+MAX(0,MIN(DCF_Base!L21*(1+F$24)/($A26-F$24),Assumptions!$B$10*DCF_Base!L21))/(1+$A26)^10-Assumptions!$B$7)/Assumptions!$B$4,"n/a")
A27: 0.115 | B27: =IF($A27>B$24,(SUMPRODUCT(DCF_Base!C21:L21/(1+$A27)^DCF_Base!C4:L4)+MAX(0,MIN(DCF_Base!L21*(1+B$24)/($A27-B$24),Assumptions!$B$10*DCF_Base!L21))/(1+$A27)^10-Assumptions!$B$7)/Assumptions!$B$4,"n/a") | C27: =IF($A27>C$24,(SUMPRODUCT(DCF_Base!C21:L21/(1+$A27)^DCF_Base!C4:L4)+MAX(0,MIN(DCF_Base!L21*(1+C$24)/($A27-C$24),Assumptions!$B$10*DCF_Base!L21))/(1+$A27)^10-Assumptions!$B$7)/Assumptions!$B$4,"n/a") | D27: =IF($A27>D$24,(SUMPRODUCT(DCF_Base!C21:L21/(1+$A27)^DCF_Base!C4:L4)+MAX(0,MIN(DCF_Base!L21*(1+D$24)/($A27-D$24),Assumptions!$B$10*DCF_Base!L21))/(1+$A27)^10-Assumptions!$B$7)/Assumptions!$B$4,"n/a") | E27: =IF($A27>E$24,(SUMPRODUCT(DCF_Base!C21:L21/(1+$A27)^DCF_Base!C4:L4)+MAX(0,MIN(DCF_Base!L21*(1+E$24)/($A27-E$24),Assumptions!$B$10*DCF_Base!L21))/(1+$A27)^10-Assumptions!$B$7)/Assumptions!$B$4,"n/a") | F27: =IF($A27>F$24,(SUMPRODUCT(DCF_Base!C21:L21/(1+$A27)^DCF_Base!C4:L4)+MAX(0,MIN(DCF_Base!L21*(1+F$24)/($A27-F$24),Assumptions!$B$10*DCF_Base!L21))/(1+$A27)^10-Assumptions!$B$7)/Assumptions!$B$4,"n/a")
A28: 0.125 | B28: =IF($A28>B$24,(SUMPRODUCT(DCF_Base!C21:L21/(1+$A28)^DCF_Base!C4:L4)+MAX(0,MIN(DCF_Base!L21*(1+B$24)/($A28-B$24),Assumptions!$B$10*DCF_Base!L21))/(1+$A28)^10-Assumptions!$B$7)/Assumptions!$B$4,"n/a") | C28: =IF($A28>C$24,(SUMPRODUCT(DCF_Base!C21:L21/(1+$A28)^DCF_Base!C4:L4)+MAX(0,MIN(DCF_Base!L21*(1+C$24)/($A28-C$24),Assumptions!$B$10*DCF_Base!L21))/(1+$A28)^10-Assumptions!$B$7)/Assumptions!$B$4,"n/a") | D28: =IF($A28>D$24,(SUMPRODUCT(DCF_Base!C21:L21/(1+$A28)^DCF_Base!C4:L4)+MAX(0,MIN(DCF_Base!L21*(1+D$24)/($A28-D$24),Assumptions!$B$10*DCF_Base!L21))/(1+$A28)^10-Assumptions!$B$7)/Assumptions!$B$4,"n/a") | E28: =IF($A28>E$24,(SUMPRODUCT(DCF_Base!C21:L21/(1+$A28)^DCF_Base!C4:L4)+MAX(0,MIN(DCF_Base!L21*(1+E$24)/($A28-E$24),Assumptions!$B$10*DCF_Base!L21))/(1+$A28)^10-Assumptions!$B$7)/Assumptions!$B$4,"n/a") | F28: =IF($A28>F$24,(SUMPRODUCT(DCF_Base!C21:L21/(1+$A28)^DCF_Base!C4:L4)+MAX(0,MIN(DCF_Base!L21*(1+F$24)/($A28-F$24),Assumptions!$B$10*DCF_Base!L21))/(1+$A28)^10-Assumptions!$B$7)/Assumptions!$B$4,"n/a")
A29: 0.135 | B29: =IF($A29>B$24,(SUMPRODUCT(DCF_Base!C21:L21/(1+$A29)^DCF_Base!C4:L4)+MAX(0,MIN(DCF_Base!L21*(1+B$24)/($A29-B$24),Assumptions!$B$10*DCF_Base!L21))/(1+$A29)^10-Assumptions!$B$7)/Assumptions!$B$4,"n/a") | C29: =IF($A29>C$24,(SUMPRODUCT(DCF_Base!C21:L21/(1+$A29)^DCF_Base!C4:L4)+MAX(0,MIN(DCF_Base!L21*(1+C$24)/($A29-C$24),Assumptions!$B$10*DCF_Base!L21))/(1+$A29)^10-Assumptions!$B$7)/Assumptions!$B$4,"n/a") | D29: =IF($A29>D$24,(SUMPRODUCT(DCF_Base!C21:L21/(1+$A29)^DCF_Base!C4:L4)+MAX(0,MIN(DCF_Base!L21*(1+D$24)/($A29-D$24),Assumptions!$B$10*DCF_Base!L21))/(1+$A29)^10-Assumptions!$B$7)/Assumptions!$B$4,"n/a") | E29: =IF($A29>E$24,(SUMPRODUCT(DCF_Base!C21:L21/(1+$A29)^DCF_Base!C4:L4)+MAX(0,MIN(DCF_Base!L21*(1+E$24)/($A29-E$24),Assumptions!$B$10*DCF_Base!L21))/(1+$A29)^10-Assumptions!$B$7)/Assumptions!$B$4,"n/a") | F29: =IF($A29>F$24,(SUMPRODUCT(DCF_Base!C21:L21/(1+$A29)^DCF_Base!C4:L4)+MAX(0,MIN(DCF_Base!L21*(1+F$24)/($A29-F$24),Assumptions!$B$10*DCF_Base!L21))/(1+$A29)^10-Assumptions!$B$7)/Assumptions!$B$4,"n/a")
