Workbook

Sheet Assumptions
A1: PCT.NZ — Precinct Properties: Blended AFFO-Capitalization / NTA Valuation Model
A2: REIT model at COST OF EQUITY — NOT a WACC owner-FCF DCF. AFFO is an equity-level, post-interest flow; net debt is NEVER deducted. Final IV = 50/50 blend of (1) AFFO capitalization with exit-AFFO-yield terminal value and (2) NTA leg (PV dividends + PV year-5 NTA x exit P/NTA).
A3: Cell colour key: YELLOW = hardcoded input (tie to PCT.NZ_DCF.json) | BLUE = live formula | GREEN = key output. Per-security flows in NZD CENTS; intrinsic values in NZD DOLLARS — units labelled on every row.
A5: GENERAL INPUTS | B5: Value | F5: Note / source
A6: Ticker | B6: PCT.NZ | F6: Precinct Properties New Zealand — stapled security (PPNZ + PPIL), NZX premium CBD office REIT
A7: Valuation date | B7: 2026-08-24 | F7: Fresh build 24-Aug-2026; FY2026 result due 27-Aug-2026 is the imminent swing factor
A8: Current price (NZD per security) | B8: 1.03 | F8: NZX close Fri 21-Aug-2026 (Yahoo regularMarketTime 2026-08-21T04:59:51Z)
A9: Stapled securities on issue (millions) | B9: 1852.8 | F9: 31-Dec-2025 balance sheet, post Oct/Nov-2025 $325m raise (1,587.0m -> 1,852.8m). Held FLAT across projection
A10: NTA per security (NZD) | B10: 1.18 | F10: 31-Dec-2025 (H1 FY2026)
A11: Net debt (NZ$ millions) — MEMO ONLY | B11: 1503.1 | F11: AUDIT LINE ONLY — NEVER DEDUCTED. AFFO is post-interest (equity-level); subtracting net debt would double-count leverage. Total debt 1,528.7 less cash 25.6 at 31-Dec-2025
A12: FY2025 AFFO per security (NZD cents) | B12: 6.54 | F12: Company-disclosed AFFO (FFO less maintenance capex and incentives), FY2025
A13: TTM AFFO per security (NZD cents) | B13: 6.07 | F13: FY2025 6.54 + H1 FY2026 2.76 - H1 FY2025 3.23; depressed by the raise (capital in the count, earnings not yet)
A14: FY2026 FFO guidance (NZD cents) | B14: 7.30-7.50 | F14: Management guidance, reaffirmed at H1 FY2026
A15: FY2026 DPS guidance (NZD cents) | B15: 6.75 | F15: Dividend has exceeded AFFO every year since FY2021 (103% of FY2025 AFFO)
A16: Entry-price hurdle rate | B16: 0.15 | F16: House 15% IRR hurdle (post-2026-07-21 entry-price formula)
A18: COST OF EQUITY BUILD (base scenario) | B18: Value | F18: Note
A19: Risk-free rate (NZ 10yr govt) | B19: 0.046 | F19: NZ 10-year ~4.5-4.7%; RBNZ raised the OCR to 2.50% Jul-2026 — long end biased up
A20: Equity risk premium | B20: 0.06 | F20: Standard NZ ERP
A21: Beta | B21: 0.8 | F21: NZ listed-property beta <1.0 (contracted rent, 97% occupancy, 6.1yr WALT) but elevated by 33.7% gearing + pure-play office
A22: CAPM base | B22: =B19+B21*B20 | F22: = rf + beta x ERP = 9.40%
A23: Office structural premium | B23: 0.0035 | F23: Only NZX pure-play premium CBD office REIT — hybrid-work / structural demand risk peers don't carry
A24: Wellington government premium | B24: 0.0025 | F24: ~25-30% Wellington weighting vs public service targeted to shrink ~14% by Jul-2029; ~172,000 sqm govt leases expire 2026-28
A25: Development execution premium | B25: 0.0025 | F25: Downtown Car Park (still consenting, ~50% NLA in pre-commitment talks) + 1,602-bed student accommodation pipeline
A26: Gearing / refinancing premium | B26: 0 | F26: 33.7% pro forma LVR mid-band; ~2.8yr debt maturity captured in beta and the bear scenario, not double-charged
A27: Illiquidity premium | B27: 0 | F27: NZ$1.9bn market cap, S&P/NZX 20 constituent — none
A28: BASE COST OF EQUITY | B28: =B22+SUM(B23:B27) | F28: = 10.25%. Cost of EQUITY, not WACC — debt cost already inside AFFO. Built in NZD off NZ rf, matching NZD flows and quote
A30: SCENARIO PARAMETERS | C30: Bear | D30: Base | E30: Bull | F30: Note
A31: Cost of equity | C31: 0.115 | D31: =B28 | E31: 0.095 | F31: Base = CoE build above; bull 9.5% (easing resumes); bear 11.5% (renewed hikes + Wellington stress)
A32: FY2026 AFFO anchor (NZD cents/security) | C32: 6.1 | D32: 6.4 | E32: 6.6 | F32: Base 6.40 = H1 actual 2.76 + guided H2 skew at ~88% AFFO/FFO conversion vs 7.30-7.50 FFO guidance
A33: AFFO growth FY2027 | C33: -0.03 | D33: 0.015 | E33: 0.03 | F33: J-curve: $325m raise deploys through FY2028-29; base fades to +2.0% terminal
A34: AFFO growth FY2028 | C34: -0.02 | D34: 0.03 | E34: 0.045
A35: AFFO growth FY2029 | C35: 0 | D35: 0.03 | E35: 0.045
A36: AFFO growth FY2030 | C36: 0.005 | D36: 0.025 | E36: 0.04
A37: AFFO growth FY2031 | C37: 0.005 | D37: 0.02 | E37: 0.035
A38: Exit AFFO yield (terminal) | C38: 0.075 | D38: 0.065 | E38: 0.0575 | F38: Base 6.5% = 15.4x — below the entire 18.1-24.7x traded FY2021-25 range (conservative)
A39: NTA growth (%/yr) | C39: -0.025 | D39: 0.01 | E39: 0.025 | F39: Base +1.0%/yr: broadly stable cap rates, PwC JV at book, modest development margin
A40: Exit P/NTA multiple | C40: 0.75 | D40: 0.9 | E40: 1.05 | F40: 10yr FY-end average ~1.02x (range 0.87-1.21x); base 0.90x = partial, not full, closure of the current 0.87x discount
A41: DPS FY2027 (NZD cents/security) | C41: 6.75 | D41: 6.75 | E41: 6.75 | F41: Base holds 6.75 flat (uncovered vs AFFO until ~FY2029); bear cuts to 5.5 from FY2028
A42: DPS FY2028 (NZD cents/security) | C42: 5.5 | D42: 6.75 | E42: 6.85
A43: DPS FY2029 (NZD cents/security) | C43: 5.5 | D43: 6.75 | E43: 7
...

Sheet AFFO Leg
B1: AFFO CAPITALIZATION LEG — company-disclosed AFFO per stapled security, capitalized at COST OF EQUITY
B2: AFFO is POST-INTEREST (equity-level). Terminal value = year-5 AFFO / exit AFFO yield (capped multiple, no Gordon growth). NET DEBT IS NOT DEDUCTED anywhere on this sheet.
B4: BASE SCENARIO | C4: CoE = 10.25%
B5: Fiscal year | C5: FY2027 | D5: FY2028 | E5: FY2029 | F5: FY2030 | G5: FY2031
B6: AFFO per security (NZD cents) | C6: =Assumptions!$D$32*(1+Assumptions!$D$33) | D6: =C6*(1+Assumptions!$D$34) | E6: =D6*(1+Assumptions!$D$35) | F6: =E6*(1+Assumptions!$D$36) | G6: =F6*(1+Assumptions!$D$37)
B7: AFFO total (NZ$ millions) | C7: =C6*Assumptions!$B$9/100 | D7: =D6*Assumptions!$B$9/100 | E7: =E6*Assumptions!$B$9/100 | F7: =F6*Assumptions!$B$9/100 | G7: =G6*Assumptions!$B$9/100
B8: Discount factor @ cost of equity | C8: =1/(1+Assumptions!$D$31)^1 | D8: =1/(1+Assumptions!$D$31)^2 | E8: =1/(1+Assumptions!$D$31)^3 | F8: =1/(1+Assumptions!$D$31)^4 | G8: =1/(1+Assumptions!$D$31)^5
B9: PV of AFFO (NZD cents) | C9: =C6*C8 | D9: =D6*D8 | E9: =E6*E8 | F9: =F6*F8 | G9: =G6*G8
B10: Sum PV AFFO FY2027-31 (NZD cents) | C10: =SUM(C9:G9)
B11: Terminal AFFO = year-5 AFFO (NZD cents) | C11: =G6
B12: Exit AFFO yield | C12: =Assumptions!$D$38
B13: Implied exit P/AFFO multiple (x) | C13: =1/C12
B14: Terminal value (NZD cents) | C14: =C11/C12
B15: PV of terminal value (NZD cents) | C15: =C14*G8
B16: Intrinsic value (NZD cents) | C16: =C10+C15
B17: INTRINSIC VALUE (NZD per security) | C17: =C16/100
B18: Terminal % of leg value | C18: =C15/C16
B19: Memo: net debt NZ$1,503.1m NOT deducted — AFFO is post-interest | C19: =Assumptions!$B$11
B22: BULL SCENARIO | C22: CoE = 9.50%
B23: Fiscal year | C23: FY2027 | D23: FY2028 | E23: FY2029 | F23: FY2030 | G23: FY2031
B24: AFFO per security (NZD cents) | C24: =Assumptions!$E$32*(1+Assumptions!$E$33) | D24: =C24*(1+Assumptions!$E$34) | E24: =D24*(1+Assumptions!$E$35) | F24: =E24*(1+Assumptions!$E$36) | G24: =F24*(1+Assumptions!$E$37)
B25: AFFO total (NZ$ millions) | C25: =C24*Assumptions!$B$9/100 | D25: =D24*Assumptions!$B$9/100 | E25: =E24*Assumptions!$B$9/100 | F25: =F24*Assumptions!$B$9/100 | G25: =G24*Assumptions!$B$9/100
B26: Discount factor @ cost of equity | C26: =1/(1+Assumptions!$E$31)^1 | D26: =1/(1+Assumptions!$E$31)^2 | E26: =1/(1+Assumptions!$E$31)^3 | F26: =1/(1+Assumptions!$E$31)^4 | G26: =1/(1+Assumptions!$E$31)^5
B27: PV of AFFO (NZD cents) | C27: =C24*C26 | D27: =D24*D26 | E27: =E24*E26 | F27: =F24*F26 | G27: =G24*G26
B28: Sum PV AFFO FY2027-31 (NZD cents) | C28: =SUM(C27:G27)
B29: Terminal AFFO = year-5 AFFO (NZD cents) | C29: =G24
B30: Exit AFFO yield | C30: =Assumptions!$E$38
B31: Implied exit P/AFFO multiple (x) | C31: =1/C30
B32: Terminal value (NZD cents) | C32: =C29/C30
B33: PV of terminal value (NZD cents) | C33: =C32*G26
B34: Intrinsic value (NZD cents) | C34: =C28+C33
B35: INTRINSIC VALUE (NZD per security) | C35: =C34/100
B36: Terminal % of leg value | C36: =C33/C34
B37: Memo: net debt NZ$1,503.1m NOT deducted — AFFO is post-interest | C37: =Assumptions!$B$11
B40: BEAR SCENARIO | C40: CoE = 11.50%
B41: Fiscal year | C41: FY2027 | D41: FY2028 | E41: FY2029 | F41: FY2030 | G41: FY2031
B42: AFFO per security (NZD cents) | C42: =Assumptions!$C$32*(1+Assumptions!$C$33) | D42: =C42*(1+Assumptions!$C$34) | E42: =D42*(1+Assumptions!$C$35) | F42: =E42*(1+Assumptions!$C$36) | G42: =F42*(1+Assumptions!$C$37)
B43: AFFO total (NZ$ millions) | C43: =C42*Assumptions!$B$9/100 | D43: =D42*Assumptions!$B$9/100 | E43: =E42*Assumptions!$B$9/100 | F43: =F42*Assumptions!$B$9/100 | G43: =G42*Assumptions!$B$9/100
B44: Discount factor @ cost of equity | C44: =1/(1+Assumptions!$C$31)^1 | D44: =1/(1+Assumptions!$C$31)^2 | E44: =1/(1+Assumptions!$C$31)^3 | F44: =1/(1+Assumptions!$C$31)^4 | G44: =1/(1+Assumptions!$C$31)^5
B45: PV of AFFO (NZD cents) | C45: =C42*C44 | D45: =D42*D44 | E45: =E42*E44 | F45: =F42*F44 | G45: =G42*G44
...

Sheet NTA Leg
B1: NTA LEG — PV of interim cash dividends + PV of year-5 NTA x justified exit P/NTA
B2: NTA is post-debt equity book value — no net-debt deduction. Discounted at the same scenario cost of equity as the AFFO leg.
B4: BASE SCENARIO | C4: CoE = 10.25%
B5: Fiscal year | C5: FY2027 | D5: FY2028 | E5: FY2029 | F5: FY2030 | G5: FY2031
B6: DPS (NZD cents/security) | C6: =Assumptions!$D$41 | D6: =Assumptions!$D$42 | E6: =Assumptions!$D$43 | F6: =Assumptions!$D$44 | G6: =Assumptions!$D$45
B7: Discount factor @ cost of equity | C7: =1/(1+Assumptions!$D$31)^1 | D7: =1/(1+Assumptions!$D$31)^2 | E7: =1/(1+Assumptions!$D$31)^3 | F7: =1/(1+Assumptions!$D$31)^4 | G7: =1/(1+Assumptions!$D$31)^5
B8: PV of DPS (NZD cents) | C8: =C6*C7 | D8: =D6*D7 | E8: =E6*E7 | F8: =F6*F7 | G8: =G6*G7
B9: NTA per security (NZD) | C9: =Assumptions!$B$10*(1+Assumptions!$D$39) | D9: =C9*(1+Assumptions!$D$39) | E9: =D9*(1+Assumptions!$D$39) | F9: =E9*(1+Assumptions!$D$39) | G9: =F9*(1+Assumptions!$D$39)
B10: Sum PV dividends FY2027-31 (NZD cents) | C10: =SUM(C8:G8)
B11: Year-5 NTA per security (NZD) | C11: =G9
B12: Exit P/NTA multiple (x) | C12: =Assumptions!$D$40
B13: Year-5 exit value (NZD/security) | C13: =C11*C12
B14: PV of exit value (NZD/security) | C14: =C13*G7
B15: INTRINSIC VALUE (NZD per security) | C15: =C10/100+C14
B16: No net-debt deduction — NTA is already post-debt equity book value.
B19: BULL SCENARIO | C19: CoE = 9.50%
B20: Fiscal year | C20: FY2027 | D20: FY2028 | E20: FY2029 | F20: FY2030 | G20: FY2031
B21: DPS (NZD cents/security) | C21: =Assumptions!$E$41 | D21: =Assumptions!$E$42 | E21: =Assumptions!$E$43 | F21: =Assumptions!$E$44 | G21: =Assumptions!$E$45
B22: Discount factor @ cost of equity | C22: =1/(1+Assumptions!$E$31)^1 | D22: =1/(1+Assumptions!$E$31)^2 | E22: =1/(1+Assumptions!$E$31)^3 | F22: =1/(1+Assumptions!$E$31)^4 | G22: =1/(1+Assumptions!$E$31)^5
B23: PV of DPS (NZD cents) | C23: =C21*C22 | D23: =D21*D22 | E23: =E21*E22 | F23: =F21*F22 | G23: =G21*G22
B24: NTA per security (NZD) | C24: =Assumptions!$B$10*(1+Assumptions!$E$39) | D24: =C24*(1+Assumptions!$E$39) | E24: =D24*(1+Assumptions!$E$39) | F24: =E24*(1+Assumptions!$E$39) | G24: =F24*(1+Assumptions!$E$39)
B25: Sum PV dividends FY2027-31 (NZD cents) | C25: =SUM(C23:G23)
B26: Year-5 NTA per security (NZD) | C26: =G24
B27: Exit P/NTA multiple (x) | C27: =Assumptions!$E$40
B28: Year-5 exit value (NZD/security) | C28: =C26*C27
B29: PV of exit value (NZD/security) | C29: =C28*G22
B30: INTRINSIC VALUE (NZD per security) | C30: =C25/100+C29
B31: No net-debt deduction — NTA is already post-debt equity book value.
B34: BEAR SCENARIO | C34: CoE = 11.50%
B35: Fiscal year | C35: FY2027 | D35: FY2028 | E35: FY2029 | F35: FY2030 | G35: FY2031
B36: DPS (NZD cents/security) | C36: =Assumptions!$C$41 | D36: =Assumptions!$C$42 | E36: =Assumptions!$C$43 | F36: =Assumptions!$C$44 | G36: =Assumptions!$C$45
B37: Discount factor @ cost of equity | C37: =1/(1+Assumptions!$C$31)^1 | D37: =1/(1+Assumptions!$C$31)^2 | E37: =1/(1+Assumptions!$C$31)^3 | F37: =1/(1+Assumptions!$C$31)^4 | G37: =1/(1+Assumptions!$C$31)^5
B38: PV of DPS (NZD cents) | C38: =C36*C37 | D38: =D36*D37 | E38: =E36*E37 | F38: =F36*F37 | G38: =G36*G37
B39: NTA per security (NZD) | C39: =Assumptions!$B$10*(1+Assumptions!$C$39) | D39: =C39*(1+Assumptions!$C$39) | E39: =D39*(1+Assumptions!$C$39) | F39: =E39*(1+Assumptions!$C$39) | G39: =F39*(1+Assumptions!$C$39)
B40: Sum PV dividends FY2027-31 (NZD cents) | C40: =SUM(C38:G38)
B41: Year-5 NTA per security (NZD) | C41: =G39
B42: Exit P/NTA multiple (x) | C42: =Assumptions!$C$40
B43: Year-5 exit value (NZD/security) | C43: =C41*C42
B44: PV of exit value (NZD/security) | C44: =C43*G37
B45: INTRINSIC VALUE (NZD per security) | C45: =C40/100+C44
...

Sheet Blend & Scenarios
A1: BLENDED INTRINSIC VALUE — 50/50 AFFO-capitalization leg / NTA leg
A3: Scenario | B3: AFFO leg IV (NZD) | C3: NTA leg IV (NZD) | D3: Blended IV (NZD) | E3: Upside vs price | F3: Probability weight
A5: AFFO leg weight | B5: 0.5
A6: NTA leg weight | B6: 0.5
A8: Bear | B8: ='AFFO Leg'!C53 | C8: ='NTA Leg'!C45 | D8: =$B$5*B8+$B$6*C8 | E8: =D8/Assumptions!$B$8-1 | F8: =Assumptions!$C$46
A9: Base | B9: ='AFFO Leg'!C17 | C9: ='NTA Leg'!C15 | D9: =$B$5*B9+$B$6*C9 | E9: =D9/Assumptions!$B$8-1 | F9: =Assumptions!$D$46
A10: Bull | B10: ='AFFO Leg'!C35 | C10: ='NTA Leg'!C30 | D10: =$B$5*B10+$B$6*C10 | E10: =D10/Assumptions!$B$8-1 | F10: =Assumptions!$E$46
A12: PROBABILITY-WEIGHTED IV (NZD per security) | D12: =SUMPRODUCT(D8:D10,F8:F10) | E12: =D12/Assumptions!$B$8-1 | G12: JSON probability_weighted.weighted_iv = 0.9263 (-10.1% vs $1.03). Weights 25/50/25 — see Assumptions row 46 rationale.
A15: AUDIT / CROSS-CHECKS (memo only)
A16: Net debt (NZ$m) — NOT deducted anywhere | B16: =Assumptions!B11 | G16: AFFO is post-interest and NTA is post-debt; deducting net debt would double-count leverage (classic REIT error).
A17: Zero-growth AFFO perpetuity floor (NZD) | B17: =Assumptions!D32/Assumptions!D31/100 | G17: FY2026e AFFO 6.40 cps / 10.25% CoE = $0.6244 — all scenario IVs sit above this floor.
A18: NTA per security anchor (NZD) | B18: =Assumptions!B10 | G18: PCT traded 0.92-1.21x NTA FY2017-25 (avg ~1.02x); NTA is a genuine central anchor, not just a ceiling.
A19: Current price implied P/NTA (x) | B19: =Assumptions!B8/Assumptions!B10 | G19: 0.873x — the cheapest P/NTA in Precinct's listed history.
A20: Base blended IV implied P/NTA (x) | B20: =D9/Assumptions!B10 | G20: ~0.80x — below every FY-end observation in the 10-year history: conservative by construction.
A21: Current price AFFO yield, TTM | B21: =Assumptions!B13/100/Assumptions!B8 | G21: 5.89% TTM AFFO yield / 16.97x P/AFFO at $1.03.
A22: Current price dividend yield | B22: =Assumptions!B15/100/Assumptions!B8 | G22: 6.55% on the 6.75 cps guided DPS — which exceeds AFFO (uncovered).

Sheet Sensitivity
B1: SENSITIVITY — AFFO-capitalization leg only, base AFFO path held constant (NZD per security)
B2: Rows = cost of equity; columns = exit AFFO yield. Live formulas over the base AFFO path on 'AFFO Leg'. Matches the JSON sensitivity matrix.
B4: CoE \ Exit AFFO yield | C4: 0.055 | D4: 0.06 | E4: 0.065 | F4: 0.07 | G4: 0.075
B5: 0.0825 | C5: =('AFFO Leg'!$C$6/(1+$B5)^1+'AFFO Leg'!$D$6/(1+$B5)^2+'AFFO Leg'!$E$6/(1+$B5)^3+'AFFO Leg'!$F$6/(1+$B5)^4+'AFFO Leg'!$G$6/(1+$B5)^5+('AFFO Leg'!$G$6/C$4)/(1+$B5)^5)/100 | D5: =('AFFO Leg'!$C$6/(1+$B5)^1+'AFFO Leg'!$D$6/(1+$B5)^2+'AFFO Leg'!$E$6/(1+$B5)^3+'AFFO Leg'!$F$6/(1+$B5)^4+'AFFO Leg'!$G$6/(1+$B5)^5+('AFFO Leg'!$G$6/D$4)/(1+$B5)^5)/100 | E5: =('AFFO Leg'!$C$6/(1+$B5)^1+'AFFO Leg'!$D$6/(1+$B5)^2+'AFFO Leg'!$E$6/(1+$B5)^3+'AFFO Leg'!$F$6/(1+$B5)^4+'AFFO Leg'!$G$6/(1+$B5)^5+('AFFO Leg'!$G$6/E$4)/(1+$B5)^5)/100 | F5: =('AFFO Leg'!$C$6/(1+$B5)^1+'AFFO Leg'!$D$6/(1+$B5)^2+'AFFO Leg'!$E$6/(1+$B5)^3+'AFFO Leg'!$F$6/(1+$B5)^4+'AFFO Leg'!$G$6/(1+$B5)^5+('AFFO Leg'!$G$6/F$4)/(1+$B5)^5)/100 | G5: =('AFFO Leg'!$C$6/(1+$B5)^1+'AFFO Leg'!$D$6/(1+$B5)^2+'AFFO Leg'!$E$6/(1+$B5)^3+'AFFO Leg'!$F$6/(1+$B5)^4+'AFFO Leg'!$G$6/(1+$B5)^5+('AFFO Leg'!$G$6/G$4)/(1+$B5)^5)/100
B6: 0.0925 | C6: =('AFFO Leg'!$C$6/(1+$B6)^1+'AFFO Leg'!$D$6/(1+$B6)^2+'AFFO Leg'!$E$6/(1+$B6)^3+'AFFO Leg'!$F$6/(1+$B6)^4+'AFFO Leg'!$G$6/(1+$B6)^5+('AFFO Leg'!$G$6/C$4)/(1+$B6)^5)/100 | D6: =('AFFO Leg'!$C$6/(1+$B6)^1+'AFFO Leg'!$D$6/(1+$B6)^2+'AFFO Leg'!$E$6/(1+$B6)^3+'AFFO Leg'!$F$6/(1+$B6)^4+'AFFO Leg'!$G$6/(1+$B6)^5+('AFFO Leg'!$G$6/D$4)/(1+$B6)^5)/100 | E6: =('AFFO Leg'!$C$6/(1+$B6)^1+'AFFO Leg'!$D$6/(1+$B6)^2+'AFFO Leg'!$E$6/(1+$B6)^3+'AFFO Leg'!$F$6/(1+$B6)^4+'AFFO Leg'!$G$6/(1+$B6)^5+('AFFO Leg'!$G$6/E$4)/(1+$B6)^5)/100 | F6: =('AFFO Leg'!$C$6/(1+$B6)^1+'AFFO Leg'!$D$6/(1+$B6)^2+'AFFO Leg'!$E$6/(1+$B6)^3+'AFFO Leg'!$F$6/(1+$B6)^4+'AFFO Leg'!$G$6/(1+$B6)^5+('AFFO Leg'!$G$6/F$4)/(1+$B6)^5)/100 | G6: =('AFFO Leg'!$C$6/(1+$B6)^1+'AFFO Leg'!$D$6/(1+$B6)^2+'AFFO Leg'!$E$6/(1+$B6)^3+'AFFO Leg'!$F$6/(1+$B6)^4+'AFFO Leg'!$G$6/(1+$B6)^5+('AFFO Leg'!$G$6/G$4)/(1+$B6)^5)/100
B7: 0.1025 | C7: =('AFFO Leg'!$C$6/(1+$B7)^1+'AFFO Leg'!$D$6/(1+$B7)^2+'AFFO Leg'!$E$6/(1+$B7)^3+'AFFO Leg'!$F$6/(1+$B7)^4+'AFFO Leg'!$G$6/(1+$B7)^5+('AFFO Leg'!$G$6/C$4)/(1+$B7)^5)/100 | D7: =('AFFO Leg'!$C$6/(1+$B7)^1+'AFFO Leg'!$D$6/(1+$B7)^2+'AFFO Leg'!$E$6/(1+$B7)^3+'AFFO Leg'!$F$6/(1+$B7)^4+'AFFO Leg'!$G$6/(1+$B7)^5+('AFFO Leg'!$G$6/D$4)/(1+$B7)^5)/100 | E7: =('AFFO Leg'!$C$6/(1+$B7)^1+'AFFO Leg'!$D$6/(1+$B7)^2+'AFFO Leg'!$E$6/(1+$B7)^3+'AFFO Leg'!$F$6/(1+$B7)^4+'AFFO Leg'!$G$6/(1+$B7)^5+('AFFO Leg'!$G$6/E$4)/(1+$B7)^5)/100 | F7: =('AFFO Leg'!$C$6/(1+$B7)^1+'AFFO Leg'!$D$6/(1+$B7)^2+'AFFO Leg'!$E$6/(1+$B7)^3+'AFFO Leg'!$F$6/(1+$B7)^4+'AFFO Leg'!$G$6/(1+$B7)^5+('AFFO Leg'!$G$6/F$4)/(1+$B7)^5)/100 | G7: =('AFFO Leg'!$C$6/(1+$B7)^1+'AFFO Leg'!$D$6/(1+$B7)^2+'AFFO Leg'!$E$6/(1+$B7)^3+'AFFO Leg'!$F$6/(1+$B7)^4+'AFFO Leg'!$G$6/(1+$B7)^5+('AFFO Leg'!$G$6/G$4)/(1+$B7)^5)/100
B8: 0.1125 | C8: =('AFFO Leg'!$C$6/(1+$B8)^1+'AFFO Leg'!$D$6/(1+$B8)^2+'AFFO Leg'!$E$6/(1+$B8)^3+'AFFO Leg'!$F$6/(1+$B8)^4+'AFFO Leg'!$G$6/(1+$B8)^5+('AFFO Leg'!$G$6/C$4)/(1+$B8)^5)/100 | D8: =('AFFO Leg'!$C$6/(1+$B8)^1+'AFFO Leg'!$D$6/(1+$B8)^2+'AFFO Leg'!$E$6/(1+$B8)^3+'AFFO Leg'!$F$6/(1+$B8)^4+'AFFO Leg'!$G$6/(1+$B8)^5+('AFFO Leg'!$G$6/D$4)/(1+$B8)^5)/100 | E8: =('AFFO Leg'!$C$6/(1+$B8)^1+'AFFO Leg'!$D$6/(1+$B8)^2+'AFFO Leg'!$E$6/(1+$B8)^3+'AFFO Leg'!$F$6/(1+$B8)^4+'AFFO Leg'!$G$6/(1+$B8)^5+('AFFO Leg'!$G$6/E$4)/(1+$B8)^5)/100 | F8: =('AFFO Leg'!$C$6/(1+$B8)^1+'AFFO Leg'!$D$6/(1+$B8)^2+'AFFO Leg'!$E$6/(1+$B8)^3+'AFFO Leg'!$F$6/(1+$B8)^4+'AFFO Leg'!$G$6/(1+$B8)^5+('AFFO Leg'!$G$6/F$4)/(1+$B8)^5)/100 | G8: =('AFFO Leg'!$C$6/(1+$B8)^1+'AFFO Leg'!$D$6/(1+$B8)^2+'AFFO Leg'!$E$6/(1+$B8)^3+'AFFO Leg'!$F$6/(1+$B8)^4+'AFFO Leg'!$G$6/(1+$B8)^5+('AFFO Leg'!$G$6/G$4)/(1+$B8)^5)/100
B9: 0.1225 | C9: =('AFFO Leg'!$C$6/(1+$B9)^1+'AFFO Leg'!$D$6/(1+$B9)^2+'AFFO Leg'!$E$6/(1+$B9)^3+'AFFO Leg'!$F$6/(1+$B9)^4+'AFFO Leg'!$G$6/(1+$B9)^5+('AFFO Leg'!$G$6/C$4)/(1+$B9)^5)/100 | D9: =('AFFO Leg'!$C$6/(1+$B9)^1+'AFFO Leg'!$D$6/(1+$B9)^2+'AFFO Leg'!$E$6/(1+$B9)^3+'AFFO Leg'!$F$6/(1+$B9)^4+'AFFO Leg'!$G$6/(1+$B9)^5+('AFFO Leg'!$G$6/D$4)/(1+$B9)^5)/100 | E9: =('AFFO Leg'!$C$6/(1+$B9)^1+'AFFO Leg'!$D$6/(1+$B9)^2+'AFFO Leg'!$E$6/(1+$B9)^3+'AFFO Leg'!$F$6/(1+$B9)^4+'AFFO Leg'!$G$6/(1+$B9)^5+('AFFO Leg'!$G$6/E$4)/(1+$B9)^5)/100 | F9: =('AFFO Leg'!$C$6/(1+$B9)^1+'AFFO Leg'!$D$6/(1+$B9)^2+'AFFO Leg'!$E$6/(1+$B9)^3+'AFFO Leg'!$F$6/(1+$B9)^4+'AFFO Leg'!$G$6/(1+$B9)^5+('AFFO Leg'!$G$6/F$4)/(1+$B9)^5)/100 | G9: =('AFFO Leg'!$C$6/(1+$B9)^1+'AFFO Leg'!$D$6/(1+$B9)^2+'AFFO Leg'!$E$6/(1+$B9)^3+'AFFO Leg'!$F$6/(1+$B9)^4+'AFFO Leg'!$G$6/(1+$B9)^5+('AFFO Leg'!$G$6/G$4)/(1+$B9)^5)/100
B11: Green cell = base case (10.25% CoE, 6.5% exit yield) -> $0.9379, the AFFO-leg base IV.

Sheet Entry Price
B1: ENTRY PRICE — 15% IRR hurdle on the base-case AFFO-capitalization leg
B2: Interim AFFO and the exit terminal value discounted at the hurdle rate. TV computed at the base-case 6.5% exit AFFO yield (what a buyer pays at exit). No net-debt adjustment — AFFO is post-interest. (IPL.NZ template, post-2026-07-21 formula.)
B4: Hurdle rate | C4: =Assumptions!B16
B5: Fiscal year | C5: FY2027 | D5: FY2028 | E5: FY2029 | F5: FY2030 | G5: FY2031
B6: Base AFFO per security (NZD cents) | C6: ='AFFO Leg'!C6 | D6: ='AFFO Leg'!D6 | E6: ='AFFO Leg'!E6 | F6: ='AFFO Leg'!F6 | G6: ='AFFO Leg'!G6
B7: PV @ hurdle (NZD cents) | C7: =C6/(1+$C$4)^1 | D7: =D6/(1+$C$4)^2 | E7: =E6/(1+$C$4)^3 | F7: =F6/(1+$C$4)^4 | G7: =G6/(1+$C$4)^5
B9: Sum PV interim AFFO @ hurdle (NZD cents) | C9: =SUM(C7:G7)
B10: Terminal value at 6.5% exit AFFO yield (NZD cents) | C10: ='AFFO Leg'!C14
B11: PV terminal @ hurdle (NZD cents) | C11: =C10/(1+$C$4)^5
B12: ENTRY PRICE (NZD per security) | C12: =(C9+C11)/100
B13: Discount from current price | C13: =C12/Assumptions!B8-1
B15: JSON entry_price.base: entry $0.7797, -24.3% below the $1.03 price. A buyer at $0.78 earns ~15%/yr on the base AFFO path.
