Workbook

Sheet DCF Model
A1: TWR.NZ - Tower Limited — Book Value Compounding Model (Base Case)
A2: Gray cells are INPUTS. Insurer model: BVPS x ROE path, dividends at payout ratio, exit P/B at cost of equity. NOT an FCF DCF. NZD.
A4: KEY INPUTS
A5: Current Stock Price (NZD) | B5: 1.965
A6: Shares (diluted, M) | B6: 346.46767
A7: Shares on issue (M) | B7: 343.41135
A8: Equity 31-Mar-2026 (NZ$M) | B8: 318.068
A9: H2 FY26 reported NPAT est (NZ$M) | B9: 18
A10: FY26 interim dividend (NZ$/sh) | B10: 0.05
A11: Cash (NZ$M) | B11: 95.611
A12: Fixed-interest investments (NZ$M) | B12: 325.896
A13: Lease liabilities (NZ$M) - not deducted | B13: 23.287
A14: Starting BVPS FY26E (30-Sep-2026) | B14: =(B8+B9-B10*B7)/B6
A15: Reported BVPS 31-Mar-2026 (diluted) | B15: =B8/B6
A17: Cost of Equity (Base) | B17: 0.11
A18: Exit Price-to-Book (Base) | B18: 1.6
A19: Payout ratio of reported NPAT (Base) | B19: 0.7
A21: ROE PATH (reported NPAT / opening equity)
B22: FY2027 | C22: FY2028 | D22: FY2029 | E22: FY2030 | F22: FY2031
A23: ROE | B23: 0.16 | C23: 0.17 | D23: 0.17 | E23: 0.165 | F23: 0.16
A25: PROJECTIONS
B26: FY26E | C26: FY2027 | D26: FY2028 | E26: FY2029 | F26: FY2030 | G26: FY2031
A27: Opening BVPS | C27: =B30 | D27: =C30 | E27: =D30 | F27: =E30 | G27: =F30
A28: EPS (= opening BVPS x ROE) | C28: =C27*B23 | D28: =D27*C23 | E28: =E27*D23 | F28: =F27*E23 | G28: =G27*F23
A29: Dividend per share | C29: =C28*$B$19 | D29: =D28*$B$19 | E29: =E28*$B$19 | F29: =F28*$B$19 | G29: =G28*$B$19
A30: Closing BVPS | B30: =B14 | C30: =C27+C28-C29 | D30: =D27+D28-D29 | E30: =E27+E28-E29 | F30: =F27+F28-F29 | G30: =G27+G28-G29
A31: Discount factor | C31: =1/(1+$B$17)^1 | D31: =1/(1+$B$17)^2 | E31: =1/(1+$B$17)^3 | F31: =1/(1+$B$17)^4 | G31: =1/(1+$B$17)^5
A32: PV of dividend | C32: =C29*C31 | D32: =D29*D31 | E32: =E29*E31 | F32: =F29*F31 | G32: =G29*G31
A34: VALUATION
A35: Sum of PV of dividends | B35: =SUM(C32:G32)
A36: Terminal BVPS (Year 5) | B36: =G30
A37: Exit P/B | B37: =B18
A38: Terminal value per share | B38: =B36*B37
A39: PV of terminal value | B39: =B38*G31
A40: INTRINSIC VALUE / SHARE | B40: =B35+B39
A41: Upside / (downside) vs price | B41: =(B40-B5)/B5
A42: Implied P/B on reported BVPS | B42: =B40/B15
A43: Implied P/E on FY27 EPS | B43: =B40/C28
A45: ENTRY PRICE (15% CAGR target)
A46: Target CAGR | B46: 0.15
...

Sheet Bull-Bear Scenarios
A1: Bull / Bear scenario detail
A3: BULL CASE
A4: Cost of equity | B4: 0.1
A5: Exit P/B | B5: 2.1
A6: Payout ratio | B6: 0.7
B7: FY2027 | C7: FY2028 | D7: FY2029 | E7: FY2030 | F7: FY2031
A8: ROE | B8: 0.19 | C8: 0.21 | D8: 0.21 | E8: 0.2 | F8: 0.2
B9: FY26E | C9: FY2027 | D9: FY2028 | E9: FY2029 | F9: FY2030 | G9: FY2031
A10: Opening BVPS | C10: =B13 | D10: =C13 | E10: =D13 | F10: =E13 | G10: =F13
A11: EPS | C11: =C10*B8 | D11: =D10*C8 | E11: =E10*D8 | F11: =F10*E8 | G11: =G10*F8
A12: Dividend per share | C12: =C11*$B$6 | D12: =D11*$B$6 | E12: =E11*$B$6 | F12: =F11*$B$6 | G12: =G11*$B$6
A13: Closing BVPS | B13: ='DCF Model'!B14 | C13: =C10+C11-C12 | D13: =D10+D11-D12 | E13: =E10+E11-E12 | F13: =F10+F11-F12 | G13: =G10+G11-G12
A14: Discount factor | C14: =1/(1+$B$4)^1 | D14: =1/(1+$B$4)^2 | E14: =1/(1+$B$4)^3 | F14: =1/(1+$B$4)^4 | G14: =1/(1+$B$4)^5
A15: PV of dividend | C15: =C12*C14 | D15: =D12*D14 | E15: =E12*E14 | F15: =F12*F14 | G15: =G12*G14
A17: Sum PV dividends | B17: =SUM(C15:G15)
A18: Terminal value per share | B18: =G13*B5
A19: PV terminal value | B19: =B18*G14
A20: INTRINSIC VALUE / SHARE | B20: =B17+B19
A21: Entry price (15%) | B21: =(B18+C12*(1+'DCF Model'!$B$46)^4+D12*(1+'DCF Model'!$B$46)^3+E12*(1+'DCF Model'!$B$46)^2+F12*(1+'DCF Model'!$B$46)+G12)/(1+'DCF Model'!$B$46)^5
A22: BEAR CASE
A23: Cost of equity | B23: 0.125
A24: Exit P/B | B24: 0.9
A25: Payout ratio | B25: 0.6
B26: FY2027 | C26: FY2028 | D26: FY2029 | E26: FY2030 | F26: FY2031
A27: ROE | B27: 0.08 | C27: 0.1 | D27: 0.11 | E27: 0.11 | F27: 0.11
B28: FY26E | C28: FY2027 | D28: FY2028 | E28: FY2029 | F28: FY2030 | G28: FY2031
A29: Opening BVPS | C29: =B32 | D29: =C32 | E29: =D32 | F29: =E32 | G29: =F32
A30: EPS | C30: =C29*B27 | D30: =D29*C27 | E30: =E29*D27 | F30: =F29*E27 | G30: =G29*F27
A31: Dividend per share | C31: =C30*$B$25 | D31: =D30*$B$25 | E31: =E30*$B$25 | F31: =F30*$B$25 | G31: =G30*$B$25
A32: Closing BVPS | B32: ='DCF Model'!B14 | C32: =C29+C30-C31 | D32: =D29+D30-D31 | E32: =E29+E30-E31 | F32: =F29+F30-F31 | G32: =G29+G30-G31
A33: Discount factor | C33: =1/(1+$B$23)^1 | D33: =1/(1+$B$23)^2 | E33: =1/(1+$B$23)^3 | F33: =1/(1+$B$23)^4 | G33: =1/(1+$B$23)^5
A34: PV of dividend | C34: =C31*C33 | D34: =D31*D33 | E34: =E31*E33 | F34: =F31*F33 | G34: =G31*G33
A36: Sum PV dividends | B36: =SUM(C34:G34)
A37: Terminal value per share | B37: =G32*B24
A38: PV terminal value | B38: =B37*G33
A39: INTRINSIC VALUE / SHARE | B39: =B36+B38
A40: Entry price (15%) | B40: =(B37+C31*(1+'DCF Model'!$B$46)^4+D31*(1+'DCF Model'!$B$46)^3+E31*(1+'DCF Model'!$B$46)^2+F31*(1+'DCF Model'!$B$46)+G31)/(1+'DCF Model'!$B$46)^5
A42: PROBABILITY WEIGHTED
A43: Weight bear | B43: 0.2
A44: Weight base | B44: 0.5
...

Sheet Sensitivity
A1: Intrinsic value / share: cost of equity (rows) x exit P/B (columns), base ROE path
A3: CoE \ Exit P/B | B3: 1.2 | C3: 1.4 | D3: 1.6 | E3: 1.8 | F3: 2
A4: 0.09 | B4: =('DCF Model'!C$29/(1+0.09)^1+'DCF Model'!D$29/(1+0.09)^2+'DCF Model'!E$29/(1+0.09)^3+'DCF Model'!F$29/(1+0.09)^4+'DCF Model'!G$29/(1+0.09)^5)+((((('DCF Model'!$B$14*(1+'DCF Model'!B$23*(1-'DCF Model'!$B$19)))*(1+'DCF Model'!C$23*(1-'DCF Model'!$B$19)))*(1+'DCF Model'!D$23*(1-'DCF Model'!$B$19)))*(1+'DCF Model'!E$23*(1-'DCF Model'!$B$19)))*(1+'DCF Model'!F$23*(1-'DCF Model'!$B$19)))*B$3/(1+0.09)^5 | C4: =('DCF Model'!C$29/(1+0.09)^1+'DCF Model'!D$29/(1+0.09)^2+'DCF Model'!E$29/(1+0.09)^3+'DCF Model'!F$29/(1+0.09)^4+'DCF Model'!G$29/(1+0.09)^5)+((((('DCF Model'!$B$14*(1+'DCF Model'!B$23*(1-'DCF Model'!$B$19)))*(1+'DCF Model'!C$23*(1-'DCF Model'!$B$19)))*(1+'DCF Model'!D$23*(1-'DCF Model'!$B$19)))*(1+'DCF Model'!E$23*(1-'DCF Model'!$B$19)))*(1+'DCF Model'!F$23*(1-'DCF Model'!$B$19)))*C$3/(1+0.09)^5 | D4: =('DCF Model'!C$29/(1+0.09)^1+'DCF Model'!D$29/(1+0.09)^2+'DCF Model'!E$29/(1+0.09)^3+'DCF Model'!F$29/(1+0.09)^4+'DCF Model'!G$29/(1+0.09)^5)+((((('DCF Model'!$B$14*(1+'DCF Model'!B$23*(1-'DCF Model'!$B$19)))*(1+'DCF Model'!C$23*(1-'DCF Model'!$B$19)))*(1+'DCF Model'!D$23*(1-'DCF Model'!$B$19)))*(1+'DCF Model'!E$23*(1-'DCF Model'!$B$19)))*(1+'DCF Model'!F$23*(1-'DCF Model'!$B$19)))*D$3/(1+0.09)^5 | E4: =('DCF Model'!C$29/(1+0.09)^1+'DCF Model'!D$29/(1+0.09)^2+'DCF Model'!E$29/(1+0.09)^3+'DCF Model'!F$29/(1+0.09)^4+'DCF Model'!G$29/(1+0.09)^5)+((((('DCF Model'!$B$14*(1+'DCF Model'!B$23*(1-'DCF Model'!$B$19)))*(1+'DCF Model'!C$23*(1-'DCF Model'!$B$19)))*(1+'DCF Model'!D$23*(1-'DCF Model'!$B$19)))*(1+'DCF Model'!E$23*(1-'DCF Model'!$B$19)))*(1+'DCF Model'!F$23*(1-'DCF Model'!$B$19)))*E$3/(1+0.09)^5 | F4: =('DCF Model'!C$29/(1+0.09)^1+'DCF Model'!D$29/(1+0.09)^2+'DCF Model'!E$29/(1+0.09)^3+'DCF Model'!F$29/(1+0.09)^4+'DCF Model'!G$29/(1+0.09)^5)+((((('DCF Model'!$B$14*(1+'DCF Model'!B$23*(1-'DCF Model'!$B$19)))*(1+'DCF Model'!C$23*(1-'DCF Model'!$B$19)))*(1+'DCF Model'!D$23*(1-'DCF Model'!$B$19)))*(1+'DCF Model'!E$23*(1-'DCF Model'!$B$19)))*(1+'DCF Model'!F$23*(1-'DCF Model'!$B$19)))*F$3/(1+0.09)^5
A5: 0.1 | B5: =('DCF Model'!C$29/(1+0.1)^1+'DCF Model'!D$29/(1+0.1)^2+'DCF Model'!E$29/(1+0.1)^3+'DCF Model'!F$29/(1+0.1)^4+'DCF Model'!G$29/(1+0.1)^5)+((((('DCF Model'!$B$14*(1+'DCF Model'!B$23*(1-'DCF Model'!$B$19)))*(1+'DCF Model'!C$23*(1-'DCF Model'!$B$19)))*(1+'DCF Model'!D$23*(1-'DCF Model'!$B$19)))*(1+'DCF Model'!E$23*(1-'DCF Model'!$B$19)))*(1+'DCF Model'!F$23*(1-'DCF Model'!$B$19)))*B$3/(1+0.1)^5 | C5: =('DCF Model'!C$29/(1+0.1)^1+'DCF Model'!D$29/(1+0.1)^2+'DCF Model'!E$29/(1+0.1)^3+'DCF Model'!F$29/(1+0.1)^4+'DCF Model'!G$29/(1+0.1)^5)+((((('DCF Model'!$B$14*(1+'DCF Model'!B$23*(1-'DCF Model'!$B$19)))*(1+'DCF Model'!C$23*(1-'DCF Model'!$B$19)))*(1+'DCF Model'!D$23*(1-'DCF Model'!$B$19)))*(1+'DCF Model'!E$23*(1-'DCF Model'!$B$19)))*(1+'DCF Model'!F$23*(1-'DCF Model'!$B$19)))*C$3/(1+0.1)^5 | D5: =('DCF Model'!C$29/(1+0.1)^1+'DCF Model'!D$29/(1+0.1)^2+'DCF Model'!E$29/(1+0.1)^3+'DCF Model'!F$29/(1+0.1)^4+'DCF Model'!G$29/(1+0.1)^5)+((((('DCF Model'!$B$14*(1+'DCF Model'!B$23*(1-'DCF Model'!$B$19)))*(1+'DCF Model'!C$23*(1-'DCF Model'!$B$19)))*(1+'DCF Model'!D$23*(1-'DCF Model'!$B$19)))*(1+'DCF Model'!E$23*(1-'DCF Model'!$B$19)))*(1+'DCF Model'!F$23*(1-'DCF Model'!$B$19)))*D$3/(1+0.1)^5 | E5: =('DCF Model'!C$29/(1+0.1)^1+'DCF Model'!D$29/(1+0.1)^2+'DCF Model'!E$29/(1+0.1)^3+'DCF Model'!F$29/(1+0.1)^4+'DCF Model'!G$29/(1+0.1)^5)+((((('DCF Model'!$B$14*(1+'DCF Model'!B$23*(1-'DCF Model'!$B$19)))*(1+'DCF Model'!C$23*(1-'DCF Model'!$B$19)))*(1+'DCF Model'!D$23*(1-'DCF Model'!$B$19)))*(1+'DCF Model'!E$23*(1-'DCF Model'!$B$19)))*(1+'DCF Model'!F$23*(1-'DCF Model'!$B$19)))*E$3/(1+0.1)^5 | F5: =('DCF Model'!C$29/(1+0.1)^1+'DCF Model'!D$29/(1+0.1)^2+'DCF Model'!E$29/(1+0.1)^3+'DCF Model'!F$29/(1+0.1)^4+'DCF Model'!G$29/(1+0.1)^5)+((((('DCF Model'!$B$14*(1+'DCF Model'!B$23*(1-'DCF Model'!$B$19)))*(1+'DCF Model'!C$23*(1-'DCF Model'!$B$19)))*(1+'DCF Model'!D$23*(1-'DCF Model'!$B$19)))*(1+'DCF Model'!E$23*(1-'DCF Model'!$B$19)))*(1+'DCF Model'!F$23*(1-'DCF Model'!$B$19)))*F$3/(1+0.1)^5
A6: 0.11 | B6: =('DCF Model'!C$29/(1+0.11)^1+'DCF Model'!D$29/(1+0.11)^2+'DCF Model'!E$29/(1+0.11)^3+'DCF Model'!F$29/(1+0.11)^4+'DCF Model'!G$29/(1+0.11)^5)+((((('DCF Model'!$B$14*(1+'DCF Model'!B$23*(1-'DCF Model'!$B$19)))*(1+'DCF Model'!C$23*(1-'DCF Model'!$B$19)))*(1+'DCF Model'!D$23*(1-'DCF Model'!$B$19)))*(1+'DCF Model'!E$23*(1-'DCF Model'!$B$19)))*(1+'DCF Model'!F$23*(1-'DCF Model'!$B$19)))*B$3/(1+0.11)^5 | C6: =('DCF Model'!C$29/(1+0.11)^1+'DCF Model'!D$29/(1+0.11)^2+'DCF Model'!E$29/(1+0.11)^3+'DCF Model'!F$29/(1+0.11)^4+'DCF Model'!G$29/(1+0.11)^5)+((((('DCF Model'!$B$14*(1+'DCF Model'!B$23*(1-'DCF Model'!$B$19)))*(1+'DCF Model'!C$23*(1-'DCF Model'!$B$19)))*(1+'DCF Model'!D$23*(1-'DCF Model'!$B$19)))*(1+'DCF Model'!E$23*(1-'DCF Model'!$B$19)))*(1+'DCF Model'!F$23*(1-'DCF Model'!$B$19)))*C$3/(1+0.11)^5 | D6: =('DCF Model'!C$29/(1+0.11)^1+'DCF Model'!D$29/(1+0.11)^2+'DCF Model'!E$29/(1+0.11)^3+'DCF Model'!F$29/(1+0.11)^4+'DCF Model'!G$29/(1+0.11)^5)+((((('DCF Model'!$B$14*(1+'DCF Model'!B$23*(1-'DCF Model'!$B$19)))*(1+'DCF Model'!C$23*(1-'DCF Model'!$B$19)))*(1+'DCF Model'!D$23*(1-'DCF Model'!$B$19)))*(1+'DCF Model'!E$23*(1-'DCF Model'!$B$19)))*(1+'DCF Model'!F$23*(1-'DCF Model'!$B$19)))*D$3/(1+0.11)^5 | E6: =('DCF Model'!C$29/(1+0.11)^1+'DCF Model'!D$29/(1+0.11)^2+'DCF Model'!E$29/(1+0.11)^3+'DCF Model'!F$29/(1+0.11)^4+'DCF Model'!G$29/(1+0.11)^5)+((((('DCF Model'!$B$14*(1+'DCF Model'!B$23*(1-'DCF Model'!$B$19)))*(1+'DCF Model'!C$23*(1-'DCF Model'!$B$19)))*(1+'DCF Model'!D$23*(1-'DCF Model'!$B$19)))*(1+'DCF Model'!E$23*(1-'DCF Model'!$B$19)))*(1+'DCF Model'!F$23*(1-'DCF Model'!$B$19)))*E$3/(1+0.11)^5 | F6: =('DCF Model'!C$29/(1+0.11)^1+'DCF Model'!D$29/(1+0.11)^2+'DCF Model'!E$29/(1+0.11)^3+'DCF Model'!F$29/(1+0.11)^4+'DCF Model'!G$29/(1+0.11)^5)+((((('DCF Model'!$B$14*(1+'DCF Model'!B$23*(1-'DCF Model'!$B$19)))*(1+'DCF Model'!C$23*(1-'DCF Model'!$B$19)))*(1+'DCF Model'!D$23*(1-'DCF Model'!$B$19)))*(1+'DCF Model'!E$23*(1-'DCF Model'!$B$19)))*(1+'DCF Model'!F$23*(1-'DCF Model'!$B$19)))*F$3/(1+0.11)^5
A7: 0.12 | B7: =('DCF Model'!C$29/(1+0.12)^1+'DCF Model'!D$29/(1+0.12)^2+'DCF Model'!E$29/(1+0.12)^3+'DCF Model'!F$29/(1+0.12)^4+'DCF Model'!G$29/(1+0.12)^5)+((((('DCF Model'!$B$14*(1+'DCF Model'!B$23*(1-'DCF Model'!$B$19)))*(1+'DCF Model'!C$23*(1-'DCF Model'!$B$19)))*(1+'DCF Model'!D$23*(1-'DCF Model'!$B$19)))*(1+'DCF Model'!E$23*(1-'DCF Model'!$B$19)))*(1+'DCF Model'!F$23*(1-'DCF Model'!$B$19)))*B$3/(1+0.12)^5 | C7: =('DCF Model'!C$29/(1+0.12)^1+'DCF Model'!D$29/(1+0.12)^2+'DCF Model'!E$29/(1+0.12)^3+'DCF Model'!F$29/(1+0.12)^4+'DCF Model'!G$29/(1+0.12)^5)+((((('DCF Model'!$B$14*(1+'DCF Model'!B$23*(1-'DCF Model'!$B$19)))*(1+'DCF Model'!C$23*(1-'DCF Model'!$B$19)))*(1+'DCF Model'!D$23*(1-'DCF Model'!$B$19)))*(1+'DCF Model'!E$23*(1-'DCF Model'!$B$19)))*(1+'DCF Model'!F$23*(1-'DCF Model'!$B$19)))*C$3/(1+0.12)^5 | D7: =('DCF Model'!C$29/(1+0.12)^1+'DCF Model'!D$29/(1+0.12)^2+'DCF Model'!E$29/(1+0.12)^3+'DCF Model'!F$29/(1+0.12)^4+'DCF Model'!G$29/(1+0.12)^5)+((((('DCF Model'!$B$14*(1+'DCF Model'!B$23*(1-'DCF Model'!$B$19)))*(1+'DCF Model'!C$23*(1-'DCF Model'!$B$19)))*(1+'DCF Model'!D$23*(1-'DCF Model'!$B$19)))*(1+'DCF Model'!E$23*(1-'DCF Model'!$B$19)))*(1+'DCF Model'!F$23*(1-'DCF Model'!$B$19)))*D$3/(1+0.12)^5 | E7: =('DCF Model'!C$29/(1+0.12)^1+'DCF Model'!D$29/(1+0.12)^2+'DCF Model'!E$29/(1+0.12)^3+'DCF Model'!F$29/(1+0.12)^4+'DCF Model'!G$29/(1+0.12)^5)+((((('DCF Model'!$B$14*(1+'DCF Model'!B$23*(1-'DCF Model'!$B$19)))*(1+'DCF Model'!C$23*(1-'DCF Model'!$B$19)))*(1+'DCF Model'!D$23*(1-'DCF Model'!$B$19)))*(1+'DCF Model'!E$23*(1-'DCF Model'!$B$19)))*(1+'DCF Model'!F$23*(1-'DCF Model'!$B$19)))*E$3/(1+0.12)^5 | F7: =('DCF Model'!C$29/(1+0.12)^1+'DCF Model'!D$29/(1+0.12)^2+'DCF Model'!E$29/(1+0.12)^3+'DCF Model'!F$29/(1+0.12)^4+'DCF Model'!G$29/(1+0.12)^5)+((((('DCF Model'!$B$14*(1+'DCF Model'!B$23*(1-'DCF Model'!$B$19)))*(1+'DCF Model'!C$23*(1-'DCF Model'!$B$19)))*(1+'DCF Model'!D$23*(1-'DCF Model'!$B$19)))*(1+'DCF Model'!E$23*(1-'DCF Model'!$B$19)))*(1+'DCF Model'!F$23*(1-'DCF Model'!$B$19)))*F$3/(1+0.12)^5
A8: 0.13 | B8: =('DCF Model'!C$29/(1+0.13)^1+'DCF Model'!D$29/(1+0.13)^2+'DCF Model'!E$29/(1+0.13)^3+'DCF Model'!F$29/(1+0.13)^4+'DCF Model'!G$29/(1+0.13)^5)+((((('DCF Model'!$B$14*(1+'DCF Model'!B$23*(1-'DCF Model'!$B$19)))*(1+'DCF Model'!C$23*(1-'DCF Model'!$B$19)))*(1+'DCF Model'!D$23*(1-'DCF Model'!$B$19)))*(1+'DCF Model'!E$23*(1-'DCF Model'!$B$19)))*(1+'DCF Model'!F$23*(1-'DCF Model'!$B$19)))*B$3/(1+0.13)^5 | C8: =('DCF Model'!C$29/(1+0.13)^1+'DCF Model'!D$29/(1+0.13)^2+'DCF Model'!E$29/(1+0.13)^3+'DCF Model'!F$29/(1+0.13)^4+'DCF Model'!G$29/(1+0.13)^5)+((((('DCF Model'!$B$14*(1+'DCF Model'!B$23*(1-'DCF Model'!$B$19)))*(1+'DCF Model'!C$23*(1-'DCF Model'!$B$19)))*(1+'DCF Model'!D$23*(1-'DCF Model'!$B$19)))*(1+'DCF Model'!E$23*(1-'DCF Model'!$B$19)))*(1+'DCF Model'!F$23*(1-'DCF Model'!$B$19)))*C$3/(1+0.13)^5 | D8: =('DCF Model'!C$29/(1+0.13)^1+'DCF Model'!D$29/(1+0.13)^2+'DCF Model'!E$29/(1+0.13)^3+'DCF Model'!F$29/(1+0.13)^4+'DCF Model'!G$29/(1+0.13)^5)+((((('DCF Model'!$B$14*(1+'DCF Model'!B$23*(1-'DCF Model'!$B$19)))*(1+'DCF Model'!C$23*(1-'DCF Model'!$B$19)))*(1+'DCF Model'!D$23*(1-'DCF Model'!$B$19)))*(1+'DCF Model'!E$23*(1-'DCF Model'!$B$19)))*(1+'DCF Model'!F$23*(1-'DCF Model'!$B$19)))*D$3/(1+0.13)^5 | E8: =('DCF Model'!C$29/(1+0.13)^1+'DCF Model'!D$29/(1+0.13)^2+'DCF Model'!E$29/(1+0.13)^3+'DCF Model'!F$29/(1+0.13)^4+'DCF Model'!G$29/(1+0.13)^5)+((((('DCF Model'!$B$14*(1+'DCF Model'!B$23*(1-'DCF Model'!$B$19)))*(1+'DCF Model'!C$23*(1-'DCF Model'!$B$19)))*(1+'DCF Model'!D$23*(1-'DCF Model'!$B$19)))*(1+'DCF Model'!E$23*(1-'DCF Model'!$B$19)))*(1+'DCF Model'!F$23*(1-'DCF Model'!$B$19)))*E$3/(1+0.13)^5 | F8: =('DCF Model'!C$29/(1+0.13)^1+'DCF Model'!D$29/(1+0.13)^2+'DCF Model'!E$29/(1+0.13)^3+'DCF Model'!F$29/(1+0.13)^4+'DCF Model'!G$29/(1+0.13)^5)+((((('DCF Model'!$B$14*(1+'DCF Model'!B$23*(1-'DCF Model'!$B$19)))*(1+'DCF Model'!C$23*(1-'DCF Model'!$B$19)))*(1+'DCF Model'!D$23*(1-'DCF Model'!$B$19)))*(1+'DCF Model'!E$23*(1-'DCF Model'!$B$19)))*(1+'DCF Model'!F$23*(1-'DCF Model'!$B$19)))*F$3/(1+0.13)^5
A10: Note: dividends here use the base-case DPS row from 'DCF Model' (payout x EPS); BVPS5 compounds at ROE x (1 - payout). Rows 9-13% CoE, columns exit P/B 1.2-2.0x.

Sheet Historical
A1: Historical (NZD m, basic shares)
A3: Period | B3: Revenue | C3: NPAT | D3: Equity | E3: Shares (M) | F3: BVPS | G3: ROE | H3: FY-end price | I3: P/B | J3: FCF (reported)
A4: FY2022 | B4: 409.601 | C4: 18.855 | D4: 317.528 | E4: 379.484 | F4: 0.8367 | G4: 0.0594 | H4: 0.7279 | I4: 0.87 | J4: 39
A5: FY2023 | B5: 470.813 | C5: -1.228 | D5: 300.265 | E5: 379.484 | F5: 0.7912 | G5: -0.0041 | H5: 0.7111 | I5: 0.9 | J5: -11.235
A6: FY2024 | B6: 555.818 | C6: 74.285 | D6: 360.156 | E6: 379.484 | F6: 0.9491 | G6: 0.2063 | H6: 1.4889 | I6: 1.57 | J6: 125.432
A7: FY2025 | B7: 594.348 | C7: 83.673 | D7: 350.665 | E7: 342.552 | F7: 1.0237 | G7: 0.2386 | H7: 1.85 | I7: 1.81 | J7: 121.701
A8: H1 FY2026 | B8: 291.169 | C8: 22.855 | D8: 318.068 | E8: 343.41135 | F8: 0.9262 | H8: 1.965 | I8: 2.12 | J8: 21.5
A10: Large events (NZ$m net) | B10: FY2023 | C10: 38 | D10: FY2024 | E10: 0 | F10: FY2025 | G10: 7.2 | H10: FY2026 ytd | I10: 23.5 | J10: Allowance FY26 | K10: 45
A11: Dividends (cps) | B11: FY2023 | C11: 4 | D11: FY2024 | E11: 6.5 | F11: FY2025 | G11: 24.5 | H11: FY2026 interim | I11: 5
A12: Growth divergence warning | B12: Every trailing CAGR describes a turnaround, not a trend: FY2022 was a weak year (NPAT NZ$18.9m), FY2023 a catastrophe loss (NZ$-1.2m; Auckland floods + Cyclone Gabrielle, NZ$38m large events) and FY2024-25 benign weather years (large events NZ$0 and NZ$7.2m vs NZ$45-50m allowances). EPS 3yr CAGR 70% and FCF 3yr CAGR 46% are meaningless; equity CAGR 3.4% is depressed by the NZ$45.5m capital return; revenue CAGR 13% straddles the IFRS 4 -> IFRS 17 break. Five-year figures are unavailable (Metrics.csv starts FY2022). Base case is anchored on FY26 guidance and a mid-cycle ROE, not on any CAGR.
