Workbook

Sheet Takeover Offer
A1: 2CC.NZ — LIVE TAKEOVER OFFER
A2: This is the dominant fact for this security — read before the DCF sheets
A5: Status | B5: LIVE — Takeovers Code full offer in progress
A6: Bidder | B6: Sena & Co Limited (CEO David Sena's family trust vehicle)
A7: Bidder's existing stake | B7: 75.924%
A8: Offer price (NZD cash) | B8: $0.80
A9: Offer type | B9: Full takeover offer, all cash, for all shares not already held
A10: Notice date | B10: 2026-07-13
A11: Offer opened | B11: 2026-07-27
A12: Offer closes | B12: 2026-08-24
A13: Extendable to | B13: 2026-10-19
A14: Minimum acceptance condition | B14: 90% of voting rights (Takeovers Code compulsory acquisition threshold)
A15: Shares needed for condition (m) | B15: 6.4
A16: % of minority needed | B16: 58.46%
A17: Independent adviser | B17: Simmons Corporate Finance
A18: Independent adviser range | B18: $0.71 - $0.90
A19: Independent adviser midpoint | B19: $0.81
A20: Independent adviser conclusion | B20: Offer price of $0.80 assessed as FAIR
A21: Independent directors recommendation | B21: Unanimous ACCEPT (Stiassny, Shaw); both intend to accept for their own holdings; independent directors were unable to negotiate Sena above $0.80
A22: Market price vs offer | B22: Current market price NZ$0.795 is trading essentially AT the $0.80 offer price, indicating the market is pricing a high probability of deal completion
A24: IMPLICATION | B24: 2CC is now primarily a takeover-arbitrage instrument, not a going-concern DCF candidate. The DCF below is retained as the standalone / 'deal-fails' anchor value, but any DCF-implied 'upside' over $0.795 is NOT actionable while the offer is live and trading near terms — a rational holder cannot capture DCF upside independently of tendering into or being squeezed out by the offer. If the 90% compulsory-acquisition threshold is reached, remaining holders will be compelled to sell at $0.80 regardless of the DCF view.
A26: DOWNSIDE IF DEAL FAILS | B26: If the 90% condition is not met and the offer lapses, the stock would likely revert to an illiquid standalone level in the vicinity of the base-case DCF intrinsic value (~$0.52) or the pre-notice trading range ($0.59-$0.66), i.e. a re-rating DOWN from the current offer-anchored price is the key risk of the deal failing, not up.
A29: Current Price | B29: 0.795
A30: Offer Price | B30: 0.8
A31: Base-case standalone DCF IV | B31: 0.5202
A32: Probability-weighted standalone IV | B32: 0.5413

Sheet DCF Model
A1: 2CC.NZ DCF Valuation Model — BASE CASE (standalone)
A2: Gray cells are INPUTS - adjust to see valuation change. See "Takeover Offer" sheet for the live $0.80 cash bid.
A4: KEY INPUTS
A5: Current Stock Price (NZD) | B5: 0.795
A6: Shares Outstanding (M) | B6: 45.5545
A7: Cash & Equivalents (NZ$M) | B7: 3.838
A8: Borrowings, ex-lease (NZ$M) | B8: 0.751
A9: Net Cash (NZ$M) [Cash - Borrowings] | B9: =B7-B8 -> 0
A10: Lease Liabilities (NZ$M) — memo only, NOT in net debt | B10: 8.977
A11: note: lease principal is already deducted in owner FCF below; adding lease liabilities to net debt would double-count
A13: Mid-Cycle Owner FCF base (NZ$M) | B13: 3.2
A14: Reported FY26 FCF (OCF-capex, NZ$M) | B14: 3.734
A15: FY26 Owner FCF (after lease principal, NZ$M) | B15: 1.513
A16: Stock-Based Compensation (NZ$M) | B16: 0
A17: SBC note: verified NIL — no share-based payment note; LTI vested nil FY25 & FY26; shares flat 5+yrs
A19: WACC (base case) | B19: 0.19
A20: Terminal Growth Rate (base case) | B20: 0.015
A21: Terminal EV/EBITDA exit multiple cap | B21: 4
A22: Terminal EBITDA (NZ$M) | B22: 8.6
A24: GROWTH ASSUMPTIONS (Base Case) | B24: FY27E | C24: FY28E | D24: FY29E | E24: FY30E | F24: FY31E
A25: FCF Growth Rate | B25: 0.06 | C25: 0.05 | D25: 0.04 | E25: 0.03 | F25: 0.025
A27: PROJECTIONS (Base Case)
B28: Base Yr | C28: FY27E | D28: FY28E | E28: FY29E | F28: FY30E | G28: FY31E
A29: Owner Free Cash Flow (NZ$M) | B29: =B13 -> 0 | C29: =B29*(1+B25) -> 0 | D29: =C29*(1+C25) -> 0 | E29: =D29*(1+D25) -> 0 | F29: =E29*(1+E25) -> 0 | G29: =F29*(1+F25) -> 0
A30: Shares Outstanding (M) | B30: =B6 -> 0 | C30: =B$6 -> 0 | D30: =B$6 -> 0 | E30: =B$6 -> 0 | F30: =B$6 -> 0 | G30: =B$6 -> 0
A31: Discount Factor | C31: =1/(1+$B$19)^1 -> 0 | D31: =1/(1+$B$19)^2 -> 0 | E31: =1/(1+$B$19)^3 -> 0 | F31: =1/(1+$B$19)^4 -> 0 | G31: =1/(1+$B$19)^5 -> 0
A32: PV of FCF (NZ$M) | C32: =C29*C31 -> 0 | D32: =D29*D31 -> 0 | E32: =E29*E31 -> 0 | F32: =F29*F31 -> 0 | G32: =G29*G31 -> 0
A34: VALUATION
A35: Sum of PV of FCF (NZ$M) | B35: =SUM(C32:G32) -> 0
A36: Terminal FCF (Year 5 x (1+g)) (NZ$M) | B36: =G29*(1+$B$20) -> 0
A37: Gordon Terminal Value (NZ$M) | B37: =B36/($B$19-$B$20) -> 0
A38: Exit-Multiple Cap Value (NZ$M) | B38: =B21*B22 -> 0
A39: Terminal Value used (lower of two) (NZ$M) | B39: =MIN(B37,B38) -> 0
A40: PV of Terminal Value (NZ$M) | B40: =B39*G31 -> 0
A41: Enterprise Value (NZ$M) | B41: =B35+B40 -> 0
A42: Add: Net Cash (NZ$M) | B42: =B9 -> 0
A43: Equity Value (NZ$M) | B43: =B41+B42 -> 0
A44: INTRINSIC VALUE/SHARE (NZD) | B44: =B43/G30 -> 0
A45: Terminal Value % of Enterprise Value | B45: =B40/B41 -> 0
A47: ENTRY PRICE (15% IRR Target)
...

Sheet Scenarios
A1: Scenario Comparison
A3: Metric | B3: Bear | C3: Base | D3: Bull
A5: FCF base (NZ$M) | B5: 2.6 | C5: 3.2 | D5: 3.9
A6: Year 1 growth % | B6: 0 | C6: 0.06 | D6: 0.1
A7: Year 5 growth % | B7: 0.015 | C7: 0.025 | D7: 0.04
A8: WACC | B8: 0.21 | C8: 0.19 | D8: 0.17
A9: Terminal growth | B9: 0.01 | C9: 0.015 | D9: 0.02
A10: Exit multiple cap (x EBITDA) | B10: 3 | C10: 4 | D10: 5.5
A11: Terminal EBITDA (NZ$M) | B11: 6.5 | C11: 8.6 | D11: 10.5
A12: Terminal Value bound by | B12: gordon | C12: gordon | D12: gordon
A13: Terminal % of EV | B13: 0.4077 | C13: 0.4612 | D13: 0.5206
A14: Implied exit multiple (TV/FCF5) | B14: 5.05 | C14: 5.8 | D14: 6.8
A15: Intrinsic Value/Share (NZD) | B15: 0.3556 | C15: 0.5202 | D15: 0.7691
A16: Upside vs current price | B16: -0.5527 | C16: -0.3457 | D16: -0.0326
A18: PROBABILITY WEIGHTING
A19: Weight: Bear | B19: 0.25
A20: Weight: Base | B20: 0.5
A21: Weight: Bull | B21: 0.25
A22: Probability-Weighted Intrinsic Value | B22: 0.5413

Sheet Sensitivity
A1: Sensitivity Analysis — Base Case
A2: Intrinsic Value by WACC & Terminal Growth (NZD/share)
A4: WACC \ Term G | B4: 0.005 | C4: 0.01 | D4: 0.015 | E4: 0.02 | F4: 0.025
A5: 0.15 | B5: =(MIN(('DCF Model'!$B$13*(1+'DCF Model'!$B$25)*(1+'DCF Model'!$C$25)*(1+'DCF Model'!$D$25)*(1+'DCF Model'!$E$25)*(1+'DCF Model'!$F$25)*(1+0.005)/(0.15-0.005)),'DCF Model'!$B$38)/(1+0.15)^5+NPV(0.15,'DCF Model'!$C$29:$G$29)+'DCF Model'!$B$9)/'DCF Model'!$G$30 -> 0 | C5: =(MIN(('DCF Model'!$B$13*(1+'DCF Model'!$B$25)*(1+'DCF Model'!$C$25)*(1+'DCF Model'!$D$25)*(1+'DCF Model'!$E$25)*(1+'DCF Model'!$F$25)*(1+0.01)/(0.15-0.01)),'DCF Model'!$B$38)/(1+0.15)^5+NPV(0.15,'DCF Model'!$C$29:$G$29)+'DCF Model'!$B$9)/'DCF Model'!$G$30 -> 0 | D5: =(MIN(('DCF Model'!$B$13*(1+'DCF Model'!$B$25)*(1+'DCF Model'!$C$25)*(1+'DCF Model'!$D$25)*(1+'DCF Model'!$E$25)*(1+'DCF Model'!$F$25)*(1+0.015)/(0.15-0.015)),'DCF Model'!$B$38)/(1+0.15)^5+NPV(0.15,'DCF Model'!$C$29:$G$29)+'DCF Model'!$B$9)/'DCF Model'!$G$30 -> 0 | E5: =(MIN(('DCF Model'!$B$13*(1+'DCF Model'!$B$25)*(1+'DCF Model'!$C$25)*(1+'DCF Model'!$D$25)*(1+'DCF Model'!$E$25)*(1+'DCF Model'!$F$25)*(1+0.02)/(0.15-0.02)),'DCF Model'!$B$38)/(1+0.15)^5+NPV(0.15,'DCF Model'!$C$29:$G$29)+'DCF Model'!$B$9)/'DCF Model'!$G$30 -> 0 | F5: =(MIN(('DCF Model'!$B$13*(1+'DCF Model'!$B$25)*(1+'DCF Model'!$C$25)*(1+'DCF Model'!$D$25)*(1+'DCF Model'!$E$25)*(1+'DCF Model'!$F$25)*(1+0.025)/(0.15-0.025)),'DCF Model'!$B$38)/(1+0.15)^5+NPV(0.15,'DCF Model'!$C$29:$G$29)+'DCF Model'!$B$9)/'DCF Model'!$G$30 -> 0
A6: 0.17 | B6: =(MIN(('DCF Model'!$B$13*(1+'DCF Model'!$B$25)*(1+'DCF Model'!$C$25)*(1+'DCF Model'!$D$25)*(1+'DCF Model'!$E$25)*(1+'DCF Model'!$F$25)*(1+0.005)/(0.17-0.005)),'DCF Model'!$B$38)/(1+0.17)^5+NPV(0.17,'DCF Model'!$C$29:$G$29)+'DCF Model'!$B$9)/'DCF Model'!$G$30 -> 0 | C6: =(MIN(('DCF Model'!$B$13*(1+'DCF Model'!$B$25)*(1+'DCF Model'!$C$25)*(1+'DCF Model'!$D$25)*(1+'DCF Model'!$E$25)*(1+'DCF Model'!$F$25)*(1+0.01)/(0.17-0.01)),'DCF Model'!$B$38)/(1+0.17)^5+NPV(0.17,'DCF Model'!$C$29:$G$29)+'DCF Model'!$B$9)/'DCF Model'!$G$30 -> 0 | D6: =(MIN(('DCF Model'!$B$13*(1+'DCF Model'!$B$25)*(1+'DCF Model'!$C$25)*(1+'DCF Model'!$D$25)*(1+'DCF Model'!$E$25)*(1+'DCF Model'!$F$25)*(1+0.015)/(0.17-0.015)),'DCF Model'!$B$38)/(1+0.17)^5+NPV(0.17,'DCF Model'!$C$29:$G$29)+'DCF Model'!$B$9)/'DCF Model'!$G$30 -> 0 | E6: =(MIN(('DCF Model'!$B$13*(1+'DCF Model'!$B$25)*(1+'DCF Model'!$C$25)*(1+'DCF Model'!$D$25)*(1+'DCF Model'!$E$25)*(1+'DCF Model'!$F$25)*(1+0.02)/(0.17-0.02)),'DCF Model'!$B$38)/(1+0.17)^5+NPV(0.17,'DCF Model'!$C$29:$G$29)+'DCF Model'!$B$9)/'DCF Model'!$G$30 -> 0 | F6: =(MIN(('DCF Model'!$B$13*(1+'DCF Model'!$B$25)*(1+'DCF Model'!$C$25)*(1+'DCF Model'!$D$25)*(1+'DCF Model'!$E$25)*(1+'DCF Model'!$F$25)*(1+0.025)/(0.17-0.025)),'DCF Model'!$B$38)/(1+0.17)^5+NPV(0.17,'DCF Model'!$C$29:$G$29)+'DCF Model'!$B$9)/'DCF Model'!$G$30 -> 0
A7: 0.19 | B7: =(MIN(('DCF Model'!$B$13*(1+'DCF Model'!$B$25)*(1+'DCF Model'!$C$25)*(1+'DCF Model'!$D$25)*(1+'DCF Model'!$E$25)*(1+'DCF Model'!$F$25)*(1+0.005)/(0.19-0.005)),'DCF Model'!$B$38)/(1+0.19)^5+NPV(0.19,'DCF Model'!$C$29:$G$29)+'DCF Model'!$B$9)/'DCF Model'!$G$30 -> 0 | C7: =(MIN(('DCF Model'!$B$13*(1+'DCF Model'!$B$25)*(1+'DCF Model'!$C$25)*(1+'DCF Model'!$D$25)*(1+'DCF Model'!$E$25)*(1+'DCF Model'!$F$25)*(1+0.01)/(0.19-0.01)),'DCF Model'!$B$38)/(1+0.19)^5+NPV(0.19,'DCF Model'!$C$29:$G$29)+'DCF Model'!$B$9)/'DCF Model'!$G$30 -> 0 | D7: =(MIN(('DCF Model'!$B$13*(1+'DCF Model'!$B$25)*(1+'DCF Model'!$C$25)*(1+'DCF Model'!$D$25)*(1+'DCF Model'!$E$25)*(1+'DCF Model'!$F$25)*(1+0.015)/(0.19-0.015)),'DCF Model'!$B$38)/(1+0.19)^5+NPV(0.19,'DCF Model'!$C$29:$G$29)+'DCF Model'!$B$9)/'DCF Model'!$G$30 -> 0 | E7: =(MIN(('DCF Model'!$B$13*(1+'DCF Model'!$B$25)*(1+'DCF Model'!$C$25)*(1+'DCF Model'!$D$25)*(1+'DCF Model'!$E$25)*(1+'DCF Model'!$F$25)*(1+0.02)/(0.19-0.02)),'DCF Model'!$B$38)/(1+0.19)^5+NPV(0.19,'DCF Model'!$C$29:$G$29)+'DCF Model'!$B$9)/'DCF Model'!$G$30 -> 0 | F7: =(MIN(('DCF Model'!$B$13*(1+'DCF Model'!$B$25)*(1+'DCF Model'!$C$25)*(1+'DCF Model'!$D$25)*(1+'DCF Model'!$E$25)*(1+'DCF Model'!$F$25)*(1+0.025)/(0.19-0.025)),'DCF Model'!$B$38)/(1+0.19)^5+NPV(0.19,'DCF Model'!$C$29:$G$29)+'DCF Model'!$B$9)/'DCF Model'!$G$30 -> 0
A8: 0.21 | B8: =(MIN(('DCF Model'!$B$13*(1+'DCF Model'!$B$25)*(1+'DCF Model'!$C$25)*(1+'DCF Model'!$D$25)*(1+'DCF Model'!$E$25)*(1+'DCF Model'!$F$25)*(1+0.005)/(0.21-0.005)),'DCF Model'!$B$38)/(1+0.21)^5+NPV(0.21,'DCF Model'!$C$29:$G$29)+'DCF Model'!$B$9)/'DCF Model'!$G$30 -> 0 | C8: =(MIN(('DCF Model'!$B$13*(1+'DCF Model'!$B$25)*(1+'DCF Model'!$C$25)*(1+'DCF Model'!$D$25)*(1+'DCF Model'!$E$25)*(1+'DCF Model'!$F$25)*(1+0.01)/(0.21-0.01)),'DCF Model'!$B$38)/(1+0.21)^5+NPV(0.21,'DCF Model'!$C$29:$G$29)+'DCF Model'!$B$9)/'DCF Model'!$G$30 -> 0 | D8: =(MIN(('DCF Model'!$B$13*(1+'DCF Model'!$B$25)*(1+'DCF Model'!$C$25)*(1+'DCF Model'!$D$25)*(1+'DCF Model'!$E$25)*(1+'DCF Model'!$F$25)*(1+0.015)/(0.21-0.015)),'DCF Model'!$B$38)/(1+0.21)^5+NPV(0.21,'DCF Model'!$C$29:$G$29)+'DCF Model'!$B$9)/'DCF Model'!$G$30 -> 0 | E8: =(MIN(('DCF Model'!$B$13*(1+'DCF Model'!$B$25)*(1+'DCF Model'!$C$25)*(1+'DCF Model'!$D$25)*(1+'DCF Model'!$E$25)*(1+'DCF Model'!$F$25)*(1+0.02)/(0.21-0.02)),'DCF Model'!$B$38)/(1+0.21)^5+NPV(0.21,'DCF Model'!$C$29:$G$29)+'DCF Model'!$B$9)/'DCF Model'!$G$30 -> 0 | F8: =(MIN(('DCF Model'!$B$13*(1+'DCF Model'!$B$25)*(1+'DCF Model'!$C$25)*(1+'DCF Model'!$D$25)*(1+'DCF Model'!$E$25)*(1+'DCF Model'!$F$25)*(1+0.025)/(0.21-0.025)),'DCF Model'!$B$38)/(1+0.21)^5+NPV(0.21,'DCF Model'!$C$29:$G$29)+'DCF Model'!$B$9)/'DCF Model'!$G$30 -> 0
A9: 0.23 | B9: =(MIN(('DCF Model'!$B$13*(1+'DCF Model'!$B$25)*(1+'DCF Model'!$C$25)*(1+'DCF Model'!$D$25)*(1+'DCF Model'!$E$25)*(1+'DCF Model'!$F$25)*(1+0.005)/(0.23-0.005)),'DCF Model'!$B$38)/(1+0.23)^5+NPV(0.23,'DCF Model'!$C$29:$G$29)+'DCF Model'!$B$9)/'DCF Model'!$G$30 -> 0 | C9: =(MIN(('DCF Model'!$B$13*(1+'DCF Model'!$B$25)*(1+'DCF Model'!$C$25)*(1+'DCF Model'!$D$25)*(1+'DCF Model'!$E$25)*(1+'DCF Model'!$F$25)*(1+0.01)/(0.23-0.01)),'DCF Model'!$B$38)/(1+0.23)^5+NPV(0.23,'DCF Model'!$C$29:$G$29)+'DCF Model'!$B$9)/'DCF Model'!$G$30 -> 0 | D9: =(MIN(('DCF Model'!$B$13*(1+'DCF Model'!$B$25)*(1+'DCF Model'!$C$25)*(1+'DCF Model'!$D$25)*(1+'DCF Model'!$E$25)*(1+'DCF Model'!$F$25)*(1+0.015)/(0.23-0.015)),'DCF Model'!$B$38)/(1+0.23)^5+NPV(0.23,'DCF Model'!$C$29:$G$29)+'DCF Model'!$B$9)/'DCF Model'!$G$30 -> 0 | E9: =(MIN(('DCF Model'!$B$13*(1+'DCF Model'!$B$25)*(1+'DCF Model'!$C$25)*(1+'DCF Model'!$D$25)*(1+'DCF Model'!$E$25)*(1+'DCF Model'!$F$25)*(1+0.02)/(0.23-0.02)),'DCF Model'!$B$38)/(1+0.23)^5+NPV(0.23,'DCF Model'!$C$29:$G$29)+'DCF Model'!$B$9)/'DCF Model'!$G$30 -> 0 | F9: =(MIN(('DCF Model'!$B$13*(1+'DCF Model'!$B$25)*(1+'DCF Model'!$C$25)*(1+'DCF Model'!$D$25)*(1+'DCF Model'!$E$25)*(1+'DCF Model'!$F$25)*(1+0.025)/(0.23-0.025)),'DCF Model'!$B$38)/(1+0.23)^5+NPV(0.23,'DCF Model'!$C$29:$G$29)+'DCF Model'!$B$9)/'DCF Model'!$G$30 -> 0
A11: Note: matches JSON sensitivity matrix (base-case FCF path, exit-multiple cap fixed at base-case value).
A13: Reference matrix (from DCF JSON, static)
A14: WACC \ Term G | B14: 0.005 | C14: 0.01 | D14: 0.015 | E14: 0.02 | F14: 0.025
A15: 0.15 | B15: 0.631 | C15: 0.644 | D15: 0.657 | E15: 0.671 | F15: 0.686
A16: 0.17 | B16: 0.562 | C16: 0.57 | D16: 0.58 | E16: 0.589 | F16: 0.6
A17: 0.19 | B17: 0.507 | C17: 0.513 | D17: 0.52 | E17: 0.527 | F17: 0.535
A18: 0.21 | B18: 0.463 | C18: 0.468 | D18: 0.473 | E18: 0.478 | F18: 0.484
A19: 0.23 | B19: 0.427 | C19: 0.431 | D19: 0.435 | E19: 0.439 | F19: 0.443

Sheet FCF Quality
A1: FCF Quality — Reported vs Owner FCF Reconciliation
A2: IFRS16 lease-heavy retailer: lease principal sits in financing activities, not OCF
B4: FY2024 | C4: FY2025 | D4: FY2026
A6: Operating Cash Flow (NZ$M) | B6: 6.921 | C6: 6.727 | D6: 4.174
A7: Less: Capex (NZ$M) | B7: 0.812 | C7: 1.315 | D7: 0.44
A8: = Reported FCF (Company definition, NZ$M) | B8: 6.109 | C8: 5.412 | D8: 3.734
A9: Less: Lease Principal Repayment (NZ$M) | B9: 1.935 | C9: 1.999 | D9: 2.221
A10: = Owner FCF (NZ$M) | B10: 4.174 | C10: 3.413 | D10: 1.513
A11: Less: SBC (NZ$M) — verified NIL | B11: 0 | C11: 0 | D11: 0
A12: = Owner FCF after SBC (NZ$M) | B12: 4.174 | C12: 3.413 | D12: 1.513
A14: Revenue (NZ$M) | B14: 86.78 | C14: 80.17 | D14: 81.71
A15: Reported FCF Margin | B15: 0.070396405 | C15: 0.067506549 | D15: 0.045698201
A16: Owner FCF Margin | B16: 0.04809864 | C16: 0.042572034 | D16: 0.018516705
A19: Memo: FY26 one-off inventory build (NZ$M) | D19: 3.109
A20: Memo: inventory build as % of reported FY26 FCF | D20: 0.83261918
A22: Excluded years note: FY2022/FY2023 cash flows excluded — distorted by wind-down of discontinued trade-finance/loan book
A23: FY26 owner FCF ($1.513m) is only 0.44x the FY24-26 median ($3.41m) and smaller than the annual lease principal itself — a trough, not the DCF base year
A25: MID-CYCLE CONVERGENCE (basis for DCF base-year FCF)
A26: Method A: Mean / Median FY24-26 owner FCF | B26: 3.03 | C26: 3.41
A27: Method B: FY26 normalised for inventory build | D27: 4.62
A28: Method C: NPAT+D&A-capex-lease (median) | D28: 3.43
A29: Method D: Structural (NPAT proxy) | D29: 3.2
A30: SELECTED DCF base-year owner FCF | D30: 3.2

Sheet Historical
A1: Historical Financials & Growth Rates
A3: Metric | B3: FY2022 | C3: FY2023 | D3: FY2024 | E3: FY2025 | F3: FY2026
A5: Revenue (NZ$M) | B5: 65.96 | C5: 82.74 | D5: 86.78 | E5: 80.17 | F5: 81.71
A6: NPAT (NZ$M) | B6: 2.594 | C6: 1.292 | D6: 6.241 | E6: 3.3 | F6: 3.188
A7: EPS (NZD) | B7: 0.057 | C7: 0.028 | D7: 0.137 | E7: 0.072 | F7: 0.07
A8: Shareholders' Equity (NZ$M) | B8: 16.17 | C8: 16.17 | D8: 20.37 | E8: 21.06 | F8: 22.15
A9: Cash (NZ$M) | B9: 3.79 | C9: 3.767 | D9: 4.673 | E9: 5.344 | F9: 3.838
A10: Shares Outstanding (M) | B10: 45.5545 | C10: 45.5545 | D10: 45.5545 | E10: 45.5545 | F10: 45.5545
A11: FY-end price (NZD) | B11: 0.77 | C11: 0.3 | D11: 0.78 | E11: 0.74 | F11: 0.59
A13: GROWTH RATES
A15: Revenue 4yr CAGR (FY22-26) | B15: 0.055
A16: Revenue 2yr CAGR (FY24-26) | B16: -0.03
A17: EPS 4yr CAGR (FY22-26) | B17: 0.053
A18: Equity 4yr CAGR (FY22-26) | B18: 0.082
A19: Equity 3yr CAGR (FY23-26) | B19: 0.111
A20: Owner FCF 2yr CAGR (FY24-26) | B20: -0.398
A22: Note: standard CAGRs unreliable here due to 4.8x NPAT peak/trough cyclicality and FY22/23 discontinued finance-book distortion. DCF uses bottom-up scenario growth paths, not a trailing CAGR.

Sheet Multiples Check
A1: Step 8c Sanity Check — Historical Trading Multiples
A3: FY-end (31 Mar) | B3: FY2022 | C3: FY2023 | D3: FY2024 | E3: FY2025 | F3: FY2026
A4: Price (NZD) | B4: 0.77 | C4: 0.3 | D4: 0.78 | E4: 0.74 | F4: 0.59
A5: P/E | B5: 13.5 | C5: 10.6 | D5: 5.7 | E5: 10.2 | F5: 8.4
A6: P/B | B6: 2.17 | C6: 0.84 | D6: 1.74 | E6: 1.6 | F6: 1.21
A7: P/Sales | B7: 0.53 | C7: 0.17 | D7: 0.41 | E7: 0.42 | F7: 0.33
A8: EV/EBITDA (FY25-26 only) | D8: 3.67 | E8: 2.94
A10: AVERAGES
A11: Avg P/E | B11: 9.7
A12: Avg P/B | B12: 1.51
A13: Avg P/Sales | B13: 0.37
A14: Avg EV/EBITDA | B14: 3.31
A16: CURRENT PRICE ($0.795) IMPLIED
A17: P/E | B17: 11.4
A18: P/B | B18: 1.63
A19: P/Sales | B19: 0.44
A20: EV/EBITDA | B20: 4.1
A21: Gross Dividend Yield | B21: 0.077
A23: BASE-CASE IV ($0.520) IMPLIED
A24: P/E | B24: 7.4
A25: P/B | B25: 1.07
A26: EV/EBITDA | B26: 2.55
A28: CONCLUSION
A29: Sanity check PASSES in neither direction — the base-case IV ($0.520) implies P/E 7.4x, P/B 1.07x and EV/EBITDA 2.55x, ALL BELOW every historical average the market has actually paid for this stock (avg P/E 9.7x, avg P/B 1.51x, avg EV/EBITDA 3.31x). This is because the model is built on a mid-cycle rather than trough or peak FCF from the outset, and the conservative outcome is driven by the 19% WACC and the low historical multiples the market has always applied to this micro-cap. The DCF says the stock is EXPENSIVE at $0.795 (current price), which agrees directionally with the independent adviser (Simmons Corporate Finance, range $0.71-$0.90), with the base case sitting below their range low end mainly because of the higher small-cap/illiquidity/regulatory WACC premiums applied here versus a professional M&A fairness opinion.

Sheet Model_Info
A1: Model Provenance & Notes
A3: Built by | B3: Claude (DCF valuation agent), per user-supplied verified figures and scenario assumptions
A4: Build date | B4: 2026-07-31
A5: Share price vintage | B5: NZ$0.795 — live Yahoo Finance quote fetched 2026-07-31
A6: Data source | B6: 2CC.NZ_Metrics.csv (audited financial statements FY2022-FY2026) and 2CC.NZ_Analysis.json (qualitative/business analysis)
A7: Dominant context | B7: LIVE takeover offer from Sena & Co Limited at NZ$0.80 cash/share, open 27-Jul-2026 to 24-Aug-2026 (extendable to 19-Oct-2026), subject to 90% acceptance condition. See "Takeover Offer" sheet.
A8: Methodology — FCF base | B8: Owner FCF (OCF - capex - IFRS16 lease principal) at a MID-CYCLE level of NZ$3.20m (base case), not the FY26 trough (NZ$1.513m) or any single peak year. Four independent estimation methods converge on NZ$3.0-3.4m — see "FCF Quality" sheet.
A9: Methodology — SBC | B9: Verified NIL. No share-based payment note in FY25/FY26 filings; LTI vested explicitly "nil" both years; shares outstanding flat at 45.5545m for 5+ years. This is a confirmed no-op adjustment, not a skipped one.
A10: Methodology — Net debt | B10: Net CASH of NZ$3.087m (Cash 3.838 - Borrowings 0.751). Lease liabilities (NZ$8.977m) are explicitly EXCLUDED from net debt because lease principal is already deducted from owner FCF — including both would double-count the lease obligation.
A11: Methodology — Terminal value | B11: Lower of Gordon-growth perpetuity and an EV/EBITDA exit-multiple cap (bear 3.0x/base 4.0x/bull 5.5x applied to terminal-year EBITDA). Gordon growth binds in ALL three scenarios given the high WACC (17-21%) relative to modest terminal growth (1.0-2.0%).
A12: Methodology — Shares | B12: Flat 45.5545m across the entire projection horizon in all scenarios — no dilution, no buybacks (company has issued neither for 5+ years).
A13: Scenario assumptions source | B13: Supplied directly by user (verified against audited financials); NOT independently re-derived by the model-building step. FCF bases: bear 2.60 / base 3.20 / bull 3.90 (NZ$M). WACC: bear 21% / base 19% / bull 17%. Terminal growth: bear 1.0% / base 1.5% / bull 2.0%.
A14: WACC build | B14: Base NZ small-cap cost of equity 11.5% + micro-cap illiquidity 2.5% + regulatory single-point-of-failure (Clean Car Standard) 1.8% + extreme cyclicality 1.5% + controlling shareholder 1.0% + single-country/single-source concentration 0.7% = 19.0%. See "wacc_rationale" in the JSON / recommendation sheet.
... A18: Staleness warning | B18: All figures are current as of the build date above. Share price, takeover offer status, and financial data will go stale — always re-verify against the live market and NZX announcements before acting on this model, especially given the live corporate action.
