Workbook
Name price: Inputs!$B$5
Name nav0: Inputs!$B$6
Name coe: Inputs!$B$23
Name hurdle: Inputs!$B$24
Name w_bear: Inputs!$B$27
Name w_base: Inputs!$B$28
Name w_bull: Inputs!$B$29

Sheet Inputs
A1: PLP.NZ — Booster Private Land and Property Fund
A2: Model: NAV/unit compounding + distributions + exit P/NAV (NOT an FCF DCF)
A3: Valuation date | B3: 2026-08-26
A5: Current price (NZD, Yahoo 2026-08-26T01:31Z) | B5: 1.304
A6: NAV per unit — current basis (18-Jun-2026 manager price) | B6: 1.301
A7: NAV per unit — 31-Mar-2026 unit price | B7: 1.2859
A8: Audited NTA per unit FY2026 (IFRS) | B8: 1.29
A9: Units on issue (m) | B9: 163.14678
A10: Net assets FY2026 (NZ$m, Fund level) | B10: 209.798
A11: PLPP look-through borrowings (NZ$m) | B11: 13.75
A12: Look-through gearing (÷ $214.5m assets) | B12: 0.064102564
A13: Total fund charges (% NAV p.a., embedded in growth paths) | B13: 0.0125
A14: FY2026 distributions (NZ$m / c per unit) | B14: 5.294
A16: Cost of equity build-up
A17: NZ risk-free rate | B17: 0.045
A18: NZ property equity risk premium | B18: 0.05
A19: Illiquidity / ~4.5% free float | B19: 0.02
A20: Valuation opacity (Level 2 manager marks) | B20: 0.01
A21: Concentration (Rolleston 32.49% of NAV) | B21: 0.01
A22: Agricultural / climate / commodity | B22: 0.005
A23: Cost of equity (sum) | B23: =SUM(B17:B22)
A24: Entry hurdle rate | B24: 0.15
A26: Scenario weights
A27: Bear | B27: 0.3
A28: Base | B28: 0.5
A29: Bull | B29: 0.2
A30: Sum (must = 1.0) | B30: =SUM(B27:B29)

Sheet History
A1: NAV per unit (manager price, 31 Mar) | C1: Return after charges & tax
A2: FY | B2: NAV/unit | C2: YoY % | D2: Return %
A3: FY2019 | B3: 0.9896
A4: FY2020 | B4: 1.0404 | C4: =B4/B3-1 | D4: 0.0764
A5: FY2021 | B5: 1.0723 | C5: =B5/B4-1 | D5: 0.063
A6: FY2022 | B6: 1.2028 | C6: =B6/B5-1 | D6: 0.14
A7: FY2023 | B7: 1.4002 | C7: =B7/B6-1 | D7: 0.1924
A8: FY2024 | B8: 1.3416 | C8: =B8/B7-1 | D8: -0.022
A9: FY2025 | B9: 1.3102 | C9: =B9/B8-1 | D9: -0.005
A10: FY2026 | B10: 1.2859 | C10: =B10/B9-1 | D10: 0.0063
A12: 7yr NAV/unit CAGR FY19-26 | B12: =(B10/B3)^(1/7)-1
A13: 3yr NAV/unit CAGR FY23-26 | B13: =(B10/B7)^(1/3)-1
A14: Since-inception avg return | B14: 0.0614
A15: 5yr avg return (after tax) | B15: 0.0493
A16: Target (after fees, before tax) | B16: 0.065

Sheet Model
A1: Scenario engine: NAV_t = NAV_{t-1}×(1+g_t); dist_t = yield×NAV_t; IV = Σ PV(dist) + PV(NAV_5 × exit P/NAV) at CoE
A3: Base scenario
A4: Year | C4: FY2027 | D4: FY2028 | E4: FY2029 | F4: FY2030 | G4: FY2031
A5: NAV growth % | C5: 0.005 | D5: 0.01 | E5: 0.015 | F5: 0.02 | G5: 0.02
A6: NAV per unit | B6: =nav0 | C6: =B6*(1+C5) | D6: =C6*(1+D5) | E6: =D6*(1+E5) | F6: =E6*(1+F5) | G6: =F6*(1+G5)
A7: Distribution yield on NAV | B7: 0.025
A8: Distribution per unit | C8: =C6*$B7 | D8: =D6*$B7 | E8: =E6*$B7 | F8: =F6*$B7 | G8: =G6*$B7
A9: Discount factor @ CoE | C9: =1/(1+coe)^1 | D9: =1/(1+coe)^2 | E9: =1/(1+coe)^3 | F9: =1/(1+coe)^4 | G9: =1/(1+coe)^5
A10: PV of distribution | C10: =C8*C9 | D10: =D8*D9 | E10: =E8*E9 | F10: =F8*F9 | G10: =G8*G9
A11: Exit P/NAV | B11: 1
A12: Year-5 exit value | B12: =G6*B11
A13: PV of exit value | B13: =B12*G9
A14: Sum PV distributions | B14: =SUM(C10:G10)
A15: Intrinsic value / unit | B15: =B14+B13
A16: Upside vs price | B16: =B15/price-1
A17: Terminal % of value | B17: =B13/B15
A19: Bull scenario
A20: Year | C20: FY2027 | D20: FY2028 | E20: FY2029 | F20: FY2030 | G20: FY2031
A21: NAV growth % | C21: 0.03 | D21: 0.035 | E21: 0.04 | F21: 0.045 | G21: 0.045
A22: NAV per unit | B22: =nav0 | C22: =B22*(1+C21) | D22: =C22*(1+D21) | E22: =D22*(1+E21) | F22: =E22*(1+F21) | G22: =F22*(1+G21)
A23: Distribution yield on NAV | B23: 0.0275
A24: Distribution per unit | C24: =C22*$B23 | D24: =D22*$B23 | E24: =E22*$B23 | F24: =F22*$B23 | G24: =G22*$B23
A25: Discount factor @ CoE | C25: =1/(1+coe)^1 | D25: =1/(1+coe)^2 | E25: =1/(1+coe)^3 | F25: =1/(1+coe)^4 | G25: =1/(1+coe)^5
A26: PV of distribution | C26: =C24*C25 | D26: =D24*D25 | E26: =E24*E25 | F26: =F24*F25 | G26: =G24*G25
A27: Exit P/NAV | B27: 1.03
A28: Year-5 exit value | B28: =G22*B27
A29: PV of exit value | B29: =B28*G25
A30: Sum PV distributions | B30: =SUM(C26:G26)
A31: Intrinsic value / unit | B31: =B30+B29
A32: Upside vs price | B32: =B31/price-1
A33: Terminal % of value | B33: =B29/B31
A35: Bear scenario
A36: Year | C36: FY2027 | D36: FY2028 | E36: FY2029 | F36: FY2030 | G36: FY2031
A37: NAV growth % | C37: -0.04 | D37: -0.03 | E37: -0.02 | F37: -0.015 | G37: -0.01
A38: NAV per unit | B38: =nav0 | C38: =B38*(1+C37) | D38: =C38*(1+D37) | E38: =D38*(1+E37) | F38: =E38*(1+F37) | G38: =F38*(1+G37)
A39: Distribution yield on NAV | B39: 0.0225
A40: Distribution per unit | C40: =C38*$B39 | D40: =D38*$B39 | E40: =E38*$B39 | F40: =F38*$B39 | G40: =G38*$B39
A41: Discount factor @ CoE | C41: =1/(1+coe)^1 | D41: =1/(1+coe)^2 | E41: =1/(1+coe)^3 | F41: =1/(1+coe)^4 | G41: =1/(1+coe)^5
A42: PV of distribution | C42: =C40*C41 | D42: =D40*D41 | E42: =E40*E41 | F42: =F40*F41 | G42: =G40*G41
A43: Exit P/NAV | B43: 0.88
...

Sheet Sensitivity
A1: IV/unit: flat NAV growth (rows) × exit P/NAV (cols), 2.5% dist yield, CoE from Inputs
A2: g \ exit P/NAV | B2: 0.85 | C2: 0.9 | D2: 0.95 | E2: 1 | F2: 1.05
A3: -0.03 | B3: =SUMPRODUCT(nav0*(1+$A$3)^ROW(INDIRECT("1:5"))*0.025/(1+coe)^ROW(INDIRECT("1:5")))+nav0*(1+$A$3)^5*B$2/(1+coe)^5 | C3: =SUMPRODUCT(nav0*(1+$A$3)^ROW(INDIRECT("1:5"))*0.025/(1+coe)^ROW(INDIRECT("1:5")))+nav0*(1+$A$3)^5*C$2/(1+coe)^5 | D3: =SUMPRODUCT(nav0*(1+$A$3)^ROW(INDIRECT("1:5"))*0.025/(1+coe)^ROW(INDIRECT("1:5")))+nav0*(1+$A$3)^5*D$2/(1+coe)^5 | E3: =SUMPRODUCT(nav0*(1+$A$3)^ROW(INDIRECT("1:5"))*0.025/(1+coe)^ROW(INDIRECT("1:5")))+nav0*(1+$A$3)^5*E$2/(1+coe)^5 | F3: =SUMPRODUCT(nav0*(1+$A$3)^ROW(INDIRECT("1:5"))*0.025/(1+coe)^ROW(INDIRECT("1:5")))+nav0*(1+$A$3)^5*F$2/(1+coe)^5
A4: -0.015 | B4: =SUMPRODUCT(nav0*(1+$A$4)^ROW(INDIRECT("1:5"))*0.025/(1+coe)^ROW(INDIRECT("1:5")))+nav0*(1+$A$4)^5*B$2/(1+coe)^5 | C4: =SUMPRODUCT(nav0*(1+$A$4)^ROW(INDIRECT("1:5"))*0.025/(1+coe)^ROW(INDIRECT("1:5")))+nav0*(1+$A$4)^5*C$2/(1+coe)^5 | D4: =SUMPRODUCT(nav0*(1+$A$4)^ROW(INDIRECT("1:5"))*0.025/(1+coe)^ROW(INDIRECT("1:5")))+nav0*(1+$A$4)^5*D$2/(1+coe)^5 | E4: =SUMPRODUCT(nav0*(1+$A$4)^ROW(INDIRECT("1:5"))*0.025/(1+coe)^ROW(INDIRECT("1:5")))+nav0*(1+$A$4)^5*E$2/(1+coe)^5 | F4: =SUMPRODUCT(nav0*(1+$A$4)^ROW(INDIRECT("1:5"))*0.025/(1+coe)^ROW(INDIRECT("1:5")))+nav0*(1+$A$4)^5*F$2/(1+coe)^5
A5: 0 | B5: =SUMPRODUCT(nav0*(1+$A$5)^ROW(INDIRECT("1:5"))*0.025/(1+coe)^ROW(INDIRECT("1:5")))+nav0*(1+$A$5)^5*B$2/(1+coe)^5 | C5: =SUMPRODUCT(nav0*(1+$A$5)^ROW(INDIRECT("1:5"))*0.025/(1+coe)^ROW(INDIRECT("1:5")))+nav0*(1+$A$5)^5*C$2/(1+coe)^5 | D5: =SUMPRODUCT(nav0*(1+$A$5)^ROW(INDIRECT("1:5"))*0.025/(1+coe)^ROW(INDIRECT("1:5")))+nav0*(1+$A$5)^5*D$2/(1+coe)^5 | E5: =SUMPRODUCT(nav0*(1+$A$5)^ROW(INDIRECT("1:5"))*0.025/(1+coe)^ROW(INDIRECT("1:5")))+nav0*(1+$A$5)^5*E$2/(1+coe)^5 | F5: =SUMPRODUCT(nav0*(1+$A$5)^ROW(INDIRECT("1:5"))*0.025/(1+coe)^ROW(INDIRECT("1:5")))+nav0*(1+$A$5)^5*F$2/(1+coe)^5
A6: 0.015 | B6: =SUMPRODUCT(nav0*(1+$A$6)^ROW(INDIRECT("1:5"))*0.025/(1+coe)^ROW(INDIRECT("1:5")))+nav0*(1+$A$6)^5*B$2/(1+coe)^5 | C6: =SUMPRODUCT(nav0*(1+$A$6)^ROW(INDIRECT("1:5"))*0.025/(1+coe)^ROW(INDIRECT("1:5")))+nav0*(1+$A$6)^5*C$2/(1+coe)^5 | D6: =SUMPRODUCT(nav0*(1+$A$6)^ROW(INDIRECT("1:5"))*0.025/(1+coe)^ROW(INDIRECT("1:5")))+nav0*(1+$A$6)^5*D$2/(1+coe)^5 | E6: =SUMPRODUCT(nav0*(1+$A$6)^ROW(INDIRECT("1:5"))*0.025/(1+coe)^ROW(INDIRECT("1:5")))+nav0*(1+$A$6)^5*E$2/(1+coe)^5 | F6: =SUMPRODUCT(nav0*(1+$A$6)^ROW(INDIRECT("1:5"))*0.025/(1+coe)^ROW(INDIRECT("1:5")))+nav0*(1+$A$6)^5*F$2/(1+coe)^5
A7: 0.03 | B7: =SUMPRODUCT(nav0*(1+$A$7)^ROW(INDIRECT("1:5"))*0.025/(1+coe)^ROW(INDIRECT("1:5")))+nav0*(1+$A$7)^5*B$2/(1+coe)^5 | C7: =SUMPRODUCT(nav0*(1+$A$7)^ROW(INDIRECT("1:5"))*0.025/(1+coe)^ROW(INDIRECT("1:5")))+nav0*(1+$A$7)^5*C$2/(1+coe)^5 | D7: =SUMPRODUCT(nav0*(1+$A$7)^ROW(INDIRECT("1:5"))*0.025/(1+coe)^ROW(INDIRECT("1:5")))+nav0*(1+$A$7)^5*D$2/(1+coe)^5 | E7: =SUMPRODUCT(nav0*(1+$A$7)^ROW(INDIRECT("1:5"))*0.025/(1+coe)^ROW(INDIRECT("1:5")))+nav0*(1+$A$7)^5*E$2/(1+coe)^5 | F7: =SUMPRODUCT(nav0*(1+$A$7)^ROW(INDIRECT("1:5"))*0.025/(1+coe)^ROW(INDIRECT("1:5")))+nav0*(1+$A$7)^5*F$2/(1+coe)^5
A8: 0.045 | B8: =SUMPRODUCT(nav0*(1+$A$8)^ROW(INDIRECT("1:5"))*0.025/(1+coe)^ROW(INDIRECT("1:5")))+nav0*(1+$A$8)^5*B$2/(1+coe)^5 | C8: =SUMPRODUCT(nav0*(1+$A$8)^ROW(INDIRECT("1:5"))*0.025/(1+coe)^ROW(INDIRECT("1:5")))+nav0*(1+$A$8)^5*C$2/(1+coe)^5 | D8: =SUMPRODUCT(nav0*(1+$A$8)^ROW(INDIRECT("1:5"))*0.025/(1+coe)^ROW(INDIRECT("1:5")))+nav0*(1+$A$8)^5*D$2/(1+coe)^5 | E8: =SUMPRODUCT(nav0*(1+$A$8)^ROW(INDIRECT("1:5"))*0.025/(1+coe)^ROW(INDIRECT("1:5")))+nav0*(1+$A$8)^5*E$2/(1+coe)^5 | F8: =SUMPRODUCT(nav0*(1+$A$8)^ROW(INDIRECT("1:5"))*0.025/(1+coe)^ROW(INDIRECT("1:5")))+nav0*(1+$A$8)^5*F$2/(1+coe)^5
A11: Base-case IV vs cost of equity
A12: CoE | B12: 0.11 | C12: 0.125 | D12: 0.14 | E12: 0.155 | F12: 0.17
A13: IV | B13: =(nav0*(1+Model!C$5))*0.025/(1+B12)^1+((nav0*(1+Model!C$5))*(1+Model!D$5))*0.025/(1+B12)^2+(((nav0*(1+Model!C$5))*(1+Model!D$5))*(1+Model!E$5))*0.025/(1+B12)^3+((((nav0*(1+Model!C$5))*(1+Model!D$5))*(1+Model!E$5))*(1+Model!F$5))*0.025/(1+B12)^4+(((((nav0*(1+Model!C$5))*(1+Model!D$5))*(1+Model!E$5))*(1+Model!F$5))*(1+Model!G$5))*0.025/(1+B12)^5+(((((nav0*(1+Model!C$5))*(1+Model!D$5))*(1+Model!E$5))*(1+Model!F$5))*(1+Model!G$5))*1/(1+B12)^5 | C13: =(nav0*(1+Model!C$5))*0.025/(1+C12)^1+((nav0*(1+Model!C$5))*(1+Model!D$5))*0.025/(1+C12)^2+(((nav0*(1+Model!C$5))*(1+Model!D$5))*(1+Model!E$5))*0.025/(1+C12)^3+((((nav0*(1+Model!C$5))*(1+Model!D$5))*(1+Model!E$5))*(1+Model!F$5))*0.025/(1+C12)^4+(((((nav0*(1+Model!C$5))*(1+Model!D$5))*(1+Model!E$5))*(1+Model!F$5))*(1+Model!G$5))*0.025/(1+C12)^5+(((((nav0*(1+Model!C$5))*(1+Model!D$5))*(1+Model!E$5))*(1+Model!F$5))*(1+Model!G$5))*1/(1+C12)^5 | D13: =(nav0*(1+Model!C$5))*0.025/(1+D12)^1+((nav0*(1+Model!C$5))*(1+Model!D$5))*0.025/(1+D12)^2+(((nav0*(1+Model!C$5))*(1+Model!D$5))*(1+Model!E$5))*0.025/(1+D12)^3+((((nav0*(1+Model!C$5))*(1+Model!D$5))*(1+Model!E$5))*(1+Model!F$5))*0.025/(1+D12)^4+(((((nav0*(1+Model!C$5))*(1+Model!D$5))*(1+Model!E$5))*(1+Model!F$5))*(1+Model!G$5))*0.025/(1+D12)^5+(((((nav0*(1+Model!C$5))*(1+Model!D$5))*(1+Model!E$5))*(1+Model!F$5))*(1+Model!G$5))*1/(1+D12)^5 | E13: =(nav0*(1+Model!C$5))*0.025/(1+E12)^1+((nav0*(1+Model!C$5))*(1+Model!D$5))*0.025/(1+E12)^2+(((nav0*(1+Model!C$5))*(1+Model!D$5))*(1+Model!E$5))*0.025/(1+E12)^3+((((nav0*(1+Model!C$5))*(1+Model!D$5))*(1+Model!E$5))*(1+Model!F$5))*0.025/(1+E12)^4+(((((nav0*(1+Model!C$5))*(1+Model!D$5))*(1+Model!E$5))*(1+Model!F$5))*(1+Model!G$5))*0.025/(1+E12)^5+(((((nav0*(1+Model!C$5))*(1+Model!D$5))*(1+Model!E$5))*(1+Model!F$5))*(1+Model!G$5))*1/(1+E12)^5 | F13: =(nav0*(1+Model!C$5))*0.025/(1+F12)^1+((nav0*(1+Model!C$5))*(1+Model!D$5))*0.025/(1+F12)^2+(((nav0*(1+Model!C$5))*(1+Model!D$5))*(1+Model!E$5))*0.025/(1+F12)^3+((((nav0*(1+Model!C$5))*(1+Model!D$5))*(1+Model!E$5))*(1+Model!F$5))*0.025/(1+F12)^4+(((((nav0*(1+Model!C$5))*(1+Model!D$5))*(1+Model!E$5))*(1+Model!F$5))*(1+Model!G$5))*0.025/(1+F12)^5+(((((nav0*(1+Model!C$5))*(1+Model!D$5))*(1+Model!E$5))*(1+Model!F$5))*(1+Model!G$5))*1/(1+F12)^5
A15: Required-return table (base scenario, 1.00x exit)
A16: Required return | B16: 0.09 | C16: 0.1 | D16: 0.11 | E16: 0.12 | F16: 0.15
A17: Value per unit | B17: =(nav0*(1+Model!C$5))*0.025/(1+B16)^1+((nav0*(1+Model!C$5))*(1+Model!D$5))*0.025/(1+B16)^2+(((nav0*(1+Model!C$5))*(1+Model!D$5))*(1+Model!E$5))*0.025/(1+B16)^3+((((nav0*(1+Model!C$5))*(1+Model!D$5))*(1+Model!E$5))*(1+Model!F$5))*0.025/(1+B16)^4+(((((nav0*(1+Model!C$5))*(1+Model!D$5))*(1+Model!E$5))*(1+Model!F$5))*(1+Model!G$5))*0.025/(1+B16)^5+(((((nav0*(1+Model!C$5))*(1+Model!D$5))*(1+Model!E$5))*(1+Model!F$5))*(1+Model!G$5))*1/(1+B16)^5 | C17: =(nav0*(1+Model!C$5))*0.025/(1+C16)^1+((nav0*(1+Model!C$5))*(1+Model!D$5))*0.025/(1+C16)^2+(((nav0*(1+Model!C$5))*(1+Model!D$5))*(1+Model!E$5))*0.025/(1+C16)^3+((((nav0*(1+Model!C$5))*(1+Model!D$5))*(1+Model!E$5))*(1+Model!F$5))*0.025/(1+C16)^4+(((((nav0*(1+Model!C$5))*(1+Model!D$5))*(1+Model!E$5))*(1+Model!F$5))*(1+Model!G$5))*0.025/(1+C16)^5+(((((nav0*(1+Model!C$5))*(1+Model!D$5))*(1+Model!E$5))*(1+Model!F$5))*(1+Model!G$5))*1/(1+C16)^5 | D17: =(nav0*(1+Model!C$5))*0.025/(1+D16)^1+((nav0*(1+Model!C$5))*(1+Model!D$5))*0.025/(1+D16)^2+(((nav0*(1+Model!C$5))*(1+Model!D$5))*(1+Model!E$5))*0.025/(1+D16)^3+((((nav0*(1+Model!C$5))*(1+Model!D$5))*(1+Model!E$5))*(1+Model!F$5))*0.025/(1+D16)^4+(((((nav0*(1+Model!C$5))*(1+Model!D$5))*(1+Model!E$5))*(1+Model!F$5))*(1+Model!G$5))*0.025/(1+D16)^5+(((((nav0*(1+Model!C$5))*(1+Model!D$5))*(1+Model!E$5))*(1+Model!F$5))*(1+Model!G$5))*1/(1+D16)^5 | E17: =(nav0*(1+Model!C$5))*0.025/(1+E16)^1+((nav0*(1+Model!C$5))*(1+Model!D$5))*0.025/(1+E16)^2+(((nav0*(1+Model!C$5))*(1+Model!D$5))*(1+Model!E$5))*0.025/(1+E16)^3+((((nav0*(1+Model!C$5))*(1+Model!D$5))*(1+Model!E$5))*(1+Model!F$5))*0.025/(1+E16)^4+(((((nav0*(1+Model!C$5))*(1+Model!D$5))*(1+Model!E$5))*(1+Model!F$5))*(1+Model!G$5))*0.025/(1+E16)^5+(((((nav0*(1+Model!C$5))*(1+Model!D$5))*(1+Model!E$5))*(1+Model!F$5))*(1+Model!G$5))*1/(1+E16)^5 | F17: =(nav0*(1+Model!C$5))*0.025/(1+F16)^1+((nav0*(1+Model!C$5))*(1+Model!D$5))*0.025/(1+F16)^2+(((nav0*(1+Model!C$5))*(1+Model!D$5))*(1+Model!E$5))*0.025/(1+F16)^3+((((nav0*(1+Model!C$5))*(1+Model!D$5))*(1+Model!E$5))*(1+Model!F$5))*0.025/(1+F16)^4+(((((nav0*(1+Model!C$5))*(1+Model!D$5))*(1+Model!E$5))*(1+Model!F$5))*(1+Model!G$5))*0.025/(1+F16)^5+(((((nav0*(1+Model!C$5))*(1+Model!D$5))*(1+Model!E$5))*(1+Model!F$5))*(1+Model!G$5))*1/(1+F16)^5
