Workbook

Sheet Model_Info
A1: VCT.NZ - Vector Limited - owner-FCF DCF model (regulated-network adaptation)
A2: Version 1.1, built 2026-09-19 by the dcf-analyst agent (Claude Fable 5.1) at the research orchestrator's request. Supersedes v1.0 (same day): anchors re-verified against core_metrics/kpis after FY2025/FY2026 were loaded; driver paths unchanged; Reconciliation tab added.
A3: STALE WARNING: every anchor below goes stale. Price is a snapshot; balance sheet is 30-Jun-2026; guidance is FY27 as issued 18-Aug-2026. Refresh after each half-year result.
A5: DATA VINTAGE
A6: Price NZ$4.72, Yahoo Finance regular close 2026-09-18T05:00:01Z (52w 4.40-5.30).
A7: Balance sheet 30-Jun-2026: face borrowings 2,235.1 + leases 52.3 - cash 5.4 = economic net debt 2,282.0 (Annual Report 2026 note 25.3).
A8: Shares 1,000,000,000 at 30-Jun-2026 (AR26 note 25.3); no options, no LTI, no convertibles. Held flat.
A9: FY26 actuals: revenue ex-contributions 1,004.4 (1,195.3 - 190.9); adjusted EBITDA 482.2; D&A 233.0; cash gross capex 531.3; contributions 191.5 cash / 190.9 revenue basis (AR26 p.62-63, results deck 18-Aug-2026; all tied to core_metrics/kpis 2026-09-19).
A10: Owner FCF 72.6 reconciles from reported FCF 101.2: + interest paid 102.5 - interest received 14.7 - Bluecurrent dividend 32.6 - tax normalisation 68.4 - working-capital timing 15.4 (AR26 cash flow statement p.63).
A11: FY27 guidance (18-Aug-2026): adj EBITDA 540-560 (includes ~54 one-off wash-up/IRIS); gross capex 605-635; contributions 160-190.
A13: METHODOLOGY
A14: Model: component owner-FCF DCF (dcf-methods/references/owner-fcf.md) on a 10-year horizon FY27-FY36, Gordon/cap terminal, end-year discounting.
... A29: CELL COLOURS: blue = hardcoded input; yellow fill = key lever; black = formula; green = cross-sheet link.

Sheet Reconciliation
A1: Reconciliation v1.0 -> v1.1 (NZD per share). Prior values hardcoded; live values link to the model. Bridge figures approximate; live cells authoritative.
A3: Scenario | B3: v1.0 (2026-09-19, price 4.72) | C3: v1.1 live | D3: Change
A4: bear | B4: 0.47 | C4: =DCF_Bear!$B$38 | D4: =C4-B4
A5: base | B5: 2.59 | C5: =DCF_Base!$B$38 | D5: =C5-B5
A6: bull | B6: 4.03 | C6: =DCF_Bull!$B$38 | D6: =C6-B6
A7: weighted | B7: 2.42 | C7: =Valuation!$B$8 | D7: =C7-B7
A9: Bridge (weighted IV)
A10: Prior weighted IV (v1.0, 2026-09-19, NZ$4.72) | B10: 2.42
A11: Anchor refresh: price unchanged (NZ$4.72, 18-Sep close; no NZX session since); economic net debt 2,282.0, shares 1,000m, FY26 adj EBITDA 482.2, contributions 190.9, D&A 233.0 all confirmed against core_metrics/kpis | B11: 0
A12: Driver change: none. FY27 guidance (adj EBITDA 540-560, gross capex 605-635, contributions 160-190, ~54 wash-up/IRIS) was already in v1.0; FY26 was an actual, not a forecast, in v1.0 | B12: 0
A13: Methodology change: none (same component owner-FCF build, 6.75% WACC, 30x cap, bridge) | B13: 0
A14: Rounding on full-precision recompute | B14: 0
A15: New weighted IV | B15: 2.42
A17: Deliberately unchanged (evidence that would move each)
A18: Growth paths (base 9/-1/5/5/9/5.5/5/4.5/4/3.5) | B18: tied to DPP4 revenue path + FY27 wash-up drop-out + DPP5 step; no new regulatory signal since v1.0 | C18: Commerce Commission DPP5 issues paper / WACC determination (2029); FY27 H1 revenue print vs the +9% path
A19: Adj EBITDA margin 50.2% FY27 then 48.5% | B19: FY27 guidance midpoint 550 reproduces exactly; FY26 actual 48.0% | C19: CEO strategic review outcomes (Sep-2026 shareholder meeting) quantifying opex savings
A20: Net capex path 41% -> 27% of revenue | B20: FY27 guidance mid (620 - 175 + 5.5 lease = 450.5) = 41.1% reproduces; AMP26 $5.4bn FY26-36 = ~$490m/yr gross average, consistent with the taper | C20: AMP27 revising the 10-year envelope; FY27 actual contributions outside 160-190
A21: 28% cash tax from FY27; 35.3 tax asset in bridge | B21: AR26 note 17 confirms the 35.3 current asset and nil non-current | C21: FY27 cash tax paid materially below 28% of EBIT after the asset is consumed
A22: Bluecurrent at 700 | B22: FY26 distributions 55 (32.6 + 10.2 + 12.1) confirmed in deck p.14; carrying value 580.4 confirmed in note 16.1 | C22: FY27 distribution guidance; any QIC/Vector sale process
A23: WACC 6.75%, terminal g 3.0/2.5/3.25, weights 25/50/25 | B23: no change in NZ 10y (~4.4%) or the regulated WACC reference since v1.0 | C23: +/-50bp move in NZ 10y govt; DPP5 WACC signalling

Sheet Actuals
A1: Reported history, continuing operations, NZD millions (AR26 five-year summary p.55; results decks). Hardcoded.
A3: Metric | B3: FY2022 | C3: FY2023 | D3: FY2024 | E3: FY2025 | F3: FY2026 | G3: Source
A4: Total revenue (incl. contributions) | C4: 902.9 | D4: 963.9 | E4: 1013 | F4: 1104 | G4: 1195.3 | H4: AR26 five-year summary
A5: Capital contributions | C5: 152 | D5: 188 | E5: 195 | F5: 210.5 | G5: 190.9 | H5: results decks; FY25/26 GAAP-to-non-GAAP reconciliation
A6: Revenue ex-contributions | C6: =C4-C5 | D6: =D4-D5 | E6: =E4-E5 | F6: =F4-F5 | G6: =G4-G5 | H6: derived
A7: Adjusted EBITDA | C7: 316.8 | D7: 311 | E7: 345.3 | F7: 401.1 | G7: 482.2 | H7: AR26 five-year summary
A8: Depreciation and amortisation | C8: 182.8 | D8: 193.7 | E8: 218.3 | F8: 231.4 | G8: 233 | H8: AR26 five-year summary
A9: Adjusted EBIT | C9: 134 | D9: 117.3 | E9: 127 | F9: 169.7 | G9: 249.2 | H9: AR26 five-year summary
A10: Net profit continuing | C10: 137.3 | D10: 101.5 | E10: 75.6 | F10: 154.7 | G10: 240.2 | H10: AR26 five-year summary (FY24 60.6 / FY25 37.0 impairments)
A11: Gross capex (deck, accrual) | C11: 370 | D11: 492 | E11: 499 | F11: 470 | G11: 544 | H11: results deck 18-Aug-2026 p.9
A12: Net capex (gross less contributions) | C12: =C11-C5 | D12: =D11-D5 | E12: =E11-E5 | F12: =F11-F5 | G12: =G11-G5 | H12: derived
A13: Operating cash flow | C13: 518.8 | D13: 517.1 | E13: 445.1 | F13: 515.2 | G13: 632.5 | H13: AR26 five-year summary
A14: Cash capex (PPE + software) | C14: 558.8 | D14: 639 | E14: 488.7 | F14: 474.9 | G14: 531.3 | H14: AR26 five-year summary (FY22-24 include discontinued)
A15: Dividends paid | C15: 169.1 | D15: 169.9 | E15: 234.9 | F15: 268.7 | G15: 255 | H15: AR26 five-year summary
A16: Economic net debt (30 June) | C16: 3296.8 | D16: 1933.1 | E16: 2128.6 | F16: 2148.3 | G16: 2282 | H16: AR26 five-year summary
A17: Total equity | C17: 2430.1 | D17: 3958 | E17: 3776.7 | F17: 3600.9 | G17: 3629 | H17: AR26 five-year summary
A18: Income tax paid | C18: 20.1 | D18: 20 | E18: 4.8 | F18: 2.7 | G18: 1.4 | H18: cash flow statements
A21: Balance-sheet snapshot 30-Jun-2026
A22: Face value of borrowings | B22: 2235.1
A23: Lease liabilities | B23: 52.3
A24: Cash and deposits | B24: 5.4
A25: Economic net debt | B25: =B22+B23-B24
A26: Investment in Bluecurrent JV (carrying) | B26: 580.4
A27: Current income tax asset | B27: 35.3
A28: Contingent consideration receivable | B28: 26.6
A29: Ordinary shares (millions) | B29: 1000
A30: Buybacks FY26 | B30: 0
A31: SBC FY26 | B31: 0
A32: FY27 guidance adj EBITDA mid | B32: 550
A33: FY27 guidance gross capex mid | B33: 620
A34: FY27 guidance contributions mid | B34: 175

Sheet Assumptions
A1: Global assumptions (blue = input). Scenario driver paths live on the DCF tabs.
A3: WACC (NZD) | B3: 0.0675 | C3: rf 4.4% + 0.65 x 5.5% = 8.0% CoE; 3.8% post-tax debt; 32.6% debt weight; same in all scenarios
A4: D&A % of revenue | B4: 0.235 | C4: FY26 23.2%; RAB/revenue ratio roughly stable so held flat
A5: WC capture on revenue change | B5: 0 | C5: regulated receivables/contract assets roughly offset; nil
A6: Net debt used in bridge | B6: =B11-B12 | C6: economic net debt less non-operating assets
A7: Diluted shares (millions) | B7: 1000 | C7: AR26 note 25.3, 30-Jun-2026
A8: Price (NZD) | B8: 4.72 | C8: Yahoo regular close 2026-09-18T05:00:01Z
A9: Terminal cap multiple (x FCF) | B9: 30 | C9: 30x for a regulated network (Gordon at WACC ~27.5x = ~1.0x RAB)
A10: Hurdle rate | B10: 0.15 | C10: entry price IRR
A11: Economic net debt 30-Jun-2026 | B11: 2282 | C11: face borrowings 2,235.1 + leases 52.3 - cash 5.4
A12: Non-operating assets | B12: =B13+B14+B15 | C12: sum of the three lines below
A13: Bluecurrent 50% JV + shareholder loans (value) | B13: 700 | C13: 55/yr distributions at 10% CoE, 2% g; carrying value 580.4
A14: Current income tax asset | B14: 35.3 | C14: prepaid tax, consumed against FY27 cash tax
A15: Contingent consideration receivable | B15: 26.6 | C15: gas trading sale earn-outs, 5.0 current + 21.6 non-current
A16: FY26 revenue ex-contributions | B16: 1004.4 | C16: 1,195.3 total less 190.9 contributions
A17: RAB estimate (electricity + gas), NZD m | B17: 4700 | C17: analyst estimate +/-10%; sanity cross-check only
A19: Scenario | B19: Terminal growth | C19: Probability | D19: Narrative
A20: bear | B20: 0.025 | C20: 0.25 | D20: NZ rates fall back toward 2021 levels before the DPP5 reset, so the allowed return on the larger RAB is cut (FY31 -5% revenue step) while political pressure on Auckland lines charges tightens the path; capex over-runs and IRIS penalties leave part of the record capex programme unrecognised (capex stays 30%+ of revenue), opex inflation and storm/resilience costs compress the margin to 46%, gas distribution volumes decline faster than accelerated depreciation recovers. Terminal growth 2.5%.
A21: base | B21: 0.03 | C21: 0.5 | D21: DPP4 (to Mar-2030) plays out as set: FY27 revenue +9% including the ~$54m wash-up/IRIS one-off that then drops out (FY28 -1%), CPI+RAB growth of ~5% a year thereafter. Net capex runs at the guided ~$450m in FY27 (41% of revenue) and tapers to 28% by FY36 as the replacement wave passes and data-centre/EV growth capex normalises. DPP5 (Apr-2030) resets on a RAB ~25-30% larger at a similar ~7% WACC, giving a +9% revenue step in FY31. Adj EBITDA margin holds ~48.5% (opex inflation offset by scale). Gas distribution declines slowly inside the blend. WACC 6.75%, terminal growth 3% (CPI ~2% + ~1% real RAB growth).
A22: bull | B22: 0.0325 | C22: 0.25 | D22: Auckland electrification and the flagged 500MW of data-centre load arrive on schedule, the capex programme is delivered efficiently (IRIS rewards rather than penalties), the DPP5 reset lands with a high allowed WACC (rates stay ~4-4.5%) on the enlarged RAB (+12% FY31 step), and the new CEO's efficiency review lifts the margin to 50%. Capex intensity falls faster (27% by FY36) as demand-side orchestration (Symphony) defers reinforcement. Terminal growth 3.25%.
A23: Weights check (must be 1) | C23: =SUM(C20:C22)
A24: Weights rationale | D24: 25/50/25 rather than the 15/50/35 house default. Bear raised to 25%: essentially all earnings depend on one regulator's five-yearly reset and the next one (DPP5, Apr-2030) falls inside the explicit horizon; gas distribution is a slowly stranding asset; the dividend is debt-funded through a record capex programme. Bull cut to 25%: it needs rates to stay high into the DPP5 reset AND the data-centre load AND efficient delivery of $600m+/yr capex, three independent things.

Sheet DCF_Bear
A1: DCF_Bear - NZD millions - drivers in blue on rows 5, 7, 9, 14, 22
A3: Year | B3: 2026A | C3: 2027E | D3: 2028E | E3: 2029E | F3: 2030E | G3: 2031E | H3: 2032E | I3: 2033E | J3: 2034E | K3: 2035E | L3: 2036E
A4: Index | B4: 0 | C4: 1 | D4: 2 | E4: 3 | F4: 4 | G4: 5 | H4: 6 | I4: 7 | J4: 8 | K4: 9 | L4: 10
A5: Revenue growth | C5: 0.085 | D5: -0.02 | E5: 0.04 | F5: 0.04 | G5: -0.05 | H5: 0.035 | I5: 0.035 | J5: 0.03 | K5: 0.03 | L5: 0.025
A6: Revenue (ex contributions) | B6: =Assumptions!B16 | C6: =B6*(1+C5) | D6: =C6*(1+D5) | E6: =D6*(1+E5) | F6: =E6*(1+F5) | G6: =F6*(1+G5) | H6: =G6*(1+H5) | I6: =H6*(1+I5) | J6: =I6*(1+J5) | ... L6: =K6*(1+L5)
A7: Adj EBITDA margin | B7: =B8/B6 | C7: 0.495 | D7: 0.47 | E7: 0.47 | F7: 0.465 | G7: 0.46 | H7: 0.46 | I7: 0.46 | J7: 0.46 | K7: 0.46 | L7: 0.46
A8: Adjusted EBITDA | B8: 482.2 | C8: =C6*C7 | D8: =D6*D7 | E8: =E6*E7 | F8: =F6*F7 | G8: =G6*G7 | H8: =H6*H7 | I8: =I6*I7 | J8: =J6*J7 | ... L8: =L6*L7
A9: SBC % revenue | C9: 0 | D9: 0 | E9: 0 | F9: 0 | G9: 0 | H9: 0 | I9: 0 | J9: 0 | K9: 0 | L9: 0
A10: SBC | C10: =-C6*C9 | D10: =-D6*D9 | E10: =-E6*E9 | F10: =-F6*F9 | G10: =-G6*G9 | H10: =-H6*H9 | I10: =-I6*I9 | J10: =-J6*J9 | ... L10: =-L6*L9
A11: Owner EBITDA | C11: =C8+C10 | D11: =D8+D10 | E11: =E8+E10 | F11: =F8+F10 | G11: =G8+G10 | H11: =H8+H10 | I11: =I8+I10 | J11: =J8+J10 | ... L11: =L8+L10
A12: D&A | B12: -233 | C12: =-C6*Assumptions!$B$4 | D12: =-D6*Assumptions!$B$4 | E12: =-E6*Assumptions!$B$4 | F12: =-F6*Assumptions!$B$4 | G12: =-G6*Assumptions!$B$4 | H12: =-H6*Assumptions!$B$4 | I12: =-I6*Assumptions!$B$4 | J12: =-J6*Assumptions!$B$4 | ... L12: =-L6*Assumptions!$B$4
A13: EBIT | B13: =B8+B12 | C13: =C11+C12 | D13: =D11+D12 | E13: =E11+E12 | F13: =F11+F12 | G13: =G11+G12 | H13: =H11+H12 | I13: =I11+I12 | J13: =J11+J12 | ... L13: =L11+L12
A14: Cash tax rate | B14: 0.28 | C14: 0.28 | D14: 0.28 | E14: 0.28 | F14: 0.28 | G14: 0.28 | H14: 0.28 | I14: 0.28 | J14: 0.28 | K14: 0.28 | L14: 0.28
A15: NOPAT | B15: =B13-MAX(0,B13)*B14 | C15: =C13-MAX(0,C13)*C14 | D15: =D13-MAX(0,D13)*D14 | E15: =E13-MAX(0,E13)*E14 | F15: =F13-MAX(0,F13)*F14 | G15: =G13-MAX(0,G13)*G14 | H15: =H13-MAX(0,H13)*H14 | I15: =I13-MAX(0,I13)*I14 | ... L15: =L13-MAX(0,L13)*L14
A16: add back D&A | B16: =-B12 | C16: =-C12 | D16: =-D12 | E16: =-E12 | F16: =-F12 | G16: =-G12 | H16: =-H12 | I16: =-I12 | ... L16: =-L12
A17: less net capex | B17: -339.8 | C17: =-C6*C22 | D17: =-D6*D22 | E17: =-E6*E22 | F17: =-F6*F22 | G17: =-G6*G22 | H17: =-H6*H22 | I17: =-I6*I22 | J17: =-J6*J22 | ... L17: =-L6*L22
A18: add working capital | C18: =Assumptions!$B$5*(C6-B6) | D18: =Assumptions!$B$5*(D6-C6) | E18: =Assumptions!$B$5*(E6-D6) | F18: =Assumptions!$B$5*(F6-E6) | G18: =Assumptions!$B$5*(G6-F6) | H18: =Assumptions!$B$5*(H6-G6) | I18: =Assumptions!$B$5*(I6-H6) | J18: =Assumptions!$B$5*(J6-I6) | ... L18: =Assumptions!$B$5*(L6-K6)
A19: Unlevered owner FCF | B19: =B15+B16+B17 | C19: =C15+C16+C17+C18 | D19: =D15+D16+D17+D18 | E19: =E15+E16+E17+E18 | F19: =F15+F16+F17+F18 | G19: =G15+G16+G17+G18 | H19: =H15+H16+H17+H18 | I19: =I15+I16+I17+I18 | J19: =J15+J16+J17+J18 | ... L19: =L15+L16+L17+L18
A20: Discount factor | C20: =1/(1+Assumptions!$B$3)^C4 | D20: =1/(1+Assumptions!$B$3)^D4 | E20: =1/(1+Assumptions!$B$3)^E4 | F20: =1/(1+Assumptions!$B$3)^F4 | G20: =1/(1+Assumptions!$B$3)^G4 | H20: =1/(1+Assumptions!$B$3)^H4 | I20: =1/(1+Assumptions!$B$3)^I4 | J20: =1/(1+Assumptions!$B$3)^J4 | ... L20: =1/(1+Assumptions!$B$3)^L4
A21: PV of FCF | C21: =C19*C20 | D21: =D19*D20 | E21: =E19*E20 | F21: =F19*F20 | G21: =G19*G20 | H21: =H19*H20 | I21: =I19*I20 | J21: =J19*J20 | ... L21: =L19*L20
A22: Net capex % revenue (driver) | C22: 0.41 | D22: 0.4 | E22: 0.39 | F22: 0.38 | G22: 0.36 | H22: 0.34 | I22: 0.33 | J22: 0.32 | K22: 0.305 | L22: 0.295
A23: Memo: FCF before SBC | C23: =C19-C10 | D23: =D19-D10 | E23: =E19-E10 | F23: =F19-F10 | G23: =G19-G10 | H23: =H19-H10 | I23: =I19-I10 | J23: =J19-J10 | ... L23: =L19-L10
A24: Memo: owner FCF margin | B24: =B19/B6 | C24: =C19/C6 | D24: =D19/D6 | E24: =E19/E6 | F24: =F19/F6 | G24: =G19/G6 | H24: =H19/H6 | I24: =I19/I6 | ... L24: =L19/L6
A26: Sum of PV (FY27-FY36) | B26: =SUM(C21:L21)
A27: Terminal growth | B27: =Assumptions!$B$20
A28: Terminal-year FCF x (1+g) | B28: =L19*(1+B27)
A29: Gordon terminal value | B29: =IF(Assumptions!$B$3>B27,B28/(Assumptions!$B$3-B27),"n/a")
A30: Cap terminal value | B30: =Assumptions!$B$9*L19
A31: Terminal value used | B31: =MAX(0,MIN(B29,B30))
A32: Implied exit multiple (x FCF) | B32: =IF(L19<>0,B31/L19,"n/a")
A33: PV of terminal value | B33: =B31*L20
A34: Enterprise value | B34: =B26+B33
A35: less net debt (bridge) | B35: =-Assumptions!$B$6
A36: Equity value | B36: =B34+B35
A37: Diluted shares (m) | B37: =Assumptions!$B$7
A38: Value per share (NZD) | B38: =B36/B37
A39: Upside vs price | B39: =B38/Assumptions!$B$8-1
A40: Terminal % of EV | B40: =B33/B34
A41: Street: PV of explicit SBC | B41: =SUMPRODUCT(-C10:L10/(1+Assumptions!$B$3)^C4:L4)
A42: Street: PV of terminal SBC | B42: =IF(Assumptions!$B$3>B27,(-L10*(1+B27)/(Assumptions!$B$3-B27))*L20,0)
...

Sheet DCF_Base
A1: DCF_Base - NZD millions - drivers in blue on rows 5, 7, 9, 14, 22
A3: Year | B3: 2026A | C3: 2027E | D3: 2028E | E3: 2029E | F3: 2030E | G3: 2031E | H3: 2032E | I3: 2033E | J3: 2034E | K3: 2035E | L3: 2036E
A4: Index | B4: 0 | C4: 1 | D4: 2 | E4: 3 | F4: 4 | G4: 5 | H4: 6 | I4: 7 | J4: 8 | K4: 9 | L4: 10
A5: Revenue growth | C5: 0.09 | D5: -0.01 | E5: 0.05 | F5: 0.05 | G5: 0.09 | H5: 0.055 | I5: 0.05 | J5: 0.045 | K5: 0.04 | L5: 0.035
A6: Revenue (ex contributions) | B6: =Assumptions!B16 | C6: =B6*(1+C5) | D6: =C6*(1+D5) | E6: =D6*(1+E5) | F6: =E6*(1+F5) | G6: =F6*(1+G5) | H6: =G6*(1+H5) | I6: =H6*(1+I5) | J6: =I6*(1+J5) | ... L6: =K6*(1+L5)
A7: Adj EBITDA margin | B7: =B8/B6 | C7: 0.502 | D7: 0.48 | E7: 0.485 | F7: 0.485 | G7: 0.485 | H7: 0.485 | I7: 0.485 | J7: 0.485 | K7: 0.485 | L7: 0.485
A8: Adjusted EBITDA | B8: 482.2 | C8: =C6*C7 | D8: =D6*D7 | E8: =E6*E7 | F8: =F6*F7 | G8: =G6*G7 | H8: =H6*H7 | I8: =I6*I7 | J8: =J6*J7 | ... L8: =L6*L7
A9: SBC % revenue | C9: 0 | D9: 0 | E9: 0 | F9: 0 | G9: 0 | H9: 0 | I9: 0 | J9: 0 | K9: 0 | L9: 0
A10: SBC | C10: =-C6*C9 | D10: =-D6*D9 | E10: =-E6*E9 | F10: =-F6*F9 | G10: =-G6*G9 | H10: =-H6*H9 | I10: =-I6*I9 | J10: =-J6*J9 | ... L10: =-L6*L9
A11: Owner EBITDA | C11: =C8+C10 | D11: =D8+D10 | E11: =E8+E10 | F11: =F8+F10 | G11: =G8+G10 | H11: =H8+H10 | I11: =I8+I10 | J11: =J8+J10 | ... L11: =L8+L10
A12: D&A | B12: -233 | C12: =-C6*Assumptions!$B$4 | D12: =-D6*Assumptions!$B$4 | E12: =-E6*Assumptions!$B$4 | F12: =-F6*Assumptions!$B$4 | G12: =-G6*Assumptions!$B$4 | H12: =-H6*Assumptions!$B$4 | I12: =-I6*Assumptions!$B$4 | J12: =-J6*Assumptions!$B$4 | ... L12: =-L6*Assumptions!$B$4
A13: EBIT | B13: =B8+B12 | C13: =C11+C12 | D13: =D11+D12 | E13: =E11+E12 | F13: =F11+F12 | G13: =G11+G12 | H13: =H11+H12 | I13: =I11+I12 | J13: =J11+J12 | ... L13: =L11+L12
A14: Cash tax rate | B14: 0.28 | C14: 0.28 | D14: 0.28 | E14: 0.28 | F14: 0.28 | G14: 0.28 | H14: 0.28 | I14: 0.28 | J14: 0.28 | K14: 0.28 | L14: 0.28
A15: NOPAT | B15: =B13-MAX(0,B13)*B14 | C15: =C13-MAX(0,C13)*C14 | D15: =D13-MAX(0,D13)*D14 | E15: =E13-MAX(0,E13)*E14 | F15: =F13-MAX(0,F13)*F14 | G15: =G13-MAX(0,G13)*G14 | H15: =H13-MAX(0,H13)*H14 | I15: =I13-MAX(0,I13)*I14 | ... L15: =L13-MAX(0,L13)*L14
A16: add back D&A | B16: =-B12 | C16: =-C12 | D16: =-D12 | E16: =-E12 | F16: =-F12 | G16: =-G12 | H16: =-H12 | I16: =-I12 | ... L16: =-L12
A17: less net capex | B17: -339.8 | C17: =-C6*C22 | D17: =-D6*D22 | E17: =-E6*E22 | F17: =-F6*F22 | G17: =-G6*G22 | H17: =-H6*H22 | I17: =-I6*I22 | J17: =-J6*J22 | ... L17: =-L6*L22
A18: add working capital | C18: =Assumptions!$B$5*(C6-B6) | D18: =Assumptions!$B$5*(D6-C6) | E18: =Assumptions!$B$5*(E6-D6) | F18: =Assumptions!$B$5*(F6-E6) | G18: =Assumptions!$B$5*(G6-F6) | H18: =Assumptions!$B$5*(H6-G6) | I18: =Assumptions!$B$5*(I6-H6) | J18: =Assumptions!$B$5*(J6-I6) | ... L18: =Assumptions!$B$5*(L6-K6)
A19: Unlevered owner FCF | B19: =B15+B16+B17 | C19: =C15+C16+C17+C18 | D19: =D15+D16+D17+D18 | E19: =E15+E16+E17+E18 | F19: =F15+F16+F17+F18 | G19: =G15+G16+G17+G18 | H19: =H15+H16+H17+H18 | I19: =I15+I16+I17+I18 | J19: =J15+J16+J17+J18 | ... L19: =L15+L16+L17+L18
A20: Discount factor | C20: =1/(1+Assumptions!$B$3)^C4 | D20: =1/(1+Assumptions!$B$3)^D4 | E20: =1/(1+Assumptions!$B$3)^E4 | F20: =1/(1+Assumptions!$B$3)^F4 | G20: =1/(1+Assumptions!$B$3)^G4 | H20: =1/(1+Assumptions!$B$3)^H4 | I20: =1/(1+Assumptions!$B$3)^I4 | J20: =1/(1+Assumptions!$B$3)^J4 | ... L20: =1/(1+Assumptions!$B$3)^L4
A21: PV of FCF | C21: =C19*C20 | D21: =D19*D20 | E21: =E19*E20 | F21: =F19*F20 | G21: =G19*G20 | H21: =H19*H20 | I21: =I19*I20 | J21: =J19*J20 | ... L21: =L19*L20
A22: Net capex % revenue (driver) | C22: 0.41 | D22: 0.39 | E22: 0.37 | F22: 0.36 | G22: 0.34 | H22: 0.32 | I22: 0.305 | J22: 0.29 | K22: 0.28 | L22: 0.27
A23: Memo: FCF before SBC | C23: =C19-C10 | D23: =D19-D10 | E23: =E19-E10 | F23: =F19-F10 | G23: =G19-G10 | H23: =H19-H10 | I23: =I19-I10 | J23: =J19-J10 | ... L23: =L19-L10
A24: Memo: owner FCF margin | B24: =B19/B6 | C24: =C19/C6 | D24: =D19/D6 | E24: =E19/E6 | F24: =F19/F6 | G24: =G19/G6 | H24: =H19/H6 | I24: =I19/I6 | ... L24: =L19/L6
A26: Sum of PV (FY27-FY36) | B26: =SUM(C21:L21)
A27: Terminal growth | B27: =Assumptions!$B$21
A28: Terminal-year FCF x (1+g) | B28: =L19*(1+B27)
A29: Gordon terminal value | B29: =IF(Assumptions!$B$3>B27,B28/(Assumptions!$B$3-B27),"n/a")
A30: Cap terminal value | B30: =Assumptions!$B$9*L19
A31: Terminal value used | B31: =MAX(0,MIN(B29,B30))
A32: Implied exit multiple (x FCF) | B32: =IF(L19<>0,B31/L19,"n/a")
A33: PV of terminal value | B33: =B31*L20
A34: Enterprise value | B34: =B26+B33
A35: less net debt (bridge) | B35: =-Assumptions!$B$6
A36: Equity value | B36: =B34+B35
A37: Diluted shares (m) | B37: =Assumptions!$B$7
A38: Value per share (NZD) | B38: =B36/B37
A39: Upside vs price | B39: =B38/Assumptions!$B$8-1
A40: Terminal % of EV | B40: =B33/B34
A41: Street: PV of explicit SBC | B41: =SUMPRODUCT(-C10:L10/(1+Assumptions!$B$3)^C4:L4)
A42: Street: PV of terminal SBC | B42: =IF(Assumptions!$B$3>B27,(-L10*(1+B27)/(Assumptions!$B$3-B27))*L20,0)
...

Sheet DCF_Bull
A1: DCF_Bull - NZD millions - drivers in blue on rows 5, 7, 9, 14, 22
A3: Year | B3: 2026A | C3: 2027E | D3: 2028E | E3: 2029E | F3: 2030E | G3: 2031E | H3: 2032E | I3: 2033E | J3: 2034E | K3: 2035E | L3: 2036E
A4: Index | B4: 0 | C4: 1 | D4: 2 | E4: 3 | F4: 4 | G4: 5 | H4: 6 | I4: 7 | J4: 8 | K4: 9 | L4: 10
A5: Revenue growth | C5: 0.095 | D5: 0 | E5: 0.06 | F5: 0.06 | G5: 0.12 | H5: 0.065 | I5: 0.06 | J5: 0.055 | K5: 0.05 | L5: 0.045
A6: Revenue (ex contributions) | B6: =Assumptions!B16 | C6: =B6*(1+C5) | D6: =C6*(1+D5) | E6: =D6*(1+E5) | F6: =E6*(1+F5) | G6: =F6*(1+G5) | H6: =G6*(1+H5) | I6: =H6*(1+I5) | J6: =I6*(1+J5) | ... L6: =K6*(1+L5)
A7: Adj EBITDA margin | B7: =B8/B6 | C7: 0.505 | D7: 0.485 | E7: 0.49 | F7: 0.495 | G7: 0.5 | H7: 0.5 | I7: 0.5 | J7: 0.5 | K7: 0.5 | L7: 0.5
A8: Adjusted EBITDA | B8: 482.2 | C8: =C6*C7 | D8: =D6*D7 | E8: =E6*E7 | F8: =F6*F7 | G8: =G6*G7 | H8: =H6*H7 | I8: =I6*I7 | J8: =J6*J7 | ... L8: =L6*L7
A9: SBC % revenue | C9: 0 | D9: 0 | E9: 0 | F9: 0 | G9: 0 | H9: 0 | I9: 0 | J9: 0 | K9: 0 | L9: 0
A10: SBC | C10: =-C6*C9 | D10: =-D6*D9 | E10: =-E6*E9 | F10: =-F6*F9 | G10: =-G6*G9 | H10: =-H6*H9 | I10: =-I6*I9 | J10: =-J6*J9 | ... L10: =-L6*L9
A11: Owner EBITDA | C11: =C8+C10 | D11: =D8+D10 | E11: =E8+E10 | F11: =F8+F10 | G11: =G8+G10 | H11: =H8+H10 | I11: =I8+I10 | J11: =J8+J10 | ... L11: =L8+L10
A12: D&A | B12: -233 | C12: =-C6*Assumptions!$B$4 | D12: =-D6*Assumptions!$B$4 | E12: =-E6*Assumptions!$B$4 | F12: =-F6*Assumptions!$B$4 | G12: =-G6*Assumptions!$B$4 | H12: =-H6*Assumptions!$B$4 | I12: =-I6*Assumptions!$B$4 | J12: =-J6*Assumptions!$B$4 | ... L12: =-L6*Assumptions!$B$4
A13: EBIT | B13: =B8+B12 | C13: =C11+C12 | D13: =D11+D12 | E13: =E11+E12 | F13: =F11+F12 | G13: =G11+G12 | H13: =H11+H12 | I13: =I11+I12 | J13: =J11+J12 | ... L13: =L11+L12
A14: Cash tax rate | B14: 0.28 | C14: 0.28 | D14: 0.28 | E14: 0.28 | F14: 0.28 | G14: 0.28 | H14: 0.28 | I14: 0.28 | J14: 0.28 | K14: 0.28 | L14: 0.28
A15: NOPAT | B15: =B13-MAX(0,B13)*B14 | C15: =C13-MAX(0,C13)*C14 | D15: =D13-MAX(0,D13)*D14 | E15: =E13-MAX(0,E13)*E14 | F15: =F13-MAX(0,F13)*F14 | G15: =G13-MAX(0,G13)*G14 | H15: =H13-MAX(0,H13)*H14 | I15: =I13-MAX(0,I13)*I14 | ... L15: =L13-MAX(0,L13)*L14
A16: add back D&A | B16: =-B12 | C16: =-C12 | D16: =-D12 | E16: =-E12 | F16: =-F12 | G16: =-G12 | H16: =-H12 | I16: =-I12 | ... L16: =-L12
A17: less net capex | B17: -339.8 | C17: =-C6*C22 | D17: =-D6*D22 | E17: =-E6*E22 | F17: =-F6*F22 | G17: =-G6*G22 | H17: =-H6*H22 | I17: =-I6*I22 | J17: =-J6*J22 | ... L17: =-L6*L22
A18: add working capital | C18: =Assumptions!$B$5*(C6-B6) | D18: =Assumptions!$B$5*(D6-C6) | E18: =Assumptions!$B$5*(E6-D6) | F18: =Assumptions!$B$5*(F6-E6) | G18: =Assumptions!$B$5*(G6-F6) | H18: =Assumptions!$B$5*(H6-G6) | I18: =Assumptions!$B$5*(I6-H6) | J18: =Assumptions!$B$5*(J6-I6) | ... L18: =Assumptions!$B$5*(L6-K6)
A19: Unlevered owner FCF | B19: =B15+B16+B17 | C19: =C15+C16+C17+C18 | D19: =D15+D16+D17+D18 | E19: =E15+E16+E17+E18 | F19: =F15+F16+F17+F18 | G19: =G15+G16+G17+G18 | H19: =H15+H16+H17+H18 | I19: =I15+I16+I17+I18 | J19: =J15+J16+J17+J18 | ... L19: =L15+L16+L17+L18
A20: Discount factor | C20: =1/(1+Assumptions!$B$3)^C4 | D20: =1/(1+Assumptions!$B$3)^D4 | E20: =1/(1+Assumptions!$B$3)^E4 | F20: =1/(1+Assumptions!$B$3)^F4 | G20: =1/(1+Assumptions!$B$3)^G4 | H20: =1/(1+Assumptions!$B$3)^H4 | I20: =1/(1+Assumptions!$B$3)^I4 | J20: =1/(1+Assumptions!$B$3)^J4 | ... L20: =1/(1+Assumptions!$B$3)^L4
A21: PV of FCF | C21: =C19*C20 | D21: =D19*D20 | E21: =E19*E20 | F21: =F19*F20 | G21: =G19*G20 | H21: =H19*H20 | I21: =I19*I20 | J21: =J19*J20 | ... L21: =L19*L20
A22: Net capex % revenue (driver) | C22: 0.41 | D22: 0.39 | E22: 0.37 | F22: 0.35 | G22: 0.33 | H22: 0.31 | I22: 0.295 | J22: 0.28 | K22: 0.27 | L22: 0.26
A23: Memo: FCF before SBC | C23: =C19-C10 | D23: =D19-D10 | E23: =E19-E10 | F23: =F19-F10 | G23: =G19-G10 | H23: =H19-H10 | I23: =I19-I10 | J23: =J19-J10 | ... L23: =L19-L10
A24: Memo: owner FCF margin | B24: =B19/B6 | C24: =C19/C6 | D24: =D19/D6 | E24: =E19/E6 | F24: =F19/F6 | G24: =G19/G6 | H24: =H19/H6 | I24: =I19/I6 | ... L24: =L19/L6
A26: Sum of PV (FY27-FY36) | B26: =SUM(C21:L21)
A27: Terminal growth | B27: =Assumptions!$B$22
A28: Terminal-year FCF x (1+g) | B28: =L19*(1+B27)
A29: Gordon terminal value | B29: =IF(Assumptions!$B$3>B27,B28/(Assumptions!$B$3-B27),"n/a")
A30: Cap terminal value | B30: =Assumptions!$B$9*L19
A31: Terminal value used | B31: =MAX(0,MIN(B29,B30))
A32: Implied exit multiple (x FCF) | B32: =IF(L19<>0,B31/L19,"n/a")
A33: PV of terminal value | B33: =B31*L20
A34: Enterprise value | B34: =B26+B33
A35: less net debt (bridge) | B35: =-Assumptions!$B$6
A36: Equity value | B36: =B34+B35
A37: Diluted shares (m) | B37: =Assumptions!$B$7
A38: Value per share (NZD) | B38: =B36/B37
A39: Upside vs price | B39: =B38/Assumptions!$B$8-1
A40: Terminal % of EV | B40: =B33/B34
A41: Street: PV of explicit SBC | B41: =SUMPRODUCT(-C10:L10/(1+Assumptions!$B$3)^C4:L4)
A42: Street: PV of terminal SBC | B42: =IF(Assumptions!$B$3>B27,(-L10*(1+B27)/(Assumptions!$B$3-B27))*L20,0)
...

Sheet FCF_Quality
A1: Reported FCF reconciled to unlevered owner FCF, continuing operations, NZD millions
B3: FY2022 | C3: FY2023 | D3: FY2024 | E3: FY2025 | F3: FY2026
A4: Adjusted EBITDA | B4: =Actuals!C7 | C4: =Actuals!D7 | D4: =Actuals!E7 | E4: =Actuals!F7 | F4: =Actuals!G7
A5: less tax at 28% on adj EBIT | B5: =-0.28*Actuals!C9 | C5: =-0.28*Actuals!D9 | D5: =-0.28*Actuals!E9 | E5: =-0.28*Actuals!F9 | F5: =-0.28*Actuals!G9
A6: less net capex (gross less contributions) | B6: =-Actuals!C12 | C6: =-Actuals!D12 | D6: =-Actuals!E12 | E6: =-Actuals!F12 | F6: =-Actuals!G12
A7: Unlevered owner FCF | B7: =C4+C5+C6 | C7: =D4+D5+D6 | D7: =E4+E5+E6 | E7: =F4+F5+F6 | F7: =G4+G5+G6
A8: Owner FCF margin (on revenue ex-contributions) | B8: =C7/Actuals!C6 | C8: =D7/Actuals!D6 | D8: =E7/Actuals!E6 | E8: =F7/Actuals!F6 | F8: =G7/Actuals!G6
A10: Memo: reported FCF (OCF less cash capex, levered) | B10: =Actuals!C13-Actuals!C14 | C10: =Actuals!D13-Actuals!D14 | D10: =Actuals!E13-Actuals!E14 | E10: =Actuals!F13-Actuals!F14 | F10: =Actuals!G13-Actuals!G14
A11: Memo: cash tax paid | B11: =Actuals!C18 | C11: =Actuals!D18 | D11: =Actuals!E18 | E11: =Actuals!F18 | F11: =Actuals!G18
A12: Memo: cash tax paid / adj EBIT (abnormal: prepaid tax asset) | B12: =Actuals!C18/Actuals!C9 | C12: =Actuals!D18/Actuals!D9 | D12: =Actuals!E18/Actuals!E9 | E12: =Actuals!F18/Actuals!F9 | F12: =Actuals!G18/Actuals!G9
A13: Memo: dividends paid / owner FCF | B13: =IF(C7>0,Actuals!C15/C7,"n/a") | C13: =IF(D7>0,Actuals!D15/D7,"n/a") | D13: =IF(E7>0,Actuals!E15/E7,"n/a") | E13: =IF(F7>0,Actuals!F15/F7,"n/a") | F13: =IF(G7>0,Actuals!G15/G7,"n/a")
A14: Memo: SBC (nil) | B14: =0 | C14: =0 | D14: =0 | E14: =0 | F14: =0
A15: Memo: interest income (excluded, adj EBITDA is pre-interest) | B15: =0 | C15: =0 | D15: =0 | E15: =0 | F15: =0
A17: FY22-FY24 reported FCF rows include since-sold gas trading/metering cash flows; the owner FCF rows use continuing-ops adjusted EBITDA and deck capex.

Sheet Valuation
A1: Valuation summary (NZD per share)
A3: Scenario | B3: Value/share | C3: Upside | D3: Probability | E3: Street value/share | F3: Entry price @15% (unfloored)
A4: bear | B4: =DCF_Bear!$B$38 | C4: =B4/Assumptions!$B$8-1 | D4: =Assumptions!$C$20 | E4: =DCF_Bear!$B$43 | F4: =(SUMPRODUCT(DCF_Bear!$C$19:$L$19/(1+Assumptions!$B$10)^DCF_Bear!$C$4:$L$4)+MAX(0,MIN(DCF_Bear!$L$19*(1+Assumptions!$B$20)/(Assumptions!$B$10-Assumptions!$B$20),Assumptions!$B$9*DCF_Bear!$L$19))/(1+Assumptions!$B$10)^10-Assumptions!$B$6)/Assumptions!$B$7
A5: base | B5: =DCF_Base!$B$38 | C5: =B5/Assumptions!$B$8-1 | D5: =Assumptions!$C$21 | E5: =DCF_Base!$B$43 | F5: =(SUMPRODUCT(DCF_Base!$C$19:$L$19/(1+Assumptions!$B$10)^DCF_Base!$C$4:$L$4)+MAX(0,MIN(DCF_Base!$L$19*(1+Assumptions!$B$21)/(Assumptions!$B$10-Assumptions!$B$21),Assumptions!$B$9*DCF_Base!$L$19))/(1+Assumptions!$B$10)^10-Assumptions!$B$6)/Assumptions!$B$7
A6: bull | B6: =DCF_Bull!$B$38 | C6: =B6/Assumptions!$B$8-1 | D6: =Assumptions!$C$22 | E6: =DCF_Bull!$B$43 | F6: =(SUMPRODUCT(DCF_Bull!$C$19:$L$19/(1+Assumptions!$B$10)^DCF_Bull!$C$4:$L$4)+MAX(0,MIN(DCF_Bull!$L$19*(1+Assumptions!$B$22)/(Assumptions!$B$10-Assumptions!$B$22),Assumptions!$B$9*DCF_Bull!$L$19))/(1+Assumptions!$B$10)^10-Assumptions!$B$6)/Assumptions!$B$7
A8: Probability-weighted value | B8: =SUMPRODUCT(B4:B6,D4:D6)
A9: Margin of safety vs price | B9: =1-Assumptions!$B$8/B8
A10: Street weighted value | B10: =SUMPRODUCT(E4:E6,D4:D6)
A11: Band position (n/a: SBC nil, house = street) | B11: =IF(ABS(B10-B8)<0.005,"n/a",(Assumptions!$B$8-B8)/(B10-B8))
A12: Weighted entry price @15% (unfloored; negative = no price meets hurdle) | B12: =SUMPRODUCT(F4:F6,D4:D6)
A13: Weighted entry price @15% floored at 0 | B13: =MAX(0,B12)
A15: Required-return table (base case; terminal value rebuilt at each rate)
A16: Required return | B16: Value/share
A17: 0.0675 | B17: =(SUMPRODUCT(DCF_Base!$C$19:$L$19/(1+$A$17)^DCF_Base!$C$4:$L$4)+MAX(0,MIN(DCF_Base!$L$19*(1+Assumptions!$B$21)/($A$17-Assumptions!$B$21),Assumptions!$B$9*DCF_Base!$L$19))/(1+$A$17)^10-Assumptions!$B$6)/Assumptions!$B$7 | C17: Model WACC row: must equal DCF_Base!B38
A18: 0.09 | B18: =(SUMPRODUCT(DCF_Base!$C$19:$L$19/(1+$A$18)^DCF_Base!$C$4:$L$4)+MAX(0,MIN(DCF_Base!$L$19*(1+Assumptions!$B$21)/($A$18-Assumptions!$B$21),Assumptions!$B$9*DCF_Base!$L$19))/(1+$A$18)^10-Assumptions!$B$6)/Assumptions!$B$7
A19: 0.1 | B19: =(SUMPRODUCT(DCF_Base!$C$19:$L$19/(1+$A$19)^DCF_Base!$C$4:$L$4)+MAX(0,MIN(DCF_Base!$L$19*(1+Assumptions!$B$21)/($A$19-Assumptions!$B$21),Assumptions!$B$9*DCF_Base!$L$19))/(1+$A$19)^10-Assumptions!$B$6)/Assumptions!$B$7
A20: 0.11 | B20: =(SUMPRODUCT(DCF_Base!$C$19:$L$19/(1+$A$20)^DCF_Base!$C$4:$L$4)+MAX(0,MIN(DCF_Base!$L$19*(1+Assumptions!$B$21)/($A$20-Assumptions!$B$21),Assumptions!$B$9*DCF_Base!$L$19))/(1+$A$20)^10-Assumptions!$B$6)/Assumptions!$B$7
A21: 0.12 | B21: =(SUMPRODUCT(DCF_Base!$C$19:$L$19/(1+$A$21)^DCF_Base!$C$4:$L$4)+MAX(0,MIN(DCF_Base!$L$19*(1+Assumptions!$B$21)/($A$21-Assumptions!$B$21),Assumptions!$B$9*DCF_Base!$L$19))/(1+$A$21)^10-Assumptions!$B$6)/Assumptions!$B$7
A22: 0.15 | B22: =(SUMPRODUCT(DCF_Base!$C$19:$L$19/(1+$A$22)^DCF_Base!$C$4:$L$4)+MAX(0,MIN(DCF_Base!$L$19*(1+Assumptions!$B$21)/($A$22-Assumptions!$B$21),Assumptions!$B$9*DCF_Base!$L$19))/(1+$A$22)^10-Assumptions!$B$6)/Assumptions!$B$7 | C22: Hurdle row (15%): must equal the base entry price
A25: Sensitivity: base value/share, WACC (rows) x terminal growth (columns)
B26: 0.02 | C26: 0.025 | D26: 0.03 | E26: 0.035 | F26: 0.04
A27: 0.0575 | B27: =IF($A27>B$26,(SUMPRODUCT(DCF_Base!$C$19:$L$19/(1+$A27)^DCF_Base!$C$4:$L$4)+MAX(0,MIN(DCF_Base!$L$19*(1+B$26)/($A27-B$26),Assumptions!$B$9*DCF_Base!$L$19))/(1+$A27)^10-Assumptions!$B$6)/Assumptions!$B$7,"n/a") | C27: =IF($A27>C$26,(SUMPRODUCT(DCF_Base!$C$19:$L$19/(1+$A27)^DCF_Base!$C$4:$L$4)+MAX(0,MIN(DCF_Base!$L$19*(1+C$26)/($A27-C$26),Assumptions!$B$9*DCF_Base!$L$19))/(1+$A27)^10-Assumptions!$B$6)/Assumptions!$B$7,"n/a") | D27: =IF($A27>D$26,(SUMPRODUCT(DCF_Base!$C$19:$L$19/(1+$A27)^DCF_Base!$C$4:$L$4)+MAX(0,MIN(DCF_Base!$L$19*(1+D$26)/($A27-D$26),Assumptions!$B$9*DCF_Base!$L$19))/(1+$A27)^10-Assumptions!$B$6)/Assumptions!$B$7,"n/a") | E27: =IF($A27>E$26,(SUMPRODUCT(DCF_Base!$C$19:$L$19/(1+$A27)^DCF_Base!$C$4:$L$4)+MAX(0,MIN(DCF_Base!$L$19*(1+E$26)/($A27-E$26),Assumptions!$B$9*DCF_Base!$L$19))/(1+$A27)^10-Assumptions!$B$6)/Assumptions!$B$7,"n/a") | F27: =IF($A27>F$26,(SUMPRODUCT(DCF_Base!$C$19:$L$19/(1+$A27)^DCF_Base!$C$4:$L$4)+MAX(0,MIN(DCF_Base!$L$19*(1+F$26)/($A27-F$26),Assumptions!$B$9*DCF_Base!$L$19))/(1+$A27)^10-Assumptions!$B$6)/Assumptions!$B$7,"n/a")
A28: 0.0625 | B28: =IF($A28>B$26,(SUMPRODUCT(DCF_Base!$C$19:$L$19/(1+$A28)^DCF_Base!$C$4:$L$4)+MAX(0,MIN(DCF_Base!$L$19*(1+B$26)/($A28-B$26),Assumptions!$B$9*DCF_Base!$L$19))/(1+$A28)^10-Assumptions!$B$6)/Assumptions!$B$7,"n/a") | C28: =IF($A28>C$26,(SUMPRODUCT(DCF_Base!$C$19:$L$19/(1+$A28)^DCF_Base!$C$4:$L$4)+MAX(0,MIN(DCF_Base!$L$19*(1+C$26)/($A28-C$26),Assumptions!$B$9*DCF_Base!$L$19))/(1+$A28)^10-Assumptions!$B$6)/Assumptions!$B$7,"n/a") | D28: =IF($A28>D$26,(SUMPRODUCT(DCF_Base!$C$19:$L$19/(1+$A28)^DCF_Base!$C$4:$L$4)+MAX(0,MIN(DCF_Base!$L$19*(1+D$26)/($A28-D$26),Assumptions!$B$9*DCF_Base!$L$19))/(1+$A28)^10-Assumptions!$B$6)/Assumptions!$B$7,"n/a") | E28: =IF($A28>E$26,(SUMPRODUCT(DCF_Base!$C$19:$L$19/(1+$A28)^DCF_Base!$C$4:$L$4)+MAX(0,MIN(DCF_Base!$L$19*(1+E$26)/($A28-E$26),Assumptions!$B$9*DCF_Base!$L$19))/(1+$A28)^10-Assumptions!$B$6)/Assumptions!$B$7,"n/a") | F28: =IF($A28>F$26,(SUMPRODUCT(DCF_Base!$C$19:$L$19/(1+$A28)^DCF_Base!$C$4:$L$4)+MAX(0,MIN(DCF_Base!$L$19*(1+F$26)/($A28-F$26),Assumptions!$B$9*DCF_Base!$L$19))/(1+$A28)^10-Assumptions!$B$6)/Assumptions!$B$7,"n/a")
A29: 0.0675 | B29: =IF($A29>B$26,(SUMPRODUCT(DCF_Base!$C$19:$L$19/(1+$A29)^DCF_Base!$C$4:$L$4)+MAX(0,MIN(DCF_Base!$L$19*(1+B$26)/($A29-B$26),Assumptions!$B$9*DCF_Base!$L$19))/(1+$A29)^10-Assumptions!$B$6)/Assumptions!$B$7,"n/a") | C29: =IF($A29>C$26,(SUMPRODUCT(DCF_Base!$C$19:$L$19/(1+$A29)^DCF_Base!$C$4:$L$4)+MAX(0,MIN(DCF_Base!$L$19*(1+C$26)/($A29-C$26),Assumptions!$B$9*DCF_Base!$L$19))/(1+$A29)^10-Assumptions!$B$6)/Assumptions!$B$7,"n/a") | D29: =IF($A29>D$26,(SUMPRODUCT(DCF_Base!$C$19:$L$19/(1+$A29)^DCF_Base!$C$4:$L$4)+MAX(0,MIN(DCF_Base!$L$19*(1+D$26)/($A29-D$26),Assumptions!$B$9*DCF_Base!$L$19))/(1+$A29)^10-Assumptions!$B$6)/Assumptions!$B$7,"n/a") | E29: =IF($A29>E$26,(SUMPRODUCT(DCF_Base!$C$19:$L$19/(1+$A29)^DCF_Base!$C$4:$L$4)+MAX(0,MIN(DCF_Base!$L$19*(1+E$26)/($A29-E$26),Assumptions!$B$9*DCF_Base!$L$19))/(1+$A29)^10-Assumptions!$B$6)/Assumptions!$B$7,"n/a") | F29: =IF($A29>F$26,(SUMPRODUCT(DCF_Base!$C$19:$L$19/(1+$A29)^DCF_Base!$C$4:$L$4)+MAX(0,MIN(DCF_Base!$L$19*(1+F$26)/($A29-F$26),Assumptions!$B$9*DCF_Base!$L$19))/(1+$A29)^10-Assumptions!$B$6)/Assumptions!$B$7,"n/a")
A30: 0.0725 | B30: =IF($A30>B$26,(SUMPRODUCT(DCF_Base!$C$19:$L$19/(1+$A30)^DCF_Base!$C$4:$L$4)+MAX(0,MIN(DCF_Base!$L$19*(1+B$26)/($A30-B$26),Assumptions!$B$9*DCF_Base!$L$19))/(1+$A30)^10-Assumptions!$B$6)/Assumptions!$B$7,"n/a") | C30: =IF($A30>C$26,(SUMPRODUCT(DCF_Base!$C$19:$L$19/(1+$A30)^DCF_Base!$C$4:$L$4)+MAX(0,MIN(DCF_Base!$L$19*(1+C$26)/($A30-C$26),Assumptions!$B$9*DCF_Base!$L$19))/(1+$A30)^10-Assumptions!$B$6)/Assumptions!$B$7,"n/a") | D30: =IF($A30>D$26,(SUMPRODUCT(DCF_Base!$C$19:$L$19/(1+$A30)^DCF_Base!$C$4:$L$4)+MAX(0,MIN(DCF_Base!$L$19*(1+D$26)/($A30-D$26),Assumptions!$B$9*DCF_Base!$L$19))/(1+$A30)^10-Assumptions!$B$6)/Assumptions!$B$7,"n/a") | E30: =IF($A30>E$26,(SUMPRODUCT(DCF_Base!$C$19:$L$19/(1+$A30)^DCF_Base!$C$4:$L$4)+MAX(0,MIN(DCF_Base!$L$19*(1+E$26)/($A30-E$26),Assumptions!$B$9*DCF_Base!$L$19))/(1+$A30)^10-Assumptions!$B$6)/Assumptions!$B$7,"n/a") | F30: =IF($A30>F$26,(SUMPRODUCT(DCF_Base!$C$19:$L$19/(1+$A30)^DCF_Base!$C$4:$L$4)+MAX(0,MIN(DCF_Base!$L$19*(1+F$26)/($A30-F$26),Assumptions!$B$9*DCF_Base!$L$19))/(1+$A30)^10-Assumptions!$B$6)/Assumptions!$B$7,"n/a")
A31: 0.0775 | B31: =IF($A31>B$26,(SUMPRODUCT(DCF_Base!$C$19:$L$19/(1+$A31)^DCF_Base!$C$4:$L$4)+MAX(0,MIN(DCF_Base!$L$19*(1+B$26)/($A31-B$26),Assumptions!$B$9*DCF_Base!$L$19))/(1+$A31)^10-Assumptions!$B$6)/Assumptions!$B$7,"n/a") | C31: =IF($A31>C$26,(SUMPRODUCT(DCF_Base!$C$19:$L$19/(1+$A31)^DCF_Base!$C$4:$L$4)+MAX(0,MIN(DCF_Base!$L$19*(1+C$26)/($A31-C$26),Assumptions!$B$9*DCF_Base!$L$19))/(1+$A31)^10-Assumptions!$B$6)/Assumptions!$B$7,"n/a") | D31: =IF($A31>D$26,(SUMPRODUCT(DCF_Base!$C$19:$L$19/(1+$A31)^DCF_Base!$C$4:$L$4)+MAX(0,MIN(DCF_Base!$L$19*(1+D$26)/($A31-D$26),Assumptions!$B$9*DCF_Base!$L$19))/(1+$A31)^10-Assumptions!$B$6)/Assumptions!$B$7,"n/a") | E31: =IF($A31>E$26,(SUMPRODUCT(DCF_Base!$C$19:$L$19/(1+$A31)^DCF_Base!$C$4:$L$4)+MAX(0,MIN(DCF_Base!$L$19*(1+E$26)/($A31-E$26),Assumptions!$B$9*DCF_Base!$L$19))/(1+$A31)^10-Assumptions!$B$6)/Assumptions!$B$7,"n/a") | F31: =IF($A31>F$26,(SUMPRODUCT(DCF_Base!$C$19:$L$19/(1+$A31)^DCF_Base!$C$4:$L$4)+MAX(0,MIN(DCF_Base!$L$19*(1+F$26)/($A31-F$26),Assumptions!$B$9*DCF_Base!$L$19))/(1+$A31)^10-Assumptions!$B$6)/Assumptions!$B$7,"n/a")
A34: Market cross-checks
A35: Market cap | B35: =Assumptions!B8*Assumptions!B7
A36: EV at price (incl. Bluecurrent etc.) | B36: =B35+Assumptions!B11
A37: Network EV at price (ex non-operating assets) | B37: =B36-Assumptions!B12
A38: Network EV / RAB estimate at price | B38: =B37/Assumptions!B17
A39: Base network EV / RAB estimate | B39: =DCF_Base!B34/Assumptions!B17
A40: EV / FY26 adj EBITDA at price | B40: =B36/DCF_Base!B8
A41: Base EV / FY27 adj EBITDA | B41: =DCF_Base!B34/DCF_Base!C8
