Workbook

Sheet Model_Info
A1: BPT.AX - Beach Energy Limited - owner-FCF DCF (depleting-reserve adaptation)
A2: Version 1.0, 2026-09-21. Fresh build; supersedes nothing (first valuation of this ticker).
A3: Built by the dcf-analyst agent (Claude Fable 5.1) on 2026-09-21 at the orchestrator's request as part of /research-stock BPT.AX.
A4: FIGURES GO STALE. Price, net debt, share count and FY27 guidance are dated below; refresh them before relying on any output.
A6: DATA VINTAGE
A7: Price: A$0.87 as of 2026-09-21T06:10:32Z regular close (ASX 16:10 AEST closing auction) (Yahoo Finance chart endpoint).
A8: Balance sheet: 30 June 2026 (Annual Report FY2026). Debt 596.7 carrying (600.0 drawn face), leases 35.6, cash 213.0 -> net debt 419.3. Company-basis net debt 387.
A9: Diluted shares: 2284.3m = FY26 weighted-average diluted (Note 6); basic on issue 2,281.3m.
A10: Guidance: FY27 production 19.5-23.0 MMboe; capex $600-700m incl. abandonment, up to 65% growth, sustaining <$450m (FY26 results, 6 Aug 2026).
A11: Reserves: 2P 156 MMboe, 2C 174 MMboe, reserve life 8.0 years at 30 June 2026.
A13: METHODOLOGY
A14: Model: owner-FCF DCF per .claude/skills/dcf-methods/references/owner-fcf.md, 10-year explicit horizon, end-of-year discounting.
... A35: Blue font = hardcoded input. Yellow fill = key lever (driver row). Black = formula. Green font = cross-sheet link.

Sheet Actuals
A1: Reported history (A$m unless stated). Source: BPT.AX_Metrics.csv / kpis table, adjudicated from Annual Reports FY2021-FY2026.
A2: Period | B2: Total revenue | C2: Underlying EBITDA | D2: Underlying NPAT | E2: OCF | F2: Investing capex | G2: Reported FCF | H2: SBC | I2: Interest income | J2: Cash tax paid | K2: Production MMboe | L2: 2P MMboe | M2: 2C MMboe | N2: Reserve life yrs | O2: DPS cps
A3: FY2021 | B3: 1562 | C3: 953 | D3: 363 | E3: 759.8 | F3: 673.6 | G3: 86.2 | H3: 2.6 | I3: 0.2 | J3: 152.9 | K3: 25.6 | L3: 339 | M3: 191 | N3: 13.2 | O3: 2
A4: FY2022 | B4: 1771.4 | C4: 1111 | D4: 504.3 | E4: 1223.2 | F4: 912.8 | G4: 310.4 | H4: 2.1 | I4: 0.4 | J4: 109.9 | K4: 21.8 | L4: 283 | M4: 221 | N4: 12.9 | O4: 2
A5: FY2023 | B5: 1646.4 | C5: 982 | D5: 384.8 | E5: 928.6 | F5: 1170.6 | G5: -242 | H5: 2.4 | I5: 4.2 | J5: 123.7 | K5: 19.5 | L5: 255 | M5: 195 | N5: 13.1 | O5: 4
A6: FY2024 | B6: 1797.6 | C6: 950 | D6: 341 | E6: 774.1 | F6: 1093 | G6: -318.9 | H6: 1.2 | I6: 8.4 | J6: 119.6 | K6: 18.2 | L6: 205 | M6: 181 | N6: 11.3 | O6: 4
A7: FY2025 | B7: 2106 | C7: 1136 | D7: 451 | E7: 1132.5 | F7: 792.6 | G7: 339.9 | H7: 4.4 | I7: 9.8 | J7: 65.2 | K7: 19.7 | L7: 173 | M7: 179 | N7: 8.8 | O7: 9
A8: FY2026 | B8: 1921.2 | C8: 1040 | D8: 355 | E8: 889.7 | F8: 734.2 | G8: 155.5 | H8: 4.6 | I8: 8 | J8: 179.7 | K8: 19.4 | L8: 156 | M8: 174 | N8: 8 | O8: 3
A10: Balance sheet snapshot 30 June 2026 (Annual Report FY2026, Statement of Financial Position)
A11: Interest-bearing liabilities (carrying) | B11: 596.7
A12: Drawn facilities (face) | B12: 600
A13: Lease liabilities | B13: 35.6
A14: Cash | B14: 213
A15: Net debt (model: debt + leases - cash) | B15: 419.3
A16: Net debt (company basis) | B16: 387
A17: Restoration provision (total) | B17: 991.8
A18: of which <1yr / 1-5yr / >5yr | B18: 117.0 / 112.4 / 762.4
A19: Deferred tax asset | B19: 215.9
A20: Total equity | B20: 3274.2
A22: Share count (Note 6)
A23: Basic shares on issue (m) | B23: 2281.3
A24: Diluted weighted-average FY26 (m) - MODEL DIVISOR | B24: 2284.3
A25: Treasury-share purchases FY26 (buyback_cash) | B25: 2.5
A27: FY27 guidance (FY26 results, 6 Aug 2026)
A28: Production MMboe | B28: 19.5-23.0
A29: Capex A$m (incl. abandonment; up to 65% growth; sustaining <450) | B29: 600-700
A30: Net gearing target | B30: <15% (FY26 10.6%)

Sheet Assumptions
A1: Global assumptions (blue = input). Notes in column C.
A3: WACC | B3: 0.1 | C3: AUD-built: AU 10yr ~4.4% + 5.5% ERP x beta 1.2 -> CoE 11.0%; Kd 4.2% post-tax; 83/17 -> 9.85% ~ 10%. Same for all scenarios.
A4: D&A % of revenue | B4: 0.25 | C4: FY26 481.6 / 1,921.2 = 25.1%.
A5: WC capture on revenue change | B5: 0 | C5: E&P receivables/payables roughly offset; held at zero.
A6: Net debt (A$m) at 30-Jun-2026 | B6: 419.3 | C6: Debt 596.7 + leases 35.6 - cash 213.0. Restoration provision is in the flows via capex %, not here.
A7: Diluted shares (m) | B7: 2284.3 | C7: FY26 weighted-average diluted, Note 6. Held flat (SBC expensed).
A8: Current price (A$) | B8: 0.87 | C8: 2026-09-21T06:10:32Z regular close (ASX 16:10 AEST closing auction)
A9: Hurdle rate (entry price) | B9: 0.15 | C9: IRR the entry price must deliver; TV rebuilt at this rate.
A10: Horizon (years) | B10: 10 | C10: 10 years so the depletion path and restoration profile are explicit.
A11: FY0 revenue (A$m, FY2026 total revenue) | B11: 1921.2 | C11: Sales revenue 1,801.2 + other revenue 120.0. Margins are on this base.
A14: Scenario | B14: Terminal growth | C14: TV cap (x FCF10) | D14: Probability
A15: Bear | B15: -0.02 | C15: 5 | D15: 0.3
A16: Base | B16: 0 | C16: 7 | D16: 0.5
A17: Bull | B17: 0.01 | C17: 9 | D17: 0.2
A18: Weights sum (must be 100%) | D18: =SUM(D15:D17)
A19: Weights rationale | B19: Bear 30% (house default 15%) because the central risk - 2P halving in four years with an 8-year reserve life - is already happening, not hypothetical, and Waitsia's steady-state reliability is unproven after a 70% cost overrun. Bull 20% (default 35%) because the bull case needs several independent things to go right: exploration success, Waitsia reliability, firmer gas prices and a benign Gas Reservation Scheme outcome. Base 50%.
A21: Scenario narratives
A22: Bear | B22: The four-year halving of 2P (283 -> 156 MMboe) continues: exploration disappoints, the Otway GSA price review lands lower, Cooper Basin flooding and Waitsia reliability issues recur, and oil weakens. Production slips 2% in FY28 then 5-6%/yr; EBITDA margin compresses to 46% as fixed field and abandonment costs weigh; all-in capex stays at 30-33% of a shrinking revenue base as the $762m of post-year-5 restoration is brought forward. Terminal cap 5x FCF with -2% growth: the business is a run-off with a residual exploration option. Owner FCF stays positive throughout, so the zero floor is not hit, but per-share value falls below the current price.
A23: Base | B23: Waitsia delivers a full year at or near 250 TJ/d and FY27 production lands mid-guidance (~21 MMboe, +8% revenue on flat realised prices); Moomba optimisation and Western Flank drilling add a further +4% in FY28. From FY29 the 8-year 2P reserve life asserts itself: production and revenue decline 2-4%/yr as Otway, Taranaki and Western Flank deplete faster than exploration and 2C conversion replace them. Underlying EBITDA margin holds ~54-55% on the Waitsia mix then drifts to 52% as fixed costs spread over falling volumes. All-in capex (development + exploration + abandonment, Beach's own guidance basis) starts at $700m (top of FY27 guidance) and settles at 28-30% of revenue, ~$100-150m/yr above pure sustaining (<$450m) to fund reserve replacement and the $992m restoration provision. Terminal value is capped at 7x FY36 FCF, roughly the reserve-life-adjusted multiple a buyer would pay for a portfolio with 2P+2C of ~330 MMboe today, rather than a growing perpetuity.
A24: Bull | B24: Reserve replacement succeeds: the eight-well Western Flank campaign, Otway nearshore FID (Enterprise East/Selie) and Taroom Trough add 2P at a pace that holds production ~22-24 MMboe through FY31; the WA 70 PJ/yr supply gap and East Coast tightness lift realised gas prices; Waitsia's high-margin LNG cargoes push underlying EBITDA margin to 57-58%. All-in capex converges to 27% of revenue as abandonment spend falls post-Equinox. Terminal cap 9x FCF, 1% growth, reflecting a business that has demonstrated it can replace what it produces. A Domestic Gas Reservation Scheme that makes Beach's domestic-committed East Coast volumes a takeover target is upside to this case, not modelled.

Sheet DCF_Bear
A1: Bear case - owner-FCF DCF, A$m. Drivers (yellow) in rows 5, 7, 9, 14, 17.
A3: Year | B3: FY2026A | C3: FY2027E | D3: FY2028E | E3: FY2029E | F3: FY2030E | G3: FY2031E | H3: FY2032E | I3: FY2033E | J3: FY2034E | K3: FY2035E | L3: FY2036E
A4: Index | B4: 0 | C4: 1 | D4: 2 | E4: 3 | F4: 4 | G4: 5 | H4: 6 | I4: 7 | J4: 8 | K4: 9 | L4: 10
A5: Revenue growth YoY | C5: 0.03 | D5: -0.02 | E5: -0.05 | F5: -0.05 | G5: -0.06 | H5: -0.06 | I5: -0.06 | J5: -0.06 | K5: -0.06 | L5: -0.06
A6: Revenue | B6: =Assumptions!$B$11 | C6: =B6*(1+C5) | D6: =C6*(1+D5) | E6: =D6*(1+E5) | F6: =E6*(1+F5) | G6: =F6*(1+G5) | H6: =G6*(1+H5) | I6: =H6*(1+I5) | J6: =I6*(1+J5) | ... L6: =K6*(1+L5)
A7: Underlying EBITDA margin | B7: 0.54132834 | C7: 0.5 | D7: 0.48 | E7: 0.47 | F7: 0.47 | G7: 0.46 | H7: 0.46 | I7: 0.46 | J7: 0.46 | K7: 0.46 | L7: 0.46
A8: Underlying EBITDA | B8: =B6*B7 | C8: =C6*C7 | D8: =D6*D7 | E8: =E6*E7 | F8: =F6*F7 | G8: =G6*G7 | H8: =H6*H7 | I8: =I6*I7 | ... L8: =L6*L7
A9: SBC % of revenue | B9: 0.0023943369 | C9: 0.0024 | D9: 0.0024 | E9: 0.0024 | F9: 0.0024 | G9: 0.0024 | H9: 0.0024 | I9: 0.0024 | J9: 0.0024 | K9: 0.0024 | L9: 0.0024
A10: SBC (expensed) | B10: =-B6*B9 | C10: =-C6*C9 | D10: =-D6*D9 | E10: =-E6*E9 | F10: =-F6*F9 | G10: =-G6*G9 | H10: =-H6*H9 | I10: =-I6*I9 | ... L10: =-L6*L9
A11: Owner EBITDA | C11: =C8+C10 | D11: =D8+D10 | E11: =E8+E10 | F11: =F8+F10 | G11: =G8+G10 | H11: =H8+H10 | I11: =I8+I10 | J11: =J8+J10 | ... L11: =L8+L10
A12: D&A | B12: -481.6 | C12: =-C6*Assumptions!$B$4 | D12: =-D6*Assumptions!$B$4 | E12: =-E6*Assumptions!$B$4 | F12: =-F6*Assumptions!$B$4 | G12: =-G6*Assumptions!$B$4 | H12: =-H6*Assumptions!$B$4 | I12: =-I6*Assumptions!$B$4 | J12: =-J6*Assumptions!$B$4 | ... L12: =-L6*Assumptions!$B$4
A13: EBIT (SBC expensed) | C13: =C11+C12 | D13: =D11+D12 | E13: =E11+E12 | F13: =F11+F12 | G13: =G11+G12 | H13: =H11+H12 | I13: =I11+I12 | J13: =J11+J12 | ... L13: =L11+L12
A14: Cash tax rate | C14: 0.25 | D14: 0.25 | E14: 0.25 | F14: 0.25 | G14: 0.25 | H14: 0.25 | I14: 0.25 | J14: 0.25 | K14: 0.25 | L14: 0.25
A15: NOPAT | C15: =C13-MAX(0,C13)*C14 | D15: =D13-MAX(0,D13)*D14 | E15: =E13-MAX(0,E13)*E14 | F15: =F13-MAX(0,F13)*F14 | G15: =G13-MAX(0,G13)*G14 | H15: =H13-MAX(0,H13)*H14 | I15: =I13-MAX(0,I13)*I14 | J15: =J13-MAX(0,J13)*J14 | ... L15: =L13-MAX(0,L13)*L14
A16: add back D&A | C16: =-C12 | D16: =-D12 | E16: =-E12 | F16: =-F12 | G16: =-G12 | H16: =-H12 | I16: =-I12 | J16: =-J12 | ... L16: =-L12
A17: All-in capex % of revenue (dev + expl + abandonment) | C17: 0.35 | D17: 0.32 | E17: 0.3 | F17: 0.3 | G17: 0.31 | H17: 0.31 | I17: 0.32 | J17: 0.32 | K17: 0.33 | L17: 0.33
A18: less all-in capex | C18: =-C6*C17 | D18: =-D6*D17 | E18: =-E6*E17 | F18: =-F6*F17 | G18: =-G6*G17 | H18: =-H6*H17 | I18: =-I6*I17 | J18: =-J6*J17 | ... L18: =-L6*L17
A19: add working capital | C19: =Assumptions!$B$5*(C6-B6) | D19: =Assumptions!$B$5*(D6-C6) | E19: =Assumptions!$B$5*(E6-D6) | F19: =Assumptions!$B$5*(F6-E6) | G19: =Assumptions!$B$5*(G6-F6) | H19: =Assumptions!$B$5*(H6-G6) | I19: =Assumptions!$B$5*(I6-H6) | J19: =Assumptions!$B$5*(J6-I6) | ... L19: =Assumptions!$B$5*(L6-K6)
A20: UNLEVERED OWNER FCF | C20: =C15+C16+C18+C19 | D20: =D15+D16+D18+D19 | E20: =E15+E16+E18+E19 | F20: =F15+F16+F18+F19 | G20: =G15+G16+G18+G19 | H20: =H15+H16+H18+H19 | I20: =I15+I16+I18+I19 | J20: =J15+J16+J18+J19 | ... L20: =L15+L16+L18+L19
A21: Discount factor | B21: 1 | C21: =1/(1+Assumptions!$B$3)^C4 | D21: =1/(1+Assumptions!$B$3)^D4 | E21: =1/(1+Assumptions!$B$3)^E4 | F21: =1/(1+Assumptions!$B$3)^F4 | G21: =1/(1+Assumptions!$B$3)^G4 | H21: =1/(1+Assumptions!$B$3)^H4 | I21: =1/(1+Assumptions!$B$3)^I4 | J21: =1/(1+Assumptions!$B$3)^J4 | ... L21: =1/(1+Assumptions!$B$3)^L4
A22: PV of FCF | C22: =C20*C21 | D22: =D20*D21 | E22: =E20*E21 | F22: =F20*F21 | G22: =G20*G21 | H22: =H20*H21 | I22: =I20*I21 | J22: =J20*J21 | ... L22: =L20*L21
A24: Memo: FCF before SBC (company-style) | C24: =C20-C10 | D24: =D20-D10 | E24: =E20-E10 | F24: =F20-F10 | G24: =G20-G10 | H24: =H20-H10 | I24: =I20-I10 | J24: =J20-J10 | ... L24: =L20-L10
A25: Memo: owner-FCF margin | C25: =C20/C6 | D25: =D20/D6 | E25: =E20/E6 | F25: =F20/F6 | G25: =G20/G6 | H25: =H20/H6 | I25: =I20/I6 | J25: =J20/J6 | ... L25: =L20/L6
A27: Sum of PV of FCF | B27: =SUM(C22:L22)
A28: Terminal growth | B28: =Assumptions!$B$15
A29: Terminal-year FCF x (1+g) | B29: =L20*(1+B28)
A30: Gordon TV | B30: =IF(Assumptions!$B$3>B28,B29/(Assumptions!$B$3-B28),0)
A31: TV cap multiple (x FCF10) | B31: =Assumptions!$C$15
A32: Cap TV | B32: =B31*L20
A33: TV used = MAX(0, MIN(Gordon, cap)) | B33: =MAX(0,MIN(B30,B32))
A34: Implied exit multiple (TV / FCF10) | B34: =IF(L20<>0,B33/L20,0)
A35: PV of TV | B35: =B33*L21
A36: Enterprise value | B36: =B27+B35
A37: less net debt | B37: =-Assumptions!$B$6
A38: Equity value | B38: =B36+B37
A39: Diluted shares (m) | B39: =Assumptions!$B$7
A40: VALUE PER SHARE (A$) | B40: =B38/B39
A41: Upside vs price | B41: =B40/Assumptions!$B$8-1
A43: Street memo: PV of explicit SBC | B43: =SUMPRODUCT(-C10:L10/(1+Assumptions!$B$3)^C4:L4)
A44: Street memo: PV of terminal SBC (same cap rule) | B44: =MAX(0,MIN(IF(Assumptions!$B$3>B28,-L10*(1+B28)/(Assumptions!$B$3-B28),0),B31*-L10))*L21
...

Sheet DCF_Base
A1: Base case - owner-FCF DCF, A$m. Drivers (yellow) in rows 5, 7, 9, 14, 17.
A3: Year | B3: FY2026A | C3: FY2027E | D3: FY2028E | E3: FY2029E | F3: FY2030E | G3: FY2031E | H3: FY2032E | I3: FY2033E | J3: FY2034E | K3: FY2035E | L3: FY2036E
A4: Index | B4: 0 | C4: 1 | D4: 2 | E4: 3 | F4: 4 | G4: 5 | H4: 6 | I4: 7 | J4: 8 | K4: 9 | L4: 10
A5: Revenue growth YoY | C5: 0.08 | D5: 0.04 | E5: -0.02 | F5: -0.03 | G5: -0.03 | H5: -0.03 | I5: -0.04 | J5: -0.04 | K5: -0.04 | L5: -0.04
A6: Revenue | B6: =Assumptions!$B$11 | C6: =B6*(1+C5) | D6: =C6*(1+D5) | E6: =D6*(1+E5) | F6: =E6*(1+F5) | G6: =F6*(1+G5) | H6: =G6*(1+H5) | I6: =H6*(1+I5) | J6: =I6*(1+J5) | ... L6: =K6*(1+L5)
A7: Underlying EBITDA margin | B7: 0.54132834 | C7: 0.54 | D7: 0.55 | E7: 0.55 | F7: 0.55 | G7: 0.54 | H7: 0.54 | I7: 0.53 | J7: 0.53 | K7: 0.52 | L7: 0.52
A8: Underlying EBITDA | B8: =B6*B7 | C8: =C6*C7 | D8: =D6*D7 | E8: =E6*E7 | F8: =F6*F7 | G8: =G6*G7 | H8: =H6*H7 | I8: =I6*I7 | ... L8: =L6*L7
A9: SBC % of revenue | B9: 0.0023943369 | C9: 0.0024 | D9: 0.0024 | E9: 0.0024 | F9: 0.0024 | G9: 0.0024 | H9: 0.0024 | I9: 0.0024 | J9: 0.0024 | K9: 0.0024 | L9: 0.0024
A10: SBC (expensed) | B10: =-B6*B9 | C10: =-C6*C9 | D10: =-D6*D9 | E10: =-E6*E9 | F10: =-F6*F9 | G10: =-G6*G9 | H10: =-H6*H9 | I10: =-I6*I9 | ... L10: =-L6*L9
A11: Owner EBITDA | C11: =C8+C10 | D11: =D8+D10 | E11: =E8+E10 | F11: =F8+F10 | G11: =G8+G10 | H11: =H8+H10 | I11: =I8+I10 | J11: =J8+J10 | ... L11: =L8+L10
A12: D&A | B12: -481.6 | C12: =-C6*Assumptions!$B$4 | D12: =-D6*Assumptions!$B$4 | E12: =-E6*Assumptions!$B$4 | F12: =-F6*Assumptions!$B$4 | G12: =-G6*Assumptions!$B$4 | H12: =-H6*Assumptions!$B$4 | I12: =-I6*Assumptions!$B$4 | J12: =-J6*Assumptions!$B$4 | ... L12: =-L6*Assumptions!$B$4
A13: EBIT (SBC expensed) | C13: =C11+C12 | D13: =D11+D12 | E13: =E11+E12 | F13: =F11+F12 | G13: =G11+G12 | H13: =H11+H12 | I13: =I11+I12 | J13: =J11+J12 | ... L13: =L11+L12
A14: Cash tax rate | C14: 0.25 | D14: 0.25 | E14: 0.25 | F14: 0.25 | G14: 0.25 | H14: 0.25 | I14: 0.25 | J14: 0.25 | K14: 0.25 | L14: 0.25
A15: NOPAT | C15: =C13-MAX(0,C13)*C14 | D15: =D13-MAX(0,D13)*D14 | E15: =E13-MAX(0,E13)*E14 | F15: =F13-MAX(0,F13)*F14 | G15: =G13-MAX(0,G13)*G14 | H15: =H13-MAX(0,H13)*H14 | I15: =I13-MAX(0,I13)*I14 | J15: =J13-MAX(0,J13)*J14 | ... L15: =L13-MAX(0,L13)*L14
A16: add back D&A | C16: =-C12 | D16: =-D12 | E16: =-E12 | F16: =-F12 | G16: =-G12 | H16: =-H12 | I16: =-I12 | J16: =-J12 | ... L16: =-L12
A17: All-in capex % of revenue (dev + expl + abandonment) | C17: 0.33 | D17: 0.3 | E17: 0.28 | F17: 0.28 | G17: 0.28 | H17: 0.28 | I17: 0.29 | J17: 0.29 | K17: 0.3 | L17: 0.3
A18: less all-in capex | C18: =-C6*C17 | D18: =-D6*D17 | E18: =-E6*E17 | F18: =-F6*F17 | G18: =-G6*G17 | H18: =-H6*H17 | I18: =-I6*I17 | J18: =-J6*J17 | ... L18: =-L6*L17
A19: add working capital | C19: =Assumptions!$B$5*(C6-B6) | D19: =Assumptions!$B$5*(D6-C6) | E19: =Assumptions!$B$5*(E6-D6) | F19: =Assumptions!$B$5*(F6-E6) | G19: =Assumptions!$B$5*(G6-F6) | H19: =Assumptions!$B$5*(H6-G6) | I19: =Assumptions!$B$5*(I6-H6) | J19: =Assumptions!$B$5*(J6-I6) | ... L19: =Assumptions!$B$5*(L6-K6)
A20: UNLEVERED OWNER FCF | C20: =C15+C16+C18+C19 | D20: =D15+D16+D18+D19 | E20: =E15+E16+E18+E19 | F20: =F15+F16+F18+F19 | G20: =G15+G16+G18+G19 | H20: =H15+H16+H18+H19 | I20: =I15+I16+I18+I19 | J20: =J15+J16+J18+J19 | ... L20: =L15+L16+L18+L19
A21: Discount factor | B21: 1 | C21: =1/(1+Assumptions!$B$3)^C4 | D21: =1/(1+Assumptions!$B$3)^D4 | E21: =1/(1+Assumptions!$B$3)^E4 | F21: =1/(1+Assumptions!$B$3)^F4 | G21: =1/(1+Assumptions!$B$3)^G4 | H21: =1/(1+Assumptions!$B$3)^H4 | I21: =1/(1+Assumptions!$B$3)^I4 | J21: =1/(1+Assumptions!$B$3)^J4 | ... L21: =1/(1+Assumptions!$B$3)^L4
A22: PV of FCF | C22: =C20*C21 | D22: =D20*D21 | E22: =E20*E21 | F22: =F20*F21 | G22: =G20*G21 | H22: =H20*H21 | I22: =I20*I21 | J22: =J20*J21 | ... L22: =L20*L21
A24: Memo: FCF before SBC (company-style) | C24: =C20-C10 | D24: =D20-D10 | E24: =E20-E10 | F24: =F20-F10 | G24: =G20-G10 | H24: =H20-H10 | I24: =I20-I10 | J24: =J20-J10 | ... L24: =L20-L10
A25: Memo: owner-FCF margin | C25: =C20/C6 | D25: =D20/D6 | E25: =E20/E6 | F25: =F20/F6 | G25: =G20/G6 | H25: =H20/H6 | I25: =I20/I6 | J25: =J20/J6 | ... L25: =L20/L6
A27: Sum of PV of FCF | B27: =SUM(C22:L22)
A28: Terminal growth | B28: =Assumptions!$B$16
A29: Terminal-year FCF x (1+g) | B29: =L20*(1+B28)
A30: Gordon TV | B30: =IF(Assumptions!$B$3>B28,B29/(Assumptions!$B$3-B28),0)
A31: TV cap multiple (x FCF10) | B31: =Assumptions!$C$16
A32: Cap TV | B32: =B31*L20
A33: TV used = MAX(0, MIN(Gordon, cap)) | B33: =MAX(0,MIN(B30,B32))
A34: Implied exit multiple (TV / FCF10) | B34: =IF(L20<>0,B33/L20,0)
A35: PV of TV | B35: =B33*L21
A36: Enterprise value | B36: =B27+B35
A37: less net debt | B37: =-Assumptions!$B$6
A38: Equity value | B38: =B36+B37
A39: Diluted shares (m) | B39: =Assumptions!$B$7
A40: VALUE PER SHARE (A$) | B40: =B38/B39
A41: Upside vs price | B41: =B40/Assumptions!$B$8-1
A43: Street memo: PV of explicit SBC | B43: =SUMPRODUCT(-C10:L10/(1+Assumptions!$B$3)^C4:L4)
A44: Street memo: PV of terminal SBC (same cap rule) | B44: =MAX(0,MIN(IF(Assumptions!$B$3>B28,-L10*(1+B28)/(Assumptions!$B$3-B28),0),B31*-L10))*L21
...

Sheet DCF_Bull
A1: Bull case - owner-FCF DCF, A$m. Drivers (yellow) in rows 5, 7, 9, 14, 17.
A3: Year | B3: FY2026A | C3: FY2027E | D3: FY2028E | E3: FY2029E | F3: FY2030E | G3: FY2031E | H3: FY2032E | I3: FY2033E | J3: FY2034E | K3: FY2035E | L3: FY2036E
A4: Index | B4: 0 | C4: 1 | D4: 2 | E4: 3 | F4: 4 | G4: 5 | H4: 6 | I4: 7 | J4: 8 | K4: 9 | L4: 10
A5: Revenue growth YoY | C5: 0.12 | D5: 0.08 | E5: 0.03 | F5: 0.02 | G5: 0.01 | H5: 0 | I5: 0 | J5: -0.01 | K5: -0.01 | L5: -0.01
A6: Revenue | B6: =Assumptions!$B$11 | C6: =B6*(1+C5) | D6: =C6*(1+D5) | E6: =D6*(1+E5) | F6: =E6*(1+F5) | G6: =F6*(1+G5) | H6: =G6*(1+H5) | I6: =H6*(1+I5) | J6: =I6*(1+J5) | ... L6: =K6*(1+L5)
A7: Underlying EBITDA margin | B7: 0.54132834 | C7: 0.55 | D7: 0.57 | E7: 0.58 | F7: 0.58 | G7: 0.58 | H7: 0.58 | I7: 0.57 | J7: 0.57 | K7: 0.57 | L7: 0.57
A8: Underlying EBITDA | B8: =B6*B7 | C8: =C6*C7 | D8: =D6*D7 | E8: =E6*E7 | F8: =F6*F7 | G8: =G6*G7 | H8: =H6*H7 | I8: =I6*I7 | ... L8: =L6*L7
A9: SBC % of revenue | B9: 0.0023943369 | C9: 0.0024 | D9: 0.0024 | E9: 0.0024 | F9: 0.0024 | G9: 0.0024 | H9: 0.0024 | I9: 0.0024 | J9: 0.0024 | K9: 0.0024 | L9: 0.0024
A10: SBC (expensed) | B10: =-B6*B9 | C10: =-C6*C9 | D10: =-D6*D9 | E10: =-E6*E9 | F10: =-F6*F9 | G10: =-G6*G9 | H10: =-H6*H9 | I10: =-I6*I9 | ... L10: =-L6*L9
A11: Owner EBITDA | C11: =C8+C10 | D11: =D8+D10 | E11: =E8+E10 | F11: =F8+F10 | G11: =G8+G10 | H11: =H8+H10 | I11: =I8+I10 | J11: =J8+J10 | ... L11: =L8+L10
A12: D&A | B12: -481.6 | C12: =-C6*Assumptions!$B$4 | D12: =-D6*Assumptions!$B$4 | E12: =-E6*Assumptions!$B$4 | F12: =-F6*Assumptions!$B$4 | G12: =-G6*Assumptions!$B$4 | H12: =-H6*Assumptions!$B$4 | I12: =-I6*Assumptions!$B$4 | J12: =-J6*Assumptions!$B$4 | ... L12: =-L6*Assumptions!$B$4
A13: EBIT (SBC expensed) | C13: =C11+C12 | D13: =D11+D12 | E13: =E11+E12 | F13: =F11+F12 | G13: =G11+G12 | H13: =H11+H12 | I13: =I11+I12 | J13: =J11+J12 | ... L13: =L11+L12
A14: Cash tax rate | C14: 0.25 | D14: 0.25 | E14: 0.25 | F14: 0.25 | G14: 0.25 | H14: 0.25 | I14: 0.25 | J14: 0.25 | K14: 0.25 | L14: 0.25
A15: NOPAT | C15: =C13-MAX(0,C13)*C14 | D15: =D13-MAX(0,D13)*D14 | E15: =E13-MAX(0,E13)*E14 | F15: =F13-MAX(0,F13)*F14 | G15: =G13-MAX(0,G13)*G14 | H15: =H13-MAX(0,H13)*H14 | I15: =I13-MAX(0,I13)*I14 | J15: =J13-MAX(0,J13)*J14 | ... L15: =L13-MAX(0,L13)*L14
A16: add back D&A | C16: =-C12 | D16: =-D12 | E16: =-E12 | F16: =-F12 | G16: =-G12 | H16: =-H12 | I16: =-I12 | J16: =-J12 | ... L16: =-L12
A17: All-in capex % of revenue (dev + expl + abandonment) | C17: 0.32 | D17: 0.29 | E17: 0.27 | F17: 0.27 | G17: 0.27 | H17: 0.27 | I17: 0.27 | J17: 0.27 | K17: 0.27 | L17: 0.27
A18: less all-in capex | C18: =-C6*C17 | D18: =-D6*D17 | E18: =-E6*E17 | F18: =-F6*F17 | G18: =-G6*G17 | H18: =-H6*H17 | I18: =-I6*I17 | J18: =-J6*J17 | ... L18: =-L6*L17
A19: add working capital | C19: =Assumptions!$B$5*(C6-B6) | D19: =Assumptions!$B$5*(D6-C6) | E19: =Assumptions!$B$5*(E6-D6) | F19: =Assumptions!$B$5*(F6-E6) | G19: =Assumptions!$B$5*(G6-F6) | H19: =Assumptions!$B$5*(H6-G6) | I19: =Assumptions!$B$5*(I6-H6) | J19: =Assumptions!$B$5*(J6-I6) | ... L19: =Assumptions!$B$5*(L6-K6)
A20: UNLEVERED OWNER FCF | C20: =C15+C16+C18+C19 | D20: =D15+D16+D18+D19 | E20: =E15+E16+E18+E19 | F20: =F15+F16+F18+F19 | G20: =G15+G16+G18+G19 | H20: =H15+H16+H18+H19 | I20: =I15+I16+I18+I19 | J20: =J15+J16+J18+J19 | ... L20: =L15+L16+L18+L19
A21: Discount factor | B21: 1 | C21: =1/(1+Assumptions!$B$3)^C4 | D21: =1/(1+Assumptions!$B$3)^D4 | E21: =1/(1+Assumptions!$B$3)^E4 | F21: =1/(1+Assumptions!$B$3)^F4 | G21: =1/(1+Assumptions!$B$3)^G4 | H21: =1/(1+Assumptions!$B$3)^H4 | I21: =1/(1+Assumptions!$B$3)^I4 | J21: =1/(1+Assumptions!$B$3)^J4 | ... L21: =1/(1+Assumptions!$B$3)^L4
A22: PV of FCF | C22: =C20*C21 | D22: =D20*D21 | E22: =E20*E21 | F22: =F20*F21 | G22: =G20*G21 | H22: =H20*H21 | I22: =I20*I21 | J22: =J20*J21 | ... L22: =L20*L21
A24: Memo: FCF before SBC (company-style) | C24: =C20-C10 | D24: =D20-D10 | E24: =E20-E10 | F24: =F20-F10 | G24: =G20-G10 | H24: =H20-H10 | I24: =I20-I10 | J24: =J20-J10 | ... L24: =L20-L10
A25: Memo: owner-FCF margin | C25: =C20/C6 | D25: =D20/D6 | E25: =E20/E6 | F25: =F20/F6 | G25: =G20/G6 | H25: =H20/H6 | I25: =I20/I6 | J25: =J20/J6 | ... L25: =L20/L6
A27: Sum of PV of FCF | B27: =SUM(C22:L22)
A28: Terminal growth | B28: =Assumptions!$B$17
A29: Terminal-year FCF x (1+g) | B29: =L20*(1+B28)
A30: Gordon TV | B30: =IF(Assumptions!$B$3>B28,B29/(Assumptions!$B$3-B28),0)
A31: TV cap multiple (x FCF10) | B31: =Assumptions!$C$17
A32: Cap TV | B32: =B31*L20
A33: TV used = MAX(0, MIN(Gordon, cap)) | B33: =MAX(0,MIN(B30,B32))
A34: Implied exit multiple (TV / FCF10) | B34: =IF(L20<>0,B33/L20,0)
A35: PV of TV | B35: =B33*L21
A36: Enterprise value | B36: =B27+B35
A37: less net debt | B37: =-Assumptions!$B$6
A38: Equity value | B38: =B36+B37
A39: Diluted shares (m) | B39: =Assumptions!$B$7
A40: VALUE PER SHARE (A$) | B40: =B38/B39
A41: Upside vs price | B41: =B40/Assumptions!$B$8-1
A43: Street memo: PV of explicit SBC | B43: =SUMPRODUCT(-C10:L10/(1+Assumptions!$B$3)^C4:L4)
A44: Street memo: PV of terminal SBC (same cap rule) | B44: =MAX(0,MIN(IF(Assumptions!$B$3>B28,-L10*(1+B28)/(Assumptions!$B$3-B28),0),B31*-L10))*L21
...

Sheet FCF_Quality
A1: Reported FCF reconciled to owner FCF (A$m). Sources: cash flow statements FY2021-FY2026; SBC from statement of changes in equity.
A2: Period | B2: Revenue | C2: FCF (company: OCF - investing capex) | D2: less SBC | E2: less interest income | F2: Owner FCF | G2: Reported FCF margin | H2: Owner FCF margin | I2: Memo: cash tax paid | J2: Memo: restoration paid (in OCF)
A3: FY2021 | B3: 1562 | C3: 86.2 | D3: 2.6 | E3: 0.2 | F3: =C3-D3-E3 | G3: =C3/B3 | H3: =F3/B3 | I3: 152.9
A4: FY2022 | B4: 1771.4 | C4: 310.4 | D4: 2.1 | E4: 0.4 | F4: =C4-D4-E4 | G4: =C4/B4 | H4: =F4/B4 | I4: 109.9
A5: FY2023 | B5: 1646.4 | C5: -242 | D5: 2.4 | E5: 4.2 | F5: =C5-D5-E5 | G5: =C5/B5 | H5: =F5/B5 | I5: 123.7
A6: FY2024 | B6: 1797.6 | C6: -318.9 | D6: 1.2 | E6: 8.4 | F6: =C6-D6-E6 | G6: =C6/B6 | H6: =F6/B6 | I6: 119.6
A7: FY2025 | B7: 2106 | C7: 339.9 | D7: 4.4 | E7: 9.8 | F7: =C7-D7-E7 | G7: =C7/B7 | H7: =F7/B7 | I7: 65.2 | J7: 46.7
A8: FY2026 | B8: 1921.2 | C8: 155.5 | D8: 4.6 | E8: 8 | F8: =C8-D8-E8 | G8: =C8/B8 | H8: =F8/B8 | I8: 179.7 | J8: 124.7
A10: Notes: FY23/FY24 owner FCF negative during Waitsia construction. Reported FCF is levered (financing costs 39.6 inside OCF) and includes restoration payments; the forward build is unlevered, EBITDA-based, and charges restoration inside all-in capex. FY26 cash tax 179.7 includes ~66 of FY25 catch-up (current tax liability 72.4 -> 6.3): abnormal, ramped to 25% in the model.

Sheet Valuation
A1: Valuation summary (A$ per share). Green = links; every closed-form cell rebuilds the terminal value at its own rate.
A3: Scenario | B3: Value per share | C3: Upside vs price | D3: Probability | E3: Street value per share | F3: TV bound
A4: Bear | B4: =DCF_Bear!$B$40 | C4: =B4/Assumptions!$B$8-1 | D4: =Assumptions!$D$15 | E4: =DCF_Bear!$B$45 | F4: =IF(DCF_Bear!$B$33=0,"floor",IF(DCF_Bear!$B$30<=DCF_Bear!$B$32,"gordon","cap"))
A5: Base | B5: =DCF_Base!$B$40 | C5: =B5/Assumptions!$B$8-1 | D5: =Assumptions!$D$16 | E5: =DCF_Base!$B$45 | F5: =IF(DCF_Base!$B$33=0,"floor",IF(DCF_Base!$B$30<=DCF_Base!$B$32,"gordon","cap"))
A6: Bull | B6: =DCF_Bull!$B$40 | C6: =B6/Assumptions!$B$8-1 | D6: =Assumptions!$D$17 | E6: =DCF_Bull!$B$45 | F6: =IF(DCF_Bull!$B$33=0,"floor",IF(DCF_Bull!$B$30<=DCF_Bull!$B$32,"gordon","cap"))
A8: Probability-weighted value (house) | B8: =SUMPRODUCT(B4:B6,D4:D6)
A9: Street weighted value | B9: =SUMPRODUCT(E4:E6,D4:D6)
A10: Current price | B10: =Assumptions!$B$8
A11: Margin of safety (1 - price/weighted) | B11: =1-B10/B8
A12: Band position (price-house)/(street-house) | B12: =IF(ABS(B9-B8)<0.02,"n/a - band collapsed (SBC ~0.2% of revenue)",(B10-B8)/(B9-B8))
A14: 15%-hurdle entry prices (TV rebuilt at the hurdle)
A15: Scenario | B15: Entry price | C15: vs current price | D15: Probability
A16: Bear | B16: =IF(Assumptions!$B$9>Assumptions!$B$15,(SUMPRODUCT(DCF_Bear!$C$20:$L$20/(1+Assumptions!$B$9)^DCF_Bear!$C$4:$L$4)+MAX(0,MIN(DCF_Bear!$L$20*(1+Assumptions!$B$15)/(Assumptions!$B$9-Assumptions!$B$15),Assumptions!$C$15*DCF_Bear!$L$20))/(1+Assumptions!$B$9)^Assumptions!$B$10-Assumptions!$B$6)/Assumptions!$B$7,"n/a") | C16: =B16/Assumptions!$B$8-1 | D16: =Assumptions!$D$15
A17: Base | B17: =IF(Assumptions!$B$9>Assumptions!$B$16,(SUMPRODUCT(DCF_Base!$C$20:$L$20/(1+Assumptions!$B$9)^DCF_Base!$C$4:$L$4)+MAX(0,MIN(DCF_Base!$L$20*(1+Assumptions!$B$16)/(Assumptions!$B$9-Assumptions!$B$16),Assumptions!$C$16*DCF_Base!$L$20))/(1+Assumptions!$B$9)^Assumptions!$B$10-Assumptions!$B$6)/Assumptions!$B$7,"n/a") | C17: =B17/Assumptions!$B$8-1 | D17: =Assumptions!$D$16
A18: Bull | B18: =IF(Assumptions!$B$9>Assumptions!$B$17,(SUMPRODUCT(DCF_Bull!$C$20:$L$20/(1+Assumptions!$B$9)^DCF_Bull!$C$4:$L$4)+MAX(0,MIN(DCF_Bull!$L$20*(1+Assumptions!$B$17)/(Assumptions!$B$9-Assumptions!$B$17),Assumptions!$C$17*DCF_Bull!$L$20))/(1+Assumptions!$B$9)^Assumptions!$B$10-Assumptions!$B$6)/Assumptions!$B$7,"n/a") | C18: =B18/Assumptions!$B$8-1 | D18: =Assumptions!$D$17
A19: Weighted entry price (buy-below) | B19: =SUMPRODUCT(B16:B18,D16:D18) | C19: =B19/Assumptions!$B$8-1
A21: Required-return table (base case; each row rebuilds TV at that rate)
A22: Required return | B22: Value per share
A23: 0.09 | B23: =IF($A$23>Assumptions!$B$16,(SUMPRODUCT(DCF_Base!$C$20:$L$20/(1+$A$23)^DCF_Base!$C$4:$L$4)+MAX(0,MIN(DCF_Base!$L$20*(1+Assumptions!$B$16)/($A$23-Assumptions!$B$16),Assumptions!$C$16*DCF_Base!$L$20))/(1+$A$23)^Assumptions!$B$10-Assumptions!$B$6)/Assumptions!$B$7,"n/a")
A24: 0.1 | B24: =IF($A$24>Assumptions!$B$16,(SUMPRODUCT(DCF_Base!$C$20:$L$20/(1+$A$24)^DCF_Base!$C$4:$L$4)+MAX(0,MIN(DCF_Base!$L$20*(1+Assumptions!$B$16)/($A$24-Assumptions!$B$16),Assumptions!$C$16*DCF_Base!$L$20))/(1+$A$24)^Assumptions!$B$10-Assumptions!$B$6)/Assumptions!$B$7,"n/a")
A25: 0.11 | B25: =IF($A$25>Assumptions!$B$16,(SUMPRODUCT(DCF_Base!$C$20:$L$20/(1+$A$25)^DCF_Base!$C$4:$L$4)+MAX(0,MIN(DCF_Base!$L$20*(1+Assumptions!$B$16)/($A$25-Assumptions!$B$16),Assumptions!$C$16*DCF_Base!$L$20))/(1+$A$25)^Assumptions!$B$10-Assumptions!$B$6)/Assumptions!$B$7,"n/a")
A26: 0.12 | B26: =IF($A$26>Assumptions!$B$16,(SUMPRODUCT(DCF_Base!$C$20:$L$20/(1+$A$26)^DCF_Base!$C$4:$L$4)+MAX(0,MIN(DCF_Base!$L$20*(1+Assumptions!$B$16)/($A$26-Assumptions!$B$16),Assumptions!$C$16*DCF_Base!$L$20))/(1+$A$26)^Assumptions!$B$10-Assumptions!$B$6)/Assumptions!$B$7,"n/a")
A27: 0.15 | B27: =IF($A$27>Assumptions!$B$16,(SUMPRODUCT(DCF_Base!$C$20:$L$20/(1+$A$27)^DCF_Base!$C$4:$L$4)+MAX(0,MIN(DCF_Base!$L$20*(1+Assumptions!$B$16)/($A$27-Assumptions!$B$16),Assumptions!$C$16*DCF_Base!$L$20))/(1+$A$27)^Assumptions!$B$10-Assumptions!$B$6)/Assumptions!$B$7,"n/a")
A28: =Assumptions!$B$3 | B28: =IF($A$28>Assumptions!$B$16,(SUMPRODUCT(DCF_Base!$C$20:$L$20/(1+$A$28)^DCF_Base!$C$4:$L$4)+MAX(0,MIN(DCF_Base!$L$20*(1+Assumptions!$B$16)/($A$28-Assumptions!$B$16),Assumptions!$C$16*DCF_Base!$L$20))/(1+$A$28)^Assumptions!$B$10-Assumptions!$B$6)/Assumptions!$B$7,"n/a") | C28: model WACC - must equal DCF_Base!B40
A30: Sensitivity: base-case value per share, WACC (rows) x terminal growth (cols). Cap binds throughout -> flat across g by design.
A31: WACC \ g | B31: -0.01 | C31: -0.005 | D31: 0 | E31: 0.005 | F31: 0.01
A32: 0.08 | B32: =IF($A$32>B$31,(SUMPRODUCT(DCF_Base!$C$20:$L$20/(1+$A$32)^DCF_Base!$C$4:$L$4)+MAX(0,MIN(DCF_Base!$L$20*(1+B$31)/($A$32-B$31),Assumptions!$C$16*DCF_Base!$L$20))/(1+$A$32)^Assumptions!$B$10-Assumptions!$B$6)/Assumptions!$B$7,"n/a") | C32: =IF($A$32>C$31,(SUMPRODUCT(DCF_Base!$C$20:$L$20/(1+$A$32)^DCF_Base!$C$4:$L$4)+MAX(0,MIN(DCF_Base!$L$20*(1+C$31)/($A$32-C$31),Assumptions!$C$16*DCF_Base!$L$20))/(1+$A$32)^Assumptions!$B$10-Assumptions!$B$6)/Assumptions!$B$7,"n/a") | D32: =IF($A$32>D$31,(SUMPRODUCT(DCF_Base!$C$20:$L$20/(1+$A$32)^DCF_Base!$C$4:$L$4)+MAX(0,MIN(DCF_Base!$L$20*(1+D$31)/($A$32-D$31),Assumptions!$C$16*DCF_Base!$L$20))/(1+$A$32)^Assumptions!$B$10-Assumptions!$B$6)/Assumptions!$B$7,"n/a") | E32: =IF($A$32>E$31,(SUMPRODUCT(DCF_Base!$C$20:$L$20/(1+$A$32)^DCF_Base!$C$4:$L$4)+MAX(0,MIN(DCF_Base!$L$20*(1+E$31)/($A$32-E$31),Assumptions!$C$16*DCF_Base!$L$20))/(1+$A$32)^Assumptions!$B$10-Assumptions!$B$6)/Assumptions!$B$7,"n/a") | F32: =IF($A$32>F$31,(SUMPRODUCT(DCF_Base!$C$20:$L$20/(1+$A$32)^DCF_Base!$C$4:$L$4)+MAX(0,MIN(DCF_Base!$L$20*(1+F$31)/($A$32-F$31),Assumptions!$C$16*DCF_Base!$L$20))/(1+$A$32)^Assumptions!$B$10-Assumptions!$B$6)/Assumptions!$B$7,"n/a")
A33: 0.09 | B33: =IF($A$33>B$31,(SUMPRODUCT(DCF_Base!$C$20:$L$20/(1+$A$33)^DCF_Base!$C$4:$L$4)+MAX(0,MIN(DCF_Base!$L$20*(1+B$31)/($A$33-B$31),Assumptions!$C$16*DCF_Base!$L$20))/(1+$A$33)^Assumptions!$B$10-Assumptions!$B$6)/Assumptions!$B$7,"n/a") | C33: =IF($A$33>C$31,(SUMPRODUCT(DCF_Base!$C$20:$L$20/(1+$A$33)^DCF_Base!$C$4:$L$4)+MAX(0,MIN(DCF_Base!$L$20*(1+C$31)/($A$33-C$31),Assumptions!$C$16*DCF_Base!$L$20))/(1+$A$33)^Assumptions!$B$10-Assumptions!$B$6)/Assumptions!$B$7,"n/a") | D33: =IF($A$33>D$31,(SUMPRODUCT(DCF_Base!$C$20:$L$20/(1+$A$33)^DCF_Base!$C$4:$L$4)+MAX(0,MIN(DCF_Base!$L$20*(1+D$31)/($A$33-D$31),Assumptions!$C$16*DCF_Base!$L$20))/(1+$A$33)^Assumptions!$B$10-Assumptions!$B$6)/Assumptions!$B$7,"n/a") | E33: =IF($A$33>E$31,(SUMPRODUCT(DCF_Base!$C$20:$L$20/(1+$A$33)^DCF_Base!$C$4:$L$4)+MAX(0,MIN(DCF_Base!$L$20*(1+E$31)/($A$33-E$31),Assumptions!$C$16*DCF_Base!$L$20))/(1+$A$33)^Assumptions!$B$10-Assumptions!$B$6)/Assumptions!$B$7,"n/a") | F33: =IF($A$33>F$31,(SUMPRODUCT(DCF_Base!$C$20:$L$20/(1+$A$33)^DCF_Base!$C$4:$L$4)+MAX(0,MIN(DCF_Base!$L$20*(1+F$31)/($A$33-F$31),Assumptions!$C$16*DCF_Base!$L$20))/(1+$A$33)^Assumptions!$B$10-Assumptions!$B$6)/Assumptions!$B$7,"n/a")
A34: 0.1 | B34: =IF($A$34>B$31,(SUMPRODUCT(DCF_Base!$C$20:$L$20/(1+$A$34)^DCF_Base!$C$4:$L$4)+MAX(0,MIN(DCF_Base!$L$20*(1+B$31)/($A$34-B$31),Assumptions!$C$16*DCF_Base!$L$20))/(1+$A$34)^Assumptions!$B$10-Assumptions!$B$6)/Assumptions!$B$7,"n/a") | C34: =IF($A$34>C$31,(SUMPRODUCT(DCF_Base!$C$20:$L$20/(1+$A$34)^DCF_Base!$C$4:$L$4)+MAX(0,MIN(DCF_Base!$L$20*(1+C$31)/($A$34-C$31),Assumptions!$C$16*DCF_Base!$L$20))/(1+$A$34)^Assumptions!$B$10-Assumptions!$B$6)/Assumptions!$B$7,"n/a") | D34: =IF($A$34>D$31,(SUMPRODUCT(DCF_Base!$C$20:$L$20/(1+$A$34)^DCF_Base!$C$4:$L$4)+MAX(0,MIN(DCF_Base!$L$20*(1+D$31)/($A$34-D$31),Assumptions!$C$16*DCF_Base!$L$20))/(1+$A$34)^Assumptions!$B$10-Assumptions!$B$6)/Assumptions!$B$7,"n/a") | E34: =IF($A$34>E$31,(SUMPRODUCT(DCF_Base!$C$20:$L$20/(1+$A$34)^DCF_Base!$C$4:$L$4)+MAX(0,MIN(DCF_Base!$L$20*(1+E$31)/($A$34-E$31),Assumptions!$C$16*DCF_Base!$L$20))/(1+$A$34)^Assumptions!$B$10-Assumptions!$B$6)/Assumptions!$B$7,"n/a") | F34: =IF($A$34>F$31,(SUMPRODUCT(DCF_Base!$C$20:$L$20/(1+$A$34)^DCF_Base!$C$4:$L$4)+MAX(0,MIN(DCF_Base!$L$20*(1+F$31)/($A$34-F$31),Assumptions!$C$16*DCF_Base!$L$20))/(1+$A$34)^Assumptions!$B$10-Assumptions!$B$6)/Assumptions!$B$7,"n/a")
A35: 0.11 | B35: =IF($A$35>B$31,(SUMPRODUCT(DCF_Base!$C$20:$L$20/(1+$A$35)^DCF_Base!$C$4:$L$4)+MAX(0,MIN(DCF_Base!$L$20*(1+B$31)/($A$35-B$31),Assumptions!$C$16*DCF_Base!$L$20))/(1+$A$35)^Assumptions!$B$10-Assumptions!$B$6)/Assumptions!$B$7,"n/a") | C35: =IF($A$35>C$31,(SUMPRODUCT(DCF_Base!$C$20:$L$20/(1+$A$35)^DCF_Base!$C$4:$L$4)+MAX(0,MIN(DCF_Base!$L$20*(1+C$31)/($A$35-C$31),Assumptions!$C$16*DCF_Base!$L$20))/(1+$A$35)^Assumptions!$B$10-Assumptions!$B$6)/Assumptions!$B$7,"n/a") | D35: =IF($A$35>D$31,(SUMPRODUCT(DCF_Base!$C$20:$L$20/(1+$A$35)^DCF_Base!$C$4:$L$4)+MAX(0,MIN(DCF_Base!$L$20*(1+D$31)/($A$35-D$31),Assumptions!$C$16*DCF_Base!$L$20))/(1+$A$35)^Assumptions!$B$10-Assumptions!$B$6)/Assumptions!$B$7,"n/a") | E35: =IF($A$35>E$31,(SUMPRODUCT(DCF_Base!$C$20:$L$20/(1+$A$35)^DCF_Base!$C$4:$L$4)+MAX(0,MIN(DCF_Base!$L$20*(1+E$31)/($A$35-E$31),Assumptions!$C$16*DCF_Base!$L$20))/(1+$A$35)^Assumptions!$B$10-Assumptions!$B$6)/Assumptions!$B$7,"n/a") | F35: =IF($A$35>F$31,(SUMPRODUCT(DCF_Base!$C$20:$L$20/(1+$A$35)^DCF_Base!$C$4:$L$4)+MAX(0,MIN(DCF_Base!$L$20*(1+F$31)/($A$35-F$31),Assumptions!$C$16*DCF_Base!$L$20))/(1+$A$35)^Assumptions!$B$10-Assumptions!$B$6)/Assumptions!$B$7,"n/a")
A36: 0.12 | B36: =IF($A$36>B$31,(SUMPRODUCT(DCF_Base!$C$20:$L$20/(1+$A$36)^DCF_Base!$C$4:$L$4)+MAX(0,MIN(DCF_Base!$L$20*(1+B$31)/($A$36-B$31),Assumptions!$C$16*DCF_Base!$L$20))/(1+$A$36)^Assumptions!$B$10-Assumptions!$B$6)/Assumptions!$B$7,"n/a") | C36: =IF($A$36>C$31,(SUMPRODUCT(DCF_Base!$C$20:$L$20/(1+$A$36)^DCF_Base!$C$4:$L$4)+MAX(0,MIN(DCF_Base!$L$20*(1+C$31)/($A$36-C$31),Assumptions!$C$16*DCF_Base!$L$20))/(1+$A$36)^Assumptions!$B$10-Assumptions!$B$6)/Assumptions!$B$7,"n/a") | D36: =IF($A$36>D$31,(SUMPRODUCT(DCF_Base!$C$20:$L$20/(1+$A$36)^DCF_Base!$C$4:$L$4)+MAX(0,MIN(DCF_Base!$L$20*(1+D$31)/($A$36-D$31),Assumptions!$C$16*DCF_Base!$L$20))/(1+$A$36)^Assumptions!$B$10-Assumptions!$B$6)/Assumptions!$B$7,"n/a") | E36: =IF($A$36>E$31,(SUMPRODUCT(DCF_Base!$C$20:$L$20/(1+$A$36)^DCF_Base!$C$4:$L$4)+MAX(0,MIN(DCF_Base!$L$20*(1+E$31)/($A$36-E$31),Assumptions!$C$16*DCF_Base!$L$20))/(1+$A$36)^Assumptions!$B$10-Assumptions!$B$6)/Assumptions!$B$7,"n/a") | F36: =IF($A$36>F$31,(SUMPRODUCT(DCF_Base!$C$20:$L$20/(1+$A$36)^DCF_Base!$C$4:$L$4)+MAX(0,MIN(DCF_Base!$L$20*(1+F$31)/($A$36-F$31),Assumptions!$C$16*DCF_Base!$L$20))/(1+$A$36)^Assumptions!$B$10-Assumptions!$B$6)/Assumptions!$B$7,"n/a")
