Workbook

Sheet DCF Model
A1: GEN.NZ Book-Value Compounding Model
A2: NOT AN FCF DCF -- General Capital is a deposit-taking lender. Gray cells are INPUTS.
A3: Model: PV(dividends) + PV(exit value = Year-5 BVPS x exit P/B), discounted at Cost of Equity.
A5: KEY INPUTS
A6: Current Stock Price | B6: 0.26
A7: Shares Outstanding (M) | B7: 91.877912
A8: Total Equity, FY2026 (NZ$M) | B8: 31.297921
A9: Book Value per Share (BVPS) | B9: =B8/B7 -> 0
A10: Intangibles + Goodwill (NZ$M) | B10: 4.318
A11: Tangible Book Value per Share (TBVPS) | B11: =(B8-B10)/B7 -> 0
A12: FY2026 ROE (avg equity, %) | B12: 0.09
A13: Dividend Payout Ratio (%) | B13: 0.4
A14: Sustainable BV Growth = ROE x (1-Payout) | B14: =B12*(1-B13) -> 0
A16: Cost of Equity (CoE) | B16: 0.1675
A17: Management's own CGU discount rate (anchor, memo) | B17: 0.173 | C17: (FY26 goodwill impairment test, Finance CGU)
A18: Exit P/B Multiple (Year 5) | B18: 0.8
A20: ROE ASSUMPTIONS (Base Case) | B20: FY27 | C20: FY28 | D20: FY29 | E20: FY30 | F20: FY31
A21: ROE (%) | B21: 0.087 | C21: 0.088 | D21: 0.089 | E21: 0.09 | F21: 0.09
A23: PROJECTIONS (Base Case)
B24: FY27 | C24: FY28 | D24: FY29 | E24: FY30 | F24: FY31
A25: Opening Book Value (NZ$M) | B25: =B8 -> 0 | C25: =B29 -> 0 | D25: =C29 -> 0 | E25: =D29 -> 0 | F25: =E29 -> 0
A26: Net Income (NZ$M) | B26: =B25*B21 -> 0 | C26: =C25*C21 -> 0 | D26: =D25*D21 -> 0 | E26: =E25*E21 -> 0 | F26: =F25*F21 -> 0
A27: Dividends Paid (NZ$M) | B27: =B26*$B$13 -> 0 | C27: =C26*$B$13 -> 0 | D27: =D26*$B$13 -> 0 | E27: =E26*$B$13 -> 0 | F27: =F26*$B$13 -> 0
A28: DPS (NZ$) | B28: =B27/$B$7 -> 0 | C28: =C27/$B$7 -> 0 | D28: =D27/$B$7 -> 0 | E28: =E27/$B$7 -> 0 | F28: =F27/$B$7 -> 0
A29: Closing Book Value (NZ$M) | B29: =B25+B26-B27 -> 0 | C29: =C25+C26-C27 -> 0 | D29: =D25+D26-D27 -> 0 | E29: =E25+E26-E27 -> 0 | F29: =F25+F26-F27 -> 0
A30: BVPS (NZ$) | B30: =B29/$B$7 -> 0 | C30: =C29/$B$7 -> 0 | D30: =D29/$B$7 -> 0 | E30: =E29/$B$7 -> 0 | F30: =F29/$B$7 -> 0
A31: Discount Factor (at CoE) | B31: =1/(1+$B$16)^1 -> 0 | C31: =1/(1+$B$16)^2 -> 0 | D31: =1/(1+$B$16)^3 -> 0 | E31: =1/(1+$B$16)^4 -> 0 | F31: =1/(1+$B$16)^5 -> 0
A32: PV of DPS | B32: =B28*B31 -> 0 | C32: =C28*C31 -> 0 | D32: =D28*D31 -> 0 | E32: =E28*E31 -> 0 | F32: =F28*F31 -> 0
A34: VALUATION
A35: Sum PV of Dividends (Yrs 1-5) | B35: =SUM(B32:F32) -> 0
A36: Year-5 Exit BVPS | B36: =F30 -> 0
A37: Exit Value per Share (Yr5 BVPS x Exit P/B) | B37: =B36*B18 -> 0
A38: PV of Exit Value | B38: =B37*F31 -> 0
A39: INTRINSIC VALUE / SHARE | B39: =B35+B38 -> 0
A40: Upside / (Downside) vs Current Price | B40: =(B39-B6)/B6 -> 0
A41: Implied P/B of Intrinsic Value | B41: =B39/B9 -> 0
A42: Implied P/TBV of Intrinsic Value | B42: =B39/B11 -> 0
A44: ENTRY PRICE (15% IRR Target)
A45: Hurdle Rate | B45: 0.15
A46: PV of Dividends @ Hurdle | B46: =NPV(B45,B28:F28) -> 0
...

Sheet Sensitivity
A1: Sensitivity Analysis
A2: Intrinsic Value by Cost of Equity & Exit P/B Multiple (Base ROE/payout path)
A4: CoE \ Exit P/B | B4: 0.4 | C4: 0.6 | D4: 0.8 | E4: 1 | F4: 1.2
A5: 0.1475 | B5: =NPV(0.1475,'DCF Model'!$B$28:$F$28)+('DCF Model'!$F$30*0.4)/(1+0.1475)^5 -> 0 | C5: =NPV(0.1475,'DCF Model'!$B$28:$F$28)+('DCF Model'!$F$30*0.6)/(1+0.1475)^5 -> 0 | D5: =NPV(0.1475,'DCF Model'!$B$28:$F$28)+('DCF Model'!$F$30*0.8)/(1+0.1475)^5 -> 0 | E5: =NPV(0.1475,'DCF Model'!$B$28:$F$28)+('DCF Model'!$F$30*1.0)/(1+0.1475)^5 -> 0 | F5: =NPV(0.1475,'DCF Model'!$B$28:$F$28)+('DCF Model'!$F$30*1.2)/(1+0.1475)^5 -> 0
A6: 0.1575 | B6: =NPV(0.1575,'DCF Model'!$B$28:$F$28)+('DCF Model'!$F$30*0.4)/(1+0.1575)^5 -> 0 | C6: =NPV(0.1575,'DCF Model'!$B$28:$F$28)+('DCF Model'!$F$30*0.6)/(1+0.1575)^5 -> 0 | D6: =NPV(0.1575,'DCF Model'!$B$28:$F$28)+('DCF Model'!$F$30*0.8)/(1+0.1575)^5 -> 0 | E6: =NPV(0.1575,'DCF Model'!$B$28:$F$28)+('DCF Model'!$F$30*1.0)/(1+0.1575)^5 -> 0 | F6: =NPV(0.1575,'DCF Model'!$B$28:$F$28)+('DCF Model'!$F$30*1.2)/(1+0.1575)^5 -> 0
A7: 0.1675 | B7: =NPV(0.1675,'DCF Model'!$B$28:$F$28)+('DCF Model'!$F$30*0.4)/(1+0.1675)^5 -> 0 | C7: =NPV(0.1675,'DCF Model'!$B$28:$F$28)+('DCF Model'!$F$30*0.6)/(1+0.1675)^5 -> 0 | D7: =NPV(0.1675,'DCF Model'!$B$28:$F$28)+('DCF Model'!$F$30*0.8)/(1+0.1675)^5 -> 0 | E7: =NPV(0.1675,'DCF Model'!$B$28:$F$28)+('DCF Model'!$F$30*1.0)/(1+0.1675)^5 -> 0 | F7: =NPV(0.1675,'DCF Model'!$B$28:$F$28)+('DCF Model'!$F$30*1.2)/(1+0.1675)^5 -> 0
A8: 0.1775 | B8: =NPV(0.1775,'DCF Model'!$B$28:$F$28)+('DCF Model'!$F$30*0.4)/(1+0.1775)^5 -> 0 | C8: =NPV(0.1775,'DCF Model'!$B$28:$F$28)+('DCF Model'!$F$30*0.6)/(1+0.1775)^5 -> 0 | D8: =NPV(0.1775,'DCF Model'!$B$28:$F$28)+('DCF Model'!$F$30*0.8)/(1+0.1775)^5 -> 0 | E8: =NPV(0.1775,'DCF Model'!$B$28:$F$28)+('DCF Model'!$F$30*1.0)/(1+0.1775)^5 -> 0 | F8: =NPV(0.1775,'DCF Model'!$B$28:$F$28)+('DCF Model'!$F$30*1.2)/(1+0.1775)^5 -> 0
A9: 0.1875 | B9: =NPV(0.1875,'DCF Model'!$B$28:$F$28)+('DCF Model'!$F$30*0.4)/(1+0.1875)^5 -> 0 | C9: =NPV(0.1875,'DCF Model'!$B$28:$F$28)+('DCF Model'!$F$30*0.6)/(1+0.1875)^5 -> 0 | D9: =NPV(0.1875,'DCF Model'!$B$28:$F$28)+('DCF Model'!$F$30*0.8)/(1+0.1875)^5 -> 0 | E9: =NPV(0.1875,'DCF Model'!$B$28:$F$28)+('DCF Model'!$F$30*1.0)/(1+0.1875)^5 -> 0 | F9: =NPV(0.1875,'DCF Model'!$B$28:$F$28)+('DCF Model'!$F$30*1.2)/(1+0.1875)^5 -> 0

Sheet Historical
A1: Historical Growth & ROE Trend
A2: GEN.NZ has NO meaningful FCF -- reported OCF is a funding-flow artefact (see valuation_philosophy in JSON). This sheet replaces the FCF Quality sheet used for FCF-DCF tickers.
A4: Metric | B4: 3-Year CAGR | C4: 5-Year CAGR | D4: Note
A5: Operating Income | B5: 0.1453 | C5: 0.3756 | D5: Loan-book-growth driven; not the DCF driver
A6: NPAT | B6: 0.0645 | C6: 1.0162 | D6: Costs outrunning revenue -- see divergence warning
A7: EPS (restated x4 pre-Aug-2024) | B7: -0.0884 | C7: 0.7153 | D7: Negative 3yr CAGR
A8: Book Value per Share (restated) | B8: 0.0848 | C8: 0.0781 | D8: Most reliable historical series
A10: ROE Trend (avg equity)
A11: FY | B11: FY2022 | C11: FY2023 | D11: FY2024 | E11: FY2025 | F11: FY2026
A12: ROE % | B12: 0.116 | C12: 0.119 | D12: 0.103 | E12: 0.1 | F12: 0.09
A14: Selected Growth Rate (sustainable, ROE x retention): | B14: 0.054
A15: Source: | B15: sustainable_growth_roe_x_retention -- ROE(FY2026, ~9.0%) x (1 - 40% payout ratio) = 5.4% per year. This is the maximum book-value growth rate financeable from retained earnings alone without diluting shareholders via a below-book equity raise or drawing down capital-ratio headroom indefinitely -- deliberately NOT the loan-book growth rate (management guides 27.8% FY27 loan growth, moderating to 20-35%), which would require either continued capital-ratio drawdown or new equity.

Sheet Model_Info
A1: Model Provenance & Notes
A3: Ticker | B3: GEN.NZ -- General Capital Limited
A4: Model built by | B4: Claude Agent (DCF valuation skill), per /Users/swilliams/Stocks/Research .claude CLAUDE.md workflow
A5: Build date | B5: 2026-08-11
A6: Data vintage | B6: FY2026 annual report (year ended 31-Mar-2026, released 22-Jun-2026); share price NZ$0.26 verified live from Yahoo Finance on 11-Aug-2026
A7: Model type | B7: Book-value compounding (BVPS growth x exit Price/Book) with dividend income, discounted at Cost of Equity -- NOT a free-cash-flow DCF
A8: Why not FCF DCF | B8: GEN.NZ is a non-bank deposit taker. Reported OCF is dominated by loan origination/deposit flows (FY26 OCF -NZ$24.6m despite +NZ$2.72m NPAT) and has no valuation meaning. See valuation_philosophy block in the JSON for the full explanation.
A9: Share count basis | B9: 1-for-4 consolidation executed 2-Aug-2024. FY2019-FY2024 EPS/per-share figures in the CSV are UN-restated (pre-consolidation basis); this model restates them x4 for the historical_growth CAGRs only. FY2025-FY2026 and all forward projections use the post-consolidation share count (91.877912m), held FLAT (no SBC -- verified nil; no buybacks or equity raise assumed).
A10: Cost of equity build | B10: 16.75% -- see cost_of_equity.coe_rationale in the JSON. Anchored against management's own 17.3% pre-tax Finance-CGU discount rate from the FY26 goodwill impairment test.
A11: Growth driver | B11: Sustainable book-value growth = ROE x (1 - payout ratio) = 9.0% x 60% = 5.4%/yr, NOT the loan-book growth rate (management guides 27.8%+ for FY27) -- a lender cannot grow book value faster than retained earnings support without dilutive capital raising.
A12: Exit multiple discipline | B12: Exit P/B multiples (0.60x bear / 0.80x base / 1.10x bull) are anchored to the stock's OWN observed post-consolidation trading range (0.74x-0.88x FY2025-FY2026), not a theoretical re-rating.
A13: Sanity check | B13: Yahoo Finance historical monthly prices for GEN.NZ are NOT retroactively split-adjusted for the Aug-2024 consolidation; pre-consolidation P/B multiples (raw price x raw pre-split shares) of 3.3x-5.8x are an ILLIQUID MICRO-CAP PRICING ARTEFACT and are excluded from the historical average used in the sanity check. Only the post-consolidation FY2025-FY2026 P/B range (0.74x-0.82x) is used as the reliable anchor. See sanity_check block in the JSON for full detail.
A14: What to refresh after next earnings | B14: Update shares_outstanding, book_value_total, NPAT, ROE trend and DPS from the FY2027 annual report (expected ~Jun-2027); re-verify the current share price; re-check whether ROE continues its 4-year downtrend or begins to stabilise/recover (this is the single most important variable to re-test); re-run the sanity check against the latest 12 months of trading.
... A16: Staleness warning | B16: All figures in this workbook are point-in-time as of the Data Vintage above. GEN.NZ is a fast-growing (in balance-sheet terms), thinly-traded micro-cap -- re-verify all inputs before relying on this model for a live decision.
