Workbook

Sheet NAV Model
A1: BIF.NZ NAV-Compounding Valuation Model
A2: NOT an FCF DCF -- BIF is a venture-capital unit trust with no revenue/EBITDA/FCF. Gray cells are INPUTS.
A4: KEY INPUTS
A5: Current Unit Price | B5: 1.508
A6: NAV/unit -- 31-Mar-2026 audited | B6: 1.5114
A7: NAV/unit -- latest strike (3-Jul-2026, used as base) | B7: 1.4759
A8: Units on issue (M) | B8: 16.330729
A9: Net assets FY2026 (M) | B9: 24.683
A10: Total debt (M) | B10: 0
A11: Net debt adjustment (M) | B11: 0 | C11: Set to 0 -- cash is already inside NAV; adding net cash again would double-count
A13: Cost of Equity (built up, see WACC Rationale sheet) | B13: 0.2
A15: COST OF EQUITY BUILD-UP
A16: NZ risk-free rate | B16: 0.045
A17: NZ equity risk premium | B17: 0.06
A18: Level 3 manager-marked / no price test premium | B18: 0.025
A19: Zero-realisation / untested exit premium | B19: 0.02
A20: Illiquidity / tiny free-float premium | B20: 0.025
A21: Early-stage venture risk premium | B21: 0.025
A22: Total Cost of Equity (sum, formula) | B22: =SUM(B16:B21) -> 0
A23: BASE CASE NAV GROWTH ASSUMPTIONS
B24: FY2027 | C24: FY2028 | D24: FY2029 | E24: FY2030 | F24: FY2031
A25: NAV Growth Rate | B25: 0.04 | C25: 0.05 | D25: 0.055 | E25: 0.06 | F25: 0.06
A26: Exit Price-to-NAV multiple (Year 5) | B26: 0.9
A28: BASE CASE NAV PROJECTION
B29: Base | C29: FY2027 | D29: FY2028 | E29: FY2029 | F29: FY2030 | G29: FY2031
A30: NAV per unit | B30: =B7 -> 0 | C30: =B30*(1+B25) -> 0 | D30: =C30*(1+C25) -> 0 | E30: =D30*(1+D25) -> 0 | F30: =E30*(1+E25) -> 0 | G30: =F30*(1+F25) -> 0
A31: Discount factor (at Cost of Equity) | C31: =1/(1+$B$13)^1 -> 0 | D31: =1/(1+$B$13)^2 -> 0 | E31: =1/(1+$B$13)^3 -> 0 | F31: =1/(1+$B$13)^4 -> 0 | G31: =1/(1+$B$13)^5 -> 0
A33: Note: no interim distributions exist or are projected -- BIF has paid unitholders nothing since
A34: a single $568k FY2022 distribution. 100% of value is the single Year-5 exit realisation.
A36: VALUATION (Base Case)
A37: Year-5 NAV per unit | B37: =G30 -> 0
A38: Exit Price-to-NAV multiple | B38: =B26 -> 0
A39: Year-5 Exit Value | B39: =B37*B38 -> 0
A40: PV of Year-5 Exit Value (at Cost of Equity) | B40: =B39*G31 -> 0
A41: Less: net debt adjustment (per unit) | B41: =B11 -> 0
A42: INTRINSIC VALUE PER UNIT (Base Case) | B42: =B40-B41 -> 0
A44: Upside/(Downside) to Intrinsic Value | B44: =(B42-B5)/B5 -> 0
A46: ENTRY PRICE (15% IRR Target)
A47: Hurdle rate | B47: 0.15
A48: PV of interim distributions @ hurdle | B48: 0 | C48: Zero -- no distributions projected
...

Sheet Scenarios
A1: Scenario Comparison
B3: Bear | C3: Base | D3: Bull
A4: NAV growth path (Y1-Y5) | B4: -3.0%, 0.0%, 1.0%, 2.0%, 2.0% | C4: 4.0%, 5.0%, 5.5%, 6.0%, 6.0% | D4: 10.0%, 12.0%, 14.0%, 16.0%, 18.0%
A5: Exit Price-to-NAV multiple | B5: 0.75 | C5: 0.9 | D5: 1
A6: Cost of Equity | B6: 0.2 | C6: 0.2 | D6: 0.2
A7: Year-5 NAV per unit | B7: 1.5044 | C7: 1.9105 | D7: 2.8374
A8: Year-5 Exit Value | B8: 1.1283 | C8: 1.7195 | D8: 2.8374
A9: Intrinsic Value per Unit | B9: 0.4534 | C9: 0.691 | D9: 1.1402
A10: Upside/(Downside) to Current Price | B10: -0.6993 | C10: -0.5418 | D10: -0.2439
A12: Probability weight | B12: 0.25 | C12: 0.55 | D12: 0.2
A14: PROBABILITY-WEIGHTED INTRINSIC VALUE | B14: =B9*B12+C9*C12+D9*D12 -> 0
A15: Current Price | B15: 1.508
A16: Weighted Upside/(Downside) | B16: =(B14-B15)/B15 -> 0

Sheet Sensitivity
A1: Sensitivity Analysis
A2: Intrinsic Value by NAV Growth Rate & Exit Price-to-NAV
A4: Growth \ Exit P/NAV | B4: 0.7 | C4: 0.8 | D4: 0.9 | E4: 1 | F4: 1.1
A5: 0 | B5: =('NAV Model'!$B$7*(1+0.0)^5*0.7)/(1+'NAV Model'!$B$13)^5 -> 0 | C5: =('NAV Model'!$B$7*(1+0.0)^5*0.8)/(1+'NAV Model'!$B$13)^5 -> 0 | D5: =('NAV Model'!$B$7*(1+0.0)^5*0.9)/(1+'NAV Model'!$B$13)^5 -> 0 | E5: =('NAV Model'!$B$7*(1+0.0)^5*1.0)/(1+'NAV Model'!$B$13)^5 -> 0 | F5: =('NAV Model'!$B$7*(1+0.0)^5*1.1)/(1+'NAV Model'!$B$13)^5 -> 0
A6: 0.03 | B6: =('NAV Model'!$B$7*(1+0.03)^5*0.7)/(1+'NAV Model'!$B$13)^5 -> 0 | C6: =('NAV Model'!$B$7*(1+0.03)^5*0.8)/(1+'NAV Model'!$B$13)^5 -> 0 | D6: =('NAV Model'!$B$7*(1+0.03)^5*0.9)/(1+'NAV Model'!$B$13)^5 -> 0 | E6: =('NAV Model'!$B$7*(1+0.03)^5*1.0)/(1+'NAV Model'!$B$13)^5 -> 0 | F6: =('NAV Model'!$B$7*(1+0.03)^5*1.1)/(1+'NAV Model'!$B$13)^5 -> 0
A7: 0.06 | B7: =('NAV Model'!$B$7*(1+0.06)^5*0.7)/(1+'NAV Model'!$B$13)^5 -> 0 | C7: =('NAV Model'!$B$7*(1+0.06)^5*0.8)/(1+'NAV Model'!$B$13)^5 -> 0 | D7: =('NAV Model'!$B$7*(1+0.06)^5*0.9)/(1+'NAV Model'!$B$13)^5 -> 0 | E7: =('NAV Model'!$B$7*(1+0.06)^5*1.0)/(1+'NAV Model'!$B$13)^5 -> 0 | F7: =('NAV Model'!$B$7*(1+0.06)^5*1.1)/(1+'NAV Model'!$B$13)^5 -> 0
A8: 0.09 | B8: =('NAV Model'!$B$7*(1+0.09)^5*0.7)/(1+'NAV Model'!$B$13)^5 -> 0 | C8: =('NAV Model'!$B$7*(1+0.09)^5*0.8)/(1+'NAV Model'!$B$13)^5 -> 0 | D8: =('NAV Model'!$B$7*(1+0.09)^5*0.9)/(1+'NAV Model'!$B$13)^5 -> 0 | E8: =('NAV Model'!$B$7*(1+0.09)^5*1.0)/(1+'NAV Model'!$B$13)^5 -> 0 | F8: =('NAV Model'!$B$7*(1+0.09)^5*1.1)/(1+'NAV Model'!$B$13)^5 -> 0
A9: 0.12 | B9: =('NAV Model'!$B$7*(1+0.12)^5*0.7)/(1+'NAV Model'!$B$13)^5 -> 0 | C9: =('NAV Model'!$B$7*(1+0.12)^5*0.8)/(1+'NAV Model'!$B$13)^5 -> 0 | D9: =('NAV Model'!$B$7*(1+0.12)^5*0.9)/(1+'NAV Model'!$B$13)^5 -> 0 | E9: =('NAV Model'!$B$7*(1+0.12)^5*1.0)/(1+'NAV Model'!$B$13)^5 -> 0 | F9: =('NAV Model'!$B$7*(1+0.12)^5*1.1)/(1+'NAV Model'!$B$13)^5 -> 0
A10: 0.15 | B10: =('NAV Model'!$B$7*(1+0.15)^5*0.7)/(1+'NAV Model'!$B$13)^5 -> 0 | C10: =('NAV Model'!$B$7*(1+0.15)^5*0.8)/(1+'NAV Model'!$B$13)^5 -> 0 | D10: =('NAV Model'!$B$7*(1+0.15)^5*0.9)/(1+'NAV Model'!$B$13)^5 -> 0 | E10: =('NAV Model'!$B$7*(1+0.15)^5*1.0)/(1+'NAV Model'!$B$13)^5 -> 0 | F10: =('NAV Model'!$B$7*(1+0.15)^5*1.1)/(1+'NAV Model'!$B$13)^5 -> 0
A12: Cost of Equity Sensitivity (Base Case, 6% terminal growth, 0.90x exit)
A13: Cost of Equity
B14: 0.17 | C14: 0.185 | D14: 0.2 | E14: 0.215 | F14: 0.23
A15: Intrinsic Value | B15: ='NAV Model'!$B$39/(1+0.17)^5 -> 0 | C15: ='NAV Model'!$B$39/(1+0.185)^5 -> 0 | D15: ='NAV Model'!$B$39/(1+0.2)^5 -> 0 | E15: ='NAV Model'!$B$39/(1+0.215)^5 -> 0 | F15: ='NAV Model'!$B$39/(1+0.23)^5 -> 0

Sheet NAV Reconciliation
A1: NAV Reconciliation (FCF-Quality equivalent for a fund)
A2: BIF has no FCF; this sheet reconciles NAV per unit growth to net asset TOTAL growth to show how much of the headline growth is capital raising vs investment performance.
A4: Period | B4: FY2022 | C4: FY2023 | D4: FY2024 | E4: FY2025 | F4: FY2026
A5: Net assets (M) | B5: 7.62 | C5: 14.086 | D5: 19.455 | E5: 20.363 | F5: 24.683
A6: Units on issue (M) | B6: 6.097365 | C6: 10.120588 | D6: 12.630107 | E6: 14.416518 | F6: 16.330729
A7: NAV per unit (formula) | B7: =B5/B6 -> 0 | C7: =C5/C6 -> 0 | D7: =D5/D6 -> 0 | E7: =E5/E6 -> 0 | F7: =F5/F6 -> 0
A8: NAV per unit YoY growth (formula) | C8: =(C7/B7)-1 -> 0 | D8: =(D7/C7)-1 -> 0 | E8: =(E7/D7)-1 -> 0 | F8: =(F7/E7)-1 -> 0
A10: Net asset TOTAL 4yr CAGR (FY22-FY26) | B10: =(F5/B5)^(1/4)-1 -> 0
A11: Units on issue 4yr CAGR (FY22-FY26) | B11: =(F6/B6)^(1/4)-1 -> 0
A12: NAV per unit 4yr CAGR (FY22-FY26) | B12: =(F7/B7)^(1/4)-1 -> 0
A14: Memo: net profit after tax (M) | B14: 1.245 | C14: 1.003 | D14: 1.593 | E14: -1.739 | F14: 1.593
A15: Memo: distributions paid to unitholders (M) | B15: 0.568 | C15: 0 | D15: 0 | E15: 0 | F15: 0
A16: Cumulative distributions since inception: | B16: $568k total, FY2022 only. Zero distributions FY2023-FY2026.

Sheet Model_Info
A1: Model Provenance & Notes
A4: Built by | B4: Claude Agent (dcf-analyst role), Stocks Research pipeline
A5: Build date | B5: 2026-08-09
A6: Model type | B6: NAV-per-unit compounding with exit price-to-NAV multiple. NOT an FCF DCF -- BIF is a venture-capital unit trust with no revenue, EBITDA, capex or free cash flow.
A7: Share price date | B7: 2026-08-09 -- Yahoo Finance live quote, 1.508 NZD. Note: BIF is exceptionally illiquid; Yahoo shows an essentially flat $1.504-$1.508 52-week range, so this quote is nominal rather than a market-clearing price.
A8: NAV data vintage | B8: 31-Mar-2026 audited annual report (FY2026 NAV/unit $1.5114) plus post-balance-date NZX announcements through 3-Jul-2026 (latest unit issue at $1.4759/unit, used as the model's NAV base).
A9: Key methodology choice | B9: NAV base for projections is the LATEST OBSERVABLE STRIKE ($1.4759, 3-Jul-2026), not the higher audited FY2026 NAV ($1.5114), because the manager's own most recent pricing action embeds a mark-down not yet reflected in the annual report. This is treated as a genuine, adverse data point.
A10: Cost of equity | B10: 20.0% built up from NZ risk-free (4.5%) + NZ ERP (6.0%) + four structural premiums (Level 3 marking, zero realisations, illiquidity, early-stage venture risk, 2.0-2.5% each). See WACC build-up on 'NAV Model' sheet and wacc_rationale in the JSON.
A11: Net debt treatment | B11: Set to zero. Cash ($0.326m, 1.3% of net assets) is already inside NAV per unit; adding net cash again on top of a NAV-based valuation would double-count the same asset. Total debt is genuinely nil.
A12: Terminal value construction | B12: IV = NAV_year5 x exit_price_to_NAV / (1+CoE)^5. No Gordon Growth perpetuity is used -- the fund does not generate a cash flow stream to capitalize; the entire value is the single year-5 realisation event.
A13: Entry price construction | B13: With no interim distributions, entry price collapses to the year-5 base-case exit value discounted at a 15% hurdle rate. This is a substantive fact about BIF (it distributes nothing), not a shortcut.
A14: What to refresh after next disclosure | B14: (1) Any new NZX valuation-adjustment announcement or unit issue price -- update nav_per_unit_current_basis and re-run; (2) FY2027 annual report NAV/unit and net asset figures -- extend the NAV history table; (3) any realised exit/distribution -- this would be the first real cash-flow evidence for the exit thesis and should prompt a reassessment of the zero-realisation risk premium in cost of equity; (4) ownership/free-float disclosure -- if Booster's related-party holding percentage changes materially, revisit the illiquidity premium.
A15: Cell colour convention | B15: Gray-filled cells (light blue-gray, #dfe6e9) are INPUTS meant to be adjusted. White cells with borders are FORMULAS that recalculate automatically. Green-filled cells are headline RESULTS. All formulas reference the 'NAV Model' sheet inputs so changing WACC, NAV growth or exit multiple flows through the whole model.
A16: Staleness warning | B16: All figures in this workbook go stale, especially the current unit price and the 'latest strike' NAV base, both of which can move materially given BIF's history of NZX valuation-adjustment announcements between annual reports. Re-check both against the company's most recent NZX release before relying on this model.
