Workbook

Sheet Model_Info
A1: ALX.AX (Atlas Arteria) valuation workbook -- version 1, 2026-09-21. Supersedes nothing (first valuation).
A2: Built by the dcf-analyst agent (Claude Fable 5.1) at the research orchestrator's request, from ALX.AX_DCF.json of the same date.
A3: MODEL: distribution-based sum-of-parts with finite concession lives. Cash actually received at ALX corporate level (APRR/MAF2 distributions, Skyway distributions + CCPI loan interest) less corporate costs and tax, FY2026-FY2035 (APRR expiry Nov-2035), discounted at COST OF EQUITY. Terminal = explicit PV at end-2035 of the surviving tails (Skyway to 2104, AREA/ADELAC/A79, bull re-concession lump). No Gordon.
A4: Why not owner-FCF: consolidated OCF (A$88.2m FY25) excludes the A$516.8m of distributions booked in investing; the dominant stream ends in 9 years. Project debt (TRIP II, Warnow, CCPI, APRR/FE) is non-recourse and already serviced before the flows -- it is NOT subtracted (AFFO rule).
A5: DATA VINTAGE: price A$4.44 ASX close 2026-09-21T06:10Z (Yahoo). Balance sheet 31-Dec-2025 (FY2025 annual report, 26-Feb-2026) -- corporate cash A$150.6m, no corporate debt; US$100m OTPP put settlement paid Jul/Aug-2026 applied. Diluted securities 1,453.3m (AR2025 note 18). FY2026 guidance: distribution 40cps; H1-26 OFCF 19.1cps (Analysis JSON; H1-26 filing not in folder). FX spot 2026-09-21: EURAUD 1.6102, AUDUSD 0.7131.
A6: DRIVERS: the APRR EUR receipt path and the Skyway US$ path per scenario (Assumptions rows 31-38) are the agent's judgment set 2026-09-21; scenario FX, corporate cost, tail growth and Greenway/Warnow equity are on Assumptions rows 14-27. Cost of equity 8.5% AUD (4.3% ACGB + 0.8 x 5.25%), same for all scenarios -- risk lives in the flows.
A7: REFRESH after the next print: corporate cash (H1-26 / FY26 balance sheet), the Sep-2026 APRR distribution, Greenway rate-case outcome (hearing ~Sep/Oct-2026), TST status in the 2027 French budget, any Skyway sale, spot FX. Figures go stale.
A8: COLOURS: blue = hardcoded input; yellow fill = key lever; black = formula; green = cross-sheet link.

Sheet Actuals
A1: Item (A$m) | B1: FY2019 | C1: FY2020 | D1: FY2021 | E1: FY2022 | F1: FY2023 | G1: FY2024 | H1: FY2025 | I1: Source
A2: Distributions received from associates (investing) | B2: 238.2 | C2: 310.9 | D2: 307.8 | E2: 406.9 | F2: 619.6 | G2: 618.9 | H2: 516.8 | I2: kpis.DistributionsFromAssociates; AR2025 line 6381
A3: of which MAF2 (APRR) | G3: 569.4 | H3: 498.2 | I3: AR2025 note 25 line 8686
A4: of which CCPI (Skyway) | G4: 49.4 | H4: 18.7 | I4: AR2025 note 25 line 8687
A5: CCPI shareholder-loan interest | F5: 18.1 | G5: 17.7 | H5: 18.1 | I5: AR2025 line 6114
A6: Company operating free cash flow | G6: 527.1 | H6: 505.9 | I6: AR2025 p.23
A7: Statutory operating cash flow | B7: 76.4 | C7: 39.3 | D7: 47.5 | E7: 73.8 | F7: 84.7 | G7: 93.2 | H7: 88.2 | I7: Metrics.csv
A8: Distributions paid | B8: 151.7 | C8: 105.5 | D8: 273.3 | E8: 388.4 | F8: 580.4 | G8: 580.4 | H8: 580.4 | I8: kpis.DividendsPaid
A9: Corporate + centralised costs | G9: 44.9 | H9: 52.6 | I9: Appendix 4E lines 187-191
A10: Share-based payments | D10: 2.5 | E10: 3.1 | F10: 3.7 | G10: 3.4 | H10: 3.4 | I10: cash flow statement
A11: Corporate cash (year end) | G11: 225.5 | H11: 150.6 | I11: AR2025 p.23
A12: Proportional EBITDA | G12: 1381 | H12: 1509.9 | I12: kpis.ProportionalEBITDA
A14: Balance-sheet snapshot 31-Dec-2025: corporate cash 150.6; corporate debt 0 (A$50m WCF undrawn); TRIP II bonds 1,497.1 and Warnow 197.5 non-recourse (excluded); securities on issue 1,450.8m, diluted 1,453.3m; no buyback.
A15: Post balance sheet: US$100m OTPP put extinguishment paid 1-Jul and 11-Aug-2026 (Analysis JSON); IFM holds 67.43% after A$5.10 offer closed Jul-2026.

Sheet Assumptions
A1: Globals
A3: Price (A$) | B3: 4.44 | C3: ASX close 2026-09-21
A4: Diluted securities (m) | B4: 1453.289 | C4: AR2025 note 18
A5: Corporate cash 31-Dec-2025 (A$m) | B5: 150.6 | C5: AR2025 p.23
A6: OTPP put settlement (A$m, negative) | B6: -140.2 | C6: US$100m / 0.7131
A7: Cost of equity | B7: 0.085 | C7: AUD: 4.3% + 0.8 x 5.25%
A8: Hurdle rate | B8: 0.15 | C8: house
A9: Horizon (years) | B9: 10 | C9: FY2026-35 = APRR expiry
A10: FY2025 SBC (A$m) | B10: 3.4 | C10: inside corporate costs; memo only
A12: Scenario drivers
C13: Bear | D13: Base | E13: Bull
A14: EUR/AUD (A$ per EUR) | C14: 1.53 | D14: 1.6102 | E14: 1.7
A15: AUD/USD (US$ per A$) | C15: 0.75 | D15: 0.7131 | E15: 0.68
A16: Corporate costs FY2026 (A$m) | C16: 46 | D16: 44 | E16: 42
A17: Corporate cost growth | C17: 0.03 | D17: 0.025 | E17: 0.02
A18: Corporate tax FY2026 (A$m) | C18: 8 | D18: 8 | E18: 8
A19: Corporate tax growth | C19: 0.02 | D19: 0.02 | E19: 0.02
A20: Skyway tail growth (post-2035) | C20: 0.03 | D20: 0.035 | E20: 0.04
A21: Skyway tail years (2036-2104) | C21: 69 | D21: 69 | E21: 69
A22: French tail EUR m/yr (AREA/ADELAC/A79) | C22: 5 | D22: 12 | E22: 18
A23: French tail years | C23: 25 | D23: 25 | E23: 25
A24: French re-concession value at 2035 (A$m) | C24: 0 | D24: 0 | E24: 600
A25: Greenway equity today (A$m) | C25: 0 | D25: 150 | E25: 450
... A27: Probability weight | C27: 0.2 | D27: 0.55 | E27: 0.25
A28: Weights sum (must be 1) | B28: =SUM(C27:E27)
A30: APRR-group receipts to ALX, EUR m (driver) | C30: FY2026 | D30: FY2027 | E30: FY2028 | F30: FY2029 | G30: FY2030 | H30: FY2031 | I30: FY2032 | J30: FY2033 | K30: FY2034 | L30: FY2035
A31: Bear | C31: 275 | D31: 285 | E31: 290 | F31: 290 | G31: 285 | H31: 275 | I31: 260 | J31: 235 | K31: 200 | L31: 150
A32: Base | C32: 290 | D32: 315 | E32: 325 | F32: 330 | G32: 330 | H32: 325 | I32: 310 | J32: 290 | K32: 250 | L32: 200
A33: Bull | C33: 295 | D33: 335 | E33: 350 | F33: 360 | G33: 365 | H33: 365 | I33: 360 | J33: 345 | K33: 320 | L33: 290
A35: Skyway distributions + CCPI loan interest to ALX, US$ m (driver) | C35: FY2026 | D35: FY2027 | E35: FY2028 | F35: FY2029 | G35: FY2030 | H35: FY2031 | I35: FY2032 | J35: FY2033 | K35: FY2034 | L35: FY2035
A36: Bear | C36: 24 | D36: 25 | E36: 26 | F36: 27 | G36: 29 | H36: 30 | I36: 32 | J36: 33 | K36: 35 | L36: 37
A37: Base | C37: 25 | D37: 27 | E37: 29 | F37: 31 | G37: 33 | H37: 35 | I37: 38 | J37: 41 | K37: 44 | L37: 47
A38: Bull | C38: 26 | D38: 28 | E38: 31 | F38: 34 | G38: 37 | H38: 40 | I38: 43 | J38: 47 | K38: 51 | L38: 55
A40: Narratives
A41: Bear | B41: TST-style surcharges recur and the long-distance transport tax bites (payout ~EUR285m and falling), traffic flat, APRR deleverages earlier and harder (FY2035 EUR150m); Greenway rate case fails again (equity nil, possible restructuring); Warnow nil; Skyway growth 5%; AUD stronger still (EUR/AUD 1.53, AUD/USD 0.75). 67%-controlled register with thin free float.
A42: Base | B42: APRR runs to Nov-2035 expiry with TST rolling off after 2026, tolls +~2%/yr and traffic +~1%; distributions taper from 2032 as APRR/FE deleverages to zero by expiry; no re-concession value. Skyway compounds ~7%/yr on its contractual toll formula and is retained (or sold near this value). Greenway rate case yields a partial increase worth A$150m of equity. FX held at spot.
A43: Bull | B43: Stronger French traffic and no further French tax measures; APRR distributions ~EUR360m mid-decade and a slower taper; A$600m of value at 2035 from an APRR extension/new French concession (Ambition France Transports keeps the concession model; A412 and A79 tails larger). Greenway rate case fully granted (A$450m); Skyway grows 8%/yr and its tail 4%; weaker AUD (EUR/AUD 1.70). IFM clean-up is NOT priced — it would be a premium on top.

Sheet DCF_Bear
A1: DCF_Bear -- A$m unless stated; column B = FY2025 actual, C..L = FY2026-FY2035
A3: Year | B3: 2025A | C3: 2026E | D3: 2027E | E3: 2028E | F3: 2029E | G3: 2030E | H3: 2031E | I3: 2032E | J3: 2033E | K3: 2034E | L3: 2035E
A4: Index | B4: 0 | C4: 1 | D4: 2 | E4: 3 | F4: 4 | G4: 5 | H4: 6 | I4: 7 | J4: 8 | K4: 9 | L4: 10
A5: APRR-group receipts (EUR m) | C5: =Assumptions!C31 | D5: =Assumptions!D31 | E5: =Assumptions!E31 | F5: =Assumptions!F31 | G5: =Assumptions!G31 | H5: =Assumptions!H31 | I5: =Assumptions!I31 | J5: =Assumptions!J31 | ... L5: =Assumptions!L31
A6: EUR/AUD | C6: =Assumptions!$C$14 | D6: =Assumptions!$C$14 | E6: =Assumptions!$C$14 | F6: =Assumptions!$C$14 | G6: =Assumptions!$C$14 | H6: =Assumptions!$C$14 | I6: =Assumptions!$C$14 | J6: =Assumptions!$C$14 | ... L6: =Assumptions!$C$14
A7: APRR receipts (A$m) | B7: 498.2 | C7: =C5*C6 | D7: =D5*D6 | E7: =E5*E6 | F7: =F5*F6 | G7: =G5*G6 | H7: =H5*H6 | I7: =I5*I6 | J7: =J5*J6 | ... L7: =L5*L6
A8: Skyway receipts (US$ m) | C8: =Assumptions!C36 | D8: =Assumptions!D36 | E8: =Assumptions!E36 | F8: =Assumptions!F36 | G8: =Assumptions!G36 | H8: =Assumptions!H36 | I8: =Assumptions!I36 | J8: =Assumptions!J36 | ... L8: =Assumptions!L36
A9: AUD/USD | C9: =Assumptions!$C$15 | D9: =Assumptions!$C$15 | E9: =Assumptions!$C$15 | F9: =Assumptions!$C$15 | G9: =Assumptions!$C$15 | H9: =Assumptions!$C$15 | I9: =Assumptions!$C$15 | J9: =Assumptions!$C$15 | ... L9: =Assumptions!$C$15
A10: Skyway receipts (A$m) | B10: 36.8 | C10: =C8/C9 | D10: =D8/D9 | E10: =E8/E9 | F10: =F8/F9 | G10: =G8/G9 | H10: =H8/H9 | I10: =I8/I9 | J10: =J8/J9 | ... L10: =L8/L9
A11: Total receipts | B11: =B7+B10 | C11: =C7+C10 | D11: =D7+D10 | E11: =E7+E10 | F11: =F7+F10 | G11: =G7+G10 | H11: =H7+H10 | I11: =I7+I10 | ... L11: =L7+L10
A12: Receipts growth | C12: =C11/B11-1 | D12: =D11/C11-1 | E12: =E11/D11-1 | F12: =F11/E11-1 | G12: =G11/F11-1 | H12: =H11/G11-1 | I12: =I11/H11-1 | J12: =J11/I11-1 | ... L12: =L11/K11-1
A13: Corporate cash costs incl. SBC (negative) | B13: -52.6 | C13: =-Assumptions!$C$16*(1+Assumptions!$C$17)^(C4-1) | D13: =-Assumptions!$C$16*(1+Assumptions!$C$17)^(D4-1) | E13: =-Assumptions!$C$16*(1+Assumptions!$C$17)^(E4-1) | F13: =-Assumptions!$C$16*(1+Assumptions!$C$17)^(F4-1) | G13: =-Assumptions!$C$16*(1+Assumptions!$C$17)^(G4-1) | H13: =-Assumptions!$C$16*(1+Assumptions!$C$17)^(H4-1) | I13: =-Assumptions!$C$16*(1+Assumptions!$C$17)^(I4-1) | J13: =-Assumptions!$C$16*(1+Assumptions!$C$17)^(J4-1) | ... L13: =-Assumptions!$C$16*(1+Assumptions!$C$17)^(L4-1)
A14: memo: SBC inside corporate costs | B14: 3.4 | C14: =Assumptions!$B$10*(1+Assumptions!$C$17)^(C4-1) | D14: =Assumptions!$B$10*(1+Assumptions!$C$17)^(D4-1) | E14: =Assumptions!$B$10*(1+Assumptions!$C$17)^(E4-1) | F14: =Assumptions!$B$10*(1+Assumptions!$C$17)^(F4-1) | G14: =Assumptions!$B$10*(1+Assumptions!$C$17)^(G4-1) | H14: =Assumptions!$B$10*(1+Assumptions!$C$17)^(H4-1) | I14: =Assumptions!$B$10*(1+Assumptions!$C$17)^(I4-1) | J14: =Assumptions!$B$10*(1+Assumptions!$C$17)^(J4-1) | ... L14: =Assumptions!$B$10*(1+Assumptions!$C$17)^(L4-1)
A15: Owner EBITDA (receipts less corporate costs) | B15: =B11+B13 | C15: =C11+C13 | D15: =D11+D13 | E15: =E11+E13 | F15: =F11+F13 | G15: =G11+G13 | H15: =H11+H13 | I15: =I11+I13 | ... L15: =L11+L13
A16: Corporate tax (negative) | B16: -8 | C16: =-Assumptions!$C$18*(1+Assumptions!$C$19)^(C4-1) | D16: =-Assumptions!$C$18*(1+Assumptions!$C$19)^(D4-1) | E16: =-Assumptions!$C$18*(1+Assumptions!$C$19)^(E4-1) | F16: =-Assumptions!$C$18*(1+Assumptions!$C$19)^(F4-1) | G16: =-Assumptions!$C$18*(1+Assumptions!$C$19)^(G4-1) | H16: =-Assumptions!$C$18*(1+Assumptions!$C$19)^(H4-1) | I16: =-Assumptions!$C$18*(1+Assumptions!$C$19)^(I4-1) | J16: =-Assumptions!$C$18*(1+Assumptions!$C$19)^(J4-1) | ... L16: =-Assumptions!$C$18*(1+Assumptions!$C$19)^(L4-1)
A17: Distributable cash = owner FCF | B17: =B15+B16 | C17: =C15+C16 | D17: =D15+D16 | E17: =E15+E16 | F17: =F15+F16 | G17: =G15+G16 | H17: =H15+H16 | I17: =I15+I16 | ... L17: =L15+L16
A18: per security (cents) | B18: =B17/Assumptions!$B$4*100 | C18: =C17/Assumptions!$B$4*100 | D18: =D17/Assumptions!$B$4*100 | E18: =E17/Assumptions!$B$4*100 | F18: =F17/Assumptions!$B$4*100 | G18: =G17/Assumptions!$B$4*100 | H18: =H17/Assumptions!$B$4*100 | I18: =I17/Assumptions!$B$4*100 | ... L18: =L17/Assumptions!$B$4*100
A19: Discount factor | C19: =1/(1+Assumptions!$B$7)^C4 | D19: =1/(1+Assumptions!$B$7)^D4 | E19: =1/(1+Assumptions!$B$7)^E4 | F19: =1/(1+Assumptions!$B$7)^F4 | G19: =1/(1+Assumptions!$B$7)^G4 | H19: =1/(1+Assumptions!$B$7)^H4 | I19: =1/(1+Assumptions!$B$7)^I4 | J19: =1/(1+Assumptions!$B$7)^J4 | ... L19: =1/(1+Assumptions!$B$7)^L4
A20: PV of distributable cash | C20: =C17*C19 | D20: =D17*D19 | E20: =E17*E19 | F20: =F17*F19 | G20: =G17*G19 | H20: =H17*H19 | I20: =I17*I19 | J20: =J17*J19 | ... L20: =L17*L19
A22: Sum of PV (FY2026-35) | B22: =SUM(C20:L20)
A23: Skyway receipts FY2035 (A$m) | B23: =L10
A24: Skyway tail growth | B24: =Assumptions!$C$20
A25: Skyway tail years | B25: =Assumptions!$C$21
A26: Skyway tail value at end-2035 | B26: =B23*(1+B24)/(Assumptions!$B$7-B24)*(1-((1+B24)/(1+Assumptions!$B$7))^B25)
A27: French tail EUR m/yr | B27: =Assumptions!$C$22
A28: French tail A$m/yr | B28: =B27*Assumptions!$C$14
A29: French tail years | B29: =Assumptions!$C$23
A30: French tail value at end-2035 | B30: =B28/Assumptions!$B$7*(1-(1+Assumptions!$B$7)^-B29)
A31: French re-concession lump at 2035 | B31: =Assumptions!$C$24
A32: Terminal (residual) value at end-2035 | B32: =B26+B30+B31
A33: Implied multiple of FY2035 distributable cash | B33: =B32/L17
A34: PV of terminal | B34: =B32*L19
A35: Enterprise value (PV of all equity flows) | B35: =B22+B34
A36: Corporate cash 31-Dec-2025 | B36: =Assumptions!$B$5
A37: less OTPP put settlement | B37: =Assumptions!$B$6
A38: Greenway equity (locked up) | B38: =Assumptions!$C$25
A39: Warnow equity | B39: =Assumptions!$C$26
A40: Net cash / bridge | B40: =SUM(B36:B39)
A41: Equity value | B41: =B35+B40
A42: Diluted securities (m) | B42: =Assumptions!$B$4
...

Sheet DCF_Base
A1: DCF_Base -- A$m unless stated; column B = FY2025 actual, C..L = FY2026-FY2035
A3: Year | B3: 2025A | C3: 2026E | D3: 2027E | E3: 2028E | F3: 2029E | G3: 2030E | H3: 2031E | I3: 2032E | J3: 2033E | K3: 2034E | L3: 2035E
A4: Index | B4: 0 | C4: 1 | D4: 2 | E4: 3 | F4: 4 | G4: 5 | H4: 6 | I4: 7 | J4: 8 | K4: 9 | L4: 10
A5: APRR-group receipts (EUR m) | C5: =Assumptions!C32 | D5: =Assumptions!D32 | E5: =Assumptions!E32 | F5: =Assumptions!F32 | G5: =Assumptions!G32 | H5: =Assumptions!H32 | I5: =Assumptions!I32 | J5: =Assumptions!J32 | ... L5: =Assumptions!L32
A6: EUR/AUD | C6: =Assumptions!$D$14 | D6: =Assumptions!$D$14 | E6: =Assumptions!$D$14 | F6: =Assumptions!$D$14 | G6: =Assumptions!$D$14 | H6: =Assumptions!$D$14 | I6: =Assumptions!$D$14 | J6: =Assumptions!$D$14 | ... L6: =Assumptions!$D$14
A7: APRR receipts (A$m) | B7: 498.2 | C7: =C5*C6 | D7: =D5*D6 | E7: =E5*E6 | F7: =F5*F6 | G7: =G5*G6 | H7: =H5*H6 | I7: =I5*I6 | J7: =J5*J6 | ... L7: =L5*L6
A8: Skyway receipts (US$ m) | C8: =Assumptions!C37 | D8: =Assumptions!D37 | E8: =Assumptions!E37 | F8: =Assumptions!F37 | G8: =Assumptions!G37 | H8: =Assumptions!H37 | I8: =Assumptions!I37 | J8: =Assumptions!J37 | ... L8: =Assumptions!L37
A9: AUD/USD | C9: =Assumptions!$D$15 | D9: =Assumptions!$D$15 | E9: =Assumptions!$D$15 | F9: =Assumptions!$D$15 | G9: =Assumptions!$D$15 | H9: =Assumptions!$D$15 | I9: =Assumptions!$D$15 | J9: =Assumptions!$D$15 | ... L9: =Assumptions!$D$15
A10: Skyway receipts (A$m) | B10: 36.8 | C10: =C8/C9 | D10: =D8/D9 | E10: =E8/E9 | F10: =F8/F9 | G10: =G8/G9 | H10: =H8/H9 | I10: =I8/I9 | J10: =J8/J9 | ... L10: =L8/L9
A11: Total receipts | B11: =B7+B10 | C11: =C7+C10 | D11: =D7+D10 | E11: =E7+E10 | F11: =F7+F10 | G11: =G7+G10 | H11: =H7+H10 | I11: =I7+I10 | ... L11: =L7+L10
A12: Receipts growth | C12: =C11/B11-1 | D12: =D11/C11-1 | E12: =E11/D11-1 | F12: =F11/E11-1 | G12: =G11/F11-1 | H12: =H11/G11-1 | I12: =I11/H11-1 | J12: =J11/I11-1 | ... L12: =L11/K11-1
A13: Corporate cash costs incl. SBC (negative) | B13: -52.6 | C13: =-Assumptions!$D$16*(1+Assumptions!$D$17)^(C4-1) | D13: =-Assumptions!$D$16*(1+Assumptions!$D$17)^(D4-1) | E13: =-Assumptions!$D$16*(1+Assumptions!$D$17)^(E4-1) | F13: =-Assumptions!$D$16*(1+Assumptions!$D$17)^(F4-1) | G13: =-Assumptions!$D$16*(1+Assumptions!$D$17)^(G4-1) | H13: =-Assumptions!$D$16*(1+Assumptions!$D$17)^(H4-1) | I13: =-Assumptions!$D$16*(1+Assumptions!$D$17)^(I4-1) | J13: =-Assumptions!$D$16*(1+Assumptions!$D$17)^(J4-1) | ... L13: =-Assumptions!$D$16*(1+Assumptions!$D$17)^(L4-1)
A14: memo: SBC inside corporate costs | B14: 3.4 | C14: =Assumptions!$B$10*(1+Assumptions!$D$17)^(C4-1) | D14: =Assumptions!$B$10*(1+Assumptions!$D$17)^(D4-1) | E14: =Assumptions!$B$10*(1+Assumptions!$D$17)^(E4-1) | F14: =Assumptions!$B$10*(1+Assumptions!$D$17)^(F4-1) | G14: =Assumptions!$B$10*(1+Assumptions!$D$17)^(G4-1) | H14: =Assumptions!$B$10*(1+Assumptions!$D$17)^(H4-1) | I14: =Assumptions!$B$10*(1+Assumptions!$D$17)^(I4-1) | J14: =Assumptions!$B$10*(1+Assumptions!$D$17)^(J4-1) | ... L14: =Assumptions!$B$10*(1+Assumptions!$D$17)^(L4-1)
A15: Owner EBITDA (receipts less corporate costs) | B15: =B11+B13 | C15: =C11+C13 | D15: =D11+D13 | E15: =E11+E13 | F15: =F11+F13 | G15: =G11+G13 | H15: =H11+H13 | I15: =I11+I13 | ... L15: =L11+L13
A16: Corporate tax (negative) | B16: -8 | C16: =-Assumptions!$D$18*(1+Assumptions!$D$19)^(C4-1) | D16: =-Assumptions!$D$18*(1+Assumptions!$D$19)^(D4-1) | E16: =-Assumptions!$D$18*(1+Assumptions!$D$19)^(E4-1) | F16: =-Assumptions!$D$18*(1+Assumptions!$D$19)^(F4-1) | G16: =-Assumptions!$D$18*(1+Assumptions!$D$19)^(G4-1) | H16: =-Assumptions!$D$18*(1+Assumptions!$D$19)^(H4-1) | I16: =-Assumptions!$D$18*(1+Assumptions!$D$19)^(I4-1) | J16: =-Assumptions!$D$18*(1+Assumptions!$D$19)^(J4-1) | ... L16: =-Assumptions!$D$18*(1+Assumptions!$D$19)^(L4-1)
A17: Distributable cash = owner FCF | B17: =B15+B16 | C17: =C15+C16 | D17: =D15+D16 | E17: =E15+E16 | F17: =F15+F16 | G17: =G15+G16 | H17: =H15+H16 | I17: =I15+I16 | ... L17: =L15+L16
A18: per security (cents) | B18: =B17/Assumptions!$B$4*100 | C18: =C17/Assumptions!$B$4*100 | D18: =D17/Assumptions!$B$4*100 | E18: =E17/Assumptions!$B$4*100 | F18: =F17/Assumptions!$B$4*100 | G18: =G17/Assumptions!$B$4*100 | H18: =H17/Assumptions!$B$4*100 | I18: =I17/Assumptions!$B$4*100 | ... L18: =L17/Assumptions!$B$4*100
A19: Discount factor | C19: =1/(1+Assumptions!$B$7)^C4 | D19: =1/(1+Assumptions!$B$7)^D4 | E19: =1/(1+Assumptions!$B$7)^E4 | F19: =1/(1+Assumptions!$B$7)^F4 | G19: =1/(1+Assumptions!$B$7)^G4 | H19: =1/(1+Assumptions!$B$7)^H4 | I19: =1/(1+Assumptions!$B$7)^I4 | J19: =1/(1+Assumptions!$B$7)^J4 | ... L19: =1/(1+Assumptions!$B$7)^L4
A20: PV of distributable cash | C20: =C17*C19 | D20: =D17*D19 | E20: =E17*E19 | F20: =F17*F19 | G20: =G17*G19 | H20: =H17*H19 | I20: =I17*I19 | J20: =J17*J19 | ... L20: =L17*L19
A22: Sum of PV (FY2026-35) | B22: =SUM(C20:L20)
A23: Skyway receipts FY2035 (A$m) | B23: =L10
A24: Skyway tail growth | B24: =Assumptions!$D$20
A25: Skyway tail years | B25: =Assumptions!$D$21
A26: Skyway tail value at end-2035 | B26: =B23*(1+B24)/(Assumptions!$B$7-B24)*(1-((1+B24)/(1+Assumptions!$B$7))^B25)
A27: French tail EUR m/yr | B27: =Assumptions!$D$22
A28: French tail A$m/yr | B28: =B27*Assumptions!$D$14
A29: French tail years | B29: =Assumptions!$D$23
A30: French tail value at end-2035 | B30: =B28/Assumptions!$B$7*(1-(1+Assumptions!$B$7)^-B29)
A31: French re-concession lump at 2035 | B31: =Assumptions!$D$24
A32: Terminal (residual) value at end-2035 | B32: =B26+B30+B31
A33: Implied multiple of FY2035 distributable cash | B33: =B32/L17
A34: PV of terminal | B34: =B32*L19
A35: Enterprise value (PV of all equity flows) | B35: =B22+B34
A36: Corporate cash 31-Dec-2025 | B36: =Assumptions!$B$5
A37: less OTPP put settlement | B37: =Assumptions!$B$6
A38: Greenway equity (locked up) | B38: =Assumptions!$D$25
A39: Warnow equity | B39: =Assumptions!$D$26
A40: Net cash / bridge | B40: =SUM(B36:B39)
A41: Equity value | B41: =B35+B40
A42: Diluted securities (m) | B42: =Assumptions!$B$4
...

Sheet DCF_Bull
A1: DCF_Bull -- A$m unless stated; column B = FY2025 actual, C..L = FY2026-FY2035
A3: Year | B3: 2025A | C3: 2026E | D3: 2027E | E3: 2028E | F3: 2029E | G3: 2030E | H3: 2031E | I3: 2032E | J3: 2033E | K3: 2034E | L3: 2035E
A4: Index | B4: 0 | C4: 1 | D4: 2 | E4: 3 | F4: 4 | G4: 5 | H4: 6 | I4: 7 | J4: 8 | K4: 9 | L4: 10
A5: APRR-group receipts (EUR m) | C5: =Assumptions!C33 | D5: =Assumptions!D33 | E5: =Assumptions!E33 | F5: =Assumptions!F33 | G5: =Assumptions!G33 | H5: =Assumptions!H33 | I5: =Assumptions!I33 | J5: =Assumptions!J33 | ... L5: =Assumptions!L33
A6: EUR/AUD | C6: =Assumptions!$E$14 | D6: =Assumptions!$E$14 | E6: =Assumptions!$E$14 | F6: =Assumptions!$E$14 | G6: =Assumptions!$E$14 | H6: =Assumptions!$E$14 | I6: =Assumptions!$E$14 | J6: =Assumptions!$E$14 | ... L6: =Assumptions!$E$14
A7: APRR receipts (A$m) | B7: 498.2 | C7: =C5*C6 | D7: =D5*D6 | E7: =E5*E6 | F7: =F5*F6 | G7: =G5*G6 | H7: =H5*H6 | I7: =I5*I6 | J7: =J5*J6 | ... L7: =L5*L6
A8: Skyway receipts (US$ m) | C8: =Assumptions!C38 | D8: =Assumptions!D38 | E8: =Assumptions!E38 | F8: =Assumptions!F38 | G8: =Assumptions!G38 | H8: =Assumptions!H38 | I8: =Assumptions!I38 | J8: =Assumptions!J38 | ... L8: =Assumptions!L38
A9: AUD/USD | C9: =Assumptions!$E$15 | D9: =Assumptions!$E$15 | E9: =Assumptions!$E$15 | F9: =Assumptions!$E$15 | G9: =Assumptions!$E$15 | H9: =Assumptions!$E$15 | I9: =Assumptions!$E$15 | J9: =Assumptions!$E$15 | ... L9: =Assumptions!$E$15
A10: Skyway receipts (A$m) | B10: 36.8 | C10: =C8/C9 | D10: =D8/D9 | E10: =E8/E9 | F10: =F8/F9 | G10: =G8/G9 | H10: =H8/H9 | I10: =I8/I9 | J10: =J8/J9 | ... L10: =L8/L9
A11: Total receipts | B11: =B7+B10 | C11: =C7+C10 | D11: =D7+D10 | E11: =E7+E10 | F11: =F7+F10 | G11: =G7+G10 | H11: =H7+H10 | I11: =I7+I10 | ... L11: =L7+L10
A12: Receipts growth | C12: =C11/B11-1 | D12: =D11/C11-1 | E12: =E11/D11-1 | F12: =F11/E11-1 | G12: =G11/F11-1 | H12: =H11/G11-1 | I12: =I11/H11-1 | J12: =J11/I11-1 | ... L12: =L11/K11-1
A13: Corporate cash costs incl. SBC (negative) | B13: -52.6 | C13: =-Assumptions!$E$16*(1+Assumptions!$E$17)^(C4-1) | D13: =-Assumptions!$E$16*(1+Assumptions!$E$17)^(D4-1) | E13: =-Assumptions!$E$16*(1+Assumptions!$E$17)^(E4-1) | F13: =-Assumptions!$E$16*(1+Assumptions!$E$17)^(F4-1) | G13: =-Assumptions!$E$16*(1+Assumptions!$E$17)^(G4-1) | H13: =-Assumptions!$E$16*(1+Assumptions!$E$17)^(H4-1) | I13: =-Assumptions!$E$16*(1+Assumptions!$E$17)^(I4-1) | J13: =-Assumptions!$E$16*(1+Assumptions!$E$17)^(J4-1) | ... L13: =-Assumptions!$E$16*(1+Assumptions!$E$17)^(L4-1)
A14: memo: SBC inside corporate costs | B14: 3.4 | C14: =Assumptions!$B$10*(1+Assumptions!$E$17)^(C4-1) | D14: =Assumptions!$B$10*(1+Assumptions!$E$17)^(D4-1) | E14: =Assumptions!$B$10*(1+Assumptions!$E$17)^(E4-1) | F14: =Assumptions!$B$10*(1+Assumptions!$E$17)^(F4-1) | G14: =Assumptions!$B$10*(1+Assumptions!$E$17)^(G4-1) | H14: =Assumptions!$B$10*(1+Assumptions!$E$17)^(H4-1) | I14: =Assumptions!$B$10*(1+Assumptions!$E$17)^(I4-1) | J14: =Assumptions!$B$10*(1+Assumptions!$E$17)^(J4-1) | ... L14: =Assumptions!$B$10*(1+Assumptions!$E$17)^(L4-1)
A15: Owner EBITDA (receipts less corporate costs) | B15: =B11+B13 | C15: =C11+C13 | D15: =D11+D13 | E15: =E11+E13 | F15: =F11+F13 | G15: =G11+G13 | H15: =H11+H13 | I15: =I11+I13 | ... L15: =L11+L13
A16: Corporate tax (negative) | B16: -8 | C16: =-Assumptions!$E$18*(1+Assumptions!$E$19)^(C4-1) | D16: =-Assumptions!$E$18*(1+Assumptions!$E$19)^(D4-1) | E16: =-Assumptions!$E$18*(1+Assumptions!$E$19)^(E4-1) | F16: =-Assumptions!$E$18*(1+Assumptions!$E$19)^(F4-1) | G16: =-Assumptions!$E$18*(1+Assumptions!$E$19)^(G4-1) | H16: =-Assumptions!$E$18*(1+Assumptions!$E$19)^(H4-1) | I16: =-Assumptions!$E$18*(1+Assumptions!$E$19)^(I4-1) | J16: =-Assumptions!$E$18*(1+Assumptions!$E$19)^(J4-1) | ... L16: =-Assumptions!$E$18*(1+Assumptions!$E$19)^(L4-1)
A17: Distributable cash = owner FCF | B17: =B15+B16 | C17: =C15+C16 | D17: =D15+D16 | E17: =E15+E16 | F17: =F15+F16 | G17: =G15+G16 | H17: =H15+H16 | I17: =I15+I16 | ... L17: =L15+L16
A18: per security (cents) | B18: =B17/Assumptions!$B$4*100 | C18: =C17/Assumptions!$B$4*100 | D18: =D17/Assumptions!$B$4*100 | E18: =E17/Assumptions!$B$4*100 | F18: =F17/Assumptions!$B$4*100 | G18: =G17/Assumptions!$B$4*100 | H18: =H17/Assumptions!$B$4*100 | I18: =I17/Assumptions!$B$4*100 | ... L18: =L17/Assumptions!$B$4*100
A19: Discount factor | C19: =1/(1+Assumptions!$B$7)^C4 | D19: =1/(1+Assumptions!$B$7)^D4 | E19: =1/(1+Assumptions!$B$7)^E4 | F19: =1/(1+Assumptions!$B$7)^F4 | G19: =1/(1+Assumptions!$B$7)^G4 | H19: =1/(1+Assumptions!$B$7)^H4 | I19: =1/(1+Assumptions!$B$7)^I4 | J19: =1/(1+Assumptions!$B$7)^J4 | ... L19: =1/(1+Assumptions!$B$7)^L4
A20: PV of distributable cash | C20: =C17*C19 | D20: =D17*D19 | E20: =E17*E19 | F20: =F17*F19 | G20: =G17*G19 | H20: =H17*H19 | I20: =I17*I19 | J20: =J17*J19 | ... L20: =L17*L19
A22: Sum of PV (FY2026-35) | B22: =SUM(C20:L20)
A23: Skyway receipts FY2035 (A$m) | B23: =L10
A24: Skyway tail growth | B24: =Assumptions!$E$20
A25: Skyway tail years | B25: =Assumptions!$E$21
A26: Skyway tail value at end-2035 | B26: =B23*(1+B24)/(Assumptions!$B$7-B24)*(1-((1+B24)/(1+Assumptions!$B$7))^B25)
A27: French tail EUR m/yr | B27: =Assumptions!$E$22
A28: French tail A$m/yr | B28: =B27*Assumptions!$E$14
A29: French tail years | B29: =Assumptions!$E$23
A30: French tail value at end-2035 | B30: =B28/Assumptions!$B$7*(1-(1+Assumptions!$B$7)^-B29)
A31: French re-concession lump at 2035 | B31: =Assumptions!$E$24
A32: Terminal (residual) value at end-2035 | B32: =B26+B30+B31
A33: Implied multiple of FY2035 distributable cash | B33: =B32/L17
A34: PV of terminal | B34: =B32*L19
A35: Enterprise value (PV of all equity flows) | B35: =B22+B34
A36: Corporate cash 31-Dec-2025 | B36: =Assumptions!$B$5
A37: less OTPP put settlement | B37: =Assumptions!$B$6
A38: Greenway equity (locked up) | B38: =Assumptions!$E$25
A39: Warnow equity | B39: =Assumptions!$E$26
A40: Net cash / bridge | B40: =SUM(B36:B39)
A41: Equity value | B41: =B35+B40
A42: Diluted securities (m) | B42: =Assumptions!$B$4
...

Sheet FCF_Quality
A1: FY2025 bridge (A$m) | B1: Value | C1: Note
A2: Statutory operating cash flow | B2: 88.2 | C2: Greenway/Skyway/Warnow ops only
A3: less capex | B3: -0.6
A4: Equals reported FCF (statutory) | B4: =B2+B3 | C4: NOT cash generation for this holdco
A5: Distributions from MAF2 (APRR) | B5: 498.2 | C5: investing activities
A6: Distributions from CCPI (Skyway) | B6: 18.7 | C6: investing activities
A7: CCPI shareholder-loan interest | B7: 18.1 | C7: operating
A8: Equals receipts at ALX level | B8: =B5+B6+B7 | C8: model revenue base 535.0
A9: less centralised costs incl. SBC 3.4 and one-offs | B9: -52.6 | C9: Appendix 4E
A10: less corporate tax | B10: -8
A11: Equals owner FCF (last_fcf) | B11: =B8+B9+B10 | C11: 474.4
A12: memo: company operating free cash flow | B12: 505.9 | C12: includes other finance income 20.2 and Greenway/Warnow net ops; excluded from the model
A13: memo: distributions paid | B13: -580.4 | C13: 40cps -- above 90-110% coverage policy in 2025/26 (TST)
A14: memo: owner FCF per security (cents) | B14: =B11/Assumptions!B4*100

Sheet Valuation
A1: Valuation summary (A$ per security)
A2: Scenario | B2: Value/security | C2: Upside | D2: Weight | E2: Entry price @15% | F2: Street value/security
A3: Bear | B3: =DCF_Bear!B43 | C3: =DCF_Bear!B44 | D3: =Assumptions!C27 | E3: =DCF_Bear!B51 | F3: =(DCF_Bear!B41+SUMPRODUCT(DCF_Bear!C14:L14*DCF_Bear!C19:L19))/DCF_Bear!B42
A4: Base | B4: =DCF_Base!B43 | C4: =DCF_Base!B44 | D4: =Assumptions!D27 | E4: =DCF_Base!B51 | F4: =(DCF_Base!B41+SUMPRODUCT(DCF_Base!C14:L14*DCF_Base!C19:L19))/DCF_Base!B42
A5: Bull | B5: =DCF_Bull!B43 | C5: =DCF_Bull!B44 | D5: =Assumptions!E27 | E5: =DCF_Bull!B51 | F5: =(DCF_Bull!B41+SUMPRODUCT(DCF_Bull!C14:L14*DCF_Bull!C19:L19))/DCF_Bull!B42
A7: Probability-weighted value | B7: =SUMPRODUCT(B3:B5,D3:D5)
A8: Margin of safety vs price | B8: =1-Assumptions!B3/B7
A9: Weighted entry price @15% | B9: =SUMPRODUCT(E3:E5,D3:D5)
A10: Street weighted value | B10: =SUMPRODUCT(F3:F5,D3:D5)
A11: Band position | B11: n/a -- SBC 0.6% of receipts, house and street coincide
A13: Required-return table (base): residual rebuilt at each rate
A14: Rate | B14: Value/security
A15: 0.09 | B15: =(SUMPRODUCT(DCF_Base!$C$17:$L$17/(1+$A15)^DCF_Base!$C$4:$L$4)+(DCF_Base!$B$23*(1+DCF_Base!$B$24)/($A15-DCF_Base!$B$24)*(1-((1+DCF_Base!$B$24)/(1+$A15))^DCF_Base!$B$25)+DCF_Base!$B$28/$A15*(1-(1+$A15)^-DCF_Base!$B$29)+DCF_Base!$B$31)/(1+$A15)^10+DCF_Base!$B$40)/DCF_Base!$B$42
A16: 0.1 | B16: =(SUMPRODUCT(DCF_Base!$C$17:$L$17/(1+$A16)^DCF_Base!$C$4:$L$4)+(DCF_Base!$B$23*(1+DCF_Base!$B$24)/($A16-DCF_Base!$B$24)*(1-((1+DCF_Base!$B$24)/(1+$A16))^DCF_Base!$B$25)+DCF_Base!$B$28/$A16*(1-(1+$A16)^-DCF_Base!$B$29)+DCF_Base!$B$31)/(1+$A16)^10+DCF_Base!$B$40)/DCF_Base!$B$42
A17: 0.11 | B17: =(SUMPRODUCT(DCF_Base!$C$17:$L$17/(1+$A17)^DCF_Base!$C$4:$L$4)+(DCF_Base!$B$23*(1+DCF_Base!$B$24)/($A17-DCF_Base!$B$24)*(1-((1+DCF_Base!$B$24)/(1+$A17))^DCF_Base!$B$25)+DCF_Base!$B$28/$A17*(1-(1+$A17)^-DCF_Base!$B$29)+DCF_Base!$B$31)/(1+$A17)^10+DCF_Base!$B$40)/DCF_Base!$B$42
A18: 0.12 | B18: =(SUMPRODUCT(DCF_Base!$C$17:$L$17/(1+$A18)^DCF_Base!$C$4:$L$4)+(DCF_Base!$B$23*(1+DCF_Base!$B$24)/($A18-DCF_Base!$B$24)*(1-((1+DCF_Base!$B$24)/(1+$A18))^DCF_Base!$B$25)+DCF_Base!$B$28/$A18*(1-(1+$A18)^-DCF_Base!$B$29)+DCF_Base!$B$31)/(1+$A18)^10+DCF_Base!$B$40)/DCF_Base!$B$42
A19: 0.15 | B19: =(SUMPRODUCT(DCF_Base!$C$17:$L$17/(1+$A19)^DCF_Base!$C$4:$L$4)+(DCF_Base!$B$23*(1+DCF_Base!$B$24)/($A19-DCF_Base!$B$24)*(1-((1+DCF_Base!$B$24)/(1+$A19))^DCF_Base!$B$25)+DCF_Base!$B$28/$A19*(1-(1+$A19)^-DCF_Base!$B$29)+DCF_Base!$B$31)/(1+$A19)^10+DCF_Base!$B$40)/DCF_Base!$B$42 | C19: Must equal DCF_Base!B51 (entry price)
A20: =Assumptions!B7 | B20: =(SUMPRODUCT(DCF_Base!$C$17:$L$17/(1+$A20)^DCF_Base!$C$4:$L$4)+(DCF_Base!$B$23*(1+DCF_Base!$B$24)/($A20-DCF_Base!$B$24)*(1-((1+DCF_Base!$B$24)/(1+$A20))^DCF_Base!$B$25)+DCF_Base!$B$28/$A20*(1-(1+$A20)^-DCF_Base!$B$29)+DCF_Base!$B$31)/(1+$A20)^10+DCF_Base!$B$40)/DCF_Base!$B$42 | C20: Row at model cost of equity; must equal DCF_Base!B43
A23: Sensitivity (base): cost of equity (rows) x Skyway tail growth (cols)
B24: 0.025 | C24: 0.03 | D24: 0.035 | E24: 0.04 | F24: 0.045
A25: 0.065 | B25: =IF($A25>B$24,(SUMPRODUCT(DCF_Base!$C$17:$L$17/(1+$A25)^DCF_Base!$C$4:$L$4)+(DCF_Base!$B$23*(1+B$24)/($A25-B$24)*(1-((1+B$24)/(1+$A25))^DCF_Base!$B$25)+DCF_Base!$B$28/$A25*(1-(1+$A25)^-DCF_Base!$B$29)+DCF_Base!$B$31)/(1+$A25)^10+DCF_Base!$B$40)/DCF_Base!$B$42,"n/a") | C25: =IF($A25>C$24,(SUMPRODUCT(DCF_Base!$C$17:$L$17/(1+$A25)^DCF_Base!$C$4:$L$4)+(DCF_Base!$B$23*(1+C$24)/($A25-C$24)*(1-((1+C$24)/(1+$A25))^DCF_Base!$B$25)+DCF_Base!$B$28/$A25*(1-(1+$A25)^-DCF_Base!$B$29)+DCF_Base!$B$31)/(1+$A25)^10+DCF_Base!$B$40)/DCF_Base!$B$42,"n/a") | D25: =IF($A25>D$24,(SUMPRODUCT(DCF_Base!$C$17:$L$17/(1+$A25)^DCF_Base!$C$4:$L$4)+(DCF_Base!$B$23*(1+D$24)/($A25-D$24)*(1-((1+D$24)/(1+$A25))^DCF_Base!$B$25)+DCF_Base!$B$28/$A25*(1-(1+$A25)^-DCF_Base!$B$29)+DCF_Base!$B$31)/(1+$A25)^10+DCF_Base!$B$40)/DCF_Base!$B$42,"n/a") | E25: =IF($A25>E$24,(SUMPRODUCT(DCF_Base!$C$17:$L$17/(1+$A25)^DCF_Base!$C$4:$L$4)+(DCF_Base!$B$23*(1+E$24)/($A25-E$24)*(1-((1+E$24)/(1+$A25))^DCF_Base!$B$25)+DCF_Base!$B$28/$A25*(1-(1+$A25)^-DCF_Base!$B$29)+DCF_Base!$B$31)/(1+$A25)^10+DCF_Base!$B$40)/DCF_Base!$B$42,"n/a") | F25: =IF($A25>F$24,(SUMPRODUCT(DCF_Base!$C$17:$L$17/(1+$A25)^DCF_Base!$C$4:$L$4)+(DCF_Base!$B$23*(1+F$24)/($A25-F$24)*(1-((1+F$24)/(1+$A25))^DCF_Base!$B$25)+DCF_Base!$B$28/$A25*(1-(1+$A25)^-DCF_Base!$B$29)+DCF_Base!$B$31)/(1+$A25)^10+DCF_Base!$B$40)/DCF_Base!$B$42,"n/a")
A26: 0.075 | B26: =IF($A26>B$24,(SUMPRODUCT(DCF_Base!$C$17:$L$17/(1+$A26)^DCF_Base!$C$4:$L$4)+(DCF_Base!$B$23*(1+B$24)/($A26-B$24)*(1-((1+B$24)/(1+$A26))^DCF_Base!$B$25)+DCF_Base!$B$28/$A26*(1-(1+$A26)^-DCF_Base!$B$29)+DCF_Base!$B$31)/(1+$A26)^10+DCF_Base!$B$40)/DCF_Base!$B$42,"n/a") | C26: =IF($A26>C$24,(SUMPRODUCT(DCF_Base!$C$17:$L$17/(1+$A26)^DCF_Base!$C$4:$L$4)+(DCF_Base!$B$23*(1+C$24)/($A26-C$24)*(1-((1+C$24)/(1+$A26))^DCF_Base!$B$25)+DCF_Base!$B$28/$A26*(1-(1+$A26)^-DCF_Base!$B$29)+DCF_Base!$B$31)/(1+$A26)^10+DCF_Base!$B$40)/DCF_Base!$B$42,"n/a") | D26: =IF($A26>D$24,(SUMPRODUCT(DCF_Base!$C$17:$L$17/(1+$A26)^DCF_Base!$C$4:$L$4)+(DCF_Base!$B$23*(1+D$24)/($A26-D$24)*(1-((1+D$24)/(1+$A26))^DCF_Base!$B$25)+DCF_Base!$B$28/$A26*(1-(1+$A26)^-DCF_Base!$B$29)+DCF_Base!$B$31)/(1+$A26)^10+DCF_Base!$B$40)/DCF_Base!$B$42,"n/a") | E26: =IF($A26>E$24,(SUMPRODUCT(DCF_Base!$C$17:$L$17/(1+$A26)^DCF_Base!$C$4:$L$4)+(DCF_Base!$B$23*(1+E$24)/($A26-E$24)*(1-((1+E$24)/(1+$A26))^DCF_Base!$B$25)+DCF_Base!$B$28/$A26*(1-(1+$A26)^-DCF_Base!$B$29)+DCF_Base!$B$31)/(1+$A26)^10+DCF_Base!$B$40)/DCF_Base!$B$42,"n/a") | F26: =IF($A26>F$24,(SUMPRODUCT(DCF_Base!$C$17:$L$17/(1+$A26)^DCF_Base!$C$4:$L$4)+(DCF_Base!$B$23*(1+F$24)/($A26-F$24)*(1-((1+F$24)/(1+$A26))^DCF_Base!$B$25)+DCF_Base!$B$28/$A26*(1-(1+$A26)^-DCF_Base!$B$29)+DCF_Base!$B$31)/(1+$A26)^10+DCF_Base!$B$40)/DCF_Base!$B$42,"n/a")
A27: 0.085 | B27: =IF($A27>B$24,(SUMPRODUCT(DCF_Base!$C$17:$L$17/(1+$A27)^DCF_Base!$C$4:$L$4)+(DCF_Base!$B$23*(1+B$24)/($A27-B$24)*(1-((1+B$24)/(1+$A27))^DCF_Base!$B$25)+DCF_Base!$B$28/$A27*(1-(1+$A27)^-DCF_Base!$B$29)+DCF_Base!$B$31)/(1+$A27)^10+DCF_Base!$B$40)/DCF_Base!$B$42,"n/a") | C27: =IF($A27>C$24,(SUMPRODUCT(DCF_Base!$C$17:$L$17/(1+$A27)^DCF_Base!$C$4:$L$4)+(DCF_Base!$B$23*(1+C$24)/($A27-C$24)*(1-((1+C$24)/(1+$A27))^DCF_Base!$B$25)+DCF_Base!$B$28/$A27*(1-(1+$A27)^-DCF_Base!$B$29)+DCF_Base!$B$31)/(1+$A27)^10+DCF_Base!$B$40)/DCF_Base!$B$42,"n/a") | D27: =IF($A27>D$24,(SUMPRODUCT(DCF_Base!$C$17:$L$17/(1+$A27)^DCF_Base!$C$4:$L$4)+(DCF_Base!$B$23*(1+D$24)/($A27-D$24)*(1-((1+D$24)/(1+$A27))^DCF_Base!$B$25)+DCF_Base!$B$28/$A27*(1-(1+$A27)^-DCF_Base!$B$29)+DCF_Base!$B$31)/(1+$A27)^10+DCF_Base!$B$40)/DCF_Base!$B$42,"n/a") | E27: =IF($A27>E$24,(SUMPRODUCT(DCF_Base!$C$17:$L$17/(1+$A27)^DCF_Base!$C$4:$L$4)+(DCF_Base!$B$23*(1+E$24)/($A27-E$24)*(1-((1+E$24)/(1+$A27))^DCF_Base!$B$25)+DCF_Base!$B$28/$A27*(1-(1+$A27)^-DCF_Base!$B$29)+DCF_Base!$B$31)/(1+$A27)^10+DCF_Base!$B$40)/DCF_Base!$B$42,"n/a") | F27: =IF($A27>F$24,(SUMPRODUCT(DCF_Base!$C$17:$L$17/(1+$A27)^DCF_Base!$C$4:$L$4)+(DCF_Base!$B$23*(1+F$24)/($A27-F$24)*(1-((1+F$24)/(1+$A27))^DCF_Base!$B$25)+DCF_Base!$B$28/$A27*(1-(1+$A27)^-DCF_Base!$B$29)+DCF_Base!$B$31)/(1+$A27)^10+DCF_Base!$B$40)/DCF_Base!$B$42,"n/a")
A28: 0.095 | B28: =IF($A28>B$24,(SUMPRODUCT(DCF_Base!$C$17:$L$17/(1+$A28)^DCF_Base!$C$4:$L$4)+(DCF_Base!$B$23*(1+B$24)/($A28-B$24)*(1-((1+B$24)/(1+$A28))^DCF_Base!$B$25)+DCF_Base!$B$28/$A28*(1-(1+$A28)^-DCF_Base!$B$29)+DCF_Base!$B$31)/(1+$A28)^10+DCF_Base!$B$40)/DCF_Base!$B$42,"n/a") | C28: =IF($A28>C$24,(SUMPRODUCT(DCF_Base!$C$17:$L$17/(1+$A28)^DCF_Base!$C$4:$L$4)+(DCF_Base!$B$23*(1+C$24)/($A28-C$24)*(1-((1+C$24)/(1+$A28))^DCF_Base!$B$25)+DCF_Base!$B$28/$A28*(1-(1+$A28)^-DCF_Base!$B$29)+DCF_Base!$B$31)/(1+$A28)^10+DCF_Base!$B$40)/DCF_Base!$B$42,"n/a") | D28: =IF($A28>D$24,(SUMPRODUCT(DCF_Base!$C$17:$L$17/(1+$A28)^DCF_Base!$C$4:$L$4)+(DCF_Base!$B$23*(1+D$24)/($A28-D$24)*(1-((1+D$24)/(1+$A28))^DCF_Base!$B$25)+DCF_Base!$B$28/$A28*(1-(1+$A28)^-DCF_Base!$B$29)+DCF_Base!$B$31)/(1+$A28)^10+DCF_Base!$B$40)/DCF_Base!$B$42,"n/a") | E28: =IF($A28>E$24,(SUMPRODUCT(DCF_Base!$C$17:$L$17/(1+$A28)^DCF_Base!$C$4:$L$4)+(DCF_Base!$B$23*(1+E$24)/($A28-E$24)*(1-((1+E$24)/(1+$A28))^DCF_Base!$B$25)+DCF_Base!$B$28/$A28*(1-(1+$A28)^-DCF_Base!$B$29)+DCF_Base!$B$31)/(1+$A28)^10+DCF_Base!$B$40)/DCF_Base!$B$42,"n/a") | F28: =IF($A28>F$24,(SUMPRODUCT(DCF_Base!$C$17:$L$17/(1+$A28)^DCF_Base!$C$4:$L$4)+(DCF_Base!$B$23*(1+F$24)/($A28-F$24)*(1-((1+F$24)/(1+$A28))^DCF_Base!$B$25)+DCF_Base!$B$28/$A28*(1-(1+$A28)^-DCF_Base!$B$29)+DCF_Base!$B$31)/(1+$A28)^10+DCF_Base!$B$40)/DCF_Base!$B$42,"n/a")
A29: 0.105 | B29: =IF($A29>B$24,(SUMPRODUCT(DCF_Base!$C$17:$L$17/(1+$A29)^DCF_Base!$C$4:$L$4)+(DCF_Base!$B$23*(1+B$24)/($A29-B$24)*(1-((1+B$24)/(1+$A29))^DCF_Base!$B$25)+DCF_Base!$B$28/$A29*(1-(1+$A29)^-DCF_Base!$B$29)+DCF_Base!$B$31)/(1+$A29)^10+DCF_Base!$B$40)/DCF_Base!$B$42,"n/a") | C29: =IF($A29>C$24,(SUMPRODUCT(DCF_Base!$C$17:$L$17/(1+$A29)^DCF_Base!$C$4:$L$4)+(DCF_Base!$B$23*(1+C$24)/($A29-C$24)*(1-((1+C$24)/(1+$A29))^DCF_Base!$B$25)+DCF_Base!$B$28/$A29*(1-(1+$A29)^-DCF_Base!$B$29)+DCF_Base!$B$31)/(1+$A29)^10+DCF_Base!$B$40)/DCF_Base!$B$42,"n/a") | D29: =IF($A29>D$24,(SUMPRODUCT(DCF_Base!$C$17:$L$17/(1+$A29)^DCF_Base!$C$4:$L$4)+(DCF_Base!$B$23*(1+D$24)/($A29-D$24)*(1-((1+D$24)/(1+$A29))^DCF_Base!$B$25)+DCF_Base!$B$28/$A29*(1-(1+$A29)^-DCF_Base!$B$29)+DCF_Base!$B$31)/(1+$A29)^10+DCF_Base!$B$40)/DCF_Base!$B$42,"n/a") | E29: =IF($A29>E$24,(SUMPRODUCT(DCF_Base!$C$17:$L$17/(1+$A29)^DCF_Base!$C$4:$L$4)+(DCF_Base!$B$23*(1+E$24)/($A29-E$24)*(1-((1+E$24)/(1+$A29))^DCF_Base!$B$25)+DCF_Base!$B$28/$A29*(1-(1+$A29)^-DCF_Base!$B$29)+DCF_Base!$B$31)/(1+$A29)^10+DCF_Base!$B$40)/DCF_Base!$B$42,"n/a") | F29: =IF($A29>F$24,(SUMPRODUCT(DCF_Base!$C$17:$L$17/(1+$A29)^DCF_Base!$C$4:$L$4)+(DCF_Base!$B$23*(1+F$24)/($A29-F$24)*(1-((1+F$24)/(1+$A29))^DCF_Base!$B$25)+DCF_Base!$B$28/$A29*(1-(1+$A29)^-DCF_Base!$B$29)+DCF_Base!$B$31)/(1+$A29)^10+DCF_Base!$B$40)/DCF_Base!$B$42,"n/a")
