Workbook

Sheet DCF Model
A1: AIA.NZ DCF Valuation Model (Base Case, 10-Year Component Build)
A2: Gray cells are INPUTS - adjust to see valuation change. Owner FCF is built from EBITDAFI margin -> D&A -> tax -> capex -> working capital each year (NOT a flat margin).
A4: KEY INPUTS
A5: Current Stock Price (NZ$) | B5: 8.76
A6: Shares Outstanding, current (M) | B6: 1705.7
A7: Cash & Equivalents (H1-2026, NZ$M) | B7: 360.6
A8: Total Debt (H1-2026, NZ$M) | B8: 2652.1
A9: Net Debt (NZ$M) | B9: =B8-B7 -> 0
A10: Annual Share Growth (uncovered dilution, SBC net of buybacks) | B10: 2.7e-05
A12: WACC (base) | B12: 0.075
A13: Terminal Growth Rate (base) | B13: 0.0225
A14: Terminal Cap Multiple (x FCF, ceiling on Gordon TV) | B14: 20
A15: FY2025 Revenue actual (NZ$M) — growth anchor | B15: 1004.7
A17: BASE CASE ASSUMPTIONS BY YEAR
B18: FY2026 | C18: FY2027 | D18: FY2028 | E18: FY2029 | F18: FY2030 | G18: FY2031 | H18: FY2032 | I18: FY2033 | J18: FY2034 | K18: FY2035
A19: Revenue growth % | B19: 0.05 | C19: 0.06 | D19: 0.07 | E19: 0.075 | F19: 0.065 | G19: 0.055 | H19: 0.05 | I19: 0.045 | J19: 0.04 | K19: 0.04
A20: EBITDAFI margin % | B20: 0.705 | C20: 0.71 | D20: 0.715 | E20: 0.72 | F20: 0.723 | G20: 0.725 | H20: 0.727 | I20: 0.728 | J20: 0.729 | K20: 0.73
A21: SBC % of revenue | B21: 0.0004 | C21: 0.0004 | D21: 0.0004 | E21: 0.0004 | F21: 0.0004 | G21: 0.0004 | H21: 0.0004 | I21: 0.0004 | J21: 0.0004 | K21: 0.0004
A22: D&A % of revenue | B22: 0.21 | C22: 0.22 | D22: 0.225 | E22: 0.225 | F22: 0.22 | G22: 0.21 | H22: 0.195 | I22: 0.18 | J22: 0.165 | K22: 0.155
A23: Capex (NZ$M, absolute — mgmt guided) | B23: 1100 | C23: 1300 | D23: 1400 | E23: 1300 | F23: 1000 | G23: 700 | H23: 450 | I23: 350 | J23: 320 | K23: 320
A24: Cash tax rate % | B24: 0.27 | C24: 0.27 | D24: 0.27 | E24: 0.27 | F24: 0.27 | G24: 0.27 | H24: 0.27 | I24: 0.27 | J24: 0.27 | K24: 0.27
A25: Working capital capture % of revenue growth (constant) | B25: 0.05
A27: PROJECTIONS (BASE CASE)
B28: FY2026 | C28: FY2027 | D28: FY2028 | E28: FY2029 | F28: FY2030 | G28: FY2031 | H28: FY2032 | I28: FY2033 | J28: FY2034 | K28: FY2035
A29: Revenue (NZ$M) | B29: =$B$15*(1+B19) -> 0 | C29: =B29*(1+C19) -> 0 | D29: =C29*(1+D19) -> 0 | E29: =D29*(1+E19) -> 0 | F29: =E29*(1+F19) -> 0 | G29: =F29*(1+G19) -> 0 | H29: =G29*(1+H19) -> 0 | I29: =H29*(1+I19) -> 0 | J29: =I29*(1+J19) -> 0 | K29: =J29*(1+K19) -> 0
A30: Adj. EBITDAFI (NZ$M) | B30: =B29*B20 -> 0 | C30: =C29*C20 -> 0 | D30: =D29*D20 -> 0 | E30: =E29*E20 -> 0 | F30: =F29*F20 -> 0 | G30: =G29*G20 -> 0 | H30: =H29*H20 -> 0 | I30: =I29*I20 -> 0 | ... K30: =K29*K20 -> 0
A31: Less: SBC (NZ$M) | B31: =B29*B21 -> 0 | C31: =C29*C21 -> 0 | D31: =D29*D21 -> 0 | E31: =E29*E21 -> 0 | F31: =F29*F21 -> 0 | G31: =G29*G21 -> 0 | H31: =H29*H21 -> 0 | I31: =I29*I21 -> 0 | ... K31: =K29*K21 -> 0
A32: Less: D&A (NZ$M) | B32: =B29*B22 -> 0 | C32: =C29*C22 -> 0 | D32: =D29*D22 -> 0 | E32: =E29*E22 -> 0 | F32: =F29*F22 -> 0 | G32: =G29*G22 -> 0 | H32: =H29*H22 -> 0 | I32: =I29*I22 -> 0 | ... K32: =K29*K22 -> 0
A33: EBIT (NZ$M) | B33: =B30-B31-B32 -> 0 | C33: =C30-C31-C32 -> 0 | D33: =D30-D31-D32 -> 0 | E33: =E30-E31-E32 -> 0 | F33: =F30-F31-F32 -> 0 | G33: =G30-G31-G32 -> 0 | H33: =H30-H31-H32 -> 0 | I33: =I30-I31-I32 -> 0 | ... K33: =K30-K31-K32 -> 0
A34: NOPAT = EBIT x (1-tax) (NZ$M) | B34: =B33*(1-B24) -> 0 | C34: =C33*(1-C24) -> 0 | D34: =D33*(1-D24) -> 0 | E34: =E33*(1-E24) -> 0 | F34: =F33*(1-F24) -> 0 | G34: =G33*(1-G24) -> 0 | H34: =H33*(1-H24) -> 0 | I34: =I33*(1-I24) -> 0 | ... K34: =K33*(1-K24) -> 0
A35: Add back: D&A (NZ$M) | B35: =B32 -> 0 | C35: =C32 -> 0 | D35: =D32 -> 0 | E35: =E32 -> 0 | F35: =F32 -> 0 | G35: =G32 -> 0 | H35: =H32 -> 0 | I35: =I32 -> 0 | ... K35: =K32 -> 0
A36: Less: Capex (NZ$M, mgmt guided) | B36: =B23 -> 0 | C36: =C23 -> 0 | D36: =D23 -> 0 | E36: =E23 -> 0 | F36: =F23 -> 0 | G36: =G23 -> 0 | H36: =H23 -> 0 | I36: =I23 -> 0 | ... K36: =K23 -> 0
A37: Working capital (capture x delta revenue) (NZ$M) | B37: =$B$25*(B29-$B$15) -> 0 | C37: =$B$25*(C29-B29) -> 0 | D37: =$B$25*(D29-C29) -> 0 | E37: =$B$25*(E29-D29) -> 0 | F37: =$B$25*(F29-E29) -> 0 | G37: =$B$25*(G29-F29) -> 0 | H37: =$B$25*(H29-G29) -> 0 | I37: =$B$25*(I29-H29) -> 0 | J37: =$B$25*(J29-I29) -> 0 | K37: =$B$25*(K29-J29) -> 0
A38: Owner FCF (NZ$M) | B38: =B34+B35-B36+B37 -> 0 | C38: =C34+C35-C36+C37 -> 0 | D38: =D34+D35-D36+D37 -> 0 | E38: =E34+E35-E36+E37 -> 0 | F38: =F34+F35-F36+F37 -> 0 | G38: =G34+G35-G36+G37 -> 0 | H38: =H34+H35-H36+H37 -> 0 | I38: =I34+I35-I36+I37 -> 0 | ... K38: =K34+K35-K36+K37 -> 0
A39: Owner FCF margin % (memo) | B39: =B38/B29 -> 0 | C39: =C38/C29 -> 0 | D39: =D38/D29 -> 0 | E39: =E38/E29 -> 0 | F39: =F38/F29 -> 0 | G39: =G38/G29 -> 0 | H39: =H38/H29 -> 0 | I39: =I38/I29 -> 0 | ... K39: =K38/K29 -> 0
A40: Discount Factor @ WACC | B40: =1/(1+$B$12)^1 -> 0 | C40: =1/(1+$B$12)^2 -> 0 | D40: =1/(1+$B$12)^3 -> 0 | E40: =1/(1+$B$12)^4 -> 0 | F40: =1/(1+$B$12)^5 -> 0 | G40: =1/(1+$B$12)^6 -> 0 | H40: =1/(1+$B$12)^7 -> 0 | I40: =1/(1+$B$12)^8 -> 0 | J40: =1/(1+$B$12)^9 -> 0 | K40: =1/(1+$B$12)^10 -> 0
A41: PV of Owner FCF (NZ$M) | B41: =B38*B40 -> 0 | C41: =C38*C40 -> 0 | D41: =D38*D40 -> 0 | E41: =E38*E40 -> 0 | F41: =F38*F40 -> 0 | G41: =G38*G40 -> 0 | H41: =H38*H40 -> 0 | I41: =I38*I40 -> 0 | ... K41: =K38*K40 -> 0
A42: Projected Shares Outstanding (M) | B42: =$B$6*(1+$B$10) -> 0 | C42: =B42*(1+$B$10) -> 0 | D42: =C42*(1+$B$10) -> 0 | E42: =D42*(1+$B$10) -> 0 | F42: =E42*(1+$B$10) -> 0 | G42: =F42*(1+$B$10) -> 0 | H42: =G42*(1+$B$10) -> 0 | I42: =H42*(1+$B$10) -> 0 | J42: =I42*(1+$B$10) -> 0 | K42: =J42*(1+$B$10) -> 0
A44: VALUATION
A45: Sum of PV of FCF (NZ$M) | B45: =SUM(B41:K41) -> 0
...

Sheet Sensitivity
A1: Sensitivity Analysis - Base Case Intrinsic Value
A2: Rows = WACC, Columns = Terminal Growth. Uses the DCF Model sheet base-case FCF path.
A4: WACC \ Term G | B4: 0.0125 | C4: 0.0175 | D4: 0.0225 | E4: 0.0275 | F4: 0.0325
A5: 0.055 | B5: =(NPV(0.055,'DCF Model'!B38:K38)+MIN('DCF Model'!K38*(1+0.0125)/(0.055-0.0125),'DCF Model'!$B$14*'DCF Model'!K38)/(1+0.055)^10-'DCF Model'!$B$9)/'DCF Model'!K42 -> 0 | C5: =(NPV(0.055,'DCF Model'!B38:K38)+MIN('DCF Model'!K38*(1+0.0175)/(0.055-0.0175),'DCF Model'!$B$14*'DCF Model'!K38)/(1+0.055)^10-'DCF Model'!$B$9)/'DCF Model'!K42 -> 0 | D5: =(NPV(0.055,'DCF Model'!B38:K38)+MIN('DCF Model'!K38*(1+0.0225)/(0.055-0.0225),'DCF Model'!$B$14*'DCF Model'!K38)/(1+0.055)^10-'DCF Model'!$B$9)/'DCF Model'!K42 -> 0 | E5: =(NPV(0.055,'DCF Model'!B38:K38)+MIN('DCF Model'!K38*(1+0.0275)/(0.055-0.0275),'DCF Model'!$B$14*'DCF Model'!K38)/(1+0.055)^10-'DCF Model'!$B$9)/'DCF Model'!K42 -> 0 | F5: =(NPV(0.055,'DCF Model'!B38:K38)+MIN('DCF Model'!K38*(1+0.0325)/(0.055-0.0325),'DCF Model'!$B$14*'DCF Model'!K38)/(1+0.055)^10-'DCF Model'!$B$9)/'DCF Model'!K42 -> 0
A6: 0.065 | B6: =(NPV(0.065,'DCF Model'!B38:K38)+MIN('DCF Model'!K38*(1+0.0125)/(0.065-0.0125),'DCF Model'!$B$14*'DCF Model'!K38)/(1+0.065)^10-'DCF Model'!$B$9)/'DCF Model'!K42 -> 0 | C6: =(NPV(0.065,'DCF Model'!B38:K38)+MIN('DCF Model'!K38*(1+0.0175)/(0.065-0.0175),'DCF Model'!$B$14*'DCF Model'!K38)/(1+0.065)^10-'DCF Model'!$B$9)/'DCF Model'!K42 -> 0 | D6: =(NPV(0.065,'DCF Model'!B38:K38)+MIN('DCF Model'!K38*(1+0.0225)/(0.065-0.0225),'DCF Model'!$B$14*'DCF Model'!K38)/(1+0.065)^10-'DCF Model'!$B$9)/'DCF Model'!K42 -> 0 | E6: =(NPV(0.065,'DCF Model'!B38:K38)+MIN('DCF Model'!K38*(1+0.0275)/(0.065-0.0275),'DCF Model'!$B$14*'DCF Model'!K38)/(1+0.065)^10-'DCF Model'!$B$9)/'DCF Model'!K42 -> 0 | F6: =(NPV(0.065,'DCF Model'!B38:K38)+MIN('DCF Model'!K38*(1+0.0325)/(0.065-0.0325),'DCF Model'!$B$14*'DCF Model'!K38)/(1+0.065)^10-'DCF Model'!$B$9)/'DCF Model'!K42 -> 0
A7: 0.075 | B7: =(NPV(0.075,'DCF Model'!B38:K38)+MIN('DCF Model'!K38*(1+0.0125)/(0.075-0.0125),'DCF Model'!$B$14*'DCF Model'!K38)/(1+0.075)^10-'DCF Model'!$B$9)/'DCF Model'!K42 -> 0 | C7: =(NPV(0.075,'DCF Model'!B38:K38)+MIN('DCF Model'!K38*(1+0.0175)/(0.075-0.0175),'DCF Model'!$B$14*'DCF Model'!K38)/(1+0.075)^10-'DCF Model'!$B$9)/'DCF Model'!K42 -> 0 | D7: =(NPV(0.075,'DCF Model'!B38:K38)+MIN('DCF Model'!K38*(1+0.0225)/(0.075-0.0225),'DCF Model'!$B$14*'DCF Model'!K38)/(1+0.075)^10-'DCF Model'!$B$9)/'DCF Model'!K42 -> 0 | E7: =(NPV(0.075,'DCF Model'!B38:K38)+MIN('DCF Model'!K38*(1+0.0275)/(0.075-0.0275),'DCF Model'!$B$14*'DCF Model'!K38)/(1+0.075)^10-'DCF Model'!$B$9)/'DCF Model'!K42 -> 0 | F7: =(NPV(0.075,'DCF Model'!B38:K38)+MIN('DCF Model'!K38*(1+0.0325)/(0.075-0.0325),'DCF Model'!$B$14*'DCF Model'!K38)/(1+0.075)^10-'DCF Model'!$B$9)/'DCF Model'!K42 -> 0
A8: 0.085 | B8: =(NPV(0.085,'DCF Model'!B38:K38)+MIN('DCF Model'!K38*(1+0.0125)/(0.085-0.0125),'DCF Model'!$B$14*'DCF Model'!K38)/(1+0.085)^10-'DCF Model'!$B$9)/'DCF Model'!K42 -> 0 | C8: =(NPV(0.085,'DCF Model'!B38:K38)+MIN('DCF Model'!K38*(1+0.0175)/(0.085-0.0175),'DCF Model'!$B$14*'DCF Model'!K38)/(1+0.085)^10-'DCF Model'!$B$9)/'DCF Model'!K42 -> 0 | D8: =(NPV(0.085,'DCF Model'!B38:K38)+MIN('DCF Model'!K38*(1+0.0225)/(0.085-0.0225),'DCF Model'!$B$14*'DCF Model'!K38)/(1+0.085)^10-'DCF Model'!$B$9)/'DCF Model'!K42 -> 0 | E8: =(NPV(0.085,'DCF Model'!B38:K38)+MIN('DCF Model'!K38*(1+0.0275)/(0.085-0.0275),'DCF Model'!$B$14*'DCF Model'!K38)/(1+0.085)^10-'DCF Model'!$B$9)/'DCF Model'!K42 -> 0 | F8: =(NPV(0.085,'DCF Model'!B38:K38)+MIN('DCF Model'!K38*(1+0.0325)/(0.085-0.0325),'DCF Model'!$B$14*'DCF Model'!K38)/(1+0.085)^10-'DCF Model'!$B$9)/'DCF Model'!K42 -> 0
A9: 0.095 | B9: =(NPV(0.095,'DCF Model'!B38:K38)+MIN('DCF Model'!K38*(1+0.0125)/(0.095-0.0125),'DCF Model'!$B$14*'DCF Model'!K38)/(1+0.095)^10-'DCF Model'!$B$9)/'DCF Model'!K42 -> 0 | C9: =(NPV(0.095,'DCF Model'!B38:K38)+MIN('DCF Model'!K38*(1+0.0175)/(0.095-0.0175),'DCF Model'!$B$14*'DCF Model'!K38)/(1+0.095)^10-'DCF Model'!$B$9)/'DCF Model'!K42 -> 0 | D9: =(NPV(0.095,'DCF Model'!B38:K38)+MIN('DCF Model'!K38*(1+0.0225)/(0.095-0.0225),'DCF Model'!$B$14*'DCF Model'!K38)/(1+0.095)^10-'DCF Model'!$B$9)/'DCF Model'!K42 -> 0 | E9: =(NPV(0.095,'DCF Model'!B38:K38)+MIN('DCF Model'!K38*(1+0.0275)/(0.095-0.0275),'DCF Model'!$B$14*'DCF Model'!K38)/(1+0.095)^10-'DCF Model'!$B$9)/'DCF Model'!K42 -> 0 | F9: =(NPV(0.095,'DCF Model'!B38:K38)+MIN('DCF Model'!K38*(1+0.0325)/(0.095-0.0325),'DCF Model'!$B$14*'DCF Model'!K38)/(1+0.095)^10-'DCF Model'!$B$9)/'DCF Model'!K42 -> 0
A12: Note: cells shown here recompute the terminal-year FCF at the base-case growth path
A13: (revenue/margin/capex assumptions unchanged); only WACC and terminal growth vary.

Sheet Scenarios
A1: Scenario Summary
A3: Metric | B3: Bull | C3: Base | D3: Bear
A4: WACC | B4: 0.07 | C4: 0.075 | D4: 0.085
A5: Terminal Growth | B5: 0.025 | C5: 0.0225 | D5: 0.02
A6: Sum PV of FCF (NZ$M) | B6: -226.2 | C6: -788.5 | D6: -1594.3
A7: PV Terminal Value (NZ$M) | B7: 9081.3 | C7: 6317.8 | D7: 2719.3
A8: Enterprise Value (NZ$M) | B8: 8855.1 | C8: 5529.4 | D8: 1124.9
A9: Equity Value (NZ$M) | B9: 6563.6 | C9: 3237.9 | D9: -1166.6
A10: Intrinsic Value/Share (NZ$) | B10: 3.85 | C10: 1.9 | D10: -0.68
A11: Upside/Downside vs NZ$8.76 | B11: -0.561 | C11: -0.783 | D11: -1.078
A12: Terminal % of Value | B12: 1.026 | C12: 1.143 | D12: 2.417
A13: Implied Exit Multiple (x FCF) | B13: 20 | C13: 19.5 | D13: 15
A15: Probability-Weighted IV (NZ$) | B15: 1.74
A16: Weights (Bull/Base/Bear) | B16: 25% / 50% / 25%
A18: Entry Price (15% IRR hurdle, base case) (NZ$) | B18: -0.06
A19: Bear case negative equity value note: | B19: A negative equity intrinsic value in the bear case is a genuine model output, not an error: it reflects that the ~NZ$1.0-1.6bn/yr capex program is largely already committed/contractual (NZ$1.31bn of PP&E purchase obligations at Dec-2025) and debt-funded, so a scenario combining sustained capacity cuts, weaker margins, and a higher WACC leaves owner FCF unable to service the resulting debt build without either delaying capex, cutting the dividend, or raising further equity. Read as a warning signal (leverage/refinancing risk in a severe downside, reinforced by the June-2026 traffic print already showing capacity-driven passenger declines), not a literal negative per-share value.

Sheet FCF Quality
A1: FCF Quality: Reported vs Owner FCF Reconciliation
A2: Historical reported FCF is deeply negative during the capex supercycle; SBC is immaterial for AIA.NZ.
B4: FY2019 | C4: FY2020 | D4: FY2021 | E4: FY2022 | F4: FY2023 | G4: FY2024 | H4: FY2025 | I4: H1-2026
A5: Reported FCF (company definition, NZ$M) | B5: 136.8 | C5: -64.7 | D5: -139 | E5: -163.4 | F5: -246.8 | G5: -581 | H5: -570.1 | I5: -246.9
A6: Reported Capex (NZ$M, memo) | B6: -239.1 | C6: -240.5 | D6: -200 | E6: -264.6 | F6: -571.9 | G6: -1077.3 | H6: -1044.4 | I6: -432.3
A7: Less: SBC (immaterial, NZ$M) | B7: 0 | C7: 0 | D7: 0 | E7: -0.1 | F7: 0.5 | G7: 0.2 | H7: 0.6
A8: Less: Interest Income (NZ$0 - net debt, not net cash) | B8: 0 | C8: 0 | D8: 0 | E8: 0 | F8: 0 | G8: 0 | H8: 0 | I8: 0
A9: Owner FCF (approx = Reported FCF, SBC immaterial) (NZ$M) | B9: 136.8 | C9: -64.7 | D9: -139 | E9: -163.4 | F9: -246.8 | G9: -581 | H9: -570.1 | I9: -246.9
A10: Revenue (NZ$M, memo) | B10: 743.4 | C10: 567 | D10: 281.1 | E10: 300.3 | F10: 625.9 | G10: 895.5 | H10: 1004.7 | I10: 519.6
A11: Reported FCF Margin % | B11: 0.18401937 | C11: -0.11410935 | D11: -0.49448595 | E11: -0.54412254 | F11: -0.39431219 | G11: -0.64879955 | H11: -0.56743306 | I11: -0.47517321
A13: Memo: why owner FCF ~= reported FCF for AIA.NZ
A14: Unlike SBC-heavy tech names, AIA.NZ's SBC is immaterial (NZ$0.1-0.6m/yr executive LTI plan, 8 people) so the SBC/interest-income adjustments that matter elsewhere in this framework barely move the needle here. The dominant driver of AIA.NZ's negative FCF is capex (debt-funded terminal/airfield programme), not SBC or working capital timing. The 10-year projected model builds owner FCF from EBITDAFI margin, D&A, tax, capex-guidance and a working-capital-on-revenue-growth capture, NOT by extrapolating the historical reported FCF margin forward (which would wrongly assume the capex supercycle never ends).

Sheet Model_Info
A1: Model Provenance & Methodology Notes
A4: Ticker | B4: AIA.NZ
A5: Company | B5: Auckland International Airport Limited
A6: Valuation Date | B6: 2026-08-09
A7: Share Price Used | B7: NZ$8.76 (Yahoo Finance live quote, verified 2026-08-09)
A8: Data Vintage | B8: FY2025 (year ended 30-Jun-2025) full-year actuals + H1-2026 (half year ended 31-Dec-2025) interim actuals. FY2026 annual results (year ended 30-Jun-2026) are due 20-Aug-2026 and are NOT reflected here.
A9: Net Debt Basis | B9: H1-2026: Total Debt NZ$2,652.1m - Cash NZ$360.6m = NZ$2,291.5m
A10: Shares Outstanding Basis | B10: H1-2026: 1,705.7m shares (post Sep-2024 NZ$1.4bn equity raise, 1472m -> 1688m -> 1705.7m at H1-26)
A11: Methodology | B11: 10-year explicit component-build owner FCF DCF (revenue -> EBITDAFI margin -> less SBC -> less D&A -> EBIT -> tax-effected NOPAT -> add back D&A -> less capex -> plus/minus working capital-on-revenue-growth). A 10-year horizon (not 5) is used because AIA.NZ is mid-capex-supercycle: margins/FCF do not mature until the capex programme tapers post-FY29.
A12: Why NOT trailing-FCF DCF | B12: Reported FCF has been negative every year FY2023-25 (-NZ$247m to -NZ$581m) purely from a debt-funded terminal/airfield capex supercycle (NZ$1.0-1.6bn/yr guided to ~2029). A DCF grown off trailing FCF would either explode a negative base or require an arbitrary positive override; the component build instead lets capex taper explicitly to a ~NZ$320m/yr maintenance level post-FY32.
A13: Excluded Outlier Years | B13: FY2018 & FY2021 (investment-property revaluation gains inflate NPAT/EBITDA); FY2020-23 (COVID border closures/recovery); FY2024 (NZ$5.5m NPAT one-off deferred-tax charge, NZ removed building depreciation deductions).
A14: WACC / Terminal Growth (Base) | B14: 7.5% / 2.25% -- large-cap regulated infrastructure; NOT stacked with small-cap/illiquidity premiums (this is a ~NZ$15bn NZX large cap). Cross-referenced against AIA's own PSE4 regulatory target return of 7.82% (actual aero return 5.53%).
A15: Terminal Value Cap | B15: 20x terminal-year FCF (15x in bear case) -- binds instead of Gordon growth at low WACC/high-g combinations; see Sensitivity sheet.
... A21: Staleness Warning | B21: All figures in this workbook reflect data as of the Valuation Date above. Share price, net debt, shares outstanding and guidance figures WILL go stale after the next earnings release or market move -- re-verify before relying on this model.
