Workbook

Sheet README
A1: Citigroup Inc. (C) — Residual Income Valuation Model
A2: This is a G-SIB BANK HOLDING COMPANY. Standard unlevered FCF DCF is not meaningful for a depository/markets institution.
A4: METHODOLOGY: Residual Income (Excess-Return) Model on Tangible Common Equity (TCE) Why not a standard FCF DCF? Free cash flow is not a valid concept for a bank: deposits and short-term borrowings are operating funding (not net debt), loan/trading-book flows swamp any FCF proxy, and bank capital is regulated (CET1) rather than freely distributable. Instead, this model values Citigroup as: Intrinsic Equity Value = Starting Tangible Book Value (TBV) + PV of future Residual Income, where Residual Income = (ROTCE - Cost of Equity) x Beginning TBV + PV of the Terminal Exit Value in excess of ending book value (Terminal Exit Value = Ending TBV x Exit Price/Tangible-Book multiple) Cost of Equity (CoE), not WACC, is used as the discount rate — standard bank-valuation convention since we are discounting an equity-level residual income stream, not an unlevered enterprise FCF stream. Citigroup's ROTCE has historically sat below cost of equity (FY2022-2025 estimated ROTCE ~5-8%) but inflected sharply in H1 2026 to a disclosed 13.0-13.1%, above the FY2026 guided 10-11% range, as the multi-year Transformation program nears completion (OCC consent order terminated Dec-2025) and Markets/Banking revenue hit a decade-best quarter. The valuation question is whether this inflection is durable (bull), merely holds near the H1 2026 run-rate (base), or reverts toward the historical band as capital markets normalize (bear). TANGIBLE BOOK VALUE ANCHOR (ESTIMATED as of ~2026-06-30 — see notes): Book Value: $212,413M (est.) / 1,785.8M shares (est.) = $118.95/share Less: Goodwill + identifiable intangibles ~$22,459M (estimated, held roughly constant vs. recent 10-Ks) = Tangible Book Value: ~$189,954M total / $106.37 per share <- valuation anchor IMPORTANT DATA LIMITATION: C_Metrics.csv (SEC XBRL extraction) is populated only through FY2025/Q3-2025 — no 2026 10-Q has yet been extracted into core_metrics. The anchor above rolls the FY2025 actuals (equity $213,822M, shares 1,873.1M) forward through H1 2026 using figures disclosed qualitatively in C_Analysis.json (Q2 2026 net income $5.8bn actual; Q1 2026 net income estimated; H1 2026 buybacks $10.3bn actual; dividend at pre-hike rate). Refresh this model once Q2/Q3 2026 10-Qs are extracted into the CSV. SCENARIOS: BASE: RoTCE holds near the H1 2026 run-rate, 11.5%->13.0% over 5 years; buybacks 3-4%/yr; dividend payout 35%; exit at 1.15x TBV; CoE 11.0% BULL: RoTCE keeps compounding toward top-tier peer levels, 12.5%->16.0%; buybacks 4-5%/yr; dividend payout 30%; exit at 1.4x TBV; CoE 10.0% BEAR: H1 2026 strength was cyclical; RoTCE reverts to 9.0-9.5%; buybacks slow to 2-2.5%/yr; dividend payout 40%; exit at 0.9x TBV; CoE 12.0% Gray cells are INPUTS — adjust the ROTCE path, buyback rate, dividend payout, Cost of Equity, or Exit P/TBV multiple on each scenario tab to see the valuation update automatically.

Sheet Base Case
A1: C — BASE CASE (Residual Income Model)
A2: Gray cells are INPUTS - adjust to see valuation change
A4: KEY INPUTS
A5: Current Stock Price | B5: 134.28
A6: Shares Outstanding (M, est.) | B6: 1785.8
A7: Book Value Total ($M, est.) | B7: 212413
A8: Goodwill + Intangibles ($M, est.) | B8: 22459
A9: (unused)
A10: Starting Tangible Book Value ($M) | B10: =B7-B8 -> 189954
A11: Starting TBV per Share | B11: =B10/B6 -> 106.36913
A13: Cost of Equity (CoE) | B13: 0.11
A14: Exit P/TBV Multiple (Year 5) | B14: 1.15
A15: Dividend Payout Ratio | B15: 0.35
A17: YEAR-BY-YEAR ASSUMPTIONS
B18: Year 1 | C18: Year 2 | D18: Year 3 | E18: Year 4 | F18: Year 5
A19: ROTCE (on beginning TBV) | B19: 0.115 | C19: 0.12 | D19: 0.125 | E19: 0.13 | F19: 0.13
A20: Buyback % of Shares | B20: 0.04 | C20: 0.04 | D20: 0.035 | E20: 0.03 | F20: 0.03
A22: PROJECTIONS
B23: Year 1 | C23: Year 2 | D23: Year 3 | E23: Year 4 | F23: Year 5
A24: Beginning TBV ($M) | B24: =$B$10 -> 189954 | C24: =B31 -> 196554.9 | D24: =C31 -> 204023.99 | E24: =D31 -> 213460.1 | F24: =E31 -> 225093.67
A25: Net Income ($M) | B25: =B19*B24 -> 21844.71 | C25: =C19*C24 -> 23586.588 | D25: =D19*D24 -> 25502.998 | E25: =E19*E24 -> 27749.813 | F25: =F19*F24 -> 29262.177
A26: Residual Income ($M) | B26: =(B19-$B$13)*B24 -> 949.77 | C26: =(C19-$B$13)*C24 -> 1965.549 | D26: =(D19-$B$13)*D24 -> 3060.3598 | E26: =(E19-$B$13)*E24 -> 4269.2019 | F26: =(F19-$B$13)*F24 -> 4501.8734
A27: Dividends Paid ($M) | B27: =B25*$B$15 -> 7645.6485 | C27: =C25*$B$15 -> 8255.3059 | D27: =D25*$B$15 -> 8926.0495 | E27: =E25*$B$15 -> 9712.4344 | F27: =F25*$B$15 -> 10241.762
A28: Retained Earnings ($M) | B28: =B25-B27 -> 14199.061 | C28: =C25-C27 -> 15331.282 | D28: =D25-D27 -> 16576.949 | E28: =E25-E27 -> 18037.378 | F28: =F25-F27 -> 19020.415
A29: Shares Repurchased (M) | B29: =$B$6*B20 -> 71.432 | C29: =B32*C20 -> 68.57472 | D29: =C32*D20 -> 57.602765 | E29: =D32*E20 -> 47.645715 | F29: =E32*F20 -> 46.216344
A30: Cash for Buybacks ($M) | B30: =B29*(B24/$B$6) -> 7598.16 | C30: =C29*(C24/B32) -> 7862.1961 | D30: =D29*(D24/C32) -> 7140.8396 | E30: =E29*(E24/D32) -> 6403.8029 | F30: =F29*(F24/E32) -> 6752.8102
A31: Ending TBV ($M) | B31: =B24+B28-B30 -> 196554.9 | C31: =C24+C28-C30 -> 204023.99 | D31: =D24+D28-D30 -> 213460.1 | E31: =E24+E28-E30 -> 225093.67 | F31: =F24+F28-F30 -> 237361.28
A32: Ending Shares (M) | B32: =$B$6-B29 -> 1714.368 | C32: =B32-C29 -> 1645.7933 | D32: =C32-D29 -> 1588.1905 | E32: =D32-E29 -> 1540.5448 | F32: =E32-F29 -> 1494.3285
A33: Ending TBV per Share | B33: =B31/B32 -> 114.65152 | C33: =C31/C32 -> 123.96696 | D33: =D31/D32 -> 134.40459 | E33: =E31/E32 -> 146.11303 | F33: =F31/F32 -> 158.84144
A34: Discount Factor | B34: =1/(1+$B$13)^1 -> 0.9009009 | C34: =1/(1+$B$13)^2 -> 0.81162243 | D34: =1/(1+$B$13)^3 -> 0.73119138 | E34: =1/(1+$B$13)^4 -> 0.65873097 | F34: =1/(1+$B$13)^5 -> 0.59345133
A35: PV of Residual Income ($M) | B35: =B26*B34 -> 855.64865 | C35: =C26*C34 -> 1595.2837 | D35: =D26*D34 -> 2237.7087 | E35: =E26*E34 -> 2812.2556 | F35: =F26*F34 -> 2671.6428
A37: VALUATION
A38: Sum of PV of Residual Income ($M) | B38: =SUM(B35:F35) -> 10172.539
A39: Ending TBV Total ($M) | B39: =F31 -> 237361.28
A40: Ending Shares (M) | B40: =F32 -> 1494.3285
A41: Exit P/TBV Multiple | B41: =B14 -> 1.15
A42: Terminal Equity Value ($M) | B42: =B39*B41 -> 272965.47
A43: Excess Over Book at Exit ($M) | B43: =B42-B39 -> 35604.192
A44: PV of Exit Premium ($M) | B44: =B43/(1+$B$13)^5 -> 21129.355
A45: Intrinsic Equity Value ($M) | B45: =B10+B38+B44 -> 221255.89
...

Sheet Bull Case
A1: C — BULL CASE (Residual Income Model)
A2: Gray cells are INPUTS - adjust to see valuation change
A4: KEY INPUTS
A5: Current Stock Price | B5: 134.28
A6: Shares Outstanding (M, est.) | B6: 1785.8
A7: Book Value Total ($M, est.) | B7: 212413
A8: Goodwill + Intangibles ($M, est.) | B8: 22459
A9: (unused)
A10: Starting Tangible Book Value ($M) | B10: =B7-B8 -> 189954
A11: Starting TBV per Share | B11: =B10/B6 -> 106.36913
A13: Cost of Equity (CoE) | B13: 0.1
A14: Exit P/TBV Multiple (Year 5) | B14: 1.4
A15: Dividend Payout Ratio | B15: 0.3
A17: YEAR-BY-YEAR ASSUMPTIONS
B18: Year 1 | C18: Year 2 | D18: Year 3 | E18: Year 4 | F18: Year 5
A19: ROTCE (on beginning TBV) | B19: 0.125 | C19: 0.14 | D19: 0.15 | E19: 0.155 | F19: 0.16
A20: Buyback % of Shares | B20: 0.05 | C20: 0.05 | D20: 0.045 | E20: 0.04 | F20: 0.04
A22: PROJECTIONS
B23: Year 1 | C23: Year 2 | D23: Year 3 | E23: Year 4 | F23: Year 5
A24: Beginning TBV ($M) | B24: =$B$10 -> 189954 | C24: =B31 -> 197077.27 | D24: =C31 -> 206536.98 | E24: =D31 -> 218929.2 | F24: =E31 -> 233925.85
A25: Net Income ($M) | B25: =B19*B24 -> 23744.25 | C25: =C19*C24 -> 27590.819 | D25: =D19*D24 -> 30980.548 | E25: =E19*E24 -> 33934.027 | F25: =F19*F24 -> 37428.137
A26: Residual Income ($M) | B26: =(B19-$B$13)*B24 -> 4748.85 | C26: =(C19-$B$13)*C24 -> 7883.091 | D26: =(D19-$B$13)*D24 -> 10326.849 | E26: =(E19-$B$13)*E24 -> 12041.106 | F26: =(F19-$B$13)*F24 -> 14035.551
A27: Dividends Paid ($M) | B27: =B25*$B$15 -> 7123.275 | C27: =C25*$B$15 -> 8277.2455 | D27: =D25*$B$15 -> 9294.1643 | E27: =E25*$B$15 -> 10180.208 | F27: =F25*$B$15 -> 11228.441
A28: Retained Earnings ($M) | B28: =B25-B27 -> 16620.975 | C28: =C25-C27 -> 19313.573 | D28: =D25-D27 -> 21686.383 | E28: =E25-E27 -> 23753.819 | F28: =F25-F27 -> 26199.696
A29: Shares Repurchased (M) | B29: =$B$6*B20 -> 89.29 | C29: =B32*C20 -> 84.8255 | D29: =C32*D20 -> 72.525802 | E29: =D32*E20 -> 61.566348 | F29: =E32*F20 -> 59.103694
A30: Cash for Buybacks ($M) | B30: =B29*(B24/$B$6) -> 9497.7 | C30: =C29*(C24/B32) -> 9853.8638 | D30: =D29*(D24/C32) -> 9294.1643 | E30: =E29*(E24/D32) -> 8757.1681 | F30: =F29*(F24/E32) -> 9357.0341
A31: Ending TBV ($M) | B31: =B24+B28-B30 -> 197077.27 | C31: =C24+C28-C30 -> 206536.98 | D31: =D24+D28-D30 -> 218929.2 | E31: =E24+E28-E30 -> 233925.85 | F31: =F24+F28-F30 -> 250768.52
A32: Ending Shares (M) | B32: =$B$6-B29 -> 1696.51 | C32: =B32-C29 -> 1611.6845 | D32: =C32-D29 -> 1539.1587 | E32: =D32-E29 -> 1477.5923 | F32: =E32-F29 -> 1418.4887
A33: Ending TBV per Share | B33: =B31/B32 -> 116.16629 | C33: =C31/C32 -> 128.14976 | D33: =D31/D32 -> 142.23953 | E33: =E31/E32 -> 158.31556 | F33: =F31/F32 -> 176.7857
A34: Discount Factor | B34: =1/(1+$B$13)^1 -> 0.90909091 | C34: =1/(1+$B$13)^2 -> 0.82644628 | D34: =1/(1+$B$13)^3 -> 0.7513148 | E34: =1/(1+$B$13)^4 -> 0.68301346 | F34: =1/(1+$B$13)^5 -> 0.62092132
A35: PV of Residual Income ($M) | B35: =B26*B34 -> 4317.1364 | C35: =C26*C34 -> 6514.9512 | D35: =D26*D34 -> 7758.7147 | E35: =E26*E34 -> 8224.2375 | F35: =F26*F34 -> 8714.973
A37: VALUATION
A38: Sum of PV of Residual Income ($M) | B38: =SUM(B35:F35) -> 35530.013
A39: Ending TBV Total ($M) | B39: =F31 -> 250768.52
A40: Ending Shares (M) | B40: =F32 -> 1418.4887
A41: Exit P/TBV Multiple | B41: =B14 -> 1.4
A42: Terminal Equity Value ($M) | B42: =B39*B41 -> 351075.92
A43: Excess Over Book at Exit ($M) | B43: =B42-B39 -> 100307.41
A44: PV of Exit Premium ($M) | B44: =B43/(1+$B$13)^5 -> 62283.007
A45: Intrinsic Equity Value ($M) | B45: =B10+B38+B44 -> 287767.02
...

Sheet Bear Case
A1: C — BEAR CASE (Residual Income Model)
A2: Gray cells are INPUTS - adjust to see valuation change
A4: KEY INPUTS
A5: Current Stock Price | B5: 134.28
A6: Shares Outstanding (M, est.) | B6: 1785.8
A7: Book Value Total ($M, est.) | B7: 212413
A8: Goodwill + Intangibles ($M, est.) | B8: 22459
A9: (unused)
A10: Starting Tangible Book Value ($M) | B10: =B7-B8 -> 189954
A11: Starting TBV per Share | B11: =B10/B6 -> 106.36913
A13: Cost of Equity (CoE) | B13: 0.12
A14: Exit P/TBV Multiple (Year 5) | B14: 0.9
A15: Dividend Payout Ratio | B15: 0.4
A17: YEAR-BY-YEAR ASSUMPTIONS
B18: Year 1 | C18: Year 2 | D18: Year 3 | E18: Year 4 | F18: Year 5
A19: ROTCE (on beginning TBV) | B19: 0.095 | C19: 0.09 | D19: 0.09 | E19: 0.095 | F19: 0.095
A20: Buyback % of Shares | B20: 0.025 | C20: 0.02 | D20: 0.02 | E20: 0.02 | F20: 0.02
A22: PROJECTIONS
B23: Year 1 | C23: Year 2 | D23: Year 3 | E23: Year 4 | F23: Year 5
A24: Beginning TBV ($M) | B24: =$B$10 -> 189954 | C24: =B31 -> 196032.53 | D24: =C31 -> 202697.63 | E24: =D31 -> 209589.35 | F24: =E31 -> 217344.16
A25: Net Income ($M) | B25: =B19*B24 -> 18045.63 | C25: =C19*C24 -> 17642.928 | D25: =D19*D24 -> 18242.787 | E25: =E19*E24 -> 19910.989 | F25: =F19*F24 -> 20647.695
A26: Residual Income ($M) | B26: =(B19-$B$13)*B24 -> -4748.85 | C26: =(C19-$B$13)*C24 -> -5880.9758 | D26: =(D19-$B$13)*D24 -> -6080.929 | E26: =(E19-$B$13)*E24 -> -5239.7338 | F26: =(F19-$B$13)*F24 -> -5433.604
A27: Dividends Paid ($M) | B27: =B25*$B$15 -> 7218.252 | C27: =C25*$B$15 -> 7057.171 | D27: =D25*$B$15 -> 7297.1148 | E27: =E25*$B$15 -> 7964.3954 | F27: =F25*$B$15 -> 8259.0781
A28: Retained Earnings ($M) | B28: =B25-B27 -> 10827.378 | C28: =C25-C27 -> 10585.757 | D28: =D25-D27 -> 10945.672 | E28: =E25-E27 -> 11946.593 | F28: =F25-F27 -> 12388.617
A29: Shares Repurchased (M) | B29: =$B$6*B20 -> 44.645 | C29: =B32*C20 -> 34.8231 | D29: =C32*D20 -> 34.126638 | E29: =D32*E20 -> 33.444105 | F29: =E32*F20 -> 32.775223
A30: Cash for Buybacks ($M) | B30: =B29*(B24/$B$6) -> 4748.85 | C30: =C29*(C24/B32) -> 3920.6506 | D30: =D29*(D24/C32) -> 4053.9527 | E30: =E29*(E24/D32) -> 4191.7871 | F30: =F29*(F24/E32) -> 4346.8832
A31: Ending TBV ($M) | B31: =B24+B28-B30 -> 196032.53 | C31: =C24+C28-C30 -> 202697.63 | D31: =D24+D28-D30 -> 209589.35 | E31: =E24+E28-E30 -> 217344.16 | F31: =F24+F28-F30 -> 225385.89
A32: Ending Shares (M) | B32: =$B$6-B29 -> 1741.155 | C32: =B32-C29 -> 1706.3319 | D32: =C32-D29 -> 1672.2053 | E32: =D32-E29 -> 1638.7612 | F32: =E32-F29 -> 1605.9859
A33: Ending TBV per Share | B33: =B31/B32 -> 112.58764 | C33: =C31/C32 -> 118.79145 | D33: =D31/D32 -> 125.3371 | E33: =E31/E32 -> 132.62711 | F33: =F31/F32 -> 140.34114
A34: Discount Factor | B34: =1/(1+$B$13)^1 -> 0.89285714 | C34: =1/(1+$B$13)^2 -> 0.79719388 | D34: =1/(1+$B$13)^3 -> 0.71178025 | E34: =1/(1+$B$13)^4 -> 0.63551808 | F34: =1/(1+$B$13)^5 -> 0.56742686
A35: PV of Residual Income ($M) | B35: =B26*B34 -> -4240.0446 | C35: =C26*C34 -> -4688.2779 | D35: =D26*D34 -> -4328.2852 | E35: =E26*E34 -> -3329.9456 | F35: =F26*F34 -> -3083.1728
A37: VALUATION
A38: Sum of PV of Residual Income ($M) | B38: =SUM(B35:F35) -> -19669.726
A39: Ending TBV Total ($M) | B39: =F31 -> 225385.89
A40: Ending Shares (M) | B40: =F32 -> 1605.9859
A41: Exit P/TBV Multiple | B41: =B14 -> 0.9
A42: Terminal Equity Value ($M) | B42: =B39*B41 -> 202847.3
A43: Excess Over Book at Exit ($M) | B43: =B42-B39 -> -22538.589
A44: PV of Exit Premium ($M) | B44: =B43/(1+$B$13)^5 -> -12789.001
A45: Intrinsic Equity Value ($M) | B45: =B10+B38+B44 -> 157495.27
...

Sheet Summary
A1: Citigroup (C) Valuation Summary
A3: SCENARIO SUMMARY
A4: Scenario | B4: Intrinsic Value/Share | C4: Upside/(Downside) | D4: Implied Exit P/TBV | E4: Probability Weight
A5: Bear | B5: ='Bear Case'!B46 -> 88.19312 | C5: =(B5-B10)/B10 -> -0.34321478 | D5: ='Bear Case'!B47 -> 0.82912322 | E5: 0.25
A6: Base | B6: ='Base Case'!B46 -> 123.89735 | C6: =(B6-B10)/B10 -> -0.077320869 | D6: ='Base Case'!B47 -> 1.1647867 | E6: 0.5
A7: Bull | B7: ='Bull Case'!B46 -> 161.1418 | C7: =(B7-B10)/B10 -> 0.20004317 | D7: ='Bull Case'!B47 -> 1.51493 | E7: 0.25
A9: Current Stock Price
A10: Current Stock Price (ref) | B10: 134.28
A12: PROBABILITY-WEIGHTED INTRINSIC VALUE | B12: =B5*E5+B6*E6+B7*E7 -> 124.28241
A13: Weighted Upside/(Downside) | B13: =(B12-B10)/B10 -> -0.074453337
A15: ENTRY PRICE (15% CAGR Target, off Base Case)
A16: Base Terminal Equity Value ($M) | B16: ='Base Case'!B42 -> 272965.47
A17: Base Ending Shares (M) | B17: ='Base Case'!B40 -> 1494.3285
A18: Terminal Value per Share | B18: =B16/B17 -> 182.66765
A19: Years to Terminal | B19: 5
A20: Entry Price (15% CAGR) | B20: =B18/(1.15^B19) -> 90.818107
A21: Entry Discount from Current Price | B21: =(B20-B10)/B10 -> -0.32366617

Sheet Sensitivity
A1: Sensitivity Analysis — Base Case
A2: Intrinsic Value per Share by Cost of Equity & Exit P/TBV Multiple
A3: (Static values shown; matches Base Case sheet mechanics)
A5: CoE \ Exit P/TBV | B5: 0.85 | C5: 1 | D5: 1.15 | E5: 1.3 | F5: 1.45
A6: 0.09 | B6: 108.38 | C6: 121.34 | D6: 134.3 | E6: 147.26 | F6: 160.21
A7: 0.1 | B7: 104.2 | C7: 116.58 | D7: 128.96 | E7: 141.34 | F7: 153.72
A8: 0.11 | B8: 100.23 | C8: 112.07 | D8: 123.9 | E8: 135.73 | F8: 147.56
A9: 0.12 | B9: 96.46 | C9: 107.78 | D9: 119.09 | E9: 130.4 | F9: 141.71
A10: 0.13 | B10: 92.88 | C10: 103.7 | D10: 114.52 | E10: 125.34 | F10: 136.16
A12: Note: matrix computed in Python using Base Case RoTCE (11.5%->13.0%) and buyback (4.0%->3.0%) paths;
A13: shown as static reference values. Adjust CoE / Exit P/TBV directly on the Base Case tab for live recalculation.

Sheet Historical
A1: Historical Growth Rates (Reference Only)
A2: NOTE: Standard CAGR growth-selection logic does NOT apply cleanly to Citigroup — see warning below.
A4: Metric | B4: Value
A5: Revenue 3yr CAGR (FY22->FY25) | B5: 0.0303
A6: Revenue 5yr CAGR (FY20->FY25) | B6: 0.0244
A7: Shareholders' Equity 3yr CAGR (FY22->FY25) | B7: 0.0194
A8: Shareholders' Equity 5yr CAGR (FY20->FY25) | B8: 0.0133
A9: EPS 3yr CAGR (FY22->FY25) — noisy, not a clean anchor | B9: 0.0033
A10: EPS 5yr CAGR (FY20->FY25) — inflated by FY21 reserve releases | B10: 0.0845
A11: ROE FY2022 (%) | B11: 0.074
A12: ROE FY2023 (%) | B12: 0.0455
A13: ROE FY2024 (%) | B13: 0.0613
A14: ROE FY2025 (%) | B14: 0.0676
A15: Estimated ROTCE FY2022 (%) | B15: 0.0833
A16: Estimated ROTCE FY2023 (%) | B16: 0.051
... A19: Disclosed RoTCE H1 2026 (%) | B19: 0.131
A21: Growth Divergence Warning:
A22: Standard CAGR growth-rate selection does not apply to a bank residual-income model. Shareholders' equity CAGR is nearly flat (1.3-1.9% over 3-5yr) because large buybacks roughly offset retained earnings — this is a capital-return story, not a growth story. EPS CAGR is volatile and not a clean anchor: FY2023 EPS ($4.07) was depressed by elevated expenses/reserve builds and FY2021 EPS ($10.21, not shown as a CAGR endpoint here) was inflated by reserve releases post-COVID. The Net-income-based ROTCE trajectory (rising from an estimated ~5-8% in FY2022-2025 to a disclosed 13.0-13.1% in H1 2026) is the operative signal driving this valuation, not any revenue or EPS CAGR.
