Workbook

Sheet Company Overview
A1: FLOW TRADERS LTD (FLOW.AS)
A2: DCF Valuation Model
A3: January 2026
A4: Currency: EUR (€)
A6: COMPANY PROFILE
A7: Ticker: | B7: FLOW.AS (Euronext Amsterdam)
A8: Industry: | B8: Capital Markets / Market Making
A9: Business Description: | B9: Financial technology-enabled multi-asset class liquidity provider
A10: Headquarters: | B10: Amsterdam, Netherlands
A11: Founded: | B11: 2004
A12: Employees: | B12: 607
A14: MARKET DATA (As of Jan 2026)
A15: Current Stock Price (€): | B15: 26.12
A16: Shares Outstanding (M): | B16: 43.56
A17: Market Cap (€M): | B17: =B15*B16 -> 1137.7872
A18: 52-Week Range (€): | B18: 21.80 - 31.04
A19: Beta (5Y Monthly): | B19: 0.19
A20: P/E Ratio (TTM): | B20: 6.2
A21: EPS (TTM) €: | B21: 4.21
A23: KEY INVESTMENT HIGHLIGHTS
A24: • Leading global ETP market maker (Europe's largest)
A25: • Benefits from market volatility (counter-cyclical)
A26: • Expanding into digital assets, fixed income, and FX
A27: • Strong technology platform with high barriers to entry
A28: • 2024 was second-best year in company history
A29: • Capital expansion plan increasing trading capacity

Sheet Historical Financials
A1: HISTORICAL FINANCIAL DATA
A2: All amounts in EUR millions unless otherwise stated
B4: FY 2021 | C4: FY 2022 | D4: FY 2023 | E4: FY 2024 | F4: H1 2025 | G4: LTM
A5: INCOME STATEMENT
A6: Total Income (NTI + Other) | B6: 557 | C6: 672 | D6: 303.9 | E6: 479.3 | F6: 314.3 | G6: =E6-F6+314.3+143.9 -> 623.2
A7: Net Trading Income | B7: 545 | C7: 659 | D7: 300.3 | E7: 467.8 | F7: 313.8 | G7: =E7-F7+313.8+143.4 -> 611.2
A8: Fixed Operating Expenses | B8: 160 | C8: 170 | D8: 174.1 | E8: 179.1 | F8: 97 | G8: =E8-F8+97+49.8 -> 228.9
A9: Variable Operating Expenses | B9: 108 | C9: 115 | D9: 62.2 | E9: 85.3 | F9: 52.6 | G9: =E9-F9+52.6+26.2 -> 111.5
A10: Total Operating Expenses | B10: =B8+B9 -> 268 | C10: =C8+C9 -> 285 | D10: =D8+D9 -> 236.3 | E10: =E8+E9 -> 264.4 | F10: =F8+F9 -> 149.6 | G10: =G8+G9 -> 340.4
A11: EBITDA | B11: 290 | C11: 387 | D11: 67.5 | E11: 214.9 | F11: 119.3 | G11: =E11-F11+119.3+68 -> 282.9
A12: EBITDA Margin % | B12: =B11/B6 -> 0.52064632 | C12: =C11/C6 -> 0.57589286 | D12: =D11/D6 -> 0.22211254 | E12: =E11/E6 -> 0.44836219 | F12: =F11/F6 -> 0.37957366 | G12: =G11/G6 -> 0.45394737
A13: Net Profit | B13: 181.9 | C13: 126.1 | D13: 36.2 | E13: 159.5 | F13: 85.5 | G13: =E13-F13+85.5+51.3 -> 210.8
A14: Net Margin % | B14: =B13/B6 -> 0.32657092 | C14: =C13/C6 -> 0.18764881 | D14: =D13/D6 -> 0.11911813 | E14: =E13/E6 -> 0.33277697 | F14: =F13/F6 -> 0.27203309 | G14: =G13/G6 -> 0.33825417
A15: Diluted EPS (€) | B15: 4.17 | C15: 2.92 | D15: 0.81 | E15: 3.56 | F15: 1.97 | G15: =G13/43.56 -> 4.8393021
A17: BALANCE SHEET DATA
A18: Trading Capital | B18: 550 | C18: 545 | D18: 584 | E18: 775 | F18: 831
A19: Shareholders' Equity | B19: 520 | C19: 590 | D19: 586 | E19: 766 | F19: 817
A20: Return on Equity % | B20: =B13/B19 -> 0.34980769 | C20: =C13/C19 -> 0.21372881 | D20: =D13/D19 -> 0.061774744 | E20: =E13/E19 -> 0.20822454 | F20: =(F13*2)/F19 -> 0.20930233
A22: TRADING METRICS
A23: ETP Value Traded (€B) | B23: 1650 | C23: 1580 | D23: 1465 | E23: 1545 | F23: 943
A24: Avg. VIX | B24: 19.7 | C24: 25.6 | D24: 13.9 | E24: 15.5 | F24: 18.2
A25: Return on Trading Capital % | B25: =B7/B18 -> 0.99090909 | C25: =C7/C18 -> 1.2091743 | D25: =D7/D18 -> 0.51421233 | E25: =E7/E18 -> 0.6036129 | F25: =(F7*2)/F18 -> 0.75523466

Sheet DCF Assumptions
A1: DCF MODEL ASSUMPTIONS
A3: REVENUE GROWTH ASSUMPTIONS
A4: Base Year Total Income (€M) - FY 2024: | B4: 479.3
A5: Year 1 Growth Rate (2025): | B5: 0.12 | C5: Revenue more volatile than equity - use conservative rates
A6: Year 2 Growth Rate (2026): | B6: 0.08 | C6: Slightly below historical
A7: Year 3 Growth Rate (2027): | B7: 0.06 | C7: Tapering toward steady state
A8: Year 4 Growth Rate (2028): | B8: 0.05 | C8: Mature growth
A9: Year 5 Growth Rate (2029): | B9: 0.04 | C9: Terminal approach
A11: MARGIN ASSUMPTIONS
A12: Target EBITDA Margin: | B12: 0.32 | C12: Cycle-average (range 22%-45%)
A13: D&A as % of Revenue: | B13: 0.02
A14: Tax Rate: | B14: 0.25 | C14: Netherlands corporate tax
A15: CapEx as % of Revenue: | B15: 0.015 | C15: Low capital intensity
A16: Change in NWC as % of Revenue Change: | B16: 0.05
A18: WACC ASSUMPTIONS
A19: Risk-Free Rate: | B19: 0.035 | C19: 10Y German Bund
A20: Equity Risk Premium: | B20: 0.065 | C20: European market premium
A21: Beta (Levered): | B21: 1.2 | C21: Adjusted for earnings volatility
A22: Cost of Equity (CAPM): | B22: =B19+B21*B20 -> 0.113 | C22: Rf + Beta × ERP
A23: Cost of Debt (Pre-tax): | B23: 0.055
A24: Cost of Debt (After-tax): | B24: =B23*(1-B14) -> 0.04125
A25: Debt Weight: | B25: 0.3 | C25: Target capital structure
A26: Equity Weight: | B26: =1-B25 -> 0.7
A27: WACC: | B27: =B22*B26+B24*B25 -> 0.091475
A29: TERMINAL VALUE ASSUMPTIONS
A30: Terminal Growth Rate: | B30: 0.03 | C30: Conservative long-term growth
A32: NOTES ON BETA
A33: Flow Traders has an unusually low beta (0.19) because:
A34: • Market makers benefit from volatility
A35: • When markets decline, volatility increases, boosting trading profits
A36: • This counter-cyclical nature provides portfolio diversification
A37: • However, this may understate true systematic risk
A38: • Consider using industry beta (0.8-1.2) for sensitivity analysis
A39: NOTE: Using industry beta (0.90) instead of reported (0.19) for more realistic valuation
A40: GROWTH RATE RATIONALE
A41: • 10-year equity CAGR: ~18% (remarkably consistent)
A42: • Equity growth driven by retained earnings across volatility cycles
A43: • Revenue/NTI volatile YoY but compounds with equity over time
... A45: • Key insight: Focus on equity compounding, not annual profit swings

Sheet Equity Growth Model
A1: EQUITY GROWTH VALUATION MODEL
A2: Based on 10-year historical equity CAGR of ~18%
A4: HISTORICAL SHAREHOLDERS' EQUITY
A5: Year | B5: Equity (€M) | C5: YoY Growth
A6: 2015 (IPO) | B6: 156
A7: 2016 | B7: 184 | C7: 0.18
A8: 2017 | B8: 217 | C8: 0.18
A9: 2018 | B9: 256 | C9: 0.18
A10: 2019 | B10: 302 | C10: 0.18
A11: 2020 | B11: 425 | C11: 0.41
A12: 2021 | B12: 520 | C12: 0.22
A13: 2022 | B13: 590 | C13: 0.13
A14: 2023 | B14: 586 | C14: -0.01
A15: 2024 | B15: 766 | C15: 0.31
A16: H1 2025 | B16: 817
A18: 10-Year CAGR (2015-2025): | B18: =(B16/B6)^(1/10)-1 -> 0.18007537
A20: PROJECTION ASSUMPTIONS
A21: Current Equity (H1 2025, €M): | B21: 817
A22: Assumed Equity Growth Rate: | B22: 0.15 | C22: Conservative vs. 18% historical
A23: Cost of Equity: | B23: 0.1
A24: Terminal Growth Rate: | B24: 0.03
A25: Shares Outstanding (M): | B25: 43.56
A27: EQUITY PROJECTIONS
B28: Year 0 | C28: Year 1 | D28: Year 2 | E28: Year 3 | F28: Year 4 | G28: Year 5 | H28: Terminal
B29: 2025 | C29: 2026 | D29: 2027 | E29: 2028 | F29: 2029 | G29: 2030 | H29: TV
A30: Shareholders' Equity | B30: =B21 -> 817 | C30: =B30*(1+$B$22) -> 939.55 | D30: =C30*(1+$B$22) -> 1080.4825 | E30: =D30*(1+$B$22) -> 1242.5549 | F30: =E30*(1+$B$22) -> 1428.9381 | G30: =F30*(1+$B$22) -> 1643.2788
A32: EXCESS RETURNS VALUATION
A33: (Value = Book + PV of Future Excess Returns)
A35: ROE (Equity Growth Rate): | B35: =B22 -> 0.15
A36: Cost of Equity: | B36: =B23 -> 0.1
A37: Excess ROE Spread: | B37: =B35-B36 -> 0.05
A39: Excess Earnings (€M) | C39: =C30*$B$37 -> 46.9775 | D39: =D30*$B$37 -> 54.024125 | E39: =E30*$B$37 -> 62.127744 | F39: =F30*$B$37 -> 71.446905 | G39: =G30*$B$37 -> 82.163941
A40: Terminal Value of Excess Returns | H40: =G39*(1+$B$24)/($B$23-$B$24) -> 1208.9837
A42: Discount Factor | C42: =1/(1+$B$23)^1 -> 0.90909091 | D42: =1/(1+$B$23)^2 -> 0.82644628 | E42: =1/(1+$B$23)^3 -> 0.7513148 | F42: =1/(1+$B$23)^4 -> 0.68301346 | G42: =1/(1+$B$23)^5 -> 0.62092132 | H42: =1/(1+$B$23)^5 -> 0.62092132
A43: PV of Excess Earnings | C43: =C39*C42 -> 42.706818 | D43: =D39*D42 -> 44.648037 | E43: =E39*E42 -> 46.677493 | F43: =F39*F42 -> 48.799198 | G43: =G39*G42 -> 51.017343
A44: PV of Terminal Excess Returns | H44: =H40*H42 -> 750.68376
A46: VALUATION SUMMARY
A47: Current Book Value (€M): | B47: =B21 -> 817
A48: PV of Excess Returns (Years 1-5): | B48: =SUM(C43:G43) -> 233.84889
A49: PV of Terminal Excess Returns: | B49: =H44 -> 750.68376
...

Sheet DCF Valuation
A1: DISCOUNTED CASH FLOW VALUATION
B3: Base | C3: Year 1 | D3: Year 2 | E3: Year 3 | F3: Year 4 | G3: Year 5 | H3: Terminal
B4: FY 2024 | C4: FY 2025E | D4: FY 2026E | E4: FY 2027E | F4: FY 2028E | G4: FY 2029E | H4: TV
A5: REVENUE PROJECTIONS
A6: Total Income (€M) | B6: ='DCF Assumptions'!B4 -> 479.3 | C6: =B6*(1+'DCF Assumptions'!B5) -> 536.816 | D6: =C6*(1+'DCF Assumptions'!B6) -> 579.76128 | E6: =D6*(1+'DCF Assumptions'!B7) -> 614.54696 | F6: =E6*(1+'DCF Assumptions'!B8) -> 645.2743 | G6: =F6*(1+'DCF Assumptions'!B9) -> 671.08528
A7: Growth Rate | B7: - | C7: ='DCF Assumptions'!B5 -> 0.12 | D7: ='DCF Assumptions'!B6 -> 0.08 | E7: ='DCF Assumptions'!B7 -> 0.06 | F7: ='DCF Assumptions'!B8 -> 0.05 | G7: ='DCF Assumptions'!B9 -> 0.04
A9: EBITDA CALCULATION
A10: EBITDA Margin | B10: 0.45 | C10: ='DCF Assumptions'!B12 -> 0.32 | D10: ='DCF Assumptions'!B12 -> 0.32 | E10: ='DCF Assumptions'!B12 -> 0.32 | F10: ='DCF Assumptions'!B12 -> 0.32 | G10: ='DCF Assumptions'!B12 -> 0.32
A11: EBITDA | B11: =B6*B10 -> 215.685 | C11: =C6*C10 -> 171.78112 | D11: =D6*D10 -> 185.52361 | E11: =E6*E10 -> 196.65503 | F11: =F6*F10 -> 206.48778 | G11: =G6*G10 -> 214.74729
A13: FREE CASH FLOW CALCULATION
A14: EBITDA | C14: =C11 -> 171.78112 | D14: =D11 -> 185.52361 | E14: =E11 -> 196.65503 | F14: =F11 -> 206.48778 | G14: =G11 -> 214.74729
A15: Less: D&A | C15: =-C6*'DCF Assumptions'!B13 -> -10.73632 | D15: =-D6*'DCF Assumptions'!B13 -> -11.595226 | E15: =-E6*'DCF Assumptions'!B13 -> -12.290939 | F15: =-F6*'DCF Assumptions'!B13 -> -12.905486 | G15: =-G6*'DCF Assumptions'!B13 -> -13.421706
A16: EBIT | C16: =C14+C15 -> 161.0448 | D16: =D14+D15 -> 173.92838 | E16: =E14+E15 -> 184.36409 | F16: =F14+F15 -> 193.58229 | G16: =G14+G15 -> 201.32558
A17: Less: Taxes | C17: =-C16*'DCF Assumptions'!B14 -> -40.2612 | D17: =-D16*'DCF Assumptions'!B14 -> -43.482096 | E17: =-E16*'DCF Assumptions'!B14 -> -46.091022 | F17: =-F16*'DCF Assumptions'!B14 -> -48.395573 | G17: =-G16*'DCF Assumptions'!B14 -> -50.331396
A18: NOPAT (EBIAT) | C18: =C16+C17 -> 120.7836 | D18: =D16+D17 -> 130.44629 | E18: =E16+E17 -> 138.27307 | F18: =F16+F17 -> 145.18672 | G18: =G16+G17 -> 150.99419
A19: Add: D&A | C19: =-C15 -> 10.73632 | D19: =-D15 -> 11.595226 | E19: =-E15 -> 12.290939 | F19: =-F15 -> 12.905486 | G19: =-G15 -> 13.421706
A20: Less: CapEx | C20: =-C6*'DCF Assumptions'!B15 -> -8.05224 | D20: =-D6*'DCF Assumptions'!B15 -> -8.6964192 | E20: =-E6*'DCF Assumptions'!B15 -> -9.2182044 | F20: =-F6*'DCF Assumptions'!B15 -> -9.6791146 | G20: =-G6*'DCF Assumptions'!B15 -> -10.066279
A21: Less: Change in NWC | C21: =-(C6-B6)*'DCF Assumptions'!B16 -> -2.8758 | D21: =-(D6-C6)*'DCF Assumptions'!B16 -> -2.147264 | E21: =-(E6-D6)*'DCF Assumptions'!B16 -> -1.7392838 | F21: =-(F6-E6)*'DCF Assumptions'!B16 -> -1.5363674 | G21: =-(G6-F6)*'DCF Assumptions'!B16 -> -1.2905486
A22: Unlevered Free Cash Flow | C22: =SUM(C18:C21) -> 120.59188 | D22: =SUM(D18:D21) -> 131.19783 | E22: =SUM(E18:E21) -> 139.60652 | F22: =SUM(F18:F21) -> 146.87672 | G22: =SUM(G18:G21) -> 153.05907
A24: TERMINAL VALUE
A25: Terminal FCF (Year 5 * (1+g)) | H25: =G22*(1+'DCF Assumptions'!B30) -> 157.65084
A26: Terminal Value (Gordon Growth) | H26: =H25/('DCF Assumptions'!B27-'DCF Assumptions'!B30) -> 2564.4707
A28: PRESENT VALUE CALCULATION
A29: WACC | B29: ='DCF Assumptions'!B27 -> 0.091475
A30: Discount Factor | C30: =1/(1+$B$29)^1 -> 0.91619139 | D30: =1/(1+$B$29)^2 -> 0.83940667 | E30: =1/(1+$B$29)^3 -> 0.76905716 | F30: =1/(1+$B$29)^4 -> 0.70460355 | G30: =1/(1+$B$29)^5 -> 0.64555171 | H30: =1/(1+$B$29)^5 -> 0.64555171
A31: PV of FCF | C31: =C22*C30 -> 110.48524 | D31: =D22*D30 -> 110.12833 | E31: =E22*E30 -> 107.36539 | F31: =F22*F30 -> 103.48986 | G31: =G22*G30 -> 98.807541
A32: PV of Terminal Value | H32: =H26*H30 -> 1655.4985
A34: VALUATION SUMMARY
A35: Sum of PV of FCFs | B35: =SUM(C31:G31) -> 530.27637
A36: PV of Terminal Value | B36: =H32 -> 1655.4985
A37: Enterprise Value | B37: =B35+B36 -> 2185.7748
A39: EQUITY VALUE
A40: Enterprise Value | B40: =B37 -> 2185.7748
A41: Less: Net Debt (estimated) | B41: -100 | C41: Flow Traders has net cash position
A42: Equity Value | B42: =B40-B41 -> 2285.7748
A44: Shares Outstanding (M) | B44: 43.56
A45: Implied Share Price (€) | B45: =B42/B44 -> 52.47417
A47: Current Share Price (€) | B47: 26.12
A48: Upside / (Downside) % | B48: =(B45-B47)/B47 -> 1.0089651

Sheet Sensitivity Analysis
A1: SENSITIVITY ANALYSIS
A3: IMPLIED SHARE PRICE SENSITIVITY
A4: WACC vs. Terminal Growth Rate
B6: Terminal Growth Rate
C7: 0.01 | D7: 0.015 | E7: 0.02 | F7: 0.025 | G7: 0.03
A8: WACC
B9: 0.07 | C9: 45.3 | D9: 48.4 | E9: 52.2 | F9: 56.8 | G9: 62.6
B10: 0.08 | C10: 40.6 | D10: 42.9 | E10: 45.6 | F10: 48.8 | G10: 52.6
B11: 0.09 | C11: 37.1 | D11: 38.9 | E11: 40.9 | F11: 43.2 | G11: 45.9
B12: 0.1 | C12: 34.4 | D12: 35.8 | E12: 37.4 | F12: 39.1 | G12: 41.2
B13: 0.11 | C13: 32.2 | D13: 33.4 | E13: 34.6 | F13: 36 | G13: 37.6
B14: 0.12 | C14: 30.4 | D14: 31.4 | E14: 32.4 | F14: 33.6 | G14: 34.8
A18: REVENUE GROWTH SENSITIVITY
A19: Impact of Year 1 Growth Rate on Implied Share Price
B21: Y1 Growth | C21: Implied Price | D21: % Diff
B22: 0.05 | C22: 32 | D22: -20%
B23: 0.08 | C23: 35 | D23: -12%
B24: 0.12 | C24: 40 | D24: Base
B25: 0.15 | C25: 44 | D25: 10%
B26: 0.2 | C26: 50 | D26: 25%
A29: BETA SENSITIVITY
A30: Impact of Beta on WACC and Implied Price
B32: Beta | C32: Cost of Equity | D32: WACC | E32: Implied Price
B33: 0.19 | C33: 0.047 | D33: 0.046 | E33: 79.1
B34: 0.6 | C34: 0.074 | D34: 0.064 | E34: 56.1
B35: 0.9 | C35: 0.093 | D35: 0.078 | E35: 46.3
B36: 1.2 | C36: 0.113 | D36: 0.091 | E36: 39.4
B37: 1.5 | C37: 0.133 | D37: 0.105 | E37: 34.2
A39: NOTE: The reported beta of 0.19 may understate risk. Industry beta typically 0.8-1.2.

Sheet Comparable Analysis
A1: COMPARABLE COMPANY ANALYSIS
A3: SELECTED COMPARABLES
A5: Company | B5: Ticker | C5: Market Cap (€M) | D5: P/E | E5: EV/EBITDA | F5: EV/Revenue | G5: ROE %
A6: Flow Traders | B6: FLOW.AS | C6: 1137 | D6: 6.2 | E6: 5.3 | F6: 1.4 | G6: 24
A7: Virtu Financial | B7: VIRT | C7: 7192 | D7: 8.5 | E7: 6.8 | F7: 2.1 | G7: 32
A8: Citadel Securities* | B8: Private | C8: N/A | D8: N/A | E8: N/A | F8: N/A | G8: N/A
A9: Jane Street* | B9: Private | C9: N/A | D9: N/A | E9: N/A | F9: N/A | G9: N/A
A11: * Private companies - limited public data available
A13: VALUATION SUMMARY
A15: DCF Implied Value (€/share): | B15: ='DCF Valuation'!B45 -> 52.47417
A16: Current Price (€): | B16: 26.12
A17: Upside/(Downside): | B17: =(B15-B16)/B16 -> 1.0089651
A19: MULTIPLE-BASED VALUATION
A20: LTM EPS (€): | B20: 4.21
A21: Industry Average P/E: | B21: 7.5
A22: P/E Implied Value (€): | B22: =B20*B21 -> 31.575
A24: LTM EBITDA (€M): | B24: 280
A25: Industry Average EV/EBITDA: | B25: 6
A26: Implied EV (€M): | B26: =B24*B25 -> 1680
A27: Less: Net Debt (€M): | B27: -100
A28: Implied Equity Value (€M): | B28: =B26-B27 -> 1780
A29: EV/EBITDA Implied Price (€): | B29: =B28/43.56 -> 40.863177
A31: VALUATION RANGE SUMMARY
A33: Methodology | B33: Low | C33: Base | D33: High
A34: DCF Valuation | B34: 28 | C34: ='DCF Valuation'!B45 -> 52.47417 | D34: 45
A35: P/E Multiple | B35: 25 | C35: =B22 -> 31.575 | D35: 38
A36: EV/EBITDA Multiple | B36: 30 | C36: =B29 -> 40.863177 | D36: 42
A38: 52-Week Range | B38: 21.8 | D38: 31.04
A39: Current Price | C39: 26.12

Sheet Risks & Catalysts
A1: INVESTMENT RISKS AND CATALYSTS
A3: KEY RISKS
A5: 1. Market Volatility Dependency
A6: - Profits highly correlated with market volatility (VIX)
A7: - Extended low-volatility periods compress margins significantly
A8: - 2023 showed impact: Net profit dropped 71% YoY in low-vol environment
A10: 2. Competitive Pressure
A11: - Facing competition from larger players (Citadel, Jane Street)
A12: - Technology arms race requires continued investment
A13: - Spread compression in key markets
A15: 3. Regulatory Risk
A16: - Increasing scrutiny of market makers and HFT firms
... A51: - Target 69%+ return on trading capital
