Workbook

Sheet Model_Info
A1: EBOS Group Limited (EBO.NZ / EBO.AX) -- owner-FCF DCF workbook, version 2026-09-08
A2: Supersedes: EBO.NZ_DCF_Model.xlsx of 2026-06-27 (5-yr growth on reported levered FCF, Gordon-only TV, per-scenario WACC).
A3: Built by: dcf-analyst agent (Claude, model claude-fable-5-1) on 2026-09-08 at the request of the research orchestrator (tier-2 refresh after the 19-Aug-2026 FY2026 result).
A4: Figures go stale. Price, FX, net debt and share count are dated below; refresh them before relying on any output.
A6: DATA VINTAGE
A7: Price: NZ$20.48, Yahoo EBO.NZ regular close 2026-09-08T04:59:55Z. Parity: EBO.AX A$16.67 x AUD/NZD 1.231 = NZ$20.52 (0.2%).
A8: FX: AUD/NZD 1.231, Yahoo AUDNZD=X 2026-09-08T05:56:07Z (52wk 1.108-1.233).
A9: Balance sheet: 31-Dec-2025 (H1 FY2026 interim, unaudited) -- bank loans A$1,371.2m, cash A$250.3m, NCI put liability A$57.9m, lease liabilities A$473.9m (excluded, see leases).
A10: Shares: 204.993m on issue 31-Dec-2025 + ~1.3m dilutive rights = 206.3m fully diluted; DRP issuance since Dec-2025 (~2-4m) NOT yet counted.
A11: FY2026 actuals (19-Aug-2026 result, via EBO.NZ_Analysis.json): revenue A$13,481m, underlying EBITDA A$614m, underlying FCF A$241m, reported FCF A$204m, leverage 2.1x. Annual report not yet extracted.
A12: Guidance (19-Aug-2026): FY2027 underlying EBITDA A$635-655m, capex ~A$100m, no M&A assumed.
A14: METHODOLOGY
... A27: CELL COLOURS: blue = hardcoded input; yellow fill = key lever; black = formula; green = cross-sheet link; green fill = headline value.

Sheet Assumptions
A1: Global assumptions (AUD millions unless stated)
A4: WACC (%) | B4: 8.5 | C4: AUD-built: 9.3% CoE (4.3% rf + 5.0% ERP x beta 1.0), 5.8% after-tax Kd, 74/26 -> 8.4%, rounded
A5: D&A ex-ROU (% revenue) | B5: 0.68 | C5: FY2025 PPE dep ~33 + amortisation 46.7 = 0.65%; H1 FY26 annualised 0.65%; DCs commissioned -> 0.68%
A6: Lease cash (% revenue) | B6: 0.65 | C6: principal + interest: FY2025 80.7 (0.66%), H1 FY2026 44.1 (0.65%)
A7: SBC (% revenue) | B7: 0.05 | C7: FY2023-24 run-rate ~A$7m; FY2025/H1 FY26 were reversals
A8: Cash tax rate on EBIT (%) | B8: 28.5 | C8: guided ETR ~28% + non-deductible PPA amortisation
A9: Net debt (bank loans - cash + NCI put), 31-Dec-2025 | B9: 1178.8 | C9: 1,371.2 - 250.3 + 57.9; leases excluded (treatment B)
A10: Diluted shares (m) | B10: 206.3 | C10: 204.993 on issue + ~1.3 dilutive rights; flat
A11: Price (NZD), 2026-09-08 close | B11: 20.48 | C11: Yahoo EBO.NZ regularMarketPrice
A12: AUD/NZD | B12: 1.231 | C12: Yahoo AUDNZD=X 2026-09-08; parity vs EBO.AX 0.2%
A13: Terminal value cap (x owner FCF_10) | B13: 15 | C13: slow-growing distributor; Gordon at 8.5%/2.5% = 17.1x so the cap binds
A14: Hurdle rate for entry price | B14: 0.15 | C14: 15% IRR, TV rebuilt at the hurdle
A15: FY2026 revenue (A$m, actual) | B15: 13481 | C15: 19-Aug-2026 result, +9.9%
... A17: FY2026 capex (A$m, approx) | B17: 145 | C17: final DC renewal year
A20: Per-scenario | B20: Bear | C20: Base | D20: Bull
A21: Terminal growth (%) | B21: 2 | C21: 2.5 | D21: 3
A22: Probability weight | B22: 0.25 | C22: 0.5 | D22: 0.25
A23: Working-capital capture (% of revenue change; negative = outflow) | B23: -4 | C23: -3 | D23: -2.5
A24: Weights check (must be 1.00) | B24: =SUM(B22:D22)
A26: Scenario narratives
A27: Bear | B27: The FY2027 productivity inflection slips: FY2027 EBITDA misses the guide (modelled A$604m, a repeat of the April-2026 fuel-driven downgrade), the New Zealand Chemist Warehouse wholesale contract rolls off at end-CY2026 (management-sized at ~1% of group EBITDA, ~A$6-8m, ~2% of revenue at wholesale margins -- charged as -1.5% revenue growth and -0.15pp of margin in FY2028), and GOR margin compression from 1PWA caps and GLP-1 mix does not reverse, leaving the margin at 4.2-4.3% through the horizon. Post-commissioning IT/optimisation spend keeps capex at 0.75% of revenue and working capital absorbs 4% of revenue growth. Revenue growth 1.5-3%. Terminal growth 2.0%. Leverage stays near the top of the 1.7-2.3x range but there is no going-concern or covenant path here -- the bear is a low-return, no-re-rating distributor, not a solvency case.
A28: Base | B28: FY2027 lands inside the A$635-655m guide (modelled A$647m on +5.5% revenue and a 4.55% margin). The DC program is complete, so capex steps down to the guided ~A$100m (0.71% of revenue) and stays near 0.7% -- roughly equal to ex-ROU D&A -- while Kemps Creek productivity, the July-2026 expanded CSO regime, and faster-growing Retail Pharmacy Brands / MedTech / Animal Care lift the group EBITDA margin from 4.55% to a 4.9% plateau by FY2032 (still below the ~5.0% of FY2021-22, because 1PWA caps and GLP-1/high-value-medicine mix keep compressing GOR margin). Revenue growth decays from 5.5% to 3% as GLP-1 volume growth normalises. Working capital absorbs 3% of each year's revenue increase (~20 cash-conversion days). Terminal value hits the 15x owner-FCF cap; Gordon at 8.5%/2.5% would have paid 17.1x.
A29: Bull | B29: GLP-1 and >A$1,000/dose medicines keep compounding at double digits, Retail Pharmacy Brands (780+ stores, retail media, CareClinics) and MedTech/aesthetics (K-Talyst, Origin Biologics) grow well ahead of group, and Paringa/SVS lift Animal Care -- revenue +7% in FY2027 tapering to 3.5%. FY2027 EBITDA beats the top of the guide (modelled A$666m) and the DC automation payback (30% Kemps Creek uplift) plus mix shift carries the margin to 5.4% by FY2034. Working-capital drag is lighter (2.5% capture) as cash-conversion days keep improving. Terminal growth 3.0%. This needs BOTH the growth and the margin legs to come through; ~A$150m/yr of self-funded bolt-ons are NOT in the numbers and are upside to this case.

Sheet DCF_Bear
A1: Bear scenario -- unlevered owner FCF, AUD millions
A3: Year | B3: FY2026A | C3: FY2027E | D3: FY2028E | E3: FY2029E | F3: FY2030E | G3: FY2031E | H3: FY2032E | I3: FY2033E | J3: FY2034E | K3: FY2035E | L3: FY2036E
A4: Year index | B4: 0 | C4: 1 | D4: 2 | E4: 3 | F4: 4 | G4: 5 | H4: 6 | I4: 7 | J4: 8 | K4: 9 | L4: 10
A5: Revenue growth (%) [driver] | C5: 3 | D5: 1.5 | E5: 2.5 | F5: 3 | G5: 3 | H5: 3 | I5: 2.5 | J5: 2.5 | K5: 2.5 | L5: 2.5
A6: Revenue | B6: =Assumptions!$B$15 | C6: =B6*(1+C5/100) | D6: =C6*(1+D5/100) | E6: =D6*(1+E5/100) | F6: =E6*(1+F5/100) | G6: =F6*(1+G5/100) | H6: =G6*(1+H5/100) | I6: =H6*(1+I5/100) | J6: =I6*(1+J5/100) | ... L6: =K6*(1+L5/100)
A7: Underlying EBITDA margin (%) [driver] | B7: 4.55 | C7: 4.35 | D7: 4.2 | E7: 4.2 | F7: 4.25 | G7: 4.3 | H7: 4.3 | I7: 4.3 | J7: 4.3 | K7: 4.3 | L7: 4.3
A8: Underlying EBITDA | B8: =B6*B7/100 | C8: =C6*C7/100 | D8: =D6*D7/100 | E8: =E6*E7/100 | F8: =F6*F7/100 | G8: =G6*G7/100 | H8: =H6*H7/100 | I8: =I6*I7/100 | ... L8: =L6*L7/100
A9: SBC (% revenue) [driver] | B9: =Assumptions!$B$7 | C9: 0.05 | D9: 0.05 | E9: 0.05 | F9: 0.05 | G9: 0.05 | H9: 0.05 | I9: 0.05 | J9: 0.05 | K9: 0.05 | L9: 0.05
A10: SBC | B10: =-B6*B9/100 | C10: =-C6*C9/100 | D10: =-D6*D9/100 | E10: =-E6*E9/100 | F10: =-F6*F9/100 | G10: =-G6*G9/100 | H10: =-H6*H9/100 | I10: =-I6*I9/100 | ... L10: =-L6*L9/100
A11: Lease cash (% revenue) | B11: =Assumptions!$B$6 | C11: =Assumptions!$B$6 | D11: =Assumptions!$B$6 | E11: =Assumptions!$B$6 | F11: =Assumptions!$B$6 | G11: =Assumptions!$B$6 | H11: =Assumptions!$B$6 | I11: =Assumptions!$B$6 | ... L11: =Assumptions!$B$6
A12: Lease cash (principal + interest) | B12: =-B6*B11/100 | C12: =-C6*C11/100 | D12: =-D6*D11/100 | E12: =-E6*E11/100 | F12: =-F6*F11/100 | G12: =-G6*G11/100 | H12: =-H6*H11/100 | I12: =-I6*I11/100 | ... L12: =-L6*L11/100
A13: Owner EBITDA (after SBC and leases) | B13: =B8+B10+B12 | C13: =C8+C10+C12 | D13: =D8+D10+D12 | E13: =E8+E10+E12 | F13: =F8+F10+F12 | G13: =G8+G10+G12 | H13: =H8+H10+H12 | I13: =I8+I10+I12 | ... L13: =L8+L10+L12
A14: D&A ex-ROU | B14: =-B6*Assumptions!$B$5/100 | C14: =-C6*Assumptions!$B$5/100 | D14: =-D6*Assumptions!$B$5/100 | E14: =-E6*Assumptions!$B$5/100 | F14: =-F6*Assumptions!$B$5/100 | G14: =-G6*Assumptions!$B$5/100 | H14: =-H6*Assumptions!$B$5/100 | I14: =-I6*Assumptions!$B$5/100 | ... L14: =-L6*Assumptions!$B$5/100
A15: EBIT | B15: =B13+B14 | C15: =C13+C14 | D15: =D13+D14 | E15: =E13+E14 | F15: =F13+F14 | G15: =G13+G14 | H15: =H13+H14 | I15: =I13+I14 | ... L15: =L13+L14
A16: Cash tax rate on EBIT (%) [driver] | B16: =Assumptions!$B$8 | C16: 28.5 | D16: 28.5 | E16: 28.5 | F16: 28.5 | G16: 28.5 | H16: 28.5 | I16: 28.5 | J16: 28.5 | K16: 28.5 | L16: 28.5
A17: NOPAT | B17: =B15-MAX(0,B15)*B16/100 | C17: =C15-MAX(0,C15)*C16/100 | D17: =D15-MAX(0,D15)*D16/100 | E17: =E15-MAX(0,E15)*E16/100 | F17: =F15-MAX(0,F15)*F16/100 | G17: =G15-MAX(0,G15)*G16/100 | H17: =H15-MAX(0,H15)*H16/100 | I17: =I15-MAX(0,I15)*I16/100 | ... L17: =L15-MAX(0,L15)*L16/100
A18: add back D&A | B18: =-B14 | C18: =-C14 | D18: =-D14 | E18: =-E14 | F18: =-F14 | G18: =-G14 | H18: =-H14 | I18: =-I14 | ... L18: =-L14
A19: Capex (% revenue) [driver] | B19: =Assumptions!$B$17/B6*100 | C19: 0.75 | D19: 0.75 | E19: 0.75 | F19: 0.75 | G19: 0.75 | H19: 0.75 | I19: 0.75 | J19: 0.75 | K19: 0.75 | L19: 0.75
A20: Capex | B20: =-B6*B19/100 | C20: =-C6*C19/100 | D20: =-D6*D19/100 | E20: =-E6*E19/100 | F20: =-F6*F19/100 | G20: =-G6*G19/100 | H20: =-H6*H19/100 | I20: =-I6*I19/100 | ... L20: =-L6*L19/100
A21: Working-capital build (capture x revenue change) | B21: -7 | C21: =Assumptions!$B$23/100*(C6-B6) | D21: =Assumptions!$B$23/100*(D6-C6) | E21: =Assumptions!$B$23/100*(E6-D6) | F21: =Assumptions!$B$23/100*(F6-E6) | G21: =Assumptions!$B$23/100*(G6-F6) | H21: =Assumptions!$B$23/100*(H6-G6) | I21: =Assumptions!$B$23/100*(I6-H6) | J21: =Assumptions!$B$23/100*(J6-I6) | ... L21: =Assumptions!$B$23/100*(L6-K6)
A22: Unlevered owner FCF | B22: =B17+B18+B20+B21 | C22: =C17+C18+C20+C21 | D22: =D17+D18+D20+D21 | E22: =E17+E18+E20+E21 | F22: =F17+F18+F20+F21 | G22: =G17+G18+G20+G21 | H22: =H17+H18+H20+H21 | I22: =I17+I18+I20+I21 | ... L22: =L17+L18+L20+L21
A23: Discount factor | C23: =1/(1+Assumptions!$B$4/100)^C4 | D23: =1/(1+Assumptions!$B$4/100)^D4 | E23: =1/(1+Assumptions!$B$4/100)^E4 | F23: =1/(1+Assumptions!$B$4/100)^F4 | G23: =1/(1+Assumptions!$B$4/100)^G4 | H23: =1/(1+Assumptions!$B$4/100)^H4 | I23: =1/(1+Assumptions!$B$4/100)^I4 | J23: =1/(1+Assumptions!$B$4/100)^J4 | ... L23: =1/(1+Assumptions!$B$4/100)^L4
A24: PV of owner FCF | C24: =C22*C23 | D24: =D22*D23 | E24: =E22*E23 | F24: =F22*F23 | G24: =G22*G23 | H24: =H22*H23 | I24: =I22*I23 | J24: =J22*J23 | ... L24: =L22*L23
A26: Memo: FCF before SBC (street style) | B26: =B22-B10 | C26: =C22-C10 | D26: =D22-D10 | E26: =E22-E10 | F26: =F22-F10 | G26: =G22-G10 | H26: =H22-H10 | I26: =I22-I10 | ... L26: =L22-L10
A27: Memo: owner FCF margin (%) | B27: =B22/B6*100 | C27: =C22/C6*100 | D27: =D22/D6*100 | E27: =E22/E6*100 | F27: =F22/F6*100 | G27: =G22/G6*100 | H27: =H22/H6*100 | I27: =I22/I6*100 | ... L27: =L22/L6*100
A29: Sum of PV (explicit years) | B29: =SUM(C24:L24)
A30: Terminal growth (%) | B30: =Assumptions!$B$21
A31: Terminal-year FCF x (1+g) | B31: =L22*(1+B30/100)
A32: Gordon TV | B32: =IF(Assumptions!$B$4>B30,B31/((Assumptions!$B$4-B30)/100),"n/a")
A33: Cap TV (cap x FCF_10) | B33: =Assumptions!$B$13*L22
A34: Terminal value used = MAX(0,MIN(Gordon,cap)) | B34: =MAX(0,MIN(B32,B33))
A35: Implied exit multiple (TV / FCF_10) | B35: =B34/L22
A36: PV of terminal value | B36: =B34*L23
A37: Enterprise value | B37: =B29+B36
A38: less net debt (bank + NCI put; leases excluded) | B38: =-Assumptions!$B$9
A39: Equity value | B39: =B37+B38
A40: Diluted shares (m) | B40: =Assumptions!$B$10
A41: Value per share (AUD) | B41: =B39/B40
A42: Value per share (NZD) | B42: =B41*Assumptions!$B$12
A43: Upside vs price (%) | B43: =(B42/Assumptions!$B$11-1)*100
...

Sheet DCF_Base
A1: Base scenario -- unlevered owner FCF, AUD millions
A3: Year | B3: FY2026A | C3: FY2027E | D3: FY2028E | E3: FY2029E | F3: FY2030E | G3: FY2031E | H3: FY2032E | I3: FY2033E | J3: FY2034E | K3: FY2035E | L3: FY2036E
A4: Year index | B4: 0 | C4: 1 | D4: 2 | E4: 3 | F4: 4 | G4: 5 | H4: 6 | I4: 7 | J4: 8 | K4: 9 | L4: 10
A5: Revenue growth (%) [driver] | C5: 5.5 | D5: 5 | E5: 4.5 | F5: 4.5 | G5: 4 | H5: 4 | I5: 3.5 | J5: 3.5 | K5: 3 | L5: 3
A6: Revenue | B6: =Assumptions!$B$15 | C6: =B6*(1+C5/100) | D6: =C6*(1+D5/100) | E6: =D6*(1+E5/100) | F6: =E6*(1+F5/100) | G6: =F6*(1+G5/100) | H6: =G6*(1+H5/100) | I6: =H6*(1+I5/100) | J6: =I6*(1+J5/100) | ... L6: =K6*(1+L5/100)
A7: Underlying EBITDA margin (%) [driver] | B7: 4.55 | C7: 4.55 | D7: 4.65 | E7: 4.75 | F7: 4.8 | G7: 4.85 | H7: 4.9 | I7: 4.9 | J7: 4.9 | K7: 4.9 | L7: 4.9
A8: Underlying EBITDA | B8: =B6*B7/100 | C8: =C6*C7/100 | D8: =D6*D7/100 | E8: =E6*E7/100 | F8: =F6*F7/100 | G8: =G6*G7/100 | H8: =H6*H7/100 | I8: =I6*I7/100 | ... L8: =L6*L7/100
A9: SBC (% revenue) [driver] | B9: =Assumptions!$B$7 | C9: 0.05 | D9: 0.05 | E9: 0.05 | F9: 0.05 | G9: 0.05 | H9: 0.05 | I9: 0.05 | J9: 0.05 | K9: 0.05 | L9: 0.05
A10: SBC | B10: =-B6*B9/100 | C10: =-C6*C9/100 | D10: =-D6*D9/100 | E10: =-E6*E9/100 | F10: =-F6*F9/100 | G10: =-G6*G9/100 | H10: =-H6*H9/100 | I10: =-I6*I9/100 | ... L10: =-L6*L9/100
A11: Lease cash (% revenue) | B11: =Assumptions!$B$6 | C11: =Assumptions!$B$6 | D11: =Assumptions!$B$6 | E11: =Assumptions!$B$6 | F11: =Assumptions!$B$6 | G11: =Assumptions!$B$6 | H11: =Assumptions!$B$6 | I11: =Assumptions!$B$6 | ... L11: =Assumptions!$B$6
A12: Lease cash (principal + interest) | B12: =-B6*B11/100 | C12: =-C6*C11/100 | D12: =-D6*D11/100 | E12: =-E6*E11/100 | F12: =-F6*F11/100 | G12: =-G6*G11/100 | H12: =-H6*H11/100 | I12: =-I6*I11/100 | ... L12: =-L6*L11/100
A13: Owner EBITDA (after SBC and leases) | B13: =B8+B10+B12 | C13: =C8+C10+C12 | D13: =D8+D10+D12 | E13: =E8+E10+E12 | F13: =F8+F10+F12 | G13: =G8+G10+G12 | H13: =H8+H10+H12 | I13: =I8+I10+I12 | ... L13: =L8+L10+L12
A14: D&A ex-ROU | B14: =-B6*Assumptions!$B$5/100 | C14: =-C6*Assumptions!$B$5/100 | D14: =-D6*Assumptions!$B$5/100 | E14: =-E6*Assumptions!$B$5/100 | F14: =-F6*Assumptions!$B$5/100 | G14: =-G6*Assumptions!$B$5/100 | H14: =-H6*Assumptions!$B$5/100 | I14: =-I6*Assumptions!$B$5/100 | ... L14: =-L6*Assumptions!$B$5/100
A15: EBIT | B15: =B13+B14 | C15: =C13+C14 | D15: =D13+D14 | E15: =E13+E14 | F15: =F13+F14 | G15: =G13+G14 | H15: =H13+H14 | I15: =I13+I14 | ... L15: =L13+L14
A16: Cash tax rate on EBIT (%) [driver] | B16: =Assumptions!$B$8 | C16: 28.5 | D16: 28.5 | E16: 28.5 | F16: 28.5 | G16: 28.5 | H16: 28.5 | I16: 28.5 | J16: 28.5 | K16: 28.5 | L16: 28.5
A17: NOPAT | B17: =B15-MAX(0,B15)*B16/100 | C17: =C15-MAX(0,C15)*C16/100 | D17: =D15-MAX(0,D15)*D16/100 | E17: =E15-MAX(0,E15)*E16/100 | F17: =F15-MAX(0,F15)*F16/100 | G17: =G15-MAX(0,G15)*G16/100 | H17: =H15-MAX(0,H15)*H16/100 | I17: =I15-MAX(0,I15)*I16/100 | ... L17: =L15-MAX(0,L15)*L16/100
A18: add back D&A | B18: =-B14 | C18: =-C14 | D18: =-D14 | E18: =-E14 | F18: =-F14 | G18: =-G14 | H18: =-H14 | I18: =-I14 | ... L18: =-L14
A19: Capex (% revenue) [driver] | B19: =Assumptions!$B$17/B6*100 | C19: 0.71 | D19: 0.7 | E19: 0.7 | F19: 0.7 | G19: 0.7 | H19: 0.7 | I19: 0.7 | J19: 0.7 | K19: 0.7 | L19: 0.7
A20: Capex | B20: =-B6*B19/100 | C20: =-C6*C19/100 | D20: =-D6*D19/100 | E20: =-E6*E19/100 | F20: =-F6*F19/100 | G20: =-G6*G19/100 | H20: =-H6*H19/100 | I20: =-I6*I19/100 | ... L20: =-L6*L19/100
A21: Working-capital build (capture x revenue change) | B21: -7 | C21: =Assumptions!$C$23/100*(C6-B6) | D21: =Assumptions!$C$23/100*(D6-C6) | E21: =Assumptions!$C$23/100*(E6-D6) | F21: =Assumptions!$C$23/100*(F6-E6) | G21: =Assumptions!$C$23/100*(G6-F6) | H21: =Assumptions!$C$23/100*(H6-G6) | I21: =Assumptions!$C$23/100*(I6-H6) | J21: =Assumptions!$C$23/100*(J6-I6) | ... L21: =Assumptions!$C$23/100*(L6-K6)
A22: Unlevered owner FCF | B22: =B17+B18+B20+B21 | C22: =C17+C18+C20+C21 | D22: =D17+D18+D20+D21 | E22: =E17+E18+E20+E21 | F22: =F17+F18+F20+F21 | G22: =G17+G18+G20+G21 | H22: =H17+H18+H20+H21 | I22: =I17+I18+I20+I21 | ... L22: =L17+L18+L20+L21
A23: Discount factor | C23: =1/(1+Assumptions!$B$4/100)^C4 | D23: =1/(1+Assumptions!$B$4/100)^D4 | E23: =1/(1+Assumptions!$B$4/100)^E4 | F23: =1/(1+Assumptions!$B$4/100)^F4 | G23: =1/(1+Assumptions!$B$4/100)^G4 | H23: =1/(1+Assumptions!$B$4/100)^H4 | I23: =1/(1+Assumptions!$B$4/100)^I4 | J23: =1/(1+Assumptions!$B$4/100)^J4 | ... L23: =1/(1+Assumptions!$B$4/100)^L4
A24: PV of owner FCF | C24: =C22*C23 | D24: =D22*D23 | E24: =E22*E23 | F24: =F22*F23 | G24: =G22*G23 | H24: =H22*H23 | I24: =I22*I23 | J24: =J22*J23 | ... L24: =L22*L23
A26: Memo: FCF before SBC (street style) | B26: =B22-B10 | C26: =C22-C10 | D26: =D22-D10 | E26: =E22-E10 | F26: =F22-F10 | G26: =G22-G10 | H26: =H22-H10 | I26: =I22-I10 | ... L26: =L22-L10
A27: Memo: owner FCF margin (%) | B27: =B22/B6*100 | C27: =C22/C6*100 | D27: =D22/D6*100 | E27: =E22/E6*100 | F27: =F22/F6*100 | G27: =G22/G6*100 | H27: =H22/H6*100 | I27: =I22/I6*100 | ... L27: =L22/L6*100
A29: Sum of PV (explicit years) | B29: =SUM(C24:L24)
A30: Terminal growth (%) | B30: =Assumptions!$C$21
A31: Terminal-year FCF x (1+g) | B31: =L22*(1+B30/100)
A32: Gordon TV | B32: =IF(Assumptions!$B$4>B30,B31/((Assumptions!$B$4-B30)/100),"n/a")
A33: Cap TV (cap x FCF_10) | B33: =Assumptions!$B$13*L22
A34: Terminal value used = MAX(0,MIN(Gordon,cap)) | B34: =MAX(0,MIN(B32,B33))
A35: Implied exit multiple (TV / FCF_10) | B35: =B34/L22
A36: PV of terminal value | B36: =B34*L23
A37: Enterprise value | B37: =B29+B36
A38: less net debt (bank + NCI put; leases excluded) | B38: =-Assumptions!$B$9
A39: Equity value | B39: =B37+B38
A40: Diluted shares (m) | B40: =Assumptions!$B$10
A41: Value per share (AUD) | B41: =B39/B40
A42: Value per share (NZD) | B42: =B41*Assumptions!$B$12
A43: Upside vs price (%) | B43: =(B42/Assumptions!$B$11-1)*100
...

Sheet DCF_Bull
A1: Bull scenario -- unlevered owner FCF, AUD millions
A3: Year | B3: FY2026A | C3: FY2027E | D3: FY2028E | E3: FY2029E | F3: FY2030E | G3: FY2031E | H3: FY2032E | I3: FY2033E | J3: FY2034E | K3: FY2035E | L3: FY2036E
A4: Year index | B4: 0 | C4: 1 | D4: 2 | E4: 3 | F4: 4 | G4: 5 | H4: 6 | I4: 7 | J4: 8 | K4: 9 | L4: 10
A5: Revenue growth (%) [driver] | C5: 7 | D5: 6.5 | E5: 6 | F5: 5.5 | G5: 5 | H5: 4.5 | I5: 4 | J5: 4 | K5: 3.5 | L5: 3.5
A6: Revenue | B6: =Assumptions!$B$15 | C6: =B6*(1+C5/100) | D6: =C6*(1+D5/100) | E6: =D6*(1+E5/100) | F6: =E6*(1+F5/100) | G6: =F6*(1+G5/100) | H6: =G6*(1+H5/100) | I6: =H6*(1+I5/100) | J6: =I6*(1+J5/100) | ... L6: =K6*(1+L5/100)
A7: Underlying EBITDA margin (%) [driver] | B7: 4.55 | C7: 4.62 | D7: 4.8 | E7: 4.95 | F7: 5.1 | G7: 5.2 | H7: 5.3 | I7: 5.35 | J7: 5.4 | K7: 5.4 | L7: 5.4
A8: Underlying EBITDA | B8: =B6*B7/100 | C8: =C6*C7/100 | D8: =D6*D7/100 | E8: =E6*E7/100 | F8: =F6*F7/100 | G8: =G6*G7/100 | H8: =H6*H7/100 | I8: =I6*I7/100 | ... L8: =L6*L7/100
A9: SBC (% revenue) [driver] | B9: =Assumptions!$B$7 | C9: 0.05 | D9: 0.05 | E9: 0.05 | F9: 0.05 | G9: 0.05 | H9: 0.05 | I9: 0.05 | J9: 0.05 | K9: 0.05 | L9: 0.05
A10: SBC | B10: =-B6*B9/100 | C10: =-C6*C9/100 | D10: =-D6*D9/100 | E10: =-E6*E9/100 | F10: =-F6*F9/100 | G10: =-G6*G9/100 | H10: =-H6*H9/100 | I10: =-I6*I9/100 | ... L10: =-L6*L9/100
A11: Lease cash (% revenue) | B11: =Assumptions!$B$6 | C11: =Assumptions!$B$6 | D11: =Assumptions!$B$6 | E11: =Assumptions!$B$6 | F11: =Assumptions!$B$6 | G11: =Assumptions!$B$6 | H11: =Assumptions!$B$6 | I11: =Assumptions!$B$6 | ... L11: =Assumptions!$B$6
A12: Lease cash (principal + interest) | B12: =-B6*B11/100 | C12: =-C6*C11/100 | D12: =-D6*D11/100 | E12: =-E6*E11/100 | F12: =-F6*F11/100 | G12: =-G6*G11/100 | H12: =-H6*H11/100 | I12: =-I6*I11/100 | ... L12: =-L6*L11/100
A13: Owner EBITDA (after SBC and leases) | B13: =B8+B10+B12 | C13: =C8+C10+C12 | D13: =D8+D10+D12 | E13: =E8+E10+E12 | F13: =F8+F10+F12 | G13: =G8+G10+G12 | H13: =H8+H10+H12 | I13: =I8+I10+I12 | ... L13: =L8+L10+L12
A14: D&A ex-ROU | B14: =-B6*Assumptions!$B$5/100 | C14: =-C6*Assumptions!$B$5/100 | D14: =-D6*Assumptions!$B$5/100 | E14: =-E6*Assumptions!$B$5/100 | F14: =-F6*Assumptions!$B$5/100 | G14: =-G6*Assumptions!$B$5/100 | H14: =-H6*Assumptions!$B$5/100 | I14: =-I6*Assumptions!$B$5/100 | ... L14: =-L6*Assumptions!$B$5/100
A15: EBIT | B15: =B13+B14 | C15: =C13+C14 | D15: =D13+D14 | E15: =E13+E14 | F15: =F13+F14 | G15: =G13+G14 | H15: =H13+H14 | I15: =I13+I14 | ... L15: =L13+L14
A16: Cash tax rate on EBIT (%) [driver] | B16: =Assumptions!$B$8 | C16: 28.5 | D16: 28.5 | E16: 28.5 | F16: 28.5 | G16: 28.5 | H16: 28.5 | I16: 28.5 | J16: 28.5 | K16: 28.5 | L16: 28.5
A17: NOPAT | B17: =B15-MAX(0,B15)*B16/100 | C17: =C15-MAX(0,C15)*C16/100 | D17: =D15-MAX(0,D15)*D16/100 | E17: =E15-MAX(0,E15)*E16/100 | F17: =F15-MAX(0,F15)*F16/100 | G17: =G15-MAX(0,G15)*G16/100 | H17: =H15-MAX(0,H15)*H16/100 | I17: =I15-MAX(0,I15)*I16/100 | ... L17: =L15-MAX(0,L15)*L16/100
A18: add back D&A | B18: =-B14 | C18: =-C14 | D18: =-D14 | E18: =-E14 | F18: =-F14 | G18: =-G14 | H18: =-H14 | I18: =-I14 | ... L18: =-L14
A19: Capex (% revenue) [driver] | B19: =Assumptions!$B$17/B6*100 | C19: 0.71 | D19: 0.7 | E19: 0.7 | F19: 0.7 | G19: 0.7 | H19: 0.7 | I19: 0.7 | J19: 0.7 | K19: 0.7 | L19: 0.7
A20: Capex | B20: =-B6*B19/100 | C20: =-C6*C19/100 | D20: =-D6*D19/100 | E20: =-E6*E19/100 | F20: =-F6*F19/100 | G20: =-G6*G19/100 | H20: =-H6*H19/100 | I20: =-I6*I19/100 | ... L20: =-L6*L19/100
A21: Working-capital build (capture x revenue change) | B21: -7 | C21: =Assumptions!$D$23/100*(C6-B6) | D21: =Assumptions!$D$23/100*(D6-C6) | E21: =Assumptions!$D$23/100*(E6-D6) | F21: =Assumptions!$D$23/100*(F6-E6) | G21: =Assumptions!$D$23/100*(G6-F6) | H21: =Assumptions!$D$23/100*(H6-G6) | I21: =Assumptions!$D$23/100*(I6-H6) | J21: =Assumptions!$D$23/100*(J6-I6) | ... L21: =Assumptions!$D$23/100*(L6-K6)
A22: Unlevered owner FCF | B22: =B17+B18+B20+B21 | C22: =C17+C18+C20+C21 | D22: =D17+D18+D20+D21 | E22: =E17+E18+E20+E21 | F22: =F17+F18+F20+F21 | G22: =G17+G18+G20+G21 | H22: =H17+H18+H20+H21 | I22: =I17+I18+I20+I21 | ... L22: =L17+L18+L20+L21
A23: Discount factor | C23: =1/(1+Assumptions!$B$4/100)^C4 | D23: =1/(1+Assumptions!$B$4/100)^D4 | E23: =1/(1+Assumptions!$B$4/100)^E4 | F23: =1/(1+Assumptions!$B$4/100)^F4 | G23: =1/(1+Assumptions!$B$4/100)^G4 | H23: =1/(1+Assumptions!$B$4/100)^H4 | I23: =1/(1+Assumptions!$B$4/100)^I4 | J23: =1/(1+Assumptions!$B$4/100)^J4 | ... L23: =1/(1+Assumptions!$B$4/100)^L4
A24: PV of owner FCF | C24: =C22*C23 | D24: =D22*D23 | E24: =E22*E23 | F24: =F22*F23 | G24: =G22*G23 | H24: =H22*H23 | I24: =I22*I23 | J24: =J22*J23 | ... L24: =L22*L23
A26: Memo: FCF before SBC (street style) | B26: =B22-B10 | C26: =C22-C10 | D26: =D22-D10 | E26: =E22-E10 | F26: =F22-F10 | G26: =G22-G10 | H26: =H22-H10 | I26: =I22-I10 | ... L26: =L22-L10
A27: Memo: owner FCF margin (%) | B27: =B22/B6*100 | C27: =C22/C6*100 | D27: =D22/D6*100 | E27: =E22/E6*100 | F27: =F22/F6*100 | G27: =G22/G6*100 | H27: =H22/H6*100 | I27: =I22/I6*100 | ... L27: =L22/L6*100
A29: Sum of PV (explicit years) | B29: =SUM(C24:L24)
A30: Terminal growth (%) | B30: =Assumptions!$D$21
A31: Terminal-year FCF x (1+g) | B31: =L22*(1+B30/100)
A32: Gordon TV | B32: =IF(Assumptions!$B$4>B30,B31/((Assumptions!$B$4-B30)/100),"n/a")
A33: Cap TV (cap x FCF_10) | B33: =Assumptions!$B$13*L22
A34: Terminal value used = MAX(0,MIN(Gordon,cap)) | B34: =MAX(0,MIN(B32,B33))
A35: Implied exit multiple (TV / FCF_10) | B35: =B34/L22
A36: PV of terminal value | B36: =B34*L23
A37: Enterprise value | B37: =B29+B36
A38: less net debt (bank + NCI put; leases excluded) | B38: =-Assumptions!$B$9
A39: Equity value | B39: =B37+B38
A40: Diluted shares (m) | B40: =Assumptions!$B$10
A41: Value per share (AUD) | B41: =B39/B40
A42: Value per share (NZD) | B42: =B41*Assumptions!$B$12
A43: Upside vs price (%) | B43: =(B42/Assumptions!$B$11-1)*100
...

Sheet FCF_Quality
A1: Reported FCF reconciled to owner FCF (levered, company basis), AUD millions
B3: FY2020 | C3: FY2021 | D3: FY2022 | E3: FY2023 | F3: FY2024 | G3: FY2025 | H3: FY2026
A4: Revenue | B4: 8765.5 | C4: 9202.9 | D4: 10734.1 | E4: 12237.4 | F4: 13189.1 | G4: 12266.9 | H4: 13481
A5: Free cash flow (company: OCF - capex) | B5: 205 | C5: 221.2 | D5: 167 | E5: 297.4 | F5: 252.3 | G5: 293.4 | H5: 204
A6: less: IFRS-16 lease principal (financing) | B6: 32 | C6: 35.3 | D6: 40.9 | E6: 49 | F6: 68.6 | G6: 56.6 | H6: 61
A7: less: SBC (equity-settled; negative = reversal) | B7: 2.7 | C7: 3.7 | D7: 0.9 | E7: 5 | F7: 9.1 | G7: -0.9 | H7: 0
A8: Owner FCF (levered) | B8: =B5-B6-B7 | C8: =C5-C6-C7 | D8: =D5-D6-D7 | E8: =E5-E6-E7 | F8: =F5-F6-F7 | G8: =G5-G6-G7 | H8: =H5-H6-H7
A9: Reported FCF margin (%) | B9: =B5/B4*100 | C9: =C5/C4*100 | D9: =D5/D4*100 | E9: =E5/E4*100 | F9: =F5/F4*100 | G9: =G5/G4*100 | H9: =H5/H4*100
A10: Owner FCF margin (%) | B10: =B8/B4*100 | C10: =C8/C4*100 | D10: =D8/D4*100 | E10: =E8/E4*100 | F10: =F8/F4*100 | G10: =G8/G4*100 | H10: =H8/H4*100
A11: Memo: interest paid (inside OCF) -- the forward model is UNLEVERED and does not deduct this | F11: 100.9 | G11: 113.5 | H11: 120
A12: Memo: notes | B12: FY2025 includes a ~A$75m one-off Chemist Warehouse working-capital release; FY2026 reported FCF A$204m vs underlying A$241m (one-off DC transition cash costs); FY2026 lease principal estimated as H1 x2; FY2026 SBC set to 0 (H1 was a A$3.6m benefit).
A14: Sources: cash-flow statements EBO.NZ_Annual_FY2021-FY2025.txt (repayment of lease liabilities, share-based payments), H1 FY2026 interim; FY2026 from the 19-Aug-2026 result.

Sheet Actuals
A1: Reported history (EBO.NZ_Metrics.csv, AUD millions from FY2019; EPS in AUD) and FY2026 result / guidance
B3: FY2019 | C3: FY2020 | D3: FY2021 | E3: FY2022 | F3: FY2023 | G3: FY2024 | H3: H1 FY2025 | I3: FY2025 | J3: H1 FY2026 | K3: FY2026 (result)
A4: Revenue | B4: 6930.4 | C4: 8765.5 | D4: 9202.9 | E4: 10734.1 | F4: 12237.4 | G4: 13189.1 | H4: 5991.4 | I4: 12266.9 | J4: 6767.7 | K4: 13481
A5: EBITDA (statutory; FY2026 = underlying) | B5: 250.4 | C5: 333.6 | D5: 363.3 | E5: 405.8 | F5: 568.8 | G5: 605.6 | H5: 275.8 | I5: 555.6 | J5: 302.7 | K5: 614
A6: Net income (attributable; FY2026 statutory) | B6: 136.7 | C6: 161.5 | D6: 184 | E6: 202 | F6: 263.4 | G6: 271.5 | H6: 110.5 | I6: 215.1 | J6: 124.8 | K6: 225
A7: Operating cash flow | B7: 118.5 | C7: 229.2 | D7: 298.3 | E7: 248.7 | F7: 391.4 | G7: 348.2 | H7: 189.8 | I7: 418.5 | J7: 46.6
A8: Free cash flow (reported) | B8: 85.5 | C8: 205 | D8: 221.2 | E8: 167 | F8: 297.4 | G8: 252.3 | H8: 126 | I8: 293.4 | J8: -24 | K8: 204
A9: Shareholders' equity | B9: 1239.3 | C9: 1310.9 | D9: 1659.3 | E9: 1918.8 | F9: 2303.4 | G9: 2451 | H9: 2481.1 | I9: 2739.6 | J9: 2751.4
A10: Bank debt (ex leases) | B10: 521.6 | C10: 875.1 | D10: 1146.9 | E10: 1432 | F10: 1646 | G10: 1235.8 | H10: 1302.6 | I10: 1102.5 | J10: 1371.2
A11: Cash | B11: 130.8 | C11: 183.5 | D11: 264.3 | E11: 342.5 | F11: 211.9 | G11: 216.9 | H11: 237.9 | I11: 184.3 | J11: 250.3
A12: Shares outstanding (m) | B12: 152.2 | C12: 160.6 | D12: 162.6 | E12: 176.4 | F12: 198.2 | G12: 192.2 | H12: 194.7 | I12: 196.1 | J12: 205
A13: EPS (AUD) | B13: 0.898 | C13: 1.006 | D13: 1.132 | E13: 1.145 | F13: 1.329 | G13: 1.413 | H13: 0.569 | I13: 1.097 | J13: 0.611
A16: Balance-sheet snapshot 31-Dec-2025 (H1 FY2026 interim)
A17: Bank loans (current + non-current) | B17: 1371.2
A18: Cash and cash equivalents | B18: 250.3
A19: Lease liabilities (current + non-current) -- EXCLUDED from net debt | B19: 473.9
A20: Other financial liabilities: put options over NCI | B20: 57.9
A21: Non-controlling interests (equity, negative under put accounting) | B21: -48.1
A22: Shares on issue (m) | B22: 204.993
A23: Dilutive rights est. (m) | B23: 1.3
A24: FY2026 leverage (company, pre-IFRS16) | B24: 2.1x
A26: Guidance (19-Aug-2026)
A27: FY2027 underlying EBITDA (A$m) | B27: 635-655
A28: FY2027 capex (A$m) | B28: ~100
A29: FY2027 M&A in guidance | B29: none; ~A$150m capacity
A30: Dividend | B30: 60-80% of underlying NPAT; FY2026 total NZ$1.185
A31: NZ Chemist Warehouse wholesale contract | B31: rolls off end-CY2026; ~1% of group EBITDA
A33: Buybacks: none. Share issuance: DRP each dividend (~40% participation), FY2025 A$254m placement + retail offer.

Sheet Reconciliation
A1: Reconciliation to the 2026-06-27 DCF (NZD per share; AUD in column C)
A3: Prior version (2026-06-27, price NZ$20.65, AUD/NZD 1.10) | B3: NZD | C3: AUD
A4: Bear | B4: 11.07 | C4: 10.06
A5: Base | B5: 24.43 | C5: 22.21
A6: Bull | B6: 36.59 | C6: 33.26
A7: Weighted | B7: 24.13 | C7: 21.94
A9: Current version (live links)
A10: Bear | B10: =DCF_Bear!B42 | C10: =DCF_Bear!B41
A11: Base | B11: =DCF_Base!B42 | C11: =DCF_Base!B41
A12: Bull | B12: =DCF_Bull!B42 | C12: =DCF_Bull!B41
A13: Weighted | B13: =Valuation!B9 | C13: =Valuation!C9
A15: Bridge (approximate, hardcoded from the JSON; live cells above are authoritative)
A16: Prior weighted IV (2026-06-27, price NZ$20.65, AUD/NZD 1.10) | B16: 24.13 | C16: 21.94
A17: Flows rebuilt: unlevered component build from FY2026 actuals (EBITDA 614 -> FY27 guide 645), lease cash charged in the flows (treatment B), interest no longer deducted from FCF, FY27 capex ~A$100m -- on the prior 5-yr Gordon frame and prior WACCs | B17: -1.56 | C17: -1.42
A18: Horizon 5 -> 10 years and terminal value capped at 15x owner FCF (Gordon exceeded the cap in every scenario) | B18: -0.06 | C18: -0.05
A19: Single 8.5% AUD WACC in all scenarios (prior 9.0/8.5/10.5 charged risk in both the flows and the rate) | B19: 1.76 | C19: 1.6
A20: Anchors: diluted shares 205.0 -> 206.3m, NCI put liability A$57.9m added to the net-debt bridge | B20: -0.46 | C20: -0.42
A21: AUD/NZD 1.10 -> 1.231 (Yahoo AUDNZD=X 2026-09-08; NZD weakened) | B21: 2.84 | C21: 0
A22: New weighted IV | B22: 26.65 | C22: 21.65

Sheet Valuation
A1: Valuation summary
A3: Scenario | B3: Value/share NZD | C3: Value/share AUD | D3: Upside % | E3: Weight | F3: Street NZD | G3: Entry NZD @hurdle | H3: Entry AUD
A4: Bear | B4: =DCF_Bear!B42 | C4: =DCF_Bear!B41 | D4: =(B4/Assumptions!$B$11-1)*100 | E4: =Assumptions!B22 | F4: =DCF_Bear!B50 | G4: =DCF_Bear!B57 | H4: =DCF_Bear!B56
A5: Base | B5: =DCF_Base!B42 | C5: =DCF_Base!B41 | D5: =(B5/Assumptions!$B$11-1)*100 | E5: =Assumptions!C22 | F5: =DCF_Base!B50 | G5: =DCF_Base!B57 | H5: =DCF_Base!B56
A6: Bull | B6: =DCF_Bull!B42 | C6: =DCF_Bull!B41 | D6: =(B6/Assumptions!$B$11-1)*100 | E6: =Assumptions!D22 | F6: =DCF_Bull!B50 | G6: =DCF_Bull!B57 | H6: =DCF_Bull!B56
A8: Current price (NZD) | B8: =Assumptions!B11
A9: Probability-weighted value | B9: =SUMPRODUCT(B4:B6,E4:E6) | C9: =SUMPRODUCT(C4:C6,E4:E6)
A10: Upside vs price (%) | B10: =(B9/B8-1)*100
A11: Margin of safety (1 - price/weighted) | B11: =1-B8/B9
A12: Street weighted value (NZD) | B12: =SUMPRODUCT(F4:F6,E4:E6)
A13: Band position (price - house)/(street - house) | B13: =IF(ABS(B12-B9)<0.005,"n/a",(B8-B9)/(B12-B9))
A14: Weighted entry price at hurdle (NZD) -- buy-below price | B14: =SUMPRODUCT(G4:G6,E4:E6) | C14: =SUMPRODUCT(H4:H6,E4:E6)
A15: Entry discount from current (%) | B15: =(B14/B8-1)*100
A18: Required-return table (base case, NZD per share; TV rebuilt at each rate)
A19: Required return (%) | B19: 8.5 | C19: 9 | D19: 10 | E19: 11 | F19: 12 | G19: 15
A20: Value per share (NZD) | B20: =IF(B19/100>Assumptions!$C$21/100,(SUMPRODUCT(DCF_Base!$C$22:$L$22/(1+B19/100)^DCF_Base!$C$4:$L$4)+MAX(0,MIN(DCF_Base!$L$22*(1+Assumptions!$C$21/100)/((B19-Assumptions!$C$21)/100),Assumptions!$B$13*DCF_Base!$L$22))/(1+B19/100)^10-Assumptions!$B$9)/Assumptions!$B$10*Assumptions!$B$12,"n/a") | C20: =IF(C19/100>Assumptions!$C$21/100,(SUMPRODUCT(DCF_Base!$C$22:$L$22/(1+C19/100)^DCF_Base!$C$4:$L$4)+MAX(0,MIN(DCF_Base!$L$22*(1+Assumptions!$C$21/100)/((C19-Assumptions!$C$21)/100),Assumptions!$B$13*DCF_Base!$L$22))/(1+C19/100)^10-Assumptions!$B$9)/Assumptions!$B$10*Assumptions!$B$12,"n/a") | D20: =IF(D19/100>Assumptions!$C$21/100,(SUMPRODUCT(DCF_Base!$C$22:$L$22/(1+D19/100)^DCF_Base!$C$4:$L$4)+MAX(0,MIN(DCF_Base!$L$22*(1+Assumptions!$C$21/100)/((D19-Assumptions!$C$21)/100),Assumptions!$B$13*DCF_Base!$L$22))/(1+D19/100)^10-Assumptions!$B$9)/Assumptions!$B$10*Assumptions!$B$12,"n/a") | E20: =IF(E19/100>Assumptions!$C$21/100,(SUMPRODUCT(DCF_Base!$C$22:$L$22/(1+E19/100)^DCF_Base!$C$4:$L$4)+MAX(0,MIN(DCF_Base!$L$22*(1+Assumptions!$C$21/100)/((E19-Assumptions!$C$21)/100),Assumptions!$B$13*DCF_Base!$L$22))/(1+E19/100)^10-Assumptions!$B$9)/Assumptions!$B$10*Assumptions!$B$12,"n/a") | F20: =IF(F19/100>Assumptions!$C$21/100,(SUMPRODUCT(DCF_Base!$C$22:$L$22/(1+F19/100)^DCF_Base!$C$4:$L$4)+MAX(0,MIN(DCF_Base!$L$22*(1+Assumptions!$C$21/100)/((F19-Assumptions!$C$21)/100),Assumptions!$B$13*DCF_Base!$L$22))/(1+F19/100)^10-Assumptions!$B$9)/Assumptions!$B$10*Assumptions!$B$12,"n/a") | G20: =IF(G19/100>Assumptions!$C$21/100,(SUMPRODUCT(DCF_Base!$C$22:$L$22/(1+G19/100)^DCF_Base!$C$4:$L$4)+MAX(0,MIN(DCF_Base!$L$22*(1+Assumptions!$C$21/100)/((G19-Assumptions!$C$21)/100),Assumptions!$B$13*DCF_Base!$L$22))/(1+G19/100)^10-Assumptions!$B$9)/Assumptions!$B$10*Assumptions!$B$12,"n/a")
A21: Check: the WACC column equals DCF_Base!B42 and the 15% column equals DCF_Base!B57
A24: Sensitivity: WACC (rows) x terminal growth (columns), base case, NZD per share
A25: WACC \ g | B25: 1.5 | C25: 2 | D25: 2.5 | E25: 3 | F25: 3.5
A26: 6.5 | B26: =IF($A26/100>B$25/100,(SUMPRODUCT(DCF_Base!$C$22:$L$22/(1+$A26/100)^DCF_Base!$C$4:$L$4)+MAX(0,MIN(DCF_Base!$L$22*(1+B$25/100)/(($A26-B$25)/100),Assumptions!$B$13*DCF_Base!$L$22))/(1+$A26/100)^10-Assumptions!$B$9)/Assumptions!$B$10*Assumptions!$B$12,"n/a") | C26: =IF($A26/100>C$25/100,(SUMPRODUCT(DCF_Base!$C$22:$L$22/(1+$A26/100)^DCF_Base!$C$4:$L$4)+MAX(0,MIN(DCF_Base!$L$22*(1+C$25/100)/(($A26-C$25)/100),Assumptions!$B$13*DCF_Base!$L$22))/(1+$A26/100)^10-Assumptions!$B$9)/Assumptions!$B$10*Assumptions!$B$12,"n/a") | D26: =IF($A26/100>D$25/100,(SUMPRODUCT(DCF_Base!$C$22:$L$22/(1+$A26/100)^DCF_Base!$C$4:$L$4)+MAX(0,MIN(DCF_Base!$L$22*(1+D$25/100)/(($A26-D$25)/100),Assumptions!$B$13*DCF_Base!$L$22))/(1+$A26/100)^10-Assumptions!$B$9)/Assumptions!$B$10*Assumptions!$B$12,"n/a") | E26: =IF($A26/100>E$25/100,(SUMPRODUCT(DCF_Base!$C$22:$L$22/(1+$A26/100)^DCF_Base!$C$4:$L$4)+MAX(0,MIN(DCF_Base!$L$22*(1+E$25/100)/(($A26-E$25)/100),Assumptions!$B$13*DCF_Base!$L$22))/(1+$A26/100)^10-Assumptions!$B$9)/Assumptions!$B$10*Assumptions!$B$12,"n/a") | F26: =IF($A26/100>F$25/100,(SUMPRODUCT(DCF_Base!$C$22:$L$22/(1+$A26/100)^DCF_Base!$C$4:$L$4)+MAX(0,MIN(DCF_Base!$L$22*(1+F$25/100)/(($A26-F$25)/100),Assumptions!$B$13*DCF_Base!$L$22))/(1+$A26/100)^10-Assumptions!$B$9)/Assumptions!$B$10*Assumptions!$B$12,"n/a")
A27: 7.5 | B27: =IF($A27/100>B$25/100,(SUMPRODUCT(DCF_Base!$C$22:$L$22/(1+$A27/100)^DCF_Base!$C$4:$L$4)+MAX(0,MIN(DCF_Base!$L$22*(1+B$25/100)/(($A27-B$25)/100),Assumptions!$B$13*DCF_Base!$L$22))/(1+$A27/100)^10-Assumptions!$B$9)/Assumptions!$B$10*Assumptions!$B$12,"n/a") | C27: =IF($A27/100>C$25/100,(SUMPRODUCT(DCF_Base!$C$22:$L$22/(1+$A27/100)^DCF_Base!$C$4:$L$4)+MAX(0,MIN(DCF_Base!$L$22*(1+C$25/100)/(($A27-C$25)/100),Assumptions!$B$13*DCF_Base!$L$22))/(1+$A27/100)^10-Assumptions!$B$9)/Assumptions!$B$10*Assumptions!$B$12,"n/a") | D27: =IF($A27/100>D$25/100,(SUMPRODUCT(DCF_Base!$C$22:$L$22/(1+$A27/100)^DCF_Base!$C$4:$L$4)+MAX(0,MIN(DCF_Base!$L$22*(1+D$25/100)/(($A27-D$25)/100),Assumptions!$B$13*DCF_Base!$L$22))/(1+$A27/100)^10-Assumptions!$B$9)/Assumptions!$B$10*Assumptions!$B$12,"n/a") | E27: =IF($A27/100>E$25/100,(SUMPRODUCT(DCF_Base!$C$22:$L$22/(1+$A27/100)^DCF_Base!$C$4:$L$4)+MAX(0,MIN(DCF_Base!$L$22*(1+E$25/100)/(($A27-E$25)/100),Assumptions!$B$13*DCF_Base!$L$22))/(1+$A27/100)^10-Assumptions!$B$9)/Assumptions!$B$10*Assumptions!$B$12,"n/a") | F27: =IF($A27/100>F$25/100,(SUMPRODUCT(DCF_Base!$C$22:$L$22/(1+$A27/100)^DCF_Base!$C$4:$L$4)+MAX(0,MIN(DCF_Base!$L$22*(1+F$25/100)/(($A27-F$25)/100),Assumptions!$B$13*DCF_Base!$L$22))/(1+$A27/100)^10-Assumptions!$B$9)/Assumptions!$B$10*Assumptions!$B$12,"n/a")
A28: 8.5 | B28: =IF($A28/100>B$25/100,(SUMPRODUCT(DCF_Base!$C$22:$L$22/(1+$A28/100)^DCF_Base!$C$4:$L$4)+MAX(0,MIN(DCF_Base!$L$22*(1+B$25/100)/(($A28-B$25)/100),Assumptions!$B$13*DCF_Base!$L$22))/(1+$A28/100)^10-Assumptions!$B$9)/Assumptions!$B$10*Assumptions!$B$12,"n/a") | C28: =IF($A28/100>C$25/100,(SUMPRODUCT(DCF_Base!$C$22:$L$22/(1+$A28/100)^DCF_Base!$C$4:$L$4)+MAX(0,MIN(DCF_Base!$L$22*(1+C$25/100)/(($A28-C$25)/100),Assumptions!$B$13*DCF_Base!$L$22))/(1+$A28/100)^10-Assumptions!$B$9)/Assumptions!$B$10*Assumptions!$B$12,"n/a") | D28: =IF($A28/100>D$25/100,(SUMPRODUCT(DCF_Base!$C$22:$L$22/(1+$A28/100)^DCF_Base!$C$4:$L$4)+MAX(0,MIN(DCF_Base!$L$22*(1+D$25/100)/(($A28-D$25)/100),Assumptions!$B$13*DCF_Base!$L$22))/(1+$A28/100)^10-Assumptions!$B$9)/Assumptions!$B$10*Assumptions!$B$12,"n/a") | E28: =IF($A28/100>E$25/100,(SUMPRODUCT(DCF_Base!$C$22:$L$22/(1+$A28/100)^DCF_Base!$C$4:$L$4)+MAX(0,MIN(DCF_Base!$L$22*(1+E$25/100)/(($A28-E$25)/100),Assumptions!$B$13*DCF_Base!$L$22))/(1+$A28/100)^10-Assumptions!$B$9)/Assumptions!$B$10*Assumptions!$B$12,"n/a") | F28: =IF($A28/100>F$25/100,(SUMPRODUCT(DCF_Base!$C$22:$L$22/(1+$A28/100)^DCF_Base!$C$4:$L$4)+MAX(0,MIN(DCF_Base!$L$22*(1+F$25/100)/(($A28-F$25)/100),Assumptions!$B$13*DCF_Base!$L$22))/(1+$A28/100)^10-Assumptions!$B$9)/Assumptions!$B$10*Assumptions!$B$12,"n/a")
A29: 9.5 | B29: =IF($A29/100>B$25/100,(SUMPRODUCT(DCF_Base!$C$22:$L$22/(1+$A29/100)^DCF_Base!$C$4:$L$4)+MAX(0,MIN(DCF_Base!$L$22*(1+B$25/100)/(($A29-B$25)/100),Assumptions!$B$13*DCF_Base!$L$22))/(1+$A29/100)^10-Assumptions!$B$9)/Assumptions!$B$10*Assumptions!$B$12,"n/a") | C29: =IF($A29/100>C$25/100,(SUMPRODUCT(DCF_Base!$C$22:$L$22/(1+$A29/100)^DCF_Base!$C$4:$L$4)+MAX(0,MIN(DCF_Base!$L$22*(1+C$25/100)/(($A29-C$25)/100),Assumptions!$B$13*DCF_Base!$L$22))/(1+$A29/100)^10-Assumptions!$B$9)/Assumptions!$B$10*Assumptions!$B$12,"n/a") | D29: =IF($A29/100>D$25/100,(SUMPRODUCT(DCF_Base!$C$22:$L$22/(1+$A29/100)^DCF_Base!$C$4:$L$4)+MAX(0,MIN(DCF_Base!$L$22*(1+D$25/100)/(($A29-D$25)/100),Assumptions!$B$13*DCF_Base!$L$22))/(1+$A29/100)^10-Assumptions!$B$9)/Assumptions!$B$10*Assumptions!$B$12,"n/a") | E29: =IF($A29/100>E$25/100,(SUMPRODUCT(DCF_Base!$C$22:$L$22/(1+$A29/100)^DCF_Base!$C$4:$L$4)+MAX(0,MIN(DCF_Base!$L$22*(1+E$25/100)/(($A29-E$25)/100),Assumptions!$B$13*DCF_Base!$L$22))/(1+$A29/100)^10-Assumptions!$B$9)/Assumptions!$B$10*Assumptions!$B$12,"n/a") | F29: =IF($A29/100>F$25/100,(SUMPRODUCT(DCF_Base!$C$22:$L$22/(1+$A29/100)^DCF_Base!$C$4:$L$4)+MAX(0,MIN(DCF_Base!$L$22*(1+F$25/100)/(($A29-F$25)/100),Assumptions!$B$13*DCF_Base!$L$22))/(1+$A29/100)^10-Assumptions!$B$9)/Assumptions!$B$10*Assumptions!$B$12,"n/a")
A30: 10.5 | B30: =IF($A30/100>B$25/100,(SUMPRODUCT(DCF_Base!$C$22:$L$22/(1+$A30/100)^DCF_Base!$C$4:$L$4)+MAX(0,MIN(DCF_Base!$L$22*(1+B$25/100)/(($A30-B$25)/100),Assumptions!$B$13*DCF_Base!$L$22))/(1+$A30/100)^10-Assumptions!$B$9)/Assumptions!$B$10*Assumptions!$B$12,"n/a") | C30: =IF($A30/100>C$25/100,(SUMPRODUCT(DCF_Base!$C$22:$L$22/(1+$A30/100)^DCF_Base!$C$4:$L$4)+MAX(0,MIN(DCF_Base!$L$22*(1+C$25/100)/(($A30-C$25)/100),Assumptions!$B$13*DCF_Base!$L$22))/(1+$A30/100)^10-Assumptions!$B$9)/Assumptions!$B$10*Assumptions!$B$12,"n/a") | D30: =IF($A30/100>D$25/100,(SUMPRODUCT(DCF_Base!$C$22:$L$22/(1+$A30/100)^DCF_Base!$C$4:$L$4)+MAX(0,MIN(DCF_Base!$L$22*(1+D$25/100)/(($A30-D$25)/100),Assumptions!$B$13*DCF_Base!$L$22))/(1+$A30/100)^10-Assumptions!$B$9)/Assumptions!$B$10*Assumptions!$B$12,"n/a") | E30: =IF($A30/100>E$25/100,(SUMPRODUCT(DCF_Base!$C$22:$L$22/(1+$A30/100)^DCF_Base!$C$4:$L$4)+MAX(0,MIN(DCF_Base!$L$22*(1+E$25/100)/(($A30-E$25)/100),Assumptions!$B$13*DCF_Base!$L$22))/(1+$A30/100)^10-Assumptions!$B$9)/Assumptions!$B$10*Assumptions!$B$12,"n/a") | F30: =IF($A30/100>F$25/100,(SUMPRODUCT(DCF_Base!$C$22:$L$22/(1+$A30/100)^DCF_Base!$C$4:$L$4)+MAX(0,MIN(DCF_Base!$L$22*(1+F$25/100)/(($A30-F$25)/100),Assumptions!$B$13*DCF_Base!$L$22))/(1+$A30/100)^10-Assumptions!$B$9)/Assumptions!$B$10*Assumptions!$B$12,"n/a")
A32: Cells where the 15x cap binds are flat across g -- that is the cap doing its job, not an error.
