Workbook

Sheet README
B1: Wise Group plc (Nasdaq: WSE / LSE: WISE) — Two-Part DCF with Probability-Weighted Regulatory Scenarios
B2: Valuation date: 21 July 2026. All figures USD millions unless noted. Reporting currency USD (switched from GBP with FY2026). FY ends 31 March.
B4: STRUCTURE
B5: 1. Historicals — FY2022–Q1 FY27 metrics from user-supplied WISE_L_Metrics.csv (source: company reports).
B6: 2. Assumptions — all global inputs. BLUE font = hardcoded input you can change. YELLOW fill = assumption that most needs verifying or is the key judgment call.
B7: 3. Core DCF — transaction + card revenue (net revenue EXCLUDING net interest on customer balances), 10-yr explicit + terminal.
B8: 4. Float — customer-holdings interest stream valued separately at a NORMALIZED retained yield (not the current spot yield).
B9: 5. Scenarios — regulatory outcomes A–D (Belgian AML probe) each re-run as a mini-DCF; probability-weighted value and market-implied probability check.
B10: 6. Sensitivity — WACC x terminal growth grid; normalized float yield sensitivity.
B12: WHY THE FLOAT IS SEPARATED
B13: ~24% of FY2026 net revenue ($609m net) was interest on customer balances. That stream is rate-cyclical: blending it into one DCF capitalises a
B14: cyclical peak at a growth multiple. Here the core engine and the float carry separate growth, margin, and terminal assumptions.
... B34: public probe reporting Jun–Jul 2026. Prepared for Stephen, 21 July 2026.

Sheet Historicals
B1: Historical metrics — company reports via user-supplied WISE_L_Metrics.csv. $m except customers (000s), volume/holdings ($bn), take rate (%), shares (m), EPS (cents).
B2: Period | C2: NetRevenue | D2: TransactionRevenue | E2: InterestIncomeNet | F2: OperatingIncome | G2: IncomeBeforeTax | H2: NetIncome | I2: EPSBasic | J2: EPSDiluted | K2: FreeCashFlow | L2: ActiveCustomers | M2: CrossBorderVolume | N2: CustomerHoldings | O2: TakeRate | P2: InstantPayments | Q2: TotalEquity | R2: TotalDebt | S2: CashAndEquivalents | T2: SharesOutstanding
B3: FY2022 | C3: 757.7 | D3: 761.5 | E3: -3.8 | F3: 66.2 | G3: 59.7 | H3: 44.7 | I3: 4.62 | J3: 4.32 | K3: 154.1 | Q3: 556.5 | R3: 130.2 | S3: 486.6 | T3: 1034
B4: FY2023 | C4: 1147.4 | D4: 1006.9 | E4: 162.4 | F4: 187.1 | G4: 174.3 | H4: 135.7 | I4: 13.72 | J4: 13.02 | K4: 253.8 | Q4: 686.5 | R4: 314.6 | S4: 798.6 | T4: 1042.4
B5: Q1 FY2024 | L5: 6670 | M5: 35.3 | N5: 14.4 | O5: 0.67 | P5: 57
B6: Q2 FY2024 | L6: 7232 | M6: 37.1 | N6: 15.6 | O6: 0.67 | P6: 60
B7: Q3 FY2024 | L7: 7512 | M7: 38.3 | N7: 16.1 | O7: 0.67 | P7: 61
B8: Q4 FY2024 | L8: 7911 | M8: 38.9 | N8: 16.9 | O8: 0.67 | P8: 62
B9: FY2024 | C9: 1776.1 | D9: 1323.1 | E9: 453 | F9: 650.1 | G9: 656.7 | H9: 501.5 | I9: 48.57 | J9: 47.81 | K9: 487.2 | L9: 7911 | T9: 1048.9
B10: Q1 FY2025 | C10: 502.7 | D10: 367.5 | E10: 135.2 | L10: 8374 | M10: 41.9 | N10: 22.1 | O10: 0.64 | P10: 59
B11: Q2 FY2025 | C11: 532.6 | D11: 391.1 | E11: 141.5 | L11: 8892 | M11: 45.7 | N11: 24.7 | O11: 0.59 | P11: 63
B12: Q3 FY2025 | C12: 539.6 | D12: 398 | E12: 141.6 | L12: 9047 | M12: 48.4 | N12: 25.7 | O12: 0.56 | P12: 65
B13: Q4 FY2025 | C13: 524 | D13: 389.7 | E13: 134.3 | L13: 9290 | M13: 49.2 | N13: 27.8 | O13: 0.53 | P13: 65
B14: FY2025 | C14: 2098.9 | D14: 1546.3 | E14: 552.6 | F14: 728.2 | G14: 717.5 | H14: 550.3 | I14: 53.31 | J14: 52.63 | K14: 535.8 | L14: 9290 | M14: 185.2 | N14: 27.8 | Q14: 1737.4 | R14: 128.4 | T14: 1045.7
B15: Q1 FY2026 | C15: 573.3 | D15: 424.8 | E15: 148.5 | L15: 9797 | M15: 55 | N15: 31.5 | O15: 0.52 | P15: 70
B16: Q2 FY2026 | C16: 610.5 | D16: 458.4 | E16: 152.1 | L16: 10440 | M16: 59 | N16: 33.9 | O16: 0.52 | P16: 74
B17: Q3 FY2026 | C17: 651.2 | D17: 496.2 | E17: 155 | L17: 10896 | M17: 63.1 | N17: 37 | O17: 0.52 | P17: 74
B18: Q4 FY2026 | C18: 667.8 | D18: 514.2 | E18: 153.6 | L18: 11290 | M18: 66.5 | N18: 39 | O18: 0.51
B19: FY2026 | C19: 2502.8 | D19: 1893.6 | E19: 609.2 | F19: 590.7 | G19: 660.4 | H19: 498.7 | I19: 48.92 | J19: 48.43 | K19: 532.8 | L19: 11290 | M19: 243.6 | N19: 39 | Q19: 1925.2 | R19: 334.7 | T19: 1029.7
B20: Q1 FY2027 | C20: 714 | D20: 540.9 | E20: 173.1 | L20: 11863 | M20: 69.3 | N20: 41.2 | O20: 0.5 | P20: 77

Sheet Assumptions
A1: Global Assumptions
A3: Valuation date | B3: 2026-07-21 | C3: Trading day of build
A4: WACC | B4: 0.1 | C4: Default; flex in Sensitivity tab. Beta ~0.5-0.75 per data providers argues lower; regulatory uncertainty argues higher.
A5: Terminal growth — core | B5: 0.03 | C5: Long-run core (transaction+card) growth
A6: Terminal growth — float | B6: 0.02 | C6: Long-run holdings-driven interest growth
A7: Tax rate | B7: 0.25 | C7: FY2026 effective ~24.5% (498.7/660.4)
A8: FCF conversion (of NOPAT) | B8: 1 | C8: FY2026 FCF $532.8m vs NI $498.7m (~107%); 100% is mildly conservative
A9: Shares outstanding (m) | B9: 1002.5 | C9: Diluted ~1,000-1,005m per 20-F share capital note (Claude Code extraction, 21 Jul 2026); midpoint used. Prior placeholder 1,029.7m basic.
A10: Net corporate cash ($m) | B10: 1874 | C10: VERIFIED via 20-F: net corporate cash +$1,874m ex-leases (+$1,725m incl. leases), customer/safeguarded funds excluded (Claude Code extraction, 21 Jul 2026).
A11: GBP/USD | B11: 1.34 | C11: For WISE.L pence translation
A12: Europe (Wise Europe-served) revenue share | B12: 0.27 | C12: VERIFIED: ~27% of net revenue via Wise Europe (range 25-29%); geographic note shows Europe ex-UK $713.2m = 28.5% of FY2026 net revenue (Claude Code extraction, 21 Jul 2026).
A13: Normalized retained float yield | B13: 0.015 | C13: FY2026 actual retained yield 2.22% of avg balances per 20-F; normalized ~1.5% per rate-cycle analysis (Claude Code extraction, 21 Jul 2026).
A14: Float pre-tax margin | B14: 0.85 | C14: Treasury/safeguarding/allocated costs vs interest stream — allocation judgment
A15: Core net revenue, FY2026 ($m) | B15: 1893.6 | C15: Net revenue 2,502.8 less net interest 609.2 (equals transaction revenue)
... A18: Fine payment timing (yrs from now) | B18: 1.5 | C18: Discounting for scenario fines/one-offs
A20: Legend: BLUE = input (edit these). YELLOW = key judgment/verify. Black = formula. Green = cross-sheet link.

Sheet CoreDCF
B1: Core Engine DCF — transaction + card net revenue (excludes float interest)
B2: ($m) | C2: FY2027 | D2: FY2028 | E2: FY2029 | F2: FY2030 | G2: FY2031 | H2: FY2032 | I2: FY2033 | J2: FY2034 | K2: FY2035 | L2: FY2036 | M2: Summary
B3: Period | C3: 1 | D3: 2 | E3: 3 | F3: 4 | G3: 5 | H3: 6 | I3: 7 | J3: 8 | K3: 9 | L3: 10
B4: Core revenue growth (input) | C4: 0.22 | D4: 0.19 | E4: 0.17 | F4: 0.15 | G4: 0.13 | H4: 0.11 | I4: 0.09 | J4: 0.07 | K4: 0.06 | L4: 0.05
B5: Core net revenue | C5: =Assumptions!$B$15*(1+C4) -> 2310.192 | D5: =C5*(1+D4) -> 2749.1285 | E5: =D5*(1+E4) -> 3216.4803 | F5: =E5*(1+F4) -> 3698.9524 | G5: =F5*(1+G4) -> 4179.8162 | H5: =G5*(1+H4) -> 4639.596 | I5: =H5*(1+I4) -> 5057.1596 | J5: =I5*(1+J4) -> 5411.1608 | K5: =J5*(1+K4) -> 5735.8304 | L5: =K5*(1+L4) -> 6022.6219
B6: YoY growth check
B7: Core pre-tax (IBT) margin (input) | C7: 0.06 | D7: 0.09 | E7: 0.12 | F7: 0.14 | G7: 0.16 | H7: 0.17 | I7: 0.18 | J7: 0.18 | K7: 0.18 | L7: 0.18
B8: Core IBT | C8: =C5*C7 -> 138.61152 | D8: =D5*D7 -> 247.42156 | E8: =E5*E7 -> 385.97764 | F8: =F5*F7 -> 517.85333 | G8: =G5*G7 -> 668.77059 | H8: =H5*H7 -> 788.73131 | I8: =I5*I7 -> 910.28873 | J8: =J5*J7 -> 974.00894 | ... L8: =L5*L7 -> 1084.0719
B9: Core NOPAT | C9: =C8*(1-Assumptions!$B$7) -> 103.95864 | D9: =D8*(1-Assumptions!$B$7) -> 185.56617 | E9: =E8*(1-Assumptions!$B$7) -> 289.48323 | F9: =F8*(1-Assumptions!$B$7) -> 388.39 | G9: =G8*(1-Assumptions!$B$7) -> 501.57794 | H9: =H8*(1-Assumptions!$B$7) -> 591.54848 | I9: =I8*(1-Assumptions!$B$7) -> 682.71655 | J9: =J8*(1-Assumptions!$B$7) -> 730.5067 | ... L9: =L8*(1-Assumptions!$B$7) -> 813.05396
B10: Core FCF | C10: =C9*Assumptions!$B$8 -> 103.95864 | D10: =D9*Assumptions!$B$8 -> 185.56617 | E10: =E9*Assumptions!$B$8 -> 289.48323 | F10: =F9*Assumptions!$B$8 -> 388.39 | G10: =G9*Assumptions!$B$8 -> 501.57794 | H10: =H9*Assumptions!$B$8 -> 591.54848 | I10: =I9*Assumptions!$B$8 -> 682.71655 | J10: =J9*Assumptions!$B$8 -> 730.5067 | ... L10: =L9*Assumptions!$B$8 -> 813.05396
B11: Discount factor | C11: =1/(1+Assumptions!$B$4)^C3 -> 0.90909091 | D11: =1/(1+Assumptions!$B$4)^D3 -> 0.82644628 | E11: =1/(1+Assumptions!$B$4)^E3 -> 0.7513148 | F11: =1/(1+Assumptions!$B$4)^F3 -> 0.68301346 | G11: =1/(1+Assumptions!$B$4)^G3 -> 0.62092132 | H11: =1/(1+Assumptions!$B$4)^H3 -> 0.56447393 | I11: =1/(1+Assumptions!$B$4)^I3 -> 0.51315812 | J11: =1/(1+Assumptions!$B$4)^J3 -> 0.46650738 | ... L11: =1/(1+Assumptions!$B$4)^L3 -> 0.38554329
B12: PV of FCF | C12: =C10*C11 -> 94.507855 | D12: =D10*D11 -> 153.36047 | E12: =E10*E11 -> 217.49303 | F12: =F10*F11 -> 265.2756 | G12: =G10*G11 -> 311.44044 | H12: =H10*H11 -> 333.9137 | I12: =I10*I11 -> 350.34154 | J12: =J10*J11 -> 340.78677 | ... L12: =L10*L11 -> 313.4675
B14: Sum PV explicit FCF | N14: =SUM(C12:L12) -> 2708.9814
B15: Terminal value (Gordon, yr-10 FCF) | N15: =L10*(1+Assumptions!$B$5)/(Assumptions!$B$4-Assumptions!$B$5) -> 11963.508
B16: PV of terminal value | N16: =N15*L11 -> 4612.4503
B17: CORE ENTERPRISE VALUE | N17: =N14+N16 -> 7321.4318
B19: FY27 core growth 22% vs Q1 FY27 actual transaction growth 27% YoY. Margin ramp start validated by 20-F work: core ex-float FY2026 pre-tax margin was -1% to +6.6% depending on cost allocation (Claude Code extraction) — the 6% FY27 start sits at the generous end; the ramp to 18% is the key judgment.

Sheet Float
B1: Float DCF — net interest on customer holdings at NORMALIZED retained yield
B2: ($m) | C2: FY2027 | D2: FY2028 | E2: FY2029 | F2: FY2030 | G2: FY2031 | H2: FY2032 | I2: FY2033 | J2: FY2034 | K2: FY2035 | L2: FY2036 | M2: Summary
B3: Period | C3: 1 | D3: 2 | E3: 3 | F3: 4 | G3: 5 | H3: 6 | I3: 7 | J3: 8 | K3: 9 | L3: 10
B4: Holdings growth (input) | C4: 0.25 | D4: 0.2 | E4: 0.17 | F4: 0.14 | G4: 0.12 | H4: 0.1 | I4: 0.08 | J4: 0.07 | K4: 0.06 | L4: 0.05
B5: Customer holdings, yr-end ($bn) | C5: =Assumptions!$B$16*(1+C4) -> 48.75 | D5: =C5*(1+D4) -> 58.5 | E5: =D5*(1+E4) -> 68.445 | F5: =E5*(1+F4) -> 78.0273 | G5: =F5*(1+G4) -> 87.390576 | H5: =G5*(1+H4) -> 96.129634 | I5: =H5*(1+I4) -> 103.82 | J5: =I5*(1+J4) -> 111.0874 | K5: =J5*(1+K4) -> 117.75265 | L5: =K5*(1+L4) -> 123.64028
B6: Average holdings ($bn) | C6: =(Assumptions!$B$16+C5)/2 -> 43.875 | D6: =(C5+D5)/2 -> 53.625 | E6: =(D5+E5)/2 -> 63.4725 | F6: =(E5+F5)/2 -> 73.23615 | G6: =(F5+G5)/2 -> 82.708938 | H6: =(G5+H5)/2 -> 91.760105 | I6: =(H5+I5)/2 -> 99.974819 | J6: =(I5+J5)/2 -> 107.4537 | K6: =(J5+K5)/2 -> 114.42003 | L6: =(K5+L5)/2 -> 120.69647
B7: Net interest revenue ($m) | C7: =C6*1000*Assumptions!$B$13 -> 658.125 | D7: =D6*1000*Assumptions!$B$13 -> 804.375 | E7: =E6*1000*Assumptions!$B$13 -> 952.0875 | F7: =F6*1000*Assumptions!$B$13 -> 1098.5422 | G7: =G6*1000*Assumptions!$B$13 -> 1240.6341 | H7: =H6*1000*Assumptions!$B$13 -> 1376.4016 | I7: =I6*1000*Assumptions!$B$13 -> 1499.6223 | J7: =J6*1000*Assumptions!$B$13 -> 1611.8056 | ... L7: =L6*1000*Assumptions!$B$13 -> 1810.447
B8: Float IBT ($m) | C8: =C7*Assumptions!$B$14 -> 559.40625 | D8: =D7*Assumptions!$B$14 -> 683.71875 | E8: =E7*Assumptions!$B$14 -> 809.27437 | F8: =F7*Assumptions!$B$14 -> 933.76091 | G8: =G7*Assumptions!$B$14 -> 1054.539 | H8: =H7*Assumptions!$B$14 -> 1169.9413 | I8: =I7*Assumptions!$B$14 -> 1274.6789 | J8: =J7*Assumptions!$B$14 -> 1370.0347 | ... L8: =L7*Assumptions!$B$14 -> 1538.8799
B9: Float NOPAT = FCF ($m) | C9: =C8*(1-Assumptions!$B$7) -> 419.55469 | D9: =D8*(1-Assumptions!$B$7) -> 512.78906 | E9: =E8*(1-Assumptions!$B$7) -> 606.95578 | F9: =F8*(1-Assumptions!$B$7) -> 700.32068 | G9: =G8*(1-Assumptions!$B$7) -> 790.90422 | H9: =H8*(1-Assumptions!$B$7) -> 877.456 | I9: =I8*(1-Assumptions!$B$7) -> 956.00921 | J9: =J8*(1-Assumptions!$B$7) -> 1027.526 | ... L9: =L8*(1-Assumptions!$B$7) -> 1154.1599
B10: Discount factor | C10: =1/(1+Assumptions!$B$4)^C3 -> 0.90909091 | D10: =1/(1+Assumptions!$B$4)^D3 -> 0.82644628 | E10: =1/(1+Assumptions!$B$4)^E3 -> 0.7513148 | F10: =1/(1+Assumptions!$B$4)^F3 -> 0.68301346 | G10: =1/(1+Assumptions!$B$4)^G3 -> 0.62092132 | H10: =1/(1+Assumptions!$B$4)^H3 -> 0.56447393 | I10: =1/(1+Assumptions!$B$4)^I3 -> 0.51315812 | J10: =1/(1+Assumptions!$B$4)^J3 -> 0.46650738 | ... L10: =1/(1+Assumptions!$B$4)^L3 -> 0.38554329
B11: PV of FCF | C11: =C9*C10 -> 381.41335 | D11: =D9*D10 -> 423.79261 | E11: =E9*E10 -> 456.01486 | F11: =F9*F10 -> 478.32845 | G11: =G9*G10 -> 491.08929 | H11: =H9*H10 -> 495.30104 | I11: =I9*I10 -> 490.58389 | J11: =J9*J10 -> 479.34849 | ... L11: =L9*L10 -> 444.97862
B13: Sum PV explicit FCF | N13: =SUM(C11:L11) -> 4604.8734
B14: Terminal value | N14: =L9*(1+Assumptions!$B$6)/(Assumptions!$B$4-Assumptions!$B$6) -> 14715.539
B15: PV of terminal value | N15: =N14*L10 -> 5673.4774
B16: FLOAT ENTERPRISE VALUE | N16: =N13+N15 -> 10278.351
B18: Blended check vs guidance
B19: Total net revenue (core + float, FY27) | C19: =CoreDCF!C5+C7 -> 2968.317
B20: Implied total net revenue growth FY27 (guide: mid 15-20%) | C20: =C19/2502.8-1 -> 0.18599848
B21: Implied blended IBT margin FY27 (guide: ~25%; actual yield > normalized would lift this) | C21: =(CoreDCF!C8+C8)/C19 -> 0.23515607
B22: Note: normalized yield (1.25%) sits well below the ~1.8% currently earned, so near-term modelled float revenue deliberately undershoots reported — the haircut IS the rate-cycle adjustment. At spot yields the blended FY27 margin check would be near guidance.

Sheet Scenarios
B1: Regulatory Scenarios — Belgian AML probe (probability-weighted)
B3: BASE (no regulatory impact)
B4: Core EV | C4: =CoreDCF!N17 -> 7321.4318
B5: Float EV | C5: =Float!N16 -> 10278.351
B6: Net corporate cash | C6: =Assumptions!$B$10 -> 1874
B7: Base equity value | C7: =C4+C5+C6 -> 19473.783
B8: Base value / share (USD) | C8: =C7/Assumptions!$B$9 -> 19.42522
B9: Base value / share (GBX, WISE.L) | C9: =C8/Assumptions!$B$11*100 -> 1449.6433
B11: Scenario parameters (all BLUE cells are inputs)
B12: Scenario | C12: Probability | D12: Fine ($m) | E12: Compliance drag (% core rev) | F12: Drag yrs | G12: Growth haircut (pts) | H12: Haircut yrs | I12: One-off cost ($m)
B13: A — Settlement + remediation | C13: 0.55 | D13: 150 | E13: 0.015 | F13: 3 | G13: 0 | H13: 0 | I13: 0
B14: B — Conviction, no caps | C14: 0.25 | D14: 600 | E14: 0.02 | F14: 4 | G14: 0.04 | H14: 2 | I14: 0
B15: C — NBB growth restrictions | C15: 0.15 | D15: 400 | E15: 0.025 | F15: 5 | G15: 0.06 | H15: 2 | I15: 0
B16: D — Licence withdrawal / restructuring | C16: 0.05 | D16: 800 | E16: 0.03 | F16: 5 | G16: 0.12 | H16: 3 | I16: 800
B17: Probability check (must = 100%) | C17: =SUM(C13:C16) -> 1
B18: Haircut derivation: C assumes European growth ~0 for 2 yrs; at verified ~27% Europe share and ~20%+ base growth that is ~6pts off group core growth. D one-off $800m reflects the $1,119m parent guarantee and $331m EMTN cross-default web identified in the 20-F (Claude Code extraction) — a licence event would not stay contained to the Belgian entity. Fine sizes remain judgment: only $23.8m provisioned group-wide, Belgian probe unprovisioned/unquantified.
B20: Per-scenario core mini-DCFs (float EV held at base; D's EU float attrition proxied inside one-off cost)
B21: Scenario A: adj. growth | C21: =CoreDCF!C4-IF(CoreDCF!C3<=$H$13,$G$13,0) -> 0.22 | D21: =CoreDCF!D4-IF(CoreDCF!D3<=$H$13,$G$13,0) -> 0.19 | E21: =CoreDCF!E4-IF(CoreDCF!E3<=$H$13,$G$13,0) -> 0.17 | F21: =CoreDCF!F4-IF(CoreDCF!F3<=$H$13,$G$13,0) -> 0.15 | G21: =CoreDCF!G4-IF(CoreDCF!G3<=$H$13,$G$13,0) -> 0.13 | H21: =CoreDCF!H4-IF(CoreDCF!H3<=$H$13,$G$13,0) -> 0.11 | I21: =CoreDCF!I4-IF(CoreDCF!I3<=$H$13,$G$13,0) -> 0.09 | J21: =CoreDCF!J4-IF(CoreDCF!J3<=$H$13,$G$13,0) -> 0.07 | ... L21: =CoreDCF!L4-IF(CoreDCF!L3<=$H$13,$G$13,0) -> 0.05
B22: Core revenue | C22: =Assumptions!$B$15*(1+C21) -> 2310.192 | D22: =C22*(1+D21) -> 2749.1285 | E22: =D22*(1+E21) -> 3216.4803 | F22: =E22*(1+F21) -> 3698.9524 | G22: =F22*(1+G21) -> 4179.8162 | H22: =G22*(1+H21) -> 4639.596 | I22: =H22*(1+I21) -> 5057.1596 | J22: =I22*(1+J21) -> 5411.1608 | K22: =J22*(1+K21) -> 5735.8304 | L22: =K22*(1+L21) -> 6022.6219
B23: Core IBT (margin - compliance drag) | C23: =C22*(CoreDCF!C7-IF(CoreDCF!C3<=$F$13,$E$13,0)) -> 103.95864 | D23: =D22*(CoreDCF!D7-IF(CoreDCF!D3<=$F$13,$E$13,0)) -> 206.18464 | E23: =E22*(CoreDCF!E7-IF(CoreDCF!E3<=$F$13,$E$13,0)) -> 337.73043 | F23: =F22*(CoreDCF!F7-IF(CoreDCF!F3<=$F$13,$E$13,0)) -> 517.85333 | G23: =G22*(CoreDCF!G7-IF(CoreDCF!G3<=$F$13,$E$13,0)) -> 668.77059 | H23: =H22*(CoreDCF!H7-IF(CoreDCF!H3<=$F$13,$E$13,0)) -> 788.73131 | I23: =I22*(CoreDCF!I7-IF(CoreDCF!I3<=$F$13,$E$13,0)) -> 910.28873 | J23: =J22*(CoreDCF!J7-IF(CoreDCF!J3<=$F$13,$E$13,0)) -> 974.00894 | ... L23: =L22*(CoreDCF!L7-IF(CoreDCF!L3<=$F$13,$E$13,0)) -> 1084.0719
B24: FCF (NOPAT x conversion) | C24: =C23*(1-Assumptions!$B$7)*Assumptions!$B$8 -> 77.96898 | D24: =D23*(1-Assumptions!$B$7)*Assumptions!$B$8 -> 154.63848 | E24: =E23*(1-Assumptions!$B$7)*Assumptions!$B$8 -> 253.29783 | F24: =F23*(1-Assumptions!$B$7)*Assumptions!$B$8 -> 388.39 | G24: =G23*(1-Assumptions!$B$7)*Assumptions!$B$8 -> 501.57794 | H24: =H23*(1-Assumptions!$B$7)*Assumptions!$B$8 -> 591.54848 | I24: =I23*(1-Assumptions!$B$7)*Assumptions!$B$8 -> 682.71655 | J24: =J23*(1-Assumptions!$B$7)*Assumptions!$B$8 -> 730.5067 | ... L24: =L23*(1-Assumptions!$B$7)*Assumptions!$B$8 -> 813.05396
B25: PV of FCF | C25: =C24*CoreDCF!C11 -> 70.880891 | D25: =D24*CoreDCF!D11 -> 127.80039 | E25: =E24*CoreDCF!E11 -> 190.30641 | F25: =F24*CoreDCF!F11 -> 265.2756 | G25: =G24*CoreDCF!G11 -> 311.44044 | H25: =H24*CoreDCF!H11 -> 333.9137 | I25: =I24*CoreDCF!I11 -> 350.34154 | J25: =J24*CoreDCF!J11 -> 340.78677 | ... L25: =L24*CoreDCF!L11 -> 313.4675
B26: Core EV / Equity / per share | N26: =SUM(C25:L25)+L24*(1+Assumptions!$B$5)/(Assumptions!$B$4-Assumptions!$B$5)*CoreDCF!L11 -> 7245.0581
B27: Equity value | N27: =N26+$C$5+$C$6-($D$13+$I$13)/(1+Assumptions!$B$4)^Assumptions!$B$18 -> 19267.391
B28: Value / share (USD) | N28: =N27/Assumptions!$B$9 -> 19.219343
B29: Scenario B: adj. growth | C29: =CoreDCF!C4-IF(CoreDCF!C3<=$H$14,$G$14,0) -> 0.18 | D29: =CoreDCF!D4-IF(CoreDCF!D3<=$H$14,$G$14,0) -> 0.15 | E29: =CoreDCF!E4-IF(CoreDCF!E3<=$H$14,$G$14,0) -> 0.17 | F29: =CoreDCF!F4-IF(CoreDCF!F3<=$H$14,$G$14,0) -> 0.15 | G29: =CoreDCF!G4-IF(CoreDCF!G3<=$H$14,$G$14,0) -> 0.13 | H29: =CoreDCF!H4-IF(CoreDCF!H3<=$H$14,$G$14,0) -> 0.11 | I29: =CoreDCF!I4-IF(CoreDCF!I3<=$H$14,$G$14,0) -> 0.09 | J29: =CoreDCF!J4-IF(CoreDCF!J3<=$H$14,$G$14,0) -> 0.07 | ... L29: =CoreDCF!L4-IF(CoreDCF!L3<=$H$14,$G$14,0) -> 0.05
B30: Core revenue | C30: =Assumptions!$B$15*(1+C29) -> 2234.448 | D30: =C30*(1+D29) -> 2569.6152 | E30: =D30*(1+E29) -> 3006.4498 | F30: =E30*(1+F29) -> 3457.4173 | G30: =F30*(1+G29) -> 3906.8815 | H30: =G30*(1+H29) -> 4336.6385 | I30: =H30*(1+I29) -> 4726.9359 | J30: =I30*(1+J29) -> 5057.8214 | K30: =J30*(1+K29) -> 5361.2907 | L30: =K30*(1+L29) -> 5629.3553
B31: Core IBT (margin - compliance drag) | C31: =C30*(CoreDCF!C7-IF(CoreDCF!C3<=$F$14,$E$14,0)) -> 89.37792 | D31: =D30*(CoreDCF!D7-IF(CoreDCF!D3<=$F$14,$E$14,0)) -> 179.87306 | E31: =E30*(CoreDCF!E7-IF(CoreDCF!E3<=$F$14,$E$14,0)) -> 300.64498 | F31: =F30*(CoreDCF!F7-IF(CoreDCF!F3<=$F$14,$E$14,0)) -> 414.89007 | G31: =G30*(CoreDCF!G7-IF(CoreDCF!G3<=$F$14,$E$14,0)) -> 625.10104 | H31: =H30*(CoreDCF!H7-IF(CoreDCF!H3<=$F$14,$E$14,0)) -> 737.22854 | I31: =I30*(CoreDCF!I7-IF(CoreDCF!I3<=$F$14,$E$14,0)) -> 850.84847 | J31: =J30*(CoreDCF!J7-IF(CoreDCF!J3<=$F$14,$E$14,0)) -> 910.40786 | ... L31: =L30*(CoreDCF!L7-IF(CoreDCF!L3<=$F$14,$E$14,0)) -> 1013.2839
B32: FCF (NOPAT x conversion) | C32: =C31*(1-Assumptions!$B$7)*Assumptions!$B$8 -> 67.03344 | D32: =D31*(1-Assumptions!$B$7)*Assumptions!$B$8 -> 134.9048 | E32: =E31*(1-Assumptions!$B$7)*Assumptions!$B$8 -> 225.48373 | F32: =F31*(1-Assumptions!$B$7)*Assumptions!$B$8 -> 311.16755 | G32: =G31*(1-Assumptions!$B$7)*Assumptions!$B$8 -> 468.82578 | H32: =H31*(1-Assumptions!$B$7)*Assumptions!$B$8 -> 552.9214 | I32: =I31*(1-Assumptions!$B$7)*Assumptions!$B$8 -> 638.13635 | J32: =J31*(1-Assumptions!$B$7)*Assumptions!$B$8 -> 682.80589 | ... L32: =L31*(1-Assumptions!$B$7)*Assumptions!$B$8 -> 759.96296
B33: PV of FCF | C33: =C32*CoreDCF!C11 -> 60.939491 | D33: =D32*CoreDCF!D11 -> 111.49157 | E33: =E32*CoreDCF!E11 -> 169.40927 | F33: =F32*CoreDCF!F11 -> 212.53163 | G33: =G32*CoreDCF!G11 -> 291.10392 | H33: =H32*CoreDCF!H11 -> 312.10972 | I33: =I32*CoreDCF!I11 -> 327.46485 | J33: =J32*CoreDCF!J11 -> 318.53399 | ... L33: =L32*CoreDCF!L11 -> 292.99862
B34: Core EV / Equity / per share | N34: =SUM(C33:L33)+L32*(1+Assumptions!$B$5)/(Assumptions!$B$4-Assumptions!$B$5)*CoreDCF!L11 -> 6714.7994
B35: Equity value | N35: =N34+$C$5+$C$6-($D$14+$I$14)/(1+Assumptions!$B$4)^Assumptions!$B$18 -> 18347.08
B36: Value / share (USD) | N36: =N35/Assumptions!$B$9 -> 18.301326
B37: Scenario C: adj. growth | C37: =CoreDCF!C4-IF(CoreDCF!C3<=$H$15,$G$15,0) -> 0.16 | D37: =CoreDCF!D4-IF(CoreDCF!D3<=$H$15,$G$15,0) -> 0.13 | E37: =CoreDCF!E4-IF(CoreDCF!E3<=$H$15,$G$15,0) -> 0.17 | F37: =CoreDCF!F4-IF(CoreDCF!F3<=$H$15,$G$15,0) -> 0.15 | G37: =CoreDCF!G4-IF(CoreDCF!G3<=$H$15,$G$15,0) -> 0.13 | H37: =CoreDCF!H4-IF(CoreDCF!H3<=$H$15,$G$15,0) -> 0.11 | I37: =CoreDCF!I4-IF(CoreDCF!I3<=$H$15,$G$15,0) -> 0.09 | J37: =CoreDCF!J4-IF(CoreDCF!J3<=$H$15,$G$15,0) -> 0.07 | ... L37: =CoreDCF!L4-IF(CoreDCF!L3<=$H$15,$G$15,0) -> 0.05
B38: Core revenue | C38: =Assumptions!$B$15*(1+C37) -> 2196.576 | D38: =C38*(1+D37) -> 2482.1309 | E38: =D38*(1+E37) -> 2904.0931 | F38: =E38*(1+F37) -> 3339.7071 | G38: =F38*(1+G37) -> 3773.869 | H38: =G38*(1+H37) -> 4188.9946 | I38: =H38*(1+I37) -> 4566.0041 | J38: =I38*(1+J37) -> 4885.6244 | K38: =J38*(1+K37) -> 5178.7619 | L38: =K38*(1+L37) -> 5437.7
B39: Core IBT (margin - compliance drag) | C39: =C38*(CoreDCF!C7-IF(CoreDCF!C3<=$F$15,$E$15,0)) -> 76.88016 | D39: =D38*(CoreDCF!D7-IF(CoreDCF!D3<=$F$15,$E$15,0)) -> 161.33851 | E39: =E38*(CoreDCF!E7-IF(CoreDCF!E3<=$F$15,$E$15,0)) -> 275.88885 | F39: =F38*(CoreDCF!F7-IF(CoreDCF!F3<=$F$15,$E$15,0)) -> 384.06632 | G39: =G38*(CoreDCF!G7-IF(CoreDCF!G3<=$F$15,$E$15,0)) -> 509.47232 | H39: =H38*(CoreDCF!H7-IF(CoreDCF!H3<=$F$15,$E$15,0)) -> 712.12908 | I39: =I38*(CoreDCF!I7-IF(CoreDCF!I3<=$F$15,$E$15,0)) -> 821.88074 | J39: =J38*(CoreDCF!J7-IF(CoreDCF!J3<=$F$15,$E$15,0)) -> 879.4124 | ... L39: =L38*(CoreDCF!L7-IF(CoreDCF!L3<=$F$15,$E$15,0)) -> 978.786
B40: FCF (NOPAT x conversion) | C40: =C39*(1-Assumptions!$B$7)*Assumptions!$B$8 -> 57.66012 | D40: =D39*(1-Assumptions!$B$7)*Assumptions!$B$8 -> 121.00388 | E40: =E39*(1-Assumptions!$B$7)*Assumptions!$B$8 -> 206.91664 | F40: =F39*(1-Assumptions!$B$7)*Assumptions!$B$8 -> 288.04974 | G40: =G39*(1-Assumptions!$B$7)*Assumptions!$B$8 -> 382.10424 | H40: =H39*(1-Assumptions!$B$7)*Assumptions!$B$8 -> 534.09681 | I40: =I39*(1-Assumptions!$B$7)*Assumptions!$B$8 -> 616.41056 | J40: =J39*(1-Assumptions!$B$7)*Assumptions!$B$8 -> 659.5593 | ... L40: =L39*(1-Assumptions!$B$7)*Assumptions!$B$8 -> 734.0895
B41: PV of FCF | C41: =C40*CoreDCF!C11 -> 52.418291 | D41: =D40*CoreDCF!D11 -> 100.00321 | E41: =E40*CoreDCF!E11 -> 155.45953 | F41: =F40*CoreDCF!F11 -> 196.74185 | G41: =G40*CoreDCF!G11 -> 237.25667 | H41: =H40*CoreDCF!H11 -> 301.48373 | I41: =I40*CoreDCF!I11 -> 316.31608 | J41: =J40*CoreDCF!J11 -> 307.68928 | ... L41: =L40*CoreDCF!L11 -> 283.02328
B42: Core EV / Equity / per share | N42: =SUM(C41:L41)+L40*(1+Assumptions!$B$5)/(Assumptions!$B$4-Assumptions!$B$5)*CoreDCF!L11 -> 6411.3779
B43: Equity value | N43: =N42+$C$5+$C$6-($D$15+$I$15)/(1+Assumptions!$B$4)^Assumptions!$B$18 -> 18217.015
...

Sheet Sensitivity
B1: Sensitivity — BASE value / share (USD), pre-regulatory-haircut
B3: WACC (rows) x terminal core growth (cols)
C4: 0.02 | D4: 0.025 | E4: 0.03 | F4: 0.035 | G4: 0.04
B5: 0.08 | C5: =(NPV($B5,CoreDCF!$C$10:$L$10)+CoreDCF!$L$10*(1+C$4)/($B5-C$4)/(1+$B5)^10+NPV($B5,Float!$C$9:$L$9)+Float!$L$9*(1+Assumptions!$B$6)/($B5-Assumptions!$B$6)/(1+$B5)^10+Assumptions!$B$10)/Assumptions!$B$9 -> 25.453357 | D5: =(NPV($B5,CoreDCF!$C$10:$L$10)+CoreDCF!$L$10*(1+D$4)/($B5-D$4)/(1+$B5)^10+NPV($B5,Float!$C$9:$L$9)+Float!$L$9*(1+Assumptions!$B$6)/($B5-Assumptions!$B$6)/(1+$B5)^10+Assumptions!$B$10)/Assumptions!$B$9 -> 26.068077 | E5: =(NPV($B5,CoreDCF!$C$10:$L$10)+CoreDCF!$L$10*(1+E$4)/($B5-E$4)/(1+$B5)^10+NPV($B5,Float!$C$9:$L$9)+Float!$L$9*(1+Assumptions!$B$6)/($B5-Assumptions!$B$6)/(1+$B5)^10+Assumptions!$B$10)/Assumptions!$B$9 -> 26.80574 | F5: =(NPV($B5,CoreDCF!$C$10:$L$10)+CoreDCF!$L$10*(1+F$4)/($B5-F$4)/(1+$B5)^10+NPV($B5,Float!$C$9:$L$9)+Float!$L$9*(1+Assumptions!$B$6)/($B5-Assumptions!$B$6)/(1+$B5)^10+Assumptions!$B$10)/Assumptions!$B$9 -> 27.70733 | G5: =(NPV($B5,CoreDCF!$C$10:$L$10)+CoreDCF!$L$10*(1+G$4)/($B5-G$4)/(1+$B5)^10+NPV($B5,Float!$C$9:$L$9)+Float!$L$9*(1+Assumptions!$B$6)/($B5-Assumptions!$B$6)/(1+$B5)^10+Assumptions!$B$10)/Assumptions!$B$9 -> 28.834316
B6: 0.09 | C6: =(NPV($B6,CoreDCF!$C$10:$L$10)+CoreDCF!$L$10*(1+C$4)/($B6-C$4)/(1+$B6)^10+NPV($B6,Float!$C$9:$L$9)+Float!$L$9*(1+Assumptions!$B$6)/($B6-Assumptions!$B$6)/(1+$B6)^10+Assumptions!$B$10)/Assumptions!$B$9 -> 21.645858 | D6: =(NPV($B6,CoreDCF!$C$10:$L$10)+CoreDCF!$L$10*(1+D$4)/($B6-D$4)/(1+$B6)^10+NPV($B6,Float!$C$9:$L$9)+Float!$L$9*(1+Assumptions!$B$6)/($B6-Assumptions!$B$6)/(1+$B6)^10+Assumptions!$B$10)/Assumptions!$B$9 -> 22.056208 | E6: =(NPV($B6,CoreDCF!$C$10:$L$10)+CoreDCF!$L$10*(1+E$4)/($B6-E$4)/(1+$B6)^10+NPV($B6,Float!$C$9:$L$9)+Float!$L$9*(1+Assumptions!$B$6)/($B6-Assumptions!$B$6)/(1+$B6)^10+Assumptions!$B$10)/Assumptions!$B$9 -> 22.534951 | F6: =(NPV($B6,CoreDCF!$C$10:$L$10)+CoreDCF!$L$10*(1+F$4)/($B6-F$4)/(1+$B6)^10+NPV($B6,Float!$C$9:$L$9)+Float!$L$9*(1+Assumptions!$B$6)/($B6-Assumptions!$B$6)/(1+$B6)^10+Assumptions!$B$10)/Assumptions!$B$9 -> 23.100737 | G6: =(NPV($B6,CoreDCF!$C$10:$L$10)+CoreDCF!$L$10*(1+G$4)/($B6-G$4)/(1+$B6)^10+NPV($B6,Float!$C$9:$L$9)+Float!$L$9*(1+Assumptions!$B$6)/($B6-Assumptions!$B$6)/(1+$B6)^10+Assumptions!$B$10)/Assumptions!$B$9 -> 23.779681
B7: 0.1 | C7: =(NPV($B7,CoreDCF!$C$10:$L$10)+CoreDCF!$L$10*(1+C$4)/($B7-C$4)/(1+$B7)^10+NPV($B7,Float!$C$9:$L$9)+Float!$L$9*(1+Assumptions!$B$6)/($B7-Assumptions!$B$6)/(1+$B7)^10+Assumptions!$B$10)/Assumptions!$B$9 -> 18.811015 | D7: =(NPV($B7,CoreDCF!$C$10:$L$10)+CoreDCF!$L$10*(1+D$4)/($B7-D$4)/(1+$B7)^10+NPV($B7,Float!$C$9:$L$9)+Float!$L$9*(1+Assumptions!$B$6)/($B7-Assumptions!$B$6)/(1+$B7)^10+Assumptions!$B$10)/Assumptions!$B$9 -> 19.097644 | E7: =(NPV($B7,CoreDCF!$C$10:$L$10)+CoreDCF!$L$10*(1+E$4)/($B7-E$4)/(1+$B7)^10+NPV($B7,Float!$C$9:$L$9)+Float!$L$9*(1+Assumptions!$B$6)/($B7-Assumptions!$B$6)/(1+$B7)^10+Assumptions!$B$10)/Assumptions!$B$9 -> 19.42522 | F7: =(NPV($B7,CoreDCF!$C$10:$L$10)+CoreDCF!$L$10*(1+F$4)/($B7-F$4)/(1+$B7)^10+NPV($B7,Float!$C$9:$L$9)+Float!$L$9*(1+Assumptions!$B$6)/($B7-Assumptions!$B$6)/(1+$B7)^10+Assumptions!$B$10)/Assumptions!$B$9 -> 19.803191 | G7: =(NPV($B7,CoreDCF!$C$10:$L$10)+CoreDCF!$L$10*(1+G$4)/($B7-G$4)/(1+$B7)^10+NPV($B7,Float!$C$9:$L$9)+Float!$L$9*(1+Assumptions!$B$6)/($B7-Assumptions!$B$6)/(1+$B7)^10+Assumptions!$B$10)/Assumptions!$B$9 -> 20.244159
B8: 0.11 | C8: =(NPV($B8,CoreDCF!$C$10:$L$10)+CoreDCF!$L$10*(1+C$4)/($B8-C$4)/(1+$B8)^10+NPV($B8,Float!$C$9:$L$9)+Float!$L$9*(1+Assumptions!$B$6)/($B8-Assumptions!$B$6)/(1+$B8)^10+Assumptions!$B$10)/Assumptions!$B$9 -> 16.623332 | D8: =(NPV($B8,CoreDCF!$C$10:$L$10)+CoreDCF!$L$10*(1+D$4)/($B8-D$4)/(1+$B8)^10+NPV($B8,Float!$C$9:$L$9)+Float!$L$9*(1+Assumptions!$B$6)/($B8-Assumptions!$B$6)/(1+$B8)^10+Assumptions!$B$10)/Assumptions!$B$9 -> 16.830554 | E8: =(NPV($B8,CoreDCF!$C$10:$L$10)+CoreDCF!$L$10*(1+E$4)/($B8-E$4)/(1+$B8)^10+NPV($B8,Float!$C$9:$L$9)+Float!$L$9*(1+Assumptions!$B$6)/($B8-Assumptions!$B$6)/(1+$B8)^10+Assumptions!$B$10)/Assumptions!$B$9 -> 17.063679 | F8: =(NPV($B8,CoreDCF!$C$10:$L$10)+CoreDCF!$L$10*(1+F$4)/($B8-F$4)/(1+$B8)^10+NPV($B8,Float!$C$9:$L$9)+Float!$L$9*(1+Assumptions!$B$6)/($B8-Assumptions!$B$6)/(1+$B8)^10+Assumptions!$B$10)/Assumptions!$B$9 -> 17.327888 | G8: =(NPV($B8,CoreDCF!$C$10:$L$10)+CoreDCF!$L$10*(1+G$4)/($B8-G$4)/(1+$B8)^10+NPV($B8,Float!$C$9:$L$9)+Float!$L$9*(1+Assumptions!$B$6)/($B8-Assumptions!$B$6)/(1+$B8)^10+Assumptions!$B$10)/Assumptions!$B$9 -> 17.629841
B9: 0.12 | C9: =(NPV($B9,CoreDCF!$C$10:$L$10)+CoreDCF!$L$10*(1+C$4)/($B9-C$4)/(1+$B9)^10+NPV($B9,Float!$C$9:$L$9)+Float!$L$9*(1+Assumptions!$B$6)/($B9-Assumptions!$B$6)/(1+$B9)^10+Assumptions!$B$10)/Assumptions!$B$9 -> 14.887602 | D9: =(NPV($B9,CoreDCF!$C$10:$L$10)+CoreDCF!$L$10*(1+D$4)/($B9-D$4)/(1+$B9)^10+NPV($B9,Float!$C$9:$L$9)+Float!$L$9*(1+Assumptions!$B$6)/($B9-Assumptions!$B$6)/(1+$B9)^10+Assumptions!$B$10)/Assumptions!$B$9 -> 15.041531 | E9: =(NPV($B9,CoreDCF!$C$10:$L$10)+CoreDCF!$L$10*(1+E$4)/($B9-E$4)/(1+$B9)^10+NPV($B9,Float!$C$9:$L$9)+Float!$L$9*(1+Assumptions!$B$6)/($B9-Assumptions!$B$6)/(1+$B9)^10+Assumptions!$B$10)/Assumptions!$B$9 -> 15.212563 | F9: =(NPV($B9,CoreDCF!$C$10:$L$10)+CoreDCF!$L$10*(1+F$4)/($B9-F$4)/(1+$B9)^10+NPV($B9,Float!$C$9:$L$9)+Float!$L$9*(1+Assumptions!$B$6)/($B9-Assumptions!$B$6)/(1+$B9)^10+Assumptions!$B$10)/Assumptions!$B$9 -> 15.403716 | G9: =(NPV($B9,CoreDCF!$C$10:$L$10)+CoreDCF!$L$10*(1+G$4)/($B9-G$4)/(1+$B9)^10+NPV($B9,Float!$C$9:$L$9)+Float!$L$9*(1+Assumptions!$B$6)/($B9-Assumptions!$B$6)/(1+$B9)^10+Assumptions!$B$10)/Assumptions!$B$9 -> 15.618763
B11: Center cell (10% / 3.0%) ties to Scenarios!C8 base value per share.
B13: Normalized float yield sensitivity (base value / share, USD)
C14: 0.0075 | D14: 0.01 | E14: 0.0125 | F14: 0.015 | G14: 0.0175
B15: Value / share | C15: =(CoreDCF!$N$17+Float!$N$16*C$14/Assumptions!$B$13+Assumptions!$B$10)/Assumptions!$B$9 -> 14.29886 | D15: =(CoreDCF!$N$17+Float!$N$16*D$14/Assumptions!$B$13+Assumptions!$B$10)/Assumptions!$B$9 -> 16.007647 | E15: =(CoreDCF!$N$17+Float!$N$16*E$14/Assumptions!$B$13+Assumptions!$B$10)/Assumptions!$B$9 -> 17.716433 | F15: =(CoreDCF!$N$17+Float!$N$16*F$14/Assumptions!$B$13+Assumptions!$B$10)/Assumptions!$B$9 -> 19.42522 | G15: =(CoreDCF!$N$17+Float!$N$16*G$14/Assumptions!$B$13+Assumptions!$B$10)/Assumptions!$B$9 -> 21.134006
B16: Float EV scales linearly with retained yield; 1.75% approximates the current spot economics, 1.25% the modelled normalized level.
B18: Scenario C probability sensitivity (weighted value / share; P(C) taken from P(A))
C19: 0.05 | D19: 0.1 | E19: 0.15 | F19: 0.2 | G19: 0.3
B20: Weighted value / share | C20: =(Scenarios!$C$13+Scenarios!$C$15-C$19)*Scenarios!$N$28+Scenarios!$C$14*Scenarios!$N$36+C$19*Scenarios!$N$44+Scenarios!$C$16*Scenarios!$N$52 -> 18.770203 | D20: =(Scenarios!$C$13+Scenarios!$C$15-D$19)*Scenarios!$N$28+Scenarios!$C$14*Scenarios!$N$36+D$19*Scenarios!$N$44+Scenarios!$C$16*Scenarios!$N$52 -> 18.717816 | E20: =(Scenarios!$C$13+Scenarios!$C$15-E$19)*Scenarios!$N$28+Scenarios!$C$14*Scenarios!$N$36+E$19*Scenarios!$N$44+Scenarios!$C$16*Scenarios!$N$52 -> 18.665428 | F20: =(Scenarios!$C$13+Scenarios!$C$15-F$19)*Scenarios!$N$28+Scenarios!$C$14*Scenarios!$N$36+F$19*Scenarios!$N$44+Scenarios!$C$16*Scenarios!$N$52 -> 18.61304 | G20: =(Scenarios!$C$13+Scenarios!$C$15-G$19)*Scenarios!$N$28+Scenarios!$C$14*Scenarios!$N$36+G$19*Scenarios!$N$44+Scenarios!$C$16*Scenarios!$N$52 -> 18.508264
