Workbook

Sheet DCF Model
A1: BFG.NZ (Burger Fuel Group) DCF Valuation Model
A2: Gray cells are INPUTS - adjust to see valuation change. NZD millions unless noted.
A4: KEY INPUTS
A5: Current Stock Price (NZD) | B5: 0.32
A6: Shares Outstanding (M) | B6: 35.235787
A7: Cash & Equivalents (M) | B7: 6.131307
A8: Total Debt (M) | B8: 0
A9: Net Debt (M) [negative = net cash] | B9: =B8-B7 -> 0
A10: Reported FCF, FY2026 (M) | B10: 2.938
A11: Less: Bank Interest Income (M) | B11: 0.160916
A12: Less: IFRS16 Lease Principal Repayment (M) | B12: 0.861726
A13: Owner FCF, Base Year (M) | B13: =B10-B11-B12 -> 0
A14: Stock-Based Compensation | B14: 0 | C14: Confirmed ZERO - no SBC scheme exists (full-text verified)
A15: Annual Share Growth (dilution) | B15: 0 | C15: No SBC, no buybacks planned - share count held flat
A17: WACC (Base) | B17: 0.17
A18: Terminal Growth Rate | B18: 0.02
A19: Terminal Cap Multiple (x owner FCF) | B19: 15
A21: WACC BUILD (documented stack)
A22: NZ small-cap base | B22: 0.115
A23: Nano-cap illiquidity premium | B23: 0.025
A24: Register concentration premium | B24: 0.0175
A25: Single-market cyclicality premium | B25: 0.0125
A26: Total WACC (sum, matches B17) | B26: =SUM(B22:B25) -> 0
A28: GROWTH ASSUMPTIONS (Base Case - Revenue growth) | B28: FY27 | C28: FY28 | D28: FY29 | E28: FY30 | F28: FY31
B29: 0.015 | C29: 0.015 | D29: 0.015 | E29: 0.01 | F29: 0.01
A30: EBITDA Margin | B30: 0.187 | C30: 0.188 | D30: 0.189 | E30: 0.189 | F30: 0.19
A31: D&A % of Revenue | B31: 0.072 | C31: 0.072 | D31: 0.072 | E31: 0.072 | F31: 0.072
A32: Capex % of Revenue | B32: 0.023 | C32: 0.023 | D32: 0.023 | E32: 0.023 | F32: 0.023
A33: Lease Principal % of Revenue | B33: 0.034 | C33: 0.034 | D33: 0.034 | E33: 0.034 | F33: 0.034
A34: Franchisee Lending % of Revenue | B34: 0.0117 | C34: 0.0117 | D34: 0.0117 | E34: 0.0117 | F34: 0.0117
A35: Cash Tax Rate | B35: 0.27 | C35: 0.28 | D35: 0.28 | E35: 0.28 | F35: 0.28
A37: PROJECTIONS (component build)
B38: FY27 | C38: FY28 | D38: FY29 | E38: FY30 | F38: FY31
A39: Revenue | B39: =B40*(1+B29) -> 0 | C39: =B39*(1+C29) -> 0 | D39: =C39*(1+D29) -> 0 | E39: =D39*(1+E29) -> 0 | F39: =E39*(1+F29) -> 0
A40: Revenue FY2026 (actual, helper) | B40: 24.845
A41: Adj. EBITDA | B41: =B39*B30 -> 0 | C41: =C39*C30 -> 0 | D41: =D39*D30 -> 0 | E41: =E39*E30 -> 0 | F41: =F39*F30 -> 0
A42: D&A | B42: =B39*$B$31 -> 0 | C42: =C39*$B$31 -> 0 | D42: =D39*$B$31 -> 0 | E42: =E39*$B$31 -> 0 | F42: =F39*$B$31 -> 0
A43: EBIT | B43: =B41-B42 -> 0 | C43: =C41-C42 -> 0 | D43: =D41-D42 -> 0 | E43: =E41-E42 -> 0 | F43: =F41-F42 -> 0
A44: NOPAT | B44: =B43*(1-B35) -> 0 | C44: =C43*(1-C35) -> 0 | D44: =D43*(1-D35) -> 0 | E44: =E43*(1-E35) -> 0 | F44: =F43*(1-F35) -> 0
A45: Capex | B45: =B39*$B$32 -> 0 | C45: =C39*$B$32 -> 0 | D45: =D39*$B$32 -> 0 | E45: =E39*$B$32 -> 0 | F45: =F39*$B$32 -> 0
...

Sheet Sensitivity
A1: Sensitivity Analysis
A2: Intrinsic Value by WACC & Terminal Growth (Base Case)
A4: WACC \ Term G | B4: 0.01 | C4: 0.015 | D4: 0.02 | E4: 0.025 | F4: 0.03
A5: 0.13 | B5: =(SUMPRODUCT('DCF Model'!$B$48:$F$48,1/(1+0.13)^{1,2,3,4,5})+MIN('DCF Model'!$F$48*(1+0.01)/(0.13-0.01),'DCF Model'!$B$19*'DCF Model'!$F$48)/(1+0.13)^5-'DCF Model'!$B$9)/'DCF Model'!$B$6 -> 0 | C5: =(SUMPRODUCT('DCF Model'!$B$48:$F$48,1/(1+0.13)^{1,2,3,4,5})+MIN('DCF Model'!$F$48*(1+0.015)/(0.13-0.015),'DCF Model'!$B$19*'DCF Model'!$F$48)/(1+0.13)^5-'DCF Model'!$B$9)/'DCF Model'!$B$6 -> 0 | D5: =(SUMPRODUCT('DCF Model'!$B$48:$F$48,1/(1+0.13)^{1,2,3,4,5})+MIN('DCF Model'!$F$48*(1+0.02)/(0.13-0.02),'DCF Model'!$B$19*'DCF Model'!$F$48)/(1+0.13)^5-'DCF Model'!$B$9)/'DCF Model'!$B$6 -> 0 | E5: =(SUMPRODUCT('DCF Model'!$B$48:$F$48,1/(1+0.13)^{1,2,3,4,5})+MIN('DCF Model'!$F$48*(1+0.025)/(0.13-0.025),'DCF Model'!$B$19*'DCF Model'!$F$48)/(1+0.13)^5-'DCF Model'!$B$9)/'DCF Model'!$B$6 -> 0 | F5: =(SUMPRODUCT('DCF Model'!$B$48:$F$48,1/(1+0.13)^{1,2,3,4,5})+MIN('DCF Model'!$F$48*(1+0.03)/(0.13-0.03),'DCF Model'!$B$19*'DCF Model'!$F$48)/(1+0.13)^5-'DCF Model'!$B$9)/'DCF Model'!$B$6 -> 0
A6: 0.15 | B6: =(SUMPRODUCT('DCF Model'!$B$48:$F$48,1/(1+0.15)^{1,2,3,4,5})+MIN('DCF Model'!$F$48*(1+0.01)/(0.15-0.01),'DCF Model'!$B$19*'DCF Model'!$F$48)/(1+0.15)^5-'DCF Model'!$B$9)/'DCF Model'!$B$6 -> 0 | C6: =(SUMPRODUCT('DCF Model'!$B$48:$F$48,1/(1+0.15)^{1,2,3,4,5})+MIN('DCF Model'!$F$48*(1+0.015)/(0.15-0.015),'DCF Model'!$B$19*'DCF Model'!$F$48)/(1+0.15)^5-'DCF Model'!$B$9)/'DCF Model'!$B$6 -> 0 | D6: =(SUMPRODUCT('DCF Model'!$B$48:$F$48,1/(1+0.15)^{1,2,3,4,5})+MIN('DCF Model'!$F$48*(1+0.02)/(0.15-0.02),'DCF Model'!$B$19*'DCF Model'!$F$48)/(1+0.15)^5-'DCF Model'!$B$9)/'DCF Model'!$B$6 -> 0 | E6: =(SUMPRODUCT('DCF Model'!$B$48:$F$48,1/(1+0.15)^{1,2,3,4,5})+MIN('DCF Model'!$F$48*(1+0.025)/(0.15-0.025),'DCF Model'!$B$19*'DCF Model'!$F$48)/(1+0.15)^5-'DCF Model'!$B$9)/'DCF Model'!$B$6 -> 0 | F6: =(SUMPRODUCT('DCF Model'!$B$48:$F$48,1/(1+0.15)^{1,2,3,4,5})+MIN('DCF Model'!$F$48*(1+0.03)/(0.15-0.03),'DCF Model'!$B$19*'DCF Model'!$F$48)/(1+0.15)^5-'DCF Model'!$B$9)/'DCF Model'!$B$6 -> 0
A7: 0.17 | B7: =(SUMPRODUCT('DCF Model'!$B$48:$F$48,1/(1+0.17)^{1,2,3,4,5})+MIN('DCF Model'!$F$48*(1+0.01)/(0.17-0.01),'DCF Model'!$B$19*'DCF Model'!$F$48)/(1+0.17)^5-'DCF Model'!$B$9)/'DCF Model'!$B$6 -> 0 | C7: =(SUMPRODUCT('DCF Model'!$B$48:$F$48,1/(1+0.17)^{1,2,3,4,5})+MIN('DCF Model'!$F$48*(1+0.015)/(0.17-0.015),'DCF Model'!$B$19*'DCF Model'!$F$48)/(1+0.17)^5-'DCF Model'!$B$9)/'DCF Model'!$B$6 -> 0 | D7: =(SUMPRODUCT('DCF Model'!$B$48:$F$48,1/(1+0.17)^{1,2,3,4,5})+MIN('DCF Model'!$F$48*(1+0.02)/(0.17-0.02),'DCF Model'!$B$19*'DCF Model'!$F$48)/(1+0.17)^5-'DCF Model'!$B$9)/'DCF Model'!$B$6 -> 0 | E7: =(SUMPRODUCT('DCF Model'!$B$48:$F$48,1/(1+0.17)^{1,2,3,4,5})+MIN('DCF Model'!$F$48*(1+0.025)/(0.17-0.025),'DCF Model'!$B$19*'DCF Model'!$F$48)/(1+0.17)^5-'DCF Model'!$B$9)/'DCF Model'!$B$6 -> 0 | F7: =(SUMPRODUCT('DCF Model'!$B$48:$F$48,1/(1+0.17)^{1,2,3,4,5})+MIN('DCF Model'!$F$48*(1+0.03)/(0.17-0.03),'DCF Model'!$B$19*'DCF Model'!$F$48)/(1+0.17)^5-'DCF Model'!$B$9)/'DCF Model'!$B$6 -> 0
A8: 0.19 | B8: =(SUMPRODUCT('DCF Model'!$B$48:$F$48,1/(1+0.19)^{1,2,3,4,5})+MIN('DCF Model'!$F$48*(1+0.01)/(0.19-0.01),'DCF Model'!$B$19*'DCF Model'!$F$48)/(1+0.19)^5-'DCF Model'!$B$9)/'DCF Model'!$B$6 -> 0 | C8: =(SUMPRODUCT('DCF Model'!$B$48:$F$48,1/(1+0.19)^{1,2,3,4,5})+MIN('DCF Model'!$F$48*(1+0.015)/(0.19-0.015),'DCF Model'!$B$19*'DCF Model'!$F$48)/(1+0.19)^5-'DCF Model'!$B$9)/'DCF Model'!$B$6 -> 0 | D8: =(SUMPRODUCT('DCF Model'!$B$48:$F$48,1/(1+0.19)^{1,2,3,4,5})+MIN('DCF Model'!$F$48*(1+0.02)/(0.19-0.02),'DCF Model'!$B$19*'DCF Model'!$F$48)/(1+0.19)^5-'DCF Model'!$B$9)/'DCF Model'!$B$6 -> 0 | E8: =(SUMPRODUCT('DCF Model'!$B$48:$F$48,1/(1+0.19)^{1,2,3,4,5})+MIN('DCF Model'!$F$48*(1+0.025)/(0.19-0.025),'DCF Model'!$B$19*'DCF Model'!$F$48)/(1+0.19)^5-'DCF Model'!$B$9)/'DCF Model'!$B$6 -> 0 | F8: =(SUMPRODUCT('DCF Model'!$B$48:$F$48,1/(1+0.19)^{1,2,3,4,5})+MIN('DCF Model'!$F$48*(1+0.03)/(0.19-0.03),'DCF Model'!$B$19*'DCF Model'!$F$48)/(1+0.19)^5-'DCF Model'!$B$9)/'DCF Model'!$B$6 -> 0
A9: 0.21 | B9: =(SUMPRODUCT('DCF Model'!$B$48:$F$48,1/(1+0.21)^{1,2,3,4,5})+MIN('DCF Model'!$F$48*(1+0.01)/(0.21-0.01),'DCF Model'!$B$19*'DCF Model'!$F$48)/(1+0.21)^5-'DCF Model'!$B$9)/'DCF Model'!$B$6 -> 0 | C9: =(SUMPRODUCT('DCF Model'!$B$48:$F$48,1/(1+0.21)^{1,2,3,4,5})+MIN('DCF Model'!$F$48*(1+0.015)/(0.21-0.015),'DCF Model'!$B$19*'DCF Model'!$F$48)/(1+0.21)^5-'DCF Model'!$B$9)/'DCF Model'!$B$6 -> 0 | D9: =(SUMPRODUCT('DCF Model'!$B$48:$F$48,1/(1+0.21)^{1,2,3,4,5})+MIN('DCF Model'!$F$48*(1+0.02)/(0.21-0.02),'DCF Model'!$B$19*'DCF Model'!$F$48)/(1+0.21)^5-'DCF Model'!$B$9)/'DCF Model'!$B$6 -> 0 | E9: =(SUMPRODUCT('DCF Model'!$B$48:$F$48,1/(1+0.21)^{1,2,3,4,5})+MIN('DCF Model'!$F$48*(1+0.025)/(0.21-0.025),'DCF Model'!$B$19*'DCF Model'!$F$48)/(1+0.21)^5-'DCF Model'!$B$9)/'DCF Model'!$B$6 -> 0 | F9: =(SUMPRODUCT('DCF Model'!$B$48:$F$48,1/(1+0.21)^{1,2,3,4,5})+MIN('DCF Model'!$F$48*(1+0.03)/(0.21-0.03),'DCF Model'!$B$19*'DCF Model'!$F$48)/(1+0.21)^5-'DCF Model'!$B$9)/'DCF Model'!$B$6 -> 0

Sheet FCF Quality
A1: FCF Quality - Reported to Owner FCF Reconciliation
A3: NZD millions
B5: FY2024 | C5: FY2025 | D5: FY2026
A7: Reported Free Cash Flow (company def.) | B7: 2.386 | C7: 1.374 | D7: 2.938
A8: Less: Bank Interest Income | B8: -0.297754 | C8: -0.195118 | D8: -0.160916
A9: Less: IFRS16 Lease Principal Repayment | B9: -0.955937 | C9: -0.739683 | D9: -0.861726
A10: = Owner FCF | B10: =SUM(B6:B8) -> 0 | C10: =SUM(C6:C8) -> 0 | D10: =SUM(D6:D8) -> 0
A12: Revenue | B12: 26.247734 | C12: 24.055874 | D12: 24.844844
A13: Reported FCF Margin | B13: =B6/B12 -> 0 | C13: =C6/C12 -> 0 | D13: =D6/D12 -> 0
A14: Owner FCF Margin | B14: =B10/B12 -> 0 | C14: =C10/C12 -> 0 | D14: =D10/D12 -> 0
A16: Memo: SBC
A17: Stock-based compensation - CONFIRMED ZERO (no scheme exists, full-text verified across all FY2018-FY2026 filings)
A19: Memo: Cash Tax Rate
A20: FY2026 effective tax rate: 25.9% | FY2025: 33.1% - both near/above the 28% NZ statutory rate, no valuation-allowance benefit to ramp down
A22: Memo: One-offs normalized out (earnings, not cash flow)
A23: FY2026: $288K Ponsonby store sale gain (non-cash, direct-method CF statement unaffected)
A24: FY2024: ~$205.5K contested capital-return legal costs (real cash cost, already in reported FCF)
A25: FY2025: ~$221.7K contested capital-return legal costs (real cash cost, already in reported FCF)
A27: Memo: Franchisee lending (investing activity, recurring drag)
A28: FY2024 net -$1.8K | FY2025 net -$71.4K | FY2026 net -$289.9K - modelled forward as ~1.0-1.5% of revenue

Sheet Historical
A1: Historical Growth Rates
A3: Metric | B3: 3-Year CAGR | C3: 5-8 Year CAGR
A5: Revenue | B5: 0.0277 | C5: 0.059
A6: Revenue (8yr) | C6: 0.0004
A7: EPS (distorted - see note) | B7: 0.4618 | C7: 0.3159
A8: Equity (distorted - see note) | C8: 0.0274
A9: Owner FCF (2yr, noisy small base) | B9: 0.3007
A11: Selected Growth Rate (DCF driver): | B11: 0.012
A12: Source: | B12: revenue_and_system_sales_trend - NOT equity/EPS/FCF CAGR
A14: Growth divergence warning:
A15: SEVERE: Revenue is essentially flat over 8 years (FY2018 $24.774m to FY2026 $24.845m, 0.04% CAGR). EPS and FCF CAGRs shown above (31-46% and 11-30%) are statistical artifacts of a depressed FY2023/24 or FY2024/25 base recovering to a normalized FY2026, combined with the 30% share-count reduction from the June-2024 capital return (50.337m to 35.236m shares) - they are NOT indicative of a growth trajectory and must not be used as the DCF driver. Equity CAGR is similarly distorted by the same capital return (a $4.33m cash outflow that mechanically shrinks book value independent of trading performance). Per management's own FY2027 guidance ('roughly flat' system sales, 'far more challenging operating environment'), the DCF growth driver used is revenue/system-sales trend of approximately 0-2% per year, not any of the CAGRs above.

Sheet Model_Info
A1: Model Provenance & Notes
A3: Built by | B3: Claude agent (DCF valuation skill), Anthropic
A4: Data vintage - price | B4: NZ$0.32, Yahoo Finance NZSE, quoted 2026-08-09
A5: Data vintage - financials | B5: FY2026 preliminary results (year ended 31 March 2026), released 29 May 2026; FY2018-FY2026 annual reports and H1-2018 through H1-2025 half-year reports in research/BFG.NZ/Extracted/
A6: Methodology | B6: Component owner-FCF build (EBITDA -> D&A -> tax -> capex -> lease principal -> franchisee lending), 5-year explicit horizon (margins already near mature/steady-state, no ramp needed), Gordon growth terminal value capped at 15x Yr5 owner FCF, 3-scenario (bull/base/bear) probability-weighted (25/50/25)
A7: SBC treatment | B7: Confirmed genuinely ZERO via full-text search of every FY2018-FY2026 filing - no share-based payment scheme exists. This is NOT an "unavailable" case; it is a verified true zero.
A8: Interest income treatment | B8: Bank interest income ($160,916 FY2026) stripped from FCF because net cash ($6.13m) exceeds 1x the FCF base. The separate IFRS16 sublease "Interest Income - non-occupied leases" ($785,502) is NOT stripped because it is exactly offset by an equal IFRS16 sublease interest EXPENSE - net zero real cash effect, confirmed by direct comparison of both P&L lines.
A9: Lease principal treatment | B9: IFRS16 lease liability principal repayments ($861,726 FY2026) are a real cash cost sitting in financing activities that reported OCF/FCF excludes; deducted from reported FCF to reach owner FCF, consistent with treatment of 2CC.NZ and TAH.NZ elsewhere in this repo.
A10: Ponsonby $288K gain treatment | B10: NOT deducted from FCF - BFG uses the DIRECT method cash flow statement (Receipts from customers, not a Net-Profit reconciliation), so this non-cash P&L gain never inflated reported OCF/FCF in the first place. Only normalized out of NetIncome/EPS commentary.
A11: FY2024/25 legal costs | B11: Real cash SG&A costs (~$205.5K FY24, ~$221.7K FY25) already inside those years reported FCF - explains why FY2026 profit growth (+91.8%) partly reflects the absence of a one-off drag rather than organic acceleration. NOT extrapolated forward.
A12: Growth driver | B12: Revenue / Total System Sales trend (~0-2%/yr), NOT equity/EPS/FCF CAGR - all three are distorted by the June-2024 30% share cancellation capital return and/or the FY24-25 legal cost swing. Revenue is essentially flat over 8 years (0.04% CAGR).
A13: WACC | B13: 17.0% base case - documented 4-layer stack: NZ small-cap base (11.5%) + nano-cap illiquidity (2.5%) + register concentration (1.75%) + single-market cyclicality (1.25%). See Wacc build in DCF Model sheet rows 21-26.
A14: Entry price | B14: Capped at intrinsic value because WACC (17%) exceeds the 15% IRR hurdle rate here - an edge case not seen in most tickers in this repo (which typically have WACC below 15%). Paying full intrinsic value already delivers an expected return equal to WACC, so no rational investor should pay MORE than IV chasing a return target below the required return.
... A17: Staleness warning | B17: All figures are current as of the FY2026 preliminary result (29 May 2026) and the 8 Aug 2026 share price. This is a nano-cap with thin trading and event risk (new store openings, Middle East developments, any renewed shareholder disputes) - re-verify before relying on this model more than one reporting period out.
