Workbook

Sheet Overview
A1: NU (Nu Holdings) - DCF Valuation Summary
A2: Distributable-Earnings Bank Model | Discounted at Cost of Equity | net_debt = 0
A4: Current Price | B4: 14.09
A5: Shares Outstanding (M) | B5: 4910.3
A6: Base Year TTM Net Income (M) | B6: 3183.8
B8: Bear | C8: Base | D8: Bull
A9: Intrinsic Value / Share | B9: ='Bear Case'!B40 -> 0 | C9: ='Base Case'!B40 -> 0 | D9: ='Bull Case'!B40 -> 0
A10: Upside / (Downside) | B10: ='Bear Case'!B41 -> 0 | C10: ='Base Case'!B41 -> 0 | D10: ='Bull Case'!B41 -> 0
A11: Entry Price (15% IRR) | B11: ='Bear Case'!B50 -> 0 | C11: ='Base Case'!B50 -> 0 | D11: ='Bull Case'!B50 -> 0
A12: Terminal Value % of Equity Value | B12: ='Bear Case'!B42 -> 0 | C12: ='Base Case'!B42 -> 0 | D12: ='Bull Case'!B42 -> 0
A13: Implied Exit P/E (Yr5 NI) | B13: ='Bear Case'!B43 -> 0 | C13: ='Base Case'!B43 -> 0 | D13: ='Bull Case'!B43 -> 0
A15: PROBABILITY-WEIGHTED VALUATION
A16: Weight - Bear | B16: 0.25
A17: Weight - Base | B17: 0.5
A18: Weight - Bull | B18: 0.25
A19: Weighted Intrinsic Value | B19: =B9*B16+C9*B17+D9*B18 -> 0
A20: Weighted Upside / (Downside) | B20: =(B19-B4)/B4 -> 0
A22: Note: current TTM P/E is ~21.7x. All three scenarios imply exit P/E multiples
A23: well below today's multiple (7-10x), so the model does NOT assume multiple expansion.

Sheet Base Case
A1: NU DCF - Base Case (Distributable Earnings Model)
A2: Gray cells are INPUTS - adjust to see valuation change. Bank equity model: net_debt=0, discount at Cost of Equity.
A4: KEY INPUTS
A5: Current Stock Price | B5: 14.09
A6: Shares Outstanding (M) | B6: 4910.3
A7: Net Debt (M) [bank: 0] | B7: 0
A8: Base Year Net Income - TTM (M) | B8: 3183.8
A10: Cost of Equity (CoE) | B10: 0.135
A11: Terminal Growth Rate | B11: 0.0375
A12: Terminal (Mature) ROE | B12: 0.22
A13: Exit P/E Cap (on Yr5 NI) | B13: 18
A15: GROWTH & ROE ASSUMPTIONS
B16: Year 1 | C16: Year 2 | D16: Year 3 | E16: Year 4 | F16: Year 5
A17: NI Growth Rate | B17: 0.35 | C17: 0.28 | D17: 0.22 | E17: 0.18 | F17: 0.15
A18: ROE (period) | B18: 0.28 | C18: 0.27 | D18: 0.26 | E18: 0.255 | F18: 0.25
A20: PROJECTIONS (Net Income & Distributable Earnings, $M)
B21: Year 1 | C21: Year 2 | D21: Year 3 | E21: Year 4 | F21: Year 5
A22: Net Income | B22: =B8*(1+B17) -> 0 | C22: =B22*(1+C17) -> 0 | D22: =C22*(1+D17) -> 0 | E22: =D22*(1+E17) -> 0 | F22: =E22*(1+F17) -> 0
A23: Retention Ratio (=Growth/ROE, capped 0-100%) | B23: =MIN(1,MAX(0,B17/B18)) -> 0 | C23: =MIN(1,MAX(0,C17/C18)) -> 0 | D23: =MIN(1,MAX(0,D17/D18)) -> 0 | E23: =MIN(1,MAX(0,E17/E18)) -> 0 | F23: =MIN(1,MAX(0,F17/F18)) -> 0
A24: Payout Ratio | B24: =1-B23 -> 0 | C24: =1-C23 -> 0 | D24: =1-D23 -> 0 | E24: =1-E23 -> 0 | F24: =1-F23 -> 0
A25: Distributable Earnings | B25: =B22*B24 -> 0 | C25: =C22*C24 -> 0 | D25: =D22*D24 -> 0 | E25: =E22*E24 -> 0 | F25: =F22*F24 -> 0
A26: Discount Factor (at CoE) | B26: =1/(1+$B$10)^1 -> 0 | C26: =1/(1+$B$10)^2 -> 0 | D26: =1/(1+$B$10)^3 -> 0 | E26: =1/(1+$B$10)^4 -> 0 | F26: =1/(1+$B$10)^5 -> 0
A27: PV of Distributable Earnings | B27: =B25*B26 -> 0 | C27: =C25*C26 -> 0 | D27: =D25*D26 -> 0 | E27: =E25*E26 -> 0 | F27: =F25*F26 -> 0
A29: VALUATION
A30: Sum of PV of Distributable Earnings | B30: =SUM(B27:F27) -> 0
A31: Terminal Retention (=TermG/TermROE) | B31: =MIN(1,MAX(0,B11/B12)) -> 0
A32: Terminal Payout Ratio | B32: =1-B31 -> 0
A33: Net Income Year 6 (=NI Yr5 * (1+TermG)) | B33: =F22*(1+B11) -> 0
A34: Terminal Distributable Earnings (Yr6) | B34: =B33*B32 -> 0
A35: Gordon Terminal Value | B35: =B34/(B10-B11) -> 0
A36: Exit P/E Cap Value (=ExitPE x NI Yr5) | B36: =B13*F22 -> 0
A37: Terminal Value (=MIN(Gordon, Exit P/E Cap)) | B37: =MIN(B35,B36) -> 0
A38: PV of Terminal Value | B38: =B37*F26 -> 0
A39: Equity Value (=SumPV + PVTerminal - NetDebt) | B39: =B30+B38-B7 -> 0
A40: INTRINSIC VALUE / SHARE | B40: =B39/B6 -> 0
A41: Upside / (Downside) vs Current Price | B41: =(B40-B5)/B5 -> 0
A42: Terminal Value % of Equity Value | B42: =B38/B39 -> 0
A43: Implied Exit P/E (on Yr5 NI) | B43: =B37/F22 -> 0
A45: ENTRY PRICE (15% IRR Target)
A46: Hurdle Rate | B46: 0.15
...

Sheet Bull Case
A1: NU DCF - Bull Case (Distributable Earnings Model)
A2: Gray cells are INPUTS - adjust to see valuation change. Bank equity model: net_debt=0, discount at Cost of Equity.
A4: KEY INPUTS
A5: Current Stock Price | B5: 14.09
A6: Shares Outstanding (M) | B6: 4910.3
A7: Net Debt (M) [bank: 0] | B7: 0
A8: Base Year Net Income - TTM (M) | B8: 3183.8
A10: Cost of Equity (CoE) | B10: 0.125
A11: Terminal Growth Rate | B11: 0.04
A12: Terminal (Mature) ROE | B12: 0.25
A13: Exit P/E Cap (on Yr5 NI) | B13: 24
A15: GROWTH & ROE ASSUMPTIONS
B16: Year 1 | C16: Year 2 | D16: Year 3 | E16: Year 4 | F16: Year 5
A17: NI Growth Rate | B17: 0.42 | C17: 0.35 | D17: 0.29 | E17: 0.25 | F17: 0.22
A18: ROE (period) | B18: 0.3 | C18: 0.295 | D18: 0.29 | E18: 0.285 | F18: 0.28
A20: PROJECTIONS (Net Income & Distributable Earnings, $M)
B21: Year 1 | C21: Year 2 | D21: Year 3 | E21: Year 4 | F21: Year 5
A22: Net Income | B22: =B8*(1+B17) -> 0 | C22: =B22*(1+C17) -> 0 | D22: =C22*(1+D17) -> 0 | E22: =D22*(1+E17) -> 0 | F22: =E22*(1+F17) -> 0
A23: Retention Ratio (=Growth/ROE, capped 0-100%) | B23: =MIN(1,MAX(0,B17/B18)) -> 0 | C23: =MIN(1,MAX(0,C17/C18)) -> 0 | D23: =MIN(1,MAX(0,D17/D18)) -> 0 | E23: =MIN(1,MAX(0,E17/E18)) -> 0 | F23: =MIN(1,MAX(0,F17/F18)) -> 0
A24: Payout Ratio | B24: =1-B23 -> 0 | C24: =1-C23 -> 0 | D24: =1-D23 -> 0 | E24: =1-E23 -> 0 | F24: =1-F23 -> 0
A25: Distributable Earnings | B25: =B22*B24 -> 0 | C25: =C22*C24 -> 0 | D25: =D22*D24 -> 0 | E25: =E22*E24 -> 0 | F25: =F22*F24 -> 0
A26: Discount Factor (at CoE) | B26: =1/(1+$B$10)^1 -> 0 | C26: =1/(1+$B$10)^2 -> 0 | D26: =1/(1+$B$10)^3 -> 0 | E26: =1/(1+$B$10)^4 -> 0 | F26: =1/(1+$B$10)^5 -> 0
A27: PV of Distributable Earnings | B27: =B25*B26 -> 0 | C27: =C25*C26 -> 0 | D27: =D25*D26 -> 0 | E27: =E25*E26 -> 0 | F27: =F25*F26 -> 0
A29: VALUATION
A30: Sum of PV of Distributable Earnings | B30: =SUM(B27:F27) -> 0
A31: Terminal Retention (=TermG/TermROE) | B31: =MIN(1,MAX(0,B11/B12)) -> 0
A32: Terminal Payout Ratio | B32: =1-B31 -> 0
A33: Net Income Year 6 (=NI Yr5 * (1+TermG)) | B33: =F22*(1+B11) -> 0
A34: Terminal Distributable Earnings (Yr6) | B34: =B33*B32 -> 0
A35: Gordon Terminal Value | B35: =B34/(B10-B11) -> 0
A36: Exit P/E Cap Value (=ExitPE x NI Yr5) | B36: =B13*F22 -> 0
A37: Terminal Value (=MIN(Gordon, Exit P/E Cap)) | B37: =MIN(B35,B36) -> 0
A38: PV of Terminal Value | B38: =B37*F26 -> 0
A39: Equity Value (=SumPV + PVTerminal - NetDebt) | B39: =B30+B38-B7 -> 0
A40: INTRINSIC VALUE / SHARE | B40: =B39/B6 -> 0
A41: Upside / (Downside) vs Current Price | B41: =(B40-B5)/B5 -> 0
A42: Terminal Value % of Equity Value | B42: =B38/B39 -> 0
A43: Implied Exit P/E (on Yr5 NI) | B43: =B37/F22 -> 0
A45: ENTRY PRICE (15% IRR Target)
A46: Hurdle Rate | B46: 0.15
...

Sheet Bear Case
A1: NU DCF - Bear Case (Distributable Earnings Model)
A2: Gray cells are INPUTS - adjust to see valuation change. Bank equity model: net_debt=0, discount at Cost of Equity.
A4: KEY INPUTS
A5: Current Stock Price | B5: 14.09
A6: Shares Outstanding (M) | B6: 4910.3
A7: Net Debt (M) [bank: 0] | B7: 0
A8: Base Year Net Income - TTM (M) | B8: 3183.8
A10: Cost of Equity (CoE) | B10: 0.15
A11: Terminal Growth Rate | B11: 0.03
A12: Terminal (Mature) ROE | B12: 0.18
A13: Exit P/E Cap (on Yr5 NI) | B13: 12
A15: GROWTH & ROE ASSUMPTIONS
B16: Year 1 | C16: Year 2 | D16: Year 3 | E16: Year 4 | F16: Year 5
A17: NI Growth Rate | B17: -0.05 | C17: 0.05 | D17: 0.1 | E17: 0.14 | F17: 0.16
A18: ROE (period) | B18: 0.22 | C18: 0.2 | D18: 0.21 | E18: 0.22 | F18: 0.23
A20: PROJECTIONS (Net Income & Distributable Earnings, $M)
B21: Year 1 | C21: Year 2 | D21: Year 3 | E21: Year 4 | F21: Year 5
A22: Net Income | B22: =B8*(1+B17) -> 0 | C22: =B22*(1+C17) -> 0 | D22: =C22*(1+D17) -> 0 | E22: =D22*(1+E17) -> 0 | F22: =E22*(1+F17) -> 0
A23: Retention Ratio (=Growth/ROE, capped 0-100%) | B23: =MIN(1,MAX(0,B17/B18)) -> 0 | C23: =MIN(1,MAX(0,C17/C18)) -> 0 | D23: =MIN(1,MAX(0,D17/D18)) -> 0 | E23: =MIN(1,MAX(0,E17/E18)) -> 0 | F23: =MIN(1,MAX(0,F17/F18)) -> 0
A24: Payout Ratio | B24: =1-B23 -> 0 | C24: =1-C23 -> 0 | D24: =1-D23 -> 0 | E24: =1-E23 -> 0 | F24: =1-F23 -> 0
A25: Distributable Earnings | B25: =B22*B24 -> 0 | C25: =C22*C24 -> 0 | D25: =D22*D24 -> 0 | E25: =E22*E24 -> 0 | F25: =F22*F24 -> 0
A26: Discount Factor (at CoE) | B26: =1/(1+$B$10)^1 -> 0 | C26: =1/(1+$B$10)^2 -> 0 | D26: =1/(1+$B$10)^3 -> 0 | E26: =1/(1+$B$10)^4 -> 0 | F26: =1/(1+$B$10)^5 -> 0
A27: PV of Distributable Earnings | B27: =B25*B26 -> 0 | C27: =C25*C26 -> 0 | D27: =D25*D26 -> 0 | E27: =E25*E26 -> 0 | F27: =F25*F26 -> 0
A29: VALUATION
A30: Sum of PV of Distributable Earnings | B30: =SUM(B27:F27) -> 0
A31: Terminal Retention (=TermG/TermROE) | B31: =MIN(1,MAX(0,B11/B12)) -> 0
A32: Terminal Payout Ratio | B32: =1-B31 -> 0
A33: Net Income Year 6 (=NI Yr5 * (1+TermG)) | B33: =F22*(1+B11) -> 0
A34: Terminal Distributable Earnings (Yr6) | B34: =B33*B32 -> 0
A35: Gordon Terminal Value | B35: =B34/(B10-B11) -> 0
A36: Exit P/E Cap Value (=ExitPE x NI Yr5) | B36: =B13*F22 -> 0
A37: Terminal Value (=MIN(Gordon, Exit P/E Cap)) | B37: =MIN(B35,B36) -> 0
A38: PV of Terminal Value | B38: =B37*F26 -> 0
A39: Equity Value (=SumPV + PVTerminal - NetDebt) | B39: =B30+B38-B7 -> 0
A40: INTRINSIC VALUE / SHARE | B40: =B39/B6 -> 0
A41: Upside / (Downside) vs Current Price | B41: =(B40-B5)/B5 -> 0
A42: Terminal Value % of Equity Value | B42: =B38/B39 -> 0
A43: Implied Exit P/E (on Yr5 NI) | B43: =B37/F22 -> 0
A45: ENTRY PRICE (15% IRR Target)
A46: Hurdle Rate | B46: 0.15
...

Sheet Sensitivity
A1: Sensitivity Analysis - Base Case
A2: Intrinsic Value by Cost of Equity & Terminal Growth
A4: CoE \ Term G | B4: 0.025 | C4: 0.03 | D4: 0.035 | E4: 0.04 | F4: 0.045
A5: 0.115 | B5: 11.75 | C5: 12.15 | D5: 12.6 | E5: 13.1 | F5: 13.67
A6: 0.125 | B6: 10.21 | C6: 10.49 | D6: 10.81 | E6: 11.16 | F6: 11.55
A7: 0.135 | B7: 8.96 | C7: 9.17 | D7: 9.39 | E7: 9.64 | F7: 9.92
A8: 0.145 | B8: 7.93 | C8: 8.08 | D8: 8.25 | E8: 8.43 | F8: 8.63
A9: 0.155 | B9: 7.07 | C9: 7.19 | D9: 7.31 | E9: 7.44 | F9: 7.58
A11: Note: matrix computed with base-case growth path, ROE path and exit P/E cap;
A12: only Cost of Equity and Terminal Growth are varied (matches DCF JSON sensitivity block).

Sheet Historical
A1: Historical Growth Rates (Hypergrowth Era - Decelerated in Model)
A3: Metric | B3: CAGR / Growth
A4: Revenue 3yr CAGR (FY22-FY25) | B4: 0.488
A5: Revenue 5yr CAGR (FY20-FY25) | B5: 0.845
A6: Equity 3yr CAGR (FY22-FY25) | B6: 0.322
A7: Equity 5yr CAGR (FY20-FY25) | B7: 0.915
A8: EPS 2yr CAGR since profitability (FY23-FY25) | B8: 0.66
A9: Net Income 2yr CAGR (FY23-FY25) | B9: 0.669
A11: Growth Rate Source:
A12: net_income_growth_path (decelerating: 35% -> 28% -> 22% -> 18% -> 15%), not a single historical CAGR
A14: Growth Divergence Warning:
A15: Revenue 3yr CAGR (48.8%), equity 3yr CAGR (32.2%) and net income 2yr CAGR (66.9%) all reflect NU's hypergrowth 2022-2025 era and diverge sharply from each other and from any sustainable long-run rate. All historical CAGRs are decelerated aggressively in the projection (base case starts at 35% net income growth in Y1, well below trailing rates, and falls to 15% by Y5, then further to 3.75% terminal growth) per analyst consensus of ~30% near-term EPS growth fading over time.
A17: FCF Note:
A18: Not applicable/meaningful - NU is a deposit-funded bank; operating cash flow is dominated by deposit inflows and loan growth, not owner FCF. Distributable earnings used instead (see valuation_philosophy).
