Workbook

Sheet Model_Info
A1: SKL.NZ Skellerup Holdings DCF model provenance and how to use it
A3: Version | B3: v1.0 -- first valuation of this ticker. Supersedes nothing; no prior SKL.NZ_DCF.json existed.
A4: Built by | B4: dcf-analyst agent (Claude Opus 5), 2026-08-28, at the user request to value SKL.NZ.
A5: Model | B5: Component-built owner-FCF DCF, 10-year explicit horizon, three probability-weighted scenarios.
A6: Method source | B6: Routed via .claude/skills/dcf-methods/SKILL.md to references/owner-fcf.md, including the section 7 non-US / cyclical adaptations.
A7: Why this model | B7: Skellerup is a straightforward profitable operating company (two-segment engineered polymer manufacturer) with a conservatively geared balance sheet. None of the bank / REIT / LIC / holdco / distressed exclusions apply.
A9: DATA VINTAGE -- all figures go stale
A10: Price | B10: NZ$7.48, Yahoo Finance regular session close 2026-08-28T04:59:59Z. 52-week range 4.91-7.59; the price sits at the TOP of its 10-year range. Verified live, not a frozen quote.
A11: Latest actual year | B11: FY2026 (year to 30 June 2026), sourced from the 19-Aug-2026 results release -- NOT a published annual report. Refresh when the FY2026 annual report appears.
A12: Balance sheet | B12: Net debt NZ$2.0m at 2026-06-30 (disclosed in the results release). FY2026 equity / total debt / cash columns are deliberately NULL; FY2025 book equity of NZ$240.2m at 2025-06-30 is used for book-value multiples.
A13: Share count | B13: 196,071,582 shares, flat since FY2024. Held flat in the model.
A14: Guidance | B14: FY2027: management "broadly comfortable" with consensus, no point estimate issued. Medium-term ambition 11-12% compound earnings growth. Capex modestly below FY2026 NZ$15.1m. Tariffs "substantially offset" entering FY2027.
A16: METHODOLOGY CHOICES
A17: Normalisation | B17: FY2026 statutory NPAT of 67.7 includes a ~NZ$4.8m one-off Wigram fire insurance gain. The model anchors on NORMALISED NPAT 64.2 and NORMALISED EBIT 89.3 throughout. Never anchor terminal value on 67.7.
A18: SBC | B18: Genuinely ZERO -- verified against every cash flow statement FY2015-FY2026. SBC rows are kept explicit at 0.0% per section 7(e) rather than deleted. House and street bases therefore coincide and band position is n/a, not 0%.
A19: Share count treatment | B19: Flat. With zero SBC there is neither an SBC charge nor a dilution drag to allocate.
A20: Leases | B20: No adjustment. Skellerup owner-occupies its principal plants; lease liabilities are immaterial and no lease principal is separately disclosed. lease_cost_pct is 0. Section 7(b) requires ONE treatment be chosen and stated -- this is it.
A21: Minority interests | B21: None. No NCI deduction needed.
A22: Working capital | B22: NEGATIVE capture of -8% of the revenue CHANGE. This is an inventory- and receivables-heavy manufacturer, so growth ABSORBS cash. Opposite sign to a prepaid subscription business.
A23: WACC | B23: 10.5% NZD-built, applied identically to all three scenarios. NZ 10y bond ~4.3% + ERP ~6.0% x beta ~1.05. No illiquidity premium (mid-cap at NZ$1.47bn). Per section 7(f) cyclical / tariff / dairy risk is charged ONCE in the flows and the weights, never a second time in the discount rate.
A24: Terminal value | B24: max(0, min(Gordon, 15x year-10 owner FCF)). The 15x cap rather than 20x reflects a cyclical industrial. All three scenarios bind on Gordon; none hits the zero floor.
A25: Horizon | B25: 10 years. Required because the base-case margin is still fading at year 5 and must mature before being capitalised.
A27: WHOSE JUDGMENT | B27: The scenario driver paths are the dcf-analyst agent judgment as at 2026-08-28, set on the FY2026 results release, the Fonterra 2026/27 payout cut to $9.25/kgMS, and the disclosed tariff position. They are not management guidance.
A28: THE CENTRAL ASSUMPTION | B28: Base case fades EBITDA margin from the all-time-high 27.5% to a mid-cycle 25.5%. Over ten years revenue compounded 6.32% while EBIT compounded 11.71% -- the whole wedge is margin expansion, which is finite. A bull must disagree with this one cell path.
A29: REFRESH AFTER NEXT PRINT | B29: H1 FY2027 (Feb 2027): the FY2027 revenue growth rate (row 5) and the year-1 EBITDA margin (row 7) on each DCF tab, plus price, net debt and share count on Assumptions. Leave later-year paths alone unless the evidence actually touches them.
A31: COLOUR LEGEND | B31: Blue = hardcoded input. Yellow fill = key lever you are meant to flex. Black = formula. Green = cross-sheet link. Never paste a value over a formula.

Sheet Actuals
A1: SKL.NZ reported history (NZD millions unless stated) source: SKL.NZ_Metrics.csv, from filings + 19-Aug-2026 results release
A3: Fiscal year (30 June) | B3: FY2017 | C3: FY2018 | D3: FY2019 | E3: FY2020 | F3: FY2021 | G3: FY2022 | H3: FY2023 | I3: FY2024 | J3: FY2025 | K3: FY2026
A4: Revenue | B4: 210.322 | C4: 240.408 | D4: 245.792 | E4: 251.389 | F4: 279.515 | G4: 316.829 | H4: 333.537 | I4: 330.578 | J4: 353.478 | K4: 390.1
A5: EBITDA (normalised) | B5: 40.638 | C5: 47.237 | D5: 48.93 | E5: 55.253 | F5: 68.734 | G5: 80.523 | H5: 86.892 | I5: 88.52 | J5: 94.943 | K5: 107.3
A6: EBIT (normalised) | B6: 32.849 | C6: 39.781 | D6: 41.798 | E6: 42.486 | F6: 56.361 | G6: 66.76 | H6: 71.659 | I6: 72.688 | J6: 78.036 | K6: 89.3
A7: Net profit -- statutory | B7: 22.11 | C7: 27.277 | D7: 29.063 | E7: 29.064 | F7: 40.175 | G7: 47.813 | H7: 50.941 | I7: 46.893 | J7: 54.549 | K7: 67.7
A8: Net profit -- NORMALISED | B8: 22.11 | C8: 27.277 | D8: 29.063 | E8: 29.064 | F8: 40.175 | G8: 47.813 | H8: 50.941 | I8: 50.014 | J8: 54.549 | K8: 64.2
A9: Operating cash flow | B9: 21.229 | C9: 28.345 | D9: 28.92 | E9: 48.006 | F9: 58.796 | G9: 43.322 | H9: 54.114 | I9: 70.81 | J9: 66.487 | K9: 83.6
A10: Capital expenditure | B10: 12.695 | C10: 5.428 | D10: 4.593 | E10: 4.383 | F10: 7.478 | G10: 10.186 | H10: 8.247 | I10: 9.444 | J10: 9.201 | K10: 15.1
A11: Shareholders equity (book) | B11: 159.247 | C11: 172.286 | D11: 178.392 | E11: 184.563 | F11: 196.149 | G11: 211.208 | H11: 225.436 | I11: 229.493 | J11: 240.19
A12: Stock-based compensation | B12: 0 | C12: 0 | D12: 0 | E12: 0 | F12: 0 | G12: 0 | H12: 0 | I12: 0 | J12: 0 | K12: 0
A13: Shares outstanding (m) | B13: 192.806 | C13: 192.806 | D13: 194.289 | E13: 194.753 | F13: 195.102 | G13: 195.276 | H13: 195.804 | I13: 196.072 | J13: 196.072 | K13: 196.072
A14: Free cash flow (OCF less capex) | B14: =B9-B10 | C14: =C9-C10 | D14: =D9-D10 | E14: =E9-E10 | F14: =F9-F10 | G14: =G9-G10 | H14: =H9-H10 | I14: =I9-I10 | ... K14: =K9-K10
A15: Owner FCF (identical: SBC is zero) | B15: =B14 | C15: =C14 | D15: =D14 | E15: =E14 | F15: =F14 | G15: =G14 | H15: =H14 | I15: =I14 | ... K15: =K14
A16: EBIT margin | B16: =B6/B4 | C16: =C6/C4 | D16: =D6/D4 | E16: =E6/E4 | F16: =F6/F4 | G16: =G6/G4 | H16: =H6/H4 | I16: =I6/I4 | ... K16: =K6/K4
A17: Owner FCF margin | B17: =B15/B4 | C17: =C15/C4 | D17: =D15/D4 | E17: =E15/E4 | F17: =F15/F4 | G17: =G15/G4 | H17: =H15/H4 | I17: =I15/I4 | ... K17: =K15/K4
A19: Source note | B19: FY2017-FY2025 from annual report filings via SKL.NZ_Metrics.csv. FY2026 from the 19-Aug-2026 results release -- no annual report published yet.
A20: Normalisation note | B20: FY2026 statutory NPAT 67.7 includes a ~NZ$4.8m Wigram fire insurance gain; normalised is 64.2. FY2024 statutory 46.893 excludes a 3.121 abnormal tax item; normalised is 50.014.
A21: Balance sheet note | B21: FY2026 equity is blank by design -- the results release carries no balance sheet. FY2025 equity 240.190 at 2025-06-30 is used for book-value multiples.
A22: SBC note | B22: Zero in every year, verified against the cash flow statements. Adjusted and unadjusted bases coincide.
A23: Buyback note | B23: No share repurchase programme. The flat share count is a fact, not a modelling convention -- the count moved only 192.8m to 196.1m in eleven years.
A24: Balance sheet strength | B24: Net debt NZ$2.0m at FY2026 (from NZ$12.4m at FY2025) against a NZ$55m facility. Effectively unlevered.
A25: Dividend | B25: FY2026 DPS 30.0 cents against EPS 32.8 cents -- a ~91% payout. This is a high-payout compounder, which is why book value barely grows and equity CAGR is not the right forward driver.

Sheet Assumptions
A1: SKL.NZ global assumptions and scenario settings
A3: Global
A4: WACC (all scenarios) | B4: 0.105 | D4: NZD-built: NZ 10y ~4.3% + ERP ~6.0% x beta ~1.05. Same rate in every scenario -- risk is charged once, in the flows.
A5: D&A as % of revenue | B5: 0.046 | D5: FY2025 actual 4.78%, FY2026 ~4.6%. Held flat.
A6: Working capital capture | B6: -0.08 | D6: NEGATIVE: growth absorbs cash in an inventory-heavy manufacturer. Applied to the CHANGE in revenue.
A7: Terminal FCF cap multiple | B7: 15 | D7: Lower than the 20x default because this is a cyclical industrial.
A8: Net debt (NZ$m) | B8: 2 | D8: NZ$2.0m at 2026-06-30, disclosed in the results release. Positive = debt.
A9: Diluted shares (m) | B9: 196.07158 | D9: Flat. Zero SBC means no dilution drag.
A10: Current price (NZ$) | B10: 7.48 | D10: Yahoo 2026-08-28T04:59:59Z. At the top of the 10-year range.
A11: Hurdle rate for entry price | B11: 0.15 | D11: House standard 15% IRR.
A13: Scenario settings
A14: Scenario | B14: Terminal growth | C14: Probability | D14: Narrative
A15: Bear | B15: 0.02 | C15: 0.25 | D15: The two external risks the company itself flags both bite. Fonterra's payout cut deepens and Agri's footwear and equipment-adjacent discretionary lines soften after a near-record season, while US tariff policy re-escalates against the ~37-40% of group revenue that is US-market exposed with ~85% of it manufactured in China, Vietnam and NZ -- a headwind management describes as 'substantially', not permanently, offset and subject to rates that 'change every week'. Revenue stalls at 1-1.5% for two years and EBITDA margin mean-reverts to 21.5%, roughly the FY2019-20 level, which is a return to normal rather than a crisis. Lumpy single-customer events like the H1 FY26 Health & Hygiene production pause recur.
A16: Base | B16: 0.0225 | C16: 0.5 | D16: Skellerup keeps its specification lock-in and its new-product cadence, but the ten-year run of record EBIT stops compounding at the top line's expense: revenue grows 6% in FY2027 (management is 'broadly comfortable' with consensus and reports steady early trading) and fades toward ~3% as the Fonterra 2026/27 payout cut to $9.25/kgMS works through farmer discretionary spend. The decisive assumption is margin. FY2026's 22.9% EBIT / 27.5% EBITDA margin is an all-time high reached after a 7.3pp expansion from FY2017's 15.6%; the base case fades EBITDA to a still-excellent 25.5% mid-cycle level rather than treating the peak as the new floor. Capex rises from 3.9% of revenue to ~4.6%, meeting D&A, because an asset-heavy manufacturer part-way through a modernisation and Wigram CV-line rebuild cannot under-invest against depreciation indefinitely.
A17: Bull | B17: 0.025 | C17: 0.25 | D17: Management's stated 11-12% medium-term compound earnings ambition is delivered. Industrial's potable-water/wastewater exposure compounds against a structurally growing US infrastructure theme, the ~12.5% blended tariff regime stays 'substantially offset' permanently rather than temporarily, Agri holds its consumable replacement-cycle volumes through a softer payout, and the NZ$55m undrawn facility funds accretive bolt-on M&A. Margins do not merely hold at the record but creep to 28.5% EBITDA on mix and operating leverage. Revenue compounds 9% falling to 4.5%. Even this case reaches only $6.08 -- below the current price.
A18: Weights check (must be 100%) | C18: =SUM(C15:C17) | D18: If this is not 100% the probability-weighted value below is meaningless.
A20: Weights rationale | B20: Shifted from the 15/50/35 house default to 25/50/25. Bear raised to 25% because two of the company's flagged downside risks are already in motion rather than hypothetical -- Fonterra's 2026/27 payout has been cut to $9.25/kgMS from ~$9.75, and management itself describes the tariff position as 'substantially' offset with rates that 'change every week' against 37-40% US-exposed revenue. Bull cut to 25% because that case needs several independent things to go right at once (margins hold at an all-time high AND tariffs stay neutralised permanently AND accretive M&A is executed AND Agri holds through a softer payout), which is exactly the situation the method file says should reduce bull weight. Base held at 50%: management's own repeated caution that 'these record results cannot continue ad infinitum' is the base case, in the company's own words.
A21: WACC rationale | B21: 10.5% NZD-denominated, applied identically to all three scenarios. Built from NZD inputs per section 7(a): NZ 10-year government bond ~4.3% risk-free, equity risk premium ~6.0% (the standard NZ market premium; NZ equity premia run above US/AU on market depth), levered beta ~1.05 for a diversified industrial with a dairy-cyclical segment, giving ~10.6%, rounded to 10.5%. The balance sheet is effectively unlevered (net debt NZ$2.0m against a NZ$1.47bn market cap) so WACC and cost of equity coincide -- no debt-weighting benefit is taken. NO illiquidity premium is stacked: at a ~NZ$1.47bn market cap Skellerup is a mid-cap, not the micro-cap that would justify one. Per section 7(f), the genuine risk factors -- dairy-cycle exposure to the Fonterra payout cut, ~37-40% US-market revenue against fluid tariff policy, FX translation and raw-material/freight input costs -- are charged ONCE, in the bear-scenario flows and in the 25% bear weight, NOT a second time as a WACC premium. Using a higher WACC in the bear case than the bull would have charged the same risk a third time and was deliberately avoided.

Sheet DCF_Bear
A1: SKL.NZ BEAR case component owner-FCF build (NZD millions)
A3: Fiscal year | B3: FY2026A | C3: FY2027E | D3: FY2028E | E3: FY2029E | F3: FY2030E | G3: FY2031E | H3: FY2032E | I3: FY2033E | J3: FY2034E | K3: FY2035E | L3: FY2036E
A4: Year index (discount exponent) | B4: 0 | C4: 1 | D4: 2 | E4: 3 | F4: 4 | G4: 5 | H4: 6 | I4: 7 | J4: 8 | K4: 9 | L4: 10
A5: Revenue growth YoY | C5: 0.015 | D5: 0.01 | E5: 0.02 | F5: 0.025 | G5: 0.025 | H5: 0.03 | I5: 0.03 | J5: 0.025 | K5: 0.025 | L5: 0.025
A6: Revenue | B6: 390.1 | C6: =B6*(1+C5) | D6: =C6*(1+D5) | E6: =D6*(1+E5) | F6: =E6*(1+F5) | G6: =F6*(1+G5) | H6: =G6*(1+H5) | I6: =H6*(1+I5) | J6: =I6*(1+J5) | ... L6: =K6*(1+L5)
A7: Adjusted EBITDA margin | C7: 0.255 | D7: 0.24 | E7: 0.23 | F7: 0.223 | G7: 0.218 | H7: 0.215 | I7: 0.215 | J7: 0.215 | K7: 0.215 | L7: 0.215
A8: Adjusted EBITDA | C8: =C6*C7 | D8: =D6*D7 | E8: =E6*E7 | F8: =F6*F7 | G8: =G6*G7 | H8: =H6*H7 | I8: =I6*I7 | J8: =J6*J7 | ... L8: =L6*L7
A9: SBC as % of revenue | C9: 0 | D9: 0 | E9: 0 | F9: 0 | G9: 0 | H9: 0 | I9: 0 | J9: 0 | K9: 0 | L9: 0
A10: SBC (negative) | C10: =-C6*C9 | D10: =-D6*D9 | E10: =-E6*E9 | F10: =-F6*F9 | G10: =-G6*G9 | H10: =-H6*H9 | I10: =-I6*I9 | J10: =-J6*J9 | ... L10: =-L6*L9
A11: Owner EBITDA (after SBC) | C11: =C8+C10 | D11: =D8+D10 | E11: =E8+E10 | F11: =F8+F10 | G11: =G8+G10 | H11: =H8+H10 | I11: =I8+I10 | J11: =J8+J10 | ... L11: =L8+L10
A12: Depreciation and amortisation (negative) | C12: =-C6*Assumptions!$B$5 | D12: =-D6*Assumptions!$B$5 | E12: =-E6*Assumptions!$B$5 | F12: =-F6*Assumptions!$B$5 | G12: =-G6*Assumptions!$B$5 | H12: =-H6*Assumptions!$B$5 | I12: =-I6*Assumptions!$B$5 | J12: =-J6*Assumptions!$B$5 | ... L12: =-L6*Assumptions!$B$5
A13: EBIT (SBC expensed) | C13: =C11+C12 | D13: =D11+D12 | E13: =E11+E12 | F13: =F11+F12 | G13: =G11+G12 | H13: =H11+H12 | I13: =I11+I12 | J13: =J11+J12 | ... L13: =L11+L12
A14: Cash tax rate | C14: 0.26 | D14: 0.26 | E14: 0.26 | F14: 0.26 | G14: 0.26 | H14: 0.26 | I14: 0.26 | J14: 0.26 | K14: 0.26 | L14: 0.26
A15: NOPAT | C15: =C13*(1-C14) | D15: =D13*(1-D14) | E15: =E13*(1-E14) | F15: =F13*(1-F14) | G15: =G13*(1-G14) | H15: =H13*(1-H14) | I15: =I13*(1-I14) | J15: =J13*(1-J14) | ... L15: =L13*(1-L14)
A16: add back D&A | C16: =-C12 | D16: =-D12 | E16: =-E12 | F16: =-F12 | G16: =-G12 | H16: =-H12 | I16: =-I12 | J16: =-J12 | ... L16: =-L12
A17: Capex as % of revenue (negative) | C17: -0.043 | D17: -0.045 | E17: -0.046 | F17: -0.047 | G17: -0.047 | H17: -0.047 | I17: -0.047 | J17: -0.047 | K17: -0.047 | L17: -0.047
A18: Capital expenditure | C18: =C6*C17 | D18: =D6*D17 | E18: =E6*E17 | F18: =F6*F17 | G18: =G6*G17 | H18: =H6*H17 | I18: =I6*I17 | J18: =J6*J17 | ... L18: =L6*L17
A19: Working capital movement | C19: =Assumptions!$B$6*(C6-B6) | D19: =Assumptions!$B$6*(D6-C6) | E19: =Assumptions!$B$6*(E6-D6) | F19: =Assumptions!$B$6*(F6-E6) | G19: =Assumptions!$B$6*(G6-F6) | H19: =Assumptions!$B$6*(H6-G6) | I19: =Assumptions!$B$6*(I6-H6) | J19: =Assumptions!$B$6*(J6-I6) | ... L19: =Assumptions!$B$6*(L6-K6)
A20: UNLEVERED OWNER FREE CASH FLOW | C20: =C15+C16+C18+C19 | D20: =D15+D16+D18+D19 | E20: =E15+E16+E18+E19 | F20: =F15+F16+F18+F19 | G20: =G15+G16+G18+G19 | H20: =H15+H16+H18+H19 | I20: =I15+I16+I18+I19 | J20: =J15+J16+J18+J19 | ... L20: =L15+L16+L18+L19
A21: Discount factor | C21: =1/(1+Assumptions!$B$4)^C4 | D21: =1/(1+Assumptions!$B$4)^D4 | E21: =1/(1+Assumptions!$B$4)^E4 | F21: =1/(1+Assumptions!$B$4)^F4 | G21: =1/(1+Assumptions!$B$4)^G4 | H21: =1/(1+Assumptions!$B$4)^H4 | I21: =1/(1+Assumptions!$B$4)^I4 | J21: =1/(1+Assumptions!$B$4)^J4 | ... L21: =1/(1+Assumptions!$B$4)^L4
A22: PV of owner FCF | C22: =C20*C21 | D22: =D20*D21 | E22: =E20*E21 | F22: =F20*F21 | G22: =G20*G21 | H22: =H20*H21 | I22: =I20*I21 | J22: =J20*J21 | ... L22: =L20*L21
A24: Memo: FCF before SBC (company style) | C24: =C20-C10 | D24: =D20-D10 | E24: =E20-E10 | F24: =F20-F10 | G24: =G20-G10 | H24: =H20-H10 | I24: =I20-I10 | J24: =J20-J10 | ... L24: =L20-L10
A25: Memo: implied owner FCF margin | C25: =C20/C6 | D25: =D20/D6 | E25: =E20/E6 | F25: =F20/F6 | G25: =G20/G6 | H25: =H20/H6 | I25: =I20/I6 | J25: =J20/J6 | ... L25: =L20/L6
A26: Sum of PV of explicit FCF | B26: =SUM(C22:L22)
A27: Terminal growth rate | B27: =Assumptions!$B$15
A28: Terminal year FCF grown one year | B28: =L20*(1+B27)
A29: Gordon terminal value | B29: =B28/(Assumptions!$B$4-B27)
A30: Cap terminal value (multiple x FY10 FCF) | B30: =Assumptions!$B$7*L20
A31: Terminal value used | B31: =MAX(0,MIN(B29,B30))
A32: Which bound applied | B32: =IF(B31=0,"zero floor",IF(B31=B29,"gordon","cap"))
A33: Implied exit multiple | B33: =B31/L20
A34: PV of terminal value | B34: =B31*L21
A35: Enterprise value | B35: =B26+B34
A36: less net debt | B36: =-Assumptions!$B$8
A37: Equity value | B37: =B35+B36
A38: Diluted shares (m) | B38: =Assumptions!$B$9
A39: VALUE PER SHARE (NZ$) | B39: =B37/B38
A40: Upside vs current price | B40: =B39/Assumptions!$B$10-1
A41: Terminal value as % of EV | B41: =B34/B35
A43: Street basis memo (SBC treated as non-cash)
...

Sheet DCF_Base
A1: SKL.NZ BASE case component owner-FCF build (NZD millions)
A3: Fiscal year | B3: FY2026A | C3: FY2027E | D3: FY2028E | E3: FY2029E | F3: FY2030E | G3: FY2031E | H3: FY2032E | I3: FY2033E | J3: FY2034E | K3: FY2035E | L3: FY2036E
A4: Year index (discount exponent) | B4: 0 | C4: 1 | D4: 2 | E4: 3 | F4: 4 | G4: 5 | H4: 6 | I4: 7 | J4: 8 | K4: 9 | L4: 10
A5: Revenue growth YoY | C5: 0.06 | D5: 0.055 | E5: 0.05 | F5: 0.045 | G5: 0.04 | H5: 0.04 | I5: 0.035 | J5: 0.035 | K5: 0.03 | L5: 0.03
A6: Revenue | B6: 390.1 | C6: =B6*(1+C5) | D6: =C6*(1+D5) | E6: =D6*(1+E5) | F6: =E6*(1+F5) | G6: =F6*(1+G5) | H6: =G6*(1+H5) | I6: =H6*(1+I5) | J6: =I6*(1+J5) | ... L6: =K6*(1+L5)
A7: Adjusted EBITDA margin | C7: 0.272 | D7: 0.268 | E7: 0.264 | F7: 0.26 | G7: 0.257 | H7: 0.255 | I7: 0.255 | J7: 0.255 | K7: 0.255 | L7: 0.255
A8: Adjusted EBITDA | C8: =C6*C7 | D8: =D6*D7 | E8: =E6*E7 | F8: =F6*F7 | G8: =G6*G7 | H8: =H6*H7 | I8: =I6*I7 | J8: =J6*J7 | ... L8: =L6*L7
A9: SBC as % of revenue | C9: 0 | D9: 0 | E9: 0 | F9: 0 | G9: 0 | H9: 0 | I9: 0 | J9: 0 | K9: 0 | L9: 0
A10: SBC (negative) | C10: =-C6*C9 | D10: =-D6*D9 | E10: =-E6*E9 | F10: =-F6*F9 | G10: =-G6*G9 | H10: =-H6*H9 | I10: =-I6*I9 | J10: =-J6*J9 | ... L10: =-L6*L9
A11: Owner EBITDA (after SBC) | C11: =C8+C10 | D11: =D8+D10 | E11: =E8+E10 | F11: =F8+F10 | G11: =G8+G10 | H11: =H8+H10 | I11: =I8+I10 | J11: =J8+J10 | ... L11: =L8+L10
A12: Depreciation and amortisation (negative) | C12: =-C6*Assumptions!$B$5 | D12: =-D6*Assumptions!$B$5 | E12: =-E6*Assumptions!$B$5 | F12: =-F6*Assumptions!$B$5 | G12: =-G6*Assumptions!$B$5 | H12: =-H6*Assumptions!$B$5 | I12: =-I6*Assumptions!$B$5 | J12: =-J6*Assumptions!$B$5 | ... L12: =-L6*Assumptions!$B$5
A13: EBIT (SBC expensed) | C13: =C11+C12 | D13: =D11+D12 | E13: =E11+E12 | F13: =F11+F12 | G13: =G11+G12 | H13: =H11+H12 | I13: =I11+I12 | J13: =J11+J12 | ... L13: =L11+L12
A14: Cash tax rate | C14: 0.26 | D14: 0.26 | E14: 0.26 | F14: 0.26 | G14: 0.26 | H14: 0.26 | I14: 0.26 | J14: 0.26 | K14: 0.26 | L14: 0.26
A15: NOPAT | C15: =C13*(1-C14) | D15: =D13*(1-D14) | E15: =E13*(1-E14) | F15: =F13*(1-F14) | G15: =G13*(1-G14) | H15: =H13*(1-H14) | I15: =I13*(1-I14) | J15: =J13*(1-J14) | ... L15: =L13*(1-L14)
A16: add back D&A | C16: =-C12 | D16: =-D12 | E16: =-E12 | F16: =-F12 | G16: =-G12 | H16: =-H12 | I16: =-I12 | J16: =-J12 | ... L16: =-L12
A17: Capex as % of revenue (negative) | C17: -0.04 | D17: -0.042 | E17: -0.044 | F17: -0.045 | G17: -0.046 | H17: -0.046 | I17: -0.046 | J17: -0.046 | K17: -0.046 | L17: -0.046
A18: Capital expenditure | C18: =C6*C17 | D18: =D6*D17 | E18: =E6*E17 | F18: =F6*F17 | G18: =G6*G17 | H18: =H6*H17 | I18: =I6*I17 | J18: =J6*J17 | ... L18: =L6*L17
A19: Working capital movement | C19: =Assumptions!$B$6*(C6-B6) | D19: =Assumptions!$B$6*(D6-C6) | E19: =Assumptions!$B$6*(E6-D6) | F19: =Assumptions!$B$6*(F6-E6) | G19: =Assumptions!$B$6*(G6-F6) | H19: =Assumptions!$B$6*(H6-G6) | I19: =Assumptions!$B$6*(I6-H6) | J19: =Assumptions!$B$6*(J6-I6) | ... L19: =Assumptions!$B$6*(L6-K6)
A20: UNLEVERED OWNER FREE CASH FLOW | C20: =C15+C16+C18+C19 | D20: =D15+D16+D18+D19 | E20: =E15+E16+E18+E19 | F20: =F15+F16+F18+F19 | G20: =G15+G16+G18+G19 | H20: =H15+H16+H18+H19 | I20: =I15+I16+I18+I19 | J20: =J15+J16+J18+J19 | ... L20: =L15+L16+L18+L19
A21: Discount factor | C21: =1/(1+Assumptions!$B$4)^C4 | D21: =1/(1+Assumptions!$B$4)^D4 | E21: =1/(1+Assumptions!$B$4)^E4 | F21: =1/(1+Assumptions!$B$4)^F4 | G21: =1/(1+Assumptions!$B$4)^G4 | H21: =1/(1+Assumptions!$B$4)^H4 | I21: =1/(1+Assumptions!$B$4)^I4 | J21: =1/(1+Assumptions!$B$4)^J4 | ... L21: =1/(1+Assumptions!$B$4)^L4
A22: PV of owner FCF | C22: =C20*C21 | D22: =D20*D21 | E22: =E20*E21 | F22: =F20*F21 | G22: =G20*G21 | H22: =H20*H21 | I22: =I20*I21 | J22: =J20*J21 | ... L22: =L20*L21
A24: Memo: FCF before SBC (company style) | C24: =C20-C10 | D24: =D20-D10 | E24: =E20-E10 | F24: =F20-F10 | G24: =G20-G10 | H24: =H20-H10 | I24: =I20-I10 | J24: =J20-J10 | ... L24: =L20-L10
A25: Memo: implied owner FCF margin | C25: =C20/C6 | D25: =D20/D6 | E25: =E20/E6 | F25: =F20/F6 | G25: =G20/G6 | H25: =H20/H6 | I25: =I20/I6 | J25: =J20/J6 | ... L25: =L20/L6
A26: Sum of PV of explicit FCF | B26: =SUM(C22:L22)
A27: Terminal growth rate | B27: =Assumptions!$B$16
A28: Terminal year FCF grown one year | B28: =L20*(1+B27)
A29: Gordon terminal value | B29: =B28/(Assumptions!$B$4-B27)
A30: Cap terminal value (multiple x FY10 FCF) | B30: =Assumptions!$B$7*L20
A31: Terminal value used | B31: =MAX(0,MIN(B29,B30))
A32: Which bound applied | B32: =IF(B31=0,"zero floor",IF(B31=B29,"gordon","cap"))
A33: Implied exit multiple | B33: =B31/L20
A34: PV of terminal value | B34: =B31*L21
A35: Enterprise value | B35: =B26+B34
A36: less net debt | B36: =-Assumptions!$B$8
A37: Equity value | B37: =B35+B36
A38: Diluted shares (m) | B38: =Assumptions!$B$9
A39: VALUE PER SHARE (NZ$) | B39: =B37/B38
A40: Upside vs current price | B40: =B39/Assumptions!$B$10-1
A41: Terminal value as % of EV | B41: =B34/B35
A43: Street basis memo (SBC treated as non-cash)
...

Sheet DCF_Bull
A1: SKL.NZ BULL case component owner-FCF build (NZD millions)
A3: Fiscal year | B3: FY2026A | C3: FY2027E | D3: FY2028E | E3: FY2029E | F3: FY2030E | G3: FY2031E | H3: FY2032E | I3: FY2033E | J3: FY2034E | K3: FY2035E | L3: FY2036E
A4: Year index (discount exponent) | B4: 0 | C4: 1 | D4: 2 | E4: 3 | F4: 4 | G4: 5 | H4: 6 | I4: 7 | J4: 8 | K4: 9 | L4: 10
A5: Revenue growth YoY | C5: 0.09 | D5: 0.085 | E5: 0.08 | F5: 0.075 | G5: 0.07 | H5: 0.065 | I5: 0.06 | J5: 0.055 | K5: 0.05 | L5: 0.045
A6: Revenue | B6: 390.1 | C6: =B6*(1+C5) | D6: =C6*(1+D5) | E6: =D6*(1+E5) | F6: =E6*(1+F5) | G6: =F6*(1+G5) | H6: =G6*(1+H5) | I6: =H6*(1+I5) | J6: =I6*(1+J5) | ... L6: =K6*(1+L5)
A7: Adjusted EBITDA margin | C7: 0.276 | D7: 0.278 | E7: 0.28 | F7: 0.282 | G7: 0.284 | H7: 0.285 | I7: 0.285 | J7: 0.285 | K7: 0.285 | L7: 0.285
A8: Adjusted EBITDA | C8: =C6*C7 | D8: =D6*D7 | E8: =E6*E7 | F8: =F6*F7 | G8: =G6*G7 | H8: =H6*H7 | I8: =I6*I7 | J8: =J6*J7 | ... L8: =L6*L7
A9: SBC as % of revenue | C9: 0 | D9: 0 | E9: 0 | F9: 0 | G9: 0 | H9: 0 | I9: 0 | J9: 0 | K9: 0 | L9: 0
A10: SBC (negative) | C10: =-C6*C9 | D10: =-D6*D9 | E10: =-E6*E9 | F10: =-F6*F9 | G10: =-G6*G9 | H10: =-H6*H9 | I10: =-I6*I9 | J10: =-J6*J9 | ... L10: =-L6*L9
A11: Owner EBITDA (after SBC) | C11: =C8+C10 | D11: =D8+D10 | E11: =E8+E10 | F11: =F8+F10 | G11: =G8+G10 | H11: =H8+H10 | I11: =I8+I10 | J11: =J8+J10 | ... L11: =L8+L10
A12: Depreciation and amortisation (negative) | C12: =-C6*Assumptions!$B$5 | D12: =-D6*Assumptions!$B$5 | E12: =-E6*Assumptions!$B$5 | F12: =-F6*Assumptions!$B$5 | G12: =-G6*Assumptions!$B$5 | H12: =-H6*Assumptions!$B$5 | I12: =-I6*Assumptions!$B$5 | J12: =-J6*Assumptions!$B$5 | ... L12: =-L6*Assumptions!$B$5
A13: EBIT (SBC expensed) | C13: =C11+C12 | D13: =D11+D12 | E13: =E11+E12 | F13: =F11+F12 | G13: =G11+G12 | H13: =H11+H12 | I13: =I11+I12 | J13: =J11+J12 | ... L13: =L11+L12
A14: Cash tax rate | C14: 0.26 | D14: 0.26 | E14: 0.26 | F14: 0.26 | G14: 0.26 | H14: 0.26 | I14: 0.26 | J14: 0.26 | K14: 0.26 | L14: 0.26
A15: NOPAT | C15: =C13*(1-C14) | D15: =D13*(1-D14) | E15: =E13*(1-E14) | F15: =F13*(1-F14) | G15: =G13*(1-G14) | H15: =H13*(1-H14) | I15: =I13*(1-I14) | J15: =J13*(1-J14) | ... L15: =L13*(1-L14)
A16: add back D&A | C16: =-C12 | D16: =-D12 | E16: =-E12 | F16: =-F12 | G16: =-G12 | H16: =-H12 | I16: =-I12 | J16: =-J12 | ... L16: =-L12
A17: Capex as % of revenue (negative) | C17: -0.042 | D17: -0.043 | E17: -0.044 | F17: -0.045 | G17: -0.045 | H17: -0.045 | I17: -0.045 | J17: -0.045 | K17: -0.045 | L17: -0.045
A18: Capital expenditure | C18: =C6*C17 | D18: =D6*D17 | E18: =E6*E17 | F18: =F6*F17 | G18: =G6*G17 | H18: =H6*H17 | I18: =I6*I17 | J18: =J6*J17 | ... L18: =L6*L17
A19: Working capital movement | C19: =Assumptions!$B$6*(C6-B6) | D19: =Assumptions!$B$6*(D6-C6) | E19: =Assumptions!$B$6*(E6-D6) | F19: =Assumptions!$B$6*(F6-E6) | G19: =Assumptions!$B$6*(G6-F6) | H19: =Assumptions!$B$6*(H6-G6) | I19: =Assumptions!$B$6*(I6-H6) | J19: =Assumptions!$B$6*(J6-I6) | ... L19: =Assumptions!$B$6*(L6-K6)
A20: UNLEVERED OWNER FREE CASH FLOW | C20: =C15+C16+C18+C19 | D20: =D15+D16+D18+D19 | E20: =E15+E16+E18+E19 | F20: =F15+F16+F18+F19 | G20: =G15+G16+G18+G19 | H20: =H15+H16+H18+H19 | I20: =I15+I16+I18+I19 | J20: =J15+J16+J18+J19 | ... L20: =L15+L16+L18+L19
A21: Discount factor | C21: =1/(1+Assumptions!$B$4)^C4 | D21: =1/(1+Assumptions!$B$4)^D4 | E21: =1/(1+Assumptions!$B$4)^E4 | F21: =1/(1+Assumptions!$B$4)^F4 | G21: =1/(1+Assumptions!$B$4)^G4 | H21: =1/(1+Assumptions!$B$4)^H4 | I21: =1/(1+Assumptions!$B$4)^I4 | J21: =1/(1+Assumptions!$B$4)^J4 | ... L21: =1/(1+Assumptions!$B$4)^L4
A22: PV of owner FCF | C22: =C20*C21 | D22: =D20*D21 | E22: =E20*E21 | F22: =F20*F21 | G22: =G20*G21 | H22: =H20*H21 | I22: =I20*I21 | J22: =J20*J21 | ... L22: =L20*L21
A24: Memo: FCF before SBC (company style) | C24: =C20-C10 | D24: =D20-D10 | E24: =E20-E10 | F24: =F20-F10 | G24: =G20-G10 | H24: =H20-H10 | I24: =I20-I10 | J24: =J20-J10 | ... L24: =L20-L10
A25: Memo: implied owner FCF margin | C25: =C20/C6 | D25: =D20/D6 | E25: =E20/E6 | F25: =F20/F6 | G25: =G20/G6 | H25: =H20/H6 | I25: =I20/I6 | J25: =J20/J6 | ... L25: =L20/L6
A26: Sum of PV of explicit FCF | B26: =SUM(C22:L22)
A27: Terminal growth rate | B27: =Assumptions!$B$17
A28: Terminal year FCF grown one year | B28: =L20*(1+B27)
A29: Gordon terminal value | B29: =B28/(Assumptions!$B$4-B27)
A30: Cap terminal value (multiple x FY10 FCF) | B30: =Assumptions!$B$7*L20
A31: Terminal value used | B31: =MAX(0,MIN(B29,B30))
A32: Which bound applied | B32: =IF(B31=0,"zero floor",IF(B31=B29,"gordon","cap"))
A33: Implied exit multiple | B33: =B31/L20
A34: PV of terminal value | B34: =B31*L21
A35: Enterprise value | B35: =B26+B34
A36: less net debt | B36: =-Assumptions!$B$8
A37: Equity value | B37: =B35+B36
A38: Diluted shares (m) | B38: =Assumptions!$B$9
A39: VALUE PER SHARE (NZ$) | B39: =B37/B38
A40: Upside vs current price | B40: =B39/Assumptions!$B$10-1
A41: Terminal value as % of EV | B41: =B34/B35
A43: Street basis memo (SBC treated as non-cash)
...

Sheet FCF_Quality
A1: SKL.NZ reported FCF reconciled to owner FCF (NZD millions)
A3: Fiscal year | B3: FY2017 | C3: FY2018 | D3: FY2019 | E3: FY2020 | F3: FY2021 | G3: FY2022 | H3: FY2023 | I3: FY2024 | J3: FY2025 | K3: FY2026
A4: Operating cash flow | B4: 21.229 | C4: 28.345 | D4: 28.92 | E4: 48.006 | F4: 58.796 | G4: 43.322 | H4: 54.114 | I4: 70.81 | J4: 66.487 | K4: 83.6
A5: less capital expenditure | B5: -12.695 | C5: -5.428 | D5: -4.593 | E5: -4.383 | F5: -7.478 | G5: -10.186 | H5: -8.247 | I5: -9.444 | J5: -9.201 | K5: -15.1
A6: Free cash flow (company definition) | B6: =B4+B5 | C6: =C4+C5 | D6: =D4+D5 | E6: =E4+E5 | F6: =F4+F5 | G6: =G4+G5 | H6: =H4+H5 | I6: =I4+I5 | ... K6: =K4+K5
A7: less SBC incl. equity-award taxes | B7: 0 | C7: 0 | D7: 0 | E7: 0 | F7: 0 | G7: 0 | H7: 0 | I7: 0 | J7: 0 | K7: 0
A8: less interest income | B8: -0.029 | C8: -0.074 | D8: -0.053 | E8: -0.014 | F8: -0.026 | G8: -0.049 | H8: -0.006 | I8: -0.115 | J8: -0.186 | K8: -0.19
A9: OWNER FREE CASH FLOW | B9: =B6+B7+B8 | C9: =C6+C7+C8 | D9: =D6+D7+D8 | E9: =E6+E7+E8 | F9: =F6+F7+F8 | G9: =G6+G7+G8 | H9: =H6+H7+H8 | I9: =I6+I7+I8 | ... K9: =K6+K7+K8
A10: Revenue | B10: 210.322 | C10: 240.408 | D10: 245.792 | E10: 251.389 | F10: 279.515 | G10: 316.829 | H10: 333.537 | I10: 330.578 | J10: 353.478 | K10: 390.1
A11: Reported FCF margin | B11: =B6/B10 | C11: =C6/C10 | D11: =D6/D10 | E11: =E6/E10 | F11: =F6/F10 | G11: =G6/G10 | H11: =H6/H10 | I11: =I6/I10 | ... K11: =K6/K10
A12: Owner FCF margin | B12: =B9/B10 | C12: =C9/C10 | D12: =D9/D10 | E12: =E9/E10 | F12: =F9/F10 | G12: =G9/G10 | H12: =H9/H10 | I12: =I9/I10 | ... K12: =K9/K10
A13: Normalised NPAT | B13: 22.11 | C13: 27.277 | D13: 29.063 | E13: 29.064 | F13: 40.175 | G13: 47.813 | H13: 50.941 | I13: 50.014 | J13: 54.549 | K13: 64.2
A14: Memo: OCF less (normalised NPAT + D&A) | B14: =B4-(B13+B15) | C14: =C4-(C13+C15) | D14: =D4-(D13+D15) | E14: =E4-(E13+E15) | F14: =F4-(F13+F15) | G14: =G4-(G13+G15) | H14: =H4-(H13+H15) | I14: =I4-(I13+I15) | ... K14: =K4-(K13+K15)
A15: Depreciation and amortisation | B15: 7.789 | C15: 7.456 | D15: 7.132 | E15: 12.767 | F15: 12.373 | G15: 13.763 | H15: 15.233 | I15: 15.832 | J15: 16.907 | K15: 18
A17: SBC memo | B17: Zero in every year -- verified against the cash flow statements FY2015-FY2026. There is no SBC adjustment and the owner FCF series equals the reported FCF series.
A18: Working capital memo | B18: Row 14 is the test the method file demands: FY2026 OCF of 83.6 against normalised NPAT plus D&A of 82.2 leaves only +1.4. There is NO deferred-revenue or working-capital windfall inflating the FY2026 base -- unlike the subscription-business trap this engine was built to catch. The base is clean.
A19: Cash tax memo | B19: FY2026 implied cash tax rate on normalised earnings is ~25.6%, close to the 28% NZ statutory rate and not abnormal. No ramp is required; the model holds 26% flat.
A20: Capex memo | B20: FY2026 capex of 15.1 is BELOW D&A of ~18.0. The model raises capex toward D&A (4.6% of revenue) over the forecast, because an asset-heavy manufacturer part-way through a modernisation programme and a Wigram CV-line rebuild cannot under-invest against depreciation indefinitely.

Sheet Valuation
A1: SKL.NZ valuation summary, entry prices, required returns and sensitivity
A3: Scenario | B3: Value per share | C3: Upside vs price | D3: Probability | E3: Street value/sh | F3: Terminal % of EV
A4: Bear | B4: =DCF_Bear!$B$39 | C4: =B4/Assumptions!$B$10-1 | D4: =Assumptions!$C$15 | E4: =DCF_Bear!$B$46 | F4: =DCF_Bear!$B$41
A5: Base | B5: =DCF_Base!$B$39 | C5: =B5/Assumptions!$B$10-1 | D5: =Assumptions!$C$16 | E5: =DCF_Base!$B$46 | F5: =DCF_Base!$B$41
A6: Bull | B6: =DCF_Bull!$B$39 | C6: =B6/Assumptions!$B$10-1 | D6: =Assumptions!$C$17 | E6: =DCF_Bull!$B$46 | F6: =DCF_Bull!$B$41
A7: PROBABILITY-WEIGHTED VALUE | B7: =SUMPRODUCT(B4:B6,D4:D6) | C7: =B7/Assumptions!$B$10-1 | E7: =SUMPRODUCT(E4:E6,D4:D6)
A8: Margin of safety at current price | B8: =1-Assumptions!$B$10/B7 | D8: Negative means the price is ABOVE the weighted value.
A9: Band position (house to street) | B9: n/a -- SBC is zero, so house and street coincide and the band collapses to a point.
A11: 15% hurdle entry prices
A12: Scenario | B12: Entry price | C12: Discount vs price
A13: Bear | B13: =(SUMPRODUCT(DCF_Bear!C20:L20,1/(1+Assumptions!$B$11)^DCF_Bear!C4:L4)+DCF_Bear!$B$31/(1+Assumptions!$B$11)^10-Assumptions!$B$8)/Assumptions!$B$9 | C13: =B13/Assumptions!$B$10-1
A14: Base | B14: =(SUMPRODUCT(DCF_Base!C20:L20,1/(1+Assumptions!$B$11)^DCF_Base!C4:L4)+DCF_Base!$B$31/(1+Assumptions!$B$11)^10-Assumptions!$B$8)/Assumptions!$B$9 | C14: =B14/Assumptions!$B$10-1
A15: Bull | B15: =(SUMPRODUCT(DCF_Bull!C20:L20,1/(1+Assumptions!$B$11)^DCF_Bull!C4:L4)+DCF_Bull!$B$31/(1+Assumptions!$B$11)^10-Assumptions!$B$8)/Assumptions!$B$9 | C15: =B15/Assumptions!$B$10-1
A16: WEIGHTED ENTRY PRICE (buy below) | B16: =SUMPRODUCT(B13:B15,D4:D6)
A18: Required-return table (base case)
A19: Required return | B19: 0.09 | C19: 0.1 | D19: 0.105 | E19: 0.11 | F19: 0.12 | G19: 0.15
A20: Value per share (NZ$) | B20: =(SUMPRODUCT(DCF_Base!C20:L20,1/(1+B$19)^DCF_Base!C4:L4)+DCF_Base!$B$31/(1+B$19)^10-Assumptions!$B$8)/Assumptions!$B$9 | C20: =(SUMPRODUCT(DCF_Base!C20:L20,1/(1+C$19)^DCF_Base!C4:L4)+DCF_Base!$B$31/(1+C$19)^10-Assumptions!$B$8)/Assumptions!$B$9 | D20: =(SUMPRODUCT(DCF_Base!C20:L20,1/(1+D$19)^DCF_Base!C4:L4)+DCF_Base!$B$31/(1+D$19)^10-Assumptions!$B$8)/Assumptions!$B$9 | E20: =(SUMPRODUCT(DCF_Base!C20:L20,1/(1+E$19)^DCF_Base!C4:L4)+DCF_Base!$B$31/(1+E$19)^10-Assumptions!$B$8)/Assumptions!$B$9 | F20: =(SUMPRODUCT(DCF_Base!C20:L20,1/(1+F$19)^DCF_Base!C4:L4)+DCF_Base!$B$31/(1+F$19)^10-Assumptions!$B$8)/Assumptions!$B$9 | G20: =(SUMPRODUCT(DCF_Base!C20:L20,1/(1+G$19)^DCF_Base!C4:L4)+DCF_Base!$B$31/(1+G$19)^10-Assumptions!$B$8)/Assumptions!$B$9
A21: Note | B21: At NZ$7.48 the base-case flows do not deliver even a 9% return. The price implies a required return below 6%.
A23: Sensitivity: WACC (rows) x terminal growth (columns), base case
A24: WACC \ terminal g | B24: 0.0125 | C24: 0.0175 | D24: 0.0225 | E24: 0.0275 | F24: 0.0325
A25: 0.085 | B25: =IF($A25<=B$24,"n/a",(SUMPRODUCT(DCF_Base!C20:L20,1/(1+$A25)^DCF_Base!C4:L4)+MAX(0,MIN(DCF_Base!$L$20*(1+B$24)/($A25-B$24),Assumptions!$B$7*DCF_Base!$L$20))/(1+$A25)^10-Assumptions!$B$8)/Assumptions!$B$9) | C25: =IF($A25<=C$24,"n/a",(SUMPRODUCT(DCF_Base!C20:L20,1/(1+$A25)^DCF_Base!C4:L4)+MAX(0,MIN(DCF_Base!$L$20*(1+C$24)/($A25-C$24),Assumptions!$B$7*DCF_Base!$L$20))/(1+$A25)^10-Assumptions!$B$8)/Assumptions!$B$9) | D25: =IF($A25<=D$24,"n/a",(SUMPRODUCT(DCF_Base!C20:L20,1/(1+$A25)^DCF_Base!C4:L4)+MAX(0,MIN(DCF_Base!$L$20*(1+D$24)/($A25-D$24),Assumptions!$B$7*DCF_Base!$L$20))/(1+$A25)^10-Assumptions!$B$8)/Assumptions!$B$9) | E25: =IF($A25<=E$24,"n/a",(SUMPRODUCT(DCF_Base!C20:L20,1/(1+$A25)^DCF_Base!C4:L4)+MAX(0,MIN(DCF_Base!$L$20*(1+E$24)/($A25-E$24),Assumptions!$B$7*DCF_Base!$L$20))/(1+$A25)^10-Assumptions!$B$8)/Assumptions!$B$9) | F25: =IF($A25<=F$24,"n/a",(SUMPRODUCT(DCF_Base!C20:L20,1/(1+$A25)^DCF_Base!C4:L4)+MAX(0,MIN(DCF_Base!$L$20*(1+F$24)/($A25-F$24),Assumptions!$B$7*DCF_Base!$L$20))/(1+$A25)^10-Assumptions!$B$8)/Assumptions!$B$9)
A26: 0.095 | B26: =IF($A26<=B$24,"n/a",(SUMPRODUCT(DCF_Base!C20:L20,1/(1+$A26)^DCF_Base!C4:L4)+MAX(0,MIN(DCF_Base!$L$20*(1+B$24)/($A26-B$24),Assumptions!$B$7*DCF_Base!$L$20))/(1+$A26)^10-Assumptions!$B$8)/Assumptions!$B$9) | C26: =IF($A26<=C$24,"n/a",(SUMPRODUCT(DCF_Base!C20:L20,1/(1+$A26)^DCF_Base!C4:L4)+MAX(0,MIN(DCF_Base!$L$20*(1+C$24)/($A26-C$24),Assumptions!$B$7*DCF_Base!$L$20))/(1+$A26)^10-Assumptions!$B$8)/Assumptions!$B$9) | D26: =IF($A26<=D$24,"n/a",(SUMPRODUCT(DCF_Base!C20:L20,1/(1+$A26)^DCF_Base!C4:L4)+MAX(0,MIN(DCF_Base!$L$20*(1+D$24)/($A26-D$24),Assumptions!$B$7*DCF_Base!$L$20))/(1+$A26)^10-Assumptions!$B$8)/Assumptions!$B$9) | E26: =IF($A26<=E$24,"n/a",(SUMPRODUCT(DCF_Base!C20:L20,1/(1+$A26)^DCF_Base!C4:L4)+MAX(0,MIN(DCF_Base!$L$20*(1+E$24)/($A26-E$24),Assumptions!$B$7*DCF_Base!$L$20))/(1+$A26)^10-Assumptions!$B$8)/Assumptions!$B$9) | F26: =IF($A26<=F$24,"n/a",(SUMPRODUCT(DCF_Base!C20:L20,1/(1+$A26)^DCF_Base!C4:L4)+MAX(0,MIN(DCF_Base!$L$20*(1+F$24)/($A26-F$24),Assumptions!$B$7*DCF_Base!$L$20))/(1+$A26)^10-Assumptions!$B$8)/Assumptions!$B$9)
A27: 0.105 | B27: =IF($A27<=B$24,"n/a",(SUMPRODUCT(DCF_Base!C20:L20,1/(1+$A27)^DCF_Base!C4:L4)+MAX(0,MIN(DCF_Base!$L$20*(1+B$24)/($A27-B$24),Assumptions!$B$7*DCF_Base!$L$20))/(1+$A27)^10-Assumptions!$B$8)/Assumptions!$B$9) | C27: =IF($A27<=C$24,"n/a",(SUMPRODUCT(DCF_Base!C20:L20,1/(1+$A27)^DCF_Base!C4:L4)+MAX(0,MIN(DCF_Base!$L$20*(1+C$24)/($A27-C$24),Assumptions!$B$7*DCF_Base!$L$20))/(1+$A27)^10-Assumptions!$B$8)/Assumptions!$B$9) | D27: =IF($A27<=D$24,"n/a",(SUMPRODUCT(DCF_Base!C20:L20,1/(1+$A27)^DCF_Base!C4:L4)+MAX(0,MIN(DCF_Base!$L$20*(1+D$24)/($A27-D$24),Assumptions!$B$7*DCF_Base!$L$20))/(1+$A27)^10-Assumptions!$B$8)/Assumptions!$B$9) | E27: =IF($A27<=E$24,"n/a",(SUMPRODUCT(DCF_Base!C20:L20,1/(1+$A27)^DCF_Base!C4:L4)+MAX(0,MIN(DCF_Base!$L$20*(1+E$24)/($A27-E$24),Assumptions!$B$7*DCF_Base!$L$20))/(1+$A27)^10-Assumptions!$B$8)/Assumptions!$B$9) | F27: =IF($A27<=F$24,"n/a",(SUMPRODUCT(DCF_Base!C20:L20,1/(1+$A27)^DCF_Base!C4:L4)+MAX(0,MIN(DCF_Base!$L$20*(1+F$24)/($A27-F$24),Assumptions!$B$7*DCF_Base!$L$20))/(1+$A27)^10-Assumptions!$B$8)/Assumptions!$B$9)
A28: 0.115 | B28: =IF($A28<=B$24,"n/a",(SUMPRODUCT(DCF_Base!C20:L20,1/(1+$A28)^DCF_Base!C4:L4)+MAX(0,MIN(DCF_Base!$L$20*(1+B$24)/($A28-B$24),Assumptions!$B$7*DCF_Base!$L$20))/(1+$A28)^10-Assumptions!$B$8)/Assumptions!$B$9) | C28: =IF($A28<=C$24,"n/a",(SUMPRODUCT(DCF_Base!C20:L20,1/(1+$A28)^DCF_Base!C4:L4)+MAX(0,MIN(DCF_Base!$L$20*(1+C$24)/($A28-C$24),Assumptions!$B$7*DCF_Base!$L$20))/(1+$A28)^10-Assumptions!$B$8)/Assumptions!$B$9) | D28: =IF($A28<=D$24,"n/a",(SUMPRODUCT(DCF_Base!C20:L20,1/(1+$A28)^DCF_Base!C4:L4)+MAX(0,MIN(DCF_Base!$L$20*(1+D$24)/($A28-D$24),Assumptions!$B$7*DCF_Base!$L$20))/(1+$A28)^10-Assumptions!$B$8)/Assumptions!$B$9) | E28: =IF($A28<=E$24,"n/a",(SUMPRODUCT(DCF_Base!C20:L20,1/(1+$A28)^DCF_Base!C4:L4)+MAX(0,MIN(DCF_Base!$L$20*(1+E$24)/($A28-E$24),Assumptions!$B$7*DCF_Base!$L$20))/(1+$A28)^10-Assumptions!$B$8)/Assumptions!$B$9) | F28: =IF($A28<=F$24,"n/a",(SUMPRODUCT(DCF_Base!C20:L20,1/(1+$A28)^DCF_Base!C4:L4)+MAX(0,MIN(DCF_Base!$L$20*(1+F$24)/($A28-F$24),Assumptions!$B$7*DCF_Base!$L$20))/(1+$A28)^10-Assumptions!$B$8)/Assumptions!$B$9)
A29: 0.125 | B29: =IF($A29<=B$24,"n/a",(SUMPRODUCT(DCF_Base!C20:L20,1/(1+$A29)^DCF_Base!C4:L4)+MAX(0,MIN(DCF_Base!$L$20*(1+B$24)/($A29-B$24),Assumptions!$B$7*DCF_Base!$L$20))/(1+$A29)^10-Assumptions!$B$8)/Assumptions!$B$9) | C29: =IF($A29<=C$24,"n/a",(SUMPRODUCT(DCF_Base!C20:L20,1/(1+$A29)^DCF_Base!C4:L4)+MAX(0,MIN(DCF_Base!$L$20*(1+C$24)/($A29-C$24),Assumptions!$B$7*DCF_Base!$L$20))/(1+$A29)^10-Assumptions!$B$8)/Assumptions!$B$9) | D29: =IF($A29<=D$24,"n/a",(SUMPRODUCT(DCF_Base!C20:L20,1/(1+$A29)^DCF_Base!C4:L4)+MAX(0,MIN(DCF_Base!$L$20*(1+D$24)/($A29-D$24),Assumptions!$B$7*DCF_Base!$L$20))/(1+$A29)^10-Assumptions!$B$8)/Assumptions!$B$9) | E29: =IF($A29<=E$24,"n/a",(SUMPRODUCT(DCF_Base!C20:L20,1/(1+$A29)^DCF_Base!C4:L4)+MAX(0,MIN(DCF_Base!$L$20*(1+E$24)/($A29-E$24),Assumptions!$B$7*DCF_Base!$L$20))/(1+$A29)^10-Assumptions!$B$8)/Assumptions!$B$9) | F29: =IF($A29<=F$24,"n/a",(SUMPRODUCT(DCF_Base!C20:L20,1/(1+$A29)^DCF_Base!C4:L4)+MAX(0,MIN(DCF_Base!$L$20*(1+F$24)/($A29-F$24),Assumptions!$B$7*DCF_Base!$L$20))/(1+$A29)^10-Assumptions!$B$8)/Assumptions!$B$9)
A31: Sensitivity note | B31: Every cell in the grid sits below the NZ$7.48 market price. Rows flatten at 8.5% WACC because the 15x terminal cap binds there -- correct behaviour for a cyclical.
A33: VERDICT | B33: Skellerup is a genuinely high-quality business trading at a price that already pays for its quality and then some. The verdict is OVERVALUED at NZ$7.48, on a weighted IV of NZ$4.51 -- and the reason is arithmetic, not pessimism about the company.
