Workbook

Sheet DCF Model
A1: FSLR — First Solar DCF Valuation Model
A2: Gray cells are INPUTS — adjust to see valuation update automatically
A3: Valuation date: 2026-07-06 | Price verified via Yahoo Finance
A5: KEY INPUTS
A6: Current Stock Price | B6: 224.57 | C6: ← Yahoo Finance verified 2026-07-06
A7: Shares Outstanding (M) | B7: 107.3
A8: Cash & Equivalents (M) | B8: 2803.5
A9: Total Debt (M) | B9: 498.8 | C9: India Credit Facility + working capital facilities
A10: Net Debt (M) [negative = net cash] | B10: =B9-B8 -> 0
A11: Base Year FCF (M) [normalised] | B11: 1200 | C11: FY2025 post-buildout normalised (not historical median -$305M)
A12: WACC | B12: 0.11 | C12: Includes +1.5% 45X legislative-dependency premium
A13: Terminal Growth Rate | B13: 0.025 | C13: Capped at 2.5% — mature manufacturing, commodity exposure
A15: FCF GROWTH ASSUMPTIONS (BASE CASE)
B16: Year 1 | C16: Year 2 | D16: Year 3 | E16: Year 4 | F16: Year 5
A17: Annual FCF Growth Rate | B17: 0.15 | C17: 0.2 | D17: 0.15 | E17: 0.08 | F17: 0.05
A19: PROJECTIONS
B20: Base FCF | C20: Year 1 | D20: Year 2 | E20: Year 3 | F20: Year 4 | G20: Year 5
A21: Free Cash Flow (M) | B21: =B11 -> 0 | C21: =B21*(1+B17) -> 0 | D21: =C21*(1+C17) -> 0 | E21: =D21*(1+D17) -> 0 | F21: =E21*(1+E17) -> 0 | G21: =F21*(1+F17) -> 0
A22: Discount Factor | C22: =1/(1+$B$12)^1 -> 0 | D22: =1/(1+$B$12)^2 -> 0 | E22: =1/(1+$B$12)^3 -> 0 | F22: =1/(1+$B$12)^4 -> 0 | G22: =1/(1+$B$12)^5 -> 0
A23: PV of FCF (M) | C23: =C21*C22 -> 0 | D23: =D21*D22 -> 0 | E23: =E21*E22 -> 0 | F23: =F21*F22 -> 0 | G23: =G21*G22 -> 0
A25: VALUATION
A26: Sum of PV of FCF (M) | B26: =SUM(C23:G23) -> 0
A27: Terminal FCF [Year5 × (1+g)] | B27: =G21*(1+$B$13) -> 0
A28: Terminal Value (perpetuity) | B28: =B27/( $B$12-$B$13) -> 0
A29: PV of Terminal Value | B29: =B28*G22 -> 0
A30: Enterprise Value (M) | B30: =B26+B29 -> 0
A31: Less: Net Debt (M) [debt − cash] | B31: =B10 -> 0
A32: Equity Value (M) | B32: =B30-B31 -> 0
A33: INTRINSIC VALUE / SHARE | B33: =B32/B7 -> 0
A34: Upside / (Downside) to IV | B34: =(B33-B6)/B6 -> 0
A36: ENTRY PRICE — 15% CAGR Target
A37: Terminal Value per Share | B37: =B28/B7 -> 0
A38: Entry Price (15% CAGR over 5 years) | B38: =B37/(1.15^5) -> 0
A39: Current Premium to Entry Price | B39: =(B6-B38)/B6 -> 0
A41: SANITY CHECK (vs FY2025 actuals)
A42: FY2025 EPS | B42: 14.21 | C42: Historical avg P/E ~22x, max ~31x
A43: Implied P/E (IV / EPS) | B43: =B33/B41 -> 0 | C43: PASS if < 44x (2× historical avg). Result: ~16x
A44: FY2025 Book Value / Share | B44: 88.89 | C44: Historical avg P/B ~1.83x, max ~2.94x
A45: Implied P/B (IV / Book) | B45: =B33/B43 -> 0 | C45: PASS if < 4.4x (1.5× historical max). Result: ~2.6x
A46: FY2025 EBITDA est. (M) | B46: 1947 | C46: Operating income $1,597M + D&A ~$350M
...

Sheet Scenarios
A1: FSLR — Scenario Comparison
A2: Base / Bull / Bear cases with independent WACC and growth assumptions
A4: Metric | B4: BASE CASE | C4: BULL CASE | D4: BEAR CASE
A5: Year 1 FCF (M) | B5: 1380 | C5: 1500 | D5: 1260
A6: Year 2 FCF (M) | B6: 1656 | C6: 1920 | D6: 1323
A7: Year 3 FCF (M) | B7: 1904.4 | C7: 2304 | D7: 1323
A8: Year 4 FCF (M) | B8: 2056.8 | C8: 2580.5 | D8: 1256.9
A9: Year 5 FCF (M) | B9: 2159.6 | C9: 2786.9 | D9: 1194
A10: Sum PV of FCF (M) | B10: 6616.2 | C10: 8410.5 | D10: 4487
A11: Terminal Value (M) | B11: 26042.2 | C11: 43947.3 | D11: 10538.3
A12: PV of Terminal Value (M) | B12: 15456.1 | C12: 28561.3 | D12: 5720.2
A13: Enterprise Value (M) | B13: 22072.3 | C13: 36971.8 | D13: 10207.2
A14: Less: Net Debt (M) | B14: -2304.7 | C14: -2304.7 | D14: -2304.7
A15: Equity Value (M) | B15: 24377 | C15: 39276.5 | D15: 12511.9
A16: Intrinsic Value / Share | B16: 227.19 | C16: 366.04 | D16: 116.61
A17: Upside / (Downside) | B17: 1.2% | C17: 63.0% | D17: -48.1%
A18: Entry Price @ 15% CAGR | B18: 120.67 | C18: 203.63 | D18: 48.83
A21: PROBABILITY WEIGHTS
A22: Weight | B22: 50% | C22: 25% | D22: 25%
A23: Probability-Weighted IV | B23: 234.26 | C23: Upside from current: | D23: 4.3%
A25: KEY SCENARIO DRIVERS
A26: BASE | B26: Contracted backlog ramp (14→17.7 GW US), CuRe adders, 45X preserved to 2032. WACC 11% includes +1.5% 45X policy premium.
A27: BULL | B27: Strong Section 232 tariffs, ITC patent exclusion order, 45X fully intact, SE Asia capacity utilised via SC finishing facility.
A28: BEAR | B28: 45X erosion (20-30% reduction via legislation), weak 232 outcome, SE Asia write-downs, booking pace fails to recover post-2028.

Sheet Sensitivity
A1: FSLR — Sensitivity Analysis: Intrinsic Value by WACC & Terminal Growth
A2: Base case FCF growth rates held constant. Net cash ($2,304.7M) added to equity value in all cells.
A3: Current price $224.57 shown in gold. Green = premium to current; Red = discount.
A5: WACC \ Term-G | B5: 0.015 | C5: 0.02 | D5: 0.025 | E5: 0.03 | F5: 0.035
A6: 0.08 | B6: 302.4 | C6: 321.4 | D6: 343.8 | E6: 370.7 | F6: 403.6
A7: 0.09 | B7: 263.6 | C7: 277.2 | D7: 292.9 | E7: 311.2 | F7: 332.8
A8: 0.1 | B8: 234.1 | C8: 244.2 | D8: 255.6 | E8: 268.7 | F8: 283.8
A9: 0.11 | B9: 210.8 | C9: 218.5 | D9: 227.2 | E9: 236.9 | F9: 248
A10: 0.12 | B10: 191.9 | C10: 198 | D10: 204.7 | E10: 212.2 | F10: 220.6
A13: Legend: | B13: > +15% upside | C13: Within ±15% | D13: Near current price | E13: > 15% discount
A15: Base case IV: $227.19 (WACC 11%, TG 2.5%) | Current: $224.57 — stock appears approximately fairly valued in base case
A17: FORMULA REFERENCE (live recalc from DCF Model inputs)
A18: Each cell below recomputes IV using live FCF projections from DCF Model sheet and the row/column WACC/TG.
A20: LIVE SENSITIVITY (updates with DCF Model inputs)
A21: WACC \ Term-G | B21: 0.015 | C21: 0.02 | D21: 0.025 | E21: 0.03 | F21: 0.035
A22: 0.08 | B22: =('DCF Model'!C21/(1+0.08)^1 + 'DCF Model'!D21/(1+0.08)^2 + 'DCF Model'!E21/(1+0.08)^3 + 'DCF Model'!F21/(1+0.08)^4 + 'DCF Model'!G21/(1+0.08)^5 + ('DCF Model'!G21*(1+0.015)/(0.08-0.015))/(1+0.08)^5 - 'DCF Model'!B10) / 'DCF Model'!B7 -> 0 | C22: =('DCF Model'!C21/(1+0.08)^1 + 'DCF Model'!D21/(1+0.08)^2 + 'DCF Model'!E21/(1+0.08)^3 + 'DCF Model'!F21/(1+0.08)^4 + 'DCF Model'!G21/(1+0.08)^5 + ('DCF Model'!G21*(1+0.02)/(0.08-0.02))/(1+0.08)^5 - 'DCF Model'!B10) / 'DCF Model'!B7 -> 0 | D22: =('DCF Model'!C21/(1+0.08)^1 + 'DCF Model'!D21/(1+0.08)^2 + 'DCF Model'!E21/(1+0.08)^3 + 'DCF Model'!F21/(1+0.08)^4 + 'DCF Model'!G21/(1+0.08)^5 + ('DCF Model'!G21*(1+0.025)/(0.08-0.025))/(1+0.08)^5 - 'DCF Model'!B10) / 'DCF Model'!B7 -> 0 | E22: =('DCF Model'!C21/(1+0.08)^1 + 'DCF Model'!D21/(1+0.08)^2 + 'DCF Model'!E21/(1+0.08)^3 + 'DCF Model'!F21/(1+0.08)^4 + 'DCF Model'!G21/(1+0.08)^5 + ('DCF Model'!G21*(1+0.03)/(0.08-0.03))/(1+0.08)^5 - 'DCF Model'!B10) / 'DCF Model'!B7 -> 0 | F22: =('DCF Model'!C21/(1+0.08)^1 + 'DCF Model'!D21/(1+0.08)^2 + 'DCF Model'!E21/(1+0.08)^3 + 'DCF Model'!F21/(1+0.08)^4 + 'DCF Model'!G21/(1+0.08)^5 + ('DCF Model'!G21*(1+0.035)/(0.08-0.035))/(1+0.08)^5 - 'DCF Model'!B10) / 'DCF Model'!B7 -> 0
A23: 0.09 | B23: =('DCF Model'!C21/(1+0.09)^1 + 'DCF Model'!D21/(1+0.09)^2 + 'DCF Model'!E21/(1+0.09)^3 + 'DCF Model'!F21/(1+0.09)^4 + 'DCF Model'!G21/(1+0.09)^5 + ('DCF Model'!G21*(1+0.015)/(0.09-0.015))/(1+0.09)^5 - 'DCF Model'!B10) / 'DCF Model'!B7 -> 0 | C23: =('DCF Model'!C21/(1+0.09)^1 + 'DCF Model'!D21/(1+0.09)^2 + 'DCF Model'!E21/(1+0.09)^3 + 'DCF Model'!F21/(1+0.09)^4 + 'DCF Model'!G21/(1+0.09)^5 + ('DCF Model'!G21*(1+0.02)/(0.09-0.02))/(1+0.09)^5 - 'DCF Model'!B10) / 'DCF Model'!B7 -> 0 | D23: =('DCF Model'!C21/(1+0.09)^1 + 'DCF Model'!D21/(1+0.09)^2 + 'DCF Model'!E21/(1+0.09)^3 + 'DCF Model'!F21/(1+0.09)^4 + 'DCF Model'!G21/(1+0.09)^5 + ('DCF Model'!G21*(1+0.025)/(0.09-0.025))/(1+0.09)^5 - 'DCF Model'!B10) / 'DCF Model'!B7 -> 0 | E23: =('DCF Model'!C21/(1+0.09)^1 + 'DCF Model'!D21/(1+0.09)^2 + 'DCF Model'!E21/(1+0.09)^3 + 'DCF Model'!F21/(1+0.09)^4 + 'DCF Model'!G21/(1+0.09)^5 + ('DCF Model'!G21*(1+0.03)/(0.09-0.03))/(1+0.09)^5 - 'DCF Model'!B10) / 'DCF Model'!B7 -> 0 | F23: =('DCF Model'!C21/(1+0.09)^1 + 'DCF Model'!D21/(1+0.09)^2 + 'DCF Model'!E21/(1+0.09)^3 + 'DCF Model'!F21/(1+0.09)^4 + 'DCF Model'!G21/(1+0.09)^5 + ('DCF Model'!G21*(1+0.035)/(0.09-0.035))/(1+0.09)^5 - 'DCF Model'!B10) / 'DCF Model'!B7 -> 0
A24: 0.1 | B24: =('DCF Model'!C21/(1+0.1)^1 + 'DCF Model'!D21/(1+0.1)^2 + 'DCF Model'!E21/(1+0.1)^3 + 'DCF Model'!F21/(1+0.1)^4 + 'DCF Model'!G21/(1+0.1)^5 + ('DCF Model'!G21*(1+0.015)/(0.1-0.015))/(1+0.1)^5 - 'DCF Model'!B10) / 'DCF Model'!B7 -> 0 | C24: =('DCF Model'!C21/(1+0.1)^1 + 'DCF Model'!D21/(1+0.1)^2 + 'DCF Model'!E21/(1+0.1)^3 + 'DCF Model'!F21/(1+0.1)^4 + 'DCF Model'!G21/(1+0.1)^5 + ('DCF Model'!G21*(1+0.02)/(0.1-0.02))/(1+0.1)^5 - 'DCF Model'!B10) / 'DCF Model'!B7 -> 0 | D24: =('DCF Model'!C21/(1+0.1)^1 + 'DCF Model'!D21/(1+0.1)^2 + 'DCF Model'!E21/(1+0.1)^3 + 'DCF Model'!F21/(1+0.1)^4 + 'DCF Model'!G21/(1+0.1)^5 + ('DCF Model'!G21*(1+0.025)/(0.1-0.025))/(1+0.1)^5 - 'DCF Model'!B10) / 'DCF Model'!B7 -> 0 | E24: =('DCF Model'!C21/(1+0.1)^1 + 'DCF Model'!D21/(1+0.1)^2 + 'DCF Model'!E21/(1+0.1)^3 + 'DCF Model'!F21/(1+0.1)^4 + 'DCF Model'!G21/(1+0.1)^5 + ('DCF Model'!G21*(1+0.03)/(0.1-0.03))/(1+0.1)^5 - 'DCF Model'!B10) / 'DCF Model'!B7 -> 0 | F24: =('DCF Model'!C21/(1+0.1)^1 + 'DCF Model'!D21/(1+0.1)^2 + 'DCF Model'!E21/(1+0.1)^3 + 'DCF Model'!F21/(1+0.1)^4 + 'DCF Model'!G21/(1+0.1)^5 + ('DCF Model'!G21*(1+0.035)/(0.1-0.035))/(1+0.1)^5 - 'DCF Model'!B10) / 'DCF Model'!B7 -> 0
A25: 0.11 | B25: =('DCF Model'!C21/(1+0.11)^1 + 'DCF Model'!D21/(1+0.11)^2 + 'DCF Model'!E21/(1+0.11)^3 + 'DCF Model'!F21/(1+0.11)^4 + 'DCF Model'!G21/(1+0.11)^5 + ('DCF Model'!G21*(1+0.015)/(0.11-0.015))/(1+0.11)^5 - 'DCF Model'!B10) / 'DCF Model'!B7 -> 0 | C25: =('DCF Model'!C21/(1+0.11)^1 + 'DCF Model'!D21/(1+0.11)^2 + 'DCF Model'!E21/(1+0.11)^3 + 'DCF Model'!F21/(1+0.11)^4 + 'DCF Model'!G21/(1+0.11)^5 + ('DCF Model'!G21*(1+0.02)/(0.11-0.02))/(1+0.11)^5 - 'DCF Model'!B10) / 'DCF Model'!B7 -> 0 | D25: =('DCF Model'!C21/(1+0.11)^1 + 'DCF Model'!D21/(1+0.11)^2 + 'DCF Model'!E21/(1+0.11)^3 + 'DCF Model'!F21/(1+0.11)^4 + 'DCF Model'!G21/(1+0.11)^5 + ('DCF Model'!G21*(1+0.025)/(0.11-0.025))/(1+0.11)^5 - 'DCF Model'!B10) / 'DCF Model'!B7 -> 0 | E25: =('DCF Model'!C21/(1+0.11)^1 + 'DCF Model'!D21/(1+0.11)^2 + 'DCF Model'!E21/(1+0.11)^3 + 'DCF Model'!F21/(1+0.11)^4 + 'DCF Model'!G21/(1+0.11)^5 + ('DCF Model'!G21*(1+0.03)/(0.11-0.03))/(1+0.11)^5 - 'DCF Model'!B10) / 'DCF Model'!B7 -> 0 | F25: =('DCF Model'!C21/(1+0.11)^1 + 'DCF Model'!D21/(1+0.11)^2 + 'DCF Model'!E21/(1+0.11)^3 + 'DCF Model'!F21/(1+0.11)^4 + 'DCF Model'!G21/(1+0.11)^5 + ('DCF Model'!G21*(1+0.035)/(0.11-0.035))/(1+0.11)^5 - 'DCF Model'!B10) / 'DCF Model'!B7 -> 0
A26: 0.12 | B26: =('DCF Model'!C21/(1+0.12)^1 + 'DCF Model'!D21/(1+0.12)^2 + 'DCF Model'!E21/(1+0.12)^3 + 'DCF Model'!F21/(1+0.12)^4 + 'DCF Model'!G21/(1+0.12)^5 + ('DCF Model'!G21*(1+0.015)/(0.12-0.015))/(1+0.12)^5 - 'DCF Model'!B10) / 'DCF Model'!B7 -> 0 | C26: =('DCF Model'!C21/(1+0.12)^1 + 'DCF Model'!D21/(1+0.12)^2 + 'DCF Model'!E21/(1+0.12)^3 + 'DCF Model'!F21/(1+0.12)^4 + 'DCF Model'!G21/(1+0.12)^5 + ('DCF Model'!G21*(1+0.02)/(0.12-0.02))/(1+0.12)^5 - 'DCF Model'!B10) / 'DCF Model'!B7 -> 0 | D26: =('DCF Model'!C21/(1+0.12)^1 + 'DCF Model'!D21/(1+0.12)^2 + 'DCF Model'!E21/(1+0.12)^3 + 'DCF Model'!F21/(1+0.12)^4 + 'DCF Model'!G21/(1+0.12)^5 + ('DCF Model'!G21*(1+0.025)/(0.12-0.025))/(1+0.12)^5 - 'DCF Model'!B10) / 'DCF Model'!B7 -> 0 | E26: =('DCF Model'!C21/(1+0.12)^1 + 'DCF Model'!D21/(1+0.12)^2 + 'DCF Model'!E21/(1+0.12)^3 + 'DCF Model'!F21/(1+0.12)^4 + 'DCF Model'!G21/(1+0.12)^5 + ('DCF Model'!G21*(1+0.03)/(0.12-0.03))/(1+0.12)^5 - 'DCF Model'!B10) / 'DCF Model'!B7 -> 0 | F26: =('DCF Model'!C21/(1+0.12)^1 + 'DCF Model'!D21/(1+0.12)^2 + 'DCF Model'!E21/(1+0.12)^3 + 'DCF Model'!F21/(1+0.12)^4 + 'DCF Model'!G21/(1+0.12)^5 + ('DCF Model'!G21*(1+0.035)/(0.12-0.035))/(1+0.12)^5 - 'DCF Model'!B10) / 'DCF Model'!B7 -> 0

Sheet Historical
A1: FSLR — Historical Growth Rates & Context
A3: Metric | B3: 3-Year CAGR | C3: 5-Year CAGR
A4: Revenue | B4: 0.2584 | C4: 0.14
A5: EPS | B5: N/A (see note) | C5: 0.3067
A6: Shareholders Equity | B6: 0.1779 | C6: 0.1156
A7: FCF | B7: N/A (see note) | C7: N/A (see note)
A9: Selected Growth Rate (DCF anchor): | B9: 0.1156 | C9: equity_5yr_cagr
A10: Divergence warning: | B10: None — all within 30pp threshold
A12: NOTES
A13: • EPS 3yr CAGR not computed: FY2022 EPS was -$0.41 (negative base year).
A14: • FCF 3yr and 5yr CAGRs not computed: FCF was negative FY2016-FY2024 during $5B+ capacity buildout.
A15: • Historical median FCF is -$305M and is deliberately NOT used as the DCF base year FCF.
A16: • DCF base FCF = $1,200M, reflecting FY2025 post-buildout actuals ($1,187M) and forward normalisation.
A17: • 45X manufacturing credits (~$1.6B in FY2025, guided $2.1-2.2B in FY2026) are included in FCF as cash received via tax credit transfers.
A18: • WACC premium of +1.5% (base) / +2.5% (bear) applied for 45X legislative single-point-of-failure risk.
A19: • Net cash position: -$2,304.7M net debt (i.e., $2,304.7M net cash) adds directly to equity value.
A22: SANITY CHECK RESULTS
A23: Multiple | B23: Value | C23: Assessment
A24: Implied P/E (base IV / FY2025 EPS) | B24: 16.0x | C24: Hist avg ~22x, max ~31x — PASS (< 44x threshold)
A25: Implied P/B (base IV / FY2025 Book) | B25: 2.56x | C25: Hist avg 1.83x, max 2.94x — PASS (< 4.4x threshold)
A26: Implied EV/EBITDA (base EV / FY2025 EBITDA) | B26: 11.3x | C26: ~8x forward — reasonable for contracted backlog business
