Workbook

Sheet Model_Info
A1: VNT.NZ owner-FCF DCF model
A2: Version | B2: v1 (fresh build) 2026-09-19. Supersedes nothing: first DCF for this ticker.
A3: Built by | B3: dcf-analyst agent (Claude Fable 5.1), 2026-09-19, at the request of the research-stock orchestrator (user: Stephen Williams).
A4: Data vintage | B4: Price NZ$7.49 VNT.NZ, Yahoo regularMarketTime 2026-09-18T04:08:13Z (NZX regular close). ASX parity VNT.AX A$6.00 x AUDNZD 1.2435 (Yahoo, 2026-09-19) = NZ$7.46 (0.4% tie).
B5: Balance sheet: 30-Jun-2026 (H1 FY2026 Appendix 4D, 24-Aug-2026): gross borrowings A$1,050.0m, cash A$480.8m, lease liabilities A$179.1m (excluded, treatment B).
B6: Share count: 826.6m fully diluted at 30-Jun-2026 (817.8m issued - 10.8m treasury + 19.6m dilutive rights). Held flat.
B7: FY0 = FY2025 actuals (31-Dec-2025): revenue A$6,141.1m, underlying EBITDA A$532.1m (8.66%), statutory EBITDA A$557.0m incl. A$24.9m TSRC gain.
B8: Guidance: FY2026 underlying NPATA +7-10% on A$257.6m (reaffirmed 24-Aug-2026); OCF conversion >90%; payout 60-80% NPATA; A$300m buyback 2025-26.
A9: Methodology | B9: Owner-FCF DCF, component-built (EBITDA - SBC - lease cash - D&A ex-ROU = EBIT; tax; + D&A - capex + WC), 10-year explicit horizon, end-of-year discounting.
B10: Leases: treatment (B) -- lease principal + interest charged in the flows (1.2% of revenue); lease liabilities excluded from net debt; D&A is ex-ROU.
B11: Terminal value = MAX(0, MIN(Gordon, 15x FCF_10)); 15x because low-margin contracted services. Cap binds in all three scenarios.
B12: Single AUD WACC 8.5% for all scenarios (CoE 8.9% = 4.4% rf + 5.0% ERP x 0.9 beta; Kd 3.9% after tax; E/D 90/10). ACCC litigation is in the bear flows and weights, not in WACC.
B13: All per-share values are computed in AUD and converted to NZD at the Assumptions FX rate. Unsuffixed JSON keys are NZD (quote currency).
A14: Scenario drivers | B14: Judgment of the dcf-analyst agent, set 2026-09-19 from the FY2025 annual report, H1 FY2026 4D and VNT.NZ_Analysis.json. Rows 5, 7, 9, 17, 21 on each DCF tab are the only hardcoded drivers.
A15: Refresh after next print | B15: FY2026 results (Feb-2027): revenue, underlying EBITDA margin, cash tax, capex, lease cash, net debt (31-Dec-2026), diluted count after the buyback, FY2027 guidance; AUDNZD rate; ACCC trial outcome (May-2027).
A16: Staleness | B16: Every figure in this workbook goes stale: price daily, FX daily, balance sheet each half. Check Model_Info dates before relying on any output.
A17: Cell legend | B17: Blue = hardcoded input; yellow fill = key lever; black = formula; green = cross-sheet link.

Sheet Actuals
A1: Item (A$m) | B1: FY2020 | C1: FY2021 | D1: FY2022 | E1: FY2023 | F1: FY2024 | G1: FY2025 | H1: H1 FY2026 | I1: Source
A2: Revenue | B2: 3223.9 | C2: 4557.4 | D2: 5167.5 | E2: 5676.4 | F2: 6105.5 | G2: 6141.1 | H2: 2893.6 | I2: Metrics.csv / income statements
A3: EBITDA statutory | B3: 265.8 | C3: 312.2 | D3: 414.3 | E3: 465.2 | F3: 499.3 | G3: 557 | H3: 273.3 | I3: Metrics.csv; FY2025 incl. A$24.9m TSRC gain
A4: EBITDA underlying | F4: 499.3 | G4: 532.1 | H4: 273.3 | I4: Annual FY2025 s3.1; H1 FY2026 s2
A5: Net income | B5: 28 | C5: 19.5 | D5: 191.2 | E5: 189.8 | F5: 220.2 | G5: 272.2 | H5: 127.6 | I5: Metrics.csv
A6: Underlying NPATA | F6: 227.9 | G6: 257.6 | H6: 128.2 | I6: Annual FY2025 s3.2; H1 FY2026
A7: Operating cash flow | B7: 82.5 | C7: 124.6 | D7: 289.9 | E7: 305.9 | F7: 356.2 | G7: 378.9 | H7: 178 | I7: Cash flow statements
A8: Capex (PP&E + intangibles) | B8: 29.2 | C8: 36.3 | D8: 38.4 | E8: 50.9 | F8: 69 | G8: 110.1 | H8: 61 | I8: Cash flow statements
A9: Reported FCF (OCF - capex) | B9: 53.3 | C9: 88.3 | D9: 251.5 | E9: 255 | F9: 287.2 | G9: 268.8 | H9: 117 | I9: derived
A10: Lease principal repaid | B10: 52.9 | C10: 63.8 | D10: 64.4 | E10: 62.2 | F10: 59 | G10: 61.6 | H10: 30.1 | I10: Financing cash flows
A11: Lease interest paid | C11: 8.2 | D11: 7.1 | E11: 6.7 | F11: 7.1 | G11: 9.4 | H11: 5.7 | I11: Operating cash flows
A12: SBC expense | B12: 0 | C12: 3.1 | D12: 7.6 | E12: 4.4 | F12: 5.2 | G12: 5.9 | I12: OCF reconciliation / equity statement
A13: Owner FCF (levered) = FCF - lease principal - SBC | B13: 0.4 | C13: 21.4 | D13: 179.5 | E13: 188.4 | F13: 223 | G13: 201.3 | I13: derived
A14: Depreciation (total, incl. ROU) | C14: 108.9 | D14: 104.1 | E14: 106.6 | F14: 105.6 | G14: 100.7 | H14: 55 | I14: Income statements
A15: ROU depreciation | F15: 59 | G15: 61.6 | I15: Note 3.2.1
A16: Amortisation | C16: 85.9 | D16: 55 | E16: 39.1 | F16: 33 | G16: 20.6 | H16: 7.3 | I16: Income statements
A17: Income tax paid | C17: 35.3 | D17: 25.7 | E17: 58.2 | F17: 59 | G17: 73.8 | H17: 51 | I17: Operating cash flows
A18: Interest received | C18: 1 | D18: 1.6 | E18: 6.2 | F18: 11.1 | G18: 10.5 | H18: 2.9 | I18: Operating cash flows
A19: Interest and other finance costs paid | F19: 45 | G19: 48.8 | H19: 24.6 | I19: Operating cash flows
A20: Share buyback | C20: 4.5 | D20: 0 | E20: 0 | F20: 0 | G20: 137.8 | H20: 48.3 | I20: Financing cash flows
A21: Treasury shares purchased | F21: 0 | G21: 28 | H21: 0.6 | I21: Financing cash flows
A22: Dividends paid | C22: 38.5 | D22: 75.5 | E22: 139.9 | F22: 158.6 | G22: 178.4 | H22: 102.7 | I22: Financing cash flows
A23: Shareholders' equity | B23: 33.7 | C23: 390.5 | D23: 520.9 | E23: 570.2 | F23: 630.9 | G23: 561.1 | H23: 540.2 | I23: Balance sheets
A24: Gross borrowings (ex capitalised costs) | F24: 750 | G24: 750 | H24: 1050 | I24: Note 4.4
A25: Cash | B25: 444.3 | C25: 180.2 | D25: 280 | E25: 338.7 | F25: 392.8 | G25: 236.3 | H25: 480.8 | I25: Balance sheets
A26: Lease liabilities | F26: 143.8 | G26: 190.2 | H26: 179.1 | I26: Note 3.2.2 / balance sheet
A27: Company net debt incl. leases | F27: 501 | G27: 703.9 | H27: 748.3 | I27: OFR
A28: Shares issued (m) | F28: 855.5 | G28: 826.4 | H28: 817.8 | I28: Note 4.3
A29: Diluted WANOS (m) | F29: 864.3 | G29: 850.7 | H29: 826.9 | I29: Note 4.1
A30: Work in hand (A$bn) | F30: 19.3 | G30: 22.1 | H30: 21.1 | I30: OFR
A32: Guidance FY2026: underlying NPATA growth 7-10% (ex A$24.9m TSRC gain); 87% of FY2026 revenue secured at H1; OCF conversion >90%; dividend payout 60-80% of NPATA; A$300m cumulative buyback 2025-26 (A$185.8m used to 30-Jun-2026).

Sheet Assumptions
A1: Global inputs
A2: WACC (AUD, all scenarios) | B2: 0.085 | C2: CoE 8.9% (rf 4.4% + 5.0% ERP x 0.9 beta), Kd 3.9% after tax, E/D 90/10 -> 8.4%, rounded 8.5%
A3: Lease cash % of revenue (principal + interest) | B3: 0.012 | C3: FY2025 1.16%, H1 FY2026 1.24%; treatment B
A4: D&A ex-ROU % of revenue | B4: 0.01 | C4: FY2025: depreciation 100.7 - ROU 61.6 + amortisation 20.6 = 59.7 = 0.97%
A5: Working-capital capture on revenue CHANGE | B5: 0.03 | C5: Negative NWC business: growth releases ~3c per $ of new revenue; outflow when revenue falls
A6: Net bank debt A$m (30-Jun-2026) | B6: 569.2 | C6: Gross borrowings 1,050.0 - cash 480.8; lease liabilities 179.1 excluded
A7: Diluted shares (m), flat | B7: 826.6 | C7: 817.8 issued - 10.8 treasury + 19.6 dilutive rights, 30-Jun-2026
A8: Current price NZ$ (VNT.NZ) | B8: 7.49 | C8: Yahoo 2026-09-18T04:08:13Z NZX close
A9: AUD -> NZD rate | B9: 1.2435 | C9: Yahoo AUDNZD=X 2026-09-19; parity VNT.AX A$6.00 -> NZ$7.46 vs NZ$7.49
A10: Terminal value cap (x FCF_10) | B10: 15 | C10: Low-margin contracted services; Gordon at 8.5%/2.5% would be 17.1x
A11: Hurdle IRR for entry price | B11: 0.15 | C11: House standard
A12: FY2025 revenue A$m (FY0) | B12: 6141.1 | C12: Annual report FY2025
A15: Per scenario | B15: Bear | C15: Base | D15: Bull
A16: Terminal growth | B16: 0.02 | C16: 0.025 | D16: 0.03
A17: Probability weight | B17: 0.25 | C17: 0.5 | D17: 0.25
A18: Weights check (must be 1.0) | B18: =SUM(B17:D17)
A20: Scenario narratives
A21: Bear | B21: The Defence transition drags into FY2027 (revenue -4% then flat), the ACCC cartel case produces an adverse finding in mid-2027 with a penalty, legal and remediation cost of ~A$70m (FY2027 margin 7.3%) and a lasting hit to Defence tender competitiveness, insourcing and re-tender losses cap growth at 2-2.5%, and the margin settles back at the FY2025 level of 8.5% as labour inflation on fixed-price/unit-rate contracts erodes the mix gains. Capex stays at 1.5-1.8% of revenue to keep winning work. Terminal growth 2.0%. No solvency path: ND/EBITDA ~1.4x incl. leases, covenant 3.25x.
A22: Base | B22: Ventia converts its A$21bn work-in-hand and 87% FY26 revenue cover into a flat-to-slightly-down FY2026 (Defence Base Services transition) and then 4-5% growth as the A$2.7bn BST and A$935m Clothing Defence contracts, nbn Field Module/FTTN, Yarra Valley Water and the Victorian road contracts ramp -- broadly the 4.7% market CAGR. Underlying EBITDA margin lifts from 8.7% to 9.5% in FY2026 (guidance-consistent: NPATA ~A$279m, +8%) and plateaus at 9.8% as the mix keeps tilting to Energy/Water/Resources. Capex normalises from 1.8% to 1.3% of revenue after the rig and SAP programmes. The ACCC case settles or is decided without changing Defence eligibility. Terminal growth 2.5%, cap 15x owner FCF (binds).
A23: Bull | B23: New Defence contracts mobilise on time and Defence spending heads toward 2.3% of GDP, telecommunications wins (nbn, Optus) and the energy-transition/water pipeline push growth to 5-6.5% in FY2027-29, and the mix shift plus AI/digital productivity tools (VenSpark, VenSights) take the underlying margin to 10.6% by FY2031. Capex falls back to 1.2% of revenue and the buyback keeps the count flat at no cost to the model. ACCC outcome immaterial. Terminal growth 3.0%.

Sheet DCF_Bear
A1: DCF_Bear -- A$m unless stated; drivers in blue on rows 5, 7, 9, 17, 21
A3: Year | B3: 2025A | C3: 2026E | D3: 2027E | E3: 2028E | F3: 2029E | G3: 2030E | H3: 2031E | I3: 2032E | J3: 2033E | K3: 2034E | L3: 2035E
A4: Index | B4: 0 | C4: 1 | D4: 2 | E4: 3 | F4: 4 | G4: 5 | H4: 6 | I4: 7 | J4: 8 | K4: 9 | L4: 10
A5: Revenue growth YoY | C5: -0.04 | D5: 0 | E5: 0.015 | F5: 0.02 | G5: 0.025 | H5: 0.025 | I5: 0.025 | J5: 0.025 | K5: 0.02 | L5: 0.02
A6: Revenue | B6: =Assumptions!$B$12 | C6: =B6*(1+C5) | D6: =C6*(1+D5) | E6: =D6*(1+E5) | F6: =E6*(1+F5) | G6: =F6*(1+G5) | H6: =G6*(1+H5) | I6: =H6*(1+I5) | J6: =I6*(1+J5) | ... L6: =K6*(1+L5)
A7: Adj (underlying) EBITDA margin | C7: 0.092 | D7: 0.073 | E7: 0.084 | F7: 0.085 | G7: 0.085 | H7: 0.085 | I7: 0.085 | J7: 0.085 | K7: 0.085 | L7: 0.085
A8: Adjusted EBITDA | C8: =C6*C7 | D8: =D6*D7 | E8: =E6*E7 | F8: =F6*F7 | G8: =G6*G7 | H8: =H6*H7 | I8: =I6*I7 | J8: =J6*J7 | ... L8: =L6*L7
A9: SBC % of revenue | C9: 0.0015 | D9: 0.0015 | E9: 0.0015 | F9: 0.0015 | G9: 0.0015 | H9: 0.0015 | I9: 0.0015 | J9: 0.0015 | K9: 0.0015 | L9: 0.0015
A10: SBC (negative) | C10: =-C6*C9 | D10: =-D6*D9 | E10: =-E6*E9 | F10: =-F6*F9 | G10: =-G6*G9 | H10: =-H6*H9 | I10: =-I6*I9 | J10: =-J6*J9 | ... L10: =-L6*L9
A11: Lease cash % of revenue | C11: =Assumptions!$B$3 | D11: =Assumptions!$B$3 | E11: =Assumptions!$B$3 | F11: =Assumptions!$B$3 | G11: =Assumptions!$B$3 | H11: =Assumptions!$B$3 | I11: =Assumptions!$B$3 | J11: =Assumptions!$B$3 | ... L11: =Assumptions!$B$3
A12: Lease cash (negative) | C12: =-C6*C11 | D12: =-D6*D11 | E12: =-E6*E11 | F12: =-F6*F11 | G12: =-G6*G11 | H12: =-H6*H11 | I12: =-I6*I11 | J12: =-J6*J11 | ... L12: =-L6*L11
A13: Owner EBITDA (post SBC, post lease) | C13: =C8+C10+C12 | D13: =D8+D10+D12 | E13: =E8+E10+E12 | F13: =F8+F10+F12 | G13: =G8+G10+G12 | H13: =H8+H10+H12 | I13: =I8+I10+I12 | J13: =J8+J10+J12 | ... L13: =L8+L10+L12
A14: D&A ex-ROU % of revenue | C14: =Assumptions!$B$4 | D14: =Assumptions!$B$4 | E14: =Assumptions!$B$4 | F14: =Assumptions!$B$4 | G14: =Assumptions!$B$4 | H14: =Assumptions!$B$4 | I14: =Assumptions!$B$4 | J14: =Assumptions!$B$4 | ... L14: =Assumptions!$B$4
A15: D&A (negative) | C15: =-C6*C14 | D15: =-D6*D14 | E15: =-E6*E14 | F15: =-F6*F14 | G15: =-G6*G14 | H15: =-H6*H14 | I15: =-I6*I14 | J15: =-J6*J14 | ... L15: =-L6*L14
A16: EBIT | C16: =C13+C15 | D16: =D13+D15 | E16: =E13+E15 | F16: =F13+F15 | G16: =G13+G15 | H16: =H13+H15 | I16: =I13+I15 | J16: =J13+J15 | ... L16: =L13+L15
A17: Cash tax rate | C17: 0.28 | D17: 0.29 | E17: 0.3 | F17: 0.3 | G17: 0.3 | H17: 0.3 | I17: 0.3 | J17: 0.3 | K17: 0.3 | L17: 0.3
A18: Cash tax (negative) | C18: =-MAX(0,C16)*C17 | D18: =-MAX(0,D16)*D17 | E18: =-MAX(0,E16)*E17 | F18: =-MAX(0,F16)*F17 | G18: =-MAX(0,G16)*G17 | H18: =-MAX(0,H16)*H17 | I18: =-MAX(0,I16)*I17 | J18: =-MAX(0,J16)*J17 | ... L18: =-MAX(0,L16)*L17
A19: NOPAT | C19: =C16+C18 | D19: =D16+D18 | E19: =E16+E18 | F19: =F16+F18 | G19: =G16+G18 | H19: =H16+H18 | I19: =I16+I18 | J19: =J16+J18 | ... L19: =L16+L18
A20: add back D&A | C20: =-C15 | D20: =-D15 | E20: =-E15 | F20: =-F15 | G20: =-G15 | H20: =-H15 | I20: =-I15 | J20: =-J15 | ... L20: =-L15
A21: Capex % of revenue | C21: 0.018 | D21: 0.017 | E21: 0.016 | F21: 0.015 | G21: 0.015 | H21: 0.015 | I21: 0.015 | J21: 0.015 | K21: 0.015 | L21: 0.015
A22: Capex (negative) | C22: =-C6*C21 | D22: =-D6*D21 | E22: =-E6*E21 | F22: =-F6*F21 | G22: =-G6*G21 | H22: =-H6*H21 | I22: =-I6*I21 | J22: =-J6*J21 | ... L22: =-L6*L21
A23: Working capital (capture x rev change) | C23: =Assumptions!$B$5*(C6-B6) | D23: =Assumptions!$B$5*(D6-C6) | E23: =Assumptions!$B$5*(E6-D6) | F23: =Assumptions!$B$5*(F6-E6) | G23: =Assumptions!$B$5*(G6-F6) | H23: =Assumptions!$B$5*(H6-G6) | I23: =Assumptions!$B$5*(I6-H6) | J23: =Assumptions!$B$5*(J6-I6) | ... L23: =Assumptions!$B$5*(L6-K6)
A24: Unlevered owner FCF | C24: =C19+C20+C22+C23 | D24: =D19+D20+D22+D23 | E24: =E19+E20+E22+E23 | F24: =F19+F20+F22+F23 | G24: =G19+G20+G22+G23 | H24: =H19+H20+H22+H23 | I24: =I19+I20+I22+I23 | J24: =J19+J20+J22+J23 | ... L24: =L19+L20+L22+L23
A25: Discount factor | C25: =1/(1+Assumptions!$B$2)^C4 | D25: =1/(1+Assumptions!$B$2)^D4 | E25: =1/(1+Assumptions!$B$2)^E4 | F25: =1/(1+Assumptions!$B$2)^F4 | G25: =1/(1+Assumptions!$B$2)^G4 | H25: =1/(1+Assumptions!$B$2)^H4 | I25: =1/(1+Assumptions!$B$2)^I4 | J25: =1/(1+Assumptions!$B$2)^J4 | ... L25: =1/(1+Assumptions!$B$2)^L4
A26: PV of FCF | C26: =C24*C25 | D26: =D24*D25 | E26: =E24*E25 | F26: =F24*F25 | G26: =G24*G25 | H26: =H24*H25 | I26: =I24*I25 | J26: =J24*J25 | ... L26: =L24*L25
A28: Memo: FCF before SBC (company-style) | C28: =C24-C10 | D28: =D24-D10 | E28: =E24-E10 | F28: =F24-F10 | G28: =G24-G10 | H28: =H24-H10 | I28: =I24-I10 | J28: =J24-J10 | ... L28: =L24-L10
A29: Memo: owner FCF margin | C29: =C24/C6 | D29: =D24/D6 | E29: =E24/E6 | F29: =F24/F6 | G29: =G24/G6 | H29: =H24/H6 | I29: =I24/I6 | J29: =J24/J6 | ... L29: =L24/L6
A31: Sum of PV of FCF (Y1-Y10) | B31: =SUM(C26:L26)
A32: Terminal growth | B32: =Assumptions!$B$16
A33: Terminal-year FCF x (1+g) | B33: =L24*(1+B32)
A34: Gordon TV | B34: =B33/(Assumptions!$B$2-B32)
A35: Cap TV (cap x FCF_10) | B35: =Assumptions!$B$10*L24
A36: TV used = MAX(0, MIN(Gordon, cap)) | B36: =MAX(0,MIN(B34,B35))
A37: Implied exit multiple (TV / FCF_10) | B37: =B36/L24
A38: PV of TV | B38: =B36*L25
A39: Enterprise value | B39: =B31+B38
A40: less net bank debt | B40: =-Assumptions!$B$6
A41: Equity value | B41: =B39+B40
A42: Diluted shares (m) | B42: =Assumptions!$B$7
A43: Value per share A$ | B43: =B41/B42
...

Sheet DCF_Base
A1: DCF_Base -- A$m unless stated; drivers in blue on rows 5, 7, 9, 17, 21
A3: Year | B3: 2025A | C3: 2026E | D3: 2027E | E3: 2028E | F3: 2029E | G3: 2030E | H3: 2031E | I3: 2032E | J3: 2033E | K3: 2034E | L3: 2035E
A4: Index | B4: 0 | C4: 1 | D4: 2 | E4: 3 | F4: 4 | G4: 5 | H4: 6 | I4: 7 | J4: 8 | K4: 9 | L4: 10
A5: Revenue growth YoY | C5: -0.015 | D5: 0.05 | E5: 0.045 | F5: 0.04 | G5: 0.04 | H5: 0.035 | I5: 0.035 | J5: 0.03 | K5: 0.03 | L5: 0.0275
A6: Revenue | B6: =Assumptions!$B$12 | C6: =B6*(1+C5) | D6: =C6*(1+D5) | E6: =D6*(1+E5) | F6: =E6*(1+F5) | G6: =F6*(1+G5) | H6: =G6*(1+H5) | I6: =H6*(1+I5) | J6: =I6*(1+J5) | ... L6: =K6*(1+L5)
A7: Adj (underlying) EBITDA margin | C7: 0.095 | D7: 0.096 | E7: 0.097 | F7: 0.0975 | G7: 0.098 | H7: 0.098 | I7: 0.098 | J7: 0.098 | K7: 0.098 | L7: 0.098
A8: Adjusted EBITDA | C8: =C6*C7 | D8: =D6*D7 | E8: =E6*E7 | F8: =F6*F7 | G8: =G6*G7 | H8: =H6*H7 | I8: =I6*I7 | J8: =J6*J7 | ... L8: =L6*L7
A9: SBC % of revenue | C9: 0.0015 | D9: 0.0015 | E9: 0.0015 | F9: 0.0015 | G9: 0.0015 | H9: 0.0015 | I9: 0.0015 | J9: 0.0015 | K9: 0.0015 | L9: 0.0015
A10: SBC (negative) | C10: =-C6*C9 | D10: =-D6*D9 | E10: =-E6*E9 | F10: =-F6*F9 | G10: =-G6*G9 | H10: =-H6*H9 | I10: =-I6*I9 | J10: =-J6*J9 | ... L10: =-L6*L9
A11: Lease cash % of revenue | C11: =Assumptions!$B$3 | D11: =Assumptions!$B$3 | E11: =Assumptions!$B$3 | F11: =Assumptions!$B$3 | G11: =Assumptions!$B$3 | H11: =Assumptions!$B$3 | I11: =Assumptions!$B$3 | J11: =Assumptions!$B$3 | ... L11: =Assumptions!$B$3
A12: Lease cash (negative) | C12: =-C6*C11 | D12: =-D6*D11 | E12: =-E6*E11 | F12: =-F6*F11 | G12: =-G6*G11 | H12: =-H6*H11 | I12: =-I6*I11 | J12: =-J6*J11 | ... L12: =-L6*L11
A13: Owner EBITDA (post SBC, post lease) | C13: =C8+C10+C12 | D13: =D8+D10+D12 | E13: =E8+E10+E12 | F13: =F8+F10+F12 | G13: =G8+G10+G12 | H13: =H8+H10+H12 | I13: =I8+I10+I12 | J13: =J8+J10+J12 | ... L13: =L8+L10+L12
A14: D&A ex-ROU % of revenue | C14: =Assumptions!$B$4 | D14: =Assumptions!$B$4 | E14: =Assumptions!$B$4 | F14: =Assumptions!$B$4 | G14: =Assumptions!$B$4 | H14: =Assumptions!$B$4 | I14: =Assumptions!$B$4 | J14: =Assumptions!$B$4 | ... L14: =Assumptions!$B$4
A15: D&A (negative) | C15: =-C6*C14 | D15: =-D6*D14 | E15: =-E6*E14 | F15: =-F6*F14 | G15: =-G6*G14 | H15: =-H6*H14 | I15: =-I6*I14 | J15: =-J6*J14 | ... L15: =-L6*L14
A16: EBIT | C16: =C13+C15 | D16: =D13+D15 | E16: =E13+E15 | F16: =F13+F15 | G16: =G13+G15 | H16: =H13+H15 | I16: =I13+I15 | J16: =J13+J15 | ... L16: =L13+L15
A17: Cash tax rate | C17: 0.28 | D17: 0.29 | E17: 0.3 | F17: 0.3 | G17: 0.3 | H17: 0.3 | I17: 0.3 | J17: 0.3 | K17: 0.3 | L17: 0.3
A18: Cash tax (negative) | C18: =-MAX(0,C16)*C17 | D18: =-MAX(0,D16)*D17 | E18: =-MAX(0,E16)*E17 | F18: =-MAX(0,F16)*F17 | G18: =-MAX(0,G16)*G17 | H18: =-MAX(0,H16)*H17 | I18: =-MAX(0,I16)*I17 | J18: =-MAX(0,J16)*J17 | ... L18: =-MAX(0,L16)*L17
A19: NOPAT | C19: =C16+C18 | D19: =D16+D18 | E19: =E16+E18 | F19: =F16+F18 | G19: =G16+G18 | H19: =H16+H18 | I19: =I16+I18 | J19: =J16+J18 | ... L19: =L16+L18
A20: add back D&A | C20: =-C15 | D20: =-D15 | E20: =-E15 | F20: =-F15 | G20: =-G15 | H20: =-H15 | I20: =-I15 | J20: =-J15 | ... L20: =-L15
A21: Capex % of revenue | C21: 0.017 | D21: 0.016 | E21: 0.015 | F21: 0.014 | G21: 0.013 | H21: 0.013 | I21: 0.013 | J21: 0.013 | K21: 0.013 | L21: 0.013
A22: Capex (negative) | C22: =-C6*C21 | D22: =-D6*D21 | E22: =-E6*E21 | F22: =-F6*F21 | G22: =-G6*G21 | H22: =-H6*H21 | I22: =-I6*I21 | J22: =-J6*J21 | ... L22: =-L6*L21
A23: Working capital (capture x rev change) | C23: =Assumptions!$B$5*(C6-B6) | D23: =Assumptions!$B$5*(D6-C6) | E23: =Assumptions!$B$5*(E6-D6) | F23: =Assumptions!$B$5*(F6-E6) | G23: =Assumptions!$B$5*(G6-F6) | H23: =Assumptions!$B$5*(H6-G6) | I23: =Assumptions!$B$5*(I6-H6) | J23: =Assumptions!$B$5*(J6-I6) | ... L23: =Assumptions!$B$5*(L6-K6)
A24: Unlevered owner FCF | C24: =C19+C20+C22+C23 | D24: =D19+D20+D22+D23 | E24: =E19+E20+E22+E23 | F24: =F19+F20+F22+F23 | G24: =G19+G20+G22+G23 | H24: =H19+H20+H22+H23 | I24: =I19+I20+I22+I23 | J24: =J19+J20+J22+J23 | ... L24: =L19+L20+L22+L23
A25: Discount factor | C25: =1/(1+Assumptions!$B$2)^C4 | D25: =1/(1+Assumptions!$B$2)^D4 | E25: =1/(1+Assumptions!$B$2)^E4 | F25: =1/(1+Assumptions!$B$2)^F4 | G25: =1/(1+Assumptions!$B$2)^G4 | H25: =1/(1+Assumptions!$B$2)^H4 | I25: =1/(1+Assumptions!$B$2)^I4 | J25: =1/(1+Assumptions!$B$2)^J4 | ... L25: =1/(1+Assumptions!$B$2)^L4
A26: PV of FCF | C26: =C24*C25 | D26: =D24*D25 | E26: =E24*E25 | F26: =F24*F25 | G26: =G24*G25 | H26: =H24*H25 | I26: =I24*I25 | J26: =J24*J25 | ... L26: =L24*L25
A28: Memo: FCF before SBC (company-style) | C28: =C24-C10 | D28: =D24-D10 | E28: =E24-E10 | F28: =F24-F10 | G28: =G24-G10 | H28: =H24-H10 | I28: =I24-I10 | J28: =J24-J10 | ... L28: =L24-L10
A29: Memo: owner FCF margin | C29: =C24/C6 | D29: =D24/D6 | E29: =E24/E6 | F29: =F24/F6 | G29: =G24/G6 | H29: =H24/H6 | I29: =I24/I6 | J29: =J24/J6 | ... L29: =L24/L6
A31: Sum of PV of FCF (Y1-Y10) | B31: =SUM(C26:L26)
A32: Terminal growth | B32: =Assumptions!$C$16
A33: Terminal-year FCF x (1+g) | B33: =L24*(1+B32)
A34: Gordon TV | B34: =B33/(Assumptions!$B$2-B32)
A35: Cap TV (cap x FCF_10) | B35: =Assumptions!$B$10*L24
A36: TV used = MAX(0, MIN(Gordon, cap)) | B36: =MAX(0,MIN(B34,B35))
A37: Implied exit multiple (TV / FCF_10) | B37: =B36/L24
A38: PV of TV | B38: =B36*L25
A39: Enterprise value | B39: =B31+B38
A40: less net bank debt | B40: =-Assumptions!$B$6
A41: Equity value | B41: =B39+B40
A42: Diluted shares (m) | B42: =Assumptions!$B$7
A43: Value per share A$ | B43: =B41/B42
...

Sheet DCF_Bull
A1: DCF_Bull -- A$m unless stated; drivers in blue on rows 5, 7, 9, 17, 21
A3: Year | B3: 2025A | C3: 2026E | D3: 2027E | E3: 2028E | F3: 2029E | G3: 2030E | H3: 2031E | I3: 2032E | J3: 2033E | K3: 2034E | L3: 2035E
A4: Index | B4: 0 | C4: 1 | D4: 2 | E4: 3 | F4: 4 | G4: 5 | H4: 6 | I4: 7 | J4: 8 | K4: 9 | L4: 10
A5: Revenue growth YoY | C5: 0 | D5: 0.065 | E5: 0.06 | F5: 0.055 | G5: 0.05 | H5: 0.045 | I5: 0.04 | J5: 0.04 | K5: 0.035 | L5: 0.035
A6: Revenue | B6: =Assumptions!$B$12 | C6: =B6*(1+C5) | D6: =C6*(1+D5) | E6: =D6*(1+E5) | F6: =E6*(1+F5) | G6: =F6*(1+G5) | H6: =G6*(1+H5) | I6: =H6*(1+I5) | J6: =I6*(1+J5) | ... L6: =K6*(1+L5)
A7: Adj (underlying) EBITDA margin | C7: 0.096 | D7: 0.099 | E7: 0.101 | F7: 0.103 | G7: 0.105 | H7: 0.106 | I7: 0.106 | J7: 0.106 | K7: 0.106 | L7: 0.106
A8: Adjusted EBITDA | C8: =C6*C7 | D8: =D6*D7 | E8: =E6*E7 | F8: =F6*F7 | G8: =G6*G7 | H8: =H6*H7 | I8: =I6*I7 | J8: =J6*J7 | ... L8: =L6*L7
A9: SBC % of revenue | C9: 0.0015 | D9: 0.0015 | E9: 0.0015 | F9: 0.0015 | G9: 0.0015 | H9: 0.0015 | I9: 0.0015 | J9: 0.0015 | K9: 0.0015 | L9: 0.0015
A10: SBC (negative) | C10: =-C6*C9 | D10: =-D6*D9 | E10: =-E6*E9 | F10: =-F6*F9 | G10: =-G6*G9 | H10: =-H6*H9 | I10: =-I6*I9 | J10: =-J6*J9 | ... L10: =-L6*L9
A11: Lease cash % of revenue | C11: =Assumptions!$B$3 | D11: =Assumptions!$B$3 | E11: =Assumptions!$B$3 | F11: =Assumptions!$B$3 | G11: =Assumptions!$B$3 | H11: =Assumptions!$B$3 | I11: =Assumptions!$B$3 | J11: =Assumptions!$B$3 | ... L11: =Assumptions!$B$3
A12: Lease cash (negative) | C12: =-C6*C11 | D12: =-D6*D11 | E12: =-E6*E11 | F12: =-F6*F11 | G12: =-G6*G11 | H12: =-H6*H11 | I12: =-I6*I11 | J12: =-J6*J11 | ... L12: =-L6*L11
A13: Owner EBITDA (post SBC, post lease) | C13: =C8+C10+C12 | D13: =D8+D10+D12 | E13: =E8+E10+E12 | F13: =F8+F10+F12 | G13: =G8+G10+G12 | H13: =H8+H10+H12 | I13: =I8+I10+I12 | J13: =J8+J10+J12 | ... L13: =L8+L10+L12
A14: D&A ex-ROU % of revenue | C14: =Assumptions!$B$4 | D14: =Assumptions!$B$4 | E14: =Assumptions!$B$4 | F14: =Assumptions!$B$4 | G14: =Assumptions!$B$4 | H14: =Assumptions!$B$4 | I14: =Assumptions!$B$4 | J14: =Assumptions!$B$4 | ... L14: =Assumptions!$B$4
A15: D&A (negative) | C15: =-C6*C14 | D15: =-D6*D14 | E15: =-E6*E14 | F15: =-F6*F14 | G15: =-G6*G14 | H15: =-H6*H14 | I15: =-I6*I14 | J15: =-J6*J14 | ... L15: =-L6*L14
A16: EBIT | C16: =C13+C15 | D16: =D13+D15 | E16: =E13+E15 | F16: =F13+F15 | G16: =G13+G15 | H16: =H13+H15 | I16: =I13+I15 | J16: =J13+J15 | ... L16: =L13+L15
A17: Cash tax rate | C17: 0.28 | D17: 0.29 | E17: 0.3 | F17: 0.3 | G17: 0.3 | H17: 0.3 | I17: 0.3 | J17: 0.3 | K17: 0.3 | L17: 0.3
A18: Cash tax (negative) | C18: =-MAX(0,C16)*C17 | D18: =-MAX(0,D16)*D17 | E18: =-MAX(0,E16)*E17 | F18: =-MAX(0,F16)*F17 | G18: =-MAX(0,G16)*G17 | H18: =-MAX(0,H16)*H17 | I18: =-MAX(0,I16)*I17 | J18: =-MAX(0,J16)*J17 | ... L18: =-MAX(0,L16)*L17
A19: NOPAT | C19: =C16+C18 | D19: =D16+D18 | E19: =E16+E18 | F19: =F16+F18 | G19: =G16+G18 | H19: =H16+H18 | I19: =I16+I18 | J19: =J16+J18 | ... L19: =L16+L18
A20: add back D&A | C20: =-C15 | D20: =-D15 | E20: =-E15 | F20: =-F15 | G20: =-G15 | H20: =-H15 | I20: =-I15 | J20: =-J15 | ... L20: =-L15
A21: Capex % of revenue | C21: 0.017 | D21: 0.015 | E21: 0.014 | F21: 0.013 | G21: 0.012 | H21: 0.012 | I21: 0.012 | J21: 0.012 | K21: 0.012 | L21: 0.012
A22: Capex (negative) | C22: =-C6*C21 | D22: =-D6*D21 | E22: =-E6*E21 | F22: =-F6*F21 | G22: =-G6*G21 | H22: =-H6*H21 | I22: =-I6*I21 | J22: =-J6*J21 | ... L22: =-L6*L21
A23: Working capital (capture x rev change) | C23: =Assumptions!$B$5*(C6-B6) | D23: =Assumptions!$B$5*(D6-C6) | E23: =Assumptions!$B$5*(E6-D6) | F23: =Assumptions!$B$5*(F6-E6) | G23: =Assumptions!$B$5*(G6-F6) | H23: =Assumptions!$B$5*(H6-G6) | I23: =Assumptions!$B$5*(I6-H6) | J23: =Assumptions!$B$5*(J6-I6) | ... L23: =Assumptions!$B$5*(L6-K6)
A24: Unlevered owner FCF | C24: =C19+C20+C22+C23 | D24: =D19+D20+D22+D23 | E24: =E19+E20+E22+E23 | F24: =F19+F20+F22+F23 | G24: =G19+G20+G22+G23 | H24: =H19+H20+H22+H23 | I24: =I19+I20+I22+I23 | J24: =J19+J20+J22+J23 | ... L24: =L19+L20+L22+L23
A25: Discount factor | C25: =1/(1+Assumptions!$B$2)^C4 | D25: =1/(1+Assumptions!$B$2)^D4 | E25: =1/(1+Assumptions!$B$2)^E4 | F25: =1/(1+Assumptions!$B$2)^F4 | G25: =1/(1+Assumptions!$B$2)^G4 | H25: =1/(1+Assumptions!$B$2)^H4 | I25: =1/(1+Assumptions!$B$2)^I4 | J25: =1/(1+Assumptions!$B$2)^J4 | ... L25: =1/(1+Assumptions!$B$2)^L4
A26: PV of FCF | C26: =C24*C25 | D26: =D24*D25 | E26: =E24*E25 | F26: =F24*F25 | G26: =G24*G25 | H26: =H24*H25 | I26: =I24*I25 | J26: =J24*J25 | ... L26: =L24*L25
A28: Memo: FCF before SBC (company-style) | C28: =C24-C10 | D28: =D24-D10 | E28: =E24-E10 | F28: =F24-F10 | G28: =G24-G10 | H28: =H24-H10 | I28: =I24-I10 | J28: =J24-J10 | ... L28: =L24-L10
A29: Memo: owner FCF margin | C29: =C24/C6 | D29: =D24/D6 | E29: =E24/E6 | F29: =F24/F6 | G29: =G24/G6 | H29: =H24/H6 | I29: =I24/I6 | J29: =J24/J6 | ... L29: =L24/L6
A31: Sum of PV of FCF (Y1-Y10) | B31: =SUM(C26:L26)
A32: Terminal growth | B32: =Assumptions!$D$16
A33: Terminal-year FCF x (1+g) | B33: =L24*(1+B32)
A34: Gordon TV | B34: =B33/(Assumptions!$B$2-B32)
A35: Cap TV (cap x FCF_10) | B35: =Assumptions!$B$10*L24
A36: TV used = MAX(0, MIN(Gordon, cap)) | B36: =MAX(0,MIN(B34,B35))
A37: Implied exit multiple (TV / FCF_10) | B37: =B36/L24
A38: PV of TV | B38: =B36*L25
A39: Enterprise value | B39: =B31+B38
A40: less net bank debt | B40: =-Assumptions!$B$6
A41: Equity value | B41: =B39+B40
A42: Diluted shares (m) | B42: =Assumptions!$B$7
A43: Value per share A$ | B43: =B41/B42
...

Sheet FCF_Quality
A1: Reported FCF reconciled to owner FCF (A$m), levered basis
B2: FY2020 | C2: FY2021 | D2: FY2022 | E2: FY2023 | F2: FY2024 | G2: FY2025
A3: Revenue | B3: 3223.9 | C3: 4557.4 | D3: 5167.5 | E3: 5676.4 | F3: 6105.5 | G3: 6141.1
A4: Free cash flow (company definition: OCF - capex) | B4: 53.3 | C4: 88.3 | D4: 251.5 | E4: 255 | F4: 287.2 | G4: 268.8
A5: less: IFRS-16 lease principal | B5: -52.9 | C5: -63.8 | D5: -64.4 | E5: -62.2 | F5: -59 | G5: -61.6
A6: less: SBC | B6: 0 | C6: -3.1 | D6: -7.6 | E6: -4.4 | F6: -5.2 | G6: -5.9
A7: less: interest income | B7: 0 | C7: 0 | D7: 0 | E7: 0 | F7: 0 | G7: 0
A8: Owner FCF (levered) = sum of the four lines above | B8: =SUM(B4:B7) | C8: =SUM(C4:C7) | D8: =SUM(D4:D7) | E8: =SUM(E4:E7) | F8: =SUM(F4:F7) | G8: =SUM(G4:G7)
A9: Reported FCF margin | B9: =B4/B3 | C9: =C4/C3 | D9: =D4/D3 | E9: =E4/E3 | F9: =F4/F3 | G9: =G4/G3
A10: Owner FCF margin | B10: =B8/B3 | C10: =C8/C3 | D10: =D8/D3 | E10: =E8/E3 | F10: =F8/F3 | G10: =G8/G3
A11: Memo: cash tax paid | C11: 35.3 | D11: 25.7 | E11: 58.2 | F11: 59 | G11: 73.8
A12: Memo: cash tax / underlying PBT (FY2025 20.3% is below the 30% statutory rate -- timing) | C12: =C11/-19.8 | D12: =D11/221.3 | E12: =E11/270.1 | F12: =F11/313.0 | G12: =G11/363.4
A13: Memo: lease interest paid (inside OCF already) | C13: 8.2 | D13: 7.1 | E13: 6.7 | F13: 7.1 | G13: 9.4
A15: Interest income (A$10.5m FY2025) is not stripped: net borrower, cash netted in the bridge. Deferred revenue (contract liabilities) fell 413 -> 339 in FY2025 (a ~A$74m OCF headwind) and rose to 388 at H1 FY2026: working-capital timing, not earnings.

Sheet Valuation
A1: Valuation summary (NZ$ per share unless stated; AUD twins alongside)
A3: Scenario | B3: Value/share A$ | C3: Value/share NZ$ | D3: Upside vs price | E3: Probability | F3: Street NZ$
A4: Bear | B4: =DCF_Bear!$B$43 | C4: =DCF_Bear!$B$44 | D4: =C4/Assumptions!$B$8-1 | E4: =Assumptions!$B$17 | F4: =DCF_Bear!$B$50
A5: Base | B5: =DCF_Base!$B$43 | C5: =DCF_Base!$B$44 | D5: =C5/Assumptions!$B$8-1 | E5: =Assumptions!$C$17 | F5: =DCF_Base!$B$50
A6: Bull | B6: =DCF_Bull!$B$43 | C6: =DCF_Bull!$B$44 | D6: =C6/Assumptions!$B$8-1 | E6: =Assumptions!$D$17 | F6: =DCF_Bull!$B$50
A8: Probability-weighted value A$ | B8: =SUMPRODUCT(B4:B6,E4:E6)
A9: Probability-weighted value NZ$ | B9: =SUMPRODUCT(C4:C6,E4:E6)
A10: Street weighted value NZ$ | B10: =SUMPRODUCT(F4:F6,E4:E6)
A11: Current price NZ$ | B11: =Assumptions!$B$8
A12: Margin of safety (1 - price/weighted) | B12: =1-B11/B9
A13: Band position (price - house)/(street - house); n/a-ish: SBC ~0.15% of revenue | B13: =IF(ABS(B10-B9)<0.001,"n/a",(B11-B9)/(B10-B9))
A15: 15% hurdle entry price (TV rebuilt at the hurdle)
A16: Scenario | B16: Entry A$ | C16: Entry NZ$ | D16: Discount vs price | E16: Street entry NZ$
A17: Bear | B17: =(SUMPRODUCT(DCF_Bear!$C$24:$L$24/(1+Assumptions!$B$11)^DCF_Bear!$C$4:$L$4)+MAX(0,MIN(DCF_Bear!$L$24*(1+Assumptions!$B$16)/(Assumptions!$B$11-Assumptions!$B$16),Assumptions!$B$10*DCF_Bear!$L$24))/(1+Assumptions!$B$11)^10-Assumptions!$B$6)/Assumptions!$B$7 | C17: =(SUMPRODUCT(DCF_Bear!$C$24:$L$24/(1+Assumptions!$B$11)^DCF_Bear!$C$4:$L$4)+MAX(0,MIN(DCF_Bear!$L$24*(1+Assumptions!$B$16)/(Assumptions!$B$11-Assumptions!$B$16),Assumptions!$B$10*DCF_Bear!$L$24))/(1+Assumptions!$B$11)^10-Assumptions!$B$6)/Assumptions!$B$7*Assumptions!$B$9 | D17: =C17/Assumptions!$B$8-1 | E17: =(SUMPRODUCT(DCF_Bear!$C$24:$L$24/(1+Assumptions!$B$11)^DCF_Bear!$C$4:$L$4)+MAX(0,MIN(DCF_Bear!$L$24*(1+Assumptions!$B$16)/(Assumptions!$B$11-Assumptions!$B$16),Assumptions!$B$10*DCF_Bear!$L$24))/(1+Assumptions!$B$11)^10-Assumptions!$B$6+SUMPRODUCT(-DCF_Bear!$C$10:$L$10/(1+Assumptions!$B$11)^DCF_Bear!$C$4:$L$4)+(-DCF_Bear!$L$10*(1+Assumptions!$B$16)/(Assumptions!$B$11-Assumptions!$B$16))/(1+Assumptions!$B$11)^10)/Assumptions!$B$7*Assumptions!$B$9
A18: Base | B18: =(SUMPRODUCT(DCF_Base!$C$24:$L$24/(1+Assumptions!$B$11)^DCF_Base!$C$4:$L$4)+MAX(0,MIN(DCF_Base!$L$24*(1+Assumptions!$C$16)/(Assumptions!$B$11-Assumptions!$C$16),Assumptions!$B$10*DCF_Base!$L$24))/(1+Assumptions!$B$11)^10-Assumptions!$B$6)/Assumptions!$B$7 | C18: =(SUMPRODUCT(DCF_Base!$C$24:$L$24/(1+Assumptions!$B$11)^DCF_Base!$C$4:$L$4)+MAX(0,MIN(DCF_Base!$L$24*(1+Assumptions!$C$16)/(Assumptions!$B$11-Assumptions!$C$16),Assumptions!$B$10*DCF_Base!$L$24))/(1+Assumptions!$B$11)^10-Assumptions!$B$6)/Assumptions!$B$7*Assumptions!$B$9 | D18: =C18/Assumptions!$B$8-1 | E18: =(SUMPRODUCT(DCF_Base!$C$24:$L$24/(1+Assumptions!$B$11)^DCF_Base!$C$4:$L$4)+MAX(0,MIN(DCF_Base!$L$24*(1+Assumptions!$C$16)/(Assumptions!$B$11-Assumptions!$C$16),Assumptions!$B$10*DCF_Base!$L$24))/(1+Assumptions!$B$11)^10-Assumptions!$B$6+SUMPRODUCT(-DCF_Base!$C$10:$L$10/(1+Assumptions!$B$11)^DCF_Base!$C$4:$L$4)+(-DCF_Base!$L$10*(1+Assumptions!$C$16)/(Assumptions!$B$11-Assumptions!$C$16))/(1+Assumptions!$B$11)^10)/Assumptions!$B$7*Assumptions!$B$9
A19: Bull | B19: =(SUMPRODUCT(DCF_Bull!$C$24:$L$24/(1+Assumptions!$B$11)^DCF_Bull!$C$4:$L$4)+MAX(0,MIN(DCF_Bull!$L$24*(1+Assumptions!$D$16)/(Assumptions!$B$11-Assumptions!$D$16),Assumptions!$B$10*DCF_Bull!$L$24))/(1+Assumptions!$B$11)^10-Assumptions!$B$6)/Assumptions!$B$7 | C19: =(SUMPRODUCT(DCF_Bull!$C$24:$L$24/(1+Assumptions!$B$11)^DCF_Bull!$C$4:$L$4)+MAX(0,MIN(DCF_Bull!$L$24*(1+Assumptions!$D$16)/(Assumptions!$B$11-Assumptions!$D$16),Assumptions!$B$10*DCF_Bull!$L$24))/(1+Assumptions!$B$11)^10-Assumptions!$B$6)/Assumptions!$B$7*Assumptions!$B$9 | D19: =C19/Assumptions!$B$8-1 | E19: =(SUMPRODUCT(DCF_Bull!$C$24:$L$24/(1+Assumptions!$B$11)^DCF_Bull!$C$4:$L$4)+MAX(0,MIN(DCF_Bull!$L$24*(1+Assumptions!$D$16)/(Assumptions!$B$11-Assumptions!$D$16),Assumptions!$B$10*DCF_Bull!$L$24))/(1+Assumptions!$B$11)^10-Assumptions!$B$6+SUMPRODUCT(-DCF_Bull!$C$10:$L$10/(1+Assumptions!$B$11)^DCF_Bull!$C$4:$L$4)+(-DCF_Bull!$L$10*(1+Assumptions!$D$16)/(Assumptions!$B$11-Assumptions!$D$16))/(1+Assumptions!$B$11)^10)/Assumptions!$B$7*Assumptions!$B$9
A20: Probability-weighted entry price NZ$ (buy-below) | B20: =SUMPRODUCT(B17:B19,E4:E6) | C20: =SUMPRODUCT(C17:C19,E4:E6)
A22: Required-return table (base case), TV rebuilt at each rate
A23: Required return | B23: Value/share A$ | C23: Value/share NZ$
A24: ="WACC "&TEXT(Assumptions!$B$2,"0.0%") | B24: =(SUMPRODUCT(DCF_Base!$C$24:$L$24/(1+Assumptions!$B$2)^DCF_Base!$C$4:$L$4)+MAX(0,MIN(DCF_Base!$L$24*(1+Assumptions!$C$16)/(Assumptions!$B$2-Assumptions!$C$16),Assumptions!$B$10*DCF_Base!$L$24))/(1+Assumptions!$B$2)^10-Assumptions!$B$6)/Assumptions!$B$7 | C24: =(SUMPRODUCT(DCF_Base!$C$24:$L$24/(1+Assumptions!$B$2)^DCF_Base!$C$4:$L$4)+MAX(0,MIN(DCF_Base!$L$24*(1+Assumptions!$C$16)/(Assumptions!$B$2-Assumptions!$C$16),Assumptions!$B$10*DCF_Base!$L$24))/(1+Assumptions!$B$2)^10-Assumptions!$B$6)/Assumptions!$B$7*Assumptions!$B$9
A25: 9% | B25: =(SUMPRODUCT(DCF_Base!$C$24:$L$24/(1+0.09)^DCF_Base!$C$4:$L$4)+MAX(0,MIN(DCF_Base!$L$24*(1+Assumptions!$C$16)/(0.09-Assumptions!$C$16),Assumptions!$B$10*DCF_Base!$L$24))/(1+0.09)^10-Assumptions!$B$6)/Assumptions!$B$7 | C25: =(SUMPRODUCT(DCF_Base!$C$24:$L$24/(1+0.09)^DCF_Base!$C$4:$L$4)+MAX(0,MIN(DCF_Base!$L$24*(1+Assumptions!$C$16)/(0.09-Assumptions!$C$16),Assumptions!$B$10*DCF_Base!$L$24))/(1+0.09)^10-Assumptions!$B$6)/Assumptions!$B$7*Assumptions!$B$9
A26: 10% | B26: =(SUMPRODUCT(DCF_Base!$C$24:$L$24/(1+0.1)^DCF_Base!$C$4:$L$4)+MAX(0,MIN(DCF_Base!$L$24*(1+Assumptions!$C$16)/(0.1-Assumptions!$C$16),Assumptions!$B$10*DCF_Base!$L$24))/(1+0.1)^10-Assumptions!$B$6)/Assumptions!$B$7 | C26: =(SUMPRODUCT(DCF_Base!$C$24:$L$24/(1+0.1)^DCF_Base!$C$4:$L$4)+MAX(0,MIN(DCF_Base!$L$24*(1+Assumptions!$C$16)/(0.1-Assumptions!$C$16),Assumptions!$B$10*DCF_Base!$L$24))/(1+0.1)^10-Assumptions!$B$6)/Assumptions!$B$7*Assumptions!$B$9
A27: 11% | B27: =(SUMPRODUCT(DCF_Base!$C$24:$L$24/(1+0.11)^DCF_Base!$C$4:$L$4)+MAX(0,MIN(DCF_Base!$L$24*(1+Assumptions!$C$16)/(0.11-Assumptions!$C$16),Assumptions!$B$10*DCF_Base!$L$24))/(1+0.11)^10-Assumptions!$B$6)/Assumptions!$B$7 | C27: =(SUMPRODUCT(DCF_Base!$C$24:$L$24/(1+0.11)^DCF_Base!$C$4:$L$4)+MAX(0,MIN(DCF_Base!$L$24*(1+Assumptions!$C$16)/(0.11-Assumptions!$C$16),Assumptions!$B$10*DCF_Base!$L$24))/(1+0.11)^10-Assumptions!$B$6)/Assumptions!$B$7*Assumptions!$B$9
A28: 12% | B28: =(SUMPRODUCT(DCF_Base!$C$24:$L$24/(1+0.12)^DCF_Base!$C$4:$L$4)+MAX(0,MIN(DCF_Base!$L$24*(1+Assumptions!$C$16)/(0.12-Assumptions!$C$16),Assumptions!$B$10*DCF_Base!$L$24))/(1+0.12)^10-Assumptions!$B$6)/Assumptions!$B$7 | C28: =(SUMPRODUCT(DCF_Base!$C$24:$L$24/(1+0.12)^DCF_Base!$C$4:$L$4)+MAX(0,MIN(DCF_Base!$L$24*(1+Assumptions!$C$16)/(0.12-Assumptions!$C$16),Assumptions!$B$10*DCF_Base!$L$24))/(1+0.12)^10-Assumptions!$B$6)/Assumptions!$B$7*Assumptions!$B$9
A29: 15% | B29: =(SUMPRODUCT(DCF_Base!$C$24:$L$24/(1+0.15)^DCF_Base!$C$4:$L$4)+MAX(0,MIN(DCF_Base!$L$24*(1+Assumptions!$C$16)/(0.15-Assumptions!$C$16),Assumptions!$B$10*DCF_Base!$L$24))/(1+0.15)^10-Assumptions!$B$6)/Assumptions!$B$7 | C29: =(SUMPRODUCT(DCF_Base!$C$24:$L$24/(1+0.15)^DCF_Base!$C$4:$L$4)+MAX(0,MIN(DCF_Base!$L$24*(1+Assumptions!$C$16)/(0.15-Assumptions!$C$16),Assumptions!$B$10*DCF_Base!$L$24))/(1+0.15)^10-Assumptions!$B$6)/Assumptions!$B$7*Assumptions!$B$9
A30: Check: WACC row = DCF_Base!B44; 15% row = base entry price (C17).
A32: Sensitivity (base, NZ$/share): rows WACC, columns terminal growth
A33: WACC \ g | B33: 0.015 | C33: 0.02 | D33: 0.025 | E33: 0.03 | F33: 0.035
A34: 0.065 | B34: =IF($A34>B$33,(SUMPRODUCT(DCF_Base!$C$24:$L$24/(1+$A34)^DCF_Base!$C$4:$L$4)+MAX(0,MIN(DCF_Base!$L$24*(1+B$33)/($A34-B$33),Assumptions!$B$10*DCF_Base!$L$24))/(1+$A34)^10-Assumptions!$B$6)/Assumptions!$B$7*Assumptions!$B$9,"n/a") | C34: =IF($A34>C$33,(SUMPRODUCT(DCF_Base!$C$24:$L$24/(1+$A34)^DCF_Base!$C$4:$L$4)+MAX(0,MIN(DCF_Base!$L$24*(1+C$33)/($A34-C$33),Assumptions!$B$10*DCF_Base!$L$24))/(1+$A34)^10-Assumptions!$B$6)/Assumptions!$B$7*Assumptions!$B$9,"n/a") | D34: =IF($A34>D$33,(SUMPRODUCT(DCF_Base!$C$24:$L$24/(1+$A34)^DCF_Base!$C$4:$L$4)+MAX(0,MIN(DCF_Base!$L$24*(1+D$33)/($A34-D$33),Assumptions!$B$10*DCF_Base!$L$24))/(1+$A34)^10-Assumptions!$B$6)/Assumptions!$B$7*Assumptions!$B$9,"n/a") | E34: =IF($A34>E$33,(SUMPRODUCT(DCF_Base!$C$24:$L$24/(1+$A34)^DCF_Base!$C$4:$L$4)+MAX(0,MIN(DCF_Base!$L$24*(1+E$33)/($A34-E$33),Assumptions!$B$10*DCF_Base!$L$24))/(1+$A34)^10-Assumptions!$B$6)/Assumptions!$B$7*Assumptions!$B$9,"n/a") | F34: =IF($A34>F$33,(SUMPRODUCT(DCF_Base!$C$24:$L$24/(1+$A34)^DCF_Base!$C$4:$L$4)+MAX(0,MIN(DCF_Base!$L$24*(1+F$33)/($A34-F$33),Assumptions!$B$10*DCF_Base!$L$24))/(1+$A34)^10-Assumptions!$B$6)/Assumptions!$B$7*Assumptions!$B$9,"n/a")
A35: 0.075 | B35: =IF($A35>B$33,(SUMPRODUCT(DCF_Base!$C$24:$L$24/(1+$A35)^DCF_Base!$C$4:$L$4)+MAX(0,MIN(DCF_Base!$L$24*(1+B$33)/($A35-B$33),Assumptions!$B$10*DCF_Base!$L$24))/(1+$A35)^10-Assumptions!$B$6)/Assumptions!$B$7*Assumptions!$B$9,"n/a") | C35: =IF($A35>C$33,(SUMPRODUCT(DCF_Base!$C$24:$L$24/(1+$A35)^DCF_Base!$C$4:$L$4)+MAX(0,MIN(DCF_Base!$L$24*(1+C$33)/($A35-C$33),Assumptions!$B$10*DCF_Base!$L$24))/(1+$A35)^10-Assumptions!$B$6)/Assumptions!$B$7*Assumptions!$B$9,"n/a") | D35: =IF($A35>D$33,(SUMPRODUCT(DCF_Base!$C$24:$L$24/(1+$A35)^DCF_Base!$C$4:$L$4)+MAX(0,MIN(DCF_Base!$L$24*(1+D$33)/($A35-D$33),Assumptions!$B$10*DCF_Base!$L$24))/(1+$A35)^10-Assumptions!$B$6)/Assumptions!$B$7*Assumptions!$B$9,"n/a") | E35: =IF($A35>E$33,(SUMPRODUCT(DCF_Base!$C$24:$L$24/(1+$A35)^DCF_Base!$C$4:$L$4)+MAX(0,MIN(DCF_Base!$L$24*(1+E$33)/($A35-E$33),Assumptions!$B$10*DCF_Base!$L$24))/(1+$A35)^10-Assumptions!$B$6)/Assumptions!$B$7*Assumptions!$B$9,"n/a") | F35: =IF($A35>F$33,(SUMPRODUCT(DCF_Base!$C$24:$L$24/(1+$A35)^DCF_Base!$C$4:$L$4)+MAX(0,MIN(DCF_Base!$L$24*(1+F$33)/($A35-F$33),Assumptions!$B$10*DCF_Base!$L$24))/(1+$A35)^10-Assumptions!$B$6)/Assumptions!$B$7*Assumptions!$B$9,"n/a")
A36: 0.085 | B36: =IF($A36>B$33,(SUMPRODUCT(DCF_Base!$C$24:$L$24/(1+$A36)^DCF_Base!$C$4:$L$4)+MAX(0,MIN(DCF_Base!$L$24*(1+B$33)/($A36-B$33),Assumptions!$B$10*DCF_Base!$L$24))/(1+$A36)^10-Assumptions!$B$6)/Assumptions!$B$7*Assumptions!$B$9,"n/a") | C36: =IF($A36>C$33,(SUMPRODUCT(DCF_Base!$C$24:$L$24/(1+$A36)^DCF_Base!$C$4:$L$4)+MAX(0,MIN(DCF_Base!$L$24*(1+C$33)/($A36-C$33),Assumptions!$B$10*DCF_Base!$L$24))/(1+$A36)^10-Assumptions!$B$6)/Assumptions!$B$7*Assumptions!$B$9,"n/a") | D36: =IF($A36>D$33,(SUMPRODUCT(DCF_Base!$C$24:$L$24/(1+$A36)^DCF_Base!$C$4:$L$4)+MAX(0,MIN(DCF_Base!$L$24*(1+D$33)/($A36-D$33),Assumptions!$B$10*DCF_Base!$L$24))/(1+$A36)^10-Assumptions!$B$6)/Assumptions!$B$7*Assumptions!$B$9,"n/a") | E36: =IF($A36>E$33,(SUMPRODUCT(DCF_Base!$C$24:$L$24/(1+$A36)^DCF_Base!$C$4:$L$4)+MAX(0,MIN(DCF_Base!$L$24*(1+E$33)/($A36-E$33),Assumptions!$B$10*DCF_Base!$L$24))/(1+$A36)^10-Assumptions!$B$6)/Assumptions!$B$7*Assumptions!$B$9,"n/a") | F36: =IF($A36>F$33,(SUMPRODUCT(DCF_Base!$C$24:$L$24/(1+$A36)^DCF_Base!$C$4:$L$4)+MAX(0,MIN(DCF_Base!$L$24*(1+F$33)/($A36-F$33),Assumptions!$B$10*DCF_Base!$L$24))/(1+$A36)^10-Assumptions!$B$6)/Assumptions!$B$7*Assumptions!$B$9,"n/a")
A37: 0.095 | B37: =IF($A37>B$33,(SUMPRODUCT(DCF_Base!$C$24:$L$24/(1+$A37)^DCF_Base!$C$4:$L$4)+MAX(0,MIN(DCF_Base!$L$24*(1+B$33)/($A37-B$33),Assumptions!$B$10*DCF_Base!$L$24))/(1+$A37)^10-Assumptions!$B$6)/Assumptions!$B$7*Assumptions!$B$9,"n/a") | C37: =IF($A37>C$33,(SUMPRODUCT(DCF_Base!$C$24:$L$24/(1+$A37)^DCF_Base!$C$4:$L$4)+MAX(0,MIN(DCF_Base!$L$24*(1+C$33)/($A37-C$33),Assumptions!$B$10*DCF_Base!$L$24))/(1+$A37)^10-Assumptions!$B$6)/Assumptions!$B$7*Assumptions!$B$9,"n/a") | D37: =IF($A37>D$33,(SUMPRODUCT(DCF_Base!$C$24:$L$24/(1+$A37)^DCF_Base!$C$4:$L$4)+MAX(0,MIN(DCF_Base!$L$24*(1+D$33)/($A37-D$33),Assumptions!$B$10*DCF_Base!$L$24))/(1+$A37)^10-Assumptions!$B$6)/Assumptions!$B$7*Assumptions!$B$9,"n/a") | E37: =IF($A37>E$33,(SUMPRODUCT(DCF_Base!$C$24:$L$24/(1+$A37)^DCF_Base!$C$4:$L$4)+MAX(0,MIN(DCF_Base!$L$24*(1+E$33)/($A37-E$33),Assumptions!$B$10*DCF_Base!$L$24))/(1+$A37)^10-Assumptions!$B$6)/Assumptions!$B$7*Assumptions!$B$9,"n/a") | F37: =IF($A37>F$33,(SUMPRODUCT(DCF_Base!$C$24:$L$24/(1+$A37)^DCF_Base!$C$4:$L$4)+MAX(0,MIN(DCF_Base!$L$24*(1+F$33)/($A37-F$33),Assumptions!$B$10*DCF_Base!$L$24))/(1+$A37)^10-Assumptions!$B$6)/Assumptions!$B$7*Assumptions!$B$9,"n/a")
A38: 0.105 | B38: =IF($A38>B$33,(SUMPRODUCT(DCF_Base!$C$24:$L$24/(1+$A38)^DCF_Base!$C$4:$L$4)+MAX(0,MIN(DCF_Base!$L$24*(1+B$33)/($A38-B$33),Assumptions!$B$10*DCF_Base!$L$24))/(1+$A38)^10-Assumptions!$B$6)/Assumptions!$B$7*Assumptions!$B$9,"n/a") | C38: =IF($A38>C$33,(SUMPRODUCT(DCF_Base!$C$24:$L$24/(1+$A38)^DCF_Base!$C$4:$L$4)+MAX(0,MIN(DCF_Base!$L$24*(1+C$33)/($A38-C$33),Assumptions!$B$10*DCF_Base!$L$24))/(1+$A38)^10-Assumptions!$B$6)/Assumptions!$B$7*Assumptions!$B$9,"n/a") | D38: =IF($A38>D$33,(SUMPRODUCT(DCF_Base!$C$24:$L$24/(1+$A38)^DCF_Base!$C$4:$L$4)+MAX(0,MIN(DCF_Base!$L$24*(1+D$33)/($A38-D$33),Assumptions!$B$10*DCF_Base!$L$24))/(1+$A38)^10-Assumptions!$B$6)/Assumptions!$B$7*Assumptions!$B$9,"n/a") | E38: =IF($A38>E$33,(SUMPRODUCT(DCF_Base!$C$24:$L$24/(1+$A38)^DCF_Base!$C$4:$L$4)+MAX(0,MIN(DCF_Base!$L$24*(1+E$33)/($A38-E$33),Assumptions!$B$10*DCF_Base!$L$24))/(1+$A38)^10-Assumptions!$B$6)/Assumptions!$B$7*Assumptions!$B$9,"n/a") | F38: =IF($A38>F$33,(SUMPRODUCT(DCF_Base!$C$24:$L$24/(1+$A38)^DCF_Base!$C$4:$L$4)+MAX(0,MIN(DCF_Base!$L$24*(1+F$33)/($A38-F$33),Assumptions!$B$10*DCF_Base!$L$24))/(1+$A38)^10-Assumptions!$B$6)/Assumptions!$B$7*Assumptions!$B$9,"n/a")
