Workbook

Sheet Model_Info
A1: BioSyent Inc. (RX.V, TSX Venture, CAD) -- Owner-FCF DCF Model, version 1 (fresh build; supersedes nothing)
A3: Built by: dcf-analyst agent (Claude, Fable 5), 2026-08-27, at the orchestrator's request. All figures in CAD millions unless noted.
A4: FIGURES GO STALE. Refresh after every results print. Next: Q3-2026 (approx Nov-2026) -- refresh price, the net-debt bridge (acquisition loan paydown, contingent consideration remeasurement), Oral Health margin trend, and Thyconvi launch traction.
A6: DATA VINTAGE
A7: Price: CAD 15.70 working price per orchestrator (Yahoo regular close 2026-08-26 was 15.84; 52w range 10.65-15.96).
A8: Balance sheet: 2026-06-30 (Q2-2026 interim). The FY2025 (Dec-2025) balance sheet is STALE -- the 2026-03-01 Oral Science acquisition cut net cash from $31.1m to ~$6.4m.
A9: Share count: 11,393,271 = Q2-2026 basic weighted average, includes the 234,192 Oral Science consideration shares. Held FLAT (SBC fully expensed; NCIB funds the flat count).
A10: Guidance: none numeric (company issues no formal guidance). Q2-2026 MD&A: higher H2-2026 selling/marketing spend for the Thyconvi pre-launch; no significant tariff impact on COGS expected.
A12: METHODOLOGY CHOICES (each charged once)
A13: Model: owner-FCF DCF, component build, 10-year horizon -- operating company (specialty pharma in-licensor/distributor); routed via dcf-methods SKILL.md; owner-fcf.md section 7 applied (non-US filer).
A14: Margins: built from the POST-ACQUISITION blend (H1-2026 GM 71.5% / OM 21.0% / EBITDA ~25.5%), never from FY2025's pre-deal 76.6%/26.0%. H1-2026 revenue +59.7% but net income only +19.7% -- the deal bought revenue at lower margin.
A15: Mid-cycling: FY2025 owner FCF $7.80m is a PEAK (1.8x the FY2019-25 median ~$4.3m; OCF conversion and capex both flattering). The model projects from revenue x normalized components (Y1 owner-FCF margin 12.7% vs 18.1% actual), with reinvestment normalized at 2% of revenue (product-rights purchases are lumpy: FY2024 $4.63m vs FY2025 $0.34m).
... A25: Blue font = hardcoded input. Yellow fill = key driver row (the only hardcoded rows on DCF tabs: growth, EBITDA margin, SBC %, tax). Black = formula. Green font = cross-sheet link. Green fill = the value-per-share result.

Sheet Actuals
A1: Reported history (CAD millions; source: annual filings / Metrics.csv, verified in RX.V_ValuationContext.md)
B3: FY2019 | C3: FY2020 | D3: FY2021 | E3: FY2022 | F3: FY2023 | G3: FY2024 | H3: FY2025 | I3: H1-2026
A4: Revenue | B4: 21.424 | C4: 22.332 | D4: 28.618 | E4: 27.925 | F4: 31.59 | G4: 35.031 | H4: 43.052 | I4: 33.781
A5: EBITDA | B5: 5.68 | C5: 5.54 | D5: 8.64 | E5: 7.433 | F5: 7.926 | G5: 9.343 | H5: 12.045 | I5: 8.615
A6: Net income | B6: 4.369 | C6: 3.795 | D6: 6.282 | E6: 5.458 | F6: 6.46 | G6: 7.27 | H6: 9.012 | I6: 5.194
A7: Basic EPS ($) | B7: 0.31 | C7: 0.29 | D7: 0.495 | E7: 0.444 | F7: 0.541 | G7: 0.627 | H7: 0.8 | I7: 0.457
A8: Operating cash flow | B8: 4.402 | C8: 6.894 | D8: 4.675 | E8: 4.949 | F8: 5.055 | G8: 8.663 | H8: 9.009 | I8: 5.248
A9: Capex (PP&E+intangibles) | B9: 0.504 | C9: 0.014 | D9: 0.085 | E9: 0.047 | F9: 0.06 | G9: 4.67 | H9: 0.39 | I9: 0.045
A10: Share-based payments | B10: 0.263 | C10: 0.266 | D10: 0.334 | E10: 0.44 | F10: 0.513 | G10: 0.554 | H10: 0.625 | I10: 0.369
A11: Shareholders' equity | B11: 25.795 | C11: 26.796 | D11: 31.555 | E11: 33.363 | F11: 34.76 | G11: 35.003 | H11: 41.466 | I11: 45.843
A12: Shares wavg (m) | B12: 13.945 | C12: 12.997 | D12: 12.689 | E12: 12.303 | F12: 11.95 | G12: 11.587 | H12: 11.262 | I12: 11.393
A14: Balance sheet 2026-06-30 (whole-dollar filings scaled to millions): cash 5.692 + ST inv 3.251 + LT inv 3.294 = liquid 12.237; ST bank debt 2.000; lease liabilities 1.141 (excluded from net debt, treatment B); contingent consideration 3.846; equity 45.843; BVPS 4.02.
A15: Oral Science acquisition closed 2026-03-01: total consideration $31.48m (cash 24.309 + 234,192 shares at FV 3.474 + contingent 3.846 - WC adj 0.147); 72.7% of PPA is intangibles+goodwill, PROVISIONAL.
A16: H1-2026 vs H1-2025: revenue +59.7% (33.78 vs 21.16) but net income +19.7% (5.19 vs 4.34); GM 71.5% vs 76.8%; OM 21.0% vs 26.2% -- the acquisition structurally reset margins DOWN.
A17: Customer concentration FY2025: four customers = $33.18m = 77.1% of revenue; largest single customer 34.2%.
A18: Dividend $0.055/quarter ($0.22/yr, ~1.4%); H1-2026 buybacks $3.09m (14x FY2025's $0.215m); $6m of the $8m acquisition facilities repaid in H1-2026.

Sheet Assumptions
A1: Global assumptions (blue = input)
A2: WACC (%) | B2: 13.5 | E2: CAD-built: 10.5% Canadian small-cap base (GoC 10y ~3.4% + ERP ~5.5% + size) + 2.0% customer concentration + 1.0% TSXV illiquidity. Same for all scenarios (risk charged once).
A3: D&A (% of revenue) | B3: 2 | E3: Tax-deductible depreciation + amortization of directly purchased product rights. Excludes non-deductible PPA amortization of acquired intangibles (~$3.6m/yr run-rate), which is non-cash AND non-tax-deductible, hence value-irrelevant here.
A4: Capex (% of revenue) | B4: 2 | E4: NORMALIZED reinvestment. FY2025's $0.39m (0.9%) understates the recurring cost of periodically buying product rights (FY2024: $4.63m). 2% of revenue ~= $1.4-2.2m/yr across the horizon.
A5: WC capture (% of rev change) | B5: -8 | E5: Distributor economics: growth consumes receivables+inventory. Negative = cash drag on the CHANGE in revenue. Mid-cycles FY2025's unusually favourable OCF conversion.
A6: Lease cost (% of revenue) | B6: 0.4 | E6: Treatment (B): IFRS-16 lease cost charged in the flows (~$0.3m/yr on the post-acquisition footprint); lease liabilities excluded from net debt.
A7: Cash tax rate (%) | B7: 26 | E7: Canadian combined statutory ~26.5%; FY2025 effective ~25.4%. No abnormal items to ramp from.
A8: Net debt (negative = net cash) | B8: -6.391 | E8: 2026-06-30: -(cash 5.692 + ST inv 3.251 + LT inv 3.294) + bank debt 2.000 + contingent consideration 3.846. Leases excluded (treatment B). NOT the stale Dec-2025 figure of -31.1.
A9: Shares outstanding (m) | B9: 11.393271 | E9: Q2-2026 basic wavg incl. 234,192 consideration shares; held flat (SBC expensed; diluted ~11.5m would be ~1% lower per share).
A10: Current price (CAD) | B10: 15.7 | E10: Working price per orchestrator; Yahoo regular close 2026-08-26 was 15.84 (99th percentile of the 10y range 3.61-15.84).
A11: Terminal cap multiple (x FCF10) | B11: 15 | E11: Lower cap for a structurally slower business. Gordon binds in all scenarios anyway.
A12: FY0 (FY2025) revenue | B12: 43.052 | E12: Reported FY2025 revenue. Y1 growth of ~62-70% is mostly the Oral Science annualization, locked in by H1-2026 (+59.7%).
A13: Hurdle rate (%) | B13: 15 | E13: Entry-price IRR hurdle.
A16: Per scenario | B16: Bear | C16: Base | D16: Bull
A17: Terminal growth (%) | B17: 1.5 | C17: 2.5 | D17: 3 | E17: Bear 1.5 / Base 2.5 / Bull 3.0.
A18: Probability weight | B18: 0.25 | C18: 0.5 | D18: 0.25 | E18: Bear raised to 25% (in-licensed portfolio terminable; mixed launch record: Gelclair discontinued, Combogesic returned; provisional PPA 72.7% intangibles+goodwill). Bull cut to 25% (needs Thyconvi + integration + FeraMAX defence simultaneously).
A19: Weights sum (must be 1.0) | B19: =SUM(B18:D18)
A21: BEAR: the Gelclair/Combogesic pattern repeats -- Thyconvi does not convert, a licensor repatriates a meaningful product, private label clips FeraMAX to zero growth, Oral Science proves ex-growth with partial impairment of the provisional intangibles. Margin compresses to 22% EBITDA.
A22: BASE: Oral Science annualizes (+67% FY2026) at the new blended ~25% EBITDA margin, then organic mid-single-digit growth (FeraMAX defended, Thyconvi modest, Oral Health at category rates); margins hold ~26%; reinvestment normalized at 2% of revenue.
A23: BULL: Thyconvi (only liquid levothyroxine in Canada) becomes a durable franchise, Oral Science cross-selling lifts EBITDA margin back toward 28%, international compounds; high-single/low-double-digit growth for five years.

Sheet DCF_Bear
A1: Bear scenario -- component owner-FCF build (CAD m). Drivers (yellow): rows 5, 7, 9, 16.
B3: 2025A | C3: 2026E | D3: 2027E | E3: 2028E | F3: 2029E | G3: 2030E | H3: 2031E | I3: 2032E | J3: 2033E | K3: 2034E | L3: 2035E
A4: Year index (discount exponent) | B4: 0 | C4: 1 | D4: 2 | E4: 3 | F4: 4 | G4: 5 | H4: 6 | I4: 7 | J4: 8 | K4: 9 | L4: 10
A5: Revenue growth YoY (%) | C5: 62 | D5: 3 | E5: 1 | F5: 0 | G5: 1 | H5: 1.5 | I5: 1.5 | J5: 1.5 | K5: 1.5 | L5: 1.5
A6: Revenue | B6: 43.052 | C6: =B6*(1+C5/100) | D6: =C6*(1+D5/100) | E6: =D6*(1+E5/100) | F6: =E6*(1+F5/100) | G6: =F6*(1+G5/100) | H6: =G6*(1+H5/100) | I6: =H6*(1+I5/100) | J6: =I6*(1+J5/100) | ... L6: =K6*(1+L5/100)
A7: Adj EBITDA margin (%) | C7: 24 | D7: 23.5 | E7: 23 | F7: 22.5 | G7: 22 | H7: 22 | I7: 22 | J7: 22 | K7: 22 | L7: 22
A8: Adjusted EBITDA | C8: =C6*C7/100 | D8: =D6*D7/100 | E8: =E6*E7/100 | F8: =F6*F7/100 | G8: =G6*G7/100 | H8: =H6*H7/100 | I8: =I6*I7/100 | J8: =J6*J7/100 | ... L8: =L6*L7/100
A9: SBC % of revenue | C9: 1.1 | D9: 1.1 | E9: 1 | F9: 1 | G9: 1 | H9: 1 | I9: 1 | J9: 1 | K9: 1 | L9: 1
A10: SBC $ | C10: =-C6*C9/100 | D10: =-D6*D9/100 | E10: =-E6*E9/100 | F10: =-F6*F9/100 | G10: =-G6*G9/100 | H10: =-H6*H9/100 | I10: =-I6*I9/100 | J10: =-J6*J9/100 | ... L10: =-L6*L9/100
A11: Owner EBITDA (SBC expensed) | C11: =C8+C10 | D11: =D8+D10 | E11: =E8+E10 | F11: =F8+F10 | G11: =G8+G10 | H11: =H8+H10 | I11: =I8+I10 | J11: =J8+J10 | ... L11: =L8+L10
A12: Lease cost % of revenue | C12: =Assumptions!$B$6 | D12: =Assumptions!$B$6 | E12: =Assumptions!$B$6 | F12: =Assumptions!$B$6 | G12: =Assumptions!$B$6 | H12: =Assumptions!$B$6 | I12: =Assumptions!$B$6 | J12: =Assumptions!$B$6 | ... L12: =Assumptions!$B$6
A13: Lease cost $ | C13: =-C6*C12/100 | D13: =-D6*D12/100 | E13: =-E6*E12/100 | F13: =-F6*F12/100 | G13: =-G6*G12/100 | H13: =-H6*H12/100 | I13: =-I6*I12/100 | J13: =-J6*J12/100 | ... L13: =-L6*L12/100
A14: D&A $ | C14: =-C6*Assumptions!$B$3/100 | D14: =-D6*Assumptions!$B$3/100 | E14: =-E6*Assumptions!$B$3/100 | F14: =-F6*Assumptions!$B$3/100 | G14: =-G6*Assumptions!$B$3/100 | H14: =-H6*Assumptions!$B$3/100 | I14: =-I6*Assumptions!$B$3/100 | J14: =-J6*Assumptions!$B$3/100 | ... L14: =-L6*Assumptions!$B$3/100
A15: EBIT (SBC+lease expensed) | C15: =C11+C13+C14 | D15: =D11+D13+D14 | E15: =E11+E13+E14 | F15: =F11+F13+F14 | G15: =G11+G13+G14 | H15: =H11+H13+H14 | I15: =I11+I13+I14 | J15: =J11+J13+J14 | ... L15: =L11+L13+L14
A16: Cash tax rate (%) | C16: 26 | D16: 26 | E16: 26 | F16: 26 | G16: 26 | H16: 26 | I16: 26 | J16: 26 | K16: 26 | L16: 26
A17: NOPAT | C17: =C15*(1-C16/100) | D17: =D15*(1-D16/100) | E17: =E15*(1-E16/100) | F17: =F15*(1-F16/100) | G17: =G15*(1-G16/100) | H17: =H15*(1-H16/100) | I17: =I15*(1-I16/100) | J17: =J15*(1-J16/100) | ... L17: =L15*(1-L16/100)
A18: add back D&A | C18: =-C14 | D18: =-D14 | E18: =-E14 | F18: =-F14 | G18: =-G14 | H18: =-H14 | I18: =-I14 | J18: =-J14 | ... L18: =-L14
A19: less capex | C19: =-C6*Assumptions!$B$4/100 | D19: =-D6*Assumptions!$B$4/100 | E19: =-E6*Assumptions!$B$4/100 | F19: =-F6*Assumptions!$B$4/100 | G19: =-G6*Assumptions!$B$4/100 | H19: =-H6*Assumptions!$B$4/100 | I19: =-I6*Assumptions!$B$4/100 | J19: =-J6*Assumptions!$B$4/100 | ... L19: =-L6*Assumptions!$B$4/100
A20: add working capital (on change) | C20: =Assumptions!$B$5/100*(C6-B6) | D20: =Assumptions!$B$5/100*(D6-C6) | E20: =Assumptions!$B$5/100*(E6-D6) | F20: =Assumptions!$B$5/100*(F6-E6) | G20: =Assumptions!$B$5/100*(G6-F6) | H20: =Assumptions!$B$5/100*(H6-G6) | I20: =Assumptions!$B$5/100*(I6-H6) | J20: =Assumptions!$B$5/100*(J6-I6) | ... L20: =Assumptions!$B$5/100*(L6-K6)
A21: Unlevered owner FCF | C21: =C17+C18+C19+C20 | D21: =D17+D18+D19+D20 | E21: =E17+E18+E19+E20 | F21: =F17+F18+F19+F20 | G21: =G17+G18+G19+G20 | H21: =H17+H18+H19+H20 | I21: =I17+I18+I19+I20 | J21: =J17+J18+J19+J20 | ... L21: =L17+L18+L19+L20
A22: Discount factor | C22: =1/(1+Assumptions!$B$2/100)^C4 | D22: =1/(1+Assumptions!$B$2/100)^D4 | E22: =1/(1+Assumptions!$B$2/100)^E4 | F22: =1/(1+Assumptions!$B$2/100)^F4 | G22: =1/(1+Assumptions!$B$2/100)^G4 | H22: =1/(1+Assumptions!$B$2/100)^H4 | I22: =1/(1+Assumptions!$B$2/100)^I4 | J22: =1/(1+Assumptions!$B$2/100)^J4 | ... L22: =1/(1+Assumptions!$B$2/100)^L4
A23: PV of FCF | C23: =C21*C22 | D23: =D21*D22 | E23: =E21*E22 | F23: =F21*F22 | G23: =G21*G22 | H23: =H21*H22 | I23: =I21*I22 | J23: =J21*J22 | ... L23: =L21*L22
A25: Memo: FCF before SBC (company-style) | C25: =C21-C10 | D25: =D21-D10 | E25: =E21-E10 | F25: =F21-F10 | G25: =G21-G10 | H25: =H21-H10 | I25: =I21-I10 | J25: =J21-J10 | ... L25: =L21-L10
A26: Memo: owner-FCF margin | C26: =C21/C6 | D26: =D21/D6 | E26: =E21/E6 | F26: =F21/F6 | G26: =G21/G6 | H26: =H21/H6 | I26: =I21/I6 | J26: =J21/J6 | ... L26: =L21/L6
A28: Sum of PV of FCF | B28: =SUM(C23:L23)
A29: Terminal growth (%) | B29: =Assumptions!$B$17
A30: Terminal-year FCF x (1+g) | B30: =L21*(1+B29/100)
A31: Gordon terminal value | B31: =B30/((Assumptions!$B$2-B29)/100)
A32: Cap terminal value (15x FCF10) | B32: =Assumptions!$B$11*L21
A33: Terminal value used | B33: =MAX(0,MIN(B31,B32))
A34: Implied exit multiple (x FCF10) | B34: =B33/L21
A35: PV of terminal value | B35: =B33*L22
A36: Enterprise value | B36: =B28+B35
A37: add net cash (less net debt) | B37: =-Assumptions!$B$8
A38: Equity value | B38: =B36+B37
A39: Shares (m) | B39: =Assumptions!$B$9
A40: VALUE PER SHARE (CAD) | B40: =B38/B39
A41: Upside vs current price | B41: =B40/Assumptions!$B$10-1
A43: Street memo: PV of explicit SBC | B43: =SUMPRODUCT(-C10:L10/(1+Assumptions!$B$2/100)^C4:L4)
A44: Street memo: PV of terminal SBC | B44: =(-L10*(1+B29/100)/((Assumptions!$B$2-B29)/100))*L22
...

Sheet DCF_Base
A1: Base scenario -- component owner-FCF build (CAD m). Drivers (yellow): rows 5, 7, 9, 16.
B3: 2025A | C3: 2026E | D3: 2027E | E3: 2028E | F3: 2029E | G3: 2030E | H3: 2031E | I3: 2032E | J3: 2033E | K3: 2034E | L3: 2035E
A4: Year index (discount exponent) | B4: 0 | C4: 1 | D4: 2 | E4: 3 | F4: 4 | G4: 5 | H4: 6 | I4: 7 | J4: 8 | K4: 9 | L4: 10
A5: Revenue growth YoY (%) | C5: 67 | D5: 8 | E5: 7 | F5: 6 | G5: 5 | H5: 5 | I5: 4.5 | J5: 4 | K5: 3.5 | L5: 3
A6: Revenue | B6: 43.052 | C6: =B6*(1+C5/100) | D6: =C6*(1+D5/100) | E6: =D6*(1+E5/100) | F6: =E6*(1+F5/100) | G6: =F6*(1+G5/100) | H6: =G6*(1+H5/100) | I6: =H6*(1+I5/100) | J6: =I6*(1+J5/100) | ... L6: =K6*(1+L5/100)
A7: Adj EBITDA margin (%) | C7: 25 | D7: 25.5 | E7: 25.5 | F7: 26 | G7: 26 | H7: 26 | I7: 26 | J7: 26 | K7: 26 | L7: 26
A8: Adjusted EBITDA | C8: =C6*C7/100 | D8: =D6*D7/100 | E8: =E6*E7/100 | F8: =F6*F7/100 | G8: =G6*G7/100 | H8: =H6*H7/100 | I8: =I6*I7/100 | J8: =J6*J7/100 | ... L8: =L6*L7/100
A9: SBC % of revenue | C9: 1.1 | D9: 1.1 | E9: 1 | F9: 1 | G9: 1 | H9: 1 | I9: 1 | J9: 1 | K9: 1 | L9: 1
A10: SBC $ | C10: =-C6*C9/100 | D10: =-D6*D9/100 | E10: =-E6*E9/100 | F10: =-F6*F9/100 | G10: =-G6*G9/100 | H10: =-H6*H9/100 | I10: =-I6*I9/100 | J10: =-J6*J9/100 | ... L10: =-L6*L9/100
A11: Owner EBITDA (SBC expensed) | C11: =C8+C10 | D11: =D8+D10 | E11: =E8+E10 | F11: =F8+F10 | G11: =G8+G10 | H11: =H8+H10 | I11: =I8+I10 | J11: =J8+J10 | ... L11: =L8+L10
A12: Lease cost % of revenue | C12: =Assumptions!$B$6 | D12: =Assumptions!$B$6 | E12: =Assumptions!$B$6 | F12: =Assumptions!$B$6 | G12: =Assumptions!$B$6 | H12: =Assumptions!$B$6 | I12: =Assumptions!$B$6 | J12: =Assumptions!$B$6 | ... L12: =Assumptions!$B$6
A13: Lease cost $ | C13: =-C6*C12/100 | D13: =-D6*D12/100 | E13: =-E6*E12/100 | F13: =-F6*F12/100 | G13: =-G6*G12/100 | H13: =-H6*H12/100 | I13: =-I6*I12/100 | J13: =-J6*J12/100 | ... L13: =-L6*L12/100
A14: D&A $ | C14: =-C6*Assumptions!$B$3/100 | D14: =-D6*Assumptions!$B$3/100 | E14: =-E6*Assumptions!$B$3/100 | F14: =-F6*Assumptions!$B$3/100 | G14: =-G6*Assumptions!$B$3/100 | H14: =-H6*Assumptions!$B$3/100 | I14: =-I6*Assumptions!$B$3/100 | J14: =-J6*Assumptions!$B$3/100 | ... L14: =-L6*Assumptions!$B$3/100
A15: EBIT (SBC+lease expensed) | C15: =C11+C13+C14 | D15: =D11+D13+D14 | E15: =E11+E13+E14 | F15: =F11+F13+F14 | G15: =G11+G13+G14 | H15: =H11+H13+H14 | I15: =I11+I13+I14 | J15: =J11+J13+J14 | ... L15: =L11+L13+L14
A16: Cash tax rate (%) | C16: 26 | D16: 26 | E16: 26 | F16: 26 | G16: 26 | H16: 26 | I16: 26 | J16: 26 | K16: 26 | L16: 26
A17: NOPAT | C17: =C15*(1-C16/100) | D17: =D15*(1-D16/100) | E17: =E15*(1-E16/100) | F17: =F15*(1-F16/100) | G17: =G15*(1-G16/100) | H17: =H15*(1-H16/100) | I17: =I15*(1-I16/100) | J17: =J15*(1-J16/100) | ... L17: =L15*(1-L16/100)
A18: add back D&A | C18: =-C14 | D18: =-D14 | E18: =-E14 | F18: =-F14 | G18: =-G14 | H18: =-H14 | I18: =-I14 | J18: =-J14 | ... L18: =-L14
A19: less capex | C19: =-C6*Assumptions!$B$4/100 | D19: =-D6*Assumptions!$B$4/100 | E19: =-E6*Assumptions!$B$4/100 | F19: =-F6*Assumptions!$B$4/100 | G19: =-G6*Assumptions!$B$4/100 | H19: =-H6*Assumptions!$B$4/100 | I19: =-I6*Assumptions!$B$4/100 | J19: =-J6*Assumptions!$B$4/100 | ... L19: =-L6*Assumptions!$B$4/100
A20: add working capital (on change) | C20: =Assumptions!$B$5/100*(C6-B6) | D20: =Assumptions!$B$5/100*(D6-C6) | E20: =Assumptions!$B$5/100*(E6-D6) | F20: =Assumptions!$B$5/100*(F6-E6) | G20: =Assumptions!$B$5/100*(G6-F6) | H20: =Assumptions!$B$5/100*(H6-G6) | I20: =Assumptions!$B$5/100*(I6-H6) | J20: =Assumptions!$B$5/100*(J6-I6) | ... L20: =Assumptions!$B$5/100*(L6-K6)
A21: Unlevered owner FCF | C21: =C17+C18+C19+C20 | D21: =D17+D18+D19+D20 | E21: =E17+E18+E19+E20 | F21: =F17+F18+F19+F20 | G21: =G17+G18+G19+G20 | H21: =H17+H18+H19+H20 | I21: =I17+I18+I19+I20 | J21: =J17+J18+J19+J20 | ... L21: =L17+L18+L19+L20
A22: Discount factor | C22: =1/(1+Assumptions!$B$2/100)^C4 | D22: =1/(1+Assumptions!$B$2/100)^D4 | E22: =1/(1+Assumptions!$B$2/100)^E4 | F22: =1/(1+Assumptions!$B$2/100)^F4 | G22: =1/(1+Assumptions!$B$2/100)^G4 | H22: =1/(1+Assumptions!$B$2/100)^H4 | I22: =1/(1+Assumptions!$B$2/100)^I4 | J22: =1/(1+Assumptions!$B$2/100)^J4 | ... L22: =1/(1+Assumptions!$B$2/100)^L4
A23: PV of FCF | C23: =C21*C22 | D23: =D21*D22 | E23: =E21*E22 | F23: =F21*F22 | G23: =G21*G22 | H23: =H21*H22 | I23: =I21*I22 | J23: =J21*J22 | ... L23: =L21*L22
A25: Memo: FCF before SBC (company-style) | C25: =C21-C10 | D25: =D21-D10 | E25: =E21-E10 | F25: =F21-F10 | G25: =G21-G10 | H25: =H21-H10 | I25: =I21-I10 | J25: =J21-J10 | ... L25: =L21-L10
A26: Memo: owner-FCF margin | C26: =C21/C6 | D26: =D21/D6 | E26: =E21/E6 | F26: =F21/F6 | G26: =G21/G6 | H26: =H21/H6 | I26: =I21/I6 | J26: =J21/J6 | ... L26: =L21/L6
A28: Sum of PV of FCF | B28: =SUM(C23:L23)
A29: Terminal growth (%) | B29: =Assumptions!$C$17
A30: Terminal-year FCF x (1+g) | B30: =L21*(1+B29/100)
A31: Gordon terminal value | B31: =B30/((Assumptions!$B$2-B29)/100)
A32: Cap terminal value (15x FCF10) | B32: =Assumptions!$B$11*L21
A33: Terminal value used | B33: =MAX(0,MIN(B31,B32))
A34: Implied exit multiple (x FCF10) | B34: =B33/L21
A35: PV of terminal value | B35: =B33*L22
A36: Enterprise value | B36: =B28+B35
A37: add net cash (less net debt) | B37: =-Assumptions!$B$8
A38: Equity value | B38: =B36+B37
A39: Shares (m) | B39: =Assumptions!$B$9
A40: VALUE PER SHARE (CAD) | B40: =B38/B39
A41: Upside vs current price | B41: =B40/Assumptions!$B$10-1
A43: Street memo: PV of explicit SBC | B43: =SUMPRODUCT(-C10:L10/(1+Assumptions!$B$2/100)^C4:L4)
A44: Street memo: PV of terminal SBC | B44: =(-L10*(1+B29/100)/((Assumptions!$B$2-B29)/100))*L22
...

Sheet DCF_Bull
A1: Bull scenario -- component owner-FCF build (CAD m). Drivers (yellow): rows 5, 7, 9, 16.
B3: 2025A | C3: 2026E | D3: 2027E | E3: 2028E | F3: 2029E | G3: 2030E | H3: 2031E | I3: 2032E | J3: 2033E | K3: 2034E | L3: 2035E
A4: Year index (discount exponent) | B4: 0 | C4: 1 | D4: 2 | E4: 3 | F4: 4 | G4: 5 | H4: 6 | I4: 7 | J4: 8 | K4: 9 | L4: 10
A5: Revenue growth YoY (%) | C5: 70 | D5: 12 | E5: 10 | F5: 9 | G5: 8 | H5: 7 | I5: 6 | J5: 5 | K5: 4.5 | L5: 4
A6: Revenue | B6: 43.052 | C6: =B6*(1+C5/100) | D6: =C6*(1+D5/100) | E6: =D6*(1+E5/100) | F6: =E6*(1+F5/100) | G6: =F6*(1+G5/100) | H6: =G6*(1+H5/100) | I6: =H6*(1+I5/100) | J6: =I6*(1+J5/100) | ... L6: =K6*(1+L5/100)
A7: Adj EBITDA margin (%) | C7: 25.5 | D7: 26.5 | E7: 27 | F7: 27.5 | G7: 28 | H7: 28 | I7: 28 | J7: 28 | K7: 28 | L7: 28
A8: Adjusted EBITDA | C8: =C6*C7/100 | D8: =D6*D7/100 | E8: =E6*E7/100 | F8: =F6*F7/100 | G8: =G6*G7/100 | H8: =H6*H7/100 | I8: =I6*I7/100 | J8: =J6*J7/100 | ... L8: =L6*L7/100
A9: SBC % of revenue | C9: 1.1 | D9: 1.1 | E9: 1 | F9: 1 | G9: 1 | H9: 1 | I9: 1 | J9: 1 | K9: 1 | L9: 1
A10: SBC $ | C10: =-C6*C9/100 | D10: =-D6*D9/100 | E10: =-E6*E9/100 | F10: =-F6*F9/100 | G10: =-G6*G9/100 | H10: =-H6*H9/100 | I10: =-I6*I9/100 | J10: =-J6*J9/100 | ... L10: =-L6*L9/100
A11: Owner EBITDA (SBC expensed) | C11: =C8+C10 | D11: =D8+D10 | E11: =E8+E10 | F11: =F8+F10 | G11: =G8+G10 | H11: =H8+H10 | I11: =I8+I10 | J11: =J8+J10 | ... L11: =L8+L10
A12: Lease cost % of revenue | C12: =Assumptions!$B$6 | D12: =Assumptions!$B$6 | E12: =Assumptions!$B$6 | F12: =Assumptions!$B$6 | G12: =Assumptions!$B$6 | H12: =Assumptions!$B$6 | I12: =Assumptions!$B$6 | J12: =Assumptions!$B$6 | ... L12: =Assumptions!$B$6
A13: Lease cost $ | C13: =-C6*C12/100 | D13: =-D6*D12/100 | E13: =-E6*E12/100 | F13: =-F6*F12/100 | G13: =-G6*G12/100 | H13: =-H6*H12/100 | I13: =-I6*I12/100 | J13: =-J6*J12/100 | ... L13: =-L6*L12/100
A14: D&A $ | C14: =-C6*Assumptions!$B$3/100 | D14: =-D6*Assumptions!$B$3/100 | E14: =-E6*Assumptions!$B$3/100 | F14: =-F6*Assumptions!$B$3/100 | G14: =-G6*Assumptions!$B$3/100 | H14: =-H6*Assumptions!$B$3/100 | I14: =-I6*Assumptions!$B$3/100 | J14: =-J6*Assumptions!$B$3/100 | ... L14: =-L6*Assumptions!$B$3/100
A15: EBIT (SBC+lease expensed) | C15: =C11+C13+C14 | D15: =D11+D13+D14 | E15: =E11+E13+E14 | F15: =F11+F13+F14 | G15: =G11+G13+G14 | H15: =H11+H13+H14 | I15: =I11+I13+I14 | J15: =J11+J13+J14 | ... L15: =L11+L13+L14
A16: Cash tax rate (%) | C16: 26 | D16: 26 | E16: 26 | F16: 26 | G16: 26 | H16: 26 | I16: 26 | J16: 26 | K16: 26 | L16: 26
A17: NOPAT | C17: =C15*(1-C16/100) | D17: =D15*(1-D16/100) | E17: =E15*(1-E16/100) | F17: =F15*(1-F16/100) | G17: =G15*(1-G16/100) | H17: =H15*(1-H16/100) | I17: =I15*(1-I16/100) | J17: =J15*(1-J16/100) | ... L17: =L15*(1-L16/100)
A18: add back D&A | C18: =-C14 | D18: =-D14 | E18: =-E14 | F18: =-F14 | G18: =-G14 | H18: =-H14 | I18: =-I14 | J18: =-J14 | ... L18: =-L14
A19: less capex | C19: =-C6*Assumptions!$B$4/100 | D19: =-D6*Assumptions!$B$4/100 | E19: =-E6*Assumptions!$B$4/100 | F19: =-F6*Assumptions!$B$4/100 | G19: =-G6*Assumptions!$B$4/100 | H19: =-H6*Assumptions!$B$4/100 | I19: =-I6*Assumptions!$B$4/100 | J19: =-J6*Assumptions!$B$4/100 | ... L19: =-L6*Assumptions!$B$4/100
A20: add working capital (on change) | C20: =Assumptions!$B$5/100*(C6-B6) | D20: =Assumptions!$B$5/100*(D6-C6) | E20: =Assumptions!$B$5/100*(E6-D6) | F20: =Assumptions!$B$5/100*(F6-E6) | G20: =Assumptions!$B$5/100*(G6-F6) | H20: =Assumptions!$B$5/100*(H6-G6) | I20: =Assumptions!$B$5/100*(I6-H6) | J20: =Assumptions!$B$5/100*(J6-I6) | ... L20: =Assumptions!$B$5/100*(L6-K6)
A21: Unlevered owner FCF | C21: =C17+C18+C19+C20 | D21: =D17+D18+D19+D20 | E21: =E17+E18+E19+E20 | F21: =F17+F18+F19+F20 | G21: =G17+G18+G19+G20 | H21: =H17+H18+H19+H20 | I21: =I17+I18+I19+I20 | J21: =J17+J18+J19+J20 | ... L21: =L17+L18+L19+L20
A22: Discount factor | C22: =1/(1+Assumptions!$B$2/100)^C4 | D22: =1/(1+Assumptions!$B$2/100)^D4 | E22: =1/(1+Assumptions!$B$2/100)^E4 | F22: =1/(1+Assumptions!$B$2/100)^F4 | G22: =1/(1+Assumptions!$B$2/100)^G4 | H22: =1/(1+Assumptions!$B$2/100)^H4 | I22: =1/(1+Assumptions!$B$2/100)^I4 | J22: =1/(1+Assumptions!$B$2/100)^J4 | ... L22: =1/(1+Assumptions!$B$2/100)^L4
A23: PV of FCF | C23: =C21*C22 | D23: =D21*D22 | E23: =E21*E22 | F23: =F21*F22 | G23: =G21*G22 | H23: =H21*H22 | I23: =I21*I22 | J23: =J21*J22 | ... L23: =L21*L22
A25: Memo: FCF before SBC (company-style) | C25: =C21-C10 | D25: =D21-D10 | E25: =E21-E10 | F25: =F21-F10 | G25: =G21-G10 | H25: =H21-H10 | I25: =I21-I10 | J25: =J21-J10 | ... L25: =L21-L10
A26: Memo: owner-FCF margin | C26: =C21/C6 | D26: =D21/D6 | E26: =E21/E6 | F26: =F21/F6 | G26: =G21/G6 | H26: =H21/H6 | I26: =I21/I6 | J26: =J21/J6 | ... L26: =L21/L6
A28: Sum of PV of FCF | B28: =SUM(C23:L23)
A29: Terminal growth (%) | B29: =Assumptions!$D$17
A30: Terminal-year FCF x (1+g) | B30: =L21*(1+B29/100)
A31: Gordon terminal value | B31: =B30/((Assumptions!$B$2-B29)/100)
A32: Cap terminal value (15x FCF10) | B32: =Assumptions!$B$11*L21
A33: Terminal value used | B33: =MAX(0,MIN(B31,B32))
A34: Implied exit multiple (x FCF10) | B34: =B33/L21
A35: PV of terminal value | B35: =B33*L22
A36: Enterprise value | B36: =B28+B35
A37: add net cash (less net debt) | B37: =-Assumptions!$B$8
A38: Equity value | B38: =B36+B37
A39: Shares (m) | B39: =Assumptions!$B$9
A40: VALUE PER SHARE (CAD) | B40: =B38/B39
A41: Upside vs current price | B41: =B40/Assumptions!$B$10-1
A43: Street memo: PV of explicit SBC | B43: =SUMPRODUCT(-C10:L10/(1+Assumptions!$B$2/100)^C4:L4)
A44: Street memo: PV of terminal SBC | B44: =(-L10*(1+B29/100)/((Assumptions!$B$2-B29)/100))*L22
...

Sheet FCF_Quality
A1: Reported FCF reconciled to owner FCF (CAD m). FY2025 is a PEAK -- the model does not project from it.
B3: FY2019 | C3: FY2020 | D3: FY2021 | E3: FY2022 | F3: FY2023 | G3: FY2024 | H3: FY2025
A4: Operating cash flow (already excl. finance income) | B4: 4.402 | C4: 6.894 | D4: 4.675 | E4: 4.949 | F4: 5.055 | G4: 8.663 | H4: 9.009
A5: less: capex incl. intangible/product-rights additions | B5: 0.504 | C5: 0.014 | D5: 0.085 | E5: 0.047 | F5: 0.06 | G5: 4.67 | H5: 0.39
A6: less: share-based payments | B6: 0.263 | C6: 0.266 | D6: 0.334 | E6: 0.44 | F6: 0.513 | G6: 0.554 | H6: 0.625
A7: less: lease principal (est. 2019-23) | B7: 0.18 | C7: 0.185 | D7: 0.19 | E7: 0.19 | F7: 0.19 | G7: 0.183 | H7: 0.197
A8: Revenue | B8: 21.424 | C8: 22.332 | D8: 28.618 | E8: 27.925 | F8: 31.59 | G8: 35.031 | H8: 43.052
A9: Owner FCF (OCF - capex - SBC - lease) | B9: =B4-B5-B6-B7 | C9: =C4-C5-C6-C7 | D9: =D4-D5-D6-D7 | E9: =E4-E5-E6-E7 | F9: =F4-F5-F6-F7 | G9: =G4-G5-G6-G7 | H9: =H4-H5-H6-H7
A10: Reported FCF (OCF - capex) | B10: =B4-B5 | C10: =C4-C5 | D10: =D4-D5 | E10: =E4-E5 | F10: =F4-F5 | G10: =G4-G5 | H10: =H4-H5
A11: Owner FCF margin | B11: =B9/B8 | C11: =C9/C8 | D11: =D9/D8 | E11: =E9/E8 | F11: =F9/F8 | G11: =G9/G8 | H11: =H9/H8
A12: Reported FCF margin | B12: =B10/B8 | C12: =C10/C8 | D12: =D10/D8 | E12: =E10/E8 | F12: =F10/F8 | G12: =G10/G8 | H12: =H10/H8
A14: Memo: FY2025 owner FCF $7.80m = 1.8x the FY2019-25 median (~$4.3m). Conversion was peak (favourable WC) and capex trough ($0.39m vs FY2024's $4.67m of product-rights purchases -- real, recurring, lumpy reinvestment).
A15: Memo: cash tax rate normal throughout (~25-26%); no abnormal releases to ramp from.
A16: Memo: finance income (FY2025 $0.886m) is excluded from OCF by presentation; its matching assets ($12.24m liquid at Jun-2026) are in the net-debt bridge, so it is not double-counted.

Sheet Valuation
A1: Valuation summary (CAD/share)
A3: Scenario | B3: Value/share | C3: Upside | D3: Weight | E3: Street value | F3: Entry @15%
A4: Bear | B4: =DCF_Bear!$B$40 | C4: =B4/Assumptions!$B$10-1 | D4: =Assumptions!$B$18 | E4: =DCF_Bear!$B$45 | F4: =(SUMPRODUCT(DCF_Bear!$C$21:$L$21/(1+Assumptions!$B$13/100)^DCF_Bear!$C$4:$L$4)+DCF_Bear!$B$33/(1+Assumptions!$B$13/100)^10-Assumptions!$B$8)/Assumptions!$B$9
A5: Base | B5: =DCF_Base!$B$40 | C5: =B5/Assumptions!$B$10-1 | D5: =Assumptions!$C$18 | E5: =DCF_Base!$B$45 | F5: =(SUMPRODUCT(DCF_Base!$C$21:$L$21/(1+Assumptions!$B$13/100)^DCF_Base!$C$4:$L$4)+DCF_Base!$B$33/(1+Assumptions!$B$13/100)^10-Assumptions!$B$8)/Assumptions!$B$9
A6: Bull | B6: =DCF_Bull!$B$40 | C6: =B6/Assumptions!$B$10-1 | D6: =Assumptions!$D$18 | E6: =DCF_Bull!$B$45 | F6: =(SUMPRODUCT(DCF_Bull!$C$21:$L$21/(1+Assumptions!$B$13/100)^DCF_Bull!$C$4:$L$4)+DCF_Bull!$B$33/(1+Assumptions!$B$13/100)^10-Assumptions!$B$8)/Assumptions!$B$9
A8: Probability-weighted IV | B8: =SUMPRODUCT(B4:B6,D4:D6)
A9: Street weighted IV | B9: =SUMPRODUCT(E4:E6,D4:D6)
A10: Weighted entry price (buy-below) | B10: =SUMPRODUCT(F4:F6,D4:D6)
A11: Margin of safety at current price | B11: =1-Assumptions!$B$10/B8
A12: Band position (house->street) | B12: =(Assumptions!$B$10-B8)/(B9-B8)
A13: Band note: SBC ~1% of revenue, so the house/street band is only ~$0.7 wide; price sits far above BOTH -- the gap is valuation, not SBC accounting.
A15: Required-return table (base case; TV computed at model WACC, discounted at r)
A16: Required return r (%) | B16: 9 | C16: 10 | D16: 11 | E16: 12 | F16: 13.5 | G16: 15
A17: Value per share | B17: =(SUMPRODUCT(DCF_Base!$C$21:$L$21/(1+B$16/100)^DCF_Base!$C$4:$L$4)+DCF_Base!$B$33/(1+B$16/100)^10-Assumptions!$B$8)/Assumptions!$B$9 | C17: =(SUMPRODUCT(DCF_Base!$C$21:$L$21/(1+C$16/100)^DCF_Base!$C$4:$L$4)+DCF_Base!$B$33/(1+C$16/100)^10-Assumptions!$B$8)/Assumptions!$B$9 | D17: =(SUMPRODUCT(DCF_Base!$C$21:$L$21/(1+D$16/100)^DCF_Base!$C$4:$L$4)+DCF_Base!$B$33/(1+D$16/100)^10-Assumptions!$B$8)/Assumptions!$B$9 | E17: =(SUMPRODUCT(DCF_Base!$C$21:$L$21/(1+E$16/100)^DCF_Base!$C$4:$L$4)+DCF_Base!$B$33/(1+E$16/100)^10-Assumptions!$B$8)/Assumptions!$B$9 | F17: =(SUMPRODUCT(DCF_Base!$C$21:$L$21/(1+F$16/100)^DCF_Base!$C$4:$L$4)+DCF_Base!$B$33/(1+F$16/100)^10-Assumptions!$B$8)/Assumptions!$B$9 | G17: =(SUMPRODUCT(DCF_Base!$C$21:$L$21/(1+G$16/100)^DCF_Base!$C$4:$L$4)+DCF_Base!$B$33/(1+G$16/100)^10-Assumptions!$B$8)/Assumptions!$B$9
A18: Note: 13.5% is the model's own WACC. Today's $15.70 implies roughly an 8.5-9% forward return on the base path.
A20: Sensitivity: WACC (rows) x terminal growth (cols), base case
B21: 1.5 | C21: 2 | D21: 2.5 | E21: 3 | F21: 3.5
A22: 11.5 | B22: =IF($A22>B$21,(SUMPRODUCT(DCF_Base!$C$21:$L$21/(1+$A22/100)^DCF_Base!$C$4:$L$4)+MAX(0,MIN(DCF_Base!$L$21*(1+B$21/100)/(($A22-B$21)/100),Assumptions!$B$11*DCF_Base!$L$21))/(1+$A22/100)^10-Assumptions!$B$8)/Assumptions!$B$9,"n/a") | C22: =IF($A22>C$21,(SUMPRODUCT(DCF_Base!$C$21:$L$21/(1+$A22/100)^DCF_Base!$C$4:$L$4)+MAX(0,MIN(DCF_Base!$L$21*(1+C$21/100)/(($A22-C$21)/100),Assumptions!$B$11*DCF_Base!$L$21))/(1+$A22/100)^10-Assumptions!$B$8)/Assumptions!$B$9,"n/a") | D22: =IF($A22>D$21,(SUMPRODUCT(DCF_Base!$C$21:$L$21/(1+$A22/100)^DCF_Base!$C$4:$L$4)+MAX(0,MIN(DCF_Base!$L$21*(1+D$21/100)/(($A22-D$21)/100),Assumptions!$B$11*DCF_Base!$L$21))/(1+$A22/100)^10-Assumptions!$B$8)/Assumptions!$B$9,"n/a") | E22: =IF($A22>E$21,(SUMPRODUCT(DCF_Base!$C$21:$L$21/(1+$A22/100)^DCF_Base!$C$4:$L$4)+MAX(0,MIN(DCF_Base!$L$21*(1+E$21/100)/(($A22-E$21)/100),Assumptions!$B$11*DCF_Base!$L$21))/(1+$A22/100)^10-Assumptions!$B$8)/Assumptions!$B$9,"n/a") | F22: =IF($A22>F$21,(SUMPRODUCT(DCF_Base!$C$21:$L$21/(1+$A22/100)^DCF_Base!$C$4:$L$4)+MAX(0,MIN(DCF_Base!$L$21*(1+F$21/100)/(($A22-F$21)/100),Assumptions!$B$11*DCF_Base!$L$21))/(1+$A22/100)^10-Assumptions!$B$8)/Assumptions!$B$9,"n/a")
A23: 12.5 | B23: =IF($A23>B$21,(SUMPRODUCT(DCF_Base!$C$21:$L$21/(1+$A23/100)^DCF_Base!$C$4:$L$4)+MAX(0,MIN(DCF_Base!$L$21*(1+B$21/100)/(($A23-B$21)/100),Assumptions!$B$11*DCF_Base!$L$21))/(1+$A23/100)^10-Assumptions!$B$8)/Assumptions!$B$9,"n/a") | C23: =IF($A23>C$21,(SUMPRODUCT(DCF_Base!$C$21:$L$21/(1+$A23/100)^DCF_Base!$C$4:$L$4)+MAX(0,MIN(DCF_Base!$L$21*(1+C$21/100)/(($A23-C$21)/100),Assumptions!$B$11*DCF_Base!$L$21))/(1+$A23/100)^10-Assumptions!$B$8)/Assumptions!$B$9,"n/a") | D23: =IF($A23>D$21,(SUMPRODUCT(DCF_Base!$C$21:$L$21/(1+$A23/100)^DCF_Base!$C$4:$L$4)+MAX(0,MIN(DCF_Base!$L$21*(1+D$21/100)/(($A23-D$21)/100),Assumptions!$B$11*DCF_Base!$L$21))/(1+$A23/100)^10-Assumptions!$B$8)/Assumptions!$B$9,"n/a") | E23: =IF($A23>E$21,(SUMPRODUCT(DCF_Base!$C$21:$L$21/(1+$A23/100)^DCF_Base!$C$4:$L$4)+MAX(0,MIN(DCF_Base!$L$21*(1+E$21/100)/(($A23-E$21)/100),Assumptions!$B$11*DCF_Base!$L$21))/(1+$A23/100)^10-Assumptions!$B$8)/Assumptions!$B$9,"n/a") | F23: =IF($A23>F$21,(SUMPRODUCT(DCF_Base!$C$21:$L$21/(1+$A23/100)^DCF_Base!$C$4:$L$4)+MAX(0,MIN(DCF_Base!$L$21*(1+F$21/100)/(($A23-F$21)/100),Assumptions!$B$11*DCF_Base!$L$21))/(1+$A23/100)^10-Assumptions!$B$8)/Assumptions!$B$9,"n/a")
A24: 13.5 | B24: =IF($A24>B$21,(SUMPRODUCT(DCF_Base!$C$21:$L$21/(1+$A24/100)^DCF_Base!$C$4:$L$4)+MAX(0,MIN(DCF_Base!$L$21*(1+B$21/100)/(($A24-B$21)/100),Assumptions!$B$11*DCF_Base!$L$21))/(1+$A24/100)^10-Assumptions!$B$8)/Assumptions!$B$9,"n/a") | C24: =IF($A24>C$21,(SUMPRODUCT(DCF_Base!$C$21:$L$21/(1+$A24/100)^DCF_Base!$C$4:$L$4)+MAX(0,MIN(DCF_Base!$L$21*(1+C$21/100)/(($A24-C$21)/100),Assumptions!$B$11*DCF_Base!$L$21))/(1+$A24/100)^10-Assumptions!$B$8)/Assumptions!$B$9,"n/a") | D24: =IF($A24>D$21,(SUMPRODUCT(DCF_Base!$C$21:$L$21/(1+$A24/100)^DCF_Base!$C$4:$L$4)+MAX(0,MIN(DCF_Base!$L$21*(1+D$21/100)/(($A24-D$21)/100),Assumptions!$B$11*DCF_Base!$L$21))/(1+$A24/100)^10-Assumptions!$B$8)/Assumptions!$B$9,"n/a") | E24: =IF($A24>E$21,(SUMPRODUCT(DCF_Base!$C$21:$L$21/(1+$A24/100)^DCF_Base!$C$4:$L$4)+MAX(0,MIN(DCF_Base!$L$21*(1+E$21/100)/(($A24-E$21)/100),Assumptions!$B$11*DCF_Base!$L$21))/(1+$A24/100)^10-Assumptions!$B$8)/Assumptions!$B$9,"n/a") | F24: =IF($A24>F$21,(SUMPRODUCT(DCF_Base!$C$21:$L$21/(1+$A24/100)^DCF_Base!$C$4:$L$4)+MAX(0,MIN(DCF_Base!$L$21*(1+F$21/100)/(($A24-F$21)/100),Assumptions!$B$11*DCF_Base!$L$21))/(1+$A24/100)^10-Assumptions!$B$8)/Assumptions!$B$9,"n/a")
A25: 14.5 | B25: =IF($A25>B$21,(SUMPRODUCT(DCF_Base!$C$21:$L$21/(1+$A25/100)^DCF_Base!$C$4:$L$4)+MAX(0,MIN(DCF_Base!$L$21*(1+B$21/100)/(($A25-B$21)/100),Assumptions!$B$11*DCF_Base!$L$21))/(1+$A25/100)^10-Assumptions!$B$8)/Assumptions!$B$9,"n/a") | C25: =IF($A25>C$21,(SUMPRODUCT(DCF_Base!$C$21:$L$21/(1+$A25/100)^DCF_Base!$C$4:$L$4)+MAX(0,MIN(DCF_Base!$L$21*(1+C$21/100)/(($A25-C$21)/100),Assumptions!$B$11*DCF_Base!$L$21))/(1+$A25/100)^10-Assumptions!$B$8)/Assumptions!$B$9,"n/a") | D25: =IF($A25>D$21,(SUMPRODUCT(DCF_Base!$C$21:$L$21/(1+$A25/100)^DCF_Base!$C$4:$L$4)+MAX(0,MIN(DCF_Base!$L$21*(1+D$21/100)/(($A25-D$21)/100),Assumptions!$B$11*DCF_Base!$L$21))/(1+$A25/100)^10-Assumptions!$B$8)/Assumptions!$B$9,"n/a") | E25: =IF($A25>E$21,(SUMPRODUCT(DCF_Base!$C$21:$L$21/(1+$A25/100)^DCF_Base!$C$4:$L$4)+MAX(0,MIN(DCF_Base!$L$21*(1+E$21/100)/(($A25-E$21)/100),Assumptions!$B$11*DCF_Base!$L$21))/(1+$A25/100)^10-Assumptions!$B$8)/Assumptions!$B$9,"n/a") | F25: =IF($A25>F$21,(SUMPRODUCT(DCF_Base!$C$21:$L$21/(1+$A25/100)^DCF_Base!$C$4:$L$4)+MAX(0,MIN(DCF_Base!$L$21*(1+F$21/100)/(($A25-F$21)/100),Assumptions!$B$11*DCF_Base!$L$21))/(1+$A25/100)^10-Assumptions!$B$8)/Assumptions!$B$9,"n/a")
A26: 15.5 | B26: =IF($A26>B$21,(SUMPRODUCT(DCF_Base!$C$21:$L$21/(1+$A26/100)^DCF_Base!$C$4:$L$4)+MAX(0,MIN(DCF_Base!$L$21*(1+B$21/100)/(($A26-B$21)/100),Assumptions!$B$11*DCF_Base!$L$21))/(1+$A26/100)^10-Assumptions!$B$8)/Assumptions!$B$9,"n/a") | C26: =IF($A26>C$21,(SUMPRODUCT(DCF_Base!$C$21:$L$21/(1+$A26/100)^DCF_Base!$C$4:$L$4)+MAX(0,MIN(DCF_Base!$L$21*(1+C$21/100)/(($A26-C$21)/100),Assumptions!$B$11*DCF_Base!$L$21))/(1+$A26/100)^10-Assumptions!$B$8)/Assumptions!$B$9,"n/a") | D26: =IF($A26>D$21,(SUMPRODUCT(DCF_Base!$C$21:$L$21/(1+$A26/100)^DCF_Base!$C$4:$L$4)+MAX(0,MIN(DCF_Base!$L$21*(1+D$21/100)/(($A26-D$21)/100),Assumptions!$B$11*DCF_Base!$L$21))/(1+$A26/100)^10-Assumptions!$B$8)/Assumptions!$B$9,"n/a") | E26: =IF($A26>E$21,(SUMPRODUCT(DCF_Base!$C$21:$L$21/(1+$A26/100)^DCF_Base!$C$4:$L$4)+MAX(0,MIN(DCF_Base!$L$21*(1+E$21/100)/(($A26-E$21)/100),Assumptions!$B$11*DCF_Base!$L$21))/(1+$A26/100)^10-Assumptions!$B$8)/Assumptions!$B$9,"n/a") | F26: =IF($A26>F$21,(SUMPRODUCT(DCF_Base!$C$21:$L$21/(1+$A26/100)^DCF_Base!$C$4:$L$4)+MAX(0,MIN(DCF_Base!$L$21*(1+F$21/100)/(($A26-F$21)/100),Assumptions!$B$11*DCF_Base!$L$21))/(1+$A26/100)^10-Assumptions!$B$8)/Assumptions!$B$9,"n/a")
A28: Sanity check: base IV $11.39 implies 15.3x FY2025 SBC-adj P/E (hist avg 19.7x), 2.83x Jun-2026 book (hist max 4.27x), 10.8x EV/EBITDA -- PASS. Price $15.70 = 19.6x P/E and 4.26x P/B, the 10-year book-multiple maximum.
