Workbook

Sheet Summary
A1: SPROUTS FARMERS MARKET (SFM)
A2: DCF Valuation Summary
A3: As of January 12, 2026
A5: COMPANY PROFILE
A6: Industry | B6: Specialty Grocery Retail | C6: Stores | D6: 464+ (24 states)
A7: Business | B7: Natural/Organic Foods | C7: Employees | D7: ~35,000
A8: Key Strengths | B8: Strong brand, health focus, margin expansion
A10: VALUATION SUMMARY
A11: Current Stock Price | B11: ='DCF Model'!B50 -> 77.4 | C11: WACC | D11: =Assumptions!B29 -> 0.081730453
A12: DCF Implied Share Price | B12: ='DCF Model'!B49 -> 126.42131 | C12: Terminal Growth | D12: =Assumptions!B38 -> 0.025
A13: Upside / (Downside) | B13: ='DCF Model'!B51 -> 0.63335027 | C13: Beta | D13: =Assumptions!B19 -> 0.73
A14: Analyst Consensus Target | B14: 130 | C14: Risk-Free Rate | D14: =Assumptions!B17 -> 0.0418
A16: Market Cap ($M) | B16: =Assumptions!B14 -> 7559.658 | C16: FY26 Revenue Growth | D16: =Assumptions!B33 -> 0.12
A17: Enterprise Value ($M) | B17: ='DCF Model'!B44 -> 12066.569 | C17: 5-Yr Rev CAGR | D17: 0.09
A18: Shares Outstanding (M) | B18: =Assumptions!B13 -> 97.67 | C18: Terminal EBITDA Margin | D18: =Assumptions!B46 -> 0.105
A20: KEY VALUATION METRICS
A21: P/E Ratio (TTM) | B21: 15 | C21: Return on Equity | D21: 0.37
A22: EV/EBITDA (TTM) | B22: 9.6 | C22: Profit Margin (TTM) | D22: 0.059
A23: EV/Revenue (TTM) | B23: 1.08 | C23: Debt/Equity | D23: 0.03
A24: Price/Book | B24: 5.4 | C24: Free Cash Flow Yield | D24: 0.059
A26: INVESTMENT THESIS
A27: • Differentiated positioning in growing natural/organic grocery market
A28: • Strong same-store sales growth (5-7%) driven by health-conscious consumers
A29: • Expanding EBITDA margins from operational efficiencies
A30: • Unit growth of ~10% annually with 140+ approved new locations
A31: • Robust free cash flow generation supporting buybacks
A32: • Low debt levels provide financial flexibility
A34: KEY RISKS
A35: • Grocery industry competition (Whole Foods, Kroger, Costco)
A36: • Consumer spending sensitivity in economic downturns
A37: • Inflation impact on food costs and margins
A38: • Execution risk on aggressive store expansion plan
... A42: Sources: Company filings, Yahoo Finance, Bloomberg, analyst reports

Sheet DCF Model
A1: SPROUTS FARMERS MARKET (SFM) - DISCOUNTED CASH FLOW MODEL
A2: ($ in millions, except per share data)
B4: Base Year | C4: Year 1 | D4: Year 2 | E4: Year 3 | F4: Year 4 | G4: Year 5 | H4: Terminal
B5: 2025 | C5: 2026 | D5: 2027 | E5: 2028 | F5: 2029 | G5: 2030 | H5: 2031+
A7: REVENUE PROJECTIONS
A8: Revenue | B8: =Assumptions!B32 -> 8654 | C8: =B8*(1+Assumptions!B33) -> 9692.48 | D8: =C8*(1+Assumptions!B34) -> 10661.728 | E8: =D8*(1+Assumptions!B35) -> 11621.284 | F8: =E8*(1+Assumptions!B36) -> 12550.986 | G8: =F8*(1+Assumptions!B37) -> 13429.555 | H8: =G8*(1+Assumptions!B38) -> 13765.294
A9: Growth Rate | B9: N/A | C9: =Assumptions!B33 -> 0.12 | D9: =Assumptions!B34 -> 0.1 | E9: =Assumptions!B35 -> 0.09 | F9: =Assumptions!B36 -> 0.08 | G9: =Assumptions!B37 -> 0.07 | H9: =Assumptions!B38 -> 0.025
A11: EBITDA CALCULATION
A12: EBITDA Margin | B12: N/A | C12: =Assumptions!B41 -> 0.095 | D12: =Assumptions!B42 -> 0.098 | E12: =Assumptions!B43 -> 0.1 | F12: =Assumptions!B44 -> 0.102 | G12: =Assumptions!B45 -> 0.104 | H12: =Assumptions!B46 -> 0.105
A13: EBITDA | B13: =B8*0.092 -> 796.168 | C13: =C8*C12 -> 920.7856 | D13: =D8*D12 -> 1044.8493 | E13: =E8*E12 -> 1162.1284 | F13: =F8*F12 -> 1280.2006 | G13: =G8*G12 -> 1396.6737 | H13: =H8*H12 -> 1445.3559
A15: FREE CASH FLOW CALCULATION
A16: EBITDA | C16: =C13 -> 920.7856 | D16: =D13 -> 1044.8493 | E16: =E13 -> 1162.1284 | F16: =F13 -> 1280.2006 | G16: =G13 -> 1396.6737 | H16: =H13 -> 1445.3559
A17: Less: D&A | C17: =-C8*Assumptions!B49 -> -290.7744 | D17: =-D8*Assumptions!B49 -> -319.85184 | E17: =-E8*Assumptions!B49 -> -348.63851 | F17: =-F8*Assumptions!B49 -> -376.52959 | G17: =-G8*Assumptions!B49 -> -402.88666 | H17: =-H8*Assumptions!B49 -> -412.95882
A18: EBIT | C18: =C16+C17 -> 630.0112 | D18: =D16+D17 -> 724.9975 | E18: =E16+E17 -> 813.48985 | F18: =F16+F17 -> 903.67101 | G18: =G16+G17 -> 993.78709 | H18: =H16+H17 -> 1032.3971
A19: Less: Taxes | C19: =-C18*Assumptions!B52 -> -157.5028 | D19: =-D18*Assumptions!B52 -> -181.24938 | E19: =-E18*Assumptions!B52 -> -203.37246 | F19: =-F18*Assumptions!B52 -> -225.91775 | G19: =-G18*Assumptions!B52 -> -248.44677 | H19: =-H18*Assumptions!B52 -> -258.09926
A20: EBIAT (NOPAT) | C20: =C18+C19 -> 472.5084 | D20: =D18+D19 -> 543.74813 | E20: =E18+E19 -> 610.11738 | F20: =F18+F19 -> 677.75325 | G20: =G18+G19 -> 745.34032 | H20: =H18+H19 -> 774.29779
A21: Add: D&A | C21: =-C17 -> 290.7744 | D21: =-D17 -> 319.85184 | E21: =-E17 -> 348.63851 | F21: =-F17 -> 376.52959 | G21: =-G17 -> 402.88666 | H21: =-H17 -> 412.95882
A22: Less: CapEx | C22: =-C8*Assumptions!B50 -> -271.38944 | D22: =-D8*Assumptions!B50 -> -298.52838 | E22: =-E8*Assumptions!B50 -> -325.39594 | F22: =-F8*Assumptions!B50 -> -351.42761 | G22: =-G8*Assumptions!B50 -> -376.02755 | H22: =-H8*Assumptions!B50 -> -385.42824
A23: Less: Change in NWC | C23: =-(C8-B8)*Assumptions!B51 -> -20.7696 | D23: =-(D8-C8)*Assumptions!B51 -> -19.38496 | E23: =-(E8-D8)*Assumptions!B51 -> -19.19111 | F23: =-(F8-E8)*Assumptions!B51 -> -18.594054 | G23: =-(G8-F8)*Assumptions!B51 -> -17.571381 | H23: =-(H8-G8)*Assumptions!B51 -> -6.7147776
A24: Unlevered Free Cash Flow | C24: =SUM(C20:C23) -> 471.12376 | D24: =SUM(D20:D23) -> 545.68662 | E24: =SUM(E20:E23) -> 614.16884 | F24: =SUM(F20:F23) -> 684.26117 | G24: =SUM(G20:G23) -> 754.62805
A26: DCF VALUATION
A27: WACC | B27: =Assumptions!B29 -> 0.081730453
A28: Terminal Growth Rate | B28: =Assumptions!B38 -> 0.025
A30: Discount Period | C30: 0.5 | D30: 1.5 | E30: 2.5 | F30: 3.5 | G30: 4.5
A31: Discount Factor | C31: =1/((1+$B$27)^C30) -> 0.96148048 | D31: =1/((1+$B$27)^D30) -> 0.88883555 | E31: =1/((1+$B$27)^E30) -> 0.82167932 | F31: =1/((1+$B$27)^F30) -> 0.75959711 | G31: =1/((1+$B$27)^G30) -> 0.70220553
A32: Present Value of FCF | C32: =C24*C31 -> 452.9763 | D32: =D24*D31 -> 485.02567 | E32: =E24*E31 -> 504.64984 | F32: =F24*F31 -> 519.76281 | G32: =G24*G31 -> 529.90399
A34: Sum of PV of FCFs | B34: =SUM(C32:G32) -> 2492.3186
A36: TERMINAL VALUE CALCULATION
A37: Terminal Year FCF | B37: =G24*(1+B28) -> 773.49375
A38: Terminal Value (Gordon Growth) | B38: =B37/(B27-B28) -> 13634.542
A39: PV of Terminal Value | B39: =B38*G31 -> 9574.2508
A41: ENTERPRISE VALUE TO EQUITY VALUE
A42: PV of Forecast FCFs | B42: =B34 -> 2492.3186
A43: PV of Terminal Value | B43: =B39 -> 9574.2508
A44: Enterprise Value | B44: =B42+B43 -> 12066.569
A45: Less: Total Debt | B45: =Assumptions!B24 -> 41
A46: Add: Cash | B46: 322
A47: Equity Value | B47: =B44-B45+B46 -> 12347.569
A48: Shares Outstanding (M) | B48: =Assumptions!B13 -> 97.67
A49: Implied Share Price | B49: =B47/B48 -> 126.42131
...

Sheet Assumptions
A1: SPROUTS FARMERS MARKET (SFM) - DCF ASSUMPTIONS
A3: Company Information
A4: Company Name | B4: Sprouts Farmers Market, Inc.
A5: Ticker | B5: SFM
A6: Exchange | B6: NASDAQ
A7: Sector | B7: Consumer Defensive
A8: Industry | B8: Specialty Grocery Retail
A9: Valuation Date | B9: January 12, 2026
A11: Market Data
A12: Current Stock Price ($) | B12: 77.4 | C12: Source: NASDAQ, Jan 2026
A13: Shares Outstanding (M) | B13: 97.67 | C13: Source: Company filings Q3 2025
A14: Market Cap ($M) | B14: =B12*B13 -> 7559.658
A16: WACC Assumptions
A17: Risk-Free Rate | B17: 0.0418 | C17: 10-Year Treasury Yield, Jan 2026
A18: Equity Risk Premium | B18: 0.055 | C18: Historical average
A19: Beta (5Y Monthly) | B19: 0.73 | C19: Source: Yahoo Finance
A20: Cost of Equity | B20: =B17+B19*B18 -> 0.08195 | C20: CAPM: Rf + Beta * ERP
A21: Cost of Debt (Pre-tax) | B21: 0.055 | C21: Estimated based on credit facility
A22: Tax Rate | B22: 0.25 | C22: Effective tax rate ~25%
A23: Cost of Debt (After-tax) | B23: =B21*(1-B22) -> 0.04125
A24: Debt ($M) | B24: 41 | C24: Long-term debt ex. operating leases
A25: Equity Value ($M) | B25: =B14 -> 7559.658
A26: Total Capital ($M) | B26: =B24+B25 -> 7600.658
A27: Debt Weight | B27: =B24/B26 -> 0.0053942698
A28: Equity Weight | B28: =B25/B26 -> 0.99460573
A29: WACC | B29: =B27*B23+B28*B20 -> 0.081730453
A31: Growth Assumptions
A32: Base Year Revenue ($M) | B32: 8654 | C32: TTM as of Sep 2025
A33: Year 1 Revenue Growth | B33: 0.12 | C33: Analyst consensus ~12%
A34: Year 2 Revenue Growth | B34: 0.1
A35: Year 3 Revenue Growth | B35: 0.09
A36: Year 4 Revenue Growth | B36: 0.08
A37: Year 5 Revenue Growth | B37: 0.07
A38: Terminal Growth Rate | B38: 0.025 | C38: Long-term GDP growth proxy
A40: Margin Assumptions
A41: EBITDA Margin Year 1 | B41: 0.095 | C41: Expanding from 9.2% TTM
A42: EBITDA Margin Year 2 | B42: 0.098
A43: EBITDA Margin Year 3 | B43: 0.1
A44: EBITDA Margin Year 4 | B44: 0.102
A45: EBITDA Margin Year 5 | B45: 0.104
...

Sheet Historical Financials
A1: HISTORICAL FINANCIALS ($ in millions)
A3: Metric | B3: FY2020 | C3: FY2021 | D3: FY2022 | E3: FY2023 | F3: FY2024
A4: Revenue | B4: 6100 | C4: 6404 | D4: 6404 | E4: 6837 | F4: 7719
A5: Revenue Growth % | C5: 5.0% | D5: 0.0% | E5: 6.8% | F5: 12.9%
A6: Cost of Revenue | B6: 3891 | C6: 4056 | D6: 4056 | E6: 4316 | F6: 4778
A7: Gross Profit | B7: 2209 | C7: 2349 | D7: 2349 | E7: 2522 | F7: 2941
A8: Gross Margin % | B8: 36.2% | C8: 36.7% | D8: 36.7% | E8: 36.9% | F8: 38.1%
A9: Operating Expenses | B9: 1870 | C9: 1979 | D9: 1979 | E9: 2132 | F9: 2424
A10: Operating Income | B10: 339 | C10: 369 | D10: 369 | E10: 390 | F10: 517
A11: Operating Margin % | B11: 5.6% | C11: 5.8% | D11: 5.8% | E11: 5.7% | F11: 6.7%
A12: Net Income | B12: 244 | C12: 261 | D12: 261 | E12: 259 | F12: 381
A13: Net Margin % | B13: 4.0% | C13: 4.1% | D13: 4.1% | E13: 3.8% | F13: 4.9%
A15: EBITDA (Est.) | B15: 500 | C15: 530 | D15: 530 | E15: 560 | F15: 680
A16: EBITDA Margin % | B16: 8.2% | C16: 8.3% | D16: 8.3% | E16: 8.2% | F16: 8.8%
A19: Cash Flow Statement
A20: Metric | B20: FY2020 | C20: FY2021 | D20: FY2022 | E20: FY2023 | F20: FY2024
A21: Operating Cash Flow | B21: 454 | C21: 383 | D21: 383 | E21: 425 | F21: 645
A22: CapEx (net) | B22: 120 | C22: 130 | D22: 155 | E22: 185 | F22: 200
A23: Free Cash Flow | B23: 334 | C23: 253 | D23: 228 | E23: 240 | F23: 445
A26: Balance Sheet Highlights
A27: Metric | B27: FY2020 | C27: FY2021 | D27: FY2022 | E27: FY2023 | F27: FY2024
A28: Cash & Equivalents | B28: 170 | C28: 245 | D28: 293 | E28: 202 | F28: 265
A29: Total Assets | B29: 2806 | C29: 2923 | D29: 3070 | E29: 3327 | F29: 3641
A30: Total Debt (incl. leases) | B30: 1478 | C30: 1514 | D30: 1541 | E30: 1661 | F30: 1679
A31: Long-term Debt (ex. leases) | B31: 256 | C31: 250 | D31: 250 | E31: 125 | F31: 0
A32: Shareholders Equity | B32: 881 | C32: 960 | D32: 1046 | E32: 1149 | F32: 1322
A33: Shares Outstanding (M) | B33: 118 | C33: 111 | D33: 105 | E33: 101 | F33: 99
A36: Sources: Company 10-K filings, Yahoo Finance, MacroTrends
