Workbook

Sheet Model_Info
A1: ADYEN (ADYEN.AS) - OWNER-FCF DCF MODEL
A3: Lineage | B3: v1.0, built 9-Aug-2026 by Claude (Opus 5) with Stephen via claude.ai, using the tech-dcf-workbook engine (openpyxl; recalculated in LibreOffice; key outputs hand-checked). Supersedes nothing in this file's lineage - BUT a prior Adyen 3-scenario workbook was built in Jul-2026 (ADR basis, ~$9.45/ADR) and was NOT available to this session. Scenario paths here were constructed fresh from the post-checkpoint architecture, NOT carried over. RECONCILE against the July file before treating any change in value as new information.
A5: DATA VINTAGE
A6: FY0 anchors (FY2025) | B6: Net revenue EUR2,364.2m, reported EBITDA EUR1,245.7m (52.7%), FCF conversion 87%, capex 5% of net revenue. Source: Adyen H2 2025 results release + shareholder letter, adyen.com, 12-Feb-2026.
A7: FY1 guidance (2026) | B7: 20-22% net revenue growth on a CONSTANT-CURRENCY basis; EBITDA margin broadly in line with 2025; capex up to 5% of net revenue; >55% EBITDA margin by 2028. Reiterated at Q1 2026 business update, 6-May-2026. Investor Day 11-Nov-2025: ~20% annual net revenue growth in the years after 2026.
A8: Latest actuals | B8: Q1 2026 business update 6-May-2026: net revenue EUR620.8m, +16% reported / +20% cc; processed volume EUR382.0bn +21%; Digital EUR349.6m +13%cc, Unified Commerce EUR196.2m +28%cc, Platforms EUR75.0m +40%cc.
A9: Income-statement structure | B9: FY2025 IFRS: operating income EUR1,096.3m; net non-operating interest income EUR272.6m; pre-tax EUR1,368.9m; net income EUR1,062.5m -> effective tax 22.4%. Source: Yahoo Finance ADYEN.AS income statement (S&P Global Market Intelligence), read 9-Aug-2026. CONFIRMS float income sits BELOW operating income.
A10: Balance sheet / shares / price | B10: Total equity EUR4.23bn at 31-Dec-2024 (TipRanks/S&P); +EUR1.06bn FY25 net income, no dividend or buyback -> ~EUR5.2-5.3bn at 31-Dec-2025. Owner net cash here is an ESTIMATE of EUR4.2bn at 1-Jul-2026 after ~EUR1.04bn cash spent on Talon.One (EUR750m) and Orb ($335m), both closed 1-Jul-2026. Shares 31.55m. Price EUR933.20, Amsterdam close 7-Aug-2026.
A11: KNOWN GAPS - fix at H1 print | B11: (a) SBC % of net revenue is an ESTIMATE of 3.0%, inferred from ~1.1% annual share-count growth and low reported SBC history; replace from the share-based payments note. (b) Owner net cash is an ESTIMATE; replace with the reported H1-2026 balance sheet, taking own funds only and EXCLUDING merchant funds in transit. (c) Diluted share count: replace with the H1 letter figure.
A13: METHODOLOGY
A14: Owner-FCF basis | B14: SBC fully expensed and projected explicitly per scenario-year as % of net revenue; cash tax normalized; D&A and capex as % of net revenue; working capital neutral; diluted shares held FLAT (SBC expensing substitutes for grant dilution - never do both). TV = Gordon capped at 20x terminal owner FCF. End-of-year discounting, 10-year explicit horizon. WACC 10.5%. Street-convention values (SBC as non-cash) shown as memos - the house/street pair is the accounting-regime price band.
A15: IFRS SBC adjustment | B15: IMPORTANT AND EASY TO MISREAD. Under IFRS, Adyen's share-based payment expense sits inside operating expenses, so the reported 52.7% FY25 EBITDA margin is ALREADY net of SBC - unlike US-GAAP tech names where non-GAAP EBITDA adds SBC back. Row 7 of each DCF tab is therefore fed the PRE-SBC margin (reported margin + SBC%), so that row 11 ('EBITDA less SBC') reproduces the reported figure. Feeding the reported 52.7% into row 7 would double-count SBC and understate value. Row 7 minus row 9 = the margin management actually guides to.
A16: Float income (separate) | B16: The house rule excludes interest income from flows because the cash pile is added separately as net cash. Adyen is the exception that proves it: most of the EUR272.6m FY25 net interest income is earned on MERCHANT funds in transit - a liability, not owner cash - so excluding it while adding only owner net cash would delete the stream. It is instead valued on its own Float_Income tab (after-tax, discounted at the same WACC, terminal value capped at 12x - a tighter cap than the operating 20x because the stream is rate-dependent and lower quality) and added to net cash on row 35 of each DCF tab. No double count: owner net cash on Assumptions excludes merchant funds entirely. Screeners that show ~EUR12.4bn 'net cash' for Adyen are counting merchant float and understate EV by roughly EUR8bn.
A17: Net revenue, not IFRS revenue | B17: Revenue driver is Adyen's non-IFRS 'net revenue' (settlement + processing + other services, net of costs incurred from financial institutions) - the measure management guides on and the denominator of the take rate. FY25 IFRS revenue was EUR2,646.9m; net revenue EUR2,364.2m.
A18: Cash tax | B18: FY25 effective rate 22.4% (Dutch statutory 25.8%, reduced by innovation-box style relief). The engine's default 'ramp to ~21%' is a US-federal convention and does NOT apply here; the rate is instead ramped UP toward 25.0-25.8% on the view that the relief narrows. D&A excludes amortisation of acquired Talon.One/Orb intangibles, which is largely non-deductible - including it would overstate the tax shield.
A19: Growth is REPORTED, not cc | B19: Row 5 of each DCF tab is reported EUR growth. Management guides in constant currency. Q1 2026 was +20% cc but +16% reported - a 4pp FX drag. Base FY26 of 18% reported implies roughly 20-21% cc, i.e. the low end of the 20-22% guide. Do not compare row 5 directly to guidance without adding back the FX drag.
A20: Scenario drivers | B20: Scenario architecture proposed by Claude on 9-Aug-2026 from the same-day deep dive and signed off by Stephen unchanged, at house 15/50/35 weights. Stephen flagged two calls as contestable and delegated them: (i) weights - house 15/50/35 retained rather than shifting to 20/50/30, because the bear path itself was hardened instead (growth fades to 3%, margin to 46%, float halves), which is the cleaner way to express that guidance has already drifted three times; (ii) the Talon.One/Orb acquisitions - placed in Base as mildly accretive from 2027 (+1-2pp growth, small near-term margin drag) AND as an explicit moat-erosion driver in Bear, rather than as a blanket discount, so the character-change risk is priced through the scenario weights rather than hidden in a haircut.
A22: UPDATE INSTRUCTIONS
A23: At the H1 2026 print (13-Aug-26) | B23: Refresh price, owner net cash (+date, merchant funds excluded), diluted shares, and the FY26 driver columns. The three things that should move drivers: (1) H1 constant-currency growth - at or below 20% is a FOURTH guidance disappointment and argues for shifting weight to Bear, not just trimming Base; (2) H1 take rate vs 16.85bps in H1'25 - the eBay mix tailwind is largely lapped, so continued expansion is the single best evidence the Bull monetisation path is real; (3) H1 reported EBITDA margin vs 50% in H1'25, and whether the >55%-by-2028 objective is reiterated. Also replace the two estimated inputs flagged in KNOWN GAPS above.
A24: Conventions | B24: Blue = hardcoded input. Yellow fill = key lever. Black = formula. Green = cross-sheet link. Amber fill = a judgment or estimate that needs replacing with reported data. All amounts EURm unless stated.
A26: NOT INVESTMENT ADVICE | B26: This is Stephen's own valuation framework computed at the inputs above. Every scenario path is a judgment, not a forecast.

Sheet Actuals_Data
A1: ADYEN - reported actuals and guidance (all blue = as reported)
A2: EURm unless stated. Sources named per block. Nothing on this tab is a Claude estimate unless marked ESTIMATE.
A4: Full-year history | B4: FY2023 | C4: FY2024 | D4: FY2025 | G4: Source
A5: Net revenue (non-IFRS) | B5: 1626.1 | C5: 1996.1 | D5: 2364.2 | G5: H2'23/H2'24/H2'25 results releases, adyen.com
A6: Net revenue growth, reported | C6: 0.228 | D6: 0.184 | G6: computed
A7: Net revenue growth, constant currency | C7: 0.23 | D7: 0.21 | G7: as disclosed
A8: Processed volume (EURbn) | B8: 970 | C8: 1285.9 | D8: 1394.3 | G8: results releases
A9: Volume growth ex single large customer | C9: 0.27 | D9: 0.21 | G9: as disclosed (eBay unwind distorts headline)
A10: Take rate (bps) = net rev / volume | B10: =B5/B8*10 -> 16.763918 | C10: =C5/C8*10 -> 15.52298 | D10: =D5/D8*10 -> 16.956179 | G10: computed below
A11: Reported EBITDA | B11: 742.6 | C11: 992.3 | D11: 1245.7 | G11: results releases
A12: Reported EBITDA margin | B12: 0.457 | C12: 0.497 | D12: 0.527 | G12: as disclosed (46% / 50% / 53%)
A13: IFRS operating income | B13: 681.8 | C13: 872.5 | D13: 1096.3 | G13: Yahoo Finance ADYEN.AS income stmt (S&P Global MI), 9-Aug-26
A14: Net non-operating interest income (float) | B14: 241.6 | C14: 350.1 | D14: 272.6 | G14: same - NOTE: sits BELOW operating income
A15: Net income | B15: 698.3 | C15: 925.2 | D15: 1062.5 | G15: same
A16: Effective tax rate | D16: 0.224 | G16: computed: 1 - NI / (op income + float)
A17: Capex, % of net revenue | B17: 0.04 | C17: 0.05 | D17: 0.05 | G17: as disclosed
A18: FCF conversion (company definition) | C18: 0.87 | D18: 0.87 | G18: as disclosed
A20: Half-year and quarterly detail
B21: H1 2025 | C21: H2 2025 | D21: Q1 2026 | G21: Source
A22: Net revenue | B22: 1093.5 | C22: 1270.7 | D22: 620.8 | G22: H1'25 / H2'25 releases; Q1'26 business update 6-May-26
A23: Growth, reported | B23: 0.2 | C23: 0.17 | D23: 0.16 | G23: as disclosed
A24: Growth, constant currency | B24: 0.2 | C24: 0.21 | D24: 0.2 | G24: as disclosed
A25: Processed volume (EURbn) | B25: 649 | C25: 745.3 | D25: 382 | G25: as disclosed
A26: Take rate (bps) | B26: 16.85 | C26: 17.06 | D26: 16.25 | G26: computed; H1'24 was 14.74bps - expansion driven by eBay mix exit
A27: Reported EBITDA margin | B27: 0.5 | C27: 0.55 | G27: as disclosed; H2 margin is structurally above H1
A28: Digital net revenue | B28: 638.9 | D28: 349.6 | G28: segment disclosure
A29: Unified Commerce net revenue | D29: 196.2 | G29: segment disclosure
A30: Platforms net revenue | D30: 75 | G30: segment disclosure; +40% cc, fastest-growing pillar
A32: Guidance in force (reiterated at Q1 2026, 6-May-2026)
A33: 2026 net revenue growth (constant currency) | B33: 20% to 22% | G33: H2'25 release 12-Feb-26, reiterated 6-May-26
A34: 2026 EBITDA margin | B34: broadly in line with 2025 (~53%) | G34: same; H2 margin above H1 as usual
A35: EBITDA margin objective | B35: above 55% by 2028 | G35: raised at Investor Day 11-Nov-25 from >50% by 2026
A36: Capex | B36: up to 5% of net revenue | G36: same
A37: Net revenue growth, years after 2026 | B37: approximately 20% annually | G37: Investor Day 11-Nov-25
A38: 2026 net new hires | B38: 550 to 650 | G38: H2'25 shareholder letter
A40: Balance sheet, shares, price
A41: Total equity, 31-Dec-2024 | B41: 4230 | G41: TipRanks / S&P Global MI
A42: FY2025 net income (no dividend, no buyback) | B42: 1062.5 | G42: implies ~EUR5.2-5.3bn equity at 31-Dec-25
A43: Talon.One consideration | B43: 750 | G43: announced 23-Apr-26, closed 1-Jul-26, funded from cash
A44: Orb consideration (~$335m) | B44: 285 | G44: announced 11-Jun-26, closed 1-Jul-26, funded from cash
...

Sheet Assumptions
A1: ADYEN.AS - Global Assumptions & Scenario Parameters
A2: Blue = hardcoded input. Yellow = key lever. All amounts EURm unless stated.
A4: Global inputs
A5: WACC / discount rate | B5: 0.105 | H5: House default for this risk class. Beta ~1.86 argues higher; net cash and A- rating argue lower.
A6: D&A (% of net revenue) | B6: 0.06 | H6: FY25 actual 6.3%. Excludes acquired-intangible amortisation (largely non-deductible).
A7: Capex (% of net revenue) | B7: 0.05 | H7: Guided and actual: up to 5%. Data centres and infrastructure.
A8: Working-capital capture (% of YoY rev incr.) | B8: 0 | H8: ZERO by design. Adyen deducts its fees at settlement, so fee-business WC is near-neutral. Merchant funds in transit are a LIABILITY and are excluded entirely - they show up only as the float-income stream.
A9: Owner net cash (EURm) | B9: 4200 | H9: OWNER net cash est. at 1-Jul-26, post Talon.One+Orb. Excludes merchant funds in transit - see Actuals_Data
A10: Shares (mm) | B10: 31.55 | H10: shares outstanding, stockanalysis.com/Morningstar, Jul-26; replace with H1'26 diluted count
A11: Current share price (EUR) | B11: 933.2 | H11: Euronext Amsterdam regular close 7-Aug-2026 (Yahoo/Morningstar). H1 print 13-Aug-26
A12: Terminal value cap (x terminal owner FCF) | B12: 20 | H12: House standard.
A13: Float terminal cap (x terminal after-tax float) | B13: 12 | H13: Tighter than the operating cap: the float stream is rate-dependent and lower quality.
A15: Scenario parameters | C15: Bear | D15: Base | E15: Bull
A16: Terminal growth rate | C16: 0.015 | D16: 0.03 | E16: 0.035
A17: Probability weight | C17: 0.15 | D17: 0.5 | E17: 0.35 | F17: =SUM(C17:E17) -> 1 | G17: must sum to 100%
A19: Scenario narratives
A20: Bear | B20: The take-rate expansion of 2024-25 was a mix artifact - low-take-rate eBay volume leaving, not pricing power. Once that comp laps, North American price competition from Stripe and the Braintree/PayPal complex compresses the markup. Guidance drifts a fourth time. Talon.One and Orb integration consumes management attention and the single-platform simplicity that was the whole moat starts to fray. Growth fades to low single digits; reported EBITDA margin peaks and slides to 46%; SBC creeps up to retain people under pressure; ECB normalisation halves the float stream.
A21: Base | B21: 2026 lands at the low end of the 20-22% constant-currency guide (~18% reported after FX drag). Wallet-share expansion with existing enterprise customers plus the 2025 cohort ramp carries ~20% cc for two more years, then fades toward high single digits as the base gets large. Management hits its >55% EBITDA margin objective in 2028 and grinds to ~57%. Talon.One and Orb add 1-2pp of growth from 2027 and are mildly margin-dilutive first. Float income roughly flat: volume growth offsets falling rates.
A22: Bull | B22: Embedded financial products inflect - issuing volumes already grew 8x in 2025 and Platforms is compounding at ~40%. Take rate keeps climbing on genuine monetisation (Uplift, Dynamic Identification, now promotions and billing) rather than mix, toward 18-19bps. Adyen Agentic becomes the enterprise adapter across UCP/ACP/AP2, so agentic commerce arrives as incremental volume rather than disintermediation. Operating leverage on a single platform takes reported EBITDA margin past 60%; float income grows with volume and balances.

Sheet DCF_Bear
A1: ADYEN.AS DCF - Bear - mix tailwind exhausts; NA price pressure
A2: Owner-FCF basis: SBC fully expensed, float income valued separately (Float_Income tab), share count flat. Blue rows = per-year drivers. Row 7 is PRE-SBC margin; row 7 less row 9 = the reported margin management guides to.
B3: 2025A | C3: 2026E | D3: 2027E | E3: 2028E | F3: 2029E | G3: 2030E | H3: 2031E | I3: 2032E | J3: 2033E | K3: 2034E | L3: 2035E
A4: Year index (for discounting) | B4: 0 | C4: 1 | D4: 2 | E4: 3 | F4: 4 | G4: 5 | H4: 6 | I4: 7 | J4: 8 | K4: 9 | L4: 10
A5: Net revenue growth YoY (REPORTED EUR) | C5: 0.15 | D5: 0.11 | E5: 0.09 | F5: 0.07 | G5: 0.06 | H5: 0.05 | I5: 0.04 | J5: 0.04 | K5: 0.03 | L5: 0.03
A6: Net revenue | B6: 2364.2 | C6: =B6*(1+C5) -> 2718.83 | D6: =C6*(1+D5) -> 3017.9013 | E6: =D6*(1+E5) -> 3289.5124 | F6: =E6*(1+F5) -> 3519.7783 | G6: =F6*(1+G5) -> 3730.965 | H6: =G6*(1+H5) -> 3917.5132 | I6: =H6*(1+I5) -> 4074.2138 | J6: =I6*(1+J5) -> 4237.1823 | ... L6: =K6*(1+L5) -> 4495.2267
A7: EBITDA margin, PRE-SBC | B7: 0.557 | C7: 0.55 | D7: 0.542 | E7: 0.534 | F7: 0.525 | G7: 0.516 | H7: 0.517 | I7: 0.508 | J7: 0.508 | K7: 0.499 | L7: 0.5
A8: EBITDA, pre-SBC | C8: =C6*C7 -> 1495.3565 | D8: =D6*D7 -> 1635.7025 | E8: =E6*E7 -> 1756.5996 | F8: =F6*F7 -> 1847.8836 | G8: =G6*G7 -> 1925.1779 | H8: =H6*H7 -> 2025.3543 | I8: =I6*I7 -> 2069.7006 | J8: =J6*J7 -> 2152.4886 | ... L8: =L6*L7 -> 2247.6134
A9: SBC (% of net revenue) | B9: 0.03 | C9: 0.03 | D9: 0.032 | E9: 0.034 | F9: 0.035 | G9: 0.036 | H9: 0.037 | I9: 0.038 | J9: 0.038 | K9: 0.039 | L9: 0.04
A10: SBC | C10: =-C6*C9 -> -81.5649 | D10: =-D6*D9 -> -96.572842 | E10: =-E6*E9 -> -111.84342 | F10: =-F6*F9 -> -123.19224 | G10: =-G6*G9 -> -134.31474 | H10: =-H6*H9 -> -144.94799 | I10: =-I6*I9 -> -154.82012 | J10: =-J6*J9 -> -161.01293 | ... L10: =-L6*L9 -> -179.80907
A11: Reported EBITDA (post-SBC, = guided measure) | C11: =C8+C10 -> 1413.7916 | D11: =D8+D10 -> 1539.1297 | E11: =E8+E10 -> 1644.7562 | F11: =F8+F10 -> 1724.6914 | G11: =G8+G10 -> 1790.8632 | H11: =H8+H10 -> 1880.4064 | I11: =I8+I10 -> 1914.8805 | J11: =J8+J10 -> 1991.4757 | ... L11: =L8+L10 -> 2067.8043
A12: D&A | C12: =-C6*Assumptions!$B$6 -> -163.1298 | D12: =-D6*Assumptions!$B$6 -> -181.07408 | E12: =-E6*Assumptions!$B$6 -> -197.37075 | F12: =-F6*Assumptions!$B$6 -> -211.1867 | G12: =-G6*Assumptions!$B$6 -> -223.8579 | H12: =-H6*Assumptions!$B$6 -> -235.05079 | I12: =-I6*Assumptions!$B$6 -> -244.45283 | J12: =-J6*Assumptions!$B$6 -> -254.23094 | ... L12: =-L6*Assumptions!$B$6 -> -269.7136
A13: EBIT (SBC expensed) | C13: =C11+C12 -> 1250.6618 | D13: =D11+D12 -> 1358.0556 | E13: =E11+E12 -> 1447.3855 | F13: =F11+F12 -> 1513.5047 | G13: =G11+G12 -> 1567.0053 | H13: =H11+H12 -> 1645.3556 | I13: =I11+I12 -> 1670.4276 | J13: =J11+J12 -> 1737.2447 | ... L13: =L11+L12 -> 1798.0907
A14: Cash tax rate | C14: 0.23 | D14: 0.238 | E14: 0.245 | F14: 0.25 | G14: 0.255 | H14: 0.258 | I14: 0.258 | J14: 0.258 | K14: 0.258 | L14: 0.258
A15: NOPAT | C15: =C13*(1-C14) -> 963.00959 | D15: =D13*(1-D14) -> 1034.8384 | E15: =E13*(1-E14) -> 1092.776 | F15: =F13*(1-F14) -> 1135.1285 | G15: =G13*(1-G14) -> 1167.4189 | H15: =H13*(1-H14) -> 1220.8538 | I15: =I13*(1-I14) -> 1239.4573 | J15: =J13*(1-J14) -> 1289.0356 | ... L15: =L13*(1-L14) -> 1334.1833
A16: add: D&A | C16: =-C12 -> 163.1298 | D16: =-D12 -> 181.07408 | E16: =-E12 -> 197.37075 | F16: =-F12 -> 211.1867 | G16: =-G12 -> 223.8579 | H16: =-H12 -> 235.05079 | I16: =-I12 -> 244.45283 | J16: =-J12 -> 254.23094 | ... L16: =-L12 -> 269.7136
A17: less: capex | C17: =-C6*Assumptions!$B$7 -> -135.9415 | D17: =-D6*Assumptions!$B$7 -> -150.89506 | E17: =-E6*Assumptions!$B$7 -> -164.47562 | F17: =-F6*Assumptions!$B$7 -> -175.98891 | G17: =-G6*Assumptions!$B$7 -> -186.54825 | H17: =-H6*Assumptions!$B$7 -> -195.87566 | I17: =-I6*Assumptions!$B$7 -> -203.71069 | J17: =-J6*Assumptions!$B$7 -> -211.85912 | ... L17: =-L6*Assumptions!$B$7 -> -224.76134
A18: add: working capital | C18: =Assumptions!$B$8*(C6-B6) -> 0 | D18: =Assumptions!$B$8*(D6-C6) -> 0 | E18: =Assumptions!$B$8*(E6-D6) -> 0 | F18: =Assumptions!$B$8*(F6-E6) -> 0 | G18: =Assumptions!$B$8*(G6-F6) -> 0 | H18: =Assumptions!$B$8*(H6-G6) -> 0 | I18: =Assumptions!$B$8*(I6-H6) -> 0 | J18: =Assumptions!$B$8*(J6-I6) -> 0 | ... L18: =Assumptions!$B$8*(L6-K6) -> 0
A19: Unlevered owner FCF (operating only) | C19: =C15+C16+C17+C18 -> 990.19789 | D19: =D15+D16+D17+D18 -> 1065.0174 | E19: =E15+E16+E17+E18 -> 1125.6711 | F19: =F15+F16+F17+F18 -> 1170.3263 | G19: =G15+G16+G17+G18 -> 1204.7286 | H19: =H15+H16+H17+H18 -> 1260.029 | I19: =I15+I16+I17+I18 -> 1280.1994 | J19: =J15+J16+J17+J18 -> 1331.4074 | ... L19: =L15+L16+L17+L18 -> 1379.1356
A20: Discount factor | C20: =1/(1+Assumptions!$B$5)^C4 -> 0.90497738 | D20: =1/(1+Assumptions!$B$5)^D4 -> 0.81898405 | E20: =1/(1+Assumptions!$B$5)^E4 -> 0.74116204 | F20: =1/(1+Assumptions!$B$5)^F4 -> 0.67073487 | G20: =1/(1+Assumptions!$B$5)^G4 -> 0.60699989 | H20: =1/(1+Assumptions!$B$5)^H4 -> 0.54932116 | I20: =1/(1+Assumptions!$B$5)^I4 -> 0.49712323 | J20: =1/(1+Assumptions!$B$5)^J4 -> 0.44988527 | ... L20: =1/(1+Assumptions!$B$5)^L4 -> 0.36844886
A21: PV of FCF | C21: =C19*C20 -> 896.10668 | D21: =D19*D20 -> 872.23224 | E21: =E19*E20 -> 834.30472 | F21: =F19*F20 -> 784.97865 | G21: =G19*G20 -> 731.27012 | H21: =H19*H20 -> 692.16057 | I21: =I19*I20 -> 636.41688 | J21: =J19*J20 -> 598.98059 | ... L21: =L19*L20 -> 508.14093
A23: Memo: reported EBITDA margin (row 11 / row 6) | C23: =C11/C6 -> 0.52 | D23: =D11/D6 -> 0.51 | E23: =E11/E6 -> 0.5 | F23: =F11/F6 -> 0.49 | G23: =G11/G6 -> 0.48 | H23: =H11/H6 -> 0.48 | I23: =I11/I6 -> 0.47 | J23: =J11/J6 -> 0.47 | ... L23: =L11/L6 -> 0.46
A24: Memo: implied owner FCF margin | C24: =C19/C6 -> 0.3642 | D24: =D19/D6 -> 0.3529 | E24: =E19/E6 -> 0.3422 | F24: =F19/F6 -> 0.3325 | G24: =G19/G6 -> 0.3229 | H24: =H19/H6 -> 0.32164 | I24: =I19/I6 -> 0.31422 | J24: =J19/J6 -> 0.31422 | ... L24: =L19/L6 -> 0.3068
A25: Valuation
A26: PV of FCF, explicit years | B26: =SUM(C21:L21) -> 7099.7329
A27: Terminal growth rate | B27: =Assumptions!$C$16 -> 0.015
A28: Terminal-year owner FCF x (1+g) | B28: =L19*(1+B27) -> 1399.8226
A29: Terminal value - Gordon | B29: =B28/(Assumptions!$B$5-B27) -> 15553.584
A30: Terminal value - cap | B30: =Assumptions!$B$12*L19 -> 27582.711
A31: Terminal value used (lower of the two) | B31: =MIN(B29,B30) -> 15553.584
A32: Implied exit multiple | B32: =B31/L19 -> 11.277778
A33: PV of terminal value | B33: =B31*L20 -> 5730.7004
A34: Enterprise value, operating business | B34: =B26+B33 -> 12830.433
A35: add: owner net cash + PV of float stream | B35: =Assumptions!$B$9+Float_Income!$B$17 -> 5188.0465
A36: Equity value | B36: =B34+B35 -> 18018.48
A37: Shares (mm) | B37: =Assumptions!$B$10 -> 31.55
A38: Value per share | B38: =B36/B37 -> 571.10871
A39: Upside / (downside) vs current price | B39: =B38/Assumptions!$B$11-1 -> -0.38801038
A41: Memo: value if SBC treated as non-cash | B41: =SUMPRODUCT(-C10:L10/(1+Assumptions!$B$5)^C4:L4) -> 764.53158
A42: plus PV of terminal SBC | B42: =(-L10*(1+B27)/(Assumptions!$B$5-B27))*L20 -> 747.15782
...

Sheet DCF_Base
A1: ADYEN.AS DCF - Base - guide holds at the low end; margin reaches 55%+ by 2028
A2: Owner-FCF basis: SBC fully expensed, float income valued separately (Float_Income tab), share count flat. Blue rows = per-year drivers. Row 7 is PRE-SBC margin; row 7 less row 9 = the reported margin management guides to.
B3: 2025A | C3: 2026E | D3: 2027E | E3: 2028E | F3: 2029E | G3: 2030E | H3: 2031E | I3: 2032E | J3: 2033E | K3: 2034E | L3: 2035E
A4: Year index (for discounting) | B4: 0 | C4: 1 | D4: 2 | E4: 3 | F4: 4 | G4: 5 | H4: 6 | I4: 7 | J4: 8 | K4: 9 | L4: 10
A5: Net revenue growth YoY (REPORTED EUR) | C5: 0.18 | D5: 0.17 | E5: 0.16 | F5: 0.15 | G5: 0.13 | H5: 0.12 | I5: 0.11 | J5: 0.1 | K5: 0.09 | L5: 0.08
A6: Net revenue | B6: 2364.2 | C6: =B6*(1+C5) -> 2789.756 | D6: =C6*(1+D5) -> 3264.0145 | E6: =D6*(1+E5) -> 3786.2568 | F6: =E6*(1+F5) -> 4354.1954 | G6: =F6*(1+G5) -> 4920.2408 | H6: =G6*(1+H5) -> 5510.6697 | I6: =H6*(1+I5) -> 6116.8433 | J6: =I6*(1+J5) -> 6728.5277 | ... L6: =K6*(1+L5) -> 7920.8228
A7: EBITDA margin, PRE-SBC | B7: 0.557 | C7: 0.56 | D7: 0.575 | E7: 0.584 | F7: 0.588 | G7: 0.593 | H7: 0.594 | I7: 0.596 | J7: 0.596 | K7: 0.596 | L7: 0.595
A8: EBITDA, pre-SBC | C8: =C6*C7 -> 1562.2634 | D8: =D6*D7 -> 1876.8083 | E8: =E6*E7 -> 2211.174 | F8: =F6*F7 -> 2560.2669 | G8: =G6*G7 -> 2917.7028 | H8: =H6*H7 -> 3273.3378 | I8: =I6*I7 -> 3645.6386 | J8: =J6*J7 -> 4010.2025 | ... L8: =L6*L7 -> 4712.8895
A9: SBC (% of net revenue) | B9: 0.03 | C9: 0.03 | D9: 0.03 | E9: 0.029 | F9: 0.028 | G9: 0.028 | H9: 0.027 | I9: 0.027 | J9: 0.026 | K9: 0.026 | L9: 0.025
A10: SBC | C10: =-C6*C9 -> -83.69268 | D10: =-D6*D9 -> -97.920436 | E10: =-E6*E9 -> -109.80145 | F10: =-F6*F9 -> -121.91747 | G10: =-G6*G9 -> -137.76674 | H10: =-H6*H9 -> -148.78808 | I10: =-I6*I9 -> -165.15477 | J10: =-J6*J9 -> -174.94172 | ... L10: =-L6*L9 -> -198.02057
A11: Reported EBITDA (post-SBC, = guided measure) | C11: =C8+C10 -> 1478.5707 | D11: =D8+D10 -> 1778.8879 | E11: =E8+E10 -> 2101.3725 | F11: =F8+F10 -> 2438.3494 | G11: =G8+G10 -> 2779.936 | H11: =H8+H10 -> 3124.5497 | I11: =I8+I10 -> 3480.4839 | J11: =J8+J10 -> 3835.2608 | ... L11: =L8+L10 -> 4514.869
A12: D&A | C12: =-C6*Assumptions!$B$6 -> -167.38536 | D12: =-D6*Assumptions!$B$6 -> -195.84087 | E12: =-E6*Assumptions!$B$6 -> -227.17541 | F12: =-F6*Assumptions!$B$6 -> -261.25172 | G12: =-G6*Assumptions!$B$6 -> -295.21445 | H12: =-H6*Assumptions!$B$6 -> -330.64018 | I12: =-I6*Assumptions!$B$6 -> -367.0106 | J12: =-J6*Assumptions!$B$6 -> -403.71166 | ... L12: =-L6*Assumptions!$B$6 -> -475.24937
A13: EBIT (SBC expensed) | C13: =C11+C12 -> 1311.1853 | D13: =D11+D12 -> 1583.047 | E13: =E11+E12 -> 1874.1971 | F13: =F11+F12 -> 2177.0977 | G13: =G11+G12 -> 2484.7216 | H13: =H11+H12 -> 2793.9095 | I13: =I11+I12 -> 3113.4733 | J13: =J11+J12 -> 3431.5491 | ... L13: =L11+L12 -> 4039.6196
A14: Cash tax rate | C14: 0.23 | D14: 0.235 | E14: 0.24 | F14: 0.245 | G14: 0.25 | H14: 0.25 | I14: 0.25 | J14: 0.25 | K14: 0.25 | L14: 0.25
A15: NOPAT | C15: =C13*(1-C14) -> 1009.6127 | D15: =D13*(1-D14) -> 1211.031 | E15: =E13*(1-E14) -> 1424.3898 | F15: =F13*(1-F14) -> 1643.7088 | G15: =G13*(1-G14) -> 1863.5412 | H15: =H13*(1-H14) -> 2095.4321 | I15: =I13*(1-I14) -> 2335.1049 | J15: =J13*(1-J14) -> 2573.6618 | ... L15: =L13*(1-L14) -> 3029.7147
A16: add: D&A | C16: =-C12 -> 167.38536 | D16: =-D12 -> 195.84087 | E16: =-E12 -> 227.17541 | F16: =-F12 -> 261.25172 | G16: =-G12 -> 295.21445 | H16: =-H12 -> 330.64018 | I16: =-I12 -> 367.0106 | J16: =-J12 -> 403.71166 | ... L16: =-L12 -> 475.24937
A17: less: capex | C17: =-C6*Assumptions!$B$7 -> -139.4878 | D17: =-D6*Assumptions!$B$7 -> -163.20073 | E17: =-E6*Assumptions!$B$7 -> -189.31284 | F17: =-F6*Assumptions!$B$7 -> -217.70977 | G17: =-G6*Assumptions!$B$7 -> -246.01204 | H17: =-H6*Assumptions!$B$7 -> -275.53348 | I17: =-I6*Assumptions!$B$7 -> -305.84217 | J17: =-J6*Assumptions!$B$7 -> -336.42638 | ... L17: =-L6*Assumptions!$B$7 -> -396.04114
A18: add: working capital | C18: =Assumptions!$B$8*(C6-B6) -> 0 | D18: =Assumptions!$B$8*(D6-C6) -> 0 | E18: =Assumptions!$B$8*(E6-D6) -> 0 | F18: =Assumptions!$B$8*(F6-E6) -> 0 | G18: =Assumptions!$B$8*(G6-F6) -> 0 | H18: =Assumptions!$B$8*(H6-G6) -> 0 | I18: =Assumptions!$B$8*(I6-H6) -> 0 | J18: =Assumptions!$B$8*(J6-I6) -> 0 | ... L18: =Assumptions!$B$8*(L6-K6) -> 0
A19: Unlevered owner FCF (operating only) | C19: =C15+C16+C17+C18 -> 1037.5103 | D19: =D15+D16+D17+D18 -> 1243.6711 | E19: =E15+E16+E17+E18 -> 1462.2524 | F19: =F15+F16+F17+F18 -> 1687.2507 | G19: =G15+G16+G17+G18 -> 1912.7436 | H19: =H15+H16+H17+H18 -> 2150.5388 | I19: =I15+I16+I17+I18 -> 2396.2734 | J19: =J15+J16+J17+J18 -> 2640.9471 | ... L19: =L15+L16+L17+L18 -> 3108.9229
A20: Discount factor | C20: =1/(1+Assumptions!$B$5)^C4 -> 0.90497738 | D20: =1/(1+Assumptions!$B$5)^D4 -> 0.81898405 | E20: =1/(1+Assumptions!$B$5)^E4 -> 0.74116204 | F20: =1/(1+Assumptions!$B$5)^F4 -> 0.67073487 | G20: =1/(1+Assumptions!$B$5)^G4 -> 0.60699989 | H20: =1/(1+Assumptions!$B$5)^H4 -> 0.54932116 | I20: =1/(1+Assumptions!$B$5)^I4 -> 0.49712323 | J20: =1/(1+Assumptions!$B$5)^J4 -> 0.44988527 | ... L20: =1/(1+Assumptions!$B$5)^L4 -> 0.36844886
A21: PV of FCF | C21: =C19*C20 -> 938.92331 | D21: =D19*D20 -> 1018.5468 | E21: =E19*E20 -> 1083.766 | F21: =F19*F20 -> 1131.6979 | G21: =G19*G20 -> 1161.0351 | H21: =H19*H20 -> 1181.3365 | I21: =I19*I20 -> 1191.2431 | J21: =J19*J20 -> 1188.1232 | ... L21: =L19*L20 -> 1145.4791
A23: Memo: reported EBITDA margin (row 11 / row 6) | C23: =C11/C6 -> 0.53 | D23: =D11/D6 -> 0.545 | E23: =E11/E6 -> 0.555 | F23: =F11/F6 -> 0.56 | G23: =G11/G6 -> 0.565 | H23: =H11/H6 -> 0.567 | I23: =I11/I6 -> 0.569 | J23: =J11/J6 -> 0.57 | ... L23: =L11/L6 -> 0.57
A24: Memo: implied owner FCF margin | C24: =C19/C6 -> 0.3719 | D24: =D19/D6 -> 0.381025 | E24: =E19/E6 -> 0.3862 | F24: =F19/F6 -> 0.3875 | G24: =G19/G6 -> 0.38875 | H24: =H19/H6 -> 0.39025 | I24: =I19/I6 -> 0.39175 | J24: =J19/J6 -> 0.3925 | ... L24: =L19/L6 -> 0.3925
A25: Valuation
A26: PV of FCF, explicit years | B26: =SUM(C21:L21) -> 11212.146
A27: Terminal growth rate | B27: =Assumptions!$D$16 -> 0.03
A28: Terminal-year owner FCF x (1+g) | B28: =L19*(1+B27) -> 3202.1906
A29: Terminal value - Gordon | B29: =B28/(Assumptions!$B$5-B27) -> 42695.875
A30: Terminal value - cap | B30: =Assumptions!$B$12*L19 -> 62178.459
A31: Terminal value used (lower of the two) | B31: =MIN(B29,B30) -> 42695.875
A32: Implied exit multiple | B32: =B31/L19 -> 13.733333
A33: PV of terminal value | B33: =B31*L20 -> 15731.247
A34: Enterprise value, operating business | B34: =B26+B33 -> 26943.392
A35: add: owner net cash + PV of float stream | B35: =Assumptions!$B$9+Float_Income!$B$32 -> 6110.4564
A36: Equity value | B36: =B34+B35 -> 33053.849
A37: Shares (mm) | B37: =Assumptions!$B$10 -> 31.55
A38: Value per share | B38: =B36/B37 -> 1047.6656
A39: Upside / (downside) vs current price | B39: =B38/Assumptions!$B$11-1 -> 0.12265921
A41: Memo: value if SBC treated as non-cash | B41: =SUMPRODUCT(-C10:L10/(1+Assumptions!$B$5)^C4:L4) -> 795.84881
A42: plus PV of terminal SBC | B42: =(-L10*(1+B27)/(Assumptions!$B$5-B27))*L20 -> 1001.9902
...

Sheet DCF_Bull
A1: ADYEN.AS DCF - Bull - embedded finance inflects; agentic harness wins
A2: Owner-FCF basis: SBC fully expensed, float income valued separately (Float_Income tab), share count flat. Blue rows = per-year drivers. Row 7 is PRE-SBC margin; row 7 less row 9 = the reported margin management guides to.
B3: 2025A | C3: 2026E | D3: 2027E | E3: 2028E | F3: 2029E | G3: 2030E | H3: 2031E | I3: 2032E | J3: 2033E | K3: 2034E | L3: 2035E
A4: Year index (for discounting) | B4: 0 | C4: 1 | D4: 2 | E4: 3 | F4: 4 | G4: 5 | H4: 6 | I4: 7 | J4: 8 | K4: 9 | L4: 10
A5: Net revenue growth YoY (REPORTED EUR) | C5: 0.2 | D5: 0.2 | E5: 0.19 | F5: 0.18 | G5: 0.17 | H5: 0.16 | I5: 0.14 | J5: 0.13 | K5: 0.12 | L5: 0.11
A6: Net revenue | B6: 2364.2 | C6: =B6*(1+C5) -> 2837.04 | D6: =C6*(1+D5) -> 3404.448 | E6: =D6*(1+E5) -> 4051.2931 | F6: =E6*(1+F5) -> 4780.5259 | G6: =F6*(1+G5) -> 5593.2153 | H6: =G6*(1+H5) -> 6488.1297 | I6: =H6*(1+I5) -> 7396.4679 | J6: =I6*(1+J5) -> 8358.0087 | ... L6: =K6*(1+L5) -> 10390.676
A7: EBITDA margin, PRE-SBC | B7: 0.557 | C7: 0.565 | D7: 0.584 | E7: 0.603 | F7: 0.617 | G7: 0.626 | H7: 0.63 | I7: 0.632 | J7: 0.633 | K7: 0.632 | L7: 0.632
A8: EBITDA, pre-SBC | C8: =C6*C7 -> 1602.9276 | D8: =D6*D7 -> 1988.1976 | E8: =E6*E7 -> 2442.9298 | F8: =F6*F7 -> 2949.5845 | G8: =G6*G7 -> 3501.3528 | H8: =H6*H7 -> 4087.5217 | I8: =I6*I7 -> 4674.5677 | J8: =J6*J7 -> 5290.6195 | ... L8: =L6*L7 -> 6566.9075
A9: SBC (% of net revenue) | B9: 0.03 | C9: 0.03 | D9: 0.029 | E9: 0.028 | F9: 0.027 | G9: 0.026 | H9: 0.025 | I9: 0.024 | J9: 0.023 | K9: 0.022 | L9: 0.022
A10: SBC | C10: =-C6*C9 -> -85.1112 | D10: =-D6*D9 -> -98.728992 | E10: =-E6*E9 -> -113.43621 | F10: =-F6*F9 -> -129.0742 | G10: =-G6*G9 -> -145.4236 | H10: =-H6*H9 -> -162.20324 | I10: =-I6*I9 -> -177.51523 | J10: =-J6*J9 -> -192.2342 | ... L10: =-L6*L9 -> -228.59488
A11: Reported EBITDA (post-SBC, = guided measure) | C11: =C8+C10 -> 1517.8164 | D11: =D8+D10 -> 1889.4686 | E11: =E8+E10 -> 2329.4935 | F11: =F8+F10 -> 2820.5103 | G11: =G8+G10 -> 3355.9292 | H11: =H8+H10 -> 3925.3185 | I11: =I8+I10 -> 4497.0525 | J11: =J8+J10 -> 5098.3853 | ... L11: =L8+L10 -> 6338.3126
A12: D&A | C12: =-C6*Assumptions!$B$6 -> -170.2224 | D12: =-D6*Assumptions!$B$6 -> -204.26688 | E12: =-E6*Assumptions!$B$6 -> -243.07759 | F12: =-F6*Assumptions!$B$6 -> -286.83155 | G12: =-G6*Assumptions!$B$6 -> -335.59292 | H12: =-H6*Assumptions!$B$6 -> -389.28778 | I12: =-I6*Assumptions!$B$6 -> -443.78807 | J12: =-J6*Assumptions!$B$6 -> -501.48052 | ... L12: =-L6*Assumptions!$B$6 -> -623.44059
A13: EBIT (SBC expensed) | C13: =C11+C12 -> 1347.594 | D13: =D11+D12 -> 1685.2018 | E13: =E11+E12 -> 2086.416 | F13: =F11+F12 -> 2533.6787 | G13: =G11+G12 -> 3020.3363 | H13: =H11+H12 -> 3536.0307 | I13: =I11+I12 -> 4053.2644 | J13: =J11+J12 -> 4596.9048 | ... L13: =L11+L12 -> 5714.872
A14: Cash tax rate | C14: 0.228 | D14: 0.232 | E14: 0.236 | F14: 0.24 | G14: 0.245 | H14: 0.248 | I14: 0.25 | J14: 0.25 | K14: 0.25 | L14: 0.25
A15: NOPAT | C15: =C13*(1-C14) -> 1040.3426 | D15: =D13*(1-D14) -> 1294.235 | E15: =E13*(1-E14) -> 1594.0218 | F15: =F13*(1-F14) -> 1925.5958 | G15: =G13*(1-G14) -> 2280.3539 | H15: =H13*(1-H14) -> 2659.0951 | I15: =I13*(1-I14) -> 3039.9483 | J15: =J13*(1-J14) -> 3447.6786 | ... L15: =L13*(1-L14) -> 4286.154
A16: add: D&A | C16: =-C12 -> 170.2224 | D16: =-D12 -> 204.26688 | E16: =-E12 -> 243.07759 | F16: =-F12 -> 286.83155 | G16: =-G12 -> 335.59292 | H16: =-H12 -> 389.28778 | I16: =-I12 -> 443.78807 | J16: =-J12 -> 501.48052 | ... L16: =-L12 -> 623.44059
A17: less: capex | C17: =-C6*Assumptions!$B$7 -> -141.852 | D17: =-D6*Assumptions!$B$7 -> -170.2224 | E17: =-E6*Assumptions!$B$7 -> -202.56466 | F17: =-F6*Assumptions!$B$7 -> -239.02629 | G17: =-G6*Assumptions!$B$7 -> -279.66076 | H17: =-H6*Assumptions!$B$7 -> -324.40649 | I17: =-I6*Assumptions!$B$7 -> -369.82339 | J17: =-J6*Assumptions!$B$7 -> -417.90044 | ... L17: =-L6*Assumptions!$B$7 -> -519.53382
A18: add: working capital | C18: =Assumptions!$B$8*(C6-B6) -> 0 | D18: =Assumptions!$B$8*(D6-C6) -> 0 | E18: =Assumptions!$B$8*(E6-D6) -> 0 | F18: =Assumptions!$B$8*(F6-E6) -> 0 | G18: =Assumptions!$B$8*(G6-F6) -> 0 | H18: =Assumptions!$B$8*(H6-G6) -> 0 | I18: =Assumptions!$B$8*(I6-H6) -> 0 | J18: =Assumptions!$B$8*(J6-I6) -> 0 | ... L18: =Assumptions!$B$8*(L6-K6) -> 0
A19: Unlevered owner FCF (operating only) | C19: =C15+C16+C17+C18 -> 1068.713 | D19: =D15+D16+D17+D18 -> 1328.2794 | E19: =E15+E16+E17+E18 -> 1634.5347 | F19: =F15+F16+F17+F18 -> 1973.4011 | G19: =G15+G16+G17+G18 -> 2336.286 | H19: =H15+H16+H17+H18 -> 2723.9764 | I19: =I15+I16+I17+I18 -> 3113.913 | J19: =J15+J16+J17+J18 -> 3531.2587 | ... L19: =L15+L16+L17+L18 -> 4390.0608
A20: Discount factor | C20: =1/(1+Assumptions!$B$5)^C4 -> 0.90497738 | D20: =1/(1+Assumptions!$B$5)^D4 -> 0.81898405 | E20: =1/(1+Assumptions!$B$5)^E4 -> 0.74116204 | F20: =1/(1+Assumptions!$B$5)^F4 -> 0.67073487 | G20: =1/(1+Assumptions!$B$5)^G4 -> 0.60699989 | H20: =1/(1+Assumptions!$B$5)^H4 -> 0.54932116 | I20: =1/(1+Assumptions!$B$5)^I4 -> 0.49712323 | J20: =1/(1+Assumptions!$B$5)^J4 -> 0.44988527 | ... L20: =1/(1+Assumptions!$B$5)^L4 -> 0.36844886
A21: PV of FCF | C21: =C19*C20 -> 967.16106 | D21: =D19*D20 -> 1087.8397 | E21: =E19*E20 -> 1211.4551 | F21: =F19*F20 -> 1323.6289 | G21: =G19*G20 -> 1418.1254 | H21: =H19*H20 -> 1496.3379 | I21: =I19*I20 -> 1547.9985 | J21: =J19*J20 -> 1588.6613 | ... L21: =L19*L20 -> 1617.5129
A23: Memo: reported EBITDA margin (row 11 / row 6) | C23: =C11/C6 -> 0.535 | D23: =D11/D6 -> 0.555 | E23: =E11/E6 -> 0.575 | F23: =F11/F6 -> 0.59 | G23: =G11/G6 -> 0.6 | H23: =H11/H6 -> 0.605 | I23: =I11/I6 -> 0.608 | J23: =J11/J6 -> 0.61 | ... L23: =L11/L6 -> 0.61
A24: Memo: implied owner FCF margin | C24: =C19/C6 -> 0.3767 | D24: =D19/D6 -> 0.39016 | E24: =E19/E6 -> 0.40346 | F24: =F19/F6 -> 0.4128 | G24: =G19/G6 -> 0.4177 | H24: =H19/H6 -> 0.41984 | I24: =I19/I6 -> 0.421 | J24: =J19/J6 -> 0.4225 | ... L24: =L19/L6 -> 0.4225
A25: Valuation
A26: PV of FCF, explicit years | B26: =SUM(C21:L21) -> 13868.947
A27: Terminal growth rate | B27: =Assumptions!$E$16 -> 0.035
A28: Terminal-year owner FCF x (1+g) | B28: =L19*(1+B27) -> 4543.7129
A29: Terminal value - Gordon | B29: =B28/(Assumptions!$B$5-B27) -> 64910.185
A30: Terminal value - cap | B30: =Assumptions!$B$12*L19 -> 87801.216
A31: Terminal value used (lower of the two) | B31: =MIN(B29,B30) -> 64910.185
A32: Implied exit multiple | B32: =B31/L19 -> 14.785714
A33: PV of terminal value | B33: =B31*L20 -> 23916.084
A34: Enterprise value, operating business | B34: =B26+B33 -> 37785.031
A35: add: owner net cash + PV of float stream | B35: =Assumptions!$B$9+Float_Income!$B$47 -> 6961.2962
A36: Equity value | B36: =B34+B35 -> 44746.327
A37: Shares (mm) | B37: =Assumptions!$B$10 -> 31.55
A38: Value per share | B38: =B36/B37 -> 1418.2671
A39: Upside / (downside) vs current price | B39: =B38/Assumptions!$B$11-1 -> 0.51978901
A41: Memo: value if SBC treated as non-cash | B41: =SUMPRODUCT(-C10:L10/(1+Assumptions!$B$5)^C4:L4) -> 848.70607
A42: plus PV of terminal SBC | B42: =(-L10*(1+B27)/(Assumptions!$B$5-B27))*L20 -> 1245.3345
...

Sheet Float_Income
A1: ADYEN - float / net interest income, valued separately
A2: Interest earned on merchant funds in transit plus own cash. Kept OUT of the operating DCF (house rule: no interest income in flows) and valued here instead, because the merchant funds that generate most of it are a liability and are NOT in owner net cash. Total per scenario feeds row 35 of the matching DCF tab.
A3: FY2025 actual pre-tax float income: EUR272.6m (FY2024: EUR350.1m, FY2023: EUR241.6m) - falling with ECB policy rates. Source: Yahoo Finance ADYEN.AS income statement, 9-Aug-2026.
A5: Bear | B5: 2025A | C5: 2026E | D5: 2027E | E5: 2028E | F5: 2029E | G5: 2030E | H5: 2031E | I5: 2032E | J5: 2033E | K5: 2034E | L5: 2035E
A6: Pre-tax float income | B6: 272.6 | C6: 230 | D6: 200 | E6: 175 | F6: 155 | G6: 140 | H6: 128 | I6: 118 | J6: 108 | K6: 99 | L6: 90
A7: Cash tax rate (link to DCF tab) | C7: =DCF_Bear!C14 -> 0.23 | D7: =DCF_Bear!D14 -> 0.238 | E7: =DCF_Bear!E14 -> 0.245 | F7: =DCF_Bear!F14 -> 0.25 | G7: =DCF_Bear!G14 -> 0.255 | H7: =DCF_Bear!H14 -> 0.258 | I7: =DCF_Bear!I14 -> 0.258 | J7: =DCF_Bear!J14 -> 0.258 | ... L7: =DCF_Bear!L14 -> 0.258
A8: After-tax float income | C8: =C6*(1-C7) -> 177.1 | D8: =D6*(1-D7) -> 152.4 | E8: =E6*(1-E7) -> 132.125 | F8: =F6*(1-F7) -> 116.25 | G8: =G6*(1-G7) -> 104.3 | H8: =H6*(1-H7) -> 94.976 | I8: =I6*(1-I7) -> 87.556 | J8: =J6*(1-J7) -> 80.136 | ... L8: =L6*(1-L7) -> 66.78
A9: Discount factor (link to DCF tab) | C9: =DCF_Bear!C20 -> 0.90497738 | D9: =DCF_Bear!D20 -> 0.81898405 | E9: =DCF_Bear!E20 -> 0.74116204 | F9: =DCF_Bear!F20 -> 0.67073487 | G9: =DCF_Bear!G20 -> 0.60699989 | H9: =DCF_Bear!H20 -> 0.54932116 | I9: =DCF_Bear!I20 -> 0.49712323 | J9: =DCF_Bear!J20 -> 0.44988527 | ... L9: =DCF_Bear!L20 -> 0.36844886
A10: PV of after-tax float income | C10: =C8*C9 -> 160.27149 | D10: =D8*D9 -> 124.81317 | E10: =E8*E9 -> 97.926034 | F10: =F8*F9 -> 77.972929 | G10: =G8*G9 -> 63.310088 | H10: =H8*H9 -> 52.172327 | I10: =I8*I9 -> 43.526121 | J10: =J8*J9 -> 36.052006 | ... L10: =L8*L9 -> 24.605015
A11: PV, explicit years | B11: =SUM(C10:L10) -> 710.55658
A12: Terminal growth rate (link) | B12: =Assumptions!$C$16 -> 0.015
A13: Terminal value - Gordon | B13: =L8*(1+B12)/(Assumptions!$B$5-B12) -> 753.13
A14: Terminal value - cap | B14: =Assumptions!$B$13*L8 -> 801.36
A15: Terminal value used (lower) | B15: =MIN(B13,B14) -> 753.13
A16: PV of terminal value | B16: =B15*L9 -> 277.48989
A17: Total float-stream value | B17: =B11+B16 -> 988.04647 | C17: =B17/Assumptions!$B$10 -> 31.316845 | D17: per share
A20: Base | B20: 2025A | C20: 2026E | D20: 2027E | E20: 2028E | F20: 2029E | G20: 2030E | H20: 2031E | I20: 2032E | J20: 2033E | K20: 2034E | L20: 2035E
A21: Pre-tax float income | B21: 272.6 | C21: 255 | D21: 250 | E21: 246 | F21: 243 | G21: 241 | H21: 240 | I21: 240 | J21: 240 | K21: 240 | L21: 240
A22: Cash tax rate (link to DCF tab) | C22: =DCF_Base!C14 -> 0.23 | D22: =DCF_Base!D14 -> 0.235 | E22: =DCF_Base!E14 -> 0.24 | F22: =DCF_Base!F14 -> 0.245 | G22: =DCF_Base!G14 -> 0.25 | H22: =DCF_Base!H14 -> 0.25 | I22: =DCF_Base!I14 -> 0.25 | J22: =DCF_Base!J14 -> 0.25 | ... L22: =DCF_Base!L14 -> 0.25
A23: After-tax float income | C23: =C21*(1-C22) -> 196.35 | D23: =D21*(1-D22) -> 191.25 | E23: =E21*(1-E22) -> 186.96 | F23: =F21*(1-F22) -> 183.465 | G23: =G21*(1-G22) -> 180.75 | H23: =H21*(1-H22) -> 180 | I23: =I21*(1-I22) -> 180 | J23: =J21*(1-J22) -> 180 | ... L23: =L21*(1-L22) -> 180
A24: Discount factor (link to DCF tab) | C24: =DCF_Base!C20 -> 0.90497738 | D24: =DCF_Base!D20 -> 0.81898405 | E24: =DCF_Base!E20 -> 0.74116204 | F24: =DCF_Base!F20 -> 0.67073487 | G24: =DCF_Base!G20 -> 0.60699989 | H24: =DCF_Base!H20 -> 0.54932116 | I24: =DCF_Base!I20 -> 0.49712323 | J24: =DCF_Base!J20 -> 0.44988527 | ... L24: =DCF_Base!L20 -> 0.36844886
A25: PV of after-tax float income | C25: =C23*C24 -> 177.69231 | D25: =D23*D24 -> 156.6307 | E25: =E23*E24 -> 138.56765 | F25: =F23*F24 -> 123.05637 | G25: =G23*G24 -> 109.71523 | H25: =H23*H24 -> 98.87781 | I25: =I23*I24 -> 89.482181 | J25: =J23*J24 -> 80.979349 | ... L25: =L23*L24 -> 66.320795
A26: PV, explicit years | B26: =SUM(C25:L25) -> 1114.6069
A27: Terminal growth rate (link) | B27: =Assumptions!$D$16 -> 0.03
A28: Terminal value - Gordon | B28: =L23*(1+B27)/(Assumptions!$B$5-B27) -> 2472
A29: Terminal value - cap | B29: =Assumptions!$B$13*L23 -> 2160
A30: Terminal value used (lower) | B30: =MIN(B28,B29) -> 2160
A31: PV of terminal value | B31: =B30*L24 -> 795.84954
A32: Total float-stream value | B32: =B26+B31 -> 1910.4564 | C32: =B32/Assumptions!$B$10 -> 60.553294 | D32: per share
A35: Bull | B35: 2025A | C35: 2026E | D35: 2027E | E35: 2028E | F35: 2029E | G35: 2030E | H35: 2031E | I35: 2032E | J35: 2033E | K35: 2034E | L35: 2035E
A36: Pre-tax float income | B36: 272.6 | C36: 265 | D36: 275 | E36: 288 | F36: 300 | G36: 315 | H36: 330 | I36: 348 | J36: 365 | K36: 382 | L36: 400
A37: Cash tax rate (link to DCF tab) | C37: =DCF_Bull!C14 -> 0.228 | D37: =DCF_Bull!D14 -> 0.232 | E37: =DCF_Bull!E14 -> 0.236 | F37: =DCF_Bull!F14 -> 0.24 | G37: =DCF_Bull!G14 -> 0.245 | H37: =DCF_Bull!H14 -> 0.248 | I37: =DCF_Bull!I14 -> 0.25 | J37: =DCF_Bull!J14 -> 0.25 | ... L37: =DCF_Bull!L14 -> 0.25
A38: After-tax float income | C38: =C36*(1-C37) -> 204.58 | D38: =D36*(1-D37) -> 211.2 | E38: =E36*(1-E37) -> 220.032 | F38: =F36*(1-F37) -> 228 | G38: =G36*(1-G37) -> 237.825 | H38: =H36*(1-H37) -> 248.16 | I38: =I36*(1-I37) -> 261 | J38: =J36*(1-J37) -> 273.75 | ... L38: =L36*(1-L37) -> 300
A39: Discount factor (link to DCF tab) | C39: =DCF_Bull!C20 -> 0.90497738 | D39: =DCF_Bull!D20 -> 0.81898405 | E39: =DCF_Bull!E20 -> 0.74116204 | F39: =DCF_Bull!F20 -> 0.67073487 | G39: =DCF_Bull!G20 -> 0.60699989 | H39: =DCF_Bull!H20 -> 0.54932116 | I39: =DCF_Bull!I20 -> 0.49712323 | J39: =DCF_Bull!J20 -> 0.44988527 | ... L39: =DCF_Bull!L20 -> 0.36844886
A40: PV of after-tax float income | C40: =C38*C39 -> 185.14027 | D40: =D38*D39 -> 172.96943 | E40: =E38*E39 -> 163.07937 | F40: =F38*F39 -> 152.92755 | G40: =G38*G39 -> 144.35975 | H40: =H38*H39 -> 136.31954 | I40: =I38*I39 -> 129.74916 | J40: =J38*J39 -> 123.15609 | ... L40: =L38*L39 -> 110.53466
A41: PV, explicit years | B41: =SUM(C40:L40) -> 1434.8803
A42: Terminal growth rate (link) | B42: =Assumptions!$E$16 -> 0.035
A43: Terminal value - Gordon | B43: =L38*(1+B42)/(Assumptions!$B$5-B42) -> 4435.7143
A44: Terminal value - cap | B44: =Assumptions!$B$13*L38 -> 3600
A45: Terminal value used (lower) | B45: =MIN(B43,B44) -> 3600
...

Sheet Valuation
A1: ADYEN.AS - Valuation Summary & Sensitivity
A2: Owner-FCF basis (SBC expensed) unless marked street. Green = links. All discount-rate variants below re-discount BOTH the operating FCF stream and the float stream at the stated rate.
B4: Bear | C4: Base | D4: Bull
A5: Value per share | B5: =DCF_Bear!$B$38 -> 571.10871 | C5: =DCF_Base!$B$38 -> 1047.6656 | D5: =DCF_Bull!$B$38 -> 1418.2671
A6: Upside / (downside) vs price | B6: =B5/Assumptions!$B$11-1 -> -0.38801038 | C6: =C5/Assumptions!$B$11-1 -> 0.12265921 | D6: =D5/Assumptions!$B$11-1 -> 0.51978901
A7: Probability | B7: =Assumptions!$C$17 -> 0.15 | C7: =Assumptions!$D$17 -> 0.5 | D7: =Assumptions!$E$17 -> 0.35
A8: Value per share, SBC as non-cash (street) | B8: =DCF_Bear!$B$43 -> 619.0228 | C8: =DCF_Base!$B$43 -> 1104.6494 | D8: =DCF_Bull!$B$43 -> 1484.6392
A10: Probability-weighted value per share | B10: =SUMPRODUCT(B5:D5,B7:D7) -> 1105.8926
A11: Current price | B11: =Assumptions!$B$11 -> 933.2
A12: Margin of safety vs weighted value | B12: =1-B11/B10 -> 0.15615674
A13: Weighted value, SBC as non-cash (street) | B13: =SUMPRODUCT(B8:D8,B7:D7) -> 1164.8018
A14: Band position (0%=house, 100%=street) | B14: =(Assumptions!$B$11-B10)/(B13-B10) -> -2.9315015 | G14: NOT an error if negative: the price sits BELOW even the house (SBC-expensed) value, so the accounting-regime band does not bind here. Adyen's SBC is small - the house/street gap is only about EUR59/share, versus multiples of that for US-GAAP tech names.
A15: Memo: float stream as % of weighted value | B15: =(Float_Income!$C$17*B7+Float_Income!$C$32*C7+Float_Income!$C$47*D7)/B10 -> 0.059324586
G16: row 15: how much of the weighted value is the rate-dependent float stream
A18: Base case - value per share at different required returns
A19: Required return | B19: Value / share
A20: 0.09 | B20: =(SUMPRODUCT(DCF_Base!$C$19:$L$19/(1+$A20)^DCF_Base!$C$4:$L$4)+MIN(DCF_Base!$L$19*(1+Assumptions!$D$16)/($A20-Assumptions!$D$16),Assumptions!$B$12*DCF_Base!$L$19)/(1+$A20)^10+SUMPRODUCT(Float_Income!$C$23:$L$23/(1+$A20)^DCF_Base!$C$4:$L$4)+MIN(Float_Income!$L$23*(1+Assumptions!$D$16)/($A20-Assumptions!$D$16),Assumptions!$B$13*Float_Income!$L$23)/(1+$A20)^10+Assumptions!$B$9)/Assumptions!$B$10 -> 1298.5022
A21: 0.1 | B21: =(SUMPRODUCT(DCF_Base!$C$19:$L$19/(1+$A21)^DCF_Base!$C$4:$L$4)+MIN(DCF_Base!$L$19*(1+Assumptions!$D$16)/($A21-Assumptions!$D$16),Assumptions!$B$12*DCF_Base!$L$19)/(1+$A21)^10+SUMPRODUCT(Float_Income!$C$23:$L$23/(1+$A21)^DCF_Base!$C$4:$L$4)+MIN(Float_Income!$L$23*(1+Assumptions!$D$16)/($A21-Assumptions!$D$16),Assumptions!$B$13*Float_Income!$L$23)/(1+$A21)^10+Assumptions!$B$9)/Assumptions!$B$10 -> 1119.261
A22: 0.105 | B22: =(SUMPRODUCT(DCF_Base!$C$19:$L$19/(1+$A22)^DCF_Base!$C$4:$L$4)+MIN(DCF_Base!$L$19*(1+Assumptions!$D$16)/($A22-Assumptions!$D$16),Assumptions!$B$12*DCF_Base!$L$19)/(1+$A22)^10+SUMPRODUCT(Float_Income!$C$23:$L$23/(1+$A22)^DCF_Base!$C$4:$L$4)+MIN(Float_Income!$L$23*(1+Assumptions!$D$16)/($A22-Assumptions!$D$16),Assumptions!$B$13*Float_Income!$L$23)/(1+$A22)^10+Assumptions!$B$9)/Assumptions!$B$10 -> 1047.6656
A23: 0.11 | B23: =(SUMPRODUCT(DCF_Base!$C$19:$L$19/(1+$A23)^DCF_Base!$C$4:$L$4)+MIN(DCF_Base!$L$19*(1+Assumptions!$D$16)/($A23-Assumptions!$D$16),Assumptions!$B$12*DCF_Base!$L$19)/(1+$A23)^10+SUMPRODUCT(Float_Income!$C$23:$L$23/(1+$A23)^DCF_Base!$C$4:$L$4)+MIN(Float_Income!$L$23*(1+Assumptions!$D$16)/($A23-Assumptions!$D$16),Assumptions!$B$13*Float_Income!$L$23)/(1+$A23)^10+Assumptions!$B$9)/Assumptions!$B$10 -> 985.08677
A24: 0.12 | B24: =(SUMPRODUCT(DCF_Base!$C$19:$L$19/(1+$A24)^DCF_Base!$C$4:$L$4)+MIN(DCF_Base!$L$19*(1+Assumptions!$D$16)/($A24-Assumptions!$D$16),Assumptions!$B$12*DCF_Base!$L$19)/(1+$A24)^10+SUMPRODUCT(Float_Income!$C$23:$L$23/(1+$A24)^DCF_Base!$C$4:$L$4)+MIN(Float_Income!$L$23*(1+Assumptions!$D$16)/($A24-Assumptions!$D$16),Assumptions!$B$13*Float_Income!$L$23)/(1+$A24)^10+Assumptions!$B$9)/Assumptions!$B$10 -> 879.95613
A25: 0.15 | B25: =(SUMPRODUCT(DCF_Base!$C$19:$L$19/(1+$A25)^DCF_Base!$C$4:$L$4)+MIN(DCF_Base!$L$19*(1+Assumptions!$D$16)/($A25-Assumptions!$D$16),Assumptions!$B$12*DCF_Base!$L$19)/(1+$A25)^10+SUMPRODUCT(Float_Income!$C$23:$L$23/(1+$A25)^DCF_Base!$C$4:$L$4)+MIN(Float_Income!$L$23*(1+Assumptions!$D$16)/($A25-Assumptions!$D$16),Assumptions!$B$13*Float_Income!$L$23)/(1+$A25)^10+Assumptions!$B$9)/Assumptions!$B$10 -> 669.14144
A27: 15%-hurdle entry per scenario + weighted | B27: =(SUMPRODUCT(DCF_Bear!$C$19:$L$19/(1+0.15)^DCF_Bear!$C$4:$L$4)+MIN(DCF_Bear!$L$19*(1+Assumptions!$C$16)/(0.15-Assumptions!$C$16),Assumptions!$B$12*DCF_Bear!$L$19)/(1+0.15)^10+SUMPRODUCT(Float_Income!$C$8:$L$8/(1+0.15)^DCF_Bear!$C$4:$L$4)+MIN(Float_Income!$L$8*(1+Assumptions!$C$16)/(0.15-Assumptions!$C$16),Assumptions!$B$13*Float_Income!$L$8)/(1+0.15)^10+Assumptions!$B$9)/Assumptions!$B$10 -> 423.34542 | C27: =(SUMPRODUCT(DCF_Base!$C$19:$L$19/(1+0.15)^DCF_Base!$C$4:$L$4)+MIN(DCF_Base!$L$19*(1+Assumptions!$D$16)/(0.15-Assumptions!$D$16),Assumptions!$B$12*DCF_Base!$L$19)/(1+0.15)^10+SUMPRODUCT(Float_Income!$C$23:$L$23/(1+0.15)^DCF_Base!$C$4:$L$4)+MIN(Float_Income!$L$23*(1+Assumptions!$D$16)/(0.15-Assumptions!$D$16),Assumptions!$B$13*Float_Income!$L$23)/(1+0.15)^10+Assumptions!$B$9)/Assumptions!$B$10 -> 669.14144 | D27: =(SUMPRODUCT(DCF_Bull!$C$19:$L$19/(1+0.15)^DCF_Bull!$C$4:$L$4)+MIN(DCF_Bull!$L$19*(1+Assumptions!$E$16)/(0.15-Assumptions!$E$16),Assumptions!$B$12*DCF_Bull!$L$19)/(1+0.15)^10+SUMPRODUCT(Float_Income!$C$38:$L$38/(1+0.15)^DCF_Bull!$C$4:$L$4)+MIN(Float_Income!$L$38*(1+Assumptions!$E$16)/(0.15-Assumptions!$E$16),Assumptions!$B$13*Float_Income!$L$38)/(1+0.15)^10+Assumptions!$B$9)/Assumptions!$B$10 -> 850.25367 | E27: =SUMPRODUCT(B27:D27,$B$7:$D$7) -> 695.66132 | G27: model buy-below price at a 15% hurdle
A28: same, street basis | B28: =B27+(SUMPRODUCT(-DCF_Bear!$C$10:$L$10/(1+0.15)^DCF_Bear!$C$4:$L$4)+(-DCF_Bear!$L$10*(1+Assumptions!$C$16)/(0.15-Assumptions!$C$16))/(1+0.15)^10)/Assumptions!$B$10 -> 453.62126 | C28: =C27+(SUMPRODUCT(-DCF_Base!$C$10:$L$10/(1+0.15)^DCF_Base!$C$4:$L$4)+(-DCF_Base!$L$10*(1+Assumptions!$D$16)/(0.15-Assumptions!$D$16))/(1+0.15)^10)/Assumptions!$B$10 -> 702.86899 | D28: =D27+(SUMPRODUCT(-DCF_Bull!$C$10:$L$10/(1+0.15)^DCF_Bull!$C$4:$L$4)+(-DCF_Bull!$L$10*(1+Assumptions!$E$16)/(0.15-Assumptions!$E$16))/(1+0.15)^10)/Assumptions!$B$10 -> 888.05535 | E28: =SUMPRODUCT(B28:D28,$B$7:$D$7) -> 730.29705
A30: Base case - value per share: WACC x terminal growth
A31: WACC \ g | B31: 0.02 | C31: 0.025 | D31: 0.03 | E31: 0.035 | F31: 0.04
A32: 0.095 | B32: =IF($A32>B$31,(SUMPRODUCT(DCF_Base!$C$19:$L$19/(1+$A32)^DCF_Base!$C$4:$L$4)+MIN(DCF_Base!$L$19*(1+B$31)/($A32-B$31),Assumptions!$B$12*DCF_Base!$L$19)/(1+$A32)^10+SUMPRODUCT(Float_Income!$C$23:$L$23/(1+$A32)^DCF_Base!$C$4:$L$4)+MIN(Float_Income!$L$23*(1+B$31)/($A32-B$31),Assumptions!$B$13*Float_Income!$L$23)/(1+$A32)^10+Assumptions!$B$9)/Assumptions!$B$10,"n/a") -> 1112.6385 | C32: =IF($A32>C$31,(SUMPRODUCT(DCF_Base!$C$19:$L$19/(1+$A32)^DCF_Base!$C$4:$L$4)+MIN(DCF_Base!$L$19*(1+C$31)/($A32-C$31),Assumptions!$B$12*DCF_Base!$L$19)/(1+$A32)^10+SUMPRODUCT(Float_Income!$C$23:$L$23/(1+$A32)^DCF_Base!$C$4:$L$4)+MIN(Float_Income!$L$23*(1+C$31)/($A32-C$31),Assumptions!$B$13*Float_Income!$L$23)/(1+$A32)^10+Assumptions!$B$9)/Assumptions!$B$10,"n/a") -> 1154.1047 | D32: =IF($A32>D$31,(SUMPRODUCT(DCF_Base!$C$19:$L$19/(1+$A32)^DCF_Base!$C$4:$L$4)+MIN(DCF_Base!$L$19*(1+D$31)/($A32-D$31),Assumptions!$B$12*DCF_Base!$L$19)/(1+$A32)^10+SUMPRODUCT(Float_Income!$C$23:$L$23/(1+$A32)^DCF_Base!$C$4:$L$4)+MIN(Float_Income!$L$23*(1+D$31)/($A32-D$31),Assumptions!$B$13*Float_Income!$L$23)/(1+$A32)^10+Assumptions!$B$9)/Assumptions!$B$10,"n/a") -> 1201.9503 | E32: =IF($A32>E$31,(SUMPRODUCT(DCF_Base!$C$19:$L$19/(1+$A32)^DCF_Base!$C$4:$L$4)+MIN(DCF_Base!$L$19*(1+E$31)/($A32-E$31),Assumptions!$B$12*DCF_Base!$L$19)/(1+$A32)^10+SUMPRODUCT(Float_Income!$C$23:$L$23/(1+$A32)^DCF_Base!$C$4:$L$4)+MIN(Float_Income!$L$23*(1+E$31)/($A32-E$31),Assumptions!$B$13*Float_Income!$L$23)/(1+$A32)^10+Assumptions!$B$9)/Assumptions!$B$10,"n/a") -> 1257.7701 | F32: =IF($A32>F$31,(SUMPRODUCT(DCF_Base!$C$19:$L$19/(1+$A32)^DCF_Base!$C$4:$L$4)+MIN(DCF_Base!$L$19*(1+F$31)/($A32-F$31),Assumptions!$B$12*DCF_Base!$L$19)/(1+$A32)^10+SUMPRODUCT(Float_Income!$C$23:$L$23/(1+$A32)^DCF_Base!$C$4:$L$4)+MIN(Float_Income!$L$23*(1+F$31)/($A32-F$31),Assumptions!$B$13*Float_Income!$L$23)/(1+$A32)^10+Assumptions!$B$9)/Assumptions!$B$10,"n/a") -> 1323.7391
A33: 0.1 | B33: =IF($A33>B$31,(SUMPRODUCT(DCF_Base!$C$19:$L$19/(1+$A33)^DCF_Base!$C$4:$L$4)+MIN(DCF_Base!$L$19*(1+B$31)/($A33-B$31),Assumptions!$B$12*DCF_Base!$L$19)/(1+$A33)^10+SUMPRODUCT(Float_Income!$C$23:$L$23/(1+$A33)^DCF_Base!$C$4:$L$4)+MIN(Float_Income!$L$23*(1+B$31)/($A33-B$31),Assumptions!$B$13*Float_Income!$L$23)/(1+$A33)^10+Assumptions!$B$9)/Assumptions!$B$10,"n/a") -> 1044.6353 | C33: =IF($A33>C$31,(SUMPRODUCT(DCF_Base!$C$19:$L$19/(1+$A33)^DCF_Base!$C$4:$L$4)+MIN(DCF_Base!$L$19*(1+C$31)/($A33-C$31),Assumptions!$B$12*DCF_Base!$L$19)/(1+$A33)^10+SUMPRODUCT(Float_Income!$C$23:$L$23/(1+$A33)^DCF_Base!$C$4:$L$4)+MIN(Float_Income!$L$23*(1+C$31)/($A33-C$31),Assumptions!$B$13*Float_Income!$L$23)/(1+$A33)^10+Assumptions!$B$9)/Assumptions!$B$10,"n/a") -> 1079.4607 | D33: =IF($A33>D$31,(SUMPRODUCT(DCF_Base!$C$19:$L$19/(1+$A33)^DCF_Base!$C$4:$L$4)+MIN(DCF_Base!$L$19*(1+D$31)/($A33-D$31),Assumptions!$B$12*DCF_Base!$L$19)/(1+$A33)^10+SUMPRODUCT(Float_Income!$C$23:$L$23/(1+$A33)^DCF_Base!$C$4:$L$4)+MIN(Float_Income!$L$23*(1+D$31)/($A33-D$31),Assumptions!$B$13*Float_Income!$L$23)/(1+$A33)^10+Assumptions!$B$9)/Assumptions!$B$10,"n/a") -> 1119.261 | E33: =IF($A33>E$31,(SUMPRODUCT(DCF_Base!$C$19:$L$19/(1+$A33)^DCF_Base!$C$4:$L$4)+MIN(DCF_Base!$L$19*(1+E$31)/($A33-E$31),Assumptions!$B$12*DCF_Base!$L$19)/(1+$A33)^10+SUMPRODUCT(Float_Income!$C$23:$L$23/(1+$A33)^DCF_Base!$C$4:$L$4)+MIN(Float_Income!$L$23*(1+E$31)/($A33-E$31),Assumptions!$B$13*Float_Income!$L$23)/(1+$A33)^10+Assumptions!$B$9)/Assumptions!$B$10,"n/a") -> 1165.1845 | F33: =IF($A33>F$31,(SUMPRODUCT(DCF_Base!$C$19:$L$19/(1+$A33)^DCF_Base!$C$4:$L$4)+MIN(DCF_Base!$L$19*(1+F$31)/($A33-F$31),Assumptions!$B$12*DCF_Base!$L$19)/(1+$A33)^10+SUMPRODUCT(Float_Income!$C$23:$L$23/(1+$A33)^DCF_Base!$C$4:$L$4)+MIN(Float_Income!$L$23*(1+F$31)/($A33-F$31),Assumptions!$B$13*Float_Income!$L$23)/(1+$A33)^10+Assumptions!$B$9)/Assumptions!$B$10,"n/a") -> 1218.762
A34: 0.105 | B34: =IF($A34>B$31,(SUMPRODUCT(DCF_Base!$C$19:$L$19/(1+$A34)^DCF_Base!$C$4:$L$4)+MIN(DCF_Base!$L$19*(1+B$31)/($A34-B$31),Assumptions!$B$12*DCF_Base!$L$19)/(1+$A34)^10+SUMPRODUCT(Float_Income!$C$23:$L$23/(1+$A34)^DCF_Base!$C$4:$L$4)+MIN(Float_Income!$L$23*(1+B$31)/($A34-B$31),Assumptions!$B$13*Float_Income!$L$23)/(1+$A34)^10+Assumptions!$B$9)/Assumptions!$B$10,"n/a") -> 984.73381 | C34: =IF($A34>C$31,(SUMPRODUCT(DCF_Base!$C$19:$L$19/(1+$A34)^DCF_Base!$C$4:$L$4)+MIN(DCF_Base!$L$19*(1+C$31)/($A34-C$31),Assumptions!$B$12*DCF_Base!$L$19)/(1+$A34)^10+SUMPRODUCT(Float_Income!$C$23:$L$23/(1+$A34)^DCF_Base!$C$4:$L$4)+MIN(Float_Income!$L$23*(1+C$31)/($A34-C$31),Assumptions!$B$13*Float_Income!$L$23)/(1+$A34)^10+Assumptions!$B$9)/Assumptions!$B$10,"n/a") -> 1014.2331 | D34: =IF($A34>D$31,(SUMPRODUCT(DCF_Base!$C$19:$L$19/(1+$A34)^DCF_Base!$C$4:$L$4)+MIN(DCF_Base!$L$19*(1+D$31)/($A34-D$31),Assumptions!$B$12*DCF_Base!$L$19)/(1+$A34)^10+SUMPRODUCT(Float_Income!$C$23:$L$23/(1+$A34)^DCF_Base!$C$4:$L$4)+MIN(Float_Income!$L$23*(1+D$31)/($A34-D$31),Assumptions!$B$13*Float_Income!$L$23)/(1+$A34)^10+Assumptions!$B$9)/Assumptions!$B$10,"n/a") -> 1047.6656 | E34: =IF($A34>E$31,(SUMPRODUCT(DCF_Base!$C$19:$L$19/(1+$A34)^DCF_Base!$C$4:$L$4)+MIN(DCF_Base!$L$19*(1+E$31)/($A34-E$31),Assumptions!$B$12*DCF_Base!$L$19)/(1+$A34)^10+SUMPRODUCT(Float_Income!$C$23:$L$23/(1+$A34)^DCF_Base!$C$4:$L$4)+MIN(Float_Income!$L$23*(1+E$31)/($A34-E$31),Assumptions!$B$13*Float_Income!$L$23)/(1+$A34)^10+Assumptions!$B$9)/Assumptions!$B$10,"n/a") -> 1085.8741 | F34: =IF($A34>F$31,(SUMPRODUCT(DCF_Base!$C$19:$L$19/(1+$A34)^DCF_Base!$C$4:$L$4)+MIN(DCF_Base!$L$19*(1+F$31)/($A34-F$31),Assumptions!$B$12*DCF_Base!$L$19)/(1+$A34)^10+SUMPRODUCT(Float_Income!$C$23:$L$23/(1+$A34)^DCF_Base!$C$4:$L$4)+MIN(Float_Income!$L$23*(1+F$31)/($A34-F$31),Assumptions!$B$13*Float_Income!$L$23)/(1+$A34)^10+Assumptions!$B$9)/Assumptions!$B$10,"n/a") -> 1129.961
A35: 0.11 | B35: =IF($A35>B$31,(SUMPRODUCT(DCF_Base!$C$19:$L$19/(1+$A35)^DCF_Base!$C$4:$L$4)+MIN(DCF_Base!$L$19*(1+B$31)/($A35-B$31),Assumptions!$B$12*DCF_Base!$L$19)/(1+$A35)^10+SUMPRODUCT(Float_Income!$C$23:$L$23/(1+$A35)^DCF_Base!$C$4:$L$4)+MIN(Float_Income!$L$23*(1+B$31)/($A35-B$31),Assumptions!$B$13*Float_Income!$L$23)/(1+$A35)^10+Assumptions!$B$9)/Assumptions!$B$10,"n/a") -> 930.24509 | C35: =IF($A35>C$31,(SUMPRODUCT(DCF_Base!$C$19:$L$19/(1+$A35)^DCF_Base!$C$4:$L$4)+MIN(DCF_Base!$L$19*(1+C$31)/($A35-C$31),Assumptions!$B$12*DCF_Base!$L$19)/(1+$A35)^10+SUMPRODUCT(Float_Income!$C$23:$L$23/(1+$A35)^DCF_Base!$C$4:$L$4)+MIN(Float_Income!$L$23*(1+C$31)/($A35-C$31),Assumptions!$B$13*Float_Income!$L$23)/(1+$A35)^10+Assumptions!$B$9)/Assumptions!$B$10,"n/a") -> 956.7621 | D35: =IF($A35>D$31,(SUMPRODUCT(DCF_Base!$C$19:$L$19/(1+$A35)^DCF_Base!$C$4:$L$4)+MIN(DCF_Base!$L$19*(1+D$31)/($A35-D$31),Assumptions!$B$12*DCF_Base!$L$19)/(1+$A35)^10+SUMPRODUCT(Float_Income!$C$23:$L$23/(1+$A35)^DCF_Base!$C$4:$L$4)+MIN(Float_Income!$L$23*(1+D$31)/($A35-D$31),Assumptions!$B$13*Float_Income!$L$23)/(1+$A35)^10+Assumptions!$B$9)/Assumptions!$B$10,"n/a") -> 985.08677 | E35: =IF($A35>E$31,(SUMPRODUCT(DCF_Base!$C$19:$L$19/(1+$A35)^DCF_Base!$C$4:$L$4)+MIN(DCF_Base!$L$19*(1+E$31)/($A35-E$31),Assumptions!$B$12*DCF_Base!$L$19)/(1+$A35)^10+SUMPRODUCT(Float_Income!$C$23:$L$23/(1+$A35)^DCF_Base!$C$4:$L$4)+MIN(Float_Income!$L$23*(1+E$31)/($A35-E$31),Assumptions!$B$13*Float_Income!$L$23)/(1+$A35)^10+Assumptions!$B$9)/Assumptions!$B$10,"n/a") -> 1017.1881 | F35: =IF($A35>F$31,(SUMPRODUCT(DCF_Base!$C$19:$L$19/(1+$A35)^DCF_Base!$C$4:$L$4)+MIN(DCF_Base!$L$19*(1+F$31)/($A35-F$31),Assumptions!$B$12*DCF_Base!$L$19)/(1+$A35)^10+SUMPRODUCT(Float_Income!$C$23:$L$23/(1+$A35)^DCF_Base!$C$4:$L$4)+MIN(Float_Income!$L$23*(1+F$31)/($A35-F$31),Assumptions!$B$13*Float_Income!$L$23)/(1+$A35)^10+Assumptions!$B$9)/Assumptions!$B$10,"n/a") -> 1053.8753
A36: 0.115 | B36: =IF($A36>B$31,(SUMPRODUCT(DCF_Base!$C$19:$L$19/(1+$A36)^DCF_Base!$C$4:$L$4)+MIN(DCF_Base!$L$19*(1+B$31)/($A36-B$31),Assumptions!$B$12*DCF_Base!$L$19)/(1+$A36)^10+SUMPRODUCT(Float_Income!$C$23:$L$23/(1+$A36)^DCF_Base!$C$4:$L$4)+MIN(Float_Income!$L$23*(1+B$31)/($A36-B$31),Assumptions!$B$13*Float_Income!$L$23)/(1+$A36)^10+Assumptions!$B$9)/Assumptions!$B$10,"n/a") -> 881.69573 | C36: =IF($A36>C$31,(SUMPRODUCT(DCF_Base!$C$19:$L$19/(1+$A36)^DCF_Base!$C$4:$L$4)+MIN(DCF_Base!$L$19*(1+C$31)/($A36-C$31),Assumptions!$B$12*DCF_Base!$L$19)/(1+$A36)^10+SUMPRODUCT(Float_Income!$C$23:$L$23/(1+$A36)^DCF_Base!$C$4:$L$4)+MIN(Float_Income!$L$23*(1+C$31)/($A36-C$31),Assumptions!$B$13*Float_Income!$L$23)/(1+$A36)^10+Assumptions!$B$9)/Assumptions!$B$10,"n/a") -> 904.58249 | D36: =IF($A36>D$31,(SUMPRODUCT(DCF_Base!$C$19:$L$19/(1+$A36)^DCF_Base!$C$4:$L$4)+MIN(DCF_Base!$L$19*(1+D$31)/($A36-D$31),Assumptions!$B$12*DCF_Base!$L$19)/(1+$A36)^10+SUMPRODUCT(Float_Income!$C$23:$L$23/(1+$A36)^DCF_Base!$C$4:$L$4)+MIN(Float_Income!$L$23*(1+D$31)/($A36-D$31),Assumptions!$B$13*Float_Income!$L$23)/(1+$A36)^10+Assumptions!$B$9)/Assumptions!$B$10,"n/a") -> 929.93582 | E36: =IF($A36>E$31,(SUMPRODUCT(DCF_Base!$C$19:$L$19/(1+$A36)^DCF_Base!$C$4:$L$4)+MIN(DCF_Base!$L$19*(1+E$31)/($A36-E$31),Assumptions!$B$12*DCF_Base!$L$19)/(1+$A36)^10+SUMPRODUCT(Float_Income!$C$23:$L$23/(1+$A36)^DCF_Base!$C$4:$L$4)+MIN(Float_Income!$L$23*(1+E$31)/($A36-E$31),Assumptions!$B$13*Float_Income!$L$23)/(1+$A36)^10+Assumptions!$B$9)/Assumptions!$B$10,"n/a") -> 957.13763 | F36: =IF($A36>F$31,(SUMPRODUCT(DCF_Base!$C$19:$L$19/(1+$A36)^DCF_Base!$C$4:$L$4)+MIN(DCF_Base!$L$19*(1+F$31)/($A36-F$31),Assumptions!$B$12*DCF_Base!$L$19)/(1+$A36)^10+SUMPRODUCT(Float_Income!$C$23:$L$23/(1+$A36)^DCF_Base!$C$4:$L$4)+MIN(Float_Income!$L$23*(1+F$31)/($A36-F$31),Assumptions!$B$13*Float_Income!$L$23)/(1+$A36)^10+Assumptions!$B$9)/Assumptions!$B$10,"n/a") -> 987.96636
A38: Reverse read
A39: What the current price implies | B39: At a 10.5% required return and a flat 53% reported EBITDA margin, EUR933 requires roughly a 13% net revenue CAGR for a decade - about a third off management's ~20% ambition.
