Workbook

Sheet Model_Info
A1: SE (Sea Limited, NYSE) DCF model - version 1.0, fresh build (no prior SE DCF superseded)
A2: Built by the dcf-analyst agent (Claude / Fable 5) on 2026-08-26 at the user's request.
A4: DATA VINTAGE
A5: Price $123.18 USD, Yahoo Finance regular close 2026-08-25T20:00:02Z (verified live). 52w range $77.05-$199.30.
A6: Balance sheet: 30-Jun-2026 (H1-2026 6-K filed 2026-08-11, EX-99.1 of accession 0001193125-26-344596). All bridge anchors incl. short-term investments $5,569.6m are 30-Jun-2026.
A7: Shares: 634.5m weighted-average DILUTED ADS, H1-2026 6-K (basic 611.5m). Held flat - SBC fully expensed.
A8: Guidance: FY2026 - Shopee GMV ~25% growth; Shopee adjusted EBITDA >= FY2025 in absolute dollars and to exceed $1bn (management is explicitly trading margin for growth). H1-2026 actuals: revenue $14,885m +47.4%, operating income $1,243m +31.7%, SBC $294m.
A10: METHODOLOGY - SUM OF THE PARTS (routed via dcf-methods SKILL.md: Sea straddles two rows)
A11: 1. OpCo (Shopee + Garena + corporate): 10-year component owner-FCF DCF per references/owner-fcf.md. FY0 revenue $19,138m = group $22,938m less Monee $3,800m. WACC 11.5% (USD flows; rf 4.3% + 1.35x4.5% ERP + ~1.1pp EM/FX premium). Identical WACC across scenarios - competitive and title risk priced in the scenario flows, not stacked on the rate.
A12: 2. Monee (digital financial services): an embedded EM consumer lender ($11.1bn principal at Jun-2026, +62.5% YoY, deposit/escrow funded) valued on DISTRIBUTABLE earnings = post-tax earnings less equity retained at 15% of loan-book growth, discounted at 14.5% cost of equity. A lender does not fit an FCF DCF: its book build sits in investing activities while provisions are added back in OCF, so consolidated FCF misstates it in both directions. Deposits/escrow are NOT net debt.
A13: 3. Surplus corporate net cash $4,878m added once in the bridge: cash 3,529.3 + ST inv 5,569.6 - 900 deposit-liquidity reserve - 1,100 escrow reserve (filed shortfall ~$868m: escrow 3,329.8 vs restricted cash 2,461.5; extra $232m is deliberate conservatism) - 2,220.6 corporate debt (borrowings 1,224.3 + converts 996.3). Gross cash is NOT all distributable.
A14: Leases: US GAAP ASC 842 - operating lease cost already inside adj EBITDA; operating lease liabilities ($1,906m) EXCLUDED from debt. Finance leases immaterial ($45m). One treatment, charged once.
... A24: CELL LEGEND: blue = hardcoded input, yellow fill = key driver lever, black = formula, green = cross-sheet link. Figures go stale; this file is a model, not a record.

Sheet Actuals
A1: Metric | B1: FY2020 | C1: FY2021 | D1: FY2022 | E1: FY2023 | F1: FY2024 | G1: FY2025 | H1: H1-2026
A2: Revenue ($m) | B2: 4375.7 | C2: 9955.2 | D2: 12449.7 | E2: 13063.6 | F2: 16819.9 | G2: 22938.5 | H2: 14885.3
A3: Gross profit ($m) | B3: 1348.9 | C3: 3895.7 | D3: 5185.3 | E3: 5833.6 | F3: 7205.1 | G3: 10243.7 | H3: 6695.5
A4: Operating income ($m) | B4: -1303.3 | C4: -1583.1 | D4: -1487.5 | E4: 224.8 | F4: 662.2 | G4: 1985.3 | H4: 1243.3
A5: Net income ($m) | B5: -1618.1 | C5: -2046.8 | D5: -1651.4 | E5: 150.7 | F5: 444.3 | G5: 1578.1 | H5: 868.7
A6: Operating cash flow ($m) | B6: 555.9 | C6: 208.6 | D6: -1055.7 | E6: 2079.7 | F6: 3277.4 | G6: 5024.5 | H6: 2563.9
A7: Capex ($m) | B7: 336.3 | C7: 772.2 | D7: 924.2 | E7: 241.6 | F7: 318.2 | G7: 513.8 | H7: 495
A8: Reported FCF ($m) | B8: 219.6 | C8: -563.5 | D8: -1979.9 | E8: 1838.1 | F8: 2959.3 | G8: 4510.7 | H8: 2068.9
A9: SBC ($m) | B9: 290.2 | C9: 470.3 | D9: 705.9 | E9: 685 | F9: 715.8 | G9: 625 | H9: 293.8
A10: Interest income ($m) | B10: 24.8 | C10: 36.1 | D10: 115.5 | E10: 331.3 | F10: 365.8 | G10: 331.1
A11: Provision for credit losses ($m) | B11: 51.1 | C11: 115.1 | D11: 493.6 | E11: 627.9 | F11: 764.8 | G11: 1379.2 | H11: 1021
A12: Shareholders' equity ($m) | B12: 3420.2 | C12: 7424.4 | D12: 5810.8 | E12: 6697.6 | F12: 8372.3 | G12: 12526.5 | H12: 12911.3
A13: Diluted shares (m, wtd) | B13: 477.3 | C13: 532.7 | D13: 558.1 | E13: 594.4 | F13: 604.7 | G13: 638.2 | H13: 634.5
A16: FY2025 SEGMENTS (source: Q4-2025 6-K)
A17: Shopee revenue $16,600m, adj EBITDA $880.6m; GMV $127.4bn
A18: Garena revenue $2,400m (bookings $2,900m), adj EBITDA $1,700m
A19: Monee revenue $3,800m, adj EBITDA $1,000m (post-provision)
A20: Group adj EBITDA $3,400m (unallocated ~-$180m)
A22: BALANCE SNAPSHOT 30-Jun-2026 (H1-2026 6-K)
A23: Loans receivable net $8,904m current + $715m non-current (allowance $1,115m); principal outstanding $11.1bn incl $1.1bn off-book channeling, +62.5% YoY
A24: Deposits payable $4,285m; escrow payables + customer advances $3,330m - operating funding, NOT debt
A25: Corporate debt $2,220.6m = borrowings $1,224m + convertible notes $996m; operating lease liabilities $1,906m (excluded, ASC 842); finance leases immaterial
A26: Unrestricted cash $3,529.3m; restricted cash $2,461.5m (backs escrow); ST investments $5,569.6m; long-term investments $2,756.1m (not credited); NCI $138.3m (not deducted, immaterial)
A27: Buybacks: $14.5m FY2025, $416.8m H1-2026 under $1bn Nov-2025 authorization (actual cash, not authorization)

Sheet Assumptions
A1: GLOBALS
A3: Current price (USD) | B3: 123.18 | E3: Yahoo regular close 2026-08-25T20:00:02Z - goes stale
A4: Price as of | B4: 2026-08-25 regular close
A5: Diluted shares (m, flat) | B5: 634.5 | E5: H1-2026 weighted diluted; flat because SBC is expensed
A6: OpCo WACC | B6: 0.115 | E6: USD: rf 4.3% + 1.35x4.5% ERP + ~1.1pp EM/FX premium; same for all scenarios
A7: Monee cost of equity | B7: 0.145 | E7: rf + 1.5xERP + EM consumer-credit + unseasoned-book premia
A8: D&A % of OpCo revenue | B8: 0.022 | E8: FY2025 D&A $372m trending toward capex as logistics assets season
A9: Capex % of OpCo revenue | B9: 0.028 | E9: FY2025 actual 2.7% of OpCo revenue; logistics build continues
A10: WC capture % of revenue CHANGE | B10: 0.08 | E10: Deferred revenue (Garena bookings>revenue) + payables; FY2025 actual ~9%
A11: Cash tax rate | B11: 0.26 | E11: FY2025 cash taxes $591m / ~$2.24bn pre-tax = 26.4%; EM withholding keeps it high - no fade
A13: SURPLUS NET CASH BRIDGE (30-Jun-2026, $m)
A14: Unrestricted cash | B14: 3529.3 | E14: H1-2026 6-K; restricted cash ~$2,260m sits outside this line
A15: Short-term investments | B15: 5569.6 | E15: 30-Jun-2026, Q2 2026 6-K EX-99.1 (acc. 0001193125-26-344596)
A16: Less: Monee deposit-liquidity reserve | B16: -900 | E16: ~20% of deposits payable $4,285m ring-fenced in bank entities
A17: Less: escrow backing reserve | B17: -1100 | E17: Escrow+advances $3,329.8m less restricted cash $2,461.5m = $868m filed shortfall; extra held as conservatism
A18: Less: corporate debt | B18: -2220.6 | E18: Borrowings $1,224m + convertible notes $996m; deposits/escrow are NOT debt
A19: Surplus net cash | B19: =SUM(B14:B18)
A21: MONEE GLOBALS
A22: Loan book FY2025 year-end ($m, principal) | B22: 9000 | E22: Interpolated: $6.83bn Jun-2025, $11.1bn Jun-2026 (+62.5% YoY); incl. off-book channeling
A23: Capital ratio (equity % of book) | B23: 0.15 | E23: Equity retained per $ of book growth before earnings are distributable
A25: SCENARIO GRID | B25: Bear | C25: Base | D25: Bull
A26: OpCo terminal growth | B26: 0.02 | C26: 0.03 | D26: 0.035
A27: OpCo TV cap (x FCF10) | B27: 15 | C27: 20 | D27: 20
A28: Probability weight | B28: 0.25 | C28: 0.5 | D28: 0.25
A29: Monee terminal growth | B29: 0.025 | C29: 0.035 | D29: 0.04
A30: Monee exit-P/E cap | B30: 10 | C30: 12 | D30: 14
A31: Weight sum check (must be 100%) | B31: =SUM(B28:D28)
A33: SCENARIO NARRATIVES
A34: Bear | E34: TikTok subsidy war reverses Shopee take-rate gains (margin stalls 9.5-12.5%, growth fades to GDP); Garena recovery proves promotional; Monee credit cycle hits in 2027 (ROA collapses to 3.5%, partial rebuild to 4.0%); Indonesia withholding tax and Brazil parcel tax bite.
A35: Base | E35: Duopoly holds; margin traded for growth per guidance (OpCo +38% FY2026 at 10.4% margin) then matures to 17% by Y10; Free Fire ages without a successor; Monee fades 42%->5% book growth, ROA 8.5%->5.0% as rate caps and seasoning normalize returns.
A36: Bull | E36: Subsidy rationalization; ad monetization closes toward mature peers (19% margin); Garena IP collaborations durable; Monee seasons benignly (ROA fade only to 6.0%) and compounds into Brazil/Philippines.

Sheet DCF_Bear
A1: Bear scenario - OpCo (Shopee+Garena+corporate) 10-yr owner-FCF DCF; all $m
A3: Year | B3: 2025A | C3: FY2026E | D3: FY2027E | E3: FY2028E | F3: FY2029E | G3: FY2030E | H3: FY2031E | I3: FY2032E | J3: FY2033E | K3: FY2034E | L3: FY2035E
A4: Year index | B4: 0 | C4: 1 | D4: 2 | E4: 3 | F4: 4 | G4: 5 | H4: 6 | I4: 7 | J4: 8 | K4: 9 | L4: 10
A5: Revenue growth YoY | C5: 0.33 | D5: 0.16 | E5: 0.1 | F5: 0.07 | G5: 0.05 | H5: 0.04 | I5: 0.035 | J5: 0.03 | K5: 0.025 | L5: 0.02
A6: Revenue | B6: 19138 | C6: =B6*(1+C5) | D6: =C6*(1+D5) | E6: =D6*(1+E5) | F6: =E6*(1+F5) | G6: =F6*(1+G5) | H6: =G6*(1+H5) | I6: =H6*(1+I5) | J6: =I6*(1+J5) | ... L6: =K6*(1+L5)
A7: Adj EBITDA margin | B7: =B8/B6 | C7: 0.095 | D7: 0.095 | E7: 0.1 | F7: 0.105 | G7: 0.11 | H7: 0.115 | I7: 0.118 | J7: 0.121 | K7: 0.123 | L7: 0.125
A8: Adjusted EBITDA | B8: 2400 | C8: =C6*C7 | D8: =D6*D7 | E8: =E6*E7 | F8: =F6*F7 | G8: =G6*G7 | H8: =H6*H7 | I8: =I6*I7 | J8: =J6*J7 | ... L8: =L6*L7
A9: SBC % of revenue | B9: =-B10/B6 | C9: 0.024 | D9: 0.0235 | E9: 0.023 | F9: 0.0225 | G9: 0.022 | H9: 0.0215 | I9: 0.021 | J9: 0.0205 | K9: 0.02 | L9: 0.02
A10: SBC $ | B10: -531 | C10: =-C6*C9 | D10: =-D6*D9 | E10: =-E6*E9 | F10: =-F6*F9 | G10: =-G6*G9 | H10: =-H6*H9 | I10: =-I6*I9 | J10: =-J6*J9 | ... L10: =-L6*L9
A11: Owner EBITDA (SBC expensed) | B11: =B8+B10 | C11: =C8+C10 | D11: =D8+D10 | E11: =E8+E10 | F11: =F8+F10 | G11: =G8+G10 | H11: =H8+H10 | I11: =I8+I10 | ... L11: =L8+L10
A12: D&A | B12: =-B6*Assumptions!$B$8 | C12: =-C6*Assumptions!$B$8 | D12: =-D6*Assumptions!$B$8 | E12: =-E6*Assumptions!$B$8 | F12: =-F6*Assumptions!$B$8 | G12: =-G6*Assumptions!$B$8 | H12: =-H6*Assumptions!$B$8 | I12: =-I6*Assumptions!$B$8 | ... L12: =-L6*Assumptions!$B$8
A13: EBIT (SBC expensed) | B13: =B11+B12 | C13: =C11+C12 | D13: =D11+D12 | E13: =E11+E12 | F13: =F11+F12 | G13: =G11+G12 | H13: =H11+H12 | I13: =I11+I12 | ... L13: =L11+L12
A14: Cash tax rate | B14: 0.26 | C14: 0.26 | D14: 0.26 | E14: 0.26 | F14: 0.26 | G14: 0.26 | H14: 0.26 | I14: 0.26 | J14: 0.26 | K14: 0.26 | L14: 0.26
A15: NOPAT | B15: =B13*(1-B14) | C15: =C13*(1-C14) | D15: =D13*(1-D14) | E15: =E13*(1-E14) | F15: =F13*(1-F14) | G15: =G13*(1-G14) | H15: =H13*(1-H14) | I15: =I13*(1-I14) | ... L15: =L13*(1-L14)
A16: add back D&A | B16: =-B12 | C16: =-C12 | D16: =-D12 | E16: =-E12 | F16: =-F12 | G16: =-G12 | H16: =-H12 | I16: =-I12 | ... L16: =-L12
A17: less capex | B17: -513.8 | C17: =-C6*Assumptions!$B$9 | D17: =-D6*Assumptions!$B$9 | E17: =-E6*Assumptions!$B$9 | F17: =-F6*Assumptions!$B$9 | G17: =-G6*Assumptions!$B$9 | H17: =-H6*Assumptions!$B$9 | I17: =-I6*Assumptions!$B$9 | J17: =-J6*Assumptions!$B$9 | ... L17: =-L6*Assumptions!$B$9
A18: add working capital capture | B18: 377.4 | C18: =Assumptions!$B$10*(C6-B6) | D18: =Assumptions!$B$10*(D6-C6) | E18: =Assumptions!$B$10*(E6-D6) | F18: =Assumptions!$B$10*(F6-E6) | G18: =Assumptions!$B$10*(G6-F6) | H18: =Assumptions!$B$10*(H6-G6) | I18: =Assumptions!$B$10*(I6-H6) | J18: =Assumptions!$B$10*(J6-I6) | ... L18: =Assumptions!$B$10*(L6-K6)
A19: Unlevered owner FCF | B19: =B15+B16+B17+B18 | C19: =C15+C16+C17+C18 | D19: =D15+D16+D17+D18 | E19: =E15+E16+E17+E18 | F19: =F15+F16+F17+F18 | G19: =G15+G16+G17+G18 | H19: =H15+H16+H17+H18 | I19: =I15+I16+I17+I18 | ... L19: =L15+L16+L17+L18
A20: Discount factor @ WACC | C20: =1/(1+Assumptions!$B$6)^C4 | D20: =1/(1+Assumptions!$B$6)^D4 | E20: =1/(1+Assumptions!$B$6)^E4 | F20: =1/(1+Assumptions!$B$6)^F4 | G20: =1/(1+Assumptions!$B$6)^G4 | H20: =1/(1+Assumptions!$B$6)^H4 | I20: =1/(1+Assumptions!$B$6)^I4 | J20: =1/(1+Assumptions!$B$6)^J4 | ... L20: =1/(1+Assumptions!$B$6)^L4
A21: PV of FCF | C21: =C19*C20 | D21: =D19*D20 | E21: =E19*E20 | F21: =F19*F20 | G21: =G19*G20 | H21: =H19*H20 | I21: =I19*I20 | J21: =J19*J20 | ... L21: =L19*L20
A23: Memo: FCF before SBC (street-style) | C23: =C19-C10 | D23: =D19-D10 | E23: =E19-E10 | F23: =F19-F10 | G23: =G19-G10 | H23: =H19-H10 | I23: =I19-I10 | J23: =J19-J10 | ... L23: =L19-L10
A24: Memo: owner-FCF margin | B24: =B19/B6 | C24: =C19/C6 | D24: =D19/D6 | E24: =E19/E6 | F24: =F19/F6 | G24: =G19/G6 | H24: =H19/H6 | I24: =I19/I6 | ... L24: =L19/L6
A26: Sum PV of FCF (Y1-10) | B26: =SUM(C21:L21)
A27: Terminal growth | B27: =Assumptions!$B$26
A28: Terminal FCF (Y10 grown) | B28: =L19*(1+B27)
A29: Gordon TV | B29: =B28/(Assumptions!$B$6-B27)
A30: Cap TV | B30: =Assumptions!$B$27*L19
A31: TV used = MAX(0, MIN(Gordon, cap)) | B31: =MAX(0,MIN(B29,B30))
A32: Implied exit multiple (TV/FCF10) | B32: =B31/L19
A33: PV of terminal value | B33: =B31/(1+Assumptions!$B$6)^10
A34: OpCo enterprise value | B34: =B26+B33
A35: Monee equity value (distributable-earnings model) | B35: =Monee!$B$20
A36: Surplus corporate net cash | B36: =Assumptions!$B$19
A37: Equity value | B37: =B34+B35+B36
A38: Diluted shares (m, flat) | B38: =Assumptions!$B$5
A39: VALUE PER SHARE (house basis) | B39: =B37/B38
A40: Upside vs current price | B40: =B39/Assumptions!$B$3-1
A42: Street memo: PV of explicit SBC | B42: =SUMPRODUCT(-C10:L10/(1+Assumptions!$B$6)^C4:L4)
A43: Street memo: PV of terminal SBC | B43: =(-L10)*(1+B27)/(Assumptions!$B$6-B27)/(1+Assumptions!$B$6)^10
A44: Street value per share (SBC as non-cash) | B44: =(B37+B42+B43)/B38

Sheet DCF_Base
A1: Base scenario - OpCo (Shopee+Garena+corporate) 10-yr owner-FCF DCF; all $m
A3: Year | B3: 2025A | C3: FY2026E | D3: FY2027E | E3: FY2028E | F3: FY2029E | G3: FY2030E | H3: FY2031E | I3: FY2032E | J3: FY2033E | K3: FY2034E | L3: FY2035E
A4: Year index | B4: 0 | C4: 1 | D4: 2 | E4: 3 | F4: 4 | G4: 5 | H4: 6 | I4: 7 | J4: 8 | K4: 9 | L4: 10
A5: Revenue growth YoY | C5: 0.38 | D5: 0.24 | E5: 0.18 | F5: 0.14 | G5: 0.11 | H5: 0.09 | I5: 0.075 | J5: 0.065 | K5: 0.055 | L5: 0.045
A6: Revenue | B6: 19138 | C6: =B6*(1+C5) | D6: =C6*(1+D5) | E6: =D6*(1+E5) | F6: =E6*(1+F5) | G6: =F6*(1+G5) | H6: =G6*(1+H5) | I6: =H6*(1+I5) | J6: =I6*(1+J5) | ... L6: =K6*(1+L5)
A7: Adj EBITDA margin | B7: =B8/B6 | C7: 0.104 | D7: 0.115 | E7: 0.125 | F7: 0.135 | G7: 0.145 | H7: 0.152 | I7: 0.158 | J7: 0.163 | K7: 0.167 | L7: 0.17
A8: Adjusted EBITDA | B8: 2400 | C8: =C6*C7 | D8: =D6*D7 | E8: =E6*E7 | F8: =F6*F7 | G8: =G6*G7 | H8: =H6*H7 | I8: =I6*I7 | J8: =J6*J7 | ... L8: =L6*L7
A9: SBC % of revenue | B9: =-B10/B6 | C9: 0.024 | D9: 0.023 | E9: 0.022 | F9: 0.021 | G9: 0.02 | H9: 0.019 | I9: 0.018 | J9: 0.017 | K9: 0.0165 | L9: 0.016
A10: SBC $ | B10: -531 | C10: =-C6*C9 | D10: =-D6*D9 | E10: =-E6*E9 | F10: =-F6*F9 | G10: =-G6*G9 | H10: =-H6*H9 | I10: =-I6*I9 | J10: =-J6*J9 | ... L10: =-L6*L9
A11: Owner EBITDA (SBC expensed) | B11: =B8+B10 | C11: =C8+C10 | D11: =D8+D10 | E11: =E8+E10 | F11: =F8+F10 | G11: =G8+G10 | H11: =H8+H10 | I11: =I8+I10 | ... L11: =L8+L10
A12: D&A | B12: =-B6*Assumptions!$B$8 | C12: =-C6*Assumptions!$B$8 | D12: =-D6*Assumptions!$B$8 | E12: =-E6*Assumptions!$B$8 | F12: =-F6*Assumptions!$B$8 | G12: =-G6*Assumptions!$B$8 | H12: =-H6*Assumptions!$B$8 | I12: =-I6*Assumptions!$B$8 | ... L12: =-L6*Assumptions!$B$8
A13: EBIT (SBC expensed) | B13: =B11+B12 | C13: =C11+C12 | D13: =D11+D12 | E13: =E11+E12 | F13: =F11+F12 | G13: =G11+G12 | H13: =H11+H12 | I13: =I11+I12 | ... L13: =L11+L12
A14: Cash tax rate | B14: 0.26 | C14: 0.26 | D14: 0.26 | E14: 0.26 | F14: 0.26 | G14: 0.26 | H14: 0.26 | I14: 0.26 | J14: 0.26 | K14: 0.26 | L14: 0.26
A15: NOPAT | B15: =B13*(1-B14) | C15: =C13*(1-C14) | D15: =D13*(1-D14) | E15: =E13*(1-E14) | F15: =F13*(1-F14) | G15: =G13*(1-G14) | H15: =H13*(1-H14) | I15: =I13*(1-I14) | ... L15: =L13*(1-L14)
A16: add back D&A | B16: =-B12 | C16: =-C12 | D16: =-D12 | E16: =-E12 | F16: =-F12 | G16: =-G12 | H16: =-H12 | I16: =-I12 | ... L16: =-L12
A17: less capex | B17: -513.8 | C17: =-C6*Assumptions!$B$9 | D17: =-D6*Assumptions!$B$9 | E17: =-E6*Assumptions!$B$9 | F17: =-F6*Assumptions!$B$9 | G17: =-G6*Assumptions!$B$9 | H17: =-H6*Assumptions!$B$9 | I17: =-I6*Assumptions!$B$9 | J17: =-J6*Assumptions!$B$9 | ... L17: =-L6*Assumptions!$B$9
A18: add working capital capture | B18: 377.4 | C18: =Assumptions!$B$10*(C6-B6) | D18: =Assumptions!$B$10*(D6-C6) | E18: =Assumptions!$B$10*(E6-D6) | F18: =Assumptions!$B$10*(F6-E6) | G18: =Assumptions!$B$10*(G6-F6) | H18: =Assumptions!$B$10*(H6-G6) | I18: =Assumptions!$B$10*(I6-H6) | J18: =Assumptions!$B$10*(J6-I6) | ... L18: =Assumptions!$B$10*(L6-K6)
A19: Unlevered owner FCF | B19: =B15+B16+B17+B18 | C19: =C15+C16+C17+C18 | D19: =D15+D16+D17+D18 | E19: =E15+E16+E17+E18 | F19: =F15+F16+F17+F18 | G19: =G15+G16+G17+G18 | H19: =H15+H16+H17+H18 | I19: =I15+I16+I17+I18 | ... L19: =L15+L16+L17+L18
A20: Discount factor @ WACC | C20: =1/(1+Assumptions!$B$6)^C4 | D20: =1/(1+Assumptions!$B$6)^D4 | E20: =1/(1+Assumptions!$B$6)^E4 | F20: =1/(1+Assumptions!$B$6)^F4 | G20: =1/(1+Assumptions!$B$6)^G4 | H20: =1/(1+Assumptions!$B$6)^H4 | I20: =1/(1+Assumptions!$B$6)^I4 | J20: =1/(1+Assumptions!$B$6)^J4 | ... L20: =1/(1+Assumptions!$B$6)^L4
A21: PV of FCF | C21: =C19*C20 | D21: =D19*D20 | E21: =E19*E20 | F21: =F19*F20 | G21: =G19*G20 | H21: =H19*H20 | I21: =I19*I20 | J21: =J19*J20 | ... L21: =L19*L20
A23: Memo: FCF before SBC (street-style) | C23: =C19-C10 | D23: =D19-D10 | E23: =E19-E10 | F23: =F19-F10 | G23: =G19-G10 | H23: =H19-H10 | I23: =I19-I10 | J23: =J19-J10 | ... L23: =L19-L10
A24: Memo: owner-FCF margin | B24: =B19/B6 | C24: =C19/C6 | D24: =D19/D6 | E24: =E19/E6 | F24: =F19/F6 | G24: =G19/G6 | H24: =H19/H6 | I24: =I19/I6 | ... L24: =L19/L6
A26: Sum PV of FCF (Y1-10) | B26: =SUM(C21:L21)
A27: Terminal growth | B27: =Assumptions!$C$26
A28: Terminal FCF (Y10 grown) | B28: =L19*(1+B27)
A29: Gordon TV | B29: =B28/(Assumptions!$B$6-B27)
A30: Cap TV | B30: =Assumptions!$C$27*L19
A31: TV used = MAX(0, MIN(Gordon, cap)) | B31: =MAX(0,MIN(B29,B30))
A32: Implied exit multiple (TV/FCF10) | B32: =B31/L19
A33: PV of terminal value | B33: =B31/(1+Assumptions!$B$6)^10
A34: OpCo enterprise value | B34: =B26+B33
A35: Monee equity value (distributable-earnings model) | B35: =Monee!$B$37
A36: Surplus corporate net cash | B36: =Assumptions!$B$19
A37: Equity value | B37: =B34+B35+B36
A38: Diluted shares (m, flat) | B38: =Assumptions!$B$5
A39: VALUE PER SHARE (house basis) | B39: =B37/B38
A40: Upside vs current price | B40: =B39/Assumptions!$B$3-1
A42: Street memo: PV of explicit SBC | B42: =SUMPRODUCT(-C10:L10/(1+Assumptions!$B$6)^C4:L4)
A43: Street memo: PV of terminal SBC | B43: =(-L10)*(1+B27)/(Assumptions!$B$6-B27)/(1+Assumptions!$B$6)^10
A44: Street value per share (SBC as non-cash) | B44: =(B37+B42+B43)/B38

Sheet DCF_Bull
A1: Bull scenario - OpCo (Shopee+Garena+corporate) 10-yr owner-FCF DCF; all $m
A3: Year | B3: 2025A | C3: FY2026E | D3: FY2027E | E3: FY2028E | F3: FY2029E | G3: FY2030E | H3: FY2031E | I3: FY2032E | J3: FY2033E | K3: FY2034E | L3: FY2035E
A4: Year index | B4: 0 | C4: 1 | D4: 2 | E4: 3 | F4: 4 | G4: 5 | H4: 6 | I4: 7 | J4: 8 | K4: 9 | L4: 10
A5: Revenue growth YoY | C5: 0.42 | D5: 0.3 | E5: 0.24 | F5: 0.18 | G5: 0.14 | H5: 0.11 | I5: 0.09 | J5: 0.075 | K5: 0.06 | L5: 0.05
A6: Revenue | B6: 19138 | C6: =B6*(1+C5) | D6: =C6*(1+D5) | E6: =D6*(1+E5) | F6: =E6*(1+F5) | G6: =F6*(1+G5) | H6: =G6*(1+H5) | I6: =H6*(1+I5) | J6: =I6*(1+J5) | ... L6: =K6*(1+L5)
A7: Adj EBITDA margin | B7: =B8/B6 | C7: 0.108 | D7: 0.125 | E7: 0.14 | F7: 0.155 | G7: 0.165 | H7: 0.173 | I7: 0.18 | J7: 0.185 | K7: 0.188 | L7: 0.19
A8: Adjusted EBITDA | B8: 2400 | C8: =C6*C7 | D8: =D6*D7 | E8: =E6*E7 | F8: =F6*F7 | G8: =G6*G7 | H8: =H6*H7 | I8: =I6*I7 | J8: =J6*J7 | ... L8: =L6*L7
A9: SBC % of revenue | B9: =-B10/B6 | C9: 0.024 | D9: 0.023 | E9: 0.022 | F9: 0.021 | G9: 0.02 | H9: 0.019 | I9: 0.018 | J9: 0.017 | K9: 0.0165 | L9: 0.016
A10: SBC $ | B10: -531 | C10: =-C6*C9 | D10: =-D6*D9 | E10: =-E6*E9 | F10: =-F6*F9 | G10: =-G6*G9 | H10: =-H6*H9 | I10: =-I6*I9 | J10: =-J6*J9 | ... L10: =-L6*L9
A11: Owner EBITDA (SBC expensed) | B11: =B8+B10 | C11: =C8+C10 | D11: =D8+D10 | E11: =E8+E10 | F11: =F8+F10 | G11: =G8+G10 | H11: =H8+H10 | I11: =I8+I10 | ... L11: =L8+L10
A12: D&A | B12: =-B6*Assumptions!$B$8 | C12: =-C6*Assumptions!$B$8 | D12: =-D6*Assumptions!$B$8 | E12: =-E6*Assumptions!$B$8 | F12: =-F6*Assumptions!$B$8 | G12: =-G6*Assumptions!$B$8 | H12: =-H6*Assumptions!$B$8 | I12: =-I6*Assumptions!$B$8 | ... L12: =-L6*Assumptions!$B$8
A13: EBIT (SBC expensed) | B13: =B11+B12 | C13: =C11+C12 | D13: =D11+D12 | E13: =E11+E12 | F13: =F11+F12 | G13: =G11+G12 | H13: =H11+H12 | I13: =I11+I12 | ... L13: =L11+L12
A14: Cash tax rate | B14: 0.26 | C14: 0.26 | D14: 0.26 | E14: 0.26 | F14: 0.26 | G14: 0.26 | H14: 0.26 | I14: 0.26 | J14: 0.26 | K14: 0.26 | L14: 0.26
A15: NOPAT | B15: =B13*(1-B14) | C15: =C13*(1-C14) | D15: =D13*(1-D14) | E15: =E13*(1-E14) | F15: =F13*(1-F14) | G15: =G13*(1-G14) | H15: =H13*(1-H14) | I15: =I13*(1-I14) | ... L15: =L13*(1-L14)
A16: add back D&A | B16: =-B12 | C16: =-C12 | D16: =-D12 | E16: =-E12 | F16: =-F12 | G16: =-G12 | H16: =-H12 | I16: =-I12 | ... L16: =-L12
A17: less capex | B17: -513.8 | C17: =-C6*Assumptions!$B$9 | D17: =-D6*Assumptions!$B$9 | E17: =-E6*Assumptions!$B$9 | F17: =-F6*Assumptions!$B$9 | G17: =-G6*Assumptions!$B$9 | H17: =-H6*Assumptions!$B$9 | I17: =-I6*Assumptions!$B$9 | J17: =-J6*Assumptions!$B$9 | ... L17: =-L6*Assumptions!$B$9
A18: add working capital capture | B18: 377.4 | C18: =Assumptions!$B$10*(C6-B6) | D18: =Assumptions!$B$10*(D6-C6) | E18: =Assumptions!$B$10*(E6-D6) | F18: =Assumptions!$B$10*(F6-E6) | G18: =Assumptions!$B$10*(G6-F6) | H18: =Assumptions!$B$10*(H6-G6) | I18: =Assumptions!$B$10*(I6-H6) | J18: =Assumptions!$B$10*(J6-I6) | ... L18: =Assumptions!$B$10*(L6-K6)
A19: Unlevered owner FCF | B19: =B15+B16+B17+B18 | C19: =C15+C16+C17+C18 | D19: =D15+D16+D17+D18 | E19: =E15+E16+E17+E18 | F19: =F15+F16+F17+F18 | G19: =G15+G16+G17+G18 | H19: =H15+H16+H17+H18 | I19: =I15+I16+I17+I18 | ... L19: =L15+L16+L17+L18
A20: Discount factor @ WACC | C20: =1/(1+Assumptions!$B$6)^C4 | D20: =1/(1+Assumptions!$B$6)^D4 | E20: =1/(1+Assumptions!$B$6)^E4 | F20: =1/(1+Assumptions!$B$6)^F4 | G20: =1/(1+Assumptions!$B$6)^G4 | H20: =1/(1+Assumptions!$B$6)^H4 | I20: =1/(1+Assumptions!$B$6)^I4 | J20: =1/(1+Assumptions!$B$6)^J4 | ... L20: =1/(1+Assumptions!$B$6)^L4
A21: PV of FCF | C21: =C19*C20 | D21: =D19*D20 | E21: =E19*E20 | F21: =F19*F20 | G21: =G19*G20 | H21: =H19*H20 | I21: =I19*I20 | J21: =J19*J20 | ... L21: =L19*L20
A23: Memo: FCF before SBC (street-style) | C23: =C19-C10 | D23: =D19-D10 | E23: =E19-E10 | F23: =F19-F10 | G23: =G19-G10 | H23: =H19-H10 | I23: =I19-I10 | J23: =J19-J10 | ... L23: =L19-L10
A24: Memo: owner-FCF margin | B24: =B19/B6 | C24: =C19/C6 | D24: =D19/D6 | E24: =E19/E6 | F24: =F19/F6 | G24: =G19/G6 | H24: =H19/H6 | I24: =I19/I6 | ... L24: =L19/L6
A26: Sum PV of FCF (Y1-10) | B26: =SUM(C21:L21)
A27: Terminal growth | B27: =Assumptions!$D$26
A28: Terminal FCF (Y10 grown) | B28: =L19*(1+B27)
A29: Gordon TV | B29: =B28/(Assumptions!$B$6-B27)
A30: Cap TV | B30: =Assumptions!$D$27*L19
A31: TV used = MAX(0, MIN(Gordon, cap)) | B31: =MAX(0,MIN(B29,B30))
A32: Implied exit multiple (TV/FCF10) | B32: =B31/L19
A33: PV of terminal value | B33: =B31/(1+Assumptions!$B$6)^10
A34: OpCo enterprise value | B34: =B26+B33
A35: Monee equity value (distributable-earnings model) | B35: =Monee!$B$54
A36: Surplus corporate net cash | B36: =Assumptions!$B$19
A37: Equity value | B37: =B34+B35+B36
A38: Diluted shares (m, flat) | B38: =Assumptions!$B$5
A39: VALUE PER SHARE (house basis) | B39: =B37/B38
A40: Upside vs current price | B40: =B39/Assumptions!$B$3-1
A42: Street memo: PV of explicit SBC | B42: =SUMPRODUCT(-C10:L10/(1+Assumptions!$B$6)^C4:L4)
A43: Street memo: PV of terminal SBC | B43: =(-L10)*(1+B27)/(Assumptions!$B$6-B27)/(1+Assumptions!$B$6)^10
A44: Street value per share (SBC as non-cash) | B44: =(B37+B42+B43)/B38

Sheet Monee
A1: Monee - distributable-earnings lender model. Earnings less equity retained (15% of book growth) at 14.5% CoE. Deposits/escrow are operating funding, never net debt. All $m.
A4: Bear scenario
A5: Year index | B5: 0 | C5: 1 | D5: 2 | E5: 3 | F5: 4 | G5: 5 | H5: 6 | I5: 7 | J5: 8 | K5: 9 | L5: 10
A6: Book growth YoY | C6: 0.3 | D6: 0.08 | E6: 0.1 | F6: 0.12 | G6: 0.1 | H6: 0.08 | I6: 0.06 | J6: 0.05 | K6: 0.04 | L6: 0.03
A7: Loan book year-end (principal) | B7: =Assumptions!$B$22 | C7: =B7*(1+C6) | D7: =C7*(1+D6) | E7: =D7*(1+E6) | F7: =E7*(1+F6) | G7: =F7*(1+G6) | H7: =G7*(1+H6) | I7: =H7*(1+I6) | J7: =I7*(1+J6) | ... L7: =K7*(1+L6)
A8: Average book | C8: =(B7+C7)/2 | D8: =(C7+D7)/2 | E8: =(D7+E7)/2 | F8: =(E7+F7)/2 | G8: =(F7+G7)/2 | H8: =(G7+H7)/2 | I8: =(H7+I7)/2 | J8: =(I7+J7)/2 | ... L8: =(K7+L7)/2
A9: ROA on avg book | C9: 0.075 | D9: 0.035 | E9: 0.045 | F9: 0.05 | G9: 0.05 | H9: 0.048 | I9: 0.046 | J9: 0.044 | K9: 0.042 | L9: 0.04
A10: Post-tax earnings | C10: =C8*C9 | D10: =D8*D9 | E10: =E8*E9 | F10: =F8*F9 | G10: =G8*G9 | H10: =H8*H9 | I10: =I8*I9 | J10: =J8*J9 | ... L10: =L8*L9
A11: Equity retained (15% x book growth) | C11: =Assumptions!$B$23*(C7-B7) | D11: =Assumptions!$B$23*(D7-C7) | E11: =Assumptions!$B$23*(E7-D7) | F11: =Assumptions!$B$23*(F7-E7) | G11: =Assumptions!$B$23*(G7-F7) | H11: =Assumptions!$B$23*(H7-G7) | I11: =Assumptions!$B$23*(I7-H7) | J11: =Assumptions!$B$23*(J7-I7) | ... L11: =Assumptions!$B$23*(L7-K7)
A12: Distributable earnings | C12: =C10-C11 | D12: =D10-D11 | E12: =E10-E11 | F12: =F10-F11 | G12: =G10-G11 | H12: =H10-H11 | I12: =I10-I11 | J12: =J10-J11 | ... L12: =L10-L11
A13: Discount factor @ CoE | C13: =1/(1+Assumptions!$B$7)^C5 | D13: =1/(1+Assumptions!$B$7)^D5 | E13: =1/(1+Assumptions!$B$7)^E5 | F13: =1/(1+Assumptions!$B$7)^F5 | G13: =1/(1+Assumptions!$B$7)^G5 | H13: =1/(1+Assumptions!$B$7)^H5 | I13: =1/(1+Assumptions!$B$7)^I5 | J13: =1/(1+Assumptions!$B$7)^J5 | ... L13: =1/(1+Assumptions!$B$7)^L5
A14: PV of distributable | C14: =C12*C13 | D14: =D12*D13 | E14: =E12*E13 | F14: =F12*F13 | G14: =G12*G13 | H14: =H12*H13 | I14: =I12*I13 | J14: =J12*J13 | ... L14: =L12*L13
A15: Sum PV of distributable | B15: =SUM(C14:L14)
A16: Gordon TV on distributable | B16: =L12*(1+Assumptions!$B$29)/(Assumptions!$B$7-Assumptions!$B$29)
A17: Cap TV (exit P/E x terminal earnings) | B17: =Assumptions!$B$30*L10
A18: TV used = MAX(0, MIN(Gordon, cap)) | B18: =MAX(0,MIN(B16,B17))
A19: PV of TV | B19: =B18/(1+Assumptions!$B$7)^10
A20: MONEE EQUITY VALUE | B20: =B15+B19
A21: Base scenario
A22: Year index | B22: 0 | C22: 1 | D22: 2 | E22: 3 | F22: 4 | G22: 5 | H22: 6 | I22: 7 | J22: 8 | K22: 9 | L22: 10
A23: Book growth YoY | C23: 0.42 | D23: 0.33 | E23: 0.25 | F23: 0.18 | G23: 0.14 | H23: 0.11 | I23: 0.09 | J23: 0.07 | K23: 0.06 | L23: 0.05
A24: Loan book year-end (principal) | B24: =Assumptions!$B$22 | C24: =B24*(1+C23) | D24: =C24*(1+D23) | E24: =D24*(1+E23) | F24: =E24*(1+F23) | G24: =F24*(1+G23) | H24: =G24*(1+H23) | I24: =H24*(1+I23) | J24: =I24*(1+J23) | ... L24: =K24*(1+L23)
A25: Average book | C25: =(B24+C24)/2 | D25: =(C24+D24)/2 | E25: =(D24+E24)/2 | F25: =(E24+F24)/2 | G25: =(F24+G24)/2 | H25: =(G24+H24)/2 | I25: =(H24+I24)/2 | J25: =(I24+J24)/2 | ... L25: =(K24+L24)/2
A26: ROA on avg book | C26: 0.085 | D26: 0.08 | E26: 0.075 | F26: 0.07 | G26: 0.065 | H26: 0.062 | I26: 0.058 | J26: 0.055 | K26: 0.052 | L26: 0.05
A27: Post-tax earnings | C27: =C25*C26 | D27: =D25*D26 | E27: =E25*E26 | F27: =F25*F26 | G27: =G25*G26 | H27: =H25*H26 | I27: =I25*I26 | J27: =J25*J26 | ... L27: =L25*L26
A28: Equity retained (15% x book growth) | C28: =Assumptions!$B$23*(C24-B24) | D28: =Assumptions!$B$23*(D24-C24) | E28: =Assumptions!$B$23*(E24-D24) | F28: =Assumptions!$B$23*(F24-E24) | G28: =Assumptions!$B$23*(G24-F24) | H28: =Assumptions!$B$23*(H24-G24) | I28: =Assumptions!$B$23*(I24-H24) | J28: =Assumptions!$B$23*(J24-I24) | ... L28: =Assumptions!$B$23*(L24-K24)
A29: Distributable earnings | C29: =C27-C28 | D29: =D27-D28 | E29: =E27-E28 | F29: =F27-F28 | G29: =G27-G28 | H29: =H27-H28 | I29: =I27-I28 | J29: =J27-J28 | ... L29: =L27-L28
A30: Discount factor @ CoE | C30: =1/(1+Assumptions!$B$7)^C22 | D30: =1/(1+Assumptions!$B$7)^D22 | E30: =1/(1+Assumptions!$B$7)^E22 | F30: =1/(1+Assumptions!$B$7)^F22 | G30: =1/(1+Assumptions!$B$7)^G22 | H30: =1/(1+Assumptions!$B$7)^H22 | I30: =1/(1+Assumptions!$B$7)^I22 | J30: =1/(1+Assumptions!$B$7)^J22 | ... L30: =1/(1+Assumptions!$B$7)^L22
A31: PV of distributable | C31: =C29*C30 | D31: =D29*D30 | E31: =E29*E30 | F31: =F29*F30 | G31: =G29*G30 | H31: =H29*H30 | I31: =I29*I30 | J31: =J29*J30 | ... L31: =L29*L30
A32: Sum PV of distributable | B32: =SUM(C31:L31)
A33: Gordon TV on distributable | B33: =L29*(1+Assumptions!$C$29)/(Assumptions!$B$7-Assumptions!$C$29)
A34: Cap TV (exit P/E x terminal earnings) | B34: =Assumptions!$C$30*L27
A35: TV used = MAX(0, MIN(Gordon, cap)) | B35: =MAX(0,MIN(B33,B34))
A36: PV of TV | B36: =B35/(1+Assumptions!$B$7)^10
A37: MONEE EQUITY VALUE | B37: =B32+B36
A38: Bull scenario
A39: Year index | B39: 0 | C39: 1 | D39: 2 | E39: 3 | F39: 4 | G39: 5 | H39: 6 | I39: 7 | J39: 8 | K39: 9 | L39: 10
A40: Book growth YoY | C40: 0.45 | D40: 0.38 | E40: 0.3 | F40: 0.24 | G40: 0.18 | H40: 0.14 | I40: 0.11 | J40: 0.09 | K40: 0.075 | L40: 0.06
A41: Loan book year-end (principal) | B41: =Assumptions!$B$22 | C41: =B41*(1+C40) | D41: =C41*(1+D40) | E41: =D41*(1+E40) | F41: =E41*(1+F40) | G41: =F41*(1+G40) | H41: =G41*(1+H40) | I41: =H41*(1+I40) | J41: =I41*(1+J40) | ... L41: =K41*(1+L40)
A42: Average book | C42: =(B41+C41)/2 | D42: =(C41+D41)/2 | E42: =(D41+E41)/2 | F42: =(E41+F41)/2 | G42: =(F41+G41)/2 | H42: =(G41+H41)/2 | I42: =(H41+I41)/2 | J42: =(I41+J41)/2 | ... L42: =(K41+L41)/2
...

Sheet FCF_Quality
A1: Consolidated reported FCF reconciled to owner FCF - and why the consolidated series is NOT the DCF base
C3: FY2020 | D3: FY2021 | E3: FY2022 | F3: FY2023 | G3: FY2024 | H3: FY2025
A4: Reported FCF (OCF - capex) | C4: 219.6 | D4: -563.5 | E4: -1979.9 | F4: 1838.1 | G4: 2959.3 | H4: 4510.7
A5: less: SBC | C5: -290.2 | D5: -470.3 | E5: -705.9 | F5: -685 | G5: -715.8 | H5: -625
A6: less: interest income | C6: -24.8 | D6: -36.1 | E6: -115.5 | F6: -331.3 | G6: -365.8 | H6: -331.1
A7: Owner FCF (consolidated convention) | C7: =SUM(C4:C6) | D7: =SUM(D4:D6) | E7: =SUM(E4:E6) | F7: =SUM(F4:F6) | G7: =SUM(G4:G6) | H7: =SUM(H4:H6)
A8: Memo: revenue | C8: 4375.7 | D8: 9955.2 | E8: 12449.7 | F8: 13063.6 | G8: 16819.9 | H8: 22938.5
A9: Owner FCF margin | C9: =C7/C8 | D9: =D7/D8 | E9: =E7/E8 | F9: =F7/F8 | G9: =G7/G8 | H9: =H7/H8
A10: Memo: provision for credit losses (added back in OCF) | C10: 51.1 | D10: 115.1 | E10: 493.6 | F10: 627.9 | G10: 764.8 | H10: 1379.2
A11: Memo: cash taxes paid | C11: 144.9 | D11: 207.4 | E11: 313.8 | F11: 318.9 | G11: 515.3 | H11: 591.1
A14: WHY THE $3,554.6m FY2025 CONSOLIDATED OWNER FCF IS NOT THE DCF BASE:
A15: Sea classifies the loan-book build (~$3.8bn net increase in loans receivable FY2025) in INVESTING activities and adds the $1,379m credit provision back inside OCF,
A16: so reported FCF carries Monee's pre-provision earnings without the cash its growth consumes. The DCF therefore uses the component-built OpCo owner FCF
A17: (FY2025: $1,356m = seg adj EBITDA 2,400 - SBC 531 - D&A 421, taxed 26%, + D&A - capex 513.8 + WC 377) and values Monee separately on distributable earnings.
A18: Deferred-revenue increase FY2025 was +$562m (Garena bookings > revenue), captured forward via the 8% WC-capture driver on revenue CHANGE.

Sheet Valuation
A1: SE valuation summary - sum of the parts, house basis (SBC expensed, flat 634.5m diluted count)
A3: Scenario | B3: Bear | C3: Base | D3: Bull
A4: Value per share (house) | B4: =DCF_Bear!$B$39 | C4: =DCF_Base!$B$39 | D4: =DCF_Bull!$B$39
A5: Upside vs price | B5: =B4/Assumptions!$B$3-1 | C5: =C4/Assumptions!$B$3-1 | D5: =D4/Assumptions!$B$3-1
A6: Probability weight | B6: =Assumptions!$B$28 | C6: =Assumptions!$C$28 | D6: =Assumptions!$D$28
A7: Street value per share | B7: =DCF_Bear!$B$44 | C7: =DCF_Base!$B$44 | D7: =DCF_Bull!$B$44
A9: PROBABILITY-WEIGHTED VALUE (house) | B9: =SUMPRODUCT(B4:D4,B6:D6)
A10: Weighted street value | B10: =SUMPRODUCT(B7:D7,B6:D6)
A11: Margin of safety at current price | B11: =1-Assumptions!$B$3/B9
A12: Band position (0%=house, 100%=street) | B12: =(Assumptions!$B$3-B9)/(B10-B9) | E12: Above 100% = the price exceeds even the SBC-as-non-cash ceiling
A14: REQUIRED-RETURN TABLE (base case; TVs held at model rates)
A15: Required return | B15: 0.09 | C15: 0.1 | D15: 0.11 | E15: 0.115 | F15: 0.12 | G15: 0.15
A16: Value per share | B16: =(SUMPRODUCT(DCF_Base!$C$19:$L$19/(1+B15)^DCF_Base!$C$4:$L$4)+DCF_Base!$B$31/(1+B15)^10+SUMPRODUCT(Monee!$C$29:$L$29/(1+B15)^Monee!$C$22:$L$22)+Monee!$B$35/(1+B15)^10+Assumptions!$B$19)/Assumptions!$B$5 | C16: =(SUMPRODUCT(DCF_Base!$C$19:$L$19/(1+C15)^DCF_Base!$C$4:$L$4)+DCF_Base!$B$31/(1+C15)^10+SUMPRODUCT(Monee!$C$29:$L$29/(1+C15)^Monee!$C$22:$L$22)+Monee!$B$35/(1+C15)^10+Assumptions!$B$19)/Assumptions!$B$5 | D16: =(SUMPRODUCT(DCF_Base!$C$19:$L$19/(1+D15)^DCF_Base!$C$4:$L$4)+DCF_Base!$B$31/(1+D15)^10+SUMPRODUCT(Monee!$C$29:$L$29/(1+D15)^Monee!$C$22:$L$22)+Monee!$B$35/(1+D15)^10+Assumptions!$B$19)/Assumptions!$B$5 | E16: =(SUMPRODUCT(DCF_Base!$C$19:$L$19/(1+E15)^DCF_Base!$C$4:$L$4)+DCF_Base!$B$31/(1+E15)^10+SUMPRODUCT(Monee!$C$29:$L$29/(1+E15)^Monee!$C$22:$L$22)+Monee!$B$35/(1+E15)^10+Assumptions!$B$19)/Assumptions!$B$5 | F16: =(SUMPRODUCT(DCF_Base!$C$19:$L$19/(1+F15)^DCF_Base!$C$4:$L$4)+DCF_Base!$B$31/(1+F15)^10+SUMPRODUCT(Monee!$C$29:$L$29/(1+F15)^Monee!$C$22:$L$22)+Monee!$B$35/(1+F15)^10+Assumptions!$B$19)/Assumptions!$B$5 | G16: =(SUMPRODUCT(DCF_Base!$C$19:$L$19/(1+G15)^DCF_Base!$C$4:$L$4)+DCF_Base!$B$31/(1+G15)^10+SUMPRODUCT(Monee!$C$29:$L$29/(1+G15)^Monee!$C$22:$L$22)+Monee!$B$35/(1+G15)^10+Assumptions!$B$19)/Assumptions!$B$5
A18: 15%-HURDLE ENTRY PRICES (buy-below)
A19: Entry price | B19: =(SUMPRODUCT(DCF_Bear!$C$19:$L$19/(1+0.15)^DCF_Bear!$C$4:$L$4)+DCF_Bear!$B$31/(1+0.15)^10+SUMPRODUCT(Monee!$C$12:$L$12/(1+0.15)^Monee!$C$5:$L$5)+Monee!$B$18/(1+0.15)^10+Assumptions!$B$19)/Assumptions!$B$5 | C19: =(SUMPRODUCT(DCF_Base!$C$19:$L$19/(1+0.15)^DCF_Base!$C$4:$L$4)+DCF_Base!$B$31/(1+0.15)^10+SUMPRODUCT(Monee!$C$29:$L$29/(1+0.15)^Monee!$C$22:$L$22)+Monee!$B$35/(1+0.15)^10+Assumptions!$B$19)/Assumptions!$B$5 | D19: =(SUMPRODUCT(DCF_Bull!$C$19:$L$19/(1+0.15)^DCF_Bull!$C$4:$L$4)+DCF_Bull!$B$31/(1+0.15)^10+SUMPRODUCT(Monee!$C$46:$L$46/(1+0.15)^Monee!$C$39:$L$39)+Monee!$B$52/(1+0.15)^10+Assumptions!$B$19)/Assumptions!$B$5
A20: WEIGHTED ENTRY PRICE | B20: =SUMPRODUCT(B19:D19,B6:D6)
A22: SENSITIVITY - base case: OpCo WACC (rows) x OpCo terminal growth (cols); Monee at base value, cash constant
C23: 0.02 | D23: 0.025 | E23: 0.03 | F23: 0.035 | G23: 0.04
B24: 0.095 | C24: =IF($B24>C$23,(SUMPRODUCT(DCF_Base!$C$19:$L$19/(1+$B24)^DCF_Base!$C$4:$L$4)+MAX(0,MIN(DCF_Base!$L$19*(1+C$23)/($B24-C$23),Assumptions!$C$27*DCF_Base!$L$19))/(1+$B24)^10+Monee!$B$37+Assumptions!$B$19)/Assumptions!$B$5,"n/a") | D24: =IF($B24>D$23,(SUMPRODUCT(DCF_Base!$C$19:$L$19/(1+$B24)^DCF_Base!$C$4:$L$4)+MAX(0,MIN(DCF_Base!$L$19*(1+D$23)/($B24-D$23),Assumptions!$C$27*DCF_Base!$L$19))/(1+$B24)^10+Monee!$B$37+Assumptions!$B$19)/Assumptions!$B$5,"n/a") | E24: =IF($B24>E$23,(SUMPRODUCT(DCF_Base!$C$19:$L$19/(1+$B24)^DCF_Base!$C$4:$L$4)+MAX(0,MIN(DCF_Base!$L$19*(1+E$23)/($B24-E$23),Assumptions!$C$27*DCF_Base!$L$19))/(1+$B24)^10+Monee!$B$37+Assumptions!$B$19)/Assumptions!$B$5,"n/a") | F24: =IF($B24>F$23,(SUMPRODUCT(DCF_Base!$C$19:$L$19/(1+$B24)^DCF_Base!$C$4:$L$4)+MAX(0,MIN(DCF_Base!$L$19*(1+F$23)/($B24-F$23),Assumptions!$C$27*DCF_Base!$L$19))/(1+$B24)^10+Monee!$B$37+Assumptions!$B$19)/Assumptions!$B$5,"n/a") | G24: =IF($B24>G$23,(SUMPRODUCT(DCF_Base!$C$19:$L$19/(1+$B24)^DCF_Base!$C$4:$L$4)+MAX(0,MIN(DCF_Base!$L$19*(1+G$23)/($B24-G$23),Assumptions!$C$27*DCF_Base!$L$19))/(1+$B24)^10+Monee!$B$37+Assumptions!$B$19)/Assumptions!$B$5,"n/a")
B25: 0.105 | C25: =IF($B25>C$23,(SUMPRODUCT(DCF_Base!$C$19:$L$19/(1+$B25)^DCF_Base!$C$4:$L$4)+MAX(0,MIN(DCF_Base!$L$19*(1+C$23)/($B25-C$23),Assumptions!$C$27*DCF_Base!$L$19))/(1+$B25)^10+Monee!$B$37+Assumptions!$B$19)/Assumptions!$B$5,"n/a") | D25: =IF($B25>D$23,(SUMPRODUCT(DCF_Base!$C$19:$L$19/(1+$B25)^DCF_Base!$C$4:$L$4)+MAX(0,MIN(DCF_Base!$L$19*(1+D$23)/($B25-D$23),Assumptions!$C$27*DCF_Base!$L$19))/(1+$B25)^10+Monee!$B$37+Assumptions!$B$19)/Assumptions!$B$5,"n/a") | E25: =IF($B25>E$23,(SUMPRODUCT(DCF_Base!$C$19:$L$19/(1+$B25)^DCF_Base!$C$4:$L$4)+MAX(0,MIN(DCF_Base!$L$19*(1+E$23)/($B25-E$23),Assumptions!$C$27*DCF_Base!$L$19))/(1+$B25)^10+Monee!$B$37+Assumptions!$B$19)/Assumptions!$B$5,"n/a") | F25: =IF($B25>F$23,(SUMPRODUCT(DCF_Base!$C$19:$L$19/(1+$B25)^DCF_Base!$C$4:$L$4)+MAX(0,MIN(DCF_Base!$L$19*(1+F$23)/($B25-F$23),Assumptions!$C$27*DCF_Base!$L$19))/(1+$B25)^10+Monee!$B$37+Assumptions!$B$19)/Assumptions!$B$5,"n/a") | G25: =IF($B25>G$23,(SUMPRODUCT(DCF_Base!$C$19:$L$19/(1+$B25)^DCF_Base!$C$4:$L$4)+MAX(0,MIN(DCF_Base!$L$19*(1+G$23)/($B25-G$23),Assumptions!$C$27*DCF_Base!$L$19))/(1+$B25)^10+Monee!$B$37+Assumptions!$B$19)/Assumptions!$B$5,"n/a")
B26: 0.115 | C26: =IF($B26>C$23,(SUMPRODUCT(DCF_Base!$C$19:$L$19/(1+$B26)^DCF_Base!$C$4:$L$4)+MAX(0,MIN(DCF_Base!$L$19*(1+C$23)/($B26-C$23),Assumptions!$C$27*DCF_Base!$L$19))/(1+$B26)^10+Monee!$B$37+Assumptions!$B$19)/Assumptions!$B$5,"n/a") | D26: =IF($B26>D$23,(SUMPRODUCT(DCF_Base!$C$19:$L$19/(1+$B26)^DCF_Base!$C$4:$L$4)+MAX(0,MIN(DCF_Base!$L$19*(1+D$23)/($B26-D$23),Assumptions!$C$27*DCF_Base!$L$19))/(1+$B26)^10+Monee!$B$37+Assumptions!$B$19)/Assumptions!$B$5,"n/a") | E26: =IF($B26>E$23,(SUMPRODUCT(DCF_Base!$C$19:$L$19/(1+$B26)^DCF_Base!$C$4:$L$4)+MAX(0,MIN(DCF_Base!$L$19*(1+E$23)/($B26-E$23),Assumptions!$C$27*DCF_Base!$L$19))/(1+$B26)^10+Monee!$B$37+Assumptions!$B$19)/Assumptions!$B$5,"n/a") | F26: =IF($B26>F$23,(SUMPRODUCT(DCF_Base!$C$19:$L$19/(1+$B26)^DCF_Base!$C$4:$L$4)+MAX(0,MIN(DCF_Base!$L$19*(1+F$23)/($B26-F$23),Assumptions!$C$27*DCF_Base!$L$19))/(1+$B26)^10+Monee!$B$37+Assumptions!$B$19)/Assumptions!$B$5,"n/a") | G26: =IF($B26>G$23,(SUMPRODUCT(DCF_Base!$C$19:$L$19/(1+$B26)^DCF_Base!$C$4:$L$4)+MAX(0,MIN(DCF_Base!$L$19*(1+G$23)/($B26-G$23),Assumptions!$C$27*DCF_Base!$L$19))/(1+$B26)^10+Monee!$B$37+Assumptions!$B$19)/Assumptions!$B$5,"n/a")
B27: 0.125 | C27: =IF($B27>C$23,(SUMPRODUCT(DCF_Base!$C$19:$L$19/(1+$B27)^DCF_Base!$C$4:$L$4)+MAX(0,MIN(DCF_Base!$L$19*(1+C$23)/($B27-C$23),Assumptions!$C$27*DCF_Base!$L$19))/(1+$B27)^10+Monee!$B$37+Assumptions!$B$19)/Assumptions!$B$5,"n/a") | D27: =IF($B27>D$23,(SUMPRODUCT(DCF_Base!$C$19:$L$19/(1+$B27)^DCF_Base!$C$4:$L$4)+MAX(0,MIN(DCF_Base!$L$19*(1+D$23)/($B27-D$23),Assumptions!$C$27*DCF_Base!$L$19))/(1+$B27)^10+Monee!$B$37+Assumptions!$B$19)/Assumptions!$B$5,"n/a") | E27: =IF($B27>E$23,(SUMPRODUCT(DCF_Base!$C$19:$L$19/(1+$B27)^DCF_Base!$C$4:$L$4)+MAX(0,MIN(DCF_Base!$L$19*(1+E$23)/($B27-E$23),Assumptions!$C$27*DCF_Base!$L$19))/(1+$B27)^10+Monee!$B$37+Assumptions!$B$19)/Assumptions!$B$5,"n/a") | F27: =IF($B27>F$23,(SUMPRODUCT(DCF_Base!$C$19:$L$19/(1+$B27)^DCF_Base!$C$4:$L$4)+MAX(0,MIN(DCF_Base!$L$19*(1+F$23)/($B27-F$23),Assumptions!$C$27*DCF_Base!$L$19))/(1+$B27)^10+Monee!$B$37+Assumptions!$B$19)/Assumptions!$B$5,"n/a") | G27: =IF($B27>G$23,(SUMPRODUCT(DCF_Base!$C$19:$L$19/(1+$B27)^DCF_Base!$C$4:$L$4)+MAX(0,MIN(DCF_Base!$L$19*(1+G$23)/($B27-G$23),Assumptions!$C$27*DCF_Base!$L$19))/(1+$B27)^10+Monee!$B$37+Assumptions!$B$19)/Assumptions!$B$5,"n/a")
B28: 0.135 | C28: =IF($B28>C$23,(SUMPRODUCT(DCF_Base!$C$19:$L$19/(1+$B28)^DCF_Base!$C$4:$L$4)+MAX(0,MIN(DCF_Base!$L$19*(1+C$23)/($B28-C$23),Assumptions!$C$27*DCF_Base!$L$19))/(1+$B28)^10+Monee!$B$37+Assumptions!$B$19)/Assumptions!$B$5,"n/a") | D28: =IF($B28>D$23,(SUMPRODUCT(DCF_Base!$C$19:$L$19/(1+$B28)^DCF_Base!$C$4:$L$4)+MAX(0,MIN(DCF_Base!$L$19*(1+D$23)/($B28-D$23),Assumptions!$C$27*DCF_Base!$L$19))/(1+$B28)^10+Monee!$B$37+Assumptions!$B$19)/Assumptions!$B$5,"n/a") | E28: =IF($B28>E$23,(SUMPRODUCT(DCF_Base!$C$19:$L$19/(1+$B28)^DCF_Base!$C$4:$L$4)+MAX(0,MIN(DCF_Base!$L$19*(1+E$23)/($B28-E$23),Assumptions!$C$27*DCF_Base!$L$19))/(1+$B28)^10+Monee!$B$37+Assumptions!$B$19)/Assumptions!$B$5,"n/a") | F28: =IF($B28>F$23,(SUMPRODUCT(DCF_Base!$C$19:$L$19/(1+$B28)^DCF_Base!$C$4:$L$4)+MAX(0,MIN(DCF_Base!$L$19*(1+F$23)/($B28-F$23),Assumptions!$C$27*DCF_Base!$L$19))/(1+$B28)^10+Monee!$B$37+Assumptions!$B$19)/Assumptions!$B$5,"n/a") | G28: =IF($B28>G$23,(SUMPRODUCT(DCF_Base!$C$19:$L$19/(1+$B28)^DCF_Base!$C$4:$L$4)+MAX(0,MIN(DCF_Base!$L$19*(1+G$23)/($B28-G$23),Assumptions!$C$27*DCF_Base!$L$19))/(1+$B28)^10+Monee!$B$37+Assumptions!$B$19)/Assumptions!$B$5,"n/a")
