Workbook

Sheet Executive Summary
A1: UBER TECHNOLOGIES INC. (NYSE: UBER)
A2: Discounted Cash Flow (DCF) Valuation Model
A3: Analysis Date: January 02, 2026
A5: COMPANY OVERVIEW
A6: Industry: | B6: Technology / Transportation Network
A7: Business Segments: | B7: Mobility, Delivery, Freight
A8: Headquarters: | B8: San Francisco, California
A9: Employees: | B9: ~31,100
A10: Global Presence: | B10: 70+ countries, 15,000+ cities
A11: Ticker: | B11: NYSE: UBER
A14: KEY INVESTMENT HIGHLIGHTS
A15: • Global leader in ride-hailing with dominant market share vs. competitors
A16: • Diversified platform: Mobility + Delivery + Freight + Advertising
A17: • Strong network effects and two-sided marketplace advantage
A18: • Achieved profitability inflection in 2023-2024
A19: • 30+ million Uber One members driving customer retention
A20: • Strategic partnerships in autonomous vehicles (Waymo, Aurora)
A21: • Record $6.9B free cash flow in 2024
A24: KEY RISKS
A25: • Regulatory risk: Gig worker classification (AB5-type legislation)
A26: • Competitive pressure from regional players and new entrants
A27: • AV disruption risk if autonomous technology matures rapidly
... A29: • Legal/litigation costs averaging ~$400M+ per quarter

Sheet Analyst Comparison
A1: DCF MODEL ASSUMPTIONS vs. ANALYST CONSENSUS
A2: Comparison of our projections with Wall Street analyst estimates
A4: REVENUE PROJECTIONS ($B)
A5: Year | B5: Our DCF Model | C5: Analyst Consensus | D5: Difference | E5: Assessment
A6: 2024A | B6: 44 | C6: 44 | D6: 0.0% | E6: Actual
A7: 2025E | B7: 51.9 | C7: 52 | D7: -0.2% | E7: In Line
A8: 2026E | B8: 60.2 | C8: 60.1 | D8: +0.2% | E8: In Line
A9: 2027E | B9: 68.6 | C9: 68 | D9: +0.9% | E9: Slightly Higher
A10: 2028E | B10: 76.9 | C10: 75 | D10: +2.5% | E10: Slightly Higher
A11: 2029E | B11: 84.5 | C11: 82 | D11: +3.0% | E11: Slightly Higher
A14: REVENUE GROWTH RATES
A15: Year | B15: Our DCF Model | C15: Analyst Consensus | D15: Difference | E15: Assessment
A16: 2025E | B16: 18.0% | C16: 18.2% | D16: -0.2pp | E16: In Line
A17: 2026E | B17: 16.0% | C17: 15.6% | D17: +0.4pp | E17: In Line
A18: 2027E | B18: 14.0% | C18: 13.2% | D18: +0.8pp | E18: Slightly Higher
A19: 2028E | B19: 12.0% | C19: 10.3% | D19: +1.7pp | E19: Higher
A20: 2029E | B20: 10.0% | C20: 9.3% | D20: +0.7pp | E20: Slightly Higher
A21: Terminal | B21: 3.5% | C21: 3.0-4.0% | D21: N/A | E21: Reasonable
A24: ADJUSTED EBITDA PROJECTIONS ($B)
A25: Year | B25: Our DCF Model | C25: Analyst Consensus | D25: Difference | E25: Assessment
A26: 2024A | B26: 6.5 | C26: 6.5 | D26: 0.0% | E26: Actual
A27: 2025E | B27: 8.6 | C27: 8.7 | D27: -1.1% | E27: In Line
A28: 2026E | B28: 10.8 | C28: 10.5 | D28: +2.9% | E28: Slightly Higher
A29: 2027E | B29: 13.4 | C29: 12.5 | D29: +7.2% | E29: Higher
A30: 2028E | B30: 16.1 | C30: 14.1 | D30: +14.2% | E30: Higher
A31: 2029E | B31: 18.6 | C31: 16 | D31: +16.3% | E31: Higher
A34: EBITDA MARGIN (% of Revenue)
A35: Year | B35: Our DCF Model | C35: Analyst Consensus | D35: Difference | E35: Assessment
A36: 2024A | B36: 14.9% | C36: 14.9% | D36: 0.0pp | E36: Actual
A37: 2025E | B37: 16.5% | C37: 16.7% | D37: -0.2pp | E37: In Line
A38: 2026E | B38: 18.0% | C38: 17.5% | D38: +0.5pp | E38: Slightly Higher
A39: 2027E | B39: 19.5% | C39: 18.4% | D39: +1.1pp | E39: Higher
A40: 2028E | B40: 21.0% | C40: 18.8% | D40: +2.2pp | E40: Higher
A41: 2029E | B41: 22.0% | C41: 19.5% | D41: +2.5pp | E41: Higher
A44: VALUATION COMPARISON
A45: Metric | B45: Our DCF Model | C45: Analyst Consensus | D45: Notes
A46: Implied Share Price | B46: $86 | C46: $109-$114 | D46: Our DCF is more conservative
A47: Price Target Range | B47: $75-$105 | C47: $78-$150 | D47: Similar low end
A48: WACC | B48: 9.8% | C48: ~9.5-10.5% | D48: Within typical range
A49: Terminal Growth | B49: 3.5% | C49: 3.0-4.0% | D49: Reasonable assumption
...

Sheet Historical Financials
A1: UBER TECHNOLOGIES - HISTORICAL FINANCIAL PERFORMANCE
A3: Metric | B3: 2021 | C3: 2022 | D3: 2023 | E3: 2024 | F3: TTM Q3 2025
A4: Revenue ($mm) | B4: 17455 | C4: 31877 | D4: 37281 | E4: 43978 | F4: 49610
A5: YoY Revenue Growth (%) | B5: N/A | C5: 82.6% | D5: 16.9% | E5: 18.0% | F5: 18.3%
A7: Gross Bookings ($mm) | B7: 90415 | C7: 115395 | D7: 137753 | E7: 162000 | F7: 185000
A8: Take Rate (Revenue/GB) | B8: 19.3% | C8: 27.6% | D8: 27.1% | E8: 27.2% | F8: 26.8%
A10: Adjusted EBITDA ($mm) | B10: 7 | C10: 1586 | D10: 4053 | E10: 6532 | F10: 8100
A11: Adj. EBITDA Margin (% Rev) | B11: 0.0% | C11: 5.0% | D11: 10.9% | E11: 14.9% | F11: 16.3%
A12: Adj. EBITDA Margin (% GB) | B12: 0.0% | C12: 1.4% | D12: 2.9% | E12: 4.0% | F12: 4.4%
A14: Operating Income ($mm) | B14: -3826 | C14: -1832 | D14: 1872 | E14: 2840 | F14: 4600
A15: Net Income ($mm) | B15: -496 | C15: -9141 | D15: 1887 | E15: 9856 | F15: 16640
A17: Operating Cash Flow ($mm) | B17: -445 | C17: 642 | D17: 3585 | E17: 7295 | F17: 8800
A18: Capital Expenditures ($mm) | B18: 136 | C18: 252 | D18: 223 | E18: 400 | F18: 350
A19: Free Cash Flow ($mm) | B19: -581 | C19: 390 | D19: 3362 | E19: 6895 | F19: 8450
A21: D&A ($mm) | B21: 1019 | C21: 947 | D21: 823 | E21: 737 | F21: 720
A22: Stock-Based Comp ($mm) | B22: 1168 | C22: 1793 | D22: 1935 | E22: 2200 | F22: 2400
A25: Source: Company SEC Filings (10-K, 10-Q), Investor Relations Press Releases

Sheet Segment Analysis
A1: UBER SEGMENT BREAKDOWN - FY 2024
A3: Segment | B3: Gross Bookings ($mm) | C3: Revenue ($mm) | D3: Adj. EBITDA ($mm) | E3: EBITDA Margin (% GB)
A4: Mobility | B4: 83000 | C4: 25000 | D4: 6100 | E4: 7.3%
A5: Delivery | B5: 74600 | C5: 13700 | D5: 2300 | E5: 3.1%
A6: Freight | B6: 4900 | C6: 5200 | D6: -100 | E6: -2.0%
A7: Corporate/Other | B7: 0 | C7: 78 | D7: 232 | E7: N/A
A8: TOTAL | B8: 162500 | C8: 43978 | D8: 6532 | E8: 4.0%
A11: SEGMENT GROWTH TRENDS
A12: Mobility: | B12: 25% YoY revenue growth; 7-8% EBITDA margin on gross bookings
A13: Delivery: | B13: 21% YoY revenue growth; margin expansion from advertising
A14: Freight: | B14: Challenging market cycle; revenue flat; strategic optionality
A15: Advertising: | B15: High-margin growth driver across Mobility & Delivery (~$1B+)

Sheet DCF Assumptions
A1: DCF MODEL ASSUMPTIONS
A3: REVENUE GROWTH ASSUMPTIONS
A4: Base Year Revenue (2024, $mm) | B4: 43978
A6: Year 1 Growth (2025E) | B6: 0.18
A7: Year 2 Growth (2026E) | B7: 0.16
A8: Year 3 Growth (2027E) | B8: 0.14
A9: Year 4 Growth (2028E) | B9: 0.12
A10: Year 5 Growth (2029E) | B10: 0.1
A11: Terminal Growth Rate | B11: 0.035
A14: MARGIN ASSUMPTIONS
A15: 2024 EBITDA Margin (% Rev) | B15: 14.9%
A17: Year 1 EBITDA Margin | B17: 0.165
A18: Year 2 EBITDA Margin | B18: 0.18
A19: Year 3 EBITDA Margin | B19: 0.195
A20: Year 4 EBITDA Margin | B20: 0.21
A21: Year 5 EBITDA Margin | B21: 0.22
A22: Terminal EBITDA Margin | B22: 0.22
A25: WACC COMPONENTS
A26: Risk-Free Rate (10Y Treasury) | B26: 4.25%
A27: Equity Risk Premium | B27: 5.50%
A28: Beta (Levered) | B28: 1.19
A29: Cost of Equity | B29: 10.80%
A31: Pre-Tax Cost of Debt | B31: 5.50%
A32: Tax Rate | B32: 21.0%
A33: After-Tax Cost of Debt | B33: 4.35%
A35: Debt / Total Cap | B35: 6.0%
A36: Equity / Total Cap | B36: 94.0%
B37: 0.098
A38: WACC | B38: 10.4%
A41: OTHER ASSUMPTIONS
A42: D&A as % of Revenue | B42: 1.5%
A43: CapEx as % of Revenue | B43: 1.0%
A44: Change in NWC as % of ΔRev | B44: 2.0%
A45: Effective Tax Rate | B45: 21.0%

Sheet DCF Model
A1: UBER TECHNOLOGIES - DCF VALUATION MODEL
A3: REVENUE PROJECTIONS
B4: 2024A | C4: 2025E | D4: 2026E | E4: 2027E | F4: 2028E | G4: 2029E | H4: Terminal
A5: Revenue ($mm) | B5: 43978 | C5: =B5*(1+'DCF Assumptions'!B6) | D5: =C5*(1+'DCF Assumptions'!B7) | E5: =D5*(1+'DCF Assumptions'!B8) | F5: =E5*(1+'DCF Assumptions'!B9) | G5: =F5*(1+'DCF Assumptions'!B10) | H5: =G5*(1+'DCF Assumptions'!B11)
A6: YoY Growth | B6: 18.0% | C6: ='DCF Assumptions'!B6 | D6: ='DCF Assumptions'!B7 | E6: ='DCF Assumptions'!B8 | F6: ='DCF Assumptions'!B9 | G6: ='DCF Assumptions'!B10 | H6: ='DCF Assumptions'!B11
A8: EBITDA PROJECTIONS
A9: EBITDA Margin | B9: 0.149 | C9: ='DCF Assumptions'!B17 | D9: ='DCF Assumptions'!B18 | E9: ='DCF Assumptions'!B19 | F9: ='DCF Assumptions'!B20 | G9: ='DCF Assumptions'!B21 | H9: ='DCF Assumptions'!B22
A10: EBITDA ($mm) | B10: =B5*B9 | C10: =C5*C9 | D10: =D5*D9 | E10: =E5*E9 | F10: =F5*F9 | G10: =G5*G9 | H10: =H5*H9
A12: FREE CASH FLOW BUILD
A13: EBITDA | C13: =C10 | D13: =D10 | E13: =E10 | F13: =F10 | G13: =G10
A14: Less: D&A | C14: =-C5*'DCF Assumptions'!B42 | D14: =-D5*'DCF Assumptions'!B42 | E14: =-E5*'DCF Assumptions'!B42 | F14: =-F5*'DCF Assumptions'!B42 | G14: =-G5*'DCF Assumptions'!B42
A15: EBIT | C15: =C13+C14 | D15: =D13+D14 | E15: =E13+E14 | F15: =F13+F14 | G15: =G13+G14
A16: Less: Taxes (21%) | C16: =-C15*'DCF Assumptions'!B45 | D16: =-D15*'DCF Assumptions'!B45 | E16: =-E15*'DCF Assumptions'!B45 | F16: =-F15*'DCF Assumptions'!B45 | G16: =-G15*'DCF Assumptions'!B45
A17: EBIAT (NOPAT) | C17: =C15+C16 | D17: =D15+D16 | E17: =E15+E16 | F17: =F15+F16 | G17: =G15+G16
A18: Plus: D&A | C18: =-C14 | D18: =-D14 | E18: =-E14 | F18: =-F14 | G18: =-G14
A19: Less: CapEx | C19: =-C5*'DCF Assumptions'!B43 | D19: =-D5*'DCF Assumptions'!B43 | E19: =-E5*'DCF Assumptions'!B43 | F19: =-F5*'DCF Assumptions'!B43 | G19: =-G5*'DCF Assumptions'!B43
A20: Less: Δ NWC | C20: =-(C5-B5)*'DCF Assumptions'!B44 | D20: =-(D5-C5)*'DCF Assumptions'!B44 | E20: =-(E5-D5)*'DCF Assumptions'!B44 | F20: =-(F5-E5)*'DCF Assumptions'!B44 | G20: =-(G5-F5)*'DCF Assumptions'!B44
A21: Unlevered FCF | C21: =SUM(C17:C20) | D21: =SUM(D17:D20) | E21: =SUM(E17:E20) | F21: =SUM(F17:F20) | G21: =SUM(G17:G20)
A23: DCF VALUATION
A24: WACC | B24: 0.098
A25: Terminal Growth Rate | B25: 0.035
A27: Discount Period | C27: 1 | D27: 2 | E27: 3 | F27: 4 | G27: 5
A28: Discount Factor | C28: =1/(1+$B$24)^C27 | D28: =1/(1+$B$24)^D27 | E28: =1/(1+$B$24)^E27 | F28: =1/(1+$B$24)^F27 | G28: =1/(1+$B$24)^G27
A29: PV of FCF | C29: =C21*C28 | D29: =D21*D28 | E29: =E21*E28 | F29: =F21*F28 | G29: =G21*G28
A31: Sum of PV FCFs | B31: =SUM(C29:G29)
A33: TERMINAL VALUE CALCULATION
A34: Terminal Year FCF | B34: =G21*(1+B25)
A35: Terminal Value (Gordon Growth) | B35: =B34/(B24-B25)
A36: PV of Terminal Value | B36: =B35*G28
A38: ENTERPRISE VALUE
A39: PV of FCFs | B39: =B31
A40: PV of Terminal Value | B40: =B36
A41: Enterprise Value | B41: =B39+B40
A43: EQUITY VALUE BRIDGE
A44: Enterprise Value | B44: =B41
A45: Less: Total Debt | B45: -11000
A46: Plus: Cash & Equivalents | B46: 9000
A47: Equity Value | B47: =SUM(B44:B46)
A49: Shares Outstanding (mm) | B49: 2084
A50: IMPLIED SHARE PRICE | B50: =B47/B49
...

Sheet Sensitivity Analysis
A1: SENSITIVITY ANALYSIS
A3: IMPLIED SHARE PRICE: WACC vs. TERMINAL GROWTH RATE
B5: Terminal Growth Rate | C5: 2.5% | D5: 3.0% | E5: 3.5% | F5: 4.0% | G5: 4.5%
A6: WACC | B6: 8.5% | C6: 118 | D6: 127 | E6: 138 | F6: 152 | G6: 169
B7: 9.0% | C7: 104 | D7: 111 | E7: 120 | F7: 130 | G7: 143
B8: 9.5% | C8: 93 | D8: 99 | E8: 106 | F8: 114 | G8: 123
B9: 9.8% | C9: 86 | D9: 91 | E9: 97 | F9: 104 | G9: 112
B10: 10.0% | C10: 83 | D10: 88 | E10: 93 | F10: 100 | G10: 107
B11: 10.5% | C11: 75 | D11: 79 | E11: 83 | F11: 88 | G11: 94
B12: 11.0% | C12: 68 | D12: 71 | E12: 75 | F12: 79 | G12: 84
A14: Note: Yellow cell represents base case scenario (WACC: 9.8%, TGR: 3.5%)
A17: IMPLIED SHARE PRICE: REVENUE GROWTH vs. EBITDA MARGIN (Year 5)
B19: Yr5 Revenue Growth | C19: 8% | D19: 9% | E19: 10% | F19: 11% | G19: 12%
A20: Terminal | B20: 20% | C20: 75 | D20: 80 | E20: 86 | F20: 92 | G20: 98
A21: EBITDA | B21: 21% | C21: 79 | D21: 85 | E21: 91 | F21: 97 | G21: 104
A22: Margin | B22: 22% | C22: 84 | D22: 90 | E22: 97 | F22: 104 | G22: 111
B23: 23% | C23: 89 | D23: 95 | E23: 102 | F23: 109 | G23: 117
B24: 24% | C24: 93 | D24: 100 | E24: 107 | F24: 115 | G24: 123

Sheet Comparable Valuation
A1: COMPARABLE COMPANY ANALYSIS
A3: Company | B3: Ticker | C3: Market Cap ($B) | D3: EV ($B) | E3: Revenue ($B) | F3: EV/Revenue | G3: EV/EBITDA | H3: P/E (FWD)
A4: Uber Technologies | B4: UBER | C4: 170 | D4: 175 | E4: 50 | F4: 3.5x | G4: 21.6x | H4: 24.3x
A5: Lyft Inc. | B5: LYFT | C5: 6 | D5: 5 | E5: 6 | F5: 0.8x | G5: 8.0x | H5: 12.5x
A6: DoorDash Inc. | B6: DASH | C6: 75 | D6: 72 | E6: 10 | F6: 7.2x | G6: 45.0x | H6: 65.0x
A7: Airbnb Inc. | B7: ABNB | C7: 95 | D7: 90 | E7: 11 | F7: 8.2x | G7: 22.0x | H7: 28.0x
A8: Booking Holdings | B8: BKNG | C8: 175 | D8: 180 | E8: 23 | F8: 7.8x | G8: 18.5x | H8: 22.0x
A9: Grab Holdings | B9: GRAB | C9: 20 | D9: 17 | E9: 3 | F9: 5.7x | G9: 35.0x | H9: NM
A11: Peer Average (excl. UBER) | F11: 5.9x | G11: 25.7x | H11: 31.9x
A12: Peer Median (excl. UBER) | F12: 6.5x | G12: 22.0x | H12: 25.0x
A15: IMPLIED VALUATION FOR UBER
A16: Metric | B16: Multiple | C16: Uber Metric | D16: Implied EV ($B) | E16: Implied Share Price
A17: EV/Revenue (Peer Median) | B17: 6.5x | C17: $50B | D17: $325B | E17: $155
A18: EV/EBITDA (Peer Median) | B18: 22.0x | C18: $8.1B | D18: $178B | E18: $85
A19: P/E Forward (Peer Median) | B19: 25.0x | C19: $3.6 EPS | D19: - | E19: $90

Sheet Valuation Summary
A1: VALUATION SUMMARY
A3: SUMMARY OF VALUATION METHODOLOGIES
A4: Methodology | B4: Low | C4: Base | D4: High | E4: Weight
A5: DCF (5-yr explicit forecast) | B5: $75 | C5: $86 | D5: $105 | E5: 50%
A6: EV/EBITDA Multiple (Comps) | B6: $75 | C6: $90 | D6: $110 | E6: 25%
A7: EV/Revenue Multiple (Comps) | B7: $90 | C7: $110 | D7: $140 | E7: 15%
A8: Analyst Consensus PT | B8: $78 | C8: $109 | D8: $150 | E8: 10%
A10: WEIGHTED AVERAGE PRICE TARGET | B10: $80 | C10: $95 | D10: $115
A12: Current Stock Price | B12: 82
A13: Implied Upside to Base Case | C13: 16%
A16: INVESTMENT RECOMMENDATION
A17: Rating: | B17: BUY
A19: 12-Month Price Target: | B19: $95
A20: Expected Return: | B20: 16%
A23: INVESTMENT THESIS
A24: 1. Dominant platform with strong network effects and global scale
A25: 2. Profitability inflection achieved; FCF generation accelerating
A26: 3. Multiple growth vectors: Advertising, Uber One, AV partnerships
A27: 4. Margin expansion runway as operating leverage kicks in
A28: 5. Favorable risk/reward at current valuation vs. growth profile
