Workbook

Sheet Model_Info
A1: PORT OF TAURANGA (POT.NZ) - OWNER-FCF DCF MODEL
A2: Version: 1.0 (fresh build - no prior DCF exists for this ticker). Supersedes: nothing.
A3: Built by: dcf-analyst agent (Claude, model claude-fable-5) on 2026-08-26 at the orchestrator's request.
A5: DATA VINTAGE - figures go stale; refresh after the FY2026 result (due ~Aug-2026):
A6: Price: NZD 8.115, NZX regular close, fetched 2026-08-26 (verified market data supplied by orchestrator). Top of the 10-year 3.76-8.90 monthly-close range.
A7: Balance sheet: H1 FY2026 interim, 31-Dec-2025. Borrowings 498.707, lease liabilities 58.727, cash 27.475, investments in + advances to equity-accounted investees 322.229 (all NZD m).
A8: Shares: 680.909m ordinary, flat for a decade, no buybacks, no dilution (employee-scheme purchases <NZ$1m/yr).
A9: Guidance: FY2026 underlying NPAT NZ$142-152m, RAISED at the H1 result (H1 NPAT 70.2, +16.6% YoY).
A10: History: POT.NZ_Metrics.csv (core_metrics, NZD millions) + kpis table (UnderlyingNetProfit, DandA, CashTaxesPaid).
A12: METHODOLOGY CHOICES (one line each):
A13: 1. Owner-FCF DCF, 10-year component build - POT is a capital-intensive monopoly port OPERATING company; not a REIT/bank/LIC (dcf-methods routing table).
A14: 2. Base year mid-cycled: FY2025 reported NPAT 173.4 includes the one-off NZ$49.245m Northport/Marsden disposal gain - underlying NPAT 126.0 used; FY2025 capex of 28.1 is a consent-blocked trough (10yr avg ~38-45) - deferred, not avoided.
... A26: CELL COLOURS: BLUE font = hardcoded input; YELLOW fill = key driver lever; BLACK = formula; GREEN = cross-sheet link.

Sheet Actuals
A1: POT.NZ actuals - all hardcoded, NZD millions. Sources: POT.NZ_Metrics.csv (core_metrics), kpis table, annual/interim filings. FY2025 net income includes the one-off NZ$49.245m disposal gain; FY-end prices supplied by orchestrator 2026-08-26.
A3: Period | B3: FY2016 | C3: FY2017 | D3: FY2018 | E3: FY2019 | F3: FY2020 | G3: FY2021 | H3: FY2022 | I3: FY2023 | J3: FY2024 | K3: FY2025 | L3: H1 FY2026
A4: Revenue | B4: 245.521 | C4: 255.882 | D4: 283.726 | E4: 313.263 | F4: 301.985 | G4: 338.281 | H4: 375.288 | I4: 420.929 | J4: 417.375 | K4: 464.675 | L4: 244.128
A5: EBITDA (reported, incl EAI share) | B5: 143.18 | C5: 152.385 | D5: 169.236 | E5: 181.27 | F5: 165.198 | G5: 189.917 | H5: 204.663 | I5: 219.081 | J5: 203.739 | K5: 234.504 | L5: 122.376
A6: Core EBITDA (excl EAI share) | J6: 198.794 | K6: 228.399 | L6: 122.376
A7: Net income (reported) | B7: 77.314 | C7: 83.441 | D7: 94.273 | E7: 100.577 | F7: 88.679 | G7: 102.375 | H7: 111.317 | I7: 117.136 | J7: 90.849 | K7: 173.373 | L7: 70.214
A8: Underlying NPAT (kpis) | G8: 104.058 | H8: 112.357 | I8: 117.792 | J8: 102.29 | K8: 126.036
A9: Operating cash flow | B9: 88.069 | C9: 98.185 | D9: 99.431 | E9: 112.189 | F9: 117.137 | G9: 99.682 | H9: 145.249 | I9: 144.572 | J9: 135.837 | K9: 171.981 | L9: 77.792
A10: Capex | B10: 58.863 | C10: 65.269 | D10: 17.399 | E10: 41.125 | F10: 38.239 | G10: 22.267 | H10: 21.345 | I10: 44.84 | J10: 42.612 | K10: 28.135 | L10: 25.162
A11: Free cash flow (reported) | B11: 29.206 | C11: 32.916 | D11: 82.032 | E11: 71.064 | F11: 78.898 | G11: 77.415 | H11: 123.904 | I11: 99.732 | J11: 93.225 | K11: 143.846 | L11: 52.63
A12: Dividends paid | H12: 95.242 | I12: 102.054 | J12: 100.689 | K12: 106.801 | L12: 65.991
A13: Shareholders equity | B13: 885.684 | C13: 931.943 | D13: 1121.98 | E13: 1165.885 | F13: 1195.184 | G13: 1396.968 | H13: 2074.438 | I13: 2133.716 | J13: 2183.157 | K13: 2273.771 | L13: 2279.671
A14: Total debt (borrowings) | B14: 320.2 | C14: 380.363 | D14: 405.356 | E14: 446.213 | F14: 488.458 | G14: 485 | H14: 442.472 | I14: 450.775 | J14: 462.962 | K14: 467.884 | L14: 498.707
A15: Cash | B15: 11.58 | C15: 5.184 | D15: 5.836 | E15: 3.903 | F15: 8.565 | G15: 7.886 | H15: 7.272 | I15: 8.506 | J15: 18.728 | K15: 8.975 | L15: 27.475
A16: D&A (kpis) | B16: 23.722 | C16: 24.46 | D16: 25.269 | E16: 27.585 | J16: 43.77 | K16: 42.925 | L16: 22.844
A17: Cash taxes paid (kpis) | B17: 28.991 | C17: 29.444 | D17: 32.03 | E17: 34.68 | F17: 35.293 | J17: 44.075 | K17: 43.115 | L17: 31.765
A18: FY-end share price (Jun close) | C18: 4.45 | D18: 5.1 | E18: 6.34 | F18: 7.7 | G18: 7.03 | H18: 6.22 | I18: 6.24 | J18: 4.72 | K18: 6.85
A20: Balance-sheet snapshot 31-Dec-2025: borrowings 498.707 + lease liabilities 58.727 - cash 27.475 = net debt 529.959; investments in EAI 284.148 + advances 38.081 = 322.229. Guidance FY2026 underlying NPAT 142-152 (raised). No NCI. Buybacks: none (0.636 FY2025 employee-scheme only).

Sheet Assumptions
A1: GLOBAL ASSUMPTIONS (blue = input; yellow = key lever)
A3: WACC % | B3: 7.75 | D3: NZD: rf ~4.4% + 5.0% ERP x beta ~0.75; ~10% debt at ~3.8% after tax. No illiquidity premium (NZX-50 large cap, A-/Stable monopoly). Same rate all scenarios - risk charged once, in weights.
A4: D&A % of revenue | B4: 9.4 | D4: FY2025 actual 42.9/464.7 = 9.2%; held near-flat as the asset base grows with the build.
A5: WC capture % of revenue change | B5: -5 | D5: Net working capital ~5-6% of revenue (receivables 15.5% less payables ~10%); growth absorbs cash.
A6: Cash tax rate % | B6: 28 | D6: NZ statutory 28%; FY2025 cash taxes paid 43.1 on underlying PBT ex-EAI ~163 = 26.4% - statutory is mildly conservative.
A7: Net debt incl leases (NZD m) | B7: 529.959 | D7: 31-Dec-2025: borrowings 498.707 + lease liabilities 58.727 - cash 27.475. Leases-as-debt treatment A.
A8: Equity-accounted investments + advances (NZD m) | B8: 322.229 | D8: Matching asset for the EAI profit stripped from flows: investments 284.148 + advances 38.081 at Dec-2025 carrying value (NGL at Jun-2025 fair value).
A9: Diluted shares (m) | B9: 680.909 | D9: Flat for a decade; no buybacks, no dilution; SBC zero so count held flat charges nothing twice.
A10: Current price (NZD) | B10: 8.115 | D10: NZX close 2026-08-26. Top of the 10-year 3.76-8.90 range.
A11: Terminal cap multiple (x FCF) | B11: 20 | D11: Gordon binds in all scenarios; the cap only bites in low-WACC sensitivity corners.
A13: PER-SCENARIO
A14: Scenario | B14: Terminal growth % | C14: Probability weight
A15: Bear | B15: 2 | C15: 0.25
A16: Base | B16: 2.25 | C16: 0.5
A17: Bull | B17: 2.5 | C17: 0.25
A18: Weights sum (must be 1.0) | C18: =SUM(C15:C17)
A20: SCENARIO NARRATIVES
A21: BEAR: Stella Passage consent blocked again (fresh judicial review or iwi negotiation impasse) - project shelved for the decade; soft NZ export-commodity cycle (weak China log demand) and alliance restructuring trim call frequency; margin stalls ~49%; maintenance-only capex means near-term FCF exceeds base but there is no capacity growth. Terminal g 2.0%.
A22: BASE: consent granted during FY2027 (re-lodged Jan-2026 under the amended Fast-track Act); berth + cranes built FY2027-31, capex peaking ~NZ$140m/yr and suppressing mid-decade FCF; revenue +8% FY2026 (guidance-anchored) decelerating to 2.5%; core margin 49.2% -> 52% on productivity, MetroPort repricing and tariffs. Terminal g 2.25% (NZ long-run nominal GDP).
A23: BULL: consent clears early; volumes pass the FY2022 peak (1.24m TEU) as bigger ships consolidate at the only NZ port able to berth them; Ruakura/Rolleston scale; margin to 53.5%; faster, larger build. Terminal g 2.5%.

Sheet DCF_Bear
A1: DCF Bear - core port operations (EAI share excluded from flows; investee stakes added in the bridge). Only rows 5,7,9,14,17 are drivers.
A3: Year | B3: 2025A | C3: FY2026E | D3: FY2027E | E3: FY2028E | F3: FY2029E | G3: FY2030E | H3: FY2031E | I3: FY2032E | J3: FY2033E | K3: FY2034E | L3: FY2035E
A4: Index (discount exponent) | B4: 0 | C4: 1 | D4: 2 | E4: 3 | F4: 4 | G4: 5 | H4: 6 | I4: 7 | J4: 8 | K4: 9 | L4: 10
A5: Revenue growth YoY % [DRIVER] | C5: 6.5 | D5: 3 | E5: 2.5 | F5: 2.5 | G5: 2.5 | H5: 2.5 | I5: 2.5 | J5: 2 | K5: 2 | L5: 2
A6: Revenue | B6: 464.675 | C6: =B6*(1+C5/100) | D6: =C6*(1+D5/100) | E6: =D6*(1+E5/100) | F6: =E6*(1+F5/100) | G6: =F6*(1+G5/100) | H6: =G6*(1+H5/100) | I6: =H6*(1+I5/100) | J6: =I6*(1+J5/100) | ... L6: =K6*(1+L5/100)
A7: Core EBITDA margin % [DRIVER] | B7: 49.15 | C7: 49.8 | D7: 49.5 | E7: 49.3 | F7: 49.2 | G7: 49 | H7: 49 | I7: 49 | J7: 49 | K7: 49 | L7: 49
A8: Core EBITDA (excl EAI) | B8: =B6*B7/100 | C8: =C6*C7/100 | D8: =D6*D7/100 | E8: =E6*E7/100 | F8: =F6*F7/100 | G8: =G6*G7/100 | H8: =H6*H7/100 | I8: =I6*I7/100 | ... L8: =L6*L7/100
A9: SBC % of revenue [DRIVER - zero, NZX] | C9: 0 | D9: 0 | E9: 0 | F9: 0 | G9: 0 | H9: 0 | I9: 0 | J9: 0 | K9: 0 | L9: 0
A10: SBC $ | C10: =-C6*C9/100 | D10: =-D6*D9/100 | E10: =-E6*E9/100 | F10: =-F6*F9/100 | G10: =-G6*G9/100 | H10: =-H6*H9/100 | I10: =-I6*I9/100 | J10: =-J6*J9/100 | ... L10: =-L6*L9/100
A11: Owner EBITDA | C11: =C8+C10 | D11: =D8+D10 | E11: =E8+E10 | F11: =F8+F10 | G11: =G8+G10 | H11: =H8+H10 | I11: =I8+I10 | J11: =J8+J10 | ... L11: =L8+L10
A12: D&A | C12: =-C6*Assumptions!$B$4/100 | D12: =-D6*Assumptions!$B$4/100 | E12: =-E6*Assumptions!$B$4/100 | F12: =-F6*Assumptions!$B$4/100 | G12: =-G6*Assumptions!$B$4/100 | H12: =-H6*Assumptions!$B$4/100 | I12: =-I6*Assumptions!$B$4/100 | J12: =-J6*Assumptions!$B$4/100 | ... L12: =-L6*Assumptions!$B$4/100
A13: EBIT | C13: =C11+C12 | D13: =D11+D12 | E13: =E11+E12 | F13: =F11+F12 | G13: =G11+G12 | H13: =H11+H12 | I13: =I11+I12 | J13: =J11+J12 | ... L13: =L11+L12
A14: Cash tax rate % [DRIVER] | C14: 28 | D14: 28 | E14: 28 | F14: 28 | G14: 28 | H14: 28 | I14: 28 | J14: 28 | K14: 28 | L14: 28
A15: NOPAT | C15: =C13*(1-C14/100) | D15: =D13*(1-D14/100) | E15: =E13*(1-E14/100) | F15: =F13*(1-F14/100) | G15: =G13*(1-G14/100) | H15: =H13*(1-H14/100) | I15: =I13*(1-I14/100) | J15: =J13*(1-J14/100) | ... L15: =L13*(1-L14/100)
A16: add back D&A | C16: =-C12 | D16: =-D12 | E16: =-E12 | F16: =-F12 | G16: =-G12 | H16: =-H12 | I16: =-I12 | J16: =-J12 | ... L16: =-L12
A17: Capex % of revenue [DRIVER, per-year taper] | C17: 10.1 | D17: 10.8 | E17: 9.6 | F17: 9.3 | G17: 9.1 | H17: 9.2 | I17: 9.2 | J17: 9.2 | K17: 9.2 | L17: 9.2
A18: Capex $ | C18: =-C6*C17/100 | D18: =-D6*D17/100 | E18: =-E6*E17/100 | F18: =-F6*F17/100 | G18: =-G6*G17/100 | H18: =-H6*H17/100 | I18: =-I6*I17/100 | J18: =-J6*J17/100 | ... L18: =-L6*L17/100
A19: Working capital (on revenue CHANGE) | C19: =Assumptions!$B$5/100*(C6-B6) | D19: =Assumptions!$B$5/100*(D6-C6) | E19: =Assumptions!$B$5/100*(E6-D6) | F19: =Assumptions!$B$5/100*(F6-E6) | G19: =Assumptions!$B$5/100*(G6-F6) | H19: =Assumptions!$B$5/100*(H6-G6) | I19: =Assumptions!$B$5/100*(I6-H6) | J19: =Assumptions!$B$5/100*(J6-I6) | ... L19: =Assumptions!$B$5/100*(L6-K6)
A20: UNLEVERED OWNER FCF | C20: =C15+C16+C18+C19 | D20: =D15+D16+D18+D19 | E20: =E15+E16+E18+E19 | F20: =F15+F16+F18+F19 | G20: =G15+G16+G18+G19 | H20: =H15+H16+H18+H19 | I20: =I15+I16+I18+I19 | J20: =J15+J16+J18+J19 | ... L20: =L15+L16+L18+L19
A21: Discount factor | C21: =1/(1+Assumptions!$B$3/100)^C4 | D21: =1/(1+Assumptions!$B$3/100)^D4 | E21: =1/(1+Assumptions!$B$3/100)^E4 | F21: =1/(1+Assumptions!$B$3/100)^F4 | G21: =1/(1+Assumptions!$B$3/100)^G4 | H21: =1/(1+Assumptions!$B$3/100)^H4 | I21: =1/(1+Assumptions!$B$3/100)^I4 | J21: =1/(1+Assumptions!$B$3/100)^J4 | ... L21: =1/(1+Assumptions!$B$3/100)^L4
A22: PV of FCF | C22: =C20*C21 | D22: =D20*D21 | E22: =E20*E21 | F22: =F20*F21 | G22: =G20*G21 | H22: =H20*H21 | I22: =I20*I21 | J22: =J20*J21 | ... L22: =L20*L21
A24: Memo: FCF before SBC (company-style) | B24: Memo FY0 owner FCF ~131.5 (mid-cycle capex 45) | C24: =C20-C10 | D24: =D20-D10 | E24: =E20-E10 | F24: =F20-F10 | G24: =G20-G10 | H24: =H20-H10 | I24: =I20-I10 | J24: =J20-J10 | ... L24: =L20-L10
A25: Memo: owner FCF margin | C25: =C20/C6 | D25: =D20/D6 | E25: =E20/E6 | F25: =F20/F6 | G25: =G20/G6 | H25: =H20/H6 | I25: =I20/I6 | J25: =J20/J6 | ... L25: =L20/L6
A27: Sum PV of FCF | B27: =SUM(C22:L22)
A28: Terminal growth % | B28: =Assumptions!$B$15
A29: Terminal FCF | B29: =L20*(1+B28/100)
A30: Gordon TV | B30: =B29/(Assumptions!$B$3/100-B28/100)
A31: Cap TV (20x FCF) | B31: =Assumptions!$B$11*L20
A32: TV used = MAX(0,MIN(Gordon,Cap)) | B32: =MAX(0,MIN(B30,B31))
A33: Implied exit multiple (x FCF) | B33: =B32/L20
A34: Implied exit EV/EBITDA (x) | B34: =B32/L8
A35: PV of terminal value | B35: =B32*L21
A36: Enterprise value (core) | B36: =B27+B35
A37: add: EAI investments + advances | B37: =Assumptions!$B$8
A38: less: net debt incl leases | B38: =-Assumptions!$B$7
A39: EQUITY VALUE | B39: =B36+B37+B38
A40: Diluted shares (m) | B40: =Assumptions!$B$9
A41: VALUE PER SHARE (NZD) | B41: =B39/B40
A42: Upside vs price | B42: =B41/Assumptions!$B$10-1
A44: Street memo: PV explicit SBC | B44: =SUMPRODUCT(-C10:L10,C21:L21)
...

Sheet DCF_Base
A1: DCF Base - core port operations (EAI share excluded from flows; investee stakes added in the bridge). Only rows 5,7,9,14,17 are drivers.
A3: Year | B3: 2025A | C3: FY2026E | D3: FY2027E | E3: FY2028E | F3: FY2029E | G3: FY2030E | H3: FY2031E | I3: FY2032E | J3: FY2033E | K3: FY2034E | L3: FY2035E
A4: Index (discount exponent) | B4: 0 | C4: 1 | D4: 2 | E4: 3 | F4: 4 | G4: 5 | H4: 6 | I4: 7 | J4: 8 | K4: 9 | L4: 10
A5: Revenue growth YoY % [DRIVER] | C5: 8 | D5: 5.5 | E5: 5 | F5: 4.5 | G5: 4.5 | H5: 4.5 | I5: 4 | J5: 3.5 | K5: 3 | L5: 2.5
A6: Revenue | B6: 464.675 | C6: =B6*(1+C5/100) | D6: =C6*(1+D5/100) | E6: =D6*(1+E5/100) | F6: =E6*(1+F5/100) | G6: =F6*(1+G5/100) | H6: =G6*(1+H5/100) | I6: =H6*(1+I5/100) | J6: =I6*(1+J5/100) | ... L6: =K6*(1+L5/100)
A7: Core EBITDA margin % [DRIVER] | B7: 49.15 | C7: 50 | D7: 50.5 | E7: 50.8 | F7: 51.2 | G7: 51.5 | H7: 51.8 | I7: 52 | J7: 52 | K7: 52 | L7: 52
A8: Core EBITDA (excl EAI) | B8: =B6*B7/100 | C8: =C6*C7/100 | D8: =D6*D7/100 | E8: =E6*E7/100 | F8: =F6*F7/100 | G8: =G6*G7/100 | H8: =H6*H7/100 | I8: =I6*I7/100 | ... L8: =L6*L7/100
A9: SBC % of revenue [DRIVER - zero, NZX] | C9: 0 | D9: 0 | E9: 0 | F9: 0 | G9: 0 | H9: 0 | I9: 0 | J9: 0 | K9: 0 | L9: 0
A10: SBC $ | C10: =-C6*C9/100 | D10: =-D6*D9/100 | E10: =-E6*E9/100 | F10: =-F6*F9/100 | G10: =-G6*G9/100 | H10: =-H6*H9/100 | I10: =-I6*I9/100 | J10: =-J6*J9/100 | ... L10: =-L6*L9/100
A11: Owner EBITDA | C11: =C8+C10 | D11: =D8+D10 | E11: =E8+E10 | F11: =F8+F10 | G11: =G8+G10 | H11: =H8+H10 | I11: =I8+I10 | J11: =J8+J10 | ... L11: =L8+L10
A12: D&A | C12: =-C6*Assumptions!$B$4/100 | D12: =-D6*Assumptions!$B$4/100 | E12: =-E6*Assumptions!$B$4/100 | F12: =-F6*Assumptions!$B$4/100 | G12: =-G6*Assumptions!$B$4/100 | H12: =-H6*Assumptions!$B$4/100 | I12: =-I6*Assumptions!$B$4/100 | J12: =-J6*Assumptions!$B$4/100 | ... L12: =-L6*Assumptions!$B$4/100
A13: EBIT | C13: =C11+C12 | D13: =D11+D12 | E13: =E11+E12 | F13: =F11+F12 | G13: =G11+G12 | H13: =H11+H12 | I13: =I11+I12 | J13: =J11+J12 | ... L13: =L11+L12
A14: Cash tax rate % [DRIVER] | C14: 28 | D14: 28 | E14: 28 | F14: 28 | G14: 28 | H14: 28 | I14: 28 | J14: 28 | K14: 28 | L14: 28
A15: NOPAT | C15: =C13*(1-C14/100) | D15: =D13*(1-D14/100) | E15: =E13*(1-E14/100) | F15: =F13*(1-F14/100) | G15: =G13*(1-G14/100) | H15: =H13*(1-H14/100) | I15: =I13*(1-I14/100) | J15: =J13*(1-J14/100) | ... L15: =L13*(1-L14/100)
A16: add back D&A | C16: =-C12 | D16: =-D12 | E16: =-E12 | F16: =-F12 | G16: =-G12 | H16: =-H12 | I16: =-I12 | J16: =-J12 | ... L16: =-L12
A17: Capex % of revenue [DRIVER, per-year taper] | C17: 10 | D17: 17 | E17: 25.2 | F17: 24.1 | G17: 16.5 | H17: 11 | I17: 8.5 | J17: 8.5 | K17: 8.5 | L17: 8.5
A18: Capex $ | C18: =-C6*C17/100 | D18: =-D6*D17/100 | E18: =-E6*E17/100 | F18: =-F6*F17/100 | G18: =-G6*G17/100 | H18: =-H6*H17/100 | I18: =-I6*I17/100 | J18: =-J6*J17/100 | ... L18: =-L6*L17/100
A19: Working capital (on revenue CHANGE) | C19: =Assumptions!$B$5/100*(C6-B6) | D19: =Assumptions!$B$5/100*(D6-C6) | E19: =Assumptions!$B$5/100*(E6-D6) | F19: =Assumptions!$B$5/100*(F6-E6) | G19: =Assumptions!$B$5/100*(G6-F6) | H19: =Assumptions!$B$5/100*(H6-G6) | I19: =Assumptions!$B$5/100*(I6-H6) | J19: =Assumptions!$B$5/100*(J6-I6) | ... L19: =Assumptions!$B$5/100*(L6-K6)
A20: UNLEVERED OWNER FCF | C20: =C15+C16+C18+C19 | D20: =D15+D16+D18+D19 | E20: =E15+E16+E18+E19 | F20: =F15+F16+F18+F19 | G20: =G15+G16+G18+G19 | H20: =H15+H16+H18+H19 | I20: =I15+I16+I18+I19 | J20: =J15+J16+J18+J19 | ... L20: =L15+L16+L18+L19
A21: Discount factor | C21: =1/(1+Assumptions!$B$3/100)^C4 | D21: =1/(1+Assumptions!$B$3/100)^D4 | E21: =1/(1+Assumptions!$B$3/100)^E4 | F21: =1/(1+Assumptions!$B$3/100)^F4 | G21: =1/(1+Assumptions!$B$3/100)^G4 | H21: =1/(1+Assumptions!$B$3/100)^H4 | I21: =1/(1+Assumptions!$B$3/100)^I4 | J21: =1/(1+Assumptions!$B$3/100)^J4 | ... L21: =1/(1+Assumptions!$B$3/100)^L4
A22: PV of FCF | C22: =C20*C21 | D22: =D20*D21 | E22: =E20*E21 | F22: =F20*F21 | G22: =G20*G21 | H22: =H20*H21 | I22: =I20*I21 | J22: =J20*J21 | ... L22: =L20*L21
A24: Memo: FCF before SBC (company-style) | B24: Memo FY0 owner FCF ~131.5 (mid-cycle capex 45) | C24: =C20-C10 | D24: =D20-D10 | E24: =E20-E10 | F24: =F20-F10 | G24: =G20-G10 | H24: =H20-H10 | I24: =I20-I10 | J24: =J20-J10 | ... L24: =L20-L10
A25: Memo: owner FCF margin | C25: =C20/C6 | D25: =D20/D6 | E25: =E20/E6 | F25: =F20/F6 | G25: =G20/G6 | H25: =H20/H6 | I25: =I20/I6 | J25: =J20/J6 | ... L25: =L20/L6
A27: Sum PV of FCF | B27: =SUM(C22:L22)
A28: Terminal growth % | B28: =Assumptions!$B$16
A29: Terminal FCF | B29: =L20*(1+B28/100)
A30: Gordon TV | B30: =B29/(Assumptions!$B$3/100-B28/100)
A31: Cap TV (20x FCF) | B31: =Assumptions!$B$11*L20
A32: TV used = MAX(0,MIN(Gordon,Cap)) | B32: =MAX(0,MIN(B30,B31))
A33: Implied exit multiple (x FCF) | B33: =B32/L20
A34: Implied exit EV/EBITDA (x) | B34: =B32/L8
A35: PV of terminal value | B35: =B32*L21
A36: Enterprise value (core) | B36: =B27+B35
A37: add: EAI investments + advances | B37: =Assumptions!$B$8
A38: less: net debt incl leases | B38: =-Assumptions!$B$7
A39: EQUITY VALUE | B39: =B36+B37+B38
A40: Diluted shares (m) | B40: =Assumptions!$B$9
A41: VALUE PER SHARE (NZD) | B41: =B39/B40
A42: Upside vs price | B42: =B41/Assumptions!$B$10-1
A44: Street memo: PV explicit SBC | B44: =SUMPRODUCT(-C10:L10,C21:L21)
...

Sheet DCF_Bull
A1: DCF Bull - core port operations (EAI share excluded from flows; investee stakes added in the bridge). Only rows 5,7,9,14,17 are drivers.
A3: Year | B3: 2025A | C3: FY2026E | D3: FY2027E | E3: FY2028E | F3: FY2029E | G3: FY2030E | H3: FY2031E | I3: FY2032E | J3: FY2033E | K3: FY2034E | L3: FY2035E
A4: Index (discount exponent) | B4: 0 | C4: 1 | D4: 2 | E4: 3 | F4: 4 | G4: 5 | H4: 6 | I4: 7 | J4: 8 | K4: 9 | L4: 10
A5: Revenue growth YoY % [DRIVER] | C5: 9 | D5: 7 | E5: 6.5 | F5: 6 | G5: 6 | H5: 5.5 | I5: 5 | J5: 4.5 | K5: 4 | L5: 3
A6: Revenue | B6: 464.675 | C6: =B6*(1+C5/100) | D6: =C6*(1+D5/100) | E6: =D6*(1+E5/100) | F6: =E6*(1+F5/100) | G6: =F6*(1+G5/100) | H6: =G6*(1+H5/100) | I6: =H6*(1+I5/100) | J6: =I6*(1+J5/100) | ... L6: =K6*(1+L5/100)
A7: Core EBITDA margin % [DRIVER] | B7: 49.15 | C7: 50.2 | D7: 51 | E7: 51.6 | F7: 52.2 | G7: 52.7 | H7: 53.1 | I7: 53.5 | J7: 53.5 | K7: 53.5 | L7: 53.5
A8: Core EBITDA (excl EAI) | B8: =B6*B7/100 | C8: =C6*C7/100 | D8: =D6*D7/100 | E8: =E6*E7/100 | F8: =F6*F7/100 | G8: =G6*G7/100 | H8: =H6*H7/100 | I8: =I6*I7/100 | ... L8: =L6*L7/100
A9: SBC % of revenue [DRIVER - zero, NZX] | C9: 0 | D9: 0 | E9: 0 | F9: 0 | G9: 0 | H9: 0 | I9: 0 | J9: 0 | K9: 0 | L9: 0
A10: SBC $ | C10: =-C6*C9/100 | D10: =-D6*D9/100 | E10: =-E6*E9/100 | F10: =-F6*F9/100 | G10: =-G6*G9/100 | H10: =-H6*H9/100 | I10: =-I6*I9/100 | J10: =-J6*J9/100 | ... L10: =-L6*L9/100
A11: Owner EBITDA | C11: =C8+C10 | D11: =D8+D10 | E11: =E8+E10 | F11: =F8+F10 | G11: =G8+G10 | H11: =H8+H10 | I11: =I8+I10 | J11: =J8+J10 | ... L11: =L8+L10
A12: D&A | C12: =-C6*Assumptions!$B$4/100 | D12: =-D6*Assumptions!$B$4/100 | E12: =-E6*Assumptions!$B$4/100 | F12: =-F6*Assumptions!$B$4/100 | G12: =-G6*Assumptions!$B$4/100 | H12: =-H6*Assumptions!$B$4/100 | I12: =-I6*Assumptions!$B$4/100 | J12: =-J6*Assumptions!$B$4/100 | ... L12: =-L6*Assumptions!$B$4/100
A13: EBIT | C13: =C11+C12 | D13: =D11+D12 | E13: =E11+E12 | F13: =F11+F12 | G13: =G11+G12 | H13: =H11+H12 | I13: =I11+I12 | J13: =J11+J12 | ... L13: =L11+L12
A14: Cash tax rate % [DRIVER] | C14: 28 | D14: 28 | E14: 28 | F14: 28 | G14: 28 | H14: 28 | I14: 28 | J14: 28 | K14: 28 | L14: 28
A15: NOPAT | C15: =C13*(1-C14/100) | D15: =D13*(1-D14/100) | E15: =E13*(1-E14/100) | F15: =F13*(1-F14/100) | G15: =G13*(1-G14/100) | H15: =H13*(1-H14/100) | I15: =I13*(1-I14/100) | J15: =J13*(1-J14/100) | ... L15: =L13*(1-L14/100)
A16: add back D&A | C16: =-C12 | D16: =-D12 | E16: =-E12 | F16: =-F12 | G16: =-G12 | H16: =-H12 | I16: =-I12 | J16: =-J12 | ... L16: =-L12
A17: Capex % of revenue [DRIVER, per-year taper] | C17: 10.9 | D17: 18.5 | E17: 26 | F17: 24.5 | G17: 17 | H17: 11 | I17: 8.5 | J17: 8.5 | K17: 8.5 | L17: 8.5
A18: Capex $ | C18: =-C6*C17/100 | D18: =-D6*D17/100 | E18: =-E6*E17/100 | F18: =-F6*F17/100 | G18: =-G6*G17/100 | H18: =-H6*H17/100 | I18: =-I6*I17/100 | J18: =-J6*J17/100 | ... L18: =-L6*L17/100
A19: Working capital (on revenue CHANGE) | C19: =Assumptions!$B$5/100*(C6-B6) | D19: =Assumptions!$B$5/100*(D6-C6) | E19: =Assumptions!$B$5/100*(E6-D6) | F19: =Assumptions!$B$5/100*(F6-E6) | G19: =Assumptions!$B$5/100*(G6-F6) | H19: =Assumptions!$B$5/100*(H6-G6) | I19: =Assumptions!$B$5/100*(I6-H6) | J19: =Assumptions!$B$5/100*(J6-I6) | ... L19: =Assumptions!$B$5/100*(L6-K6)
A20: UNLEVERED OWNER FCF | C20: =C15+C16+C18+C19 | D20: =D15+D16+D18+D19 | E20: =E15+E16+E18+E19 | F20: =F15+F16+F18+F19 | G20: =G15+G16+G18+G19 | H20: =H15+H16+H18+H19 | I20: =I15+I16+I18+I19 | J20: =J15+J16+J18+J19 | ... L20: =L15+L16+L18+L19
A21: Discount factor | C21: =1/(1+Assumptions!$B$3/100)^C4 | D21: =1/(1+Assumptions!$B$3/100)^D4 | E21: =1/(1+Assumptions!$B$3/100)^E4 | F21: =1/(1+Assumptions!$B$3/100)^F4 | G21: =1/(1+Assumptions!$B$3/100)^G4 | H21: =1/(1+Assumptions!$B$3/100)^H4 | I21: =1/(1+Assumptions!$B$3/100)^I4 | J21: =1/(1+Assumptions!$B$3/100)^J4 | ... L21: =1/(1+Assumptions!$B$3/100)^L4
A22: PV of FCF | C22: =C20*C21 | D22: =D20*D21 | E22: =E20*E21 | F22: =F20*F21 | G22: =G20*G21 | H22: =H20*H21 | I22: =I20*I21 | J22: =J20*J21 | ... L22: =L20*L21
A24: Memo: FCF before SBC (company-style) | B24: Memo FY0 owner FCF ~131.5 (mid-cycle capex 45) | C24: =C20-C10 | D24: =D20-D10 | E24: =E20-E10 | F24: =F20-F10 | G24: =G20-G10 | H24: =H20-H10 | I24: =I20-I10 | J24: =J20-J10 | ... L24: =L20-L10
A25: Memo: owner FCF margin | C25: =C20/C6 | D25: =D20/D6 | E25: =E20/E6 | F25: =F20/F6 | G25: =G20/G6 | H25: =H20/H6 | I25: =I20/I6 | J25: =J20/J6 | ... L25: =L20/L6
A27: Sum PV of FCF | B27: =SUM(C22:L22)
A28: Terminal growth % | B28: =Assumptions!$B$17
A29: Terminal FCF | B29: =L20*(1+B28/100)
A30: Gordon TV | B30: =B29/(Assumptions!$B$3/100-B28/100)
A31: Cap TV (20x FCF) | B31: =Assumptions!$B$11*L20
A32: TV used = MAX(0,MIN(Gordon,Cap)) | B32: =MAX(0,MIN(B30,B31))
A33: Implied exit multiple (x FCF) | B33: =B32/L20
A34: Implied exit EV/EBITDA (x) | B34: =B32/L8
A35: PV of terminal value | B35: =B32*L21
A36: Enterprise value (core) | B36: =B27+B35
A37: add: EAI investments + advances | B37: =Assumptions!$B$8
A38: less: net debt incl leases | B38: =-Assumptions!$B$7
A39: EQUITY VALUE | B39: =B36+B37+B38
A40: Diluted shares (m) | B40: =Assumptions!$B$9
A41: VALUE PER SHARE (NZD) | B41: =B39/B40
A42: Upside vs price | B42: =B41/Assumptions!$B$10-1
A44: Street memo: PV explicit SBC | B44: =SUMPRODUCT(-C10:L10,C21:L21)
...

Sheet FCF_Quality
A1: FCF quality - reported vs owner basis, NZD m. SBC = 0 and interest income immaterial (0.3-1.2m, net-debt company), so the owner adjustment for POT is CAPEX PHASING, not comp: FY2025 capex of 28.1 is a consent-blocked trough vs ~38-45 mid-cycle.
A3: Period | B3: FY2021 | C3: FY2022 | D3: FY2023 | E3: FY2024 | F3: FY2025
A4: Operating cash flow | B4: 99.682 | C4: 145.249 | D4: 144.572 | E4: 135.837 | F4: 171.981
A5: less: capex (actual) | B5: -22.267 | C5: -21.345 | D5: -44.84 | E5: -42.612 | F5: -28.135
A6: equals: Free cash flow (company definition) | B6: 77.415 | C6: 123.904 | D6: 99.732 | E6: 93.225 | F6: 143.846
A7: less: SBC incl equity-award taxes | B7: 0 | C7: 0 | D7: 0 | E7: 0 | F7: 0
A8: less: interest income (not stripped - net debt) | B8: 0 | C8: 0 | D8: 0 | E8: 0 | F8: 0
A9: equals: Owner FCF (as-reported capex) | B9: 77.415 | C9: 123.904 | D9: 99.732 | E9: 93.225 | F9: 143.846
A10: Memo: mid-cycle capex | B10: -45 | C10: -45 | D10: -45 | E10: -45 | F10: -45
A11: Memo: owner FCF at mid-cycle capex | B11: 54.682 | C11: 100.249 | D11: 99.572 | E11: 90.837 | F11: 126.981
A12: Reported FCF margin % | B12: 22.9 | C12: 33 | D12: 23.7 | E12: 22.3 | F12: 31
A13: Owner FCF margin % (mid-cycle capex) | B13: 16.2 | C13: 26.7 | D13: 23.7 | E13: 21.8 | F13: 27.3
A14: Memo: cash tax rate % (cash taxes/PBT ex-gain) | E14: 31.9 | F14: 25.5
A16: FY2025 reported NPAT 173.4 includes the NZ$49.245m one-off disposal gain (non-cash, investing) - it does NOT flatter OCF, but it does flatter reported NPAT/EPS. FY2025 FCF of 143.8 IS flattered by the capex trough: Stella Passage spend is deferred, not avoided. last_fcf in the JSON = 172.0 OCF - 45.0 mid-cycle capex = 127.0.

Sheet Valuation
A1: VALUATION SUMMARY - POT.NZ (NZD)
A3: Scenario | B3: Value/share | C3: Upside vs price | D3: Weight | E3: Street value/share | F3: Entry price @15% IRR
A4: Bear | B4: =DCF_Bear!$B$41 | C4: =B4/Assumptions!$B$10-1 | D4: =Assumptions!$C$15 | E4: =DCF_Bear!$B$46 | F4: =(SUMPRODUCT(DCF_Bear!$C$20:$L$20/1.15^DCF_Bear!$C$4:$L$4)+DCF_Bear!$B$32/1.15^10-Assumptions!$B$7+Assumptions!$B$8)/Assumptions!$B$9
A5: Base | B5: =DCF_Base!$B$41 | C5: =B5/Assumptions!$B$10-1 | D5: =Assumptions!$C$16 | E5: =DCF_Base!$B$46 | F5: =(SUMPRODUCT(DCF_Base!$C$20:$L$20/1.15^DCF_Base!$C$4:$L$4)+DCF_Base!$B$32/1.15^10-Assumptions!$B$7+Assumptions!$B$8)/Assumptions!$B$9
A6: Bull | B6: =DCF_Bull!$B$41 | C6: =B6/Assumptions!$B$10-1 | D6: =Assumptions!$C$17 | E6: =DCF_Bull!$B$46 | F6: =(SUMPRODUCT(DCF_Bull!$C$20:$L$20/1.15^DCF_Bull!$C$4:$L$4)+DCF_Bull!$B$32/1.15^10-Assumptions!$B$7+Assumptions!$B$8)/Assumptions!$B$9
A8: PROBABILITY-WEIGHTED VALUE | B8: =SUMPRODUCT(B4:B6,D4:D6)
A9: Margin of safety vs price | B9: =1-Assumptions!$B$10/B8
A10: Weighted entry price @15% IRR | B10: =SUMPRODUCT(F4:F6,D4:D6)
A11: Street weighted value (= house) | B11: =SUMPRODUCT(E4:E6,D4:D6)
A12: Band position | B12: n/a - SBC-zero market: house = street, the accounting-regime band collapses to a point
A14: REQUIRED-RETURN TABLE (Base case; TV held at WACC-Gordon fair value, discounting at r)
A15: Required return % | B15: 7.75 | C15: 9 | D15: 10 | E15: 11 | F15: 12 | G15: 15
A16: Value per share | B16: =(SUMPRODUCT(DCF_Base!$C$20:$L$20/(1+B15/100)^DCF_Base!$C$4:$L$4)+DCF_Base!$B$32/(1+B15/100)^10-Assumptions!$B$7+Assumptions!$B$8)/Assumptions!$B$9 | C16: =(SUMPRODUCT(DCF_Base!$C$20:$L$20/(1+C15/100)^DCF_Base!$C$4:$L$4)+DCF_Base!$B$32/(1+C15/100)^10-Assumptions!$B$7+Assumptions!$B$8)/Assumptions!$B$9 | D16: =(SUMPRODUCT(DCF_Base!$C$20:$L$20/(1+D15/100)^DCF_Base!$C$4:$L$4)+DCF_Base!$B$32/(1+D15/100)^10-Assumptions!$B$7+Assumptions!$B$8)/Assumptions!$B$9 | E16: =(SUMPRODUCT(DCF_Base!$C$20:$L$20/(1+E15/100)^DCF_Base!$C$4:$L$4)+DCF_Base!$B$32/(1+E15/100)^10-Assumptions!$B$7+Assumptions!$B$8)/Assumptions!$B$9 | F16: =(SUMPRODUCT(DCF_Base!$C$20:$L$20/(1+F15/100)^DCF_Base!$C$4:$L$4)+DCF_Base!$B$32/(1+F15/100)^10-Assumptions!$B$7+Assumptions!$B$8)/Assumptions!$B$9 | G16: =(SUMPRODUCT(DCF_Base!$C$20:$L$20/(1+G15/100)^DCF_Base!$C$4:$L$4)+DCF_Base!$B$32/(1+G15/100)^10-Assumptions!$B$7+Assumptions!$B$8)/Assumptions!$B$9
A17: Note: at NZD 8.115 the implied required return is ~5.5-6%, below the 7.75% WACC - the market prices POT at bond-plus returns.
A19: SENSITIVITY - Base value/share: WACC (rows) x terminal growth (cols). Full closed form; 20x cap and r>g guard applied.
B20: WACC% \ g% | C20: 1.25 | D20: 1.75 | E20: 2.25 | F20: 2.75 | G20: 3.25
B21: 6.75 | C21: =IF($B$21>C$20,(SUMPRODUCT(DCF_Base!$C$20:$L$20/(1+$B$21/100)^DCF_Base!$C$4:$L$4)+MAX(0,MIN(DCF_Base!$L$20*(1+C$20/100)/($B$21/100-C$20/100),Assumptions!$B$11*DCF_Base!$L$20))/(1+$B$21/100)^10-Assumptions!$B$7+Assumptions!$B$8)/Assumptions!$B$9,"n/a") | D21: =IF($B$21>D$20,(SUMPRODUCT(DCF_Base!$C$20:$L$20/(1+$B$21/100)^DCF_Base!$C$4:$L$4)+MAX(0,MIN(DCF_Base!$L$20*(1+D$20/100)/($B$21/100-D$20/100),Assumptions!$B$11*DCF_Base!$L$20))/(1+$B$21/100)^10-Assumptions!$B$7+Assumptions!$B$8)/Assumptions!$B$9,"n/a") | E21: =IF($B$21>E$20,(SUMPRODUCT(DCF_Base!$C$20:$L$20/(1+$B$21/100)^DCF_Base!$C$4:$L$4)+MAX(0,MIN(DCF_Base!$L$20*(1+E$20/100)/($B$21/100-E$20/100),Assumptions!$B$11*DCF_Base!$L$20))/(1+$B$21/100)^10-Assumptions!$B$7+Assumptions!$B$8)/Assumptions!$B$9,"n/a") | F21: =IF($B$21>F$20,(SUMPRODUCT(DCF_Base!$C$20:$L$20/(1+$B$21/100)^DCF_Base!$C$4:$L$4)+MAX(0,MIN(DCF_Base!$L$20*(1+F$20/100)/($B$21/100-F$20/100),Assumptions!$B$11*DCF_Base!$L$20))/(1+$B$21/100)^10-Assumptions!$B$7+Assumptions!$B$8)/Assumptions!$B$9,"n/a") | G21: =IF($B$21>G$20,(SUMPRODUCT(DCF_Base!$C$20:$L$20/(1+$B$21/100)^DCF_Base!$C$4:$L$4)+MAX(0,MIN(DCF_Base!$L$20*(1+G$20/100)/($B$21/100-G$20/100),Assumptions!$B$11*DCF_Base!$L$20))/(1+$B$21/100)^10-Assumptions!$B$7+Assumptions!$B$8)/Assumptions!$B$9,"n/a")
B22: 7.25 | C22: =IF($B$22>C$20,(SUMPRODUCT(DCF_Base!$C$20:$L$20/(1+$B$22/100)^DCF_Base!$C$4:$L$4)+MAX(0,MIN(DCF_Base!$L$20*(1+C$20/100)/($B$22/100-C$20/100),Assumptions!$B$11*DCF_Base!$L$20))/(1+$B$22/100)^10-Assumptions!$B$7+Assumptions!$B$8)/Assumptions!$B$9,"n/a") | D22: =IF($B$22>D$20,(SUMPRODUCT(DCF_Base!$C$20:$L$20/(1+$B$22/100)^DCF_Base!$C$4:$L$4)+MAX(0,MIN(DCF_Base!$L$20*(1+D$20/100)/($B$22/100-D$20/100),Assumptions!$B$11*DCF_Base!$L$20))/(1+$B$22/100)^10-Assumptions!$B$7+Assumptions!$B$8)/Assumptions!$B$9,"n/a") | E22: =IF($B$22>E$20,(SUMPRODUCT(DCF_Base!$C$20:$L$20/(1+$B$22/100)^DCF_Base!$C$4:$L$4)+MAX(0,MIN(DCF_Base!$L$20*(1+E$20/100)/($B$22/100-E$20/100),Assumptions!$B$11*DCF_Base!$L$20))/(1+$B$22/100)^10-Assumptions!$B$7+Assumptions!$B$8)/Assumptions!$B$9,"n/a") | F22: =IF($B$22>F$20,(SUMPRODUCT(DCF_Base!$C$20:$L$20/(1+$B$22/100)^DCF_Base!$C$4:$L$4)+MAX(0,MIN(DCF_Base!$L$20*(1+F$20/100)/($B$22/100-F$20/100),Assumptions!$B$11*DCF_Base!$L$20))/(1+$B$22/100)^10-Assumptions!$B$7+Assumptions!$B$8)/Assumptions!$B$9,"n/a") | G22: =IF($B$22>G$20,(SUMPRODUCT(DCF_Base!$C$20:$L$20/(1+$B$22/100)^DCF_Base!$C$4:$L$4)+MAX(0,MIN(DCF_Base!$L$20*(1+G$20/100)/($B$22/100-G$20/100),Assumptions!$B$11*DCF_Base!$L$20))/(1+$B$22/100)^10-Assumptions!$B$7+Assumptions!$B$8)/Assumptions!$B$9,"n/a")
B23: 7.75 | C23: =IF($B$23>C$20,(SUMPRODUCT(DCF_Base!$C$20:$L$20/(1+$B$23/100)^DCF_Base!$C$4:$L$4)+MAX(0,MIN(DCF_Base!$L$20*(1+C$20/100)/($B$23/100-C$20/100),Assumptions!$B$11*DCF_Base!$L$20))/(1+$B$23/100)^10-Assumptions!$B$7+Assumptions!$B$8)/Assumptions!$B$9,"n/a") | D23: =IF($B$23>D$20,(SUMPRODUCT(DCF_Base!$C$20:$L$20/(1+$B$23/100)^DCF_Base!$C$4:$L$4)+MAX(0,MIN(DCF_Base!$L$20*(1+D$20/100)/($B$23/100-D$20/100),Assumptions!$B$11*DCF_Base!$L$20))/(1+$B$23/100)^10-Assumptions!$B$7+Assumptions!$B$8)/Assumptions!$B$9,"n/a") | E23: =IF($B$23>E$20,(SUMPRODUCT(DCF_Base!$C$20:$L$20/(1+$B$23/100)^DCF_Base!$C$4:$L$4)+MAX(0,MIN(DCF_Base!$L$20*(1+E$20/100)/($B$23/100-E$20/100),Assumptions!$B$11*DCF_Base!$L$20))/(1+$B$23/100)^10-Assumptions!$B$7+Assumptions!$B$8)/Assumptions!$B$9,"n/a") | F23: =IF($B$23>F$20,(SUMPRODUCT(DCF_Base!$C$20:$L$20/(1+$B$23/100)^DCF_Base!$C$4:$L$4)+MAX(0,MIN(DCF_Base!$L$20*(1+F$20/100)/($B$23/100-F$20/100),Assumptions!$B$11*DCF_Base!$L$20))/(1+$B$23/100)^10-Assumptions!$B$7+Assumptions!$B$8)/Assumptions!$B$9,"n/a") | G23: =IF($B$23>G$20,(SUMPRODUCT(DCF_Base!$C$20:$L$20/(1+$B$23/100)^DCF_Base!$C$4:$L$4)+MAX(0,MIN(DCF_Base!$L$20*(1+G$20/100)/($B$23/100-G$20/100),Assumptions!$B$11*DCF_Base!$L$20))/(1+$B$23/100)^10-Assumptions!$B$7+Assumptions!$B$8)/Assumptions!$B$9,"n/a")
B24: 8.25 | C24: =IF($B$24>C$20,(SUMPRODUCT(DCF_Base!$C$20:$L$20/(1+$B$24/100)^DCF_Base!$C$4:$L$4)+MAX(0,MIN(DCF_Base!$L$20*(1+C$20/100)/($B$24/100-C$20/100),Assumptions!$B$11*DCF_Base!$L$20))/(1+$B$24/100)^10-Assumptions!$B$7+Assumptions!$B$8)/Assumptions!$B$9,"n/a") | D24: =IF($B$24>D$20,(SUMPRODUCT(DCF_Base!$C$20:$L$20/(1+$B$24/100)^DCF_Base!$C$4:$L$4)+MAX(0,MIN(DCF_Base!$L$20*(1+D$20/100)/($B$24/100-D$20/100),Assumptions!$B$11*DCF_Base!$L$20))/(1+$B$24/100)^10-Assumptions!$B$7+Assumptions!$B$8)/Assumptions!$B$9,"n/a") | E24: =IF($B$24>E$20,(SUMPRODUCT(DCF_Base!$C$20:$L$20/(1+$B$24/100)^DCF_Base!$C$4:$L$4)+MAX(0,MIN(DCF_Base!$L$20*(1+E$20/100)/($B$24/100-E$20/100),Assumptions!$B$11*DCF_Base!$L$20))/(1+$B$24/100)^10-Assumptions!$B$7+Assumptions!$B$8)/Assumptions!$B$9,"n/a") | F24: =IF($B$24>F$20,(SUMPRODUCT(DCF_Base!$C$20:$L$20/(1+$B$24/100)^DCF_Base!$C$4:$L$4)+MAX(0,MIN(DCF_Base!$L$20*(1+F$20/100)/($B$24/100-F$20/100),Assumptions!$B$11*DCF_Base!$L$20))/(1+$B$24/100)^10-Assumptions!$B$7+Assumptions!$B$8)/Assumptions!$B$9,"n/a") | G24: =IF($B$24>G$20,(SUMPRODUCT(DCF_Base!$C$20:$L$20/(1+$B$24/100)^DCF_Base!$C$4:$L$4)+MAX(0,MIN(DCF_Base!$L$20*(1+G$20/100)/($B$24/100-G$20/100),Assumptions!$B$11*DCF_Base!$L$20))/(1+$B$24/100)^10-Assumptions!$B$7+Assumptions!$B$8)/Assumptions!$B$9,"n/a")
B25: 8.75 | C25: =IF($B$25>C$20,(SUMPRODUCT(DCF_Base!$C$20:$L$20/(1+$B$25/100)^DCF_Base!$C$4:$L$4)+MAX(0,MIN(DCF_Base!$L$20*(1+C$20/100)/($B$25/100-C$20/100),Assumptions!$B$11*DCF_Base!$L$20))/(1+$B$25/100)^10-Assumptions!$B$7+Assumptions!$B$8)/Assumptions!$B$9,"n/a") | D25: =IF($B$25>D$20,(SUMPRODUCT(DCF_Base!$C$20:$L$20/(1+$B$25/100)^DCF_Base!$C$4:$L$4)+MAX(0,MIN(DCF_Base!$L$20*(1+D$20/100)/($B$25/100-D$20/100),Assumptions!$B$11*DCF_Base!$L$20))/(1+$B$25/100)^10-Assumptions!$B$7+Assumptions!$B$8)/Assumptions!$B$9,"n/a") | E25: =IF($B$25>E$20,(SUMPRODUCT(DCF_Base!$C$20:$L$20/(1+$B$25/100)^DCF_Base!$C$4:$L$4)+MAX(0,MIN(DCF_Base!$L$20*(1+E$20/100)/($B$25/100-E$20/100),Assumptions!$B$11*DCF_Base!$L$20))/(1+$B$25/100)^10-Assumptions!$B$7+Assumptions!$B$8)/Assumptions!$B$9,"n/a") | F25: =IF($B$25>F$20,(SUMPRODUCT(DCF_Base!$C$20:$L$20/(1+$B$25/100)^DCF_Base!$C$4:$L$4)+MAX(0,MIN(DCF_Base!$L$20*(1+F$20/100)/($B$25/100-F$20/100),Assumptions!$B$11*DCF_Base!$L$20))/(1+$B$25/100)^10-Assumptions!$B$7+Assumptions!$B$8)/Assumptions!$B$9,"n/a") | G25: =IF($B$25>G$20,(SUMPRODUCT(DCF_Base!$C$20:$L$20/(1+$B$25/100)^DCF_Base!$C$4:$L$4)+MAX(0,MIN(DCF_Base!$L$20*(1+G$20/100)/($B$25/100-G$20/100),Assumptions!$B$11*DCF_Base!$L$20))/(1+$B$25/100)^10-Assumptions!$B$7+Assumptions!$B$8)/Assumptions!$B$9,"n/a")
A28: MARKET-MULTIPLE REFERENCE (sanity-check fix): exit at POT's own 10yr MEDIAN EV/EBITDA instead of Gordon
A29: 10yr median trading EV/EBITDA (x) | B29: 22.8
A30: Reference value per share | B30: =(DCF_Base!$B$27+$B$29*DCF_Base!$L$8*DCF_Base!$L$21-Assumptions!$B$7+Assumptions!$B$8)/Assumptions!$B$9
A31: Gap house->reference->price = the explicitly-stated price of the scarcity-premium/re-rate assumption. House Gordon implies ~11x exit EV/EBITDA vs the 18-35x decade range. Reference ~7.17 reconciles to Jarden's 7.00 underweight target; FB 9.40 assumes current multiples persist. Sell-side targets are cross-checks, not inputs.
