Workbook

Sheet Summary
A1: Duolingo (NASDAQ: DUOL) — Owner-FCF DCF Model
A2: Prepared 29-Jul-26 · Q2 2026 results due 5-Aug-26 · Analysis, not investment advice
A4: Snapshot | D4: Valuation (owner-FCF basis)
A5: Share price (29-Jul-26) | B5: =Assumptions!B11 -> 140 | D5: Bear (25%) | E5: =DCF_Bear!B38 -> 43.247776
A6: 52-week range | B6: $87.89 – $468.00 | D6: Base (50%) | E6: =DCF_Base!B38 -> 100.60528
A7: All-time high (14-May-25) | B7: 540.68 | D7: Bull (25%) | E7: =DCF_Bull!B38 -> 159.64488
A8: Fully diluted shares (mm) | B8: =Assumptions!B10 -> 49.8 | D8: Probability-weighted | E8: =Valuation!B10 -> 101.0258
A9: Market cap (diluted, $mm) | B9: =Assumptions!B11*Assumptions!B10 -> 6972 | D9: Upside / (downside) | E9: =Valuation!B12 -> -0.27838712
A10: Net cash ($mm) | B10: =Assumptions!B9 -> 1140.5 | D10: Weighted value, SBC as non-cash | E10: =Valuation!B13 -> 155.24474
A11: Enterprise value ($mm) | B11: =B9-B10 -> 5831.5 | D11: 15% required-return entry price | E11: =Valuation!B23 -> 66.974009
A12: EV / FY26E Adj EBITDA | B12: =B11/Historical!G19 -> 18.81129
A13: EV / FY26E reported FCF | B13: =B11/Historical!G26 -> 16.426761
A14: EV / FY26E owner FCF | B14: =B11/FCF_Quality!D8 -> 45.117988
A16: The setup
A17: • Down ~75% from the May-25 high. The Feb-26 pivot deliberately trades ~$50mm of bookings (~5pts of growth) for free-user experience to chase 100M DAUs by 2028; FY26 guide: bookings +10.5%, revenue +16.1%, EBITDA margin ~25.7% (from 29.5%), gross margin easing to ~69% on AI compute.
A18: • Q1-26 delivered: revenue +27%, DAUs +21% (56.5M), EBITDA margin 28.6%, FCF $148mm, buybacks running ahead of dilution. Q2 guide implies the bookings trough (+6%); management expects H2 reacceleration — that claim gets tested 5-Aug.
A19: • FCF quality is the crux: 2025 reported FCF $360mm becomes ~$167mm owner FCF after expensing $149mm SBC and removing $45mm interest income; the deferred-revenue tailwind (+$123mm in 2025) also fades as bookings growth slows.
A20: • At ~$133 the market roughly prices the BASE case with SBC treated as non-cash (~$160), or something between base and bull on strict owner FCF. On this model's conservative treatment, the weighted value sits below the price — the margin of safety appeared at the ~$88 lows, not here.
A21: • Watch: 5-Aug Q2 print (bookings vs +6% guide, H2 commentary, DAU trajectory), buyback pace vs $400mm authorization, Max/Video-Call-in-Super monetization data, Chess/Math traction, and any evidence on the AI-substitution bear case.
A23: Provenance, data vintage, and update instructions: see the Model_Info tab.

Sheet Historical
A1: DUOL — Historical Financials ($mm)
A2: Source: Q4/FY2025 shareholder letter (8-K, 26-Feb-26) and Q1 2026 shareholder letter. Blue = reported figures.
B4: FY2023 | C4: FY2024 | D4: FY2025 | E4: Q1 2025 | F4: Q1 2026 | G4: FY2026 Guide
A5: Total bookings | B5: 622 | C5: 870.6 | D5: 1158.4 | E5: 271.6 | F5: 308.5 | G5: 1280
A6: Subscription bookings | C6: 730.7 | D6: 996.3 | F6: 268.1
A7: Bookings growth YoY | C7: =C5/B5-1 -> 0.39967846 | D7: =D5/C5-1 -> 0.33057661 | F7: =F5/E5-1 -> 0.13586156 | G7: =G5/D5-1 -> 0.10497238
A8: Revenue | B8: 531.1 | C8: 748 | D8: 1037.6 | E8: 230.7 | F8: 292 | G8: 1205
A9: Revenue growth YoY | C9: =C8/B8-1 -> 0.40839767 | D9: =D8/C8-1 -> 0.38716578 | F9: =F8/E8-1 -> 0.26571305 | G9: =G8/D8-1 -> 0.16133385
A10: Gross profit | C10: 544.4 | D10: 749.5
A11: Gross margin | C11: =C10/C8 -> 0.72780749 | D11: =D10/D8 -> 0.72234002 | F11: 0.73 | G11: 0.695
A12: R&D | C12: 235.3 | D12: 306.3
A13: S&M | C13: 90.5 | D13: 125.7
A14: G&A | C14: 156 | D14: 181.9
A15: Operating income (GAAP) | C15: =C10-C12-C13-C14 -> 62.6 | D15: =D10-D12-D13-D14 -> 135.6
A16: Interest income | C16: 42.7 | D16: 45.2
A17: Net income (GAAP) | C17: 88.6 | D17: 414.1 | E17: 35.1 | F17: 43.5
A18: 2025 ex one-time $256.7mm tax benefit | D18: =D17-256.7 -> 157.4
A19: Adjusted EBITDA | C19: 191.9 | D19: 305.9 | E19: 62.8 | F19: 83.4 | G19: 310
A20: Adj EBITDA margin | C20: =C19/C8 -> 0.2565508 | D20: =D19/D8 -> 0.29481496 | E20: =E19/E8 -> 0.272215 | F20: =F19/F8 -> 0.28561644 | G20: =G19/G8 -> 0.25726141
A21: SBC (incl. taxes paid on equity awards) | C21: 120.3 | D21: 148.6 | G21: =0.15*G8 -> 180.75
A22: SBC % of revenue | C22: =C21/C8 -> 0.16082888 | D22: =D21/D8 -> 0.14321511 | G22: =G21/G8 -> 0.15
A23: D&A | C23: 10.9 | D23: 14.4
A24: Operating cash flow | C24: 285.5 | D24: 387.8 | E24: 105.6 | F24: 150.8
A25: Capex + capitalized software | C25: 21.1 | D25: 27.4
A26: Free cash flow (company definition) | C26: 264.4 | D26: 360.4 | E26: 103 | F26: 147.8 | G26: 355
A27: FCF margin | C27: =C26/C8 -> 0.35347594 | D27: =D26/D8 -> 0.34734002 | E27: =E26/E8 -> 0.44646727 | F27: =F26/F8 -> 0.50616438 | G27: =G26/G8 -> 0.29460581
A28: Deferred revenue (balance) | C28: 372.9 | D28: 496.2
A29: YoY increase (cash tailwind) | D29: =D28-C28 -> 123.3
A30: Cash + short-term investments | C30: 877.6 | D30: 1140.5
A32: Operating metrics
A33: DAUs, quarter avg (mm) | C33: 40.5 | D33: 52.7 | E33: 46.6 | F33: 56.5
A34: DAU growth YoY | C34: 0.51 | D34: =D33/C33-1 -> 0.30123457 | E34: 0.49 | F34: =F33/E33-1 -> 0.21244635
A35: MAUs (mm) | C35: 116.7 | D35: 133.1 | E35: 130.2
A36: Paid subscribers, period end (mm) | C36: 9.5 | D36: 12.2 | E36: 10.3 | F36: 12.5
A38: FY23 bookings derived from reported +40% FY24 growth; FY24/FY25 DAU rows are Q4 quarter averages. FY26 guide: revenue/bookings/EBITDA at May-26 point estimates; FCF shown at the '>$350mm' guide.
A41: Guidance detail: Q2-26 rev $295.5mm, bookings $283.5mm (+6%), Adj EBITDA $71.0mm (24.0%). Gross margin ~71% Q1-26 easing to ~69% (AI feature costs). Q2 2026 results due 5-Aug-26.

Sheet Quarterly_Data
A1: DUOL — Quarterly Metrics (source: Stephen's DUOL_Metrics.csv, uploaded 29-Jul-26)
A2: Blue = as supplied. Derived columns W-Z are formulas. FY rows shaded. See discrepancy notes below — the DCF & Historical tabs retain 8-K figures where the two differ.
A4: Period | B4: Revenue | C4: GrossProfit | D4: GrossMargin | E4: OperatingIncome | F4: OperatingMargin | G4: EBITDA | H4: NetIncome | I4: NetMargin | J4: EPSDiluted | K4: OperatingCashFlow | L4: CapEx | M4: FreeCashFlow | N4: ShareholdersEquity | O4: TotalDebt | P4: CashAndEquivalents | Q4: SharesOutstanding | R4: DAU | S4: MAU | T4: Bookings | U4: Subscribers | V4: SubscriptionBookings | W4: DAU/MAU | X4: Subs/MAU | Y4: Bookings per DAU (annualized) | Z4: Sub bookings per subscriber (annualized)
A5: Q1 2022 | B5: 81.3 | C5: 59.7 | D5: 0.735 | E5: -8.3 | F5: -0.102 | G5: 9.7 | H5: 1 | I5: 0.012 | K5: -12.2 | M5: 16.9 | R5: 12.5 | S5: 49.2 | T5: 93.8 | U5: 2.9 | V5: 72.9 | W5: =R5/S5 -> 0.25406504 | X5: =U5/S5 -> 0.058943089 | Y5: =T5*4/R5 -> 30.016 | Z5: =V5*4/U5 -> 100.55172
A6: Q2 2022 | B6: 88.4 | C6: 65 | D6: 0.735 | E6: -4.5 | F6: -0.051 | G6: 9.9 | H6: -4.4 | I6: -0.05 | J6: -0.1 | M6: 18.2 | R6: 13.3 | S6: 52.3 | T6: 104.8 | U6: 3.3 | V6: 82.4 | W6: =R6/S6 -> 0.2543021 | X6: =U6/S6 -> 0.063097514 | Y6: =T6*4/R6 -> 31.518797 | Z6: =V6*4/U6 -> 99.878788
A7: Q3 2022 | B7: 92.1 | C7: 67.8 | D7: 0.736 | E7: -5.3 | F7: -0.058 | G7: 8.9 | H7: -5.3 | I7: -0.058 | J7: -0.12 | M7: 15.9 | R7: 14.9 | S7: 54.8 | T7: 106.1 | U7: 3.7 | V7: 90.8 | W7: =R7/S7 -> 0.27189781 | X7: =U7/S7 -> 0.067518248 | Y7: =T7*4/R7 -> 28.483221 | Z7: =V7*4/U7 -> 98.162162
A8: Q4 2022 | B8: 107.7 | C8: 78.8 | D8: 0.732 | E8: 8 | F8: 0.074 | G8: 15.9 | H8: -5 | I8: -0.046 | J8: -0.11 | M8: 22.7 | R8: 16.3 | S8: 60.7 | T8: 133.3 | U8: 4.2 | V8: 103.9 | W8: =R8/S8 -> 0.26853377 | X8: =U8/S8 -> 0.069192751 | Y8: =T8*4/R8 -> 32.711656 | Z8: =V8*4/U8 -> 98.952381
A9: FY2022 | B9: 369.5 | C9: 271.3 | D9: 0.734 | E9: -10.1 | F9: -0.027 | G9: 39.3 | H9: 1.6 | I9: 0.004 | J9: -0.04 | K9: 60.8 | L9: 9.5 | M9: 73.3 | R9: 14.9 | S9: 54.8 | T9: 438 | U9: 4.2 | V9: 350 | W9: =R9/S9 -> 0.27189781 | X9: =U9/S9 -> 0.076642336 | Y9: =T9*1/R9 -> 29.395973 | Z9: =V9*1/U9 -> 83.333333
A10: Q1 2023 | B10: 115.7 | C10: 84.2 | D10: 0.728 | E10: -8.5 | F10: -0.073 | G10: 21.5 | H10: -2.6 | I10: -0.022 | J10: -0.06 | M10: 24.9 | R10: 20.3 | S10: 72.6 | T10: 138.5 | U10: 4.8 | V10: 114.7 | W10: =R10/S10 -> 0.27961433 | X10: =U10/S10 -> 0.066115702 | Y10: =T10*4/R10 -> 27.29064 | Z10: =V10*4/U10 -> 95.583333
A11: Q2 2023 | B11: 126.8 | C11: 93.1 | D11: 0.734 | E11: -4.9 | F11: -0.038 | G11: 24.9 | H11: 3.8 | I11: 0.03 | J11: 0.08 | M11: 31.3 | R11: 21.4 | S11: 74.1 | T11: 146.5 | U11: 5.2 | V11: 124.7 | W11: =R11/S11 -> 0.28879892 | X11: =U11/S11 -> 0.070175439 | Y11: =T11*4/R11 -> 27.383178 | Z11: =V11*4/U11 -> 95.923077
A12: Q3 2023 | B12: 137.6 | C12: 101.4 | D12: 0.737 | E12: -4.7 | F12: -0.034 | G12: 31.2 | H12: 2.8 | I12: 0.02 | J12: 0.06 | M12: 38.9 | R12: 24.2 | S12: 83.1 | T12: 159.8 | U12: 5.8 | V12: 133.9 | W12: =R12/S12 -> 0.2912154 | X12: =U12/S12 -> 0.069795427 | Y12: =T12*4/R12 -> 26.413223 | Z12: =V12*4/U12 -> 92.344828
A13: Q4 2023 | B13: 151 | C13: 110.4 | D13: 0.731 | E13: 4.8 | F13: 0.032 | G13: 42 | H13: 12.4 | I13: 0.082 | J13: 0.26 | K13: 49.2 | L13: 1.5 | M13: 57.9 | N13: 584.8 | P13: 747.6 | Q13: 44.8 | R13: 26.9 | S13: 88.4 | T13: 191 | U13: 6.6 | V13: 152.1 | W13: =R13/S13 -> 0.30429864 | X13: =U13/S13 -> 0.074660633 | Y13: =T13*4/R13 -> 28.401487 | Z13: =V13*4/U13 -> 92.181818
A14: FY2023 | B14: 531.1 | C14: 389 | D14: 0.733 | E14: -13.3 | F14: -0.025 | G14: 93.7 | H14: 16.1 | I14: 0.03 | J14: 0.35 | K14: 153.6 | L14: 13.6 | M14: 142.2 | N14: 584.8 | P14: 747.6 | Q14: 44.8 | R14: 24.2 | S14: 83.1 | T14: 635.8 | U14: 6.6 | V14: 525.4 | W14: =R14/S14 -> 0.2912154 | X14: =U14/S14 -> 0.079422383 | Y14: =T14*1/R14 -> 26.272727 | Z14: =V14*1/U14 -> 79.606061
A15: Q1 2024 | B15: 167.6 | C15: 122.4 | D15: 0.73 | E15: 16.4 | F15: 0.098 | G15: 46.8 | H15: 27 | I15: 0.161 | J15: 0.59 | K15: 29.6 | L15: 3.3 | M15: 38.4 | N15: 711.1 | P15: 747.6 | Q15: 45.4 | R15: 31.4 | S15: 97.6 | T15: 196.8 | U15: 7.4 | V15: 168.6 | W15: =R15/S15 -> 0.32172131 | X15: =U15/S15 -> 0.075819672 | Y15: =T15*4/R15 -> 25.070064 | Z15: =V15*4/U15 -> 91.135135
A16: Q2 2024 | B16: 178.3 | C16: 131 | D16: 0.735 | E16: 18.7 | F16: 0.105 | G16: 49.1 | H16: 24.4 | I16: 0.137 | J16: 0.54 | K16: 38.4 | L16: 2.7 | M16: 40.5 | N16: 766.9 | P16: 747.6 | Q16: 45.4 | R16: 34.1 | S16: 103.6 | T16: 206.3 | U16: 8 | V16: 180.3 | W16: =R16/S16 -> 0.32915058 | X16: =U16/S16 -> 0.077220077 | Y16: =T16*4/R16 -> 24.199413 | Z16: =V16*4/U16 -> 90.15
A17: Q3 2024 | B17: 192.6 | C17: 140.4 | D17: 0.729 | E17: 13.6 | F17: 0.071 | G17: 54.9 | H17: 23.4 | I17: 0.121 | J17: 0.49 | K17: 56.3 | L17: 5.1 | M17: 51.2 | N17: 791.6 | P17: 787.6 | Q17: 45.4 | R17: 37.2 | S17: 113.1 | T17: 223.6 | U17: 8.6 | V17: 189.9 | W17: =R17/S17 -> 0.32891247 | X17: =U17/S17 -> 0.076038904 | Y17: =T17*4/R17 -> 24.043011 | Z17: =V17*4/U17 -> 88.325581
A18: Q4 2024 | B18: 209.6 | C18: 150.6 | D18: 0.719 | E18: 13.9 | F18: 0.066 | G18: 64.5 | H18: 13.9 | I18: 0.066 | J18: 0.29 | K18: 83.3 | L18: 3.5 | M18: 87.8 | N18: 882 | P18: 838.6 | Q18: 46 | R18: 40.5 | S18: 116.7 | T18: 271.6 | U18: 9.5 | V18: 213.9 | W18: =R18/S18 -> 0.3470437 | X18: =U18/S18 -> 0.081405313 | Y18: =T18*4/R18 -> 26.824691 | Z18: =V18*4/U18 -> 90.063158
A19: FY2024 | B19: 748 | C19: 544.4 | D19: 0.728 | E19: 62.6 | F19: 0.084 | G19: 215.3 | H19: 88.6 | I19: 0.118 | J19: 1.91 | K19: 207.6 | L19: 14.6 | M19: 218 | N19: 882 | P19: 838.6 | Q19: 46 | R19: 40.5 | S19: 116.7 | T19: 898.3 | U19: 9.5 | V19: 752.7 | W19: =R19/S19 -> 0.3470437 | X19: =U19/S19 -> 0.081405313 | Y19: =T19*1/R19 -> 22.180247 | Z19: =V19*1/U19 -> 79.231579
A20: Q1 2025 | B20: 230.7 | C20: 164.1 | D20: 0.711 | E20: 23.6 | F20: 0.102 | G20: 64.7 | H20: 35.1 | I20: 0.152 | J20: 0.74 | K20: 50.5 | L20: 3.5 | M20: 53.9 | N20: 893.8 | P20: 877.6 | Q20: 46 | R20: 46 | S20: 126.6 | T20: 267.7 | U20: 10.4 | V20: 232.7 | W20: =R20/S20 -> 0.36334913 | X20: =U20/S20 -> 0.082148499 | Y20: =T20*4/R20 -> 23.278261 | Z20: =V20*4/U20 -> 89.5
A21: Q2 2025 | B21: 251.7 | C21: 182.6 | D21: 0.726 | E21: 33.4 | F21: 0.133 | G21: 72.1 | H21: 44.8 | I21: 0.178 | J21: 0.94 | K21: 67.6 | L21: 2.9 | M21: 70.5 | N21: 977 | P21: 1068.1 | Q21: 47.6 | R21: 49.5 | S21: 131.2 | T21: 289.1 | U21: 11 | V21: 251.6 | W21: =R21/S21 -> 0.37728659 | X21: =U21/S21 -> 0.083841463 | Y21: =T21*4/R21 -> 23.361616 | Z21: =V21*4/U21 -> 91.490909
A22: Q3 2025 | B22: 271.7 | C22: 196.9 | D22: 0.725 | E22: 35.2 | F22: 0.13 | G22: 80.3 | H22: 292.2 | I22: 1.075 | J22: 5.95 | K22: 84.2 | L22: 6.8 | M22: 77.4 | N22: 1307.5 | P22: 1121.5 | Q22: 49.1 | R22: 50.5 | S22: 135.3 | T22: 313.6 | U22: 11.5 | V22: 268.9 | W22: =R22/S22 -> 0.37324464 | X22: =U22/S22 -> 0.084996305 | Y22: =T22*4/R22 -> 24.839604 | Z22: =V22*4/U22 -> 93.530435
A23: Q4 2025 | B23: 282.9 | C23: 205.9 | D23: 0.728 | E23: 43.5 | F23: 0.154 | G23: 84.3 | H23: 42 | I23: 0.148 | J23: 0.84 | K23: 107.3 | L23: 13.5 | M23: 93.7 | N23: 1347 | O23: 0 | P23: 1036.4 | Q23: 49.8 | R23: 52.7 | S23: 133.1 | T23: 336.8 | U23: 12.2 | V23: 296.6 | W23: =R23/S23 -> 0.3959429 | X23: =U23/S23 -> 0.091660406 | Y23: =T23*4/R23 -> 25.563567 | Z23: =V23*4/U23 -> 97.245902
A24: FY2025 | B24: 1037.6 | C24: 749.5 | D24: 0.722 | E24: 135.6 | F24: 0.131 | G24: 305.9 | H24: 414.1 | I24: 0.399 | J24: 8.38 | K24: 387.8 | L24: 27.4 | M24: 360.4 | N24: 1347 | O24: 0 | P24: 1036.4 | Q24: 49.8 | R24: 52.7 | S24: 133.1 | T24: 1158.4 | U24: 12.2 | V24: 996.3 | W24: =R24/S24 -> 0.3959429 | X24: =U24/S24 -> 0.091660406 | Y24: =T24*1/R24 -> 21.981025 | Z24: =V24*1/U24 -> 81.663934
A25: Q1 2026 | B25: 292 | C25: 213.1 | D25: 0.73 | E25: 44.5 | F25: 0.153 | G25: 83.4 | H25: 43.5 | I25: 0.149 | J25: 0.89 | K25: 150.8 | L25: 3 | M25: 147.8 | N25: 1391.8 | O25: 0 | P25: 1138.6 | Q25: 49 | R25: 56.5 | S25: 137.8 | T25: 308.5 | U25: 12.5 | V25: 268.1 | W25: =R25/S25 -> 0.41001451 | X25: =U25/S25 -> 0.090711176 | Y25: =T25*4/R25 -> 21.840708 | Z25: =V25*4/U25 -> 85.792
A27: Scenario cross-check: 2028E total bookings ($mm) = FY25 bookings x (1+DAU CAGR)^3 x (1+bookings-per-DAU drift)^3
A28: DAU CAGR \ per-DAU drift | B28: -0.08 | C28: -0.06 | D28: -0.04 | E28: -0.02 | F28: 0
A29: 0.12 | B29: =1158.4*(1+$A29)^3*(1+B28)^3 -> 1267.2903 | C29: =1158.4*(1+$A29)^3*(1+C28)^3 -> 1351.7494 | D29: =1158.4*(1+$A29)^3*(1+D28)^3 -> 1439.8801 | E29: =1158.4*(1+$A29)^3*(1+E28)^3 -> 1531.7604 | F29: =1158.4*(1+$A29)^3*(1+F28)^3 -> 1627.4686
A30: 0.16 | B30: =1158.4*(1+$A30)^3*(1+B28)^3 -> 1407.9784 | C30: =1158.4*(1+$A30)^3*(1+C28)^3 -> 1501.8138 | D30: =1158.4*(1+$A30)^3*(1+D28)^3 -> 1599.7283 | E30: =1158.4*(1+$A30)^3*(1+E28)^3 -> 1701.8087 | F30: =1158.4*(1+$A30)^3*(1+F28)^3 -> 1808.1419
A31: 0.2 | B31: =1158.4*(1+$A31)^3*(1+B28)^3 -> 1558.7116 | C31: =1158.4*(1+$A31)^3*(1+C28)^3 -> 1662.5926 | D31: =1158.4*(1+$A31)^3*(1+D28)^3 -> 1770.9895 | E31: =1158.4*(1+$A31)^3*(1+E28)^3 -> 1883.9983 | F31: =1158.4*(1+$A31)^3*(1+F28)^3 -> 2001.7152
A32: 0.24 | B32: =1158.4*(1+$A32)^3*(1+B28)^3 -> 1719.8362 | C32: =1158.4*(1+$A32)^3*(1+C28)^3 -> 1834.4554 | D32: =1158.4*(1+$A32)^3*(1+D28)^3 -> 1954.0573 | E32: =1158.4*(1+$A32)^3*(1+E28)^3 -> 2078.7479 | F32: =1158.4*(1+$A32)^3*(1+F28)^3 -> 2208.6332
A34: Compare with the DCF tabs' 2028 revenue paths: Bear ~$1,341mm / Base ~$1,538mm / Bull ~$1,683mm (bookings run ~5% above revenue while growing). Management's 100M-DAU-by-2028 goal = ~24% DAU CAGR; with the observed -5 to -6%/yr per-DAU drift that implies ~17-18% bookings growth — i.e., the bull case requires the target to be roughly hit. Base ~ mid-teens DAU growth with drift persisting; bear = DAU fading to low-teens.
A38: Data quality notes
A39: • FY2024 rows diverge from the 8-K: bookings $898.3 vs $870.6 reported (sub bookings $752.7 vs $730.7); OCF $207.6 vs $285.5; FCF $218.0 vs $264.4 recast; 'EBITDA' $215.3 vs $191.9 company Adj EBITDA. Q1-2024 OCF of $29.6 appears to be the Q1-2023 figure (Q1-2024 reported: $83.5).
A41: • The EBITDA column mixes definitions: 2023/2025/Q1-26 rows match company Adjusted EBITDA; 2024 rows follow a vendor calculation. FCF pre-2025 uses the old company definition (adds back equity-award taxes); 2025 onward uses the recast definition.
A43: • 2025 and Q1-2026 rows tie to the shareholder letters exactly. User-metric columns (DAU/MAU/subscribers) have no 8-K conflict and are the primary value of this data set.

Sheet FCF_Quality
A1: DUOL — FCF Quality: Reported FCF vs Owner FCF
A2: Headline FCF is flattered by SBC, interest on the cash pile, and the deferred-revenue tailwind. Owner FCF strips these out.
B4: FY2024 | C4: FY2025 | D4: FY2026E
A5: Free cash flow, company definition | B5: =Historical!C26 -> 264.4 | C5: =Historical!D26 -> 360.4 | D5: =Historical!G26 -> 355
A6: less: SBC incl. equity-award taxes | B6: =-Historical!C21 -> -120.3 | C6: =-Historical!D21 -> -148.6 | D6: =-Historical!G21 -> -180.75
A7: less: interest income (belongs to the cash pile) | B7: =-Historical!C16 -> -42.7 | C7: =-Historical!D16 -> -45.2 | D7: -45
A8: Owner FCF | B8: =B5+B6+B7 -> 101.4 | C8: =C5+C6+C7 -> 166.6 | D8: =D5+D6+D7 -> 129.25
A9: Reported FCF margin | B9: =Historical!C27 -> 0.35347594 | C9: =Historical!D27 -> 0.34734002 | D9: =Historical!G27 -> 0.29460581
A10: Owner FCF margin | B10: =B8/Historical!C8 -> 0.1355615 | C10: =C8/Historical!D8 -> 0.16056284 | D10: =D8/Historical!G8 -> 0.10726141
A12: Memo: deferred revenue increase inside OCF | C12: =Historical!D29 -> 123.3
A13: = 34% of 2025 reported FCF. This cash is real but is a function of bookings growing faster than revenue; it fades as growth slows (2026 bookings-revenue gap narrows to ~$75mm).
A15: Memo: GAAP net income | C15: =Historical!D17 -> 414.1
A16: ex one-time $256.7mm tax benefit (VA release) | C16: =Historical!D18 -> 157.4
A19: What you pay at the current price
A20: Market cap (diluted) | B20: =Assumptions!B11*Assumptions!B10 -> 6972
A21: less: net cash | B21: =-Assumptions!B9 -> -1140.5
A22: Enterprise value | B22: =B20+B21 -> 5831.5
A23: EV / FY26E Adj EBITDA (~$310mm) | B23: =B22/Historical!G19 -> 18.81129
A24: EV / FY26E reported FCF (>$350mm) | B24: =B22/D5 -> 16.426761
A25: EV / FY26E owner FCF | B25: =B22/D8 -> 45.117988
A27: The multiple you quote depends entirely on SBC treatment: the same EV is ~16x headline FCF but ~40x+ owner FCF. The DCF sheets expense SBC in full and hold the share count flat; each sheet also shows the per-share value if you instead treat SBC as non-cash (market convention).

Sheet Assumptions
A1: DUOL — Global Assumptions & Scenario Parameters
A2: Blue = hardcoded input (edit these). Yellow = key levers. All $ in millions unless stated.
A4: Global inputs
A5: WACC / discount rate | B5: 0.105
A6: D&A (% of revenue) | B6: 0.015
A7: Capex + capitalized software (% of revenue) | B7: 0.023
A8: Working-capital capture (% of YoY revenue increase) | B8: 0.18
A9: Net cash: cash + ST investments, Dec-31-25 ($mm) | B9: 1140.5
A10: Fully diluted shares (mm) | B10: 49.8
A11: Current share price (29-Jul-26, user-supplied) | B11: 140
A12: Terminal value cap (x terminal-year owner FCF) | B12: 20
A14: Scenario parameters | C14: Bear | D14: Base | E14: Bull
A15: Terminal growth rate | C15: 0.015 | D15: 0.03 | E15: 0.035
A16: Probability weight | C16: 0.25 | D16: 0.5 | E16: 0.25 | F16: =SUM(C16:E16) -> 1 | G16: must sum to 100%
A18: Scenario narratives
A19: Bear | B19: AI erosion is real: LLM assistants absorb casual language practice; the 2026 user-growth pivot fails to reignite bookings. Revenue growth fades to ~1-2% by 2034-35; EBITDA margin stuck ~23-24% on AI compute costs; SBC stays heavy (~13-15% of revenue).
A20: Base | B20: Pivot partially works: ~20% DAU growth compounds, monetization levers re-engage from 2027-28 (Video Call in Super, Max repricing, ads). Revenue ~10% CAGR to 2035; EBITDA margin recovers from 25.5% to 32%; SBC fades to 10% of revenue.
A21: Bull | B21: 100M DAU by 2028 achieved; management's stated ~20% bookings capability returns 2027-29; Chess/Math/Music add second engines; AI content leverage lifts EBITDA margin to 35%; SBC disciplined to 8%.
A23: Sources & notes
A24: • FY24/FY25 financials: Duolingo Q4/FY2025 shareholder letter (8-K filed 26-Feb-26, SEC EDGAR). Q1-26: Q1 2026 shareholder letter (May-26).
A25: • FY26 guidance (May-26 reiteration): revenue ~$1,205mm (+16.1%), bookings ~$1,280mm (+10.5%), Adj EBITDA ~$310mm (25.7%), FCF >$350mm, SBC ~15% of revenue, effective tax BENEFIT ~6%.
A26: • Net cash = $1,036.4mm cash + $104.1mm ST investments at 31-Dec-25; no debt. Q1-26 ended with ~$1.1bn cash after $50.6mm of buybacks ($400mm authorization outstanding).
A27: • Diluted shares held flat at 49.8mm: SBC is fully expensed in owner FCF, and the $400mm buyback has so far more than offset grant dilution (mgmt: 3-yr avg net dilution <2%/yr). Do not also grow the share count — that would double-count.
A28: • Cash tax path: 2026 is a guided ~6% benefit; DTAs (valuation allowance released 2025, one-time $256.7mm GAAP benefit) shelter near-term cash taxes, ramping to a 21% normalized rate by 2029-30.
A29: • Working capital: deferred revenue grows while bookings > revenue (deferred rev +$123.3mm in 2025). Modeled as 18% of the YoY revenue increase — this tailwind fades as growth slows.
A30: • Interest income (~$45mm/yr) is EXCLUDED from FCF because the cash generating it is added separately as net cash.

Sheet DCF_Bear
A1: DUOL DCF — Bear — AI erosion / pivot fails
A2: Owner-FCF basis: SBC fully expensed, interest income excluded, share count flat. Blue rows = per-year drivers (edit).
B3: 2025A | C3: 2026E | D3: 2027E | E3: 2028E | F3: 2029E | G3: 2030E | H3: 2031E | I3: 2032E | J3: 2033E | K3: 2034E | L3: 2035E
A4: Year index (for discounting) | B4: 0 | C4: 1 | D4: 2 | E4: 3 | F4: 4 | G4: 5 | H4: 6 | I4: 7 | J4: 8 | K4: 9 | L4: 10
A5: Revenue growth YoY | C5: 0.15 | D5: 0.07 | E5: 0.05 | F5: 0.04 | G5: 0.03 | H5: 0.03 | I5: 0.02 | J5: 0.02 | K5: 0.01 | L5: 0.01
A6: Revenue | B6: =Historical!D8 -> 1037.6 | C6: =B6*(1+C5) -> 1193.24 | D6: =C6*(1+D5) -> 1276.7668 | E6: =D6*(1+E5) -> 1340.6051 | F6: =E6*(1+F5) -> 1394.2293 | G6: =F6*(1+G5) -> 1436.0562 | H6: =G6*(1+H5) -> 1479.1379 | I6: =H6*(1+I5) -> 1508.7207 | J6: =I6*(1+J5) -> 1538.8951 | ... L6: =K6*(1+L5) -> 1569.8269
A7: Adj EBITDA margin | B7: =Historical!D20 -> 0.29481496 | C7: 0.245 | D7: 0.24 | E7: 0.24 | F7: 0.24 | G7: 0.24 | H7: 0.24 | I7: 0.235 | J7: 0.235 | K7: 0.23 | L7: 0.23
A8: Adjusted EBITDA | B8: =Historical!D19 -> 305.9 | C8: =C6*C7 -> 292.3438 | D8: =D6*D7 -> 306.42403 | E8: =E6*E7 -> 321.74523 | F8: =F6*F7 -> 334.61504 | G8: =G6*G7 -> 344.65349 | H8: =H6*H7 -> 354.9931 | I8: =I6*I7 -> 354.54936 | J8: =J6*J7 -> 361.64034 | ... L8: =L6*L7 -> 361.06018
A9: SBC (% of revenue) | B9: =Historical!D22 -> 0.14321511 | C9: 0.15 | D9: 0.145 | E9: 0.14 | F9: 0.14 | G9: 0.135 | H9: 0.135 | I9: 0.13 | J9: 0.13 | K9: 0.13 | L9: 0.13
A10: SBC (incl. equity-award taxes) | B10: =-Historical!D21 -> -148.6 | C10: =-C6*C9 -> -178.986 | D10: =-D6*D9 -> -185.13119 | E10: =-E6*E9 -> -187.68472 | F10: =-F6*F9 -> -195.19211 | G10: =-G6*G9 -> -193.86759 | H10: =-H6*H9 -> -199.68362 | I10: =-I6*I9 -> -196.13369 | J10: =-J6*J9 -> -200.05636 | ... L10: =-L6*L9 -> -204.07749
A11: EBITDA less SBC ('owner EBITDA') | C11: =C8+C10 -> 113.3578 | D11: =D8+D10 -> 121.29285 | E11: =E8+E10 -> 134.06051 | F11: =F8+F10 -> 139.42293 | G11: =G8+G10 -> 150.7859 | H11: =H8+H10 -> 155.30948 | I11: =I8+I10 -> 158.41567 | J11: =J8+J10 -> 161.58398 | ... L11: =L8+L10 -> 156.98269
A12: D&A | C12: =-C6*Assumptions!$B$6 -> -17.8986 | D12: =-D6*Assumptions!$B$6 -> -19.151502 | E12: =-E6*Assumptions!$B$6 -> -20.109077 | F12: =-F6*Assumptions!$B$6 -> -20.91344 | G12: =-G6*Assumptions!$B$6 -> -21.540843 | H12: =-H6*Assumptions!$B$6 -> -22.187069 | I12: =-I6*Assumptions!$B$6 -> -22.63081 | J12: =-J6*Assumptions!$B$6 -> -23.083426 | ... L12: =-L6*Assumptions!$B$6 -> -23.547403
A13: EBIT (SBC expensed) | C13: =C11+C12 -> 95.4592 | D13: =D11+D12 -> 102.14134 | E13: =E11+E12 -> 113.95144 | F13: =F11+F12 -> 118.50949 | G13: =G11+G12 -> 129.24506 | H13: =H11+H12 -> 133.12241 | I13: =I11+I12 -> 135.78486 | J13: =J11+J12 -> 138.50056 | ... L13: =L11+L12 -> 133.43528
A14: Cash tax rate (neg = benefit) | C14: -0.06 | D14: 0.05 | E14: 0.12 | F14: 0.18 | G14: 0.21 | H14: 0.21 | I14: 0.21 | J14: 0.21 | K14: 0.21 | L14: 0.21
A15: NOPAT | C15: =C13*(1-C14) -> 101.18675 | D15: =D13*(1-D14) -> 97.034277 | E15: =E13*(1-E14) -> 100.27726 | F15: =F13*(1-F14) -> 97.177785 | G15: =G13*(1-G14) -> 102.1036 | H15: =H13*(1-H14) -> 105.16671 | I15: =I13*(1-I14) -> 107.27004 | J15: =J13*(1-J14) -> 109.41544 | ... L15: =L13*(1-L14) -> 105.41387
A16: add: D&A | C16: =-C12 -> 17.8986 | D16: =-D12 -> 19.151502 | E16: =-E12 -> 20.109077 | F16: =-F12 -> 20.91344 | G16: =-G12 -> 21.540843 | H16: =-H12 -> 22.187069 | I16: =-I12 -> 22.63081 | J16: =-J12 -> 23.083426 | ... L16: =-L12 -> 23.547403
A17: less: capex + capitalized software | C17: =-C6*Assumptions!$B$7 -> -27.44452 | D17: =-D6*Assumptions!$B$7 -> -29.365636 | E17: =-E6*Assumptions!$B$7 -> -30.833918 | F17: =-F6*Assumptions!$B$7 -> -32.067275 | G17: =-G6*Assumptions!$B$7 -> -33.029293 | H17: =-H6*Assumptions!$B$7 -> -34.020172 | I17: =-I6*Assumptions!$B$7 -> -34.700575 | J17: =-J6*Assumptions!$B$7 -> -35.394587 | ... L17: =-L6*Assumptions!$B$7 -> -36.106018
A18: add: working capital (deferred-rev tailwind) | C18: =Assumptions!$B$8*(C6-B6) -> 28.0152 | D18: =Assumptions!$B$8*(D6-C6) -> 15.034824 | E18: =Assumptions!$B$8*(E6-D6) -> 11.490901 | F18: =Assumptions!$B$8*(F6-E6) -> 9.652357 | G18: =Assumptions!$B$8*(G6-F6) -> 7.5288385 | H18: =Assumptions!$B$8*(H6-G6) -> 7.7547036 | I18: =Assumptions!$B$8*(I6-H6) -> 5.3248965 | J18: =Assumptions!$B$8*(J6-I6) -> 5.4313944 | ... L18: =Assumptions!$B$8*(L6-K6) -> 2.7977113
A19: Unlevered owner FCF | C19: =C15+C16+C17+C18 -> 119.65603 | D19: =D15+D16+D17+D18 -> 101.85497 | E19: =E15+E16+E17+E18 -> 101.04332 | F19: =F15+F16+F17+F18 -> 95.676308 | G19: =G15+G16+G17+G18 -> 98.143986 | H19: =H15+H16+H17+H18 -> 101.08831 | I19: =I15+I16+I17+I18 -> 100.52517 | J19: =J15+J16+J17+J18 -> 102.53567 | ... L19: =L15+L16+L17+L18 -> 95.652971
A20: Discount factor | C20: =1/(1+Assumptions!$B$5)^C4 -> 0.90497738 | D20: =1/(1+Assumptions!$B$5)^D4 -> 0.81898405 | E20: =1/(1+Assumptions!$B$5)^E4 -> 0.74116204 | F20: =1/(1+Assumptions!$B$5)^F4 -> 0.67073487 | G20: =1/(1+Assumptions!$B$5)^G4 -> 0.60699989 | H20: =1/(1+Assumptions!$B$5)^H4 -> 0.54932116 | I20: =1/(1+Assumptions!$B$5)^I4 -> 0.49712323 | J20: =1/(1+Assumptions!$B$5)^J4 -> 0.44988527 | ... L20: =1/(1+Assumptions!$B$5)^L4 -> 0.36844886
A21: PV of FCF | C21: =C19*C20 -> 108.286 | D21: =D19*D20 -> 83.417593 | E21: =E19*E20 -> 74.889476 | F21: =F19*F20 -> 64.173436 | G21: =G19*G20 -> 59.573389 | H21: =H19*H20 -> 55.529946 | I21: =I19*I20 -> 49.973397 | J21: =J19*J20 -> 46.12929 | ... L21: =L19*L20 -> 35.243228
A23: Memo: FCF before SBC (company-style) | C23: =C19-C10 -> 298.64203 | D23: =D19-D10 -> 286.98615 | E23: =E19-E10 -> 288.72804 | F23: =F19-F10 -> 290.86842 | G23: =G19-G10 -> 292.01158 | H23: =H19-H10 -> 300.77192 | I23: =I19-I10 -> 296.65886 | J23: =J19-J10 -> 302.59204 | ... L23: =L19-L10 -> 299.73046
A24: Memo: implied owner FCF margin | C24: =C19/C6 -> 0.10027826 | D24: =D19/D6 -> 0.079775701 | E24: =E19/E6 -> 0.075371429 | F24: =F19/F6 -> 0.068623077 | G24: =G19/G6 -> 0.068342718 | H24: =H19/H6 -> 0.068342718 | I24: =I19/I6 -> 0.066629412 | J24: =J19/J6 -> 0.066629412 | ... L24: =L19/L6 -> 0.060932178
A25: Valuation
A26: PV of FCF, 2026-2035 | B26: =SUM(C21:L21) -> 615.77394
A27: Terminal growth rate | B27: =Assumptions!$C$15 -> 0.015
A28: Terminal-year owner FCF x (1+g) | B28: =L19*(1+B27) -> 97.087766
A29: Terminal value — Gordon | B29: =B28/(Assumptions!$B$5-B27) -> 1078.753
A30: Terminal value — cap (20x terminal FCF) | B30: =Assumptions!$B$12*L19 -> 1913.0594
A31: Terminal value used (lower of the two) | B31: =MIN(B29,B30) -> 1078.753
A32: Implied exit multiple | B32: =B31/L19 -> 11.277778
A33: PV of terminal value | B33: =B31*L20 -> 397.4653
A34: Enterprise value | B34: =B26+B33 -> 1013.2392
A35: add: net cash | B35: =Assumptions!$B$9 -> 1140.5
A36: Equity value | B36: =B34+B35 -> 2153.7392
A37: Fully diluted shares (mm) | B37: =Assumptions!$B$10 -> 49.8
A38: Value per share | B38: =B36/B37 -> 43.247776
A39: Upside / (downside) vs current price | B39: =B38/Assumptions!$B$11-1 -> -0.69108732
A41: Memo: value if SBC treated as non-cash (market convention) | B41: =SUMPRODUCT(-C10:L10/(1+Assumptions!$B$5)^C4:L4) -> 1155.9545 | C41: PV of 2026-35 SBC
A42: plus PV of terminal SBC | B42: =(-L10*(1+B27)/(Assumptions!$B$5-B27))*L20 -> 848.00002
...

Sheet DCF_Base
A1: DUOL DCF — Base — pivot partially works
A2: Owner-FCF basis: SBC fully expensed, interest income excluded, share count flat. Blue rows = per-year drivers (edit).
B3: 2025A | C3: 2026E | D3: 2027E | E3: 2028E | F3: 2029E | G3: 2030E | H3: 2031E | I3: 2032E | J3: 2033E | K3: 2034E | L3: 2035E
A4: Year index (for discounting) | B4: 0 | C4: 1 | D4: 2 | E4: 3 | F4: 4 | G4: 5 | H4: 6 | I4: 7 | J4: 8 | K4: 9 | L4: 10
A5: Revenue growth YoY | C5: 0.161 | D5: 0.12 | E5: 0.14 | F5: 0.13 | G5: 0.11 | H5: 0.1 | I5: 0.09 | J5: 0.08 | K5: 0.07 | L5: 0.06
A6: Revenue | B6: =Historical!D8 -> 1037.6 | C6: =B6*(1+C5) -> 1204.6536 | D6: =C6*(1+D5) -> 1349.212 | E6: =D6*(1+E5) -> 1538.1017 | F6: =E6*(1+F5) -> 1738.0549 | G6: =F6*(1+G5) -> 1929.241 | H6: =G6*(1+H5) -> 2122.1651 | I6: =H6*(1+I5) -> 2313.1599 | J6: =I6*(1+J5) -> 2498.2127 | ... L6: =K6*(1+L5) -> 2833.4729
A7: Adj EBITDA margin | B7: =Historical!D20 -> 0.29481496 | C7: 0.255 | D7: 0.265 | E7: 0.275 | F7: 0.285 | G7: 0.295 | H7: 0.3 | I7: 0.305 | J7: 0.31 | K7: 0.315 | L7: 0.32
A8: Adjusted EBITDA | B8: =Historical!D19 -> 305.9 | C8: =C6*C7 -> 307.18667 | D8: =D6*D7 -> 357.54119 | E8: =E6*E7 -> 422.97797 | F8: =F6*F7 -> 495.34566 | G8: =G6*G7 -> 569.12609 | H8: =H6*H7 -> 636.64952 | I8: =I6*I7 -> 705.51378 | J8: =J6*J7 -> 774.44595 | ... L8: =L6*L7 -> 906.71132
A9: SBC (% of revenue) | B9: =Historical!D22 -> 0.14321511 | C9: 0.15 | D9: 0.145 | E9: 0.14 | F9: 0.13 | G9: 0.125 | H9: 0.12 | I9: 0.115 | J9: 0.11 | K9: 0.105 | L9: 0.1
A10: SBC (incl. equity-award taxes) | B10: =-Historical!D21 -> -148.6 | C10: =-C6*C9 -> -180.69804 | D10: =-D6*D9 -> -195.63574 | E10: =-E6*E9 -> -215.33424 | F10: =-F6*F9 -> -225.94714 | G10: =-G6*G9 -> -241.15512 | H10: =-H6*H9 -> -254.65981 | I10: =-I6*I9 -> -266.01339 | J10: =-J6*J9 -> -274.8034 | ... L10: =-L6*L9 -> -283.34729
A11: EBITDA less SBC ('owner EBITDA') | C11: =C8+C10 -> 126.48863 | D11: =D8+D10 -> 161.90544 | E11: =E8+E10 -> 207.64373 | F11: =F8+F10 -> 269.39852 | G11: =G8+G10 -> 327.97097 | H11: =H8+H10 -> 381.98971 | I11: =I8+I10 -> 439.50039 | J11: =J8+J10 -> 499.64255 | ... L11: =L8+L10 -> 623.36403
A12: D&A | C12: =-C6*Assumptions!$B$6 -> -18.069804 | D12: =-D6*Assumptions!$B$6 -> -20.23818 | E12: =-E6*Assumptions!$B$6 -> -23.071526 | F12: =-F6*Assumptions!$B$6 -> -26.070824 | G12: =-G6*Assumptions!$B$6 -> -28.938615 | H12: =-H6*Assumptions!$B$6 -> -31.832476 | I12: =-I6*Assumptions!$B$6 -> -34.697399 | J12: =-J6*Assumptions!$B$6 -> -37.473191 | ... L12: =-L6*Assumptions!$B$6 -> -42.502093
A13: EBIT (SBC expensed) | C13: =C11+C12 -> 108.41882 | D13: =D11+D12 -> 141.66726 | E13: =E11+E12 -> 184.57221 | F13: =F11+F12 -> 243.32769 | G13: =G11+G12 -> 299.03235 | H13: =H11+H12 -> 350.15724 | I13: =I11+I12 -> 404.80299 | J13: =J11+J12 -> 462.16936 | ... L13: =L11+L12 -> 580.86194
A14: Cash tax rate (neg = benefit) | C14: -0.06 | D14: 0.08 | E14: 0.15 | F14: 0.2 | G14: 0.21 | H14: 0.21 | I14: 0.21 | J14: 0.21 | K14: 0.21 | L14: 0.21
A15: NOPAT | C15: =C13*(1-C14) -> 114.92395 | D15: =D13*(1-D14) -> 130.33388 | E15: =E13*(1-E14) -> 156.88638 | F15: =F13*(1-F14) -> 194.66215 | G15: =G13*(1-G14) -> 236.23556 | H15: =H13*(1-H14) -> 276.62422 | I15: =I13*(1-I14) -> 319.79436 | J15: =J13*(1-J14) -> 365.11379 | ... L15: =L13*(1-L14) -> 458.88093
A16: add: D&A | C16: =-C12 -> 18.069804 | D16: =-D12 -> 20.23818 | E16: =-E12 -> 23.071526 | F16: =-F12 -> 26.070824 | G16: =-G12 -> 28.938615 | H16: =-H12 -> 31.832476 | I16: =-I12 -> 34.697399 | J16: =-J12 -> 37.473191 | ... L16: =-L12 -> 42.502093
A17: less: capex + capitalized software | C17: =-C6*Assumptions!$B$7 -> -27.707033 | D17: =-D6*Assumptions!$B$7 -> -31.031877 | E17: =-E6*Assumptions!$B$7 -> -35.376339 | F17: =-F6*Assumptions!$B$7 -> -39.975264 | G17: =-G6*Assumptions!$B$7 -> -44.372543 | H17: =-H6*Assumptions!$B$7 -> -48.809797 | I17: =-I6*Assumptions!$B$7 -> -53.202679 | J17: =-J6*Assumptions!$B$7 -> -57.458893 | ... L17: =-L6*Assumptions!$B$7 -> -65.169876
A18: add: working capital (deferred-rev tailwind) | C18: =Assumptions!$B$8*(C6-B6) -> 30.069648 | D18: =Assumptions!$B$8*(D6-C6) -> 26.020518 | E18: =Assumptions!$B$8*(E6-D6) -> 34.000143 | F18: =Assumptions!$B$8*(F6-E6) -> 35.99158 | G18: =Assumptions!$B$8*(G6-F6) -> 34.413488 | H18: =Assumptions!$B$8*(H6-G6) -> 34.726338 | I18: =Assumptions!$B$8*(I6-H6) -> 34.379074 | J18: =Assumptions!$B$8*(J6-I6) -> 33.309503 | ... L18: =Assumptions!$B$8*(L6-K6) -> 28.869346
A19: Unlevered owner FCF | C19: =C15+C16+C17+C18 -> 135.35637 | D19: =D15+D16+D17+D18 -> 145.5607 | E19: =E15+E16+E17+E18 -> 178.5817 | F19: =F15+F16+F17+F18 -> 216.74929 | G19: =G15+G16+G17+G18 -> 255.21512 | H19: =H15+H16+H17+H18 -> 294.37324 | I19: =I15+I16+I17+I18 -> 335.66816 | J19: =J15+J16+J17+J18 -> 378.43759 | ... L19: =L15+L16+L17+L18 -> 465.0825
A20: Discount factor | C20: =1/(1+Assumptions!$B$5)^C4 -> 0.90497738 | D20: =1/(1+Assumptions!$B$5)^D4 -> 0.81898405 | E20: =1/(1+Assumptions!$B$5)^E4 -> 0.74116204 | F20: =1/(1+Assumptions!$B$5)^F4 -> 0.67073487 | G20: =1/(1+Assumptions!$B$5)^G4 -> 0.60699989 | H20: =1/(1+Assumptions!$B$5)^H4 -> 0.54932116 | I20: =1/(1+Assumptions!$B$5)^I4 -> 0.49712323 | J20: =1/(1+Assumptions!$B$5)^J4 -> 0.44988527 | ... L20: =1/(1+Assumptions!$B$5)^L4 -> 0.36844886
A21: PV of FCF | C21: =C19*C20 -> 122.49445 | D21: =D19*D20 -> 119.21189 | E21: =E19*E20 -> 132.35798 | F21: =F19*F20 -> 145.38131 | G21: =G19*G20 -> 154.91555 | H21: =H19*H20 -> 161.70545 | I21: =I19*I20 -> 166.86844 | J21: =J19*J20 -> 170.2535 | ... L21: =L19*L20 -> 171.35912
A23: Memo: FCF before SBC (company-style) | C23: =C19-C10 -> 316.05441 | D23: =D19-D10 -> 341.19645 | E23: =E19-E10 -> 393.91594 | F23: =F19-F10 -> 442.69644 | G23: =G19-G10 -> 496.37024 | H23: =H19-H10 -> 549.03305 | I23: =I19-I10 -> 601.68155 | J23: =J19-J10 -> 653.24099 | ... L23: =L19-L10 -> 748.42978
A24: Memo: implied owner FCF margin | C24: =C19/C6 -> 0.11236124 | D24: =D19/D6 -> 0.10788571 | E24: =E19/E6 -> 0.11610526 | F24: =F19/F6 -> 0.12470796 | G24: =G19/G6 -> 0.13228784 | H24: =H19/H6 -> 0.13871364 | I24: =I19/I6 -> 0.14511239 | J24: =J19/J6 -> 0.15148333 | ... L24: =L19/L6 -> 0.16413868
A25: Valuation
A26: PV of FCF, 2026-2035 | B26: =SUM(C21:L21) -> 1516.311
A27: Terminal growth rate | B27: =Assumptions!$D$15 -> 0.03
A28: Terminal-year owner FCF x (1+g) | B28: =L19*(1+B27) -> 479.03497
A29: Terminal value — Gordon | B29: =B28/(Assumptions!$B$5-B27) -> 6387.133
A30: Terminal value — cap (20x terminal FCF) | B30: =Assumptions!$B$12*L19 -> 9301.6499
A31: Terminal value used (lower of the two) | B31: =MIN(B29,B30) -> 6387.133
A32: Implied exit multiple | B32: =B31/L19 -> 13.733333
A33: PV of terminal value | B33: =B31*L20 -> 2353.3319
A34: Enterprise value | B34: =B26+B33 -> 3869.6429
A35: add: net cash | B35: =Assumptions!$B$9 -> 1140.5
A36: Equity value | B36: =B34+B35 -> 5010.1429
A37: Fully diluted shares (mm) | B37: =Assumptions!$B$10 -> 49.8
A38: Value per share | B38: =B36/B37 -> 100.60528
A39: Upside / (downside) vs current price | B39: =B38/Assumptions!$B$11-1 -> -0.28139087
A41: Memo: value if SBC treated as non-cash (market convention) | B41: =SUMPRODUCT(-C10:L10/(1+Assumptions!$B$5)^C4:L4) -> 1395.7125 | C41: PV of 2026-35 SBC
A42: plus PV of terminal SBC | B42: =(-L10*(1+B27)/(Assumptions!$B$5-B27))*L20 -> 1433.7461
...

Sheet DCF_Bull
A1: DUOL DCF — Bull — 100M DAUs by 2028, monetization returns
A2: Owner-FCF basis: SBC fully expensed, interest income excluded, share count flat. Blue rows = per-year drivers (edit).
B3: 2025A | C3: 2026E | D3: 2027E | E3: 2028E | F3: 2029E | G3: 2030E | H3: 2031E | I3: 2032E | J3: 2033E | K3: 2034E | L3: 2035E
A4: Year index (for discounting) | B4: 0 | C4: 1 | D4: 2 | E4: 3 | F4: 4 | G4: 5 | H4: 6 | I4: 7 | J4: 8 | K4: 9 | L4: 10
A5: Revenue growth YoY | C5: 0.165 | D5: 0.17 | E5: 0.19 | F5: 0.18 | G5: 0.16 | H5: 0.14 | I5: 0.12 | J5: 0.11 | K5: 0.1 | L5: 0.09
A6: Revenue | B6: =Historical!D8 -> 1037.6 | C6: =B6*(1+C5) -> 1208.804 | D6: =C6*(1+D5) -> 1414.3007 | E6: =D6*(1+E5) -> 1683.0178 | F6: =E6*(1+F5) -> 1985.961 | G6: =F6*(1+G5) -> 2303.7148 | H6: =G6*(1+H5) -> 2626.2348 | I6: =H6*(1+I5) -> 2941.383 | J6: =I6*(1+J5) -> 3264.9352 | ... L6: =K6*(1+L5) -> 3914.6573
A7: Adj EBITDA margin | B7: =Historical!D20 -> 0.29481496 | C7: 0.26 | D7: 0.275 | E7: 0.29 | F7: 0.305 | G7: 0.32 | H7: 0.33 | I7: 0.34 | J7: 0.345 | K7: 0.35 | L7: 0.35
A8: Adjusted EBITDA | B8: =Historical!D19 -> 305.9 | C8: =C6*C7 -> 314.28904 | D8: =D6*D7 -> 388.93269 | E8: =E6*E7 -> 488.07516 | F8: =F6*F7 -> 605.71811 | G8: =G6*G7 -> 737.18873 | H8: =H6*H7 -> 866.6575 | I8: =I6*I7 -> 1000.0702 | J8: =J6*J7 -> 1126.4026 | ... L8: =L6*L7 -> 1370.13
A9: SBC (% of revenue) | B9: =Historical!D22 -> 0.14321511 | C9: 0.15 | D9: 0.135 | E9: 0.125 | F9: 0.115 | G9: 0.105 | H9: 0.1 | I9: 0.095 | J9: 0.09 | K9: 0.085 | L9: 0.08
A10: SBC (incl. equity-award taxes) | B10: =-Historical!D21 -> -148.6 | C10: =-C6*C9 -> -181.3206 | D10: =-D6*D9 -> -190.93059 | E10: =-E6*E9 -> -210.37723 | F10: =-F6*F9 -> -228.38552 | G10: =-G6*G9 -> -241.89005 | H10: =-H6*H9 -> -262.62348 | I10: =-I6*I9 -> -279.43139 | J10: =-J6*J9 -> -293.84416 | ... L10: =-L6*L9 -> -313.17258
A11: EBITDA less SBC ('owner EBITDA') | C11: =C8+C10 -> 132.96844 | D11: =D8+D10 -> 198.0021 | E11: =E8+E10 -> 277.69794 | F11: =F8+F10 -> 377.33259 | G11: =G8+G10 -> 495.29868 | H11: =H8+H10 -> 604.03401 | I11: =I8+I10 -> 720.63884 | J11: =J8+J10 -> 832.55847 | ... L11: =L8+L10 -> 1056.9575
A12: D&A | C12: =-C6*Assumptions!$B$6 -> -18.13206 | D12: =-D6*Assumptions!$B$6 -> -21.21451 | E12: =-E6*Assumptions!$B$6 -> -25.245267 | F12: =-F6*Assumptions!$B$6 -> -29.789415 | G12: =-G6*Assumptions!$B$6 -> -34.555722 | H12: =-H6*Assumptions!$B$6 -> -39.393523 | I12: =-I6*Assumptions!$B$6 -> -44.120745 | J12: =-J6*Assumptions!$B$6 -> -48.974027 | ... L12: =-L6*Assumptions!$B$6 -> -58.719859
A13: EBIT (SBC expensed) | C13: =C11+C12 -> 114.83638 | D13: =D11+D12 -> 176.78759 | E13: =E11+E12 -> 252.45267 | F13: =F11+F12 -> 347.54318 | G13: =G11+G12 -> 460.74296 | H13: =H11+H12 -> 564.64049 | I13: =I11+I12 -> 676.5181 | J13: =J11+J12 -> 783.58444 | ... L13: =L11+L12 -> 998.2376
A14: Cash tax rate (neg = benefit) | C14: -0.06 | D14: 0.08 | E14: 0.15 | F14: 0.2 | G14: 0.21 | H14: 0.21 | I14: 0.21 | J14: 0.21 | K14: 0.21 | L14: 0.21
A15: NOPAT | C15: =C13*(1-C14) -> 121.72656 | D15: =D13*(1-D14) -> 162.64458 | E15: =E13*(1-E14) -> 214.58477 | F15: =F13*(1-F14) -> 278.03454 | G15: =G13*(1-G14) -> 363.98693 | H15: =H13*(1-H14) -> 446.06599 | I15: =I13*(1-I14) -> 534.4493 | J15: =J13*(1-J14) -> 619.03171 | ... L15: =L13*(1-L14) -> 788.6077
A16: add: D&A | C16: =-C12 -> 18.13206 | D16: =-D12 -> 21.21451 | E16: =-E12 -> 25.245267 | F16: =-F12 -> 29.789415 | G16: =-G12 -> 34.555722 | H16: =-H12 -> 39.393523 | I16: =-I12 -> 44.120745 | J16: =-J12 -> 48.974027 | ... L16: =-L12 -> 58.719859
A17: less: capex + capitalized software | C17: =-C6*Assumptions!$B$7 -> -27.802492 | D17: =-D6*Assumptions!$B$7 -> -32.528916 | E17: =-E6*Assumptions!$B$7 -> -38.70941 | F17: =-F6*Assumptions!$B$7 -> -45.677103 | G17: =-G6*Assumptions!$B$7 -> -52.98544 | H17: =-H6*Assumptions!$B$7 -> -60.403401 | I17: =-I6*Assumptions!$B$7 -> -67.65181 | J17: =-J6*Assumptions!$B$7 -> -75.093509 | ... L17: =-L6*Assumptions!$B$7 -> -90.037117
A18: add: working capital (deferred-rev tailwind) | C18: =Assumptions!$B$8*(C6-B6) -> 30.81672 | D18: =Assumptions!$B$8*(D6-C6) -> 36.989402 | E18: =Assumptions!$B$8*(E6-D6) -> 48.369083 | F18: =Assumptions!$B$8*(F6-E6) -> 54.529777 | G18: =Assumptions!$B$8*(G6-F6) -> 57.195677 | H18: =Assumptions!$B$8*(H6-G6) -> 58.053612 | I18: =Assumptions!$B$8*(I6-H6) -> 56.726673 | J18: =Assumptions!$B$8*(J6-I6) -> 58.239384 | ... L18: =Assumptions!$B$8*(L6-K6) -> 58.181145
A19: Unlevered owner FCF | C19: =C15+C16+C17+C18 -> 142.87285 | D19: =D15+D16+D17+D18 -> 188.31958 | E19: =E15+E16+E17+E18 -> 249.48971 | F19: =F15+F16+F17+F18 -> 316.67663 | G19: =G15+G16+G17+G18 -> 402.75289 | H19: =H15+H16+H17+H18 -> 483.10972 | I19: =I15+I16+I17+I18 -> 567.6449 | J19: =J15+J16+J17+J18 -> 651.15161 | ... L19: =L15+L16+L17+L18 -> 815.47159
A20: Discount factor | C20: =1/(1+Assumptions!$B$5)^C4 -> 0.90497738 | D20: =1/(1+Assumptions!$B$5)^D4 -> 0.81898405 | E20: =1/(1+Assumptions!$B$5)^E4 -> 0.74116204 | F20: =1/(1+Assumptions!$B$5)^F4 -> 0.67073487 | G20: =1/(1+Assumptions!$B$5)^G4 -> 0.60699989 | H20: =1/(1+Assumptions!$B$5)^H4 -> 0.54932116 | I20: =1/(1+Assumptions!$B$5)^I4 -> 0.49712323 | J20: =1/(1+Assumptions!$B$5)^J4 -> 0.44988527 | ... L20: =1/(1+Assumptions!$B$5)^L4 -> 0.36844886
A21: PV of FCF | C21: =C19*C20 -> 129.2967 | D21: =D19*D20 -> 154.23073 | E21: =E19*E20 -> 184.9123 | F21: =F19*F20 -> 212.40606 | G21: =G19*G20 -> 244.47096 | H21: =H19*H20 -> 265.3824 | I21: =I19*I20 -> 282.18947 | J21: =J19*J20 -> 292.94352 | ... L21: =L19*L20 -> 300.45958
A23: Memo: FCF before SBC (company-style) | C23: =C19-C10 -> 324.19345 | D23: =D19-D10 -> 379.25017 | E23: =E19-E10 -> 459.86694 | F23: =F19-F10 -> 545.06215 | G23: =G19-G10 -> 644.64295 | H23: =H19-H10 -> 745.73321 | I23: =I19-I10 -> 847.07629 | J23: =J19-J10 -> 944.99577 | ... L23: =L19-L10 -> 1128.6442
A24: Memo: implied owner FCF margin | C24: =C19/C6 -> 0.11819356 | D24: =D19/D6 -> 0.13315385 | E24: =E19/E6 -> 0.1482395 | F24: =F19/F6 -> 0.15945763 | G24: =G19/G6 -> 0.17482759 | H24: =H19/H6 -> 0.18395526 | I24: =I19/I6 -> 0.19298571 | J24: =J19/J6 -> 0.19943784 | ... L24: =L19/L6 -> 0.20831239
A25: Valuation
A26: PV of FCF, 2026-2035 | B26: =SUM(C21:L21) -> 2367.3055
A27: Terminal growth rate | B27: =Assumptions!$E$15 -> 0.035
A28: Terminal-year owner FCF x (1+g) | B28: =L19*(1+B27) -> 844.0131
A29: Terminal value — Gordon | B29: =B28/(Assumptions!$B$5-B27) -> 12057.33
A30: Terminal value — cap (20x terminal FCF) | B30: =Assumptions!$B$12*L19 -> 16309.432
A31: Terminal value used (lower of the two) | B31: =MIN(B29,B30) -> 12057.33
A32: Implied exit multiple | B32: =B31/L19 -> 14.785714
A33: PV of terminal value | B33: =B31*L20 -> 4442.5095
A34: Enterprise value | B34: =B26+B33 -> 6809.815
A35: add: net cash | B35: =Assumptions!$B$9 -> 1140.5
A36: Equity value | B36: =B34+B35 -> 7950.315
A37: Fully diluted shares (mm) | B37: =Assumptions!$B$10 -> 49.8
A38: Value per share | B38: =B36/B37 -> 159.64488
A39: Upside / (downside) vs current price | B39: =B38/Assumptions!$B$11-1 -> 0.14032057
A41: Memo: value if SBC treated as non-cash (market convention) | B41: =SUMPRODUCT(-C10:L10/(1+Assumptions!$B$5)^C4:L4) -> 1431.4448 | C41: PV of 2026-35 SBC
A42: plus PV of terminal SBC | B42: =(-L10*(1+B27)/(Assumptions!$B$5-B27))*L20 -> 1706.0952
...

Sheet Valuation
A1: DUOL — Valuation Summary & Sensitivity
A2: All per-share values on the owner-FCF basis (SBC expensed). Green = links to scenario sheets.
B4: Bear | C4: Base | D4: Bull
A5: Value per share | B5: =DCF_Bear!B38 -> 43.247776 | C5: =DCF_Base!B38 -> 100.60528 | D5: =DCF_Bull!B38 -> 159.64488
A6: Upside / (downside) vs price | B6: =DCF_Bear!B39 -> -0.69108732 | C6: =DCF_Base!B39 -> -0.28139087 | D6: =DCF_Bull!B39 -> 0.14032057
A7: Probability | B7: =Assumptions!C16 -> 0.25 | C7: =Assumptions!D16 -> 0.5 | D7: =Assumptions!E16 -> 0.25
A8: Value per share, SBC as non-cash | B8: =DCF_Bear!B43 -> 83.487827 | C8: =DCF_Base!B43 -> 157.42172 | D8: =DCF_Bull!B43 -> 222.64769
A10: Probability-weighted value per share | B10: =SUMPRODUCT(B5:D5,B7:D7) -> 101.0258
A11: Current price | B11: =Assumptions!B11 -> 140
A12: Margin of safety vs weighted value | B12: =B10/B11-1 -> -0.27838712
A13: Weighted value, SBC as non-cash | B13: =SUMPRODUCT(B8:D8,B7:D7) -> 155.24474
A16: Base case — value per share at different required returns
A17: Required return | B17: Value / share
A18: 0.09 | B18: =(SUMPRODUCT(DCF_Base!$C$19:$L$19/(1+$A18)^DCF_Base!$C$4:$L$4)+MIN(DCF_Base!$L$19*(1+Assumptions!$D$15)/($A18-Assumptions!$D$15),Assumptions!$B$12*DCF_Base!$L$19)/(1+$A18)^10+Assumptions!$B$9)/Assumptions!$B$10 -> 123.63018
A19: 0.1 | B19: =(SUMPRODUCT(DCF_Base!$C$19:$L$19/(1+$A19)^DCF_Base!$C$4:$L$4)+MIN(DCF_Base!$L$19*(1+Assumptions!$D$15)/($A19-Assumptions!$D$15),Assumptions!$B$12*DCF_Base!$L$19)/(1+$A19)^10+Assumptions!$B$9)/Assumptions!$B$10 -> 107.15123
A20: 0.105 | B20: =(SUMPRODUCT(DCF_Base!$C$19:$L$19/(1+$A20)^DCF_Base!$C$4:$L$4)+MIN(DCF_Base!$L$19*(1+Assumptions!$D$15)/($A20-Assumptions!$D$15),Assumptions!$B$12*DCF_Base!$L$19)/(1+$A20)^10+Assumptions!$B$9)/Assumptions!$B$10 -> 100.60528
A21: 0.11 | B21: =(SUMPRODUCT(DCF_Base!$C$19:$L$19/(1+$A21)^DCF_Base!$C$4:$L$4)+MIN(DCF_Base!$L$19*(1+Assumptions!$D$15)/($A21-Assumptions!$D$15),Assumptions!$B$12*DCF_Base!$L$19)/(1+$A21)^10+Assumptions!$B$9)/Assumptions!$B$10 -> 94.904629
A22: 0.12 | B22: =(SUMPRODUCT(DCF_Base!$C$19:$L$19/(1+$A22)^DCF_Base!$C$4:$L$4)+MIN(DCF_Base!$L$19*(1+Assumptions!$D$15)/($A22-Assumptions!$D$15),Assumptions!$B$12*DCF_Base!$L$19)/(1+$A22)^10+Assumptions!$B$9)/Assumptions!$B$10 -> 85.47206
A23: 0.15 | B23: =(SUMPRODUCT(DCF_Base!$C$19:$L$19/(1+$A23)^DCF_Base!$C$4:$L$4)+MIN(DCF_Base!$L$19*(1+Assumptions!$D$15)/($A23-Assumptions!$D$15),Assumptions!$B$12*DCF_Base!$L$19)/(1+$A23)^10+Assumptions!$B$9)/Assumptions!$B$10 -> 66.974009 | C23: 15% required-return entry price
A26: Base case — value per share: WACC x terminal growth
A27: WACC \ g | B27: 0.02 | C27: 0.025 | D27: 0.03 | E27: 0.035 | F27: 0.04
A28: 0.095 | B28: =(SUMPRODUCT(DCF_Base!$C$19:$L$19/(1+$A28)^DCF_Base!$C$4:$L$4)+MIN(DCF_Base!$L$19*(1+B$27)/($A28-B$27),Assumptions!$B$12*DCF_Base!$L$19)/(1+$A28)^10+Assumptions!$B$9)/Assumptions!$B$10 -> 106.27443 | C28: =(SUMPRODUCT(DCF_Base!$C$19:$L$19/(1+$A28)^DCF_Base!$C$4:$L$4)+MIN(DCF_Base!$L$19*(1+C$27)/($A28-C$27),Assumptions!$B$12*DCF_Base!$L$19)/(1+$A28)^10+Assumptions!$B$9)/Assumptions!$B$10 -> 110.20436 | D28: =(SUMPRODUCT(DCF_Base!$C$19:$L$19/(1+$A28)^DCF_Base!$C$4:$L$4)+MIN(DCF_Base!$L$19*(1+D$27)/($A28-D$27),Assumptions!$B$12*DCF_Base!$L$19)/(1+$A28)^10+Assumptions!$B$9)/Assumptions!$B$10 -> 114.73889 | E28: =(SUMPRODUCT(DCF_Base!$C$19:$L$19/(1+$A28)^DCF_Base!$C$4:$L$4)+MIN(DCF_Base!$L$19*(1+E$27)/($A28-E$27),Assumptions!$B$12*DCF_Base!$L$19)/(1+$A28)^10+Assumptions!$B$9)/Assumptions!$B$10 -> 120.02917 | F28: =(SUMPRODUCT(DCF_Base!$C$19:$L$19/(1+$A28)^DCF_Base!$C$4:$L$4)+MIN(DCF_Base!$L$19*(1+F$27)/($A28-F$27),Assumptions!$B$12*DCF_Base!$L$19)/(1+$A28)^10+Assumptions!$B$9)/Assumptions!$B$10 -> 126.28132
A29: 0.1 | B29: =(SUMPRODUCT(DCF_Base!$C$19:$L$19/(1+$A29)^DCF_Base!$C$4:$L$4)+MIN(DCF_Base!$L$19*(1+B$27)/($A29-B$27),Assumptions!$B$12*DCF_Base!$L$19)/(1+$A29)^10+Assumptions!$B$9)/Assumptions!$B$10 -> 100.07864 | C29: =(SUMPRODUCT(DCF_Base!$C$19:$L$19/(1+$A29)^DCF_Base!$C$4:$L$4)+MIN(DCF_Base!$L$19*(1+C$27)/($A29-C$27),Assumptions!$B$12*DCF_Base!$L$19)/(1+$A29)^10+Assumptions!$B$9)/Assumptions!$B$10 -> 103.37918 | D29: =(SUMPRODUCT(DCF_Base!$C$19:$L$19/(1+$A29)^DCF_Base!$C$4:$L$4)+MIN(DCF_Base!$L$19*(1+D$27)/($A29-D$27),Assumptions!$B$12*DCF_Base!$L$19)/(1+$A29)^10+Assumptions!$B$9)/Assumptions!$B$10 -> 107.15123 | E29: =(SUMPRODUCT(DCF_Base!$C$19:$L$19/(1+$A29)^DCF_Base!$C$4:$L$4)+MIN(DCF_Base!$L$19*(1+E$27)/($A29-E$27),Assumptions!$B$12*DCF_Base!$L$19)/(1+$A29)^10+Assumptions!$B$9)/Assumptions!$B$10 -> 111.50359 | F29: =(SUMPRODUCT(DCF_Base!$C$19:$L$19/(1+$A29)^DCF_Base!$C$4:$L$4)+MIN(DCF_Base!$L$19*(1+F$27)/($A29-F$27),Assumptions!$B$12*DCF_Base!$L$19)/(1+$A29)^10+Assumptions!$B$9)/Assumptions!$B$10 -> 116.58135
A30: 0.105 | B30: =(SUMPRODUCT(DCF_Base!$C$19:$L$19/(1+$A30)^DCF_Base!$C$4:$L$4)+MIN(DCF_Base!$L$19*(1+B$27)/($A30-B$27),Assumptions!$B$12*DCF_Base!$L$19)/(1+$A30)^10+Assumptions!$B$9)/Assumptions!$B$10 -> 94.640972 | C30: =(SUMPRODUCT(DCF_Base!$C$19:$L$19/(1+$A30)^DCF_Base!$C$4:$L$4)+MIN(DCF_Base!$L$19*(1+C$27)/($A30-C$27),Assumptions!$B$12*DCF_Base!$L$19)/(1+$A30)^10+Assumptions!$B$9)/Assumptions!$B$10 -> 97.436741 | D30: =(SUMPRODUCT(DCF_Base!$C$19:$L$19/(1+$A30)^DCF_Base!$C$4:$L$4)+MIN(DCF_Base!$L$19*(1+D$27)/($A30-D$27),Assumptions!$B$12*DCF_Base!$L$19)/(1+$A30)^10+Assumptions!$B$9)/Assumptions!$B$10 -> 100.60528 | E30: =(SUMPRODUCT(DCF_Base!$C$19:$L$19/(1+$A30)^DCF_Base!$C$4:$L$4)+MIN(DCF_Base!$L$19*(1+E$27)/($A30-E$27),Assumptions!$B$12*DCF_Base!$L$19)/(1+$A30)^10+Assumptions!$B$9)/Assumptions!$B$10 -> 104.22646 | F30: =(SUMPRODUCT(DCF_Base!$C$19:$L$19/(1+$A30)^DCF_Base!$C$4:$L$4)+MIN(DCF_Base!$L$19*(1+F$27)/($A30-F$27),Assumptions!$B$12*DCF_Base!$L$19)/(1+$A30)^10+Assumptions!$B$9)/Assumptions!$B$10 -> 108.40476
A31: 0.11 | B31: =(SUMPRODUCT(DCF_Base!$C$19:$L$19/(1+$A31)^DCF_Base!$C$4:$L$4)+MIN(DCF_Base!$L$19*(1+B$27)/($A31-B$27),Assumptions!$B$12*DCF_Base!$L$19)/(1+$A31)^10+Assumptions!$B$9)/Assumptions!$B$10 -> 89.834006 | C31: =(SUMPRODUCT(DCF_Base!$C$19:$L$19/(1+$A31)^DCF_Base!$C$4:$L$4)+MIN(DCF_Base!$L$19*(1+C$27)/($A31-C$27),Assumptions!$B$12*DCF_Base!$L$19)/(1+$A31)^10+Assumptions!$B$9)/Assumptions!$B$10 -> 92.220182 | D31: =(SUMPRODUCT(DCF_Base!$C$19:$L$19/(1+$A31)^DCF_Base!$C$4:$L$4)+MIN(DCF_Base!$L$19*(1+D$27)/($A31-D$27),Assumptions!$B$12*DCF_Base!$L$19)/(1+$A31)^10+Assumptions!$B$9)/Assumptions!$B$10 -> 94.904629 | E31: =(SUMPRODUCT(DCF_Base!$C$19:$L$19/(1+$A31)^DCF_Base!$C$4:$L$4)+MIN(DCF_Base!$L$19*(1+E$27)/($A31-E$27),Assumptions!$B$12*DCF_Base!$L$19)/(1+$A31)^10+Assumptions!$B$9)/Assumptions!$B$10 -> 97.947003 | F31: =(SUMPRODUCT(DCF_Base!$C$19:$L$19/(1+$A31)^DCF_Base!$C$4:$L$4)+MIN(DCF_Base!$L$19*(1+F$27)/($A31-F$27),Assumptions!$B$12*DCF_Base!$L$19)/(1+$A31)^10+Assumptions!$B$9)/Assumptions!$B$10 -> 101.424
A32: 0.115 | B32: =(SUMPRODUCT(DCF_Base!$C$19:$L$19/(1+$A32)^DCF_Base!$C$4:$L$4)+MIN(DCF_Base!$L$19*(1+B$27)/($A32-B$27),Assumptions!$B$12*DCF_Base!$L$19)/(1+$A32)^10+Assumptions!$B$9)/Assumptions!$B$10 -> 85.557191 | C32: =(SUMPRODUCT(DCF_Base!$C$19:$L$19/(1+$A32)^DCF_Base!$C$4:$L$4)+MIN(DCF_Base!$L$19*(1+C$27)/($A32-C$27),Assumptions!$B$12*DCF_Base!$L$19)/(1+$A32)^10+Assumptions!$B$9)/Assumptions!$B$10 -> 87.607554 | D32: =(SUMPRODUCT(DCF_Base!$C$19:$L$19/(1+$A32)^DCF_Base!$C$4:$L$4)+MIN(DCF_Base!$L$19*(1+D$27)/($A32-D$27),Assumptions!$B$12*DCF_Base!$L$19)/(1+$A32)^10+Assumptions!$B$9)/Assumptions!$B$10 -> 89.899136 | E32: =(SUMPRODUCT(DCF_Base!$C$19:$L$19/(1+$A32)^DCF_Base!$C$4:$L$4)+MIN(DCF_Base!$L$19*(1+E$27)/($A32-E$27),Assumptions!$B$12*DCF_Base!$L$19)/(1+$A32)^10+Assumptions!$B$9)/Assumptions!$B$10 -> 92.477166 | F32: =(SUMPRODUCT(DCF_Base!$C$19:$L$19/(1+$A32)^DCF_Base!$C$4:$L$4)+MIN(DCF_Base!$L$19*(1+F$27)/($A32-F$27),Assumptions!$B$12*DCF_Base!$L$19)/(1+$A32)^10+Assumptions!$B$9)/Assumptions!$B$10 -> 95.398933
A35: Base case — value per share: 2035 owner-FCF margin x WACC (terminal g = 3.0%)
A36: FCF mgn \ WACC | B36: 0.095 | C36: 0.105 | D36: 0.115
A37: 0.1 | B37: =(SUMPRODUCT(DCF_Base!$C$19:$L$19/(1+B$36)^DCF_Base!$C$4:$L$4)+MIN($A37*DCF_Base!$L$6*(1+Assumptions!$D$15)/(B$36-Assumptions!$D$15),Assumptions!$B$12*$A37*DCF_Base!$L$6)/(1+B$36)^10+Assumptions!$B$9)/Assumptions!$B$10 -> 91.404713 | C37: =(SUMPRODUCT(DCF_Base!$C$19:$L$19/(1+C$36)^DCF_Base!$C$4:$L$4)+MIN($A37*DCF_Base!$L$6*(1+Assumptions!$D$15)/(C$36-Assumptions!$D$15),Assumptions!$B$12*$A37*DCF_Base!$L$6)/(1+C$36)^10+Assumptions!$B$9)/Assumptions!$B$10 -> 82.1397 | D37: =(SUMPRODUCT(DCF_Base!$C$19:$L$19/(1+D$36)^DCF_Base!$C$4:$L$4)+MIN($A37*DCF_Base!$L$6*(1+Assumptions!$D$15)/(D$36-Assumptions!$D$15),Assumptions!$B$12*$A37*DCF_Base!$L$6)/(1+D$36)^10+Assumptions!$B$9)/Assumptions!$B$10 -> 75.009662
A38: 0.13 | B38: =(SUMPRODUCT(DCF_Base!$C$19:$L$19/(1+B$36)^DCF_Base!$C$4:$L$4)+MIN($A38*DCF_Base!$L$6*(1+Assumptions!$D$15)/(B$36-Assumptions!$D$15),Assumptions!$B$12*$A38*DCF_Base!$L$6)/(1+B$36)^10+Assumptions!$B$9)/Assumptions!$B$10 -> 102.31896 | C38: =(SUMPRODUCT(DCF_Base!$C$19:$L$19/(1+C$36)^DCF_Base!$C$4:$L$4)+MIN($A38*DCF_Base!$L$6*(1+Assumptions!$D$15)/(C$36-Assumptions!$D$15),Assumptions!$B$12*$A38*DCF_Base!$L$6)/(1+C$36)^10+Assumptions!$B$9)/Assumptions!$B$10 -> 90.776725 | D38: =(SUMPRODUCT(DCF_Base!$C$19:$L$19/(1+D$36)^DCF_Base!$C$4:$L$4)+MIN($A38*DCF_Base!$L$6*(1+Assumptions!$D$15)/(D$36-Assumptions!$D$15),Assumptions!$B$12*$A38*DCF_Base!$L$6)/(1+D$36)^10+Assumptions!$B$9)/Assumptions!$B$10 -> 81.974012
A39: 0.16 | B39: =(SUMPRODUCT(DCF_Base!$C$19:$L$19/(1+B$36)^DCF_Base!$C$4:$L$4)+MIN($A39*DCF_Base!$L$6*(1+Assumptions!$D$15)/(B$36-Assumptions!$D$15),Assumptions!$B$12*$A39*DCF_Base!$L$6)/(1+B$36)^10+Assumptions!$B$9)/Assumptions!$B$10 -> 113.2332 | C39: =(SUMPRODUCT(DCF_Base!$C$19:$L$19/(1+C$36)^DCF_Base!$C$4:$L$4)+MIN($A39*DCF_Base!$L$6*(1+Assumptions!$D$15)/(C$36-Assumptions!$D$15),Assumptions!$B$12*$A39*DCF_Base!$L$6)/(1+C$36)^10+Assumptions!$B$9)/Assumptions!$B$10 -> 99.413749 | D39: =(SUMPRODUCT(DCF_Base!$C$19:$L$19/(1+D$36)^DCF_Base!$C$4:$L$4)+MIN($A39*DCF_Base!$L$6*(1+Assumptions!$D$15)/(D$36-Assumptions!$D$15),Assumptions!$B$12*$A39*DCF_Base!$L$6)/(1+D$36)^10+Assumptions!$B$9)/Assumptions!$B$10 -> 88.938362
A40: 0.19 | B40: =(SUMPRODUCT(DCF_Base!$C$19:$L$19/(1+B$36)^DCF_Base!$C$4:$L$4)+MIN($A40*DCF_Base!$L$6*(1+Assumptions!$D$15)/(B$36-Assumptions!$D$15),Assumptions!$B$12*$A40*DCF_Base!$L$6)/(1+B$36)^10+Assumptions!$B$9)/Assumptions!$B$10 -> 124.14744 | C40: =(SUMPRODUCT(DCF_Base!$C$19:$L$19/(1+C$36)^DCF_Base!$C$4:$L$4)+MIN($A40*DCF_Base!$L$6*(1+Assumptions!$D$15)/(C$36-Assumptions!$D$15),Assumptions!$B$12*$A40*DCF_Base!$L$6)/(1+C$36)^10+Assumptions!$B$9)/Assumptions!$B$10 -> 108.05077 | D40: =(SUMPRODUCT(DCF_Base!$C$19:$L$19/(1+D$36)^DCF_Base!$C$4:$L$4)+MIN($A40*DCF_Base!$L$6*(1+Assumptions!$D$15)/(D$36-Assumptions!$D$15),Assumptions!$B$12*$A40*DCF_Base!$L$6)/(1+D$36)^10+Assumptions!$B$9)/Assumptions!$B$10 -> 95.902712
A41: 0.22 | B41: =(SUMPRODUCT(DCF_Base!$C$19:$L$19/(1+B$36)^DCF_Base!$C$4:$L$4)+MIN($A41*DCF_Base!$L$6*(1+Assumptions!$D$15)/(B$36-Assumptions!$D$15),Assumptions!$B$12*$A41*DCF_Base!$L$6)/(1+B$36)^10+Assumptions!$B$9)/Assumptions!$B$10 -> 135.06169 | C41: =(SUMPRODUCT(DCF_Base!$C$19:$L$19/(1+C$36)^DCF_Base!$C$4:$L$4)+MIN($A41*DCF_Base!$L$6*(1+Assumptions!$D$15)/(C$36-Assumptions!$D$15),Assumptions!$B$12*$A41*DCF_Base!$L$6)/(1+C$36)^10+Assumptions!$B$9)/Assumptions!$B$10 -> 116.6878 | D41: =(SUMPRODUCT(DCF_Base!$C$19:$L$19/(1+D$36)^DCF_Base!$C$4:$L$4)+MIN($A41*DCF_Base!$L$6*(1+Assumptions!$D$15)/(D$36-Assumptions!$D$15),Assumptions!$B$12*$A41*DCF_Base!$L$6)/(1+D$36)^10+Assumptions!$B$9)/Assumptions!$B$10 -> 102.86706
A43: Base case reaches a ~16% owner-FCF margin by 2035 (see DCF_Base row 24). The 2026 starting point is ~11%.

Sheet Model_Info
A1: Model Provenance & Maintenance Notes
A2: Embedded so that a future session (human or AI) can pick this file up with full context.
A4: Who built this
A5: • Prepared by Claude Fable 5, an AI assistant made by Anthropic, via the claude.ai chat interface, on 29 July 2026, at Stephen's request.
A6: • Built programmatically in Python (openpyxl); all ~650 formulas recalculated in LibreOffice and verified error-free. Key outputs were cross-checked against independent hand calculations before delivery.
A7: • File version 1.3 (v1.0 initial build 29-Jul-26; v1.1 adds this tab; v1.2 refreshes the share price to $140.00 user-supplied; v1.3 adds the Quarterly_Data tab from Stephen's DUOL_Metrics.csv upload — includes a DAU-monetization decomposition and notes where the CSV's 2024 figures diverge from the 8-K).
A9: Data vintage — check before reusing
A10: • Share price $140.00 as of 29-Jul-26 (user-supplied; the original build used the $132.82 close of 27-Jul-26). FY2024/FY2025 financials: Duolingo Q4/FY2025 shareholder letter, 8-K filed 26-Feb-26 (SEC EDGAR). Q1-2026 actuals and FY26 guidance: Q1 2026 shareholder letter and earnings call (May-26).
A11: • FY26 guidance used: revenue ~$1,205mm (+16.1%), bookings ~$1,280mm (+10.5%), Adj EBITDA ~$310mm (25.7%), FCF >$350mm, SBC ~15% of revenue, ~6% effective tax benefit.
A12: • All figures were sourced by live web search on 29-Jul-26. IMPORTANT: Q2 2026 results are due 5-Aug-26 and will partially supersede this file.
A14: Methodology choices (so you don't have to reverse-engineer them)
A15: • Owner-FCF basis: SBC (incl. equity-award taxes) fully expensed; interest income excluded (the cash pile is added separately); diluted shares held FLAT at 49.8mm because the $400mm buyback offsets grant dilution — do not also grow the share count, that double-counts.
... A26: • If this workbook is re-uploaded to a later conversation: treat everything above as a snapshot dated 29-Jul-26. Verify the price, latest quarter, guidance, and share count before drawing conclusions. The scenario drivers reflect judgment calls made with Stephen's value-investing framework (owner earnings, margin of safety, probability-weighted scenarios) — they are inputs to challenge, not facts.
