Workbook

Sheet Model_Info
A1: DUOLINGO (DUOL) - DCF, v2.0
A3: Lineage | B3: v2.0, 6 Aug 2026 NZT. Direct successor to DUOL_FCF_Model_Jul2026.xlsx v1.8 (29 Jul 2026): same engine, Q2 FY26 anchors. SUPERSEDES the interim 6-Aug rebuild (DUOL_DCF_Q2FY26.xlsx), which contained two methodology errors vs the July engine - see Reconciliation tab. Built by Claude (Fable 5) with Stephen via claude.ai; openpyxl; all formulas recalculated in LibreOffice, key outputs hand-checked.
A5: DATA VINTAGE
A6: Q2 FY26 actuals & guidance | B6: Q2 2026 shareholder letter + press release, 5 Aug 2026, Form 8-K (SEC EDGAR accession 0001628280-26-053299). FY26 guide: revenue ~$1,207mm (+16.3%), bookings ~$1,285mm (+10.9%), Adj EBITDA ~$320mm (26.5%, raised ~1pt), SBC ~15% of revenue, GAAP tax rate 23-25% (cash taxes still DTA-sheltered).
A7: FY25 anchors | B7: Revenue $1,037.6mm, Adj EBITDA margin 29.5%, SBC 14.3% of revenue - carried from July file's Historical tab (Q4/FY25 shareholder letter, 8-K 26-Feb-26).
A8: Balance sheet / shares / price | B8: Net cash $1,313.9mm (cash $1,180.9 + ST inv $133.0, 30-Jun-26). Diluted shares 50.7mm (letter table; July's 49.8mm was the pre-Q2 count). Price $119.70 = user-supplied after-hours print ~9am 6-Aug NZT; session swung +7% to -11% post-release - replace with the next regular close.
A10: METHODOLOGY (unchanged from v1.8)
A11: Owner-FCF basis | B11: SBC (incl. equity-award taxes) fully expensed; INTEREST INCOME EXCLUDED from flows (the cash pile is added separately - including both double-counts); cash tax ramps from the guided ~6% 2026 benefit (DTA shelter) to a 21% normalized rate by 2029-30; D&A 1.5% and capex 2.3% of revenue; deferred-revenue working-capital tailwind = 18% of the YoY revenue increase, fading as growth slows; diluted shares held FLAT (SBC expensed substitutes for grant dilution; buyback offsets). TV = Gordon, capped at 20x terminal owner FCF. End-of-year discounting. WACC 10.5%. Each DCF tab also shows the street-convention value (SBC as non-cash) - the house/street pair is the accounting-regime price band.
A12: Scenarios | B12: Bear/Base/Bull 15/50/35 (Stephen, 29-Jul-26). Terminal growth 1.5/3.0/3.5%. Driver rows (blue: 5, 7, 9, 14 on each DCF tab) carry the July judgment paths; only 2026 columns were updated to the post-Q2 guide, with two small documented tweaks (bear 2026 revenue/margin can no longer undo the H1 already banked; bull 2026 margin follows the beat). 2027+ paths deliberately NOT re-judged - the print's cross-currents (DAU +23% accel vs bookings +8%) argue in opposite directions; revisit after the call transcript.
A14: UPDATE INSTRUCTIONS
A15: Each quarter | B15: Refresh price (Assumptions B11), net cash (B9), shares (B10, check buyback pace vs $400mm - $71.9mm used through 1-Aug), 2026 driver columns vs guidance, and reassess blue rows 5/7/9/14 per scenario. Valuation, hurdle prices, and sensitivities recalculate.
A16: Conventions | B16: Blue = hardcoded input. Yellow = key levers. Black = formula. Green = cross-sheet link. Prefilled values are working examples of the expected format.

Sheet Reconciliation
A1: RECONCILIATION - July v1.8 vs 6-Aug interim rebuild vs v2.0
A3: Per-share values (owner-FCF / house basis)
A4: Model | B4: Bear | C4: Base | D4: Bull | E4: Weighted | F4: Notes
A5: July v1.8 (29-Jul, at $140, pre-Q2 anchors) | B5: 43.25 | C5: 100.61 | D5: 159.64 | E5: 112.67 | F5: Weights 15/50/35; WACC 10.5%; net cash $1,140.5; shares 49.8; MoS at $140 was -19.5% (price above value).
A6: 6-Aug interim rebuild (SUPERSEDED) | B6: 74.86 | C6: 140.82 | D6: 212.83 | E6: 156.13 | F6: Two errors vs the July engine: (1) valued reported FCF including ~$47mm/yr interest income AND added the cash pile - double count worth roughly $12-15/share; (2) no cash-tax normalization - perpetuated the temporary DTA shelter instead of ramping to 21%, inflating mature-year margins (22% vs ~16% base terminal owner margin). Also WACC 10.0% vs 10.5% and bear terminal 2.5% vs 1.5%. Revenue paths were NOT the driver - base CAGR ~10% in both.
A7: v2.0 (this file: July engine + Q2 anchors) | B7: =DCF_Bear!$B$38 -> 46.444552 | C7: =DCF_Base!$B$38 -> 102.60505 | D7: =DCF_Bull!$B$38 -> 160.45978 | E7: =Valuation!$B$10 -> 114.43013 | F7: Anchor updates vs v1.8: net cash +$173mm (30-Jun), shares 49.8 -> 50.7, 2026 revenue growth 16.1% -> 16.3%, 2026 EBITDA margin to the raised 26.5% guide (bear 26.0 / bull 27.0), price $119.70. 2027+ driver judgments unchanged from July pending the call transcript.
A9: Street basis (SBC as non-cash), v2.0 | B9: =DCF_Bear!$B$43 -> 86.313985 | C9: =DCF_Base!$B$43 -> 158.50905 | D9: =DCF_Bull!$B$43 -> 222.3442 | E9: =Valuation!$B$13 -> 170.02209
A11: Bridge, interim rebuild -> v2.0 base case (approximate, $/share)
A12: Interim rebuild base | B12: 140.82 | F12: As delivered this morning
A13: Exclude interest income from flows | B13: -13.5 | F13: Ends the cash-pile double count (July methodology)
A14: Cash-tax ramp to 21% by 2029-30 | B14: -19 | F14: Ends the perpetual DTA shelter; hits mature-year flows and TV hardest
A15: WACC 10.0% -> 10.5% | B15: -7.5
A16: Engine detail (WC tailwind, D&A/capex split, TV cap) | B16: 1.5 | F16: Net small
A17: v2.0 base case | B17: 102.3 | F17: Ties to DCF_Base!B38 (live)
A19: Bridge figures are static estimates for orientation; the live numbers above are authoritative.

Sheet Assumptions
A1: DUOL - Global Assumptions & Scenario Parameters (v2.0)
A2: Blue = hardcoded input. Yellow = key levers. All $ in millions unless stated.
A4: Global inputs
A5: WACC / discount rate | B5: 0.105 | H5: July v1.8 value, unchanged
A6: D&A (% of revenue) | B6: 0.015
A7: Capex + capitalized software (% of revenue) | B7: 0.023
A8: Working-capital capture (% of YoY revenue incr.) | B8: 0.18 | H8: Deferred-revenue tailwind; fades as growth slows
A9: Net cash: cash + ST investments, 30-Jun-26 ($mm) | B9: 1313.9 | H9: Was $1,140.5 (31-Dec-25) in v1.8
A10: Fully diluted shares (mm) | B10: 50.7 | H10: Q2 letter table; was 49.8 in v1.8
A11: Current share price (after-hours 5-Aug US ET) | B11: 119.7 | H11: User-supplied; volatile tape - refresh at next close
A12: Terminal value cap (x terminal-year owner FCF) | B12: 20
A14: Scenario parameters | C14: Bear | D14: Base | E14: Bull
A15: Terminal growth rate | C15: 0.015 | D15: 0.03 | E15: 0.035
A16: Probability weight | C16: 0.15 | D16: 0.5 | E16: 0.35 | F16: =SUM(C16:E16) -> 1 | G16: must sum to 100%
A18: Scenario narratives (post-Q2 print)
A19: Bear | B19: AI erosion is real: assistants absorb casual practice; the user-growth pivot delivers DAUs but never bookings - Q2's users +23% / bookings +8% split becomes permanent. Revenue fades to ~1-2% by 2034-35; EBITDA ~23-24%; SBC stays 13-14.5%.
A20: Base | B20: Pivot partially works: ~20%+ DAU growth compounds (Q2 confirmed acceleration), monetization re-engages 2027-28 (free-trial cohorts convert, Video Call in Super, ads). Revenue ~10% CAGR to 2035; EBITDA 26.5% -> 32%; SBC fades to 10%.
A21: Bull | B21: 100M DAU by 2028 on track (Q2's 23% = the required run-rate); ~20% bookings capability returns 2027-29; Chess/Math/Music second engines; EBITDA to 35%; SBC disciplined to 8%.

Sheet DCF_Bear
A1: DUOL DCF - Bear - AI erosion; DAUs without bookings
A2: Owner-FCF basis: SBC fully expensed, interest income excluded, share count flat. Blue rows = per-year drivers (edit).
B3: 2025A | C3: 2026E | D3: 2027E | E3: 2028E | F3: 2029E | G3: 2030E | H3: 2031E | I3: 2032E | J3: 2033E | K3: 2034E | L3: 2035E
A4: Year index (for discounting) | B4: 0 | C4: 1 | D4: 2 | E4: 3 | F4: 4 | G4: 5 | H4: 6 | I4: 7 | J4: 8 | K4: 9 | L4: 10
A5: Revenue growth YoY | C5: 0.16 | D5: 0.07 | E5: 0.05 | F5: 0.04 | G5: 0.03 | H5: 0.03 | I5: 0.02 | J5: 0.02 | K5: 0.01 | L5: 0.01
A6: Revenue | B6: 1037.6 | C6: =B6*(1+C5) -> 1203.616 | D6: =C6*(1+D5) -> 1287.8691 | E6: =D6*(1+E5) -> 1352.2626 | F6: =E6*(1+F5) -> 1406.3531 | G6: =F6*(1+G5) -> 1448.5437 | H6: =G6*(1+H5) -> 1492 | I6: =H6*(1+I5) -> 1521.84 | J6: =I6*(1+J5) -> 1552.2768 | ... L6: =K6*(1+L5) -> 1583.4775
A7: Adj EBITDA margin | B7: 0.295 | C7: 0.26 | D7: 0.24 | E7: 0.24 | F7: 0.24 | G7: 0.24 | H7: 0.24 | I7: 0.235 | J7: 0.235 | K7: 0.23 | L7: 0.23
A8: Adjusted EBITDA | C8: =C6*C7 -> 312.94016 | D8: =D6*D7 -> 309.08859 | E8: =E6*E7 -> 324.54302 | F8: =F6*F7 -> 337.52474 | G8: =G6*G7 -> 347.65048 | H8: =H6*H7 -> 358.08 | I8: =I6*I7 -> 357.6324 | J8: =J6*J7 -> 364.78504 | ... L8: =L6*L7 -> 364.19984
A9: SBC (% of revenue) | B9: 0.143 | C9: 0.15 | D9: 0.145 | E9: 0.14 | F9: 0.14 | G9: 0.135 | H9: 0.135 | I9: 0.13 | J9: 0.13 | K9: 0.13 | L9: 0.13
A10: SBC (incl. equity-award taxes) | C10: =-C6*C9 -> -180.5424 | D10: =-D6*D9 -> -186.74102 | E10: =-E6*E9 -> -189.31676 | F10: =-F6*F9 -> -196.88943 | G10: =-G6*G9 -> -195.5534 | H10: =-H6*H9 -> -201.42 | I10: =-I6*I9 -> -197.8392 | J10: =-J6*J9 -> -201.79598 | ... L10: =-L6*L9 -> -205.85208
A11: EBITDA less SBC ('owner EBITDA') | C11: =C8+C10 -> 132.39776 | D11: =D8+D10 -> 122.34757 | E11: =E8+E10 -> 135.22626 | F11: =F8+F10 -> 140.63531 | G11: =G8+G10 -> 152.09709 | H11: =H8+H10 -> 156.66 | I11: =I8+I10 -> 159.7932 | J11: =J8+J10 -> 162.98906 | ... L11: =L8+L10 -> 158.34775
A12: D&A | C12: =-C6*Assumptions!$B$6 -> -18.05424 | D12: =-D6*Assumptions!$B$6 -> -19.318037 | E12: =-E6*Assumptions!$B$6 -> -20.283939 | F12: =-F6*Assumptions!$B$6 -> -21.095296 | G12: =-G6*Assumptions!$B$6 -> -21.728155 | H12: =-H6*Assumptions!$B$6 -> -22.38 | I12: =-I6*Assumptions!$B$6 -> -22.8276 | J12: =-J6*Assumptions!$B$6 -> -23.284152 | ... L12: =-L6*Assumptions!$B$6 -> -23.752163
A13: EBIT (SBC expensed) | C13: =C11+C12 -> 114.34352 | D13: =D11+D12 -> 103.02953 | E13: =E11+E12 -> 114.94232 | F13: =F11+F12 -> 119.54001 | G13: =G11+G12 -> 130.36893 | H13: =H11+H12 -> 134.28 | I13: =I11+I12 -> 136.9656 | J13: =J11+J12 -> 139.70491 | ... L13: =L11+L12 -> 134.59559
A14: Cash tax rate (neg = benefit) | C14: -0.06 | D14: 0.05 | E14: 0.12 | F14: 0.18 | G14: 0.21 | H14: 0.21 | I14: 0.21 | J14: 0.21 | K14: 0.21 | L14: 0.21
A15: NOPAT | C15: =C13*(1-C14) -> 121.20413 | D15: =D13*(1-D14) -> 97.878053 | E15: =E13*(1-E14) -> 101.14924 | F15: =F13*(1-F14) -> 98.02281 | G15: =G13*(1-G14) -> 102.99146 | H15: =H13*(1-H14) -> 106.0812 | I15: =I13*(1-I14) -> 108.20282 | J15: =J13*(1-J14) -> 110.36688 | ... L15: =L13*(1-L14) -> 106.33052
A16: add: D&A | C16: =-C12 -> 18.05424 | D16: =-D12 -> 19.318037 | E16: =-E12 -> 20.283939 | F16: =-F12 -> 21.095296 | G16: =-G12 -> 21.728155 | H16: =-H12 -> 22.38 | I16: =-I12 -> 22.8276 | J16: =-J12 -> 23.284152 | ... L16: =-L12 -> 23.752163
A17: less: capex + capitalized software | C17: =-C6*Assumptions!$B$7 -> -27.683168 | D17: =-D6*Assumptions!$B$7 -> -29.62099 | E17: =-E6*Assumptions!$B$7 -> -31.102039 | F17: =-F6*Assumptions!$B$7 -> -32.346121 | G17: =-G6*Assumptions!$B$7 -> -33.316504 | H17: =-H6*Assumptions!$B$7 -> -34.316 | I17: =-I6*Assumptions!$B$7 -> -35.00232 | J17: =-J6*Assumptions!$B$7 -> -35.702366 | ... L17: =-L6*Assumptions!$B$7 -> -36.419984
A18: add: working capital (deferred-rev tailwind) | C18: =Assumptions!$B$8*(C6-B6) -> 29.88288 | D18: =Assumptions!$B$8*(D6-C6) -> 15.165562 | E18: =Assumptions!$B$8*(E6-D6) -> 11.590822 | F18: =Assumptions!$B$8*(F6-E6) -> 9.7362905 | G18: =Assumptions!$B$8*(G6-F6) -> 7.5943066 | H18: =Assumptions!$B$8*(H6-G6) -> 7.8221358 | I18: =Assumptions!$B$8*(I6-H6) -> 5.3711999 | J18: =Assumptions!$B$8*(J6-I6) -> 5.4786239 | ... L18: =Assumptions!$B$8*(L6-K6) -> 2.8220392
A19: Unlevered owner FCF | C19: =C15+C16+C17+C18 -> 141.45808 | D19: =D15+D16+D17+D18 -> 102.74066 | E19: =E15+E16+E17+E18 -> 101.92196 | F19: =F15+F16+F17+F18 -> 96.508276 | G19: =G15+G16+G17+G18 -> 98.997412 | H19: =H15+H16+H17+H18 -> 101.96733 | I19: =I15+I16+I17+I18 -> 101.3993 | J19: =J15+J16+J17+J18 -> 103.42729 | ... L19: =L15+L16+L17+L18 -> 96.484736
A20: Discount factor | C20: =1/(1+Assumptions!$B$5)^C4 -> 0.90497738 | D20: =1/(1+Assumptions!$B$5)^D4 -> 0.81898405 | E20: =1/(1+Assumptions!$B$5)^E4 -> 0.74116204 | F20: =1/(1+Assumptions!$B$5)^F4 -> 0.67073487 | G20: =1/(1+Assumptions!$B$5)^G4 -> 0.60699989 | H20: =1/(1+Assumptions!$B$5)^H4 -> 0.54932116 | I20: =1/(1+Assumptions!$B$5)^I4 -> 0.49712323 | J20: =1/(1+Assumptions!$B$5)^J4 -> 0.44988527 | ... L20: =1/(1+Assumptions!$B$5)^L4 -> 0.36844886
A21: PV of FCF | C21: =C19*C20 -> 128.01636 | D21: =D19*D20 -> 84.142963 | E21: =E19*E20 -> 75.540689 | F21: =F19*F20 -> 64.731466 | G21: =G19*G20 -> 60.091418 | H21: =H19*H20 -> 56.012815 | I21: =I19*I20 -> 50.407948 | J21: =J19*J20 -> 46.530414 | ... L21: =L19*L20 -> 35.549691
A23: Memo: FCF before SBC (company-style) | C23: =C19-C10 -> 322.00048 | D23: =D19-D10 -> 289.48168 | E23: =E19-E10 -> 291.23872 | F23: =F19-F10 -> 293.39771 | G23: =G19-G10 -> 294.55081 | H23: =H19-H10 -> 303.38733 | I23: =I19-I10 -> 299.2385 | J23: =J19-J10 -> 305.22327 | ... L23: =L19-L10 -> 302.33682
A24: Memo: implied owner FCF margin | C24: =C19/C6 -> 0.11752759 | D24: =D19/D6 -> 0.079775701 | E24: =E19/E6 -> 0.075371429 | F24: =F19/F6 -> 0.068623077 | G24: =G19/G6 -> 0.068342718 | H24: =H19/H6 -> 0.068342718 | I24: =I19/I6 -> 0.066629412 | J24: =J19/J6 -> 0.066629412 | ... L24: =L19/L6 -> 0.060932178
A25: Valuation
A26: PV of FCF, 2026-2035 | B26: =SUM(C21:L21) -> 639.91724
A27: Terminal growth rate | B27: =Assumptions!$C$15 -> 0.015
A28: Terminal-year owner FCF x (1+g) | B28: =L19*(1+B27) -> 97.932007
A29: Terminal value - Gordon | B29: =B28/(Assumptions!$B$5-B27) -> 1088.1334
A30: Terminal value - cap (20x terminal FCF) | B30: =Assumptions!$B$12*L19 -> 1929.6947
A31: Terminal value used (lower of the two) | B31: =MIN(B29,B30) -> 1088.1334
A32: Implied exit multiple | B32: =B31/L19 -> 11.277778
A33: PV of terminal value | B33: =B31*L20 -> 400.92152
A34: Enterprise value | B34: =B26+B33 -> 1040.8388
A35: add: net cash | B35: =Assumptions!$B$9 -> 1313.9
A36: Equity value | B36: =B34+B35 -> 2354.7388
A37: Fully diluted shares (mm) | B37: =Assumptions!$B$10 -> 50.7
A38: Value per share | B38: =B36/B37 -> 46.444552
A39: Upside / (downside) vs current price | B39: =B38/Assumptions!$B$11-1 -> -0.61199205
A41: Memo: value if SBC treated as non-cash (market convention) | B41: =SUMPRODUCT(-C10:L10/(1+Assumptions!$B$5)^C4:L4) -> 1166.0063 | C41: PV of 2026-35 SBC
A42: plus PV of terminal SBC | B42: =(-L10*(1+B27)/(Assumptions!$B$5-B27))*L20 -> 855.37394
...

Sheet DCF_Base
A1: DUOL DCF - Base - pivot partially works
A2: Owner-FCF basis: SBC fully expensed, interest income excluded, share count flat. Blue rows = per-year drivers (edit).
B3: 2025A | C3: 2026E | D3: 2027E | E3: 2028E | F3: 2029E | G3: 2030E | H3: 2031E | I3: 2032E | J3: 2033E | K3: 2034E | L3: 2035E
A4: Year index (for discounting) | B4: 0 | C4: 1 | D4: 2 | E4: 3 | F4: 4 | G4: 5 | H4: 6 | I4: 7 | J4: 8 | K4: 9 | L4: 10
A5: Revenue growth YoY | C5: 0.163 | D5: 0.12 | E5: 0.14 | F5: 0.13 | G5: 0.11 | H5: 0.1 | I5: 0.09 | J5: 0.08 | K5: 0.07 | L5: 0.06
A6: Revenue | B6: 1037.6 | C6: =B6*(1+C5) -> 1206.7288 | D6: =C6*(1+D5) -> 1351.5363 | E6: =D6*(1+E5) -> 1540.7513 | F6: =E6*(1+F5) -> 1741.049 | G6: =F6*(1+G5) -> 1932.5644 | H6: =G6*(1+H5) -> 2125.8208 | I6: =H6*(1+I5) -> 2317.1447 | J6: =I6*(1+J5) -> 2502.5163 | ... L6: =K6*(1+L5) -> 2838.354
A7: Adj EBITDA margin | B7: 0.295 | C7: 0.265 | D7: 0.265 | E7: 0.275 | F7: 0.285 | G7: 0.295 | H7: 0.3 | I7: 0.305 | J7: 0.31 | K7: 0.315 | L7: 0.32
A8: Adjusted EBITDA | C8: =C6*C7 -> 319.78313 | D8: =D6*D7 -> 358.15711 | E8: =E6*E7 -> 423.70662 | F8: =F6*F7 -> 496.19897 | G8: =G6*G7 -> 570.1065 | H8: =H6*H7 -> 637.74625 | I8: =I6*I7 -> 706.72914 | J8: =J6*J7 -> 775.78005 | ... L8: =L6*L7 -> 908.27327
A9: SBC (% of revenue) | B9: 0.143 | C9: 0.15 | D9: 0.145 | E9: 0.14 | F9: 0.13 | G9: 0.125 | H9: 0.12 | I9: 0.115 | J9: 0.11 | K9: 0.105 | L9: 0.1
A10: SBC (incl. equity-award taxes) | C10: =-C6*C9 -> -181.00932 | D10: =-D6*D9 -> -195.97276 | E10: =-E6*E9 -> -215.70519 | F10: =-F6*F9 -> -226.33637 | G10: =-G6*G9 -> -241.57055 | H10: =-H6*H9 -> -255.0985 | I10: =-I6*I9 -> -266.47164 | J10: =-J6*J9 -> -275.27679 | ... L10: =-L6*L9 -> -283.8354
A11: EBITDA less SBC ('owner EBITDA') | C11: =C8+C10 -> 138.77381 | D11: =D8+D10 -> 162.18435 | E11: =E8+E10 -> 208.00143 | F11: =F8+F10 -> 269.8626 | G11: =G8+G10 -> 328.53595 | H11: =H8+H10 -> 382.64775 | I11: =I8+I10 -> 440.25749 | J11: =J8+J10 -> 500.50326 | ... L11: =L8+L10 -> 624.43787
A12: D&A | C12: =-C6*Assumptions!$B$6 -> -18.100932 | D12: =-D6*Assumptions!$B$6 -> -20.273044 | E12: =-E6*Assumptions!$B$6 -> -23.11127 | F12: =-F6*Assumptions!$B$6 -> -26.115735 | G12: =-G6*Assumptions!$B$6 -> -28.988466 | H12: =-H6*Assumptions!$B$6 -> -31.887313 | I12: =-I6*Assumptions!$B$6 -> -34.757171 | J12: =-J6*Assumptions!$B$6 -> -37.537744 | ... L12: =-L6*Assumptions!$B$6 -> -42.57531
A13: EBIT (SBC expensed) | C13: =C11+C12 -> 120.67288 | D13: =D11+D12 -> 141.91131 | E13: =E11+E12 -> 184.89016 | F13: =F11+F12 -> 243.74686 | G13: =G11+G12 -> 299.54748 | H13: =H11+H12 -> 350.76044 | I13: =I11+I12 -> 405.50032 | J13: =J11+J12 -> 462.96551 | ... L13: =L11+L12 -> 581.86256
A14: Cash tax rate (neg = benefit) | C14: -0.06 | D14: 0.08 | E14: 0.15 | F14: 0.2 | G14: 0.21 | H14: 0.21 | I14: 0.21 | J14: 0.21 | K14: 0.21 | L14: 0.21
A15: NOPAT | C15: =C13*(1-C14) -> 127.91325 | D15: =D13*(1-D14) -> 130.5584 | E15: =E13*(1-E14) -> 157.15664 | F15: =F13*(1-F14) -> 194.99749 | G15: =G13*(1-G14) -> 236.64251 | H15: =H13*(1-H14) -> 277.10075 | I15: =I13*(1-I14) -> 320.34526 | J15: =J13*(1-J14) -> 365.74276 | ... L15: =L13*(1-L14) -> 459.67143
A16: add: D&A | C16: =-C12 -> 18.100932 | D16: =-D12 -> 20.273044 | E16: =-E12 -> 23.11127 | F16: =-F12 -> 26.115735 | G16: =-G12 -> 28.988466 | H16: =-H12 -> 31.887313 | I16: =-I12 -> 34.757171 | J16: =-J12 -> 37.537744 | ... L16: =-L12 -> 42.57531
A17: less: capex + capitalized software | C17: =-C6*Assumptions!$B$7 -> -27.754762 | D17: =-D6*Assumptions!$B$7 -> -31.085334 | E17: =-E6*Assumptions!$B$7 -> -35.437281 | F17: =-F6*Assumptions!$B$7 -> -40.044127 | G17: =-G6*Assumptions!$B$7 -> -44.448981 | H17: =-H6*Assumptions!$B$7 -> -48.893879 | I17: =-I6*Assumptions!$B$7 -> -53.294328 | J17: =-J6*Assumptions!$B$7 -> -57.557875 | ... L17: =-L6*Assumptions!$B$7 -> -65.282141
A18: add: working capital (deferred-rev tailwind) | C18: =Assumptions!$B$8*(C6-B6) -> 30.443184 | D18: =Assumptions!$B$8*(D6-C6) -> 26.065342 | E18: =Assumptions!$B$8*(E6-D6) -> 34.058714 | F18: =Assumptions!$B$8*(F6-E6) -> 36.053581 | G18: =Assumptions!$B$8*(G6-F6) -> 34.47277 | H18: =Assumptions!$B$8*(H6-G6) -> 34.786159 | I18: =Assumptions!$B$8*(I6-H6) -> 34.438298 | J18: =Assumptions!$B$8*(J6-I6) -> 33.366884 | ... L18: =Assumptions!$B$8*(L6-K6) -> 28.919078
A19: Unlevered owner FCF | C19: =C15+C16+C17+C18 -> 148.70261 | D19: =D15+D16+D17+D18 -> 145.81145 | E19: =E15+E16+E17+E18 -> 178.88934 | F19: =F15+F16+F17+F18 -> 217.12268 | G19: =G15+G16+G17+G18 -> 255.65477 | H19: =H15+H16+H17+H18 -> 294.88034 | I19: =I15+I16+I17+I18 -> 336.2464 | J19: =J15+J16+J17+J18 -> 379.08951 | ... L19: =L15+L16+L17+L18 -> 465.88367
A20: Discount factor | C20: =1/(1+Assumptions!$B$5)^C4 -> 0.90497738 | D20: =1/(1+Assumptions!$B$5)^D4 -> 0.81898405 | E20: =1/(1+Assumptions!$B$5)^E4 -> 0.74116204 | F20: =1/(1+Assumptions!$B$5)^F4 -> 0.67073487 | G20: =1/(1+Assumptions!$B$5)^G4 -> 0.60699989 | H20: =1/(1+Assumptions!$B$5)^H4 -> 0.54932116 | I20: =1/(1+Assumptions!$B$5)^I4 -> 0.49712323 | J20: =1/(1+Assumptions!$B$5)^J4 -> 0.44988527 | ... L20: =1/(1+Assumptions!$B$5)^L4 -> 0.36844886
A21: PV of FCF | C21: =C19*C20 -> 134.57249 | D21: =D19*D20 -> 119.41726 | E21: =E19*E20 -> 132.58599 | F21: =F19*F20 -> 145.63175 | G21: =G19*G20 -> 155.18241 | H21: =H19*H20 -> 161.98401 | I21: =I19*I20 -> 167.15589 | J21: =J19*J20 -> 170.54679 | ... L21: =L19*L20 -> 171.65431
A23: Memo: FCF before SBC (company-style) | C23: =C19-C10 -> 329.71193 | D23: =D19-D10 -> 341.78421 | E23: =E19-E10 -> 394.59453 | F23: =F19-F10 -> 443.45905 | G23: =G19-G10 -> 497.22531 | H23: =H19-H10 -> 549.97884 | I23: =I19-I10 -> 602.71804 | J23: =J19-J10 -> 654.3663 | ... L23: =L19-L10 -> 749.71907
A24: Memo: implied owner FCF margin | C24: =C19/C6 -> 0.12322786 | D24: =D19/D6 -> 0.10788571 | E24: =E19/E6 -> 0.11610526 | F24: =F19/F6 -> 0.12470796 | G24: =G19/G6 -> 0.13228784 | H24: =H19/H6 -> 0.13871364 | I24: =I19/I6 -> 0.14511239 | J24: =J19/J6 -> 0.15148333 | ... L24: =L19/L6 -> 0.16413868
A25: Valuation
A26: PV of FCF, 2026-2035 | B26: =SUM(C21:L21) -> 1530.7901
A27: Terminal growth rate | B27: =Assumptions!$D$15 -> 0.03
A28: Terminal-year owner FCF x (1+g) | B28: =L19*(1+B27) -> 479.86018
A29: Terminal value - Gordon | B29: =B28/(Assumptions!$B$5-B27) -> 6398.1358
A30: Terminal value - cap (20x terminal FCF) | B30: =Assumptions!$B$12*L19 -> 9317.6734
A31: Terminal value used (lower of the two) | B31: =MIN(B29,B30) -> 6398.1358
A32: Implied exit multiple | B32: =B31/L19 -> 13.733333
A33: PV of terminal value | B33: =B31*L20 -> 2357.3858
A34: Enterprise value | B34: =B26+B33 -> 3888.176
A35: add: net cash | B35: =Assumptions!$B$9 -> 1313.9
A36: Equity value | B36: =B34+B35 -> 5202.076
A37: Fully diluted shares (mm) | B37: =Assumptions!$B$10 -> 50.7
A38: Value per share | B38: =B36/B37 -> 102.60505
A39: Upside / (downside) vs current price | B39: =B38/Assumptions!$B$11-1 -> -0.14281497
A41: Memo: value if SBC treated as non-cash (market convention) | B41: =SUMPRODUCT(-C10:L10/(1+Assumptions!$B$5)^C4:L4) -> 1398.1169 | C41: PV of 2026-35 SBC
A42: plus PV of terminal SBC | B42: =(-L10*(1+B27)/(Assumptions!$B$5-B27))*L20 -> 1436.2159
...

Sheet DCF_Bull
A1: DUOL DCF - Bull - 100M DAU by 2028; monetization converts
A2: Owner-FCF basis: SBC fully expensed, interest income excluded, share count flat. Blue rows = per-year drivers (edit).
B3: 2025A | C3: 2026E | D3: 2027E | E3: 2028E | F3: 2029E | G3: 2030E | H3: 2031E | I3: 2032E | J3: 2033E | K3: 2034E | L3: 2035E
A4: Year index (for discounting) | B4: 0 | C4: 1 | D4: 2 | E4: 3 | F4: 4 | G4: 5 | H4: 6 | I4: 7 | J4: 8 | K4: 9 | L4: 10
A5: Revenue growth YoY | C5: 0.165 | D5: 0.17 | E5: 0.19 | F5: 0.18 | G5: 0.16 | H5: 0.14 | I5: 0.12 | J5: 0.11 | K5: 0.1 | L5: 0.09
A6: Revenue | B6: 1037.6 | C6: =B6*(1+C5) -> 1208.804 | D6: =C6*(1+D5) -> 1414.3007 | E6: =D6*(1+E5) -> 1683.0178 | F6: =E6*(1+F5) -> 1985.961 | G6: =F6*(1+G5) -> 2303.7148 | H6: =G6*(1+H5) -> 2626.2348 | I6: =H6*(1+I5) -> 2941.383 | J6: =I6*(1+J5) -> 3264.9352 | ... L6: =K6*(1+L5) -> 3914.6573
A7: Adj EBITDA margin | B7: 0.295 | C7: 0.27 | D7: 0.275 | E7: 0.29 | F7: 0.305 | G7: 0.32 | H7: 0.33 | I7: 0.34 | J7: 0.345 | K7: 0.35 | L7: 0.35
A8: Adjusted EBITDA | C8: =C6*C7 -> 326.37708 | D8: =D6*D7 -> 388.93269 | E8: =E6*E7 -> 488.07516 | F8: =F6*F7 -> 605.71811 | G8: =G6*G7 -> 737.18873 | H8: =H6*H7 -> 866.6575 | I8: =I6*I7 -> 1000.0702 | J8: =J6*J7 -> 1126.4026 | ... L8: =L6*L7 -> 1370.13
A9: SBC (% of revenue) | B9: 0.143 | C9: 0.15 | D9: 0.135 | E9: 0.125 | F9: 0.115 | G9: 0.105 | H9: 0.1 | I9: 0.095 | J9: 0.09 | K9: 0.085 | L9: 0.08
A10: SBC (incl. equity-award taxes) | C10: =-C6*C9 -> -181.3206 | D10: =-D6*D9 -> -190.93059 | E10: =-E6*E9 -> -210.37723 | F10: =-F6*F9 -> -228.38552 | G10: =-G6*G9 -> -241.89005 | H10: =-H6*H9 -> -262.62348 | I10: =-I6*I9 -> -279.43139 | J10: =-J6*J9 -> -293.84416 | ... L10: =-L6*L9 -> -313.17258
A11: EBITDA less SBC ('owner EBITDA') | C11: =C8+C10 -> 145.05648 | D11: =D8+D10 -> 198.0021 | E11: =E8+E10 -> 277.69794 | F11: =F8+F10 -> 377.33259 | G11: =G8+G10 -> 495.29868 | H11: =H8+H10 -> 604.03401 | I11: =I8+I10 -> 720.63884 | J11: =J8+J10 -> 832.55847 | ... L11: =L8+L10 -> 1056.9575
A12: D&A | C12: =-C6*Assumptions!$B$6 -> -18.13206 | D12: =-D6*Assumptions!$B$6 -> -21.21451 | E12: =-E6*Assumptions!$B$6 -> -25.245267 | F12: =-F6*Assumptions!$B$6 -> -29.789415 | G12: =-G6*Assumptions!$B$6 -> -34.555722 | H12: =-H6*Assumptions!$B$6 -> -39.393523 | I12: =-I6*Assumptions!$B$6 -> -44.120745 | J12: =-J6*Assumptions!$B$6 -> -48.974027 | ... L12: =-L6*Assumptions!$B$6 -> -58.719859
A13: EBIT (SBC expensed) | C13: =C11+C12 -> 126.92442 | D13: =D11+D12 -> 176.78759 | E13: =E11+E12 -> 252.45267 | F13: =F11+F12 -> 347.54318 | G13: =G11+G12 -> 460.74296 | H13: =H11+H12 -> 564.64049 | I13: =I11+I12 -> 676.5181 | J13: =J11+J12 -> 783.58444 | ... L13: =L11+L12 -> 998.2376
A14: Cash tax rate (neg = benefit) | C14: -0.06 | D14: 0.08 | E14: 0.15 | F14: 0.2 | G14: 0.21 | H14: 0.21 | I14: 0.21 | J14: 0.21 | K14: 0.21 | L14: 0.21
A15: NOPAT | C15: =C13*(1-C14) -> 134.53989 | D15: =D13*(1-D14) -> 162.64458 | E15: =E13*(1-E14) -> 214.58477 | F15: =F13*(1-F14) -> 278.03454 | G15: =G13*(1-G14) -> 363.98693 | H15: =H13*(1-H14) -> 446.06599 | I15: =I13*(1-I14) -> 534.4493 | J15: =J13*(1-J14) -> 619.03171 | ... L15: =L13*(1-L14) -> 788.6077
A16: add: D&A | C16: =-C12 -> 18.13206 | D16: =-D12 -> 21.21451 | E16: =-E12 -> 25.245267 | F16: =-F12 -> 29.789415 | G16: =-G12 -> 34.555722 | H16: =-H12 -> 39.393523 | I16: =-I12 -> 44.120745 | J16: =-J12 -> 48.974027 | ... L16: =-L12 -> 58.719859
A17: less: capex + capitalized software | C17: =-C6*Assumptions!$B$7 -> -27.802492 | D17: =-D6*Assumptions!$B$7 -> -32.528916 | E17: =-E6*Assumptions!$B$7 -> -38.70941 | F17: =-F6*Assumptions!$B$7 -> -45.677103 | G17: =-G6*Assumptions!$B$7 -> -52.98544 | H17: =-H6*Assumptions!$B$7 -> -60.403401 | I17: =-I6*Assumptions!$B$7 -> -67.65181 | J17: =-J6*Assumptions!$B$7 -> -75.093509 | ... L17: =-L6*Assumptions!$B$7 -> -90.037117
A18: add: working capital (deferred-rev tailwind) | C18: =Assumptions!$B$8*(C6-B6) -> 30.81672 | D18: =Assumptions!$B$8*(D6-C6) -> 36.989402 | E18: =Assumptions!$B$8*(E6-D6) -> 48.369083 | F18: =Assumptions!$B$8*(F6-E6) -> 54.529777 | G18: =Assumptions!$B$8*(G6-F6) -> 57.195677 | H18: =Assumptions!$B$8*(H6-G6) -> 58.053612 | I18: =Assumptions!$B$8*(I6-H6) -> 56.726673 | J18: =Assumptions!$B$8*(J6-I6) -> 58.239384 | ... L18: =Assumptions!$B$8*(L6-K6) -> 58.181145
A19: Unlevered owner FCF | C19: =C15+C16+C17+C18 -> 155.68617 | D19: =D15+D16+D17+D18 -> 188.31958 | E19: =E15+E16+E17+E18 -> 249.48971 | F19: =F15+F16+F17+F18 -> 316.67663 | G19: =G15+G16+G17+G18 -> 402.75289 | H19: =H15+H16+H17+H18 -> 483.10972 | I19: =I15+I16+I17+I18 -> 567.6449 | J19: =J15+J16+J17+J18 -> 651.15161 | ... L19: =L15+L16+L17+L18 -> 815.47159
A20: Discount factor | C20: =1/(1+Assumptions!$B$5)^C4 -> 0.90497738 | D20: =1/(1+Assumptions!$B$5)^D4 -> 0.81898405 | E20: =1/(1+Assumptions!$B$5)^E4 -> 0.74116204 | F20: =1/(1+Assumptions!$B$5)^F4 -> 0.67073487 | G20: =1/(1+Assumptions!$B$5)^G4 -> 0.60699989 | H20: =1/(1+Assumptions!$B$5)^H4 -> 0.54932116 | I20: =1/(1+Assumptions!$B$5)^I4 -> 0.49712323 | J20: =1/(1+Assumptions!$B$5)^J4 -> 0.44988527 | ... L20: =1/(1+Assumptions!$B$5)^L4 -> 0.36844886
A21: PV of FCF | C21: =C19*C20 -> 140.89246 | D21: =D19*D20 -> 154.23073 | E21: =E19*E20 -> 184.9123 | F21: =F19*F20 -> 212.40606 | G21: =G19*G20 -> 244.47096 | H21: =H19*H20 -> 265.3824 | I21: =I19*I20 -> 282.18947 | J21: =J19*J20 -> 292.94352 | ... L21: =L19*L20 -> 300.45958
A23: Memo: FCF before SBC (company-style) | C23: =C19-C10 -> 337.00677 | D23: =D19-D10 -> 379.25017 | E23: =E19-E10 -> 459.86694 | F23: =F19-F10 -> 545.06215 | G23: =G19-G10 -> 644.64295 | H23: =H19-H10 -> 745.73321 | I23: =I19-I10 -> 847.07629 | J23: =J19-J10 -> 944.99577 | ... L23: =L19-L10 -> 1128.6442
A24: Memo: implied owner FCF margin | C24: =C19/C6 -> 0.12879356 | D24: =D19/D6 -> 0.13315385 | E24: =E19/E6 -> 0.1482395 | F24: =F19/F6 -> 0.15945763 | G24: =G19/G6 -> 0.17482759 | H24: =H19/H6 -> 0.18395526 | I24: =I19/I6 -> 0.19298571 | J24: =J19/J6 -> 0.19943784 | ... L24: =L19/L6 -> 0.20831239
A25: Valuation
A26: PV of FCF, 2026-2035 | B26: =SUM(C21:L21) -> 2378.9013
A27: Terminal growth rate | B27: =Assumptions!$E$15 -> 0.035
A28: Terminal-year owner FCF x (1+g) | B28: =L19*(1+B27) -> 844.0131
A29: Terminal value - Gordon | B29: =B28/(Assumptions!$B$5-B27) -> 12057.33
A30: Terminal value - cap (20x terminal FCF) | B30: =Assumptions!$B$12*L19 -> 16309.432
A31: Terminal value used (lower of the two) | B31: =MIN(B29,B30) -> 12057.33
A32: Implied exit multiple | B32: =B31/L19 -> 14.785714
A33: PV of terminal value | B33: =B31*L20 -> 4442.5095
A34: Enterprise value | B34: =B26+B33 -> 6821.4108
A35: add: net cash | B35: =Assumptions!$B$9 -> 1313.9
A36: Equity value | B36: =B34+B35 -> 8135.3108
A37: Fully diluted shares (mm) | B37: =Assumptions!$B$10 -> 50.7
A38: Value per share | B38: =B36/B37 -> 160.45978
A39: Upside / (downside) vs current price | B39: =B38/Assumptions!$B$11-1 -> 0.34051611
A41: Memo: value if SBC treated as non-cash (market convention) | B41: =SUMPRODUCT(-C10:L10/(1+Assumptions!$B$5)^C4:L4) -> 1431.4448 | C41: PV of 2026-35 SBC
A42: plus PV of terminal SBC | B42: =(-L10*(1+B27)/(Assumptions!$B$5-B27))*L20 -> 1706.0952
...

Sheet Valuation
A1: DUOL - Valuation Summary & Sensitivity (v2.0)
A2: All per-share values on the owner-FCF basis (SBC expensed) unless marked street. Green = links.
B4: Bear | C4: Base | D4: Bull
A5: Value per share | B5: =DCF_Bear!$B$38 -> 46.444552 | C5: =DCF_Base!$B$38 -> 102.60505 | D5: =DCF_Bull!$B$38 -> 160.45978
A6: Upside / (downside) vs price | B6: =B5/Assumptions!$B$11-1 -> -0.61199205 | C6: =C5/Assumptions!$B$11-1 -> -0.14281497 | D6: =D5/Assumptions!$B$11-1 -> 0.34051611
A7: Probability | B7: =Assumptions!$C$16 -> 0.15 | C7: =Assumptions!$D$16 -> 0.5 | D7: =Assumptions!$E$16 -> 0.35
A8: Value per share, SBC as non-cash (street) | B8: =DCF_Bear!$B$43 -> 86.313985 | C8: =DCF_Base!$B$43 -> 158.50905 | D8: =DCF_Bull!$B$43 -> 222.3442
A10: Probability-weighted value per share | B10: =SUMPRODUCT(B5:D5,B7:D7) -> 114.43013
A11: Current price | B11: =Assumptions!$B$11 -> 119.7
A12: Margin of safety vs weighted value | B12: =1-B11/B10 -> -0.046053174
A13: Weighted value, SBC as non-cash (street) | B13: =SUMPRODUCT(B8:D8,B7:D7) -> 170.02209
A14: House-street band vs price | B14: =B10 -> 114.43013 | C14: =B13 -> 170.02209 | D14: price sits at: | E14: =(Assumptions!$B$11-B10)/(B13-B10) -> 0.094795552 | G14: 0% = house floor, 100% = street ceiling
A17: Base case - value per share at different required returns
A18: Required return | B18: Value / share
A19: 0.09 | B19: =(SUMPRODUCT(DCF_Base!$C$19:$L$19/(1+$A19)^DCF_Base!$C$4:$L$4)+MIN(DCF_Base!$L$19*(1+Assumptions!$D$15)/($A19-Assumptions!$D$15),Assumptions!$B$12*DCF_Base!$L$19)/(1+$A19)^10+Assumptions!$B$9)/Assumptions!$B$10 -> 125.26341
A20: 0.1 | B20: =(SUMPRODUCT(DCF_Base!$C$19:$L$19/(1+$A20)^DCF_Base!$C$4:$L$4)+MIN(DCF_Base!$L$19*(1+Assumptions!$D$15)/($A20-Assumptions!$D$15),Assumptions!$B$12*DCF_Base!$L$19)/(1+$A20)^10+Assumptions!$B$9)/Assumptions!$B$10 -> 109.04694
A21: 0.105 | B21: =(SUMPRODUCT(DCF_Base!$C$19:$L$19/(1+$A21)^DCF_Base!$C$4:$L$4)+MIN(DCF_Base!$L$19*(1+Assumptions!$D$15)/($A21-Assumptions!$D$15),Assumptions!$B$12*DCF_Base!$L$19)/(1+$A21)^10+Assumptions!$B$9)/Assumptions!$B$10 -> 102.60505
A22: 0.11 | B22: =(SUMPRODUCT(DCF_Base!$C$19:$L$19/(1+$A22)^DCF_Base!$C$4:$L$4)+MIN(DCF_Base!$L$19*(1+Assumptions!$D$15)/($A22-Assumptions!$D$15),Assumptions!$B$12*DCF_Base!$L$19)/(1+$A22)^10+Assumptions!$B$9)/Assumptions!$B$10 -> 96.994894
A23: 0.12 | B23: =(SUMPRODUCT(DCF_Base!$C$19:$L$19/(1+$A23)^DCF_Base!$C$4:$L$4)+MIN(DCF_Base!$L$19*(1+Assumptions!$D$15)/($A23-Assumptions!$D$15),Assumptions!$B$12*DCF_Base!$L$19)/(1+$A23)^10+Assumptions!$B$9)/Assumptions!$B$10 -> 87.711726
A24: 0.15 | B24: =(SUMPRODUCT(DCF_Base!$C$19:$L$19/(1+$A24)^DCF_Base!$C$4:$L$4)+MIN(DCF_Base!$L$19*(1+Assumptions!$D$15)/($A24-Assumptions!$D$15),Assumptions!$B$12*DCF_Base!$L$19)/(1+$A24)^10+Assumptions!$B$9)/Assumptions!$B$10 -> 69.504718 | C24: 15% required-return entry price
A25: 15%-hurdle entry: Bear / Base / Bull / weighted | B25: =(SUMPRODUCT(DCF_Bear!$C$19:$L$19/(1+0.15)^DCF_Bear!$C$4:$L$4)+MIN(DCF_Bear!$L$19*(1+Assumptions!$C$15)/(0.15-Assumptions!$C$15),Assumptions!$B$12*DCF_Bear!$L$19)/(1+0.15)^10+Assumptions!$B$9)/Assumptions!$B$10 -> 40.085584 | C25: =(SUMPRODUCT(DCF_Base!$C$19:$L$19/(1+0.15)^DCF_Base!$C$4:$L$4)+MIN(DCF_Base!$L$19*(1+Assumptions!$D$15)/(0.15-Assumptions!$D$15),Assumptions!$B$12*DCF_Base!$L$19)/(1+0.15)^10+Assumptions!$B$9)/Assumptions!$B$10 -> 69.504718 | D25: =(SUMPRODUCT(DCF_Bull!$C$19:$L$19/(1+0.15)^DCF_Bull!$C$4:$L$4)+MIN(DCF_Bull!$L$19*(1+Assumptions!$E$15)/(0.15-Assumptions!$E$15),Assumptions!$B$12*DCF_Bull!$L$19)/(1+0.15)^10+Assumptions!$B$9)/Assumptions!$B$10 -> 98.580507 | E25: =SUMPRODUCT(B25:D25,$B$7:$D$7) -> 75.268374 | G25: model buy-below price at a 15% hurdle
A26: same, street basis (house + SBC PV) | B26: =B25+(SUMPRODUCT(-DCF_Bear!$C$10:$L$10/(1+0.15)^DCF_Bear!$C$4:$L$4)+(-DCF_Bear!$L$10*(1+Assumptions!$C$15)/(0.15-Assumptions!$C$15))/(1+0.15)^10)/Assumptions!$B$10 -> 66.7381 | C26: =C25+(SUMPRODUCT(-DCF_Base!$C$10:$L$10/(1+0.15)^DCF_Base!$C$4:$L$4)+(-DCF_Base!$L$10*(1+Assumptions!$D$15)/(0.15-Assumptions!$D$15))/(1+0.15)^10)/Assumptions!$B$10 -> 104.01483 | D26: =D25+(SUMPRODUCT(-DCF_Bull!$C$10:$L$10/(1+0.15)^DCF_Bull!$C$4:$L$4)+(-DCF_Bull!$L$10*(1+Assumptions!$E$15)/(0.15-Assumptions!$E$15))/(1+0.15)^10)/Assumptions!$B$10 -> 135.39999 | E26: =SUMPRODUCT(B26:D26,$B$7:$D$7) -> 109.40813
A28: Base case - value per share: WACC x terminal growth
A29: WACC \ g | B29: 0.02 | C29: 0.025 | D29: 0.03 | E29: 0.035 | F29: 0.04
A30: 0.095 | B30: =IF($A30>B$29,(SUMPRODUCT(DCF_Base!$C$19:$L$19/(1+$A30)^DCF_Base!$C$4:$L$4)+MIN(DCF_Base!$L$19*(1+B$29)/($A30-B$29),Assumptions!$B$12*DCF_Base!$L$19)/(1+$A30)^10+Assumptions!$B$9)/Assumptions!$B$10,"n/a") -> 108.1853 | C30: =IF($A30>C$29,(SUMPRODUCT(DCF_Base!$C$19:$L$19/(1+$A30)^DCF_Base!$C$4:$L$4)+MIN(DCF_Base!$L$19*(1+C$29)/($A30-C$29),Assumptions!$B$12*DCF_Base!$L$19)/(1+$A30)^10+Assumptions!$B$9)/Assumptions!$B$10,"n/a") -> 112.05211 | D30: =IF($A30>D$29,(SUMPRODUCT(DCF_Base!$C$19:$L$19/(1+$A30)^DCF_Base!$C$4:$L$4)+MIN(DCF_Base!$L$19*(1+D$29)/($A30-D$29),Assumptions!$B$12*DCF_Base!$L$19)/(1+$A30)^10+Assumptions!$B$9)/Assumptions!$B$10,"n/a") -> 116.51382 | E30: =IF($A30>E$29,(SUMPRODUCT(DCF_Base!$C$19:$L$19/(1+$A30)^DCF_Base!$C$4:$L$4)+MIN(DCF_Base!$L$19*(1+E$29)/($A30-E$29),Assumptions!$B$12*DCF_Base!$L$19)/(1+$A30)^10+Assumptions!$B$9)/Assumptions!$B$10,"n/a") -> 121.71914 | F30: =IF($A30>F$29,(SUMPRODUCT(DCF_Base!$C$19:$L$19/(1+$A30)^DCF_Base!$C$4:$L$4)+MIN(DCF_Base!$L$19*(1+F$29)/($A30-F$29),Assumptions!$B$12*DCF_Base!$L$19)/(1+$A30)^10+Assumptions!$B$9)/Assumptions!$B$10,"n/a") -> 127.87089
A31: 0.1 | B31: =IF($A31>B$29,(SUMPRODUCT(DCF_Base!$C$19:$L$19/(1+$A31)^DCF_Base!$C$4:$L$4)+MIN(DCF_Base!$L$19*(1+B$29)/($A31-B$29),Assumptions!$B$12*DCF_Base!$L$19)/(1+$A31)^10+Assumptions!$B$9)/Assumptions!$B$10,"n/a") -> 102.08793 | C31: =IF($A31>C$29,(SUMPRODUCT(DCF_Base!$C$19:$L$19/(1+$A31)^DCF_Base!$C$4:$L$4)+MIN(DCF_Base!$L$19*(1+C$29)/($A31-C$29),Assumptions!$B$12*DCF_Base!$L$19)/(1+$A31)^10+Assumptions!$B$9)/Assumptions!$B$10,"n/a") -> 105.33547 | D31: =IF($A31>D$29,(SUMPRODUCT(DCF_Base!$C$19:$L$19/(1+$A31)^DCF_Base!$C$4:$L$4)+MIN(DCF_Base!$L$19*(1+D$29)/($A31-D$29),Assumptions!$B$12*DCF_Base!$L$19)/(1+$A31)^10+Assumptions!$B$9)/Assumptions!$B$10,"n/a") -> 109.04694 | E31: =IF($A31>E$29,(SUMPRODUCT(DCF_Base!$C$19:$L$19/(1+$A31)^DCF_Base!$C$4:$L$4)+MIN(DCF_Base!$L$19*(1+E$29)/($A31-E$29),Assumptions!$B$12*DCF_Base!$L$19)/(1+$A31)^10+Assumptions!$B$9)/Assumptions!$B$10,"n/a") -> 113.32941 | F31: =IF($A31>F$29,(SUMPRODUCT(DCF_Base!$C$19:$L$19/(1+$A31)^DCF_Base!$C$4:$L$4)+MIN(DCF_Base!$L$19*(1+F$29)/($A31-F$29),Assumptions!$B$12*DCF_Base!$L$19)/(1+$A31)^10+Assumptions!$B$9)/Assumptions!$B$10,"n/a") -> 118.32562
A32: 0.105 | B32: =IF($A32>B$29,(SUMPRODUCT(DCF_Base!$C$19:$L$19/(1+$A32)^DCF_Base!$C$4:$L$4)+MIN(DCF_Base!$L$19*(1+B$29)/($A32-B$29),Assumptions!$B$12*DCF_Base!$L$19)/(1+$A32)^10+Assumptions!$B$9)/Assumptions!$B$10,"n/a") -> 96.736525 | C32: =IF($A32>C$29,(SUMPRODUCT(DCF_Base!$C$19:$L$19/(1+$A32)^DCF_Base!$C$4:$L$4)+MIN(DCF_Base!$L$19*(1+C$29)/($A32-C$29),Assumptions!$B$12*DCF_Base!$L$19)/(1+$A32)^10+Assumptions!$B$9)/Assumptions!$B$10,"n/a") -> 99.487395 | D32: =IF($A32>D$29,(SUMPRODUCT(DCF_Base!$C$19:$L$19/(1+$A32)^DCF_Base!$C$4:$L$4)+MIN(DCF_Base!$L$19*(1+D$29)/($A32-D$29),Assumptions!$B$12*DCF_Base!$L$19)/(1+$A32)^10+Assumptions!$B$9)/Assumptions!$B$10,"n/a") -> 102.60505 | E32: =IF($A32>E$29,(SUMPRODUCT(DCF_Base!$C$19:$L$19/(1+$A32)^DCF_Base!$C$4:$L$4)+MIN(DCF_Base!$L$19*(1+E$29)/($A32-E$29),Assumptions!$B$12*DCF_Base!$L$19)/(1+$A32)^10+Assumptions!$B$9)/Assumptions!$B$10,"n/a") -> 106.16808 | F32: =IF($A32>F$29,(SUMPRODUCT(DCF_Base!$C$19:$L$19/(1+$A32)^DCF_Base!$C$4:$L$4)+MIN(DCF_Base!$L$19*(1+F$29)/($A32-F$29),Assumptions!$B$12*DCF_Base!$L$19)/(1+$A32)^10+Assumptions!$B$9)/Assumptions!$B$10,"n/a") -> 110.27927
A33: 0.11 | B33: =IF($A33>B$29,(SUMPRODUCT(DCF_Base!$C$19:$L$19/(1+$A33)^DCF_Base!$C$4:$L$4)+MIN(DCF_Base!$L$19*(1+B$29)/($A33-B$29),Assumptions!$B$12*DCF_Base!$L$19)/(1+$A33)^10+Assumptions!$B$9)/Assumptions!$B$10,"n/a") -> 92.005702 | C33: =IF($A33>C$29,(SUMPRODUCT(DCF_Base!$C$19:$L$19/(1+$A33)^DCF_Base!$C$4:$L$4)+MIN(DCF_Base!$L$19*(1+C$29)/($A33-C$29),Assumptions!$B$12*DCF_Base!$L$19)/(1+$A33)^10+Assumptions!$B$9)/Assumptions!$B$10,"n/a") -> 94.353557 | D33: =IF($A33>D$29,(SUMPRODUCT(DCF_Base!$C$19:$L$19/(1+$A33)^DCF_Base!$C$4:$L$4)+MIN(DCF_Base!$L$19*(1+D$29)/($A33-D$29),Assumptions!$B$12*DCF_Base!$L$19)/(1+$A33)^10+Assumptions!$B$9)/Assumptions!$B$10,"n/a") -> 96.994894 | E33: =IF($A33>E$29,(SUMPRODUCT(DCF_Base!$C$19:$L$19/(1+$A33)^DCF_Base!$C$4:$L$4)+MIN(DCF_Base!$L$19*(1+E$29)/($A33-E$29),Assumptions!$B$12*DCF_Base!$L$19)/(1+$A33)^10+Assumptions!$B$9)/Assumptions!$B$10,"n/a") -> 99.988409 | F33: =IF($A33>F$29,(SUMPRODUCT(DCF_Base!$C$19:$L$19/(1+$A33)^DCF_Base!$C$4:$L$4)+MIN(DCF_Base!$L$19*(1+F$29)/($A33-F$29),Assumptions!$B$12*DCF_Base!$L$19)/(1+$A33)^10+Assumptions!$B$9)/Assumptions!$B$10,"n/a") -> 103.40957
A34: 0.115 | B34: =IF($A34>B$29,(SUMPRODUCT(DCF_Base!$C$19:$L$19/(1+$A34)^DCF_Base!$C$4:$L$4)+MIN(DCF_Base!$L$19*(1+B$29)/($A34-B$29),Assumptions!$B$12*DCF_Base!$L$19)/(1+$A34)^10+Assumptions!$B$9)/Assumptions!$B$10,"n/a") -> 87.796525 | C34: =IF($A34>C$29,(SUMPRODUCT(DCF_Base!$C$19:$L$19/(1+$A34)^DCF_Base!$C$4:$L$4)+MIN(DCF_Base!$L$19*(1+C$29)/($A34-C$29),Assumptions!$B$12*DCF_Base!$L$19)/(1+$A34)^10+Assumptions!$B$9)/Assumptions!$B$10,"n/a") -> 89.81396 | D34: =IF($A34>D$29,(SUMPRODUCT(DCF_Base!$C$19:$L$19/(1+$A34)^DCF_Base!$C$4:$L$4)+MIN(DCF_Base!$L$19*(1+D$29)/($A34-D$29),Assumptions!$B$12*DCF_Base!$L$19)/(1+$A34)^10+Assumptions!$B$9)/Assumptions!$B$10,"n/a") -> 92.068741 | E34: =IF($A34>E$29,(SUMPRODUCT(DCF_Base!$C$19:$L$19/(1+$A34)^DCF_Base!$C$4:$L$4)+MIN(DCF_Base!$L$19*(1+E$29)/($A34-E$29),Assumptions!$B$12*DCF_Base!$L$19)/(1+$A34)^10+Assumptions!$B$9)/Assumptions!$B$10,"n/a") -> 94.605369 | F34: =IF($A34>F$29,(SUMPRODUCT(DCF_Base!$C$19:$L$19/(1+$A34)^DCF_Base!$C$4:$L$4)+MIN(DCF_Base!$L$19*(1+F$29)/($A34-F$29),Assumptions!$B$12*DCF_Base!$L$19)/(1+$A34)^10+Assumptions!$B$9)/Assumptions!$B$10,"n/a") -> 97.480214
