Workbook

Sheet Model_Info
A1: VGL.NZ Vista Group International -- owner-FCF DCF model
A2: Version 1.0, 2026-09-19. Fresh build; supersedes nothing (first valuation of this ticker).
A3: Built by the dcf-analyst agent (Claude Fable 5.1) at the research orchestrator's request.
A5: DATA VINTAGE -- these figures go stale
A6: Price NZ$2.91 at 2026-09-18T05:00:01Z (Yahoo, NZX regular close Fri 18 Sep 2026). Refresh before use.
A7: Balance sheet: net bank debt NZ$5.8m at 30-Jun-2026 (H1 FY2026 results announcement, via Analysis JSON). All other anchors 31-Dec-2025 (FY2025 annual report).
A8: Share count: 238.834m on issue (FY2025 AR shareholder statistics) + 2.7m dilutive rights (note 6.2) = 241.5m fully diluted, held flat.
A9: Guidance FY2026 (3-Aug-2026): revenue NZ$179-184m, EBITDA margin 18-20%, FCF neutral in H2; 2030 ARR aspiration NZ$315m.
A11: METHODOLOGY
A12: Owner-FCF DCF, component build, 10-year horizon (margin still ramping at year 5), end-of-year discounting, TV = MAX(0, MIN(Gordon, 18x FCF10)).
A13: SBC fully expensed (0.5% of revenue) and share count held flat -- charged once. Street memo adds SBC back.
A14: Leases: treatment B -- full lease cash (principal + interest) in the flows via lease % of revenue; lease liabilities EXCLUDED from net debt; D&A ex right-of-use depreciation.
... A26: Text cells never begin with '='. Sheet names contain no spaces.

Sheet Actuals
A1: Metric (NZ$m) | B1: FY2020 | C1: FY2021 | D1: FY2022 | E1: FY2023 | F1: FY2024 | G1: FY2025 | H1: Source
A2: Revenue | B2: 87.5 | C2: 98.1 | D2: 135.1 | E2: 143 | F2: 150 | G2: 164.3 | H2: Income statement, core_metrics
A3: EBITDA (IS subtotal, post-IFRS16) | B3: -11.4 | C3: 6.5 | D3: 10.6 | E3: 13.3 | F3: 21.6 | G3: 28.2 | H3: Income statement EBITDA line
A4: Net income (total incl NCI) | B4: -57.1 | C4: -9.9 | D4: -20.9 | E4: -13.6 | F4: -0.6 | G4: 2.6 | H4: Income statement
A5: Operating cash flow | B5: 3 | C5: 11.3 | D5: 12.4 | E5: 9 | F5: 16.8 | G5: 27.8 | H5: Cash flow statement
A6: Capex (PPE + capitalised software) | B6: 14.2 | C6: 12.8 | D6: 18.9 | E6: 20.3 | F6: 18.1 | G6: 21.1 | H6: Cash flow statement, investing
A7: Reported FCF (OCF - capex) | B7: -11.2 | C7: -1.5 | D7: -6.5 | E7: -11.3 | F7: -1.3 | G7: 6.7 | H7: Derived
A8: Share-based payments | B8: 0.5 | C8: 5.2 | D8: 4.5 | E8: 3.2 | F8: 1.8 | G8: 0.9 | H8: Statement of changes in equity
A9: Interest income | B9: 0.7 | C9: 0.5 | D9: 0.8 | E9: 1 | F9: 0.4 | G9: 0.1 | H9: Finance income
A10: Lease cash (principal + interest) | B10: 6.4 | C10: 3.8 | D10: 5.9 | E10: 5.8 | F10: 6.6 | G10: 6.8 | H10: Lease note: repayment incl. interest (FY23 = principal 5.3 + est. 0.5)
A11: Finance costs (interest-paid proxy) | B11: 2.2 | C11: 2 | D11: 2.1 | E11: 2.7 | F11: 2.8 | G11: 2.1 | H11: P&L finance costs; FY2025 = actual interest paid 2.1
A12: Amortisation | B12: 7.3 | C12: 7.8 | D12: 11.5 | E12: 13 | F12: 14 | G12: 15.9 | H12: kpis
A13: Depreciation (incl ROU) | B13: 10.4 | C13: 6.1 | D13: 5.7 | E13: 6.9 | F13: 5.8 | G13: 5.6 | H13: kpis; FY2025 ROU depreciation 4.4
... A15: Cash taxes paid | B15: 0.9 | C15: 1.6 | D15: -0.4 | E15: -0.1 | F15: 0.4 | G15: 0.3 | H15: kpis
A16: ARR | D16: 118 | E16: 126.3 | F16: 145.6 | G16: 163 | H16: kpis; H1 FY2026 170.1
A17: Cash and equivalents | B17: 67.1 | C17: 60.4 | D17: 46 | E17: 28.5 | F17: 21.8 | G17: 20 | H17: Balance sheet
A18: Borrowings (ex lease) | F18: 20.7 | G18: 19.3 | H18: Note 3.2
A19: Lease liabilities | F19: 8.8 | G19: 13.6 | H19: Note 4.6
A20: Diluted weighted shares (m) | B20: 217.7 | C20: 230.7 | D20: 237.4 | E20: 238.6 | F20: 240.4 | G20: 241.2 | H20: EPS note
A22: Guidance FY2026 (3-Aug-2026)
A23: Revenue NZ$179-184m; EBITDA margin 18-20%; FCF neutral in H2 FY2026; 2030 exit-rate ARR aspiration NZ$315m; H1 FY2026 revenue 86.3 (+12.1%), net loss -1.5, ARR 170.1, net debt ~5.8.
A24: Buybacks: none FY2020-FY2025. No ordinary dividend. Activist (Potentia/Admetus 19.9%) exited Sep-2025 at NZ$3.00.

Sheet Assumptions
A1: Global inputs
A2: Share price (NZD) | B2: 2.91 | C2: Yahoo 2026-09-18T05:00:01Z NZX close
A3: Fully diluted shares (m) | B3: 241.5 | C3: 238.834m on issue + 2.7m rights; held flat (SBC expensed)
A4: Net bank debt ex-lease (NZ$m) | B4: 5.8 | C4: 30-Jun-2026; FY2025 was net cash 0.7
A5: NCI value deducted (NZ$m) | B5: 10.5 | C5: FY25 NCI profit 0.7 x 15; charged once, here
A6: Net debt for bridge (NZ$m) | B6: =B4+B5 | C6: net bank debt + NCI value; lease liabilities excluded (treatment B)
A7: FY2025 revenue (NZ$m) | B7: 164.3 | C7: FY0 actual
A8: WACC (all scenarios) | B8: 0.115 | C8: NZD-built; see Model_Info
A9: Hurdle rate for entry price | B9: 0.15 | C9: House 15% IRR
A10: Terminal value cap (x FCF10) | B10: 18 | C10: Below the 20x default: moderate cinema cyclicality
A11: Working-capital capture of revenue change | B11: 0.15 | C11: Deferred revenue up 5.3 on 14.3 revenue growth FY25; positive = prepaid inflow
A12: Horizon (years) | B12: 10 | C12: Margin still ramping at year 5
A14: Per scenario | B14: Bear | C14: Base | D14: Bull
A15: Terminal growth | B15: 0.025 | C15: 0.03 | D15: 0.035
A16: Probability weight | B16: 0.2 | C16: 0.5 | D16: 0.3
A17: Weights check (must be 100%) | B17: =SUM(B16:D16)
A19: Scenario narratives
A20: Bear | B20: Bear: FY2026 comes in at the bottom of guidance (+8%), then a weak 2027-28 slate (as in the 2023 strike year) and a slower cloud delivery ramp hold growth at 2-4%; a major circuit renegotiates or churns (the Cinemex 2019 departure is the precedent). EBITDA margin stalls at 17-20% because the incremental delivery/technology spend is never fully recovered, capitalised software stays above 10% of revenue and lease cost stays at ~3.5%. Owner FCF is negative for three years and only reaches ~4% of revenue by FY2035; terminal growth 2.5%. Same WACC as base -- risk is charged in the flows, not the rate.
A21: Base | B21: Base: FY2026 lands at the guidance midpoint (revenue NZ$181.5m, +10.5%; EBITDA margin 18.0%, the low half of the 18-20% guide given H1's 13.8% FX-adjusted margin). Growth decays 10.5% -> 3.5% over ten years as the Vista Cloud migration (35% of sites at FY25; ODEON/AMC, Kinepolis, Cinepolis Mexico, Cineworld UK, Cinemex signed) lifts SaaS mix, but the 2030 ARR aspiration of NZ$315m is NOT reached (base revenue ~NZ$247m in FY2030). EBITDA margin expands 1pp/yr to 25.5% by FY2035 as onboarding costs are recovered and expensed R&D leverages. Capitalised software (12.5% of revenue in FY25, 14% assumed in FY26 while delivery capacity is being added) tapers to 8% by FY2034; D&A converges on capex with a lag. Lease cash (4.1% of revenue in FY25 after a new HQ lease) scales down to 2.8%. Cash tax shielded by NZ$28.5m of recognised deferred tax assets on ~NZ$100m of NZ losses, ramping from 5% to the 28% statutory rate by FY2033. Owner FCF goes from ~zero (FY25: NZ$1.0m) to ~10.8% of revenue at maturity.
A22: Bull | B22: Bull: the cloud pipeline converts at pace and Vista Payments scales toward its NZ$15m+ ARR aspiration, so revenue compounds 12-13% through FY2029 and reaches ~NZ$292m in FY2030 (ARR run-rate ~NZ$315m, matching the stated 2030 aspiration). A strong 2026-27 slate (Avengers, Star Wars, Dune, Toy Story) lifts GTV-linked revenue. Operating leverage takes the EBITDA margin to 30% by FY2035 (vertical-SaaS peer territory), capitalised software falls to 7.5% of revenue and lease cost to 2.5%. Same tax ramp and WACC as base; terminal growth 3.5%.

Sheet DCF_Bear
A1: DCF -- Bear scenario (NZ$m; per share NZD)
A3: Year | B3: 2025A | C3: 2026E | D3: 2027E | E3: 2028E | F3: 2029E | G3: 2030E | H3: 2031E | I3: 2032E | J3: 2033E | K3: 2034E | L3: 2035E
A4: Index | B4: 0 | C4: 1 | D4: 2 | E4: 3 | F4: 4 | G4: 5 | H4: 6 | I4: 7 | J4: 8 | K4: 9 | L4: 10
A5: Revenue growth YoY | C5: 0.08 | D5: 0.04 | E5: 0.02 | F5: 0.03 | G5: 0.03 | H5: 0.03 | I5: 0.03 | J5: 0.025 | K5: 0.025 | L5: 0.025
A6: Revenue | B6: =Assumptions!$B$7 | C6: =B6*(1+C5) | D6: =C6*(1+D5) | E6: =D6*(1+E5) | F6: =E6*(1+F5) | G6: =F6*(1+G5) | H6: =G6*(1+H5) | I6: =H6*(1+I5) | J6: =I6*(1+J5) | ... L6: =K6*(1+L5)
A7: Adj EBITDA margin (post-IFRS16) | B7: =B8/B6 | C7: 0.175 | D7: 0.175 | E7: 0.17 | F7: 0.175 | G7: 0.18 | H7: 0.185 | I7: 0.19 | J7: 0.195 | K7: 0.2 | L7: 0.2
A8: Adjusted EBITDA | B8: 28.2 | C8: =C6*C7 | D8: =D6*D7 | E8: =E6*E7 | F8: =F6*F7 | G8: =G6*G7 | H8: =H6*H7 | I8: =I6*I7 | J8: =J6*J7 | ... L8: =L6*L7
A9: SBC % of revenue | B9: =-B10/B6 | C9: 0.005 | D9: 0.005 | E9: 0.005 | F9: 0.005 | G9: 0.005 | H9: 0.005 | I9: 0.005 | J9: 0.005 | K9: 0.005 | L9: 0.005
A10: SBC (negative) | B10: -0.9 | C10: =-C6*C9 | D10: =-D6*D9 | E10: =-E6*E9 | F10: =-F6*F9 | G10: =-G6*G9 | H10: =-H6*H9 | I10: =-I6*I9 | J10: =-J6*J9 | ... L10: =-L6*L9
A11: Lease cash % of revenue | B11: =-B12/B6 | C11: 0.04 | D11: 0.04 | E11: 0.039 | F11: 0.039 | G11: 0.038 | H11: 0.037 | I11: 0.036 | J11: 0.036 | K11: 0.035 | L11: 0.035
A12: Lease cash (negative) | B12: -6.8 | C12: =-C6*C11 | D12: =-D6*D11 | E12: =-E6*E11 | F12: =-F6*F11 | G12: =-G6*G11 | H12: =-H6*H11 | I12: =-I6*I11 | J12: =-J6*J11 | ... L12: =-L6*L11
A13: Owner EBITDA (after SBC, lease) | B13: =B8+B10+B12 | C13: =C8+C10+C12 | D13: =D8+D10+D12 | E13: =E8+E10+E12 | F13: =F8+F10+F12 | G13: =G8+G10+G12 | H13: =H8+H10+H12 | I13: =I8+I10+I12 | ... L13: =L8+L10+L12
A14: D&A % of revenue (ex ROU) | B14: =-B15/B6 | C14: 0.104 | D14: 0.104 | E14: 0.104 | F14: 0.104 | G14: 0.103 | H14: 0.102 | I14: 0.101 | J14: 0.1 | K14: 0.1 | L14: 0.1
A15: D&A (negative) | B15: -17.1 | C15: =-C6*C14 | D15: =-D6*D14 | E15: =-E6*E14 | F15: =-F6*F14 | G15: =-G6*G14 | H15: =-H6*H14 | I15: =-I6*I14 | J15: =-J6*J14 | ... L15: =-L6*L14
A16: EBIT | B16: =B13+B15 | C16: =C13+C15 | D16: =D13+D15 | E16: =E13+E15 | F16: =F13+F15 | G16: =G13+G15 | H16: =H13+H15 | I16: =I13+I15 | ... L16: =L13+L15
A17: Cash tax rate | C17: 0.05 | D17: 0.05 | E17: 0.08 | F17: 0.12 | G17: 0.16 | H17: 0.2 | I17: 0.24 | J17: 0.28 | K17: 0.28 | L17: 0.28
A18: Cash tax on MAX(0,EBIT) (negative) | C18: =-MAX(0,C16)*C17 | D18: =-MAX(0,D16)*D17 | E18: =-MAX(0,E16)*E17 | F18: =-MAX(0,F16)*F17 | G18: =-MAX(0,G16)*G17 | H18: =-MAX(0,H16)*H17 | I18: =-MAX(0,I16)*I17 | J18: =-MAX(0,J16)*J17 | ... L18: =-MAX(0,L16)*L17
A19: NOPAT | C19: =C16+C18 | D19: =D16+D18 | E19: =E16+E18 | F19: =F16+F18 | G19: =G16+G18 | H19: =H16+H18 | I19: =I16+I18 | J19: =J16+J18 | ... L19: =L16+L18
A20: Add back D&A | C20: =-C15 | D20: =-D15 | E20: =-E15 | F20: =-F15 | G20: =-G15 | H20: =-H15 | I20: =-I15 | J20: =-J15 | ... L20: =-L15
A21: Capex % of revenue (incl capitalised software) | B21: =-B22/B6 | C21: 0.14 | D21: 0.135 | E21: 0.13 | F21: 0.125 | G21: 0.12 | H21: 0.115 | I21: 0.11 | J21: 0.105 | K21: 0.105 | L21: 0.105
A22: Capex (negative) | B22: -21.1 | C22: =-C6*C21 | D22: =-D6*D21 | E22: =-E6*E21 | F22: =-F6*F21 | G22: =-G6*G21 | H22: =-H6*H21 | I22: =-I6*I21 | J22: =-J6*J21 | ... L22: =-L6*L21
A23: Working capital (capture x revenue change) | C23: =Assumptions!$B$11*(C6-B6) | D23: =Assumptions!$B$11*(D6-C6) | E23: =Assumptions!$B$11*(E6-D6) | F23: =Assumptions!$B$11*(F6-E6) | G23: =Assumptions!$B$11*(G6-F6) | H23: =Assumptions!$B$11*(H6-G6) | I23: =Assumptions!$B$11*(I6-H6) | J23: =Assumptions!$B$11*(J6-I6) | ... L23: =Assumptions!$B$11*(L6-K6)
A24: Unlevered owner FCF | B24: 1 | C24: =C19+C20+C22+C23 | D24: =D19+D20+D22+D23 | E24: =E19+E20+E22+E23 | F24: =F19+F20+F22+F23 | G24: =G19+G20+G22+G23 | H24: =H19+H20+H22+H23 | I24: =I19+I20+I22+I23 | J24: =J19+J20+J22+J23 | ... L24: =L19+L20+L22+L23
A25: Discount factor | C25: =1/(1+Assumptions!$B$8)^C4 | D25: =1/(1+Assumptions!$B$8)^D4 | E25: =1/(1+Assumptions!$B$8)^E4 | F25: =1/(1+Assumptions!$B$8)^F4 | G25: =1/(1+Assumptions!$B$8)^G4 | H25: =1/(1+Assumptions!$B$8)^H4 | I25: =1/(1+Assumptions!$B$8)^I4 | J25: =1/(1+Assumptions!$B$8)^J4 | ... L25: =1/(1+Assumptions!$B$8)^L4
A26: PV of FCF | C26: =C24*C25 | D26: =D24*D25 | E26: =E24*E25 | F26: =F24*F25 | G26: =G24*G25 | H26: =H24*H25 | I26: =I24*I25 | J26: =J24*J25 | ... L26: =L24*L25
A28: Memo: FCF before SBC (company-style) | C28: =C24-C10 | D28: =D24-D10 | E28: =E24-E10 | F28: =F24-F10 | G28: =G24-G10 | H28: =H24-H10 | I28: =I24-I10 | J28: =J24-J10 | ... L28: =L24-L10
A29: Memo: owner FCF margin | B29: =B24/B6 | C29: =C24/C6 | D29: =D24/D6 | E29: =E24/E6 | F29: =F24/F6 | G29: =G24/G6 | H29: =H24/H6 | I29: =I24/I6 | ... L29: =L24/L6
A31: Sum of PV of FCF | B31: =SUM(C26:L26)
A32: Terminal growth | B32: =Assumptions!$B$15
A33: Terminal-year FCF x (1+g) | B33: =L24*(1+B32)
A34: Gordon terminal value | B34: =IF(Assumptions!$B$8>B32,B33/(Assumptions!$B$8-B32),0)
A35: Cap terminal value (cap x FCF10) | B35: =Assumptions!$B$10*L24
A36: Terminal value used = MAX(0,MIN(Gordon,cap)) | B36: =MAX(0,MIN(B34,B35))
A37: Implied exit multiple (TV / FCF10) | B37: =IF(L24<>0,B36/L24,0)
A38: PV of terminal value | B38: =B36*L25
A39: Enterprise value | B39: =B31+B38
A40: Less net debt (bank net debt + NCI) | B40: =-Assumptions!$B$6
A41: Equity value | B41: =B39+B40
A42: Diluted shares (m) | B42: =Assumptions!$B$3
A43: VALUE PER SHARE (NZD) | B43: =B41/B42
...

Sheet DCF_Base
A1: DCF -- Base scenario (NZ$m; per share NZD)
A3: Year | B3: 2025A | C3: 2026E | D3: 2027E | E3: 2028E | F3: 2029E | G3: 2030E | H3: 2031E | I3: 2032E | J3: 2033E | K3: 2034E | L3: 2035E
A4: Index | B4: 0 | C4: 1 | D4: 2 | E4: 3 | F4: 4 | G4: 5 | H4: 6 | I4: 7 | J4: 8 | K4: 9 | L4: 10
A5: Revenue growth YoY | C5: 0.105 | D5: 0.095 | E5: 0.085 | F5: 0.075 | G5: 0.065 | H5: 0.055 | I5: 0.05 | J5: 0.045 | K5: 0.04 | L5: 0.035
A6: Revenue | B6: =Assumptions!$B$7 | C6: =B6*(1+C5) | D6: =C6*(1+D5) | E6: =D6*(1+E5) | F6: =E6*(1+F5) | G6: =F6*(1+G5) | H6: =G6*(1+H5) | I6: =H6*(1+I5) | J6: =I6*(1+J5) | ... L6: =K6*(1+L5)
A7: Adj EBITDA margin (post-IFRS16) | B7: =B8/B6 | C7: 0.18 | D7: 0.19 | E7: 0.2 | F7: 0.21 | G7: 0.22 | H7: 0.23 | I7: 0.24 | J7: 0.245 | K7: 0.25 | L7: 0.255
A8: Adjusted EBITDA | B8: 28.2 | C8: =C6*C7 | D8: =D6*D7 | E8: =E6*E7 | F8: =F6*F7 | G8: =G6*G7 | H8: =H6*H7 | I8: =I6*I7 | J8: =J6*J7 | ... L8: =L6*L7
A9: SBC % of revenue | B9: =-B10/B6 | C9: 0.005 | D9: 0.005 | E9: 0.005 | F9: 0.005 | G9: 0.005 | H9: 0.005 | I9: 0.005 | J9: 0.005 | K9: 0.005 | L9: 0.005
A10: SBC (negative) | B10: -0.9 | C10: =-C6*C9 | D10: =-D6*D9 | E10: =-E6*E9 | F10: =-F6*F9 | G10: =-G6*G9 | H10: =-H6*H9 | I10: =-I6*I9 | J10: =-J6*J9 | ... L10: =-L6*L9
A11: Lease cash % of revenue | B11: =-B12/B6 | C11: 0.04 | D11: 0.039 | E11: 0.038 | F11: 0.036 | G11: 0.034 | H11: 0.032 | I11: 0.031 | J11: 0.03 | K11: 0.029 | L11: 0.028
A12: Lease cash (negative) | B12: -6.8 | C12: =-C6*C11 | D12: =-D6*D11 | E12: =-E6*E11 | F12: =-F6*F11 | G12: =-G6*G11 | H12: =-H6*H11 | I12: =-I6*I11 | J12: =-J6*J11 | ... L12: =-L6*L11
A13: Owner EBITDA (after SBC, lease) | B13: =B8+B10+B12 | C13: =C8+C10+C12 | D13: =D8+D10+D12 | E13: =E8+E10+E12 | F13: =F8+F10+F12 | G13: =G8+G10+G12 | H13: =H8+H10+H12 | I13: =I8+I10+I12 | ... L13: =L8+L10+L12
A14: D&A % of revenue (ex ROU) | B14: =-B15/B6 | C14: 0.104 | D14: 0.104 | E14: 0.103 | F14: 0.101 | G14: 0.098 | H14: 0.095 | I14: 0.092 | J14: 0.089 | K14: 0.086 | L14: 0.083
A15: D&A (negative) | B15: -17.1 | C15: =-C6*C14 | D15: =-D6*D14 | E15: =-E6*E14 | F15: =-F6*F14 | G15: =-G6*G14 | H15: =-H6*H14 | I15: =-I6*I14 | J15: =-J6*J14 | ... L15: =-L6*L14
A16: EBIT | B16: =B13+B15 | C16: =C13+C15 | D16: =D13+D15 | E16: =E13+E15 | F16: =F13+F15 | G16: =G13+G15 | H16: =H13+H15 | I16: =I13+I15 | ... L16: =L13+L15
A17: Cash tax rate | C17: 0.05 | D17: 0.05 | E17: 0.08 | F17: 0.12 | G17: 0.16 | H17: 0.2 | I17: 0.24 | J17: 0.28 | K17: 0.28 | L17: 0.28
A18: Cash tax on MAX(0,EBIT) (negative) | C18: =-MAX(0,C16)*C17 | D18: =-MAX(0,D16)*D17 | E18: =-MAX(0,E16)*E17 | F18: =-MAX(0,F16)*F17 | G18: =-MAX(0,G16)*G17 | H18: =-MAX(0,H16)*H17 | I18: =-MAX(0,I16)*I17 | J18: =-MAX(0,J16)*J17 | ... L18: =-MAX(0,L16)*L17
A19: NOPAT | C19: =C16+C18 | D19: =D16+D18 | E19: =E16+E18 | F19: =F16+F18 | G19: =G16+G18 | H19: =H16+H18 | I19: =I16+I18 | J19: =J16+J18 | ... L19: =L16+L18
A20: Add back D&A | C20: =-C15 | D20: =-D15 | E20: =-E15 | F20: =-F15 | G20: =-G15 | H20: =-H15 | I20: =-I15 | J20: =-J15 | ... L20: =-L15
A21: Capex % of revenue (incl capitalised software) | B21: =-B22/B6 | C21: 0.14 | D21: 0.13 | E21: 0.12 | F21: 0.11 | G21: 0.1 | H21: 0.095 | I21: 0.09 | J21: 0.085 | K21: 0.08 | L21: 0.08
A22: Capex (negative) | B22: -21.1 | C22: =-C6*C21 | D22: =-D6*D21 | E22: =-E6*E21 | F22: =-F6*F21 | G22: =-G6*G21 | H22: =-H6*H21 | I22: =-I6*I21 | J22: =-J6*J21 | ... L22: =-L6*L21
A23: Working capital (capture x revenue change) | C23: =Assumptions!$B$11*(C6-B6) | D23: =Assumptions!$B$11*(D6-C6) | E23: =Assumptions!$B$11*(E6-D6) | F23: =Assumptions!$B$11*(F6-E6) | G23: =Assumptions!$B$11*(G6-F6) | H23: =Assumptions!$B$11*(H6-G6) | I23: =Assumptions!$B$11*(I6-H6) | J23: =Assumptions!$B$11*(J6-I6) | ... L23: =Assumptions!$B$11*(L6-K6)
A24: Unlevered owner FCF | B24: 1 | C24: =C19+C20+C22+C23 | D24: =D19+D20+D22+D23 | E24: =E19+E20+E22+E23 | F24: =F19+F20+F22+F23 | G24: =G19+G20+G22+G23 | H24: =H19+H20+H22+H23 | I24: =I19+I20+I22+I23 | J24: =J19+J20+J22+J23 | ... L24: =L19+L20+L22+L23
A25: Discount factor | C25: =1/(1+Assumptions!$B$8)^C4 | D25: =1/(1+Assumptions!$B$8)^D4 | E25: =1/(1+Assumptions!$B$8)^E4 | F25: =1/(1+Assumptions!$B$8)^F4 | G25: =1/(1+Assumptions!$B$8)^G4 | H25: =1/(1+Assumptions!$B$8)^H4 | I25: =1/(1+Assumptions!$B$8)^I4 | J25: =1/(1+Assumptions!$B$8)^J4 | ... L25: =1/(1+Assumptions!$B$8)^L4
A26: PV of FCF | C26: =C24*C25 | D26: =D24*D25 | E26: =E24*E25 | F26: =F24*F25 | G26: =G24*G25 | H26: =H24*H25 | I26: =I24*I25 | J26: =J24*J25 | ... L26: =L24*L25
A28: Memo: FCF before SBC (company-style) | C28: =C24-C10 | D28: =D24-D10 | E28: =E24-E10 | F28: =F24-F10 | G28: =G24-G10 | H28: =H24-H10 | I28: =I24-I10 | J28: =J24-J10 | ... L28: =L24-L10
A29: Memo: owner FCF margin | B29: =B24/B6 | C29: =C24/C6 | D29: =D24/D6 | E29: =E24/E6 | F29: =F24/F6 | G29: =G24/G6 | H29: =H24/H6 | I29: =I24/I6 | ... L29: =L24/L6
A31: Sum of PV of FCF | B31: =SUM(C26:L26)
A32: Terminal growth | B32: =Assumptions!$C$15
A33: Terminal-year FCF x (1+g) | B33: =L24*(1+B32)
A34: Gordon terminal value | B34: =IF(Assumptions!$B$8>B32,B33/(Assumptions!$B$8-B32),0)
A35: Cap terminal value (cap x FCF10) | B35: =Assumptions!$B$10*L24
A36: Terminal value used = MAX(0,MIN(Gordon,cap)) | B36: =MAX(0,MIN(B34,B35))
A37: Implied exit multiple (TV / FCF10) | B37: =IF(L24<>0,B36/L24,0)
A38: PV of terminal value | B38: =B36*L25
A39: Enterprise value | B39: =B31+B38
A40: Less net debt (bank net debt + NCI) | B40: =-Assumptions!$B$6
A41: Equity value | B41: =B39+B40
A42: Diluted shares (m) | B42: =Assumptions!$B$3
A43: VALUE PER SHARE (NZD) | B43: =B41/B42
...

Sheet DCF_Bull
A1: DCF -- Bull scenario (NZ$m; per share NZD)
A3: Year | B3: 2025A | C3: 2026E | D3: 2027E | E3: 2028E | F3: 2029E | G3: 2030E | H3: 2031E | I3: 2032E | J3: 2033E | K3: 2034E | L3: 2035E
A4: Index | B4: 0 | C4: 1 | D4: 2 | E4: 3 | F4: 4 | G4: 5 | H4: 6 | I4: 7 | J4: 8 | K4: 9 | L4: 10
A5: Revenue growth YoY | C5: 0.12 | D5: 0.13 | E5: 0.13 | F5: 0.12 | G5: 0.11 | H5: 0.09 | I5: 0.08 | J5: 0.065 | K5: 0.05 | L5: 0.04
A6: Revenue | B6: =Assumptions!$B$7 | C6: =B6*(1+C5) | D6: =C6*(1+D5) | E6: =D6*(1+E5) | F6: =E6*(1+F5) | G6: =F6*(1+G5) | H6: =G6*(1+H5) | I6: =H6*(1+I5) | J6: =I6*(1+J5) | ... L6: =K6*(1+L5)
A7: Adj EBITDA margin (post-IFRS16) | B7: =B8/B6 | C7: 0.19 | D7: 0.205 | E7: 0.22 | F7: 0.235 | G7: 0.25 | H7: 0.265 | I7: 0.28 | J7: 0.29 | K7: 0.295 | L7: 0.3
A8: Adjusted EBITDA | B8: 28.2 | C8: =C6*C7 | D8: =D6*D7 | E8: =E6*E7 | F8: =F6*F7 | G8: =G6*G7 | H8: =H6*H7 | I8: =I6*I7 | J8: =J6*J7 | ... L8: =L6*L7
A9: SBC % of revenue | B9: =-B10/B6 | C9: 0.005 | D9: 0.005 | E9: 0.005 | F9: 0.005 | G9: 0.005 | H9: 0.005 | I9: 0.005 | J9: 0.005 | K9: 0.005 | L9: 0.005
A10: SBC (negative) | B10: -0.9 | C10: =-C6*C9 | D10: =-D6*D9 | E10: =-E6*E9 | F10: =-F6*F9 | G10: =-G6*G9 | H10: =-H6*H9 | I10: =-I6*I9 | J10: =-J6*J9 | ... L10: =-L6*L9
A11: Lease cash % of revenue | B11: =-B12/B6 | C11: 0.04 | D11: 0.038 | E11: 0.036 | F11: 0.034 | G11: 0.032 | H11: 0.03 | I11: 0.028 | J11: 0.027 | K11: 0.026 | L11: 0.025
A12: Lease cash (negative) | B12: -6.8 | C12: =-C6*C11 | D12: =-D6*D11 | E12: =-E6*E11 | F12: =-F6*F11 | G12: =-G6*G11 | H12: =-H6*H11 | I12: =-I6*I11 | J12: =-J6*J11 | ... L12: =-L6*L11
A13: Owner EBITDA (after SBC, lease) | B13: =B8+B10+B12 | C13: =C8+C10+C12 | D13: =D8+D10+D12 | E13: =E8+E10+E12 | F13: =F8+F10+F12 | G13: =G8+G10+G12 | H13: =H8+H10+H12 | I13: =I8+I10+I12 | ... L13: =L8+L10+L12
A14: D&A % of revenue (ex ROU) | B14: =-B15/B6 | C14: 0.104 | D14: 0.103 | E14: 0.101 | F14: 0.098 | G14: 0.094 | H14: 0.09 | I14: 0.086 | J14: 0.082 | K14: 0.079 | L14: 0.077
A15: D&A (negative) | B15: -17.1 | C15: =-C6*C14 | D15: =-D6*D14 | E15: =-E6*E14 | F15: =-F6*F14 | G15: =-G6*G14 | H15: =-H6*H14 | I15: =-I6*I14 | J15: =-J6*J14 | ... L15: =-L6*L14
A16: EBIT | B16: =B13+B15 | C16: =C13+C15 | D16: =D13+D15 | E16: =E13+E15 | F16: =F13+F15 | G16: =G13+G15 | H16: =H13+H15 | I16: =I13+I15 | ... L16: =L13+L15
A17: Cash tax rate | C17: 0.05 | D17: 0.05 | E17: 0.08 | F17: 0.12 | G17: 0.16 | H17: 0.2 | I17: 0.24 | J17: 0.28 | K17: 0.28 | L17: 0.28
A18: Cash tax on MAX(0,EBIT) (negative) | C18: =-MAX(0,C16)*C17 | D18: =-MAX(0,D16)*D17 | E18: =-MAX(0,E16)*E17 | F18: =-MAX(0,F16)*F17 | G18: =-MAX(0,G16)*G17 | H18: =-MAX(0,H16)*H17 | I18: =-MAX(0,I16)*I17 | J18: =-MAX(0,J16)*J17 | ... L18: =-MAX(0,L16)*L17
A19: NOPAT | C19: =C16+C18 | D19: =D16+D18 | E19: =E16+E18 | F19: =F16+F18 | G19: =G16+G18 | H19: =H16+H18 | I19: =I16+I18 | J19: =J16+J18 | ... L19: =L16+L18
A20: Add back D&A | C20: =-C15 | D20: =-D15 | E20: =-E15 | F20: =-F15 | G20: =-G15 | H20: =-H15 | I20: =-I15 | J20: =-J15 | ... L20: =-L15
A21: Capex % of revenue (incl capitalised software) | B21: =-B22/B6 | C21: 0.14 | D21: 0.125 | E21: 0.115 | F21: 0.105 | G21: 0.095 | H21: 0.085 | I21: 0.08 | J21: 0.075 | K21: 0.075 | L21: 0.075
A22: Capex (negative) | B22: -21.1 | C22: =-C6*C21 | D22: =-D6*D21 | E22: =-E6*E21 | F22: =-F6*F21 | G22: =-G6*G21 | H22: =-H6*H21 | I22: =-I6*I21 | J22: =-J6*J21 | ... L22: =-L6*L21
A23: Working capital (capture x revenue change) | C23: =Assumptions!$B$11*(C6-B6) | D23: =Assumptions!$B$11*(D6-C6) | E23: =Assumptions!$B$11*(E6-D6) | F23: =Assumptions!$B$11*(F6-E6) | G23: =Assumptions!$B$11*(G6-F6) | H23: =Assumptions!$B$11*(H6-G6) | I23: =Assumptions!$B$11*(I6-H6) | J23: =Assumptions!$B$11*(J6-I6) | ... L23: =Assumptions!$B$11*(L6-K6)
A24: Unlevered owner FCF | B24: 1 | C24: =C19+C20+C22+C23 | D24: =D19+D20+D22+D23 | E24: =E19+E20+E22+E23 | F24: =F19+F20+F22+F23 | G24: =G19+G20+G22+G23 | H24: =H19+H20+H22+H23 | I24: =I19+I20+I22+I23 | J24: =J19+J20+J22+J23 | ... L24: =L19+L20+L22+L23
A25: Discount factor | C25: =1/(1+Assumptions!$B$8)^C4 | D25: =1/(1+Assumptions!$B$8)^D4 | E25: =1/(1+Assumptions!$B$8)^E4 | F25: =1/(1+Assumptions!$B$8)^F4 | G25: =1/(1+Assumptions!$B$8)^G4 | H25: =1/(1+Assumptions!$B$8)^H4 | I25: =1/(1+Assumptions!$B$8)^I4 | J25: =1/(1+Assumptions!$B$8)^J4 | ... L25: =1/(1+Assumptions!$B$8)^L4
A26: PV of FCF | C26: =C24*C25 | D26: =D24*D25 | E26: =E24*E25 | F26: =F24*F25 | G26: =G24*G25 | H26: =H24*H25 | I26: =I24*I25 | J26: =J24*J25 | ... L26: =L24*L25
A28: Memo: FCF before SBC (company-style) | C28: =C24-C10 | D28: =D24-D10 | E28: =E24-E10 | F28: =F24-F10 | G28: =G24-G10 | H28: =H24-H10 | I28: =I24-I10 | J28: =J24-J10 | ... L28: =L24-L10
A29: Memo: owner FCF margin | B29: =B24/B6 | C29: =C24/C6 | D29: =D24/D6 | E29: =E24/E6 | F29: =F24/F6 | G29: =G24/G6 | H29: =H24/H6 | I29: =I24/I6 | ... L29: =L24/L6
A31: Sum of PV of FCF | B31: =SUM(C26:L26)
A32: Terminal growth | B32: =Assumptions!$D$15
A33: Terminal-year FCF x (1+g) | B33: =L24*(1+B32)
A34: Gordon terminal value | B34: =IF(Assumptions!$B$8>B32,B33/(Assumptions!$B$8-B32),0)
A35: Cap terminal value (cap x FCF10) | B35: =Assumptions!$B$10*L24
A36: Terminal value used = MAX(0,MIN(Gordon,cap)) | B36: =MAX(0,MIN(B34,B35))
A37: Implied exit multiple (TV / FCF10) | B37: =IF(L24<>0,B36/L24,0)
A38: PV of terminal value | B38: =B36*L25
A39: Enterprise value | B39: =B31+B38
A40: Less net debt (bank net debt + NCI) | B40: =-Assumptions!$B$6
A41: Equity value | B41: =B39+B40
A42: Diluted shares (m) | B42: =Assumptions!$B$3
A43: VALUE PER SHARE (NZD) | B43: =B41/B42
...

Sheet FCF_Quality
A1: Reported FCF reconciled to unlevered owner FCF (NZ$m)
B2: FY2020 | C2: FY2021 | D2: FY2022 | E2: FY2023 | F2: FY2024 | G2: FY2025
A3: Revenue | B3: =Actuals!B2 | C3: =Actuals!C2 | D3: =Actuals!D2 | E3: =Actuals!E2 | F3: =Actuals!F2 | G3: =Actuals!G2
A4: Free cash flow (company definition: OCF - capex) | B4: =Actuals!B7 | C4: =Actuals!C7 | D4: =Actuals!D7 | E4: =Actuals!E7 | F4: =Actuals!F7 | G4: =Actuals!G7
A5: less: SBC incl. equity-award taxes | B5: =-Actuals!B8 | C5: =-Actuals!C8 | D5: =-Actuals!D8 | E5: =-Actuals!E8 | F5: =-Actuals!F8 | G5: =-Actuals!G8
A6: less: interest income | B6: =-Actuals!B9 | C6: =-Actuals!C9 | D6: =-Actuals!D9 | E6: =-Actuals!E9 | F6: =-Actuals!F9 | G6: =-Actuals!G9
A7: less: lease cash (principal + interest) | B7: =-Actuals!B10 | C7: =-Actuals!C10 | D7: =-Actuals!D10 | E7: =-Actuals!E10 | F7: =-Actuals!F10 | G7: =-Actuals!G10
A8: add: interest paid on borrowings (unlever; FY25 actual, earlier P&L proxy) | B8: =Actuals!B11 | C8: =Actuals!C11 | D8: =Actuals!D11 | E8: =Actuals!E11 | F8: =Actuals!F11 | G8: =Actuals!G11
A9: Owner FCF (unlevered) | B9: =B4+B5+B6+B7+B8 | C9: =C4+C5+C6+C7+C8 | D9: =D4+D5+D6+D7+D8 | E9: =E4+E5+E6+E7+E8 | F9: =F4+F5+F6+F7+F8 | G9: =G4+G5+G6+G7+G8
A10: Reported FCF margin | B10: =B4/B3 | C10: =C4/C3 | D10: =D4/D3 | E10: =E4/E3 | F10: =F4/F3 | G10: =G4/G3
A11: Owner FCF margin | B11: =B9/B3 | C11: =C9/C3 | D11: =D9/D3 | E11: =E9/E3 | F11: =F9/F3 | G11: =G9/G3
A12: Memo: deferred-revenue increase inside OCF | C12: =Actuals!C14-Actuals!B14 | D12: =Actuals!D14-Actuals!C14 | E12: =Actuals!E14-Actuals!D14 | F12: =Actuals!F14-Actuals!E14 | G12: =Actuals!G14-Actuals!F14
A13: Memo: deferred-revenue increase as % of reported FCF | C13: =IF(C4<>0,C12/C4,0) | D13: =IF(D4<>0,D12/D4,0) | E13: =IF(E4<>0,E12/E4,0) | F13: =IF(F4<>0,F12/F4,0) | G13: =IF(G4<>0,G12/G4,0)
A14: Memo: cash taxes paid | B14: =Actuals!B15 | C14: =Actuals!C15 | D14: =Actuals!D15 | E14: =Actuals!E15 | F14: =Actuals!F15 | G14: =Actuals!G15
A15: Memo: cash tax rate vs 28% statutory -- ABNORMAL (tax losses) | B15: shielded | C15: shielded | D15: shielded | E15: shielded | F15: shielded | G15: shielded

Sheet Valuation
A1: Valuation summary (NZD per share)
A2: Scenario | B2: Value/share | C2: Upside vs price | D2: Probability | E2: Street value/share | F2: Entry price @ hurdle
A3: Bear | B3: =DCF_Bear!$B$43 | C3: =B3/Assumptions!$B$2-1 | D3: =Assumptions!$B$16 | E3: =DCF_Bear!$B$49 | F3: =(SUMPRODUCT(DCF_Bear!$C$24:$L$24/(1+Assumptions!$B$9)^DCF_Bear!$C$4:$L$4)+MAX(0,MIN(DCF_Bear!$L$24*(1+Assumptions!$B$15)/(Assumptions!$B$9-Assumptions!$B$15),Assumptions!$B$10*DCF_Bear!$L$24))/(1+Assumptions!$B$9)^Assumptions!$B$12-Assumptions!$B$6)/Assumptions!$B$3
A4: Base | B4: =DCF_Base!$B$43 | C4: =B4/Assumptions!$B$2-1 | D4: =Assumptions!$C$16 | E4: =DCF_Base!$B$49 | F4: =(SUMPRODUCT(DCF_Base!$C$24:$L$24/(1+Assumptions!$B$9)^DCF_Base!$C$4:$L$4)+MAX(0,MIN(DCF_Base!$L$24*(1+Assumptions!$C$15)/(Assumptions!$B$9-Assumptions!$C$15),Assumptions!$B$10*DCF_Base!$L$24))/(1+Assumptions!$B$9)^Assumptions!$B$12-Assumptions!$B$6)/Assumptions!$B$3
A5: Bull | B5: =DCF_Bull!$B$43 | C5: =B5/Assumptions!$B$2-1 | D5: =Assumptions!$D$16 | E5: =DCF_Bull!$B$49 | F5: =(SUMPRODUCT(DCF_Bull!$C$24:$L$24/(1+Assumptions!$B$9)^DCF_Bull!$C$4:$L$4)+MAX(0,MIN(DCF_Bull!$L$24*(1+Assumptions!$D$15)/(Assumptions!$B$9-Assumptions!$D$15),Assumptions!$B$10*DCF_Bull!$L$24))/(1+Assumptions!$B$9)^Assumptions!$B$12-Assumptions!$B$6)/Assumptions!$B$3
A7: Probability-weighted value per share | B7: =SUMPRODUCT(B3:B5,D3:D5)
A8: Current price | B8: =Assumptions!$B$2
A9: Margin of safety (1 - price/weighted) | B9: =1-B8/B7
A10: Street weighted value per share | B10: =SUMPRODUCT(E3:E5,D3:D5)
A11: Band position (price - house)/(street - house) | B11: =IF(B10<>B7,(B8-B7)/(B10-B7),"n/a")
A12: Weighted 15%-hurdle entry price (buy below) | B12: =SUMPRODUCT(F3:F5,D3:D5)
A14: Required-return table (base case; TV rebuilt at each rate)
A15: Required return | B15: 0.09 | C15: 0.1 | D15: 0.11 | E15: 0.115 | F15: 0.12 | G15: 0.15 | H15: WACC row
A16: Value per share | B16: =(SUMPRODUCT(DCF_Base!$C$24:$L$24/(1+B$15)^DCF_Base!$C$4:$L$4)+MAX(0,MIN(DCF_Base!$L$24*(1+Assumptions!$C$15)/(B$15-Assumptions!$C$15),Assumptions!$B$10*DCF_Base!$L$24))/(1+B$15)^Assumptions!$B$12-Assumptions!$B$6)/Assumptions!$B$3 | C16: =(SUMPRODUCT(DCF_Base!$C$24:$L$24/(1+C$15)^DCF_Base!$C$4:$L$4)+MAX(0,MIN(DCF_Base!$L$24*(1+Assumptions!$C$15)/(C$15-Assumptions!$C$15),Assumptions!$B$10*DCF_Base!$L$24))/(1+C$15)^Assumptions!$B$12-Assumptions!$B$6)/Assumptions!$B$3 | D16: =(SUMPRODUCT(DCF_Base!$C$24:$L$24/(1+D$15)^DCF_Base!$C$4:$L$4)+MAX(0,MIN(DCF_Base!$L$24*(1+Assumptions!$C$15)/(D$15-Assumptions!$C$15),Assumptions!$B$10*DCF_Base!$L$24))/(1+D$15)^Assumptions!$B$12-Assumptions!$B$6)/Assumptions!$B$3 | E16: =(SUMPRODUCT(DCF_Base!$C$24:$L$24/(1+E$15)^DCF_Base!$C$4:$L$4)+MAX(0,MIN(DCF_Base!$L$24*(1+Assumptions!$C$15)/(E$15-Assumptions!$C$15),Assumptions!$B$10*DCF_Base!$L$24))/(1+E$15)^Assumptions!$B$12-Assumptions!$B$6)/Assumptions!$B$3 | F16: =(SUMPRODUCT(DCF_Base!$C$24:$L$24/(1+F$15)^DCF_Base!$C$4:$L$4)+MAX(0,MIN(DCF_Base!$L$24*(1+Assumptions!$C$15)/(F$15-Assumptions!$C$15),Assumptions!$B$10*DCF_Base!$L$24))/(1+F$15)^Assumptions!$B$12-Assumptions!$B$6)/Assumptions!$B$3 | G16: =(SUMPRODUCT(DCF_Base!$C$24:$L$24/(1+G$15)^DCF_Base!$C$4:$L$4)+MAX(0,MIN(DCF_Base!$L$24*(1+Assumptions!$C$15)/(G$15-Assumptions!$C$15),Assumptions!$B$10*DCF_Base!$L$24))/(1+G$15)^Assumptions!$B$12-Assumptions!$B$6)/Assumptions!$B$3 | H16: =(SUMPRODUCT(DCF_Base!$C$24:$L$24/(1+Assumptions!$B$8)^DCF_Base!$C$4:$L$4)+MAX(0,MIN(DCF_Base!$L$24*(1+Assumptions!$C$15)/(Assumptions!$B$8-Assumptions!$C$15),Assumptions!$B$10*DCF_Base!$L$24))/(1+Assumptions!$B$8)^Assumptions!$B$12-Assumptions!$B$6)/Assumptions!$B$3
A18: Sensitivity: WACC (rows) x terminal growth (columns), base case, NZD/share
B19: 0.02 | C19: 0.025 | D19: 0.03 | E19: 0.035 | F19: 0.04
A20: 0.095 | B20: =IF($A20>B$19,(SUMPRODUCT(DCF_Base!$C$24:$L$24/(1+$A20)^DCF_Base!$C$4:$L$4)+MAX(0,MIN(DCF_Base!$L$24*(1+B$19)/($A20-B$19),Assumptions!$B$10*DCF_Base!$L$24))/(1+$A20)^Assumptions!$B$12-Assumptions!$B$6)/Assumptions!$B$3,"n/a") | C20: =IF($A20>C$19,(SUMPRODUCT(DCF_Base!$C$24:$L$24/(1+$A20)^DCF_Base!$C$4:$L$4)+MAX(0,MIN(DCF_Base!$L$24*(1+C$19)/($A20-C$19),Assumptions!$B$10*DCF_Base!$L$24))/(1+$A20)^Assumptions!$B$12-Assumptions!$B$6)/Assumptions!$B$3,"n/a") | D20: =IF($A20>D$19,(SUMPRODUCT(DCF_Base!$C$24:$L$24/(1+$A20)^DCF_Base!$C$4:$L$4)+MAX(0,MIN(DCF_Base!$L$24*(1+D$19)/($A20-D$19),Assumptions!$B$10*DCF_Base!$L$24))/(1+$A20)^Assumptions!$B$12-Assumptions!$B$6)/Assumptions!$B$3,"n/a") | E20: =IF($A20>E$19,(SUMPRODUCT(DCF_Base!$C$24:$L$24/(1+$A20)^DCF_Base!$C$4:$L$4)+MAX(0,MIN(DCF_Base!$L$24*(1+E$19)/($A20-E$19),Assumptions!$B$10*DCF_Base!$L$24))/(1+$A20)^Assumptions!$B$12-Assumptions!$B$6)/Assumptions!$B$3,"n/a") | F20: =IF($A20>F$19,(SUMPRODUCT(DCF_Base!$C$24:$L$24/(1+$A20)^DCF_Base!$C$4:$L$4)+MAX(0,MIN(DCF_Base!$L$24*(1+F$19)/($A20-F$19),Assumptions!$B$10*DCF_Base!$L$24))/(1+$A20)^Assumptions!$B$12-Assumptions!$B$6)/Assumptions!$B$3,"n/a")
A21: 0.105 | B21: =IF($A21>B$19,(SUMPRODUCT(DCF_Base!$C$24:$L$24/(1+$A21)^DCF_Base!$C$4:$L$4)+MAX(0,MIN(DCF_Base!$L$24*(1+B$19)/($A21-B$19),Assumptions!$B$10*DCF_Base!$L$24))/(1+$A21)^Assumptions!$B$12-Assumptions!$B$6)/Assumptions!$B$3,"n/a") | C21: =IF($A21>C$19,(SUMPRODUCT(DCF_Base!$C$24:$L$24/(1+$A21)^DCF_Base!$C$4:$L$4)+MAX(0,MIN(DCF_Base!$L$24*(1+C$19)/($A21-C$19),Assumptions!$B$10*DCF_Base!$L$24))/(1+$A21)^Assumptions!$B$12-Assumptions!$B$6)/Assumptions!$B$3,"n/a") | D21: =IF($A21>D$19,(SUMPRODUCT(DCF_Base!$C$24:$L$24/(1+$A21)^DCF_Base!$C$4:$L$4)+MAX(0,MIN(DCF_Base!$L$24*(1+D$19)/($A21-D$19),Assumptions!$B$10*DCF_Base!$L$24))/(1+$A21)^Assumptions!$B$12-Assumptions!$B$6)/Assumptions!$B$3,"n/a") | E21: =IF($A21>E$19,(SUMPRODUCT(DCF_Base!$C$24:$L$24/(1+$A21)^DCF_Base!$C$4:$L$4)+MAX(0,MIN(DCF_Base!$L$24*(1+E$19)/($A21-E$19),Assumptions!$B$10*DCF_Base!$L$24))/(1+$A21)^Assumptions!$B$12-Assumptions!$B$6)/Assumptions!$B$3,"n/a") | F21: =IF($A21>F$19,(SUMPRODUCT(DCF_Base!$C$24:$L$24/(1+$A21)^DCF_Base!$C$4:$L$4)+MAX(0,MIN(DCF_Base!$L$24*(1+F$19)/($A21-F$19),Assumptions!$B$10*DCF_Base!$L$24))/(1+$A21)^Assumptions!$B$12-Assumptions!$B$6)/Assumptions!$B$3,"n/a")
A22: 0.115 | B22: =IF($A22>B$19,(SUMPRODUCT(DCF_Base!$C$24:$L$24/(1+$A22)^DCF_Base!$C$4:$L$4)+MAX(0,MIN(DCF_Base!$L$24*(1+B$19)/($A22-B$19),Assumptions!$B$10*DCF_Base!$L$24))/(1+$A22)^Assumptions!$B$12-Assumptions!$B$6)/Assumptions!$B$3,"n/a") | C22: =IF($A22>C$19,(SUMPRODUCT(DCF_Base!$C$24:$L$24/(1+$A22)^DCF_Base!$C$4:$L$4)+MAX(0,MIN(DCF_Base!$L$24*(1+C$19)/($A22-C$19),Assumptions!$B$10*DCF_Base!$L$24))/(1+$A22)^Assumptions!$B$12-Assumptions!$B$6)/Assumptions!$B$3,"n/a") | D22: =IF($A22>D$19,(SUMPRODUCT(DCF_Base!$C$24:$L$24/(1+$A22)^DCF_Base!$C$4:$L$4)+MAX(0,MIN(DCF_Base!$L$24*(1+D$19)/($A22-D$19),Assumptions!$B$10*DCF_Base!$L$24))/(1+$A22)^Assumptions!$B$12-Assumptions!$B$6)/Assumptions!$B$3,"n/a") | E22: =IF($A22>E$19,(SUMPRODUCT(DCF_Base!$C$24:$L$24/(1+$A22)^DCF_Base!$C$4:$L$4)+MAX(0,MIN(DCF_Base!$L$24*(1+E$19)/($A22-E$19),Assumptions!$B$10*DCF_Base!$L$24))/(1+$A22)^Assumptions!$B$12-Assumptions!$B$6)/Assumptions!$B$3,"n/a") | F22: =IF($A22>F$19,(SUMPRODUCT(DCF_Base!$C$24:$L$24/(1+$A22)^DCF_Base!$C$4:$L$4)+MAX(0,MIN(DCF_Base!$L$24*(1+F$19)/($A22-F$19),Assumptions!$B$10*DCF_Base!$L$24))/(1+$A22)^Assumptions!$B$12-Assumptions!$B$6)/Assumptions!$B$3,"n/a")
A23: 0.125 | B23: =IF($A23>B$19,(SUMPRODUCT(DCF_Base!$C$24:$L$24/(1+$A23)^DCF_Base!$C$4:$L$4)+MAX(0,MIN(DCF_Base!$L$24*(1+B$19)/($A23-B$19),Assumptions!$B$10*DCF_Base!$L$24))/(1+$A23)^Assumptions!$B$12-Assumptions!$B$6)/Assumptions!$B$3,"n/a") | C23: =IF($A23>C$19,(SUMPRODUCT(DCF_Base!$C$24:$L$24/(1+$A23)^DCF_Base!$C$4:$L$4)+MAX(0,MIN(DCF_Base!$L$24*(1+C$19)/($A23-C$19),Assumptions!$B$10*DCF_Base!$L$24))/(1+$A23)^Assumptions!$B$12-Assumptions!$B$6)/Assumptions!$B$3,"n/a") | D23: =IF($A23>D$19,(SUMPRODUCT(DCF_Base!$C$24:$L$24/(1+$A23)^DCF_Base!$C$4:$L$4)+MAX(0,MIN(DCF_Base!$L$24*(1+D$19)/($A23-D$19),Assumptions!$B$10*DCF_Base!$L$24))/(1+$A23)^Assumptions!$B$12-Assumptions!$B$6)/Assumptions!$B$3,"n/a") | E23: =IF($A23>E$19,(SUMPRODUCT(DCF_Base!$C$24:$L$24/(1+$A23)^DCF_Base!$C$4:$L$4)+MAX(0,MIN(DCF_Base!$L$24*(1+E$19)/($A23-E$19),Assumptions!$B$10*DCF_Base!$L$24))/(1+$A23)^Assumptions!$B$12-Assumptions!$B$6)/Assumptions!$B$3,"n/a") | F23: =IF($A23>F$19,(SUMPRODUCT(DCF_Base!$C$24:$L$24/(1+$A23)^DCF_Base!$C$4:$L$4)+MAX(0,MIN(DCF_Base!$L$24*(1+F$19)/($A23-F$19),Assumptions!$B$10*DCF_Base!$L$24))/(1+$A23)^Assumptions!$B$12-Assumptions!$B$6)/Assumptions!$B$3,"n/a")
A24: 0.135 | B24: =IF($A24>B$19,(SUMPRODUCT(DCF_Base!$C$24:$L$24/(1+$A24)^DCF_Base!$C$4:$L$4)+MAX(0,MIN(DCF_Base!$L$24*(1+B$19)/($A24-B$19),Assumptions!$B$10*DCF_Base!$L$24))/(1+$A24)^Assumptions!$B$12-Assumptions!$B$6)/Assumptions!$B$3,"n/a") | C24: =IF($A24>C$19,(SUMPRODUCT(DCF_Base!$C$24:$L$24/(1+$A24)^DCF_Base!$C$4:$L$4)+MAX(0,MIN(DCF_Base!$L$24*(1+C$19)/($A24-C$19),Assumptions!$B$10*DCF_Base!$L$24))/(1+$A24)^Assumptions!$B$12-Assumptions!$B$6)/Assumptions!$B$3,"n/a") | D24: =IF($A24>D$19,(SUMPRODUCT(DCF_Base!$C$24:$L$24/(1+$A24)^DCF_Base!$C$4:$L$4)+MAX(0,MIN(DCF_Base!$L$24*(1+D$19)/($A24-D$19),Assumptions!$B$10*DCF_Base!$L$24))/(1+$A24)^Assumptions!$B$12-Assumptions!$B$6)/Assumptions!$B$3,"n/a") | E24: =IF($A24>E$19,(SUMPRODUCT(DCF_Base!$C$24:$L$24/(1+$A24)^DCF_Base!$C$4:$L$4)+MAX(0,MIN(DCF_Base!$L$24*(1+E$19)/($A24-E$19),Assumptions!$B$10*DCF_Base!$L$24))/(1+$A24)^Assumptions!$B$12-Assumptions!$B$6)/Assumptions!$B$3,"n/a") | F24: =IF($A24>F$19,(SUMPRODUCT(DCF_Base!$C$24:$L$24/(1+$A24)^DCF_Base!$C$4:$L$4)+MAX(0,MIN(DCF_Base!$L$24*(1+F$19)/($A24-F$19),Assumptions!$B$10*DCF_Base!$L$24))/(1+$A24)^Assumptions!$B$12-Assumptions!$B$6)/Assumptions!$B$3,"n/a")
