Workbook

Sheet DCF Model
A1: HLG.NZ DCF Valuation Model (Base Case)
A2: Gray cells are INPUTS - adjust to see valuation change. 10-year horizon (margin not mature by Y5).
A4: KEY INPUTS
A5: Current Stock Price (NZD) | B5: 10.65
A6: Shares Outstanding (M) | B6: 59.649
A7: Cash & Equivalents (M) | B7: 58.3
A8: Total Debt excl. Leases (M) | B8: 0
A9: Net Debt (M) [debt - cash; leases excluded] | B9: =B8-B7 -> 0
A10: Reported FCF FY2025 (OCF - Capex, M) | B10: 72.8
A11: Less: Lease Principal Repayments (M) | B11: 30.141
A12: Less: Interest Income (M) | B12: 2
A13: Less: SBC (negligible, M) | B13: 0
A14: Base Year Owner FCF (M) | B14: =B10-B11-B12-B13 -> 0
A16: WACC | B16: 0.105
A17: Terminal Growth Rate | B17: 0.0225
A18: Terminal Cap Multiple (x FCF) | B18: 14
A19: Base Revenue FY2025 (M) | B19: 470.72072
A22: COMPONENT ASSUMPTIONS (BASE CASE)
B23: FY2026 | C23: FY2027 | D23: FY2028 | E23: FY2029 | F23: FY2030 | G23: FY2031 | H23: FY2032 | I23: FY2033 | J23: FY2034 | K23: FY2035
A24: Revenue Growth % | B24: 0.11 | C24: 0.09 | D24: 0.075 | E24: 0.065 | F24: 0.055 | G24: 0.05 | H24: 0.045 | I24: 0.043 | J24: 0.041 | K24: 0.04
A25: EBIT Margin % | B25: 0.133 | C25: 0.135 | D25: 0.137 | E25: 0.139 | F25: 0.14 | G25: 0.141 | H25: 0.142 | I25: 0.143 | J25: 0.144 | K25: 0.145
A26: D&A % of Revenue | B26: 0.086 | C26: 0.086 | D26: 0.086 | E26: 0.086 | F26: 0.086 | G26: 0.086 | H26: 0.086 | I26: 0.086 | J26: 0.086 | K26: 0.086
A27: Capex % of Revenue | B27: 0.038 | C27: 0.036 | D27: 0.034 | E27: 0.033 | F27: 0.033 | G27: 0.033 | H27: 0.033 | I27: 0.033 | J27: 0.033 | K27: 0.033
A28: Lease Principal % of Revenue | B28: 0.062 | C28: 0.061 | D28: 0.06 | E28: 0.059 | F28: 0.059 | G28: 0.058 | H28: 0.058 | I28: 0.058 | J28: 0.058 | K28: 0.058
A29: Lease Interest % of Revenue | B29: 0.01 | C29: 0.01 | D29: 0.01 | E29: 0.01 | F29: 0.01 | G29: 0.01 | H29: 0.01 | I29: 0.01 | J29: 0.01 | K29: 0.01
A30: Cash Tax Rate % | B30: 0.31 | C30: 0.305 | D30: 0.3 | E30: 0.3 | F30: 0.295 | G30: 0.29 | H30: 0.29 | I30: 0.29 | J30: 0.29 | K30: 0.29
A31: WC Capture % of Rev Growth (drag) | B31: -0.06
A33: PROJECTIONS (FORMULAS)
B34: FY2026 | C34: FY2027 | D34: FY2028 | E34: FY2029 | F34: FY2030 | G34: FY2031 | H34: FY2032 | I34: FY2033 | J34: FY2034 | K34: FY2035
A35: Revenue | B35: =$B$19*(1+B24) -> 0 | C35: =B35*(1+C24) -> 0 | D35: =C35*(1+D24) -> 0 | E35: =D35*(1+E24) -> 0 | F35: =E35*(1+F24) -> 0 | G35: =F35*(1+G24) -> 0 | H35: =G35*(1+H24) -> 0 | I35: =H35*(1+I24) -> 0 | J35: =I35*(1+J24) -> 0 | K35: =J35*(1+K24) -> 0
A36: EBIT | B36: =B35*B25 -> 0 | C36: =C35*C25 -> 0 | D36: =D35*D25 -> 0 | E36: =E35*E25 -> 0 | F36: =F35*F25 -> 0 | G36: =G35*G25 -> 0 | H36: =H35*H25 -> 0 | I36: =I35*I25 -> 0 | ... K36: =K35*K25 -> 0
A37: D&A | B37: =B35*B26 -> 0 | C37: =C35*C26 -> 0 | D37: =D35*D26 -> 0 | E37: =E35*E26 -> 0 | F37: =F35*F26 -> 0 | G37: =G35*G26 -> 0 | H37: =H35*H26 -> 0 | I37: =I35*I26 -> 0 | ... K37: =K35*K26 -> 0
A38: NOPAT (EBIT x (1-tax)) | B38: =B36*(1-B30) -> 0 | C38: =C36*(1-C30) -> 0 | D38: =D36*(1-D30) -> 0 | E38: =E36*(1-E30) -> 0 | F38: =F36*(1-F30) -> 0 | G38: =G36*(1-G30) -> 0 | H38: =H36*(1-H30) -> 0 | I38: =I36*(1-I30) -> 0 | ... K38: =K36*(1-K30) -> 0
A39: Capex | B39: =B35*B27 -> 0 | C39: =C35*C27 -> 0 | D39: =D35*D27 -> 0 | E39: =E35*E27 -> 0 | F39: =F35*F27 -> 0 | G39: =G35*G27 -> 0 | H39: =H35*H27 -> 0 | I39: =I35*I27 -> 0 | ... K39: =K35*K27 -> 0
A40: Lease Principal Repayment | B40: =B35*B28 -> 0 | C40: =C35*C28 -> 0 | D40: =D35*D28 -> 0 | E40: =E35*E28 -> 0 | F40: =F35*F28 -> 0 | G40: =G35*G28 -> 0 | H40: =H35*H28 -> 0 | I40: =I35*I28 -> 0 | ... K40: =K35*K28 -> 0
A41: Lease Interest (after-tax) | B41: =B35*B29*(1-B30) -> 0 | C41: =C35*C29*(1-C30) -> 0 | D41: =D35*D29*(1-D30) -> 0 | E41: =E35*E29*(1-E30) -> 0 | F41: =F35*F29*(1-F30) -> 0 | G41: =G35*G29*(1-G30) -> 0 | H41: =H35*H29*(1-H30) -> 0 | I41: =I35*I29*(1-I30) -> 0 | ... K41: =K35*K29*(1-K30) -> 0
A42: Working Capital (on rev change) | B42: =$B$31*(B35-$B$19) -> 0 | C42: =$B$31*(C35-B35) -> 0 | D42: =$B$31*(D35-C35) -> 0 | E42: =$B$31*(E35-D35) -> 0 | F42: =$B$31*(F35-E35) -> 0 | G42: =$B$31*(G35-F35) -> 0 | H42: =$B$31*(H35-G35) -> 0 | I42: =$B$31*(I35-H35) -> 0 | J42: =$B$31*(J35-I35) -> 0 | K42: =$B$31*(K35-J35) -> 0
A43: Owner FCF | B43: =B38+B37-B39-B40-B41+B42 -> 0 | C43: =C38+C37-C39-C40-C41+C42 -> 0 | D43: =D38+D37-D39-D40-D41+D42 -> 0 | E43: =E38+E37-E39-E40-E41+E42 -> 0 | F43: =F38+F37-F39-F40-F41+F42 -> 0 | G43: =G38+G37-G39-G40-G41+G42 -> 0 | H43: =H38+H37-H39-H40-H41+H42 -> 0 | I43: =I38+I37-I39-I40-I41+I42 -> 0 | ... K43: =K38+K37-K39-K40-K41+K42 -> 0
A44: Owner FCF Margin % | B44: =B43/B35 -> 0 | C44: =C43/C35 -> 0 | D44: =D43/D35 -> 0 | E44: =E43/E35 -> 0 | F44: =F43/F35 -> 0 | G44: =G43/G35 -> 0 | H44: =H43/H35 -> 0 | I44: =I43/I35 -> 0 | ... K44: =K43/K35 -> 0
A45: Discount Factor | B45: =1/(1+$B$16)^1 -> 0 | C45: =1/(1+$B$16)^2 -> 0 | D45: =1/(1+$B$16)^3 -> 0 | E45: =1/(1+$B$16)^4 -> 0 | F45: =1/(1+$B$16)^5 -> 0 | G45: =1/(1+$B$16)^6 -> 0 | H45: =1/(1+$B$16)^7 -> 0 | I45: =1/(1+$B$16)^8 -> 0 | J45: =1/(1+$B$16)^9 -> 0 | K45: =1/(1+$B$16)^10 -> 0
...

Sheet Sensitivity
A1: Sensitivity Analysis
A2: Intrinsic Value by WACC & Terminal Growth (Base Case, 10yr)
A4: WACC \ Term G | B4: 0.0125 | C4: 0.0175 | D4: 0.0225 | E4: 0.0275 | F4: 0.0325
A5: 0.085 | B5: =('DCF Model'!B43/(1+0.085)^1+'DCF Model'!C43/(1+0.085)^2+'DCF Model'!D43/(1+0.085)^3+'DCF Model'!E43/(1+0.085)^4+'DCF Model'!F43/(1+0.085)^5+'DCF Model'!G43/(1+0.085)^6+'DCF Model'!H43/(1+0.085)^7+'DCF Model'!I43/(1+0.085)^8+'DCF Model'!J43/(1+0.085)^9+'DCF Model'!K43/(1+0.085)^10+MIN(('DCF Model'!K43*(1+0.0125)/(0.085-0.0125)),('DCF Model'!K43*'DCF Model'!$B$18))/(1+0.085)^10-'DCF Model'!$B$9)/'DCF Model'!$B$6 -> 0 | C5: =('DCF Model'!B43/(1+0.085)^1+'DCF Model'!C43/(1+0.085)^2+'DCF Model'!D43/(1+0.085)^3+'DCF Model'!E43/(1+0.085)^4+'DCF Model'!F43/(1+0.085)^5+'DCF Model'!G43/(1+0.085)^6+'DCF Model'!H43/(1+0.085)^7+'DCF Model'!I43/(1+0.085)^8+'DCF Model'!J43/(1+0.085)^9+'DCF Model'!K43/(1+0.085)^10+MIN(('DCF Model'!K43*(1+0.0175)/(0.085-0.0175)),('DCF Model'!K43*'DCF Model'!$B$18))/(1+0.085)^10-'DCF Model'!$B$9)/'DCF Model'!$B$6 -> 0 | D5: =('DCF Model'!B43/(1+0.085)^1+'DCF Model'!C43/(1+0.085)^2+'DCF Model'!D43/(1+0.085)^3+'DCF Model'!E43/(1+0.085)^4+'DCF Model'!F43/(1+0.085)^5+'DCF Model'!G43/(1+0.085)^6+'DCF Model'!H43/(1+0.085)^7+'DCF Model'!I43/(1+0.085)^8+'DCF Model'!J43/(1+0.085)^9+'DCF Model'!K43/(1+0.085)^10+MIN(('DCF Model'!K43*(1+0.0225)/(0.085-0.0225)),('DCF Model'!K43*'DCF Model'!$B$18))/(1+0.085)^10-'DCF Model'!$B$9)/'DCF Model'!$B$6 -> 0 | E5: =('DCF Model'!B43/(1+0.085)^1+'DCF Model'!C43/(1+0.085)^2+'DCF Model'!D43/(1+0.085)^3+'DCF Model'!E43/(1+0.085)^4+'DCF Model'!F43/(1+0.085)^5+'DCF Model'!G43/(1+0.085)^6+'DCF Model'!H43/(1+0.085)^7+'DCF Model'!I43/(1+0.085)^8+'DCF Model'!J43/(1+0.085)^9+'DCF Model'!K43/(1+0.085)^10+MIN(('DCF Model'!K43*(1+0.0275)/(0.085-0.0275)),('DCF Model'!K43*'DCF Model'!$B$18))/(1+0.085)^10-'DCF Model'!$B$9)/'DCF Model'!$B$6 -> 0 | F5: =('DCF Model'!B43/(1+0.085)^1+'DCF Model'!C43/(1+0.085)^2+'DCF Model'!D43/(1+0.085)^3+'DCF Model'!E43/(1+0.085)^4+'DCF Model'!F43/(1+0.085)^5+'DCF Model'!G43/(1+0.085)^6+'DCF Model'!H43/(1+0.085)^7+'DCF Model'!I43/(1+0.085)^8+'DCF Model'!J43/(1+0.085)^9+'DCF Model'!K43/(1+0.085)^10+MIN(('DCF Model'!K43*(1+0.0325)/(0.085-0.0325)),('DCF Model'!K43*'DCF Model'!$B$18))/(1+0.085)^10-'DCF Model'!$B$9)/'DCF Model'!$B$6 -> 0
A6: 0.095 | B6: =('DCF Model'!B43/(1+0.095)^1+'DCF Model'!C43/(1+0.095)^2+'DCF Model'!D43/(1+0.095)^3+'DCF Model'!E43/(1+0.095)^4+'DCF Model'!F43/(1+0.095)^5+'DCF Model'!G43/(1+0.095)^6+'DCF Model'!H43/(1+0.095)^7+'DCF Model'!I43/(1+0.095)^8+'DCF Model'!J43/(1+0.095)^9+'DCF Model'!K43/(1+0.095)^10+MIN(('DCF Model'!K43*(1+0.0125)/(0.095-0.0125)),('DCF Model'!K43*'DCF Model'!$B$18))/(1+0.095)^10-'DCF Model'!$B$9)/'DCF Model'!$B$6 -> 0 | C6: =('DCF Model'!B43/(1+0.095)^1+'DCF Model'!C43/(1+0.095)^2+'DCF Model'!D43/(1+0.095)^3+'DCF Model'!E43/(1+0.095)^4+'DCF Model'!F43/(1+0.095)^5+'DCF Model'!G43/(1+0.095)^6+'DCF Model'!H43/(1+0.095)^7+'DCF Model'!I43/(1+0.095)^8+'DCF Model'!J43/(1+0.095)^9+'DCF Model'!K43/(1+0.095)^10+MIN(('DCF Model'!K43*(1+0.0175)/(0.095-0.0175)),('DCF Model'!K43*'DCF Model'!$B$18))/(1+0.095)^10-'DCF Model'!$B$9)/'DCF Model'!$B$6 -> 0 | D6: =('DCF Model'!B43/(1+0.095)^1+'DCF Model'!C43/(1+0.095)^2+'DCF Model'!D43/(1+0.095)^3+'DCF Model'!E43/(1+0.095)^4+'DCF Model'!F43/(1+0.095)^5+'DCF Model'!G43/(1+0.095)^6+'DCF Model'!H43/(1+0.095)^7+'DCF Model'!I43/(1+0.095)^8+'DCF Model'!J43/(1+0.095)^9+'DCF Model'!K43/(1+0.095)^10+MIN(('DCF Model'!K43*(1+0.0225)/(0.095-0.0225)),('DCF Model'!K43*'DCF Model'!$B$18))/(1+0.095)^10-'DCF Model'!$B$9)/'DCF Model'!$B$6 -> 0 | E6: =('DCF Model'!B43/(1+0.095)^1+'DCF Model'!C43/(1+0.095)^2+'DCF Model'!D43/(1+0.095)^3+'DCF Model'!E43/(1+0.095)^4+'DCF Model'!F43/(1+0.095)^5+'DCF Model'!G43/(1+0.095)^6+'DCF Model'!H43/(1+0.095)^7+'DCF Model'!I43/(1+0.095)^8+'DCF Model'!J43/(1+0.095)^9+'DCF Model'!K43/(1+0.095)^10+MIN(('DCF Model'!K43*(1+0.0275)/(0.095-0.0275)),('DCF Model'!K43*'DCF Model'!$B$18))/(1+0.095)^10-'DCF Model'!$B$9)/'DCF Model'!$B$6 -> 0 | F6: =('DCF Model'!B43/(1+0.095)^1+'DCF Model'!C43/(1+0.095)^2+'DCF Model'!D43/(1+0.095)^3+'DCF Model'!E43/(1+0.095)^4+'DCF Model'!F43/(1+0.095)^5+'DCF Model'!G43/(1+0.095)^6+'DCF Model'!H43/(1+0.095)^7+'DCF Model'!I43/(1+0.095)^8+'DCF Model'!J43/(1+0.095)^9+'DCF Model'!K43/(1+0.095)^10+MIN(('DCF Model'!K43*(1+0.0325)/(0.095-0.0325)),('DCF Model'!K43*'DCF Model'!$B$18))/(1+0.095)^10-'DCF Model'!$B$9)/'DCF Model'!$B$6 -> 0
A7: 0.105 | B7: =('DCF Model'!B43/(1+0.105)^1+'DCF Model'!C43/(1+0.105)^2+'DCF Model'!D43/(1+0.105)^3+'DCF Model'!E43/(1+0.105)^4+'DCF Model'!F43/(1+0.105)^5+'DCF Model'!G43/(1+0.105)^6+'DCF Model'!H43/(1+0.105)^7+'DCF Model'!I43/(1+0.105)^8+'DCF Model'!J43/(1+0.105)^9+'DCF Model'!K43/(1+0.105)^10+MIN(('DCF Model'!K43*(1+0.0125)/(0.105-0.0125)),('DCF Model'!K43*'DCF Model'!$B$18))/(1+0.105)^10-'DCF Model'!$B$9)/'DCF Model'!$B$6 -> 0 | C7: =('DCF Model'!B43/(1+0.105)^1+'DCF Model'!C43/(1+0.105)^2+'DCF Model'!D43/(1+0.105)^3+'DCF Model'!E43/(1+0.105)^4+'DCF Model'!F43/(1+0.105)^5+'DCF Model'!G43/(1+0.105)^6+'DCF Model'!H43/(1+0.105)^7+'DCF Model'!I43/(1+0.105)^8+'DCF Model'!J43/(1+0.105)^9+'DCF Model'!K43/(1+0.105)^10+MIN(('DCF Model'!K43*(1+0.0175)/(0.105-0.0175)),('DCF Model'!K43*'DCF Model'!$B$18))/(1+0.105)^10-'DCF Model'!$B$9)/'DCF Model'!$B$6 -> 0 | D7: =('DCF Model'!B43/(1+0.105)^1+'DCF Model'!C43/(1+0.105)^2+'DCF Model'!D43/(1+0.105)^3+'DCF Model'!E43/(1+0.105)^4+'DCF Model'!F43/(1+0.105)^5+'DCF Model'!G43/(1+0.105)^6+'DCF Model'!H43/(1+0.105)^7+'DCF Model'!I43/(1+0.105)^8+'DCF Model'!J43/(1+0.105)^9+'DCF Model'!K43/(1+0.105)^10+MIN(('DCF Model'!K43*(1+0.0225)/(0.105-0.0225)),('DCF Model'!K43*'DCF Model'!$B$18))/(1+0.105)^10-'DCF Model'!$B$9)/'DCF Model'!$B$6 -> 0 | E7: =('DCF Model'!B43/(1+0.105)^1+'DCF Model'!C43/(1+0.105)^2+'DCF Model'!D43/(1+0.105)^3+'DCF Model'!E43/(1+0.105)^4+'DCF Model'!F43/(1+0.105)^5+'DCF Model'!G43/(1+0.105)^6+'DCF Model'!H43/(1+0.105)^7+'DCF Model'!I43/(1+0.105)^8+'DCF Model'!J43/(1+0.105)^9+'DCF Model'!K43/(1+0.105)^10+MIN(('DCF Model'!K43*(1+0.0275)/(0.105-0.0275)),('DCF Model'!K43*'DCF Model'!$B$18))/(1+0.105)^10-'DCF Model'!$B$9)/'DCF Model'!$B$6 -> 0 | F7: =('DCF Model'!B43/(1+0.105)^1+'DCF Model'!C43/(1+0.105)^2+'DCF Model'!D43/(1+0.105)^3+'DCF Model'!E43/(1+0.105)^4+'DCF Model'!F43/(1+0.105)^5+'DCF Model'!G43/(1+0.105)^6+'DCF Model'!H43/(1+0.105)^7+'DCF Model'!I43/(1+0.105)^8+'DCF Model'!J43/(1+0.105)^9+'DCF Model'!K43/(1+0.105)^10+MIN(('DCF Model'!K43*(1+0.0325)/(0.105-0.0325)),('DCF Model'!K43*'DCF Model'!$B$18))/(1+0.105)^10-'DCF Model'!$B$9)/'DCF Model'!$B$6 -> 0
A8: 0.115 | B8: =('DCF Model'!B43/(1+0.115)^1+'DCF Model'!C43/(1+0.115)^2+'DCF Model'!D43/(1+0.115)^3+'DCF Model'!E43/(1+0.115)^4+'DCF Model'!F43/(1+0.115)^5+'DCF Model'!G43/(1+0.115)^6+'DCF Model'!H43/(1+0.115)^7+'DCF Model'!I43/(1+0.115)^8+'DCF Model'!J43/(1+0.115)^9+'DCF Model'!K43/(1+0.115)^10+MIN(('DCF Model'!K43*(1+0.0125)/(0.115-0.0125)),('DCF Model'!K43*'DCF Model'!$B$18))/(1+0.115)^10-'DCF Model'!$B$9)/'DCF Model'!$B$6 -> 0 | C8: =('DCF Model'!B43/(1+0.115)^1+'DCF Model'!C43/(1+0.115)^2+'DCF Model'!D43/(1+0.115)^3+'DCF Model'!E43/(1+0.115)^4+'DCF Model'!F43/(1+0.115)^5+'DCF Model'!G43/(1+0.115)^6+'DCF Model'!H43/(1+0.115)^7+'DCF Model'!I43/(1+0.115)^8+'DCF Model'!J43/(1+0.115)^9+'DCF Model'!K43/(1+0.115)^10+MIN(('DCF Model'!K43*(1+0.0175)/(0.115-0.0175)),('DCF Model'!K43*'DCF Model'!$B$18))/(1+0.115)^10-'DCF Model'!$B$9)/'DCF Model'!$B$6 -> 0 | D8: =('DCF Model'!B43/(1+0.115)^1+'DCF Model'!C43/(1+0.115)^2+'DCF Model'!D43/(1+0.115)^3+'DCF Model'!E43/(1+0.115)^4+'DCF Model'!F43/(1+0.115)^5+'DCF Model'!G43/(1+0.115)^6+'DCF Model'!H43/(1+0.115)^7+'DCF Model'!I43/(1+0.115)^8+'DCF Model'!J43/(1+0.115)^9+'DCF Model'!K43/(1+0.115)^10+MIN(('DCF Model'!K43*(1+0.0225)/(0.115-0.0225)),('DCF Model'!K43*'DCF Model'!$B$18))/(1+0.115)^10-'DCF Model'!$B$9)/'DCF Model'!$B$6 -> 0 | E8: =('DCF Model'!B43/(1+0.115)^1+'DCF Model'!C43/(1+0.115)^2+'DCF Model'!D43/(1+0.115)^3+'DCF Model'!E43/(1+0.115)^4+'DCF Model'!F43/(1+0.115)^5+'DCF Model'!G43/(1+0.115)^6+'DCF Model'!H43/(1+0.115)^7+'DCF Model'!I43/(1+0.115)^8+'DCF Model'!J43/(1+0.115)^9+'DCF Model'!K43/(1+0.115)^10+MIN(('DCF Model'!K43*(1+0.0275)/(0.115-0.0275)),('DCF Model'!K43*'DCF Model'!$B$18))/(1+0.115)^10-'DCF Model'!$B$9)/'DCF Model'!$B$6 -> 0 | F8: =('DCF Model'!B43/(1+0.115)^1+'DCF Model'!C43/(1+0.115)^2+'DCF Model'!D43/(1+0.115)^3+'DCF Model'!E43/(1+0.115)^4+'DCF Model'!F43/(1+0.115)^5+'DCF Model'!G43/(1+0.115)^6+'DCF Model'!H43/(1+0.115)^7+'DCF Model'!I43/(1+0.115)^8+'DCF Model'!J43/(1+0.115)^9+'DCF Model'!K43/(1+0.115)^10+MIN(('DCF Model'!K43*(1+0.0325)/(0.115-0.0325)),('DCF Model'!K43*'DCF Model'!$B$18))/(1+0.115)^10-'DCF Model'!$B$9)/'DCF Model'!$B$6 -> 0
A9: 0.125 | B9: =('DCF Model'!B43/(1+0.125)^1+'DCF Model'!C43/(1+0.125)^2+'DCF Model'!D43/(1+0.125)^3+'DCF Model'!E43/(1+0.125)^4+'DCF Model'!F43/(1+0.125)^5+'DCF Model'!G43/(1+0.125)^6+'DCF Model'!H43/(1+0.125)^7+'DCF Model'!I43/(1+0.125)^8+'DCF Model'!J43/(1+0.125)^9+'DCF Model'!K43/(1+0.125)^10+MIN(('DCF Model'!K43*(1+0.0125)/(0.125-0.0125)),('DCF Model'!K43*'DCF Model'!$B$18))/(1+0.125)^10-'DCF Model'!$B$9)/'DCF Model'!$B$6 -> 0 | C9: =('DCF Model'!B43/(1+0.125)^1+'DCF Model'!C43/(1+0.125)^2+'DCF Model'!D43/(1+0.125)^3+'DCF Model'!E43/(1+0.125)^4+'DCF Model'!F43/(1+0.125)^5+'DCF Model'!G43/(1+0.125)^6+'DCF Model'!H43/(1+0.125)^7+'DCF Model'!I43/(1+0.125)^8+'DCF Model'!J43/(1+0.125)^9+'DCF Model'!K43/(1+0.125)^10+MIN(('DCF Model'!K43*(1+0.0175)/(0.125-0.0175)),('DCF Model'!K43*'DCF Model'!$B$18))/(1+0.125)^10-'DCF Model'!$B$9)/'DCF Model'!$B$6 -> 0 | D9: =('DCF Model'!B43/(1+0.125)^1+'DCF Model'!C43/(1+0.125)^2+'DCF Model'!D43/(1+0.125)^3+'DCF Model'!E43/(1+0.125)^4+'DCF Model'!F43/(1+0.125)^5+'DCF Model'!G43/(1+0.125)^6+'DCF Model'!H43/(1+0.125)^7+'DCF Model'!I43/(1+0.125)^8+'DCF Model'!J43/(1+0.125)^9+'DCF Model'!K43/(1+0.125)^10+MIN(('DCF Model'!K43*(1+0.0225)/(0.125-0.0225)),('DCF Model'!K43*'DCF Model'!$B$18))/(1+0.125)^10-'DCF Model'!$B$9)/'DCF Model'!$B$6 -> 0 | E9: =('DCF Model'!B43/(1+0.125)^1+'DCF Model'!C43/(1+0.125)^2+'DCF Model'!D43/(1+0.125)^3+'DCF Model'!E43/(1+0.125)^4+'DCF Model'!F43/(1+0.125)^5+'DCF Model'!G43/(1+0.125)^6+'DCF Model'!H43/(1+0.125)^7+'DCF Model'!I43/(1+0.125)^8+'DCF Model'!J43/(1+0.125)^9+'DCF Model'!K43/(1+0.125)^10+MIN(('DCF Model'!K43*(1+0.0275)/(0.125-0.0275)),('DCF Model'!K43*'DCF Model'!$B$18))/(1+0.125)^10-'DCF Model'!$B$9)/'DCF Model'!$B$6 -> 0 | F9: =('DCF Model'!B43/(1+0.125)^1+'DCF Model'!C43/(1+0.125)^2+'DCF Model'!D43/(1+0.125)^3+'DCF Model'!E43/(1+0.125)^4+'DCF Model'!F43/(1+0.125)^5+'DCF Model'!G43/(1+0.125)^6+'DCF Model'!H43/(1+0.125)^7+'DCF Model'!I43/(1+0.125)^8+'DCF Model'!J43/(1+0.125)^9+'DCF Model'!K43/(1+0.125)^10+MIN(('DCF Model'!K43*(1+0.0325)/(0.125-0.0325)),('DCF Model'!K43*'DCF Model'!$B$18))/(1+0.125)^10-'DCF Model'!$B$9)/'DCF Model'!$B$6 -> 0

Sheet FCF Quality
A1: FCF Quality: Reported vs Owner FCF Reconciliation
A2: IFRS 16 adopted FY2020: reported FCF post-2019 excludes rent (now financing outflow). Owner FCF restores rent as a cash cost via actual lease principal repayments.
B4: FY2017 | C4: FY2018 | D4: FY2019 | E4: FY2020 | F4: FY2021 | G4: FY2022 | H4: FY2023 | I4: FY2024 | J4: FY2025
A5: Revenue | B5: 239 | C5: 277.6 | D5: 287.6 | E5: 287.8 | F5: 350.8 | G5: 351.2 | H5: 409.7 | I5: 435.6 | J5: 470.7
A6: Reported FCF (OCF - Capex) | B6: 17.1 | C6: 26 | D6: 15.8 | E6: 59.5 | F6: 53.5 | G6: 44.2 | H6: 53.2 | I6: 69.4 | J6: 72.8
A7: less: Lease Principal Repayment | B7: 0 | C7: 0 | D7: 0 | E7: 16.992 | F7: 25.411 | G7: 23.762 | H7: 28.083 | I7: 27.896 | J7: 30.141
A8: less: Interest Income | B8: 0.2 | C8: 0.2 | D8: 0.2 | E8: 0.1 | F8: 0.1 | G8: 0.2 | H8: 1.2 | I8: 2 | J8: 2
A9: less: SBC (negligible) | B9: 0.1 | C9: 0.1 | D9: 0.1 | E9: 0 | F9: 0.1 | G9: 0.2 | H9: 0.1 | I9: 0 | J9: 0
A10: Owner FCF | B10: 16.8 | C10: 25.7 | D10: 15.5 | E10: 42.408 | F10: 27.889 | G10: 20.038 | H10: 23.817 | I10: 39.504 | J10: 40.659
A11: Reported FCF Margin % | B11: 0.071548117 | C11: 0.093659942 | D11: 0.054937413 | E11: 0.20674079 | F11: 0.15250855 | G11: 0.12585421 | H11: 0.12985111 | I11: 0.15932048 | J11: 0.15466327
A12: Owner FCF Margin % | B12: 0.070292887 | C12: 0.092579251 | D12: 0.053894298 | E12: 0.14735233 | F12: 0.07950114 | G12: 0.057055809 | H12: 0.05813278 | I12: 0.090688705 | J12: 0.08637986
A14: Memo: NPAT (sanity check) | B14: 17.3 | C14: 27.4 | D14: 29 | E14: 27.8 | F14: 33.3 | G14: 25.6 | H14: 32 | I14: 34.5 | J14: 39.5
A15: Memo: Owner FCF / NPAT | B15: 0.97109827 | C15: 0.9379562 | D15: 0.53448276 | E15: 1.5254676 | F15: 0.83750751 | G15: 0.78273438 | H15: 0.74428125 | I15: 1.1450435 | J15: 1.0293418
A16: Memo: Effective Cash Tax Rate % | I16: 0.338 | J16: 0.324
A18: Note: FY2020 owner FCF ($42.4m) exceeds NPAT ($27.8m) due to COVID-era working-capital conservation (inventory destocking, deferred capex) in the first IFRS16 transition year - not repeatable.

Sheet Historical
A1: Historical Growth Rates
A3: Metric | B3: 3-Year CAGR | C3: 5-Year CAGR
A4: Revenue | B4: 0.1025 | C4: 0.1034
A5: EPS | B5: 0.1535 | C5: 0.0703
A6: Equity/Book Value | B6: 0.0733 | C6: 0.0514
A7: Reported FCF | B7: 0.181 | C7: 0.0412
A8: Owner FCF | B8: 0.266 | C8: -0.0084
A10: Selected Growth Rate: | B10: 0.08
A11: Source: | B11: blend of equity_5yr_cagr (5.1%) and revenue/NPAT trend (~9-11%), weighted toward the conservative equity anchor but adjusted up given HLG's ~85% payout ratio structurally suppresses equity CAGR relative to true earnings power
A13: Divergence Warning:
A14: Equity 5yr CAGR (5.1%) diverges >30% from revenue 5yr CAGR (10.3%). This is NOT a quality red flag: HLG pays out ~80-90% of earnings as dividends (FY2025 DPS $0.51 / EPS $0.66), so retained earnings — and hence book value growth — mechanically lag revenue/earnings growth. Revenue and NPAT CAGRs are the more meaningful growth signals for this income-oriented compounder; equity CAGR understates growth because most profit leaves the balance sheet as dividends rather than being retained.
A19: Notes:
A20: Owner FCF CAGRs are noisy and not used as the primary growth anchor: the 5yr figure (-0.8%) is distorted by an unusually strong FY2020 (COVID-era inventory destocking + first year of IFRS16 transition creating one-off working-capital tailwinds), while the 3yr figure (26.6%) reflects rebound from the FY2022 trough (post-COVID reopening cost inflation, weak NZ consumer) to a record FY2025. Owner FCF broadly tracks NPAT ($40.7m owner FCF vs $39.5m NPAT in FY2025), confirming the lease-adjusted FCF series is sound; the DCF instead anchors forward growth on revenue/NPBT trends and NZ/AU apparel retail's structurally low-to-mid-single-digit long-run volume growth plus continued Australian expansion.

Sheet Model_Info
A1: Model Provenance & Methodology
A3: Ticker | B3: HLG.NZ - Hallenstein Glasson Holdings Limited
A4: Built by | B4: Claude DCF-analyst agent, per .claude/agents/dcf-analyst.md workflow
A5: Valuation date | B5: 2026-08-01
A6: Share price data vintage | B6: NZ$10.65, Yahoo Finance, 1 Aug 2026 (regularMarketPrice via chart API)
A7: Financial data vintage | B7: FY2025 Annual Report (year ended 1 Aug 2025) + H1-2026 interim report (6 months to 1 Feb 2026), plus FY2017-FY2025 annuals for history
A8: Horizon | B8: 10 years (FY2026-FY2035). Base-case owner-FCF margin was still rising at Year 5 (8.26%) vs Year 10 (8.86%) so the horizon was extended per the component-build maturity test.
A9: IFRS 16 lease adjustment | B9: Reported FCF (OCF-Capex) is inflated post-FY2020 because rent is excluded from OCF (moved to financing as lease principal repayments). Owner FCF deducts ACTUAL lease principal repayments per year, sourced from the financing-activities section of each Annual Report cash flow statement (Extracted/*.txt), converted from $000s to $m. Lease interest (finance expense) is also deducted after-tax in the projection build since it is a real cash cost of the lease-funded store network. Lease liabilities (~$76.6m FY2025) are EXCLUDED from net debt (operating obligations, not financial debt) to avoid double-counting since their cash service cost already sits inside owner FCF.
A10: SBC treatment | B10: Negligible ($0.0-0.2m/yr historically, no material LTI expense line) - no share dilution or SBC deduction from FCF is material. Documented as "sbc_source" in the JSON per the SBC-adjustment policy even though the amount essentially nets to zero.
A11: Net cash treatment | B11: Net cash was $58.3m FY2025 (no bank debt ever). Interest income ($2.0m FY2025) is stripped from owner FCF each year (net cash > owner FCF base) to avoid double-counting the cash pile (once via interest inside FCF, once via subtracting negative net debt in the EV bridge).
A12: Component margin build | B12: Owner FCF built from EBIT (already net of D&A incl. ROU depreciation) -> NOPAT at a normalizing cash tax rate (effective 32.4% FY25 -> ~29% blended NZ 28%/AU 30% as AU mix grows) -> add back D&A -> less capex -> less lease principal repayment -> less after-tax lease interest -> +/- working capital (modeled as a DRAG scaling with revenue GROWTH, not a tailwind, since HLG is an inventory-heavy apparel retailer with no deferred-revenue offset).
A13: Terminal value | B13: MIN of Gordon growth (WACC 10.5% base, terminal growth 2.25% base) and a 14x terminal-FCF cap (12-15x across scenarios, appropriate for a cyclical mature retailer). Gordon bound in all three scenarios (below the cap) in the base run; sensitivity table shows the cap flattening the low-WACC corner.
A14: WACC rationale | B14: Base WACC 10.5% reflects: NZ risk-free rate ~4.5-5.0%, NZ equity risk premium ~5.5-6.0%, HLG beta modestly above 1.0 given discretionary-retail/consumer-cyclical exposure, small-cap illiquidity premium for a ~NZ$635m market cap NZX stock, plus a ~0.5-1.0pp fashion/cyclical risk premium for unhedged USD sourcing exposure and intensifying online fast-fashion competition (Shein/Temu). No interest-bearing debt (lease liabilities excluded), so WACC ≈ cost of equity. Bull case uses a lower 10.0% WACC (established AU growth track record reduces execution risk); Bear case uses 11.5% (consumer recession + competitive share-loss risk both realized, raising required return).
... A18: Known limitations | B18: Owner FCF historical series is noisy (FY2020 COVID-era spike, FY2022 trough) - CAGRs on this series are not reliable growth anchors; revenue/NPAT CAGRs and component build are used instead. Effective tax rate includes permanent one-off items not expected to recur at the same magnitude - normalized path may differ from actual outturns. All figures go stale - always re-verify against the latest filings before relying on this model for investment decisions.
