Workbook

Sheet Model_Info
A1: ASX.AX -- ASX Limited owner-FCF DCF model
A2: Version | B2: 1.0, fresh build 2026-09-21 (no prior DCF for this ticker).
A3: Built by | B3: dcf-analyst agent (Claude Fable 5.1), 2026-09-21, at the request of the research-stock orchestrator for Stephen Williams.
A4: Companion file | B4: research/ASX.AX/Reports/ASX.AX_DCF.json -- the JSON is the published record; this workbook re-implements the same model with live formulas.
A5: Data vintage: price | B5: A$56.74 regular-session quote, Yahoo Finance, 2026-09-21T06:10:29Z regular session (Yahoo, AUD). Stale within days; refresh on Assumptions!B3.
A6: Data vintage: balance sheet | B6: 30 June 2026, ASX Limited Annual Report 2026 (notes 10, 11, 16, 19, 20, 25.2).
A7: Data vintage: share count | B7: 195,409,849 ordinary shares on issue at 30-Jun-2026 (AR FY26 five-year summary). Held flat; SBC expensed in flows.
A8: Data vintage: guidance | B8: FY26 results 13-Aug-2026: no numeric FY27 revenue/NPAT guidance; payout 75-85% (bottom of range for next two dividends); underlying ROE guidance 12-14% (May-2026); A$150m NTA charge by 30-Jun-2027.
A9: Methodology: model | B9: Owner-FCF DCF, component build, 10-year horizon, on an EQUITY-flow basis (net interest income inside EBITDA, FRN/lease interest charged in flows) discounted at the AUD cost of equity (9.0%). Rejected: earnings-at-CoE (hides A$120m/yr capex-over-D&A gap), reported FCF (participant margin flows make it meaningless).
A10: Methodology: revenue | B10: Segment operating revenue ex interest (A$1,254.6m FY26), the consistent 22-period series.
A11: Methodology: interest | B11: Collateral NII (A$46.2m) and interest on regulatory capital (A$46.2m) stay in flows as operating income; interest on the A$250.2m surplus own cash (A$9.4m) stripped because that cash is credited in the bridge; FRN/borrowing interest (A$18.9m) removed because the A$275m FRN is deducted in the bridge.
A12: Methodology: leases | B12: Treatment B: lease principal + interest (A$22.5m) deducted inside adj. EBITDA; lease liabilities (A$215.2m) excluded from net debt; tax-shield D&A excludes ROU depreciation.
A13: Methodology: net debt | B13: FRN A$275.0m - available own cash A$250.2m (own cash A$1,485.2m less regulatory/licence requirements A$1,235.0m) + ASIC NTA shortfall A$132.9m = A$157.7m. Consolidated cash (A$680.8m) and amounts owing to participants (A$9,161.5m) are NOT used.
... A20: Caveat | B20: All figures go stale. Text in this workbook never begins with '='. Sheet names contain no spaces.

Sheet Actuals
A1: Reported history (A$m, segment basis; source ASX.AX_Metrics.csv / annual reports)
A3: Metric | B3: FY2021 | C3: FY2022 | D3: FY2023 | E3: FY2024 | F3: FY2025 | G3: FY2026
A4: Operating revenue (segment, ex interest) | B4: 951.5 | C4: 1022.7 | D4: 1010.2 | E4: 1034.3 | F4: 1107.2 | G4: 1254.6
A5: Segment EBITDA (after SBC; FY26 incl A$30.8m ASIC Inquiry) | B5: 694.7 | C5: 739.5 | D5: 672.5 | E5: 641.8 | F5: 695.3 | G5: 765
A6: D&A (statutory) | B6: 55.5 | C6: 52.4 | D6: 39.1 | E6: 40 | F6: 49.3 | G6: 68.2
A7: Net interest income | B7: 46.7 | C7: 41.1 | D7: 70.8 | E7: 76.7 | F7: 86.8 | G7: 73.2
A8: Underlying NPAT | B8: 480.9 | C8: 508.5 | D8: 491.1 | E8: 474.2 | F8: 510 | G8: 536.4
A9: Statutory NPAT | B9: 480.9 | C9: 508.5 | D9: 317.3 | E9: 474.2 | F9: 502.6 | G9: 484.9
A10: Cash capex (CFS) | B10: 101.3 | C10: 105.8 | D10: 103.1 | E10: 137.8 | F10: 171.9 | G10: 189
A11: Lease principal paid (est. pre-FY25) | B11: 12 | C11: 12 | D11: 12 | E11: 13 | F11: 13.2 | G11: 12.8
A12: Reported OCF (incl participant flows) | B12: 5095 | C12: 203.4 | D12: -3404 | E12: 480.3 | F12: 302.9 | G12: 262.1
A13: Reported FCF = OCF - capex (UNUSABLE) | B13: 4993.7 | C13: 97.6 | D13: -3507.1 | E13: 342.5 | F13: 131 | G13: 73.1
A14: Underlying EPS (A$) | B14: 2.484 | C14: 2.627 | D14: 2.537 | E14: 2.448 | F14: 2.629 | G14: 2.758
A15: Dividend per share (A$) | B15: 2.236 | C15: 2.364 | D15: 2.283 | E15: 2.08 | F15: 2.233 | G15: 2.065
... A17: Shares on issue (m) | B17: 193.595 | C17: 193.595 | D17: 193.595 | E17: 193.888 | F17: 194.299 | G17: 195.41
A19: Balance-sheet snapshot 30-Jun-2026 (A$m)
A20: Cash and cash equivalents (consolidated, NOT used) | B20: 680.8
A21: Financial assets at amortised cost | B21: 9965.9
A22: Amounts owing to participants | B22: 9161.5
A23: ASX Group own cash + ST investments (note 25.2) | B23: 1485.2
A24: Regulatory capital + licence requirements | B24: 1235
A25: Available own cash | B25: 250.2
A26: Debt securities on issue (FRN, Feb-2027) | B26: 275
A27: Lease liabilities (excluded, treatment B) | B27: 215.2
A28: NTA | B28: 1056.8
A29: Minimum NTA by 30-Jun-2027 | B29: 1189.7
A30: ASIC NTA shortfall | B30: 132.9
A31: Regulatory capital FY26 / FY25 | B31: 1,154.0 / 1,134.0
A33: FY2026 owner-FCF component build (formulas)
A34: Segment EBITDA | B34: 765
A35: add: SBC (expensed in segment EBITDA) | B35: 17
A36: add: net interest on participant collateral | B36: 46.2
A37: add: interest on regulatory capital (55.6 gross less surplus share) | B37: 46.2
A38: less: lease principal + interest | B38: -22.5
A39: Adj EBITDA pre-SBC (owner basis) | B39: =SUM(B34:B38)
A40: less: SBC | B40: -17
A41: Owner EBITDA | B41: =B39+B40
A42: less: D&A ex ROU | B42: -48.2
A43: EBIT | B43: =B41+B42
A44: Cash tax 30% | B44: =-MAX(0,B43)*0.3
...

Sheet Assumptions
A1: Global assumptions (blue = input)
A3: Current price (A$) | B3: 56.74 | C3: 2026-09-21T06:10:29Z regular session (Yahoo, AUD)
A4: Price timestamp | B4: 2026-09-21T06:10:29Z regular session (Yahoo, AUD) | C4: Yahoo regular session
A5: Shares outstanding (m), flat | B5: 195.40985 | C5: Ordinary shares on issue 30-Jun-2026
A6: Net debt (A$m) | B6: 157.7 | C6: FRN 275.0 - available own cash 250.2 + ASIC NTA shortfall 132.9
A7: Balance sheet date | B7: 2026-06-30 | C7: FY26 annual report
A8: WC capture % of incremental revenue (regulatory capital build) | B8: -0.135 | C8: Negative: reg capital grows with the business; FY26 +20 on +147.4 revenue
A9: Terminal value cap (x FCF10) | B9: 20 | C9: House default 20x
A10: Hurdle rate (entry price) | B10: 0.15 | C10: 15% IRR
A11: FY2026 revenue (A$m) | B11: 1254.6 | C11: Segment operating revenue
A13: Scenario | B13: Cost of equity | C13: Terminal growth | D13: Probability
A14: Bear | B14: 0.09 | C14: 0.025 | D14: 0.25
A15: Base | B15: 0.09 | C15: 0.03 | D15: 0.5
A16: Bull | B16: 0.09 | C16: 0.035 | D16: 0.25
A17: Weights check (must be 100%) | D17: =SUM(D14:D16)
A19: Scenario narratives
A20: Bear | B20: Regulatory ratchet. CHESS Release 2 slips again (Drop 5 already moved to Oct-26), remediation and Accelerate spend persist, ASIC's 2025 access/pricing rules and TMX Australia (ex-Cboe, ~20% share) cap trading-fee economics, and FY26's record volumes mean-revert (flat revenue FY27, then 1.5-3%). Owner EBITDA margin compresses to 64-65% and never recovers; capex stays at 15% through FY28 and 10% thereafter. Capital charge not released. Terminal growth 2.5%.
A21: Base | B21: Franchise intact, costs stay elevated. Revenue +5%/yr near term (5-yr CAGR 5.7%), fading to 3% as FY26's record futures/cash-market volumes normalise but listings recover and super-pool growth continues. Owner EBITDA margin 68% in FY27 (FY26 ex-Inquiry 70.4% less continued Accelerate/technology cost growth and lower own-funds rates), recovering to 70% by FY32 once CHESS Release 2 is delivered (late FY28/FY29 assumed). Capex stays at 14-14.5% of revenue through FY28 then falls to a 9% run-rate; D&A rises to 8.5% as capitalised software amortises. Regulatory capital grows with the business; the A$132.9m ASIC NTA charge is treated as permanently locked (conservative).
A22: Bull | B22: New CEO delivers. Cost discipline arrives with the Attia/Accelerate reset, CHESS Release 2 lands on the revised timetable, ASIC releases the A$150m capital charge from FY28 and the payout returns to 80-90%. Revenue +8% in FY27 on sustained rate-volatility-driven derivatives volumes and a fuller IPO window, fading to 3.5%. Owner EBITDA margin recovers to 72% (FY16-19 segment margins were 70-71%). Capex normalises faster (8% by FY33). Terminal growth 3.5%.

Sheet DCF_Bear
A1: Bear scenario -- owner FCF, A$m
A2: Cost of equity | B2: =Assumptions!$B$14
A3: Year | B3: FY2026A | C3: FY2027E | D3: FY2028E | E3: FY2029E | F3: FY2030E | G3: FY2031E | H3: FY2032E | I3: FY2033E | J3: FY2034E | K3: FY2035E | L3: FY2036E
A4: Index | B4: 0 | C4: 1 | D4: 2 | E4: 3 | F4: 4 | G4: 5 | H4: 6 | I4: 7 | J4: 8 | K4: 9 | L4: 10
A5: Revenue growth YoY | C5: 0 | D5: 0.015 | E5: 0.025 | F5: 0.03 | G5: 0.03 | H5: 0.03 | I5: 0.025 | J5: 0.025 | K5: 0.025 | L5: 0.025
A6: Revenue | B6: 1254.6 | C6: =B6*(1+C5) | D6: =C6*(1+D5) | E6: =D6*(1+E5) | F6: =E6*(1+F5) | G6: =F6*(1+G5) | H6: =G6*(1+H5) | I6: =H6*(1+I5) | J6: =I6*(1+J5) | ... L6: =K6*(1+L5)
A7: Adj EBITDA margin (owner basis, pre-SBC) | B7: 0.67904791 | C7: 0.65 | D7: 0.64 | E7: 0.64 | F7: 0.645 | G7: 0.65 | H7: 0.65 | I7: 0.65 | J7: 0.65 | K7: 0.65 | L7: 0.65
A8: Adj EBITDA | B8: =B6*B7 | C8: =C6*C7 | D8: =D6*D7 | E8: =E6*E7 | F8: =F6*F7 | G8: =G6*G7 | H8: =H6*H7 | I8: =I6*I7 | ... L8: =L6*L7
A9: SBC % of revenue | B9: 0.013550136 | C9: 0.012 | D9: 0.012 | E9: 0.012 | F9: 0.012 | G9: 0.012 | H9: 0.012 | I9: 0.012 | J9: 0.012 | K9: 0.012 | L9: 0.012
A10: SBC | B10: =-B6*B9 | C10: =-C6*C9 | D10: =-D6*D9 | E10: =-E6*E9 | F10: =-F6*F9 | G10: =-G6*G9 | H10: =-H6*H9 | I10: =-I6*I9 | ... L10: =-L6*L9
A11: Owner EBITDA | B11: =B8+B10 | C11: =C8+C10 | D11: =D8+D10 | E11: =E8+E10 | F11: =F8+F10 | G11: =G8+G10 | H11: =H8+H10 | I11: =I8+I10 | ... L11: =L8+L10
A12: D&A ex ROU (tax shield) | B12: =-B6*B46 | C12: =-C6*C46 | D12: =-D6*D46 | E12: =-E6*E46 | F12: =-F6*F46 | G12: =-G6*G46 | H12: =-H6*H46 | I12: =-I6*I46 | ... L12: =-L6*L46
A13: EBIT | B13: =B11+B12 | C13: =C11+C12 | D13: =D11+D12 | E13: =E11+E12 | F13: =F11+F12 | G13: =G11+G12 | H13: =H11+H12 | I13: =I11+I12 | ... L13: =L11+L12
A14: Cash tax rate | B14: 0.3 | C14: 0.3 | D14: 0.3 | E14: 0.3 | F14: 0.3 | G14: 0.3 | H14: 0.3 | I14: 0.3 | J14: 0.3 | K14: 0.3 | L14: 0.3
A15: NOPAT | B15: =B13-MAX(0,B13)*B14 | C15: =C13-MAX(0,C13)*C14 | D15: =D13-MAX(0,D13)*D14 | E15: =E13-MAX(0,E13)*E14 | F15: =F13-MAX(0,F13)*F14 | G15: =G13-MAX(0,G13)*G14 | H15: =H13-MAX(0,H13)*H14 | I15: =I13-MAX(0,I13)*I14 | ... L15: =L13-MAX(0,L13)*L14
A16: add back D&A | B16: =-B12 | C16: =-C12 | D16: =-D12 | E16: =-E12 | F16: =-F12 | G16: =-G12 | H16: =-H12 | I16: =-I12 | ... L16: =-L12
A17: less capex | B17: =-B6*B47 | C17: =-C6*C47 | D17: =-D6*D47 | E17: =-E6*E47 | F17: =-F6*F47 | G17: =-G6*G47 | H17: =-H6*H47 | I17: =-I6*I47 | ... L17: =-L6*L47
A18: less regulatory capital build (WC) | B18: -20 | C18: =Assumptions!$B$8*(C6-B6) | D18: =Assumptions!$B$8*(D6-C6) | E18: =Assumptions!$B$8*(E6-D6) | F18: =Assumptions!$B$8*(F6-E6) | G18: =Assumptions!$B$8*(G6-F6) | H18: =Assumptions!$B$8*(H6-G6) | I18: =Assumptions!$B$8*(I6-H6) | J18: =Assumptions!$B$8*(J6-I6) | ... L18: =Assumptions!$B$8*(L6-K6)
A19: Owner FCF (post-interest) | B19: =B15+B16+B17+B18 | C19: =C15+C16+C17+C18 | D19: =D15+D16+D17+D18 | E19: =E15+E16+E17+E18 | F19: =F15+F16+F17+F18 | G19: =G15+G16+G17+G18 | H19: =H15+H16+H17+H18 | I19: =I15+I16+I17+I18 | ... L19: =L15+L16+L17+L18
A20: Discount factor | C20: =1/(1+$B$2)^C4 | D20: =1/(1+$B$2)^D4 | E20: =1/(1+$B$2)^E4 | F20: =1/(1+$B$2)^F4 | G20: =1/(1+$B$2)^G4 | H20: =1/(1+$B$2)^H4 | I20: =1/(1+$B$2)^I4 | J20: =1/(1+$B$2)^J4 | ... L20: =1/(1+$B$2)^L4
A21: PV of FCF | C21: =C19*C20 | D21: =D19*D20 | E21: =E19*E20 | F21: =F19*F20 | G21: =G19*G20 | H21: =H19*H20 | I21: =I19*I20 | J21: =J19*J20 | ... L21: =L19*L20
A23: Memo: FCF before SBC | B23: =B19-B10 | C23: =C19-C10 | D23: =D19-D10 | E23: =E19-E10 | F23: =F19-F10 | G23: =G19-G10 | H23: =H19-H10 | I23: =I19-I10 | ... L23: =L19-L10
A24: Memo: owner FCF margin | B24: =B19/B6 | C24: =C19/C6 | D24: =D19/D6 | E24: =E19/E6 | F24: =F19/F6 | G24: =G19/G6 | H24: =H19/H6 | I24: =I19/I6 | ... L24: =L19/L6
A26: Sum of PV (FY27-FY36) | B26: =SUM(C21:L21)
A27: Terminal growth | B27: =Assumptions!$C$14
A28: Terminal-year FCF x (1+g) | B28: =L19*(1+B27)
A29: Gordon TV | B29: =IF(B2>B27,B28/(B2-B27),0)
A30: Cap TV (cap x FCF10) | B30: =Assumptions!$B$9*L19
A31: TV used = MAX(0,MIN(Gordon,cap)) | B31: =MAX(0,MIN(B29,B30))
A32: Implied exit multiple (TV/FCF10) | B32: =IF(L19<>0,B31/L19,0)
A33: PV of TV | B33: =B31*L20
A34: Enterprise value (PV of equity flows) | B34: =B26+B33
A35: less net debt | B35: =-Assumptions!$B$6
A36: Equity value | B36: =B34+B35
A37: Shares (m) | B37: =Assumptions!$B$5
A38: VALUE PER SHARE (A$) | B38: =B36/B37
A39: Upside vs price | B39: =B38/Assumptions!$B$3-1
A41: Street memo: PV of explicit SBC | B41: =SUMPRODUCT(-C10:L10/(1+B2)^C4:L4)
A42: Street memo: PV of terminal SBC | B42: =IF(B2>B27,(-L10*(1+B27)/(B2-B27))*L20,0)
A43: Street value per share (A$) | B43: =(B36+B41+B42)/B37
...

Sheet DCF_Base
A1: Base scenario -- owner FCF, A$m
A2: Cost of equity | B2: =Assumptions!$B$15
A3: Year | B3: FY2026A | C3: FY2027E | D3: FY2028E | E3: FY2029E | F3: FY2030E | G3: FY2031E | H3: FY2032E | I3: FY2033E | J3: FY2034E | K3: FY2035E | L3: FY2036E
A4: Index | B4: 0 | C4: 1 | D4: 2 | E4: 3 | F4: 4 | G4: 5 | H4: 6 | I4: 7 | J4: 8 | K4: 9 | L4: 10
A5: Revenue growth YoY | C5: 0.05 | D5: 0.05 | E5: 0.045 | F5: 0.045 | G5: 0.04 | H5: 0.04 | I5: 0.035 | J5: 0.035 | K5: 0.03 | L5: 0.03
A6: Revenue | B6: 1254.6 | C6: =B6*(1+C5) | D6: =C6*(1+D5) | E6: =D6*(1+E5) | F6: =E6*(1+F5) | G6: =F6*(1+G5) | H6: =G6*(1+H5) | I6: =H6*(1+I5) | J6: =I6*(1+J5) | ... L6: =K6*(1+L5)
A7: Adj EBITDA margin (owner basis, pre-SBC) | B7: 0.67904791 | C7: 0.68 | D7: 0.68 | E7: 0.685 | F7: 0.69 | G7: 0.695 | H7: 0.7 | I7: 0.7 | J7: 0.7 | K7: 0.7 | L7: 0.7
A8: Adj EBITDA | B8: =B6*B7 | C8: =C6*C7 | D8: =D6*D7 | E8: =E6*E7 | F8: =F6*F7 | G8: =G6*G7 | H8: =H6*H7 | I8: =I6*I7 | ... L8: =L6*L7
A9: SBC % of revenue | B9: 0.013550136 | C9: 0.012 | D9: 0.012 | E9: 0.012 | F9: 0.012 | G9: 0.012 | H9: 0.012 | I9: 0.012 | J9: 0.012 | K9: 0.012 | L9: 0.012
A10: SBC | B10: =-B6*B9 | C10: =-C6*C9 | D10: =-D6*D9 | E10: =-E6*E9 | F10: =-F6*F9 | G10: =-G6*G9 | H10: =-H6*H9 | I10: =-I6*I9 | ... L10: =-L6*L9
A11: Owner EBITDA | B11: =B8+B10 | C11: =C8+C10 | D11: =D8+D10 | E11: =E8+E10 | F11: =F8+F10 | G11: =G8+G10 | H11: =H8+H10 | I11: =I8+I10 | ... L11: =L8+L10
A12: D&A ex ROU (tax shield) | B12: =-B6*B46 | C12: =-C6*C46 | D12: =-D6*D46 | E12: =-E6*E46 | F12: =-F6*F46 | G12: =-G6*G46 | H12: =-H6*H46 | I12: =-I6*I46 | ... L12: =-L6*L46
A13: EBIT | B13: =B11+B12 | C13: =C11+C12 | D13: =D11+D12 | E13: =E11+E12 | F13: =F11+F12 | G13: =G11+G12 | H13: =H11+H12 | I13: =I11+I12 | ... L13: =L11+L12
A14: Cash tax rate | B14: 0.3 | C14: 0.3 | D14: 0.3 | E14: 0.3 | F14: 0.3 | G14: 0.3 | H14: 0.3 | I14: 0.3 | J14: 0.3 | K14: 0.3 | L14: 0.3
A15: NOPAT | B15: =B13-MAX(0,B13)*B14 | C15: =C13-MAX(0,C13)*C14 | D15: =D13-MAX(0,D13)*D14 | E15: =E13-MAX(0,E13)*E14 | F15: =F13-MAX(0,F13)*F14 | G15: =G13-MAX(0,G13)*G14 | H15: =H13-MAX(0,H13)*H14 | I15: =I13-MAX(0,I13)*I14 | ... L15: =L13-MAX(0,L13)*L14
A16: add back D&A | B16: =-B12 | C16: =-C12 | D16: =-D12 | E16: =-E12 | F16: =-F12 | G16: =-G12 | H16: =-H12 | I16: =-I12 | ... L16: =-L12
A17: less capex | B17: =-B6*B47 | C17: =-C6*C47 | D17: =-D6*D47 | E17: =-E6*E47 | F17: =-F6*F47 | G17: =-G6*G47 | H17: =-H6*H47 | I17: =-I6*I47 | ... L17: =-L6*L47
A18: less regulatory capital build (WC) | B18: -20 | C18: =Assumptions!$B$8*(C6-B6) | D18: =Assumptions!$B$8*(D6-C6) | E18: =Assumptions!$B$8*(E6-D6) | F18: =Assumptions!$B$8*(F6-E6) | G18: =Assumptions!$B$8*(G6-F6) | H18: =Assumptions!$B$8*(H6-G6) | I18: =Assumptions!$B$8*(I6-H6) | J18: =Assumptions!$B$8*(J6-I6) | ... L18: =Assumptions!$B$8*(L6-K6)
A19: Owner FCF (post-interest) | B19: =B15+B16+B17+B18 | C19: =C15+C16+C17+C18 | D19: =D15+D16+D17+D18 | E19: =E15+E16+E17+E18 | F19: =F15+F16+F17+F18 | G19: =G15+G16+G17+G18 | H19: =H15+H16+H17+H18 | I19: =I15+I16+I17+I18 | ... L19: =L15+L16+L17+L18
A20: Discount factor | C20: =1/(1+$B$2)^C4 | D20: =1/(1+$B$2)^D4 | E20: =1/(1+$B$2)^E4 | F20: =1/(1+$B$2)^F4 | G20: =1/(1+$B$2)^G4 | H20: =1/(1+$B$2)^H4 | I20: =1/(1+$B$2)^I4 | J20: =1/(1+$B$2)^J4 | ... L20: =1/(1+$B$2)^L4
A21: PV of FCF | C21: =C19*C20 | D21: =D19*D20 | E21: =E19*E20 | F21: =F19*F20 | G21: =G19*G20 | H21: =H19*H20 | I21: =I19*I20 | J21: =J19*J20 | ... L21: =L19*L20
A23: Memo: FCF before SBC | B23: =B19-B10 | C23: =C19-C10 | D23: =D19-D10 | E23: =E19-E10 | F23: =F19-F10 | G23: =G19-G10 | H23: =H19-H10 | I23: =I19-I10 | ... L23: =L19-L10
A24: Memo: owner FCF margin | B24: =B19/B6 | C24: =C19/C6 | D24: =D19/D6 | E24: =E19/E6 | F24: =F19/F6 | G24: =G19/G6 | H24: =H19/H6 | I24: =I19/I6 | ... L24: =L19/L6
A26: Sum of PV (FY27-FY36) | B26: =SUM(C21:L21)
A27: Terminal growth | B27: =Assumptions!$C$15
A28: Terminal-year FCF x (1+g) | B28: =L19*(1+B27)
A29: Gordon TV | B29: =IF(B2>B27,B28/(B2-B27),0)
A30: Cap TV (cap x FCF10) | B30: =Assumptions!$B$9*L19
A31: TV used = MAX(0,MIN(Gordon,cap)) | B31: =MAX(0,MIN(B29,B30))
A32: Implied exit multiple (TV/FCF10) | B32: =IF(L19<>0,B31/L19,0)
A33: PV of TV | B33: =B31*L20
A34: Enterprise value (PV of equity flows) | B34: =B26+B33
A35: less net debt | B35: =-Assumptions!$B$6
A36: Equity value | B36: =B34+B35
A37: Shares (m) | B37: =Assumptions!$B$5
A38: VALUE PER SHARE (A$) | B38: =B36/B37
A39: Upside vs price | B39: =B38/Assumptions!$B$3-1
A41: Street memo: PV of explicit SBC | B41: =SUMPRODUCT(-C10:L10/(1+B2)^C4:L4)
A42: Street memo: PV of terminal SBC | B42: =IF(B2>B27,(-L10*(1+B27)/(B2-B27))*L20,0)
A43: Street value per share (A$) | B43: =(B36+B41+B42)/B37
...

Sheet DCF_Bull
A1: Bull scenario -- owner FCF, A$m
A2: Cost of equity | B2: =Assumptions!$B$16
A3: Year | B3: FY2026A | C3: FY2027E | D3: FY2028E | E3: FY2029E | F3: FY2030E | G3: FY2031E | H3: FY2032E | I3: FY2033E | J3: FY2034E | K3: FY2035E | L3: FY2036E
A4: Index | B4: 0 | C4: 1 | D4: 2 | E4: 3 | F4: 4 | G4: 5 | H4: 6 | I4: 7 | J4: 8 | K4: 9 | L4: 10
A5: Revenue growth YoY | C5: 0.08 | D5: 0.07 | E5: 0.065 | F5: 0.06 | G5: 0.055 | H5: 0.05 | I5: 0.045 | J5: 0.04 | K5: 0.04 | L5: 0.035
A6: Revenue | B6: 1254.6 | C6: =B6*(1+C5) | D6: =C6*(1+D5) | E6: =D6*(1+E5) | F6: =E6*(1+F5) | G6: =F6*(1+G5) | H6: =G6*(1+H5) | I6: =H6*(1+I5) | J6: =I6*(1+J5) | ... L6: =K6*(1+L5)
A7: Adj EBITDA margin (owner basis, pre-SBC) | B7: 0.67904791 | C7: 0.69 | D7: 0.695 | E7: 0.705 | F7: 0.71 | G7: 0.715 | H7: 0.72 | I7: 0.72 | J7: 0.72 | K7: 0.72 | L7: 0.72
A8: Adj EBITDA | B8: =B6*B7 | C8: =C6*C7 | D8: =D6*D7 | E8: =E6*E7 | F8: =F6*F7 | G8: =G6*G7 | H8: =H6*H7 | I8: =I6*I7 | ... L8: =L6*L7
A9: SBC % of revenue | B9: 0.013550136 | C9: 0.012 | D9: 0.012 | E9: 0.012 | F9: 0.012 | G9: 0.012 | H9: 0.012 | I9: 0.012 | J9: 0.012 | K9: 0.012 | L9: 0.012
A10: SBC | B10: =-B6*B9 | C10: =-C6*C9 | D10: =-D6*D9 | E10: =-E6*E9 | F10: =-F6*F9 | G10: =-G6*G9 | H10: =-H6*H9 | I10: =-I6*I9 | ... L10: =-L6*L9
A11: Owner EBITDA | B11: =B8+B10 | C11: =C8+C10 | D11: =D8+D10 | E11: =E8+E10 | F11: =F8+F10 | G11: =G8+G10 | H11: =H8+H10 | I11: =I8+I10 | ... L11: =L8+L10
A12: D&A ex ROU (tax shield) | B12: =-B6*B46 | C12: =-C6*C46 | D12: =-D6*D46 | E12: =-E6*E46 | F12: =-F6*F46 | G12: =-G6*G46 | H12: =-H6*H46 | I12: =-I6*I46 | ... L12: =-L6*L46
A13: EBIT | B13: =B11+B12 | C13: =C11+C12 | D13: =D11+D12 | E13: =E11+E12 | F13: =F11+F12 | G13: =G11+G12 | H13: =H11+H12 | I13: =I11+I12 | ... L13: =L11+L12
A14: Cash tax rate | B14: 0.3 | C14: 0.3 | D14: 0.3 | E14: 0.3 | F14: 0.3 | G14: 0.3 | H14: 0.3 | I14: 0.3 | J14: 0.3 | K14: 0.3 | L14: 0.3
A15: NOPAT | B15: =B13-MAX(0,B13)*B14 | C15: =C13-MAX(0,C13)*C14 | D15: =D13-MAX(0,D13)*D14 | E15: =E13-MAX(0,E13)*E14 | F15: =F13-MAX(0,F13)*F14 | G15: =G13-MAX(0,G13)*G14 | H15: =H13-MAX(0,H13)*H14 | I15: =I13-MAX(0,I13)*I14 | ... L15: =L13-MAX(0,L13)*L14
A16: add back D&A | B16: =-B12 | C16: =-C12 | D16: =-D12 | E16: =-E12 | F16: =-F12 | G16: =-G12 | H16: =-H12 | I16: =-I12 | ... L16: =-L12
A17: less capex | B17: =-B6*B47 | C17: =-C6*C47 | D17: =-D6*D47 | E17: =-E6*E47 | F17: =-F6*F47 | G17: =-G6*G47 | H17: =-H6*H47 | I17: =-I6*I47 | ... L17: =-L6*L47
A18: less regulatory capital build (WC) | B18: -20 | C18: =Assumptions!$B$8*(C6-B6) | D18: =Assumptions!$B$8*(D6-C6) | E18: =Assumptions!$B$8*(E6-D6) | F18: =Assumptions!$B$8*(F6-E6) | G18: =Assumptions!$B$8*(G6-F6) | H18: =Assumptions!$B$8*(H6-G6) | I18: =Assumptions!$B$8*(I6-H6) | J18: =Assumptions!$B$8*(J6-I6) | ... L18: =Assumptions!$B$8*(L6-K6)
A19: Owner FCF (post-interest) | B19: =B15+B16+B17+B18 | C19: =C15+C16+C17+C18 | D19: =D15+D16+D17+D18 | E19: =E15+E16+E17+E18 | F19: =F15+F16+F17+F18 | G19: =G15+G16+G17+G18 | H19: =H15+H16+H17+H18 | I19: =I15+I16+I17+I18 | ... L19: =L15+L16+L17+L18
A20: Discount factor | C20: =1/(1+$B$2)^C4 | D20: =1/(1+$B$2)^D4 | E20: =1/(1+$B$2)^E4 | F20: =1/(1+$B$2)^F4 | G20: =1/(1+$B$2)^G4 | H20: =1/(1+$B$2)^H4 | I20: =1/(1+$B$2)^I4 | J20: =1/(1+$B$2)^J4 | ... L20: =1/(1+$B$2)^L4
A21: PV of FCF | C21: =C19*C20 | D21: =D19*D20 | E21: =E19*E20 | F21: =F19*F20 | G21: =G19*G20 | H21: =H19*H20 | I21: =I19*I20 | J21: =J19*J20 | ... L21: =L19*L20
A23: Memo: FCF before SBC | B23: =B19-B10 | C23: =C19-C10 | D23: =D19-D10 | E23: =E19-E10 | F23: =F19-F10 | G23: =G19-G10 | H23: =H19-H10 | I23: =I19-I10 | ... L23: =L19-L10
A24: Memo: owner FCF margin | B24: =B19/B6 | C24: =C19/C6 | D24: =D19/D6 | E24: =E19/E6 | F24: =F19/F6 | G24: =G19/G6 | H24: =H19/H6 | I24: =I19/I6 | ... L24: =L19/L6
A26: Sum of PV (FY27-FY36) | B26: =SUM(C21:L21)
A27: Terminal growth | B27: =Assumptions!$C$16
A28: Terminal-year FCF x (1+g) | B28: =L19*(1+B27)
A29: Gordon TV | B29: =IF(B2>B27,B28/(B2-B27),0)
A30: Cap TV (cap x FCF10) | B30: =Assumptions!$B$9*L19
A31: TV used = MAX(0,MIN(Gordon,cap)) | B31: =MAX(0,MIN(B29,B30))
A32: Implied exit multiple (TV/FCF10) | B32: =IF(L19<>0,B31/L19,0)
A33: PV of TV | B33: =B31*L20
A34: Enterprise value (PV of equity flows) | B34: =B26+B33
A35: less net debt | B35: =-Assumptions!$B$6
A36: Equity value | B36: =B34+B35
A37: Shares (m) | B37: =Assumptions!$B$5
A38: VALUE PER SHARE (A$) | B38: =B36/B37
A39: Upside vs price | B39: =B38/Assumptions!$B$3-1
A41: Street memo: PV of explicit SBC | B41: =SUMPRODUCT(-C10:L10/(1+B2)^C4:L4)
A42: Street memo: PV of terminal SBC | B42: =IF(B2>B27,(-L10*(1+B27)/(B2-B27))*L20,0)
A43: Street value per share (A$) | B43: =(B36+B41+B42)/B37
...

Sheet FCF_Quality
A1: Reported FCF vs owner-FCF proxy, A$m (why reported FCF is unusable for ASX)
A3: Metric | B3: FY2021 | C3: FY2022 | D3: FY2023 | E3: FY2024 | F3: FY2025 | G3: FY2026
A4: Reported OCF | B4: 5095 | C4: 203.4 | D4: -3404 | E4: 480.3 | F4: 302.9 | G4: 262.1
A5: less cash capex | B5: -101.3 | C5: -105.8 | D5: -103.1 | E5: -137.8 | F5: -171.9 | G5: -189
A6: Reported FCF (company-style) | B6: =B4+B5 | C6: =C4+C5 | D6: =D4+D5 | E6: =E4+E5 | F6: =F4+F5 | G6: =G4+G5
A7: Memo: participant margin/financial-asset flows inside OCF | B7: 4695 | C7: -184 | D7: -3860 | E7: 145 | F7: -271.4 | G7: -358.1
A8: Underlying NPAT | B8: 480.9 | C8: 508.5 | D8: 491.1 | E8: 474.2 | F8: 510 | G8: 536.4
A9: add D&A | B9: 55.5 | C9: 52.4 | D9: 39.1 | E9: 40 | F9: 49.3 | G9: 68.2
A10: less cash capex | B10: -101.3 | C10: -105.8 | D10: -103.1 | E10: -137.8 | F10: -171.9 | G10: -189
A11: less lease principal | B11: -12 | C11: -12 | D11: -12 | E11: -13 | F11: -13.2 | G11: -12.8
A12: Owner-FCF proxy (post-interest, pre reg-capital build) | B12: =SUM(B8:B11) | C12: =SUM(C8:C11) | D12: =SUM(D8:D11) | E12: =SUM(E8:E11) | F12: =SUM(F8:F11) | G12: =SUM(G8:G11)
A13: Revenue | B13: 951.5 | C13: 1022.7 | D13: 1010.2 | E13: 1034.3 | F13: 1107.2 | G13: 1254.6
A14: Reported FCF margin | B14: =B6/B13 | C14: =C6/C13 | D14: =D6/D13 | E14: =E6/E13 | F14: =F6/F13 | G14: =G6/G13
A15: Owner-FCF proxy margin | B15: =B12/B13 | C15: =C12/C13 | D15: =D12/D13 | E15: =E12/E13 | F15: =F12/F13 | G15: =G12/G13
A16: Capex % of revenue | B16: =-B10/B13 | C16: =-C10/C13 | D16: =-D10/D13 | E16: =-E10/E13 | F16: =-F10/F13 | G16: =-G10/G13
A17: Memo: cash tax paid | B17: 209.4 | C17: 219.6 | D17: 173.4 | E17: 211.6 | F17: 192.7 | G17: 239.3
A18: Memo: SBC (reserve movement / expense) | B18: 1.2 | C18: -0.9 | D18: 8 | E18: 7.7 | F18: 9.7 | G18: 17
A21: Note: the owner-FCF proxy is flat-to-down FY21-FY26 while revenue compounded 5.7%/yr, because capex rose from ~10% to 15% of revenue on the CHESS programme.

Sheet Valuation
A1: Valuation summary (A$ per share)
A3: Scenario | B3: Value/share | C3: Upside vs price | D3: Probability | E3: Street value/share | F3: Entry price @15%
A4: Bear | B4: =DCF_Bear!$B$38 | C4: =B4/Assumptions!$B$3-1 | D4: =Assumptions!$D$14 | E4: =DCF_Bear!$B$43 | F4: =(SUMPRODUCT(DCF_Bear!$C$19:$L$19/(1+Assumptions!$B$10)^DCF_Bear!$C$4:$L$4)+MAX(0,MIN(IF(Assumptions!$B$10>Assumptions!$C$14,DCF_Bear!$L$19*(1+Assumptions!$C$14)/(Assumptions!$B$10-Assumptions!$C$14),0),Assumptions!$B$9*DCF_Bear!$L$19))/(1+Assumptions!$B$10)^10-Assumptions!$B$6)/Assumptions!$B$5
A5: Base | B5: =DCF_Base!$B$38 | C5: =B5/Assumptions!$B$3-1 | D5: =Assumptions!$D$15 | E5: =DCF_Base!$B$43 | F5: =(SUMPRODUCT(DCF_Base!$C$19:$L$19/(1+Assumptions!$B$10)^DCF_Base!$C$4:$L$4)+MAX(0,MIN(IF(Assumptions!$B$10>Assumptions!$C$15,DCF_Base!$L$19*(1+Assumptions!$C$15)/(Assumptions!$B$10-Assumptions!$C$15),0),Assumptions!$B$9*DCF_Base!$L$19))/(1+Assumptions!$B$10)^10-Assumptions!$B$6)/Assumptions!$B$5
A6: Bull | B6: =DCF_Bull!$B$38 | C6: =B6/Assumptions!$B$3-1 | D6: =Assumptions!$D$16 | E6: =DCF_Bull!$B$43 | F6: =(SUMPRODUCT(DCF_Bull!$C$19:$L$19/(1+Assumptions!$B$10)^DCF_Bull!$C$4:$L$4)+MAX(0,MIN(IF(Assumptions!$B$10>Assumptions!$C$16,DCF_Bull!$L$19*(1+Assumptions!$C$16)/(Assumptions!$B$10-Assumptions!$C$16),0),Assumptions!$B$9*DCF_Bull!$L$19))/(1+Assumptions!$B$10)^10-Assumptions!$B$6)/Assumptions!$B$5
A8: Probability-weighted value/share | B8: =SUMPRODUCT(B4:B6,D4:D6)
A9: Current price | B9: =Assumptions!$B$3
A10: Margin of safety (1 - price/weighted) | B10: =1-B9/B8
A11: Street weighted value/share | B11: =SUMPRODUCT(E4:E6,D4:D6)
A12: Band position (price-house)/(street-house) | B12: =IF(B11<>B8,(B9-B8)/(B11-B8),"n/a")
A13: Weighted entry price @15% hurdle (buy-below) | B13: =SUMPRODUCT(F4:F6,D4:D6)
A16: Required-return table (base case; TV rebuilt at each rate)
A17: Required return | B17: Value/share
A18: 0.09 | B18: =(SUMPRODUCT(DCF_Base!$C$19:$L$19/(1+$A18)^DCF_Base!$C$4:$L$4)+MAX(0,MIN(IF($A18>Assumptions!$C$15,DCF_Base!$L$19*(1+Assumptions!$C$15)/($A18-Assumptions!$C$15),0),Assumptions!$B$9*DCF_Base!$L$19))/(1+$A18)^10-Assumptions!$B$6)/Assumptions!$B$5
A19: 0.1 | B19: =(SUMPRODUCT(DCF_Base!$C$19:$L$19/(1+$A19)^DCF_Base!$C$4:$L$4)+MAX(0,MIN(IF($A19>Assumptions!$C$15,DCF_Base!$L$19*(1+Assumptions!$C$15)/($A19-Assumptions!$C$15),0),Assumptions!$B$9*DCF_Base!$L$19))/(1+$A19)^10-Assumptions!$B$6)/Assumptions!$B$5
A20: 0.11 | B20: =(SUMPRODUCT(DCF_Base!$C$19:$L$19/(1+$A20)^DCF_Base!$C$4:$L$4)+MAX(0,MIN(IF($A20>Assumptions!$C$15,DCF_Base!$L$19*(1+Assumptions!$C$15)/($A20-Assumptions!$C$15),0),Assumptions!$B$9*DCF_Base!$L$19))/(1+$A20)^10-Assumptions!$B$6)/Assumptions!$B$5
A21: 0.12 | B21: =(SUMPRODUCT(DCF_Base!$C$19:$L$19/(1+$A21)^DCF_Base!$C$4:$L$4)+MAX(0,MIN(IF($A21>Assumptions!$C$15,DCF_Base!$L$19*(1+Assumptions!$C$15)/($A21-Assumptions!$C$15),0),Assumptions!$B$9*DCF_Base!$L$19))/(1+$A21)^10-Assumptions!$B$6)/Assumptions!$B$5
A22: 0.15 | B22: =(SUMPRODUCT(DCF_Base!$C$19:$L$19/(1+$A22)^DCF_Base!$C$4:$L$4)+MAX(0,MIN(IF($A22>Assumptions!$C$15,DCF_Base!$L$19*(1+Assumptions!$C$15)/($A22-Assumptions!$C$15),0),Assumptions!$B$9*DCF_Base!$L$19))/(1+$A22)^10-Assumptions!$B$6)/Assumptions!$B$5
A23: =Assumptions!$B$15 | B23: =(SUMPRODUCT(DCF_Base!$C$19:$L$19/(1+$A23)^DCF_Base!$C$4:$L$4)+MAX(0,MIN(IF($A23>Assumptions!$C$15,DCF_Base!$L$19*(1+Assumptions!$C$15)/($A23-Assumptions!$C$15),0),Assumptions!$B$9*DCF_Base!$L$19))/(1+$A23)^10-Assumptions!$B$6)/Assumptions!$B$5 | C23: model CoE row: must equal DCF_Base!B38
A26: Sensitivity: cost of equity (rows) x terminal growth (cols), base case, A$/share
B27: 0.02 | C27: 0.025 | D27: 0.03 | E27: 0.035 | F27: 0.04
A28: 0.07 | B28: =IF($A28>B$27,(SUMPRODUCT(DCF_Base!$C$19:$L$19/(1+$A28)^DCF_Base!$C$4:$L$4)+MAX(0,MIN(IF($A28>B$27,DCF_Base!$L$19*(1+B$27)/($A28-B$27),0),Assumptions!$B$9*DCF_Base!$L$19))/(1+$A28)^10-Assumptions!$B$6)/Assumptions!$B$5,"n/a") | C28: =IF($A28>C$27,(SUMPRODUCT(DCF_Base!$C$19:$L$19/(1+$A28)^DCF_Base!$C$4:$L$4)+MAX(0,MIN(IF($A28>C$27,DCF_Base!$L$19*(1+C$27)/($A28-C$27),0),Assumptions!$B$9*DCF_Base!$L$19))/(1+$A28)^10-Assumptions!$B$6)/Assumptions!$B$5,"n/a") | D28: =IF($A28>D$27,(SUMPRODUCT(DCF_Base!$C$19:$L$19/(1+$A28)^DCF_Base!$C$4:$L$4)+MAX(0,MIN(IF($A28>D$27,DCF_Base!$L$19*(1+D$27)/($A28-D$27),0),Assumptions!$B$9*DCF_Base!$L$19))/(1+$A28)^10-Assumptions!$B$6)/Assumptions!$B$5,"n/a") | E28: =IF($A28>E$27,(SUMPRODUCT(DCF_Base!$C$19:$L$19/(1+$A28)^DCF_Base!$C$4:$L$4)+MAX(0,MIN(IF($A28>E$27,DCF_Base!$L$19*(1+E$27)/($A28-E$27),0),Assumptions!$B$9*DCF_Base!$L$19))/(1+$A28)^10-Assumptions!$B$6)/Assumptions!$B$5,"n/a") | F28: =IF($A28>F$27,(SUMPRODUCT(DCF_Base!$C$19:$L$19/(1+$A28)^DCF_Base!$C$4:$L$4)+MAX(0,MIN(IF($A28>F$27,DCF_Base!$L$19*(1+F$27)/($A28-F$27),0),Assumptions!$B$9*DCF_Base!$L$19))/(1+$A28)^10-Assumptions!$B$6)/Assumptions!$B$5,"n/a")
A29: 0.08 | B29: =IF($A29>B$27,(SUMPRODUCT(DCF_Base!$C$19:$L$19/(1+$A29)^DCF_Base!$C$4:$L$4)+MAX(0,MIN(IF($A29>B$27,DCF_Base!$L$19*(1+B$27)/($A29-B$27),0),Assumptions!$B$9*DCF_Base!$L$19))/(1+$A29)^10-Assumptions!$B$6)/Assumptions!$B$5,"n/a") | C29: =IF($A29>C$27,(SUMPRODUCT(DCF_Base!$C$19:$L$19/(1+$A29)^DCF_Base!$C$4:$L$4)+MAX(0,MIN(IF($A29>C$27,DCF_Base!$L$19*(1+C$27)/($A29-C$27),0),Assumptions!$B$9*DCF_Base!$L$19))/(1+$A29)^10-Assumptions!$B$6)/Assumptions!$B$5,"n/a") | D29: =IF($A29>D$27,(SUMPRODUCT(DCF_Base!$C$19:$L$19/(1+$A29)^DCF_Base!$C$4:$L$4)+MAX(0,MIN(IF($A29>D$27,DCF_Base!$L$19*(1+D$27)/($A29-D$27),0),Assumptions!$B$9*DCF_Base!$L$19))/(1+$A29)^10-Assumptions!$B$6)/Assumptions!$B$5,"n/a") | E29: =IF($A29>E$27,(SUMPRODUCT(DCF_Base!$C$19:$L$19/(1+$A29)^DCF_Base!$C$4:$L$4)+MAX(0,MIN(IF($A29>E$27,DCF_Base!$L$19*(1+E$27)/($A29-E$27),0),Assumptions!$B$9*DCF_Base!$L$19))/(1+$A29)^10-Assumptions!$B$6)/Assumptions!$B$5,"n/a") | F29: =IF($A29>F$27,(SUMPRODUCT(DCF_Base!$C$19:$L$19/(1+$A29)^DCF_Base!$C$4:$L$4)+MAX(0,MIN(IF($A29>F$27,DCF_Base!$L$19*(1+F$27)/($A29-F$27),0),Assumptions!$B$9*DCF_Base!$L$19))/(1+$A29)^10-Assumptions!$B$6)/Assumptions!$B$5,"n/a")
A30: 0.09 | B30: =IF($A30>B$27,(SUMPRODUCT(DCF_Base!$C$19:$L$19/(1+$A30)^DCF_Base!$C$4:$L$4)+MAX(0,MIN(IF($A30>B$27,DCF_Base!$L$19*(1+B$27)/($A30-B$27),0),Assumptions!$B$9*DCF_Base!$L$19))/(1+$A30)^10-Assumptions!$B$6)/Assumptions!$B$5,"n/a") | C30: =IF($A30>C$27,(SUMPRODUCT(DCF_Base!$C$19:$L$19/(1+$A30)^DCF_Base!$C$4:$L$4)+MAX(0,MIN(IF($A30>C$27,DCF_Base!$L$19*(1+C$27)/($A30-C$27),0),Assumptions!$B$9*DCF_Base!$L$19))/(1+$A30)^10-Assumptions!$B$6)/Assumptions!$B$5,"n/a") | D30: =IF($A30>D$27,(SUMPRODUCT(DCF_Base!$C$19:$L$19/(1+$A30)^DCF_Base!$C$4:$L$4)+MAX(0,MIN(IF($A30>D$27,DCF_Base!$L$19*(1+D$27)/($A30-D$27),0),Assumptions!$B$9*DCF_Base!$L$19))/(1+$A30)^10-Assumptions!$B$6)/Assumptions!$B$5,"n/a") | E30: =IF($A30>E$27,(SUMPRODUCT(DCF_Base!$C$19:$L$19/(1+$A30)^DCF_Base!$C$4:$L$4)+MAX(0,MIN(IF($A30>E$27,DCF_Base!$L$19*(1+E$27)/($A30-E$27),0),Assumptions!$B$9*DCF_Base!$L$19))/(1+$A30)^10-Assumptions!$B$6)/Assumptions!$B$5,"n/a") | F30: =IF($A30>F$27,(SUMPRODUCT(DCF_Base!$C$19:$L$19/(1+$A30)^DCF_Base!$C$4:$L$4)+MAX(0,MIN(IF($A30>F$27,DCF_Base!$L$19*(1+F$27)/($A30-F$27),0),Assumptions!$B$9*DCF_Base!$L$19))/(1+$A30)^10-Assumptions!$B$6)/Assumptions!$B$5,"n/a")
A31: 0.1 | B31: =IF($A31>B$27,(SUMPRODUCT(DCF_Base!$C$19:$L$19/(1+$A31)^DCF_Base!$C$4:$L$4)+MAX(0,MIN(IF($A31>B$27,DCF_Base!$L$19*(1+B$27)/($A31-B$27),0),Assumptions!$B$9*DCF_Base!$L$19))/(1+$A31)^10-Assumptions!$B$6)/Assumptions!$B$5,"n/a") | C31: =IF($A31>C$27,(SUMPRODUCT(DCF_Base!$C$19:$L$19/(1+$A31)^DCF_Base!$C$4:$L$4)+MAX(0,MIN(IF($A31>C$27,DCF_Base!$L$19*(1+C$27)/($A31-C$27),0),Assumptions!$B$9*DCF_Base!$L$19))/(1+$A31)^10-Assumptions!$B$6)/Assumptions!$B$5,"n/a") | D31: =IF($A31>D$27,(SUMPRODUCT(DCF_Base!$C$19:$L$19/(1+$A31)^DCF_Base!$C$4:$L$4)+MAX(0,MIN(IF($A31>D$27,DCF_Base!$L$19*(1+D$27)/($A31-D$27),0),Assumptions!$B$9*DCF_Base!$L$19))/(1+$A31)^10-Assumptions!$B$6)/Assumptions!$B$5,"n/a") | E31: =IF($A31>E$27,(SUMPRODUCT(DCF_Base!$C$19:$L$19/(1+$A31)^DCF_Base!$C$4:$L$4)+MAX(0,MIN(IF($A31>E$27,DCF_Base!$L$19*(1+E$27)/($A31-E$27),0),Assumptions!$B$9*DCF_Base!$L$19))/(1+$A31)^10-Assumptions!$B$6)/Assumptions!$B$5,"n/a") | F31: =IF($A31>F$27,(SUMPRODUCT(DCF_Base!$C$19:$L$19/(1+$A31)^DCF_Base!$C$4:$L$4)+MAX(0,MIN(IF($A31>F$27,DCF_Base!$L$19*(1+F$27)/($A31-F$27),0),Assumptions!$B$9*DCF_Base!$L$19))/(1+$A31)^10-Assumptions!$B$6)/Assumptions!$B$5,"n/a")
A32: 0.11 | B32: =IF($A32>B$27,(SUMPRODUCT(DCF_Base!$C$19:$L$19/(1+$A32)^DCF_Base!$C$4:$L$4)+MAX(0,MIN(IF($A32>B$27,DCF_Base!$L$19*(1+B$27)/($A32-B$27),0),Assumptions!$B$9*DCF_Base!$L$19))/(1+$A32)^10-Assumptions!$B$6)/Assumptions!$B$5,"n/a") | C32: =IF($A32>C$27,(SUMPRODUCT(DCF_Base!$C$19:$L$19/(1+$A32)^DCF_Base!$C$4:$L$4)+MAX(0,MIN(IF($A32>C$27,DCF_Base!$L$19*(1+C$27)/($A32-C$27),0),Assumptions!$B$9*DCF_Base!$L$19))/(1+$A32)^10-Assumptions!$B$6)/Assumptions!$B$5,"n/a") | D32: =IF($A32>D$27,(SUMPRODUCT(DCF_Base!$C$19:$L$19/(1+$A32)^DCF_Base!$C$4:$L$4)+MAX(0,MIN(IF($A32>D$27,DCF_Base!$L$19*(1+D$27)/($A32-D$27),0),Assumptions!$B$9*DCF_Base!$L$19))/(1+$A32)^10-Assumptions!$B$6)/Assumptions!$B$5,"n/a") | E32: =IF($A32>E$27,(SUMPRODUCT(DCF_Base!$C$19:$L$19/(1+$A32)^DCF_Base!$C$4:$L$4)+MAX(0,MIN(IF($A32>E$27,DCF_Base!$L$19*(1+E$27)/($A32-E$27),0),Assumptions!$B$9*DCF_Base!$L$19))/(1+$A32)^10-Assumptions!$B$6)/Assumptions!$B$5,"n/a") | F32: =IF($A32>F$27,(SUMPRODUCT(DCF_Base!$C$19:$L$19/(1+$A32)^DCF_Base!$C$4:$L$4)+MAX(0,MIN(IF($A32>F$27,DCF_Base!$L$19*(1+F$27)/($A32-F$27),0),Assumptions!$B$9*DCF_Base!$L$19))/(1+$A32)^10-Assumptions!$B$6)/Assumptions!$B$5,"n/a")
