Workbook

Sheet Model_Info
A1: RAD.NZ (Radius Residential Care) DCF model - version 1.0, 2026-08-27. Fresh build; supersedes nothing (first valuation of this ticker).
A2: Built by the dcf-analyst agent (Claude, Fable 5) on 2026-08-27 at the user's request, alongside research/RAD.NZ/Reports/RAD.NZ_DCF.json (the two must agree).
A4: DATA VINTAGE - these figures go stale:
A5: Price NZ$0.465 - Yahoo Finance, 2026-08-27 16:09 NZST regular session (52w 0.34-0.49).
A6: Balance sheet 31-Mar-2026 (FY2026 annual report): bank borrowings 71.564, cash 2.823, lease liabilities 141.512, NCI 0.596, equity 76.317, shares 283.862m.
A7: FY2026 P&L/CF: revenue 205.515, EBITDA 39.125, NPAT 10.053, OCF 25.121, capex 16.073, lease principal 2.830, lease interest 6.898, bank interest 4.558, cash tax 3.496.
A8: Refresh after the H1 FY2027 result (~Nov 2026) and any government decision on the Aug-2026 Ministerial Advisory Group ~7.1% price-uplift recommendation.
A10: METHODOLOGY (each choice one line):
A11: Owner-FCF DCF, 10-year explicit horizon (margins still ramping), routed via dcf-methods SKILL: operating company (care-fee revenue; not a REIT/NAV/bank).
A12: Lease treatment B: full lease CASH cost (principal+interest, ~4.8% of revenue) charged inside the flows; lease liabilities EXCLUDED from net debt. Charging both would double-count ~half the enterprise.
A13: RAD presents bank AND lease interest inside OPERATING cash flow; owner FCF adds bank interest back (unlevered; bank debt charged once in the bridge) and keeps lease interest deducted.
A14: D&A driver 3.7% is owned-asset only (13.206 total less 5.604 ROU depreciation) - ROU dep excluded to avoid double-charging leases in the tax build.
... A26: DCF tab row map: r5 growth, r7 EBITDA margin, r9 SBC%, r15 cash tax rate are the per-year drivers; lease/capex/WC/terminal params link to the Assumptions per-scenario table (rows 13-15).

Sheet Assumptions
A1: Global assumptions (blue = hardcoded input)
A2: Current price (NZD) | B2: 0.465 | C2: Yahoo 2026-08-27 16:09 NZST regular session; 52w 0.34-0.49
A3: Price as of | B3: 2026-08-27T04:09:24Z | C3: regularMarketTime
A4: WACC % | B4: 14.5 | C4: 9.0 NZ base (rf 4.4 + ERP 4.6) + 2.0 small-cap illiquidity + 2.0 single-payer concentration + 1.5 leverage; same for all scenarios
A5: Owned-asset D&A % of revenue | B5: 3.7 | C5: FY2026 total D&A 13.206 less ROU depreciation 5.604 = 7.602 owned; ROU excluded because cash lease cost is charged instead
A6: Net debt (NZ$m) | B6: 69.337 | C6: Bank 71.564 - cash 2.823 + NCI book 0.596; lease liabilities 141.512 EXCLUDED (lease treatment B)
A7: Shares outstanding (m) | B7: 283.862 | C7: 31-Mar-2026, held flat; SBC expensed so no dilution on top
A8: Hurdle rate % | B8: 15 | C8: entry-price IRR
A9: Base revenue FY2026 (NZ$m) | B9: 205.515 | C9: FY2026 annual report
A11: Per-scenario assumptions
A12: Scenario | B12: Lease cost % rev | C12: Capex % rev | D12: WC capture % of change | E12: Terminal growth % | F12: TV cap (x FCF10) | G12: Weight
A13: Bear | B13: 5 | C13: 2.5 | D13: 5 | E13: 1 | F13: 10 | G13: 0.2
A14: Base | B14: 4.8 | C14: 3 | D14: 8 | E14: 2 | F14: 12 | G14: 0.5
A15: Bull | B15: 4.8 | C15: 3.2 | D15: 8 | E15: 2.5 | F15: 13 | G15: 0.3
A16: Weight check (must equal 1.0) | G16: =SUM(G13:G15)
A18: Bear: government freezes/under-indexes the bed-day rate while wage and AEWV labour costs rise; growth 1-3%, EBITDA margin compresses to 16% (FY2024 level); fixed lease+bank charges bite; terminal growth 1%, cap 10x.
A19: Base: ARRC uplifts at wage pass-through (3-4%), MAG 7.1% uplift NOT enacted; occupancy 95-96%; Karori annualises (yr1 +9%); growth decelerates to 2.5%; margin drifts 19.2->20.5%; cash tax normalises to 28%.
A20: Bull: MAG ~7.1% price uplift enacted Budget 2027 (yr2 +11%); occupancy hits 97-98% target; capital-light 20-home pipeline executes; adjacents compound; margin reaches 22%.

Sheet DCF_Bear
A1: DCF Bear - unlevered owner FCF, lease treatment B (full lease cash cost in flows; lease liabilities excluded from net debt)
A3: Year | B3: FY2026A | C3: FY2027E | D3: FY2028E | E3: FY2029E | F3: FY2030E | G3: FY2031E | H3: FY2032E | I3: FY2033E | J3: FY2034E | K3: FY2035E | L3: FY2036E
A4: Year index | B4: 0 | C4: 1 | D4: 2 | E4: 3 | F4: 4 | G4: 5 | H4: 6 | I4: 7 | J4: 8 | K4: 9 | L4: 10
A5: Revenue growth % (driver) | C5: 5 | D5: 3 | E5: 2.5 | F5: 2 | G5: 2 | H5: 2 | I5: 1.5 | J5: 1.5 | K5: 1 | L5: 1
A6: Revenue NZ$m | B6: 205.515 | C6: =B6*(1+C5/100) | D6: =C6*(1+D5/100) | E6: =D6*(1+E5/100) | F6: =E6*(1+F5/100) | G6: =F6*(1+G5/100) | H6: =G6*(1+H5/100) | I6: =H6*(1+I5/100) | J6: =I6*(1+J5/100) | ... L6: =K6*(1+L5/100)
A7: Adj EBITDA margin % (driver) | C7: 18.5 | D7: 17.8 | E7: 17.2 | F7: 16.8 | G7: 16.5 | H7: 16.3 | I7: 16.2 | J7: 16.1 | K7: 16 | L7: 16
A8: Adjusted EBITDA (pre-lease, IFRS-16 basis) | B8: 39.125 | C8: =C6*C7/100 | D8: =D6*D7/100 | E8: =E6*E7/100 | F8: =F6*F7/100 | G8: =G6*G7/100 | H8: =H6*H7/100 | I8: =I6*I7/100 | J8: =J6*J7/100 | ... L8: =L6*L7/100
A9: SBC % of revenue (driver) | C9: 0.2 | D9: 0.2 | E9: 0.2 | F9: 0.2 | G9: 0.2 | H9: 0.2 | I9: 0.2 | J9: 0.2 | K9: 0.2 | L9: 0.2
A10: SBC $ (negative) | B10: -0.38 | C10: =-C6*C9/100 | D10: =-D6*D9/100 | E10: =-E6*E9/100 | F10: =-F6*F9/100 | G10: =-G6*G9/100 | H10: =-H6*H9/100 | I10: =-I6*I9/100 | J10: =-J6*J9/100 | ... L10: =-L6*L9/100
A11: Lease cash cost % of revenue (link) | C11: =Assumptions!$B$13 | D11: =Assumptions!$B$13 | E11: =Assumptions!$B$13 | F11: =Assumptions!$B$13 | G11: =Assumptions!$B$13 | H11: =Assumptions!$B$13 | I11: =Assumptions!$B$13 | J11: =Assumptions!$B$13 | ... L11: =Assumptions!$B$13
A12: Lease cash cost $ (principal + interest, negative) | B12: -9.728 | C12: =-C6*C11/100 | D12: =-D6*D11/100 | E12: =-E6*E11/100 | F12: =-F6*F11/100 | G12: =-G6*G11/100 | H12: =-H6*H11/100 | I12: =-I6*I11/100 | J12: =-J6*J11/100 | ... L12: =-L6*L11/100
A13: Owned-asset D&A $ (negative, link) | B13: -7.602 | C13: =-C6*Assumptions!$B$5/100 | D13: =-D6*Assumptions!$B$5/100 | E13: =-E6*Assumptions!$B$5/100 | F13: =-F6*Assumptions!$B$5/100 | G13: =-G6*Assumptions!$B$5/100 | H13: =-H6*Assumptions!$B$5/100 | I13: =-I6*Assumptions!$B$5/100 | J13: =-J6*Assumptions!$B$5/100 | ... L13: =-L6*Assumptions!$B$5/100
A14: EBIT (post-lease cash, post-SBC) | C14: =C8+C10+C12+C13 | D14: =D8+D10+D12+D13 | E14: =E8+E10+E12+E13 | F14: =F8+F10+F12+F13 | G14: =G8+G10+G12+G13 | H14: =H8+H10+H12+H13 | I14: =I8+I10+I12+I13 | J14: =J8+J10+J12+J13 | ... L14: =L8+L10+L12+L13
A15: Cash tax rate % (driver) | C15: 18 | D15: 20 | E15: 22 | F15: 25 | G15: 28 | H15: 28 | I15: 28 | J15: 28 | K15: 28 | L15: 28
A16: Cash tax $ (negative) | C16: =-MAX(0,C14)*C15/100 | D16: =-MAX(0,D14)*D15/100 | E16: =-MAX(0,E14)*E15/100 | F16: =-MAX(0,F14)*F15/100 | G16: =-MAX(0,G14)*G15/100 | H16: =-MAX(0,H14)*H15/100 | I16: =-MAX(0,I14)*I15/100 | J16: =-MAX(0,J14)*J15/100 | ... L16: =-MAX(0,L14)*L15/100
A17: NOPAT | C17: =C14+C16 | D17: =D14+D16 | E17: =E14+E16 | F17: =F14+F16 | G17: =G14+G16 | H17: =H14+H16 | I17: =I14+I16 | J17: =J14+J16 | ... L17: =L14+L16
A18: Add back D&A | C18: =-C13 | D18: =-D13 | E18: =-E13 | F18: =-F13 | G18: =-G13 | H18: =-H13 | I18: =-I13 | J18: =-J13 | ... L18: =-L13
A19: Less capex (link) | C19: =-C6*Assumptions!$C$13/100 | D19: =-D6*Assumptions!$C$13/100 | E19: =-E6*Assumptions!$C$13/100 | F19: =-F6*Assumptions!$C$13/100 | G19: =-G6*Assumptions!$C$13/100 | H19: =-H6*Assumptions!$C$13/100 | I19: =-I6*Assumptions!$C$13/100 | J19: =-J6*Assumptions!$C$13/100 | ... L19: =-L6*Assumptions!$C$13/100
A20: Add working capital (link) | C20: =(C6-B6)*Assumptions!$D$13/100 | D20: =(D6-C6)*Assumptions!$D$13/100 | E20: =(E6-D6)*Assumptions!$D$13/100 | F20: =(F6-E6)*Assumptions!$D$13/100 | G20: =(G6-F6)*Assumptions!$D$13/100 | H20: =(H6-G6)*Assumptions!$D$13/100 | I20: =(I6-H6)*Assumptions!$D$13/100 | J20: =(J6-I6)*Assumptions!$D$13/100 | ... L20: =(L6-K6)*Assumptions!$D$13/100
A21: Unlevered owner FCF | B21: 10.335 | C21: =C17+C18+C19+C20 | D21: =D17+D18+D19+D20 | E21: =E17+E18+E19+E20 | F21: =F17+F18+F19+F20 | G21: =G17+G18+G19+G20 | H21: =H17+H18+H19+H20 | I21: =I17+I18+I19+I20 | J21: =J17+J18+J19+J20 | ... L21: =L17+L18+L19+L20
A22: Discount factor | C22: =1/POWER(1+Assumptions!$B$4/100,C4) | D22: =1/POWER(1+Assumptions!$B$4/100,D4) | E22: =1/POWER(1+Assumptions!$B$4/100,E4) | F22: =1/POWER(1+Assumptions!$B$4/100,F4) | G22: =1/POWER(1+Assumptions!$B$4/100,G4) | H22: =1/POWER(1+Assumptions!$B$4/100,H4) | I22: =1/POWER(1+Assumptions!$B$4/100,I4) | J22: =1/POWER(1+Assumptions!$B$4/100,J4) | ... L22: =1/POWER(1+Assumptions!$B$4/100,L4)
A23: PV of FCF | C23: =C21*C22 | D23: =D21*D22 | E23: =E21*E22 | F23: =F21*F22 | G23: =G21*G22 | H23: =H21*H22 | I23: =I21*I22 | J23: =J21*J22 | ... L23: =L21*L22
A25: Memo: FCF before SBC (street-style) | C25: =C21-C10 | D25: =D21-D10 | E25: =E21-E10 | F25: =F21-F10 | G25: =G21-G10 | H25: =H21-H10 | I25: =I21-I10 | J25: =J21-J10 | ... L25: =L21-L10
A26: Memo: owner FCF margin % | B26: =100*B21/B6 | C26: =100*C21/C6 | D26: =100*D21/D6 | E26: =100*E21/E6 | F26: =100*F21/F6 | G26: =100*G21/G6 | H26: =100*H21/H6 | I26: =100*I21/I6 | ... L26: =100*L21/L6
A27: Note: FY2026A owner FCF 10.335 uses reported acquisition-heavy capex 16.073; the forecast capex driver is the normalized rate.
A28: Sum PV of FCF | B28: =SUM(C23:L23)
A29: Terminal growth % (link) | B29: =Assumptions!$E$13
A30: Terminal-year FCF x (1+g) | B30: =L21*(1+B29/100)
A31: Gordon TV | B31: =B30/((Assumptions!$B$4-B29)/100)
A32: Cap TV (cap x FCF10) | B32: =Assumptions!$F$13*L21
A33: TV used = MAX(0,MIN(Gordon,Cap)) | B33: =MAX(0,MIN(B31,B32))
A34: Implied exit multiple (TV/FCF10) | B34: =B33/L21
A35: PV of TV | B35: =B33*L22
A36: Enterprise value | B36: =B28+B35
A37: Less net debt (bank - cash + NCI) | B37: =-Assumptions!$B$6
A38: Equity value | B38: =B36+B37
A39: Shares (m, link) | B39: =Assumptions!$B$7
A40: VALUE PER SHARE (NZD) | B40: =B38/B39
A41: Upside vs price | B41: =B40/Assumptions!$B$2-1
A43: Street memo: PV of explicit SBC | B43: =SUMPRODUCT(-C10:L10,C22:L22)
...

Sheet DCF_Base
A1: DCF Base - unlevered owner FCF, lease treatment B (full lease cash cost in flows; lease liabilities excluded from net debt)
A3: Year | B3: FY2026A | C3: FY2027E | D3: FY2028E | E3: FY2029E | F3: FY2030E | G3: FY2031E | H3: FY2032E | I3: FY2033E | J3: FY2034E | K3: FY2035E | L3: FY2036E
A4: Year index | B4: 0 | C4: 1 | D4: 2 | E4: 3 | F4: 4 | G4: 5 | H4: 6 | I4: 7 | J4: 8 | K4: 9 | L4: 10
A5: Revenue growth % (driver) | C5: 9 | D5: 7.5 | E5: 6.5 | F5: 5.5 | G5: 5 | H5: 4.5 | I5: 4 | J5: 3.5 | K5: 3 | L5: 2.5
A6: Revenue NZ$m | B6: 205.515 | C6: =B6*(1+C5/100) | D6: =C6*(1+D5/100) | E6: =D6*(1+E5/100) | F6: =E6*(1+F5/100) | G6: =F6*(1+G5/100) | H6: =G6*(1+H5/100) | I6: =H6*(1+I5/100) | J6: =I6*(1+J5/100) | ... L6: =K6*(1+L5/100)
A7: Adj EBITDA margin % (driver) | C7: 19.2 | D7: 19.4 | E7: 19.6 | F7: 19.8 | G7: 20 | H7: 20.1 | I7: 20.2 | J7: 20.3 | K7: 20.4 | L7: 20.5
A8: Adjusted EBITDA (pre-lease, IFRS-16 basis) | B8: 39.125 | C8: =C6*C7/100 | D8: =D6*D7/100 | E8: =E6*E7/100 | F8: =F6*F7/100 | G8: =G6*G7/100 | H8: =H6*H7/100 | I8: =I6*I7/100 | J8: =J6*J7/100 | ... L8: =L6*L7/100
A9: SBC % of revenue (driver) | C9: 0.2 | D9: 0.2 | E9: 0.2 | F9: 0.2 | G9: 0.2 | H9: 0.2 | I9: 0.2 | J9: 0.2 | K9: 0.2 | L9: 0.2
A10: SBC $ (negative) | B10: -0.38 | C10: =-C6*C9/100 | D10: =-D6*D9/100 | E10: =-E6*E9/100 | F10: =-F6*F9/100 | G10: =-G6*G9/100 | H10: =-H6*H9/100 | I10: =-I6*I9/100 | J10: =-J6*J9/100 | ... L10: =-L6*L9/100
A11: Lease cash cost % of revenue (link) | C11: =Assumptions!$B$14 | D11: =Assumptions!$B$14 | E11: =Assumptions!$B$14 | F11: =Assumptions!$B$14 | G11: =Assumptions!$B$14 | H11: =Assumptions!$B$14 | I11: =Assumptions!$B$14 | J11: =Assumptions!$B$14 | ... L11: =Assumptions!$B$14
A12: Lease cash cost $ (principal + interest, negative) | B12: -9.728 | C12: =-C6*C11/100 | D12: =-D6*D11/100 | E12: =-E6*E11/100 | F12: =-F6*F11/100 | G12: =-G6*G11/100 | H12: =-H6*H11/100 | I12: =-I6*I11/100 | J12: =-J6*J11/100 | ... L12: =-L6*L11/100
A13: Owned-asset D&A $ (negative, link) | B13: -7.602 | C13: =-C6*Assumptions!$B$5/100 | D13: =-D6*Assumptions!$B$5/100 | E13: =-E6*Assumptions!$B$5/100 | F13: =-F6*Assumptions!$B$5/100 | G13: =-G6*Assumptions!$B$5/100 | H13: =-H6*Assumptions!$B$5/100 | I13: =-I6*Assumptions!$B$5/100 | J13: =-J6*Assumptions!$B$5/100 | ... L13: =-L6*Assumptions!$B$5/100
A14: EBIT (post-lease cash, post-SBC) | C14: =C8+C10+C12+C13 | D14: =D8+D10+D12+D13 | E14: =E8+E10+E12+E13 | F14: =F8+F10+F12+F13 | G14: =G8+G10+G12+G13 | H14: =H8+H10+H12+H13 | I14: =I8+I10+I12+I13 | J14: =J8+J10+J12+J13 | ... L14: =L8+L10+L12+L13
A15: Cash tax rate % (driver) | C15: 18 | D15: 20 | E15: 22 | F15: 25 | G15: 28 | H15: 28 | I15: 28 | J15: 28 | K15: 28 | L15: 28
A16: Cash tax $ (negative) | C16: =-MAX(0,C14)*C15/100 | D16: =-MAX(0,D14)*D15/100 | E16: =-MAX(0,E14)*E15/100 | F16: =-MAX(0,F14)*F15/100 | G16: =-MAX(0,G14)*G15/100 | H16: =-MAX(0,H14)*H15/100 | I16: =-MAX(0,I14)*I15/100 | J16: =-MAX(0,J14)*J15/100 | ... L16: =-MAX(0,L14)*L15/100
A17: NOPAT | C17: =C14+C16 | D17: =D14+D16 | E17: =E14+E16 | F17: =F14+F16 | G17: =G14+G16 | H17: =H14+H16 | I17: =I14+I16 | J17: =J14+J16 | ... L17: =L14+L16
A18: Add back D&A | C18: =-C13 | D18: =-D13 | E18: =-E13 | F18: =-F13 | G18: =-G13 | H18: =-H13 | I18: =-I13 | J18: =-J13 | ... L18: =-L13
A19: Less capex (link) | C19: =-C6*Assumptions!$C$14/100 | D19: =-D6*Assumptions!$C$14/100 | E19: =-E6*Assumptions!$C$14/100 | F19: =-F6*Assumptions!$C$14/100 | G19: =-G6*Assumptions!$C$14/100 | H19: =-H6*Assumptions!$C$14/100 | I19: =-I6*Assumptions!$C$14/100 | J19: =-J6*Assumptions!$C$14/100 | ... L19: =-L6*Assumptions!$C$14/100
A20: Add working capital (link) | C20: =(C6-B6)*Assumptions!$D$14/100 | D20: =(D6-C6)*Assumptions!$D$14/100 | E20: =(E6-D6)*Assumptions!$D$14/100 | F20: =(F6-E6)*Assumptions!$D$14/100 | G20: =(G6-F6)*Assumptions!$D$14/100 | H20: =(H6-G6)*Assumptions!$D$14/100 | I20: =(I6-H6)*Assumptions!$D$14/100 | J20: =(J6-I6)*Assumptions!$D$14/100 | ... L20: =(L6-K6)*Assumptions!$D$14/100
A21: Unlevered owner FCF | B21: 10.335 | C21: =C17+C18+C19+C20 | D21: =D17+D18+D19+D20 | E21: =E17+E18+E19+E20 | F21: =F17+F18+F19+F20 | G21: =G17+G18+G19+G20 | H21: =H17+H18+H19+H20 | I21: =I17+I18+I19+I20 | J21: =J17+J18+J19+J20 | ... L21: =L17+L18+L19+L20
A22: Discount factor | C22: =1/POWER(1+Assumptions!$B$4/100,C4) | D22: =1/POWER(1+Assumptions!$B$4/100,D4) | E22: =1/POWER(1+Assumptions!$B$4/100,E4) | F22: =1/POWER(1+Assumptions!$B$4/100,F4) | G22: =1/POWER(1+Assumptions!$B$4/100,G4) | H22: =1/POWER(1+Assumptions!$B$4/100,H4) | I22: =1/POWER(1+Assumptions!$B$4/100,I4) | J22: =1/POWER(1+Assumptions!$B$4/100,J4) | ... L22: =1/POWER(1+Assumptions!$B$4/100,L4)
A23: PV of FCF | C23: =C21*C22 | D23: =D21*D22 | E23: =E21*E22 | F23: =F21*F22 | G23: =G21*G22 | H23: =H21*H22 | I23: =I21*I22 | J23: =J21*J22 | ... L23: =L21*L22
A25: Memo: FCF before SBC (street-style) | C25: =C21-C10 | D25: =D21-D10 | E25: =E21-E10 | F25: =F21-F10 | G25: =G21-G10 | H25: =H21-H10 | I25: =I21-I10 | J25: =J21-J10 | ... L25: =L21-L10
A26: Memo: owner FCF margin % | B26: =100*B21/B6 | C26: =100*C21/C6 | D26: =100*D21/D6 | E26: =100*E21/E6 | F26: =100*F21/F6 | G26: =100*G21/G6 | H26: =100*H21/H6 | I26: =100*I21/I6 | ... L26: =100*L21/L6
A27: Note: FY2026A owner FCF 10.335 uses reported acquisition-heavy capex 16.073; the forecast capex driver is the normalized rate.
A28: Sum PV of FCF | B28: =SUM(C23:L23)
A29: Terminal growth % (link) | B29: =Assumptions!$E$14
A30: Terminal-year FCF x (1+g) | B30: =L21*(1+B29/100)
A31: Gordon TV | B31: =B30/((Assumptions!$B$4-B29)/100)
A32: Cap TV (cap x FCF10) | B32: =Assumptions!$F$14*L21
A33: TV used = MAX(0,MIN(Gordon,Cap)) | B33: =MAX(0,MIN(B31,B32))
A34: Implied exit multiple (TV/FCF10) | B34: =B33/L21
A35: PV of TV | B35: =B33*L22
A36: Enterprise value | B36: =B28+B35
A37: Less net debt (bank - cash + NCI) | B37: =-Assumptions!$B$6
A38: Equity value | B38: =B36+B37
A39: Shares (m, link) | B39: =Assumptions!$B$7
A40: VALUE PER SHARE (NZD) | B40: =B38/B39
A41: Upside vs price | B41: =B40/Assumptions!$B$2-1
A43: Street memo: PV of explicit SBC | B43: =SUMPRODUCT(-C10:L10,C22:L22)
...

Sheet DCF_Bull
A1: DCF Bull - unlevered owner FCF, lease treatment B (full lease cash cost in flows; lease liabilities excluded from net debt)
A3: Year | B3: FY2026A | C3: FY2027E | D3: FY2028E | E3: FY2029E | F3: FY2030E | G3: FY2031E | H3: FY2032E | I3: FY2033E | J3: FY2034E | K3: FY2035E | L3: FY2036E
A4: Year index | B4: 0 | C4: 1 | D4: 2 | E4: 3 | F4: 4 | G4: 5 | H4: 6 | I4: 7 | J4: 8 | K4: 9 | L4: 10
A5: Revenue growth % (driver) | C5: 10 | D5: 11 | E5: 8 | F5: 7 | G5: 6 | H5: 5.5 | I5: 5 | J5: 4.5 | K5: 4 | L5: 3.5
A6: Revenue NZ$m | B6: 205.515 | C6: =B6*(1+C5/100) | D6: =C6*(1+D5/100) | E6: =D6*(1+E5/100) | F6: =E6*(1+F5/100) | G6: =F6*(1+G5/100) | H6: =G6*(1+H5/100) | I6: =H6*(1+I5/100) | J6: =I6*(1+J5/100) | ... L6: =K6*(1+L5/100)
A7: Adj EBITDA margin % (driver) | C7: 19.5 | D7: 20.3 | E7: 21 | F7: 21.3 | G7: 21.6 | H7: 21.8 | I7: 21.9 | J7: 22 | K7: 22 | L7: 22
A8: Adjusted EBITDA (pre-lease, IFRS-16 basis) | B8: 39.125 | C8: =C6*C7/100 | D8: =D6*D7/100 | E8: =E6*E7/100 | F8: =F6*F7/100 | G8: =G6*G7/100 | H8: =H6*H7/100 | I8: =I6*I7/100 | J8: =J6*J7/100 | ... L8: =L6*L7/100
A9: SBC % of revenue (driver) | C9: 0.2 | D9: 0.2 | E9: 0.2 | F9: 0.2 | G9: 0.2 | H9: 0.2 | I9: 0.2 | J9: 0.2 | K9: 0.2 | L9: 0.2
A10: SBC $ (negative) | B10: -0.38 | C10: =-C6*C9/100 | D10: =-D6*D9/100 | E10: =-E6*E9/100 | F10: =-F6*F9/100 | G10: =-G6*G9/100 | H10: =-H6*H9/100 | I10: =-I6*I9/100 | J10: =-J6*J9/100 | ... L10: =-L6*L9/100
A11: Lease cash cost % of revenue (link) | C11: =Assumptions!$B$15 | D11: =Assumptions!$B$15 | E11: =Assumptions!$B$15 | F11: =Assumptions!$B$15 | G11: =Assumptions!$B$15 | H11: =Assumptions!$B$15 | I11: =Assumptions!$B$15 | J11: =Assumptions!$B$15 | ... L11: =Assumptions!$B$15
A12: Lease cash cost $ (principal + interest, negative) | B12: -9.728 | C12: =-C6*C11/100 | D12: =-D6*D11/100 | E12: =-E6*E11/100 | F12: =-F6*F11/100 | G12: =-G6*G11/100 | H12: =-H6*H11/100 | I12: =-I6*I11/100 | J12: =-J6*J11/100 | ... L12: =-L6*L11/100
A13: Owned-asset D&A $ (negative, link) | B13: -7.602 | C13: =-C6*Assumptions!$B$5/100 | D13: =-D6*Assumptions!$B$5/100 | E13: =-E6*Assumptions!$B$5/100 | F13: =-F6*Assumptions!$B$5/100 | G13: =-G6*Assumptions!$B$5/100 | H13: =-H6*Assumptions!$B$5/100 | I13: =-I6*Assumptions!$B$5/100 | J13: =-J6*Assumptions!$B$5/100 | ... L13: =-L6*Assumptions!$B$5/100
A14: EBIT (post-lease cash, post-SBC) | C14: =C8+C10+C12+C13 | D14: =D8+D10+D12+D13 | E14: =E8+E10+E12+E13 | F14: =F8+F10+F12+F13 | G14: =G8+G10+G12+G13 | H14: =H8+H10+H12+H13 | I14: =I8+I10+I12+I13 | J14: =J8+J10+J12+J13 | ... L14: =L8+L10+L12+L13
A15: Cash tax rate % (driver) | C15: 18 | D15: 20 | E15: 22 | F15: 25 | G15: 28 | H15: 28 | I15: 28 | J15: 28 | K15: 28 | L15: 28
A16: Cash tax $ (negative) | C16: =-MAX(0,C14)*C15/100 | D16: =-MAX(0,D14)*D15/100 | E16: =-MAX(0,E14)*E15/100 | F16: =-MAX(0,F14)*F15/100 | G16: =-MAX(0,G14)*G15/100 | H16: =-MAX(0,H14)*H15/100 | I16: =-MAX(0,I14)*I15/100 | J16: =-MAX(0,J14)*J15/100 | ... L16: =-MAX(0,L14)*L15/100
A17: NOPAT | C17: =C14+C16 | D17: =D14+D16 | E17: =E14+E16 | F17: =F14+F16 | G17: =G14+G16 | H17: =H14+H16 | I17: =I14+I16 | J17: =J14+J16 | ... L17: =L14+L16
A18: Add back D&A | C18: =-C13 | D18: =-D13 | E18: =-E13 | F18: =-F13 | G18: =-G13 | H18: =-H13 | I18: =-I13 | J18: =-J13 | ... L18: =-L13
A19: Less capex (link) | C19: =-C6*Assumptions!$C$15/100 | D19: =-D6*Assumptions!$C$15/100 | E19: =-E6*Assumptions!$C$15/100 | F19: =-F6*Assumptions!$C$15/100 | G19: =-G6*Assumptions!$C$15/100 | H19: =-H6*Assumptions!$C$15/100 | I19: =-I6*Assumptions!$C$15/100 | J19: =-J6*Assumptions!$C$15/100 | ... L19: =-L6*Assumptions!$C$15/100
A20: Add working capital (link) | C20: =(C6-B6)*Assumptions!$D$15/100 | D20: =(D6-C6)*Assumptions!$D$15/100 | E20: =(E6-D6)*Assumptions!$D$15/100 | F20: =(F6-E6)*Assumptions!$D$15/100 | G20: =(G6-F6)*Assumptions!$D$15/100 | H20: =(H6-G6)*Assumptions!$D$15/100 | I20: =(I6-H6)*Assumptions!$D$15/100 | J20: =(J6-I6)*Assumptions!$D$15/100 | ... L20: =(L6-K6)*Assumptions!$D$15/100
A21: Unlevered owner FCF | B21: 10.335 | C21: =C17+C18+C19+C20 | D21: =D17+D18+D19+D20 | E21: =E17+E18+E19+E20 | F21: =F17+F18+F19+F20 | G21: =G17+G18+G19+G20 | H21: =H17+H18+H19+H20 | I21: =I17+I18+I19+I20 | J21: =J17+J18+J19+J20 | ... L21: =L17+L18+L19+L20
A22: Discount factor | C22: =1/POWER(1+Assumptions!$B$4/100,C4) | D22: =1/POWER(1+Assumptions!$B$4/100,D4) | E22: =1/POWER(1+Assumptions!$B$4/100,E4) | F22: =1/POWER(1+Assumptions!$B$4/100,F4) | G22: =1/POWER(1+Assumptions!$B$4/100,G4) | H22: =1/POWER(1+Assumptions!$B$4/100,H4) | I22: =1/POWER(1+Assumptions!$B$4/100,I4) | J22: =1/POWER(1+Assumptions!$B$4/100,J4) | ... L22: =1/POWER(1+Assumptions!$B$4/100,L4)
A23: PV of FCF | C23: =C21*C22 | D23: =D21*D22 | E23: =E21*E22 | F23: =F21*F22 | G23: =G21*G22 | H23: =H21*H22 | I23: =I21*I22 | J23: =J21*J22 | ... L23: =L21*L22
A25: Memo: FCF before SBC (street-style) | C25: =C21-C10 | D25: =D21-D10 | E25: =E21-E10 | F25: =F21-F10 | G25: =G21-G10 | H25: =H21-H10 | I25: =I21-I10 | J25: =J21-J10 | ... L25: =L21-L10
A26: Memo: owner FCF margin % | B26: =100*B21/B6 | C26: =100*C21/C6 | D26: =100*D21/D6 | E26: =100*E21/E6 | F26: =100*F21/F6 | G26: =100*G21/G6 | H26: =100*H21/H6 | I26: =100*I21/I6 | ... L26: =100*L21/L6
A27: Note: FY2026A owner FCF 10.335 uses reported acquisition-heavy capex 16.073; the forecast capex driver is the normalized rate.
A28: Sum PV of FCF | B28: =SUM(C23:L23)
A29: Terminal growth % (link) | B29: =Assumptions!$E$15
A30: Terminal-year FCF x (1+g) | B30: =L21*(1+B29/100)
A31: Gordon TV | B31: =B30/((Assumptions!$B$4-B29)/100)
A32: Cap TV (cap x FCF10) | B32: =Assumptions!$F$15*L21
A33: TV used = MAX(0,MIN(Gordon,Cap)) | B33: =MAX(0,MIN(B31,B32))
A34: Implied exit multiple (TV/FCF10) | B34: =B33/L21
A35: PV of TV | B35: =B33*L22
A36: Enterprise value | B36: =B28+B35
A37: Less net debt (bank - cash + NCI) | B37: =-Assumptions!$B$6
A38: Equity value | B38: =B36+B37
A39: Shares (m, link) | B39: =Assumptions!$B$7
A40: VALUE PER SHARE (NZD) | B40: =B38/B39
A41: Upside vs price | B41: =B40/Assumptions!$B$2-1
A43: Street memo: PV of explicit SBC | B43: =SUMPRODUCT(-C10:L10,C22:L22)
...

Sheet Actuals
A1: Reported history, NZ$ millions (hardcoded from RAD.NZ_Metrics.csv / kpis / annual reports). FY ends 31 March.
A2: Metric | B2: FY2021 | C2: FY2022 | D2: FY2023 | E2: FY2024 | F2: FY2025 | G2: FY2026 | H2: Source note
A3: Revenue | B3: 126.042 | C3: 135.933 | D3: 149.997 | E3: 174.073 | F3: 180.651 | G3: 205.515 | H3: Metrics.csv
A4: EBITDA (IFRS-16, pre-lease) | B4: 23.287 | C4: 23.366 | D4: 19.474 | E4: 29.178 | F4: 33.025 | G4: 39.125 | H4: Metrics.csv
A5: Net income | B5: 1.705 | C5: 2.673 | D5: -2.106 | E5: -8.488 | F5: 7.399 | G5: 10.053 | H5: FY2023/FY2024 carry impairments
A6: Operating cash flow | B6: 13.907 | C6: 9.877 | D6: 4.037 | E6: 14.1 | F6: 20.053 | G6: 25.121 | H6: Post bank AND lease interest (both presented in operating)
A7: Capex | B7: 4.542 | C7: 38.842 | D7: 58.734 | E7: 4.133 | F7: 6.351 | G7: 16.073 | H7: FY2022/23 property acquisitions; FY2026 St Allisa (13.65 recycled via sale-and-leaseback)
A8: Bank interest paid | B8: 0.883 | C8: 1.436 | D8: 6.506 | E8: 9.388 | F8: 6.065 | G8: 4.558 | H8: Statements of cash flows
A9: Lease interest paid | B9: 8.823 | C9: 7.655 | D9: 5.934 | E9: 5.962 | F9: 5.934 | G9: 6.898 | H9: Inside operating cash flow
A10: Lease principal paid | B10: 4.028 | C10: 3.868 | D10: 2.554 | E10: 2.709 | F10: 2.932 | G10: 2.83 | H10: Financing activities
A11: SBC | B11: 1.196 | C11: 0 | D11: 0.088 | E11: 0.055 | F11: 0.06 | G11: 0.38 | H11: FY2026 LTIP 380k
A12: Cash tax paid | B12: 1.744 | C12: 2.154 | D12: 1.729 | E12: -1.303 | F12: 1.141 | G12: 3.496 | H12: FY2024 was a net refund
A13: Bank borrowings | B13: 27.212 | C13: 30 | D13: 97.687 | E13: 75.869 | F13: 70.301 | G13: 71.564 | H13: kpis
A14: Lease liabilities | B14: 184.305 | C14: 142.543 | D14: 121.53 | E14: 121.086 | F14: 122.697 | G14: 141.512 | H14: kpis; EXCLUDED from net debt (treatment B)
... A18: Dividends paid | B18: 0.732 | C18: 2.478 | D18: 2.892 | E18: 0 | F18: 3.846 | G18: 5.723 | H18: FY2026 dividend +50%
A20: Balance-sheet snapshot 31-Mar-2026: bank 71.564, cash 2.823, leases 141.512, NCI 0.596, equity 76.317. FY2019/FY2020 rows omitted: OCR-corrupted scans, IFRS-16 adoption break, pre-split counts.

Sheet FCF_Quality
A1: Reported FCF reconciled to unlevered owner FCF (NZ$m). Owner FCF = OCF - capex + bank interest paid - lease principal - SBC - interest income. Lease interest stays deducted (already inside OCF).
B2: FY2021 | C2: FY2022 | D2: FY2023 | E2: FY2024 | F2: FY2025 | G2: FY2026
A3: Operating cash flow | B3: 13.907 | C3: 9.877 | D3: 4.037 | E3: 14.1 | F3: 20.053 | G3: 25.121
A4: Less capex (reported) | B4: -4.542 | C4: -38.842 | D4: -58.734 | E4: -4.133 | F4: -6.351 | G4: -16.073
A5: Reported FCF (company-style) | B5: =B3+B4 | C5: =C3+C4 | D5: =D3+D4 | E5: =E3+E4 | F5: =F3+F4 | G5: =G3+G4
A6: Add back bank interest paid (unlevered; bank debt in bridge) | B6: 0.883 | C6: 1.436 | D6: 6.506 | E6: 9.388 | F6: 6.065 | G6: 4.558
A7: Less lease principal (moved from financing into flows) | B7: -4.028 | C7: -3.868 | D7: -2.554 | E7: -2.709 | F7: -2.932 | G7: -2.83
A8: Less SBC | B8: -1.196 | C8: 0 | D8: -0.088 | E8: -0.055 | F8: -0.06 | G8: -0.38
A9: Less interest income | B9: -0.071 | C9: -0.062 | D9: -0.067 | E9: -0.136 | F9: -0.148 | G9: -0.061
A10: OWNER FCF | B10: =B5+B6+B7+B8+B9 | C10: =C5+C6+C7+C8+C9 | D10: =D5+D6+D7+D8+D9 | E10: =E5+E6+E7+E8+E9 | F10: =F5+F6+F7+F8+F9 | G10: =G5+G6+G7+G8+G9
A11: Revenue | B11: 126.042 | C11: 135.933 | D11: 149.997 | E11: 174.073 | F11: 180.651 | G11: 205.515
A12: Reported FCF margin % | B12: =100*B5/B11 | C12: =100*C5/C11 | D12: =100*D5/D11 | E12: =100*E5/E11 | F12: =100*F5/F11 | G12: =100*G5/G11
A13: Owner FCF margin % | B13: =100*B10/B11 | C13: =100*C10/C11 | D13: =100*D10/D11 | E13: =100*E10/E11 | F13: =100*F10/F11 | G13: =100*G10/G11
A14: Memo: lease interest inside OCF | B14: -8.823 | C14: -7.655 | D14: -5.934 | E14: -5.962 | F14: -5.934 | G14: -6.898
A15: Memo: cash tax paid | B15: -1.744 | C15: -2.154 | D15: -1.729 | E15: 1.303 | F15: -1.141 | G15: -3.496
A17: FY2022/FY2023 owner FCF (-31.5, -50.9) reflect property-acquisition capex years; FY2026 capex 16.073 is acquisition-heavy (St Allisa; 13.65 recycled via related-party sale-and-leaseback, proceeds not netted here). Normalized maintenance+development capex is the ~3% forecast driver.

Sheet Valuation
A1: Valuation summary - all cells formula-driven
A3: Scenario | B3: Value/share | C3: Street/share | D3: Upside vs price | E3: Weight
A4: Bear | B4: =DCF_Bear!B40 | C4: =DCF_Bear!B45 | D4: =B4/Assumptions!$B$2-1 | E4: =Assumptions!G13
A5: Base | B5: =DCF_Base!B40 | C5: =DCF_Base!B45 | D5: =B5/Assumptions!$B$2-1 | E5: =Assumptions!G14
A6: Bull | B6: =DCF_Bull!B40 | C6: =DCF_Bull!B45 | D6: =B6/Assumptions!$B$2-1 | E6: =Assumptions!G15
A8: Probability-weighted IV | B8: =SUMPRODUCT(B4:B6,E4:E6)
A9: Street weighted IV | B9: =SUMPRODUCT(C4:C6,E4:E6)
A10: Margin of safety vs price | B10: =1-Assumptions!B2/B8
A11: Band position (house->street) | B11: =(Assumptions!B2-B8)/(B9-B8)
A12: Band note: SBC ~0.2% of revenue so the house/street band is ~3% wide - near-degenerate; position outside 0-1 is not meaningful.
A14: Entry price @15% IRR
A15: Bear | B15: =(SUMPRODUCT(DCF_Bear!C21:L21,1/POWER(1+Assumptions!$B$8/100,DCF_Bear!C4:L4))+DCF_Bear!B33/POWER(1+Assumptions!$B$8/100,10)-Assumptions!$B$6)/Assumptions!$B$7
A16: Base | B16: =(SUMPRODUCT(DCF_Base!C21:L21,1/POWER(1+Assumptions!$B$8/100,DCF_Base!C4:L4))+DCF_Base!B33/POWER(1+Assumptions!$B$8/100,10)-Assumptions!$B$6)/Assumptions!$B$7
A17: Bull | B17: =(SUMPRODUCT(DCF_Bull!C21:L21,1/POWER(1+Assumptions!$B$8/100,DCF_Bull!C4:L4))+DCF_Bull!B33/POWER(1+Assumptions!$B$8/100,10)-Assumptions!$B$6)/Assumptions!$B$7
A18: Weighted entry price | B18: =SUMPRODUCT(B15:B17,E4:E6)
A20: Required-return table (base case; TV held at model WACC, discounted at r)
A21: Required return % | B21: 9 | C21: 10 | D21: 11 | E21: 12 | F21: 14.5 | G21: 15
A22: Value per share | B22: =(SUMPRODUCT(DCF_Base!$C$21:$L$21,1/POWER(1+B21/100,DCF_Base!$C$4:$L$4))+DCF_Base!$B$33/POWER(1+B21/100,10)-Assumptions!$B$6)/Assumptions!$B$7 | C22: =(SUMPRODUCT(DCF_Base!$C$21:$L$21,1/POWER(1+C21/100,DCF_Base!$C$4:$L$4))+DCF_Base!$B$33/POWER(1+C21/100,10)-Assumptions!$B$6)/Assumptions!$B$7 | D22: =(SUMPRODUCT(DCF_Base!$C$21:$L$21,1/POWER(1+D21/100,DCF_Base!$C$4:$L$4))+DCF_Base!$B$33/POWER(1+D21/100,10)-Assumptions!$B$6)/Assumptions!$B$7 | E22: =(SUMPRODUCT(DCF_Base!$C$21:$L$21,1/POWER(1+E21/100,DCF_Base!$C$4:$L$4))+DCF_Base!$B$33/POWER(1+E21/100,10)-Assumptions!$B$6)/Assumptions!$B$7 | F22: =(SUMPRODUCT(DCF_Base!$C$21:$L$21,1/POWER(1+F21/100,DCF_Base!$C$4:$L$4))+DCF_Base!$B$33/POWER(1+F21/100,10)-Assumptions!$B$6)/Assumptions!$B$7 | G22: =(SUMPRODUCT(DCF_Base!$C$21:$L$21,1/POWER(1+G21/100,DCF_Base!$C$4:$L$4))+DCF_Base!$B$33/POWER(1+G21/100,10)-Assumptions!$B$6)/Assumptions!$B$7
A25: Sensitivity: value per share, base case (rows WACC %, cols terminal growth %)
B26: 1 | C26: 1.5 | D26: 2 | E26: 2.5 | F26: 3
A27: 12.5 | B27: =IF($A27>B$26,(SUMPRODUCT(DCF_Base!$C$21:$L$21,1/POWER(1+$A27/100,DCF_Base!$C$4:$L$4))+MAX(0,MIN(DCF_Base!$L$21*(1+B$26/100)/(($A27-B$26)/100),Assumptions!$F$14*DCF_Base!$L$21))/POWER(1+$A27/100,10)-Assumptions!$B$6)/Assumptions!$B$7,"n/a") | C27: =IF($A27>C$26,(SUMPRODUCT(DCF_Base!$C$21:$L$21,1/POWER(1+$A27/100,DCF_Base!$C$4:$L$4))+MAX(0,MIN(DCF_Base!$L$21*(1+C$26/100)/(($A27-C$26)/100),Assumptions!$F$14*DCF_Base!$L$21))/POWER(1+$A27/100,10)-Assumptions!$B$6)/Assumptions!$B$7,"n/a") | D27: =IF($A27>D$26,(SUMPRODUCT(DCF_Base!$C$21:$L$21,1/POWER(1+$A27/100,DCF_Base!$C$4:$L$4))+MAX(0,MIN(DCF_Base!$L$21*(1+D$26/100)/(($A27-D$26)/100),Assumptions!$F$14*DCF_Base!$L$21))/POWER(1+$A27/100,10)-Assumptions!$B$6)/Assumptions!$B$7,"n/a") | E27: =IF($A27>E$26,(SUMPRODUCT(DCF_Base!$C$21:$L$21,1/POWER(1+$A27/100,DCF_Base!$C$4:$L$4))+MAX(0,MIN(DCF_Base!$L$21*(1+E$26/100)/(($A27-E$26)/100),Assumptions!$F$14*DCF_Base!$L$21))/POWER(1+$A27/100,10)-Assumptions!$B$6)/Assumptions!$B$7,"n/a") | F27: =IF($A27>F$26,(SUMPRODUCT(DCF_Base!$C$21:$L$21,1/POWER(1+$A27/100,DCF_Base!$C$4:$L$4))+MAX(0,MIN(DCF_Base!$L$21*(1+F$26/100)/(($A27-F$26)/100),Assumptions!$F$14*DCF_Base!$L$21))/POWER(1+$A27/100,10)-Assumptions!$B$6)/Assumptions!$B$7,"n/a")
A28: 13.5 | B28: =IF($A28>B$26,(SUMPRODUCT(DCF_Base!$C$21:$L$21,1/POWER(1+$A28/100,DCF_Base!$C$4:$L$4))+MAX(0,MIN(DCF_Base!$L$21*(1+B$26/100)/(($A28-B$26)/100),Assumptions!$F$14*DCF_Base!$L$21))/POWER(1+$A28/100,10)-Assumptions!$B$6)/Assumptions!$B$7,"n/a") | C28: =IF($A28>C$26,(SUMPRODUCT(DCF_Base!$C$21:$L$21,1/POWER(1+$A28/100,DCF_Base!$C$4:$L$4))+MAX(0,MIN(DCF_Base!$L$21*(1+C$26/100)/(($A28-C$26)/100),Assumptions!$F$14*DCF_Base!$L$21))/POWER(1+$A28/100,10)-Assumptions!$B$6)/Assumptions!$B$7,"n/a") | D28: =IF($A28>D$26,(SUMPRODUCT(DCF_Base!$C$21:$L$21,1/POWER(1+$A28/100,DCF_Base!$C$4:$L$4))+MAX(0,MIN(DCF_Base!$L$21*(1+D$26/100)/(($A28-D$26)/100),Assumptions!$F$14*DCF_Base!$L$21))/POWER(1+$A28/100,10)-Assumptions!$B$6)/Assumptions!$B$7,"n/a") | E28: =IF($A28>E$26,(SUMPRODUCT(DCF_Base!$C$21:$L$21,1/POWER(1+$A28/100,DCF_Base!$C$4:$L$4))+MAX(0,MIN(DCF_Base!$L$21*(1+E$26/100)/(($A28-E$26)/100),Assumptions!$F$14*DCF_Base!$L$21))/POWER(1+$A28/100,10)-Assumptions!$B$6)/Assumptions!$B$7,"n/a") | F28: =IF($A28>F$26,(SUMPRODUCT(DCF_Base!$C$21:$L$21,1/POWER(1+$A28/100,DCF_Base!$C$4:$L$4))+MAX(0,MIN(DCF_Base!$L$21*(1+F$26/100)/(($A28-F$26)/100),Assumptions!$F$14*DCF_Base!$L$21))/POWER(1+$A28/100,10)-Assumptions!$B$6)/Assumptions!$B$7,"n/a")
A29: 14.5 | B29: =IF($A29>B$26,(SUMPRODUCT(DCF_Base!$C$21:$L$21,1/POWER(1+$A29/100,DCF_Base!$C$4:$L$4))+MAX(0,MIN(DCF_Base!$L$21*(1+B$26/100)/(($A29-B$26)/100),Assumptions!$F$14*DCF_Base!$L$21))/POWER(1+$A29/100,10)-Assumptions!$B$6)/Assumptions!$B$7,"n/a") | C29: =IF($A29>C$26,(SUMPRODUCT(DCF_Base!$C$21:$L$21,1/POWER(1+$A29/100,DCF_Base!$C$4:$L$4))+MAX(0,MIN(DCF_Base!$L$21*(1+C$26/100)/(($A29-C$26)/100),Assumptions!$F$14*DCF_Base!$L$21))/POWER(1+$A29/100,10)-Assumptions!$B$6)/Assumptions!$B$7,"n/a") | D29: =IF($A29>D$26,(SUMPRODUCT(DCF_Base!$C$21:$L$21,1/POWER(1+$A29/100,DCF_Base!$C$4:$L$4))+MAX(0,MIN(DCF_Base!$L$21*(1+D$26/100)/(($A29-D$26)/100),Assumptions!$F$14*DCF_Base!$L$21))/POWER(1+$A29/100,10)-Assumptions!$B$6)/Assumptions!$B$7,"n/a") | E29: =IF($A29>E$26,(SUMPRODUCT(DCF_Base!$C$21:$L$21,1/POWER(1+$A29/100,DCF_Base!$C$4:$L$4))+MAX(0,MIN(DCF_Base!$L$21*(1+E$26/100)/(($A29-E$26)/100),Assumptions!$F$14*DCF_Base!$L$21))/POWER(1+$A29/100,10)-Assumptions!$B$6)/Assumptions!$B$7,"n/a") | F29: =IF($A29>F$26,(SUMPRODUCT(DCF_Base!$C$21:$L$21,1/POWER(1+$A29/100,DCF_Base!$C$4:$L$4))+MAX(0,MIN(DCF_Base!$L$21*(1+F$26/100)/(($A29-F$26)/100),Assumptions!$F$14*DCF_Base!$L$21))/POWER(1+$A29/100,10)-Assumptions!$B$6)/Assumptions!$B$7,"n/a")
A30: 15.5 | B30: =IF($A30>B$26,(SUMPRODUCT(DCF_Base!$C$21:$L$21,1/POWER(1+$A30/100,DCF_Base!$C$4:$L$4))+MAX(0,MIN(DCF_Base!$L$21*(1+B$26/100)/(($A30-B$26)/100),Assumptions!$F$14*DCF_Base!$L$21))/POWER(1+$A30/100,10)-Assumptions!$B$6)/Assumptions!$B$7,"n/a") | C30: =IF($A30>C$26,(SUMPRODUCT(DCF_Base!$C$21:$L$21,1/POWER(1+$A30/100,DCF_Base!$C$4:$L$4))+MAX(0,MIN(DCF_Base!$L$21*(1+C$26/100)/(($A30-C$26)/100),Assumptions!$F$14*DCF_Base!$L$21))/POWER(1+$A30/100,10)-Assumptions!$B$6)/Assumptions!$B$7,"n/a") | D30: =IF($A30>D$26,(SUMPRODUCT(DCF_Base!$C$21:$L$21,1/POWER(1+$A30/100,DCF_Base!$C$4:$L$4))+MAX(0,MIN(DCF_Base!$L$21*(1+D$26/100)/(($A30-D$26)/100),Assumptions!$F$14*DCF_Base!$L$21))/POWER(1+$A30/100,10)-Assumptions!$B$6)/Assumptions!$B$7,"n/a") | E30: =IF($A30>E$26,(SUMPRODUCT(DCF_Base!$C$21:$L$21,1/POWER(1+$A30/100,DCF_Base!$C$4:$L$4))+MAX(0,MIN(DCF_Base!$L$21*(1+E$26/100)/(($A30-E$26)/100),Assumptions!$F$14*DCF_Base!$L$21))/POWER(1+$A30/100,10)-Assumptions!$B$6)/Assumptions!$B$7,"n/a") | F30: =IF($A30>F$26,(SUMPRODUCT(DCF_Base!$C$21:$L$21,1/POWER(1+$A30/100,DCF_Base!$C$4:$L$4))+MAX(0,MIN(DCF_Base!$L$21*(1+F$26/100)/(($A30-F$26)/100),Assumptions!$F$14*DCF_Base!$L$21))/POWER(1+$A30/100,10)-Assumptions!$B$6)/Assumptions!$B$7,"n/a")
A31: 16.5 | B31: =IF($A31>B$26,(SUMPRODUCT(DCF_Base!$C$21:$L$21,1/POWER(1+$A31/100,DCF_Base!$C$4:$L$4))+MAX(0,MIN(DCF_Base!$L$21*(1+B$26/100)/(($A31-B$26)/100),Assumptions!$F$14*DCF_Base!$L$21))/POWER(1+$A31/100,10)-Assumptions!$B$6)/Assumptions!$B$7,"n/a") | C31: =IF($A31>C$26,(SUMPRODUCT(DCF_Base!$C$21:$L$21,1/POWER(1+$A31/100,DCF_Base!$C$4:$L$4))+MAX(0,MIN(DCF_Base!$L$21*(1+C$26/100)/(($A31-C$26)/100),Assumptions!$F$14*DCF_Base!$L$21))/POWER(1+$A31/100,10)-Assumptions!$B$6)/Assumptions!$B$7,"n/a") | D31: =IF($A31>D$26,(SUMPRODUCT(DCF_Base!$C$21:$L$21,1/POWER(1+$A31/100,DCF_Base!$C$4:$L$4))+MAX(0,MIN(DCF_Base!$L$21*(1+D$26/100)/(($A31-D$26)/100),Assumptions!$F$14*DCF_Base!$L$21))/POWER(1+$A31/100,10)-Assumptions!$B$6)/Assumptions!$B$7,"n/a") | E31: =IF($A31>E$26,(SUMPRODUCT(DCF_Base!$C$21:$L$21,1/POWER(1+$A31/100,DCF_Base!$C$4:$L$4))+MAX(0,MIN(DCF_Base!$L$21*(1+E$26/100)/(($A31-E$26)/100),Assumptions!$F$14*DCF_Base!$L$21))/POWER(1+$A31/100,10)-Assumptions!$B$6)/Assumptions!$B$7,"n/a") | F31: =IF($A31>F$26,(SUMPRODUCT(DCF_Base!$C$21:$L$21,1/POWER(1+$A31/100,DCF_Base!$C$4:$L$4))+MAX(0,MIN(DCF_Base!$L$21*(1+F$26/100)/(($A31-F$26)/100),Assumptions!$F$14*DCF_Base!$L$21))/POWER(1+$A31/100,10)-Assumptions!$B$6)/Assumptions!$B$7,"n/a")
A33: Grid re-discounts the SAME base FCF path at the row WACC (Gordon TV recomputed at that WACC); it does not re-run the discount factors on the DCF tab.
