Workbook

Sheet Model_Info
A1: WISE GROUP (WISE) - DCF MODEL
A3: Lineage | B3: v1.0, built 22-Sep-2026 (NZ) by Claude (Fable 5.1) with Stephen via claude.ai (openpyxl; recalculated in LibreOffice; key outputs hand-checked). Fresh build - no prior Wise workbook was uploaded. Follows the equity-deep-dive checkpoint signed off in-chat on 22-Sep-26.
A5: DATA VINTAGE
A6: FY0 anchors | B6: FY26 (year to 31-Mar-26) results release 25-Jun-26 and Form 20-F (SEC accession 0001193125-26-282911): net revenue $2,502.8m; operating income $590.7m; income before tax $660.4m (26.4%); net income $498.7m; SBC ~$95.5m; interest income on customer balances $806.1m, interest paid to customers $196.9m; one-offs $45m listing costs, -$59.6m FX loss on gilts.
A7: FY1 guidance | B7: FY27 guide (25-Jun-26, reiterated 16-Jul-26): net revenue growth around the middle of 15-20% cc, assuming no change in central bank rates or customer interest payout; income-before-tax margin around the top of 20-25%. Q1 FY27 (16-Jul-26): net revenue +25% to $714.0m, volume +26%, take rate 50bps. Rates since: ECB +25bp (10-Sep), Fed hike (16-Sep), BoE hold with hawkish dissent (17-Sep).
A8: Balance sheet / shares / price | B8: Balance sheet 31-Mar-26 (20-F): total assets $33,260m of which customer funds payable $30,254m; equity $1,930m; long-term debt ~$329m (GBP250m 2030 notes). Shares: 1,025m Class A issued 31-May-26; FY26 diluted WA 1,030m used. Price 856.4p user-supplied 22-Sep-26 at GBPUSD 1.34 (estimate - refresh).
A9: Regulatory state | B9: Brussels prosecutor investigation (disclosed 1-Jun-26; direct summons being finalised, none issued as of build). NBB published administrative measure 25-Aug-26: CDD/KYC/monitoring shortcomings, full compliance required by 31-Jan-27, plus notice of non-compliance with an earlier order. OCC denied trust-bank charter 21-Jul-26 (AML deficiencies); Wise to reapply under GENIUS. US securities class action (class period 11-May to 23-Jul-26). 20-F discloses ICFR material weaknesses.
A11: METHODOLOGY
A12: Owner-FCF basis | B12: SBC (incl. equity-award taxes) fully expensed, projected explicitly per scenario-year as % of revenue; INTEREST INCOME EXCLUDED from flows (cash pile added separately - including both double-counts); cash tax ramps from the current sheltered rate to a normalized ~21%; D&A and capex as % of revenue; working capital = 0% of the YoY revenue increase (set for this business model); diluted shares held FLAT (SBC expensing substitutes for grant dilution; never do both). TV = Gordon capped at 20x terminal owner FCF. End-of-year discounting. WACC 10.5%. Street-convention values (SBC as non-cash) shown as memos - the house/street pair is the accounting-regime price band.
A13: Wise-specific choices | B13: (1) Net interest income on CUSTOMER balances is operating revenue and stays in flows; the matching asset is customer money and is NOT on the bridge - so no double count. Only interest on Wise's OWN cash is excluded (US GAAP non-operating line, ~$70m in FY26 incl. FX), and that own cash is the net-cash bridge item. (2) Leases: US GAAP operating leases are expensed in opex (operating-style treatment); lease liabilities excluded from net debt. (3) Cash tax held at 24% throughout (FY26 effective 24.5%; UK statutory 25%; no NOL shelter, DTA only $57m) - the house 21% ramp is a US default and does not apply. (4) Working capital neutral (0%): float belongs to customers, receivables immaterial. (5) Software not capitalised (20-F), so capex is PP&E only; D&A and capex both 2.5% of revenue. (6) Model in USD (reporting currency); price converted from pence at the Assumptions FX cell; pence readouts on the Valuation tab. (7) Rates: the +50bp Sep-26 hikes are in Base/Bull year-1 margin; the FY27 guide assumed no change, so guidance has upside risk. (8) Take rate is not a separate driver - it is inside revenue growth (volume growth minus take-rate compression) per the narratives.
A14: Scenario drivers | B14: Scenario paths are Claude's proposal from the 22-Sep-26 dive, confirmed by Stephen in-chat with one amendment: +50bp of policy rates added to Base and Bull year-1 margins (ECB/Fed hikes in Sep-26), Bear keeps -100bp. Weights 15/50/35 (house default, confirmed). Evidence that would move them: NBB outcome at/after 31-Jan-27; issuance and terms of the Belgian summons; Q2 (15-Oct) and H1 (12-Nov) take-rate and volume prints; any customer-interest payout change in the UK.
A16: UPDATE INSTRUCTIONS
A17: Each quarter | B17: Refresh price, net cash (+date), diluted shares, buyback pace, and the guidance-year driver columns; reassess blue rows 5/7/9/14 per scenario only where new evidence exists; add/extend the Reconciliation tab; increment the version above.
A18: Conventions | B18: Blue = hardcoded input. Yellow = key levers. Black = formula. Green = cross-sheet link. Prefilled values are working examples of the expected format.

Sheet Assumptions
A1: WISE - Global Assumptions & Scenario Parameters
A2: Blue = hardcoded input. Yellow = key levers. All $ in millions unless stated.
A4: Global inputs
A5: WACC / discount rate | B5: 0.105
A6: D&A (% of revenue) | B6: 0.025
A7: Capex + capitalized software (% of revenue) | B7: 0.025
A8: Working-capital capture (% of YoY revenue incr.) | B8: 0 | H8: Sign/size per business model
A9: Net cash ($mm) | B9: 1600 | H9: 31-Mar-26, DERIVED: own liquid resources (shareholders' equity $1,930m + debt $335m - PP&E/intangibles/other non-financial ~$300m) less the GBP250m 2030 notes and other debt ($335m). Customer balances ($30.3bn) are safeguarded and EXCLUDED. Replace with the 20-F liquidity-section own-cash figure when pulled.
A10: Fully diluted shares (mm) | B10: 1030 | H10: FY26 diluted weighted-average (20-F). 1,025m Class A issued at 31-May-26; Class B (204m) carry votes only, no economics - excluded. EST holds shares against options, so diluted WA is the safer count. Held flat (house rule).
A11: Current share price | B11: 11.48 | H11: 856.4p LSE, user-supplied 22-Sep-26 NZ time, x GBPUSD 1.34 (Assumptions FX cell). Refresh both at next London close.
A12: Terminal value cap (x terminal-year owner FCF) | B12: 20
A13: GBP/USD spot (for pence readouts) | B13: 1.34 | H13: Estimate 22-Sep-26; sterling weak after BoE hold vs Fed hike. Refresh with price. Row 13.
A15: Scenario parameters | C15: Bear | D15: Base | E15: Bull
A16: Terminal growth rate | C16: 0.015 | D16: 0.03 | E16: 0.035
A17: Probability weight | C17: 0.15 | D17: 0.5 | E17: 0.35 | F17: =SUM(C17:E17) -> 1 | G17: must sum to 100%
A19: Scenario narratives
A20: Bear | B20: NBB deadline (31-Jan-27) missed or met with conditions; EEA onboarding restricted for a period; Belgian criminal fine plus multi-year remediation. Servicing cost stays elevated, take rate cut 46->42bps with volume growth only ~15%, and rates fall 100bp so NII shrinks. Revenue growth steps down to 8-9% and fades to 4%; EBITDA margin (SBC added back) 23%; SBC stuck at 4%.
A21: Base | B21: NBB order met by January; a summons is issued but resolves as a fine in the tens of millions plus a year of headlines. FY27 revenue ~17.5% (guide mid-point) helped by +50bp of policy rates, fading ~1pt/yr to 8%. Take rate to ~44bps on ~22% volume growth. EBITDA margin 31% near term drifting to 27% as customer interest payout is enabled and rates normalise. SBC 3.8% -> 3.0%, fully bought back.
A22: Bull | B22: Regulatory issues resolve as base but Wise Platform reaches the 10% volume target, a tier-1 bank signs, and a US charter is granted under GENIUS by FY28 cutting US unit cost. Revenue ~19% for two years fading to 10%; EBITDA margin holds ~31-32% because balances grow faster than rates fall and the +50bp rate tailwind persists. Take rate 44bps by FY28 on ~28% volume. SBC to 3%.

Sheet DCF_Bear
A1: WISE DCF - Bear - compliance becomes the growth engine
A2: Owner-FCF basis: SBC fully expensed, interest income excluded, share count flat. Blue rows = per-year drivers (edit).
B3: 2026A | C3: 2027E | D3: 2028E | E3: 2029E | F3: 2030E | G3: 2031E | H3: 2032E | I3: 2033E | J3: 2034E | K3: 2035E | L3: 2036E
A4: Year index (for discounting) | B4: 0 | C4: 1 | D4: 2 | E4: 3 | F4: 4 | G4: 5 | H4: 6 | I4: 7 | J4: 8 | K4: 9 | L4: 10
A5: Revenue growth YoY | C5: 0.14 | D5: 0.08 | E5: 0.08 | F5: 0.09 | G5: 0.09 | H5: 0.08 | I5: 0.07 | J5: 0.06 | K5: 0.05 | L5: 0.04
A6: Revenue | B6: 2502.8 | C6: =B6*(1+C5) -> 2853.192 | D6: =C6*(1+D5) -> 3081.4474 | E6: =D6*(1+E5) -> 3327.9631 | F6: =E6*(1+F5) -> 3627.4798 | G6: =F6*(1+G5) -> 3953.953 | H6: =G6*(1+H5) -> 4270.2693 | I6: =H6*(1+I5) -> 4569.1881 | J6: =I6*(1+J5) -> 4843.3394 | ... L6: =K6*(1+L5) -> 5288.9266
A7: Adj EBITDA margin | B7: 0.318 | C7: 0.28 | D7: 0.24 | E7: 0.23 | F7: 0.23 | G7: 0.23 | H7: 0.23 | I7: 0.23 | J7: 0.23 | K7: 0.23 | L7: 0.23
A8: Adjusted EBITDA | C8: =C6*C7 -> 798.89376 | D8: =D6*D7 -> 739.54737 | E8: =E6*E7 -> 765.43152 | F8: =F6*F7 -> 834.32036 | G8: =G6*G7 -> 909.40919 | H8: =H6*H7 -> 982.16193 | I8: =I6*I7 -> 1050.9133 | J8: =J6*J7 -> 1113.9681 | ... L8: =L6*L7 -> 1216.4531
A9: SBC (% of revenue) | B9: 0.038 | C9: 0.04 | D9: 0.04 | E9: 0.04 | F9: 0.04 | G9: 0.04 | H9: 0.04 | I9: 0.04 | J9: 0.04 | K9: 0.04 | L9: 0.04
A10: SBC (incl. equity-award taxes) | C10: =-C6*C9 -> -114.12768 | D10: =-D6*D9 -> -123.25789 | E10: =-E6*E9 -> -133.11853 | F10: =-F6*F9 -> -145.09919 | G10: =-G6*G9 -> -158.15812 | H10: =-H6*H9 -> -170.81077 | I10: =-I6*I9 -> -182.76752 | J10: =-J6*J9 -> -193.73358 | ... L10: =-L6*L9 -> -211.55706
A11: EBITDA less SBC ('owner EBITDA') | C11: =C8+C10 -> 684.76608 | D11: =D8+D10 -> 616.28947 | E11: =E8+E10 -> 632.313 | F11: =F8+F10 -> 689.22117 | G11: =G8+G10 -> 751.25107 | H11: =H8+H10 -> 811.35116 | I11: =I8+I10 -> 868.14574 | J11: =J8+J10 -> 920.23448 | ... L11: =L8+L10 -> 1004.8961
A12: D&A | C12: =-C6*Assumptions!$B$6 -> -71.3298 | D12: =-D6*Assumptions!$B$6 -> -77.036184 | E12: =-E6*Assumptions!$B$6 -> -83.199079 | F12: =-F6*Assumptions!$B$6 -> -90.686996 | G12: =-G6*Assumptions!$B$6 -> -98.848825 | H12: =-H6*Assumptions!$B$6 -> -106.75673 | I12: =-I6*Assumptions!$B$6 -> -114.2297 | J12: =-J6*Assumptions!$B$6 -> -121.08348 | ... L12: =-L6*Assumptions!$B$6 -> -132.22317
A13: EBIT (SBC expensed) | C13: =C11+C12 -> 613.43628 | D13: =D11+D12 -> 539.25329 | E13: =E11+E12 -> 549.11392 | F13: =F11+F12 -> 598.53417 | G13: =G11+G12 -> 652.40225 | H13: =H11+H12 -> 704.59443 | I13: =I11+I12 -> 753.91604 | J13: =J11+J12 -> 799.151 | ... L13: =L11+L12 -> 872.67289
A14: Cash tax rate (neg = benefit) | C14: 0.24 | D14: 0.24 | E14: 0.24 | F14: 0.24 | G14: 0.24 | H14: 0.24 | I14: 0.24 | J14: 0.24 | K14: 0.24 | L14: 0.24
A15: NOPAT | C15: =C13*(1-C14) -> 466.21157 | D15: =D13*(1-D14) -> 409.8325 | E15: =E13*(1-E14) -> 417.32658 | F15: =F13*(1-F14) -> 454.88597 | G15: =G13*(1-G14) -> 495.82571 | H15: =H13*(1-H14) -> 535.49177 | I15: =I13*(1-I14) -> 572.97619 | J15: =J13*(1-J14) -> 607.35476 | ... L15: =L13*(1-L14) -> 663.2314
A16: add: D&A | C16: =-C12 -> 71.3298 | D16: =-D12 -> 77.036184 | E16: =-E12 -> 83.199079 | F16: =-F12 -> 90.686996 | G16: =-G12 -> 98.848825 | H16: =-H12 -> 106.75673 | I16: =-I12 -> 114.2297 | J16: =-J12 -> 121.08348 | ... L16: =-L12 -> 132.22317
A17: less: capex + capitalized software | C17: =-C6*Assumptions!$B$7 -> -71.3298 | D17: =-D6*Assumptions!$B$7 -> -77.036184 | E17: =-E6*Assumptions!$B$7 -> -83.199079 | F17: =-F6*Assumptions!$B$7 -> -90.686996 | G17: =-G6*Assumptions!$B$7 -> -98.848825 | H17: =-H6*Assumptions!$B$7 -> -106.75673 | I17: =-I6*Assumptions!$B$7 -> -114.2297 | J17: =-J6*Assumptions!$B$7 -> -121.08348 | ... L17: =-L6*Assumptions!$B$7 -> -132.22317
A18: add: working capital | C18: =Assumptions!$B$8*(C6-B6) -> 0 | D18: =Assumptions!$B$8*(D6-C6) -> 0 | E18: =Assumptions!$B$8*(E6-D6) -> 0 | F18: =Assumptions!$B$8*(F6-E6) -> 0 | G18: =Assumptions!$B$8*(G6-F6) -> 0 | H18: =Assumptions!$B$8*(H6-G6) -> 0 | I18: =Assumptions!$B$8*(I6-H6) -> 0 | J18: =Assumptions!$B$8*(J6-I6) -> 0 | ... L18: =Assumptions!$B$8*(L6-K6) -> 0
A19: Unlevered owner FCF | C19: =C15+C16+C17+C18 -> 466.21157 | D19: =D15+D16+D17+D18 -> 409.8325 | E19: =E15+E16+E17+E18 -> 417.32658 | F19: =F15+F16+F17+F18 -> 454.88597 | G19: =G15+G16+G17+G18 -> 495.82571 | H19: =H15+H16+H17+H18 -> 535.49177 | I19: =I15+I16+I17+I18 -> 572.97619 | J19: =J15+J16+J17+J18 -> 607.35476 | ... L19: =L15+L16+L17+L18 -> 663.2314
A20: Discount factor | C20: =1/(1+Assumptions!$B$5)^C4 -> 0.90497738 | D20: =1/(1+Assumptions!$B$5)^D4 -> 0.81898405 | E20: =1/(1+Assumptions!$B$5)^E4 -> 0.74116204 | F20: =1/(1+Assumptions!$B$5)^F4 -> 0.67073487 | G20: =1/(1+Assumptions!$B$5)^G4 -> 0.60699989 | H20: =1/(1+Assumptions!$B$5)^H4 -> 0.54932116 | I20: =1/(1+Assumptions!$B$5)^I4 -> 0.49712323 | J20: =1/(1+Assumptions!$B$5)^J4 -> 0.44988527 | ... L20: =1/(1+Assumptions!$B$5)^L4 -> 0.36844886
A21: PV of FCF | C21: =C19*C20 -> 421.91093 | D21: =D19*D20 -> 335.64628 | E21: =E19*E20 -> 309.30662 | F21: =F19*F20 -> 305.10788 | G21: =G19*G20 -> 300.96615 | H21: =H19*H20 -> 294.15696 | I21: =I19*I20 -> 284.83977 | J21: =J19*J20 -> 273.23996 | ... L21: =L19*L20 -> 244.36685
A23: Memo: FCF before SBC (company-style) | C23: =C19-C10 -> 580.33925 | D23: =D19-D10 -> 533.09039 | E23: =E19-E10 -> 550.4451 | F23: =F19-F10 -> 599.98516 | G23: =G19-G10 -> 653.98383 | H23: =H19-H10 -> 706.30254 | I23: =I19-I10 -> 755.74371 | J23: =J19-J10 -> 801.08834 | ... L23: =L19-L10 -> 874.78846
A24: Memo: implied owner FCF margin | C24: =C19/C6 -> 0.1634 | D24: =D19/D6 -> 0.133 | E24: =E19/E6 -> 0.1254 | F24: =F19/F6 -> 0.1254 | G24: =G19/G6 -> 0.1254 | H24: =H19/H6 -> 0.1254 | I24: =I19/I6 -> 0.1254 | J24: =J19/J6 -> 0.1254 | ... L24: =L19/L6 -> 0.1254
A25: Valuation
A26: PV of FCF, explicit years | B26: =SUM(C21:L21) -> 3029.1812
A27: Terminal growth rate | B27: =Assumptions!$C$16 -> 0.015
A28: Terminal-year owner FCF x (1+g) | B28: =L19*(1+B27) -> 673.17987
A29: Terminal value - Gordon | B29: =B28/(Assumptions!$B$5-B27) -> 7479.7763
A30: Terminal value - cap | B30: =Assumptions!$B$12*L19 -> 13264.628
A31: Terminal value used (lower of the two, floored at 0) | B31: =MAX(0,MIN(B29,B30)) -> 7479.7763
A32: Implied exit multiple | B32: =B31/L19 -> 11.277778
A33: PV of terminal value | B33: =B31*L20 -> 2755.9151
A34: Enterprise value | B34: =B26+B33 -> 5785.0963
A35: add: net cash | B35: =Assumptions!$B$9 -> 1600
A36: Equity value | B36: =B34+B35 -> 7385.0963
A37: Fully diluted shares (mm) | B37: =Assumptions!$B$10 -> 1030
A38: Value per share | B38: =B36/B37 -> 7.1699964
A39: Upside / (downside) vs current price | B39: =B38/Assumptions!$B$11-1 -> -0.37543586
A41: Memo: value if SBC treated as non-cash | B41: =SUMPRODUCT(-C10:L10/(1+Assumptions!$B$5)^C4:L4) -> 928.83017
A42: plus PV of terminal SBC | B42: =(-L10*(1+B27)/(Assumptions!$B$5-B27))*L20 -> 879.07977
...

Sheet DCF_Base
A1: WISE DCF - Base - they fix it, it costs something
A2: Owner-FCF basis: SBC fully expensed, interest income excluded, share count flat. Blue rows = per-year drivers (edit).
B3: 2026A | C3: 2027E | D3: 2028E | E3: 2029E | F3: 2030E | G3: 2031E | H3: 2032E | I3: 2033E | J3: 2034E | K3: 2035E | L3: 2036E
A4: Year index (for discounting) | B4: 0 | C4: 1 | D4: 2 | E4: 3 | F4: 4 | G4: 5 | H4: 6 | I4: 7 | J4: 8 | K4: 9 | L4: 10
A5: Revenue growth YoY | C5: 0.175 | D5: 0.16 | E5: 0.15 | F5: 0.14 | G5: 0.13 | H5: 0.12 | I5: 0.11 | J5: 0.1 | K5: 0.09 | L5: 0.08
A6: Revenue | B6: 2502.8 | C6: =B6*(1+C5) -> 2940.79 | D6: =C6*(1+D5) -> 3411.3164 | E6: =D6*(1+E5) -> 3923.0139 | F6: =E6*(1+F5) -> 4472.2358 | G6: =F6*(1+G5) -> 5053.6265 | H6: =G6*(1+H5) -> 5660.0616 | I6: =H6*(1+I5) -> 6282.6684 | J6: =I6*(1+J5) -> 6910.9352 | ... L6: =K6*(1+L5) -> 8135.553
A7: Adj EBITDA margin | B7: 0.318 | C7: 0.31 | D7: 0.3 | E7: 0.295 | F7: 0.29 | G7: 0.285 | H7: 0.28 | I7: 0.275 | J7: 0.27 | K7: 0.27 | L7: 0.27
A8: Adjusted EBITDA | C8: =C6*C7 -> 911.6449 | D8: =D6*D7 -> 1023.3949 | E8: =E6*E7 -> 1157.2891 | F8: =F6*F7 -> 1296.9484 | G8: =G6*G7 -> 1440.2835 | H8: =H6*H7 -> 1584.8173 | I8: =I6*I7 -> 1727.7338 | J8: =J6*J7 -> 1865.9525 | ... L8: =L6*L7 -> 2196.5993
A9: SBC (% of revenue) | B9: 0.038 | C9: 0.038 | D9: 0.037 | E9: 0.036 | F9: 0.035 | G9: 0.034 | H9: 0.033 | I9: 0.032 | J9: 0.031 | K9: 0.03 | L9: 0.03
A10: SBC (incl. equity-award taxes) | C10: =-C6*C9 -> -111.75002 | D10: =-D6*D9 -> -126.21871 | E10: =-E6*E9 -> -141.2285 | F10: =-F6*F9 -> -156.52825 | G10: =-G6*G9 -> -171.8233 | H10: =-H6*H9 -> -186.78203 | I10: =-I6*I9 -> -201.04539 | J10: =-J6*J9 -> -214.23899 | ... L10: =-L6*L9 -> -244.06659
A11: EBITDA less SBC ('owner EBITDA') | C11: =C8+C10 -> 799.89488 | D11: =D8+D10 -> 897.17621 | E11: =E8+E10 -> 1016.0606 | F11: =F8+F10 -> 1140.4201 | G11: =G8+G10 -> 1268.4602 | H11: =H8+H10 -> 1398.0352 | I11: =I8+I10 -> 1526.6884 | J11: =J8+J10 -> 1651.7135 | ... L11: =L8+L10 -> 1952.5327
A12: D&A | C12: =-C6*Assumptions!$B$6 -> -73.51975 | D12: =-D6*Assumptions!$B$6 -> -85.28291 | E12: =-E6*Assumptions!$B$6 -> -98.075346 | F12: =-F6*Assumptions!$B$6 -> -111.8059 | G12: =-G6*Assumptions!$B$6 -> -126.34066 | H12: =-H6*Assumptions!$B$6 -> -141.50154 | I12: =-I6*Assumptions!$B$6 -> -157.06671 | J12: =-J6*Assumptions!$B$6 -> -172.77338 | ... L12: =-L6*Assumptions!$B$6 -> -203.38882
A13: EBIT (SBC expensed) | C13: =C11+C12 -> 726.37513 | D13: =D11+D12 -> 811.8933 | E13: =E11+E12 -> 917.98524 | F13: =F11+F12 -> 1028.6142 | G13: =G11+G12 -> 1142.1196 | H13: =H11+H12 -> 1256.5337 | I13: =I11+I12 -> 1369.6217 | J13: =J11+J12 -> 1478.9401 | ... L13: =L11+L12 -> 1749.1439
A14: Cash tax rate (neg = benefit) | C14: 0.24 | D14: 0.24 | E14: 0.24 | F14: 0.24 | G14: 0.24 | H14: 0.24 | I14: 0.24 | J14: 0.24 | K14: 0.24 | L14: 0.24
A15: NOPAT | C15: =C13*(1-C14) -> 552.0451 | D15: =D13*(1-D14) -> 617.03891 | E15: =E13*(1-E14) -> 697.66878 | F15: =F13*(1-F14) -> 781.74682 | G15: =G13*(1-G14) -> 868.01088 | H15: =H13*(1-H14) -> 954.9656 | I15: =I13*(1-I14) -> 1040.9125 | J15: =J13*(1-J14) -> 1123.9945 | ... L15: =L13*(1-L14) -> 1329.3494
A16: add: D&A | C16: =-C12 -> 73.51975 | D16: =-D12 -> 85.28291 | E16: =-E12 -> 98.075346 | F16: =-F12 -> 111.8059 | G16: =-G12 -> 126.34066 | H16: =-H12 -> 141.50154 | I16: =-I12 -> 157.06671 | J16: =-J12 -> 172.77338 | ... L16: =-L12 -> 203.38882
A17: less: capex + capitalized software | C17: =-C6*Assumptions!$B$7 -> -73.51975 | D17: =-D6*Assumptions!$B$7 -> -85.28291 | E17: =-E6*Assumptions!$B$7 -> -98.075346 | F17: =-F6*Assumptions!$B$7 -> -111.8059 | G17: =-G6*Assumptions!$B$7 -> -126.34066 | H17: =-H6*Assumptions!$B$7 -> -141.50154 | I17: =-I6*Assumptions!$B$7 -> -157.06671 | J17: =-J6*Assumptions!$B$7 -> -172.77338 | ... L17: =-L6*Assumptions!$B$7 -> -203.38882
A18: add: working capital | C18: =Assumptions!$B$8*(C6-B6) -> 0 | D18: =Assumptions!$B$8*(D6-C6) -> 0 | E18: =Assumptions!$B$8*(E6-D6) -> 0 | F18: =Assumptions!$B$8*(F6-E6) -> 0 | G18: =Assumptions!$B$8*(G6-F6) -> 0 | H18: =Assumptions!$B$8*(H6-G6) -> 0 | I18: =Assumptions!$B$8*(I6-H6) -> 0 | J18: =Assumptions!$B$8*(J6-I6) -> 0 | ... L18: =Assumptions!$B$8*(L6-K6) -> 0
A19: Unlevered owner FCF | C19: =C15+C16+C17+C18 -> 552.0451 | D19: =D15+D16+D17+D18 -> 617.03891 | E19: =E15+E16+E17+E18 -> 697.66878 | F19: =F15+F16+F17+F18 -> 781.74682 | G19: =G15+G16+G17+G18 -> 868.01088 | H19: =H15+H16+H17+H18 -> 954.9656 | I19: =I15+I16+I17+I18 -> 1040.9125 | J19: =J15+J16+J17+J18 -> 1123.9945 | ... L19: =L15+L16+L17+L18 -> 1329.3494
A20: Discount factor | C20: =1/(1+Assumptions!$B$5)^C4 -> 0.90497738 | D20: =1/(1+Assumptions!$B$5)^D4 -> 0.81898405 | E20: =1/(1+Assumptions!$B$5)^E4 -> 0.74116204 | F20: =1/(1+Assumptions!$B$5)^F4 -> 0.67073487 | G20: =1/(1+Assumptions!$B$5)^G4 -> 0.60699989 | H20: =1/(1+Assumptions!$B$5)^H4 -> 0.54932116 | I20: =1/(1+Assumptions!$B$5)^I4 -> 0.49712323 | J20: =1/(1+Assumptions!$B$5)^J4 -> 0.44988527 | ... L20: =1/(1+Assumptions!$B$5)^L4 -> 0.36844886
A21: PV of FCF | C21: =C19*C20 -> 499.58832 | D21: =D19*D20 -> 505.34503 | E21: =E19*E20 -> 517.08562 | F21: =F19*F20 -> 524.34485 | G21: =G19*G20 -> 526.88251 | H21: =H19*H20 -> 524.58281 | I21: =I19*I20 -> 517.46178 | J21: =J19*J20 -> 505.66858 | ... L21: =L19*L20 -> 489.79726
A23: Memo: FCF before SBC (company-style) | C23: =C19-C10 -> 663.79512 | D23: =D19-D10 -> 743.25762 | E23: =E19-E10 -> 838.89728 | F23: =F19-F10 -> 938.27507 | G23: =G19-G10 -> 1039.8342 | H23: =H19-H10 -> 1141.7476 | I23: =I19-I10 -> 1241.9579 | J23: =J19-J10 -> 1338.2335 | ... L23: =L19-L10 -> 1573.4159
A24: Memo: implied owner FCF margin | C24: =C19/C6 -> 0.18772 | D24: =D19/D6 -> 0.18088 | E24: =E19/E6 -> 0.17784 | F24: =F19/F6 -> 0.1748 | G24: =G19/G6 -> 0.17176 | H24: =H19/H6 -> 0.16872 | I24: =I19/I6 -> 0.16568 | J24: =J19/J6 -> 0.16264 | ... L24: =L19/L6 -> 0.1634
A25: Valuation
A26: PV of FCF, explicit years | B26: =SUM(C21:L21) -> 5111.8919
A27: Terminal growth rate | B27: =Assumptions!$D$16 -> 0.03
A28: Terminal-year owner FCF x (1+g) | B28: =L19*(1+B27) -> 1369.2298
A29: Terminal value - Gordon | B29: =B28/(Assumptions!$B$5-B27) -> 18256.398
A30: Terminal value - cap | B30: =Assumptions!$B$12*L19 -> 26586.987
A31: Terminal value used (lower of the two, floored at 0) | B31: =MAX(0,MIN(B29,B30)) -> 18256.398
A32: Implied exit multiple | B32: =B31/L19 -> 13.733333
A33: PV of terminal value | B33: =B31*L20 -> 6726.549
A34: Enterprise value | B34: =B26+B33 -> 11838.441
A35: add: net cash | B35: =Assumptions!$B$9 -> 1600
A36: Equity value | B36: =B34+B35 -> 13438.441
A37: Fully diluted shares (mm) | B37: =Assumptions!$B$10 -> 1030
A38: Value per share | B38: =B36/B37 -> 13.04703
A39: Upside / (downside) vs current price | B39: =B38/Assumptions!$B$11-1 -> 0.13650087
A41: Memo: value if SBC treated as non-cash | B41: =SUMPRODUCT(-C10:L10/(1+Assumptions!$B$5)^C4:L4) -> 999.32559
A42: plus PV of terminal SBC | B42: =(-L10*(1+B27)/(Assumptions!$B$5-B27))*L20 -> 1234.9845
...

Sheet DCF_Bull
A1: WISE DCF - Bull - regulatory noise, flywheel intact
A2: Owner-FCF basis: SBC fully expensed, interest income excluded, share count flat. Blue rows = per-year drivers (edit).
B3: 2026A | C3: 2027E | D3: 2028E | E3: 2029E | F3: 2030E | G3: 2031E | H3: 2032E | I3: 2033E | J3: 2034E | K3: 2035E | L3: 2036E
A4: Year index (for discounting) | B4: 0 | C4: 1 | D4: 2 | E4: 3 | F4: 4 | G4: 5 | H4: 6 | I4: 7 | J4: 8 | K4: 9 | L4: 10
A5: Revenue growth YoY | C5: 0.19 | D5: 0.19 | E5: 0.18 | F5: 0.17 | G5: 0.16 | H5: 0.15 | I5: 0.14 | J5: 0.13 | K5: 0.12 | L5: 0.1
A6: Revenue | B6: 2502.8 | C6: =B6*(1+C5) -> 2978.332 | D6: =C6*(1+D5) -> 3544.2151 | E6: =D6*(1+E5) -> 4182.1738 | F6: =E6*(1+F5) -> 4893.1433 | G6: =F6*(1+G5) -> 5676.0463 | H6: =G6*(1+H5) -> 6527.4532 | I6: =H6*(1+I5) -> 7441.2967 | J6: =I6*(1+J5) -> 8408.6652 | ... L6: =K6*(1+L5) -> 10359.476
A7: Adj EBITDA margin | B7: 0.318 | C7: 0.32 | D7: 0.32 | E7: 0.32 | F7: 0.315 | G7: 0.31 | H7: 0.31 | I7: 0.31 | J7: 0.31 | K7: 0.31 | L7: 0.31
A8: Adjusted EBITDA | C8: =C6*C7 -> 953.06624 | D8: =D6*D7 -> 1134.1488 | E8: =E6*E7 -> 1338.2956 | F8: =F6*F7 -> 1541.3402 | G8: =G6*G7 -> 1759.5743 | H8: =H6*H7 -> 2023.5105 | I8: =I6*I7 -> 2306.802 | J8: =J6*J7 -> 2606.6862 | ... L8: =L6*L7 -> 3211.4374
A9: SBC (% of revenue) | B9: 0.038 | C9: 0.038 | D9: 0.036 | E9: 0.034 | F9: 0.032 | G9: 0.03 | H9: 0.03 | I9: 0.03 | J9: 0.03 | K9: 0.03 | L9: 0.03
A10: SBC (incl. equity-award taxes) | C10: =-C6*C9 -> -113.17662 | D10: =-D6*D9 -> -127.59174 | E10: =-E6*E9 -> -142.19391 | F10: =-F6*F9 -> -156.58059 | G10: =-G6*G9 -> -170.28139 | H10: =-H6*H9 -> -195.8236 | I10: =-I6*I9 -> -223.2389 | J10: =-J6*J9 -> -252.25996 | ... L10: =-L6*L9 -> -310.78427
A11: EBITDA less SBC ('owner EBITDA') | C11: =C8+C10 -> 839.88962 | D11: =D8+D10 -> 1006.5571 | E11: =E8+E10 -> 1196.1017 | F11: =F8+F10 -> 1384.7596 | G11: =G8+G10 -> 1589.293 | H11: =H8+H10 -> 1827.6869 | I11: =I8+I10 -> 2083.5631 | J11: =J8+J10 -> 2354.4263 | ... L11: =L8+L10 -> 2900.6532
A12: D&A | C12: =-C6*Assumptions!$B$6 -> -74.4583 | D12: =-D6*Assumptions!$B$6 -> -88.605377 | E12: =-E6*Assumptions!$B$6 -> -104.55434 | F12: =-F6*Assumptions!$B$6 -> -122.32858 | G12: =-G6*Assumptions!$B$6 -> -141.90116 | H12: =-H6*Assumptions!$B$6 -> -163.18633 | I12: =-I6*Assumptions!$B$6 -> -186.03242 | J12: =-J6*Assumptions!$B$6 -> -210.21663 | ... L12: =-L6*Assumptions!$B$6 -> -258.98689
A13: EBIT (SBC expensed) | C13: =C11+C12 -> 765.43132 | D13: =D11+D12 -> 917.95171 | E13: =E11+E12 -> 1091.5474 | F13: =F11+F12 -> 1262.431 | G13: =G11+G12 -> 1447.3918 | H13: =H11+H12 -> 1664.5006 | I13: =I11+I12 -> 1897.5306 | J13: =J11+J12 -> 2144.2096 | ... L13: =L11+L12 -> 2641.6663
A14: Cash tax rate (neg = benefit) | C14: 0.24 | D14: 0.24 | E14: 0.24 | F14: 0.24 | G14: 0.24 | H14: 0.24 | I14: 0.24 | J14: 0.24 | K14: 0.24 | L14: 0.24
A15: NOPAT | C15: =C13*(1-C14) -> 581.72781 | D15: =D13*(1-D14) -> 697.6433 | E15: =E13*(1-E14) -> 829.57599 | F15: =F13*(1-F14) -> 959.44755 | G15: =G13*(1-G14) -> 1100.0178 | H15: =H13*(1-H14) -> 1265.0204 | I15: =I13*(1-I14) -> 1442.1233 | J15: =J13*(1-J14) -> 1629.5993 | ... L15: =L13*(1-L14) -> 2007.6664
A16: add: D&A | C16: =-C12 -> 74.4583 | D16: =-D12 -> 88.605377 | E16: =-E12 -> 104.55434 | F16: =-F12 -> 122.32858 | G16: =-G12 -> 141.90116 | H16: =-H12 -> 163.18633 | I16: =-I12 -> 186.03242 | J16: =-J12 -> 210.21663 | ... L16: =-L12 -> 258.98689
A17: less: capex + capitalized software | C17: =-C6*Assumptions!$B$7 -> -74.4583 | D17: =-D6*Assumptions!$B$7 -> -88.605377 | E17: =-E6*Assumptions!$B$7 -> -104.55434 | F17: =-F6*Assumptions!$B$7 -> -122.32858 | G17: =-G6*Assumptions!$B$7 -> -141.90116 | H17: =-H6*Assumptions!$B$7 -> -163.18633 | I17: =-I6*Assumptions!$B$7 -> -186.03242 | J17: =-J6*Assumptions!$B$7 -> -210.21663 | ... L17: =-L6*Assumptions!$B$7 -> -258.98689
A18: add: working capital | C18: =Assumptions!$B$8*(C6-B6) -> 0 | D18: =Assumptions!$B$8*(D6-C6) -> 0 | E18: =Assumptions!$B$8*(E6-D6) -> 0 | F18: =Assumptions!$B$8*(F6-E6) -> 0 | G18: =Assumptions!$B$8*(G6-F6) -> 0 | H18: =Assumptions!$B$8*(H6-G6) -> 0 | I18: =Assumptions!$B$8*(I6-H6) -> 0 | J18: =Assumptions!$B$8*(J6-I6) -> 0 | ... L18: =Assumptions!$B$8*(L6-K6) -> 0
A19: Unlevered owner FCF | C19: =C15+C16+C17+C18 -> 581.72781 | D19: =D15+D16+D17+D18 -> 697.6433 | E19: =E15+E16+E17+E18 -> 829.57599 | F19: =F15+F16+F17+F18 -> 959.44755 | G19: =G15+G16+G17+G18 -> 1100.0178 | H19: =H15+H16+H17+H18 -> 1265.0204 | I19: =I15+I16+I17+I18 -> 1442.1233 | J19: =J15+J16+J17+J18 -> 1629.5993 | ... L19: =L15+L16+L17+L18 -> 2007.6664
A20: Discount factor | C20: =1/(1+Assumptions!$B$5)^C4 -> 0.90497738 | D20: =1/(1+Assumptions!$B$5)^D4 -> 0.81898405 | E20: =1/(1+Assumptions!$B$5)^E4 -> 0.74116204 | F20: =1/(1+Assumptions!$B$5)^F4 -> 0.67073487 | G20: =1/(1+Assumptions!$B$5)^G4 -> 0.60699989 | H20: =1/(1+Assumptions!$B$5)^H4 -> 0.54932116 | I20: =1/(1+Assumptions!$B$5)^I4 -> 0.49712323 | J20: =1/(1+Assumptions!$B$5)^J4 -> 0.44988527 | ... L20: =1/(1+Assumptions!$B$5)^L4 -> 0.36844886
A21: PV of FCF | C21: =C19*C20 -> 526.4505 | D21: =D19*D20 -> 571.35873 | E21: =E19*E20 -> 614.85023 | F21: =F19*F20 -> 643.53493 | G21: =G19*G20 -> 667.71066 | H21: =H19*H20 -> 694.9025 | I21: =I19*I20 -> 716.91298 | J21: =J19*J20 -> 733.13273 | ... L21: =L19*L20 -> 739.72239
A23: Memo: FCF before SBC (company-style) | C23: =C19-C10 -> 694.90442 | D23: =D19-D10 -> 825.23504 | E23: =E19-E10 -> 971.7699 | F23: =F19-F10 -> 1116.0281 | G23: =G19-G10 -> 1270.2992 | H23: =H19-H10 -> 1460.844 | I23: =I19-I10 -> 1665.3622 | J23: =J19-J10 -> 1881.8593 | ... L23: =L19-L10 -> 2318.4506
A24: Memo: implied owner FCF margin | C24: =C19/C6 -> 0.19532 | D24: =D19/D6 -> 0.19684 | E24: =E19/E6 -> 0.19836 | F24: =F19/F6 -> 0.19608 | G24: =G19/G6 -> 0.1938 | H24: =H19/H6 -> 0.1938 | I24: =I19/I6 -> 0.1938 | J24: =J19/J6 -> 0.1938 | ... L24: =L19/L6 -> 0.1938
A25: Valuation
A26: PV of FCF, explicit years | B26: =SUM(C21:L21) -> 6651.6604
A27: Terminal growth rate | B27: =Assumptions!$E$16 -> 0.035
A28: Terminal-year owner FCF x (1+g) | B28: =L19*(1+B27) -> 2077.9347
A29: Terminal value - Gordon | B29: =B28/(Assumptions!$B$5-B27) -> 29684.781
A30: Terminal value - cap | B30: =Assumptions!$B$12*L19 -> 40153.327
A31: Terminal value used (lower of the two, floored at 0) | B31: =MAX(0,MIN(B29,B30)) -> 29684.781
A32: Implied exit multiple | B32: =B31/L19 -> 14.785714
A33: PV of terminal value | B33: =B31*L20 -> 10937.324
A34: Enterprise value | B34: =B26+B33 -> 17588.984
A35: add: net cash | B35: =Assumptions!$B$9 -> 1600
A36: Equity value | B36: =B34+B35 -> 19188.984
A37: Fully diluted shares (mm) | B37: =Assumptions!$B$10 -> 1030
A38: Value per share | B38: =B36/B37 -> 18.630082
A39: Upside / (downside) vs current price | B39: =B38/Assumptions!$B$11-1 -> 0.62282943
A41: Memo: value if SBC treated as non-cash | B41: =SUMPRODUCT(-C10:L10/(1+Assumptions!$B$5)^C4:L4) -> 1082.2635
A42: plus PV of terminal SBC | B42: =(-L10*(1+B27)/(Assumptions!$B$5-B27))*L20 -> 1693.0842
...

Sheet Valuation
A1: WISE - Valuation Summary & Sensitivity
A2: Owner-FCF basis (SBC expensed) unless marked street. Green = links.
B4: Bear | C4: Base | D4: Bull
A5: Value per share | B5: =DCF_Bear!$B$38 -> 7.1699964 | C5: =DCF_Base!$B$38 -> 13.04703 | D5: =DCF_Bull!$B$38 -> 18.630082
A6: Upside / (downside) vs price | B6: =B5/Assumptions!$B$11-1 -> -0.37543586 | C6: =C5/Assumptions!$B$11-1 -> 0.13650087 | D6: =D5/Assumptions!$B$11-1 -> 0.62282943
A7: Probability | B7: =Assumptions!$C$17 -> 0.15 | C7: =Assumptions!$D$17 -> 0.5 | D7: =Assumptions!$E$17 -> 0.35
A8: Value per share, SBC as non-cash (street) | B8: =DCF_Bear!$B$43 -> 8.9252487 | C8: =DCF_Base!$B$43 -> 15.216263 | D8: =DCF_Bull!$B$43 -> 21.324594
A10: Probability-weighted value per share | B10: =SUMPRODUCT(B5:D5,B7:D7) -> 14.119543
A11: Current price | B11: =Assumptions!$B$11 -> 11.48
A12: Margin of safety vs weighted value | B12: =1-B11/B10 -> 0.18694253
A13: Weighted value, SBC as non-cash (street) | B13: =SUMPRODUCT(B8:D8,B7:D7) -> 16.410527
A14: Band position (0%=house, 100%=street) | B14: =IF(ABS(B13-B10)<0.005,"n/a - SBC=0 so house=street",(Assumptions!$B$11-B10)/(B13-B10)) -> -1.152144
A15: Value per share in pence (house) - Bear / Base / Bull | B15: =B5/Assumptions!$B$13*100 -> 535.07436 | C15: =C5/Assumptions!$B$13*100 -> 973.65896 | D15: =D5/Assumptions!$B$13*100 -> 1390.3046
A16: Weighted value in pence: house | street | current price | B16: =B10/Assumptions!$B$13*100 -> 1053.6972 | C16: =B13/Assumptions!$B$13*100 -> 1224.6662 | D16: =B11/Assumptions!$B$13*100 -> 856.71642 | G16: pence = USD value / GBPUSD spot (Assumptions B13)
A17: Base case - value per share at different required returns
A18: Required return | B18: Value / share
A19: 0.09 | B19: =(SUMPRODUCT(DCF_Base!$C$19:$L$19/(1+$A19)^DCF_Base!$C$4:$L$4)+MAX(0,MIN(DCF_Base!$L$19*(1+Assumptions!$D$16)/($A19-Assumptions!$D$16),Assumptions!$B$12*DCF_Base!$L$19))/(1+$A19)^10+Assumptions!$B$9)/Assumptions!$B$10 -> 16.265349
A20: 0.1 | B20: =(SUMPRODUCT(DCF_Base!$C$19:$L$19/(1+$A20)^DCF_Base!$C$4:$L$4)+MAX(0,MIN(DCF_Base!$L$19*(1+Assumptions!$D$16)/($A20-Assumptions!$D$16),Assumptions!$B$12*DCF_Base!$L$19))/(1+$A20)^10+Assumptions!$B$9)/Assumptions!$B$10 -> 13.963467
A21: 0.105 | B21: =(SUMPRODUCT(DCF_Base!$C$19:$L$19/(1+$A21)^DCF_Base!$C$4:$L$4)+MAX(0,MIN(DCF_Base!$L$19*(1+Assumptions!$D$16)/($A21-Assumptions!$D$16),Assumptions!$B$12*DCF_Base!$L$19))/(1+$A21)^10+Assumptions!$B$9)/Assumptions!$B$10 -> 13.04703
A22: 0.11 | B22: =(SUMPRODUCT(DCF_Base!$C$19:$L$19/(1+$A22)^DCF_Base!$C$4:$L$4)+MAX(0,MIN(DCF_Base!$L$19*(1+Assumptions!$D$16)/($A22-Assumptions!$D$16),Assumptions!$B$12*DCF_Base!$L$19))/(1+$A22)^10+Assumptions!$B$9)/Assumptions!$B$10 -> 12.247707
A23: 0.12 | B23: =(SUMPRODUCT(DCF_Base!$C$19:$L$19/(1+$A23)^DCF_Base!$C$4:$L$4)+MAX(0,MIN(DCF_Base!$L$19*(1+Assumptions!$D$16)/($A23-Assumptions!$D$16),Assumptions!$B$12*DCF_Base!$L$19))/(1+$A23)^10+Assumptions!$B$9)/Assumptions!$B$10 -> 10.92198
A24: 0.15 | B24: =(SUMPRODUCT(DCF_Base!$C$19:$L$19/(1+$A24)^DCF_Base!$C$4:$L$4)+MAX(0,MIN(DCF_Base!$L$19*(1+Assumptions!$D$16)/($A24-Assumptions!$D$16),Assumptions!$B$12*DCF_Base!$L$19))/(1+$A24)^10+Assumptions!$B$9)/Assumptions!$B$10 -> 8.3052395
A25: 15%-hurdle entry per scenario + weighted | B25: =(SUMPRODUCT(DCF_Bear!$C$19:$L$19/(1+0.15)^DCF_Bear!$C$4:$L$4)+MAX(0,MIN(DCF_Bear!$L$19*(1+Assumptions!$C$16)/(0.15-Assumptions!$C$16),Assumptions!$B$12*DCF_Bear!$L$19))/(1+0.15)^10+Assumptions!$B$9)/Assumptions!$B$10 -> 5.1646179 | C25: =(SUMPRODUCT(DCF_Base!$C$19:$L$19/(1+0.15)^DCF_Base!$C$4:$L$4)+MAX(0,MIN(DCF_Base!$L$19*(1+Assumptions!$D$16)/(0.15-Assumptions!$D$16),Assumptions!$B$12*DCF_Base!$L$19))/(1+0.15)^10+Assumptions!$B$9)/Assumptions!$B$10 -> 8.3052395 | D25: =(SUMPRODUCT(DCF_Bull!$C$19:$L$19/(1+0.15)^DCF_Bull!$C$4:$L$4)+MAX(0,MIN(DCF_Bull!$L$19*(1+Assumptions!$E$16)/(0.15-Assumptions!$E$16),Assumptions!$B$12*DCF_Bull!$L$19))/(1+0.15)^10+Assumptions!$B$9)/Assumptions!$B$10 -> 11.04615 | E25: =SUMPRODUCT(B25:D25,$B$7:$D$7) -> 8.793465 | F25: =E25/Assumptions!$B$13*100 -> 656.22873 | G25: model buy-below price at a 15% hurdle (E = USD, F = pence)
A26: same, street basis | B26: =B25+(SUMPRODUCT(-DCF_Bear!$C$10:$L$10/(1+0.15)^DCF_Bear!$C$4:$L$4)+(-DCF_Bear!$L$10*(1+Assumptions!$C$16)/(0.15-Assumptions!$C$16))/(1+0.15)^10)/Assumptions!$B$10 -> 6.2818409 | C26: =C25+(SUMPRODUCT(-DCF_Base!$C$10:$L$10/(1+0.15)^DCF_Base!$C$4:$L$4)+(-DCF_Base!$L$10*(1+Assumptions!$D$16)/(0.15-Assumptions!$D$16))/(1+0.15)^10)/Assumptions!$B$10 -> 9.5956859 | D26: =D25+(SUMPRODUCT(-DCF_Bull!$C$10:$L$10/(1+0.15)^DCF_Bull!$C$4:$L$4)+(-DCF_Bull!$L$10*(1+Assumptions!$E$16)/(0.15-Assumptions!$E$16))/(1+0.15)^10)/Assumptions!$B$10 -> 12.562795 | E26: =SUMPRODUCT(B26:D26,$B$7:$D$7) -> 10.137097
A28: Base case - value per share: WACC x terminal growth
A29: WACC \ g | B29: 0.02 | C29: 0.025 | D29: 0.03 | E29: 0.035 | F29: 0.04
A30: 0.095 | B30: =IF($A30>B$29,(SUMPRODUCT(DCF_Base!$C$19:$L$19/(1+$A30)^DCF_Base!$C$4:$L$4)+MAX(0,MIN(DCF_Base!$L$19*(1+B$29)/($A30-B$29),Assumptions!$B$12*DCF_Base!$L$19))/(1+$A30)^10+Assumptions!$B$9)/Assumptions!$B$10,"n/a") -> 13.854401 | C30: =IF($A30>C$29,(SUMPRODUCT(DCF_Base!$C$19:$L$19/(1+$A30)^DCF_Base!$C$4:$L$4)+MAX(0,MIN(DCF_Base!$L$19*(1+C$29)/($A30-C$29),Assumptions!$B$12*DCF_Base!$L$19))/(1+$A30)^10+Assumptions!$B$9)/Assumptions!$B$10,"n/a") -> 14.397508 | D30: =IF($A30>D$29,(SUMPRODUCT(DCF_Base!$C$19:$L$19/(1+$A30)^DCF_Base!$C$4:$L$4)+MAX(0,MIN(DCF_Base!$L$19*(1+D$29)/($A30-D$29),Assumptions!$B$12*DCF_Base!$L$19))/(1+$A30)^10+Assumptions!$B$9)/Assumptions!$B$10,"n/a") -> 15.02417 | E30: =IF($A30>E$29,(SUMPRODUCT(DCF_Base!$C$19:$L$19/(1+$A30)^DCF_Base!$C$4:$L$4)+MAX(0,MIN(DCF_Base!$L$19*(1+E$29)/($A30-E$29),Assumptions!$B$12*DCF_Base!$L$19))/(1+$A30)^10+Assumptions!$B$9)/Assumptions!$B$10,"n/a") -> 15.755276 | F30: =IF($A30>F$29,(SUMPRODUCT(DCF_Base!$C$19:$L$19/(1+$A30)^DCF_Base!$C$4:$L$4)+MAX(0,MIN(DCF_Base!$L$19*(1+F$29)/($A30-F$29),Assumptions!$B$12*DCF_Base!$L$19))/(1+$A30)^10+Assumptions!$B$9)/Assumptions!$B$10,"n/a") -> 16.61931
A31: 0.1 | B31: =IF($A31>B$29,(SUMPRODUCT(DCF_Base!$C$19:$L$19/(1+$A31)^DCF_Base!$C$4:$L$4)+MAX(0,MIN(DCF_Base!$L$19*(1+B$29)/($A31-B$29),Assumptions!$B$12*DCF_Base!$L$19))/(1+$A31)^10+Assumptions!$B$9)/Assumptions!$B$10,"n/a") -> 12.98605 | C31: =IF($A31>C$29,(SUMPRODUCT(DCF_Base!$C$19:$L$19/(1+$A31)^DCF_Base!$C$4:$L$4)+MAX(0,MIN(DCF_Base!$L$19*(1+C$29)/($A31-C$29),Assumptions!$B$12*DCF_Base!$L$19))/(1+$A31)^10+Assumptions!$B$9)/Assumptions!$B$10,"n/a") -> 13.442178 | D31: =IF($A31>D$29,(SUMPRODUCT(DCF_Base!$C$19:$L$19/(1+$A31)^DCF_Base!$C$4:$L$4)+MAX(0,MIN(DCF_Base!$L$19*(1+D$29)/($A31-D$29),Assumptions!$B$12*DCF_Base!$L$19))/(1+$A31)^10+Assumptions!$B$9)/Assumptions!$B$10,"n/a") -> 13.963467 | E31: =IF($A31>E$29,(SUMPRODUCT(DCF_Base!$C$19:$L$19/(1+$A31)^DCF_Base!$C$4:$L$4)+MAX(0,MIN(DCF_Base!$L$19*(1+E$29)/($A31-E$29),Assumptions!$B$12*DCF_Base!$L$19))/(1+$A31)^10+Assumptions!$B$9)/Assumptions!$B$10,"n/a") -> 14.564954 | F31: =IF($A31>F$29,(SUMPRODUCT(DCF_Base!$C$19:$L$19/(1+$A31)^DCF_Base!$C$4:$L$4)+MAX(0,MIN(DCF_Base!$L$19*(1+F$29)/($A31-F$29),Assumptions!$B$12*DCF_Base!$L$19))/(1+$A31)^10+Assumptions!$B$9)/Assumptions!$B$10,"n/a") -> 15.266689
A32: 0.105 | B32: =IF($A32>B$29,(SUMPRODUCT(DCF_Base!$C$19:$L$19/(1+$A32)^DCF_Base!$C$4:$L$4)+MAX(0,MIN(DCF_Base!$L$19*(1+B$29)/($A32-B$29),Assumptions!$B$12*DCF_Base!$L$19))/(1+$A32)^10+Assumptions!$B$9)/Assumptions!$B$10,"n/a") -> 12.222776 | C32: =IF($A32>C$29,(SUMPRODUCT(DCF_Base!$C$19:$L$19/(1+$A32)^DCF_Base!$C$4:$L$4)+MAX(0,MIN(DCF_Base!$L$19*(1+C$29)/($A32-C$29),Assumptions!$B$12*DCF_Base!$L$19))/(1+$A32)^10+Assumptions!$B$9)/Assumptions!$B$10,"n/a") -> 12.609145 | D32: =IF($A32>D$29,(SUMPRODUCT(DCF_Base!$C$19:$L$19/(1+$A32)^DCF_Base!$C$4:$L$4)+MAX(0,MIN(DCF_Base!$L$19*(1+D$29)/($A32-D$29),Assumptions!$B$12*DCF_Base!$L$19))/(1+$A32)^10+Assumptions!$B$9)/Assumptions!$B$10,"n/a") -> 13.04703 | E32: =IF($A32>E$29,(SUMPRODUCT(DCF_Base!$C$19:$L$19/(1+$A32)^DCF_Base!$C$4:$L$4)+MAX(0,MIN(DCF_Base!$L$19*(1+E$29)/($A32-E$29),Assumptions!$B$12*DCF_Base!$L$19))/(1+$A32)^10+Assumptions!$B$9)/Assumptions!$B$10,"n/a") -> 13.54747 | F32: =IF($A32>F$29,(SUMPRODUCT(DCF_Base!$C$19:$L$19/(1+$A32)^DCF_Base!$C$4:$L$4)+MAX(0,MIN(DCF_Base!$L$19*(1+F$29)/($A32-F$29),Assumptions!$B$12*DCF_Base!$L$19))/(1+$A32)^10+Assumptions!$B$9)/Assumptions!$B$10,"n/a") -> 14.124901
A33: 0.11 | B33: =IF($A33>B$29,(SUMPRODUCT(DCF_Base!$C$19:$L$19/(1+$A33)^DCF_Base!$C$4:$L$4)+MAX(0,MIN(DCF_Base!$L$19*(1+B$29)/($A33-B$29),Assumptions!$B$12*DCF_Base!$L$19))/(1+$A33)^10+Assumptions!$B$9)/Assumptions!$B$10,"n/a") -> 11.546958 | C33: =IF($A33>C$29,(SUMPRODUCT(DCF_Base!$C$19:$L$19/(1+$A33)^DCF_Base!$C$4:$L$4)+MAX(0,MIN(DCF_Base!$L$19*(1+C$29)/($A33-C$29),Assumptions!$B$12*DCF_Base!$L$19))/(1+$A33)^10+Assumptions!$B$9)/Assumptions!$B$10,"n/a") -> 11.876722 | D33: =IF($A33>D$29,(SUMPRODUCT(DCF_Base!$C$19:$L$19/(1+$A33)^DCF_Base!$C$4:$L$4)+MAX(0,MIN(DCF_Base!$L$19*(1+D$29)/($A33-D$29),Assumptions!$B$12*DCF_Base!$L$19))/(1+$A33)^10+Assumptions!$B$9)/Assumptions!$B$10,"n/a") -> 12.247707 | E33: =IF($A33>E$29,(SUMPRODUCT(DCF_Base!$C$19:$L$19/(1+$A33)^DCF_Base!$C$4:$L$4)+MAX(0,MIN(DCF_Base!$L$19*(1+E$29)/($A33-E$29),Assumptions!$B$12*DCF_Base!$L$19))/(1+$A33)^10+Assumptions!$B$9)/Assumptions!$B$10,"n/a") -> 12.668156 | F33: =IF($A33>F$29,(SUMPRODUCT(DCF_Base!$C$19:$L$19/(1+$A33)^DCF_Base!$C$4:$L$4)+MAX(0,MIN(DCF_Base!$L$19*(1+F$29)/($A33-F$29),Assumptions!$B$12*DCF_Base!$L$19))/(1+$A33)^10+Assumptions!$B$9)/Assumptions!$B$10,"n/a") -> 13.14867
A34: 0.115 | B34: =IF($A34>B$29,(SUMPRODUCT(DCF_Base!$C$19:$L$19/(1+$A34)^DCF_Base!$C$4:$L$4)+MAX(0,MIN(DCF_Base!$L$19*(1+B$29)/($A34-B$29),Assumptions!$B$12*DCF_Base!$L$19))/(1+$A34)^10+Assumptions!$B$9)/Assumptions!$B$10,"n/a") -> 10.94469 | C34: =IF($A34>C$29,(SUMPRODUCT(DCF_Base!$C$19:$L$19/(1+$A34)^DCF_Base!$C$4:$L$4)+MAX(0,MIN(DCF_Base!$L$19*(1+C$29)/($A34-C$29),Assumptions!$B$12*DCF_Base!$L$19))/(1+$A34)^10+Assumptions!$B$9)/Assumptions!$B$10,"n/a") -> 11.228046 | D34: =IF($A34>D$29,(SUMPRODUCT(DCF_Base!$C$19:$L$19/(1+$A34)^DCF_Base!$C$4:$L$4)+MAX(0,MIN(DCF_Base!$L$19*(1+D$29)/($A34-D$29),Assumptions!$B$12*DCF_Base!$L$19))/(1+$A34)^10+Assumptions!$B$9)/Assumptions!$B$10,"n/a") -> 11.544738 | E34: =IF($A34>E$29,(SUMPRODUCT(DCF_Base!$C$19:$L$19/(1+$A34)^DCF_Base!$C$4:$L$4)+MAX(0,MIN(DCF_Base!$L$19*(1+E$29)/($A34-E$29),Assumptions!$B$12*DCF_Base!$L$19))/(1+$A34)^10+Assumptions!$B$9)/Assumptions!$B$10,"n/a") -> 11.901016 | F34: =IF($A34>F$29,(SUMPRODUCT(DCF_Base!$C$19:$L$19/(1+$A34)^DCF_Base!$C$4:$L$4)+MAX(0,MIN(DCF_Base!$L$19*(1+F$29)/($A34-F$29),Assumptions!$B$12*DCF_Base!$L$19))/(1+$A34)^10+Assumptions!$B$9)/Assumptions!$B$10,"n/a") -> 12.304798
