Workbook

Sheet Model_Info
A1: WISE GROUP PLC (WISE) - DCF MODEL
A3: Lineage | B3: v1.0, built 28-Aug-2026 by Claude (Opus 4.6) with Stephen via claude.ai, following the equity-deep-dive -> tech-dcf-workbook route. Fresh build; no prior WISE workbook exists. openpyxl; recalculated in LibreOffice; key outputs hand-checked.
A5: DATA VINTAGE
A6: FY0 anchors (FY26, yr to 31-Mar-26) | B6: FY26 results release 25-Jun-26 and Form 20-F filed same day (SEC EDGAR, accession 0001193125-26-282911). Net revenue $2,502.8m; income before tax $660.4m (26.4% margin); net income ~$498.7m.
A7: Revenue build tie-out | B7: Company quarterly table in the FY26 release: FY26 cross-border revenue $1,257.0m + card/other $636.6m + net interest income $609.2m = $2,502.8m, ties exactly to reported net revenue. Same check passes for FY25 ($2,098.9m).
A8: FY1 guidance (FY27) | B8: Given 25-Jun-26: net revenue growth around the MIDDLE of the 15-20% medium-term range on a constant-currency basis; income before tax margin around the TOP of the 20-25% range. Assumes no material change in interest paid to customers or central-bank rates.
A9: Latest quarter | B9: Q1 FY27 (qtr to 30-Jun-26), released 16-Jul-26: net revenue $714.0m (+25% YoY), transaction revenue $540.9m (+27%), cross-border volume $69.3bn (+26%), active customers 11.9m (+21%), customer holdings $41.2bn (+31%), take rate 50bps (-2bps YoY), 77% instant.
A10: Balance sheet 31-Mar-26 | B10: Form 20-F: cash and equivalents $27,802.2m; AFS debt securities $4,582.7m; funds payable and amounts due to customers $30,254.2m; short-term debt $6.0m; total assets $33,259.8m; total equity ~$2,253.9m.
A11: Shares | B11: Diluted weighted-average FY26 1,019m. EST held 37.7m shares at 31-Mar-26 (deducted from both basic and diluted EPS). FY26: $470m spent on 35.9m shares into the EST.
A12: Price | B12: WSE (Nasdaq) $13.12, close 27-Aug-26; 52-week range $10.36-17.47. LSE line WISE ~860-905p over Aug-26 depending on source/date. Model is built and reported in USD.
A13: Regulatory / legal file | B13: July 2025 six-state multistate consent order, $4.2m, re Wise US AML/CFT (late SARs, transaction-monitoring data integrity, missing independent review). OCC Corporate Decision #1381, 21-Jul-26, DENIED the national trust bank charter; Wise intends to refile under a GENIUS Act framework. Belgian criminal investigation into Wise Europe disclosed Jun-26, examining >EUR500m of allegedly suspicious transactions. US securities class actions filed Aug-26, class period 11-May-26 to 23-Jul-26, lead-plaintiff deadline 29-Sep-26.
A15: METHODOLOGY
A16: Owner-FCF basis | B16: SBC (incl. equity-award taxes) fully expensed, projected explicitly per scenario-year as % of revenue; INTEREST INCOME EXCLUDED from flows (cash pile added separately - including both double-counts); cash tax ramps from the current sheltered rate to a normalized ~21%; D&A and capex as % of revenue; working capital = -2% of the YoY revenue increase (set for this business model); diluted shares held FLAT (SBC expensing substitutes for grant dilution; never do both). TV = Gordon capped at 20x terminal owner FCF. End-of-year discounting. WACC 10.5%. Street-convention values (SBC as non-cash) shown as memos - the house/street pair is the accounting-regime price band.
A17: Scenario drivers | B17: Scenario axes and driver paths set by Claude 28-Aug-2026 from the equity-deep-dive research, signed off by Stephen at the Stage-2 checkpoint the same day. Stephen set the probability weights at 20/50/30 (vs the 15/50/35 house default), raising the bear weight explicitly because of the live Belgian criminal investigation and the OCC charter denial. The central modelling judgment is the IBT-margin destination: management targets 15-20% including paying out 80% of interest income above a 1% yield to customers, but says that until it can substantially do so it expects to report 20-25%; FY26 printed 26.4%. Bear assumes the payout arrives, Bull assumes it never structurally does, Base splits the difference. NOT independently re-derived: D&A% and capex% are estimated from the PP&E roll-forward, and the SBC run-rate is inferred from the recurring EST programme - replace all three with reported figures from the 20-F cash-flow statement when read in full.
A19: UPDATE INSTRUCTIONS
A20: Each quarter | B20: Refresh price, net cash (+date), diluted shares, buyback pace, and the guidance-year driver columns; reassess blue rows 5/7/9/14 per scenario only where new evidence exists; add/extend the Reconciliation tab; increment the version above.
A21: Conventions | B21: Blue = hardcoded input. Yellow = key levers. Black = formula. Green = cross-sheet link. Prefilled values are working examples of the expected format.

Sheet Actuals_Data
A1: WISE - Reported actuals, balance sheet and guidance
A2: All figures USD millions, US GAAP, fiscal year ends 31 March. Blue = reported/hardcoded. Black = live check formula.
A4: Quarterly revenue build ($mm)
B5: Q1 FY25 | C5: Q2 FY25 | D5: Q3 FY25 | E5: Q4 FY25 | F5: Q1 FY26 | G5: Q2 FY26 | H5: Q3 FY26 | I5: Q4 FY26 | J5: Source
A6: Cross-border revenue | B6: 266.4 | C6: 270.2 | D6: 272.6 | E6: 262.5 | F6: 286.8 | G6: 305 | H6: 326.5 | I6: 338.7 | J6: Historical quarterly financials table, FY26 results release 25-Jun-26
A7: Card and other revenue | B7: 101.1 | C7: 120.9 | D7: 125.4 | E7: 127.2 | F7: 138 | G7: 153.4 | H7: 169.7 | I7: 175.5
A8: Interest income on customer balances | B8: 187.3 | C8: 198.1 | D8: 190.6 | E8: 182.3 | F8: 196.5 | G8: 202.5 | H8: 204.5 | I8: 202.6
A9: Interest expense on customer liabilities | B9: -52.1 | C9: -56.6 | D9: -49 | E9: -48 | F9: -48 | G9: -50.4 | H9: -49.5 | I9: -49
A10: Net revenue (sum) | B10: =SUM(B6:B9) -> 502.7 | C10: =SUM(C6:C9) -> 532.6 | D10: =SUM(D6:D9) -> 539.6 | E10: =SUM(E6:E9) -> 524 | F10: =SUM(F6:F9) -> 573.3 | G10: =SUM(G6:G9) -> 610.5 | H10: =SUM(H6:H9) -> 651.2 | I10: =SUM(I6:I9) -> 667.8
A11: Active customers (thousand) | B11: 8374 | C11: 8892 | D11: 9047 | E11: 9290 | F11: 9797 | G11: 10440 | H11: 10896 | I11: 11290
A12: Cross-border volume ($bn) | B12: 41.9 | C12: 45.7 | D12: 48.4 | E12: 49.2 | F12: 55 | G12: 59 | H12: 63.1 | I12: 66.5
A13: Customer balances ($bn, on balance sheet) | B13: 17.8 | C13: 19.6 | D13: 20.3 | E13: 22 | F13: 24.9 | G13: 26.4 | H13: 28.5 | I13: 30
A14: Cross-border take rate | B14: 0.0064 | C14: 0.0059 | D14: 0.0056 | E14: 0.0053 | F14: 0.0052 | G14: 0.0052 | H14: 0.0052 | I14: 0.0051
A16: Annual tie-out ($mm)
B17: FY25 | C17: FY26 | J17: Check
A18: Net revenue - sum of quarters | B18: =SUM(B10:E10) -> 2098.9 | C18: =SUM(F10:I10) -> 2502.8
A19: Net revenue - as reported | B19: 2098.9 | C19: 2502.8 | J19: FY26 release: net revenue $2.5bn, +19% YoY
A20: Difference (must be zero) | B20: =B18-B19 -> 0 | C20: =C18-C19 -> 0 | J20: Ties exactly on both years - revenue decomposition verified
A21: Income before tax | C21: 660.4 | J21: FY26 release; 26.4% margin, above the guided 20-25%
A22: IBT margin | C22: =C21/C19 -> 0.26386447
A23: Net income | C23: 498.7 | J23: Down ~9% YoY despite +19% revenue - price investment and listing costs
A24: Implied effective tax rate | C24: =1-C23/C21 -> 0.24485161
A25: Memo: one-off dual-listing costs in FY26 opex | C25: 45 | J25: c.$45m per FY26 analyst presentation; ex-listing IBT margin ~28%
A27: Balance sheet at 31-Mar-26 ($mm) and net-cash derivation
A28: Cash and cash equivalents | B28: 27802.2 | J28: Form 20-F consolidated statement of financial position
A29: add: available-for-sale debt securities | B29: 4582.7 | J29: Note 11
A30: less: funds payable and amounts due to customers | B30: -30254.2 | J30: Note 16 - customer float, NOT owner capital
A31: less: short-term debt | B31: -6 | J31: Note 17
A32: Own corporate net cash | B32: =SUM(B28:B31) -> 2124.7 | J32: Method validated: same calc on the FY25 balance sheet gives $1,800m, which is the company's own stated corporate cash of GBP1,430.2m at the Mar-25 rate
A33: less: haircut for locked regulatory capital | B33: =Assumptions!$B$9-B32 -> -424.7 | J33: Judgment. Wise's capital-allocation slide puts regulatory capital as the FIRST call on cash. Set Assumptions!B9 to B32 above to remove the haircut
A34: Net cash used in the model | B34: =Assumptions!$B$9 -> 1700
A35: Memo: total equity | B35: 2253.9 | J35: Cross-check: own net cash approximates book equity, as expected for an asset-light EMI
A37: Shares, buyback and guidance
A38: Diluted weighted-average shares FY26 (mm) | B38: 1019 | J38: Held FLAT in the model - SBC is expensed instead
A39: Shares held in the Employee Share Trust (mm) | B39: 37.7 | J39: At 31-Mar-26; deducted from basic and diluted EPS
A40: FY26 EST purchases ($mm) | B40: 470 | J40: 35.9m shares, to eliminate dilution from historic options
A41: New share purchase programme ($mm) | B41: 500 | J41: Announced 25-Jun-26; c.40% recurring EST, so c.60% genuine return
A43: FY27 guidance (given 25-Jun-26) | B43: Net revenue growth around the middle of 15-20% cc; IBT margin around the top of 20-25%. Medium-term: net revenue CAGR 15-20% off FY24, IBT margin 15-20% once 80% of interest above a 1% yield is paid out to customers.

Sheet Assumptions
A1: WISE - Global Assumptions & Scenario Parameters
A2: Blue = hardcoded input. Yellow = key levers. All $ in millions unless stated.
A4: Global inputs
A5: WACC / discount rate | B5: 0.105
A6: D&A (% of revenue) | B6: 0.028
A7: Capex + capitalized software (% of revenue) | B7: 0.04
A8: Working-capital capture (% of YoY revenue incr.) | B8: -0.02 | H8: Sign/size per business model
A9: Net cash ($mm) | B9: 1700 | H9: own corporate cash 31-Mar-26: cash 27,802.2 + AFS 4,582.7 - customer funds payable 30,254.2 - ST debt 6.0 = 2,124.7; haircut to 1,700 for locked regulatory capital
A10: Fully diluted shares (mm) | B10: 1019 | H10: diluted weighted-average FY26, 1,019m; held flat (SBC expensed)
A11: Current share price | B11: 13.12 | H11: WSE Nasdaq close 27-Aug-26 (Robinhood); LSE line ~860-905p, FX-dependent
A12: Terminal value cap (x terminal-year owner FCF) | B12: 20
A14: Scenario parameters | C14: Bear | D14: Base | E14: Bull
A15: Terminal growth rate | C15: 0.015 | D15: 0.03 | E15: 0.035
A16: Probability weight | C16: 0.2 | D16: 0.5 | E16: 0.3 | F16: =SUM(C16:E16) -> 1 | G16: must sum to 100%
A18: Scenario narratives
A19: Bear | B19: Belgian probe and/or successor actions bring EEA operational restrictions plus a material settlement; compliance opex steps up permanently and the second US charter attempt fails. Stablecoin-priced competition forces faster take-rate cuts. The 80%-of-interest-above-1% payout to customers arrives, dragging IBT margin to the 15-20% band and below. Growth fades to low single digits.
A20: Base | B20: Legal items resolve as settlements and remediation over 12-24 months with no operational restriction. Volume compounds ~20% then decelerates on the law of large numbers; take rate glides ~1-1.5bps/yr lower with card and Wise Platform partly offsetting. Balances keep compounding so net interest income holds up despite lower yields. IBT margin settles ~20-22% - inside the reported band, below FY26's 26.4% high-water mark.
A21: Bull | B21: Wise Platform and Business extend the S-curve; direct scheme connections keep unit costs falling faster than price. A GENIUS-Act charter eventually lands, cutting US rail cost. Balances pass $60bn and geographical restrictions mean the interest payout never structurally arrives, so IBT margin holds 24-25%. Legal items close for immaterial sums.

Sheet DCF_Bear
A1: WISE DCF - Bear - regulatory clip + payout arrives
A2: Owner-FCF basis: SBC fully expensed, interest income excluded, share count flat. Blue rows = per-year drivers (edit).
B3: 2026A | C3: 2027E | D3: 2028E | E3: 2029E | F3: 2030E | G3: 2031E | H3: 2032E | I3: 2033E | J3: 2034E | K3: 2035E | L3: 2036E
A4: Year index (for discounting) | B4: 0 | C4: 1 | D4: 2 | E4: 3 | F4: 4 | G4: 5 | H4: 6 | I4: 7 | J4: 8 | K4: 9 | L4: 10
A5: Revenue growth YoY | C5: 0.17 | D5: 0.12 | E5: 0.09 | F5: 0.07 | G5: 0.06 | H5: 0.05 | I5: 0.04 | J5: 0.04 | K5: 0.03 | L5: 0.03
A6: Revenue | B6: 2502.8 | C6: =B6*(1+C5) -> 2928.276 | D6: =C6*(1+D5) -> 3279.6691 | E6: =D6*(1+E5) -> 3574.8393 | F6: =E6*(1+F5) -> 3825.0781 | G6: =F6*(1+G5) -> 4054.5828 | H6: =G6*(1+H5) -> 4257.3119 | I6: =H6*(1+I5) -> 4427.6044 | J6: =I6*(1+J5) -> 4604.7086 | ... L6: =K6*(1+L5) -> 4885.1353
A7: Adj EBITDA margin | B7: 0.342 | C7: 0.325 | D7: 0.31 | E7: 0.295 | F7: 0.28 | G7: 0.27 | H7: 0.26 | I7: 0.255 | J7: 0.25 | K7: 0.245 | L7: 0.24
A8: Adjusted EBITDA | C8: =C6*C7 -> 951.6897 | D8: =D6*D7 -> 1016.6974 | E8: =E6*E7 -> 1054.5776 | F8: =F6*F7 -> 1071.0219 | G8: =G6*G7 -> 1094.7374 | H8: =H6*H7 -> 1106.9011 | I8: =I6*I7 -> 1129.0391 | J8: =J6*J7 -> 1151.1771 | ... L8: =L6*L7 -> 1172.4325
A9: SBC (% of revenue) | B9: 0.08 | C9: 0.08 | D9: 0.08 | E9: 0.078 | F9: 0.078 | G9: 0.075 | H9: 0.075 | I9: 0.073 | J9: 0.073 | K9: 0.07 | L9: 0.07
A10: SBC (incl. equity-award taxes) | C10: =-C6*C9 -> -234.26208 | D10: =-D6*D9 -> -262.37353 | E10: =-E6*E9 -> -278.83747 | F10: =-F6*F9 -> -298.35609 | G10: =-G6*G9 -> -304.09371 | H10: =-H6*H9 -> -319.29839 | I10: =-I6*I9 -> -323.21512 | J10: =-J6*J9 -> -336.14373 | ... L10: =-L6*L9 -> -341.95947
A11: EBITDA less SBC ('owner EBITDA') | C11: =C8+C10 -> 717.42762 | D11: =D8+D10 -> 754.3239 | E11: =E8+E10 -> 775.74014 | F11: =F8+F10 -> 772.66578 | G11: =G8+G10 -> 790.64364 | H11: =H8+H10 -> 787.60271 | I11: =I8+I10 -> 805.824 | J11: =J8+J10 -> 815.03342 | ... L11: =L8+L10 -> 830.47301
A12: D&A | C12: =-C6*Assumptions!$B$6 -> -81.991728 | D12: =-D6*Assumptions!$B$6 -> -91.830735 | E12: =-E6*Assumptions!$B$6 -> -100.0955 | F12: =-F6*Assumptions!$B$6 -> -107.10219 | G12: =-G6*Assumptions!$B$6 -> -113.52832 | H12: =-H6*Assumptions!$B$6 -> -119.20473 | I12: =-I6*Assumptions!$B$6 -> -123.97292 | J12: =-J6*Assumptions!$B$6 -> -128.93184 | ... L12: =-L6*Assumptions!$B$6 -> -136.78379
A13: EBIT (SBC expensed) | C13: =C11+C12 -> 635.43589 | D13: =D11+D12 -> 662.49316 | E13: =E11+E12 -> 675.64464 | F13: =F11+F12 -> 665.56359 | G13: =G11+G12 -> 677.11532 | H13: =H11+H12 -> 668.39797 | I13: =I11+I12 -> 681.85108 | J13: =J11+J12 -> 686.10158 | ... L13: =L11+L12 -> 693.68922
A14: Cash tax rate (neg = benefit) | C14: 0.235 | D14: 0.245 | E14: 0.25 | F14: 0.25 | G14: 0.25 | H14: 0.25 | I14: 0.25 | J14: 0.25 | K14: 0.25 | L14: 0.25
A15: NOPAT | C15: =C13*(1-C14) -> 486.10846 | D15: =D13*(1-D14) -> 500.18234 | E15: =E13*(1-E14) -> 506.73348 | F15: =F13*(1-F14) -> 499.17269 | G15: =G13*(1-G14) -> 507.83649 | H15: =H13*(1-H14) -> 501.29848 | I15: =I13*(1-I14) -> 511.38831 | J15: =J13*(1-J14) -> 514.57618 | ... L15: =L13*(1-L14) -> 520.26691
A16: add: D&A | C16: =-C12 -> 81.991728 | D16: =-D12 -> 91.830735 | E16: =-E12 -> 100.0955 | F16: =-F12 -> 107.10219 | G16: =-G12 -> 113.52832 | H16: =-H12 -> 119.20473 | I16: =-I12 -> 123.97292 | J16: =-J12 -> 128.93184 | ... L16: =-L12 -> 136.78379
A17: less: capex + capitalized software | C17: =-C6*Assumptions!$B$7 -> -117.13104 | D17: =-D6*Assumptions!$B$7 -> -131.18676 | E17: =-E6*Assumptions!$B$7 -> -142.99357 | F17: =-F6*Assumptions!$B$7 -> -153.00312 | G17: =-G6*Assumptions!$B$7 -> -162.18331 | H17: =-H6*Assumptions!$B$7 -> -170.29248 | I17: =-I6*Assumptions!$B$7 -> -177.10418 | J17: =-J6*Assumptions!$B$7 -> -184.18834 | ... L17: =-L6*Assumptions!$B$7 -> -195.40541
A18: add: working capital | C18: =Assumptions!$B$8*(C6-B6) -> -8.50952 | D18: =Assumptions!$B$8*(D6-C6) -> -7.0278624 | E18: =Assumptions!$B$8*(E6-D6) -> -5.9034044 | F18: =Assumptions!$B$8*(F6-E6) -> -5.0047751 | G18: =Assumptions!$B$8*(G6-F6) -> -4.5900937 | H18: =Assumptions!$B$8*(H6-G6) -> -4.0545828 | I18: =Assumptions!$B$8*(I6-H6) -> -3.4058495 | J18: =Assumptions!$B$8*(J6-I6) -> -3.5420835 | ... L18: =Assumptions!$B$8*(L6-K6) -> -2.8457099
A19: Unlevered owner FCF | C19: =C15+C16+C17+C18 -> 442.45963 | D19: =D15+D16+D17+D18 -> 453.79845 | E19: =E15+E16+E17+E18 -> 457.932 | F19: =F15+F16+F17+F18 -> 448.26698 | G19: =G15+G16+G17+G18 -> 454.59141 | H19: =H15+H16+H17+H18 -> 446.15615 | I19: =I15+I16+I17+I18 -> 454.85121 | J19: =J15+J16+J17+J18 -> 455.7776 | ... L19: =L15+L16+L17+L18 -> 458.79958
A20: Discount factor | C20: =1/(1+Assumptions!$B$5)^C4 -> 0.90497738 | D20: =1/(1+Assumptions!$B$5)^D4 -> 0.81898405 | E20: =1/(1+Assumptions!$B$5)^E4 -> 0.74116204 | F20: =1/(1+Assumptions!$B$5)^F4 -> 0.67073487 | G20: =1/(1+Assumptions!$B$5)^G4 -> 0.60699989 | H20: =1/(1+Assumptions!$B$5)^H4 -> 0.54932116 | I20: =1/(1+Assumptions!$B$5)^I4 -> 0.49712323 | J20: =1/(1+Assumptions!$B$5)^J4 -> 0.44988527 | ... L20: =1/(1+Assumptions!$B$5)^L4 -> 0.36844886
A21: PV of FCF | C21: =C19*C20 -> 400.41595 | D21: =D19*D20 -> 371.65369 | E21: =E19*E20 -> 339.40181 | F21: =F19*F20 -> 300.6683 | G21: =G19*G20 -> 275.93693 | H21: =H19*H20 -> 245.08302 | I21: =I19*I20 -> 226.1171 | J21: =J19*J20 -> 205.04763 | ... L21: =L19*L20 -> 169.04418
A23: Memo: FCF before SBC (company-style) | C23: =C19-C10 -> 676.72171 | D23: =D19-D10 -> 716.17198 | E23: =E19-E10 -> 736.76947 | F23: =F19-F10 -> 746.62307 | G23: =G19-G10 -> 758.68511 | H23: =H19-H10 -> 765.45455 | I23: =I19-I10 -> 778.06633 | J23: =J19-J10 -> 791.92132 | ... L23: =L19-L10 -> 800.75905
A24: Memo: implied owner FCF margin | C24: =C19/C6 -> 0.15109902 | D24: =D19/D6 -> 0.13836714 | E24: =E19/E6 -> 0.12809862 | F24: =F19/F6 -> 0.11719159 | G24: =G19/G6 -> 0.11211792 | H24: =H19/H6 -> 0.10479762 | I24: =I19/I6 -> 0.10273077 | J24: =J19/J6 -> 0.098980769 | ... L24: =L19/L6 -> 0.093917476
A25: Valuation
A26: PV of FCF, explicit years | B26: =SUM(C21:L21) -> 2721.963
A27: Terminal growth rate | B27: =Assumptions!$C$15 -> 0.015
A28: Terminal-year owner FCF x (1+g) | B28: =L19*(1+B27) -> 465.68157
A29: Terminal value - Gordon | B29: =B28/(Assumptions!$B$5-B27) -> 5174.2397
A30: Terminal value - cap | B30: =Assumptions!$B$12*L19 -> 9175.9916
A31: Terminal value used (lower of the two, floored at 0) | B31: =MAX(0,MIN(B29,B30)) -> 5174.2397
A32: Implied exit multiple | B32: =B31/L19 -> 11.277778
A33: PV of terminal value | B33: =B31*L20 -> 1906.4427
A34: Enterprise value | B34: =B26+B33 -> 4628.4058
A35: add: net cash | B35: =Assumptions!$B$9 -> 1700
A36: Equity value | B36: =B34+B35 -> 6328.4058
A37: Fully diluted shares (mm) | B37: =Assumptions!$B$10 -> 1019
A38: Value per share | B38: =B36/B37 -> 6.210408
A39: Upside / (downside) vs current price | B39: =B38/Assumptions!$B$11-1 -> -0.52664573
A41: Memo: value if SBC treated as non-cash | B41: =SUMPRODUCT(-C10:L10/(1+Assumptions!$B$5)^C4:L4) -> 1766.7128
A42: plus PV of terminal SBC | B42: =(-L10*(1+B27)/(Assumptions!$B$5-B27))*L20 -> 1420.9389
...

Sheet DCF_Base
A1: WISE DCF - Base - fines not restrictions; margin normalises
A2: Owner-FCF basis: SBC fully expensed, interest income excluded, share count flat. Blue rows = per-year drivers (edit).
B3: 2026A | C3: 2027E | D3: 2028E | E3: 2029E | F3: 2030E | G3: 2031E | H3: 2032E | I3: 2033E | J3: 2034E | K3: 2035E | L3: 2036E
A4: Year index (for discounting) | B4: 0 | C4: 1 | D4: 2 | E4: 3 | F4: 4 | G4: 5 | H4: 6 | I4: 7 | J4: 8 | K4: 9 | L4: 10
A5: Revenue growth YoY | C5: 0.2 | D5: 0.17 | E5: 0.15 | F5: 0.14 | G5: 0.12 | H5: 0.11 | I5: 0.1 | J5: 0.09 | K5: 0.08 | L5: 0.07
A6: Revenue | B6: 2502.8 | C6: =B6*(1+C5) -> 3003.36 | D6: =C6*(1+D5) -> 3513.9312 | E6: =D6*(1+E5) -> 4041.0209 | F6: =E6*(1+F5) -> 4606.7638 | G6: =F6*(1+G5) -> 5159.5755 | H6: =G6*(1+H5) -> 5727.1288 | I6: =H6*(1+I5) -> 6299.8416 | J6: =I6*(1+J5) -> 6866.8274 | ... L6: =K6*(1+L5) -> 7935.3057
A7: Adj EBITDA margin | B7: 0.342 | C7: 0.333 | D7: 0.33 | E7: 0.325 | F7: 0.32 | G7: 0.315 | H7: 0.31 | I7: 0.305 | J7: 0.3 | K7: 0.3 | L7: 0.3
A8: Adjusted EBITDA | C8: =C6*C7 -> 1000.1189 | D8: =D6*D7 -> 1159.5973 | E8: =E6*E7 -> 1313.3318 | F8: =F6*F7 -> 1474.1644 | G8: =G6*G7 -> 1625.2663 | H8: =H6*H7 -> 1775.4099 | I8: =I6*I7 -> 1921.4517 | J8: =J6*J7 -> 2060.0482 | ... L8: =L6*L7 -> 2380.5917
A9: SBC (% of revenue) | B9: 0.08 | C9: 0.078 | D9: 0.075 | E9: 0.072 | F9: 0.07 | G9: 0.068 | H9: 0.065 | I9: 0.063 | J9: 0.06 | K9: 0.058 | L9: 0.055
A10: SBC (incl. equity-award taxes) | C10: =-C6*C9 -> -234.26208 | D10: =-D6*D9 -> -263.54484 | E10: =-E6*E9 -> -290.9535 | F10: =-F6*F9 -> -322.47347 | G10: =-G6*G9 -> -350.85113 | H10: =-H6*H9 -> -372.26337 | I10: =-I6*I9 -> -396.89002 | J10: =-J6*J9 -> -412.00964 | ... L10: =-L6*L9 -> -436.44181
A11: EBITDA less SBC ('owner EBITDA') | C11: =C8+C10 -> 765.8568 | D11: =D8+D10 -> 896.05246 | E11: =E8+E10 -> 1022.3783 | F11: =F8+F10 -> 1151.691 | G11: =G8+G10 -> 1274.4151 | H11: =H8+H10 -> 1403.1465 | I11: =I8+I10 -> 1524.5617 | J11: =J8+J10 -> 1648.0386 | ... L11: =L8+L10 -> 1944.1499
A12: D&A | C12: =-C6*Assumptions!$B$6 -> -84.09408 | D12: =-D6*Assumptions!$B$6 -> -98.390074 | E12: =-E6*Assumptions!$B$6 -> -113.14858 | F12: =-F6*Assumptions!$B$6 -> -128.98939 | G12: =-G6*Assumptions!$B$6 -> -144.46811 | H12: =-H6*Assumptions!$B$6 -> -160.35961 | I12: =-I6*Assumptions!$B$6 -> -176.39557 | J12: =-J6*Assumptions!$B$6 -> -192.27117 | ... L12: =-L6*Assumptions!$B$6 -> -222.18856
A13: EBIT (SBC expensed) | C13: =C11+C12 -> 681.76272 | D13: =D11+D12 -> 797.66238 | E13: =E11+E12 -> 909.2297 | F13: =F11+F12 -> 1022.7016 | G13: =G11+G12 -> 1129.947 | H13: =H11+H12 -> 1242.7869 | I13: =I11+I12 -> 1348.1661 | J13: =J11+J12 -> 1455.7674 | ... L13: =L11+L12 -> 1721.9613
A14: Cash tax rate (neg = benefit) | C14: 0.23 | D14: 0.235 | E14: 0.24 | F14: 0.24 | G14: 0.24 | H14: 0.24 | I14: 0.24 | J14: 0.24 | K14: 0.24 | L14: 0.24
A15: NOPAT | C15: =C13*(1-C14) -> 524.95729 | D15: =D13*(1-D14) -> 610.21172 | E15: =E13*(1-E14) -> 691.01457 | F15: =F13*(1-F14) -> 777.25319 | G15: =G13*(1-G14) -> 858.75974 | H15: =H13*(1-H14) -> 944.51808 | I15: =I13*(1-I14) -> 1024.6062 | J15: =J13*(1-J14) -> 1106.3832 | ... L15: =L13*(1-L14) -> 1308.6906
A16: add: D&A | C16: =-C12 -> 84.09408 | D16: =-D12 -> 98.390074 | E16: =-E12 -> 113.14858 | F16: =-F12 -> 128.98939 | G16: =-G12 -> 144.46811 | H16: =-H12 -> 160.35961 | I16: =-I12 -> 176.39557 | J16: =-J12 -> 192.27117 | ... L16: =-L12 -> 222.18856
A17: less: capex + capitalized software | C17: =-C6*Assumptions!$B$7 -> -120.1344 | D17: =-D6*Assumptions!$B$7 -> -140.55725 | E17: =-E6*Assumptions!$B$7 -> -161.64084 | F17: =-F6*Assumptions!$B$7 -> -184.27055 | G17: =-G6*Assumptions!$B$7 -> -206.38302 | H17: =-H6*Assumptions!$B$7 -> -229.08515 | I17: =-I6*Assumptions!$B$7 -> -251.99367 | J17: =-J6*Assumptions!$B$7 -> -274.6731 | ... L17: =-L6*Assumptions!$B$7 -> -317.41223
A18: add: working capital | C18: =Assumptions!$B$8*(C6-B6) -> -10.0112 | D18: =Assumptions!$B$8*(D6-C6) -> -10.211424 | E18: =Assumptions!$B$8*(E6-D6) -> -10.541794 | F18: =Assumptions!$B$8*(F6-E6) -> -11.314858 | G18: =Assumptions!$B$8*(G6-F6) -> -11.056233 | H18: =Assumptions!$B$8*(H6-G6) -> -11.351066 | I18: =Assumptions!$B$8*(I6-H6) -> -11.454258 | J18: =Assumptions!$B$8*(J6-I6) -> -11.339715 | ... L18: =Assumptions!$B$8*(L6-K6) -> -10.382643
A19: Unlevered owner FCF | C19: =C15+C16+C17+C18 -> 478.90577 | D19: =D15+D16+D17+D18 -> 557.83312 | E19: =E15+E16+E17+E18 -> 631.98053 | F19: =F15+F16+F17+F18 -> 710.65716 | G19: =G15+G16+G17+G18 -> 785.7886 | H19: =H15+H16+H17+H18 -> 864.44146 | I19: =I15+I16+I17+I18 -> 937.55389 | J19: =J15+J16+J17+J18 -> 1012.6416 | ... L19: =L15+L16+L17+L18 -> 1203.0843
A20: Discount factor | C20: =1/(1+Assumptions!$B$5)^C4 -> 0.90497738 | D20: =1/(1+Assumptions!$B$5)^D4 -> 0.81898405 | E20: =1/(1+Assumptions!$B$5)^E4 -> 0.74116204 | F20: =1/(1+Assumptions!$B$5)^F4 -> 0.67073487 | G20: =1/(1+Assumptions!$B$5)^G4 -> 0.60699989 | H20: =1/(1+Assumptions!$B$5)^H4 -> 0.54932116 | I20: =1/(1+Assumptions!$B$5)^I4 -> 0.49712323 | J20: =1/(1+Assumptions!$B$5)^J4 -> 0.44988527 | ... L20: =1/(1+Assumptions!$B$5)^L4 -> 0.36844886
A21: PV of FCF | C21: =C19*C20 -> 433.39889 | D21: =D19*D20 -> 456.85643 | E21: =E19*E20 -> 468.39997 | F21: =F19*F20 -> 476.66254 | G21: =G19*G20 -> 476.97359 | H21: =H19*H20 -> 474.85599 | I21: =I19*I20 -> 466.07981 | J21: =J19*J20 -> 455.57253 | ... L21: =L19*L20 -> 443.27504
A23: Memo: FCF before SBC (company-style) | C23: =C19-C10 -> 713.16785 | D23: =D19-D10 -> 821.37796 | E23: =E19-E10 -> 922.93403 | F23: =F19-F10 -> 1033.1306 | G23: =G19-G10 -> 1136.6397 | H23: =H19-H10 -> 1236.7048 | I23: =I19-I10 -> 1334.4439 | J23: =J19-J10 -> 1424.6512 | ... L23: =L19-L10 -> 1639.5261
A24: Memo: implied owner FCF margin | C24: =C19/C6 -> 0.15945667 | D24: =D19/D6 -> 0.15874902 | E24: =E19/E6 -> 0.1563913 | F24: =F19/F6 -> 0.15426386 | G24: =G19/G6 -> 0.15229714 | H24: =H19/H6 -> 0.15093802 | I24: =I19/I6 -> 0.14882182 | J24: =J19/J6 -> 0.14746862 | ... L24: =L19/L6 -> 0.15161159
A25: Valuation
A26: PV of FCF, explicit years | B26: =SUM(C21:L21) -> 4602.4427
A27: Terminal growth rate | B27: =Assumptions!$D$15 -> 0.03
A28: Terminal-year owner FCF x (1+g) | B28: =L19*(1+B27) -> 1239.1768
A29: Terminal value - Gordon | B29: =B28/(Assumptions!$B$5-B27) -> 16522.358
A30: Terminal value - cap | B30: =Assumptions!$B$12*L19 -> 24061.686
A31: Terminal value used (lower of the two, floored at 0) | B31: =MAX(0,MIN(B29,B30)) -> 16522.358
A32: Implied exit multiple | B32: =B31/L19 -> 13.733333
A33: PV of terminal value | B33: =B31*L20 -> 6087.6439
A34: Enterprise value | B34: =B26+B33 -> 10690.087
A35: add: net cash | B35: =Assumptions!$B$9 -> 1700
A36: Equity value | B36: =B34+B35 -> 12390.087
A37: Fully diluted shares (mm) | B37: =Assumptions!$B$10 -> 1019
A38: Value per share | B38: =B36/B37 -> 12.159064
A39: Upside / (downside) vs current price | B39: =B38/Assumptions!$B$11-1 -> -0.073242039
A41: Memo: value if SBC treated as non-cash | B41: =SUMPRODUCT(-C10:L10/(1+Assumptions!$B$5)^C4:L4) -> 1995.829
A42: plus PV of terminal SBC | B42: =(-L10*(1+B27)/(Assumptions!$B$5-B27))*L20 -> 2208.4091
...

Sheet DCF_Bull
A1: WISE DCF - Bull - the network compounds; payout never arrives
A2: Owner-FCF basis: SBC fully expensed, interest income excluded, share count flat. Blue rows = per-year drivers (edit).
B3: 2026A | C3: 2027E | D3: 2028E | E3: 2029E | F3: 2030E | G3: 2031E | H3: 2032E | I3: 2033E | J3: 2034E | K3: 2035E | L3: 2036E
A4: Year index (for discounting) | B4: 0 | C4: 1 | D4: 2 | E4: 3 | F4: 4 | G4: 5 | H4: 6 | I4: 7 | J4: 8 | K4: 9 | L4: 10
A5: Revenue growth YoY | C5: 0.22 | D5: 0.21 | E5: 0.19 | F5: 0.17 | G5: 0.15 | H5: 0.14 | I5: 0.12 | J5: 0.11 | K5: 0.1 | L5: 0.09
A6: Revenue | B6: 2502.8 | C6: =B6*(1+C5) -> 3053.416 | D6: =C6*(1+D5) -> 3694.6334 | E6: =D6*(1+E5) -> 4396.6137 | F6: =E6*(1+F5) -> 5144.038 | G6: =F6*(1+G5) -> 5915.6437 | H6: =G6*(1+H5) -> 6743.8339 | I6: =H6*(1+I5) -> 7553.0939 | J6: =I6*(1+J5) -> 8383.9342 | ... L6: =K6*(1+L5) -> 10052.337
A7: Adj EBITDA margin | B7: 0.342 | C7: 0.34 | D7: 0.34 | E7: 0.345 | F7: 0.345 | G7: 0.35 | H7: 0.35 | I7: 0.35 | J7: 0.35 | K7: 0.35 | L7: 0.35
A8: Adjusted EBITDA | C8: =C6*C7 -> 1038.1614 | D8: =D6*D7 -> 1256.1753 | E8: =E6*E7 -> 1516.8317 | F8: =F6*F7 -> 1774.6931 | G8: =G6*G7 -> 2070.4753 | H8: =H6*H7 -> 2360.3418 | I8: =I6*I7 -> 2643.5829 | J8: =J6*J7 -> 2934.377 | ... L8: =L6*L7 -> 3518.318
A9: SBC (% of revenue) | B9: 0.08 | C9: 0.075 | D9: 0.07 | E9: 0.066 | F9: 0.062 | G9: 0.058 | H9: 0.055 | I9: 0.052 | J9: 0.05 | K9: 0.048 | L9: 0.045
A10: SBC (incl. equity-award taxes) | C10: =-C6*C9 -> -229.0062 | D10: =-D6*D9 -> -258.62434 | E10: =-E6*E9 -> -290.1765 | F10: =-F6*F9 -> -318.93036 | G10: =-G6*G9 -> -343.10734 | H10: =-H6*H9 -> -370.91086 | I10: =-I6*I9 -> -392.76088 | J10: =-J6*J9 -> -419.19671 | ... L10: =-L6*L9 -> -452.35517
A11: EBITDA less SBC ('owner EBITDA') | C11: =C8+C10 -> 809.15524 | D11: =D8+D10 -> 997.55101 | E11: =E8+E10 -> 1226.6552 | F11: =F8+F10 -> 1455.7628 | G11: =G8+G10 -> 1727.368 | H11: =H8+H10 -> 1989.431 | I11: =I8+I10 -> 2250.822 | J11: =J8+J10 -> 2515.1803 | ... L11: =L8+L10 -> 3065.9628
A12: D&A | C12: =-C6*Assumptions!$B$6 -> -85.495648 | D12: =-D6*Assumptions!$B$6 -> -103.44973 | E12: =-E6*Assumptions!$B$6 -> -123.10518 | F12: =-F6*Assumptions!$B$6 -> -144.03306 | G12: =-G6*Assumptions!$B$6 -> -165.63802 | H12: =-H6*Assumptions!$B$6 -> -188.82735 | I12: =-I6*Assumptions!$B$6 -> -211.48663 | J12: =-J6*Assumptions!$B$6 -> -234.75016 | ... L12: =-L6*Assumptions!$B$6 -> -281.46544
A13: EBIT (SBC expensed) | C13: =C11+C12 -> 723.65959 | D13: =D11+D12 -> 894.10127 | E13: =E11+E12 -> 1103.55 | F13: =F11+F12 -> 1311.7297 | G13: =G11+G12 -> 1561.7299 | H13: =H11+H12 -> 1800.6036 | I13: =I11+I12 -> 2039.3354 | J13: =J11+J12 -> 2280.4301 | ... L13: =L11+L12 -> 2784.4974
A14: Cash tax rate (neg = benefit) | C14: 0.23 | D14: 0.235 | E14: 0.24 | F14: 0.24 | G14: 0.24 | H14: 0.24 | I14: 0.24 | J14: 0.24 | K14: 0.24 | L14: 0.24
A15: NOPAT | C15: =C13*(1-C14) -> 557.21789 | D15: =D13*(1-D14) -> 683.98747 | E15: =E13*(1-E14) -> 838.69803 | F15: =F13*(1-F14) -> 996.91457 | G15: =G13*(1-G14) -> 1186.9148 | H15: =H13*(1-H14) -> 1368.4588 | I15: =I13*(1-I14) -> 1549.8949 | J15: =J13*(1-J14) -> 1733.1269 | ... L15: =L13*(1-L14) -> 2116.218
A16: add: D&A | C16: =-C12 -> 85.495648 | D16: =-D12 -> 103.44973 | E16: =-E12 -> 123.10518 | F16: =-F12 -> 144.03306 | G16: =-G12 -> 165.63802 | H16: =-H12 -> 188.82735 | I16: =-I12 -> 211.48663 | J16: =-J12 -> 234.75016 | ... L16: =-L12 -> 281.46544
A17: less: capex + capitalized software | C17: =-C6*Assumptions!$B$7 -> -122.13664 | D17: =-D6*Assumptions!$B$7 -> -147.78533 | E17: =-E6*Assumptions!$B$7 -> -175.86455 | F17: =-F6*Assumptions!$B$7 -> -205.76152 | G17: =-G6*Assumptions!$B$7 -> -236.62575 | H17: =-H6*Assumptions!$B$7 -> -269.75335 | I17: =-I6*Assumptions!$B$7 -> -302.12376 | J17: =-J6*Assumptions!$B$7 -> -335.35737 | ... L17: =-L6*Assumptions!$B$7 -> -402.09349
A18: add: working capital | C18: =Assumptions!$B$8*(C6-B6) -> -11.01232 | D18: =Assumptions!$B$8*(D6-C6) -> -12.824347 | E18: =Assumptions!$B$8*(E6-D6) -> -14.039607 | F18: =Assumptions!$B$8*(F6-E6) -> -14.948487 | G18: =Assumptions!$B$8*(G6-F6) -> -15.432114 | H18: =Assumptions!$B$8*(H6-G6) -> -16.563802 | I18: =Assumptions!$B$8*(I6-H6) -> -16.185201 | J18: =Assumptions!$B$8*(J6-I6) -> -16.616807 | ... L18: =Assumptions!$B$8*(L6-K6) -> -16.60019
A19: Unlevered owner FCF | C19: =C15+C16+C17+C18 -> 509.56457 | D19: =D15+D16+D17+D18 -> 626.82753 | E19: =E15+E16+E17+E18 -> 771.89906 | F19: =F15+F16+F17+F18 -> 920.23763 | G19: =G15+G16+G17+G18 -> 1100.4949 | H19: =H15+H16+H17+H18 -> 1270.969 | I19: =I15+I16+I17+I18 -> 1443.0725 | J19: =J15+J16+J17+J18 -> 1615.9029 | ... L19: =L15+L16+L17+L18 -> 1978.9898
A20: Discount factor | C20: =1/(1+Assumptions!$B$5)^C4 -> 0.90497738 | D20: =1/(1+Assumptions!$B$5)^D4 -> 0.81898405 | E20: =1/(1+Assumptions!$B$5)^E4 -> 0.74116204 | F20: =1/(1+Assumptions!$B$5)^F4 -> 0.67073487 | G20: =1/(1+Assumptions!$B$5)^G4 -> 0.60699989 | H20: =1/(1+Assumptions!$B$5)^H4 -> 0.54932116 | I20: =1/(1+Assumptions!$B$5)^I4 -> 0.49712323 | J20: =1/(1+Assumptions!$B$5)^J4 -> 0.44988527 | ... L20: =1/(1+Assumptions!$B$5)^L4 -> 0.36844886
A21: PV of FCF | C21: =C19*C20 -> 461.14441 | D21: =D19*D20 -> 513.36175 | E21: =E19*E20 -> 572.10228 | F21: =F19*F20 -> 617.23547 | G21: =G19*G20 -> 668.00029 | H21: =H19*H20 -> 698.17015 | I21: =I19*I20 -> 717.38488 | J21: =J19*J20 -> 726.9709 | ... L21: =L19*L20 -> 729.15653
A23: Memo: FCF before SBC (company-style) | C23: =C19-C10 -> 738.57077 | D23: =D19-D10 -> 885.45186 | E23: =E19-E10 -> 1062.0756 | F23: =F19-F10 -> 1239.168 | G23: =G19-G10 -> 1443.6023 | H23: =H19-H10 -> 1641.8798 | I23: =I19-I10 -> 1835.8334 | J23: =J19-J10 -> 2035.0996 | ... L23: =L19-L10 -> 2431.345
A24: Memo: implied owner FCF margin | C24: =C19/C6 -> 0.16688344 | D24: =D19/D6 -> 0.16965893 | E24: =E19/E6 -> 0.17556672 | F24: =F19/F6 -> 0.17889402 | G24: =G19/G6 -> 0.1860313 | H24: =H19/H6 -> 0.18846386 | I24: =I19/I6 -> 0.19105714 | J24: =J19/J6 -> 0.19273802 | ... L24: =L19/L6 -> 0.19686862
A25: Valuation
A26: PV of FCF, explicit years | B26: =SUM(C21:L21) -> 6433.5303
A27: Terminal growth rate | B27: =Assumptions!$E$15 -> 0.035
A28: Terminal-year owner FCF x (1+g) | B28: =L19*(1+B27) -> 2048.2544
A29: Terminal value - Gordon | B29: =B28/(Assumptions!$B$5-B27) -> 29260.778
A30: Terminal value - cap | B30: =Assumptions!$B$12*L19 -> 39579.796
A31: Terminal value used (lower of the two, floored at 0) | B31: =MAX(0,MIN(B29,B30)) -> 29260.778
A32: Implied exit multiple | B32: =B31/L19 -> 14.785714
A33: PV of terminal value | B33: =B31*L20 -> 10781.1
A34: Enterprise value | B34: =B26+B33 -> 17214.631
A35: add: net cash | B35: =Assumptions!$B$9 -> 1700
A36: Equity value | B36: =B34+B35 -> 18914.631
A37: Fully diluted shares (mm) | B37: =Assumptions!$B$10 -> 1019
A38: Value per share | B38: =B36/B37 -> 18.561953
A39: Upside / (downside) vs current price | B39: =B38/Assumptions!$B$11-1 -> 0.41478303
A41: Memo: value if SBC treated as non-cash | B41: =SUMPRODUCT(-C10:L10/(1+Assumptions!$B$5)^C4:L4) -> 1990.7938
A42: plus PV of terminal SBC | B42: =(-L10*(1+B27)/(Assumptions!$B$5-B27))*L20 -> 2464.3313
...

Sheet Valuation
A1: WISE - Valuation Summary & Sensitivity
A2: Owner-FCF basis (SBC expensed) unless marked street. Green = links.
B4: Bear | C4: Base | D4: Bull
A5: Value per share | B5: =DCF_Bear!$B$38 -> 6.210408 | C5: =DCF_Base!$B$38 -> 12.159064 | D5: =DCF_Bull!$B$38 -> 18.561953
A6: Upside / (downside) vs price | B6: =B5/Assumptions!$B$11-1 -> -0.52664573 | C6: =C5/Assumptions!$B$11-1 -> -0.073242039 | D6: =D5/Assumptions!$B$11-1 -> 0.41478303
A7: Probability | B7: =Assumptions!$C$16 -> 0.2 | C7: =Assumptions!$D$16 -> 0.5 | D7: =Assumptions!$E$16 -> 0.3
A8: Value per share, SBC as non-cash (street) | B8: =DCF_Bear!$B$43 -> 9.3386236 | C8: =DCF_Base!$B$43 -> 16.284912 | D8: =DCF_Bull!$B$43 -> 22.934009
A10: Probability-weighted value per share | B10: =SUMPRODUCT(B5:D5,B7:D7) -> 12.8902
A11: Current price | B11: =Assumptions!$B$11 -> 13.12
A12: Margin of safety vs weighted value | B12: =1-B11/B10 -> -0.017827509
A13: Weighted value, SBC as non-cash (street) | B13: =SUMPRODUCT(B8:D8,B7:D7) -> 16.890383
A14: Band position (0%=house, 100%=street) | B14: =IF(ABS(B13-B10)<0.005,"n/a - SBC=0 so house=street",(Assumptions!$B$11-B10)/(B13-B10)) -> 0.057447404
A17: Base case - value per share at different required returns
A18: Required return | B18: Value / share
A19: 0.09 | B19: =(SUMPRODUCT(DCF_Base!$C$19:$L$19/(1+$A19)^DCF_Base!$C$4:$L$4)+MAX(0,MIN(DCF_Base!$L$19*(1+Assumptions!$D$15)/($A19-Assumptions!$D$15),Assumptions!$B$12*DCF_Base!$L$19))/(1+$A19)^10+Assumptions!$B$9)/Assumptions!$B$10 -> 15.102165
A20: 0.1 | B20: =(SUMPRODUCT(DCF_Base!$C$19:$L$19/(1+$A20)^DCF_Base!$C$4:$L$4)+MAX(0,MIN(DCF_Base!$L$19*(1+Assumptions!$D$15)/($A20-Assumptions!$D$15),Assumptions!$B$12*DCF_Base!$L$19))/(1+$A20)^10+Assumptions!$B$9)/Assumptions!$B$10 -> 12.997096
A21: 0.105 | B21: =(SUMPRODUCT(DCF_Base!$C$19:$L$19/(1+$A21)^DCF_Base!$C$4:$L$4)+MAX(0,MIN(DCF_Base!$L$19*(1+Assumptions!$D$15)/($A21-Assumptions!$D$15),Assumptions!$B$12*DCF_Base!$L$19))/(1+$A21)^10+Assumptions!$B$9)/Assumptions!$B$10 -> 12.159064
A22: 0.11 | B22: =(SUMPRODUCT(DCF_Base!$C$19:$L$19/(1+$A22)^DCF_Base!$C$4:$L$4)+MAX(0,MIN(DCF_Base!$L$19*(1+Assumptions!$D$15)/($A22-Assumptions!$D$15),Assumptions!$B$12*DCF_Base!$L$19))/(1+$A22)^10+Assumptions!$B$9)/Assumptions!$B$10 -> 11.428156
A23: 0.12 | B23: =(SUMPRODUCT(DCF_Base!$C$19:$L$19/(1+$A23)^DCF_Base!$C$4:$L$4)+MAX(0,MIN(DCF_Base!$L$19*(1+Assumptions!$D$15)/($A23-Assumptions!$D$15),Assumptions!$B$12*DCF_Base!$L$19))/(1+$A23)^10+Assumptions!$B$9)/Assumptions!$B$10 -> 10.215973
A24: 0.15 | B24: =(SUMPRODUCT(DCF_Base!$C$19:$L$19/(1+$A24)^DCF_Base!$C$4:$L$4)+MAX(0,MIN(DCF_Base!$L$19*(1+Assumptions!$D$15)/($A24-Assumptions!$D$15),Assumptions!$B$12*DCF_Base!$L$19))/(1+$A24)^10+Assumptions!$B$9)/Assumptions!$B$10 -> 7.8237197
A25: 15%-hurdle entry per scenario + weighted | B25: =(SUMPRODUCT(DCF_Bear!$C$19:$L$19/(1+0.15)^DCF_Bear!$C$4:$L$4)+MAX(0,MIN(DCF_Bear!$L$19*(1+Assumptions!$C$15)/(0.15-Assumptions!$C$15),Assumptions!$B$12*DCF_Bear!$L$19))/(1+0.15)^10+Assumptions!$B$9)/Assumptions!$B$10 -> 4.7320067 | C25: =(SUMPRODUCT(DCF_Base!$C$19:$L$19/(1+0.15)^DCF_Base!$C$4:$L$4)+MAX(0,MIN(DCF_Base!$L$19*(1+Assumptions!$D$15)/(0.15-Assumptions!$D$15),Assumptions!$B$12*DCF_Base!$L$19))/(1+0.15)^10+Assumptions!$B$9)/Assumptions!$B$10 -> 7.8237197 | D25: =(SUMPRODUCT(DCF_Bull!$C$19:$L$19/(1+0.15)^DCF_Bull!$C$4:$L$4)+MAX(0,MIN(DCF_Bull!$L$19*(1+Assumptions!$E$15)/(0.15-Assumptions!$E$15),Assumptions!$B$12*DCF_Bull!$L$19))/(1+0.15)^10+Assumptions!$B$9)/Assumptions!$B$10 -> 11.010369 | E25: =SUMPRODUCT(B25:D25,$B$7:$D$7) -> 8.161372 | G25: model buy-below price at a 15% hurdle
A26: same, street basis | B26: =B25+(SUMPRODUCT(-DCF_Bear!$C$10:$L$10/(1+0.15)^DCF_Bear!$C$4:$L$4)+(-DCF_Bear!$L$10*(1+Assumptions!$C$15)/(0.15-Assumptions!$C$15))/(1+0.15)^10)/Assumptions!$B$10 -> 6.784087 | C26: =C25+(SUMPRODUCT(-DCF_Base!$C$10:$L$10/(1+0.15)^DCF_Base!$C$4:$L$4)+(-DCF_Base!$L$10*(1+Assumptions!$D$15)/(0.15-Assumptions!$D$15))/(1+0.15)^10)/Assumptions!$B$10 -> 10.330169 | D26: =D25+(SUMPRODUCT(-DCF_Bull!$C$10:$L$10/(1+0.15)^DCF_Bull!$C$4:$L$4)+(-DCF_Bull!$L$10*(1+Assumptions!$E$15)/(0.15-Assumptions!$E$15))/(1+0.15)^10)/Assumptions!$B$10 -> 13.588834 | E26: =SUMPRODUCT(B26:D26,$B$7:$D$7) -> 10.598552
A28: Base case - value per share: WACC x terminal growth
A29: WACC \ g | B29: 0.02 | C29: 0.025 | D29: 0.03 | E29: 0.035 | F29: 0.04
A30: 0.095 | B30: =IF($A30>B$29,(SUMPRODUCT(DCF_Base!$C$19:$L$19/(1+$A30)^DCF_Base!$C$4:$L$4)+MAX(0,MIN(DCF_Base!$L$19*(1+B$29)/($A30-B$29),Assumptions!$B$12*DCF_Base!$L$19))/(1+$A30)^10+Assumptions!$B$9)/Assumptions!$B$10,"n/a") -> 12.896998 | C30: =IF($A30>C$29,(SUMPRODUCT(DCF_Base!$C$19:$L$19/(1+$A30)^DCF_Base!$C$4:$L$4)+MAX(0,MIN(DCF_Base!$L$19*(1+C$29)/($A30-C$29),Assumptions!$B$12*DCF_Base!$L$19))/(1+$A30)^10+Assumptions!$B$9)/Assumptions!$B$10,"n/a") -> 13.393826 | D30: =IF($A30>D$29,(SUMPRODUCT(DCF_Base!$C$19:$L$19/(1+$A30)^DCF_Base!$C$4:$L$4)+MAX(0,MIN(DCF_Base!$L$19*(1+D$29)/($A30-D$29),Assumptions!$B$12*DCF_Base!$L$19))/(1+$A30)^10+Assumptions!$B$9)/Assumptions!$B$10,"n/a") -> 13.967088 | E30: =IF($A30>E$29,(SUMPRODUCT(DCF_Base!$C$19:$L$19/(1+$A30)^DCF_Base!$C$4:$L$4)+MAX(0,MIN(DCF_Base!$L$19*(1+E$29)/($A30-E$29),Assumptions!$B$12*DCF_Base!$L$19))/(1+$A30)^10+Assumptions!$B$9)/Assumptions!$B$10,"n/a") -> 14.635894 | F30: =IF($A30>F$29,(SUMPRODUCT(DCF_Base!$C$19:$L$19/(1+$A30)^DCF_Base!$C$4:$L$4)+MAX(0,MIN(DCF_Base!$L$19*(1+F$29)/($A30-F$29),Assumptions!$B$12*DCF_Base!$L$19))/(1+$A30)^10+Assumptions!$B$9)/Assumptions!$B$10,"n/a") -> 15.426301
A31: 0.1 | B31: =IF($A31>B$29,(SUMPRODUCT(DCF_Base!$C$19:$L$19/(1+$A31)^DCF_Base!$C$4:$L$4)+MAX(0,MIN(DCF_Base!$L$19*(1+B$29)/($A31-B$29),Assumptions!$B$12*DCF_Base!$L$19))/(1+$A31)^10+Assumptions!$B$9)/Assumptions!$B$10,"n/a") -> 12.102968 | C31: =IF($A31>C$29,(SUMPRODUCT(DCF_Base!$C$19:$L$19/(1+$A31)^DCF_Base!$C$4:$L$4)+MAX(0,MIN(DCF_Base!$L$19*(1+C$29)/($A31-C$29),Assumptions!$B$12*DCF_Base!$L$19))/(1+$A31)^10+Assumptions!$B$9)/Assumptions!$B$10,"n/a") -> 12.520227 | D31: =IF($A31>D$29,(SUMPRODUCT(DCF_Base!$C$19:$L$19/(1+$A31)^DCF_Base!$C$4:$L$4)+MAX(0,MIN(DCF_Base!$L$19*(1+D$29)/($A31-D$29),Assumptions!$B$12*DCF_Base!$L$19))/(1+$A31)^10+Assumptions!$B$9)/Assumptions!$B$10,"n/a") -> 12.997096 | E31: =IF($A31>E$29,(SUMPRODUCT(DCF_Base!$C$19:$L$19/(1+$A31)^DCF_Base!$C$4:$L$4)+MAX(0,MIN(DCF_Base!$L$19*(1+E$29)/($A31-E$29),Assumptions!$B$12*DCF_Base!$L$19))/(1+$A31)^10+Assumptions!$B$9)/Assumptions!$B$10,"n/a") -> 13.547328 | F31: =IF($A31>F$29,(SUMPRODUCT(DCF_Base!$C$19:$L$19/(1+$A31)^DCF_Base!$C$4:$L$4)+MAX(0,MIN(DCF_Base!$L$19*(1+F$29)/($A31-F$29),Assumptions!$B$12*DCF_Base!$L$19))/(1+$A31)^10+Assumptions!$B$9)/Assumptions!$B$10,"n/a") -> 14.189266
A32: 0.105 | B32: =IF($A32>B$29,(SUMPRODUCT(DCF_Base!$C$19:$L$19/(1+$A32)^DCF_Base!$C$4:$L$4)+MAX(0,MIN(DCF_Base!$L$19*(1+B$29)/($A32-B$29),Assumptions!$B$12*DCF_Base!$L$19))/(1+$A32)^10+Assumptions!$B$9)/Assumptions!$B$10,"n/a") -> 11.405047 | C32: =IF($A32>C$29,(SUMPRODUCT(DCF_Base!$C$19:$L$19/(1+$A32)^DCF_Base!$C$4:$L$4)+MAX(0,MIN(DCF_Base!$L$19*(1+C$29)/($A32-C$29),Assumptions!$B$12*DCF_Base!$L$19))/(1+$A32)^10+Assumptions!$B$9)/Assumptions!$B$10,"n/a") -> 11.758493 | D32: =IF($A32>D$29,(SUMPRODUCT(DCF_Base!$C$19:$L$19/(1+$A32)^DCF_Base!$C$4:$L$4)+MAX(0,MIN(DCF_Base!$L$19*(1+D$29)/($A32-D$29),Assumptions!$B$12*DCF_Base!$L$19))/(1+$A32)^10+Assumptions!$B$9)/Assumptions!$B$10,"n/a") -> 12.159064 | E32: =IF($A32>E$29,(SUMPRODUCT(DCF_Base!$C$19:$L$19/(1+$A32)^DCF_Base!$C$4:$L$4)+MAX(0,MIN(DCF_Base!$L$19*(1+E$29)/($A32-E$29),Assumptions!$B$12*DCF_Base!$L$19))/(1+$A32)^10+Assumptions!$B$9)/Assumptions!$B$10,"n/a") -> 12.616861 | F32: =IF($A32>F$29,(SUMPRODUCT(DCF_Base!$C$19:$L$19/(1+$A32)^DCF_Base!$C$4:$L$4)+MAX(0,MIN(DCF_Base!$L$19*(1+F$29)/($A32-F$29),Assumptions!$B$12*DCF_Base!$L$19))/(1+$A32)^10+Assumptions!$B$9)/Assumptions!$B$10,"n/a") -> 13.145087
A33: 0.11 | B33: =IF($A33>B$29,(SUMPRODUCT(DCF_Base!$C$19:$L$19/(1+$A33)^DCF_Base!$C$4:$L$4)+MAX(0,MIN(DCF_Base!$L$19*(1+B$29)/($A33-B$29),Assumptions!$B$12*DCF_Base!$L$19))/(1+$A33)^10+Assumptions!$B$9)/Assumptions!$B$10,"n/a") -> 10.78712 | C33: =IF($A33>C$29,(SUMPRODUCT(DCF_Base!$C$19:$L$19/(1+$A33)^DCF_Base!$C$4:$L$4)+MAX(0,MIN(DCF_Base!$L$19*(1+C$29)/($A33-C$29),Assumptions!$B$12*DCF_Base!$L$19))/(1+$A33)^10+Assumptions!$B$9)/Assumptions!$B$10,"n/a") -> 11.088784 | D33: =IF($A33>D$29,(SUMPRODUCT(DCF_Base!$C$19:$L$19/(1+$A33)^DCF_Base!$C$4:$L$4)+MAX(0,MIN(DCF_Base!$L$19*(1+D$29)/($A33-D$29),Assumptions!$B$12*DCF_Base!$L$19))/(1+$A33)^10+Assumptions!$B$9)/Assumptions!$B$10,"n/a") -> 11.428156 | E33: =IF($A33>E$29,(SUMPRODUCT(DCF_Base!$C$19:$L$19/(1+$A33)^DCF_Base!$C$4:$L$4)+MAX(0,MIN(DCF_Base!$L$19*(1+E$29)/($A33-E$29),Assumptions!$B$12*DCF_Base!$L$19))/(1+$A33)^10+Assumptions!$B$9)/Assumptions!$B$10,"n/a") -> 11.812778 | F33: =IF($A33>F$29,(SUMPRODUCT(DCF_Base!$C$19:$L$19/(1+$A33)^DCF_Base!$C$4:$L$4)+MAX(0,MIN(DCF_Base!$L$19*(1+F$29)/($A33-F$29),Assumptions!$B$12*DCF_Base!$L$19))/(1+$A33)^10+Assumptions!$B$9)/Assumptions!$B$10,"n/a") -> 12.252346
A34: 0.115 | B34: =IF($A34>B$29,(SUMPRODUCT(DCF_Base!$C$19:$L$19/(1+$A34)^DCF_Base!$C$4:$L$4)+MAX(0,MIN(DCF_Base!$L$19*(1+B$29)/($A34-B$29),Assumptions!$B$12*DCF_Base!$L$19))/(1+$A34)^10+Assumptions!$B$9)/Assumptions!$B$10,"n/a") -> 10.236466 | C34: =IF($A34>C$29,(SUMPRODUCT(DCF_Base!$C$19:$L$19/(1+$A34)^DCF_Base!$C$4:$L$4)+MAX(0,MIN(DCF_Base!$L$19*(1+C$29)/($A34-C$29),Assumptions!$B$12*DCF_Base!$L$19))/(1+$A34)^10+Assumptions!$B$9)/Assumptions!$B$10,"n/a") -> 10.495676 | D34: =IF($A34>D$29,(SUMPRODUCT(DCF_Base!$C$19:$L$19/(1+$A34)^DCF_Base!$C$4:$L$4)+MAX(0,MIN(DCF_Base!$L$19*(1+D$29)/($A34-D$29),Assumptions!$B$12*DCF_Base!$L$19))/(1+$A34)^10+Assumptions!$B$9)/Assumptions!$B$10,"n/a") -> 10.785381 | E34: =IF($A34>E$29,(SUMPRODUCT(DCF_Base!$C$19:$L$19/(1+$A34)^DCF_Base!$C$4:$L$4)+MAX(0,MIN(DCF_Base!$L$19*(1+E$29)/($A34-E$29),Assumptions!$B$12*DCF_Base!$L$19))/(1+$A34)^10+Assumptions!$B$9)/Assumptions!$B$10,"n/a") -> 11.1113 | F34: =IF($A34>F$29,(SUMPRODUCT(DCF_Base!$C$19:$L$19/(1+$A34)^DCF_Base!$C$4:$L$4)+MAX(0,MIN(DCF_Base!$L$19*(1+F$29)/($A34-F$29),Assumptions!$B$12*DCF_Base!$L$19))/(1+$A34)^10+Assumptions!$B$9)/Assumptions!$B$10,"n/a") -> 11.480675
