Workbook

Sheet DDM Model
A1: FSF.NZ Dividend Discount Model
A2: Gray cells are INPUTS - adjust to see valuation change
A3: NOT a group-FCF DCF: FSF unit holders receive dividends only, not group FCF (co-op prioritises Farmgate Milk Price to farmer-suppliers). See valuation_philosophy in JSON.
A5: KEY INPUTS
A6: Current Unit Price ($) | B6: 7.05
A7: Fonterra Shares Outstanding (M) - economic base | B7: 1607
A8: Cost of Equity (Base) | B8: 0.1375
A9: Terminal Growth Rate (Base) | B9: 0.0175
A10: Terminal Exit P/E Cap (Base) | B10: 8.8
A11: Net Debt Subtracted? | B11: NO - DDM values are post-interest dividend claims
A13: COST OF EQUITY BUILD
A14: NZ Equity Base | B14: 0.09
A15: + Governance / No-Vote Premium | B15: 0.0225
A16: + Fund-Structure / Wind-up Risk Premium | B16: 0.0125
A17: + Commodity Cyclicality Premium | B17: 0.0125
A18: = Cost of Equity (computed) | B18: =B14+B15+B16+B17 -> 0
A20: BASE CASE PROJECTIONS (10-Year)
B21: Y1 | C21: Y2 | D21: Y3 | E21: Y4 | F21: Y5 | G21: Y6 | H21: Y7 | I21: Y8 | J21: Y9 | K21: Y10
A22: EPS ($/share) | B22: 0.57 | C22: 0.62 | D22: 0.7 | E22: 0.728 | F22: 0.753 | G22: 0.776 | H22: 0.795 | I22: 0.813 | J22: 0.829 | K22: 0.844
A23: Payout Ratio | B23: 0.7 | C23: 0.71 | D23: 0.72 | E23: 0.73 | F23: 0.74 | G23: 0.75 | H23: 0.75 | I23: 0.75 | J23: 0.75 | K23: 0.75
A24: Dividend per Unit ($) | B24: =B22*B23 -> 0 | C24: =C22*C23 -> 0 | D24: =D22*D23 -> 0 | E24: =E22*E23 -> 0 | F24: =F22*F23 -> 0 | G24: =G22*G23 -> 0 | H24: =H22*H23 -> 0 | I24: =I22*I23 -> 0 | ... K24: =K22*K23 -> 0
A25: Discount Factor | B25: =1/(1+$B$18)^1 -> 0 | C25: =1/(1+$B$18)^2 -> 0 | D25: =1/(1+$B$18)^3 -> 0 | E25: =1/(1+$B$18)^4 -> 0 | F25: =1/(1+$B$18)^5 -> 0 | G25: =1/(1+$B$18)^6 -> 0 | H25: =1/(1+$B$18)^7 -> 0 | I25: =1/(1+$B$18)^8 -> 0 | J25: =1/(1+$B$18)^9 -> 0 | K25: =1/(1+$B$18)^10 -> 0
A26: PV of Dividend | B26: =B24*B25 -> 0 | C26: =C24*C25 -> 0 | D26: =D24*D25 -> 0 | E26: =E24*E25 -> 0 | F26: =F24*F25 -> 0 | G26: =G24*G25 -> 0 | H26: =H24*H25 -> 0 | I26: =I24*I25 -> 0 | ... K26: =K24*K25 -> 0
A28: VALUATION (BASE CASE)
A29: Sum of PV of Dividends (Y1-Y10) | B29: =SUM(B26:K26) -> 0
A30: Terminal Dividend (Y10 * (1+g)) | B30: =K24*(1+B9) -> 0
A31: Gordon Terminal Value | B31: =B30/(B18-B9) -> 0
A32: Terminal EPS (Y10 * (1+g)) | B32: =K22*(1+B9) -> 0
A33: Exit P/E Cap Terminal Value | B33: =B10*B32 -> 0
A34: Terminal Value Used (MIN of Gordon, Cap) | B34: =MIN(B31,B33) -> 0
A35: PV of Terminal Value | B35: =B34*K25 -> 0
A36: Enterprise / Equity Value (no net debt subtraction) | B36: =B29+B35 -> 0
A37: INTRINSIC VALUE / UNIT | B37: =B36 -> 0
A39: ENTRY PRICE (15% IRR Target)
A40: Hurdle Rate | B40: 0.15
A41: PV of Yrs 1-10 Dividends @ Hurdle | B41: =NPV(B40,B24:K24) -> 0
A42: PV of Terminal Value @ Hurdle (using Gordon TV at CoE) | B42: =B34/(1+B40)^10 -> 0
A43: Entry Price (15% IRR, no net debt adj.) | B43: =B41+B42 -> 0
A45: Upside to Intrinsic Value | B45: =(B37-B6)/B6 -> 0
A46: Upside to Entry Price | B46: =(B6-B43)/B6 -> 0
...

Sheet Scenarios
A1: Scenario Comparison
B3: Bear | C3: Base | D3: Bull
A5: Cost of Equity | B5: 0.1525 | C5: 0.1375 | D5: 0.1275
A6: Terminal Growth | B6: 0.01 | C6: 0.0175 | D6: 0.02
A7: Terminal Exit P/E Cap | B7: 5.9 | C7: 8.8 | D7: 10.43
A9: Intrinsic Value / Unit | B9: 2.2714 | C9: 4.2213 | D9: 6.223
A10: Upside/Downside vs Current | B10: -0.6778 | C10: -0.4012 | D10: -0.1173
A11: Terminal Value % of Total | B11: 0.279 | C11: 0.3505 | D11: 0.3954
A12: Implied Exit Multiple | B12: 4.56 | C12: 6.25 | D12: 7.44
A15: Probability Weighted IV | B15: 4.2342
A16: Weights (Bull/Base/Bear) | B16: 25% / 50% / 25%

Sheet Sensitivity
A1: Sensitivity Analysis
A2: Intrinsic Value by Cost of Equity & Terminal Growth (Base Case)
A4: CoE \ Term G | B4: -0.0025 | C4: 0.0075 | D4: 0.0175 | E4: 0.0275 | F4: 0.0375
A5: 0.1175 | B5: =NPV(0.1175,'DDM Model'!$B$24:$K$24)+(MIN(('DDM Model'!$K$24*(1+-0.0025))/(0.1175--0.0025),'DDM Model'!$B$10*('DDM Model'!$K$22*(1+-0.0025))))/(1+0.1175)^10 -> 0 | C5: =NPV(0.1175,'DDM Model'!$B$24:$K$24)+(MIN(('DDM Model'!$K$24*(1+0.0075))/(0.1175-0.0075),'DDM Model'!$B$10*('DDM Model'!$K$22*(1+0.0075))))/(1+0.1175)^10 -> 0 | D5: =NPV(0.1175,'DDM Model'!$B$24:$K$24)+(MIN(('DDM Model'!$K$24*(1+0.0175))/(0.1175-0.0175),'DDM Model'!$B$10*('DDM Model'!$K$22*(1+0.0175))))/(1+0.1175)^10 -> 0 | E5: =NPV(0.1175,'DDM Model'!$B$24:$K$24)+(MIN(('DDM Model'!$K$24*(1+0.0275))/(0.1175-0.0275),'DDM Model'!$B$10*('DDM Model'!$K$22*(1+0.0275))))/(1+0.1175)^10 -> 0 | F5: =NPV(0.1175,'DDM Model'!$B$24:$K$24)+(MIN(('DDM Model'!$K$24*(1+0.0375))/(0.1175-0.0375),'DDM Model'!$B$10*('DDM Model'!$K$22*(1+0.0375))))/(1+0.1175)^10 -> 0
A6: 0.1275 | B6: =NPV(0.1275,'DDM Model'!$B$24:$K$24)+(MIN(('DDM Model'!$K$24*(1+-0.0025))/(0.1275--0.0025),'DDM Model'!$B$10*('DDM Model'!$K$22*(1+-0.0025))))/(1+0.1275)^10 -> 0 | C6: =NPV(0.1275,'DDM Model'!$B$24:$K$24)+(MIN(('DDM Model'!$K$24*(1+0.0075))/(0.1275-0.0075),'DDM Model'!$B$10*('DDM Model'!$K$22*(1+0.0075))))/(1+0.1275)^10 -> 0 | D6: =NPV(0.1275,'DDM Model'!$B$24:$K$24)+(MIN(('DDM Model'!$K$24*(1+0.0175))/(0.1275-0.0175),'DDM Model'!$B$10*('DDM Model'!$K$22*(1+0.0175))))/(1+0.1275)^10 -> 0 | E6: =NPV(0.1275,'DDM Model'!$B$24:$K$24)+(MIN(('DDM Model'!$K$24*(1+0.0275))/(0.1275-0.0275),'DDM Model'!$B$10*('DDM Model'!$K$22*(1+0.0275))))/(1+0.1275)^10 -> 0 | F6: =NPV(0.1275,'DDM Model'!$B$24:$K$24)+(MIN(('DDM Model'!$K$24*(1+0.0375))/(0.1275-0.0375),'DDM Model'!$B$10*('DDM Model'!$K$22*(1+0.0375))))/(1+0.1275)^10 -> 0
A7: 0.1375 | B7: =NPV(0.1375,'DDM Model'!$B$24:$K$24)+(MIN(('DDM Model'!$K$24*(1+-0.0025))/(0.1375--0.0025),'DDM Model'!$B$10*('DDM Model'!$K$22*(1+-0.0025))))/(1+0.1375)^10 -> 0 | C7: =NPV(0.1375,'DDM Model'!$B$24:$K$24)+(MIN(('DDM Model'!$K$24*(1+0.0075))/(0.1375-0.0075),'DDM Model'!$B$10*('DDM Model'!$K$22*(1+0.0075))))/(1+0.1375)^10 -> 0 | D7: =NPV(0.1375,'DDM Model'!$B$24:$K$24)+(MIN(('DDM Model'!$K$24*(1+0.0175))/(0.1375-0.0175),'DDM Model'!$B$10*('DDM Model'!$K$22*(1+0.0175))))/(1+0.1375)^10 -> 0 | E7: =NPV(0.1375,'DDM Model'!$B$24:$K$24)+(MIN(('DDM Model'!$K$24*(1+0.0275))/(0.1375-0.0275),'DDM Model'!$B$10*('DDM Model'!$K$22*(1+0.0275))))/(1+0.1375)^10 -> 0 | F7: =NPV(0.1375,'DDM Model'!$B$24:$K$24)+(MIN(('DDM Model'!$K$24*(1+0.0375))/(0.1375-0.0375),'DDM Model'!$B$10*('DDM Model'!$K$22*(1+0.0375))))/(1+0.1375)^10 -> 0
A8: 0.1475 | B8: =NPV(0.1475,'DDM Model'!$B$24:$K$24)+(MIN(('DDM Model'!$K$24*(1+-0.0025))/(0.1475--0.0025),'DDM Model'!$B$10*('DDM Model'!$K$22*(1+-0.0025))))/(1+0.1475)^10 -> 0 | C8: =NPV(0.1475,'DDM Model'!$B$24:$K$24)+(MIN(('DDM Model'!$K$24*(1+0.0075))/(0.1475-0.0075),'DDM Model'!$B$10*('DDM Model'!$K$22*(1+0.0075))))/(1+0.1475)^10 -> 0 | D8: =NPV(0.1475,'DDM Model'!$B$24:$K$24)+(MIN(('DDM Model'!$K$24*(1+0.0175))/(0.1475-0.0175),'DDM Model'!$B$10*('DDM Model'!$K$22*(1+0.0175))))/(1+0.1475)^10 -> 0 | E8: =NPV(0.1475,'DDM Model'!$B$24:$K$24)+(MIN(('DDM Model'!$K$24*(1+0.0275))/(0.1475-0.0275),'DDM Model'!$B$10*('DDM Model'!$K$22*(1+0.0275))))/(1+0.1475)^10 -> 0 | F8: =NPV(0.1475,'DDM Model'!$B$24:$K$24)+(MIN(('DDM Model'!$K$24*(1+0.0375))/(0.1475-0.0375),'DDM Model'!$B$10*('DDM Model'!$K$22*(1+0.0375))))/(1+0.1475)^10 -> 0
A9: 0.1575 | B9: =NPV(0.1575,'DDM Model'!$B$24:$K$24)+(MIN(('DDM Model'!$K$24*(1+-0.0025))/(0.1575--0.0025),'DDM Model'!$B$10*('DDM Model'!$K$22*(1+-0.0025))))/(1+0.1575)^10 -> 0 | C9: =NPV(0.1575,'DDM Model'!$B$24:$K$24)+(MIN(('DDM Model'!$K$24*(1+0.0075))/(0.1575-0.0075),'DDM Model'!$B$10*('DDM Model'!$K$22*(1+0.0075))))/(1+0.1575)^10 -> 0 | D9: =NPV(0.1575,'DDM Model'!$B$24:$K$24)+(MIN(('DDM Model'!$K$24*(1+0.0175))/(0.1575-0.0175),'DDM Model'!$B$10*('DDM Model'!$K$22*(1+0.0175))))/(1+0.1575)^10 -> 0 | E9: =NPV(0.1575,'DDM Model'!$B$24:$K$24)+(MIN(('DDM Model'!$K$24*(1+0.0275))/(0.1575-0.0275),'DDM Model'!$B$10*('DDM Model'!$K$22*(1+0.0275))))/(1+0.1575)^10 -> 0 | F9: =NPV(0.1575,'DDM Model'!$B$24:$K$24)+(MIN(('DDM Model'!$K$24*(1+0.0375))/(0.1575-0.0375),'DDM Model'!$B$10*('DDM Model'!$K$22*(1+0.0375))))/(1+0.1575)^10 -> 0

Sheet Historical Multiples
A1: Historical P/E & P/B (FY-End 31 July)
A3: FY | B3: Price | C3: EPS | D3: P/E | E3: BVPS | F3: P/B
A4: 2018 | B4: 5.12 | C4: -0.14 | D4: n/m | E4: 3.94 | F4: 1.3
A5: 2019 | B5: 3.77 | C5: -0.35 | D5: n/m | E5: 3.62 | F5: 1.04
A6: 2020 | B6: 3.82 | C6: 0.43 | D6: 8.88 | E6: 4.16 | F6: 0.92
A7: 2021 | B7: 3.74 | C7: 0.36 | D7: 10.39 | E7: 4.26 | F7: 0.88
A8: 2022 | B8: 3.02 | C8: 0.36 | D8: 8.39 | E8: 4.28 | F8: 0.71
A9: 2023 | B9: 3.53 | C9: 0.95 | D9: 3.72 | E9: 4.95 | F9: 0.71
A10: 2024 | B10: 3.95 | C10: 0.67 | D10: 5.9 | E10: 5.02 | F10: 0.79
A11: 2025 | B11: 6.99 | C11: 0.67 | D11: 10.43
A12: 2026 | B12: 6.9 | D12: n/m
A15: Clean P/E stats (excl. FY18/19 losses, FY23 one-off):
A16: Min | B16: 5.9
A17: Avg | B17: 8.8
A18: Max | B18: 10.43
A20: Current price implied P/E (FY26 guide midpoint): | B20: 12.26
A21: Current price implied P/E (FY25 normalised): | B21: 9.93

Sheet Model_Info
A1: Model Provenance & Notes
A4: Built by | B4: Claude agent (dcf-modeler), Claude Agent SDK
A5: Build date | B5: 2026-08-10
A6: Share price date/source | B6: Yahoo Finance live quote, 2026-08-10, NZD $7.05 (fresh quote, user-verified)
A7: Data vintage | B7: FSF.NZ_Metrics.csv (through H1-2026 interim, 6 months to 31 Jan 2026) and FSF.NZ_Analysis.json (as of 2026-08-10)
A8: Model type | B8: DIVIDEND DISCOUNT MODEL (DDM) -- NOT a group free-cash-flow DCF
A9: Why DDM not FCF DCF | B9: FSF is a unit trust with Economic Rights over Fonterra Co-operative Group shares; no vote, no governance. Fonterra co-op governance is structurally obligated to maximise the Farmgate Milk Price paid TO farmer-suppliers (the dominant cost line, ~$15.3bn FY2025 vs ~$22-26bn group revenue) ahead of group profit/FCF available to Fund unit holders. Group FCF is not a cash flow unit holders have any claim on. The only cash unit holders receive is the declared dividend (and occasional capital returns).
A10: Denominator used | B10: ~1.607 billion Fonterra shares (the economic base) -- NOT the Fund's 107.4 million units on issue. One Fund unit = one Fonterra share's full economic entitlement.
A11: Net debt treatment | B11: NOT subtracted. Dividends are already a post-interest, post-debt-service cash flow; subtracting net debt again would double-count leverage already embedded in dividend capacity.
A12: Capital return treatment | B12: The NZ$2.00/unit tax-free capital return (paid 14-Apr-2026, Mainland sale proceeds) is a COMPLETED PAST event. Current $7.05 price is already ex-this-distribution. Excluded from intrinsic value -- adding it back would double count.
A13: Horizon | B13: 10 years -- extended from a 5yr default because FY2026 EPS is depressed by the Mainland divestment discontinuity and management guides a ~3-year recovery; a 5yr horizon would capitalise an immature, still-recovering earnings base.
A14: Terminal value method | B14: Lower of Gordon growth (on terminal dividend) and an exit P/E cap on terminal EPS, where the cap is drawn from FSF/Fonterra's own 10-year trading history (min/avg/max of clean P/E years, excluding FY2018/19 losses and the FY2023 Soprole-gain-distorted 3.72x reading).
A15: Cost of equity | B15: 13.75% base case = 9.0% NZ equity base + 2.25% governance/no-vote premium + 1.25% Fund-structure/wind-up-risk premium + 1.25% commodity-cyclicality premium. See cost_of_equity_build in the JSON for full rationale.
... A20: Staleness warning | B20: All figures will go stale. Re-verify current_price, EPS guidance, dividend history, and net debt figures against the next filing before reusing this model.
