Workbook

Sheet Model_Info
A1: DOCEBO (DCBO) - DCF MODEL
A3: Lineage | B3: v1.0, built 17-Aug-2026 by Claude (Fable 5, claude.ai chat) at Stephen's request, via the equity-deep-dive -> tech-dcf-workbook skill chain (openpyxl; recalculated in LibreOffice; key outputs hand-checked). Fresh build - no prior DCBO workbook existed.
A5: DATA VINTAGE
A6: FY0 anchors (FY2025) | B6: Revenue $242.7M, adj EBITDA $43.8M (18.0%): Q4/FY25 PR 27-Feb-26 (Business Wire/IR) plus quarterly PRs Q1-Q3 2025 (8.9/9.2/12.4). FY25 SBC ~2.3% is an ESTIMATE: H1-25 actual $2.5M per Q2-26 PR comparatives; H2-25 estimated at similar run-rate. FY25 company FCF $38.4M; NDR 99% (Q4-25 call).
A7: FY1 guidance (FY2026) | B7: Raised 3x during 2026: Feb 27 ($267.5-269.5M rev / $52.5-54.5M aEBITDA) -> May 8 ($271-273M) -> Aug 7 ($274.5-276.5M rev, $255.5-257.5M subscription, $54.5-56.5M aEBITDA ~20.1%). Q3-26 guide: $69.5-69.7M rev, $15.9-16.1M aEBITDA (~23%). Source: Q2-26 PR 7-Aug-26.
A8: Balance sheet / shares | B8: 30-Jun-26 (Q2-26 PR + 6-K interim statements, SEC EDGAR): cash $45.7M, borrowings $88.0M, contingent consideration ~$3.7M -> net debt ~$46M. Book equity ~nil (buyback artifact). Diluted w.a. shares 26.8M (basic 25.5M), down ~14% YoY. Open SIB: up to 3,431,372 sh at $20.40 ($70M), expires 26-Aug-26, funded ~$60M debt/$10M cash - NOT baked into net debt or share count (stock above offer price; treat as sensitivity: full take-up would move net debt to ~-$122M and shares to ~23.4M, roughly value-neutral at $20.40). IFRS-16 choice: treatment (A), leases as debt - lease liabilities (~$6M est) subtracted once in the bridge, no principal deducted from flows, ongoing lease renewal carried inside the 0.5% capex line.
A9: Price | B9: US$23.02, NASDAQ regular close Fri 14-Aug-2026 (CNN Markets); market cap ~$585M.
A10: Owner-margin adjustment | B10: Row-7 margins are OWNER margins: company adj-EBITDA basis LESS recurring restructuring + acquisition earn-out comp (FY26 ~$10M = ~3.6pts: restructuring ~$6.5-7M expense/$6.3M paid H1, earn-out comp ~$3.5M). Tapering: Base clean by 2028; Bull by 2027; Bear permanent ~1.5pts. Company FCF definition ADDS BACK these items - do not benchmark row 19 against reported FCF without re-adding them.
A11: Dive context | B11: Dayforce OEM wind-down 8.4% -> 2.5% of ARR YoY (immaterial by 2027); AWS Skill Builder fully off 31-Dec-25; core ARR growth ex-OEM/FX/acquired 12.5% (Q4-25) -> 13.9% (Q2-26). 365Talents acquired 20-Jan-26 ($54.6M + $5.1M earn-out, ~$9M FY26 revenue); Zive 2-Apr-26 ($7.1M). Intercap ~56.6% post Feb-26 block at $18.77.
A13: METHODOLOGY
A14: Owner-FCF basis | B14: SBC (incl. equity-award taxes) fully expensed, projected explicitly per scenario-year as % of revenue; INTEREST INCOME EXCLUDED from flows (cash pile added separately - including both double-counts); cash tax ramps from the current sheltered rate to a normalized ~21%; D&A and capex as % of revenue; working capital = 20% of the YoY revenue increase (set for this business model); diluted shares held FLAT (SBC expensing substitutes for grant dilution; never do both). TV = Gordon capped at 20x terminal owner FCF. End-of-year discounting. WACC 10.5%. Street-convention values (SBC as non-cash) shown as memos - the house/street pair is the accounting-regime price band.
A15: Scenario drivers | B15: Scenario axes, narratives, weights (15/50/35) and driver-path shapes proposed by Claude in the 17-Aug-2026 deep-dive checkpoint and CONFIRMED by Stephen same session, including: net debt basis (SIB as sensitivity, not baked in) and default weights retained despite the flagged Intercap-overhang argument for a lower bull weight. Year-1 columns anchor to the 7-Aug-26 guidance. Later-year paths are checkpoint judgments - do not silently re-judge on update.
A17: UPDATE INSTRUCTIONS
A18: Each quarter | B18: Refresh price, net cash (+date), diluted shares, buyback pace, and the guidance-year driver columns; reassess blue rows 5/7/9/14 per scenario only where new evidence exists; add/extend the Reconciliation tab; increment the version above.
A19: Conventions | B19: Blue = hardcoded input. Yellow = key levers. Black = formula. Green = cross-sheet link. Prefilled values are working examples of the expected format.

Sheet Actuals_Data
A1: DCBO - Reported Actuals, Guidance & Capital-Structure Status
A2: All values hardcoded (blue). Dollars in millions (USD) unless stated. Source note per row/block.
B4: Q1-25A | C4: Q2-25A | D4: Q3-25A | E4: Q4-25A | F4: Q1-26A | G4: Q2-26A | H4: FY2025A
A5: Total revenue | B5: 57.3 | C5: 60.7 | D5: 61.6 | E5: 63 | F5: 65.6 | G5: 68.65 | H5: 242.7 | I5: Quarterly PRs (Docebo IR / Business Wire): 8-May-25, 8-Aug-25, 7-Nov-25, 27-Feb-26, 8-May-26, 7-Aug-26. FY25 adj EBITDA = sum of quarters. Company FCF ADDS BACK restructuring, earn-out and transaction cash (H1-26 add-backs $9.2M) - not the model's owner basis.
A6: Subscription revenue | B6: 54.2 | C6: 57.1 | D6: 58 | E6: 59.1 | F6: 60.6 | G6: 63.8 | H6: 228.4
A7: Adjusted EBITDA (company basis) | B7: 8.9 | C7: 9.2 | D7: 12.4 | E7: 13.3 | F7: 11 | G7: 11.2 | H7: 43.8
A8: Adjusted EBITDA margin | B8: 0.156 | C8: 0.152 | D8: 0.201 | E8: 0.212 | F8: 0.168 | G8: 0.164 | H8: 0.18
A9: ARR, end of period | B9: 225.1 | C9: 233 | D9: 235.6 | E9: 238.1 | F9: 248.9 | G9: 255.1 | H9: 238.1
A10: Company-defined Free Cash Flow | B10: 9 | C10: 11.4 | D10: 5.7 | E10: 12.3 | F10: 27.6 | G10: 3.1 | H10: 38.4
A12: FY2026 guidance (7-Aug-26) | B12: Revenue $274.5-276.5M; subscription $255.5-257.5M; adj EBITDA $54.5-56.5M (~20.1%) | I12: Q2-26 PR. Raised three times in 2026: Feb 27 -> May 8 -> Aug 7.
A13: Q3-2026 guidance | B13: Revenue $69.5-69.7M; adj EBITDA $15.9-16.1M (~23% margin) | I13: Q2-26 PR - implies a steep H2 margin step-up as Q1 restructuring rolls off.
A14: Cash & equivalents, 30-Jun-26 | B14: 45.7 | I14: Q2-26 PR balance-sheet table.
A15: Borrowings, 30-Jun-26 | B15: 88 | I15: Q2-26 PR; credit facility drawn for 365Talents + buybacks; SIB adds ~$60M debt if taken up.
A16: Contingent consideration (est.) | B16: 3.7 | I16: Q2-26 6-K: current portion $3.3M + estimated non-current; 365Talents earn-out (max $5.1M) + Zive holdback ($0.25M).
A17: Net debt - model basis | B17: -52 | I17: Cash less borrowings less contingent consideration less lease liabilities (~$6M est: current portion $1.9M per Q2-26 WC table + estimated non-current). IFRS-16 treatment (A): leases as debt in bridge, no principal in flows, renewal via capex buffer (0.5% modeled vs ~0.25% actual PP&E). Ties to Assumptions net-cash input.
A18: Book equity, 30-Jun-26 | B18: Approximately nil (assets $242.7M vs liabilities $243.0M) | I18: Buyback artifact, not solvency - flagged for leverage framing.
A19: Weighted-avg shares, Q2-26 | B19: Basic 25.5M / diluted 26.8M - down ~14% YoY | I19: Q2-26 PR income-statement table (vs 29.6M / 30.2M in Q2-25).
A20: Buyback history | B20: Dec-23 SIB $100M at $55.00; Mar-26 SIB $60M at $20.40 (2.94M sh taken up, 3.81M tendered); NCIB ongoing; OPEN SIB up to 3.43M sh ($70M) at $20.40, expires 26-Aug-26 | I20: 6-K filings 22-Nov-23, 11-Mar-26, 21-Jul-26 (SEC EDGAR). Stock ($23.02) above open-SIB price - take-up doubtful.
A21: Ownership | B21: Intercap Equity ~56.6% incl. Feb-26 block of 3.63M sh at $18.77 ($68.1M); chair Jason Chapnik | I21: 6-K 29-Jan-26 SIB release. Majority-controlled; float ~$250M and shrinking.
A22: Largest OEM (Dayforce) wind-down | B22: 8.4% of ARR (Jun-25) -> 2.5% (Jun-26); immaterial by 2027. AWS Skill Builder fully off 31-Dec-25 | I22: Q2-26 PR; Q3-25 call (Fool transcript); guidance assumes OEM ~3-4% of FY26 revenue.
A23: Core ARR growth (ex-OEM/FX/acquired) | B23: 12.5% (Q4-25) -> 13.9% (Q2-26); reported 8.4% -> 9.5% | I23: Q4-25 and Q2-26 PRs; management expects reported/core convergence as churn comps lap (Canaccord conf 11-Aug-26).
A24: Retention & mix | B24: NDR 99% FY2025, improving sequentially; >C$100K cohort ~9pts higher 3-yr avg NDR and 56% of ARR (28% in 2020); 93% of 2025 ARR adds multi-year | I24: Q4-25 call summary (Quartr); Q2-26 investor deck (Investing.com); Oppenheimer conf Aug-26.
A25: ACV / customer counts | B25: ACV $74.8K (+27% YoY); ~3,410 active customers implied; 524 customers >$100K ARR (FY25) vs 171 (FY21) | I25: Q2-26 PR KPI table; Q2-26 investor deck.
A26: Acquisitions 2026 | B26: 365Talents 20-Jan-26: $54.6M cash + up to $5.1M earn-out, ~$9M FY26 revenue. Zive 2-Apr-26: $7.1M | I26: Acquisition PR 20-Jan-26; Q2-26 6-K business-combination note.
A27: SBC run-rate | B27: H1-26 $3.7M (2.8% of revenue; RSU expense ~2x YoY). FY25 estimated ~$5.5-6M (~2.3%) | I27: Q2-26 PR reconciliation + 6-K SBC note. FY25 H2 estimated - replace when 20-F/AIF detail is to hand.

Sheet Assumptions
A1: DCBO - Global Assumptions & Scenario Parameters
A2: Blue = hardcoded input. Yellow = key levers. All $ in millions unless stated.
A4: Global inputs
A5: WACC / discount rate | B5: 0.105
A6: D&A (% of revenue) | B6: 0.008
A7: Capex + capitalized software (% of revenue) | B7: 0.005
A8: Working-capital capture (% of YoY revenue incr.) | B8: 0.2 | H8: Sign/size per business model
A9: Net cash ($mm) | B9: -52 | H9: 30-Jun-26: cash $45.7M less borrowings $88.0M less contingent consideration ~$3.7M less IFRS-16 lease liabilities ~$6.0M est (leases-as-debt treatment; renewal charged via capex buffer). NET DEBT. Open $70M SIB at $20.40 (expires 26-Aug-26) NOT baked in - price above offer, take-up doubtful; see Model_Info
A10: Fully diluted shares (mm) | B10: 26.8 | H10: weighted-avg fully diluted, Q2-26 PR 7-Aug-26 (basic w.a. 25.5M). Held FLAT per house rule
A11: Current share price | B11: 23.02 | H11: NASDAQ regular-session close Fri 14-Aug-26 (CNN Markets)
A12: Terminal value cap (x terminal-year owner FCF) | B12: 20
A14: Scenario parameters | C14: Bear | D14: Base | E14: Bull
A15: Terminal growth rate | C15: 0.015 | D15: 0.03 | E15: 0.035
A16: Probability weight | C16: 0.15 | D16: 0.5 | E16: 0.35 | F16: =SUM(C16:E16) -> 1 | G16: must sum to 100%
A18: Scenario narratives
A19: Bear | B19: AI-era repricing and Workday/Sana suite bundling bite once the OEM comps lap: core growth fades from 13.9% to ~5-6% by 2028 with another large-logo loss; 'restructuring' proves permanent (~1.5pts charged in margin forever), so owner EBITDA stalls ~19-20% (company-adj ~21%); SBC creeps to 4% to retain talent; levered buybacks continue but no longer below value. Terminal growth 1.5%.
A20: Base | B20: Reported growth converges to core as Dayforce/AWS comps lap: ~12.5% in 2027 fading to ~8% by 2030 (government + healthcare verticals offset SMB/AI drag); company-adj EBITDA follows the +2pts/yr path toward ~27% by 2029-30 with restructuring tapering by 2028 (owner margin 16.5% -> 28%); SBC held ~3.5%; owner-FCF margin reaches ~20% terminal. Terminal growth 3.0%.
A21: Bull | B21: 365Talents/Zive attach lifts NDR above 105 and ACV keeps compounding: ARR holds 14-15% through 2029 with $1M+ deals (excluded from guidance) landing; restructurings genuinely end in 2026; company-adj EBITDA reaches ~30% and owner margin matches it by 2030; SBC disciplined at ~3%. Take-out optionality (Cornerstone private at ~5x revenue vs DCBO ~2.3x) is a kicker, not modeled. Terminal growth 3.5%.

Sheet DCF_Bear
A1: DCBO DCF - Bear - Third thesis dies; AI-era repricing
A2: Owner-FCF basis: SBC fully expensed, interest income excluded, share count flat. Blue rows = per-year drivers (edit).
B3: 2025A | C3: 2026E | D3: 2027E | E3: 2028E | F3: 2029E | G3: 2030E | H3: 2031E | I3: 2032E | J3: 2033E | K3: 2034E | L3: 2035E
A4: Year index (for discounting) | B4: 0 | C4: 1 | D4: 2 | E4: 3 | F4: 4 | G4: 5 | H4: 6 | I4: 7 | J4: 8 | K4: 9 | L4: 10
A5: Revenue growth YoY | C5: 0.125 | D5: 0.075 | E5: 0.055 | F5: 0.04 | G5: 0.03 | H5: 0.025 | I5: 0.02 | J5: 0.015 | K5: 0.01 | L5: 0.01
A6: Revenue | B6: 242.7 | C6: =B6*(1+C5) -> 273.0375 | D6: =C6*(1+D5) -> 293.51531 | E6: =D6*(1+E5) -> 309.65865 | F6: =E6*(1+F5) -> 322.045 | G6: =F6*(1+G5) -> 331.70635 | H6: =G6*(1+H5) -> 339.99901 | I6: =H6*(1+I5) -> 346.79899 | J6: =I6*(1+J5) -> 352.00097 | ... L6: =K6*(1+L5) -> 359.07619
A7: Adj EBITDA margin | B7: 0.18 | C7: 0.16 | D7: 0.185 | E7: 0.19 | F7: 0.19 | G7: 0.195 | H7: 0.195 | I7: 0.2 | J7: 0.2 | K7: 0.2 | L7: 0.2
A8: Adjusted EBITDA | C8: =C6*C7 -> 43.686 | D8: =D6*D7 -> 54.300333 | E8: =E6*E7 -> 58.835144 | F8: =F6*F7 -> 61.18855 | G8: =G6*G7 -> 64.682738 | H8: =H6*H7 -> 66.299807 | I8: =I6*I7 -> 69.359798 | J8: =J6*J7 -> 70.400195 | ... L8: =L6*L7 -> 71.815239
A9: SBC (% of revenue) | B9: 0.023 | C9: 0.03 | D9: 0.035 | E9: 0.04 | F9: 0.04 | G9: 0.04 | H9: 0.04 | I9: 0.04 | J9: 0.04 | K9: 0.04 | L9: 0.04
A10: SBC (incl. equity-award taxes) | C10: =-C6*C9 -> -8.191125 | D10: =-D6*D9 -> -10.273036 | E10: =-E6*E9 -> -12.386346 | F10: =-F6*F9 -> -12.8818 | G10: =-G6*G9 -> -13.268254 | H10: =-H6*H9 -> -13.59996 | I10: =-I6*I9 -> -13.87196 | J10: =-J6*J9 -> -14.080039 | ... L10: =-L6*L9 -> -14.363048
A11: EBITDA less SBC ('owner EBITDA') | C11: =C8+C10 -> 35.494875 | D11: =D8+D10 -> 44.027297 | E11: =E8+E10 -> 46.448798 | F11: =F8+F10 -> 48.30675 | G11: =G8+G10 -> 51.414484 | H11: =H8+H10 -> 52.699846 | I11: =I8+I10 -> 55.487838 | J11: =J8+J10 -> 56.320156 | ... L11: =L8+L10 -> 57.452191
A12: D&A | C12: =-C6*Assumptions!$B$6 -> -2.1843 | D12: =-D6*Assumptions!$B$6 -> -2.3481225 | E12: =-E6*Assumptions!$B$6 -> -2.4772692 | F12: =-F6*Assumptions!$B$6 -> -2.57636 | G12: =-G6*Assumptions!$B$6 -> -2.6536508 | H12: =-H6*Assumptions!$B$6 -> -2.7199921 | I12: =-I6*Assumptions!$B$6 -> -2.7743919 | J12: =-J6*Assumptions!$B$6 -> -2.8160078 | ... L12: =-L6*Assumptions!$B$6 -> -2.8726096
A13: EBIT (SBC expensed) | C13: =C11+C12 -> 33.310575 | D13: =D11+D12 -> 41.679174 | E13: =E11+E12 -> 43.971529 | F13: =F11+F12 -> 45.73039 | G13: =G11+G12 -> 48.760834 | H13: =H11+H12 -> 49.979854 | I13: =I11+I12 -> 52.713446 | J13: =J11+J12 -> 53.504148 | ... L13: =L11+L12 -> 54.579582
A14: Cash tax rate (neg = benefit) | C14: 0.1 | D14: 0.14 | E14: 0.18 | F14: 0.21 | G14: 0.21 | H14: 0.21 | I14: 0.21 | J14: 0.21 | K14: 0.21 | L14: 0.21
A15: NOPAT | C15: =C13*(1-C14) -> 29.979518 | D15: =D13*(1-D14) -> 35.84409 | E15: =E13*(1-E14) -> 36.056654 | F15: =F13*(1-F14) -> 36.127008 | G15: =G13*(1-G14) -> 38.521059 | H15: =H13*(1-H14) -> 39.484085 | I15: =I13*(1-I14) -> 41.643623 | J15: =J13*(1-J14) -> 42.268277 | ... L15: =L13*(1-L14) -> 43.117869
A16: add: D&A | C16: =-C12 -> 2.1843 | D16: =-D12 -> 2.3481225 | E16: =-E12 -> 2.4772692 | F16: =-F12 -> 2.57636 | G16: =-G12 -> 2.6536508 | H16: =-H12 -> 2.7199921 | I16: =-I12 -> 2.7743919 | J16: =-J12 -> 2.8160078 | ... L16: =-L12 -> 2.8726096
A17: less: capex + capitalized software | C17: =-C6*Assumptions!$B$7 -> -1.3651875 | D17: =-D6*Assumptions!$B$7 -> -1.4675766 | E17: =-E6*Assumptions!$B$7 -> -1.5482933 | F17: =-F6*Assumptions!$B$7 -> -1.610225 | G17: =-G6*Assumptions!$B$7 -> -1.6585318 | H17: =-H6*Assumptions!$B$7 -> -1.699995 | I17: =-I6*Assumptions!$B$7 -> -1.7339949 | J17: =-J6*Assumptions!$B$7 -> -1.7600049 | ... L17: =-L6*Assumptions!$B$7 -> -1.795381
A18: add: working capital | C18: =Assumptions!$B$8*(C6-B6) -> 6.0675 | D18: =Assumptions!$B$8*(D6-C6) -> 4.0955625 | E18: =Assumptions!$B$8*(E6-D6) -> 3.2286684 | F18: =Assumptions!$B$8*(F6-E6) -> 2.4772692 | G18: =Assumptions!$B$8*(G6-F6) -> 1.93227 | H18: =Assumptions!$B$8*(H6-G6) -> 1.6585318 | I18: =Assumptions!$B$8*(I6-H6) -> 1.359996 | J18: =Assumptions!$B$8*(J6-I6) -> 1.040397 | ... L18: =Assumptions!$B$8*(L6-K6) -> 0.71104197
A19: Unlevered owner FCF | C19: =C15+C16+C17+C18 -> 36.86613 | D19: =D15+D16+D17+D18 -> 40.820198 | E19: =E15+E16+E17+E18 -> 40.214298 | F19: =F15+F16+F17+F18 -> 39.570412 | G19: =G15+G16+G17+G18 -> 41.448448 | H19: =H15+H16+H17+H18 -> 42.162614 | I19: =I15+I16+I17+I18 -> 44.044016 | J19: =J15+J16+J17+J18 -> 44.364677 | ... L19: =L15+L16+L17+L18 -> 44.90614
A20: Discount factor | C20: =1/(1+Assumptions!$B$5)^C4 -> 0.90497738 | D20: =1/(1+Assumptions!$B$5)^D4 -> 0.81898405 | E20: =1/(1+Assumptions!$B$5)^E4 -> 0.74116204 | F20: =1/(1+Assumptions!$B$5)^F4 -> 0.67073487 | G20: =1/(1+Assumptions!$B$5)^G4 -> 0.60699989 | H20: =1/(1+Assumptions!$B$5)^H4 -> 0.54932116 | I20: =1/(1+Assumptions!$B$5)^I4 -> 0.49712323 | J20: =1/(1+Assumptions!$B$5)^J4 -> 0.44988527 | ... L20: =1/(1+Assumptions!$B$5)^L4 -> 0.36844886
A21: PV of FCF | C21: =C19*C20 -> 33.363014 | D21: =D19*D20 -> 33.431091 | E21: =E19*E20 -> 29.805311 | F21: =F19*F20 -> 26.541256 | G21: =G19*G20 -> 25.159203 | H21: =H19*H20 -> 23.160816 | I21: =I19*I20 -> 21.895303 | J21: =J19*J20 -> 19.959015 | ... L21: =L19*L20 -> 16.545616
A23: Memo: FCF before SBC (company-style) | C23: =C19-C10 -> 45.057255 | D23: =D19-D10 -> 51.093234 | E23: =E19-E10 -> 52.600644 | F23: =F19-F10 -> 52.452212 | G23: =G19-G10 -> 54.716702 | H23: =H19-H10 -> 55.762574 | I23: =I19-I10 -> 57.915975 | J23: =J19-J10 -> 58.444716 | ... L23: =L19-L10 -> 59.269188
A24: Memo: implied owner FCF margin | C24: =C19/C6 -> 0.13502222 | D24: =D19/D6 -> 0.13907349 | E24: =E19/E6 -> 0.12986654 | F24: =F19/F6 -> 0.12287231 | G24: =G19/G6 -> 0.12495524 | H24: =H19/H6 -> 0.12400805 | I24: =I19/I6 -> 0.12700157 | J24: =J19/J6 -> 0.12603567 | ... L24: =L19/L6 -> 0.1250602
A25: Valuation
A26: PV of FCF, explicit years | B26: =SUM(C21:L21) -> 247.96251
A27: Terminal growth rate | B27: =Assumptions!$C$15 -> 0.015
A28: Terminal-year owner FCF x (1+g) | B28: =L19*(1+B27) -> 45.579732
A29: Terminal value - Gordon | B29: =B28/(Assumptions!$B$5-B27) -> 506.44147
A30: Terminal value - cap | B30: =Assumptions!$B$12*L19 -> 898.1228
A31: Terminal value used (lower of the two, floored at 0) | B31: =MAX(0,MIN(B29,B30)) -> 506.44147
A32: Implied exit multiple | B32: =B31/L19 -> 11.277778
A33: PV of terminal value | B33: =B31*L20 -> 186.59778
A34: Enterprise value | B34: =B26+B33 -> 434.56029
A35: add: net cash | B35: =Assumptions!$B$9 -> -52
A36: Equity value | B36: =B34+B35 -> 382.56029
A37: Fully diluted shares (mm) | B37: =Assumptions!$B$10 -> 26.8
A38: Value per share | B38: =B36/B37 -> 14.274638
A39: Upside / (downside) vs current price | B39: =B38/Assumptions!$B$11-1 -> -0.37990279
A41: Memo: value if SBC treated as non-cash | B41: =SUMPRODUCT(-C10:L10/(1+Assumptions!$B$5)^C4:L4) -> 73.483712
A42: plus PV of terminal SBC | B42: =(-L10*(1+B27)/(Assumptions!$B$5-B27))*L20 -> 59.682548
...

Sheet DCF_Base
A1: DCBO DCF - Base - Convergence; slower compounder
A2: Owner-FCF basis: SBC fully expensed, interest income excluded, share count flat. Blue rows = per-year drivers (edit).
B3: 2025A | C3: 2026E | D3: 2027E | E3: 2028E | F3: 2029E | G3: 2030E | H3: 2031E | I3: 2032E | J3: 2033E | K3: 2034E | L3: 2035E
A4: Year index (for discounting) | B4: 0 | C4: 1 | D4: 2 | E4: 3 | F4: 4 | G4: 5 | H4: 6 | I4: 7 | J4: 8 | K4: 9 | L4: 10
A5: Revenue growth YoY | C5: 0.135 | D5: 0.125 | E5: 0.11 | F5: 0.095 | G5: 0.08 | H5: 0.075 | I5: 0.07 | J5: 0.065 | K5: 0.06 | L5: 0.055
A6: Revenue | B6: 242.7 | C6: =B6*(1+C5) -> 275.4645 | D6: =C6*(1+D5) -> 309.89756 | E6: =D6*(1+E5) -> 343.98629 | F6: =E6*(1+F5) -> 376.66499 | G6: =F6*(1+G5) -> 406.79819 | H6: =G6*(1+H5) -> 437.30806 | I6: =H6*(1+I5) -> 467.91962 | J6: =I6*(1+J5) -> 498.3344 | ... L6: =K6*(1+L5) -> 557.28735
A7: Adj EBITDA margin | B7: 0.18 | C7: 0.165 | D7: 0.21 | E7: 0.24 | F7: 0.258 | G7: 0.268 | H7: 0.272 | I7: 0.275 | J7: 0.278 | K7: 0.28 | L7: 0.28
A8: Adjusted EBITDA | C8: =C6*C7 -> 45.451642 | D8: =D6*D7 -> 65.078488 | E8: =E6*E7 -> 82.556711 | F8: =F6*F7 -> 97.179568 | G8: =G6*G7 -> 109.02192 | H8: =H6*H7 -> 118.94779 | I8: =I6*I7 -> 128.6779 | J8: =J6*J7 -> 138.53696 | ... L8: =L6*L7 -> 156.04046
A9: SBC (% of revenue) | B9: 0.023 | C9: 0.03 | D9: 0.035 | E9: 0.035 | F9: 0.035 | G9: 0.035 | H9: 0.035 | I9: 0.035 | J9: 0.035 | K9: 0.035 | L9: 0.035
A10: SBC (incl. equity-award taxes) | C10: =-C6*C9 -> -8.263935 | D10: =-D6*D9 -> -10.846415 | E10: =-E6*E9 -> -12.03952 | F10: =-F6*F9 -> -13.183275 | G10: =-G6*G9 -> -14.237937 | H10: =-H6*H9 -> -15.305782 | I10: =-I6*I9 -> -16.377187 | J10: =-J6*J9 -> -17.441704 | ... L10: =-L6*L9 -> -19.505057
A11: EBITDA less SBC ('owner EBITDA') | C11: =C8+C10 -> 37.187708 | D11: =D8+D10 -> 54.232073 | E11: =E8+E10 -> 70.51719 | F11: =F8+F10 -> 83.996293 | G11: =G8+G10 -> 94.783979 | H11: =H8+H10 -> 103.64201 | I11: =I8+I10 -> 112.30071 | J11: =J8+J10 -> 121.09526 | ... L11: =L8+L10 -> 136.5354
A12: D&A | C12: =-C6*Assumptions!$B$6 -> -2.203716 | D12: =-D6*Assumptions!$B$6 -> -2.4791805 | E12: =-E6*Assumptions!$B$6 -> -2.7518904 | F12: =-F6*Assumptions!$B$6 -> -3.0133199 | G12: =-G6*Assumptions!$B$6 -> -3.2543855 | H12: =-H6*Assumptions!$B$6 -> -3.4984644 | I12: =-I6*Assumptions!$B$6 -> -3.743357 | J12: =-J6*Assumptions!$B$6 -> -3.9866752 | ... L12: =-L6*Assumptions!$B$6 -> -4.4582988
A13: EBIT (SBC expensed) | C13: =C11+C12 -> 34.983992 | D13: =D11+D12 -> 51.752893 | E13: =E11+E12 -> 67.7653 | F13: =F11+F12 -> 80.982973 | G13: =G11+G12 -> 91.529593 | H13: =H11+H12 -> 100.14354 | I13: =I11+I12 -> 108.55735 | J13: =J11+J12 -> 117.10858 | ... L13: =L11+L12 -> 132.0771
A14: Cash tax rate (neg = benefit) | C14: 0.1 | D14: 0.14 | E14: 0.18 | F14: 0.21 | G14: 0.21 | H14: 0.21 | I14: 0.21 | J14: 0.21 | K14: 0.21 | L14: 0.21
A15: NOPAT | C15: =C13*(1-C14) -> 31.485592 | D15: =D13*(1-D14) -> 44.507488 | E15: =E13*(1-E14) -> 55.567546 | F15: =F13*(1-F14) -> 63.976549 | G15: =G13*(1-G14) -> 72.308379 | H15: =H13*(1-H14) -> 79.1134 | I15: =I13*(1-I14) -> 85.760308 | J15: =J13*(1-J14) -> 92.51578 | ... L15: =L13*(1-L14) -> 104.34091
A16: add: D&A | C16: =-C12 -> 2.203716 | D16: =-D12 -> 2.4791805 | E16: =-E12 -> 2.7518904 | F16: =-F12 -> 3.0133199 | G16: =-G12 -> 3.2543855 | H16: =-H12 -> 3.4984644 | I16: =-I12 -> 3.743357 | J16: =-J12 -> 3.9866752 | ... L16: =-L12 -> 4.4582988
A17: less: capex + capitalized software | C17: =-C6*Assumptions!$B$7 -> -1.3773225 | D17: =-D6*Assumptions!$B$7 -> -1.5494878 | E17: =-E6*Assumptions!$B$7 -> -1.7199315 | F17: =-F6*Assumptions!$B$7 -> -1.883325 | G17: =-G6*Assumptions!$B$7 -> -2.033991 | H17: =-H6*Assumptions!$B$7 -> -2.1865403 | I17: =-I6*Assumptions!$B$7 -> -2.3395981 | J17: =-J6*Assumptions!$B$7 -> -2.491672 | ... L17: =-L6*Assumptions!$B$7 -> -2.7864368
A18: add: working capital | C18: =Assumptions!$B$8*(C6-B6) -> 6.5529 | D18: =Assumptions!$B$8*(D6-C6) -> 6.8866125 | E18: =Assumptions!$B$8*(E6-D6) -> 6.8177464 | F18: =Assumptions!$B$8*(F6-E6) -> 6.5357396 | G18: =Assumptions!$B$8*(G6-F6) -> 6.0266399 | H18: =Assumptions!$B$8*(H6-G6) -> 6.1019729 | I18: =Assumptions!$B$8*(I6-H6) -> 6.1223128 | J18: =Assumptions!$B$8*(J6-I6) -> 6.0829551 | ... L18: =Assumptions!$B$8*(L6-K6) -> 5.810579
A19: Unlevered owner FCF | C19: =C15+C16+C17+C18 -> 38.864886 | D19: =D15+D16+D17+D18 -> 52.323793 | E19: =E15+E16+E17+E18 -> 63.417251 | F19: =F15+F16+F17+F18 -> 71.642284 | G19: =G15+G16+G17+G18 -> 79.555413 | H19: =H15+H16+H17+H18 -> 86.527297 | I19: =I15+I16+I17+I18 -> 93.28638 | J19: =J15+J16+J17+J18 -> 100.09374 | ... L19: =L15+L16+L17+L18 -> 111.82335
A20: Discount factor | C20: =1/(1+Assumptions!$B$5)^C4 -> 0.90497738 | D20: =1/(1+Assumptions!$B$5)^D4 -> 0.81898405 | E20: =1/(1+Assumptions!$B$5)^E4 -> 0.74116204 | F20: =1/(1+Assumptions!$B$5)^F4 -> 0.67073487 | G20: =1/(1+Assumptions!$B$5)^G4 -> 0.60699989 | H20: =1/(1+Assumptions!$B$5)^H4 -> 0.54932116 | I20: =1/(1+Assumptions!$B$5)^I4 -> 0.49712323 | J20: =1/(1+Assumptions!$B$5)^J4 -> 0.44988527 | ... L20: =1/(1+Assumptions!$B$5)^L4 -> 0.36844886
A21: PV of FCF | C21: =C19*C20 -> 35.171842 | D21: =D19*D20 -> 42.852352 | E21: =E19*E20 -> 47.002459 | F21: =F19*F20 -> 48.052978 | G21: =G19*G20 -> 48.290127 | H21: =H19*H20 -> 47.531276 | I21: =I19*I20 -> 46.374826 | J21: =J19*J20 -> 45.030699 | ... L21: =L19*L20 -> 41.201187
A23: Memo: FCF before SBC (company-style) | C23: =C19-C10 -> 47.128821 | D23: =D19-D10 -> 63.170208 | E23: =E19-E10 -> 75.456772 | F23: =F19-F10 -> 84.825558 | G23: =G19-G10 -> 93.79335 | H23: =H19-H10 -> 101.83308 | I23: =I19-I10 -> 109.66357 | J23: =J19-J10 -> 117.53544 | ... L23: =L19-L10 -> 131.32841
A24: Memo: implied owner FCF margin | C24: =C19/C6 -> 0.14108855 | D24: =D19/D6 -> 0.16884222 | E24: =E19/E6 -> 0.18435982 | F24: =F19/F6 -> 0.1902016 | G24: =G19/G6 -> 0.19556481 | H24: =H19/H6 -> 0.19786349 | I24: =I19/I6 -> 0.19936411 | J24: =J19/J6 -> 0.20085657 | ... L24: =L19/L6 -> 0.20065654
A25: Valuation
A26: PV of FCF, explicit years | B26: =SUM(C21:L21) -> 444.85391
A27: Terminal growth rate | B27: =Assumptions!$D$15 -> 0.03
A28: Terminal-year owner FCF x (1+g) | B28: =L19*(1+B27) -> 115.17805
A29: Terminal value - Gordon | B29: =B28/(Assumptions!$B$5-B27) -> 1535.7074
A30: Terminal value - cap | B30: =Assumptions!$B$12*L19 -> 2236.467
A31: Terminal value used (lower of the two, floored at 0) | B31: =MAX(0,MIN(B29,B30)) -> 1535.7074
A32: Implied exit multiple | B32: =B31/L19 -> 13.733333
A33: PV of terminal value | B33: =B31*L20 -> 565.82963
A34: Enterprise value | B34: =B26+B33 -> 1010.6835
A35: add: net cash | B35: =Assumptions!$B$9 -> -52
A36: Equity value | B36: =B34+B35 -> 958.68354
A37: Fully diluted shares (mm) | B37: =Assumptions!$B$10 -> 26.8
A38: Value per share | B38: =B36/B37 -> 35.771774
A39: Upside / (downside) vs current price | B39: =B38/Assumptions!$B$11-1 -> 0.55394327
A41: Memo: value if SBC treated as non-cash | B41: =SUMPRODUCT(-C10:L10/(1+Assumptions!$B$5)^C4:L4) -> 81.879724
A42: plus PV of terminal SBC | B42: =(-L10*(1+B27)/(Assumptions!$B$5-B27))*L20 -> 98.696196
...

Sheet DCF_Bull
A1: DCBO DCF - Bull - Skills+knowledge loop re-rates the franchise
A2: Owner-FCF basis: SBC fully expensed, interest income excluded, share count flat. Blue rows = per-year drivers (edit).
B3: 2025A | C3: 2026E | D3: 2027E | E3: 2028E | F3: 2029E | G3: 2030E | H3: 2031E | I3: 2032E | J3: 2033E | K3: 2034E | L3: 2035E
A4: Year index (for discounting) | B4: 0 | C4: 1 | D4: 2 | E4: 3 | F4: 4 | G4: 5 | H4: 6 | I4: 7 | J4: 8 | K4: 9 | L4: 10
A5: Revenue growth YoY | C5: 0.14 | D5: 0.145 | E5: 0.145 | F5: 0.14 | G5: 0.13 | H5: 0.12 | I5: 0.11 | J5: 0.1 | K5: 0.09 | L5: 0.08
A6: Revenue | B6: 242.7 | C6: =B6*(1+C5) -> 276.678 | D6: =C6*(1+D5) -> 316.79631 | E6: =D6*(1+E5) -> 362.73177 | F6: =E6*(1+F5) -> 413.51422 | G6: =F6*(1+G5) -> 467.27107 | H6: =G6*(1+H5) -> 523.3436 | I6: =H6*(1+I5) -> 580.9114 | J6: =I6*(1+J5) -> 639.00254 | ... L6: =K6*(1+L5) -> 752.23379
A7: Adj EBITDA margin | B7: 0.18 | C7: 0.17 | D7: 0.23 | E7: 0.26 | F7: 0.28 | G7: 0.295 | H7: 0.3 | I7: 0.3 | J7: 0.3 | K7: 0.3 | L7: 0.3
A8: Adjusted EBITDA | C8: =C6*C7 -> 47.03526 | D8: =D6*D7 -> 72.863151 | E8: =E6*E7 -> 94.310261 | F8: =F6*F7 -> 115.78398 | G8: =G6*G7 -> 137.84497 | H8: =H6*H7 -> 157.00308 | I8: =I6*I7 -> 174.27342 | J8: =J6*J7 -> 191.70076 | ... L8: =L6*L7 -> 225.67014
A9: SBC (% of revenue) | B9: 0.023 | C9: 0.03 | D9: 0.033 | E9: 0.035 | F9: 0.035 | G9: 0.035 | H9: 0.033 | I9: 0.032 | J9: 0.03 | K9: 0.03 | L9: 0.03
A10: SBC (incl. equity-award taxes) | C10: =-C6*C9 -> -8.30034 | D10: =-D6*D9 -> -10.454278 | E10: =-E6*E9 -> -12.695612 | F10: =-F6*F9 -> -14.472998 | G10: =-G6*G9 -> -16.354488 | H10: =-H6*H9 -> -17.270339 | I10: =-I6*I9 -> -18.589165 | J10: =-J6*J9 -> -19.170076 | ... L10: =-L6*L9 -> -22.567014
A11: EBITDA less SBC ('owner EBITDA') | C11: =C8+C10 -> 38.73492 | D11: =D8+D10 -> 62.408873 | E11: =E8+E10 -> 81.614649 | F11: =F8+F10 -> 101.31098 | G11: =G8+G10 -> 121.49048 | H11: =H8+H10 -> 139.73274 | I11: =I8+I10 -> 155.68425 | J11: =J8+J10 -> 172.53069 | ... L11: =L8+L10 -> 203.10312
A12: D&A | C12: =-C6*Assumptions!$B$6 -> -2.213424 | D12: =-D6*Assumptions!$B$6 -> -2.5343705 | E12: =-E6*Assumptions!$B$6 -> -2.9018542 | F12: =-F6*Assumptions!$B$6 -> -3.3081138 | G12: =-G6*Assumptions!$B$6 -> -3.7381686 | H12: =-H6*Assumptions!$B$6 -> -4.1867488 | I12: =-I6*Assumptions!$B$6 -> -4.6472912 | J12: =-J6*Assumptions!$B$6 -> -5.1120203 | ... L12: =-L6*Assumptions!$B$6 -> -6.0178703
A13: EBIT (SBC expensed) | C13: =C11+C12 -> 36.521496 | D13: =D11+D12 -> 59.874503 | E13: =E11+E12 -> 78.712795 | F13: =F11+F12 -> 98.002871 | G13: =G11+G12 -> 117.75231 | H13: =H11+H12 -> 135.54599 | I13: =I11+I12 -> 151.03696 | J13: =J11+J12 -> 167.41866 | ... L13: =L11+L12 -> 197.08525
A14: Cash tax rate (neg = benefit) | C14: 0.1 | D14: 0.14 | E14: 0.18 | F14: 0.21 | G14: 0.21 | H14: 0.21 | I14: 0.21 | J14: 0.21 | K14: 0.21 | L14: 0.21
A15: NOPAT | C15: =C13*(1-C14) -> 32.869346 | D15: =D13*(1-D14) -> 51.492072 | E15: =E13*(1-E14) -> 64.544492 | F15: =F13*(1-F14) -> 77.422268 | G15: =G13*(1-G14) -> 93.024325 | H15: =H13*(1-H14) -> 107.08133 | I15: =I13*(1-I14) -> 119.3192 | J15: =J13*(1-J14) -> 132.26075 | ... L15: =L13*(1-L14) -> 155.69735
A16: add: D&A | C16: =-C12 -> 2.213424 | D16: =-D12 -> 2.5343705 | E16: =-E12 -> 2.9018542 | F16: =-F12 -> 3.3081138 | G16: =-G12 -> 3.7381686 | H16: =-H12 -> 4.1867488 | I16: =-I12 -> 4.6472912 | J16: =-J12 -> 5.1120203 | ... L16: =-L12 -> 6.0178703
A17: less: capex + capitalized software | C17: =-C6*Assumptions!$B$7 -> -1.38339 | D17: =-D6*Assumptions!$B$7 -> -1.5839816 | E17: =-E6*Assumptions!$B$7 -> -1.8136589 | F17: =-F6*Assumptions!$B$7 -> -2.0675711 | G17: =-G6*Assumptions!$B$7 -> -2.3363554 | H17: =-H6*Assumptions!$B$7 -> -2.616718 | I17: =-I6*Assumptions!$B$7 -> -2.904557 | J17: =-J6*Assumptions!$B$7 -> -3.1950127 | ... L17: =-L6*Assumptions!$B$7 -> -3.7611689
A18: add: working capital | C18: =Assumptions!$B$8*(C6-B6) -> 6.7956 | D18: =Assumptions!$B$8*(D6-C6) -> 8.023662 | E18: =Assumptions!$B$8*(E6-D6) -> 9.187093 | F18: =Assumptions!$B$8*(F6-E6) -> 10.15649 | G18: =Assumptions!$B$8*(G6-F6) -> 10.75137 | H18: =Assumptions!$B$8*(H6-G6) -> 11.214506 | I18: =Assumptions!$B$8*(I6-H6) -> 11.513559 | J18: =Assumptions!$B$8*(J6-I6) -> 11.618228 | ... L18: =Assumptions!$B$8*(L6-K6) -> 11.144204
A19: Unlevered owner FCF | C19: =C15+C16+C17+C18 -> 40.49498 | D19: =D15+D16+D17+D18 -> 60.466123 | E19: =E15+E16+E17+E18 -> 74.81978 | F19: =F15+F16+F17+F18 -> 88.8193 | G19: =G15+G16+G17+G18 -> 105.17751 | H19: =H15+H16+H17+H18 -> 119.86587 | I19: =I15+I16+I17+I18 -> 132.57549 | J19: =J15+J16+J17+J18 -> 145.79598 | ... L19: =L15+L16+L17+L18 -> 169.09825
A20: Discount factor | C20: =1/(1+Assumptions!$B$5)^C4 -> 0.90497738 | D20: =1/(1+Assumptions!$B$5)^D4 -> 0.81898405 | E20: =1/(1+Assumptions!$B$5)^E4 -> 0.74116204 | F20: =1/(1+Assumptions!$B$5)^F4 -> 0.67073487 | G20: =1/(1+Assumptions!$B$5)^G4 -> 0.60699989 | H20: =1/(1+Assumptions!$B$5)^H4 -> 0.54932116 | I20: =1/(1+Assumptions!$B$5)^I4 -> 0.49712323 | J20: =1/(1+Assumptions!$B$5)^J4 -> 0.44988527 | ... L20: =1/(1+Assumptions!$B$5)^L4 -> 0.36844886
A21: PV of FCF | C21: =C19*C20 -> 36.647041 | D21: =D19*D20 -> 49.52079 | E21: =E19*E20 -> 55.453581 | F21: =F19*F20 -> 59.574202 | G21: =G19*G20 -> 63.842736 | H21: =H19*H20 -> 65.84486 | I21: =I19*I20 -> 65.906357 | J21: =J19*J20 -> 65.591464 | ... L21: =L19*L20 -> 62.30406
A23: Memo: FCF before SBC (company-style) | C23: =C19-C10 -> 48.79532 | D23: =D19-D10 -> 70.920401 | E23: =E19-E10 -> 87.515392 | F23: =F19-F10 -> 103.2923 | G23: =G19-G10 -> 121.532 | H23: =H19-H10 -> 137.13621 | I23: =I19-I10 -> 151.16466 | J23: =J19-J10 -> 164.96606 | ... L23: =L19-L10 -> 191.66527
A24: Memo: implied owner FCF margin | C24: =C19/C6 -> 0.1463614 | D24: =D19/D6 -> 0.19086751 | E24: =E19/E6 -> 0.20626751 | F24: =F19/F6 -> 0.2147914 | G24: =G19/G6 -> 0.22508885 | H24: =H19/H6 -> 0.22903857 | I24: =I19/I6 -> 0.22821982 | J24: =J19/J6 -> 0.22816182 | ... L24: =L19/L6 -> 0.22479481
A25: Valuation
A26: PV of FCF, explicit years | B26: =SUM(C21:L21) -> 588.91315
A27: Terminal growth rate | B27: =Assumptions!$E$15 -> 0.035
A28: Terminal-year owner FCF x (1+g) | B28: =L19*(1+B27) -> 175.01669
A29: Terminal value - Gordon | B29: =B28/(Assumptions!$B$5-B27) -> 2500.2385
A30: Terminal value - cap | B30: =Assumptions!$B$12*L19 -> 3381.9651
A31: Terminal value used (lower of the two, floored at 0) | B31: =MAX(0,MIN(B29,B30)) -> 2500.2385
A32: Implied exit multiple | B32: =B31/L19 -> 14.785714
A33: PV of terminal value | B33: =B31*L20 -> 921.21002
A34: Enterprise value | B34: =B26+B33 -> 1510.1232
A35: add: net cash | B35: =Assumptions!$B$9 -> -52
A36: Equity value | B36: =B34+B35 -> 1458.1232
A37: Fully diluted shares (mm) | B37: =Assumptions!$B$10 -> 26.8
A38: Value per share | B38: =B36/B37 -> 54.407581
A39: Upside / (downside) vs current price | B39: =B38/Assumptions!$B$11-1 -> 1.3634918
A41: Memo: value if SBC treated as non-cash | B41: =SUMPRODUCT(-C10:L10/(1+Assumptions!$B$5)^C4:L4) -> 89.292185
A42: plus PV of terminal SBC | B42: =(-L10*(1+B27)/(Assumptions!$B$5-B27))*L20 -> 122.94012
...

Sheet Valuation
A1: DCBO - Valuation Summary & Sensitivity
A2: Owner-FCF basis (SBC expensed) unless marked street. Green = links.
B4: Bear | C4: Base | D4: Bull
A5: Value per share | B5: =DCF_Bear!$B$38 -> 14.274638 | C5: =DCF_Base!$B$38 -> 35.771774 | D5: =DCF_Bull!$B$38 -> 54.407581
A6: Upside / (downside) vs price | B6: =B5/Assumptions!$B$11-1 -> -0.37990279 | C6: =C5/Assumptions!$B$11-1 -> 0.55394327 | D6: =D5/Assumptions!$B$11-1 -> 1.3634918
A7: Probability | B7: =Assumptions!$C$16 -> 0.15 | C7: =Assumptions!$D$16 -> 0.5 | D7: =Assumptions!$E$16 -> 0.35
A8: Value per share, SBC as non-cash (street) | B8: =DCF_Bear!$B$43 -> 19.243528 | C8: =DCF_Base!$B$43 -> 42.509681 | D8: =DCF_Bull!$B$43 -> 62.326697
A10: Probability-weighted value per share | B10: =SUMPRODUCT(B5:D5,B7:D7) -> 39.069736
A11: Current price | B11: =Assumptions!$B$11 -> 23.02
A12: Margin of safety vs weighted value | B12: =1-B11/B10 -> 0.41079715
A13: Weighted value, SBC as non-cash (street) | B13: =SUMPRODUCT(B8:D8,B7:D7) -> 45.955714
A14: Band position (0%=house, 100%=street) | B14: =IF(ABS(B13-B10)<0.005,"n/a - SBC=0 so house=street",(Assumptions!$B$11-B10)/(B13-B10)) -> -2.3307853
A17: Base case - value per share at different required returns
A18: Required return | B18: Value / share
A19: 0.09 | B19: =(SUMPRODUCT(DCF_Base!$C$19:$L$19/(1+$A19)^DCF_Base!$C$4:$L$4)+MAX(0,MIN(DCF_Base!$L$19*(1+Assumptions!$D$15)/($A19-Assumptions!$D$15),Assumptions!$B$12*DCF_Base!$L$19))/(1+$A19)^10+Assumptions!$B$9)/Assumptions!$B$10 -> 46.235513
A20: 0.1 | B20: =(SUMPRODUCT(DCF_Base!$C$19:$L$19/(1+$A20)^DCF_Base!$C$4:$L$4)+MAX(0,MIN(DCF_Base!$L$19*(1+Assumptions!$D$15)/($A20-Assumptions!$D$15),Assumptions!$B$12*DCF_Base!$L$19))/(1+$A20)^10+Assumptions!$B$9)/Assumptions!$B$10 -> 38.753606
A21: 0.105 | B21: =(SUMPRODUCT(DCF_Base!$C$19:$L$19/(1+$A21)^DCF_Base!$C$4:$L$4)+MAX(0,MIN(DCF_Base!$L$19*(1+Assumptions!$D$15)/($A21-Assumptions!$D$15),Assumptions!$B$12*DCF_Base!$L$19))/(1+$A21)^10+Assumptions!$B$9)/Assumptions!$B$10 -> 35.771774
A22: 0.11 | B22: =(SUMPRODUCT(DCF_Base!$C$19:$L$19/(1+$A22)^DCF_Base!$C$4:$L$4)+MAX(0,MIN(DCF_Base!$L$19*(1+Assumptions!$D$15)/($A22-Assumptions!$D$15),Assumptions!$B$12*DCF_Base!$L$19))/(1+$A22)^10+Assumptions!$B$9)/Assumptions!$B$10 -> 33.169187
A23: 0.12 | B23: =(SUMPRODUCT(DCF_Base!$C$19:$L$19/(1+$A23)^DCF_Base!$C$4:$L$4)+MAX(0,MIN(DCF_Base!$L$19*(1+Assumptions!$D$15)/($A23-Assumptions!$D$15),Assumptions!$B$12*DCF_Base!$L$19))/(1+$A23)^10+Assumptions!$B$9)/Assumptions!$B$10 -> 28.848123
A24: 0.15 | B24: =(SUMPRODUCT(DCF_Base!$C$19:$L$19/(1+$A24)^DCF_Base!$C$4:$L$4)+MAX(0,MIN(DCF_Base!$L$19*(1+Assumptions!$D$15)/($A24-Assumptions!$D$15),Assumptions!$B$12*DCF_Base!$L$19))/(1+$A24)^10+Assumptions!$B$9)/Assumptions!$B$10 -> 20.295848
A25: 15%-hurdle entry per scenario + weighted | B25: =(SUMPRODUCT(DCF_Bear!$C$19:$L$19/(1+0.15)^DCF_Bear!$C$4:$L$4)+MAX(0,MIN(DCF_Bear!$L$19*(1+Assumptions!$C$15)/(0.15-Assumptions!$C$15),Assumptions!$B$12*DCF_Bear!$L$19))/(1+0.15)^10+Assumptions!$B$9)/Assumptions!$B$10 -> 8.846294 | C25: =(SUMPRODUCT(DCF_Base!$C$19:$L$19/(1+0.15)^DCF_Base!$C$4:$L$4)+MAX(0,MIN(DCF_Base!$L$19*(1+Assumptions!$D$15)/(0.15-Assumptions!$D$15),Assumptions!$B$12*DCF_Base!$L$19))/(1+0.15)^10+Assumptions!$B$9)/Assumptions!$B$10 -> 20.295848 | D25: =(SUMPRODUCT(DCF_Bull!$C$19:$L$19/(1+0.15)^DCF_Bull!$C$4:$L$4)+MAX(0,MIN(DCF_Bull!$L$19*(1+Assumptions!$E$15)/(0.15-Assumptions!$E$15),Assumptions!$B$12*DCF_Bull!$L$19))/(1+0.15)^10+Assumptions!$B$9)/Assumptions!$B$10 -> 29.602808 | E25: =SUMPRODUCT(B25:D25,$B$7:$D$7) -> 21.835851 | G25: model buy-below price at a 15% hurdle
A26: same, street basis | B26: =B25+(SUMPRODUCT(-DCF_Bear!$C$10:$L$10/(1+0.15)^DCF_Bear!$C$4:$L$4)+(-DCF_Bear!$L$10*(1+Assumptions!$C$15)/(0.15-Assumptions!$C$15))/(1+0.15)^10)/Assumptions!$B$10 -> 12.09182 | C26: =C25+(SUMPRODUCT(-DCF_Base!$C$10:$L$10/(1+0.15)^DCF_Base!$C$4:$L$4)+(-DCF_Base!$L$10*(1+Assumptions!$D$15)/(0.15-Assumptions!$D$15))/(1+0.15)^10)/Assumptions!$B$10 -> 24.320317 | D26: =D25+(SUMPRODUCT(-DCF_Bull!$C$10:$L$10/(1+0.15)^DCF_Bull!$C$4:$L$4)+(-DCF_Bull!$L$10*(1+Assumptions!$E$15)/(0.15-Assumptions!$E$15))/(1+0.15)^10)/Assumptions!$B$10 -> 34.166978 | E26: =SUMPRODUCT(B26:D26,$B$7:$D$7) -> 25.932374
A28: Base case - value per share: WACC x terminal growth
A29: WACC \ g | B29: 0.02 | C29: 0.025 | D29: 0.03 | E29: 0.035 | F29: 0.04
A30: 0.095 | B30: =IF($A30>B$29,(SUMPRODUCT(DCF_Base!$C$19:$L$19/(1+$A30)^DCF_Base!$C$4:$L$4)+MAX(0,MIN(DCF_Base!$L$19*(1+B$29)/($A30-B$29),Assumptions!$B$12*DCF_Base!$L$19))/(1+$A30)^10+Assumptions!$B$9)/Assumptions!$B$10,"n/a") -> 38.420711 | C30: =IF($A30>C$29,(SUMPRODUCT(DCF_Base!$C$19:$L$19/(1+$A30)^DCF_Base!$C$4:$L$4)+MAX(0,MIN(DCF_Base!$L$19*(1+C$29)/($A30-C$29),Assumptions!$B$12*DCF_Base!$L$19))/(1+$A30)^10+Assumptions!$B$9)/Assumptions!$B$10,"n/a") -> 40.176536 | D30: =IF($A30>D$29,(SUMPRODUCT(DCF_Base!$C$19:$L$19/(1+$A30)^DCF_Base!$C$4:$L$4)+MAX(0,MIN(DCF_Base!$L$19*(1+D$29)/($A30-D$29),Assumptions!$B$12*DCF_Base!$L$19))/(1+$A30)^10+Assumptions!$B$9)/Assumptions!$B$10,"n/a") -> 42.202489 | E30: =IF($A30>E$29,(SUMPRODUCT(DCF_Base!$C$19:$L$19/(1+$A30)^DCF_Base!$C$4:$L$4)+MAX(0,MIN(DCF_Base!$L$19*(1+E$29)/($A30-E$29),Assumptions!$B$12*DCF_Base!$L$19))/(1+$A30)^10+Assumptions!$B$9)/Assumptions!$B$10,"n/a") -> 44.5661 | F30: =IF($A30>F$29,(SUMPRODUCT(DCF_Base!$C$19:$L$19/(1+$A30)^DCF_Base!$C$4:$L$4)+MAX(0,MIN(DCF_Base!$L$19*(1+F$29)/($A30-F$29),Assumptions!$B$12*DCF_Base!$L$19))/(1+$A30)^10+Assumptions!$B$9)/Assumptions!$B$10,"n/a") -> 47.359459
A31: 0.1 | B31: =IF($A31>B$29,(SUMPRODUCT(DCF_Base!$C$19:$L$19/(1+$A31)^DCF_Base!$C$4:$L$4)+MAX(0,MIN(DCF_Base!$L$19*(1+B$29)/($A31-B$29),Assumptions!$B$12*DCF_Base!$L$19))/(1+$A31)^10+Assumptions!$B$9)/Assumptions!$B$10,"n/a") -> 35.59369 | C31: =IF($A31>C$29,(SUMPRODUCT(DCF_Base!$C$19:$L$19/(1+$A31)^DCF_Base!$C$4:$L$4)+MAX(0,MIN(DCF_Base!$L$19*(1+C$29)/($A31-C$29),Assumptions!$B$12*DCF_Base!$L$19))/(1+$A31)^10+Assumptions!$B$9)/Assumptions!$B$10,"n/a") -> 37.068317 | D31: =IF($A31>D$29,(SUMPRODUCT(DCF_Base!$C$19:$L$19/(1+$A31)^DCF_Base!$C$4:$L$4)+MAX(0,MIN(DCF_Base!$L$19*(1+D$29)/($A31-D$29),Assumptions!$B$12*DCF_Base!$L$19))/(1+$A31)^10+Assumptions!$B$9)/Assumptions!$B$10,"n/a") -> 38.753606 | E31: =IF($A31>E$29,(SUMPRODUCT(DCF_Base!$C$19:$L$19/(1+$A31)^DCF_Base!$C$4:$L$4)+MAX(0,MIN(DCF_Base!$L$19*(1+E$29)/($A31-E$29),Assumptions!$B$12*DCF_Base!$L$19))/(1+$A31)^10+Assumptions!$B$9)/Assumptions!$B$10,"n/a") -> 40.698169 | F31: =IF($A31>F$29,(SUMPRODUCT(DCF_Base!$C$19:$L$19/(1+$A31)^DCF_Base!$C$4:$L$4)+MAX(0,MIN(DCF_Base!$L$19*(1+F$29)/($A31-F$29),Assumptions!$B$12*DCF_Base!$L$19))/(1+$A31)^10+Assumptions!$B$9)/Assumptions!$B$10,"n/a") -> 42.966827
A32: 0.105 | B32: =IF($A32>B$29,(SUMPRODUCT(DCF_Base!$C$19:$L$19/(1+$A32)^DCF_Base!$C$4:$L$4)+MAX(0,MIN(DCF_Base!$L$19*(1+B$29)/($A32-B$29),Assumptions!$B$12*DCF_Base!$L$19))/(1+$A32)^10+Assumptions!$B$9)/Assumptions!$B$10,"n/a") -> 33.107021 | C32: =IF($A32>C$29,(SUMPRODUCT(DCF_Base!$C$19:$L$19/(1+$A32)^DCF_Base!$C$4:$L$4)+MAX(0,MIN(DCF_Base!$L$19*(1+C$29)/($A32-C$29),Assumptions!$B$12*DCF_Base!$L$19))/(1+$A32)^10+Assumptions!$B$9)/Assumptions!$B$10,"n/a") -> 34.356124 | D32: =IF($A32>D$29,(SUMPRODUCT(DCF_Base!$C$19:$L$19/(1+$A32)^DCF_Base!$C$4:$L$4)+MAX(0,MIN(DCF_Base!$L$19*(1+D$29)/($A32-D$29),Assumptions!$B$12*DCF_Base!$L$19))/(1+$A32)^10+Assumptions!$B$9)/Assumptions!$B$10,"n/a") -> 35.771774 | E32: =IF($A32>E$29,(SUMPRODUCT(DCF_Base!$C$19:$L$19/(1+$A32)^DCF_Base!$C$4:$L$4)+MAX(0,MIN(DCF_Base!$L$19*(1+E$29)/($A32-E$29),Assumptions!$B$12*DCF_Base!$L$19))/(1+$A32)^10+Assumptions!$B$9)/Assumptions!$B$10,"n/a") -> 37.38966 | F32: =IF($A32>F$29,(SUMPRODUCT(DCF_Base!$C$19:$L$19/(1+$A32)^DCF_Base!$C$4:$L$4)+MAX(0,MIN(DCF_Base!$L$19*(1+F$29)/($A32-F$29),Assumptions!$B$12*DCF_Base!$L$19))/(1+$A32)^10+Assumptions!$B$9)/Assumptions!$B$10,"n/a") -> 39.256451
A33: 0.11 | B33: =IF($A33>B$29,(SUMPRODUCT(DCF_Base!$C$19:$L$19/(1+$A33)^DCF_Base!$C$4:$L$4)+MAX(0,MIN(DCF_Base!$L$19*(1+B$29)/($A33-B$29),Assumptions!$B$12*DCF_Base!$L$19))/(1+$A33)^10+Assumptions!$B$9)/Assumptions!$B$10,"n/a") -> 30.903716 | C33: =IF($A33>C$29,(SUMPRODUCT(DCF_Base!$C$19:$L$19/(1+$A33)^DCF_Base!$C$4:$L$4)+MAX(0,MIN(DCF_Base!$L$19*(1+C$29)/($A33-C$29),Assumptions!$B$12*DCF_Base!$L$19))/(1+$A33)^10+Assumptions!$B$9)/Assumptions!$B$10,"n/a") -> 31.96982 | D33: =IF($A33>D$29,(SUMPRODUCT(DCF_Base!$C$19:$L$19/(1+$A33)^DCF_Base!$C$4:$L$4)+MAX(0,MIN(DCF_Base!$L$19*(1+D$29)/($A33-D$29),Assumptions!$B$12*DCF_Base!$L$19))/(1+$A33)^10+Assumptions!$B$9)/Assumptions!$B$10,"n/a") -> 33.169187 | E33: =IF($A33>E$29,(SUMPRODUCT(DCF_Base!$C$19:$L$19/(1+$A33)^DCF_Base!$C$4:$L$4)+MAX(0,MIN(DCF_Base!$L$19*(1+E$29)/($A33-E$29),Assumptions!$B$12*DCF_Base!$L$19))/(1+$A33)^10+Assumptions!$B$9)/Assumptions!$B$10,"n/a") -> 34.528469 | F33: =IF($A33>F$29,(SUMPRODUCT(DCF_Base!$C$19:$L$19/(1+$A33)^DCF_Base!$C$4:$L$4)+MAX(0,MIN(DCF_Base!$L$19*(1+F$29)/($A33-F$29),Assumptions!$B$12*DCF_Base!$L$19))/(1+$A33)^10+Assumptions!$B$9)/Assumptions!$B$10,"n/a") -> 36.081934
A34: 0.115 | B34: =IF($A34>B$29,(SUMPRODUCT(DCF_Base!$C$19:$L$19/(1+$A34)^DCF_Base!$C$4:$L$4)+MAX(0,MIN(DCF_Base!$L$19*(1+B$29)/($A34-B$29),Assumptions!$B$12*DCF_Base!$L$19))/(1+$A34)^10+Assumptions!$B$9)/Assumptions!$B$10,"n/a") -> 28.938797 | C34: =IF($A34>C$29,(SUMPRODUCT(DCF_Base!$C$19:$L$19/(1+$A34)^DCF_Base!$C$4:$L$4)+MAX(0,MIN(DCF_Base!$L$19*(1+C$29)/($A34-C$29),Assumptions!$B$12*DCF_Base!$L$19))/(1+$A34)^10+Assumptions!$B$9)/Assumptions!$B$10,"n/a") -> 29.854865 | D34: =IF($A34>D$29,(SUMPRODUCT(DCF_Base!$C$19:$L$19/(1+$A34)^DCF_Base!$C$4:$L$4)+MAX(0,MIN(DCF_Base!$L$19*(1+D$29)/($A34-D$29),Assumptions!$B$12*DCF_Base!$L$19))/(1+$A34)^10+Assumptions!$B$9)/Assumptions!$B$10,"n/a") -> 30.878706 | E34: =IF($A34>E$29,(SUMPRODUCT(DCF_Base!$C$19:$L$19/(1+$A34)^DCF_Base!$C$4:$L$4)+MAX(0,MIN(DCF_Base!$L$19*(1+E$29)/($A34-E$29),Assumptions!$B$12*DCF_Base!$L$19))/(1+$A34)^10+Assumptions!$B$9)/Assumptions!$B$10,"n/a") -> 32.030527 | F34: =IF($A34>F$29,(SUMPRODUCT(DCF_Base!$C$19:$L$19/(1+$A34)^DCF_Base!$C$4:$L$4)+MAX(0,MIN(DCF_Base!$L$19*(1+F$29)/($A34-F$29),Assumptions!$B$12*DCF_Base!$L$19))/(1+$A34)^10+Assumptions!$B$9)/Assumptions!$B$10,"n/a") -> 33.335924
