Workbook

Sheet Model_Info
A1: TRU.NZ - TruScreen Group Limited - valuation workbook
A2: Version | B2: v1 (fresh build, 2026-09-13). Supersedes nothing - first valuation of this ticker.
A3: Built by | B3: dcf-analyst agent (Claude Fable 5.1), 2026-09-13, unattended batch run at the user's request.
A4: Model | B4: Probability-weighted scenario model on a forward (FY2029E) EV/Sales exit with explicit per-scenario dilution, discounted 2.5 years at a 25% NZD cost of equity. NOT an owner-FCF DCF: owner FCF is negative in all ten years on record, so there is no positive flow to capitalise. NOT a book model: intangibles are fully impaired. NOT a receivership waterfall: going concern with growing revenue. Wind-down is a 50% branch inside the bear scenario, so survival risk is charged once (in the weights), not again in the discount rate.
A5: Price | B5: NZ$0.015, last trade 2026-09-11T02:31:36Z (NZX regular session; thin liquidity, 52w 0.014-0.025). Yahoo Finance TRU.NZ.
A6: Share count | B6: 1,047,718,877 per the 4-Aug-2026 Capital Change Notice (NZX ann. 477288), confirmed by the 24-Aug-2026 ASM deck. Post May-Aug-2026 placement/rights/shortfall.
A7: Balance sheet | B7: Audited 31-Mar-2026 (FY2026 Annual Report). Cash NZ$1.463m, lease liabilities NZ$0.201m, no borrowings. Cash rolled forward by ESTIMATE to ~mid-Sep-2026 (see Assumptions).
A8: Raise | B8: May-Aug 2026: placement 128.74m sh @ NZ$0.014, rights 149.46m sh @ NZ$0.013, oversubscriptions 22.19m sh @ NZ$0.013 = NZ$4.034m gross (NZX ann. 473006 / 475060 / 477288).
A9: Options | B9: TRUOD 204.69m @0.022 exp 17-Jul-2027; TRUOE 89.05m @0.014 exp 4-Aug-2028; TRUOF 22.5m @0.019 exp 4-Aug-2028. Exercise-or-lapse flags per scenario.
A10: Guidance | B10: No FY2027 quantitative guidance. FY2026 guidance cut 26-Feb-2026 (NZ$2.8m -> NZ$2.4m product sales) then met. UNITAID decision expected ~Nov-2026.
A11: Lease treatment | B11: (B): lease payments inside cash overheads; lease liabilities excluded from net debt. Historical owner FCF deducts lease principal.
A12: Currency | B12: Statements and quote both NZD. Filings in whole dollars; workbook in NZ$ millions; shares in millions.
A13: Scenario drivers | B13: Agent judgment, set 2026-09-13. Blue cells on the Scen_* tabs (rows 5,7,9,10,11,15-19,26) and Assumptions are the only inputs; everything else is formula.
... A16: Staleness | B16: Figures go stale: the price moves daily and the cash estimate is a roll-forward, not a reported number.

Sheet Actuals
A1: Reported history, NZ$ millions (source: TRU.NZ_Metrics.csv / core_metrics; COGS FY2023 from ASM deck, FY2024-26 from the P&L). Filings are in whole NZD.
A2: Period | B2: Revenue | C2: COGS | D2: Other income (R&D offset) | E2: Net income | F2: OCF | G2: Capex | H2: Reported FCF | I2: SBC | J2: Interest income | K2: Lease principal | L2: Equity | M2: Cash | N2: Lease liabilities | O2: Wtd shares (m)
A3: FY2017 | B3: 0.585388 | D3: 0.810202 | E3: -3.54061 | F3: -2.57558 | G3: 0.006355 | H3: -2.581935 | I3: 0 | J3: 0.020506 | K3: 0 | L3: 14.324288 | M3: 3.671571 | N3: 0 | O3: 165.25691
A4: FY2018 | B4: 0.804062 | D4: 1.37458 | E4: -4.168792 | F4: -3.729191 | G4: 0.00311 | H4: -3.732301 | I4: 0 | J4: 0.020506 | K4: 0 | L4: 11.615882 | M4: 1.212454 | N4: 0 | O4: 195.56501
A5: FY2019 | B5: 1.862949 | D5: 1.2412 | E5: -3.380454 | F5: -2.678321 | G5: 0.410031 | H5: -3.088352 | I5: 0 | J5: 0.011647 | K5: 0 | L5: 11.320809 | M5: 1.737775 | N5: 0.626501 | O5: 209.77769
A6: FY2020 | B6: 1.288242 | D6: 1.26604 | E6: -5.196721 | F6: -1.634499 | G6: 0 | H6: -1.634499 | I6: 0.306 | J6: 0.008867 | K6: 0 | L6: 7.241067 | M6: 1.024153 | N6: 0.41028 | O6: 224.41675
A7: FY2021 | B7: 1.132641 | D7: 0.843274 | E7: -3.49001 | F7: -2.189331 | G7: 0.097524 | H7: -2.286855 | I7: 0 | J7: 0.00182 | K7: 0 | L7: 11.309191 | M7: 5.255074 | N7: 0 | O7: 323.7617
A8: FY2022 | B8: 1.678465 | D8: 0.973914 | E8: -7.892672 | F8: -2.531697 | G8: 0.002662 | H8: -2.534359 | I8: 0.144813 | J8: 0.000323 | K8: 0 | L8: 3.395051 | M8: 2.797004 | N8: 0 | O8: 362.86625
A9: FY2023 | B9: 1.662619 | C9: 1.3 | D9: 0.540016 | E9: -2.40184 | F9: -2.193786 | G9: 0.0497 | H9: -2.243486 | I9: 0.054873 | J9: 0.002854 | K9: 0 | L9: 2.542024 | M9: 2.160468 | N9: 0 | O9: 364.1917
A10: FY2024 | B10: 2.107839 | C10: 1.41607 | D10: 0.497045 | E10: -2.050533 | F10: -2.033174 | G10: 0 | H10: -2.033174 | I10: 0.089643 | J10: 0.004099 | K10: 0 | L10: 3.231934 | M10: 2.728036 | N10: 0 | O10: 422.17586
A11: FY2025 | B11: 1.712052 | C11: 1.196832 | D11: 0.393203 | E11: -2.243476 | F11: -2.289306 | G11: 0 | H11: -2.289306 | I11: 0 | J11: 0.004842 | K11: 0.084398 | L11: 1.008382 | M11: 0.365473 | N11: 0.317372 | O11: 552.74344
A12: FY2026 | B12: 2.434476 | C12: 1.666675 | D12: 0.394534 | E12: -2.252742 | F12: -2.470767 | G12: 0 | H12: -2.470767 | I12: 0.036829 | J12: 0.006213 | K12: 0.121057 | L12: 2.585462 | M12: 1.462603 | N12: 0.200695 | O12: 700.89455
A14: FY2026 cost base (NZ$m)
A15: P&L overheads ex COGS | B15: 3.416077
A16: less SBC (non-cash) | B16: -0.036829
A17: less ROU depreciation (non-cash) | B17: -0.140065
A18: add lease cash (principal + interest) | B18: 0.123066
A19: Cash overheads incl. leases | B19: 3.362249
A20: Gross margin FY2026 | B20: 0.3154
A21: Cash received from customers FY2026 (vs revenue 2.434) | B21: 1.472115
A22: Trade receivables 31-Mar-2026 (vs 0.023 prior) | B22: 1.026962
A24: Share count bridge (m)
A25: 31-Mar-2026 | B25: 747.32533
A26: + placement (Jun-2026, @0.014) | B26: 109.99999
A27: Total 12-Jun-2026 (Annual Report) | B27: 857.32532
A28: + rights 80.617 + shortfall 68.848 (30-Jun-2026, @0.013) | B28: 149.46499
A29: + oversubs 22.188 (@0.013) + placement top-up 18.740 (@0.014) (4-Aug-2026) | B29: 40.92857
A30: Total 4-Aug-2026 Capital Change Notice | B30: 1047.7189

Sheet Assumptions
A1: Global inputs (blue) - NZ$ millions, shares in millions
A3: Current price (NZ$) | B3: 0.015 | C3: Yahoo TRU.NZ last trade 2026-09-11T02:31:36Z
A4: Shares on issue today (m) | B4: 1047.7189 | C4: 4-Aug-2026 Capital Change Notice
A5: Cash 31-Mar-2026 | B5: 1.462603 | C5: FY2026 audited balance sheet
A6: Gross raise May-Aug 2026 | B6: 4.033902 | C6: 128.74m@0.014 + 149.46m@0.013 + 22.19m@0.013
A7: Raise cost % | B7: 0.09 | C7: FY2026 precedent 9.4% cash costs
A8: Net raise | B8: =B6*(1-B7) | C8: formula
A9: Pro-forma cash, start FY2027 | B9: =B5+B8 | C9: formula - the cash roll on each Scen_ tab starts here
A10: Cost of equity | B10: 0.25 | C10: NZD; rf 4.3% + 5.5% ERP x 1.5 beta + ~12.5pp nano-cap/illiquidity premium. Same for all scenarios.
A11: Horizon (years to 31-Mar-2029 exit) | B11: 2.5 | C11: from 13-Sep-2026
A12: Hurdle rate (entry price) | B12: 0.15 | C12: house standard
A13: FY2026 revenue | B13: 2.434476 | C13: FY2026 P&L
A14: Discount factor at CoE | B14: =1/(1+B10)^B11 | C14: formula
A15: Monthly burn (FY2026 run-rate) | B15: 0.215985 | C15: (OCF -2.471 + lease -0.121)/12
A16: Est. cash today (~mid-Sep-2026) | B16: =B5+B8-B15*5.5 | C16: ESTIMATE: 5.5 months of burn since 31-Mar; +/- NZ$0.5m
A18: Options (Capital Change Notice 4-Aug-2026) | B18: Number (m) | C18: Strike | D18: Expiry | E18: Proceeds if exercised
A19: TRUOD | B19: 204.69103 | C19: 0.022 | D19: 17-Jul-2027 | E19: =B19*C19
A20: TRUOE | B20: 89.045229 | C20: 0.014 | D20: 4-Aug-2028 | E20: =B20*C20
A21: TRUOF | B21: 22.5 | C21: 0.019 | D21: 4-Aug-2028 | E21: =B21*C21
A23: Scenario weights
A24: bear | B24: 0.35
A25: base | B25: 0.4
A26: bull | B26: 0.25
A27: Sum (must be 1.0) | B27: =SUM(B24:B26)
A29: Bear wind-down branch weight | B29: 0.5
A30: Bear wind-down recovery to equity (NZ$m) | B30: 0.9 | C30: ~1.2m cash entering FY2029 less ~0.8m wind-down costs plus ~0.5m IP/registrations sale
A32: Scenario narratives
A33: BEAR | B33: China (61% of sales) softens - the NZ$1.03m year-end trade receivable from a distributor on extended terms signals channel stuffing or a struggling partner - and the new markets repeat FY2026's pattern of orders slipping (Uzbekistan awaiting payment, Zimbabwe deferred): revenue FY2027E NZ$2.2m, flat thereafter, gross margin stuck at 31%. Overheads are cut to NZ$2.8m but the business still burns ~NZ$1.8m/yr, so cash (NZ$5.1m pro forma) runs out during FY2029 with no growth story to raise against; all options lapse. Two branches, 50/50: (i) wind-down / failed raise - ~NZ$1.2m cash entering FY2029 less ~NZ$0.8m of wind-down costs plus ~NZ$0.5m for the IP and registrations sold to a distributor = ~NZ$0.9m to 1,047.7m shares = NZ$0.0009 (PV NZ$0.0005); (ii) punitive recap - NZ$2.5m gross at NZ$0.005 (+500m shares -> 1,547.7m), exit at 1.0x FY2029E sales of NZ$2.4m plus ~NZ$1.8m cash = NZ$0.0027/share (PV NZ$0.0016). Blended bear IV NZ$0.0010 - a ~93% loss from NZ$0.015.
A34: BASE | B34: Revenue grows ~25%/yr off the FY2026 base: the deferred Zimbabwe 10,000-SUS order and the Uzbekistan pilot land in FY2027, India registration (guided 3-6 months from Jun-2026) opens a first commercial year in FY2028, the Vietnam HCMC 260,000-women programme ramps slowly, and China consumables grow modestly (SUS +1% in FY2026). No UNITAID win, or a win too small/late to matter inside the horizon. Gross margin improves 31.5% -> 37% as management guides ('expected to further improve in FY2027'). Cash overheads rise 4%/yr from the FY2026 NZ$3.36m because management is explicit that market development requires investment. Receivables absorb 20% of each year's revenue increase (FY2026 saw a NZ$1.0m receivable build on NZ$0.7m of growth). Cumulative FY2027-29 burn ~NZ$6.1m against NZ$5.1m pro-forma cash, so ONE further raise is modelled in FY2028: NZ$3.0m gross at NZ$0.010 (+300m shares), consistent with the annual raise cadence and each raise printing below the last (0.022 -> 0.014 -> 0.010). The NZ$0.022 TRUOD options lapse Jul-2027 and the 0.014/0.019 tranches lapse Aug-2028. Exit at 2.5x FY2029E sales - a multiple for a sub-scale, still-loss-making, distributor-led device company facing another raise, NOT the 4-5x the market has paid TRU on the story. Net cash at exit ~NZ$1.8m.
A35: BULL | B35: The Nov-2026 UNITAID decision delivers at least one of the five applications TruScreen is technology partner in (company: 'may add NZ$4m to annual revenue from FY2028 to FY2030'), the CSCCP Expert Consensus in China opens public-programme procurement so consumables finally compound, and the Vietnam/Zimbabwe/India programmes convert: FY2027E NZ$3.6m -> FY2028E NZ$6.5m -> FY2029E NZ$10.0m, gross margin 35% -> 44% on programme SUS volume. Overheads scale to NZ$4.9m. The share price re-rates above NZ$0.022 on the UNITAID news, so all 316.2m options exercise (NZ$6.18m: TRUOD in FY2028, TRUOE/TRUOF in FY2029) and NO discounted raise is needed; dilution stops at 1,364.0m. Approaching operating breakeven in FY2029 with ~NZ$6.4m net cash. Exit at 4.5x FY2029E sales - a growing, near-breakeven medtech with public-screening contracts, about the multiple the market pays TRU today. This is the scenario the current price needs to be ~two-thirds likely.
A37: Weights rationale | B37: Bear 35% (vs 15% house default): the FY2026 audit report carries a Material Uncertainty Related to Going Concern paragraph, the directors' twelve-month forecast explicitly 'assumes revenue growth from a number of markets' that the auditor could not corroborate, China is 61% of sales with a NZ$1.03m receivable on extended terms, the recurring consumable line grew 1% in a +42% year, FY2026 guidance was cut once already, and the company has been 'about to scale' since listing (revenue NZ$0.6m FY2017 -> NZ$2.4m FY2026, with a placement at a lower price nearly every year). Bull 25% (vs 35% default): there IS a dated, real catalyst - the UNITAID decision ~Nov-2026 on five applications TruScreen is technology partner in, plus the CSCCP Expert Consensus in China and Vietnam/Zimbabwe/India programmes - which is why bull is not cut further; but the bull needs three independent things (a programme win, China consumables compounding, and a share price above NZ$0.022 by Jul-2027 so the options fund the growth) and the company's ten-year record is of announced programmes converting slowly. Base 40% carries the remainder. Weights sum to 1.0.

Sheet Scen_Bear
A1: Scen_Bear: revenue -> gross profit -> cash burn -> funding -> exit at EV/Sales. Blue = driver. NZ$m.
A3: Year | B3: FY2026A | C3: FY2027E | D3: FY2028E | E3: FY2029E
A4: Index | B4: 0 | C4: 1 | D4: 2 | E4: 3
A5: Revenue growth YoY | C5: -0.096 | D5: 0.045 | E5: 0.043
A6: Revenue | B6: =Assumptions!B13 | C6: =B6*(1+C5) | D6: =C6*(1+D5) | E6: =D6*(1+E5)
A7: Gross margin | B7: 0.3154 | C7: 0.31 | D7: 0.31 | E7: 0.31
A8: Gross profit | B8: =B6*B7 | C8: =C6*C7 | D8: =D6*D7 | E8: =E6*E7
A9: Other income (R&D tax offset) | B9: 0.394534 | C9: 0.35 | D9: 0.35 | E9: 0.35
A10: Cash overheads incl. leases | B10: 3.362249 | C10: 3.1 | D10: 2.9 | E10: 2.8
A11: WC capture on revenue change (negative = outflow) | C11: 0 | D11: 0 | E11: 0
A12: Working capital change | B12: -0.41 | C12: =C11*(C6-B6) | D12: =D11*(D6-C6) | E12: =E11*(E6-D6)
A13: Operating cash flow (burn) | B13: =B8+B9-B10+B12 | C13: =C8+C9-C10+C12 | D13: =D8+D9-D10+D12 | E13: =E8+E9-E10+E12
A14: Option exercise proceeds | C14: =C15*Assumptions!$E$19+C16*Assumptions!$E$20+C17*Assumptions!$E$21 | D14: =D15*Assumptions!$E$19+D16*Assumptions!$E$20+D17*Assumptions!$E$21 | E14: =E15*Assumptions!$E$19+E16*Assumptions!$E$20+E17*Assumptions!$E$21
A15: TRUOD exercised (1/0) | C15: 0 | D15: 0 | E15: 0
A16: TRUOE exercised (1/0) | C16: 0 | D16: 0 | E16: 0
A17: TRUOF exercised (1/0) | C17: 0 | D17: 0 | E17: 0
A18: Discounted raise - gross | C18: 0 | D18: 0 | E18: 2.5
A19: Raise price (NZ$) | C19: 0 | D19: 0 | E19: 0.005
A20: Raise net of costs | C20: =C18*(1-Assumptions!$B$7) | D20: =D18*(1-Assumptions!$B$7) | E20: =E18*(1-Assumptions!$B$7)
A21: New shares from raise (m) | C21: =IF(C19>0,C18/C19,0) | D21: =IF(D19>0,D18/D19,0) | E21: =IF(E19>0,E18/E19,0)
A22: Cash at year end | C22: =Assumptions!$B$9+C13+C14+C20 | D22: =C22+D13+D14+D20 | E22: =D22+E13+E14+E20
A23: Diluted shares at year end (m) | C23: =Assumptions!$B$4+C15*Assumptions!$B$19+C16*Assumptions!$B$20+C17*Assumptions!$B$21+C21 | D23: =C23+D15*Assumptions!$B$19+D16*Assumptions!$B$20+D17*Assumptions!$B$21+D21 | E23: =D23+E15*Assumptions!$B$19+E16*Assumptions!$B$20+E17*Assumptions!$B$21+E21
A24: Memo: OCF margin | B24: =B13/B6 | C24: =C13/C6 | D24: =D13/D6 | E24: =E13/E6
A26: Exit EV/Sales multiple | B26: 1
A27: Exit EV | B27: =E6*B26
A28: Exit net cash | B28: =E22
A29: Exit equity value | B29: =B27+B28
A30: Diluted shares at exit (m) | B30: =E23
A31: Exit value per share (NZ$) | B31: =B29/B30
A32: Discount factor at CoE | B32: =Assumptions!B14
A33: VALUE PER SHARE (NZ$) | B33: =B31*B32
A34: Upside vs price | B34: =B33/Assumptions!B3-1
A35: Entry price at hurdle (NZ$) | B35: =B31/(1+Assumptions!B12)^Assumptions!B11
A37: Wind-down branch (blended into the bear value)
A38: Wind-down branch weight | B38: =Assumptions!B29
A39: Recovery to equity (NZ$m) | B39: =Assumptions!B30
A40: Recovery per share (today's count) | B40: =B39/Assumptions!B4
A41: PV of recovery per share | B41: =B40*B32
A42: BLENDED BEAR VALUE PER SHARE | B42: =B38*B41+(1-B38)*B33
A43: Blended bear entry price at hurdle | B43: =B38*B40/(1+Assumptions!B12)^Assumptions!B11+(1-B38)*B35
...

Sheet Scen_Base
A1: Scen_Base: revenue -> gross profit -> cash burn -> funding -> exit at EV/Sales. Blue = driver. NZ$m.
A3: Year | B3: FY2026A | C3: FY2027E | D3: FY2028E | E3: FY2029E
A4: Index | B4: 0 | C4: 1 | D4: 2 | E4: 3
A5: Revenue growth YoY | C5: 0.273 | D5: 0.258 | E5: 0.231
A6: Revenue | B6: =Assumptions!B13 | C6: =B6*(1+C5) | D6: =C6*(1+D5) | E6: =D6*(1+E5)
A7: Gross margin | B7: 0.3154 | C7: 0.33 | D7: 0.35 | E7: 0.37
A8: Gross profit | B8: =B6*B7 | C8: =C6*C7 | D8: =D6*D7 | E8: =E6*E7
A9: Other income (R&D tax offset) | B9: 0.394534 | C9: 0.4 | D9: 0.4 | E9: 0.4
A10: Cash overheads incl. leases | B10: 3.362249 | C10: 3.5 | D10: 3.65 | E10: 3.8
A11: WC capture on revenue change (negative = outflow) | C11: -0.2 | D11: -0.2 | E11: -0.2
A12: Working capital change | B12: -0.41 | C12: =C11*(C6-B6) | D12: =D11*(D6-C6) | E12: =E11*(E6-D6)
A13: Operating cash flow (burn) | B13: =B8+B9-B10+B12 | C13: =C8+C9-C10+C12 | D13: =D8+D9-D10+D12 | E13: =E8+E9-E10+E12
A14: Option exercise proceeds | C14: =C15*Assumptions!$E$19+C16*Assumptions!$E$20+C17*Assumptions!$E$21 | D14: =D15*Assumptions!$E$19+D16*Assumptions!$E$20+D17*Assumptions!$E$21 | E14: =E15*Assumptions!$E$19+E16*Assumptions!$E$20+E17*Assumptions!$E$21
A15: TRUOD exercised (1/0) | C15: 0 | D15: 0 | E15: 0
A16: TRUOE exercised (1/0) | C16: 0 | D16: 0 | E16: 0
A17: TRUOF exercised (1/0) | C17: 0 | D17: 0 | E17: 0
A18: Discounted raise - gross | C18: 0 | D18: 3 | E18: 0
A19: Raise price (NZ$) | C19: 0 | D19: 0.01 | E19: 0
A20: Raise net of costs | C20: =C18*(1-Assumptions!$B$7) | D20: =D18*(1-Assumptions!$B$7) | E20: =E18*(1-Assumptions!$B$7)
A21: New shares from raise (m) | C21: =IF(C19>0,C18/C19,0) | D21: =IF(D19>0,D18/D19,0) | E21: =IF(E19>0,E18/E19,0)
A22: Cash at year end | C22: =Assumptions!$B$9+C13+C14+C20 | D22: =C22+D13+D14+D20 | E22: =D22+E13+E14+E20
A23: Diluted shares at year end (m) | C23: =Assumptions!$B$4+C15*Assumptions!$B$19+C16*Assumptions!$B$20+C17*Assumptions!$B$21+C21 | D23: =C23+D15*Assumptions!$B$19+D16*Assumptions!$B$20+D17*Assumptions!$B$21+D21 | E23: =D23+E15*Assumptions!$B$19+E16*Assumptions!$B$20+E17*Assumptions!$B$21+E21
A24: Memo: OCF margin | B24: =B13/B6 | C24: =C13/C6 | D24: =D13/D6 | E24: =E13/E6
A26: Exit EV/Sales multiple | B26: 2.5
A27: Exit EV | B27: =E6*B26
A28: Exit net cash | B28: =E22
A29: Exit equity value | B29: =B27+B28
A30: Diluted shares at exit (m) | B30: =E23
A31: Exit value per share (NZ$) | B31: =B29/B30
A32: Discount factor at CoE | B32: =Assumptions!B14
A33: VALUE PER SHARE (NZ$) | B33: =B31*B32
A34: Upside vs price | B34: =B33/Assumptions!B3-1
A35: Entry price at hurdle (NZ$) | B35: =B31/(1+Assumptions!B12)^Assumptions!B11

Sheet Scen_Bull
A1: Scen_Bull: revenue -> gross profit -> cash burn -> funding -> exit at EV/Sales. Blue = driver. NZ$m.
A3: Year | B3: FY2026A | C3: FY2027E | D3: FY2028E | E3: FY2029E
A4: Index | B4: 0 | C4: 1 | D4: 2 | E4: 3
A5: Revenue growth YoY | C5: 0.479 | D5: 0.806 | E5: 0.538
A6: Revenue | B6: =Assumptions!B13 | C6: =B6*(1+C5) | D6: =C6*(1+D5) | E6: =D6*(1+E5)
A7: Gross margin | B7: 0.3154 | C7: 0.35 | D7: 0.4 | E7: 0.44
A8: Gross profit | B8: =B6*B7 | C8: =C6*C7 | D8: =D6*D7 | E8: =E6*E7
A9: Other income (R&D tax offset) | B9: 0.394534 | C9: 0.4 | D9: 0.4 | E9: 0.4
A10: Cash overheads incl. leases | B10: 3.362249 | C10: 3.7 | D10: 4.3 | E10: 4.9
A11: WC capture on revenue change (negative = outflow) | C11: -0.2 | D11: -0.2 | E11: -0.2
A12: Working capital change | B12: -0.41 | C12: =C11*(C6-B6) | D12: =D11*(D6-C6) | E12: =E11*(E6-D6)
A13: Operating cash flow (burn) | B13: =B8+B9-B10+B12 | C13: =C8+C9-C10+C12 | D13: =D8+D9-D10+D12 | E13: =E8+E9-E10+E12
A14: Option exercise proceeds | C14: =C15*Assumptions!$E$19+C16*Assumptions!$E$20+C17*Assumptions!$E$21 | D14: =D15*Assumptions!$E$19+D16*Assumptions!$E$20+D17*Assumptions!$E$21 | E14: =E15*Assumptions!$E$19+E16*Assumptions!$E$20+E17*Assumptions!$E$21
A15: TRUOD exercised (1/0) | C15: 0 | D15: 1 | E15: 0
A16: TRUOE exercised (1/0) | C16: 0 | D16: 0 | E16: 1
A17: TRUOF exercised (1/0) | C17: 0 | D17: 0 | E17: 1
A18: Discounted raise - gross | C18: 0 | D18: 0 | E18: 0
A19: Raise price (NZ$) | C19: 0 | D19: 0 | E19: 0
A20: Raise net of costs | C20: =C18*(1-Assumptions!$B$7) | D20: =D18*(1-Assumptions!$B$7) | E20: =E18*(1-Assumptions!$B$7)
A21: New shares from raise (m) | C21: =IF(C19>0,C18/C19,0) | D21: =IF(D19>0,D18/D19,0) | E21: =IF(E19>0,E18/E19,0)
A22: Cash at year end | C22: =Assumptions!$B$9+C13+C14+C20 | D22: =C22+D13+D14+D20 | E22: =D22+E13+E14+E20
A23: Diluted shares at year end (m) | C23: =Assumptions!$B$4+C15*Assumptions!$B$19+C16*Assumptions!$B$20+C17*Assumptions!$B$21+C21 | D23: =C23+D15*Assumptions!$B$19+D16*Assumptions!$B$20+D17*Assumptions!$B$21+D21 | E23: =D23+E15*Assumptions!$B$19+E16*Assumptions!$B$20+E17*Assumptions!$B$21+E21
A24: Memo: OCF margin | B24: =B13/B6 | C24: =C13/C6 | D24: =D13/D6 | E24: =E13/E6
A26: Exit EV/Sales multiple | B26: 4.5
A27: Exit EV | B27: =E6*B26
A28: Exit net cash | B28: =E22
A29: Exit equity value | B29: =B27+B28
A30: Diluted shares at exit (m) | B30: =E23
A31: Exit value per share (NZ$) | B31: =B29/B30
A32: Discount factor at CoE | B32: =Assumptions!B14
A33: VALUE PER SHARE (NZ$) | B33: =B31*B32
A34: Upside vs price | B34: =B33/Assumptions!B3-1
A35: Entry price at hurdle (NZ$) | B35: =B31/(1+Assumptions!B12)^Assumptions!B11

Sheet FCF_Quality
A1: Reported FCF reconciled to owner FCF (NZ$m). Owner FCF = reported FCF - SBC - interest income - IFRS-16 lease principal. Negative in every year.
A2: Period | B2: Reported FCF | C2: less SBC | D2: less interest income | E2: less lease principal | F2: Owner FCF | G2: Revenue | H2: Reported FCF margin | I2: Owner FCF margin
A3: FY2017 | B3: -2.581935 | C3: 0 | D3: 0.020506 | E3: 0 | F3: =B3-C3-D3-E3 | G3: 0.585388 | H3: =B3/G3 | I3: =F3/G3
A4: FY2018 | B4: -3.732301 | C4: 0 | D4: 0.020506 | E4: 0 | F4: =B4-C4-D4-E4 | G4: 0.804062 | H4: =B4/G4 | I4: =F4/G4
A5: FY2019 | B5: -3.088352 | C5: 0 | D5: 0.011647 | E5: 0 | F5: =B5-C5-D5-E5 | G5: 1.862949 | H5: =B5/G5 | I5: =F5/G5
A6: FY2020 | B6: -1.634499 | C6: 0.306 | D6: 0.008867 | E6: 0 | F6: =B6-C6-D6-E6 | G6: 1.288242 | H6: =B6/G6 | I6: =F6/G6
A7: FY2021 | B7: -2.286855 | C7: 0 | D7: 0.00182 | E7: 0 | F7: =B7-C7-D7-E7 | G7: 1.132641 | H7: =B7/G7 | I7: =F7/G7
A8: FY2022 | B8: -2.534359 | C8: 0.144813 | D8: 0.000323 | E8: 0 | F8: =B8-C8-D8-E8 | G8: 1.678465 | H8: =B8/G8 | I8: =F8/G8
A9: FY2023 | B9: -2.243486 | C9: 0.054873 | D9: 0.002854 | E9: 0 | F9: =B9-C9-D9-E9 | G9: 1.662619 | H9: =B9/G9 | I9: =F9/G9
A10: FY2024 | B10: -2.033174 | C10: 0.089643 | D10: 0.004099 | E10: 0 | F10: =B10-C10-D10-E10 | G10: 2.107839 | H10: =B10/G10 | I10: =F10/G10
A11: FY2025 | B11: -2.289306 | C11: 0 | D11: 0.004842 | E11: 0.084398 | F11: =B11-C11-D11-E11 | G11: 1.712052 | H11: =B11/G11 | I11: =F11/G11
A12: FY2026 | B12: -2.470767 | C12: 0.036829 | D12: 0.006213 | E12: 0.121057 | F12: =B12-C12-D12-E12 | G12: 2.434476 | H12: =B12/G12 | I12: =F12/G12
A14: Memo: FY2026 cash received from customers was NZ$1.472m against NZ$2.434m revenue - trade receivables rose NZ$1.0m (one distributor on extended terms). Cash tax: nil in every year (accumulated losses NZ$39.7m); the Australian R&D tax offset (NZ$0.48m cash FY2026) is the only tax flow and is a receipt.

Sheet Valuation
A1: Valuation summary (NZ$ per share)
A3: Scenario | B3: Value per share | C3: Upside vs price | D3: Weight | E3: Entry price @ hurdle | F3: Street value (= house)
A4: Bear | B4: =Scen_Bear!B42 | C4: =B4/Assumptions!B3-1 | D4: =Assumptions!B24 | E4: =Scen_Bear!B43 | F4: =B4
A5: Base | B5: =Scen_Base!B33 | C5: =B5/Assumptions!B3-1 | D5: =Assumptions!B25 | E5: =Scen_Base!B35 | F5: =B5
A6: Bull | B6: =Scen_Bull!B33 | C6: =B6/Assumptions!B3-1 | D6: =Assumptions!B26 | E6: =Scen_Bull!B35 | F6: =B6
A8: Probability-weighted value per share | B8: =SUMPRODUCT(B4:B6,D4:D6)
A9: Current price | B9: =Assumptions!B3
A10: Margin of safety (negative = overvalued) | B10: =1-B9/B8
A11: Weighted entry price at 15% hurdle | B11: =SUMPRODUCT(E4:E6,D4:D6)
A12: Street weighted value (= house; multiple-based model) | B12: =B8
A13: Band position | B13: n/a - house and street coincide (SBC band does not operate in a multiple-exit model)
A14: Weights sum check | B14: =Assumptions!B27
A16: Required-return table (base case): exit value per share discounted at r over the horizon
A17: Required return | B17: Value per share
A18: 0.09 | B18: =Scen_Base!$B$31/(1+A18)^Assumptions!$B$11
A19: 0.1 | B19: =Scen_Base!$B$31/(1+A19)^Assumptions!$B$11
A20: 0.11 | B20: =Scen_Base!$B$31/(1+A20)^Assumptions!$B$11
A21: 0.12 | B21: =Scen_Base!$B$31/(1+A21)^Assumptions!$B$11
A22: 0.15 | B22: =Scen_Base!$B$31/(1+A22)^Assumptions!$B$11
A23: =Assumptions!B10 | B23: =Scen_Base!$B$31/(1+A23)^Assumptions!$B$11 | C23: model CoE row - must equal Scen_Base!B33
A25: Sensitivity (base case): rows = cost of equity, columns = exit EV/Sales multiple on FY2029E revenue
B26: 1.5 | C26: 2.5 | D26: 3.5 | E26: 4.5 | F26: 5.5
A27: 0.2 | B27: =(B$26*Scen_Base!$E$6+Scen_Base!$E$22)/Scen_Base!$E$23/(1+$A27)^Assumptions!$B$11 | C27: =(C$26*Scen_Base!$E$6+Scen_Base!$E$22)/Scen_Base!$E$23/(1+$A27)^Assumptions!$B$11 | D27: =(D$26*Scen_Base!$E$6+Scen_Base!$E$22)/Scen_Base!$E$23/(1+$A27)^Assumptions!$B$11 | E27: =(E$26*Scen_Base!$E$6+Scen_Base!$E$22)/Scen_Base!$E$23/(1+$A27)^Assumptions!$B$11 | F27: =(F$26*Scen_Base!$E$6+Scen_Base!$E$22)/Scen_Base!$E$23/(1+$A27)^Assumptions!$B$11
A28: 0.225 | B28: =(B$26*Scen_Base!$E$6+Scen_Base!$E$22)/Scen_Base!$E$23/(1+$A28)^Assumptions!$B$11 | C28: =(C$26*Scen_Base!$E$6+Scen_Base!$E$22)/Scen_Base!$E$23/(1+$A28)^Assumptions!$B$11 | D28: =(D$26*Scen_Base!$E$6+Scen_Base!$E$22)/Scen_Base!$E$23/(1+$A28)^Assumptions!$B$11 | E28: =(E$26*Scen_Base!$E$6+Scen_Base!$E$22)/Scen_Base!$E$23/(1+$A28)^Assumptions!$B$11 | F28: =(F$26*Scen_Base!$E$6+Scen_Base!$E$22)/Scen_Base!$E$23/(1+$A28)^Assumptions!$B$11
A29: 0.25 | B29: =(B$26*Scen_Base!$E$6+Scen_Base!$E$22)/Scen_Base!$E$23/(1+$A29)^Assumptions!$B$11 | C29: =(C$26*Scen_Base!$E$6+Scen_Base!$E$22)/Scen_Base!$E$23/(1+$A29)^Assumptions!$B$11 | D29: =(D$26*Scen_Base!$E$6+Scen_Base!$E$22)/Scen_Base!$E$23/(1+$A29)^Assumptions!$B$11 | E29: =(E$26*Scen_Base!$E$6+Scen_Base!$E$22)/Scen_Base!$E$23/(1+$A29)^Assumptions!$B$11 | F29: =(F$26*Scen_Base!$E$6+Scen_Base!$E$22)/Scen_Base!$E$23/(1+$A29)^Assumptions!$B$11
A30: 0.275 | B30: =(B$26*Scen_Base!$E$6+Scen_Base!$E$22)/Scen_Base!$E$23/(1+$A30)^Assumptions!$B$11 | C30: =(C$26*Scen_Base!$E$6+Scen_Base!$E$22)/Scen_Base!$E$23/(1+$A30)^Assumptions!$B$11 | D30: =(D$26*Scen_Base!$E$6+Scen_Base!$E$22)/Scen_Base!$E$23/(1+$A30)^Assumptions!$B$11 | E30: =(E$26*Scen_Base!$E$6+Scen_Base!$E$22)/Scen_Base!$E$23/(1+$A30)^Assumptions!$B$11 | F30: =(F$26*Scen_Base!$E$6+Scen_Base!$E$22)/Scen_Base!$E$23/(1+$A30)^Assumptions!$B$11
A31: 0.3 | B31: =(B$26*Scen_Base!$E$6+Scen_Base!$E$22)/Scen_Base!$E$23/(1+$A31)^Assumptions!$B$11 | C31: =(C$26*Scen_Base!$E$6+Scen_Base!$E$22)/Scen_Base!$E$23/(1+$A31)^Assumptions!$B$11 | D31: =(D$26*Scen_Base!$E$6+Scen_Base!$E$22)/Scen_Base!$E$23/(1+$A31)^Assumptions!$B$11 | E31: =(E$26*Scen_Base!$E$6+Scen_Base!$E$22)/Scen_Base!$E$23/(1+$A31)^Assumptions!$B$11 | F31: =(F$26*Scen_Base!$E$6+Scen_Base!$E$22)/Scen_Base!$E$23/(1+$A31)^Assumptions!$B$11
A33: Memo: base case at TODAY'S EV/trailing-sales multiple (no re-rating)
A34: Market cap | B34: =Assumptions!B4*Assumptions!B3
A35: EV (mkt cap - est. cash) | B35: =B34-Assumptions!B16
A36: EV / FY2026 sales | B36: =B35/Assumptions!B13
A37: Base value per share at that multiple | B37: =(B36*Scen_Base!E6+Scen_Base!E22)/Scen_Base!E23*Assumptions!B14
A39: Verdict | B39: Weighted IV NZ$0.0081 is ~46% BELOW the current NZ$0.015 price. Stated plainly: at these weights the stock is materially overvalued. The current price is approximately the probability-weighted value at weights of roughly bear 15% / base 22% / bull 63% - i.e. the market is treating a UNITAID/NGO programme win and option-funded growth as close to the median outcome. That is a legitimate bet on a Nov-2026 binary, but it is not what the filings support, and the downside if it fails is another sub-NZ$0.01 raise. No buy signal has been reverse-engineered: the honest answer is below the price at every discount rate in the required-return table.
