Workbook

Sheet DCF Model
A1: MFT.NZ (Mainfreight Limited) DCF Valuation Model
A2: Gray cells are INPUTS - adjust to see valuation change. Owner FCF = Reported FCF less IFRS16 lease principal repayment (SBC is verified NIL).
A4: KEY INPUTS
A5: Current Stock Price (NZD) | B5: 69.01
A6: Shares Outstanding (M) - static, no SBC/buybacks | B6: 100.69855
A7: Cash & Equivalents (M) | B7: 162.189
A8: Total Debt (M) - bank/asset-finance only, excl. IFRS16 leases | B8: 135.549
A9: Net Debt (M) | B9: =B8-B7 -> 0
A10: Reported FCF FY2026 (M) [OCF - capex] | B10: 392.09
A11: Less: SBC (verified NIL for MFT) | B11: 0
A12: Less: IFRS16 Lease Principal Repayment FY2026 (M) | B12: 209.505
A13: Base Year Owner FCF (M) | B13: =B10-B11-B12 -> 0
A14: Annual Share Growth (dilution) - zero, SBC nil | B14: 0
A16: WACC (Base) | B16: 0.105
A17: Terminal Growth Rate (Base) | B17: 0.0225
A18: Terminal Cap Multiple (x Year-5 FCF) | B18: 15
A20: BASE CASE COMPONENT ASSUMPTIONS
B21: Year 1 | C21: Year 2 | D21: Year 3 | E21: Year 4 | F21: Year 5
A22: Revenue Growth % | B22: 0.03 | C22: 0.05 | D22: 0.06 | E22: 0.065 | F22: 0.065
A23: EBITDA Margin % | B23: 0.142 | C23: 0.144 | D23: 0.145 | E23: 0.145 | F23: 0.145
A24: D&A % of Revenue | B24: 0.065 | C24: 0.065 | D24: 0.064 | E24: 0.064 | F24: 0.064
A25: Capex % of Revenue | B25: 0.043 | C25: 0.042 | D25: 0.042 | E25: 0.042 | F25: 0.042
A26: Lease Principal % of Revenue | B26: 0.0385 | C26: 0.038 | D26: 0.0375 | E26: 0.0372 | F26: 0.037
A27: Cash Tax Rate % | B27: 0.28 | C27: 0.28 | D27: 0.28 | E27: 0.28 | F27: 0.28
A28: Working Capital Capture % (of YoY revenue change) | B28: 0.15
A30: PROJECTIONS (Base Case, formula-driven)
B31: Year 1 | C31: Year 2 | D31: Year 3 | E31: Year 4 | F31: Year 5
A32: Revenue | B32: =$B$33*(1+B22) -> 0 | C32: =B32*(1+C22) -> 0 | D32: =C32*(1+D22) -> 0 | E32: =D32*(1+E22) -> 0 | F32: =E32*(1+F22) -> 0
A33: FY2026 Revenue (actual, anchor) | B33: 5383.52
A34: Adj. EBITDA | B34: =B32*B23 -> 0 | C34: =C32*C23 -> 0 | D34: =D32*D23 -> 0 | E34: =E32*E23 -> 0 | F34: =F32*F23 -> 0
A35: D&A | B35: =B32*B24 -> 0 | C35: =C32*C24 -> 0 | D35: =D32*D24 -> 0 | E35: =E32*E24 -> 0 | F35: =F32*F24 -> 0
A36: EBIT | B36: =B34-B35 -> 0 | C36: =C34-C35 -> 0 | D36: =D34-D35 -> 0 | E36: =E34-E35 -> 0 | F36: =F34-F35 -> 0
A37: NOPAT (EBIT x (1-tax)) | B37: =B36*(1-B27) -> 0 | C37: =C36*(1-C27) -> 0 | D37: =D36*(1-D27) -> 0 | E37: =E36*(1-E27) -> 0 | F37: =F36*(1-F27) -> 0
A38: Capex | B38: =B32*B25 -> 0 | C38: =C32*C25 -> 0 | D38: =D32*D25 -> 0 | E38: =E32*E25 -> 0 | F38: =F32*F25 -> 0
A39: Lease Principal Repayment | B39: =B32*B26 -> 0 | C39: =C32*C26 -> 0 | D39: =D32*D26 -> 0 | E39: =E32*E26 -> 0 | F39: =F32*F26 -> 0
A40: Working Capital (capture x YoY rev change) | B40: =$B$28*(B32-$B$33) -> 0 | C40: =$B$28*(C32-B32) -> 0 | D40: =$B$28*(D32-C32) -> 0 | E40: =$B$28*(E32-D32) -> 0 | F40: =$B$28*(F32-E32) -> 0
A41: Owner Free Cash Flow | B41: =B37+B35-B38-B39+B40 -> 0 | C41: =C37+C35-C38-C39+C40 -> 0 | D41: =D37+D35-D38-D39+D40 -> 0 | E41: =E37+E35-E38-E39+E40 -> 0 | F41: =F37+F35-F38-F39+F40 -> 0
A42: Owner FCF Margin % | B42: =B41/B32 -> 0 | C42: =C41/C32 -> 0 | D42: =D41/D32 -> 0 | E42: =E41/E32 -> 0 | F42: =F41/F32 -> 0
A43: Shares Outstanding (M) | B43: =$B$6*(1+$B$14)^1 -> 0 | C43: =$B$6*(1+$B$14)^2 -> 0 | D43: =$B$6*(1+$B$14)^3 -> 0 | E43: =$B$6*(1+$B$14)^4 -> 0 | F43: =$B$6*(1+$B$14)^5 -> 0
A44: Discount Factor | B44: =1/(1+$B$16)^1 -> 0 | C44: =1/(1+$B$16)^2 -> 0 | D44: =1/(1+$B$16)^3 -> 0 | E44: =1/(1+$B$16)^4 -> 0 | F44: =1/(1+$B$16)^5 -> 0
...

Sheet Sensitivity
A1: Sensitivity Analysis
A2: Intrinsic Value by WACC & Terminal Growth (Base Case FCF path)
A4: WACC \ Term G | B4: 0.0125 | C4: 0.0175 | D4: 0.0225 | E4: 0.0275 | F4: 0.0325
A5: 0.085 | B5: =((MIN('DCF Model'!$F$41*(1+0.0125)/(0.085-0.0125),'DCF Model'!$B$18*'DCF Model'!$F$41)/(1+0.085)^5+ SUMPRODUCT('DCF Model'!$B$41:$F$41,1/(1+0.085)^{1,2,3,4,5})- 'DCF Model'!$B$9))/'DCF Model'!$F$43 -> 0 | C5: =((MIN('DCF Model'!$F$41*(1+0.0175)/(0.085-0.0175),'DCF Model'!$B$18*'DCF Model'!$F$41)/(1+0.085)^5+ SUMPRODUCT('DCF Model'!$B$41:$F$41,1/(1+0.085)^{1,2,3,4,5})- 'DCF Model'!$B$9))/'DCF Model'!$F$43 -> 0 | D5: =((MIN('DCF Model'!$F$41*(1+0.0225)/(0.085-0.0225),'DCF Model'!$B$18*'DCF Model'!$F$41)/(1+0.085)^5+ SUMPRODUCT('DCF Model'!$B$41:$F$41,1/(1+0.085)^{1,2,3,4,5})- 'DCF Model'!$B$9))/'DCF Model'!$F$43 -> 0 | E5: =((MIN('DCF Model'!$F$41*(1+0.0275)/(0.085-0.0275),'DCF Model'!$B$18*'DCF Model'!$F$41)/(1+0.085)^5+ SUMPRODUCT('DCF Model'!$B$41:$F$41,1/(1+0.085)^{1,2,3,4,5})- 'DCF Model'!$B$9))/'DCF Model'!$F$43 -> 0 | F5: =((MIN('DCF Model'!$F$41*(1+0.0325)/(0.085-0.0325),'DCF Model'!$B$18*'DCF Model'!$F$41)/(1+0.085)^5+ SUMPRODUCT('DCF Model'!$B$41:$F$41,1/(1+0.085)^{1,2,3,4,5})- 'DCF Model'!$B$9))/'DCF Model'!$F$43 -> 0
A6: 0.095 | B6: =((MIN('DCF Model'!$F$41*(1+0.0125)/(0.095-0.0125),'DCF Model'!$B$18*'DCF Model'!$F$41)/(1+0.095)^5+ SUMPRODUCT('DCF Model'!$B$41:$F$41,1/(1+0.095)^{1,2,3,4,5})- 'DCF Model'!$B$9))/'DCF Model'!$F$43 -> 0 | C6: =((MIN('DCF Model'!$F$41*(1+0.0175)/(0.095-0.0175),'DCF Model'!$B$18*'DCF Model'!$F$41)/(1+0.095)^5+ SUMPRODUCT('DCF Model'!$B$41:$F$41,1/(1+0.095)^{1,2,3,4,5})- 'DCF Model'!$B$9))/'DCF Model'!$F$43 -> 0 | D6: =((MIN('DCF Model'!$F$41*(1+0.0225)/(0.095-0.0225),'DCF Model'!$B$18*'DCF Model'!$F$41)/(1+0.095)^5+ SUMPRODUCT('DCF Model'!$B$41:$F$41,1/(1+0.095)^{1,2,3,4,5})- 'DCF Model'!$B$9))/'DCF Model'!$F$43 -> 0 | E6: =((MIN('DCF Model'!$F$41*(1+0.0275)/(0.095-0.0275),'DCF Model'!$B$18*'DCF Model'!$F$41)/(1+0.095)^5+ SUMPRODUCT('DCF Model'!$B$41:$F$41,1/(1+0.095)^{1,2,3,4,5})- 'DCF Model'!$B$9))/'DCF Model'!$F$43 -> 0 | F6: =((MIN('DCF Model'!$F$41*(1+0.0325)/(0.095-0.0325),'DCF Model'!$B$18*'DCF Model'!$F$41)/(1+0.095)^5+ SUMPRODUCT('DCF Model'!$B$41:$F$41,1/(1+0.095)^{1,2,3,4,5})- 'DCF Model'!$B$9))/'DCF Model'!$F$43 -> 0
A7: 0.105 | B7: =((MIN('DCF Model'!$F$41*(1+0.0125)/(0.105-0.0125),'DCF Model'!$B$18*'DCF Model'!$F$41)/(1+0.105)^5+ SUMPRODUCT('DCF Model'!$B$41:$F$41,1/(1+0.105)^{1,2,3,4,5})- 'DCF Model'!$B$9))/'DCF Model'!$F$43 -> 0 | C7: =((MIN('DCF Model'!$F$41*(1+0.0175)/(0.105-0.0175),'DCF Model'!$B$18*'DCF Model'!$F$41)/(1+0.105)^5+ SUMPRODUCT('DCF Model'!$B$41:$F$41,1/(1+0.105)^{1,2,3,4,5})- 'DCF Model'!$B$9))/'DCF Model'!$F$43 -> 0 | D7: =((MIN('DCF Model'!$F$41*(1+0.0225)/(0.105-0.0225),'DCF Model'!$B$18*'DCF Model'!$F$41)/(1+0.105)^5+ SUMPRODUCT('DCF Model'!$B$41:$F$41,1/(1+0.105)^{1,2,3,4,5})- 'DCF Model'!$B$9))/'DCF Model'!$F$43 -> 0 | E7: =((MIN('DCF Model'!$F$41*(1+0.0275)/(0.105-0.0275),'DCF Model'!$B$18*'DCF Model'!$F$41)/(1+0.105)^5+ SUMPRODUCT('DCF Model'!$B$41:$F$41,1/(1+0.105)^{1,2,3,4,5})- 'DCF Model'!$B$9))/'DCF Model'!$F$43 -> 0 | F7: =((MIN('DCF Model'!$F$41*(1+0.0325)/(0.105-0.0325),'DCF Model'!$B$18*'DCF Model'!$F$41)/(1+0.105)^5+ SUMPRODUCT('DCF Model'!$B$41:$F$41,1/(1+0.105)^{1,2,3,4,5})- 'DCF Model'!$B$9))/'DCF Model'!$F$43 -> 0
A8: 0.115 | B8: =((MIN('DCF Model'!$F$41*(1+0.0125)/(0.115-0.0125),'DCF Model'!$B$18*'DCF Model'!$F$41)/(1+0.115)^5+ SUMPRODUCT('DCF Model'!$B$41:$F$41,1/(1+0.115)^{1,2,3,4,5})- 'DCF Model'!$B$9))/'DCF Model'!$F$43 -> 0 | C8: =((MIN('DCF Model'!$F$41*(1+0.0175)/(0.115-0.0175),'DCF Model'!$B$18*'DCF Model'!$F$41)/(1+0.115)^5+ SUMPRODUCT('DCF Model'!$B$41:$F$41,1/(1+0.115)^{1,2,3,4,5})- 'DCF Model'!$B$9))/'DCF Model'!$F$43 -> 0 | D8: =((MIN('DCF Model'!$F$41*(1+0.0225)/(0.115-0.0225),'DCF Model'!$B$18*'DCF Model'!$F$41)/(1+0.115)^5+ SUMPRODUCT('DCF Model'!$B$41:$F$41,1/(1+0.115)^{1,2,3,4,5})- 'DCF Model'!$B$9))/'DCF Model'!$F$43 -> 0 | E8: =((MIN('DCF Model'!$F$41*(1+0.0275)/(0.115-0.0275),'DCF Model'!$B$18*'DCF Model'!$F$41)/(1+0.115)^5+ SUMPRODUCT('DCF Model'!$B$41:$F$41,1/(1+0.115)^{1,2,3,4,5})- 'DCF Model'!$B$9))/'DCF Model'!$F$43 -> 0 | F8: =((MIN('DCF Model'!$F$41*(1+0.0325)/(0.115-0.0325),'DCF Model'!$B$18*'DCF Model'!$F$41)/(1+0.115)^5+ SUMPRODUCT('DCF Model'!$B$41:$F$41,1/(1+0.115)^{1,2,3,4,5})- 'DCF Model'!$B$9))/'DCF Model'!$F$43 -> 0
A9: 0.125 | B9: =((MIN('DCF Model'!$F$41*(1+0.0125)/(0.125-0.0125),'DCF Model'!$B$18*'DCF Model'!$F$41)/(1+0.125)^5+ SUMPRODUCT('DCF Model'!$B$41:$F$41,1/(1+0.125)^{1,2,3,4,5})- 'DCF Model'!$B$9))/'DCF Model'!$F$43 -> 0 | C9: =((MIN('DCF Model'!$F$41*(1+0.0175)/(0.125-0.0175),'DCF Model'!$B$18*'DCF Model'!$F$41)/(1+0.125)^5+ SUMPRODUCT('DCF Model'!$B$41:$F$41,1/(1+0.125)^{1,2,3,4,5})- 'DCF Model'!$B$9))/'DCF Model'!$F$43 -> 0 | D9: =((MIN('DCF Model'!$F$41*(1+0.0225)/(0.125-0.0225),'DCF Model'!$B$18*'DCF Model'!$F$41)/(1+0.125)^5+ SUMPRODUCT('DCF Model'!$B$41:$F$41,1/(1+0.125)^{1,2,3,4,5})- 'DCF Model'!$B$9))/'DCF Model'!$F$43 -> 0 | E9: =((MIN('DCF Model'!$F$41*(1+0.0275)/(0.125-0.0275),'DCF Model'!$B$18*'DCF Model'!$F$41)/(1+0.125)^5+ SUMPRODUCT('DCF Model'!$B$41:$F$41,1/(1+0.125)^{1,2,3,4,5})- 'DCF Model'!$B$9))/'DCF Model'!$F$43 -> 0 | F9: =((MIN('DCF Model'!$F$41*(1+0.0325)/(0.125-0.0325),'DCF Model'!$B$18*'DCF Model'!$F$41)/(1+0.125)^5+ SUMPRODUCT('DCF Model'!$B$41:$F$41,1/(1+0.125)^{1,2,3,4,5})- 'DCF Model'!$B$9))/'DCF Model'!$F$43 -> 0

Sheet Historical
A1: Historical Growth Rates (Through-Cycle FY2017-FY2026)
A3: Metric | B3: 3-Year CAGR | C3: 5-Year / Through-Cycle CAGR
A4: Revenue | B4: -0.0175 | C4: 0.0973
A5: EPS | B5: -0.162 | C5: 0.1055
A6: Equity (Book Value) | B6: 0.0742 | C6: 0.1424
A7: Owner FCF (post-IFRS16 lease deduction) | B7: -0.1395 | C7: 0.2872
A9: Selected Growth Rate (Revenue, 9yr through-cycle): | B9: 0.0973
A10: Note:
A11: Equity CAGR (14.2% through-cycle) diverges materially above Revenue CAGR (9.7%) and EPS CAGR (10.5%). This is NOT SBC-driven dilution-avoidance (SBC is nil) -- it is retained-earnings compounding on a static share count with zero buybacks and zero dividends-out-of-capital, i.e. equity simply accumulates faster than revenue because margins expanded structurally post-IFRS16 (EBITDA margin ~8.5% pre-IFRS16 vs ~13-15% post-IFRS16, an accounting-driven step change, not organic margin gain) and because FY2022/23 windfall profits were retained rather than distributed. Revenue CAGR is used as the primary growth driver instead of equity CAGR because it is the cleanest, least distorted through-cycle series and is directly tied to the volume/branch-density growth drivers in the qualitative analysis.
A13: Note on 3yr CAGRs:
A14: 3yr CAGRs (FY23->FY26) are all negative because FY2023 was the peak of the COVID freight-rate super-spike (revenue $5,675.7m, EBITDA $851.0m, NPAT $426.5m) -- using FY2023 as a CAGR start point systematically understates growth. The 9-10yr through-cycle CAGRs (FY2017->FY2026) are used instead as they span a full up-cycle and down-cycle. Owner FCF CAGR cannot be cleanly computed pre/post IFRS16 (lease principal repayment is 0 pre-FY2020 as operating leases sat in opex instead), so the FY2020->FY2026 6yr owner-FCF CAGR (28.7%) is shown for reference only and not used as a growth driver -- it is distorted by FY2020 being an unusually low owner-FCF base (COVID-affected, high capex year, only 1.30% owner-FCF margin).

Sheet FCF Quality
A1: FCF Quality: Reported vs Owner FCF Reconciliation
A2: MFT.NZ: SBC is verified NIL. The material adjustment is IFRS16 lease principal repayment, a real recurring cash outflow excluded from the reported OCF-minus-capex FreeCashFlow figure.
A4: FY | B4: 2017 | C4: 2018 | D4: 2019 | E4: 2020 | F4: 2021 | G4: 2022 | H4: 2023 | I4: 2024 | J4: 2025 | K4: 2026
A5: Revenue | B5: 2333.591 | C5: 2618.86 | D5: 2954.087 | E5: 3095.394 | F5: 3543.838 | G5: 5218.259 | H5: 5675.709 | I5: 4717.796 | J5: 5236.437 | K5: 5383.52
A6: Reported FCF (OCF - capex) | B6: 63.927 | C6: 71.001 | D6: 94.147 | E6: 140.786 | F6: 254.204 | G6: 310.927 | H6: 433.318 | I6: 230.092 | J6: 330.739 | K6: 392.09
A7: Less: SBC (nil) | B7: 0 | C7: 0 | D7: 0 | E7: 0 | F7: 0 | G7: 0 | H7: 0 | I7: 0 | J7: 0 | K7: 0
A8: Less: IFRS16 Lease Principal | B8: 0 | C8: 0 | D8: 0 | E8: 100.644 | F8: 107.125 | G8: 119.336 | H8: 146.734 | I8: 182.85 | J8: 193.99 | K8: 209.505
A9: = Owner FCF | B9: 63.927 | C9: 71.001 | D9: 94.147 | E9: 40.142 | F9: 147.079 | G9: 191.591 | H9: 286.584 | I9: 47.242 | J9: 136.749 | K9: 182.585
A10: Reported FCF Margin % | B10: 2.7394261 | C10: 2.7111415 | D10: 3.1870084 | E10: 4.5482417 | F10: 7.173127 | G10: 5.9584432 | H10: 7.6346057 | I10: 4.8771079 | J10: 6.3161077 | K10: 7.283153
A11: Owner FCF Margin % | B11: 2.7394261 | C11: 2.7111415 | D11: 3.1870084 | E11: 1.2968301 | F11: 4.1502744 | G11: 3.6715502 | H11: 5.0493075 | I11: 1.0013574 | J11: 2.6114895 | K11: 3.3915542
A13: Memo: cash tax rate on EBIT (post-IFRS16)
A14: FY | B14: 2020 | C14: 2021 | D14: 2022 | E14: 2023 | F14: 2024 | G14: 2025 | H14: 2026
A15: Cash Tax Rate % | B15: 27.9 | C15: 24.2 | D15: 23 | E15: 29.7 | F15: 32.9 | G15: 24.2 | H15: 28.9
A16: Average ~27% is close to NZ statutory rate 28% -- no abnormal one-off, no ramp required.
A18: Memo: pre/post IFRS16 break
A19: FY2020 was the first year of IFRS16 adoption (lease principal repayment became a distinct cash flow line item, and D&A/EBITDA jumped structurally as operating lease rent moved out of opex). Pre-FY2020 FCF/EBITDA figures are NOT directly comparable to post-FY2020 figures for this reason.

Sheet Model_Info
A1: Model Provenance & Methodology
A3: Built by | B3: Claude Agent (dcf-analyst), per .claude/agents/dcf-analyst.md and Step 8/8c of .claude/skills/research-stock/SKILL.md
A4: Valuation date | B4: 2026-08-13
A5: Share price date/source | B5: NZ$69.01 - live Yahoo Finance quote fetched 2026-08-13 (MFT.NZ)
A6: Data vintage | B6: FY2026 annual report (year to 31 March 2026), H1-2026 interim (six months to 30 September 2025); MFT.NZ_Metrics.csv 20 periods FY2017-FY2026 + H1-2017..H1-2026; MFT.NZ_Analysis.json dated 2026-08-13
A7: Fiscal year | B7: Ends 31 March. FY2026 = year to 31-Mar-2026, used as the base year (complete and recent).
A8: SBC treatment | B8: Verified NIL - 10-K/annual report footnotes confirm no share-based payment expense since FY2019 (trivial $55k in FY2017 only). Share count static at 100,698,548 since FY2017. The SBC adjustment step is a genuine no-op, documented explicitly rather than skipped silently.
A9: Lease principal adjustment | B9: IFRS16 lease principal repayment (from kpis.LeasePrincipalRepayment) is deducted from reported FCF to reach owner FCF. FY2026: 392.09 - 209.505 = 182.59. Consequently net debt uses BANK/ASSET-FINANCE DEBT ONLY (excludes ~NZ$1.29bn IFRS16 lease liabilities) to avoid double-counting the same lease obligation as both a cash outflow and a balance-sheet liability.
A10: Interest income | B10: Not stripped - FY2026 interest income ($3.3m) is immaterial against a small net-cash position (~$26.6m), well below the 1x-FCF-base materiality threshold.
A11: Horizon | B11: 5 years explicit + Gordon Growth/15x cap terminal value. Base-case owner FCF margin is 4.33% (Y1) -> 5.25% (Y5), essentially flat by Y4-Y5 (capex and EBITDA margin paths deliberately held near steady-state from Y3 onward rather than tapering indefinitely), so a 5-year horizon is adequate without needing a 10-year extension.
A12: Growth driver | B12: Revenue 9-year through-cycle CAGR (FY2017->FY2026, 9.73%), spanning both the COVID freight-rate super-spike and its unwind. Equity CAGR (14.2%) was rejected as the primary driver despite the normal preference for it, because it is inflated by retained-earnings compounding on a static, zero-SBC, zero-buyback share base plus a one-off post-IFRS16 EBITDA-margin step change, not organic growth.
A13: Cyclicality handling | B13: FY2022/FY2023 (COVID freight-rate super-spike; FY2023 EBITDA $851.0m, NPAT $426.5m) explicitly excluded from historical multiple averages (Step 8c) and from 3-year CAGR windows (which would otherwise show negative growth off an unrepeatable peak). FY2026 is a soft-patch year (PBT -8.5%, H1 PBT -18.3%) reflecting global freight-rate weakness and a cost-discipline lag, not a structural declining growth rate.
A14: WACC | B14: 10.5% base (9.5% bull, 12.0% bear). No small-cap illiquidity premium (market cap ~NZ$6.9bn is large-cap for NZX). Premiums applied for freight-cycle earnings volatility (EBITDA range $398.7m FY2020 -> $851.0m FY2023 -> $759.8m FY2026, >2x swing) and offshore-execution/FX risk (66% of revenue generated offshore, Europe/Americas persistent underperformance).
... A19: Staleness warning | B19: All figures are point-in-time as of the valuation date above. Share price, WACC assumptions, and especially the freight-rate-cycle-dependent margin/growth assumptions must be re-checked against current conditions before relying on this model - do not treat it as evergreen.
