Workbook

Sheet Model_Info
A1: Ticker | B1: GNRC
A2: Company | B2: Generac Holdings Inc.
A3: Valuation date | B3: 2026-09-28
A4: Current price | B4: 208.14
A5: Price as of | B5: 2026-09-25T20:00:02Z regular close (Friday); valuation dated the following Monday
A6: Balance sheet date | B6: 2026-06-30
A7: Model | B7: owner_fcf_dcf_component
A8: Currency (model) | B8: USD
A9: Currency (quote) | B9: USD
A10: Units | B10: millions
A11: Engine | B11: dcf_engine v1
A12: Built at | B12: 2026-09-28T08:56:09Z
A13: Drivers file | B13: GNRC_Drivers.json
A14: Convention | B14: Percents stored as percents; formulas divide by 100. Blue = input, green = link, black = formula.
A15: Methodology | B15: summary: Owner-FCF DCF with SBC and equity-award withholding fully expensed, share count held flat, working capital charged on revenue growth (manufacturer, negative capture), a 10-year horizon so the data-center mix and margin ramp mature before capitalisation, and a 15x owner-FCF terminal cap (Gordon at ~12x binds; ~7x EV/EBITDA) because Generac is a cyclical industrial whose earnings round-tripped between 2021 and 2023. Discounted at 11.5% USD: a 10% market WACC plus an explicit +1.5% customer-concentration premium for the hyperscaler/Amazon dependence of the FY2027-28 step-up. Base case is anchored to the contracted backlog and the top of the pre-Amazon Investor Day FY2028 range (~$6.6B); Amazon conversion beyond a small slice is bull-case upside. Cyclicality and execution are charged in the scenario spread and a 25/50/25 weighting. House basis is the headline; the street (SBC-as-non-cash) basis is a memo. key_risks_to_valuation: Hyperscale/AI data-center capex pause or delay: the FY2027-28 revenue step-up in every scenario rests on backlog conversion by a handful of customers; a slip moves value toward the bear case quickly.; Customer concentration: the Amazon agreement (initial $2.4B, up to $8B) is roughly half the announced 2027-28 pipeline; the warrants also make Amazon's purchasing partly self-interested rather than contractual.; Residential storm-cycle lumpiness: home-standby demand spikes and troughs with outage activity; 2022-23 showed how fast a 24% margin becomes 16%.; Execution in large-scale switchgear and power infrastructure against entrenched incumbents (Caterpillar, Cummins, Eaton) and the risk of under-absorbed new capacity if demand slips.; FY2026 margin guidance includes ~1.5pt of one-off tariff refunds; tariff policy and commodity (steel, copper, battery cell) costs can move margins either way.; Adjusted-EBITDA basis: Generac excludes legal/regulatory/clean-energy charges most years; the model haircuts 0.5pt but a larger recurring gap (FY2025 GAAP EBITDA was ~5.5pts below adjusted) would lower every scenario.; Working-capital intensity (~30% of revenue): a faster ramp than modelled consumes more cash than the -15% capture assumes unless hyperscale deposits are larger than expected. sanity_check_revision: date: 2026-09-28 trigger: scripts/sanity_check.py: implied P/E 88.7x on trailing GAAP EPS exceeded 2x the 10yr average (34.7x); P/B 3.75x, EV/EBITDA 24.9x and P/S 2.35x were inside their bounds. diagnosis: Mostly a denominator artefact -- FY2025 GAAP EPS ($2.73, Q4 negative) is compressed by ~$180M of non-SBC charges and $102M of acquired-intangible amortisation, and TTM GAAP EPS through Q2 2026 is $4.41 (on which the prior IV was ~37x). But two of the check's candidates were genuinely under-charged: hyperscaler customer concentration sat in the scenario weights rather than the discount rate, and the base case front-loaded Amazon volumes that the warrant structure shows are not firm. changes: WACC 10.0% -> 11.5% in all three scenarios: +1.5% explicit customer-concentration premium (Amazon agreement ~50% of the FY2027-28 pipeline; low end of the 1.5-2.5% range because the residential dealer channel carries no concentration). Weighted IV effect -$34.11/share.; Base FY2027 growth 24% -> 20% and FY2028 14% -> 12%: FY2028 revenue re-anchored from ~$7.1B to ~$6.6B, the top of the pre-Amazon Investor Day range; Amazon conversion moves to the bull case. Weighted IV effect -$3.21/share.; Not applied: mid-cycle FCF rebuild (FY2025 owner FCF of $204M is a trough, not a peak; year-1 owner FCF ~$390M sits between FY2025 and FY2024's $530M). Not applied: a per-year growth cap at the 10.3% through-cycle CAGR (the FY2026-27 growth is guidance and contracted backlog; the base 10-year CAGR of 6.9% is already below it). Not binding: EV/EBITDA exit caps of 9.6x/17.7x/29.6x -- the terminal EV/EBITDA is ~7x under the existing 15x owner-FCF cap.; Unchanged and deliberately so: margin paths, SBC/D&A/capex/tax paths, working-capital capture, 25/50/25 weights, bull and bear growth paths, 15x terminal cap. Evidence that would move them: FY2026 results showing the tariff-refund benefit is recurring (margins), a firm take-or-pay amendment to the Amazon agreement (base growth and the WACC premium), or a Q4 2026 GAAP-to-adjusted gap that persists (margin haircut). result: Weighted IV $162.09 -> $124.77 (-23%); the implied P/E on the check's trailing denominator falls to roughly 68x, inside the 2x bound, while P/S (~1.8x) and P/B (~2.9x) sit well below their 10yr averages. The dashboard should read the valuation as deliberately conservative on the multiples that use trough GAAP earnings.
A16: Data sources | B16: price: Yahoo Finance chart API regular close at inputs.price_as_of; 52-week range 134.80-296.44. financials: SEC XBRL companyfacts for CIK 1474735 via GNRC_Metrics.csv (FY2012-Q2 2026); balance sheet, share count, dilutive securities, interest expense, D&A split, tax paid, buybacks, equity-award withholding and acquisition spend read from the same companyfacts feed (10-K FY2025 filed 2026-02-13; 10-Q Q2 2026 filed 2026-07-31). No extracted filing text exists for this ticker. qualitative: GNRC_Analysis.json (2026-09-28): Q2 2026 results and raised guidance (29 July 2026), March 2026 Investor Day FY2028 targets, Enercon acquisition, September 2026 Amazon supply agreement and warrants.
... A19: Scenario narrative: bull | B19: Generac becomes a structural AI-infrastructure supplier: the 2027 backlog and Amazon's initial $2.4B ship on schedule, Amazon exercises toward the $8B ceiling, further hyperscalers sign, and Enercon capacity lets C&I reach parity with residential by 2028 (~$7.9B). Scale in large gensets and switchgear lifts the adjusted margin to 23.5% by FY2030, and residential compounds on an active storm cycle, rising power prices and PWRcell attach. Even so, growth fades to 3% by the mid-2030s and the terminal value stays capped at a cyclical multiple.

Sheet Reconciliation
A1: Item | B1: Value | C1: Note
A2: Prior valuation_date | B2: 2026-09-28
A3: Prior price_then | B3: 208.14
A4: Prior bear | B4: 86.26
A5: Prior base | B5: 166.76
A6: Prior bull | B6: 228.57
A7: Prior weighted | B7: 162.09
A8: Prior note | B8: Fresh build earlier the same day, WACC 10.0%, base FY2027-28 growth 24%/14%; superseded after the multiples sanity check tripped.
A9: New valuation_date | B9: 2026-09-28
A10: New price_then | B10: 208.14
A11: New bear | B11: 68.32
A12: New base | B12: 125.2
A13: New bull | B13: 180.38
A14: New weighted | B14: 124.77
A16: Bridge
A17: Prior weighted IV | B17: 162.09
A18: Anchor refresh (price, net debt, shares): none, same-day | B18: 0
A19: WACC 10.0% -> 11.5%: +1.5% customer-concentration premium, all scenarios | B19: -34.11
A20: Base FY2027/28 growth 24%/14% -> 20%/12% (FY2028 revenue re-anchored to Investor Day top of range) | B20: -3.21
A21: New weighted IV | B21: 124.77 | C21: ties to probability_weighted.weighted_iv

Sheet Actuals
A1: Period | B1: Revenue | C1: CostOfRevenue | D1: GrossProfit | E1: GrossMargin | F1: OperatingIncome | G1: OperatingMargin | H1: EBITDA | I1: NetIncome | J1: NetMargin | K1: EPS | L1: OperatingCashFlow | M1: CapEx | N1: FreeCashFlow | O1: ShareholdersEquity | P1: TotalAssets | Q1: TotalLiabilities | R1: TotalDebt | S1: CashAndEquivalents | T1: SharesOutstanding | U1: StockBasedComp | V1: DividendPerShare | W1: EBITDABeforeSignificant | X1: RevenueContinuing | Y1: EBITDAContinuingBeforeSignificant | Z1: EBITContinuingBeforeSignificant | AA1: Units | AB1: Currency
A2: FY2008 | O2: -810.194 | S2: 81.229 | AA2: millions | AB2: USD
A3: FY2009 | D3: 235.85 | F3: 98.512 | I3: 43.055 | L3: 74.607 | M3: 4.525 | N3: 70.082 | O3: -742.814 | S3: 161.307 | U3: 0.038 | AA3: millions | AB3: USD
A4: FY2010 | D4: 237.357 | F4: 90.296 | I4: 56.913 | L4: 114.481 | M4: 9.631 | N4: 104.85 | O4: 441.067 | P4: 1209.883 | Q4: 768.816 | R4: 657.229 | S4: 78.583 | U4: 6.363 | V4: 0 | AA4: millions | AB4: USD
A5: FY2011 | D5: 294.654 | F5: 112.981 | I5: 324.643 | K5: 4.84 | L5: 169.712 | M5: 12.06 | N5: 157.652 | O5: 768.889 | P5: 1552.793 | Q5: 783.904 | R5: 627.246 | S5: 93.126 | T5: 67.797371 | U5: 8.646 | V5: 0 | AA5: millions | AB5: USD
A6: FY2012 | B6: 1176.306 | D6: 440.4 | E6: 37.439238 | F6: 223.555 | G6: 19.004834 | I6: 93.223 | J6: 7.9250637 | K6: 1.38 | L6: 235.594 | M6: 22.392 | N6: 213.202 | O6: 463.628 | P6: 1603.847 | Q6: 1140.219 | R6: 881.268 | S6: 108.023 | T6: 69.193138 | U6: 10.78 | V6: 6 | AA6: millions | AB6: USD
A7: FY2013 | B7: 1485.765 | D7: 569.56 | E7: 38.334461 | F7: 351.465 | G7: 23.655491 | I7: 174.539 | J7: 11.747416 | K7: 2.56 | L7: 259.944 | M7: 30.77 | N7: 229.174 | O7: 317.071 | P7: 1798.205 | Q7: 1481.134 | R7: 1187.82 | S7: 150.147 | T7: 69.667529 | U7: 12.368 | V7: 5 | AA7: millions | AB7: USD
A8: FY2014 | B8: 1460.919 | D8: 516.219 | E8: 35.335224 | F8: 293.375 | G8: 20.081538 | H8: 328.105 | I8: 174.613 | J8: 11.952271 | K8: 2.55 | L8: 252.986 | M8: 34.689 | N8: 218.297 | O8: 489.799 | P8: 1864.419 | Q8: 1392.743 | R8: 1082.658 | S8: 189.761 | T8: 70.171044 | U8: 12.612 | V8: 0 | AA8: millions | AB8: USD
A9: FY2015 | B9: 1317.299 | D9: 459.95 | E9: 34.916143 | F9: 179.561 | G9: 13.630998 | H9: 219.894 | I9: 77.747 | J9: 5.902001 | K9: 1.14 | L9: 188.619 | M9: 30.651 | N9: 157.968 | O9: 465.871 | P9: 1778.635 | Q9: 1312.764 | R9: 1037.789 | S9: 115.857 | T9: 69.200297 | U9: 8.241 | AA9: millions | AB9: USD
A10: FY2016 | B10: 1447.743 | C10: 935.322 | D10: 512.421 | E10: 35.394473 | F10: 202.752 | G10: 14.004696 | H10: 257.17 | I10: 97.178 | J10: 6.7123792 | K10: 1.48 | L10: 241.122 | M10: 30.467 | N10: 210.655 | O10: 397.179 | P10: 1865.969 | Q10: 1427.434 | R10: 1021.723 | S10: 67.272 | T10: 65.382774 | U10: 9.493 | AA10: millions | AB10: USD
A11: FY2017 | B11: 1679.373 | C11: 1094.587 | D11: 584.786 | E11: 34.821686 | F11: 250.634 | G11: 14.92426 | H11: 302.622 | I11: 159.557 | J11: 9.5009864 | K11: 2.56 | L11: 257.322 | M11: 33.261 | N11: 224.061 | O11: 554.32 | P11: 2025.965 | Q11: 1427.716 | R11: 908.12 | S11: 138.472 | T11: 62.642872 | U11: 10.205 | AA11: millions | AB11: USD
A12: FY2018 | B12: 2023.464 | C12: 1298.424 | D12: 725.04 | E12: 35.831623 | F12: 357.181 | G12: 17.651957 | H12: 404.589 | I12: 241.22 | J12: 11.921141 | K12: 3.57 | L12: 247.227 | M12: 47.601 | N12: 199.626 | O12: 761.261 | P12: 2426.314 | Q12: 1604.049 | R12: 878.373 | S12: 224.482 | T12: 62.233225 | U12: 14.563 | AA12: millions | AB12: USD
A13: FY2019 | B13: 2204.336 | C13: 1406.584 | D13: 797.752 | E13: 36.190127 | F13: 372.163 | G13: 16.883225 | H13: 432.93 | I13: 252.308 | J13: 11.445986 | K13: 4.09 | L13: 308.887 | M13: 60.802 | N13: 248.085 | O13: 1032.851 | P13: 2665.669 | Q13: 1571.591 | R13: 840.15 | S13: 322.883 | T13: 62.865446 | U13: 16.694 | AA13: millions | AB13: USD
A14: FY2020 | B14: 2485.2 | C14: 1527.546 | D14: 957.654 | E14: 38.534283 | F14: 479.106 | G14: 19.278368 | H14: 547.879 | I14: 350.576 | J14: 14.106551 | K14: 5.61 | L14: 486.533 | M14: 62.128 | N14: 424.405 | O14: 1390.204 | P14: 3235.423 | Q14: 1779.012 | R14: 845.911 | S14: 655.128 | T14: 63.737734 | U14: 20.882 | AA14: millions | AB14: USD
A15: FY2021 | B15: 3737.184 | C15: 2377.102 | D15: 1360.082 | E15: 36.393231 | F15: 721.136 | G15: 19.29624 | H15: 813.177 | I15: 556.569 | J15: 14.892737 | K15: 8.51 | L15: 411.156 | M15: 109.992 | N15: 301.164 | O15: 2214.087 | P15: 4877.78 | Q15: 2605.643 | R15: 908.021 | S15: 147.339 | T15: 64.253408 | U15: 23.954 | AA15: millions | AB15: USD
A16: FY2022 | B16: 4564.737 | C16: 3042.733 | D16: 1522.004 | E16: 33.342644 | F16: 566.33 | G16: 12.406629 | H16: 722.471 | I16: 408.87 | J16: 8.9571425 | K16: 5.55 | L16: 58.516 | M16: 86.188 | N16: -27.672 | O16: 2259.255 | P16: 5169.462 | Q16: 2799.736 | R16: 1381.818 | S16: 132.723 | T16: 64.681357 | U16: 29.481 | AA16: millions | AB16: USD
A17: FY2023 | B17: 4022.667 | C17: 2657.236 | D17: 1365.431 | E17: 33.943426 | F17: 386.199 | G17: 9.600571 | H17: 552.801 | I17: 217.12 | J17: 5.3974142 | K17: 3.31 | L17: 521.67 | M17: 129.06 | N17: 392.61 | O17: 2343.07 | P17: 5093.312 | Q17: 2743.693 | R17: 1493.448 | S17: 200.994 | T17: 62.058387 | U17: 35.492 | AA17: millions | AB17: USD
A18: FY2024 | B18: 4295.834 | C18: 2630.208 | D18: 1665.626 | E18: 38.773053 | F18: 536.742 | G18: 12.494477 | H18: 708.51 | I18: 316.978 | J18: 7.3787302 | K18: 5.46 | L18: 741.301 | M18: 136.733 | N18: 604.568 | O18: 2497.443 | P18: 5109.331 | Q18: 2611.888 | R18: 1278.374 | S18: 281.277 | T18: 60.350412 | U18: 49.248 | AA18: millions | AB18: USD
A19: FY2025 | B19: 4209.147 | C19: 2597.41 | D19: 1611.737 | E19: 38.291298 | F19: 289.191 | G19: 6.870537 | H19: 484.026 | I19: 161.354 | J19: 3.8334133 | K19: 2.73 | L19: 437.978 | M19: 169.85 | N19: 268.128 | O19: 2638.304 | P19: 5573.679 | Q19: 2934.633 | R19: 1282.448 | S19: 341.413 | T19: 59.275781 | U19: 49.947 | AA19: millions | AB19: USD

Sheet Assumptions
A1: Input | B1: Value
A2: Current price (quote currency) | B2: 208.14
A3: Shares, final projected (m) | B3: 59.8
A4: Net debt (m, model currency) | B4: 1016.1
A5: Equity bridge total (m, + adds) | B5: 0
A6: Hurdle rate (%) | B6: 15
A7: Base revenue FY0 (m) | B7: 4209.147
A8: FY0 | B8: FY2025
A9: Currency / units | B9: USD millions
A10: FX rate (model -> quote) | B10: 1
A12: BEAR | C12: FY2026 | D12: FY2027 | E12: FY2028 | F12: FY2029 | G12: FY2030 | H12: FY2031 | I12: FY2032 | J12: FY2033 | K12: FY2034 | L12: FY2035
A13: Revenue growth (%) | C13: 15 | D13: 10 | E13: 3 | F13: -3 | G13: 2 | H13: 3 | I13: 3 | J13: 3 | K13: 2.5 | L13: 2.5
A14: EBITDA margin (%) | C14: 19.5 | D14: 17.5 | E14: 16.5 | F14: 16 | G14: 17 | H14: 17.5 | I14: 18 | J14: 18 | K14: 18 | L14: 18
A15: SBC (% of revenue) | C15: 1.8 | D15: 1.6 | E15: 1.5 | F15: 1.4 | G15: 1.4 | H15: 1.3 | I15: 1.3 | J15: 1.2 | K15: 1.2 | L15: 1.2
A16: Lease cost (% of revenue) | C16: 0 | D16: 0 | E16: 0 | F16: 0 | G16: 0 | H16: 0 | I16: 0 | J16: 0 | K16: 0 | L16: 0
A17: D&A (% of revenue) | C17: 4 | D17: 3.8 | E17: 3.6 | F17: 3.4 | G17: 3.2 | H17: 3.1 | I17: 3 | J17: 3 | K17: 3 | L17: 3
A18: Capex (% of revenue) | C18: 4.5 | D18: 4.2 | E18: 3.6 | F18: 3.3 | G18: 3.2 | H18: 3.2 | I18: 3.2 | J18: 3.2 | K18: 3.2 | L18: 3.2
A19: Cash tax rate (%) | C19: 25 | D19: 25 | E19: 25 | F19: 25 | G19: 25 | H19: 25 | I19: 25 | J19: 25 | K19: 25 | L19: 25
A20: WACC (%) | B20: 11.5
A21: Terminal growth (%) | B21: 2.5
A22: Terminal cap multiple (x FCF) | B22: 15
A23: Working-capital capture (% of revenue change) | B23: -15
A24: Scenario weight | B24: 0.25
A26: BASE | C26: FY2026 | D26: FY2027 | E26: FY2028 | F26: FY2029 | G26: FY2030 | H26: FY2031 | I26: FY2032 | J26: FY2033 | K26: FY2034 | L26: FY2035
A27: Revenue growth (%) | C27: 17 | D27: 20 | E27: 12 | F27: 6 | G27: 4 | H27: 3.5 | I27: 3 | J27: 3 | K27: 3 | L27: 2.5
A28: EBITDA margin (%) | C28: 20 | D28: 19.8 | E28: 20.5 | F28: 21 | G28: 21.3 | H28: 21.5 | I28: 21.5 | J28: 21.5 | K28: 21.5 | L28: 21.5
A29: SBC (% of revenue) | C29: 1.8 | D29: 1.6 | E29: 1.5 | F29: 1.4 | G29: 1.4 | H29: 1.3 | I29: 1.3 | J29: 1.2 | K29: 1.2 | L29: 1.2
A30: Lease cost (% of revenue) | C30: 0 | D30: 0 | E30: 0 | F30: 0 | G30: 0 | H30: 0 | I30: 0 | J30: 0 | K30: 0 | L30: 0
A31: D&A (% of revenue) | C31: 4 | D31: 3.8 | E31: 3.6 | F31: 3.4 | G31: 3.2 | H31: 3.1 | I31: 3 | J31: 3 | K31: 3 | L31: 3
A32: Capex (% of revenue) | C32: 4.5 | D32: 4.5 | E32: 4 | F32: 3.8 | G32: 3.5 | H32: 3.4 | I32: 3.3 | J32: 3.2 | K32: 3.2 | L32: 3.2
A33: Cash tax rate (%) | C33: 25 | D33: 25 | E33: 25 | F33: 25 | G33: 25 | H33: 25 | I33: 25 | J33: 25 | K33: 25 | L33: 25
A34: WACC (%) | B34: 11.5
A35: Terminal growth (%) | B35: 3
A36: Terminal cap multiple (x FCF) | B36: 15
A37: Working-capital capture (% of revenue change) | B37: -15
A38: Scenario weight | B38: 0.5
A40: BULL | C40: FY2026 | D40: FY2027 | E40: FY2028 | F40: FY2029 | G40: FY2030 | H40: FY2031 | I40: FY2032 | J40: FY2033 | K40: FY2034 | L40: FY2035
A41: Revenue growth (%) | C41: 18 | D41: 32 | E41: 20 | F41: 10 | G41: 6 | H41: 5 | I41: 4 | J41: 3.5 | K41: 3 | L41: 3
A42: EBITDA margin (%) | C42: 20.5 | D42: 21 | E42: 22 | F42: 23 | G42: 23.5 | H42: 23.5 | I42: 23.5 | J42: 23.5 | K42: 23.5 | L42: 23.5
A43: SBC (% of revenue) | C43: 1.8 | D43: 1.6 | E43: 1.5 | F43: 1.4 | G43: 1.4 | H43: 1.3 | I43: 1.3 | J43: 1.2 | K43: 1.2 | L43: 1.2
...

Sheet DCF_Bear
A1: GNRC owner-FCF component DCF: bear case (millions, USD)
A3: Line | B3: FY2025 | C3: FY2026 | D3: FY2027 | E3: FY2028 | F3: FY2029 | G3: FY2030 | H3: FY2031 | I3: FY2032 | J3: FY2033 | K3: FY2034 | L3: FY2035
A4: Year index (discount exponent) | B4: 0 | C4: =B4+1 -> 1 | D4: =C4+1 -> 2 | E4: =D4+1 -> 3 | F4: =E4+1 -> 4 | G4: =F4+1 -> 5 | H4: =G4+1 -> 6 | I4: =H4+1 -> 7 | J4: =I4+1 -> 8 | ... L4: =K4+1 -> 10
A5: Revenue growth (%) | C5: =Assumptions!C13 -> 15 | D5: =Assumptions!D13 -> 10 | E5: =Assumptions!E13 -> 3 | F5: =Assumptions!F13 -> -3 | G5: =Assumptions!G13 -> 2 | H5: =Assumptions!H13 -> 3 | I5: =Assumptions!I13 -> 3 | J5: =Assumptions!J13 -> 3 | ... L5: =Assumptions!L13 -> 2.5
A6: Revenue | B6: 4209.147 | C6: =B6*(1+C5/100) -> 4840.519 | D6: =C6*(1+D5/100) -> 5324.571 | E6: =D6*(1+E5/100) -> 5484.3081 | F6: =E6*(1+F5/100) -> 5319.7788 | G6: =F6*(1+G5/100) -> 5426.1744 | H6: =G6*(1+H5/100) -> 5588.9597 | I6: =H6*(1+I5/100) -> 5756.6284 | J6: =I6*(1+J5/100) -> 5929.3273 | ... L6: =K6*(1+L5/100) -> 6229.4995
A7: EBITDA margin (%) | C7: =Assumptions!C14 -> 19.5 | D7: =Assumptions!D14 -> 17.5 | E7: =Assumptions!E14 -> 16.5 | F7: =Assumptions!F14 -> 16 | G7: =Assumptions!G14 -> 17 | H7: =Assumptions!H14 -> 17.5 | I7: =Assumptions!I14 -> 18 | J7: =Assumptions!J14 -> 18 | ... L7: =Assumptions!L14 -> 18
A8: EBITDA | C8: =C6*C7/100 -> 943.90121 | D8: =D6*D7/100 -> 931.79992 | E8: =E6*E7/100 -> 904.91083 | F8: =F6*F7/100 -> 851.16461 | G8: =G6*G7/100 -> 922.44965 | H8: =H6*H7/100 -> 978.06794 | I8: =I6*I7/100 -> 1036.1931 | J8: =J6*J7/100 -> 1067.2789 | ... L8: =L6*L7/100 -> 1121.3099
A9: SBC (% of revenue) | C9: =Assumptions!C15 -> 1.8 | D9: =Assumptions!D15 -> 1.6 | E9: =Assumptions!E15 -> 1.5 | F9: =Assumptions!F15 -> 1.4 | G9: =Assumptions!G15 -> 1.4 | H9: =Assumptions!H15 -> 1.3 | I9: =Assumptions!I15 -> 1.3 | J9: =Assumptions!J15 -> 1.2 | ... L9: =Assumptions!L15 -> 1.2
A10: SBC charge | C10: =-C6*C9/100 -> -87.129343 | D10: =-D6*D9/100 -> -85.193135 | E10: =-E6*E9/100 -> -82.264621 | F10: =-F6*F9/100 -> -74.476904 | G10: =-G6*G9/100 -> -75.966442 | H10: =-H6*H9/100 -> -72.656475 | I10: =-I6*I9/100 -> -74.83617 | J10: =-J6*J9/100 -> -71.151928 | ... L10: =-L6*L9/100 -> -74.753994
A11: Owner EBITDA (after SBC and leases) | C11: =C8+C10+C24 -> 856.77187 | D11: =D8+D10+D24 -> 846.60678 | E11: =E8+E10+E24 -> 822.64621 | F11: =F8+F10+F24 -> 776.68771 | G11: =G8+G10+G24 -> 846.48321 | H11: =H8+H10+H24 -> 905.41146 | I11: =I8+I10+I24 -> 961.35695 | J11: =J8+J10+J24 -> 996.12699 | ... L11: =L8+L10+L24 -> 1046.5559
A12: D&A | C12: =-C6*Assumptions!C17/100 -> -193.62076 | D12: =-D6*Assumptions!D17/100 -> -202.3337 | E12: =-E6*Assumptions!E17/100 -> -197.43509 | F12: =-F6*Assumptions!F17/100 -> -180.87248 | G12: =-G6*Assumptions!G17/100 -> -173.63758 | H12: =-H6*Assumptions!H17/100 -> -173.25775 | I12: =-I6*Assumptions!I17/100 -> -172.69885 | J12: =-J6*Assumptions!J17/100 -> -177.87982 | ... L12: =-L6*Assumptions!L17/100 -> -186.88498
A13: EBIT | C13: =C11+C12 -> 663.15111 | D13: =D11+D12 -> 644.27309 | E13: =E11+E12 -> 625.21112 | F13: =F11+F12 -> 595.81523 | G13: =G11+G12 -> 672.84563 | H13: =H11+H12 -> 732.15371 | I13: =I11+I12 -> 788.6581 | J13: =J11+J12 -> 818.24717 | ... L13: =L11+L12 -> 859.67093
A14: Cash tax rate (%) | C14: =Assumptions!C19 -> 25 | D14: =Assumptions!D19 -> 25 | E14: =Assumptions!E19 -> 25 | F14: =Assumptions!F19 -> 25 | G14: =Assumptions!G19 -> 25 | H14: =Assumptions!H19 -> 25 | I14: =Assumptions!I19 -> 25 | J14: =Assumptions!J19 -> 25 | ... L14: =Assumptions!L19 -> 25
A15: NOPAT | C15: =C13-MAX(0,C13)*C14/100 -> 497.36333 | D15: =D13-MAX(0,D13)*D14/100 -> 483.20481 | E15: =E13-MAX(0,E13)*E14/100 -> 468.90834 | F15: =F13-MAX(0,F13)*F14/100 -> 446.86142 | G15: =G13-MAX(0,G13)*G14/100 -> 504.63422 | H15: =H13-MAX(0,H13)*H14/100 -> 549.11529 | I15: =I13-MAX(0,I13)*I14/100 -> 591.49357 | J15: =J13-MAX(0,J13)*J14/100 -> 613.68537 | ... L15: =L13-MAX(0,L13)*L14/100 -> 644.7532
A16: D&A add-back | C16: =-C12 -> 193.62076 | D16: =-D12 -> 202.3337 | E16: =-E12 -> 197.43509 | F16: =-F12 -> 180.87248 | G16: =-G12 -> 173.63758 | H16: =-H12 -> 173.25775 | I16: =-I12 -> 172.69885 | J16: =-J12 -> 177.87982 | ... L16: =-L12 -> 186.88498
A17: Capex | C17: =-C6*Assumptions!C18/100 -> -217.82336 | D17: =-D6*Assumptions!D18/100 -> -223.63198 | E17: =-E6*Assumptions!E18/100 -> -197.43509 | F17: =-F6*Assumptions!F18/100 -> -175.5527 | G17: =-G6*Assumptions!G18/100 -> -173.63758 | H17: =-H6*Assumptions!H18/100 -> -178.84671 | I17: =-I6*Assumptions!I18/100 -> -184.21211 | J17: =-J6*Assumptions!J18/100 -> -189.73847 | ... L17: =-L6*Assumptions!L18/100 -> -199.34398
A18: Working capital | C18: =(C6-B6)*Assumptions!$B$23/100 -> -94.705808 | D18: =(D6-C6)*Assumptions!$B$23/100 -> -72.607786 | E18: =(E6-D6)*Assumptions!$B$23/100 -> -23.960569 | F18: =(F6-E6)*Assumptions!$B$23/100 -> 24.679386 | G18: =(G6-F6)*Assumptions!$B$23/100 -> -15.959337 | H18: =(H6-G6)*Assumptions!$B$23/100 -> -24.417785 | I18: =(I6-H6)*Assumptions!$B$23/100 -> -25.150318 | J18: =(J6-I6)*Assumptions!$B$23/100 -> -25.904828 | ... L18: =(L6-K6)*Assumptions!$B$23/100 -> -22.790852
A19: Unlevered owner FCF | C19: =C15+C16+C17+C18 -> 378.45493 | D19: =D15+D16+D17+D18 -> 389.29874 | E19: =E15+E16+E17+E18 -> 444.94777 | F19: =F15+F16+F17+F18 -> 476.86059 | G19: =G15+G16+G17+G18 -> 488.67488 | H19: =H15+H16+H17+H18 -> 519.10854 | I19: =I15+I16+I17+I18 -> 554.83 | J19: =J15+J16+J17+J18 -> 575.92189 | ... L19: =L15+L16+L17+L18 -> 609.50335
A20: Discount factor | C20: =1/(1+$B$27/100)^C4 -> 0.89686099 | D20: =1/(1+$B$27/100)^D4 -> 0.80435963 | E20: =1/(1+$B$27/100)^E4 -> 0.72139877 | F20: =1/(1+$B$27/100)^F4 -> 0.64699441 | G20: =1/(1+$B$27/100)^G4 -> 0.58026405 | H20: =1/(1+$B$27/100)^H4 -> 0.52041619 | I20: =1/(1+$B$27/100)^I4 -> 0.46674097 | J20: =1/(1+$B$27/100)^J4 -> 0.41860177 | ... L20: =1/(1+$B$27/100)^L4 -> 0.33670636
A21: PV of FCF | C21: =C19*C20 -> 339.42146 | D21: =D19*D20 -> 313.13619 | E21: =E19*E20 -> 320.98478 | F21: =F19*F20 -> 308.52614 | G21: =G19*G20 -> 283.56047 | H21: =H19*H20 -> 270.15249 | I21: =I19*I20 -> 258.96189 | J21: =J19*J20 -> 241.08192 | ... L21: =L19*L20 -> 205.22366
A23: Lease cost (% of revenue) | C23: =Assumptions!C16 -> 0 | D23: =Assumptions!D16 -> 0 | E23: =Assumptions!E16 -> 0 | F23: =Assumptions!F16 -> 0 | G23: =Assumptions!G16 -> 0 | H23: =Assumptions!H16 -> 0 | I23: =Assumptions!I16 -> 0 | J23: =Assumptions!J16 -> 0 | ... L23: =Assumptions!L16 -> 0
A24: Lease cost | C24: =-C6*C23/100 -> 0 | D24: =-D6*D23/100 -> 0 | E24: =-E6*E23/100 -> 0 | F24: =-F6*F23/100 -> 0 | G24: =-G6*G23/100 -> 0 | H24: =-H6*H23/100 -> 0 | I24: =-I6*I23/100 -> 0 | J24: =-J6*J23/100 -> 0 | ... L24: =-L6*L23/100 -> 0
A26: Valuation
A27: WACC (%) | B27: =Assumptions!$B$20 -> 11.5
A28: Terminal growth (%) | B28: =Assumptions!$B$21 -> 2.5
A29: Terminal cap multiple (x FCF) | B29: =Assumptions!$B$22 -> 15
A30: Sum of PV of FCF | B30: =SUM(C21:L21) -> 2764.2923
A31: Terminal-year FCF | B31: =L19 -> 609.50335
A32: Gordon terminal value | B32: =IF(B27>B28,B31*(1+B28/100)/((B27-B28)/100),B31*B29) -> 6941.5659
A33: Cap terminal value | B33: =B31*B29 -> 9142.5502
A34: Terminal value used: MAX(0,MIN(Gordon,cap)) | B34: =MAX(0,MIN(B32,B33)) -> 6941.5659
A35: PV of terminal value | B35: =B34/(1+B27/100)^L4 -> 2337.2694
A36: Enterprise value | B36: =B30+B35 -> 5101.5617
A37: Equity value (EV + bridge - net debt) | B37: =B36+Assumptions!$B$5-Assumptions!$B$4 -> 4085.4617
A38: Value per share (quote currency) | B38: =B37/Assumptions!$B$3*Assumptions!$B$10 -> 68.318758
A39: Upside vs price | B39: =B38/Assumptions!$B$2-1 -> -0.67176536
A41: Street memo: PV of explicit-period SBC | B41: =SUMPRODUCT(-C10:L10/(1+$B$27/100)^C4:L4) -> 453.35655
A42: Street memo: PV of terminal SBC (Gordon) | B42: =IF(B27>B28,-L10*(1+B28/100)/((B27-B28)/100),-L10*20)/(1+B27/100)^L4 -> 286.65999
A43: Street value per share | B43: =(B37+B41+B42)/Assumptions!$B$3*Assumptions!$B$10 -> 80.693616
A45: Hurdle rate (%) | B45: =Assumptions!$B$6 -> 15
...

Sheet DCF_Base
A1: GNRC owner-FCF component DCF: base case (millions, USD)
A3: Line | B3: FY2025 | C3: FY2026 | D3: FY2027 | E3: FY2028 | F3: FY2029 | G3: FY2030 | H3: FY2031 | I3: FY2032 | J3: FY2033 | K3: FY2034 | L3: FY2035
A4: Year index (discount exponent) | B4: 0 | C4: =B4+1 -> 1 | D4: =C4+1 -> 2 | E4: =D4+1 -> 3 | F4: =E4+1 -> 4 | G4: =F4+1 -> 5 | H4: =G4+1 -> 6 | I4: =H4+1 -> 7 | J4: =I4+1 -> 8 | ... L4: =K4+1 -> 10
A5: Revenue growth (%) | C5: =Assumptions!C27 -> 17 | D5: =Assumptions!D27 -> 20 | E5: =Assumptions!E27 -> 12 | F5: =Assumptions!F27 -> 6 | G5: =Assumptions!G27 -> 4 | H5: =Assumptions!H27 -> 3.5 | I5: =Assumptions!I27 -> 3 | J5: =Assumptions!J27 -> 3 | ... L5: =Assumptions!L27 -> 2.5
A6: Revenue | B6: 4209.147 | C6: =B6*(1+C5/100) -> 4924.702 | D6: =C6*(1+D5/100) -> 5909.6424 | E6: =D6*(1+E5/100) -> 6618.7995 | F6: =E6*(1+F5/100) -> 7015.9274 | G6: =F6*(1+G5/100) -> 7296.5645 | H6: =G6*(1+H5/100) -> 7551.9443 | I6: =H6*(1+I5/100) -> 7778.5026 | J6: =I6*(1+J5/100) -> 8011.8577 | ... L6: =K6*(1+L5/100) -> 8458.5188
A7: EBITDA margin (%) | C7: =Assumptions!C28 -> 20 | D7: =Assumptions!D28 -> 19.8 | E7: =Assumptions!E28 -> 20.5 | F7: =Assumptions!F28 -> 21 | G7: =Assumptions!G28 -> 21.3 | H7: =Assumptions!H28 -> 21.5 | I7: =Assumptions!I28 -> 21.5 | J7: =Assumptions!J28 -> 21.5 | ... L7: =Assumptions!L28 -> 21.5
A8: EBITDA | C8: =C6*C7/100 -> 984.9404 | D8: =D6*D7/100 -> 1170.1092 | E8: =E6*E7/100 -> 1356.8539 | F8: =F6*F7/100 -> 1473.3448 | G8: =G6*G7/100 -> 1554.1682 | H8: =H6*H7/100 -> 1623.668 | I8: =I6*I7/100 -> 1672.3781 | J8: =J6*J7/100 -> 1722.5494 | ... L8: =L6*L7/100 -> 1818.5815
A9: SBC (% of revenue) | C9: =Assumptions!C29 -> 1.8 | D9: =Assumptions!D29 -> 1.6 | E9: =Assumptions!E29 -> 1.5 | F9: =Assumptions!F29 -> 1.4 | G9: =Assumptions!G29 -> 1.4 | H9: =Assumptions!H29 -> 1.3 | I9: =Assumptions!I29 -> 1.3 | J9: =Assumptions!J29 -> 1.2 | ... L9: =Assumptions!L29 -> 1.2
A10: SBC charge | C10: =-C6*C9/100 -> -88.644636 | D10: =-D6*D9/100 -> -94.554278 | E10: =-E6*E9/100 -> -99.281992 | F10: =-F6*F9/100 -> -98.222984 | G10: =-G6*G9/100 -> -102.1519 | H10: =-H6*H9/100 -> -98.175276 | I10: =-I6*I9/100 -> -101.12053 | J10: =-J6*J9/100 -> -96.142292 | ... L10: =-L6*L9/100 -> -101.50223
A11: Owner EBITDA (after SBC and leases) | C11: =C8+C10+C24 -> 896.29576 | D11: =D8+D10+D24 -> 1075.5549 | E11: =E8+E10+E24 -> 1257.5719 | F11: =F8+F10+F24 -> 1375.1218 | G11: =G8+G10+G24 -> 1452.0163 | H11: =H8+H10+H24 -> 1525.4927 | I11: =I8+I10+I24 -> 1571.2575 | J11: =J8+J10+J24 -> 1626.4071 | ... L11: =L8+L10+L24 -> 1717.0793
A12: D&A | C12: =-C6*Assumptions!C31/100 -> -196.98808 | D12: =-D6*Assumptions!D31/100 -> -224.56641 | E12: =-E6*Assumptions!E31/100 -> -238.27678 | F12: =-F6*Assumptions!F31/100 -> -238.54153 | G12: =-G6*Assumptions!G31/100 -> -233.49007 | H12: =-H6*Assumptions!H31/100 -> -234.11027 | I12: =-I6*Assumptions!I31/100 -> -233.35508 | J12: =-J6*Assumptions!J31/100 -> -240.35573 | ... L12: =-L6*Assumptions!L31/100 -> -253.75556
A13: EBIT | C13: =C11+C12 -> 699.30768 | D13: =D11+D12 -> 850.9885 | E13: =E11+E12 -> 1019.2951 | F13: =F11+F12 -> 1136.5802 | G13: =G11+G12 -> 1218.5263 | H13: =H11+H12 -> 1291.3825 | I13: =I11+I12 -> 1337.9025 | J13: =J11+J12 -> 1386.0514 | ... L13: =L11+L12 -> 1463.3237
A14: Cash tax rate (%) | C14: =Assumptions!C33 -> 25 | D14: =Assumptions!D33 -> 25 | E14: =Assumptions!E33 -> 25 | F14: =Assumptions!F33 -> 25 | G14: =Assumptions!G33 -> 25 | H14: =Assumptions!H33 -> 25 | I14: =Assumptions!I33 -> 25 | J14: =Assumptions!J33 -> 25 | ... L14: =Assumptions!L33 -> 25
A15: NOPAT | C15: =C13-MAX(0,C13)*C14/100 -> 524.48076 | D15: =D13-MAX(0,D13)*D14/100 -> 638.24138 | E15: =E13-MAX(0,E13)*E14/100 -> 764.47134 | F15: =F13-MAX(0,F13)*F14/100 -> 852.43518 | G15: =G13-MAX(0,G13)*G14/100 -> 913.89471 | H15: =H13-MAX(0,H13)*H14/100 -> 968.53686 | I15: =I13-MAX(0,I13)*I14/100 -> 1003.4268 | J15: =J13-MAX(0,J13)*J14/100 -> 1039.5385 | ... L15: =L13-MAX(0,L13)*L14/100 -> 1097.4928
A16: D&A add-back | C16: =-C12 -> 196.98808 | D16: =-D12 -> 224.56641 | E16: =-E12 -> 238.27678 | F16: =-F12 -> 238.54153 | G16: =-G12 -> 233.49007 | H16: =-H12 -> 234.11027 | I16: =-I12 -> 233.35508 | J16: =-J12 -> 240.35573 | ... L16: =-L12 -> 253.75556
A17: Capex | C17: =-C6*Assumptions!C32/100 -> -221.61159 | D17: =-D6*Assumptions!D32/100 -> -265.93391 | E17: =-E6*Assumptions!E32/100 -> -264.75198 | F17: =-F6*Assumptions!F32/100 -> -266.60524 | G17: =-G6*Assumptions!G32/100 -> -255.37976 | H17: =-H6*Assumptions!H32/100 -> -256.76611 | I17: =-I6*Assumptions!I32/100 -> -256.69059 | J17: =-J6*Assumptions!J32/100 -> -256.37945 | ... L17: =-L6*Assumptions!L32/100 -> -270.6726
A18: Working capital | C18: =(C6-B6)*Assumptions!$B$37/100 -> -107.33325 | D18: =(D6-C6)*Assumptions!$B$37/100 -> -147.74106 | E18: =(E6-D6)*Assumptions!$B$37/100 -> -106.37356 | F18: =(F6-E6)*Assumptions!$B$37/100 -> -59.569195 | G18: =(G6-F6)*Assumptions!$B$37/100 -> -42.095565 | H18: =(H6-G6)*Assumptions!$B$37/100 -> -38.306964 | I18: =(I6-H6)*Assumptions!$B$37/100 -> -33.983749 | J18: =(J6-I6)*Assumptions!$B$37/100 -> -35.003262 | ... L18: =(L6-K6)*Assumptions!$B$37/100 -> -30.9458
A19: Unlevered owner FCF | C19: =C15+C16+C17+C18 -> 392.524 | D19: =D15+D16+D17+D18 -> 449.13282 | E19: =E15+E16+E17+E18 -> 631.62258 | F19: =F15+F16+F17+F18 -> 764.80228 | G19: =G15+G16+G17+G18 -> 849.90945 | H19: =H15+H16+H17+H18 -> 907.57406 | I19: =I15+I16+I17+I18 -> 946.10758 | J19: =J15+J16+J17+J18 -> 988.51156 | ... L19: =L15+L16+L17+L18 -> 1049.63
A20: Discount factor | C20: =1/(1+$B$27/100)^C4 -> 0.89686099 | D20: =1/(1+$B$27/100)^D4 -> 0.80435963 | E20: =1/(1+$B$27/100)^E4 -> 0.72139877 | F20: =1/(1+$B$27/100)^F4 -> 0.64699441 | G20: =1/(1+$B$27/100)^G4 -> 0.58026405 | H20: =1/(1+$B$27/100)^H4 -> 0.52041619 | I20: =1/(1+$B$27/100)^I4 -> 0.46674097 | J20: =1/(1+$B$27/100)^J4 -> 0.41860177 | ... L20: =1/(1+$B$27/100)^L4 -> 0.33670636
A21: PV of FCF | C21: =C19*C20 -> 352.03947 | D21: =D19*D20 -> 361.26431 | E21: =E19*E20 -> 455.65175 | F21: =F19*F20 -> 494.8228 | G21: =G19*G20 -> 493.1719 | H21: =H19*H20 -> 472.31623 | I21: =I19*I20 -> 441.58717 | J21: =J19*J20 -> 413.79269 | ... L21: =L19*L20 -> 353.41709
A23: Lease cost (% of revenue) | C23: =Assumptions!C30 -> 0 | D23: =Assumptions!D30 -> 0 | E23: =Assumptions!E30 -> 0 | F23: =Assumptions!F30 -> 0 | G23: =Assumptions!G30 -> 0 | H23: =Assumptions!H30 -> 0 | I23: =Assumptions!I30 -> 0 | J23: =Assumptions!J30 -> 0 | ... L23: =Assumptions!L30 -> 0
A24: Lease cost | C24: =-C6*C23/100 -> 0 | D24: =-D6*D23/100 -> 0 | E24: =-E6*E23/100 -> 0 | F24: =-F6*F23/100 -> 0 | G24: =-G6*G23/100 -> 0 | H24: =-H6*H23/100 -> 0 | I24: =-I6*I23/100 -> 0 | J24: =-J6*J23/100 -> 0 | ... L24: =-L6*L23/100 -> 0
A26: Valuation
A27: WACC (%) | B27: =Assumptions!$B$34 -> 11.5
A28: Terminal growth (%) | B28: =Assumptions!$B$35 -> 3
A29: Terminal cap multiple (x FCF) | B29: =Assumptions!$B$36 -> 15
A30: Sum of PV of FCF | B30: =SUM(C21:L21) -> 4220.3114
A31: Terminal-year FCF | B31: =L19 -> 1049.63
A32: Gordon terminal value | B32: =IF(B27>B28,B31*(1+B28/100)/((B27-B28)/100),B31*B29) -> 12719.046
A33: Cap terminal value | B33: =B31*B29 -> 15744.45
A34: Terminal value used: MAX(0,MIN(Gordon,cap)) | B34: =MAX(0,MIN(B32,B33)) -> 12719.046
A35: PV of terminal value | B35: =B34/(1+B27/100)^L4 -> 4282.5836
A36: Enterprise value | B36: =B30+B35 -> 8502.895
A37: Equity value (EV + bridge - net debt) | B37: =B36+Assumptions!$B$5-Assumptions!$B$4 -> 7486.795
A38: Value per share (quote currency) | B38: =B37/Assumptions!$B$3*Assumptions!$B$10 -> 125.19724
A39: Upside vs price | B39: =B38/Assumptions!$B$2-1 -> -0.39849505
A41: Street memo: PV of explicit-period SBC | B41: =SUMPRODUCT(-C10:L10/(1+$B$27/100)^C4:L4) -> 559.89245
A42: Street memo: PV of terminal SBC (Gordon) | B42: =IF(B27>B28,-L10*(1+B28/100)/((B27-B28)/100),-L10*20)/(1+B27/100)^L4 -> 414.1381
A43: Street value per share | B43: =(B37+B41+B42)/Assumptions!$B$3*Assumptions!$B$10 -> 141.48538
A45: Hurdle rate (%) | B45: =Assumptions!$B$6 -> 15
...

Sheet DCF_Bull
A1: GNRC owner-FCF component DCF: bull case (millions, USD)
A3: Line | B3: FY2025 | C3: FY2026 | D3: FY2027 | E3: FY2028 | F3: FY2029 | G3: FY2030 | H3: FY2031 | I3: FY2032 | J3: FY2033 | K3: FY2034 | L3: FY2035
A4: Year index (discount exponent) | B4: 0 | C4: =B4+1 -> 1 | D4: =C4+1 -> 2 | E4: =D4+1 -> 3 | F4: =E4+1 -> 4 | G4: =F4+1 -> 5 | H4: =G4+1 -> 6 | I4: =H4+1 -> 7 | J4: =I4+1 -> 8 | ... L4: =K4+1 -> 10
A5: Revenue growth (%) | C5: =Assumptions!C41 -> 18 | D5: =Assumptions!D41 -> 32 | E5: =Assumptions!E41 -> 20 | F5: =Assumptions!F41 -> 10 | G5: =Assumptions!G41 -> 6 | H5: =Assumptions!H41 -> 5 | I5: =Assumptions!I41 -> 4 | J5: =Assumptions!J41 -> 3.5 | ... L5: =Assumptions!L41 -> 3
A6: Revenue | B6: 4209.147 | C6: =B6*(1+C5/100) -> 4966.7935 | D6: =C6*(1+D5/100) -> 6556.1674 | E6: =D6*(1+E5/100) -> 7867.4008 | F6: =E6*(1+F5/100) -> 8654.1409 | G6: =F6*(1+G5/100) -> 9173.3894 | H6: =G6*(1+H5/100) -> 9632.0588 | I6: =H6*(1+I5/100) -> 10017.341 | J6: =I6*(1+J5/100) -> 10367.948 | ... L6: =K6*(1+L5/100) -> 10999.356
A7: EBITDA margin (%) | C7: =Assumptions!C42 -> 20.5 | D7: =Assumptions!D42 -> 21 | E7: =Assumptions!E42 -> 22 | F7: =Assumptions!F42 -> 23 | G7: =Assumptions!G42 -> 23.5 | H7: =Assumptions!H42 -> 23.5 | I7: =Assumptions!I42 -> 23.5 | J7: =Assumptions!J42 -> 23.5 | ... L7: =Assumptions!L42 -> 23.5
A8: EBITDA | C8: =C6*C7/100 -> 1018.1927 | D8: =D6*D7/100 -> 1376.7951 | E8: =E6*E7/100 -> 1730.8282 | F8: =F6*F7/100 -> 1990.4524 | G8: =G6*G7/100 -> 2155.7465 | H8: =H6*H7/100 -> 2263.5338 | I8: =I6*I7/100 -> 2354.0752 | J8: =J6*J7/100 -> 2436.4678 | ... L8: =L6*L7/100 -> 2584.8487
A9: SBC (% of revenue) | C9: =Assumptions!C43 -> 1.8 | D9: =Assumptions!D43 -> 1.6 | E9: =Assumptions!E43 -> 1.5 | F9: =Assumptions!F43 -> 1.4 | G9: =Assumptions!G43 -> 1.4 | H9: =Assumptions!H43 -> 1.3 | I9: =Assumptions!I43 -> 1.3 | J9: =Assumptions!J43 -> 1.2 | ... L9: =Assumptions!L43 -> 1.2
A10: SBC charge | C10: =-C6*C9/100 -> -89.402282 | D10: =-D6*D9/100 -> -104.89868 | E10: =-E6*E9/100 -> -118.01101 | F10: =-F6*F9/100 -> -121.15797 | G10: =-G6*G9/100 -> -128.42745 | H10: =-H6*H9/100 -> -125.21677 | I10: =-I6*I9/100 -> -130.22544 | J10: =-J6*J9/100 -> -124.41538 | ... L10: =-L6*L9/100 -> -131.99227
A11: Owner EBITDA (after SBC and leases) | C11: =C8+C10+C24 -> 928.79038 | D11: =D8+D10+D24 -> 1271.8965 | E11: =E8+E10+E24 -> 1612.8172 | F11: =F8+F10+F24 -> 1869.2944 | G11: =G8+G10+G24 -> 2027.3191 | H11: =H8+H10+H24 -> 2138.3171 | I11: =I8+I10+I24 -> 2223.8497 | J11: =J8+J10+J24 -> 2312.0524 | ... L11: =L8+L10+L24 -> 2452.8564
A12: D&A | C12: =-C6*Assumptions!C45/100 -> -198.67174 | D12: =-D6*Assumptions!D45/100 -> -249.13436 | E12: =-E6*Assumptions!E45/100 -> -283.22643 | F12: =-F6*Assumptions!F45/100 -> -294.24079 | G12: =-G6*Assumptions!G45/100 -> -293.54846 | H12: =-H6*Assumptions!H45/100 -> -298.59382 | I12: =-I6*Assumptions!I45/100 -> -300.52024 | J12: =-J6*Assumptions!J45/100 -> -311.03844 | ... L12: =-L6*Assumptions!L45/100 -> -329.98069
A13: EBIT | C13: =C11+C12 -> 730.11864 | D13: =D11+D12 -> 1022.7621 | E13: =E11+E12 -> 1329.5907 | F13: =F11+F12 -> 1575.0536 | G13: =G11+G12 -> 1733.7706 | H13: =H11+H12 -> 1839.7232 | I13: =I11+I12 -> 1923.3295 | J13: =J11+J12 -> 2001.014 | ... L13: =L11+L12 -> 2122.8757
A14: Cash tax rate (%) | C14: =Assumptions!C47 -> 25 | D14: =Assumptions!D47 -> 25 | E14: =Assumptions!E47 -> 25 | F14: =Assumptions!F47 -> 25 | G14: =Assumptions!G47 -> 25 | H14: =Assumptions!H47 -> 25 | I14: =Assumptions!I47 -> 25 | J14: =Assumptions!J47 -> 25 | ... L14: =Assumptions!L47 -> 25
A15: NOPAT | C15: =C13-MAX(0,C13)*C14/100 -> 547.58898 | D15: =D13-MAX(0,D13)*D14/100 -> 767.07158 | E15: =E13-MAX(0,E13)*E14/100 -> 997.19306 | F15: =F13-MAX(0,F13)*F14/100 -> 1181.2902 | G15: =G13-MAX(0,G13)*G14/100 -> 1300.3279 | H15: =H13-MAX(0,H13)*H14/100 -> 1379.7924 | I15: =I13-MAX(0,I13)*I14/100 -> 1442.4971 | J15: =J13-MAX(0,J13)*J14/100 -> 1500.7605 | ... L15: =L13-MAX(0,L13)*L14/100 -> 1592.1568
A16: D&A add-back | C16: =-C12 -> 198.67174 | D16: =-D12 -> 249.13436 | E16: =-E12 -> 283.22643 | F16: =-F12 -> 294.24079 | G16: =-G12 -> 293.54846 | H16: =-H12 -> 298.59382 | I16: =-I12 -> 300.52024 | J16: =-J12 -> 311.03844 | ... L16: =-L12 -> 329.98069
A17: Capex | C17: =-C6*Assumptions!C46/100 -> -238.40609 | D17: =-D6*Assumptions!D46/100 -> -314.69603 | E17: =-E6*Assumptions!E46/100 -> -330.43084 | F17: =-F6*Assumptions!F46/100 -> -328.85736 | G17: =-G6*Assumptions!G46/100 -> -321.06863 | H17: =-H6*Assumptions!H46/100 -> -327.49 | I17: =-I6*Assumptions!I46/100 -> -330.57226 | J17: =-J6*Assumptions!J46/100 -> -331.77434 | ... L17: =-L6*Assumptions!L46/100 -> -351.9794
A18: Working capital | C18: =(C6-B6)*Assumptions!$B$51/100 -> -113.64697 | D18: =(D6-C6)*Assumptions!$B$51/100 -> -238.40609 | E18: =(E6-D6)*Assumptions!$B$51/100 -> -196.68502 | F18: =(F6-E6)*Assumptions!$B$51/100 -> -118.01101 | G18: =(G6-F6)*Assumptions!$B$51/100 -> -77.887268 | H18: =(H6-G6)*Assumptions!$B$51/100 -> -68.80042 | I18: =(I6-H6)*Assumptions!$B$51/100 -> -57.792353 | J18: =(J6-I6)*Assumptions!$B$51/100 -> -52.591041 | ... L18: =(L6-K6)*Assumptions!$B$51/100 -> -48.05544
A19: Unlevered owner FCF | C19: =C15+C16+C17+C18 -> 394.20766 | D19: =D15+D16+D17+D18 -> 463.10382 | E19: =E15+E16+E17+E18 -> 753.30363 | F19: =F15+F16+F17+F18 -> 1028.6627 | G19: =G15+G16+G17+G18 -> 1194.9205 | H19: =H15+H16+H17+H18 -> 1282.0958 | I19: =I15+I16+I17+I18 -> 1354.6528 | J19: =J15+J16+J17+J18 -> 1427.4336 | ... L19: =L15+L16+L17+L18 -> 1522.1027
A20: Discount factor | C20: =1/(1+$B$27/100)^C4 -> 0.89686099 | D20: =1/(1+$B$27/100)^D4 -> 0.80435963 | E20: =1/(1+$B$27/100)^E4 -> 0.72139877 | F20: =1/(1+$B$27/100)^F4 -> 0.64699441 | G20: =1/(1+$B$27/100)^G4 -> 0.58026405 | H20: =1/(1+$B$27/100)^H4 -> 0.52041619 | I20: =1/(1+$B$27/100)^I4 -> 0.46674097 | J20: =1/(1+$B$27/100)^J4 -> 0.41860177 | ... L20: =1/(1+$B$27/100)^L4 -> 0.33670636
A21: PV of FCF | C21: =C19*C20 -> 353.54947 | D21: =D19*D20 -> 372.50202 | E21: =E19*E20 -> 543.43231 | F21: =F19*F20 -> 665.53899 | G21: =G19*G20 -> 693.36941 | H21: =H19*H20 -> 667.22342 | I21: =I19*I20 -> 632.27195 | J21: =J19*J20 -> 597.52621 | ... L21: =L19*L20 -> 512.50165
A23: Lease cost (% of revenue) | C23: =Assumptions!C44 -> 0 | D23: =Assumptions!D44 -> 0 | E23: =Assumptions!E44 -> 0 | F23: =Assumptions!F44 -> 0 | G23: =Assumptions!G44 -> 0 | H23: =Assumptions!H44 -> 0 | I23: =Assumptions!I44 -> 0 | J23: =Assumptions!J44 -> 0 | ... L23: =Assumptions!L44 -> 0
A24: Lease cost | C24: =-C6*C23/100 -> 0 | D24: =-D6*D23/100 -> 0 | E24: =-E6*E23/100 -> 0 | F24: =-F6*F23/100 -> 0 | G24: =-G6*G23/100 -> 0 | H24: =-H6*H23/100 -> 0 | I24: =-I6*I23/100 -> 0 | J24: =-J6*J23/100 -> 0 | ... L24: =-L6*L23/100 -> 0
A26: Valuation
A27: WACC (%) | B27: =Assumptions!$B$48 -> 11.5
A28: Terminal growth (%) | B28: =Assumptions!$B$49 -> 3
A29: Terminal cap multiple (x FCF) | B29: =Assumptions!$B$50 -> 15
A30: Sum of PV of FCF | B30: =SUM(C21:L21) -> 5592.7109
A31: Terminal-year FCF | B31: =L19 -> 1522.1027
A32: Gordon terminal value | B32: =IF(B27>B28,B31*(1+B28/100)/((B27-B28)/100),B31*B29) -> 18444.303
A33: Cap terminal value | B33: =B31*B29 -> 22831.54
A34: Terminal value used: MAX(0,MIN(Gordon,cap)) | B34: =MAX(0,MIN(B32,B33)) -> 18444.303
A35: PV of terminal value | B35: =B34/(1+B27/100)^L4 -> 6210.3141
A36: Enterprise value | B36: =B30+B35 -> 11803.025
A37: Equity value (EV + bridge - net debt) | B37: =B36+Assumptions!$B$5-Assumptions!$B$4 -> 10786.925
A38: Value per share (quote currency) | B38: =B37/Assumptions!$B$3*Assumptions!$B$10 -> 180.38336
A39: Upside vs price | B39: =B38/Assumptions!$B$2-1 -> -0.13335561
A41: Street memo: PV of explicit-period SBC | B41: =SUMPRODUCT(-C10:L10/(1+$B$27/100)^C4:L4) -> 673.18079
A42: Street memo: PV of terminal SBC (Gordon) | B42: =IF(B27>B28,-L10*(1+B28/100)/((B27-B28)/100),-L10*20)/(1+B27/100)^L4 -> 538.54021
A43: Street value per share | B43: =(B37+B41+B42)/Assumptions!$B$3*Assumptions!$B$10 -> 200.64626
A45: Hurdle rate (%) | B45: =Assumptions!$B$6 -> 15
...

Sheet Valuation
A1: GNRC valuation summary
A3: Scenario | B3: Value per share | C3: Upside vs price | D3: Weight | E3: Street value per share | F3: Hurdle entry price
A4: Bear | B4: =DCF_Bear!$B$38 -> 68.318758 | C4: =B4/Assumptions!$B$2-1 -> -0.67176536 | D4: =Assumptions!$B$24 -> 0.25 | E4: =DCF_Bear!$B$43 -> 80.693616 | F4: =DCF_Bear!$B$47 -> 43.342842
A5: Base | B5: =DCF_Base!$B$38 -> 125.19724 | C5: =B5/Assumptions!$B$2-1 -> -0.39849505 | D5: =Assumptions!$B$38 -> 0.5 | E5: =DCF_Base!$B$43 -> 141.48538 | F5: =DCF_Base!$B$47 -> 80.050304
A6: Bull | B6: =DCF_Bull!$B$38 -> 180.38336 | C6: =B6/Assumptions!$B$2-1 -> -0.13335561 | D6: =Assumptions!$B$52 -> 0.25 | E6: =DCF_Bull!$B$43 -> 200.64626 | F6: =DCF_Bull!$B$47 -> 115.55672
A8: Probability-weighted value per share | B8: =SUMPRODUCT(B4:B6,D4:D6) -> 124.77415
A9: Street weighted value per share | B9: =SUMPRODUCT(E4:E6,D4:D6) -> 141.07766
A10: Margin of safety (1 - price/weighted) | B10: =1-Assumptions!$B$2/B8 -> -0.66813398
A11: Band position (%; 0 = house, 100 = street) | B11: =IF(ABS(B9-B8)>0.01*ABS(B8),(Assumptions!$B$2-B8)/(B9-B8)*100,"n/a") -> 511.33695
A12: Weighted 15% hurdle entry price | B12: =SUMPRODUCT(F4:F6,D4:D6) -> 79.750044
A14: Required-return table (base case; each row rebuilds its own terminal value) | C14: Rate (%)
A15: Value per share at 9% | B15: =(SUMPRODUCT(DCF_Base!$C$19:$L$19/(1+$C$15/100)^DCF_Base!$C$4:$L$4)+MAX(0,MIN(IF($C$15>DCF_Base!$B$28,DCF_Base!$L$19*(1+DCF_Base!$B$28/100)/(($C$15-DCF_Base!$B$28)/100),DCF_Base!$L$19*DCF_Base!$B$29),DCF_Base!$L$19*DCF_Base!$B$29))/(1+$C$15/100)^DCF_Base!$L$4+Assumptions!$B$5-Assumptions!$B$4)/Assumptions!$B$3*Assumptions!$B$10 -> 174.27358 | C15: 9
A16: Value per share at 10% | B16: =(SUMPRODUCT(DCF_Base!$C$19:$L$19/(1+$C$16/100)^DCF_Base!$C$4:$L$4)+MAX(0,MIN(IF($C$16>DCF_Base!$B$28,DCF_Base!$L$19*(1+DCF_Base!$B$28/100)/(($C$16-DCF_Base!$B$28)/100),DCF_Base!$L$19*DCF_Base!$B$29),DCF_Base!$L$19*DCF_Base!$B$29))/(1+$C$16/100)^DCF_Base!$L$4+Assumptions!$B$5-Assumptions!$B$4)/Assumptions!$B$3*Assumptions!$B$10 -> 158.63789 | C16: 10
A17: Value per share at 11% | B17: =(SUMPRODUCT(DCF_Base!$C$19:$L$19/(1+$C$17/100)^DCF_Base!$C$4:$L$4)+MAX(0,MIN(IF($C$17>DCF_Base!$B$28,DCF_Base!$L$19*(1+DCF_Base!$B$28/100)/(($C$17-DCF_Base!$B$28)/100),DCF_Base!$L$19*DCF_Base!$B$29),DCF_Base!$L$19*DCF_Base!$B$29))/(1+$C$17/100)^DCF_Base!$L$4+Assumptions!$B$5-Assumptions!$B$4)/Assumptions!$B$3*Assumptions!$B$10 -> 134.93381 | C17: 11
A18: Value per share at 11.5% (WACC) | B18: =(SUMPRODUCT(DCF_Base!$C$19:$L$19/(1+$C$18/100)^DCF_Base!$C$4:$L$4)+MAX(0,MIN(IF($C$18>DCF_Base!$B$28,DCF_Base!$L$19*(1+DCF_Base!$B$28/100)/(($C$18-DCF_Base!$B$28)/100),DCF_Base!$L$19*DCF_Base!$B$29),DCF_Base!$L$19*DCF_Base!$B$29))/(1+$C$18/100)^DCF_Base!$L$4+Assumptions!$B$5-Assumptions!$B$4)/Assumptions!$B$3*Assumptions!$B$10 -> 125.19724 | C18: 11.5
A19: Value per share at 12% | B19: =(SUMPRODUCT(DCF_Base!$C$19:$L$19/(1+$C$19/100)^DCF_Base!$C$4:$L$4)+MAX(0,MIN(IF($C$19>DCF_Base!$B$28,DCF_Base!$L$19*(1+DCF_Base!$B$28/100)/(($C$19-DCF_Base!$B$28)/100),DCF_Base!$L$19*DCF_Base!$B$29),DCF_Base!$L$19*DCF_Base!$B$29))/(1+$C$19/100)^DCF_Base!$L$4+Assumptions!$B$5-Assumptions!$B$4)/Assumptions!$B$3*Assumptions!$B$10 -> 116.55706 | C19: 12
A20: Value per share at 15% | B20: =(SUMPRODUCT(DCF_Base!$C$19:$L$19/(1+$C$20/100)^DCF_Base!$C$4:$L$4)+MAX(0,MIN(IF($C$20>DCF_Base!$B$28,DCF_Base!$L$19*(1+DCF_Base!$B$28/100)/(($C$20-DCF_Base!$B$28)/100),DCF_Base!$L$19*DCF_Base!$B$29),DCF_Base!$L$19*DCF_Base!$B$29))/(1+$C$20/100)^DCF_Base!$L$4+Assumptions!$B$5-Assumptions!$B$4)/Assumptions!$B$3*Assumptions!$B$10 -> 80.050304 | C20: 15
A22: Sensitivity: value per share, rows WACC (%) x columns terminal growth (%)
B23: 2 | C23: 2.5 | D23: 3 | E23: 3.5 | F23: 4
A24: 9.5 | B24: =(SUMPRODUCT(DCF_Base!$C$19:$L$19/(1+$A$24/100)^DCF_Base!$C$4:$L$4)+MAX(0,MIN(IF($A$24>$B$23,DCF_Base!$L$19*(1+$B$23/100)/(($A$24-$B$23)/100),DCF_Base!$L$19*DCF_Base!$B$29),DCF_Base!$L$19*DCF_Base!$B$29))/(1+$A$24/100)^DCF_Base!$L$4+Assumptions!$B$5-Assumptions!$B$4)/Assumptions!$B$3*Assumptions!$B$10 -> 157.34881 | C24: =(SUMPRODUCT(DCF_Base!$C$19:$L$19/(1+$A$24/100)^DCF_Base!$C$4:$L$4)+MAX(0,MIN(IF($A$24>$C$23,DCF_Base!$L$19*(1+$C$23/100)/(($A$24-$C$23)/100),DCF_Base!$L$19*DCF_Base!$B$29),DCF_Base!$L$19*DCF_Base!$B$29))/(1+$A$24/100)^DCF_Base!$L$4+Assumptions!$B$5-Assumptions!$B$4)/Assumptions!$B$3*Assumptions!$B$10 -> 164.73497 | D24: =(SUMPRODUCT(DCF_Base!$C$19:$L$19/(1+$A$24/100)^DCF_Base!$C$4:$L$4)+MAX(0,MIN(IF($A$24>$D$23,DCF_Base!$L$19*(1+$D$23/100)/(($A$24-$D$23)/100),DCF_Base!$L$19*DCF_Base!$B$29),DCF_Base!$L$19*DCF_Base!$B$29))/(1+$A$24/100)^DCF_Base!$L$4+Assumptions!$B$5-Assumptions!$B$4)/Assumptions!$B$3*Assumptions!$B$10 -> 167.26447 | E24: =(SUMPRODUCT(DCF_Base!$C$19:$L$19/(1+$A$24/100)^DCF_Base!$C$4:$L$4)+MAX(0,MIN(IF($A$24>$E$23,DCF_Base!$L$19*(1+$E$23/100)/(($A$24-$E$23)/100),DCF_Base!$L$19*DCF_Base!$B$29),DCF_Base!$L$19*DCF_Base!$B$29))/(1+$A$24/100)^DCF_Base!$L$4+Assumptions!$B$5-Assumptions!$B$4)/Assumptions!$B$3*Assumptions!$B$10 -> 167.26447 | F24: =(SUMPRODUCT(DCF_Base!$C$19:$L$19/(1+$A$24/100)^DCF_Base!$C$4:$L$4)+MAX(0,MIN(IF($A$24>$F$23,DCF_Base!$L$19*(1+$F$23/100)/(($A$24-$F$23)/100),DCF_Base!$L$19*DCF_Base!$B$29),DCF_Base!$L$19*DCF_Base!$B$29))/(1+$A$24/100)^DCF_Base!$L$4+Assumptions!$B$5-Assumptions!$B$4)/Assumptions!$B$3*Assumptions!$B$10 -> 167.26447
A25: 10.5 | B25: =(SUMPRODUCT(DCF_Base!$C$19:$L$19/(1+$A$25/100)^DCF_Base!$C$4:$L$4)+MAX(0,MIN(IF($A$25>$B$23,DCF_Base!$L$19*(1+$B$23/100)/(($A$25-$B$23)/100),DCF_Base!$L$19*DCF_Base!$B$29),DCF_Base!$L$19*DCF_Base!$B$29))/(1+$A$25/100)^DCF_Base!$L$4+Assumptions!$B$5-Assumptions!$B$4)/Assumptions!$B$3*Assumptions!$B$10 -> 134.7768 | C25: =(SUMPRODUCT(DCF_Base!$C$19:$L$19/(1+$A$25/100)^DCF_Base!$C$4:$L$4)+MAX(0,MIN(IF($A$25>$C$23,DCF_Base!$L$19*(1+$C$23/100)/(($A$25-$C$23)/100),DCF_Base!$L$19*DCF_Base!$B$29),DCF_Base!$L$19*DCF_Base!$B$29))/(1+$A$25/100)^DCF_Base!$L$4+Assumptions!$B$5-Assumptions!$B$4)/Assumptions!$B$3*Assumptions!$B$10 -> 140.03135 | D25: =(SUMPRODUCT(DCF_Base!$C$19:$L$19/(1+$A$25/100)^DCF_Base!$C$4:$L$4)+MAX(0,MIN(IF($A$25>$D$23,DCF_Base!$L$19*(1+$D$23/100)/(($A$25-$D$23)/100),DCF_Base!$L$19*DCF_Base!$B$29),DCF_Base!$L$19*DCF_Base!$B$29))/(1+$A$25/100)^DCF_Base!$L$4+Assumptions!$B$5-Assumptions!$B$4)/Assumptions!$B$3*Assumptions!$B$10 -> 145.98651 | E25: =(SUMPRODUCT(DCF_Base!$C$19:$L$19/(1+$A$25/100)^DCF_Base!$C$4:$L$4)+MAX(0,MIN(IF($A$25>$E$23,DCF_Base!$L$19*(1+$E$23/100)/(($A$25-$E$23)/100),DCF_Base!$L$19*DCF_Base!$B$29),DCF_Base!$L$19*DCF_Base!$B$29))/(1+$A$25/100)^DCF_Base!$L$4+Assumptions!$B$5-Assumptions!$B$4)/Assumptions!$B$3*Assumptions!$B$10 -> 152.7924 | F25: =(SUMPRODUCT(DCF_Base!$C$19:$L$19/(1+$A$25/100)^DCF_Base!$C$4:$L$4)+MAX(0,MIN(IF($A$25>$F$23,DCF_Base!$L$19*(1+$F$23/100)/(($A$25-$F$23)/100),DCF_Base!$L$19*DCF_Base!$B$29),DCF_Base!$L$19*DCF_Base!$B$29))/(1+$A$25/100)^DCF_Base!$L$4+Assumptions!$B$5-Assumptions!$B$4)/Assumptions!$B$3*Assumptions!$B$10 -> 154.17822
A26: 11.5 | B26: =(SUMPRODUCT(DCF_Base!$C$19:$L$19/(1+$A$26/100)^DCF_Base!$C$4:$L$4)+MAX(0,MIN(IF($A$26>$B$23,DCF_Base!$L$19*(1+$B$23/100)/(($A$26-$B$23)/100),DCF_Base!$L$19*DCF_Base!$B$29),DCF_Base!$L$19*DCF_Base!$B$29))/(1+$A$26/100)^DCF_Base!$L$4+Assumptions!$B$5-Assumptions!$B$4)/Assumptions!$B$3*Assumptions!$B$10 -> 117.0367 | C26: =(SUMPRODUCT(DCF_Base!$C$19:$L$19/(1+$A$26/100)^DCF_Base!$C$4:$L$4)+MAX(0,MIN(IF($A$26>$C$23,DCF_Base!$L$19*(1+$C$23/100)/(($A$26-$C$23)/100),DCF_Base!$L$19*DCF_Base!$B$29),DCF_Base!$L$19*DCF_Base!$B$29))/(1+$A$26/100)^DCF_Base!$L$4+Assumptions!$B$5-Assumptions!$B$4)/Assumptions!$B$3*Assumptions!$B$10 -> 120.89029 | D26: =(SUMPRODUCT(DCF_Base!$C$19:$L$19/(1+$A$26/100)^DCF_Base!$C$4:$L$4)+MAX(0,MIN(IF($A$26>$D$23,DCF_Base!$L$19*(1+$D$23/100)/(($A$26-$D$23)/100),DCF_Base!$L$19*DCF_Base!$B$29),DCF_Base!$L$19*DCF_Base!$B$29))/(1+$A$26/100)^DCF_Base!$L$4+Assumptions!$B$5-Assumptions!$B$4)/Assumptions!$B$3*Assumptions!$B$10 -> 125.19724 | E26: =(SUMPRODUCT(DCF_Base!$C$19:$L$19/(1+$A$26/100)^DCF_Base!$C$4:$L$4)+MAX(0,MIN(IF($A$26>$E$23,DCF_Base!$L$19*(1+$E$23/100)/(($A$26-$E$23)/100),DCF_Base!$L$19*DCF_Base!$B$29),DCF_Base!$L$19*DCF_Base!$B$29))/(1+$A$26/100)^DCF_Base!$L$4+Assumptions!$B$5-Assumptions!$B$4)/Assumptions!$B$3*Assumptions!$B$10 -> 130.04256 | F26: =(SUMPRODUCT(DCF_Base!$C$19:$L$19/(1+$A$26/100)^DCF_Base!$C$4:$L$4)+MAX(0,MIN(IF($A$26>$F$23,DCF_Base!$L$19*(1+$F$23/100)/(($A$26-$F$23)/100),DCF_Base!$L$19*DCF_Base!$B$29),DCF_Base!$L$19*DCF_Base!$B$29))/(1+$A$26/100)^DCF_Base!$L$4+Assumptions!$B$5-Assumptions!$B$4)/Assumptions!$B$3*Assumptions!$B$10 -> 135.53392
A27: 12.5 | B27: =(SUMPRODUCT(DCF_Base!$C$19:$L$19/(1+$A$27/100)^DCF_Base!$C$4:$L$4)+MAX(0,MIN(IF($A$27>$B$23,DCF_Base!$L$19*(1+$B$23/100)/(($A$27-$B$23)/100),DCF_Base!$L$19*DCF_Base!$B$29),DCF_Base!$L$19*DCF_Base!$B$29))/(1+$A$27/100)^DCF_Base!$L$4+Assumptions!$B$5-Assumptions!$B$4)/Assumptions!$B$3*Assumptions!$B$10 -> 102.74375 | C27: =(SUMPRODUCT(DCF_Base!$C$19:$L$19/(1+$A$27/100)^DCF_Base!$C$4:$L$4)+MAX(0,MIN(IF($A$27>$C$23,DCF_Base!$L$19*(1+$C$23/100)/(($A$27-$C$23)/100),DCF_Base!$L$19*DCF_Base!$B$29),DCF_Base!$L$19*DCF_Base!$B$29))/(1+$A$27/100)^DCF_Base!$L$4+Assumptions!$B$5-Assumptions!$B$4)/Assumptions!$B$3*Assumptions!$B$10 -> 105.63938 | D27: =(SUMPRODUCT(DCF_Base!$C$19:$L$19/(1+$A$27/100)^DCF_Base!$C$4:$L$4)+MAX(0,MIN(IF($A$27>$D$23,DCF_Base!$L$19*(1+$D$23/100)/(($A$27-$D$23)/100),DCF_Base!$L$19*DCF_Base!$B$29),DCF_Base!$L$19*DCF_Base!$B$29))/(1+$A$27/100)^DCF_Base!$L$4+Assumptions!$B$5-Assumptions!$B$4)/Assumptions!$B$3*Assumptions!$B$10 -> 108.83981 | E27: =(SUMPRODUCT(DCF_Base!$C$19:$L$19/(1+$A$27/100)^DCF_Base!$C$4:$L$4)+MAX(0,MIN(IF($A$27>$E$23,DCF_Base!$L$19*(1+$E$23/100)/(($A$27-$E$23)/100),DCF_Base!$L$19*DCF_Base!$B$29),DCF_Base!$L$19*DCF_Base!$B$29))/(1+$A$27/100)^DCF_Base!$L$4+Assumptions!$B$5-Assumptions!$B$4)/Assumptions!$B$3*Assumptions!$B$10 -> 112.39585 | F27: =(SUMPRODUCT(DCF_Base!$C$19:$L$19/(1+$A$27/100)^DCF_Base!$C$4:$L$4)+MAX(0,MIN(IF($A$27>$F$23,DCF_Base!$L$19*(1+$F$23/100)/(($A$27-$F$23)/100),DCF_Base!$L$19*DCF_Base!$B$29),DCF_Base!$L$19*DCF_Base!$B$29))/(1+$A$27/100)^DCF_Base!$L$4+Assumptions!$B$5-Assumptions!$B$4)/Assumptions!$B$3*Assumptions!$B$10 -> 116.37024
A28: 13.5 | B28: =(SUMPRODUCT(DCF_Base!$C$19:$L$19/(1+$A$28/100)^DCF_Base!$C$4:$L$4)+MAX(0,MIN(IF($A$28>$B$23,DCF_Base!$L$19*(1+$B$23/100)/(($A$28-$B$23)/100),DCF_Base!$L$19*DCF_Base!$B$29),DCF_Base!$L$19*DCF_Base!$B$29))/(1+$A$28/100)^DCF_Base!$L$4+Assumptions!$B$5-Assumptions!$B$4)/Assumptions!$B$3*Assumptions!$B$10 -> 90.995093 | C28: =(SUMPRODUCT(DCF_Base!$C$19:$L$19/(1+$A$28/100)^DCF_Base!$C$4:$L$4)+MAX(0,MIN(IF($A$28>$C$23,DCF_Base!$L$19*(1+$C$23/100)/(($A$28-$C$23)/100),DCF_Base!$L$19*DCF_Base!$B$29),DCF_Base!$L$19*DCF_Base!$B$29))/(1+$A$28/100)^DCF_Base!$L$4+Assumptions!$B$5-Assumptions!$B$4)/Assumptions!$B$3*Assumptions!$B$10 -> 93.214576 | D28: =(SUMPRODUCT(DCF_Base!$C$19:$L$19/(1+$A$28/100)^DCF_Base!$C$4:$L$4)+MAX(0,MIN(IF($A$28>$D$23,DCF_Base!$L$19*(1+$D$23/100)/(($A$28-$D$23)/100),DCF_Base!$L$19*DCF_Base!$B$29),DCF_Base!$L$19*DCF_Base!$B$29))/(1+$A$28/100)^DCF_Base!$L$4+Assumptions!$B$5-Assumptions!$B$4)/Assumptions!$B$3*Assumptions!$B$10 -> 95.645438 | E28: =(SUMPRODUCT(DCF_Base!$C$19:$L$19/(1+$A$28/100)^DCF_Base!$C$4:$L$4)+MAX(0,MIN(IF($A$28>$E$23,DCF_Base!$L$19*(1+$E$23/100)/(($A$28-$E$23)/100),DCF_Base!$L$19*DCF_Base!$B$29),DCF_Base!$L$19*DCF_Base!$B$29))/(1+$A$28/100)^DCF_Base!$L$4+Assumptions!$B$5-Assumptions!$B$4)/Assumptions!$B$3*Assumptions!$B$10 -> 98.319386 | F28: =(SUMPRODUCT(DCF_Base!$C$19:$L$19/(1+$A$28/100)^DCF_Base!$C$4:$L$4)+MAX(0,MIN(IF($A$28>$F$23,DCF_Base!$L$19*(1+$F$23/100)/(($A$28-$F$23)/100),DCF_Base!$L$19*DCF_Base!$B$29),DCF_Base!$L$19*DCF_Base!$B$29))/(1+$A$28/100)^DCF_Base!$L$4+Assumptions!$B$5-Assumptions!$B$4)/Assumptions!$B$3*Assumptions!$B$10 -> 101.2748
