Workbook

Sheet Model_Info
A1: AGL Energy Limited (ASX: AGL.AX) - owner-FCF DCF model
A2: Version 1.0, fresh build 2026-09-21. Supersedes nothing (first valuation of this ticker).
A3: Built by the dcf-analyst agent (Claude Fable 5.1) on 2026-09-21 at the request of the research-stock orchestrator.
A5: DATA VINTAGE - these figures go stale; refresh after each result
A6: Price: A$8.45 as of 2026-09-21T06:10:31Z (16:10 AEST regular close, Yahoo AGL.AX)
A7: Balance sheet: 30 June 2026 (FY26 Annual Report). Borrowings 2,976, cash 325, net debt 2651; lease liabilities 1,058 excluded (treatment B).
A8: Diluted shares: 673.673m (FY26 AR note 24). Held flat - SBC is expensed in the flows.
A9: Guidance: FY27 Underlying EBITDA $1.9-2.2bn, Underlying NPAT $470-670m, capex ~$1.5bn (12 Aug 2026 results release).
A11: METHODOLOGY
A12: Model: owner-FCF component DCF, 10-year horizon (FY27-FY36), Gordon/14x-cap terminal, 8.0% AUD WACC, end-of-year discounting. Routed via dcf-methods: operating company, non-US, cyclical (section 7).
A13: EBITDA margin driver is the CASH-ADJUSTED POST-LEASE margin: Underlying EBITDA less rehabilitation, onerous-contract, significant-items and lease (principal+interest) cash. FY26: (2,100-87-65-173-159)/13,590 = 11.9%.
A14: Leases: treatment (B) - full lease cash charged in the flows, lease liabilities excluded from net debt, D&A ex right-of-use depreciation.
... A27: CELL COLOURS: blue = hardcoded input; yellow fill = key driver row; black = formula; green = cross-sheet link; green fill = value per share.

Sheet Actuals
A1: Reported history, AUD millions. Source: AGL annual reports FY16-FY26 (Metrics.csv / core_metrics); underlying EBITDA from the five-year summaries; lease principal disclosed separately only from FY25.
A2: FY | B2: Revenue | C2: Underlying EBITDA | D2: D&A | E2: Operating cash flow | F2: Capex | G2: Reported FCF (OCF-capex) | H2: SBC | I2: Lease principal (financing) | J2: Cash taxes paid | K2: Shareholders equity | L2: Statutory NPAT | M2: Underlying EBITDA margin
A3: 2016 | B3: 11150 | C3: 1689 | D3: 478 | E3: 1186 | F3: 546 | G3: 640 | H3: 0 | I3: 0 | J3: 166 | K3: 7926 | L3: -407 | M3: =C3/B3
A4: 2017 | B4: 12584 | C4: 1852 | D4: 484 | E4: 891 | F4: 504 | G4: 387 | H4: 0 | I4: 0 | J4: 292 | K4: 7574 | L4: 539 | M4: =C4/B4
A5: 2018 | B5: 12816 | C5: 2226 | D5: 558 | E5: 2134 | F5: 720 | G5: 1414 | H5: 6 | I5: 0 | J5: 159 | K5: 8390 | L5: 1587 | M5: =C5/B5
A6: 2019 | B6: 13246 | C6: 2236 | D6: 625 | E6: 1599 | F6: 915 | G6: 684 | H6: 6 | I6: 0 | J6: 263 | K6: 8438 | L6: 905 | M6: =C6/B6
A7: 2020 | B7: 12160 | C7: 2026 | D7: 753 | E7: 2156 | F7: 758 | G7: 1398 | H7: 9 | I7: 0 | J7: 233 | K7: 8075 | L7: 1015 | M7: =C7/B7
A8: 2021 | B8: 10942 | C8: 1666 | D8: 707 | E8: 1250 | F8: 695 | G8: 555 | H8: 9 | I8: 0 | J8: 114 | K8: 5506 | L8: -2059 | M8: =C8/B8
A9: 2022 | B9: 13221 | C9: 1218 | D9: 717 | E9: 1227 | F9: 636 | G9: 591 | H9: 1 | I9: 0 | J9: 0 | K9: 6517 | L9: 853 | M9: =C9/B9
A10: 2023 | B10: 14157 | C10: 1361 | D10: 728 | E10: 912 | F10: 624 | G10: 288 | H10: 1 | I10: 0 | J10: -1 | K10: 5119 | L10: -1270 | M10: =C10/B10
A11: 2024 | B11: 13583 | C11: 2216 | D11: 747 | E11: 2240 | F11: 838 | G11: 1402 | H11: 4 | I11: 0 | J11: 4 | K11: 5431 | L11: 703 | M11: =C11/B11
A12: 2025 | B12: 14393 | C12: 2055 | D12: 803 | E12: 841 | F12: 1125 | G12: -284 | H12: 8 | I12: 75 | J12: 268 | K12: 4858 | L12: -98 | M12: =C12/B12
A13: 2026 | B13: 13590 | C13: 2100 | D13: 837 | E13: 1148 | F13: 1438 | G13: -290 | H13: 8 | I13: 88 | J13: 126 | K13: 5276 | L13: 756 | M13: =C13/B13
A15: Balance sheet 30 Jun 2026: borrowings 2,976 (65 current + 2,911 non-current); cash 325; lease liabilities 1,058 (109 current + 949 non-current, ~850 are restated PPAs); provisions 2,469 (471 current + 1,998 non-current, incl. rehabilitation).
A16: Shares: 672,747,233 basic; 673,673,090 diluted (note 24). No buyback since FY20; DRP last operated FY22. FY26 dividends paid 329; FY26 DPS 50c fully franked (53.3% payout).
A17: FY27 guidance (12 Aug 2026): Underlying EBITDA 1,900-2,200; Underlying NPAT 470-670; capex ~800 growth + ~700 sustaining (incl ~500 for two major coal-unit outages); payout 55-60%; $50m cost program.
A18: FY26 EBITDA-to-cash leakage (excluded from Underlying EBITDA, inside OCF): rehabilitation 87; onerous contracts 65; significant items cash 173; lease interest 71 (operating) + lease principal 88 (financing); margin calls 209 (timing).

Sheet Assumptions
A1: Global assumptions (blue = input)
A3: WACC | B3: 0.08 | C3: AUD-built: Rf 4.3% + 1.0 beta x 5.5% ERP = 9.8% CoE; Kd 5.8% pre-tax; 68/32 market weights -> 7.97%. Same in all scenarios (risk charged once).
A4: Working-capital capture on revenue change | B4: -0.05 | C4: Negative: growth consumes a little cash (receivables + inventory roughly net of payables). Margin calls excluded as timing.
A5: Net debt (AUD m), 30 Jun 2026 | B5: 2651 | C5: Borrowings 2,976 less cash 325. Lease liabilities 1,058 excluded (treatment B).
A6: Diluted shares (m) | B6: 673.673 | C6: FY26 AR note 24. Held flat.
A7: Share price (AUD) | B7: 8.45 | C7: 2026-09-21T06:10:31Z (16:10 AEST regular close, Yahoo AGL.AX)
A8: Terminal FCF cap multiple (x) | B8: 14 | C8: 12-15x range for cyclical / structurally slower businesses; coal-closure tail.
A9: FY26 revenue (AUD m) | B9: 13590 | C9: FY0 base.
A10: Hurdle rate for entry price | B10: 0.15 | C10: House 15% IRR; TV rebuilt at the hurdle.
A12: Scenario | B12: Terminal growth | C12: Probability weight | D12: Narrative
A13: Bear | B13: 0.01 | C13: 0.25 | D13: New renewable supply and strong plant reliability push wholesale prices down 20%+ and volatility stays suppressed; tier-2 retailers keep taking share (NEM switching 24.4%), so revenue falls 3% in FY27 and drifts up only 1%/yr. Underlying margin compresses to ~12-13% and rehabilitation/closure cash rises as Bayswater and Loy Yang A retire, leaving a 9% cash-adjusted margin. Management trims growth capex but the coal outages and committed projects keep capex above 7% of revenue until FY33. Owner FCF is negative for four years and barely positive at the terminal; with $2.65bn of net debt the equity is worth less than zero on this path - i.e. the bear case requires an equity raise, a dividend cut, or asset sales, which is a finding rather than a rounding detail.
A14: Base | B14: 0.02 | C14: 0.5 | D14: Wholesale prices soften (2027 NSW/VIC futures -20%) so FY27 revenue is flat and Underlying EBITDA lands mid-guidance (~$2.05bn, 15.1%); thereafter customer growth, electrification and the $50m cost program hold the underlying margin at ~15% (10-yr average 14.7%) while the Liddell/Tomago batteries and Hexham/Tilt PPAs replace the margin lost as Bayswater (2030-33) and Loy Yang A (2035) close. Cash leakage eases from 3.4% of revenue (FY27, transformation overrun) to ~2.8% (rehabilitation rising toward closure, transformation and onerous costs falling away, leases ~1.2%), lifting the cash-adjusted margin from 11.7% to 12.2%. Capex tapers from $1.5bn to ~6.5% of revenue (~$1.1bn) by FY36 as the 12GW build completes with capital partners taking >2GW. Cash tax ramps 18%->30% as accelerated depreciation unwinds. Owner FCF is roughly zero in FY27-28 and reaches ~3.4% of revenue by FY36.
A15: Bull | B15: 0.025 | C15: 0.25 | D15: AI data-centre and electrification demand (management's 5 TWh -> 34 TWh pipeline) lifts volumes 3%/yr; battery arbitrage boosts Bayswater returns ~10% and the firming fleet earns premium capacity revenue as coal exits the NEM, taking the underlying margin to ~17% (FY18-19 levels) and the cash-adjusted margin to 14%. Capital partners fund most of the growth pipeline, so capex falls to 6% of revenue by FY35 and owner FCF reaches ~5.5% of revenue. Terminal growth 2.5%.
A16: Weights check (must be 100%) | C16: =SUM(C13:C15)
A18: Weights rationale | D18: 25/50/25 rather than the 15/50/35 default. Bear raised to 25%: gearing 33.6% and rising, negative FCF two years running, a >40%-wide FY27 NPAT guidance range, a history of $2bn+ coal impairments, and a bear path on which equity value is negative (refinancing/raise risk is real, not cosmetic). Bull cut to 25%: it needs several independent things to go right at once - data-centre load materialising, capital partners funding the pipeline, battery arbitrage sustaining thermal returns and wholesale volatility returning - and even then it only reaches the current price.

Sheet DCF_Bear
A1: DCF_Bear - owner-FCF component build, AUD millions. Yellow rows are the drivers.
A3: Year | B3: 2026A | C3: FY2027E | D3: FY2028E | E3: FY2029E | F3: FY2030E | G3: FY2031E | H3: FY2032E | I3: FY2033E | J3: FY2034E | K3: FY2035E | L3: FY2036E
A4: Index | B4: 0 | C4: 1 | D4: 2 | E4: 3 | F4: 4 | G4: 5 | H4: 6 | I4: 7 | J4: 8 | K4: 9 | L4: 10
A5: Revenue growth YoY | C5: -0.03 | D5: -0.01 | E5: 0 | F5: 0.005 | G5: 0.01 | H5: 0.01 | I5: 0.01 | J5: 0.01 | K5: 0.01 | L5: 0.01
A6: Revenue | B6: =Assumptions!$B$9 | C6: =B6*(1+C5) | D6: =C6*(1+D5) | E6: =D6*(1+E5) | F6: =E6*(1+F5) | G6: =F6*(1+G5) | H6: =G6*(1+H5) | I6: =H6*(1+I5) | J6: =I6*(1+J5) | ... L6: =K6*(1+L5)
A7: Adj EBITDA margin (cash-adjusted, post-lease) | C7: 0.105 | D7: 0.1 | E7: 0.098 | F7: 0.098 | G7: 0.098 | H7: 0.095 | I7: 0.095 | J7: 0.09 | K7: 0.09 | L7: 0.09
A8: Adj EBITDA | C8: =C6*C7 | D8: =D6*D7 | E8: =E6*E7 | F8: =F6*F7 | G8: =G6*G7 | H8: =H6*H7 | I8: =I6*I7 | J8: =J6*J7 | ... L8: =L6*L7
A9: SBC % of revenue | C9: 0.0006 | D9: 0.0006 | E9: 0.0006 | F9: 0.0006 | G9: 0.0006 | H9: 0.0006 | I9: 0.0006 | J9: 0.0006 | K9: 0.0006 | L9: 0.0006
A10: SBC | C10: =-C6*C9 | D10: =-D6*D9 | E10: =-E6*E9 | F10: =-F6*F9 | G10: =-G6*G9 | H10: =-H6*H9 | I10: =-I6*I9 | J10: =-J6*J9 | ... L10: =-L6*L9
A11: Owner EBITDA | C11: =C8+C10 | D11: =D8+D10 | E11: =E8+E10 | F11: =F8+F10 | G11: =G8+G10 | H11: =H8+H10 | I11: =I8+I10 | J11: =J8+J10 | ... L11: =L8+L10
A12: D&A % of revenue (ex ROU) | C12: 0.056 | D12: 0.058 | E12: 0.06 | F12: 0.062 | G12: 0.063 | H12: 0.064 | I12: 0.065 | J12: 0.065 | K12: 0.065 | L12: 0.065
A13: D&A | C13: =-C6*C12 | D13: =-D6*D12 | E13: =-E6*E12 | F13: =-F6*F12 | G13: =-G6*G12 | H13: =-H6*H12 | I13: =-I6*I12 | J13: =-J6*J12 | ... L13: =-L6*L12
A14: EBIT (SBC expensed) | C14: =C11+C13 | D14: =D11+D13 | E14: =E11+E13 | F14: =F11+F13 | G14: =G11+G13 | H14: =H11+H13 | I14: =I11+I13 | J14: =J11+J13 | ... L14: =L11+L13
A15: Cash tax rate | C15: 0.15 | D15: 0.18 | E15: 0.2 | F15: 0.22 | G15: 0.24 | H15: 0.26 | I15: 0.28 | J15: 0.3 | K15: 0.3 | L15: 0.3
A16: Cash tax | C16: =-MAX(0,C14)*C15 | D16: =-MAX(0,D14)*D15 | E16: =-MAX(0,E14)*E15 | F16: =-MAX(0,F14)*F15 | G16: =-MAX(0,G14)*G15 | H16: =-MAX(0,H14)*H15 | I16: =-MAX(0,I14)*I15 | J16: =-MAX(0,J14)*J15 | ... L16: =-MAX(0,L14)*L15
A17: NOPAT | C17: =C14+C16 | D17: =D14+D16 | E17: =E14+E16 | F17: =F14+F16 | G17: =G14+G16 | H17: =H14+H16 | I17: =I14+I16 | J17: =J14+J16 | ... L17: =L14+L16
A18: add back D&A | C18: =-C13 | D18: =-D13 | E18: =-E13 | F18: =-F13 | G18: =-G13 | H18: =-H13 | I18: =-I13 | J18: =-J13 | ... L18: =-L13
A19: Capex % of revenue (sustaining + growth) | C19: 0.11 | D19: 0.1 | E19: 0.09 | F19: 0.085 | G19: 0.08 | H19: 0.075 | I19: 0.07 | J19: 0.07 | K19: 0.065 | L19: 0.065
A20: Capex | C20: =-C6*C19 | D20: =-D6*D19 | E20: =-E6*E19 | F20: =-F6*F19 | G20: =-G6*G19 | H20: =-H6*H19 | I20: =-I6*I19 | J20: =-J6*J19 | ... L20: =-L6*L19
A21: Working capital (capture x change in revenue) | C21: =Assumptions!$B$4*(C6-B6) | D21: =Assumptions!$B$4*(D6-C6) | E21: =Assumptions!$B$4*(E6-D6) | F21: =Assumptions!$B$4*(F6-E6) | G21: =Assumptions!$B$4*(G6-F6) | H21: =Assumptions!$B$4*(H6-G6) | I21: =Assumptions!$B$4*(I6-H6) | J21: =Assumptions!$B$4*(J6-I6) | ... L21: =Assumptions!$B$4*(L6-K6)
A22: Unlevered owner FCF | C22: =C17+C18+C20+C21 | D22: =D17+D18+D20+D21 | E22: =E17+E18+E20+E21 | F22: =F17+F18+F20+F21 | G22: =G17+G18+G20+G21 | H22: =H17+H18+H20+H21 | I22: =I17+I18+I20+I21 | J22: =J17+J18+J20+J21 | ... L22: =L17+L18+L20+L21
A23: Discount factor | C23: =1/(1+Assumptions!$B$3)^C4 | D23: =1/(1+Assumptions!$B$3)^D4 | E23: =1/(1+Assumptions!$B$3)^E4 | F23: =1/(1+Assumptions!$B$3)^F4 | G23: =1/(1+Assumptions!$B$3)^G4 | H23: =1/(1+Assumptions!$B$3)^H4 | I23: =1/(1+Assumptions!$B$3)^I4 | J23: =1/(1+Assumptions!$B$3)^J4 | ... L23: =1/(1+Assumptions!$B$3)^L4
A24: PV of FCF | C24: =C22*C23 | D24: =D22*D23 | E24: =E22*E23 | F24: =F22*F23 | G24: =G22*G23 | H24: =H22*H23 | I24: =I22*I23 | J24: =J22*J23 | ... L24: =L22*L23
A26: Memo: FCF before SBC (company-style) | C26: =C22-C10 | D26: =D22-D10 | E26: =E22-E10 | F26: =F22-F10 | G26: =G22-G10 | H26: =H22-H10 | I26: =I22-I10 | J26: =J22-J10 | ... L26: =L22-L10
A27: Memo: owner FCF margin | C27: =C22/C6 | D27: =D22/D6 | E27: =E22/E6 | F27: =F22/F6 | G27: =G22/G6 | H27: =H22/H6 | I27: =I22/I6 | J27: =J22/J6 | ... L27: =L22/L6
A29: Sum of PV of FCF (FY27-FY36) | B29: =SUM(C24:L24)
A30: Terminal growth | B30: =Assumptions!$B$13
A31: Terminal-year FCF x (1+g) | B31: =L22*(1+B30)
A32: Gordon terminal value | B32: =IF(Assumptions!$B$3>B30,B31/(Assumptions!$B$3-B30),"n/a")
A33: Cap terminal value (cap x FCF_10) | B33: =Assumptions!$B$8*L22
A34: Terminal value used = MAX(0, MIN(Gordon, cap)) | B34: =MAX(0,MIN(B32,B33))
A35: Implied exit multiple (TV / FCF_10) | B35: =IF(L22<>0,B34/L22,"n/a")
A36: PV of terminal value | B36: =B34*L23
A37: Enterprise value | B37: =B29+B36
A38: less net debt | B38: =-Assumptions!$B$5
A39: Equity value | B39: =B37+B38
A40: Diluted shares (m) | B40: =Assumptions!$B$6
A41: VALUE PER SHARE (AUD) | B41: =B39/B40
A42: Upside vs price | B42: =B41/Assumptions!$B$7-1
A43: Terminal value as % of EV | B43: =IF(B37<>0,B36/B37,"n/a")
...

Sheet DCF_Base
A1: DCF_Base - owner-FCF component build, AUD millions. Yellow rows are the drivers.
A3: Year | B3: 2026A | C3: FY2027E | D3: FY2028E | E3: FY2029E | F3: FY2030E | G3: FY2031E | H3: FY2032E | I3: FY2033E | J3: FY2034E | K3: FY2035E | L3: FY2036E
A4: Index | B4: 0 | C4: 1 | D4: 2 | E4: 3 | F4: 4 | G4: 5 | H4: 6 | I4: 7 | J4: 8 | K4: 9 | L4: 10
A5: Revenue growth YoY | C5: 0 | D5: 0.015 | E5: 0.02 | F5: 0.02 | G5: 0.02 | H5: 0.02 | I5: 0.02 | J5: 0.02 | K5: 0.02 | L5: 0.02
A6: Revenue | B6: =Assumptions!$B$9 | C6: =B6*(1+C5) | D6: =C6*(1+D5) | E6: =D6*(1+E5) | F6: =E6*(1+F5) | G6: =F6*(1+G5) | H6: =G6*(1+H5) | I6: =H6*(1+I5) | J6: =I6*(1+J5) | ... L6: =K6*(1+L5)
A7: Adj EBITDA margin (cash-adjusted, post-lease) | C7: 0.117 | D7: 0.118 | E7: 0.12 | F7: 0.121 | G7: 0.122 | H7: 0.122 | I7: 0.122 | J7: 0.122 | K7: 0.122 | L7: 0.122
A8: Adj EBITDA | C8: =C6*C7 | D8: =D6*D7 | E8: =E6*E7 | F8: =F6*F7 | G8: =G6*G7 | H8: =H6*H7 | I8: =I6*I7 | J8: =J6*J7 | ... L8: =L6*L7
A9: SBC % of revenue | C9: 0.0006 | D9: 0.0006 | E9: 0.0006 | F9: 0.0006 | G9: 0.0006 | H9: 0.0006 | I9: 0.0006 | J9: 0.0006 | K9: 0.0006 | L9: 0.0006
A10: SBC | C10: =-C6*C9 | D10: =-D6*D9 | E10: =-E6*E9 | F10: =-F6*F9 | G10: =-G6*G9 | H10: =-H6*H9 | I10: =-I6*I9 | J10: =-J6*J9 | ... L10: =-L6*L9
A11: Owner EBITDA | C11: =C8+C10 | D11: =D8+D10 | E11: =E8+E10 | F11: =F8+F10 | G11: =G8+G10 | H11: =H8+H10 | I11: =I8+I10 | J11: =J8+J10 | ... L11: =L8+L10
A12: D&A % of revenue (ex ROU) | C12: 0.056 | D12: 0.058 | E12: 0.06 | F12: 0.062 | G12: 0.063 | H12: 0.064 | I12: 0.065 | J12: 0.065 | K12: 0.065 | L12: 0.065
A13: D&A | C13: =-C6*C12 | D13: =-D6*D12 | E13: =-E6*E12 | F13: =-F6*F12 | G13: =-G6*G12 | H13: =-H6*H12 | I13: =-I6*I12 | J13: =-J6*J12 | ... L13: =-L6*L12
A14: EBIT (SBC expensed) | C14: =C11+C13 | D14: =D11+D13 | E14: =E11+E13 | F14: =F11+F13 | G14: =G11+G13 | H14: =H11+H13 | I14: =I11+I13 | J14: =J11+J13 | ... L14: =L11+L13
A15: Cash tax rate | C15: 0.18 | D15: 0.2 | E15: 0.22 | F15: 0.24 | G15: 0.26 | H15: 0.28 | I15: 0.3 | J15: 0.3 | K15: 0.3 | L15: 0.3
A16: Cash tax | C16: =-MAX(0,C14)*C15 | D16: =-MAX(0,D14)*D15 | E16: =-MAX(0,E14)*E15 | F16: =-MAX(0,F14)*F15 | G16: =-MAX(0,G14)*G15 | H16: =-MAX(0,H14)*H15 | I16: =-MAX(0,I14)*I15 | J16: =-MAX(0,J14)*J15 | ... L16: =-MAX(0,L14)*L15
A17: NOPAT | C17: =C14+C16 | D17: =D14+D16 | E17: =E14+E16 | F17: =F14+F16 | G17: =G14+G16 | H17: =H14+H16 | I17: =I14+I16 | J17: =J14+J16 | ... L17: =L14+L16
A18: add back D&A | C18: =-C13 | D18: =-D13 | E18: =-E13 | F18: =-F13 | G18: =-G13 | H18: =-H13 | I18: =-I13 | J18: =-J13 | ... L18: =-L13
A19: Capex % of revenue (sustaining + growth) | C19: 0.11 | D19: 0.105 | E19: 0.1 | F19: 0.095 | G19: 0.09 | H19: 0.085 | I19: 0.08 | J19: 0.075 | K19: 0.07 | L19: 0.065
A20: Capex | C20: =-C6*C19 | D20: =-D6*D19 | E20: =-E6*E19 | F20: =-F6*F19 | G20: =-G6*G19 | H20: =-H6*H19 | I20: =-I6*I19 | J20: =-J6*J19 | ... L20: =-L6*L19
A21: Working capital (capture x change in revenue) | C21: =Assumptions!$B$4*(C6-B6) | D21: =Assumptions!$B$4*(D6-C6) | E21: =Assumptions!$B$4*(E6-D6) | F21: =Assumptions!$B$4*(F6-E6) | G21: =Assumptions!$B$4*(G6-F6) | H21: =Assumptions!$B$4*(H6-G6) | I21: =Assumptions!$B$4*(I6-H6) | J21: =Assumptions!$B$4*(J6-I6) | ... L21: =Assumptions!$B$4*(L6-K6)
A22: Unlevered owner FCF | C22: =C17+C18+C20+C21 | D22: =D17+D18+D20+D21 | E22: =E17+E18+E20+E21 | F22: =F17+F18+F20+F21 | G22: =G17+G18+G20+G21 | H22: =H17+H18+H20+H21 | I22: =I17+I18+I20+I21 | J22: =J17+J18+J20+J21 | ... L22: =L17+L18+L20+L21
A23: Discount factor | C23: =1/(1+Assumptions!$B$3)^C4 | D23: =1/(1+Assumptions!$B$3)^D4 | E23: =1/(1+Assumptions!$B$3)^E4 | F23: =1/(1+Assumptions!$B$3)^F4 | G23: =1/(1+Assumptions!$B$3)^G4 | H23: =1/(1+Assumptions!$B$3)^H4 | I23: =1/(1+Assumptions!$B$3)^I4 | J23: =1/(1+Assumptions!$B$3)^J4 | ... L23: =1/(1+Assumptions!$B$3)^L4
A24: PV of FCF | C24: =C22*C23 | D24: =D22*D23 | E24: =E22*E23 | F24: =F22*F23 | G24: =G22*G23 | H24: =H22*H23 | I24: =I22*I23 | J24: =J22*J23 | ... L24: =L22*L23
A26: Memo: FCF before SBC (company-style) | C26: =C22-C10 | D26: =D22-D10 | E26: =E22-E10 | F26: =F22-F10 | G26: =G22-G10 | H26: =H22-H10 | I26: =I22-I10 | J26: =J22-J10 | ... L26: =L22-L10
A27: Memo: owner FCF margin | C27: =C22/C6 | D27: =D22/D6 | E27: =E22/E6 | F27: =F22/F6 | G27: =G22/G6 | H27: =H22/H6 | I27: =I22/I6 | J27: =J22/J6 | ... L27: =L22/L6
A29: Sum of PV of FCF (FY27-FY36) | B29: =SUM(C24:L24)
A30: Terminal growth | B30: =Assumptions!$B$14
A31: Terminal-year FCF x (1+g) | B31: =L22*(1+B30)
A32: Gordon terminal value | B32: =IF(Assumptions!$B$3>B30,B31/(Assumptions!$B$3-B30),"n/a")
A33: Cap terminal value (cap x FCF_10) | B33: =Assumptions!$B$8*L22
A34: Terminal value used = MAX(0, MIN(Gordon, cap)) | B34: =MAX(0,MIN(B32,B33))
A35: Implied exit multiple (TV / FCF_10) | B35: =IF(L22<>0,B34/L22,"n/a")
A36: PV of terminal value | B36: =B34*L23
A37: Enterprise value | B37: =B29+B36
A38: less net debt | B38: =-Assumptions!$B$5
A39: Equity value | B39: =B37+B38
A40: Diluted shares (m) | B40: =Assumptions!$B$6
A41: VALUE PER SHARE (AUD) | B41: =B39/B40
A42: Upside vs price | B42: =B41/Assumptions!$B$7-1
A43: Terminal value as % of EV | B43: =IF(B37<>0,B36/B37,"n/a")
...

Sheet DCF_Bull
A1: DCF_Bull - owner-FCF component build, AUD millions. Yellow rows are the drivers.
A3: Year | B3: 2026A | C3: FY2027E | D3: FY2028E | E3: FY2029E | F3: FY2030E | G3: FY2031E | H3: FY2032E | I3: FY2033E | J3: FY2034E | K3: FY2035E | L3: FY2036E
A4: Index | B4: 0 | C4: 1 | D4: 2 | E4: 3 | F4: 4 | G4: 5 | H4: 6 | I4: 7 | J4: 8 | K4: 9 | L4: 10
A5: Revenue growth YoY | C5: 0.01 | D5: 0.025 | E5: 0.03 | F5: 0.03 | G5: 0.03 | H5: 0.03 | I5: 0.03 | J5: 0.03 | K5: 0.03 | L5: 0.03
A6: Revenue | B6: =Assumptions!$B$9 | C6: =B6*(1+C5) | D6: =C6*(1+D5) | E6: =D6*(1+E5) | F6: =E6*(1+F5) | G6: =F6*(1+G5) | H6: =G6*(1+H5) | I6: =H6*(1+I5) | J6: =I6*(1+J5) | ... L6: =K6*(1+L5)
A7: Adj EBITDA margin (cash-adjusted, post-lease) | C7: 0.122 | D7: 0.126 | E7: 0.13 | F7: 0.134 | G7: 0.136 | H7: 0.138 | I7: 0.14 | J7: 0.14 | K7: 0.14 | L7: 0.14
A8: Adj EBITDA | C8: =C6*C7 | D8: =D6*D7 | E8: =E6*E7 | F8: =F6*F7 | G8: =G6*G7 | H8: =H6*H7 | I8: =I6*I7 | J8: =J6*J7 | ... L8: =L6*L7
A9: SBC % of revenue | C9: 0.0006 | D9: 0.0006 | E9: 0.0006 | F9: 0.0006 | G9: 0.0006 | H9: 0.0006 | I9: 0.0006 | J9: 0.0006 | K9: 0.0006 | L9: 0.0006
A10: SBC | C10: =-C6*C9 | D10: =-D6*D9 | E10: =-E6*E9 | F10: =-F6*F9 | G10: =-G6*G9 | H10: =-H6*H9 | I10: =-I6*I9 | J10: =-J6*J9 | ... L10: =-L6*L9
A11: Owner EBITDA | C11: =C8+C10 | D11: =D8+D10 | E11: =E8+E10 | F11: =F8+F10 | G11: =G8+G10 | H11: =H8+H10 | I11: =I8+I10 | J11: =J8+J10 | ... L11: =L8+L10
A12: D&A % of revenue (ex ROU) | C12: 0.056 | D12: 0.058 | E12: 0.06 | F12: 0.062 | G12: 0.063 | H12: 0.064 | I12: 0.065 | J12: 0.065 | K12: 0.065 | L12: 0.065
A13: D&A | C13: =-C6*C12 | D13: =-D6*D12 | E13: =-E6*E12 | F13: =-F6*F12 | G13: =-G6*G12 | H13: =-H6*H12 | I13: =-I6*I12 | J13: =-J6*J12 | ... L13: =-L6*L12
A14: EBIT (SBC expensed) | C14: =C11+C13 | D14: =D11+D13 | E14: =E11+E13 | F14: =F11+F13 | G14: =G11+G13 | H14: =H11+H13 | I14: =I11+I13 | J14: =J11+J13 | ... L14: =L11+L13
A15: Cash tax rate | C15: 0.18 | D15: 0.2 | E15: 0.22 | F15: 0.24 | G15: 0.26 | H15: 0.28 | I15: 0.3 | J15: 0.3 | K15: 0.3 | L15: 0.3
A16: Cash tax | C16: =-MAX(0,C14)*C15 | D16: =-MAX(0,D14)*D15 | E16: =-MAX(0,E14)*E15 | F16: =-MAX(0,F14)*F15 | G16: =-MAX(0,G14)*G15 | H16: =-MAX(0,H14)*H15 | I16: =-MAX(0,I14)*I15 | J16: =-MAX(0,J14)*J15 | ... L16: =-MAX(0,L14)*L15
A17: NOPAT | C17: =C14+C16 | D17: =D14+D16 | E17: =E14+E16 | F17: =F14+F16 | G17: =G14+G16 | H17: =H14+H16 | I17: =I14+I16 | J17: =J14+J16 | ... L17: =L14+L16
A18: add back D&A | C18: =-C13 | D18: =-D13 | E18: =-E13 | F18: =-F13 | G18: =-G13 | H18: =-H13 | I18: =-I13 | J18: =-J13 | ... L18: =-L13
A19: Capex % of revenue (sustaining + growth) | C19: 0.11 | D19: 0.1 | E19: 0.09 | F19: 0.085 | G19: 0.08 | H19: 0.075 | I19: 0.07 | J19: 0.065 | K19: 0.06 | L19: 0.06
A20: Capex | C20: =-C6*C19 | D20: =-D6*D19 | E20: =-E6*E19 | F20: =-F6*F19 | G20: =-G6*G19 | H20: =-H6*H19 | I20: =-I6*I19 | J20: =-J6*J19 | ... L20: =-L6*L19
A21: Working capital (capture x change in revenue) | C21: =Assumptions!$B$4*(C6-B6) | D21: =Assumptions!$B$4*(D6-C6) | E21: =Assumptions!$B$4*(E6-D6) | F21: =Assumptions!$B$4*(F6-E6) | G21: =Assumptions!$B$4*(G6-F6) | H21: =Assumptions!$B$4*(H6-G6) | I21: =Assumptions!$B$4*(I6-H6) | J21: =Assumptions!$B$4*(J6-I6) | ... L21: =Assumptions!$B$4*(L6-K6)
A22: Unlevered owner FCF | C22: =C17+C18+C20+C21 | D22: =D17+D18+D20+D21 | E22: =E17+E18+E20+E21 | F22: =F17+F18+F20+F21 | G22: =G17+G18+G20+G21 | H22: =H17+H18+H20+H21 | I22: =I17+I18+I20+I21 | J22: =J17+J18+J20+J21 | ... L22: =L17+L18+L20+L21
A23: Discount factor | C23: =1/(1+Assumptions!$B$3)^C4 | D23: =1/(1+Assumptions!$B$3)^D4 | E23: =1/(1+Assumptions!$B$3)^E4 | F23: =1/(1+Assumptions!$B$3)^F4 | G23: =1/(1+Assumptions!$B$3)^G4 | H23: =1/(1+Assumptions!$B$3)^H4 | I23: =1/(1+Assumptions!$B$3)^I4 | J23: =1/(1+Assumptions!$B$3)^J4 | ... L23: =1/(1+Assumptions!$B$3)^L4
A24: PV of FCF | C24: =C22*C23 | D24: =D22*D23 | E24: =E22*E23 | F24: =F22*F23 | G24: =G22*G23 | H24: =H22*H23 | I24: =I22*I23 | J24: =J22*J23 | ... L24: =L22*L23
A26: Memo: FCF before SBC (company-style) | C26: =C22-C10 | D26: =D22-D10 | E26: =E22-E10 | F26: =F22-F10 | G26: =G22-G10 | H26: =H22-H10 | I26: =I22-I10 | J26: =J22-J10 | ... L26: =L22-L10
A27: Memo: owner FCF margin | C27: =C22/C6 | D27: =D22/D6 | E27: =E22/E6 | F27: =F22/F6 | G27: =G22/G6 | H27: =H22/H6 | I27: =I22/I6 | J27: =J22/J6 | ... L27: =L22/L6
A29: Sum of PV of FCF (FY27-FY36) | B29: =SUM(C24:L24)
A30: Terminal growth | B30: =Assumptions!$B$15
A31: Terminal-year FCF x (1+g) | B31: =L22*(1+B30)
A32: Gordon terminal value | B32: =IF(Assumptions!$B$3>B30,B31/(Assumptions!$B$3-B30),"n/a")
A33: Cap terminal value (cap x FCF_10) | B33: =Assumptions!$B$8*L22
A34: Terminal value used = MAX(0, MIN(Gordon, cap)) | B34: =MAX(0,MIN(B32,B33))
A35: Implied exit multiple (TV / FCF_10) | B35: =IF(L22<>0,B34/L22,"n/a")
A36: PV of terminal value | B36: =B34*L23
A37: Enterprise value | B37: =B29+B36
A38: less net debt | B38: =-Assumptions!$B$5
A39: Equity value | B39: =B37+B38
A40: Diluted shares (m) | B40: =Assumptions!$B$6
A41: VALUE PER SHARE (AUD) | B41: =B39/B40
A42: Upside vs price | B42: =B41/Assumptions!$B$7-1
A43: Terminal value as % of EV | B43: =IF(B37<>0,B36/B37,"n/a")
...

Sheet FCF_Quality
A1: Reported FCF reconciled to owner FCF, AUD millions (treatment B: lease principal deducted; interest income not stripped because AGL is net-debt).
A2: FY | B2: Revenue | C2: Reported FCF (OCF-capex) | D2: less SBC | E2: less lease principal | F2: Owner FCF | G2: Reported FCF margin | H2: Owner FCF margin | I2: Underlying EBITDA | J2: Cash taxes paid | K2: Cash tax / underlying EBITDA | L2: Flag
A3: =Actuals!A3 | B3: =Actuals!B3 | C3: =Actuals!G3 | D3: =-Actuals!H3 | E3: =-Actuals!I3 | F3: =C3+D3+E3 | G3: =C3/B3 | H3: =F3/B3 | I3: =Actuals!C3 | J3: =Actuals!J3 | K3: =J3/I3 | L3: =IF(K3<0.05,"abnormally low cash tax",IF(F3<0,"negative owner FCF (capex supercycle)",""))
A4: =Actuals!A4 | B4: =Actuals!B4 | C4: =Actuals!G4 | D4: =-Actuals!H4 | E4: =-Actuals!I4 | F4: =C4+D4+E4 | G4: =C4/B4 | H4: =F4/B4 | I4: =Actuals!C4 | J4: =Actuals!J4 | K4: =J4/I4 | L4: =IF(K4<0.05,"abnormally low cash tax",IF(F4<0,"negative owner FCF (capex supercycle)",""))
A5: =Actuals!A5 | B5: =Actuals!B5 | C5: =Actuals!G5 | D5: =-Actuals!H5 | E5: =-Actuals!I5 | F5: =C5+D5+E5 | G5: =C5/B5 | H5: =F5/B5 | I5: =Actuals!C5 | J5: =Actuals!J5 | K5: =J5/I5 | L5: =IF(K5<0.05,"abnormally low cash tax",IF(F5<0,"negative owner FCF (capex supercycle)",""))
A6: =Actuals!A6 | B6: =Actuals!B6 | C6: =Actuals!G6 | D6: =-Actuals!H6 | E6: =-Actuals!I6 | F6: =C6+D6+E6 | G6: =C6/B6 | H6: =F6/B6 | I6: =Actuals!C6 | J6: =Actuals!J6 | K6: =J6/I6 | L6: =IF(K6<0.05,"abnormally low cash tax",IF(F6<0,"negative owner FCF (capex supercycle)",""))
A7: =Actuals!A7 | B7: =Actuals!B7 | C7: =Actuals!G7 | D7: =-Actuals!H7 | E7: =-Actuals!I7 | F7: =C7+D7+E7 | G7: =C7/B7 | H7: =F7/B7 | I7: =Actuals!C7 | J7: =Actuals!J7 | K7: =J7/I7 | L7: =IF(K7<0.05,"abnormally low cash tax",IF(F7<0,"negative owner FCF (capex supercycle)",""))
A8: =Actuals!A8 | B8: =Actuals!B8 | C8: =Actuals!G8 | D8: =-Actuals!H8 | E8: =-Actuals!I8 | F8: =C8+D8+E8 | G8: =C8/B8 | H8: =F8/B8 | I8: =Actuals!C8 | J8: =Actuals!J8 | K8: =J8/I8 | L8: =IF(K8<0.05,"abnormally low cash tax",IF(F8<0,"negative owner FCF (capex supercycle)",""))
A9: =Actuals!A9 | B9: =Actuals!B9 | C9: =Actuals!G9 | D9: =-Actuals!H9 | E9: =-Actuals!I9 | F9: =C9+D9+E9 | G9: =C9/B9 | H9: =F9/B9 | I9: =Actuals!C9 | J9: =Actuals!J9 | K9: =J9/I9 | L9: =IF(K9<0.05,"abnormally low cash tax",IF(F9<0,"negative owner FCF (capex supercycle)",""))
A10: =Actuals!A10 | B10: =Actuals!B10 | C10: =Actuals!G10 | D10: =-Actuals!H10 | E10: =-Actuals!I10 | F10: =C10+D10+E10 | G10: =C10/B10 | H10: =F10/B10 | I10: =Actuals!C10 | J10: =Actuals!J10 | K10: =J10/I10 | L10: =IF(K10<0.05,"abnormally low cash tax",IF(F10<0,"negative owner FCF (capex supercycle)",""))
A11: =Actuals!A11 | B11: =Actuals!B11 | C11: =Actuals!G11 | D11: =-Actuals!H11 | E11: =-Actuals!I11 | F11: =C11+D11+E11 | G11: =C11/B11 | H11: =F11/B11 | I11: =Actuals!C11 | J11: =Actuals!J11 | K11: =J11/I11 | L11: =IF(K11<0.05,"abnormally low cash tax",IF(F11<0,"negative owner FCF (capex supercycle)",""))
A12: =Actuals!A12 | B12: =Actuals!B12 | C12: =Actuals!G12 | D12: =-Actuals!H12 | E12: =-Actuals!I12 | F12: =C12+D12+E12 | G12: =C12/B12 | H12: =F12/B12 | I12: =Actuals!C12 | J12: =Actuals!J12 | K12: =J12/I12 | L12: =IF(K12<0.05,"abnormally low cash tax",IF(F12<0,"negative owner FCF (capex supercycle)",""))
A13: =Actuals!A13 | B13: =Actuals!B13 | C13: =Actuals!G13 | D13: =-Actuals!H13 | E13: =-Actuals!I13 | F13: =C13+D13+E13 | G13: =C13/B13 | H13: =F13/B13 | I13: =Actuals!C13 | J13: =Actuals!J13 | K13: =J13/I13 | L13: =IF(K13<0.05,"abnormally low cash tax",IF(F13<0,"negative owner FCF (capex supercycle)",""))
A15: Memo: FY26 OCF already includes rehabilitation (87), onerous-contract (65), significant-items (173) and lease-interest (71) cash and a (209) margin-call outflow; the forward model charges the first four inside the cash-adjusted EBITDA margin and treats margin calls as timing.
A16: Memo: FY20-FY24 lease principal sat inside 'repayment of borrowings' and is not separately disclosed; those owner-FCF figures are ~50-70/yr too high.

Sheet Valuation
A1: Valuation summary (AUD per share)
A2: Scenario | B2: Value per share | C2: Upside vs price | D2: Probability | E2: Street value per share | F2: Terminal value bound
A3: Bear | B3: =DCF_Bear!$B$41 | C3: =DCF_Bear!$B$42 | D3: =Assumptions!$C$13 | E3: =DCF_Bear!$B$47 | F3: =IF(DCF_Bear!$B$34=0,"floor",IF(DCF_Bear!$B$32<=DCF_Bear!$B$33,"Gordon","cap"))
A4: Base | B4: =DCF_Base!$B$41 | C4: =DCF_Base!$B$42 | D4: =Assumptions!$C$14 | E4: =DCF_Base!$B$47 | F4: =IF(DCF_Base!$B$34=0,"floor",IF(DCF_Base!$B$32<=DCF_Base!$B$33,"Gordon","cap"))
A5: Bull | B5: =DCF_Bull!$B$41 | C5: =DCF_Bull!$B$42 | D5: =Assumptions!$C$15 | E5: =DCF_Bull!$B$47 | F5: =IF(DCF_Bull!$B$34=0,"floor",IF(DCF_Bull!$B$32<=DCF_Bull!$B$33,"Gordon","cap"))
A7: Probability-weighted value per share | B7: =SUMPRODUCT(B3:B5,D3:D5)
A8: Current price | B8: =Assumptions!$B$7
A9: Margin of safety (1 - price / weighted) | B9: =IF(B7>0,1-B8/B7,"n/a - weighted value not positive")
A10: Street probability-weighted value | B10: =SUMPRODUCT(E3:E5,D3:D5)
A11: Band position (price - house)/(street - house) | B11: =IF(ABS(B10-B7)<0.05*B8,"n/a - SBC-immaterial, band collapses",(B8-B7)/(B10-B7))
A13: Required-return table (base case; TV rebuilt at each rate)
A14: Required return | B14: Value per share
A15: 0.08 | B15: =IF($A$15>Assumptions!$B$14,(SUMPRODUCT(DCF_Base!$C$22:$L$22/(1+$A$15)^DCF_Base!$C$4:$L$4)+MAX(0,MIN(DCF_Base!$L$22*(1+Assumptions!$B$14)/($A$15-Assumptions!$B$14),Assumptions!$B$8*DCF_Base!$L$22))/(1+$A$15)^10-Assumptions!$B$5)/Assumptions!$B$6,"n/a") | C15: Model WACC row; must equal DCF_Base!B41
A16: 0.09 | B16: =IF($A$16>Assumptions!$B$14,(SUMPRODUCT(DCF_Base!$C$22:$L$22/(1+$A$16)^DCF_Base!$C$4:$L$4)+MAX(0,MIN(DCF_Base!$L$22*(1+Assumptions!$B$14)/($A$16-Assumptions!$B$14),Assumptions!$B$8*DCF_Base!$L$22))/(1+$A$16)^10-Assumptions!$B$5)/Assumptions!$B$6,"n/a")
A17: 0.1 | B17: =IF($A$17>Assumptions!$B$14,(SUMPRODUCT(DCF_Base!$C$22:$L$22/(1+$A$17)^DCF_Base!$C$4:$L$4)+MAX(0,MIN(DCF_Base!$L$22*(1+Assumptions!$B$14)/($A$17-Assumptions!$B$14),Assumptions!$B$8*DCF_Base!$L$22))/(1+$A$17)^10-Assumptions!$B$5)/Assumptions!$B$6,"n/a")
A18: 0.11 | B18: =IF($A$18>Assumptions!$B$14,(SUMPRODUCT(DCF_Base!$C$22:$L$22/(1+$A$18)^DCF_Base!$C$4:$L$4)+MAX(0,MIN(DCF_Base!$L$22*(1+Assumptions!$B$14)/($A$18-Assumptions!$B$14),Assumptions!$B$8*DCF_Base!$L$22))/(1+$A$18)^10-Assumptions!$B$5)/Assumptions!$B$6,"n/a")
A19: 0.12 | B19: =IF($A$19>Assumptions!$B$14,(SUMPRODUCT(DCF_Base!$C$22:$L$22/(1+$A$19)^DCF_Base!$C$4:$L$4)+MAX(0,MIN(DCF_Base!$L$22*(1+Assumptions!$B$14)/($A$19-Assumptions!$B$14),Assumptions!$B$8*DCF_Base!$L$22))/(1+$A$19)^10-Assumptions!$B$5)/Assumptions!$B$6,"n/a")
A20: 0.15 | B20: =IF($A$20>Assumptions!$B$14,(SUMPRODUCT(DCF_Base!$C$22:$L$22/(1+$A$20)^DCF_Base!$C$4:$L$4)+MAX(0,MIN(DCF_Base!$L$22*(1+Assumptions!$B$14)/($A$20-Assumptions!$B$14),Assumptions!$B$8*DCF_Base!$L$22))/(1+$A$20)^10-Assumptions!$B$5)/Assumptions!$B$6,"n/a") | C20: Hurdle row (15%); must equal the base entry price below
A23: 15%-hurdle entry prices (PV of interim FCF + TV rebuilt at 15% - net debt, per share)
A24: Scenario | B24: Entry price | C24: Discount from current | D24: Street entry price
A25: Bear | B25: =IF(Assumptions!$B$10>Assumptions!$B$13,(SUMPRODUCT(DCF_Bear!$C$22:$L$22/(1+Assumptions!$B$10)^DCF_Bear!$C$4:$L$4)+MAX(0,MIN(DCF_Bear!$L$22*(1+Assumptions!$B$13)/(Assumptions!$B$10-Assumptions!$B$13),Assumptions!$B$8*DCF_Bear!$L$22))/(1+Assumptions!$B$10)^10-Assumptions!$B$5)/Assumptions!$B$6,"n/a") | C25: =IF(ISNUMBER(B25),B25/Assumptions!$B$7-1,"n/a") | D25: =IF(Assumptions!$B$10>Assumptions!$B$13,(SUMPRODUCT(DCF_Bear!$C$22:$L$22/(1+Assumptions!$B$10)^DCF_Bear!$C$4:$L$4)+MAX(0,MIN(DCF_Bear!$L$22*(1+Assumptions!$B$13)/(Assumptions!$B$10-Assumptions!$B$13),Assumptions!$B$8*DCF_Bear!$L$22))/(1+Assumptions!$B$10)^10-Assumptions!$B$5+SUMPRODUCT(-DCF_Bear!$C$10:$L$10/(1+Assumptions!$B$10)^DCF_Bear!$C$4:$L$4)+(-DCF_Bear!$L$10*(1+Assumptions!$B$13)/(Assumptions!$B$10-Assumptions!$B$13))/(1+Assumptions!$B$10)^10)/Assumptions!$B$6,"n/a")
A26: Base | B26: =IF(Assumptions!$B$10>Assumptions!$B$14,(SUMPRODUCT(DCF_Base!$C$22:$L$22/(1+Assumptions!$B$10)^DCF_Base!$C$4:$L$4)+MAX(0,MIN(DCF_Base!$L$22*(1+Assumptions!$B$14)/(Assumptions!$B$10-Assumptions!$B$14),Assumptions!$B$8*DCF_Base!$L$22))/(1+Assumptions!$B$10)^10-Assumptions!$B$5)/Assumptions!$B$6,"n/a") | C26: =IF(ISNUMBER(B26),B26/Assumptions!$B$7-1,"n/a") | D26: =IF(Assumptions!$B$10>Assumptions!$B$14,(SUMPRODUCT(DCF_Base!$C$22:$L$22/(1+Assumptions!$B$10)^DCF_Base!$C$4:$L$4)+MAX(0,MIN(DCF_Base!$L$22*(1+Assumptions!$B$14)/(Assumptions!$B$10-Assumptions!$B$14),Assumptions!$B$8*DCF_Base!$L$22))/(1+Assumptions!$B$10)^10-Assumptions!$B$5+SUMPRODUCT(-DCF_Base!$C$10:$L$10/(1+Assumptions!$B$10)^DCF_Base!$C$4:$L$4)+(-DCF_Base!$L$10*(1+Assumptions!$B$14)/(Assumptions!$B$10-Assumptions!$B$14))/(1+Assumptions!$B$10)^10)/Assumptions!$B$6,"n/a")
A27: Bull | B27: =IF(Assumptions!$B$10>Assumptions!$B$15,(SUMPRODUCT(DCF_Bull!$C$22:$L$22/(1+Assumptions!$B$10)^DCF_Bull!$C$4:$L$4)+MAX(0,MIN(DCF_Bull!$L$22*(1+Assumptions!$B$15)/(Assumptions!$B$10-Assumptions!$B$15),Assumptions!$B$8*DCF_Bull!$L$22))/(1+Assumptions!$B$10)^10-Assumptions!$B$5)/Assumptions!$B$6,"n/a") | C27: =IF(ISNUMBER(B27),B27/Assumptions!$B$7-1,"n/a") | D27: =IF(Assumptions!$B$10>Assumptions!$B$15,(SUMPRODUCT(DCF_Bull!$C$22:$L$22/(1+Assumptions!$B$10)^DCF_Bull!$C$4:$L$4)+MAX(0,MIN(DCF_Bull!$L$22*(1+Assumptions!$B$15)/(Assumptions!$B$10-Assumptions!$B$15),Assumptions!$B$8*DCF_Bull!$L$22))/(1+Assumptions!$B$10)^10-Assumptions!$B$5+SUMPRODUCT(-DCF_Bull!$C$10:$L$10/(1+Assumptions!$B$10)^DCF_Bull!$C$4:$L$4)+(-DCF_Bull!$L$10*(1+Assumptions!$B$15)/(Assumptions!$B$10-Assumptions!$B$15))/(1+Assumptions!$B$10)^10)/Assumptions!$B$6,"n/a")
A28: Probability-weighted entry price (buy-below) | B28: =SUMPRODUCT(B25:B27,D3:D5)
A29: A negative entry price means no purchase price returns 15% on that path: the PV of the flows at the hurdle is below the net debt.
A31: Sensitivity: base-case value per share, WACC (rows) x terminal growth (columns); TV rebuilt at each pair
A32: WACC \ g | B32: 0.01 | C32: 0.015 | D32: 0.02 | E32: 0.025 | F32: 0.03
A33: 0.06 | B33: =IF($A$33>B$32,(SUMPRODUCT(DCF_Base!$C$22:$L$22/(1+$A$33)^DCF_Base!$C$4:$L$4)+MAX(0,MIN(DCF_Base!$L$22*(1+B$32)/($A$33-B$32),Assumptions!$B$8*DCF_Base!$L$22))/(1+$A$33)^10-Assumptions!$B$5)/Assumptions!$B$6,"n/a") | C33: =IF($A$33>C$32,(SUMPRODUCT(DCF_Base!$C$22:$L$22/(1+$A$33)^DCF_Base!$C$4:$L$4)+MAX(0,MIN(DCF_Base!$L$22*(1+C$32)/($A$33-C$32),Assumptions!$B$8*DCF_Base!$L$22))/(1+$A$33)^10-Assumptions!$B$5)/Assumptions!$B$6,"n/a") | D33: =IF($A$33>D$32,(SUMPRODUCT(DCF_Base!$C$22:$L$22/(1+$A$33)^DCF_Base!$C$4:$L$4)+MAX(0,MIN(DCF_Base!$L$22*(1+D$32)/($A$33-D$32),Assumptions!$B$8*DCF_Base!$L$22))/(1+$A$33)^10-Assumptions!$B$5)/Assumptions!$B$6,"n/a") | E33: =IF($A$33>E$32,(SUMPRODUCT(DCF_Base!$C$22:$L$22/(1+$A$33)^DCF_Base!$C$4:$L$4)+MAX(0,MIN(DCF_Base!$L$22*(1+E$32)/($A$33-E$32),Assumptions!$B$8*DCF_Base!$L$22))/(1+$A$33)^10-Assumptions!$B$5)/Assumptions!$B$6,"n/a") | F33: =IF($A$33>F$32,(SUMPRODUCT(DCF_Base!$C$22:$L$22/(1+$A$33)^DCF_Base!$C$4:$L$4)+MAX(0,MIN(DCF_Base!$L$22*(1+F$32)/($A$33-F$32),Assumptions!$B$8*DCF_Base!$L$22))/(1+$A$33)^10-Assumptions!$B$5)/Assumptions!$B$6,"n/a")
A34: 0.07 | B34: =IF($A$34>B$32,(SUMPRODUCT(DCF_Base!$C$22:$L$22/(1+$A$34)^DCF_Base!$C$4:$L$4)+MAX(0,MIN(DCF_Base!$L$22*(1+B$32)/($A$34-B$32),Assumptions!$B$8*DCF_Base!$L$22))/(1+$A$34)^10-Assumptions!$B$5)/Assumptions!$B$6,"n/a") | C34: =IF($A$34>C$32,(SUMPRODUCT(DCF_Base!$C$22:$L$22/(1+$A$34)^DCF_Base!$C$4:$L$4)+MAX(0,MIN(DCF_Base!$L$22*(1+C$32)/($A$34-C$32),Assumptions!$B$8*DCF_Base!$L$22))/(1+$A$34)^10-Assumptions!$B$5)/Assumptions!$B$6,"n/a") | D34: =IF($A$34>D$32,(SUMPRODUCT(DCF_Base!$C$22:$L$22/(1+$A$34)^DCF_Base!$C$4:$L$4)+MAX(0,MIN(DCF_Base!$L$22*(1+D$32)/($A$34-D$32),Assumptions!$B$8*DCF_Base!$L$22))/(1+$A$34)^10-Assumptions!$B$5)/Assumptions!$B$6,"n/a") | E34: =IF($A$34>E$32,(SUMPRODUCT(DCF_Base!$C$22:$L$22/(1+$A$34)^DCF_Base!$C$4:$L$4)+MAX(0,MIN(DCF_Base!$L$22*(1+E$32)/($A$34-E$32),Assumptions!$B$8*DCF_Base!$L$22))/(1+$A$34)^10-Assumptions!$B$5)/Assumptions!$B$6,"n/a") | F34: =IF($A$34>F$32,(SUMPRODUCT(DCF_Base!$C$22:$L$22/(1+$A$34)^DCF_Base!$C$4:$L$4)+MAX(0,MIN(DCF_Base!$L$22*(1+F$32)/($A$34-F$32),Assumptions!$B$8*DCF_Base!$L$22))/(1+$A$34)^10-Assumptions!$B$5)/Assumptions!$B$6,"n/a")
A35: 0.08 | B35: =IF($A$35>B$32,(SUMPRODUCT(DCF_Base!$C$22:$L$22/(1+$A$35)^DCF_Base!$C$4:$L$4)+MAX(0,MIN(DCF_Base!$L$22*(1+B$32)/($A$35-B$32),Assumptions!$B$8*DCF_Base!$L$22))/(1+$A$35)^10-Assumptions!$B$5)/Assumptions!$B$6,"n/a") | C35: =IF($A$35>C$32,(SUMPRODUCT(DCF_Base!$C$22:$L$22/(1+$A$35)^DCF_Base!$C$4:$L$4)+MAX(0,MIN(DCF_Base!$L$22*(1+C$32)/($A$35-C$32),Assumptions!$B$8*DCF_Base!$L$22))/(1+$A$35)^10-Assumptions!$B$5)/Assumptions!$B$6,"n/a") | D35: =IF($A$35>D$32,(SUMPRODUCT(DCF_Base!$C$22:$L$22/(1+$A$35)^DCF_Base!$C$4:$L$4)+MAX(0,MIN(DCF_Base!$L$22*(1+D$32)/($A$35-D$32),Assumptions!$B$8*DCF_Base!$L$22))/(1+$A$35)^10-Assumptions!$B$5)/Assumptions!$B$6,"n/a") | E35: =IF($A$35>E$32,(SUMPRODUCT(DCF_Base!$C$22:$L$22/(1+$A$35)^DCF_Base!$C$4:$L$4)+MAX(0,MIN(DCF_Base!$L$22*(1+E$32)/($A$35-E$32),Assumptions!$B$8*DCF_Base!$L$22))/(1+$A$35)^10-Assumptions!$B$5)/Assumptions!$B$6,"n/a") | F35: =IF($A$35>F$32,(SUMPRODUCT(DCF_Base!$C$22:$L$22/(1+$A$35)^DCF_Base!$C$4:$L$4)+MAX(0,MIN(DCF_Base!$L$22*(1+F$32)/($A$35-F$32),Assumptions!$B$8*DCF_Base!$L$22))/(1+$A$35)^10-Assumptions!$B$5)/Assumptions!$B$6,"n/a")
A36: 0.09 | B36: =IF($A$36>B$32,(SUMPRODUCT(DCF_Base!$C$22:$L$22/(1+$A$36)^DCF_Base!$C$4:$L$4)+MAX(0,MIN(DCF_Base!$L$22*(1+B$32)/($A$36-B$32),Assumptions!$B$8*DCF_Base!$L$22))/(1+$A$36)^10-Assumptions!$B$5)/Assumptions!$B$6,"n/a") | C36: =IF($A$36>C$32,(SUMPRODUCT(DCF_Base!$C$22:$L$22/(1+$A$36)^DCF_Base!$C$4:$L$4)+MAX(0,MIN(DCF_Base!$L$22*(1+C$32)/($A$36-C$32),Assumptions!$B$8*DCF_Base!$L$22))/(1+$A$36)^10-Assumptions!$B$5)/Assumptions!$B$6,"n/a") | D36: =IF($A$36>D$32,(SUMPRODUCT(DCF_Base!$C$22:$L$22/(1+$A$36)^DCF_Base!$C$4:$L$4)+MAX(0,MIN(DCF_Base!$L$22*(1+D$32)/($A$36-D$32),Assumptions!$B$8*DCF_Base!$L$22))/(1+$A$36)^10-Assumptions!$B$5)/Assumptions!$B$6,"n/a") | E36: =IF($A$36>E$32,(SUMPRODUCT(DCF_Base!$C$22:$L$22/(1+$A$36)^DCF_Base!$C$4:$L$4)+MAX(0,MIN(DCF_Base!$L$22*(1+E$32)/($A$36-E$32),Assumptions!$B$8*DCF_Base!$L$22))/(1+$A$36)^10-Assumptions!$B$5)/Assumptions!$B$6,"n/a") | F36: =IF($A$36>F$32,(SUMPRODUCT(DCF_Base!$C$22:$L$22/(1+$A$36)^DCF_Base!$C$4:$L$4)+MAX(0,MIN(DCF_Base!$L$22*(1+F$32)/($A$36-F$32),Assumptions!$B$8*DCF_Base!$L$22))/(1+$A$36)^10-Assumptions!$B$5)/Assumptions!$B$6,"n/a")
A37: 0.1 | B37: =IF($A$37>B$32,(SUMPRODUCT(DCF_Base!$C$22:$L$22/(1+$A$37)^DCF_Base!$C$4:$L$4)+MAX(0,MIN(DCF_Base!$L$22*(1+B$32)/($A$37-B$32),Assumptions!$B$8*DCF_Base!$L$22))/(1+$A$37)^10-Assumptions!$B$5)/Assumptions!$B$6,"n/a") | C37: =IF($A$37>C$32,(SUMPRODUCT(DCF_Base!$C$22:$L$22/(1+$A$37)^DCF_Base!$C$4:$L$4)+MAX(0,MIN(DCF_Base!$L$22*(1+C$32)/($A$37-C$32),Assumptions!$B$8*DCF_Base!$L$22))/(1+$A$37)^10-Assumptions!$B$5)/Assumptions!$B$6,"n/a") | D37: =IF($A$37>D$32,(SUMPRODUCT(DCF_Base!$C$22:$L$22/(1+$A$37)^DCF_Base!$C$4:$L$4)+MAX(0,MIN(DCF_Base!$L$22*(1+D$32)/($A$37-D$32),Assumptions!$B$8*DCF_Base!$L$22))/(1+$A$37)^10-Assumptions!$B$5)/Assumptions!$B$6,"n/a") | E37: =IF($A$37>E$32,(SUMPRODUCT(DCF_Base!$C$22:$L$22/(1+$A$37)^DCF_Base!$C$4:$L$4)+MAX(0,MIN(DCF_Base!$L$22*(1+E$32)/($A$37-E$32),Assumptions!$B$8*DCF_Base!$L$22))/(1+$A$37)^10-Assumptions!$B$5)/Assumptions!$B$6,"n/a") | F37: =IF($A$37>F$32,(SUMPRODUCT(DCF_Base!$C$22:$L$22/(1+$A$37)^DCF_Base!$C$4:$L$4)+MAX(0,MIN(DCF_Base!$L$22*(1+F$32)/($A$37-F$32),Assumptions!$B$8*DCF_Base!$L$22))/(1+$A$37)^10-Assumptions!$B$5)/Assumptions!$B$6,"n/a")
A39: The 14x cap binds across most of the grid, so terminal growth barely moves the value at low WACC; the discount rate and year-10 FCF do.
