Workbook

Sheet Model_Info
A1: SKO.NZ - Serko Limited DCF model
A2: Version | B2: v1.0 - initial build. Supersedes nothing; no prior DCF existed for this ticker.
A3: Built by | B3: dcf-analyst agent (Claude Opus 5) on 2026-08-28, at the user request to value SKO.NZ.
A4: Model type | B4: Revenue x normalizing owner-FCF-margin DCF, component-built, 10-year explicit horizon, 3 scenarios probability-weighted.
A5: WHY NOT a trailing-FCF DCF | B5: Owner FCF (reported FCF less SBC, less interest income, less IFRS-16 lease principal) is NEGATIVE in all ten years FY2017-FY2026. FY2026 owner FCF -NZ$13.02m (-10.9% of revenue), WIDER than FY2025 -NZ$11.45m. There is no positive base cash flow to grow, so value is built from revenue x a margin that normalises over the explicit horizon.
A6: Price anchor | B6: NZ$1.465, Yahoo Finance NZX regular close 2026-08-28T02:13:17Z. 52-week range NZ$1.27-3.28. GOES STALE - refresh before use.
A7: Balance sheet anchor | B7: As at 2026-03-31 (FY2026 annual report). Net cash NZ$54.146m = cash at bank 14.146 + short-term deposits 40.0. Zero interest-bearing debt.
A8: Share count | B8: 124.882m issued ordinary shares at 31-Mar-2026. Zero options outstanding, so issued = fully diluted. Held FLAT because SBC is expensed.
A9: Lease treatment | B9: Treatment (B): IFRS-16 lease principal deducted INSIDE the flows as an operating cost (lease_cost_pct row), and lease liabilities of NZ$6.934m EXCLUDED from net debt. Charged once, never both. Lease cost sits inside EBIT so it is tax-deductible.
A10: SBC treatment | B10: NZ$7.246m FY2026 expensed in the flows AND share count held flat - charged exactly once. Some SBC is additionally capitalised into development costs, so true economic SBC is slightly higher; the model does not quantify that, making it marginally generous.
A11: Interest income | B11: NZ$1.540m stripped from the flows because net cash is added back in the bridge. Counting both double-counts the cash pile.
A12: Risk charged once | B12: Structural risk (illiquidity, loss-making, FX) sits in the WACC. Booking.com contract risk sits in the FLOWS via the bear scenario. A SINGLE WACC is used across all three scenarios - no per-scenario discount-rate differences.
A13: Scenario judgment | B13: Driver paths set by the dcf-analyst agent on 2026-08-28 from FY2026 annual report actuals, FY2027 company guidance, and the Q1 FY2027 trading update. Weights 35 bear / 45 base / 20 bull - deliberately more bearish than the 15/50/35 house default.
... A16: Caveat | B16: These figures go stale. Re-anchor price, balance sheet and guidance before relying on any number here.

Sheet Actuals
A1: Serko - reported history (NZD millions)
A3: NZD millions | B3: FY2017 | C3: FY2018 | D3: FY2019 | E3: FY2020 | F3: FY2021 | G3: FY2022 | H3: FY2023 | I3: FY2024 | J3: FY2025 | K3: FY2026
A4: Revenue | B4: 14.277 | C4: 18.279 | D4: 23.361 | E4: 25.869 | F4: 12.42 | G4: 17.855 | H4: 46.492 | I4: 68.761 | J4: 88.482 | K4: 119.391
A5: EBITDA (reported) | B5: -3.394 | C5: 1.589 | D5: 1.256 | E5: -7.145 | F5: -22.325 | G5: -28.145 | H5: -21.754 | I5: -1.577 | J5: 2.75 | K5: 6.531
A6: Net profit / (loss) | B6: -3.45 | C6: 1.832 | D6: 1.633 | E6: -9.364 | F6: -29.389 | G6: -35.959 | H6: -30.54 | I6: -15.879 | J6: -21.962 | K6: -17.737
A7: Operating cash flow | B7: -1.595 | C7: 1.416 | D7: 3.647 | E7: -3.789 | F7: -18.042 | G7: -18.456 | H7: -22.326 | I7: 5.895 | J7: 4.822 | K7: 7.03
A8: Capex (PPE + capitalised dev) | B8: -1.038 | C8: -0.519 | D8: -7.279 | E8: -11.812 | F8: -7.79 | G8: -16.094 | H8: -14.014 | I8: -11.425 | J8: -6.218 | K8: -9.92
A9: Reported free cash flow | B9: -2.633 | C9: 0.897 | D9: -3.632 | E9: -15.601 | F9: -25.832 | G9: -34.55 | H9: -36.34 | I9: -5.53 | J9: -1.396 | K9: -2.89
A10: Share-based payments | B10: 0.133 | C10: 0.288 | D10: 0.576 | E10: 0.959 | F10: 3.184 | G10: 4.095 | H10: 6.008 | I10: 5.048 | J10: 5.429 | K10: 7.246
A11: Interest income | B11: 0.142 | C11: 0.475 | D11: 0.36 | E11: 1.137 | F11: 0.38 | G11: 0.696 | H11: 2.878 | I11: 4.167 | J11: 3.47 | K11: 1.54
A12: IFRS-16 lease principal | B12: 0 | C12: 0 | D12: 0 | E12: 0.6 | F12: 0.9 | G12: 1 | H12: 1.1 | I12: 1.1 | J12: 1.159 | K12: 1.344
A13: Shareholders equity | B13: 6.276 | C13: 8.344 | D13: 26.235 | E13: 63.784 | F13: 102.528 | G13: 150.881 | H13: 125.93 | I13: 115.726 | J13: 99.938 | K13: 88.663
A14: Shares outstanding (m) | B14: 74.894 | C14: 74.894 | D14: 80.923 | E14: 92.739 | F14: 107.822 | G14: 119.921 | H14: 120.443 | I14: 121.846 | J14: 123.126 | K14: 124.882
A15: OWNER FCF (reported less SBC, interest, lease) | B15: =B9-B10-B11-B12 | C15: =C9-C10-C11-C12 | D15: =D9-D10-D11-D12 | E15: =E9-E10-E11-E12 | F15: =F9-F10-F11-F12 | G15: =G9-G10-G11-G12 | H15: =H9-H10-H11-H12 | I15: =I9-I10-I11-I12 | ... K15: =K9-K10-K11-K12
A16: Owner FCF margin | B16: =B15/B4 | C16: =C15/C4 | D16: =D15/D4 | E16: =E15/E4 | F16: =F15/F4 | G16: =G15/G4 | H16: =H15/H4 | I16: =I15/I4 | ... K16: =K15/K4
A18: Source: SKO.NZ_Metrics.csv, derived from the FY2017-FY2026 annual reports.
A19: Owner FCF is NEGATIVE in all ten years - the reason this model is not a trailing-FCF DCF.
A20: Lease principal FY2026 NZ$1.344m and FY2025 NZ$1.159m are from the cash flow statement (financing). Earlier years estimated.
A21: FY2027 guidance: total income NZ$128-134m, total spend NZ$132-140m - spend EXCEEDS income at every point.
A22: FY2030 aspiration (NOT guidance): revenue NZ$250m, FCF NZ$100m.
A23: Management missed 3 of 5 FY2026 scorecard KPIs: B4B CRN threshold 4.360m not met, platform capabilities, North American ARR.
A24: Two customers = 71% of FY2026 revenue (NZ$84.9m). Booking.com contract expires 31-Mar-2029, 12-month mutual termination, non-exclusive.
A25: Net cash NZ$54.146m = cash at bank 14.146 + short-term deposits 40.0. Zero interest-bearing debt. Lease liabilities 6.934 (NOT in net debt).

Sheet Assumptions
A1: Global assumptions
A3: WACC | B3: 0.175 | C3: Cost of equity; zero interest-bearing debt so WACC = CoE. NZD-built: 4.5% NZ 10yr + 9.0% ERPxbeta + 2.0% small-cap illiquidity + 1.5% loss-making + 0.5% EUR/NZD mismatch.
A4: Working capital capture - reference only (per-scenario values below) | B4: 0.08 | C4: Applied to the CHANGE in revenue, not the level. Low at 8% - Serko has minimal deferred revenue (NZ$1.9m) and is not a prepaid subscription model. The DCF tabs read the PER-SCENARIO value from column E of the scenario table below (bull uses 10%), not this cell.
A5: Net cash (NZ$m) | B5: 54.146 | C5: Cash at bank 14.146 + short-term deposits 40.0 at 2026-03-31. Zero debt. Lease liabilities EXCLUDED (treatment B).
A6: Net debt (NZ$m) | B6: -54.146 | C6: Negative = net cash. Used in the equity bridge.
A7: Diluted shares (m) | B7: 124.882 | C7: Issued ordinary shares at 31-Mar-2026; zero options outstanding. Held FLAT because SBC is expensed.
A8: Current price (NZ$) | B8: 1.465 | C8: NZX regular close 2026-08-28T02:13:17Z. Goes stale.
A9: Hurdle rate for entry price | B9: 0.15 | C9: Required IRR for the buy-below price.
A11: Per-scenario
A12: Scenario | B12: Terminal growth | C12: TV cap multiple | D12: Probability weight | E12: WC capture % of rev change
A13: Bear | B13: 0.01 | C13: 8 | D13: 0.35 | E13: 0.08
A14: Base | B14: 0.025 | C14: 12 | D14: 0.45 | E14: 0.08
A15: Bull | B15: 0.03 | C15: 14 | D15: 0.2 | E15: 0.1
A16: Weights check (must be 100%) | D16: =SUM(D13:D15)
A18: Scenario narratives
A19: Bear | C19: THE BOOKING.COM CLIFF. The contract expires 31 March 2029 and is terminable on 12 months' notice by either side, so notice could be served as early as FY2028. Booking Holdings in-sources the SME business-travel layer it already brands as its own -- it has the capability, the customer relationship and the brand, and Serko's own COO came from Booking Holdings. Supplier commissions, 61% of revenue, run off through FY2030 (modelled as a 45% revenue collapse in that year). What remains is Zeno in Australasia -- a genuinely entrenched but MATURE business growing online bookings 1.3% a year -- plus GetThere, which management already guides to DECLINE. Serko.ai has no revenue. The residual business is subscale against its cost base, so owner FCF stays negative throughout and terminal value hits the zero floor. Equity value is negative: the NZ$54m cash pile is consumed before the rump stabilises.
A20: Base | C20: RENEWED, BUT ON WORSE TERMS. Booking.com renews in 2029 because the relationship works for both sides, but prices it to its own advantage -- Serko is non-exclusive and replaceable, and the volume tiers already ratchet the take rate down from ~48.7% toward 40% at 6m room nights. Volume keeps compounding at 15-20%; revenue grows at roughly half that as the take rate erodes, starting from the guided +8.4% in FY2027 when spend exceeds income and operating leverage goes BACKWARDS exactly as management guides. The cost optimisation programme and the roll-off of the FY2022-24 capitalised-development amortisation wave then let margins expand slowly. Owner FCF crosses zero around FY2032 -- two to three years later than management's own FY2029-30 inflection, because management's framing excludes SBC and lease principal. Terminal owner-FCF margin 5.0%. Equity value is essentially the cash.
A21: Bull | C21: THE AI OPERATING LAYER LANDS. Serko.ai converts from closed beta into a commercial product with a new pricing model, monetising two decades of proprietary corporate booking behaviour and supplier connectivity that a generic LLM wrapper cannot synthesise. The US corporate wedge -- management sizes USD$16-24bn of accommodation spend in the target industries -- converts well beyond the two customers signed to date, feeding volume into the Booking.com engine Serko already operates. Booking.com renews on acceptable terms because Serko has become harder to replace. Revenue compounds mid-to-high teens toward the NZ$250m FY2030 aspiration, and the cost-optimisation programme delivers real operating leverage to a 27.5% EBITDA margin. Even so, this lands at NZ$1.33 -- BELOW the current price, which is the single most telling output of the model.
A22: Weights rationale | C22: 35% bear / 45% base / 20% bull -- materially more bearish than the 15/50/35 house default, and deliberately so. BEAR raised to 35% because the Booking.com contract (61% of revenue, 71% concentration with one other customer) expires 31-Mar-2029 INSIDE the forecast window, is terminable by either side on 12 months' notice, and is NON-EXCLUSIVE -- so an adverse outcome is a specifically-dated contractual event, not a tail risk. Management also missed three of five FY2026 scorecard KPIs, including the B4B CRN threshold (4.360m target, not met) and North American contracted ARR. BULL cut to 20% because it requires three independent things to go right at once: Serko.ai commercialising from closed beta, the US corporate wedge converting beyond the two customers signed to date, AND Booking.com renewing on acceptable terms. BASE at 45% is the residual: contract renewed but on worse economics, consistent with the take-rate step-down already visible in Q1 FY2027 (CRNs +39%, revenue per room night -11%).

Sheet DCF_Bear
A1: BEAR case - component owner-FCF build (NZD millions)
A3: Year | B3: FY2026A | C3: FY2027E | D3: FY2028E | E3: FY2029E | F3: FY2030E | G3: FY2031E | H3: FY2032E | I3: FY2033E | J3: FY2034E | K3: FY2035E | L3: FY2036E
A4: Year index | B4: 0 | C4: 1 | D4: 2 | E4: 3 | F4: 4 | G4: 5 | H4: 6 | I4: 7 | J4: 8 | K4: 9 | L4: 10
A5: Revenue growth YoY [DRIVER] | C5: 0.05 | D5: 0.04 | E5: 0.02 | F5: -0.45 | G5: -0.08 | H5: -0.02 | I5: 0 | J5: 0.01 | K5: 0.01 | L5: 0.01
A6: Revenue | B6: 119.391 | C6: =B6*(1+C5) | D6: =C6*(1+D5) | E6: =D6*(1+E5) | F6: =E6*(1+F5) | G6: =F6*(1+G5) | H6: =G6*(1+H5) | I6: =H6*(1+I5) | J6: =I6*(1+J5) | ... L6: =K6*(1+L5)
A7: Adj EBITDA margin [DRIVER] | C7: 0.01 | D7: 0.015 | E7: 0.02 | F7: -0.08 | G7: 0 | H7: 0.03 | I7: 0.05 | J7: 0.065 | K7: 0.075 | L7: 0.08
A8: Adjusted EBITDA | C8: =C6*C7 | D8: =D6*D7 | E8: =E6*E7 | F8: =F6*F7 | G8: =G6*G7 | H8: =H6*H7 | I8: =I6*I7 | J8: =J6*J7 | ... L8: =L6*L7
A9: SBC % of revenue [DRIVER] | C9: 0.06 | D9: 0.06 | E9: 0.06 | F9: 0.07 | G9: 0.065 | H9: 0.06 | I9: 0.055 | J9: 0.055 | K9: 0.055 | L9: 0.055
A10: less SBC | C10: =-C6*C9 | D10: =-D6*D9 | E10: =-E6*E9 | F10: =-F6*F9 | G10: =-G6*G9 | H10: =-H6*H9 | I10: =-I6*I9 | J10: =-J6*J9 | ... L10: =-L6*L9
A11: Lease cost % of revenue (IFRS-16 principal) | C11: 0.011 | D11: 0.011 | E11: 0.011 | F11: 0.015 | G11: 0.013 | H11: 0.012 | I11: 0.011 | J11: 0.011 | K11: 0.011 | L11: 0.011
A12: less lease cost | C12: =-C6*C11 | D12: =-D6*D11 | E12: =-E6*E11 | F12: =-F6*F11 | G12: =-G6*G11 | H12: =-H6*H11 | I12: =-I6*I11 | J12: =-J6*J11 | ... L12: =-L6*L11
A13: D&A % of revenue | C13: 0.135 | D13: 0.13 | E13: 0.125 | F13: 0.16 | G13: 0.13 | H13: 0.11 | I13: 0.1 | J13: 0.095 | K13: 0.09 | L13: 0.09
A14: less D&A | C14: =-C6*C13 | D14: =-D6*D13 | E14: =-E6*E13 | F14: =-F6*F13 | G14: =-G6*G13 | H14: =-H6*H13 | I14: =-I6*I13 | J14: =-J6*J13 | ... L14: =-L6*L13
A15: EBIT (SBC and lease expensed) | C15: =C8+C10+C12+C14 | D15: =D8+D10+D12+D14 | E15: =E8+E10+E12+E14 | F15: =F8+F10+F12+F14 | G15: =G8+G10+G12+G14 | H15: =H8+H10+H12+H14 | I15: =I8+I10+I12+I14 | J15: =J8+J10+J12+J14 | ... L15: =L8+L10+L12+L14
A16: Cash tax rate [DRIVER] | C16: 0 | D16: 0 | E16: 0 | F16: 0 | G16: 0 | H16: 0 | I16: 0 | J16: 0 | K16: 0 | L16: 0
A17: NOPAT (tax on positive EBIT only) | C17: =C15-MAX(0,C15)*C16 | D17: =D15-MAX(0,D15)*D16 | E17: =E15-MAX(0,E15)*E16 | F17: =F15-MAX(0,F15)*F16 | G17: =G15-MAX(0,G15)*G16 | H17: =H15-MAX(0,H15)*H16 | I17: =I15-MAX(0,I15)*I16 | J17: =J15-MAX(0,J15)*J16 | ... L17: =L15-MAX(0,L15)*L16
A18: add back D&A | C18: =-C14 | D18: =-D14 | E18: =-E14 | F18: =-F14 | G18: =-G14 | H18: =-H14 | I18: =-I14 | J18: =-J14 | ... L18: =-L14
A19: Capex % of revenue | C19: 0.09 | D19: 0.09 | E19: 0.09 | F19: 0.1 | G19: 0.09 | H19: 0.085 | I19: 0.08 | J19: 0.08 | K19: 0.08 | L19: 0.08
A20: less capex | C20: =-C6*C19 | D20: =-D6*D19 | E20: =-E6*E19 | F20: =-F6*F19 | G20: =-G6*G19 | H20: =-H6*H19 | I20: =-I6*I19 | J20: =-J6*J19 | ... L20: =-L6*L19
A21: add working capital (on revenue CHANGE) | C21: =Assumptions!$E$13*(C6-B6) | D21: =Assumptions!$E$13*(D6-C6) | E21: =Assumptions!$E$13*(E6-D6) | F21: =Assumptions!$E$13*(F6-E6) | G21: =Assumptions!$E$13*(G6-F6) | H21: =Assumptions!$E$13*(H6-G6) | I21: =Assumptions!$E$13*(I6-H6) | J21: =Assumptions!$E$13*(J6-I6) | ... L21: =Assumptions!$E$13*(L6-K6)
A22: UNLEVERED OWNER FCF | C22: =C17+C18+C20+C21 | D22: =D17+D18+D20+D21 | E22: =E17+E18+E20+E21 | F22: =F17+F18+F20+F21 | G22: =G17+G18+G20+G21 | H22: =H17+H18+H20+H21 | I22: =I17+I18+I20+I21 | J22: =J17+J18+J20+J21 | ... L22: =L17+L18+L20+L21
A23: Discount factor | C23: =1/(1+Assumptions!$B3)^C4 | D23: =1/(1+Assumptions!$B3)^D4 | E23: =1/(1+Assumptions!$B3)^E4 | F23: =1/(1+Assumptions!$B3)^F4 | G23: =1/(1+Assumptions!$B3)^G4 | H23: =1/(1+Assumptions!$B3)^H4 | I23: =1/(1+Assumptions!$B3)^I4 | J23: =1/(1+Assumptions!$B3)^J4 | ... L23: =1/(1+Assumptions!$B3)^L4
A24: PV of FCF | C24: =C22*C23 | D24: =D22*D23 | E24: =E22*E23 | F24: =F22*F23 | G24: =G22*G23 | H24: =H22*H23 | I24: =I22*I23 | J24: =J22*J23 | ... L24: =L22*L23
A26: Memo: FCF before SBC (company-style) | C26: =C22-C10 | D26: =D22-D10 | E26: =E22-E10 | F26: =F22-F10 | G26: =G22-G10 | H26: =H22-H10 | I26: =I22-I10 | J26: =J22-J10 | ... L26: =L22-L10
A27: Memo: implied owner-FCF margin | C27: =C22/C6 | D27: =D22/D6 | E27: =E22/E6 | F27: =F22/F6 | G27: =G22/G6 | H27: =H22/H6 | I27: =I22/I6 | J27: =J22/J6 | ... L27: =L22/L6
A29: Sum of PV of FCF | B29: =SUM(C24:L24)
A30: Terminal growth | B30: =Assumptions!$B$13
A31: TV cap multiple | B31: =Assumptions!$C$13
A32: Terminal year FCF x (1+g) | B32: =L22*(1+B30)
A33: Gordon terminal value | B33: =IF(Assumptions!$B3>B30,B32/(Assumptions!$B3-B30),B32*B31)
A34: Cap terminal value | B34: =B31*L22
A35: TV used = MAX(0, MIN(Gordon, cap)) | B35: =MAX(0,MIN(B33,B34))
A36: Implied exit multiple | B36: =IFERROR(B35/L22,0)
A37: PV of terminal value | B37: =B35*L23
A38: Enterprise value | B38: =B29+B37
A39: less net debt (add net cash) | B39: =-Assumptions!$B6
A40: Equity value | B40: =B38+B39
A41: Diluted shares (m) | B41: =Assumptions!$B7
A42: VALUE PER SHARE | B42: =B40/B41
A43: Upside vs current price | B43: =B42/Assumptions!$B8-1
...

Sheet DCF_Base
A1: BASE case - component owner-FCF build (NZD millions)
A3: Year | B3: FY2026A | C3: FY2027E | D3: FY2028E | E3: FY2029E | F3: FY2030E | G3: FY2031E | H3: FY2032E | I3: FY2033E | J3: FY2034E | K3: FY2035E | L3: FY2036E
A4: Year index | B4: 0 | C4: 1 | D4: 2 | E4: 3 | F4: 4 | G4: 5 | H4: 6 | I4: 7 | J4: 8 | K4: 9 | L4: 10
A5: Revenue growth YoY [DRIVER] | C5: 0.084 | D5: 0.1 | E5: 0.12 | F5: 0.09 | G5: 0.08 | H5: 0.07 | I5: 0.06 | J5: 0.05 | K5: 0.045 | L5: 0.04
A6: Revenue | B6: 119.391 | C6: =B6*(1+C5) | D6: =C6*(1+D5) | E6: =D6*(1+E5) | F6: =E6*(1+F5) | G6: =F6*(1+G5) | H6: =G6*(1+H5) | I6: =H6*(1+I5) | J6: =I6*(1+J5) | ... L6: =K6*(1+L5)
A7: Adj EBITDA margin [DRIVER] | C7: 0.035 | D7: 0.055 | E7: 0.08 | F7: 0.105 | G7: 0.13 | H7: 0.15 | I7: 0.165 | J7: 0.175 | K7: 0.18 | L7: 0.185
A8: Adjusted EBITDA | C8: =C6*C7 | D8: =D6*D7 | E8: =E6*E7 | F8: =F6*F7 | G8: =G6*G7 | H8: =H6*H7 | I8: =I6*I7 | J8: =J6*J7 | ... L8: =L6*L7
A9: SBC % of revenue [DRIVER] | C9: 0.06 | D9: 0.058 | E9: 0.056 | F9: 0.054 | G9: 0.052 | H9: 0.05 | I9: 0.048 | J9: 0.046 | K9: 0.045 | L9: 0.044
A10: less SBC | C10: =-C6*C9 | D10: =-D6*D9 | E10: =-E6*E9 | F10: =-F6*F9 | G10: =-G6*G9 | H10: =-H6*H9 | I10: =-I6*I9 | J10: =-J6*J9 | ... L10: =-L6*L9
A11: Lease cost % of revenue (IFRS-16 principal) | C11: 0.011 | D11: 0.011 | E11: 0.011 | F11: 0.01 | G11: 0.01 | H11: 0.01 | I11: 0.01 | J11: 0.01 | K11: 0.01 | L11: 0.01
A12: less lease cost | C12: =-C6*C11 | D12: =-D6*D11 | E12: =-E6*E11 | F12: =-F6*F11 | G12: =-G6*G11 | H12: =-H6*H11 | I12: =-I6*I11 | J12: =-J6*J11 | ... L12: =-L6*L11
A13: D&A % of revenue | C13: 0.13 | D13: 0.12 | E13: 0.11 | F13: 0.1 | G13: 0.095 | H13: 0.09 | I13: 0.085 | J13: 0.08 | K13: 0.08 | L13: 0.08
A14: less D&A | C14: =-C6*C13 | D14: =-D6*D13 | E14: =-E6*E13 | F14: =-F6*F13 | G14: =-G6*G13 | H14: =-H6*H13 | I14: =-I6*I13 | J14: =-J6*J13 | ... L14: =-L6*L13
A15: EBIT (SBC and lease expensed) | C15: =C8+C10+C12+C14 | D15: =D8+D10+D12+D14 | E15: =E8+E10+E12+E14 | F15: =F8+F10+F12+F14 | G15: =G8+G10+G12+G14 | H15: =H8+H10+H12+H14 | I15: =I8+I10+I12+I14 | J15: =J8+J10+J12+J14 | ... L15: =L8+L10+L12+L14
A16: Cash tax rate [DRIVER] | C16: 0 | D16: 0 | E16: 0 | F16: 0 | G16: 0.03 | H16: 0.08 | I16: 0.14 | J16: 0.2 | K16: 0.25 | L16: 0.28
A17: NOPAT (tax on positive EBIT only) | C17: =C15-MAX(0,C15)*C16 | D17: =D15-MAX(0,D15)*D16 | E17: =E15-MAX(0,E15)*E16 | F17: =F15-MAX(0,F15)*F16 | G17: =G15-MAX(0,G15)*G16 | H17: =H15-MAX(0,H15)*H16 | I17: =I15-MAX(0,I15)*I16 | J17: =J15-MAX(0,J15)*J16 | ... L17: =L15-MAX(0,L15)*L16
A18: add back D&A | C18: =-C14 | D18: =-D14 | E18: =-E14 | F18: =-F14 | G18: =-G14 | H18: =-H14 | I18: =-I14 | J18: =-J14 | ... L18: =-L14
A19: Capex % of revenue | C19: 0.085 | D19: 0.082 | E19: 0.08 | F19: 0.078 | G19: 0.075 | H19: 0.072 | I19: 0.07 | J19: 0.07 | K19: 0.07 | L19: 0.07
A20: less capex | C20: =-C6*C19 | D20: =-D6*D19 | E20: =-E6*E19 | F20: =-F6*F19 | G20: =-G6*G19 | H20: =-H6*H19 | I20: =-I6*I19 | J20: =-J6*J19 | ... L20: =-L6*L19
A21: add working capital (on revenue CHANGE) | C21: =Assumptions!$E$14*(C6-B6) | D21: =Assumptions!$E$14*(D6-C6) | E21: =Assumptions!$E$14*(E6-D6) | F21: =Assumptions!$E$14*(F6-E6) | G21: =Assumptions!$E$14*(G6-F6) | H21: =Assumptions!$E$14*(H6-G6) | I21: =Assumptions!$E$14*(I6-H6) | J21: =Assumptions!$E$14*(J6-I6) | ... L21: =Assumptions!$E$14*(L6-K6)
A22: UNLEVERED OWNER FCF | C22: =C17+C18+C20+C21 | D22: =D17+D18+D20+D21 | E22: =E17+E18+E20+E21 | F22: =F17+F18+F20+F21 | G22: =G17+G18+G20+G21 | H22: =H17+H18+H20+H21 | I22: =I17+I18+I20+I21 | J22: =J17+J18+J20+J21 | ... L22: =L17+L18+L20+L21
A23: Discount factor | C23: =1/(1+Assumptions!$B3)^C4 | D23: =1/(1+Assumptions!$B3)^D4 | E23: =1/(1+Assumptions!$B3)^E4 | F23: =1/(1+Assumptions!$B3)^F4 | G23: =1/(1+Assumptions!$B3)^G4 | H23: =1/(1+Assumptions!$B3)^H4 | I23: =1/(1+Assumptions!$B3)^I4 | J23: =1/(1+Assumptions!$B3)^J4 | ... L23: =1/(1+Assumptions!$B3)^L4
A24: PV of FCF | C24: =C22*C23 | D24: =D22*D23 | E24: =E22*E23 | F24: =F22*F23 | G24: =G22*G23 | H24: =H22*H23 | I24: =I22*I23 | J24: =J22*J23 | ... L24: =L22*L23
A26: Memo: FCF before SBC (company-style) | C26: =C22-C10 | D26: =D22-D10 | E26: =E22-E10 | F26: =F22-F10 | G26: =G22-G10 | H26: =H22-H10 | I26: =I22-I10 | J26: =J22-J10 | ... L26: =L22-L10
A27: Memo: implied owner-FCF margin | C27: =C22/C6 | D27: =D22/D6 | E27: =E22/E6 | F27: =F22/F6 | G27: =G22/G6 | H27: =H22/H6 | I27: =I22/I6 | J27: =J22/J6 | ... L27: =L22/L6
A29: Sum of PV of FCF | B29: =SUM(C24:L24)
A30: Terminal growth | B30: =Assumptions!$B$14
A31: TV cap multiple | B31: =Assumptions!$C$14
A32: Terminal year FCF x (1+g) | B32: =L22*(1+B30)
A33: Gordon terminal value | B33: =IF(Assumptions!$B3>B30,B32/(Assumptions!$B3-B30),B32*B31)
A34: Cap terminal value | B34: =B31*L22
A35: TV used = MAX(0, MIN(Gordon, cap)) | B35: =MAX(0,MIN(B33,B34))
A36: Implied exit multiple | B36: =IFERROR(B35/L22,0)
A37: PV of terminal value | B37: =B35*L23
A38: Enterprise value | B38: =B29+B37
A39: less net debt (add net cash) | B39: =-Assumptions!$B6
A40: Equity value | B40: =B38+B39
A41: Diluted shares (m) | B41: =Assumptions!$B7
A42: VALUE PER SHARE | B42: =B40/B41
A43: Upside vs current price | B43: =B42/Assumptions!$B8-1
...

Sheet DCF_Bull
A1: BULL case - component owner-FCF build (NZD millions)
A3: Year | B3: FY2026A | C3: FY2027E | D3: FY2028E | E3: FY2029E | F3: FY2030E | G3: FY2031E | H3: FY2032E | I3: FY2033E | J3: FY2034E | K3: FY2035E | L3: FY2036E
A4: Year index | B4: 0 | C4: 1 | D4: 2 | E4: 3 | F4: 4 | G4: 5 | H4: 6 | I4: 7 | J4: 8 | K4: 9 | L4: 10
A5: Revenue growth YoY [DRIVER] | C5: 0.11 | D5: 0.16 | E5: 0.18 | F5: 0.16 | G5: 0.14 | H5: 0.12 | I5: 0.1 | J5: 0.08 | K5: 0.065 | L5: 0.055
A6: Revenue | B6: 119.391 | C6: =B6*(1+C5) | D6: =C6*(1+D5) | E6: =D6*(1+E5) | F6: =E6*(1+F5) | G6: =F6*(1+G5) | H6: =G6*(1+H5) | I6: =H6*(1+I5) | J6: =I6*(1+J5) | ... L6: =K6*(1+L5)
A7: Adj EBITDA margin [DRIVER] | C7: 0.05 | D7: 0.09 | E7: 0.13 | F7: 0.17 | G7: 0.205 | H7: 0.23 | I7: 0.25 | J7: 0.26 | K7: 0.27 | L7: 0.275
A8: Adjusted EBITDA | C8: =C6*C7 | D8: =D6*D7 | E8: =E6*E7 | F8: =F6*F7 | G8: =G6*G7 | H8: =H6*H7 | I8: =I6*I7 | J8: =J6*J7 | ... L8: =L6*L7
A9: SBC % of revenue [DRIVER] | C9: 0.06 | D9: 0.057 | E9: 0.054 | F9: 0.051 | G9: 0.048 | H9: 0.045 | I9: 0.043 | J9: 0.041 | K9: 0.04 | L9: 0.04
A10: less SBC | C10: =-C6*C9 | D10: =-D6*D9 | E10: =-E6*E9 | F10: =-F6*F9 | G10: =-G6*G9 | H10: =-H6*H9 | I10: =-I6*I9 | J10: =-J6*J9 | ... L10: =-L6*L9
A11: Lease cost % of revenue (IFRS-16 principal) | C11: 0.011 | D11: 0.01 | E11: 0.01 | F11: 0.01 | G11: 0.01 | H11: 0.01 | I11: 0.01 | J11: 0.01 | K11: 0.01 | L11: 0.01
A12: less lease cost | C12: =-C6*C11 | D12: =-D6*D11 | E12: =-E6*E11 | F12: =-F6*F11 | G12: =-G6*G11 | H12: =-H6*H11 | I12: =-I6*I11 | J12: =-J6*J11 | ... L12: =-L6*L11
A13: D&A % of revenue | C13: 0.125 | D13: 0.115 | E13: 0.105 | F13: 0.095 | G13: 0.09 | H13: 0.085 | I13: 0.08 | J13: 0.08 | K13: 0.08 | L13: 0.08
A14: less D&A | C14: =-C6*C13 | D14: =-D6*D13 | E14: =-E6*E13 | F14: =-F6*F13 | G14: =-G6*G13 | H14: =-H6*H13 | I14: =-I6*I13 | J14: =-J6*J13 | ... L14: =-L6*L13
A15: EBIT (SBC and lease expensed) | C15: =C8+C10+C12+C14 | D15: =D8+D10+D12+D14 | E15: =E8+E10+E12+E14 | F15: =F8+F10+F12+F14 | G15: =G8+G10+G12+G14 | H15: =H8+H10+H12+H14 | I15: =I8+I10+I12+I14 | J15: =J8+J10+J12+J14 | ... L15: =L8+L10+L12+L14
A16: Cash tax rate [DRIVER] | C16: 0 | D16: 0 | E16: 0 | F16: 0 | G16: 0 | H16: 0.05 | I16: 0.12 | J16: 0.18 | K16: 0.24 | L16: 0.28
A17: NOPAT (tax on positive EBIT only) | C17: =C15-MAX(0,C15)*C16 | D17: =D15-MAX(0,D15)*D16 | E17: =E15-MAX(0,E15)*E16 | F17: =F15-MAX(0,F15)*F16 | G17: =G15-MAX(0,G15)*G16 | H17: =H15-MAX(0,H15)*H16 | I17: =I15-MAX(0,I15)*I16 | J17: =J15-MAX(0,J15)*J16 | ... L17: =L15-MAX(0,L15)*L16
A18: add back D&A | C18: =-C14 | D18: =-D14 | E18: =-E14 | F18: =-F14 | G18: =-G14 | H18: =-H14 | I18: =-I14 | J18: =-J14 | ... L18: =-L14
A19: Capex % of revenue | C19: 0.085 | D19: 0.08 | E19: 0.078 | F19: 0.075 | G19: 0.072 | H19: 0.07 | I19: 0.07 | J19: 0.07 | K19: 0.07 | L19: 0.07
A20: less capex | C20: =-C6*C19 | D20: =-D6*D19 | E20: =-E6*E19 | F20: =-F6*F19 | G20: =-G6*G19 | H20: =-H6*H19 | I20: =-I6*I19 | J20: =-J6*J19 | ... L20: =-L6*L19
A21: add working capital (on revenue CHANGE) | C21: =Assumptions!$E$15*(C6-B6) | D21: =Assumptions!$E$15*(D6-C6) | E21: =Assumptions!$E$15*(E6-D6) | F21: =Assumptions!$E$15*(F6-E6) | G21: =Assumptions!$E$15*(G6-F6) | H21: =Assumptions!$E$15*(H6-G6) | I21: =Assumptions!$E$15*(I6-H6) | J21: =Assumptions!$E$15*(J6-I6) | ... L21: =Assumptions!$E$15*(L6-K6)
A22: UNLEVERED OWNER FCF | C22: =C17+C18+C20+C21 | D22: =D17+D18+D20+D21 | E22: =E17+E18+E20+E21 | F22: =F17+F18+F20+F21 | G22: =G17+G18+G20+G21 | H22: =H17+H18+H20+H21 | I22: =I17+I18+I20+I21 | J22: =J17+J18+J20+J21 | ... L22: =L17+L18+L20+L21
A23: Discount factor | C23: =1/(1+Assumptions!$B3)^C4 | D23: =1/(1+Assumptions!$B3)^D4 | E23: =1/(1+Assumptions!$B3)^E4 | F23: =1/(1+Assumptions!$B3)^F4 | G23: =1/(1+Assumptions!$B3)^G4 | H23: =1/(1+Assumptions!$B3)^H4 | I23: =1/(1+Assumptions!$B3)^I4 | J23: =1/(1+Assumptions!$B3)^J4 | ... L23: =1/(1+Assumptions!$B3)^L4
A24: PV of FCF | C24: =C22*C23 | D24: =D22*D23 | E24: =E22*E23 | F24: =F22*F23 | G24: =G22*G23 | H24: =H22*H23 | I24: =I22*I23 | J24: =J22*J23 | ... L24: =L22*L23
A26: Memo: FCF before SBC (company-style) | C26: =C22-C10 | D26: =D22-D10 | E26: =E22-E10 | F26: =F22-F10 | G26: =G22-G10 | H26: =H22-H10 | I26: =I22-I10 | J26: =J22-J10 | ... L26: =L22-L10
A27: Memo: implied owner-FCF margin | C27: =C22/C6 | D27: =D22/D6 | E27: =E22/E6 | F27: =F22/F6 | G27: =G22/G6 | H27: =H22/H6 | I27: =I22/I6 | J27: =J22/J6 | ... L27: =L22/L6
A29: Sum of PV of FCF | B29: =SUM(C24:L24)
A30: Terminal growth | B30: =Assumptions!$B$15
A31: TV cap multiple | B31: =Assumptions!$C$15
A32: Terminal year FCF x (1+g) | B32: =L22*(1+B30)
A33: Gordon terminal value | B33: =IF(Assumptions!$B3>B30,B32/(Assumptions!$B3-B30),B32*B31)
A34: Cap terminal value | B34: =B31*L22
A35: TV used = MAX(0, MIN(Gordon, cap)) | B35: =MAX(0,MIN(B33,B34))
A36: Implied exit multiple | B36: =IFERROR(B35/L22,0)
A37: PV of terminal value | B37: =B35*L23
A38: Enterprise value | B38: =B29+B37
A39: less net debt (add net cash) | B39: =-Assumptions!$B6
A40: Equity value | B40: =B38+B39
A41: Diluted shares (m) | B41: =Assumptions!$B7
A42: VALUE PER SHARE | B42: =B40/B41
A43: Upside vs current price | B43: =B42/Assumptions!$B8-1
...

Sheet FCF_Quality
A1: Reported FCF reconciled to owner FCF (NZD millions)
A3: NZD millions | B3: FY2017 | C3: FY2018 | D3: FY2019 | E3: FY2020 | F3: FY2021 | G3: FY2022 | H3: FY2023 | I3: FY2024 | J3: FY2025 | K3: FY2026
A4: Free cash flow (company definition) | B4: =Actuals!B9 | C4: =Actuals!C9 | D4: =Actuals!D9 | E4: =Actuals!E9 | F4: =Actuals!F9 | G4: =Actuals!G9 | H4: =Actuals!H9 | I4: =Actuals!I9 | ... K4: =Actuals!K9
A5: less: share-based payments | B5: =-Actuals!B10 | C5: =-Actuals!C10 | D5: =-Actuals!D10 | E5: =-Actuals!E10 | F5: =-Actuals!F10 | G5: =-Actuals!G10 | H5: =-Actuals!H10 | I5: =-Actuals!I10 | ... K5: =-Actuals!K10
A6: less: interest income | B6: =-Actuals!B11 | C6: =-Actuals!C11 | D6: =-Actuals!D11 | E6: =-Actuals!E11 | F6: =-Actuals!F11 | G6: =-Actuals!G11 | H6: =-Actuals!H11 | I6: =-Actuals!I11 | ... K6: =-Actuals!K11
A7: less: IFRS-16 lease principal | B7: =-Actuals!B12 | C7: =-Actuals!C12 | D7: =-Actuals!D12 | E7: =-Actuals!E12 | F7: =-Actuals!F12 | G7: =-Actuals!G12 | H7: =-Actuals!H12 | I7: =-Actuals!I12 | ... K7: =-Actuals!K12
A8: equals OWNER FCF | B8: =SUM(B4:B7) | C8: =SUM(C4:C7) | D8: =SUM(D4:D7) | E8: =SUM(E4:E7) | F8: =SUM(F4:F7) | G8: =SUM(G4:G7) | H8: =SUM(H4:H7) | I8: =SUM(I4:I7) | ... K8: =SUM(K4:K7)
A9: Reported FCF margin | B9: =Actuals!B9/Actuals!B4 | C9: =Actuals!C9/Actuals!C4 | D9: =Actuals!D9/Actuals!D4 | E9: =Actuals!E9/Actuals!E4 | F9: =Actuals!F9/Actuals!F4 | G9: =Actuals!G9/Actuals!G4 | H9: =Actuals!H9/Actuals!H4 | I9: =Actuals!I9/Actuals!I4 | ... K9: =Actuals!K9/Actuals!K4
A10: Owner FCF margin | B10: =B8/Actuals!B4 | C10: =C8/Actuals!C4 | D10: =D8/Actuals!D4 | E10: =E8/Actuals!E4 | F10: =F8/Actuals!F4 | G10: =G8/Actuals!G4 | H10: =H8/Actuals!H4 | I10: =I8/Actuals!I4 | ... K10: =K8/Actuals!K4
A12: Owner FCF is negative in ALL TEN years. Only FY2018 is even marginally positive at NZ$0.13m.
A13: FY2026 reported FCF improved to -2.89m from -1.40m only before SBC; on an owner basis the burn WIDENED from -11.45m to -13.02m.
A14: Deferred revenue is immaterial (NZ$1.938m FY2026), so unlike a prepaid SaaS there is no working-capital tailwind inside OCF.
A15: Cash taxes paid NZ$1.798m FY2026 despite pre-tax losses - foreign subsidiary taxes. NZ$138.7m of unrecognised NZ tax losses are unbooked.
A16: SBC of NZ$7.246m EXCEEDS the companys own EBITDAFI of NZ$6.5m - the headline profit metric is smaller than the equity cost it ignores.
A17: D&A of NZ$18.0m runs well above capex of NZ$9.9m as the FY2022-24 capitalised-development wave amortises - a real tailwind to FCF vs earnings.

Sheet Valuation
A1: SKO.NZ valuation summary
A3: Scenario | B3: Value per share | C3: Upside | D3: Probability | E3: Street value per share
A4: Bear | B4: =DCF_Bear!$B$42 | C4: =DCF_Bear!$B$43 | D4: =Assumptions!$D$13 | E4: =DCF_Bear!$B$48
A5: Base | B5: =DCF_Base!$B$42 | C5: =DCF_Base!$B$43 | D5: =Assumptions!$D$14 | E5: =DCF_Base!$B$48
A6: Bull | B6: =DCF_Bull!$B$42 | C6: =DCF_Bull!$B$43 | D6: =Assumptions!$D$15 | E6: =DCF_Bull!$B$48
A7: PROBABILITY-WEIGHTED VALUE | B7: =SUMPRODUCT(B4:B6,D4:D6) | E7: =SUMPRODUCT(E4:E6,D4:D6)
A8: Current price | B8: =Assumptions!$B8
A9: Margin of safety (1 - price/weighted) | B9: =1-Assumptions!$B8/B7
A10: Band position (0% house, 100% street) | B10: =(Assumptions!$B8-B7)/(E7-B7) | C10: Above 100% means the price exceeds even the SBC-as-non-cash ceiling.
A12: 15% hurdle entry price
A13: Scenario | B13: Entry price | C13: Note
A14: Bear | B14: =(SUMPRODUCT(DCF_Bear!C22:DCF_Bear!L22,1/(1+Assumptions!$B9)^DCF_Bear!C4:DCF_Bear!L4)+DCF_Bear!$B$35/(1+Assumptions!$B9)^10-Assumptions!$B6)/Assumptions!$B7
A15: Base | B15: =(SUMPRODUCT(DCF_Base!C22:DCF_Base!L22,1/(1+Assumptions!$B9)^DCF_Base!C4:DCF_Base!L4)+DCF_Base!$B$35/(1+Assumptions!$B9)^10-Assumptions!$B6)/Assumptions!$B7
A16: Bull | B16: =(SUMPRODUCT(DCF_Bull!C22:DCF_Bull!L22,1/(1+Assumptions!$B9)^DCF_Bull!C4:DCF_Bull!L4)+DCF_Bull!$B$35/(1+Assumptions!$B9)^10-Assumptions!$B6)/Assumptions!$B7
A17: WEIGHTED ENTRY PRICE (buy below) | B17: =SUMPRODUCT(B14:B16,D4:D6)
A19: Required-return table (base case)
A20: Required return | B20: 9% | C20: 10% | D20: 11% | E20: 12% | F20: 15% | G20: House WACC
A21: Value per share | B21: =(SUMPRODUCT(DCF_Base!C22:DCF_Base!L22,1/(1+0.09)^DCF_Base!C4:DCF_Base!L4)+DCF_Base!$B$35/(1+0.09)^10-Assumptions!$B6)/Assumptions!$B7 | C21: =(SUMPRODUCT(DCF_Base!C22:DCF_Base!L22,1/(1+0.1)^DCF_Base!C4:DCF_Base!L4)+DCF_Base!$B$35/(1+0.1)^10-Assumptions!$B6)/Assumptions!$B7 | D21: =(SUMPRODUCT(DCF_Base!C22:DCF_Base!L22,1/(1+0.11)^DCF_Base!C4:DCF_Base!L4)+DCF_Base!$B$35/(1+0.11)^10-Assumptions!$B6)/Assumptions!$B7 | E21: =(SUMPRODUCT(DCF_Base!C22:DCF_Base!L22,1/(1+0.12)^DCF_Base!C4:DCF_Base!L4)+DCF_Base!$B$35/(1+0.12)^10-Assumptions!$B6)/Assumptions!$B7 | F21: =(SUMPRODUCT(DCF_Base!C22:DCF_Base!L22,1/(1+0.15)^DCF_Base!C4:DCF_Base!L4)+DCF_Base!$B$35/(1+0.15)^10-Assumptions!$B6)/Assumptions!$B7 | G21: =(SUMPRODUCT(DCF_Base!C22:DCF_Base!L22,1/(1+Assumptions!$B3)^DCF_Base!C4:DCF_Base!L4)+DCF_Base!$B$35/(1+Assumptions!$B3)^10-Assumptions!$B6)/Assumptions!$B7
A22: Terminal value is computed at the house WACC (the fair exit price); only the discounting back uses the required return.
A24: Sensitivity: WACC x terminal growth (base case, value per share)
A25: WACC \ terminal g | B25: 0.015 | C25: 0.02 | D25: 0.025 | E25: 0.03 | F25: 0.035
A26: 0.155 | B26: =IF($A26>B$25,(SUMPRODUCT(DCF_Base!C22:DCF_Base!L22,1/(1+$A26)^DCF_Base!C4:DCF_Base!L4)+MAX(0,MIN(DCF_Base!L22*(1+B$25)/($A26-B$25),DCF_Base!$B$31*DCF_Base!L22))/(1+$A26)^10-Assumptions!$B6)/Assumptions!$B7,"n/a") | C26: =IF($A26>C$25,(SUMPRODUCT(DCF_Base!C22:DCF_Base!L22,1/(1+$A26)^DCF_Base!C4:DCF_Base!L4)+MAX(0,MIN(DCF_Base!L22*(1+C$25)/($A26-C$25),DCF_Base!$B$31*DCF_Base!L22))/(1+$A26)^10-Assumptions!$B6)/Assumptions!$B7,"n/a") | D26: =IF($A26>D$25,(SUMPRODUCT(DCF_Base!C22:DCF_Base!L22,1/(1+$A26)^DCF_Base!C4:DCF_Base!L4)+MAX(0,MIN(DCF_Base!L22*(1+D$25)/($A26-D$25),DCF_Base!$B$31*DCF_Base!L22))/(1+$A26)^10-Assumptions!$B6)/Assumptions!$B7,"n/a") | E26: =IF($A26>E$25,(SUMPRODUCT(DCF_Base!C22:DCF_Base!L22,1/(1+$A26)^DCF_Base!C4:DCF_Base!L4)+MAX(0,MIN(DCF_Base!L22*(1+E$25)/($A26-E$25),DCF_Base!$B$31*DCF_Base!L22))/(1+$A26)^10-Assumptions!$B6)/Assumptions!$B7,"n/a") | F26: =IF($A26>F$25,(SUMPRODUCT(DCF_Base!C22:DCF_Base!L22,1/(1+$A26)^DCF_Base!C4:DCF_Base!L4)+MAX(0,MIN(DCF_Base!L22*(1+F$25)/($A26-F$25),DCF_Base!$B$31*DCF_Base!L22))/(1+$A26)^10-Assumptions!$B6)/Assumptions!$B7,"n/a")
A27: 0.165 | B27: =IF($A27>B$25,(SUMPRODUCT(DCF_Base!C22:DCF_Base!L22,1/(1+$A27)^DCF_Base!C4:DCF_Base!L4)+MAX(0,MIN(DCF_Base!L22*(1+B$25)/($A27-B$25),DCF_Base!$B$31*DCF_Base!L22))/(1+$A27)^10-Assumptions!$B6)/Assumptions!$B7,"n/a") | C27: =IF($A27>C$25,(SUMPRODUCT(DCF_Base!C22:DCF_Base!L22,1/(1+$A27)^DCF_Base!C4:DCF_Base!L4)+MAX(0,MIN(DCF_Base!L22*(1+C$25)/($A27-C$25),DCF_Base!$B$31*DCF_Base!L22))/(1+$A27)^10-Assumptions!$B6)/Assumptions!$B7,"n/a") | D27: =IF($A27>D$25,(SUMPRODUCT(DCF_Base!C22:DCF_Base!L22,1/(1+$A27)^DCF_Base!C4:DCF_Base!L4)+MAX(0,MIN(DCF_Base!L22*(1+D$25)/($A27-D$25),DCF_Base!$B$31*DCF_Base!L22))/(1+$A27)^10-Assumptions!$B6)/Assumptions!$B7,"n/a") | E27: =IF($A27>E$25,(SUMPRODUCT(DCF_Base!C22:DCF_Base!L22,1/(1+$A27)^DCF_Base!C4:DCF_Base!L4)+MAX(0,MIN(DCF_Base!L22*(1+E$25)/($A27-E$25),DCF_Base!$B$31*DCF_Base!L22))/(1+$A27)^10-Assumptions!$B6)/Assumptions!$B7,"n/a") | F27: =IF($A27>F$25,(SUMPRODUCT(DCF_Base!C22:DCF_Base!L22,1/(1+$A27)^DCF_Base!C4:DCF_Base!L4)+MAX(0,MIN(DCF_Base!L22*(1+F$25)/($A27-F$25),DCF_Base!$B$31*DCF_Base!L22))/(1+$A27)^10-Assumptions!$B6)/Assumptions!$B7,"n/a")
A28: 0.175 | B28: =IF($A28>B$25,(SUMPRODUCT(DCF_Base!C22:DCF_Base!L22,1/(1+$A28)^DCF_Base!C4:DCF_Base!L4)+MAX(0,MIN(DCF_Base!L22*(1+B$25)/($A28-B$25),DCF_Base!$B$31*DCF_Base!L22))/(1+$A28)^10-Assumptions!$B6)/Assumptions!$B7,"n/a") | C28: =IF($A28>C$25,(SUMPRODUCT(DCF_Base!C22:DCF_Base!L22,1/(1+$A28)^DCF_Base!C4:DCF_Base!L4)+MAX(0,MIN(DCF_Base!L22*(1+C$25)/($A28-C$25),DCF_Base!$B$31*DCF_Base!L22))/(1+$A28)^10-Assumptions!$B6)/Assumptions!$B7,"n/a") | D28: =IF($A28>D$25,(SUMPRODUCT(DCF_Base!C22:DCF_Base!L22,1/(1+$A28)^DCF_Base!C4:DCF_Base!L4)+MAX(0,MIN(DCF_Base!L22*(1+D$25)/($A28-D$25),DCF_Base!$B$31*DCF_Base!L22))/(1+$A28)^10-Assumptions!$B6)/Assumptions!$B7,"n/a") | E28: =IF($A28>E$25,(SUMPRODUCT(DCF_Base!C22:DCF_Base!L22,1/(1+$A28)^DCF_Base!C4:DCF_Base!L4)+MAX(0,MIN(DCF_Base!L22*(1+E$25)/($A28-E$25),DCF_Base!$B$31*DCF_Base!L22))/(1+$A28)^10-Assumptions!$B6)/Assumptions!$B7,"n/a") | F28: =IF($A28>F$25,(SUMPRODUCT(DCF_Base!C22:DCF_Base!L22,1/(1+$A28)^DCF_Base!C4:DCF_Base!L4)+MAX(0,MIN(DCF_Base!L22*(1+F$25)/($A28-F$25),DCF_Base!$B$31*DCF_Base!L22))/(1+$A28)^10-Assumptions!$B6)/Assumptions!$B7,"n/a")
A29: 0.185 | B29: =IF($A29>B$25,(SUMPRODUCT(DCF_Base!C22:DCF_Base!L22,1/(1+$A29)^DCF_Base!C4:DCF_Base!L4)+MAX(0,MIN(DCF_Base!L22*(1+B$25)/($A29-B$25),DCF_Base!$B$31*DCF_Base!L22))/(1+$A29)^10-Assumptions!$B6)/Assumptions!$B7,"n/a") | C29: =IF($A29>C$25,(SUMPRODUCT(DCF_Base!C22:DCF_Base!L22,1/(1+$A29)^DCF_Base!C4:DCF_Base!L4)+MAX(0,MIN(DCF_Base!L22*(1+C$25)/($A29-C$25),DCF_Base!$B$31*DCF_Base!L22))/(1+$A29)^10-Assumptions!$B6)/Assumptions!$B7,"n/a") | D29: =IF($A29>D$25,(SUMPRODUCT(DCF_Base!C22:DCF_Base!L22,1/(1+$A29)^DCF_Base!C4:DCF_Base!L4)+MAX(0,MIN(DCF_Base!L22*(1+D$25)/($A29-D$25),DCF_Base!$B$31*DCF_Base!L22))/(1+$A29)^10-Assumptions!$B6)/Assumptions!$B7,"n/a") | E29: =IF($A29>E$25,(SUMPRODUCT(DCF_Base!C22:DCF_Base!L22,1/(1+$A29)^DCF_Base!C4:DCF_Base!L4)+MAX(0,MIN(DCF_Base!L22*(1+E$25)/($A29-E$25),DCF_Base!$B$31*DCF_Base!L22))/(1+$A29)^10-Assumptions!$B6)/Assumptions!$B7,"n/a") | F29: =IF($A29>F$25,(SUMPRODUCT(DCF_Base!C22:DCF_Base!L22,1/(1+$A29)^DCF_Base!C4:DCF_Base!L4)+MAX(0,MIN(DCF_Base!L22*(1+F$25)/($A29-F$25),DCF_Base!$B$31*DCF_Base!L22))/(1+$A29)^10-Assumptions!$B6)/Assumptions!$B7,"n/a")
A30: 0.195 | B30: =IF($A30>B$25,(SUMPRODUCT(DCF_Base!C22:DCF_Base!L22,1/(1+$A30)^DCF_Base!C4:DCF_Base!L4)+MAX(0,MIN(DCF_Base!L22*(1+B$25)/($A30-B$25),DCF_Base!$B$31*DCF_Base!L22))/(1+$A30)^10-Assumptions!$B6)/Assumptions!$B7,"n/a") | C30: =IF($A30>C$25,(SUMPRODUCT(DCF_Base!C22:DCF_Base!L22,1/(1+$A30)^DCF_Base!C4:DCF_Base!L4)+MAX(0,MIN(DCF_Base!L22*(1+C$25)/($A30-C$25),DCF_Base!$B$31*DCF_Base!L22))/(1+$A30)^10-Assumptions!$B6)/Assumptions!$B7,"n/a") | D30: =IF($A30>D$25,(SUMPRODUCT(DCF_Base!C22:DCF_Base!L22,1/(1+$A30)^DCF_Base!C4:DCF_Base!L4)+MAX(0,MIN(DCF_Base!L22*(1+D$25)/($A30-D$25),DCF_Base!$B$31*DCF_Base!L22))/(1+$A30)^10-Assumptions!$B6)/Assumptions!$B7,"n/a") | E30: =IF($A30>E$25,(SUMPRODUCT(DCF_Base!C22:DCF_Base!L22,1/(1+$A30)^DCF_Base!C4:DCF_Base!L4)+MAX(0,MIN(DCF_Base!L22*(1+E$25)/($A30-E$25),DCF_Base!$B$31*DCF_Base!L22))/(1+$A30)^10-Assumptions!$B6)/Assumptions!$B7,"n/a") | F30: =IF($A30>F$25,(SUMPRODUCT(DCF_Base!C22:DCF_Base!L22,1/(1+$A30)^DCF_Base!C4:DCF_Base!L4)+MAX(0,MIN(DCF_Base!L22*(1+F$25)/($A30-F$25),DCF_Base!$B$31*DCF_Base!L22))/(1+$A30)^10-Assumptions!$B6)/Assumptions!$B7,"n/a")
A32: Every cell in the grid sits far below the NZ$1.465 market price - the conclusion is not sensitive to WACC or terminal growth.
A33: Highlighted cell is the house pair (17.5% WACC, 2.5% terminal growth).
