Workbook

Sheet DCF Model
A1: BGP.NZ DCF Valuation Model - Briscoe Group Limited
A2: Gray cells are INPUTS - adjust to see valuation change. IFRS-16: lease principal deducted from FCF; net debt is CASH-ONLY (zero bank debt).
A4: KEY INPUTS
A5: Current Stock Price (NZ$) | B5: 4.6
A6: Shares Outstanding (M) | B6: 222.79
A7: Cash & Equivalents (M) | B7: 130.325
A8: Bank Debt (M) | B8: 0
A9: Net Debt (cash-only basis, M) | B9: =B8-B7
A10: Reported FCF FY2026 (M) | B10: 51.965
A11: Less: Lease Principal Repayments (M) | B11: 19.447
A12: Less: Interest Income (M) | B12: 2.971
A13: Owner FCF FY2026 (M, DC-capex depressed) | B13: =B10-B11-B12
A14: Annual Share Growth (dilution) | B14: 0
A16: WACC | B16: 0.105
A17: Terminal Growth Rate | B17: 0.025
A18: Terminal Cap Multiple (x) | B18: 14
A20: COMPONENT ASSUMPTIONS (BASE CASE)
B21: FY2027 | C21: FY2028 | D21: FY2029 | E21: FY2030 | F21: FY2031
A22: Revenue Growth % | B22: 0.01 | C22: 0.015 | D22: 0.02 | E22: 0.025 | F22: 0.025
A23: EBITDA Margin % | B23: 0.168 | C23: 0.173 | D23: 0.179 | E23: 0.184 | F23: 0.19
A24: SBC % of Revenue | B24: 0.0007 | C24: 0.0007 | D24: 0.0007 | E24: 0.0007 | F24: 0.0007
A25: D&A % of Revenue | B25: 0.046 | C25: 0.047 | D25: 0.047 | E25: 0.046 | F25: 0.046
A26: Cash Tax Rate % | B26: 0.28 | C26: 0.28 | D26: 0.28 | E26: 0.28 | F26: 0.28
A27: Capex (M) | B27: 57 | C27: 32 | D27: 20 | E27: 18 | F27: 18
A28: Lease Principal Repayments (M) | B28: 20 | C28: 20.5 | D28: 21 | E28: 21.5 | F28: 22
A29: WC Capture % of Revenue Change | B29: -0.1
A31: PROJECTIONS (FORMULAS)
B32: FY2027 | C32: FY2028 | D32: FY2029 | E32: FY2030 | F32: FY2031
A33: Revenue | B33: =798.831*(1+B22) | C33: =B33*(1+C22) | D33: =C33*(1+D22) | E33: =D33*(1+E22) | F33: =E33*(1+F22)
A34: EBITDA | B34: =B33*B23 | C34: =C33*C23 | D34: =D33*D23 | E34: =E33*E23 | F34: =F33*F23
A35: SBC | B35: =B33*B24 | C35: =C33*C24 | D35: =D33*D24 | E35: =E33*E24 | F35: =F33*F24
A36: Owner EBITDA | B36: =B34-B35 | C36: =C34-C35 | D36: =D34-D35 | E36: =E34-E35 | F36: =F34-F35
A37: D&A | B37: =B33*B25 | C37: =C33*C25 | D37: =D33*D25 | E37: =E33*E25 | F37: =F33*F25
A38: EBIT | B38: =B36-B37 | C38: =C36-C37 | D38: =D36-D37 | E38: =E36-E37 | F38: =F36-F37
A39: NOPAT | B39: =B38*(1-B26) | C39: =C38*(1-C26) | D39: =D38*(1-D26) | E39: =E38*(1-E26) | F39: =F38*(1-F26)
A40: Capex | B40: =B27 | C40: =C27 | D40: =D27 | E40: =E27 | F40: =F27
A41: Lease Principal Repayments | B41: =B28 | C41: =C28 | D41: =D28 | E41: =E28 | F41: =F28
A42: Working Capital (change in revenue x capture) | B42: =(B33-798.831)*$B$29 | C42: =(C33-B33)*$B$29 | D42: =(D33-C33)*$B$29 | E42: =(E33-D33)*$B$29 | F42: =(F33-E33)*$B$29
A43: Owner FCF | B43: =B39+B37-B40-B41+B42 | C43: =C39+C37-C40-C41+C42 | D43: =D39+D37-D40-D41+D42 | E43: =E39+E37-E40-E41+E42 | F43: =F39+F37-F40-F41+F42
A44: Owner FCF Margin % | B44: =B43/B33 | C44: =C43/C33 | D44: =D43/D33 | E44: =E43/E33 | F44: =F43/F33
...

Sheet Sensitivity
A1: Sensitivity Analysis
A2: Intrinsic Value by WACC & Terminal Growth (Base Case FCF path)
A4: WACC \ Term G | B4: 0.015 | C4: 0.02 | D4: 0.025 | E4: 0.03 | F4: 0.035
A5: 0.085 | B5: =(SUMPRODUCT('DCF Model'!$B$43:$F$43,(1/(1+0.085)^{1;2;3;4;5}))+MIN('DCF Model'!$F$43*(1+0.015)/(0.085-0.015),14*'DCF Model'!$F$43)/(1+0.085)^5-'DCF Model'!$B$9)/'DCF Model'!$B$58 | C5: =(SUMPRODUCT('DCF Model'!$B$43:$F$43,(1/(1+0.085)^{1;2;3;4;5}))+MIN('DCF Model'!$F$43*(1+0.02)/(0.085-0.02),14*'DCF Model'!$F$43)/(1+0.085)^5-'DCF Model'!$B$9)/'DCF Model'!$B$58 | D5: =(SUMPRODUCT('DCF Model'!$B$43:$F$43,(1/(1+0.085)^{1;2;3;4;5}))+MIN('DCF Model'!$F$43*(1+0.025)/(0.085-0.025),14*'DCF Model'!$F$43)/(1+0.085)^5-'DCF Model'!$B$9)/'DCF Model'!$B$58 | E5: =(SUMPRODUCT('DCF Model'!$B$43:$F$43,(1/(1+0.085)^{1;2;3;4;5}))+MIN('DCF Model'!$F$43*(1+0.03)/(0.085-0.03),14*'DCF Model'!$F$43)/(1+0.085)^5-'DCF Model'!$B$9)/'DCF Model'!$B$58 | F5: =(SUMPRODUCT('DCF Model'!$B$43:$F$43,(1/(1+0.085)^{1;2;3;4;5}))+MIN('DCF Model'!$F$43*(1+0.035)/(0.085-0.035),14*'DCF Model'!$F$43)/(1+0.085)^5-'DCF Model'!$B$9)/'DCF Model'!$B$58
A6: 0.095 | B6: =(SUMPRODUCT('DCF Model'!$B$43:$F$43,(1/(1+0.095)^{1;2;3;4;5}))+MIN('DCF Model'!$F$43*(1+0.015)/(0.095-0.015),14*'DCF Model'!$F$43)/(1+0.095)^5-'DCF Model'!$B$9)/'DCF Model'!$B$58 | C6: =(SUMPRODUCT('DCF Model'!$B$43:$F$43,(1/(1+0.095)^{1;2;3;4;5}))+MIN('DCF Model'!$F$43*(1+0.02)/(0.095-0.02),14*'DCF Model'!$F$43)/(1+0.095)^5-'DCF Model'!$B$9)/'DCF Model'!$B$58 | D6: =(SUMPRODUCT('DCF Model'!$B$43:$F$43,(1/(1+0.095)^{1;2;3;4;5}))+MIN('DCF Model'!$F$43*(1+0.025)/(0.095-0.025),14*'DCF Model'!$F$43)/(1+0.095)^5-'DCF Model'!$B$9)/'DCF Model'!$B$58 | E6: =(SUMPRODUCT('DCF Model'!$B$43:$F$43,(1/(1+0.095)^{1;2;3;4;5}))+MIN('DCF Model'!$F$43*(1+0.03)/(0.095-0.03),14*'DCF Model'!$F$43)/(1+0.095)^5-'DCF Model'!$B$9)/'DCF Model'!$B$58 | F6: =(SUMPRODUCT('DCF Model'!$B$43:$F$43,(1/(1+0.095)^{1;2;3;4;5}))+MIN('DCF Model'!$F$43*(1+0.035)/(0.095-0.035),14*'DCF Model'!$F$43)/(1+0.095)^5-'DCF Model'!$B$9)/'DCF Model'!$B$58
A7: 0.105 | B7: =(SUMPRODUCT('DCF Model'!$B$43:$F$43,(1/(1+0.105)^{1;2;3;4;5}))+MIN('DCF Model'!$F$43*(1+0.015)/(0.105-0.015),14*'DCF Model'!$F$43)/(1+0.105)^5-'DCF Model'!$B$9)/'DCF Model'!$B$58 | C7: =(SUMPRODUCT('DCF Model'!$B$43:$F$43,(1/(1+0.105)^{1;2;3;4;5}))+MIN('DCF Model'!$F$43*(1+0.02)/(0.105-0.02),14*'DCF Model'!$F$43)/(1+0.105)^5-'DCF Model'!$B$9)/'DCF Model'!$B$58 | D7: =(SUMPRODUCT('DCF Model'!$B$43:$F$43,(1/(1+0.105)^{1;2;3;4;5}))+MIN('DCF Model'!$F$43*(1+0.025)/(0.105-0.025),14*'DCF Model'!$F$43)/(1+0.105)^5-'DCF Model'!$B$9)/'DCF Model'!$B$58 | E7: =(SUMPRODUCT('DCF Model'!$B$43:$F$43,(1/(1+0.105)^{1;2;3;4;5}))+MIN('DCF Model'!$F$43*(1+0.03)/(0.105-0.03),14*'DCF Model'!$F$43)/(1+0.105)^5-'DCF Model'!$B$9)/'DCF Model'!$B$58 | F7: =(SUMPRODUCT('DCF Model'!$B$43:$F$43,(1/(1+0.105)^{1;2;3;4;5}))+MIN('DCF Model'!$F$43*(1+0.035)/(0.105-0.035),14*'DCF Model'!$F$43)/(1+0.105)^5-'DCF Model'!$B$9)/'DCF Model'!$B$58
A8: 0.115 | B8: =(SUMPRODUCT('DCF Model'!$B$43:$F$43,(1/(1+0.115)^{1;2;3;4;5}))+MIN('DCF Model'!$F$43*(1+0.015)/(0.115-0.015),14*'DCF Model'!$F$43)/(1+0.115)^5-'DCF Model'!$B$9)/'DCF Model'!$B$58 | C8: =(SUMPRODUCT('DCF Model'!$B$43:$F$43,(1/(1+0.115)^{1;2;3;4;5}))+MIN('DCF Model'!$F$43*(1+0.02)/(0.115-0.02),14*'DCF Model'!$F$43)/(1+0.115)^5-'DCF Model'!$B$9)/'DCF Model'!$B$58 | D8: =(SUMPRODUCT('DCF Model'!$B$43:$F$43,(1/(1+0.115)^{1;2;3;4;5}))+MIN('DCF Model'!$F$43*(1+0.025)/(0.115-0.025),14*'DCF Model'!$F$43)/(1+0.115)^5-'DCF Model'!$B$9)/'DCF Model'!$B$58 | E8: =(SUMPRODUCT('DCF Model'!$B$43:$F$43,(1/(1+0.115)^{1;2;3;4;5}))+MIN('DCF Model'!$F$43*(1+0.03)/(0.115-0.03),14*'DCF Model'!$F$43)/(1+0.115)^5-'DCF Model'!$B$9)/'DCF Model'!$B$58 | F8: =(SUMPRODUCT('DCF Model'!$B$43:$F$43,(1/(1+0.115)^{1;2;3;4;5}))+MIN('DCF Model'!$F$43*(1+0.035)/(0.115-0.035),14*'DCF Model'!$F$43)/(1+0.115)^5-'DCF Model'!$B$9)/'DCF Model'!$B$58
A9: 0.125 | B9: =(SUMPRODUCT('DCF Model'!$B$43:$F$43,(1/(1+0.125)^{1;2;3;4;5}))+MIN('DCF Model'!$F$43*(1+0.015)/(0.125-0.015),14*'DCF Model'!$F$43)/(1+0.125)^5-'DCF Model'!$B$9)/'DCF Model'!$B$58 | C9: =(SUMPRODUCT('DCF Model'!$B$43:$F$43,(1/(1+0.125)^{1;2;3;4;5}))+MIN('DCF Model'!$F$43*(1+0.02)/(0.125-0.02),14*'DCF Model'!$F$43)/(1+0.125)^5-'DCF Model'!$B$9)/'DCF Model'!$B$58 | D9: =(SUMPRODUCT('DCF Model'!$B$43:$F$43,(1/(1+0.125)^{1;2;3;4;5}))+MIN('DCF Model'!$F$43*(1+0.025)/(0.125-0.025),14*'DCF Model'!$F$43)/(1+0.125)^5-'DCF Model'!$B$9)/'DCF Model'!$B$58 | E9: =(SUMPRODUCT('DCF Model'!$B$43:$F$43,(1/(1+0.125)^{1;2;3;4;5}))+MIN('DCF Model'!$F$43*(1+0.03)/(0.125-0.03),14*'DCF Model'!$F$43)/(1+0.125)^5-'DCF Model'!$B$9)/'DCF Model'!$B$58 | F9: =(SUMPRODUCT('DCF Model'!$B$43:$F$43,(1/(1+0.125)^{1;2;3;4;5}))+MIN('DCF Model'!$F$43*(1+0.035)/(0.125-0.035),14*'DCF Model'!$F$43)/(1+0.125)^5-'DCF Model'!$B$9)/'DCF Model'!$B$58

Sheet FCF Quality
A1: FCF Quality Reconciliation
A2: Reported FCF -> Owner FCF, historical (IFRS-16 lease principal + interest income deducted)
B4: FY2020 | C4: FY2021 | D4: FY2022 | E4: FY2023 | F4: FY2024 | G4: FY2025 | H4: FY2026
A5: Reported FCF (OCF - capex) | B5: 60.33 | C5: 79.137 | D5: 76.599 | E5: 127.961 | F5: 108.247 | G5: 51.541 | H5: 51.965
A6: Less: Lease Principal Repayments | B6: 16.264 | C6: 15.588 | D6: 19.159 | E6: 19.065 | F6: 19.389 | G6: 20.064 | H6: 19.447
A7: Less: Interest Income | B7: 0.724 | C7: 0.421 | D7: 0.399 | E7: 2.495 | F7: 6.209 | G7: 6.127 | H7: 2.971
A8: Owner FCF | B8: =B5-B6-B7 | C8: =C5-C6-C7 | D8: =D5-D6-D7 | E8: =E5-E6-E7 | F8: =F5-F6-F7 | G8: =G5-G6-G7 | H8: =H5-H6-H7
A9: Revenue | B9: 653.017 | C9: 701.797 | D9: 744.45 | E9: 785.854 | F9: 791.953 | G9: 791.469 | H9: 798.831
A10: Reported FCF Margin % | B10: =B5/B9 | C10: =C5/C9 | D10: =D5/D9 | E10: =E5/E9 | F10: =F5/F9 | G10: =G5/G9 | H10: =H5/H9
A11: Owner FCF Margin % | B11: =B8/B9 | C11: =C8/C9 | D11: =D8/D9 | E11: =E8/E9 | F11: =F8/F9 | G11: =G8/G9 | H11: =H8/H9
A13: Memo: Capex (M) | B13: 19.178 | C13: 27.429 | D13: 19.897 | E13: 16.455 | F13: 15.059 | G13: 58.161 | H13: 50.436
A14: Memo: Cash Tax Rate (stable, ~28% NZ statutory) | B14: No abnormal-tax-rate ramp needed; FY2026 effective rate = 23.694/82.911 = 28.6%
A16: Note: FY2025-26 capex spiked ~3-4x historical maintenance level ($15-20m) due to the
A17: Drury distribution centre build; this mechanically crushes reported and owner FCF in
A18: those two years and is NOT extrapolated forward in the DCF projections (capex glides
A19: back to ~$18m/yr by Year 4-5 as the DC build completes, per FY2027 guidance of ~$57m).

Sheet Historical
A1: Historical Growth Rates
A3: Metric | B3: 3-Year CAGR | C3: 5-Year CAGR
A4: Revenue | B4: 0.0055 | C4: 0.0262
A5: EPS | B5: -0.125 | C5: -0.0416
A6: Equity (Book Value) | B6: -0.003 | C6: 0.0337
A7: FCF (reported) | B7: -0.2595 | C7: -0.0807
A8: FCF (owner, post-lease/interest) | B8: -0.3479 | C8: -0.1411
A10: Note:
A11: EPS 3yr CAGR (-12.5%) and reported/owner FCF 3yr CAGR (-26% / -35%) diverge sharply from flat revenue (+0.55%) and roughly flat equity (-0.3%). This is NOT a business-model breakdown -- it reflects (a) gross margin compression from 44.0% (FY2023) to 39.2% (FY2026) amid promotional competition, and (b) FY2025-26 capex more than tripling for the Drury DC build, mechanically crushing reported and owner FCF even as revenue and book equity held roughly flat. The DCF therefore does NOT extrapolate any of these trailing FCF/EPS CAGRs -- it builds forward FCF from EBITDA-margin recovery assumptions and a capex normalization glide path back to ~$18-20m/yr maintenance levels once the DC completes (~FY2027-28).

Sheet Model_Info
A1: BGP.NZ DCF Model - Provenance and Methodology
A3: Built by: Claude (dcf-analyst agent), Stocks Research project
A4: Valuation date: 2026-08-08
A5: Share price as of: 2026-08-08 (Yahoo Finance BGP.NZ, NZ$4.6)
A6: Data vintage: FY2026 annual report (52 weeks to 25 Jan 2026) + Q2 FY2027 trading update (Aug-2026)
A8: METHODOLOGY CHOICES
A9: 1. IFRS-16 lease adjustment: Briscoe carries ZERO bank debt; TotalDebt on the balance sheet from
A10: FY2020 onward is entirely lease liabilities (~$276m FY2026). Reported OCF is post-IFRS16 (lease
A11: interest already in P&L) but LEASE PRINCIPAL repayments sit in financing activities, so reported
A12: FCF (OCF - capex) overstates owner FCF. Owner FCF = reported FCF - lease principal repayments -
A13: interest income (net cash > 1x FCF base, so interest income is stripped per standard rule).
A14: 2. Net debt basis: CASH-ONLY (no bank debt subtracted, no lease liabilities added back), because
... A54: investment decision.
