Workbook

Sheet DP Cap Model
A1: IPL.NZ REIT Valuation Model -- Distributable Profit Capitalization
A2: Gray cells are INPUTS - adjust to see valuation change. Discount rate is COST OF EQUITY, not WACC. Net debt is NEVER subtracted (Distributable Profit is already post-interest).
A4: KEY INPUTS
A5: Current Stock Price | B5: 1.05
A6: Shares Outstanding (M), FY2026 | B6: 377.623
A7: Distributable Profit After Tax FY2026 (NZDm) | B7: 30.7
A8: Distributable Profit per Share FY2026 (cents) | B8: 8.13
A9: Stock-Based Comp | B9: 0 | C9: Verified NIL -- externally managed (SIML), no employees
A10: Annual Share Growth (dilution) % | B10: 0.005
A12: Cost of Equity (NOT WACC) | B12: 0.105
A13: Exit Distributable-Profit Yield (terminal cap rate) | B13: 0.075
A15: COST OF EQUITY BUILD
A16: Risk-free rate (NZ 10yr govt) | B16: 0.0435
A17: Equity risk premium | B17: 0.06
A18: Beta | B18: 0.75
A19: CAPM base (=B16+B17*B18) | B19: =B16+B17*B18 -> 0
A20: Tenant concentration premium (Woolworths 53%) | B20: 0.006
A21: Illiquidity premium (small-cap NZX) | B21: 0.0055
A22: Governance premium (external mgmt/related-party) | B22: 0.005
A23: Built Cost of Equity (=SUM(B19,B20:B22)) | B23: =B19+B20+B21+B22 -> 0
A25: DPS GROWTH ASSUMPTIONS (Base Case) | B25: FY2027 | C25: FY2028 | D25: FY2029 | E25: FY2030 | F25: FY2031
A26: DPS Growth Rate % | B26: -0.02 | C26: 0.005 | D26: 0.015 | E26: 0.02 | F26: 0.02
A28: PROJECTIONS
B29: FY2027 | C29: FY2028 | D29: FY2029 | E29: FY2030 | F29: FY2031
A30: Distributable Profit/Share (cents) | B30: =B8*(1+B26) -> 0 | C30: =B30*(1+C26) -> 0 | D30: =C30*(1+D26) -> 0 | E30: =D30*(1+E26) -> 0 | F30: =E30*(1+F26) -> 0
A31: Shares Outstanding (M) | B31: =B6*(1+$B$10) -> 0 | C31: =B31*(1+$B$10) -> 0 | D31: =C31*(1+$B$10) -> 0 | E31: =D31*(1+$B$10) -> 0 | F31: =E31*(1+$B$10) -> 0
A32: Total Distributable Profit (NZDm) | B32: =B30/100*B31 -> 0 | C32: =C30/100*C31 -> 0 | D32: =D30/100*D31 -> 0 | E32: =E30/100*E31 -> 0 | F32: =F30/100*F31 -> 0
A33: Discount Factor (Cost of Equity) | B33: =1/(1+$B$12)^1 -> 0 | C33: =1/(1+$B$12)^2 -> 0 | D33: =1/(1+$B$12)^3 -> 0 | E33: =1/(1+$B$12)^4 -> 0 | F33: =1/(1+$B$12)^5 -> 0
A34: PV of Distributable Profit | B34: =B32*B33 -> 0 | C34: =C32*C33 -> 0 | D34: =D32*D33 -> 0 | E34: =E32*E33 -> 0 | F34: =F32*F33 -> 0
A36: VALUATION -- DISTRIBUTABLE PROFIT CAPITALIZATION LEG
A37: Sum of PV of Distributable Profit | B37: =SUM(B34:F34) -> 0
A38: Terminal Distributable Profit (Yr5 x (1+g_last)) | B38: =F32*(1+F26) -> 0
A39: Terminal Value (=B38/B13) | B39: =B38/B13 -> 0
A40: PV of Terminal Value | B40: =B39*F33 -> 0
A41: Equity Value (NO net-debt deduction) | B41: =B37+B40 -> 0
A42: INTRINSIC VALUE/SHARE (AFFO-cap leg) | B42: =B41/F31 -> 0
A44: Upside/(Downside) to AFFO-cap IV | B44: =(B42-B5)/B5 -> 0
A46: ENTRY PRICE (15% IRR Target, AFFO-cap leg)
A47: PV of Yrs 1-5 Distributable Profit @15% | B47: =NPV(0.15,B32:F32) -> 0
A48: PV of Terminal Value @15% | B48: =B39/(1.15^5) -> 0
...

Sheet NTA Cross-Check
A1: IPL.NZ NTA-Based Valuation Leg (50% blend weight)
A2: Book NTA per share compounded forward, exited at a justified P/NTA multiple, plus PV of interim dividends.
A4: INPUTS
A5: FY2026 NTA per Share | B5: 1.62
A6: NTA Annual Growth Rate (base) | B6: 0.02
A7: Exit P/NTA Multiple (base) | B7: 0.75
A8: Payout Ratio (% of Distributable Profit paid as dividend) | B8: 0.8
A9: Cost of Equity (link to Sheet 1) | B9: ='DP Cap Model'!B12 -> 0
A11: PROJECTIONS
B12: FY2027 | C12: FY2028 | D12: FY2029 | E12: FY2030 | F12: FY2031
A13: NTA per Share | B13: =B5*(1+B6) -> 0 | C13: =B13*(1+$B$6) -> 0 | D13: =C13*(1+$B$6) -> 0 | E13: =D13*(1+$B$6) -> 0 | F13: =E13*(1+$B$6) -> 0
A14: Total Distributable Profit (link Sheet1 row32) | B14: ='DP Cap Model'!B32 -> 0 | C14: ='DP Cap Model'!C32 -> 0 | D14: ='DP Cap Model'!D32 -> 0 | E14: ='DP Cap Model'!E32 -> 0 | F14: ='DP Cap Model'!F32 -> 0
A15: Dividends Paid (Distributable Profit x Payout %) | B15: =B14*$B$8 -> 0 | C15: =C14*$B$8 -> 0 | D15: =D14*$B$8 -> 0 | E15: =E14*$B$8 -> 0 | F15: =F14*$B$8 -> 0
A16: Discount Factor (Cost of Equity) | B16: ='DP Cap Model'!B33 -> 0 | C16: ='DP Cap Model'!C33 -> 0 | D16: ='DP Cap Model'!D33 -> 0 | E16: ='DP Cap Model'!E33 -> 0 | F16: ='DP Cap Model'!F33 -> 0
A17: PV of Dividends | B17: =B15*B16 -> 0 | C17: =C15*C16 -> 0 | D17: =D15*D16 -> 0 | E17: =E15*E16 -> 0 | F17: =F15*F16 -> 0
A19: VALUATION -- NTA-BASED LEG
A20: Sum of PV of Dividends | B20: =SUM(B17:F17) -> 0
A21: Year-5 Exit Value/Share (=F13*B7) | B21: =F13*B7 -> 0
A22: Year-5 Shares Outstanding (link Sheet1) | B22: ='DP Cap Model'!F31 -> 0
A23: Year-5 Exit Equity Value | B23: =B21*B22 -> 0
A24: PV of Exit Equity Value | B24: =B23*F16 -> 0
A25: Equity Value (Dividends + Discounted Exit) | B25: =B20+B24 -> 0
A26: INTRINSIC VALUE/SHARE (NTA-based leg) | B26: =B25/B22 -> 0
A28: BLENDED INTRINSIC VALUE (50% AFFO-cap / 50% NTA-based)
A29: Blended IV/Share | B29: =0.5*'DP Cap Model'!B42+0.5*B26 -> 0
A30: Upside/(Downside) to Blended IV | B30: =(B29-'DP Cap Model'!B5)/'DP Cap Model'!B5 -> 0

Sheet Sensitivity
A1: Sensitivity Analysis (AFFO-Cap Leg)
A2: Intrinsic Value by Cost of Equity & Exit Distributable-Profit Yield
A4: CoE \ Exit Yield | B4: 0.055 | C4: 0.065 | D4: 0.075 | E4: 0.085 | F4: 0.095
A5: 0.085 | B5: =(('DP Cap Model'!$B$8/100*(1+'DP Cap Model'!$B$26)*(1+'DP Cap Model'!$C$26)*(1+'DP Cap Model'!$D$26)*(1+'DP Cap Model'!$E$26)*(1+'DP Cap Model'!$F$26)*'DP Cap Model'!$F$31)*(1-(1+0.085)^-5)/0.085+('DP Cap Model'!$B$8/100*(1+'DP Cap Model'!$B$26)*(1+'DP Cap Model'!$C$26)*(1+'DP Cap Model'!$D$26)*(1+'DP Cap Model'!$E$26)*(1+'DP Cap Model'!$F$26)*'DP Cap Model'!$F$31*(1+'DP Cap Model'!$F$26)/0.055)/(1+0.085)^5)/'DP Cap Model'!$F$31 -> 0 | C5: =(('DP Cap Model'!$B$8/100*(1+'DP Cap Model'!$B$26)*(1+'DP Cap Model'!$C$26)*(1+'DP Cap Model'!$D$26)*(1+'DP Cap Model'!$E$26)*(1+'DP Cap Model'!$F$26)*'DP Cap Model'!$F$31)*(1-(1+0.085)^-5)/0.085+('DP Cap Model'!$B$8/100*(1+'DP Cap Model'!$B$26)*(1+'DP Cap Model'!$C$26)*(1+'DP Cap Model'!$D$26)*(1+'DP Cap Model'!$E$26)*(1+'DP Cap Model'!$F$26)*'DP Cap Model'!$F$31*(1+'DP Cap Model'!$F$26)/0.065)/(1+0.085)^5)/'DP Cap Model'!$F$31 -> 0 | D5: =(('DP Cap Model'!$B$8/100*(1+'DP Cap Model'!$B$26)*(1+'DP Cap Model'!$C$26)*(1+'DP Cap Model'!$D$26)*(1+'DP Cap Model'!$E$26)*(1+'DP Cap Model'!$F$26)*'DP Cap Model'!$F$31)*(1-(1+0.085)^-5)/0.085+('DP Cap Model'!$B$8/100*(1+'DP Cap Model'!$B$26)*(1+'DP Cap Model'!$C$26)*(1+'DP Cap Model'!$D$26)*(1+'DP Cap Model'!$E$26)*(1+'DP Cap Model'!$F$26)*'DP Cap Model'!$F$31*(1+'DP Cap Model'!$F$26)/0.075)/(1+0.085)^5)/'DP Cap Model'!$F$31 -> 0 | E5: =(('DP Cap Model'!$B$8/100*(1+'DP Cap Model'!$B$26)*(1+'DP Cap Model'!$C$26)*(1+'DP Cap Model'!$D$26)*(1+'DP Cap Model'!$E$26)*(1+'DP Cap Model'!$F$26)*'DP Cap Model'!$F$31)*(1-(1+0.085)^-5)/0.085+('DP Cap Model'!$B$8/100*(1+'DP Cap Model'!$B$26)*(1+'DP Cap Model'!$C$26)*(1+'DP Cap Model'!$D$26)*(1+'DP Cap Model'!$E$26)*(1+'DP Cap Model'!$F$26)*'DP Cap Model'!$F$31*(1+'DP Cap Model'!$F$26)/0.085)/(1+0.085)^5)/'DP Cap Model'!$F$31 -> 0 | F5: =(('DP Cap Model'!$B$8/100*(1+'DP Cap Model'!$B$26)*(1+'DP Cap Model'!$C$26)*(1+'DP Cap Model'!$D$26)*(1+'DP Cap Model'!$E$26)*(1+'DP Cap Model'!$F$26)*'DP Cap Model'!$F$31)*(1-(1+0.085)^-5)/0.085+('DP Cap Model'!$B$8/100*(1+'DP Cap Model'!$B$26)*(1+'DP Cap Model'!$C$26)*(1+'DP Cap Model'!$D$26)*(1+'DP Cap Model'!$E$26)*(1+'DP Cap Model'!$F$26)*'DP Cap Model'!$F$31*(1+'DP Cap Model'!$F$26)/0.095)/(1+0.085)^5)/'DP Cap Model'!$F$31 -> 0
A6: 0.095 | B6: =(('DP Cap Model'!$B$8/100*(1+'DP Cap Model'!$B$26)*(1+'DP Cap Model'!$C$26)*(1+'DP Cap Model'!$D$26)*(1+'DP Cap Model'!$E$26)*(1+'DP Cap Model'!$F$26)*'DP Cap Model'!$F$31)*(1-(1+0.095)^-5)/0.095+('DP Cap Model'!$B$8/100*(1+'DP Cap Model'!$B$26)*(1+'DP Cap Model'!$C$26)*(1+'DP Cap Model'!$D$26)*(1+'DP Cap Model'!$E$26)*(1+'DP Cap Model'!$F$26)*'DP Cap Model'!$F$31*(1+'DP Cap Model'!$F$26)/0.055)/(1+0.095)^5)/'DP Cap Model'!$F$31 -> 0 | C6: =(('DP Cap Model'!$B$8/100*(1+'DP Cap Model'!$B$26)*(1+'DP Cap Model'!$C$26)*(1+'DP Cap Model'!$D$26)*(1+'DP Cap Model'!$E$26)*(1+'DP Cap Model'!$F$26)*'DP Cap Model'!$F$31)*(1-(1+0.095)^-5)/0.095+('DP Cap Model'!$B$8/100*(1+'DP Cap Model'!$B$26)*(1+'DP Cap Model'!$C$26)*(1+'DP Cap Model'!$D$26)*(1+'DP Cap Model'!$E$26)*(1+'DP Cap Model'!$F$26)*'DP Cap Model'!$F$31*(1+'DP Cap Model'!$F$26)/0.065)/(1+0.095)^5)/'DP Cap Model'!$F$31 -> 0 | D6: =(('DP Cap Model'!$B$8/100*(1+'DP Cap Model'!$B$26)*(1+'DP Cap Model'!$C$26)*(1+'DP Cap Model'!$D$26)*(1+'DP Cap Model'!$E$26)*(1+'DP Cap Model'!$F$26)*'DP Cap Model'!$F$31)*(1-(1+0.095)^-5)/0.095+('DP Cap Model'!$B$8/100*(1+'DP Cap Model'!$B$26)*(1+'DP Cap Model'!$C$26)*(1+'DP Cap Model'!$D$26)*(1+'DP Cap Model'!$E$26)*(1+'DP Cap Model'!$F$26)*'DP Cap Model'!$F$31*(1+'DP Cap Model'!$F$26)/0.075)/(1+0.095)^5)/'DP Cap Model'!$F$31 -> 0 | E6: =(('DP Cap Model'!$B$8/100*(1+'DP Cap Model'!$B$26)*(1+'DP Cap Model'!$C$26)*(1+'DP Cap Model'!$D$26)*(1+'DP Cap Model'!$E$26)*(1+'DP Cap Model'!$F$26)*'DP Cap Model'!$F$31)*(1-(1+0.095)^-5)/0.095+('DP Cap Model'!$B$8/100*(1+'DP Cap Model'!$B$26)*(1+'DP Cap Model'!$C$26)*(1+'DP Cap Model'!$D$26)*(1+'DP Cap Model'!$E$26)*(1+'DP Cap Model'!$F$26)*'DP Cap Model'!$F$31*(1+'DP Cap Model'!$F$26)/0.085)/(1+0.095)^5)/'DP Cap Model'!$F$31 -> 0 | F6: =(('DP Cap Model'!$B$8/100*(1+'DP Cap Model'!$B$26)*(1+'DP Cap Model'!$C$26)*(1+'DP Cap Model'!$D$26)*(1+'DP Cap Model'!$E$26)*(1+'DP Cap Model'!$F$26)*'DP Cap Model'!$F$31)*(1-(1+0.095)^-5)/0.095+('DP Cap Model'!$B$8/100*(1+'DP Cap Model'!$B$26)*(1+'DP Cap Model'!$C$26)*(1+'DP Cap Model'!$D$26)*(1+'DP Cap Model'!$E$26)*(1+'DP Cap Model'!$F$26)*'DP Cap Model'!$F$31*(1+'DP Cap Model'!$F$26)/0.095)/(1+0.095)^5)/'DP Cap Model'!$F$31 -> 0
A7: 0.105 | B7: =(('DP Cap Model'!$B$8/100*(1+'DP Cap Model'!$B$26)*(1+'DP Cap Model'!$C$26)*(1+'DP Cap Model'!$D$26)*(1+'DP Cap Model'!$E$26)*(1+'DP Cap Model'!$F$26)*'DP Cap Model'!$F$31)*(1-(1+0.105)^-5)/0.105+('DP Cap Model'!$B$8/100*(1+'DP Cap Model'!$B$26)*(1+'DP Cap Model'!$C$26)*(1+'DP Cap Model'!$D$26)*(1+'DP Cap Model'!$E$26)*(1+'DP Cap Model'!$F$26)*'DP Cap Model'!$F$31*(1+'DP Cap Model'!$F$26)/0.055)/(1+0.105)^5)/'DP Cap Model'!$F$31 -> 0 | C7: =(('DP Cap Model'!$B$8/100*(1+'DP Cap Model'!$B$26)*(1+'DP Cap Model'!$C$26)*(1+'DP Cap Model'!$D$26)*(1+'DP Cap Model'!$E$26)*(1+'DP Cap Model'!$F$26)*'DP Cap Model'!$F$31)*(1-(1+0.105)^-5)/0.105+('DP Cap Model'!$B$8/100*(1+'DP Cap Model'!$B$26)*(1+'DP Cap Model'!$C$26)*(1+'DP Cap Model'!$D$26)*(1+'DP Cap Model'!$E$26)*(1+'DP Cap Model'!$F$26)*'DP Cap Model'!$F$31*(1+'DP Cap Model'!$F$26)/0.065)/(1+0.105)^5)/'DP Cap Model'!$F$31 -> 0 | D7: =(('DP Cap Model'!$B$8/100*(1+'DP Cap Model'!$B$26)*(1+'DP Cap Model'!$C$26)*(1+'DP Cap Model'!$D$26)*(1+'DP Cap Model'!$E$26)*(1+'DP Cap Model'!$F$26)*'DP Cap Model'!$F$31)*(1-(1+0.105)^-5)/0.105+('DP Cap Model'!$B$8/100*(1+'DP Cap Model'!$B$26)*(1+'DP Cap Model'!$C$26)*(1+'DP Cap Model'!$D$26)*(1+'DP Cap Model'!$E$26)*(1+'DP Cap Model'!$F$26)*'DP Cap Model'!$F$31*(1+'DP Cap Model'!$F$26)/0.075)/(1+0.105)^5)/'DP Cap Model'!$F$31 -> 0 | E7: =(('DP Cap Model'!$B$8/100*(1+'DP Cap Model'!$B$26)*(1+'DP Cap Model'!$C$26)*(1+'DP Cap Model'!$D$26)*(1+'DP Cap Model'!$E$26)*(1+'DP Cap Model'!$F$26)*'DP Cap Model'!$F$31)*(1-(1+0.105)^-5)/0.105+('DP Cap Model'!$B$8/100*(1+'DP Cap Model'!$B$26)*(1+'DP Cap Model'!$C$26)*(1+'DP Cap Model'!$D$26)*(1+'DP Cap Model'!$E$26)*(1+'DP Cap Model'!$F$26)*'DP Cap Model'!$F$31*(1+'DP Cap Model'!$F$26)/0.085)/(1+0.105)^5)/'DP Cap Model'!$F$31 -> 0 | F7: =(('DP Cap Model'!$B$8/100*(1+'DP Cap Model'!$B$26)*(1+'DP Cap Model'!$C$26)*(1+'DP Cap Model'!$D$26)*(1+'DP Cap Model'!$E$26)*(1+'DP Cap Model'!$F$26)*'DP Cap Model'!$F$31)*(1-(1+0.105)^-5)/0.105+('DP Cap Model'!$B$8/100*(1+'DP Cap Model'!$B$26)*(1+'DP Cap Model'!$C$26)*(1+'DP Cap Model'!$D$26)*(1+'DP Cap Model'!$E$26)*(1+'DP Cap Model'!$F$26)*'DP Cap Model'!$F$31*(1+'DP Cap Model'!$F$26)/0.095)/(1+0.105)^5)/'DP Cap Model'!$F$31 -> 0
A8: 0.115 | B8: =(('DP Cap Model'!$B$8/100*(1+'DP Cap Model'!$B$26)*(1+'DP Cap Model'!$C$26)*(1+'DP Cap Model'!$D$26)*(1+'DP Cap Model'!$E$26)*(1+'DP Cap Model'!$F$26)*'DP Cap Model'!$F$31)*(1-(1+0.115)^-5)/0.115+('DP Cap Model'!$B$8/100*(1+'DP Cap Model'!$B$26)*(1+'DP Cap Model'!$C$26)*(1+'DP Cap Model'!$D$26)*(1+'DP Cap Model'!$E$26)*(1+'DP Cap Model'!$F$26)*'DP Cap Model'!$F$31*(1+'DP Cap Model'!$F$26)/0.055)/(1+0.115)^5)/'DP Cap Model'!$F$31 -> 0 | C8: =(('DP Cap Model'!$B$8/100*(1+'DP Cap Model'!$B$26)*(1+'DP Cap Model'!$C$26)*(1+'DP Cap Model'!$D$26)*(1+'DP Cap Model'!$E$26)*(1+'DP Cap Model'!$F$26)*'DP Cap Model'!$F$31)*(1-(1+0.115)^-5)/0.115+('DP Cap Model'!$B$8/100*(1+'DP Cap Model'!$B$26)*(1+'DP Cap Model'!$C$26)*(1+'DP Cap Model'!$D$26)*(1+'DP Cap Model'!$E$26)*(1+'DP Cap Model'!$F$26)*'DP Cap Model'!$F$31*(1+'DP Cap Model'!$F$26)/0.065)/(1+0.115)^5)/'DP Cap Model'!$F$31 -> 0 | D8: =(('DP Cap Model'!$B$8/100*(1+'DP Cap Model'!$B$26)*(1+'DP Cap Model'!$C$26)*(1+'DP Cap Model'!$D$26)*(1+'DP Cap Model'!$E$26)*(1+'DP Cap Model'!$F$26)*'DP Cap Model'!$F$31)*(1-(1+0.115)^-5)/0.115+('DP Cap Model'!$B$8/100*(1+'DP Cap Model'!$B$26)*(1+'DP Cap Model'!$C$26)*(1+'DP Cap Model'!$D$26)*(1+'DP Cap Model'!$E$26)*(1+'DP Cap Model'!$F$26)*'DP Cap Model'!$F$31*(1+'DP Cap Model'!$F$26)/0.075)/(1+0.115)^5)/'DP Cap Model'!$F$31 -> 0 | E8: =(('DP Cap Model'!$B$8/100*(1+'DP Cap Model'!$B$26)*(1+'DP Cap Model'!$C$26)*(1+'DP Cap Model'!$D$26)*(1+'DP Cap Model'!$E$26)*(1+'DP Cap Model'!$F$26)*'DP Cap Model'!$F$31)*(1-(1+0.115)^-5)/0.115+('DP Cap Model'!$B$8/100*(1+'DP Cap Model'!$B$26)*(1+'DP Cap Model'!$C$26)*(1+'DP Cap Model'!$D$26)*(1+'DP Cap Model'!$E$26)*(1+'DP Cap Model'!$F$26)*'DP Cap Model'!$F$31*(1+'DP Cap Model'!$F$26)/0.085)/(1+0.115)^5)/'DP Cap Model'!$F$31 -> 0 | F8: =(('DP Cap Model'!$B$8/100*(1+'DP Cap Model'!$B$26)*(1+'DP Cap Model'!$C$26)*(1+'DP Cap Model'!$D$26)*(1+'DP Cap Model'!$E$26)*(1+'DP Cap Model'!$F$26)*'DP Cap Model'!$F$31)*(1-(1+0.115)^-5)/0.115+('DP Cap Model'!$B$8/100*(1+'DP Cap Model'!$B$26)*(1+'DP Cap Model'!$C$26)*(1+'DP Cap Model'!$D$26)*(1+'DP Cap Model'!$E$26)*(1+'DP Cap Model'!$F$26)*'DP Cap Model'!$F$31*(1+'DP Cap Model'!$F$26)/0.095)/(1+0.115)^5)/'DP Cap Model'!$F$31 -> 0
A9: 0.125 | B9: =(('DP Cap Model'!$B$8/100*(1+'DP Cap Model'!$B$26)*(1+'DP Cap Model'!$C$26)*(1+'DP Cap Model'!$D$26)*(1+'DP Cap Model'!$E$26)*(1+'DP Cap Model'!$F$26)*'DP Cap Model'!$F$31)*(1-(1+0.125)^-5)/0.125+('DP Cap Model'!$B$8/100*(1+'DP Cap Model'!$B$26)*(1+'DP Cap Model'!$C$26)*(1+'DP Cap Model'!$D$26)*(1+'DP Cap Model'!$E$26)*(1+'DP Cap Model'!$F$26)*'DP Cap Model'!$F$31*(1+'DP Cap Model'!$F$26)/0.055)/(1+0.125)^5)/'DP Cap Model'!$F$31 -> 0 | C9: =(('DP Cap Model'!$B$8/100*(1+'DP Cap Model'!$B$26)*(1+'DP Cap Model'!$C$26)*(1+'DP Cap Model'!$D$26)*(1+'DP Cap Model'!$E$26)*(1+'DP Cap Model'!$F$26)*'DP Cap Model'!$F$31)*(1-(1+0.125)^-5)/0.125+('DP Cap Model'!$B$8/100*(1+'DP Cap Model'!$B$26)*(1+'DP Cap Model'!$C$26)*(1+'DP Cap Model'!$D$26)*(1+'DP Cap Model'!$E$26)*(1+'DP Cap Model'!$F$26)*'DP Cap Model'!$F$31*(1+'DP Cap Model'!$F$26)/0.065)/(1+0.125)^5)/'DP Cap Model'!$F$31 -> 0 | D9: =(('DP Cap Model'!$B$8/100*(1+'DP Cap Model'!$B$26)*(1+'DP Cap Model'!$C$26)*(1+'DP Cap Model'!$D$26)*(1+'DP Cap Model'!$E$26)*(1+'DP Cap Model'!$F$26)*'DP Cap Model'!$F$31)*(1-(1+0.125)^-5)/0.125+('DP Cap Model'!$B$8/100*(1+'DP Cap Model'!$B$26)*(1+'DP Cap Model'!$C$26)*(1+'DP Cap Model'!$D$26)*(1+'DP Cap Model'!$E$26)*(1+'DP Cap Model'!$F$26)*'DP Cap Model'!$F$31*(1+'DP Cap Model'!$F$26)/0.075)/(1+0.125)^5)/'DP Cap Model'!$F$31 -> 0 | E9: =(('DP Cap Model'!$B$8/100*(1+'DP Cap Model'!$B$26)*(1+'DP Cap Model'!$C$26)*(1+'DP Cap Model'!$D$26)*(1+'DP Cap Model'!$E$26)*(1+'DP Cap Model'!$F$26)*'DP Cap Model'!$F$31)*(1-(1+0.125)^-5)/0.125+('DP Cap Model'!$B$8/100*(1+'DP Cap Model'!$B$26)*(1+'DP Cap Model'!$C$26)*(1+'DP Cap Model'!$D$26)*(1+'DP Cap Model'!$E$26)*(1+'DP Cap Model'!$F$26)*'DP Cap Model'!$F$31*(1+'DP Cap Model'!$F$26)/0.085)/(1+0.125)^5)/'DP Cap Model'!$F$31 -> 0 | F9: =(('DP Cap Model'!$B$8/100*(1+'DP Cap Model'!$B$26)*(1+'DP Cap Model'!$C$26)*(1+'DP Cap Model'!$D$26)*(1+'DP Cap Model'!$E$26)*(1+'DP Cap Model'!$F$26)*'DP Cap Model'!$F$31)*(1-(1+0.125)^-5)/0.125+('DP Cap Model'!$B$8/100*(1+'DP Cap Model'!$B$26)*(1+'DP Cap Model'!$C$26)*(1+'DP Cap Model'!$D$26)*(1+'DP Cap Model'!$E$26)*(1+'DP Cap Model'!$F$26)*'DP Cap Model'!$F$31*(1+'DP Cap Model'!$F$26)/0.095)/(1+0.125)^5)/'DP Cap Model'!$F$31 -> 0
A11: Note: approximate closed-form annuity+terminal formula replicated per cell;
A12: matches the year-by-year build on Sheet 1 when CoE=10.5% and Exit Yield=7.5%.

Sheet Historical
A1: Historical Distributable Profit, NTA & Dividends
A3: Period | B3: FY2017 | C3: FY2018 | D3: FY2019 | E3: FY2020 | F3: FY2021 | G3: FY2022 | H3: FY2023 | I3: FY2024 | J3: FY2025 | K3: FY2026
A4: Distributable Profit Total (NZDm) | B4: 17.6 | C4: 20.5 | D4: 20.9 | E4: 21.1 | F4: 29.1 | G4: 29.9 | H4: 31 | I4: 31 | J4: 28.4 | K4: 30.7
A5: Distributable Profit/Share (cents) | B5: 9.35 | C5: 7.85 | D5: 8.01 | E5: 7.66 | F5: 8.05 | G5: 8.11 | H5: 8.44 | I5: 8.39 | J5: 7.58 | K5: 8.13
A6: NTA per Share ($) | B6: 1.55 | C6: 1.64 | D6: 1.7 | E6: 1.73 | F6: 2.08 | G6: 2.32 | H6: 1.84 | I6: 1.57 | J6: 1.6 | K6: 1.62
A7: FY-End Closing Price ($) | B7: 1.33 | C7: 1.4 | D7: 1.61 | E7: 1.65 | F7: 2.06 | G7: 1.72 | H7: 1.41 | I7: 1.16 | J7: 1.05 | K7: 1.045
A8: Implied P/NTA | B8: =B7/B6 -> 0 | C8: =C7/C6 -> 0 | D8: =D7/D6 -> 0 | E8: =E7/E6 -> 0 | F8: =F7/F6 -> 0 | G8: =G7/G6 -> 0 | H8: =H7/H6 -> 0 | I8: =I7/I6 -> 0 | ... K8: =K7/K6 -> 0
A9: Implied P/Distributable-Profit | B9: =B7/(B5/100) -> 0 | C9: =C7/(C5/100) -> 0 | D9: =D7/(D5/100) -> 0 | E9: =E7/(E5/100) -> 0 | F9: =F7/(F5/100) -> 0 | G9: =G7/(G5/100) -> 0 | H9: =H7/(H5/100) -> 0 | I9: =I7/(I5/100) -> 0 | ... K9: =K7/(K5/100) -> 0
A11: DPS 5yr CAGR (FY21-26) | B11: 0.002
A12: DPS 3yr CAGR (FY23-26) | B12: -0.0124
A13: DPS 10yr CAGR (FY17-26) | B13: -0.0154
A14: NTA 5yr CAGR | B14: -0.0488
A15: NTA 10yr CAGR | B15: 0.0049
A16: Selected Growth Driver | B16: per-share Distributable Profit 5yr CAGR (FY21-26), essentially flat
A18: Note: P/E and EV/EBITDA are deliberately omitted -- statutory EPS is
A19: fair-value-distorted (unrealised property revaluations) and EBITDA is
A20: structurally undefined under IAS 40 fair-value property accounting.

Sheet Model_Info
A1: Model Provenance & Methodology Notes
A4: Ticker | B4: IPL.NZ (Investore Property Limited)
A5: Built by | B5: Claude agent (DCF valuation skill), REIT AFFO/NTA methodology per ARG.NZ template
A6: Valuation date | B6: 2026-08-12
A7: Share price date/source | B7: Live Yahoo Finance quote, 2026-08-12: NZ$1.05
A8: Data vintage | B8: FY2026 Annual Report (year to 31-Mar-2026), published 21-May-2026; HY2026 interim (6 months to 30-Sep-2025); Chair's Letter FY26
A9: Methodology | B9: Two-leg blend, 50/50: (1) Distributable Profit After Tax capitalized at cost of equity with a terminal P/DP exit multiple; (2) book NTA per share compounded forward and exited at a justified P/NTA multiple, plus PV of interim cash dividends. NOT a WACC-based owner-FCF DCF -- see valuation_philosophy in the JSON.
A10: Why not FCF/WACC DCF | B10: Distributable Profit is already measured AFTER interest expense (an equity-level cash flow), so it is discounted at COST OF EQUITY and net debt is never subtracted a second time. Reported OCF-less-capex conflates discretionary property acquisition/development with maintenance capex. Statutory NetIncome/EPS are fair-value-revaluation noise (FY2021 +$161.3m, FY2023 -$150.2m, FY2024 -$67.1m). EBITDA is structurally undefined under IAS 40.
A11: SBC treatment | B11: Verified NIL -- Investore is externally managed by Stride Investment Management Limited (SIML) with no employees, confirmed by StockBasedComp=0.0 across all history in the Metrics CSV. The standard SBC/owner-FCF adjustment from the skill is a genuine no-op here, stated explicitly rather than silently skipped.
A12: Cost of equity build | B12: CAPM base 8.85% (rf 4.35% + beta 0.75 x ERP 6.0%) + tenant concentration premium 0.6% (Woolworths 53% of contract rent) + illiquidity premium 0.55% (small-cap NZX) + governance premium 0.5% (external management/related-party conflicts) = 10.5% base case.
A13: Key near-term risk modelled | B13: FY2027 dip in the base-case DPS growth path reflects two bond maturities refinancing at higher rates (IPL030 4.00% coupon Feb-2027, IPL020 2.40% coupon Aug-2027) plus roll-off of the 80%-hedged 4.2% weighted average cost of debt.
A14: What to refresh after next earnings | B14: Roll forward FY2026 Distributable Profit/share, NTA/share and dividend actuals; re-check bond refinancing outcomes (IPL020/IPL030 pricing once known); re-verify Woolworths % of Contract Rental and LVR; update FY-end closing price series for the sanity check; re-pull live price via Yahoo Finance chart API.
A15: Cell colour conventions | B15: Gray-filled cells = editable inputs. Green-filled bold cells = key output results. White cells with formulas = calculated, do not hand-edit. Sheet 2 pulls several cells directly from Sheet 1 via cross-sheet formulas (cost of equity, share count, distributable profit) to keep the two legs consistent.
A16: Staleness warning | B16: All figures (price, Distributable Profit, NTA, LVR, bond terms) go stale after the next quarterly/half-year/annual result and must be re-verified against the latest filing before reuse. Do not treat this file as current beyond a few months from the valuation date above.
