Workbook

Sheet Assumptions
A1: WISE PLC (WISE.L) - DCF VALUATION MODEL
A2: Currency: GBP (£ millions unless otherwise stated)
A3: Model Date: February 2026 (Revised with FY25 actuals)
A5: COMPANY OVERVIEW
A6: Company | B6: Wise plc
A7: Ticker | B7: WISE.L (LSE)
A8: Sector | B8: Fintech / Payments
A9: FY End | B9: March 31
A11: KEY DCF ASSUMPTIONS
A12: Risk-Free Rate | B12: 0.0467 | C12: UK 10Y Gilt yield
A13: Equity Risk Premium | B13: 0.0406 | C13: Market consensus
A14: Beta (Levered) | B14: 0.99 | C14: Source: Alpha Spread
A15: Cost of Equity | B15: =B12+B14*B13 -> 0.086894
A16: Cost of Debt (Pre-tax) | B16: 0.102 | C16: Interest expense / Avg debt
A17: Tax Rate | B17: 0.26 | C17: UK effective rate
A18: Cost of Debt (After-tax) | B18: =B16*(1-B17) -> 0.07548
A19: Debt / Total Capital | B19: 0.013 | C19: Based on market values
A20: Equity / Total Capital | B20: =1-B19 -> 0.987
A21: WACC | B21: =B15*B20+B18*B19 -> 0.086745618
A23: GROWTH ASSUMPTIONS
A24: Revenue Growth FY26 | B24: 0.15 | C24: Revised up: mgmt guides 15-20% underlying income growth
A25: Revenue Growth FY27 | B25: 0.16 | C25: Platform partnerships accelerating (Morgan Stanley, Nubank)
A26: Revenue Growth FY28 | B26: 0.15 | C26: Customer growth +21% YoY, holdings +33%
A27: Revenue Growth FY29 | B27: 0.14 | C27: Gradual deceleration as base grows
A28: Revenue Growth FY30 | B28: 0.12 | C28: Mature but still above-market growth
A29: Terminal Growth Rate | B29: 0.025 | C29: Long-term GDP growth
A31: MARGIN ASSUMPTIONS
A32: EBIT Margin FY25 (Base) | B32: 0.3878 | C32: Actual FY25
A33: Target EBIT Margin | B33: 0.25 | C33: Long-term normalization
A34: D&A % of Revenue | B34: 0.011 | C34: Based on FY25
A35: CapEx % of Revenue | B35: 0.02 | C35: Historical average
A36: NWC % of Revenue Change | B36: 0.05 | C36: Estimated
A38: VALUATION INPUTS
A39: Shares Outstanding (m) | B39: 1025
A40: Net Cash (Debt) £m | B40: 1331 | C40: Net cash position FY25
A41: Current Share Price (GBX) | B41: 874
A43: EXIT MULTIPLE ASSUMPTIONS
A44: Exit EV/Revenue Multiple | B44: 6.5 | C44: Revised up: US dual listing premium, investment grade rating
A45: Exit EV/EBITDA Multiple | B45: 15 | C45: Alternative approach
A46: Current EV/Revenue (FY25) | B46: ='DCF Model'!B39/Historical!E6 -> 4.9491954
...

Sheet Historical
A1: WISE PLC - HISTORICAL FINANCIALS
A2: Source: Company filings, Yahoo Finance
B4: FY2022 | C4: FY2023 | D4: FY2024 | E4: FY2025
A5: INCOME STATEMENT
A6: Total Revenue | B6: 563.8 | C6: 986.3 | D6: 1537.2 | E6: 1806.2
A7: Cost of Revenue | B7: 194.7 | C7: 348.1 | D7: 444.8 | E7: 498.4
A8: Gross Profit | B8: 369.1 | C8: 638.2 | D8: 1092.4 | E8: 1307.8
A9: Operating Expenses | B9: 320.4 | C9: 483.8 | D9: 610.2 | E9: 750
A10: Operating Income (EBIT) | B10: 48.7 | C10: 154.4 | D10: 482.2 | E10: 557.8
A11: Interest Income/(Expense) | B11: -4.8 | C11: -7.9 | D11: -0.8 | E11: 18.5
A12: Pre-Tax Income | B12: 43.9 | C12: 146.5 | D12: 481.4 | E12: 564.8
A13: Tax Expense | B13: 11 | C13: 32.5 | D13: 126.8 | E13: 148.1
A14: Net Income | B14: 32.9 | C14: 114 | D14: 354.6 | E14: 416.7
A16: KEY RATIOS
A17: Revenue Growth % | C17: =C6/B6-1 -> 0.74937921 | D17: =D6/C6-1 -> 0.55855216 | E17: =E6/D6-1 -> 0.17499349
A18: Gross Margin % | B18: =B8/B6 -> 0.65466477 | C18: =C8/C6 -> 0.64706479 | D18: =D8/D6 -> 0.71064273 | E18: =E8/E6 -> 0.72406157
A19: EBIT Margin % | B19: =B10/B6 -> 0.086378148 | C19: =C10/C6 -> 0.15654466 | D19: =D10/D6 -> 0.31368722 | E19: =E10/E6 -> 0.30882516
A20: Net Margin % | B20: =B14/B6 -> 0.058354026 | C20: =C14/C6 -> 0.11558349 | D20: =D14/D6 -> 0.23067916 | E20: =E14/E6 -> 0.23070535
A21: Effective Tax Rate % | B21: =B13/B12 -> 0.25056948 | C21: =C13/C12 -> 0.221843 | D21: =D13/D12 -> 0.26339842 | E21: =E13/E12 -> 0.26221671
A23: CASH FLOW DATA
A24: D&A | B24: 10 | C24: 12 | D24: 18.3 | E24: 18.4
A25: Capital Expenditure | B25: 11.9 | C25: 8.8 | D25: 13 | E25: 35.4
A26: Free Cash Flow | B26: 3126 | C26: 213.3 | D26: 486.6 | E26: 615.4
A28: BALANCE SHEET
A29: Total Assets | B29: 7564.4 | C29: 11904.2 | D29: 15137.4 | E29: 19246.2
A30: Total Liabilities | B30: 7155.2 | C30: 11327.3 | D30: 14157.5 | E30: 17860
A31: Total Equity | B31: 409.2 | C31: 576.9 | D31: 979.9 | E31: 1386.2
A32: Total Debt | B32: 95.7 | C32: 264.4 | D32: 224.2 | E32: 185.6
A33: Net Debt / (Cash) | B33: -262 | C33: -407 | D33: -837 | E33: -1331

Sheet DCF Model
A1: WISE PLC - DISCOUNTED CASH FLOW MODEL
A2: All figures in £ millions
A4: Projection Period | B4: Base | C4: FY2026E | D4: FY2027E | E4: FY2028E | F4: FY2029E | G4: FY2030E | H4: Terminal
A6: REVENUE PROJECTIONS
A7: Revenue | B7: 1806.2 | C7: =B7*(1+Assumptions!B24) -> 2077.13 | D7: =C7*(1+Assumptions!B25) -> 2409.4708 | E7: =D7*(1+Assumptions!B26) -> 2770.8914 | F7: =E7*(1+Assumptions!B27) -> 3158.8162 | G7: =F7*(1+Assumptions!B28) -> 3537.8742
A8: Growth Rate | C8: =Assumptions!B24 -> 0.15 | D8: =Assumptions!B25 -> 0.16 | E8: =Assumptions!B26 -> 0.15 | F8: =Assumptions!B27 -> 0.14 | G8: =Assumptions!B28 -> 0.12
A10: OPERATING PROFITABILITY
A11: EBIT Margin (declining to target) | B11: =Assumptions!B32 -> 0.3878 | C11: =(Assumptions!B32-Assumptions!B33)/5*4+Assumptions!B33 -> 0.36024 | D11: =(Assumptions!B32-Assumptions!B33)/5*3+Assumptions!B33 -> 0.33268 | E11: =(Assumptions!B32-Assumptions!B33)/5*2+Assumptions!B33 -> 0.30512 | F11: =(Assumptions!B32-Assumptions!B33)/5*1+Assumptions!B33 -> 0.27756 | G11: =Assumptions!B33 -> 0.25
A12: EBIT | B12: 557.8 | C12: =C7*C11 -> 748.26531 | D12: =D7*D11 -> 801.58275 | E12: =E7*E11 -> 845.45439 | F12: =F7*F11 -> 876.76103 | G12: =G7*G11 -> 884.46854
A13: Less: Taxes on EBIT | C13: =-C12*Assumptions!B17 -> -194.54898 | D13: =-D12*Assumptions!B17 -> -208.41151 | E13: =-E12*Assumptions!B17 -> -219.81814 | F13: =-F12*Assumptions!B17 -> -227.95787 | G13: =-G12*Assumptions!B17 -> -229.96182
A14: NOPAT (EBIT after tax) | C14: =C12+C13 -> 553.71633 | D14: =D12+D13 -> 593.17123 | E14: =E12+E13 -> 625.63625 | F14: =F12+F13 -> 648.80316 | G14: =G12+G13 -> 654.50672
A16: CASH FLOW ADJUSTMENTS
A17: Add: Depreciation & Amortization | C17: =C7*Assumptions!B34 -> 22.84843 | D17: =D7*Assumptions!B34 -> 26.504179 | E17: =E7*Assumptions!B34 -> 30.479806 | F17: =F7*Assumptions!B34 -> 34.746978 | G17: =G7*Assumptions!B34 -> 38.916616
A18: Less: Capital Expenditure | C18: =-C7*Assumptions!B35 -> -41.5426 | D18: =-D7*Assumptions!B35 -> -48.189416 | E18: =-E7*Assumptions!B35 -> -55.417828 | F18: =-F7*Assumptions!B35 -> -63.176324 | G18: =-G7*Assumptions!B35 -> -70.757483
A19: Less: Change in NWC | C19: =-(C7-B7)*Assumptions!B36 -> -13.5465 | D19: =-(D7-C7)*Assumptions!B36 -> -16.61704 | E19: =-(E7-D7)*Assumptions!B36 -> -18.071031 | F19: =-(F7-E7)*Assumptions!B36 -> -19.39624 | G19: =-(G7-F7)*Assumptions!B36 -> -18.952897
A21: UNLEVERED FREE CASH FLOW
A22: Unlevered Free Cash Flow | C22: =C14+C17+C18+C19 -> 521.47566 | D22: =D14+D17+D18+D19 -> 554.86895 | E22: =E14+E17+E18+E19 -> 582.62719 | F22: =F14+F17+F18+F19 -> 600.97758 | G22: =G14+G17+G18+G19 -> 603.71296
A24: DISCOUNTING
A25: Discount Period (Mid-Year) | C25: 0.5 | D25: 1.5 | E25: 2.5 | F25: 3.5 | G25: 4.5
A26: WACC | C26: =Assumptions!B21 -> 0.086745618 | D26: =Assumptions!B21 -> 0.086745618 | E26: =Assumptions!B21 -> 0.086745618 | F26: =Assumptions!B21 -> 0.086745618 | G26: =Assumptions!B21 -> 0.086745618
A27: Discount Factor | C27: =1/(1+C26)^C25 -> 0.95925937 | D27: =1/(1+D26)^D25 -> 0.88268989 | E27: =1/(1+E26)^E25 -> 0.8122323 | F27: =1/(1+F26)^F25 -> 0.74739873 | G27: =1/(1+G26)^G25 -> 0.68774028
A28: Present Value of FCF | C28: =C22*C27 -> 500.23041 | D28: =D22*D27 -> 489.77722 | E28: =E22*E27 -> 473.22863 | F28: =F22*F27 -> 449.16988 | G28: =G22*G27 -> 415.19772
A30: TERMINAL VALUE
A31: Terminal Year FCF | H31: =G22*(1+Assumptions!B29) -> 618.80578
A32: Terminal Growth Rate | H32: =Assumptions!B29 -> 0.025
A33: Terminal Value (Gordon Growth) | H33: =H31/(Assumptions!B21-H32) -> 10021.857
A34: PV of Terminal Value | H34: =H33/(1+Assumptions!B21)^(G25+0.5) -> 6611.6329
A36: VALUATION SUMMARY
A37: Sum of PV of FCFs | B37: =SUM(C28:G28) -> 2327.6039
A38: PV of Terminal Value | B38: =H34 -> 6611.6329
A39: Enterprise Value | B39: =B37+B38 -> 8939.2367
A40: Less: Net Debt (Add: Net Cash) | B40: =Assumptions!B40 -> 1331
A41: Equity Value | B41: =B39+B40 -> 10270.237
A42: Shares Outstanding (m) | B42: =Assumptions!B39 -> 1025
A43: Implied Share Price (£) | B43: =B41/B42 -> 10.019743
A44: Current Share Price (£) | B44: =Assumptions!B41/100 -> 8.74
A45: Upside / (Downside) | B45: =B43/B44-1 -> 0.1464237
A46: EXIT MULTIPLE APPROACH
A47: Year 5 Revenue | B47: =G7 -> 3537.8742
A48: Exit EV/Revenue Multiple | B48: =Assumptions!B44 -> 6.5
...

Sheet Sensitivity
A1: SENSITIVITY ANALYSIS
A3: IMPLIED SHARE PRICE (£)
A4: WACC vs Terminal Growth Rate
B5: WACC ↓
A6: Terminal Growth → | B6: 0.015 | C6: 0.02 | D6: 0.025 | E6: 0.03 | F6: 0.035
A7: 0.07 | B7: =('DCF Model'!C22/(1+0.07)^0.5+'DCF Model'!D22/(1+0.07)^1.5+'DCF Model'!E22/(1+0.07)^2.5+'DCF Model'!F22/(1+0.07)^3.5+'DCF Model'!G22/(1+0.07)^4.5+('DCF Model'!G22*(1+0.015)/(0.07-0.015))/(1+0.07)^5+Assumptions!B40)/Assumptions!B39 -> 11.406317 | C7: =('DCF Model'!C22/(1+0.07)^0.5+'DCF Model'!D22/(1+0.07)^1.5+'DCF Model'!E22/(1+0.07)^2.5+'DCF Model'!F22/(1+0.07)^3.5+'DCF Model'!G22/(1+0.07)^4.5+('DCF Model'!G22*(1+0.02)/(0.07-0.02))/(1+0.07)^5+Assumptions!B40)/Assumptions!B39 -> 12.223292 | D7: =('DCF Model'!C22/(1+0.07)^0.5+'DCF Model'!D22/(1+0.07)^1.5+'DCF Model'!E22/(1+0.07)^2.5+'DCF Model'!F22/(1+0.07)^3.5+'DCF Model'!G22/(1+0.07)^4.5+('DCF Model'!G22*(1+0.025)/(0.07-0.025))/(1+0.07)^5+Assumptions!B40)/Assumptions!B39 -> 13.221817 | E7: =('DCF Model'!C22/(1+0.07)^0.5+'DCF Model'!D22/(1+0.07)^1.5+'DCF Model'!E22/(1+0.07)^2.5+'DCF Model'!F22/(1+0.07)^3.5+'DCF Model'!G22/(1+0.07)^4.5+('DCF Model'!G22*(1+0.03)/(0.07-0.03))/(1+0.07)^5+Assumptions!B40)/Assumptions!B39 -> 14.469974 | F7: =('DCF Model'!C22/(1+0.07)^0.5+'DCF Model'!D22/(1+0.07)^1.5+'DCF Model'!E22/(1+0.07)^2.5+'DCF Model'!F22/(1+0.07)^3.5+'DCF Model'!G22/(1+0.07)^4.5+('DCF Model'!G22*(1+0.035)/(0.07-0.035))/(1+0.07)^5+Assumptions!B40)/Assumptions!B39 -> 16.074746
A8: 0.08 | B8: =('DCF Model'!C22/(1+0.08)^0.5+'DCF Model'!D22/(1+0.08)^1.5+'DCF Model'!E22/(1+0.08)^2.5+'DCF Model'!F22/(1+0.08)^3.5+'DCF Model'!G22/(1+0.08)^4.5+('DCF Model'!G22*(1+0.015)/(0.08-0.015))/(1+0.08)^5+Assumptions!B40)/Assumptions!B39 -> 9.863296 | C8: =('DCF Model'!C22/(1+0.08)^0.5+'DCF Model'!D22/(1+0.08)^1.5+'DCF Model'!E22/(1+0.08)^2.5+'DCF Model'!F22/(1+0.08)^3.5+'DCF Model'!G22/(1+0.08)^4.5+('DCF Model'!G22*(1+0.02)/(0.08-0.02))/(1+0.08)^5+Assumptions!B40)/Assumptions!B39 -> 10.418327 | D8: =('DCF Model'!C22/(1+0.08)^0.5+'DCF Model'!D22/(1+0.08)^1.5+'DCF Model'!E22/(1+0.08)^2.5+'DCF Model'!F22/(1+0.08)^3.5+'DCF Model'!G22/(1+0.08)^4.5+('DCF Model'!G22*(1+0.025)/(0.08-0.025))/(1+0.08)^5+Assumptions!B40)/Assumptions!B39 -> 11.074272 | E8: =('DCF Model'!C22/(1+0.08)^0.5+'DCF Model'!D22/(1+0.08)^1.5+'DCF Model'!E22/(1+0.08)^2.5+'DCF Model'!F22/(1+0.08)^3.5+'DCF Model'!G22/(1+0.08)^4.5+('DCF Model'!G22*(1+0.03)/(0.08-0.03))/(1+0.08)^5+Assumptions!B40)/Assumptions!B39 -> 11.861407 | F8: =('DCF Model'!C22/(1+0.08)^0.5+'DCF Model'!D22/(1+0.08)^1.5+'DCF Model'!E22/(1+0.08)^2.5+'DCF Model'!F22/(1+0.08)^3.5+'DCF Model'!G22/(1+0.08)^4.5+('DCF Model'!G22*(1+0.035)/(0.08-0.035))/(1+0.08)^5+Assumptions!B40)/Assumptions!B39 -> 12.82346
A9: 0.0869 | B9: =('DCF Model'!C22/(1+0.0869)^0.5+'DCF Model'!D22/(1+0.0869)^1.5+'DCF Model'!E22/(1+0.0869)^2.5+'DCF Model'!F22/(1+0.0869)^3.5+'DCF Model'!G22/(1+0.0869)^4.5+('DCF Model'!G22*(1+0.015)/(0.0869-0.015))/(1+0.0869)^5+Assumptions!B40)/Assumptions!B39 -> 9.0500474 | C9: =('DCF Model'!C22/(1+0.0869)^0.5+'DCF Model'!D22/(1+0.0869)^1.5+'DCF Model'!E22/(1+0.0869)^2.5+'DCF Model'!F22/(1+0.0869)^3.5+'DCF Model'!G22/(1+0.0869)^4.5+('DCF Model'!G22*(1+0.02)/(0.0869-0.02))/(1+0.0869)^5+Assumptions!B40)/Assumptions!B39 -> 9.488743 | D9: =('DCF Model'!C22/(1+0.0869)^0.5+'DCF Model'!D22/(1+0.0869)^1.5+'DCF Model'!E22/(1+0.0869)^2.5+'DCF Model'!F22/(1+0.0869)^3.5+'DCF Model'!G22/(1+0.0869)^4.5+('DCF Model'!G22*(1+0.025)/(0.0869-0.025))/(1+0.0869)^5+Assumptions!B40)/Assumptions!B39 -> 9.9983102 | E9: =('DCF Model'!C22/(1+0.0869)^0.5+'DCF Model'!D22/(1+0.0869)^1.5+'DCF Model'!E22/(1+0.0869)^2.5+'DCF Model'!F22/(1+0.0869)^3.5+'DCF Model'!G22/(1+0.0869)^4.5+('DCF Model'!G22*(1+0.03)/(0.0869-0.03))/(1+0.0869)^5+Assumptions!B40)/Assumptions!B39 -> 10.597432 | F9: =('DCF Model'!C22/(1+0.0869)^0.5+'DCF Model'!D22/(1+0.0869)^1.5+'DCF Model'!E22/(1+0.0869)^2.5+'DCF Model'!F22/(1+0.0869)^3.5+'DCF Model'!G22/(1+0.0869)^4.5+('DCF Model'!G22*(1+0.035)/(0.0869-0.035))/(1+0.0869)^5+Assumptions!B40)/Assumptions!B39 -> 11.311992
A10: 0.09 | B10: =('DCF Model'!C22/(1+0.09)^0.5+'DCF Model'!D22/(1+0.09)^1.5+'DCF Model'!E22/(1+0.09)^2.5+'DCF Model'!F22/(1+0.09)^3.5+'DCF Model'!G22/(1+0.09)^4.5+('DCF Model'!G22*(1+0.015)/(0.09-0.015))/(1+0.09)^5+Assumptions!B40)/Assumptions!B39 -> 8.7336739 | C10: =('DCF Model'!C22/(1+0.09)^0.5+'DCF Model'!D22/(1+0.09)^1.5+'DCF Model'!E22/(1+0.09)^2.5+'DCF Model'!F22/(1+0.09)^3.5+'DCF Model'!G22/(1+0.09)^4.5+('DCF Model'!G22*(1+0.02)/(0.09-0.02))/(1+0.09)^5+Assumptions!B40)/Assumptions!B39 -> 9.1310588 | D10: =('DCF Model'!C22/(1+0.09)^0.5+'DCF Model'!D22/(1+0.09)^1.5+'DCF Model'!E22/(1+0.09)^2.5+'DCF Model'!F22/(1+0.09)^3.5+'DCF Model'!G22/(1+0.09)^4.5+('DCF Model'!G22*(1+0.025)/(0.09-0.025))/(1+0.09)^5+Assumptions!B40)/Assumptions!B39 -> 9.5895798 | E10: =('DCF Model'!C22/(1+0.09)^0.5+'DCF Model'!D22/(1+0.09)^1.5+'DCF Model'!E22/(1+0.09)^2.5+'DCF Model'!F22/(1+0.09)^3.5+'DCF Model'!G22/(1+0.09)^4.5+('DCF Model'!G22*(1+0.03)/(0.09-0.03))/(1+0.09)^5+Assumptions!B40)/Assumptions!B39 -> 10.124521 | F10: =('DCF Model'!C22/(1+0.09)^0.5+'DCF Model'!D22/(1+0.09)^1.5+'DCF Model'!E22/(1+0.09)^2.5+'DCF Model'!F22/(1+0.09)^3.5+'DCF Model'!G22/(1+0.09)^4.5+('DCF Model'!G22*(1+0.035)/(0.09-0.035))/(1+0.09)^5+Assumptions!B40)/Assumptions!B39 -> 10.756724
A11: 0.1 | B11: =('DCF Model'!C22/(1+0.1)^0.5+'DCF Model'!D22/(1+0.1)^1.5+'DCF Model'!E22/(1+0.1)^2.5+'DCF Model'!F22/(1+0.1)^3.5+'DCF Model'!G22/(1+0.1)^4.5+('DCF Model'!G22*(1+0.015)/(0.1-0.015))/(1+0.1)^5+Assumptions!B40)/Assumptions!B39 -> 7.87139 | C11: =('DCF Model'!C22/(1+0.1)^0.5+'DCF Model'!D22/(1+0.1)^1.5+'DCF Model'!E22/(1+0.1)^2.5+'DCF Model'!F22/(1+0.1)^3.5+'DCF Model'!G22/(1+0.1)^4.5+('DCF Model'!G22*(1+0.02)/(0.1-0.02))/(1+0.1)^5+Assumptions!B40)/Assumptions!B39 -> 8.1671892 | D11: =('DCF Model'!C22/(1+0.1)^0.5+'DCF Model'!D22/(1+0.1)^1.5+'DCF Model'!E22/(1+0.1)^2.5+'DCF Model'!F22/(1+0.1)^3.5+'DCF Model'!G22/(1+0.1)^4.5+('DCF Model'!G22*(1+0.025)/(0.1-0.025))/(1+0.1)^5+Assumptions!B40)/Assumptions!B39 -> 8.5024283 | E11: =('DCF Model'!C22/(1+0.1)^0.5+'DCF Model'!D22/(1+0.1)^1.5+'DCF Model'!E22/(1+0.1)^2.5+'DCF Model'!F22/(1+0.1)^3.5+'DCF Model'!G22/(1+0.1)^4.5+('DCF Model'!G22*(1+0.03)/(0.1-0.03))/(1+0.1)^5+Assumptions!B40)/Assumptions!B39 -> 8.8855587 | F11: =('DCF Model'!C22/(1+0.1)^0.5+'DCF Model'!D22/(1+0.1)^1.5+'DCF Model'!E22/(1+0.1)^2.5+'DCF Model'!F22/(1+0.1)^3.5+'DCF Model'!G22/(1+0.1)^4.5+('DCF Model'!G22*(1+0.035)/(0.1-0.035))/(1+0.1)^5+Assumptions!B40)/Assumptions!B39 -> 9.3276322
A13: Note: Yellow highlighted cell represents base case assumptions
A16: SHARE PRICE BY EBIT MARGIN
A18: Long-term EBIT Margin | B18: 0.2 | C18: 0.22 | D18: 0.25 | E18: 0.28 | F18: 0.3
A19: Implied Share Price | B19: =('DCF Model'!C22/(1+Assumptions!B21)^0.5+'DCF Model'!D22/(1+Assumptions!B21)^1.5+'DCF Model'!E22/(1+Assumptions!B21)^2.5+'DCF Model'!F22/(1+Assumptions!B21)^3.5+('DCF Model'!G7*0.2*(1-Assumptions!B17)+'DCF Model'!G7*Assumptions!B34-'DCF Model'!G7*Assumptions!B35-('DCF Model'!G7-'DCF Model'!F7)*Assumptions!B36)/(1+Assumptions!B21)^4.5+(('DCF Model'!G7*0.2*(1-Assumptions!B17)+'DCF Model'!G7*Assumptions!B34-'DCF Model'!G7*Assumptions!B35)*(1+Assumptions!B29)/(Assumptions!B21-Assumptions!B29))/(1+Assumptions!B21)^5+Assumptions!B40)/Assumptions!B39 -> 8.7357992 | C19: =('DCF Model'!C22/(1+Assumptions!B21)^0.5+'DCF Model'!D22/(1+Assumptions!B21)^1.5+'DCF Model'!E22/(1+Assumptions!B21)^2.5+'DCF Model'!F22/(1+Assumptions!B21)^3.5+('DCF Model'!G7*0.22*(1-Assumptions!B17)+'DCF Model'!G7*Assumptions!B34-'DCF Model'!G7*Assumptions!B35-('DCF Model'!G7-'DCF Model'!F7)*Assumptions!B36)/(1+Assumptions!B21)^4.5+(('DCF Model'!G7*0.22*(1-Assumptions!B17)+'DCF Model'!G7*Assumptions!B34-'DCF Model'!G7*Assumptions!B35)*(1+Assumptions!B29)/(Assumptions!B21-Assumptions!B29))/(1+Assumptions!B21)^5+Assumptions!B40)/Assumptions!B39 -> 9.3303777 | D19: =('DCF Model'!C22/(1+Assumptions!B21)^0.5+'DCF Model'!D22/(1+Assumptions!B21)^1.5+'DCF Model'!E22/(1+Assumptions!B21)^2.5+'DCF Model'!F22/(1+Assumptions!B21)^3.5+('DCF Model'!G7*0.25*(1-Assumptions!B17)+'DCF Model'!G7*Assumptions!B34-'DCF Model'!G7*Assumptions!B35-('DCF Model'!G7-'DCF Model'!F7)*Assumptions!B36)/(1+Assumptions!B21)^4.5+(('DCF Model'!G7*0.25*(1-Assumptions!B17)+'DCF Model'!G7*Assumptions!B34-'DCF Model'!G7*Assumptions!B35)*(1+Assumptions!B29)/(Assumptions!B21-Assumptions!B29))/(1+Assumptions!B21)^5+Assumptions!B40)/Assumptions!B39 -> 10.222245 | E19: =('DCF Model'!C22/(1+Assumptions!B21)^0.5+'DCF Model'!D22/(1+Assumptions!B21)^1.5+'DCF Model'!E22/(1+Assumptions!B21)^2.5+'DCF Model'!F22/(1+Assumptions!B21)^3.5+('DCF Model'!G7*0.28*(1-Assumptions!B17)+'DCF Model'!G7*Assumptions!B34-'DCF Model'!G7*Assumptions!B35-('DCF Model'!G7-'DCF Model'!F7)*Assumptions!B36)/(1+Assumptions!B21)^4.5+(('DCF Model'!G7*0.28*(1-Assumptions!B17)+'DCF Model'!G7*Assumptions!B34-'DCF Model'!G7*Assumptions!B35)*(1+Assumptions!B29)/(Assumptions!B21-Assumptions!B29))/(1+Assumptions!B21)^5+Assumptions!B40)/Assumptions!B39 -> 11.114113 | F19: =('DCF Model'!C22/(1+Assumptions!B21)^0.5+'DCF Model'!D22/(1+Assumptions!B21)^1.5+'DCF Model'!E22/(1+Assumptions!B21)^2.5+'DCF Model'!F22/(1+Assumptions!B21)^3.5+('DCF Model'!G7*0.3*(1-Assumptions!B17)+'DCF Model'!G7*Assumptions!B34-'DCF Model'!G7*Assumptions!B35-('DCF Model'!G7-'DCF Model'!F7)*Assumptions!B36)/(1+Assumptions!B21)^4.5+(('DCF Model'!G7*0.3*(1-Assumptions!B17)+'DCF Model'!G7*Assumptions!B34-'DCF Model'!G7*Assumptions!B35)*(1+Assumptions!B29)/(Assumptions!B21-Assumptions!B29))/(1+Assumptions!B21)^5+Assumptions!B40)/Assumptions!B39 -> 11.708692
A22: EXIT MULTIPLE SENSITIVITY
A24: IMPLIED SHARE PRICE BY EXIT EV/REVENUE MULTIPLE
A26: Exit EV/Revenue | B26: 3 | C26: 3.5 | D26: 4 | E26: 4.5 | F26: 5 | G26: 5.5 | H26: 6
A27: Implied Share Price | B27: =('DCF Model'!C22/(1+Assumptions!B21)^0.5+'DCF Model'!D22/(1+Assumptions!B21)^1.5+'DCF Model'!E22/(1+Assumptions!B21)^2.5+'DCF Model'!F22/(1+Assumptions!B21)^3.5+'DCF Model'!G22/(1+Assumptions!B21)^4.5+('DCF Model'!G7*3)/(1+Assumptions!B21)^4.5+Assumptions!B40)/Assumptions!B39 -> 10.690751 | C27: =('DCF Model'!C22/(1+Assumptions!B21)^0.5+'DCF Model'!D22/(1+Assumptions!B21)^1.5+'DCF Model'!E22/(1+Assumptions!B21)^2.5+'DCF Model'!F22/(1+Assumptions!B21)^3.5+'DCF Model'!G22/(1+Assumptions!B21)^4.5+('DCF Model'!G7*3.5)/(1+Assumptions!B21)^4.5+Assumptions!B40)/Assumptions!B39 -> 11.877648 | D27: =('DCF Model'!C22/(1+Assumptions!B21)^0.5+'DCF Model'!D22/(1+Assumptions!B21)^1.5+'DCF Model'!E22/(1+Assumptions!B21)^2.5+'DCF Model'!F22/(1+Assumptions!B21)^3.5+'DCF Model'!G22/(1+Assumptions!B21)^4.5+('DCF Model'!G7*4)/(1+Assumptions!B21)^4.5+Assumptions!B40)/Assumptions!B39 -> 13.064545 | E27: =('DCF Model'!C22/(1+Assumptions!B21)^0.5+'DCF Model'!D22/(1+Assumptions!B21)^1.5+'DCF Model'!E22/(1+Assumptions!B21)^2.5+'DCF Model'!F22/(1+Assumptions!B21)^3.5+'DCF Model'!G22/(1+Assumptions!B21)^4.5+('DCF Model'!G7*4.5)/(1+Assumptions!B21)^4.5+Assumptions!B40)/Assumptions!B39 -> 14.251441 | F27: =('DCF Model'!C22/(1+Assumptions!B21)^0.5+'DCF Model'!D22/(1+Assumptions!B21)^1.5+'DCF Model'!E22/(1+Assumptions!B21)^2.5+'DCF Model'!F22/(1+Assumptions!B21)^3.5+'DCF Model'!G22/(1+Assumptions!B21)^4.5+('DCF Model'!G7*5)/(1+Assumptions!B21)^4.5+Assumptions!B40)/Assumptions!B39 -> 15.438338 | G27: =('DCF Model'!C22/(1+Assumptions!B21)^0.5+'DCF Model'!D22/(1+Assumptions!B21)^1.5+'DCF Model'!E22/(1+Assumptions!B21)^2.5+'DCF Model'!F22/(1+Assumptions!B21)^3.5+'DCF Model'!G22/(1+Assumptions!B21)^4.5+('DCF Model'!G7*5.5)/(1+Assumptions!B21)^4.5+Assumptions!B40)/Assumptions!B39 -> 16.625235 | H27: =('DCF Model'!C22/(1+Assumptions!B21)^0.5+'DCF Model'!D22/(1+Assumptions!B21)^1.5+'DCF Model'!E22/(1+Assumptions!B21)^2.5+'DCF Model'!F22/(1+Assumptions!B21)^3.5+'DCF Model'!G22/(1+Assumptions!B21)^4.5+('DCF Model'!G7*6)/(1+Assumptions!B21)^4.5+Assumptions!B40)/Assumptions!B39 -> 17.812132
A30: SHARE PRICE: WACC vs EXIT MULTIPLE
B31: WACC ↓
A32: Exit Multiple → | B32: 3.5 | C32: 4 | D32: 4.5 | E32: 5 | F32: 5.5
A33: 0.07 | B33: =('DCF Model'!C22/(1+0.07)^0.5+'DCF Model'!D22/(1+0.07)^1.5+'DCF Model'!E22/(1+0.07)^2.5+'DCF Model'!F22/(1+0.07)^3.5+'DCF Model'!G22/(1+0.07)^4.5+('DCF Model'!G7*3.5)/(1+0.07)^4.5+Assumptions!B40)/Assumptions!B39 -> 12.566134 | C33: =('DCF Model'!C22/(1+0.07)^0.5+'DCF Model'!D22/(1+0.07)^1.5+'DCF Model'!E22/(1+0.07)^2.5+'DCF Model'!F22/(1+0.07)^3.5+'DCF Model'!G22/(1+0.07)^4.5+('DCF Model'!G7*4)/(1+0.07)^4.5+Assumptions!B40)/Assumptions!B39 -> 13.838938 | D33: =('DCF Model'!C22/(1+0.07)^0.5+'DCF Model'!D22/(1+0.07)^1.5+'DCF Model'!E22/(1+0.07)^2.5+'DCF Model'!F22/(1+0.07)^3.5+'DCF Model'!G22/(1+0.07)^4.5+('DCF Model'!G7*4.5)/(1+0.07)^4.5+Assumptions!B40)/Assumptions!B39 -> 15.111742 | E33: =('DCF Model'!C22/(1+0.07)^0.5+'DCF Model'!D22/(1+0.07)^1.5+'DCF Model'!E22/(1+0.07)^2.5+'DCF Model'!F22/(1+0.07)^3.5+'DCF Model'!G22/(1+0.07)^4.5+('DCF Model'!G7*5)/(1+0.07)^4.5+Assumptions!B40)/Assumptions!B39 -> 16.384546 | F33: =('DCF Model'!C22/(1+0.07)^0.5+'DCF Model'!D22/(1+0.07)^1.5+'DCF Model'!E22/(1+0.07)^2.5+'DCF Model'!F22/(1+0.07)^3.5+'DCF Model'!G22/(1+0.07)^4.5+('DCF Model'!G7*5.5)/(1+0.07)^4.5+Assumptions!B40)/Assumptions!B39 -> 17.65735
A34: 0.08 | B34: =('DCF Model'!C22/(1+0.08)^0.5+'DCF Model'!D22/(1+0.08)^1.5+'DCF Model'!E22/(1+0.08)^2.5+'DCF Model'!F22/(1+0.08)^3.5+'DCF Model'!G22/(1+0.08)^4.5+('DCF Model'!G7*3.5)/(1+0.08)^4.5+Assumptions!B40)/Assumptions!B39 -> 12.148146 | C34: =('DCF Model'!C22/(1+0.08)^0.5+'DCF Model'!D22/(1+0.08)^1.5+'DCF Model'!E22/(1+0.08)^2.5+'DCF Model'!F22/(1+0.08)^3.5+'DCF Model'!G22/(1+0.08)^4.5+('DCF Model'!G7*4)/(1+0.08)^4.5+Assumptions!B40)/Assumptions!B39 -> 13.368769 | D34: =('DCF Model'!C22/(1+0.08)^0.5+'DCF Model'!D22/(1+0.08)^1.5+'DCF Model'!E22/(1+0.08)^2.5+'DCF Model'!F22/(1+0.08)^3.5+'DCF Model'!G22/(1+0.08)^4.5+('DCF Model'!G7*4.5)/(1+0.08)^4.5+Assumptions!B40)/Assumptions!B39 -> 14.589392 | E34: =('DCF Model'!C22/(1+0.08)^0.5+'DCF Model'!D22/(1+0.08)^1.5+'DCF Model'!E22/(1+0.08)^2.5+'DCF Model'!F22/(1+0.08)^3.5+'DCF Model'!G22/(1+0.08)^4.5+('DCF Model'!G7*5)/(1+0.08)^4.5+Assumptions!B40)/Assumptions!B39 -> 15.810015 | F34: =('DCF Model'!C22/(1+0.08)^0.5+'DCF Model'!D22/(1+0.08)^1.5+'DCF Model'!E22/(1+0.08)^2.5+'DCF Model'!F22/(1+0.08)^3.5+'DCF Model'!G22/(1+0.08)^4.5+('DCF Model'!G7*5.5)/(1+0.08)^4.5+Assumptions!B40)/Assumptions!B39 -> 17.030638
A35: 0.087 | B35: =('DCF Model'!C22/(1+0.087)^0.5+'DCF Model'!D22/(1+0.087)^1.5+'DCF Model'!E22/(1+0.087)^2.5+'DCF Model'!F22/(1+0.087)^3.5+'DCF Model'!G22/(1+0.087)^4.5+('DCF Model'!G7*3.5)/(1+0.087)^4.5+Assumptions!B40)/Assumptions!B39 -> 11.867622 | C35: =('DCF Model'!C22/(1+0.087)^0.5+'DCF Model'!D22/(1+0.087)^1.5+'DCF Model'!E22/(1+0.087)^2.5+'DCF Model'!F22/(1+0.087)^3.5+'DCF Model'!G22/(1+0.087)^4.5+('DCF Model'!G7*4)/(1+0.087)^4.5+Assumptions!B40)/Assumptions!B39 -> 13.053269 | D35: =('DCF Model'!C22/(1+0.087)^0.5+'DCF Model'!D22/(1+0.087)^1.5+'DCF Model'!E22/(1+0.087)^2.5+'DCF Model'!F22/(1+0.087)^3.5+'DCF Model'!G22/(1+0.087)^4.5+('DCF Model'!G7*4.5)/(1+0.087)^4.5+Assumptions!B40)/Assumptions!B39 -> 14.238917 | E35: =('DCF Model'!C22/(1+0.087)^0.5+'DCF Model'!D22/(1+0.087)^1.5+'DCF Model'!E22/(1+0.087)^2.5+'DCF Model'!F22/(1+0.087)^3.5+'DCF Model'!G22/(1+0.087)^4.5+('DCF Model'!G7*5)/(1+0.087)^4.5+Assumptions!B40)/Assumptions!B39 -> 15.424564 | F35: =('DCF Model'!C22/(1+0.087)^0.5+'DCF Model'!D22/(1+0.087)^1.5+'DCF Model'!E22/(1+0.087)^2.5+'DCF Model'!F22/(1+0.087)^3.5+'DCF Model'!G22/(1+0.087)^4.5+('DCF Model'!G7*5.5)/(1+0.087)^4.5+Assumptions!B40)/Assumptions!B39 -> 16.610211
A36: 0.09 | B36: =('DCF Model'!C22/(1+0.09)^0.5+'DCF Model'!D22/(1+0.09)^1.5+'DCF Model'!E22/(1+0.09)^2.5+'DCF Model'!F22/(1+0.09)^3.5+'DCF Model'!G22/(1+0.09)^4.5+('DCF Model'!G7*3.5)/(1+0.09)^4.5+Assumptions!B40)/Assumptions!B39 -> 11.750321 | C36: =('DCF Model'!C22/(1+0.09)^0.5+'DCF Model'!D22/(1+0.09)^1.5+'DCF Model'!E22/(1+0.09)^2.5+'DCF Model'!F22/(1+0.09)^3.5+'DCF Model'!G22/(1+0.09)^4.5+('DCF Model'!G7*4)/(1+0.09)^4.5+Assumptions!B40)/Assumptions!B39 -> 12.921355 | D36: =('DCF Model'!C22/(1+0.09)^0.5+'DCF Model'!D22/(1+0.09)^1.5+'DCF Model'!E22/(1+0.09)^2.5+'DCF Model'!F22/(1+0.09)^3.5+'DCF Model'!G22/(1+0.09)^4.5+('DCF Model'!G7*4.5)/(1+0.09)^4.5+Assumptions!B40)/Assumptions!B39 -> 14.092388 | E36: =('DCF Model'!C22/(1+0.09)^0.5+'DCF Model'!D22/(1+0.09)^1.5+'DCF Model'!E22/(1+0.09)^2.5+'DCF Model'!F22/(1+0.09)^3.5+'DCF Model'!G22/(1+0.09)^4.5+('DCF Model'!G7*5)/(1+0.09)^4.5+Assumptions!B40)/Assumptions!B39 -> 15.263422 | F36: =('DCF Model'!C22/(1+0.09)^0.5+'DCF Model'!D22/(1+0.09)^1.5+'DCF Model'!E22/(1+0.09)^2.5+'DCF Model'!F22/(1+0.09)^3.5+'DCF Model'!G22/(1+0.09)^4.5+('DCF Model'!G7*5.5)/(1+0.09)^4.5+Assumptions!B40)/Assumptions!B39 -> 16.434455
A37: 0.1 | B37: =('DCF Model'!C22/(1+0.1)^0.5+'DCF Model'!D22/(1+0.1)^1.5+'DCF Model'!E22/(1+0.1)^2.5+'DCF Model'!F22/(1+0.1)^3.5+'DCF Model'!G22/(1+0.1)^4.5+('DCF Model'!G7*3.5)/(1+0.1)^4.5+Assumptions!B40)/Assumptions!B39 -> 11.371505 | C37: =('DCF Model'!C22/(1+0.1)^0.5+'DCF Model'!D22/(1+0.1)^1.5+'DCF Model'!E22/(1+0.1)^2.5+'DCF Model'!F22/(1+0.1)^3.5+'DCF Model'!G22/(1+0.1)^4.5+('DCF Model'!G7*4)/(1+0.1)^4.5+Assumptions!B40)/Assumptions!B39 -> 12.495389 | D37: =('DCF Model'!C22/(1+0.1)^0.5+'DCF Model'!D22/(1+0.1)^1.5+'DCF Model'!E22/(1+0.1)^2.5+'DCF Model'!F22/(1+0.1)^3.5+'DCF Model'!G22/(1+0.1)^4.5+('DCF Model'!G7*4.5)/(1+0.1)^4.5+Assumptions!B40)/Assumptions!B39 -> 13.619273 | E37: =('DCF Model'!C22/(1+0.1)^0.5+'DCF Model'!D22/(1+0.1)^1.5+'DCF Model'!E22/(1+0.1)^2.5+'DCF Model'!F22/(1+0.1)^3.5+'DCF Model'!G22/(1+0.1)^4.5+('DCF Model'!G7*5)/(1+0.1)^4.5+Assumptions!B40)/Assumptions!B39 -> 14.743157 | F37: =('DCF Model'!C22/(1+0.1)^0.5+'DCF Model'!D22/(1+0.1)^1.5+'DCF Model'!E22/(1+0.1)^2.5+'DCF Model'!F22/(1+0.1)^3.5+'DCF Model'!G22/(1+0.1)^4.5+('DCF Model'!G7*5.5)/(1+0.1)^4.5+Assumptions!B40)/Assumptions!B39 -> 15.867041
A39: Note: Yellow cells represent base case assumptions (WACC 8.7%, Exit Multiple 4.5x)

Sheet Summary
A1: WISE PLC - INVESTMENT SUMMARY
A3: DCF VALUATION RESULT
A4: Implied Share Price | B4: ='DCF Model'!B43 -> 10.019743
A5: Current Share Price | B5: ='DCF Model'!B44 -> 8.74
A6: Upside / (Downside) | B6: ='DCF Model'!B45 -> 0.1464237
A8: KEY METRICS
A9: Enterprise Value | B9: ='DCF Model'!B39 -> 8939.2367
A10: Equity Value | B10: ='DCF Model'!B41 -> 10270.237
A11: EV/Revenue (FY25) | B11: ='DCF Model'!B39/Historical!E6 -> 4.9491954
A12: EV/EBIT (FY25) | B12: ='DCF Model'!B39/Historical!E10 -> 16.025882
A14: KEY ASSUMPTIONS
A15: WACC | B15: =Assumptions!B21 -> 0.086745618
A16: Terminal Growth Rate | B16: =Assumptions!B29 -> 0.025
A17: 5-Year Revenue CAGR | B17: =('DCF Model'!G7/'DCF Model'!B7)^(1/5)-1 -> 0.14391909
A19: INVESTMENT THESIS
A20: Bull Case (Updated Feb 2026):
A21: • US dual listing expands investor base, enables index inclusion
A22: • Platform partnerships with tier-1 banks (Morgan Stanley, StanChart)
A23: • Investment grade BBB rating from both S&P and Fitch
A24: • Customer holdings +33% YoY - balance growth accelerating
A26: Bear Case (Updated Feb 2026):
A27: • £2bn investment plan compresses near-term margins to 13-16%
A28: • Interest rate normalization reduces float income by ~£200m
A29: • Regulatory risks across 90+ jurisdictions
A30: • Execution risk on massive hiring plan (+700 FY26)
A32: VALUATION COMPARISON
A33: Method | B33: Implied Price | C33: Upside
A34: Gordon Growth (2.5% TG) | B34: ='DCF Model'!B43 -> 10.019743 | C34: ='DCF Model'!B45 -> 0.1464237
A35: Exit Multiple (4.5x Rev) | B35: ='DCF Model'!B59 -> 18.999029 | C35: ='DCF Model'!B61 -> 1.1738019
A36: Average | B36: =(B34+B35)/2 -> 14.509386 | C36: =(C34+C35)/2 -> 0.66011281
A38: SCENARIO ANALYSIS
A39: Bear Case (20%) | B39: =Scenarios!B21 -> 8.8216961 | C39: =Scenarios!B22 -> 0.0093473753
A40: Base Case (50%) | B40: =Scenarios!C21 -> 16.685731 | C40: =Scenarios!C22 -> 0.90912256
A41: Bull Case (30%) | B41: =Scenarios!D21 -> 25.536374 | C41: =Scenarios!D22 -> 1.9217819
A42: Probability-Weighted | B42: =Scenarios!B25 -> 17.768117 | C42: =Scenarios!B27 -> 1.0329653

Sheet Scenarios
A1: WISE PLC - SCENARIO ANALYSIS
A2: Probability-weighted valuation across Bear, Base, and Bull cases
A4: SCENARIO ASSUMPTIONS
A5: Assumption | B5: Bear | C5: Base | D5: Bull | E5: Notes
A6: Probability | B6: 0.2 | C6: 0.5 | D6: 0.3 | E6: Must sum to 100%. Bear reduced, Bull increased post-FY25
A7: Revenue CAGR (5-Year) | B7: 0.1 | C7: 0.15 | D7: 0.18 | E7: Base revised up to 15% (mgmt guides 15-20%)
A8: Exit EBIT Margin | B8: 0.2 | C8: 0.25 | D8: 0.3 | E8: Long-term profitability
A9: Exit EV/Revenue Multiple | B9: 3.5 | C9: 5.5 | D9: 7.5 | E9: Base/Bull revised up for US listing premium
A10: WACC | B10: 0.1 | C10: 0.087 | D10: 0.08 | E10: Higher risk = higher WACC
A12: SCENARIO OUTPUTS
A13: Output | B13: Bear | C13: Base | D13: Bull
A14: Year 5 Revenue (£m) | B14: =1806.2*(1+B7)^5 -> 2908.9032 | C14: =1806.2*(1+C7)^5 -> 3632.9134 | D14: =1806.2*(1+D7)^5 -> 4132.1481
A15: Year 5 EBIT (£m) | B15: =B14*B8 -> 581.78063 | C15: =C14*C8 -> 908.22834 | D15: =D14*D8 -> 1239.6444
A16: Terminal Value (£m) | B16: =B14*B9 -> 10181.161 | C16: =C14*C9 -> 19981.023 | D16: =D14*D9 -> 30991.11
A17: PV of Terminal Value (£m) | B17: =B16/(1+B10)^5 -> 6321.7 | C17: =C16/(1+C10)^5 -> 13166.49 | D17: =D16/(1+D10)^5 -> 21092.029
A18: PV of FCFs (£m, estimated) | B18: =2258*(B7/0.13)*(B8/0.25) -> 1389.5385 | C18: =2258*(C7/0.13)*(C8/0.25) -> 2605.3846 | D18: =2258*(D7/0.13)*(D8/0.25) -> 3751.7538
A19: Enterprise Value (£m) | B19: =B17+B18 -> 7711.2385 | C19: =C17+C18 -> 15771.874 | D19: =D17+D18 -> 24843.783
A20: Equity Value (£m) | B20: =B19+Assumptions!B40 -> 9042.2385 | C20: =C19+Assumptions!B40 -> 17102.874 | D20: =D19+Assumptions!B40 -> 26174.783
A21: Implied Share Price (£) | B21: =B20/Assumptions!B39 -> 8.8216961 | C21: =C20/Assumptions!B39 -> 16.685731 | D21: =D20/Assumptions!B39 -> 25.536374
A22: Upside / (Downside) | B22: =B21/(Assumptions!B41/100)-1 -> 0.0093473753 | C22: =C21/(Assumptions!B41/100)-1 -> 0.90912256 | D22: =D21/(Assumptions!B41/100)-1 -> 1.9217819
A24: PROBABILITY-WEIGHTED VALUATION
A25: Weighted Share Price | B25: =B21*B6+C21*C6+D21*D6 -> 17.768117
A26: Current Share Price | B26: =Assumptions!B41/100 -> 8.74
A27: Expected Upside | B27: =B25/B26-1 -> 1.0329653
A29: RISK / REWARD SUMMARY
A30: Downside (Bear Case) | B30: =B21 -> 8.8216961 | C30: =B22 -> 0.0093473753
A31: Base Case | B31: =C21 -> 16.685731 | C31: =C22 -> 0.90912256
A32: Upside (Bull Case) | B32: =D21 -> 25.536374 | C32: =D22 -> 1.9217819
A33: Risk/Reward Ratio | B33: =ABS(D21-Assumptions!B41/100)/ABS(Assumptions!B41/100-B21) -> 205.59588 | C33: (Bull upside £ / Bear downside £)
A35: KEY RISKS BY SCENARIO
A36: BEAR CASE TRIGGERS:
A37: • Interest rate cuts significantly reduce float income
A38: • £2bn investment plan fails to drive growth
A39: • Regulatory action in key markets (UK FCA, US)
A40: • Competition from banks investing in real-time payments
A41: • Macro slowdown reduces cross-border volumes
A43: BULL CASE TRIGGERS:
A44: • US dual listing drives multiple expansion + index inclusion
A45: • Platform/B2B business accelerates (Morgan Stanley, etc.)
A46: • Customer balances compound to £40bn+ (more float income)
...
