Workbook

Sheet Company Overview
B2: Adobe Inc. (NASDAQ: ADBE) — Company Overview
B3: As of February 17, 2026
B5: Key Statistics
B6: Stock Price | C6: $264 | D6: Sector | E6: Technology / Software
B7: Market Cap | C7: $108.4B | D7: CEO | E7: Shantanu Narayen
B8: Enterprise Value | C8: $108.5B | D8: FY End | E8: November
B9: Shares Outstanding | C9: 410.5M | D9: Employees | E9: ~30,000+
B10: 52-Week Range | C10: $251 — $465 | D10: HQ | E10: San Jose, CA
B11: Beta (5yr) | C11: 1.52 | D11: Founded | E11: 1982
B12: P/E (TTM) | C12: 15.4x | D12: EV/EBITDA | E12: 11.4x
B13: FCF Yield | C13: ~9.1% | D13: Analyst PT | E13: $414 (avg of 23)
B16: FY2026 Management Guidance (Dec 10, 2025)
B17: Total Revenue | C17: $25.5B — $25.7B
B18: Q1 FY2026 Revenue | C18: $6.25B — $6.30B
B19: Non-GAAP EPS (FY2026) | C19: ~$23.30 — $23.50
B20: Q1 FY2026 Non-GAAP EPS | C20: $5.85 — $5.90
B21: Non-GAAP Op Margin | C21: ~45.0%
B22: Non-GAAP Tax Rate | C22: ~18.0%
B23: Diluted Share Count | C23: ~411M (Q1), decreasing
B24: Total Adobe ARR Growth Target | C24: ~10.2% YoY (double-digit)
B27: Business Segments (FY2025)
C28: Segment | D28: Revenue | E28: % of Total | F28: YoY Growth
B29: Digital Media | C29: $17.65B | D29: 74% | E29: 11%
B30: Creative Cloud | C30: ~$13.5B | D30: 57% | E30: ~10%
B31: Document Cloud | C31: ~$4.1B | D31: 17% | E31: ~15%
B32: Digital Experience | C32: $5.87B | D32: 25% | E32: 10%
B33: Publishing & Other | C33: <$0.3B | D33: <1% | E33: Declining
B36: Investment Thesis
B37: BULL CASE
B38: • AI (Firefly, GenStudio) deepens moat, drives ARPU, expands TAM to non-designers
B39: • $25.7B ARR with 90%+ gross margins = exceptional, durable cash generation
B40: • Valuation at ~11x fwd P/E is historically cheap vs. 25-35x 5yr avg range
B41: • Aggressive buyback ($10.9B remaining) + potential Semrush acquisition
B42: • Document Cloud a sleeper growth driver at 15%+ growth, large enterprise penetration ahead
B44: BEAR CASE
B45: • Revenue growth decelerating to single digits for first time in decades
B46: • AI-native competition accelerating: Canva (180M+ users), OpenAI, Midjourney, Figma
B47: • Op margin guided DOWN to 45% (from 46%) — AI investment consuming profits
B48: • Wave of analyst downgrades: Goldman → Sell ($290), Piper → Neutral, Oppenheimer → Perform
B49: • AI commoditization risk: if generative tools become cheap/free, Creative Cloud pricing power erodes

Sheet DCF Model
B2: Adobe Inc. (ADBE) — Discounted Cash Flow Model
B3: All figures in $mm unless stated. Blue = input, Black = formula, Green = cross-sheet link.
B4: Source: Adobe FY2025 10-K, Earnings Release (Dec 10, 2025), SEC Filings
D6: FY2022A | E6: FY2023A | F6: FY2024A | G6: FY2025A | H6: FY2026E | I6: FY2027E | J6: FY2028E | K6: FY2029E | L6: FY2030E
B7: Segment Revenue Build
B8: Digital Media Revenue | C8: 12842 | D8: 14182 | E8: 15860 | F8: 17651 | G8: =F8*(1+G9) -> 19416.1 | H8: =G8*(1+H9) -> 21260.629 | I8: =H8*(1+I9) -> 23174.086 | J8: =I8*(1+J9) -> 25143.883 | K8: =J8*(1+K9) -> 27155.394
B9: DM Growth (%) | D9: =(D8-C8)/C8 -> 0.10434512 | E9: =(E8-D8)/D8 -> 0.118319 | F9: =(F8-E8)/E8 -> 0.1129256 | G9: 0.1 | H9: 0.095 | I9: 0.09 | J9: 0.085 | K9: 0.08
B10: Digital Experience Revenue | C10: 4422 | D10: 4893 | E10: 5374 | F10: 5870 | G10: =F10*(1+G11) -> 6398.3 | H10: =G10*(1+H11) -> 6942.1555 | I10: =H10*(1+I11) -> 7497.5279 | J10: =I10*(1+J11) -> 8059.8425 | K10: =J10*(1+K11) -> 8624.0315
B11: DX Growth (%) | D11: =(D10-C10)/C10 -> 0.10651289 | E11: =(E10-D10)/D10 -> 0.098303699 | F11: =(F10-E10)/E10 -> 0.092296241 | G11: 0.09 | H11: 0.085 | I11: 0.08 | J11: 0.075 | K11: 0.07
B12: Publishing & Other | C12: 342 | D12: 334 | E12: 271 | F12: 248 | G12: =F12*0.92 -> 228.16 | H12: =G12*0.92 -> 209.9072 | I12: =H12*0.92 -> 193.11462 | J12: =I12*0.92 -> 177.66545 | K12: =J12*0.92 -> 163.45222 | L12: ← declining legacy
B14: Total Revenue | C14: =C8+C10+C12 -> 17606 | D14: =D8+D10+D12 -> 19409 | E14: =E8+E10+E12 -> 21505 | F14: =F8+F10+F12 -> 23769 | G14: =G8+G10+G12 -> 26042.56 | H14: =H8+H10+H12 -> 28412.692 | I14: =I8+I10+I12 -> 30864.729 | J14: =J8+J10+J12 -> 33381.391 | K14: =K8+K10+K12 -> 35942.878
B15: Total Revenue Growth (%) | D15: =(D14-C14)/C14 -> 0.10240827 | E15: =(E14-D14)/D14 -> 0.10799114 | F15: =(F14-E14)/E14 -> 0.10527784 | G15: =(G14-F14)/F14 -> 0.09565232 | H15: =(H14-G14)/G14 -> 0.091009954 | I15: =(I14-H14)/H14 -> 0.086300746 | J15: =(J14-I14)/I14 -> 0.08153847 | K15: =(K14-J14)/J14 -> 0.076733962
B17: Annual Recurring Revenue (ARR)
B18: Digital Media ARR | C18: 13011 | D18: 14597 | E18: 16172 | F18: 19200 | G18: =F18*1.1 -> 21120 | H18: =G18*1.1 -> 23232 | I18: =H18*1.1 -> 25555.2 | J18: =I18*1.1 -> 28110.72 | K18: =J18*1.1 -> 30921.792 | L18: Source: Adobe earnings releases
B19: Total Adobe ARR | E19: 22310 | F19: 25200 | G19: =F19*1.1 -> 27720 | H19: =G19*1.1 -> 30492 | I19: =H19*1.1 -> 33541.2 | J19: =I19*1.1 -> 36895.32 | K19: =J19*1.1 -> 40584.852 | L19: FY26 guided: ~10.2% ARR growth
B20: ARR Growth (%) | G20: =(G19-F19)/F19 -> 0.1 | H20: =(H19-G19)/G19 -> 0.1 | I20: =(I19-H19)/H19 -> 0.1 | J20: =(J19-I19)/I19 -> 0.1 | K20: =(K19-J19)/J19 -> 0.1
B22: Operating Model
B23: Gross Margin (%) | C23: 0.877 | D23: 0.8787 | E23: 0.8903 | F23: 0.8927 | G23: 0.89 | H23: 0.89 | I23: 0.892 | J23: 0.893 | K23: 0.894
B24: Gross Profit | C24: =C14*C23 -> 15440.462 | D24: =D14*D23 -> 17054.688 | E24: =E14*E23 -> 19145.901 | F24: =F14*F23 -> 21218.586 | G24: =G14*G23 -> 23177.878 | H24: =H14*H23 -> 25287.296 | I24: =I14*I23 -> 27531.338 | J24: =J14*J23 -> 29809.583 | K24: =K14*K23 -> 32132.933
B25: SG&A (% of Revenue) | C25: 0.3514 | D25: 0.3485 | E25: 0.3355 | F25: 0.327 | G25: 0.32 | H25: 0.315 | I25: 0.31 | J25: 0.305 | K25: 0.3
B26: SG&A | C26: =C14*C25 -> 6186.7484 | D26: =D14*D25 -> 6764.0365 | E26: =E14*E25 -> 7214.9275 | F26: =F14*F25 -> 7772.463 | G26: =G14*G25 -> 8333.6192 | H26: =H14*H25 -> 8949.998 | I26: =I14*I25 -> 9568.0659 | J26: =J14*J25 -> 10181.324 | K26: =K14*K25 -> 10782.863
B27: R&D (% of Revenue) | C27: 0.1697 | D27: 0.1789 | E27: 0.1834 | F27: 0.178 | G27: 0.178 | H27: 0.176 | I27: 0.174 | J27: 0.172 | K27: 0.17
B28: R&D | C28: =C14*C27 -> 2987.7382 | D28: =D14*D27 -> 3472.2701 | E28: =E14*E27 -> 3944.017 | F28: =F14*F27 -> 4230.882 | G28: =G14*G27 -> 4635.5757 | H28: =H14*H27 -> 5000.6338 | I28: =I14*I27 -> 5370.4628 | J28: =J14*J27 -> 5741.5993 | K28: =K14*K27 -> 6110.2892
B29: D&A | C29: 618 | D29: 618 | E29: 585 | F29: 580 | G29: =F29*1.02 -> 591.6 | H29: =G29*1.02 -> 603.432 | I29: =H29*1.02 -> 615.50064 | J29: =I29*1.02 -> 627.81065 | K29: =J29*1.02 -> 640.36687
B31: EBIT | C31: =C24-C26-C28-C29 -> 5647.9754 | D31: =D24-D26-D28-D29 -> 6200.3817 | E31: =E24-E26-E28-E29 -> 7401.957 | F31: =F24-F26-F28-F29 -> 8635.2413 | G31: =G24-G26-G28-G29 -> 9617.0835 | H31: =H24-H26-H28-H29 -> 10733.232 | I31: =I24-I26-I28-I29 -> 11977.309 | J31: =J24-J26-J28-J29 -> 13258.848 | K31: =K24-K26-K28-K29 -> 14599.413
B32: EBIT Margin (%) | C32: =C31/C14 -> 0.32079833 | D32: =D31/D14 -> 0.3194591 | E32: =E31/E14 -> 0.34419702 | F32: =F31/F14 -> 0.36329847 | G32: =G31/G14 -> 0.36928334 | H32: =H31/H14 -> 0.37776189 | I32: =I31/I14 -> 0.38805812 | J32: =J31/J14 -> 0.3971928 | K32: =K31/K14 -> 0.40618376
B33: EBITDA | C33: =C31+C29 -> 6265.9754 | D33: =D31+D29 -> 6818.3817 | E33: =E31+E29 -> 7986.957 | F33: =F31+F29 -> 9215.2413 | G33: =G31+G29 -> 10208.684 | H33: =H31+H29 -> 11336.664 | I33: =I31+I29 -> 12592.809 | J33: =J31+J29 -> 13886.659 | K33: =K31+K29 -> 15239.78
B34: EBITDA Margin (%) | C34: =C33/C14 -> 0.3559 | D34: =D33/D14 -> 0.3513 | E34: =E33/E14 -> 0.3714 | F34: =F33/F14 -> 0.3877 | G34: =G33/G14 -> 0.392 | H34: =H33/H14 -> 0.399 | I34: =I33/I14 -> 0.408 | J34: =J33/J14 -> 0.416 | K34: =K33/K14 -> 0.424
B36: Earnings Per Share
B37: Tax Rate (%) | C37: 0.2084 | D37: 0.2016 | E37: 0.1978 | F37: 0.1837 | G37: 0.185 | H37: 0.185 | I37: 0.185 | J37: 0.185 | K37: 0.185
B38: Net Income | C38: =C31*(1-C37) -> 4470.9373 | D38: =D31*(1-D37) -> 4950.3847 | E38: =E31*(1-E37) -> 5937.8499 | F38: =F31*(1-F37) -> 7048.9475 | G38: =G31*(1-G37) -> 7837.9231 | H38: =H31*(1-H37) -> 8747.5842 | I38: =I31*(1-I37) -> 9761.5066 | J38: =J31*(1-J37) -> 10805.961 | K38: =K31*(1-K37) -> 11898.522
B39: Diluted Shares (mm) | C39: 471 | D39: 459 | E39: 450 | F39: 434 | G39: 411 | H39: 398 | I39: 386 | J39: 375 | K39: 365 | L39: ← ~3% annual buyback
B40: EPS ($) | C40: =C38/C39 -> 9.4924359 | D40: =D38/D39 -> 10.785152 | E40: =E38/E39 -> 13.195222 | F40: =F38/F39 -> 16.241814 | G40: =G38/G39 -> 19.070372 | H40: =H38/H39 -> 21.978855 | I40: =I38/I39 -> 25.288877 | J40: =J38/J39 -> 28.815897 | K40: =K38/K39 -> 32.59869
B42: Unlevered Free Cash Flow
B43: EBIT | C43: =C31 -> 5647.9754 | D43: =D31 -> 6200.3817 | E43: =E31 -> 7401.957 | F43: =F31 -> 8635.2413 | G43: =G31 -> 9617.0835 | H43: =H31 -> 10733.232 | I43: =I31 -> 11977.309 | J43: =J31 -> 13258.848 | K43: =K31 -> 14599.413
B44: Less: Taxes on EBIT | C44: =C43*C37 -> 1177.0381 | D44: =D43*D37 -> 1249.997 | E44: =E43*E37 -> 1464.1071 | F44: =F43*F37 -> 1586.2938 | G44: =G43*G37 -> 1779.1605 | H44: =H43*H37 -> 1985.648 | I44: =I43*I37 -> 2215.8021 | J44: =J43*J37 -> 2452.8869 | K44: =K43*K37 -> 2700.8915
B45: NOPAT | C45: =C43-C44 -> 4470.9373 | D45: =D43-D44 -> 4950.3847 | E45: =E43-E44 -> 5937.8499 | F45: =F43-F44 -> 7048.9475 | G45: =G43-G44 -> 7837.9231 | H45: =H43-H44 -> 8747.5842 | I45: =I43-I44 -> 9761.5066 | J45: =J43-J44 -> 10805.961 | K45: =K43-K44 -> 11898.522
B46: Plus: D&A | C46: =C29 -> 618 | D46: =D29 -> 618 | E46: =E29 -> 585 | F46: =F29 -> 580 | G46: =G29 -> 591.6 | H46: =H29 -> 603.432 | I46: =I29 -> 615.50064 | J46: =J29 -> 627.81065 | K46: =K29 -> 640.36687
B47: CapEx (% of Rev) | C47: 0.008 | D47: 0.0075 | E47: 0.008 | F47: 0.0075 | G47: 0.008 | H47: 0.008 | I47: 0.008 | J47: 0.008 | K47: 0.008
B48: Less: CapEx | C48: =C14*C47 -> 140.848 | D48: =D14*D47 -> 145.5675 | E48: =E14*E47 -> 172.04 | F48: =F14*F47 -> 178.2675 | G48: =G14*G47 -> 208.34048 | H48: =H14*H47 -> 227.30154 | I48: =I14*I47 -> 246.91783 | J48: =J14*J47 -> 267.05113 | K48: =K14*K47 -> 287.54302
...

Sheet Scenario Analysis
B2: Adobe (ADBE) — Bull / Base / Bear Scenario DCF
B3: Probability-weighted intrinsic value with entry price calculator
D5: Bull Case | E5: Base Case | F5: Bear Case
B6: Probability Weight | C6: 0.25 | D6: 0.5 | E6: 0.25
B7: Rev Growth Yr1 (%) | C7: 0.115 | D7: 0.095 | E7: 0.075
B8: Rev Growth Yr2 (%) | C8: 0.11 | D8: 0.09 | E8: 0.065
B9: Rev Growth Yr3 (%) | C9: 0.105 | D9: 0.085 | E9: 0.055
B10: Rev Growth Yr4 (%) | C10: 0.1 | D10: 0.08 | E10: 0.05
B11: Rev Growth Yr5 (%) | C11: 0.095 | D11: 0.075 | E11: 0.045
B12: Avg UFCF Margin (%) | C12: 0.34 | D12: 0.31 | E12: 0.28
B13: Terminal Growth (%) | C13: 0.035 | D13: 0.03 | E13: 0.025
B14: WACC (%) | C14: ='DCF Model'!C68 -> 0.10200904 | D14: ='DCF Model'!C68 -> 0.10200904 | E14: ='DCF Model'!C68 -> 0.10200904
B16: Base Year Revenue ($mm) | C16: ='DCF Model'!F14 -> 23769 | D16: ='DCF Model'!F14 -> 23769 | E16: ='DCF Model'!F14 -> 23769
B18: Projected Revenue & UFCF by Scenario
B19: Bull Case
B20: Year 1 Revenue | C20: =C16*(1+C7) -> 26502.435
B21: Year 2 Revenue | C21: =C20*(1+C8) -> 29417.703
B22: Year 3 Revenue | C22: =C21*(1+C9) -> 32506.562
B23: Year 4 Revenue | C23: =C22*(1+C10) -> 35757.218
B24: Year 5 Revenue | C24: =C23*(1+C11) -> 39154.154
B25: Year 5 UFCF | C25: =C24*C12 -> 13312.412
B26: Terminal Value | C26: =C25*(1+C13)/(C14-C13) -> 205619.22
B27: PV of Year 1-5 UFCFs | C27: =C20*C12/(1+C14)^1+C21*C12/(1+C14)^2+C22*C12/(1+C14)^3+C23*C12/(1+C14)^4+C24*C12/(1+C14)^5 -> 41105.325
B28: PV of Terminal Value | C28: =C26/(1+C14)^5 -> 126513.8
B29: Enterprise Value | C29: =C27+C28 -> 167619.13
B30: Equity Value | C30: =C29-'DCF Model'!C86+'DCF Model'!C87 -> 167559.13
B31: Implied Price ($) | C31: =C30/'DCF Model'!C90 -> 408.18302
B33: Base Case
B34: Year 1 Revenue | D34: =D16*(1+D7) -> 26027.055
B35: Year 2 Revenue | D35: =D34*(1+D8) -> 28369.49
B36: Year 3 Revenue | D36: =D35*(1+D9) -> 30780.897
B37: Year 4 Revenue | D37: =D36*(1+D10) -> 33243.368
B38: Year 5 Revenue | D38: =D37*(1+D11) -> 35736.621
B39: Year 5 UFCF | D39: =D38*D12 -> 11078.352
B40: Terminal Value | D40: =D39*(1+D13)/(D14-D13) -> 158462.09
B41: PV of Year 1-5 UFCFs | D41: =D34*D12/(1+D14)^1+D35*D12/(1+D14)^2+D36*D12/(1+D14)^3+D37*D12/(1+D14)^4+D38*D12/(1+D14)^5 -> 35497.111
B42: PV of Terminal Value | D42: =D40/(1+D14)^5 -> 97498.871
B43: Enterprise Value | D43: =D41+D42 -> 132995.98
B44: Equity Value | D44: =D43-'DCF Model'!C86+'DCF Model'!C87 -> 132935.98
B45: Implied Price ($) | D45: =D44/'DCF Model'!C90 -> 323.83918
...

Sheet Sensitivity Analysis
B2: Sensitivity Analysis: Implied Share Price ($)
B4: Base Case: WACC vs. Terminal Growth Rate
B5: WACC ↓ / TGR → | C5: 0.02 | D5: 0.025 | E5: 0.03 | F5: 0.035 | G5: 0.04
B6: 0.085 | C6: =('DCF Model'!G52/(1+$B$6)^1+'DCF Model'!H52/(1+$B$6)^2+'DCF Model'!I52/(1+$B$6)^3+'DCF Model'!J52/(1+$B$6)^4+'DCF Model'!K52/(1+$B$6)^5+('DCF Model'!K52*(1+C$5)/($B$6-C$5))/(1+$B$6)^5-6660+6600)/410.5 -> 405.68624 | D6: =('DCF Model'!G52/(1+$B$6)^1+'DCF Model'!H52/(1+$B$6)^2+'DCF Model'!I52/(1+$B$6)^3+'DCF Model'!J52/(1+$B$6)^4+'DCF Model'!K52/(1+$B$6)^5+('DCF Model'!K52*(1+D$5)/($B$6-D$5))/(1+$B$6)^5-6660+6600)/410.5 -> 433.1802 | E6: =('DCF Model'!G52/(1+$B$6)^1+'DCF Model'!H52/(1+$B$6)^2+'DCF Model'!I52/(1+$B$6)^3+'DCF Model'!J52/(1+$B$6)^4+'DCF Model'!K52/(1+$B$6)^5+('DCF Model'!K52*(1+E$5)/($B$6-E$5))/(1+$B$6)^5-6660+6600)/410.5 -> 465.67306 | F6: =('DCF Model'!G52/(1+$B$6)^1+'DCF Model'!H52/(1+$B$6)^2+'DCF Model'!I52/(1+$B$6)^3+'DCF Model'!J52/(1+$B$6)^4+'DCF Model'!K52/(1+$B$6)^5+('DCF Model'!K52*(1+F$5)/($B$6-F$5))/(1+$B$6)^5-6660+6600)/410.5 -> 504.66449 | G6: =('DCF Model'!G52/(1+$B$6)^1+'DCF Model'!H52/(1+$B$6)^2+'DCF Model'!I52/(1+$B$6)^3+'DCF Model'!J52/(1+$B$6)^4+'DCF Model'!K52/(1+$B$6)^5+('DCF Model'!K52*(1+G$5)/($B$6-G$5))/(1+$B$6)^5-6660+6600)/410.5 -> 552.32068
B7: 0.095 | C7: =('DCF Model'!G52/(1+$B$7)^1+'DCF Model'!H52/(1+$B$7)^2+'DCF Model'!I52/(1+$B$7)^3+'DCF Model'!J52/(1+$B$7)^4+'DCF Model'!K52/(1+$B$7)^5+('DCF Model'!K52*(1+C$5)/($B$7-C$5))/(1+$B$7)^5-6660+6600)/410.5 -> 349.65778 | D7: =('DCF Model'!G52/(1+$B$7)^1+'DCF Model'!H52/(1+$B$7)^2+'DCF Model'!I52/(1+$B$7)^3+'DCF Model'!J52/(1+$B$7)^4+'DCF Model'!K52/(1+$B$7)^5+('DCF Model'!K52*(1+D$5)/($B$7-D$5))/(1+$B$7)^5-6660+6600)/410.5 -> 369.34593 | E7: =('DCF Model'!G52/(1+$B$7)^1+'DCF Model'!H52/(1+$B$7)^2+'DCF Model'!I52/(1+$B$7)^3+'DCF Model'!J52/(1+$B$7)^4+'DCF Model'!K52/(1+$B$7)^5+('DCF Model'!K52*(1+E$5)/($B$7-E$5))/(1+$B$7)^5-6660+6600)/410.5 -> 392.06303 | F7: =('DCF Model'!G52/(1+$B$7)^1+'DCF Model'!H52/(1+$B$7)^2+'DCF Model'!I52/(1+$B$7)^3+'DCF Model'!J52/(1+$B$7)^4+'DCF Model'!K52/(1+$B$7)^5+('DCF Model'!K52*(1+F$5)/($B$7-F$5))/(1+$B$7)^5-6660+6600)/410.5 -> 418.56632 | G7: =('DCF Model'!G52/(1+$B$7)^1+'DCF Model'!H52/(1+$B$7)^2+'DCF Model'!I52/(1+$B$7)^3+'DCF Model'!J52/(1+$B$7)^4+'DCF Model'!K52/(1+$B$7)^5+('DCF Model'!K52*(1+G$5)/($B$7-G$5))/(1+$B$7)^5-6660+6600)/410.5 -> 449.88838
B8: 0.105 | C8: =('DCF Model'!G52/(1+$B$8)^1+'DCF Model'!H52/(1+$B$8)^2+'DCF Model'!I52/(1+$B$8)^3+'DCF Model'!J52/(1+$B$8)^4+'DCF Model'!K52/(1+$B$8)^5+('DCF Model'!K52*(1+C$5)/($B$8-C$5))/(1+$B$8)^5-6660+6600)/410.5 -> 306.87241 | D8: =('DCF Model'!G52/(1+$B$8)^1+'DCF Model'!H52/(1+$B$8)^2+'DCF Model'!I52/(1+$B$8)^3+'DCF Model'!J52/(1+$B$8)^4+'DCF Model'!K52/(1+$B$8)^5+('DCF Model'!K52*(1+D$5)/($B$8-D$5))/(1+$B$8)^5-6660+6600)/410.5 -> 321.53001 | E8: =('DCF Model'!G52/(1+$B$8)^1+'DCF Model'!H52/(1+$B$8)^2+'DCF Model'!I52/(1+$B$8)^3+'DCF Model'!J52/(1+$B$8)^4+'DCF Model'!K52/(1+$B$8)^5+('DCF Model'!K52*(1+E$5)/($B$8-E$5))/(1+$B$8)^5-6660+6600)/410.5 -> 338.14195 | F8: =('DCF Model'!G52/(1+$B$8)^1+'DCF Model'!H52/(1+$B$8)^2+'DCF Model'!I52/(1+$B$8)^3+'DCF Model'!J52/(1+$B$8)^4+'DCF Model'!K52/(1+$B$8)^5+('DCF Model'!K52*(1+F$5)/($B$8-F$5))/(1+$B$8)^5-6660+6600)/410.5 -> 357.12703 | G8: =('DCF Model'!G52/(1+$B$8)^1+'DCF Model'!H52/(1+$B$8)^2+'DCF Model'!I52/(1+$B$8)^3+'DCF Model'!J52/(1+$B$8)^4+'DCF Model'!K52/(1+$B$8)^5+('DCF Model'!K52*(1+G$5)/($B$8-G$5))/(1+$B$8)^5-6660+6600)/410.5 -> 379.03289
B9: 0.115 | C9: =('DCF Model'!G52/(1+$B$9)^1+'DCF Model'!H52/(1+$B$9)^2+'DCF Model'!I52/(1+$B$9)^3+'DCF Model'!J52/(1+$B$9)^4+'DCF Model'!K52/(1+$B$9)^5+('DCF Model'!K52*(1+C$5)/($B$9-C$5))/(1+$B$9)^5-6660+6600)/410.5 -> 273.14564 | D9: =('DCF Model'!G52/(1+$B$9)^1+'DCF Model'!H52/(1+$B$9)^2+'DCF Model'!I52/(1+$B$9)^3+'DCF Model'!J52/(1+$B$9)^4+'DCF Model'!K52/(1+$B$9)^5+('DCF Model'!K52*(1+D$5)/($B$9-D$5))/(1+$B$9)^5-6660+6600)/410.5 -> 284.39053 | E9: =('DCF Model'!G52/(1+$B$9)^1+'DCF Model'!H52/(1+$B$9)^2+'DCF Model'!I52/(1+$B$9)^3+'DCF Model'!J52/(1+$B$9)^4+'DCF Model'!K52/(1+$B$9)^5+('DCF Model'!K52*(1+E$5)/($B$9-E$5))/(1+$B$9)^5-6660+6600)/410.5 -> 296.95835 | F9: =('DCF Model'!G52/(1+$B$9)^1+'DCF Model'!H52/(1+$B$9)^2+'DCF Model'!I52/(1+$B$9)^3+'DCF Model'!J52/(1+$B$9)^4+'DCF Model'!K52/(1+$B$9)^5+('DCF Model'!K52*(1+F$5)/($B$9-F$5))/(1+$B$9)^5-6660+6600)/410.5 -> 311.09715 | G9: =('DCF Model'!G52/(1+$B$9)^1+'DCF Model'!H52/(1+$B$9)^2+'DCF Model'!I52/(1+$B$9)^3+'DCF Model'!J52/(1+$B$9)^4+'DCF Model'!K52/(1+$B$9)^5+('DCF Model'!K52*(1+G$5)/($B$9-G$5))/(1+$B$9)^5-6660+6600)/410.5 -> 327.12111
B10: 0.125 | C10: =('DCF Model'!G52/(1+$B$10)^1+'DCF Model'!H52/(1+$B$10)^2+'DCF Model'!I52/(1+$B$10)^3+'DCF Model'!J52/(1+$B$10)^4+'DCF Model'!K52/(1+$B$10)^5+('DCF Model'!K52*(1+C$5)/($B$10-C$5))/(1+$B$10)^5-6660+6600)/410.5 -> 245.88718 | D10: =('DCF Model'!G52/(1+$B$10)^1+'DCF Model'!H52/(1+$B$10)^2+'DCF Model'!I52/(1+$B$10)^3+'DCF Model'!J52/(1+$B$10)^4+'DCF Model'!K52/(1+$B$10)^5+('DCF Model'!K52*(1+D$5)/($B$10-D$5))/(1+$B$10)^5-6660+6600)/410.5 -> 254.72248 | E10: =('DCF Model'!G52/(1+$B$10)^1+'DCF Model'!H52/(1+$B$10)^2+'DCF Model'!I52/(1+$B$10)^3+'DCF Model'!J52/(1+$B$10)^4+'DCF Model'!K52/(1+$B$10)^5+('DCF Model'!K52*(1+E$5)/($B$10-E$5))/(1+$B$10)^5-6660+6600)/410.5 -> 264.48781 | F10: =('DCF Model'!G52/(1+$B$10)^1+'DCF Model'!H52/(1+$B$10)^2+'DCF Model'!I52/(1+$B$10)^3+'DCF Model'!J52/(1+$B$10)^4+'DCF Model'!K52/(1+$B$10)^5+('DCF Model'!K52*(1+F$5)/($B$10-F$5))/(1+$B$10)^5-6660+6600)/410.5 -> 275.33819 | G10: =('DCF Model'!G52/(1+$B$10)^1+'DCF Model'!H52/(1+$B$10)^2+'DCF Model'!I52/(1+$B$10)^3+'DCF Model'!J52/(1+$B$10)^4+'DCF Model'!K52/(1+$B$10)^5+('DCF Model'!K52*(1+G$5)/($B$10-G$5))/(1+$B$10)^5-6660+6600)/410.5 -> 287.46507
B11: 0.135 | C11: =('DCF Model'!G52/(1+$B$11)^1+'DCF Model'!H52/(1+$B$11)^2+'DCF Model'!I52/(1+$B$11)^3+'DCF Model'!J52/(1+$B$11)^4+'DCF Model'!K52/(1+$B$11)^5+('DCF Model'!K52*(1+C$5)/($B$11-C$5))/(1+$B$11)^5-6660+6600)/410.5 -> 223.40781 | D11: =('DCF Model'!G52/(1+$B$11)^1+'DCF Model'!H52/(1+$B$11)^2+'DCF Model'!I52/(1+$B$11)^3+'DCF Model'!J52/(1+$B$11)^4+'DCF Model'!K52/(1+$B$11)^5+('DCF Model'!K52*(1+D$5)/($B$11-D$5))/(1+$B$11)^5-6660+6600)/410.5 -> 230.4864 | E11: =('DCF Model'!G52/(1+$B$11)^1+'DCF Model'!H52/(1+$B$11)^2+'DCF Model'!I52/(1+$B$11)^3+'DCF Model'!J52/(1+$B$11)^4+'DCF Model'!K52/(1+$B$11)^5+('DCF Model'!K52*(1+E$5)/($B$11-E$5))/(1+$B$11)^5-6660+6600)/410.5 -> 238.23915 | F11: =('DCF Model'!G52/(1+$B$11)^1+'DCF Model'!H52/(1+$B$11)^2+'DCF Model'!I52/(1+$B$11)^3+'DCF Model'!J52/(1+$B$11)^4+'DCF Model'!K52/(1+$B$11)^5+('DCF Model'!K52*(1+F$5)/($B$11-F$5))/(1+$B$11)^5-6660+6600)/410.5 -> 246.76716 | G11: =('DCF Model'!G52/(1+$B$11)^1+'DCF Model'!H52/(1+$B$11)^2+'DCF Model'!I52/(1+$B$11)^3+'DCF Model'!J52/(1+$B$11)^4+'DCF Model'!K52/(1+$B$11)^5+('DCF Model'!K52*(1+G$5)/($B$11-G$5))/(1+$B$11)^5-6660+6600)/410.5 -> 256.19287
