Workbook

Sheet DCF Model
A1: AFT Pharmaceuticals (AFT.NZ)
A2: DCF Valuation Model — NZD millions unless stated | Fiscal year ends 31 March
A3: Gray cells are INPUTS — adjust to see valuation update automatically
B5: Input / Base | C5: Year 1 | D5: Year 2 | E5: Year 3 | F5: Year 4 | G5: Year 5
A7: KEY INPUTS
A8: Current Stock Price (NZ$) | B8: 3.4
A9: Shares Outstanding (millions) | B9: 104.866
A10: Cash & Equivalents (NZ$m) | B10: 12.1
A11: Total Debt (NZ$m) | B11: 33
A12: Net Debt (NZ$m) | B12: =B11-B10 -> 0
A13: Base Year Revenue (NZ$m, FY2025) | B13: 208
A14: Base FCF (NZ$m, FY2026e normalised) | B14: 14
A16: WACC | B16: 0.12
A17: Terminal Growth Rate | B17: 0.03
A19: GROWTH & MARGIN ASSUMPTIONS (Base Case — adjust below)
A20: Revenue Growth Rate | C20: 0.2 | D20: 0.18 | E20: 0.15 | F20: 0.12 | G20: 0.1
A21: FCF Margin (% of Revenue) | C21: 0.07 | D21: 0.08 | E21: 0.095 | F21: 0.11 | G21: 0.12
A23: BASE CASE PROJECTIONS
A24: Revenue (NZ$m) | B24: FY2025: 208.0 | C24: =$B$13*(1+C20) -> 0 | D24: =C24*(1+D20) -> 0 | E24: =D24*(1+E20) -> 0 | F24: =E24*(1+F20) -> 0 | G24: =F24*(1+G20) -> 0
A25: Free Cash Flow (NZ$m) | B25: Base FCF: =B14 | C25: =C24*C21 -> 0 | D25: =D24*D21 -> 0 | E25: =E24*E21 -> 0 | F25: =F24*F21 -> 0 | G25: =G24*G21 -> 0
A26: Discount Factor (WACC) | C26: =1/(1+$B$16)^1 -> 0 | D26: =1/(1+$B$16)^2 -> 0 | E26: =1/(1+$B$16)^3 -> 0 | F26: =1/(1+$B$16)^4 -> 0 | G26: =1/(1+$B$16)^5 -> 0
A27: PV of FCF (NZ$m) | C27: =C25*C26 -> 0 | D27: =D25*D26 -> 0 | E27: =E25*E26 -> 0 | F27: =F25*F26 -> 0 | G27: =G25*G26 -> 0
A29: VALUATION BRIDGE
A30: Sum of PV of FCF (NZ$m) | B30: =SUM(C27:G27) -> 0
A31: Terminal FCF (Year 5 FCF x (1+g)) | B31: =G25*(1+$B$17) -> 0
A32: Terminal Value (NZ$m) | B32: =B31/($B$16-$B$17) -> 0
A33: PV of Terminal Value (NZ$m) | B33: =B32*G26 -> 0
A34: Enterprise Value (NZ$m) | B34: =B30+B33 -> 0
A35: Less: Net Debt (NZ$m) | B35: =B12 -> 0
A36: Equity Value (NZ$m) | B36: =B34-B35 -> 0
A38: INTRINSIC VALUE PER SHARE (NZ$) | B38: =B36/B9 -> 0
A39: Current Price (NZ$) | B39: =B8 -> 0
A40: Upside / (Downside) to Intrinsic Value | B40: =(B38-B8)/B8 -> 0
A42: ENTRY PRICE — Target 15% CAGR to Terminal Value
A43: Terminal Value Per Share (NZ$) | B43: =B32/B9 -> 0
A44: Years to Terminal Value | B44: 5
A45: Entry Price for 15% CAGR (NZ$) | B45: =B43/(1.15^B44) -> 0
A46: Current Price vs Entry Price | B46: =(B8-B45)/B45 -> 0
A48: SCENARIO COMPARISON (Base / Bull / Bear)
A49: Scenario | B49: Bear Case | C49: Base Case | D49: Bull Case | E49: Probability | F49: Weighted
...

Sheet Sensitivity
A1: AFT.NZ — Sensitivity Analysis
A2: Intrinsic Value Per Share (NZ$) by WACC and Terminal Growth Rate
A3: Base Case FCF projections used. Current price: NZ$3.40 highlighted.
A5: WACC \ Term Growth | B5: 0.02 | C5: 0.025 | D5: 0.03 | E5: 0.035 | F5: 0.04
A6: 0.1 | B6: 4.72 | C6: 4.99 | D6: 5.3 | E6: 5.66 | F6: 6.08
A7: 0.11 | B7: 4.11 | C7: 4.32 | D7: 4.55 | E7: 4.81 | F7: 5.11
A8: 0.12 | B8: 3.63 | C8: 3.79 | D8: 3.97 | E8: 4.17 | F8: 4.39
A9: 0.13 | B9: 3.24 | C9: 3.37 | D9: 3.51 | E9: 3.66 | F9: 3.83
A10: 0.14 | B10: 2.92 | C10: 3.02 | D10: 3.13 | E10: 3.25 | F10: 3.39
A12: FORMULA-LINKED TABLE (updates with DCF Model inputs)
A13: WACC \ Term Growth | B13: 0.02 | C13: 0.025 | D13: 0.03 | E13: 0.035 | F13: 0.04
A14: 0.1 | B14: =(('DCF Model'!G25*(1+0.02)/(0.1-0.02))/(1+0.1)^5+'DCF Model'!B30-'DCF Model'!B35)/'DCF Model'!B9 -> 0 | C14: =(('DCF Model'!G25*(1+0.025)/(0.1-0.025))/(1+0.1)^5+'DCF Model'!B30-'DCF Model'!B35)/'DCF Model'!B9 -> 0 | D14: =(('DCF Model'!G25*(1+0.03)/(0.1-0.03))/(1+0.1)^5+'DCF Model'!B30-'DCF Model'!B35)/'DCF Model'!B9 -> 0 | E14: =(('DCF Model'!G25*(1+0.035)/(0.1-0.035))/(1+0.1)^5+'DCF Model'!B30-'DCF Model'!B35)/'DCF Model'!B9 -> 0 | F14: =(('DCF Model'!G25*(1+0.04)/(0.1-0.04))/(1+0.1)^5+'DCF Model'!B30-'DCF Model'!B35)/'DCF Model'!B9 -> 0
A15: 0.11 | B15: =(('DCF Model'!G25*(1+0.02)/(0.11-0.02))/(1+0.11)^5+'DCF Model'!B30-'DCF Model'!B35)/'DCF Model'!B9 -> 0 | C15: =(('DCF Model'!G25*(1+0.025)/(0.11-0.025))/(1+0.11)^5+'DCF Model'!B30-'DCF Model'!B35)/'DCF Model'!B9 -> 0 | D15: =(('DCF Model'!G25*(1+0.03)/(0.11-0.03))/(1+0.11)^5+'DCF Model'!B30-'DCF Model'!B35)/'DCF Model'!B9 -> 0 | E15: =(('DCF Model'!G25*(1+0.035)/(0.11-0.035))/(1+0.11)^5+'DCF Model'!B30-'DCF Model'!B35)/'DCF Model'!B9 -> 0 | F15: =(('DCF Model'!G25*(1+0.04)/(0.11-0.04))/(1+0.11)^5+'DCF Model'!B30-'DCF Model'!B35)/'DCF Model'!B9 -> 0
A16: 0.12 | B16: =(('DCF Model'!G25*(1+0.02)/(0.12-0.02))/(1+0.12)^5+'DCF Model'!B30-'DCF Model'!B35)/'DCF Model'!B9 -> 0 | C16: =(('DCF Model'!G25*(1+0.025)/(0.12-0.025))/(1+0.12)^5+'DCF Model'!B30-'DCF Model'!B35)/'DCF Model'!B9 -> 0 | D16: =(('DCF Model'!G25*(1+0.03)/(0.12-0.03))/(1+0.12)^5+'DCF Model'!B30-'DCF Model'!B35)/'DCF Model'!B9 -> 0 | E16: =(('DCF Model'!G25*(1+0.035)/(0.12-0.035))/(1+0.12)^5+'DCF Model'!B30-'DCF Model'!B35)/'DCF Model'!B9 -> 0 | F16: =(('DCF Model'!G25*(1+0.04)/(0.12-0.04))/(1+0.12)^5+'DCF Model'!B30-'DCF Model'!B35)/'DCF Model'!B9 -> 0
A17: 0.13 | B17: =(('DCF Model'!G25*(1+0.02)/(0.13-0.02))/(1+0.13)^5+'DCF Model'!B30-'DCF Model'!B35)/'DCF Model'!B9 -> 0 | C17: =(('DCF Model'!G25*(1+0.025)/(0.13-0.025))/(1+0.13)^5+'DCF Model'!B30-'DCF Model'!B35)/'DCF Model'!B9 -> 0 | D17: =(('DCF Model'!G25*(1+0.03)/(0.13-0.03))/(1+0.13)^5+'DCF Model'!B30-'DCF Model'!B35)/'DCF Model'!B9 -> 0 | E17: =(('DCF Model'!G25*(1+0.035)/(0.13-0.035))/(1+0.13)^5+'DCF Model'!B30-'DCF Model'!B35)/'DCF Model'!B9 -> 0 | F17: =(('DCF Model'!G25*(1+0.04)/(0.13-0.04))/(1+0.13)^5+'DCF Model'!B30-'DCF Model'!B35)/'DCF Model'!B9 -> 0
A18: 0.14 | B18: =(('DCF Model'!G25*(1+0.02)/(0.14-0.02))/(1+0.14)^5+'DCF Model'!B30-'DCF Model'!B35)/'DCF Model'!B9 -> 0 | C18: =(('DCF Model'!G25*(1+0.025)/(0.14-0.025))/(1+0.14)^5+'DCF Model'!B30-'DCF Model'!B35)/'DCF Model'!B9 -> 0 | D18: =(('DCF Model'!G25*(1+0.03)/(0.14-0.03))/(1+0.14)^5+'DCF Model'!B30-'DCF Model'!B35)/'DCF Model'!B9 -> 0 | E18: =(('DCF Model'!G25*(1+0.035)/(0.14-0.035))/(1+0.14)^5+'DCF Model'!B30-'DCF Model'!B35)/'DCF Model'!B9 -> 0 | F18: =(('DCF Model'!G25*(1+0.04)/(0.14-0.04))/(1+0.14)^5+'DCF Model'!B30-'DCF Model'!B35)/'DCF Model'!B9 -> 0
A19: Green = above current price (NZ$3.40) | Red = below current price
A20: Note: Formula-linked table (rows 13-18) updates automatically when DCF Model assumptions change

Sheet Scenarios
A1: AFT.NZ — Scenario Detail
A2: Full projections for Base, Bull, and Bear cases (NZ$m)
A5: BASE CASE
A6: Metric | B6: Y1 | C6: Y2 | D6: Y3 | E6: Y4 | F6: Y5 | G6: Terminal | H6: Total
A7: WACC: 12% | Terminal Growth: 3.0%
A8: Revenue Growth Rate | B8: 0.2 | C8: 0.18 | D8: 0.15 | E8: 0.12 | F8: 0.1
A9: FCF Margin | B9: 0.07 | C9: 0.08 | D9: 0.095 | E9: 0.11 | F9: 0.12
A10: Revenue (NZ$m) | B10: 249.6 | C10: 294.53 | D10: 338.71 | E10: 379.35 | F10: 417.29
A11: Free Cash Flow (NZ$m) | B11: 17.47 | C11: 23.56 | D11: 32.18 | E11: 41.73 | F11: 50.07
A12: Discount Factor | B12: 0.8929 | C12: 0.7972 | D12: 0.7118 | E12: 0.6355 | F12: 0.5674
A13: PV of FCF (NZ$m) | B13: 15.6 | C13: 18.78 | D13: 22.91 | E13: 26.52 | F13: 28.41
A14: Sum PV of FCF | B14: 112.22
A15: Terminal Value (NZ$m) | B15: 573.02
A16: PV of Terminal Value (NZ$m) | B16: 325.15
A17: Enterprise Value (NZ$m) | B17: 437.37
A18: Less: Net Debt (NZ$m) | B18: 20.9
A19: Equity Value (NZ$m) | B19: 416.47
A20: INTRINSIC VALUE / SHARE (NZ$) | B20: 3.97
A21: Upside / (Downside) | B21: 0.168
A22: Entry Price (15% CAGR Target) | B22: 2.72
A24: BULL CASE
A25: Metric | B25: Y1 | C25: Y2 | D25: Y3 | E25: Y4 | F25: Y5 | G25: Terminal | H25: Total
A26: WACC: 10% | Terminal Growth: 3.5%
A27: Revenue Growth Rate | B27: 0.25 | C27: 0.22 | D27: 0.18 | E27: 0.15 | F27: 0.12
A28: FCF Margin | B28: 0.08 | C28: 0.1 | D28: 0.12 | E28: 0.14 | F28: 0.15
A29: Revenue (NZ$m) | B29: 260 | C29: 317.2 | D29: 374.3 | E29: 430.4 | F29: 482.1
A30: Free Cash Flow (NZ$m) | B30: 20.8 | C30: 31.72 | D30: 44.92 | E30: 60.26 | F30: 72.32
A31: Discount Factor | B31: 0.9091 | C31: 0.8264 | D31: 0.7513 | E31: 0.683 | F31: 0.6209
A32: PV of FCF (NZ$m) | B32: 18.91 | C32: 26.21 | D32: 33.75 | E32: 41.16 | F32: 44.91
A33: Sum PV of FCF | B33: 164.93
A34: Terminal Value (NZ$m) | B34: 1151.4
A35: PV of Terminal Value (NZ$m) | B35: 714.93
A36: Enterprise Value (NZ$m) | B36: 879.86
A37: Less: Net Debt (NZ$m) | B37: 20.9
A38: Equity Value (NZ$m) | B38: 858.96
A39: INTRINSIC VALUE / SHARE (NZ$) | B39: 8.19
A40: Upside / (Downside) | B40: 1.409
A41: Entry Price (15% CAGR Target) | B41: 5.46
A43: BEAR CASE
A44: Metric | B44: Y1 | C44: Y2 | D44: Y3 | E44: Y4 | F44: Y5 | G44: Terminal | H44: Total
...

Sheet Historical Data
A1: AFT.NZ — Historical Financial Data (NZ$m)
A2: Source: AFT Pharmaceuticals annual reports, NZX filings
A4: Metric | B4: FY2016 | C4: FY2017 | D4: FY2018 | E4: FY2019 | F4: FY2020 | G4: FY2021 | H4: FY2022 | I4: FY2023 | J4: FY2024 | K4: FY2025
A5: Revenue (NZ$m) | B5: 64 | C5: 69.2 | D5: 80.1 | E5: 85.1 | F5: 105.6 | G5: 113.1 | H5: 130.3 | I5: 156.6 | J5: 195.4 | K5: 208
A6: Gross Profit (NZ$m) | B6: 23.6 | C6: 26 | D6: 34.2 | E6: 40.7 | F6: 48.3 | G6: 48.7 | H6: 61.8 | I6: 73 | J6: 88.3 | K6: 91.7
A7: Gross Margin (%) | B7: 0.368 | C7: 0.376 | D7: 0.427 | E7: 0.478 | F7: 0.457 | G7: 0.431 | H7: 0.474 | I7: 0.466 | J7: 0.452 | K7: 0.441
A8: EBITDA (NZ$m) | H8: 21.5 | I8: 21.4 | J8: 26.2 | K8: 20.9
A9: Net Income (NZ$m) | B9: -13.3 | C9: -18.4 | D9: -12.7 | E9: -2.4 | F9: 12.7 | G9: 7.8 | H9: 19.8 | I9: 10.7 | J9: 15.6 | K9: 11.4
A10: EPS (NZ$) | B10: -0.48 | C10: -0.19 | D10: -0.13 | E10: -0.03 | F10: 0.12 | G10: 0.07 | H10: 0.19 | I10: 0.1 | J10: 0.15 | K10: 0.11
A11: Free Cash Flow (NZ$m) | F11: 14.8 | G11: 0.7 | H11: 13.8 | I11: 11.4 | J11: 28.7 | K11: 12.9
A12: Shareholders Equity (NZ$m) | D12: 7.3 | E12: 5.1 | F12: 17.3 | G12: 36.6 | H12: 62.3 | I12: 73.3 | J12: 87.8 | K12: 97.1
A13: Total Debt (NZ$m) | B13: 28.2 | C13: 23.4 | D13: 30.7 | E13: 41.8 | F13: 43.2 | G13: 38.4 | H13: 37.2 | I13: 34.7 | J13: 28.2 | K13: 25.6
A14: Cash & Equivalents (NZ$m) | B14: 23.2 | C14: 16 | D14: 6.8 | E14: 6.9 | F14: 6.1 | G14: 3.2 | H14: 7.9 | I14: 4.7 | J14: 12 | K14: 11.1
A15: R&D Expenses (NZ$m) | H15: 5.5 | I15: 5.6 | J15: 8.1 | K15: 11.5
A16: Licensing Income (NZ$m) | B16: 1.8 | E16: 1.2 | F16: 3.8 | G16: 2.1 | H16: 6.7 | I16: 1.2 | J16: 8.5 | K16: 0.7
A18: Growth Rates
A19: Revenue YoY Growth | B19: 0.08125 | C19: 0.15751445 | D19: 0.062421973 | E19: 0.24089307 | F19: 0.071022727 | G19: 0.15207781 | H19: 0.2018419 | I19: 0.24776501 | J19: 0.064483112
A21: CAGR Summary
A22: Revenue 3yr CAGR (FY2022-FY2025) | B22: 0.1687
A23: Revenue 5yr CAGR (FY2020-FY2025) | B23: 0.1452
A24: Equity 3yr CAGR (FY2022-FY2025) | B24: 0.1594
A25: FCF 3yr CAGR (FY2022-FY2025) | B25: -0.0222
A26: Selected Growth Rate | B26: 0.1687 | C26: Revenue 3yr CAGR (most reliable for AFT)
A28: Equity 5yr CAGR of 41.2% is not representative of sustainable growth - AFT only turned equity positive in FY2020 (recovering from negative equity). FCF CAGRs are negative due to deliberate R&D and international hub investment suppressing free cash flow. EPS is distorted by lumpy licensing income. Revenue CAGR (3yr: 16.9%, 5yr: 14.5%) is the most reliable indicator and is used as the primary growth anchor, per the user instruction to use revenue and FCF as primary drivers for AFT.
