Workbook

Sheet Assumptions
A1: AAPL — DCF Model Assumptions (Master Control)
A2: Edit gray/blue input cells. All three scenario sheets update automatically.
A3: Valuation Date: 2026-06-12 | Current Price: $295.63 | Fiscal Year End: September
A5: Current Stock Price ($) | B5: 295.63 | C5: Live market price
A6: Shares Outstanding (M) | B6: 14726 | C6: Q2 FY2026 diluted shares
A7: Cash & Marketable Securities (M) | B7: 132000 | C7: FY2025 10-K: all liquidity ($132B)
A8: Total Debt (M) | B8: 90700 | C8: FY2025 term debt outstanding
A9: Net Debt (M) | B9: =B8-B7 -> 0 | C9: Negative = Net Cash (Apple has ~$41B net cash)
A10: Base Year FCF (M) | B10: 98767 | C10: FY2025: CFO $111.5B - CapEx $12.7B
A11: Base Year FCF (M) | B11: 98767 | C11: FY2025 FCF = CFO $111.5B - CapEx $12.7B
A13: SCENARIO ASSUMPTIONS | B13: BASE | C13: BULL | D13: BEAR
A14: WACC | B14: 0.085 | C14: 0.08 | D14: 0.09
A15: Terminal Growth Rate | B15: 0.025 | C15: 0.03 | D15: 0.02
A16: Y1 FCF Growth Rate | B16: 0.08 | C16: 0.12 | D16: 0.03
A17: Y2 FCF Growth Rate | B17: 0.07 | C17: 0.1 | D17: 0.02
A18: Y3 FCF Growth Rate | B18: 0.06 | C18: 0.09 | D18: 0.02
A19: Y4 FCF Growth Rate | B19: 0.05 | C19: 0.07 | D19: 0.01
A20: Y5 FCF Growth Rate | B20: 0.04 | C20: 0.06 | D20: 0.01
A22: WACC Rationale:
A23: Apple's WACC of 8.5% (base) / 8.0% (bull) / 9.0% (bear) is derived as follows: Risk-free rate = 4.3% (10yr US Treasury as of mid-2026). Equity risk premium = 5.0% (Damodaran US ERP). Beta = 0.85 (Apple's realized 3yr beta on monthly returns; Services revenue growing as a stabilizing force; Apple has historically been less volatile than the broader market on a trailing basis despite tech classification). CAPM: 4.3% + 0.85 * 5.0% = 8.55%. Apple's capital structure is essentially all-equity on a net basis (net cash positive), so WACC approximately equals cost of equity. The 8.5% base rate slightly rounds down CAPM to reflect the exceptional credit quality, $41B net cash buffer, and highly recurring Services revenue (now 26% of revenue at 75%+ margins). The bear case adds 50bps to reflect regulatory event risk and potential earnings uncertainty from Google TAC decision. | B23: Apple's WACC of 8.5% (base) / 8.0% (bull) / 9.0% (bear) is derived as follows: Risk-free rate = 4.3% (10yr US Treasury as of mid-2026). Equity risk premium = 5.0% (Damodaran US ERP). Beta = 0.85 (Apple's realized 3yr beta on monthly returns; Services revenue growing as a stabilizing force; Apple has historically been less volatile than the broader market on a trailing basis despite tech classification). CAPM: 4.3% + 0.85 * 5.0% = 8.55%. Apple's capital structure is essentially all-equity on a net basis (net cash positive), so WACC approximately equals cost of equity. The 8.5% base rate slightly rounds down CAPM to reflect the exceptional credit quality, $41B net cash buffer, and highly recurring Services revenue (now 26% of revenue at 75%+ margins). The bear case adds 50bps to reflect regulatory event risk and potential earnings uncertainty from Google TAC decision.

Sheet DCF_Base
A1: AAPL DCF Model — BASE CASE
A2: WACC: 8.5% | Terminal Growth: 2.5% | All inputs flow from Assumptions sheet
A4: KEY INPUTS | B4: Value
A5: Current Stock Price | B5: =Assumptions!B5 -> 0
A6: Shares Outstanding (M) | B6: =Assumptions!B6 -> 0
A7: Cash & Securities (M) | B7: =Assumptions!B7 -> 0
A8: Total Debt (M) | B8: =Assumptions!B8 -> 0
A9: Net Debt (M) | B9: =Assumptions!B9 -> 0
A10: Base Year FCF (M) | B10: =Assumptions!B10 -> 0
A12: SCENARIO ASSUMPTIONS | B12: Value
A13: WACC | B13: =Assumptions!B14 -> 0
A14: Terminal Growth Rate | B14: =Assumptions!B15 -> 0
A15: Y1 FCF Growth Rate | B15: =Assumptions!B16 -> 0
A16: Y2 FCF Growth Rate | B16: =Assumptions!B17 -> 0
A17: Y3 FCF Growth Rate | B17: =Assumptions!B18 -> 0
A18: Y4 FCF Growth Rate | B18: =Assumptions!B19 -> 0
A19: Y5 FCF Growth Rate | B19: =Assumptions!B20 -> 0
A21: FCF PROJECTIONS (in $M)
B22: BASE YEAR | C22: YEAR 1 | D22: YEAR 2 | E22: YEAR 3 | F22: YEAR 4 | G22: YEAR 5
A23: Free Cash Flow ($M) | B23: =Assumptions!B10 -> 0 | C23: =B23*(1+B13) -> 0 | D23: =C23*(1+B14) -> 0 | E23: =D23*(1+B15) -> 0 | F23: =E23*(1+B16) -> 0 | G23: =F23*(1+B17) -> 0
A24: YoY Growth Applied | C24: =B13 -> 0 | D24: =B14 -> 0 | E24: =B15 -> 0 | F24: =B16 -> 0 | G24: =B17 -> 0
A25: Discount Factor (1/(1+WACC)^n) | C25: =1/(1+$B$13)^1 -> 0 | D25: =1/(1+$B$13)^2 -> 0 | E25: =1/(1+$B$13)^3 -> 0 | F25: =1/(1+$B$13)^4 -> 0 | G25: =1/(1+$B$13)^5 -> 0
A26: PV of FCF ($M) | C26: =C23*C25 -> 0 | D26: =D23*D25 -> 0 | E26: =E23*E25 -> 0 | F26: =F23*F25 -> 0 | G26: =G23*G25 -> 0
A28: VALUATION SUMMARY | B28: Amount ($M) | C28: Per Share
A29: Sum of PV of FCF (Years 1-5) | B29: =SUM(C26:G26) -> 0 | C29: =B29/Assumptions!B6 -> 0
A30: Terminal FCF (Year 5 FCF x (1+TG)) | B30: =G23*(1+$B$14) -> 0
A31: Terminal Value (TV / (WACC - TG)) | B31: =B30/($B$13-$B$14) -> 0 | C31: =B31/Assumptions!B6 -> 0
A32: PV of Terminal Value (TV x Y5 disc factor) | B32: =B31*G25 -> 0 | C32: =B32/Assumptions!B6 -> 0
A33: Enterprise Value | B33: =B29+B32 -> 0 | C33: =B33/Assumptions!B6 -> 0
A34: Less: Net Debt (negative = net cash added) | B34: =Assumptions!B9 -> 0
A35: Equity Value | B35: =B33-B34 -> 0 | C35: =B35/Assumptions!B6 -> 0
A36: INTRINSIC VALUE PER SHARE | B36: =B35/Assumptions!B6 -> 0 | C36: =(B36-Assumptions!B5)/Assumptions!B5 -> 0
A37: (Upside shown in column C)
A39: ENTRY PRICE (15% CAGR Target) | B39: Amount
A40: Terminal Value ($M) | B40: =B31 -> 0
A41: Terminal Value per Share | B41: =B31/Assumptions!B6 -> 0
A42: Entry Price for 15% CAGR (TV/share / 1.15^5) | B42: =B41/(1.15^5) -> 0
A43: Entry Discount from Current Price | B43: =(B42-Assumptions!B5)/Assumptions!B5 -> 0
A45: VALUE COMPOSITION NOTE
A46: PV of FCF (Y1-Y5) as % of Total IV | B46: =B29/B35 -> 0
...

Sheet DCF_Bull
A1: AAPL DCF Model — BULL CASE
A2: WACC: 8.0% | Terminal Growth: 3.0% | All inputs flow from Assumptions sheet
A4: KEY INPUTS | B4: Value
A5: Current Stock Price | B5: =Assumptions!B5 -> 0
A6: Shares Outstanding (M) | B6: =Assumptions!B6 -> 0
A7: Cash & Securities (M) | B7: =Assumptions!B7 -> 0
A8: Total Debt (M) | B8: =Assumptions!B8 -> 0
A9: Net Debt (M) | B9: =Assumptions!B9 -> 0
A10: Base Year FCF (M) | B10: =Assumptions!B10 -> 0
A12: SCENARIO ASSUMPTIONS | B12: Value
A13: WACC | B13: =Assumptions!C14 -> 0
A14: Terminal Growth Rate | B14: =Assumptions!C15 -> 0
A15: Y1 FCF Growth Rate | B15: =Assumptions!C16 -> 0
A16: Y2 FCF Growth Rate | B16: =Assumptions!C17 -> 0
A17: Y3 FCF Growth Rate | B17: =Assumptions!C18 -> 0
A18: Y4 FCF Growth Rate | B18: =Assumptions!C19 -> 0
A19: Y5 FCF Growth Rate | B19: =Assumptions!C20 -> 0
A21: FCF PROJECTIONS (in $M)
B22: BASE YEAR | C22: YEAR 1 | D22: YEAR 2 | E22: YEAR 3 | F22: YEAR 4 | G22: YEAR 5
A23: Free Cash Flow ($M) | B23: =Assumptions!B10 -> 0 | C23: =B23*(1+B13) -> 0 | D23: =C23*(1+B14) -> 0 | E23: =D23*(1+B15) -> 0 | F23: =E23*(1+B16) -> 0 | G23: =F23*(1+B17) -> 0
A24: YoY Growth Applied | C24: =B13 -> 0 | D24: =B14 -> 0 | E24: =B15 -> 0 | F24: =B16 -> 0 | G24: =B17 -> 0
A25: Discount Factor (1/(1+WACC)^n) | C25: =1/(1+$B$13)^1 -> 0 | D25: =1/(1+$B$13)^2 -> 0 | E25: =1/(1+$B$13)^3 -> 0 | F25: =1/(1+$B$13)^4 -> 0 | G25: =1/(1+$B$13)^5 -> 0
A26: PV of FCF ($M) | C26: =C23*C25 -> 0 | D26: =D23*D25 -> 0 | E26: =E23*E25 -> 0 | F26: =F23*F25 -> 0 | G26: =G23*G25 -> 0
A28: VALUATION SUMMARY | B28: Amount ($M) | C28: Per Share
A29: Sum of PV of FCF (Years 1-5) | B29: =SUM(C26:G26) -> 0 | C29: =B29/Assumptions!B6 -> 0
A30: Terminal FCF (Year 5 FCF x (1+TG)) | B30: =G23*(1+$B$14) -> 0
A31: Terminal Value (TV / (WACC - TG)) | B31: =B30/($B$13-$B$14) -> 0 | C31: =B31/Assumptions!B6 -> 0
A32: PV of Terminal Value (TV x Y5 disc factor) | B32: =B31*G25 -> 0 | C32: =B32/Assumptions!B6 -> 0
A33: Enterprise Value | B33: =B29+B32 -> 0 | C33: =B33/Assumptions!B6 -> 0
A34: Less: Net Debt (negative = net cash added) | B34: =Assumptions!B9 -> 0
A35: Equity Value | B35: =B33-B34 -> 0 | C35: =B35/Assumptions!B6 -> 0
A36: INTRINSIC VALUE PER SHARE | B36: =B35/Assumptions!B6 -> 0 | C36: =(B36-Assumptions!B5)/Assumptions!B5 -> 0
A37: (Upside shown in column C)
A39: ENTRY PRICE (15% CAGR Target) | B39: Amount
A40: Terminal Value ($M) | B40: =B31 -> 0
A41: Terminal Value per Share | B41: =B31/Assumptions!B6 -> 0
A42: Entry Price for 15% CAGR (TV/share / 1.15^5) | B42: =B41/(1.15^5) -> 0
A43: Entry Discount from Current Price | B43: =(B42-Assumptions!B5)/Assumptions!B5 -> 0
A45: VALUE COMPOSITION NOTE
A46: PV of FCF (Y1-Y5) as % of Total IV | B46: =B29/B35 -> 0
...

Sheet DCF_Bear
A1: AAPL DCF Model — BEAR CASE
A2: WACC: 9.0% | Terminal Growth: 2.0% | All inputs flow from Assumptions sheet
A4: KEY INPUTS | B4: Value
A5: Current Stock Price | B5: =Assumptions!B5 -> 0
A6: Shares Outstanding (M) | B6: =Assumptions!B6 -> 0
A7: Cash & Securities (M) | B7: =Assumptions!B7 -> 0
A8: Total Debt (M) | B8: =Assumptions!B8 -> 0
A9: Net Debt (M) | B9: =Assumptions!B9 -> 0
A10: Base Year FCF (M) | B10: =Assumptions!B10 -> 0
A12: SCENARIO ASSUMPTIONS | B12: Value
A13: WACC | B13: =Assumptions!D14 -> 0
A14: Terminal Growth Rate | B14: =Assumptions!D15 -> 0
A15: Y1 FCF Growth Rate | B15: =Assumptions!D16 -> 0
A16: Y2 FCF Growth Rate | B16: =Assumptions!D17 -> 0
A17: Y3 FCF Growth Rate | B17: =Assumptions!D18 -> 0
A18: Y4 FCF Growth Rate | B18: =Assumptions!D19 -> 0
A19: Y5 FCF Growth Rate | B19: =Assumptions!D20 -> 0
A21: FCF PROJECTIONS (in $M)
B22: BASE YEAR | C22: YEAR 1 | D22: YEAR 2 | E22: YEAR 3 | F22: YEAR 4 | G22: YEAR 5
A23: Free Cash Flow ($M) | B23: =Assumptions!B10 -> 0 | C23: =B23*(1+B13) -> 0 | D23: =C23*(1+B14) -> 0 | E23: =D23*(1+B15) -> 0 | F23: =E23*(1+B16) -> 0 | G23: =F23*(1+B17) -> 0
A24: YoY Growth Applied | C24: =B13 -> 0 | D24: =B14 -> 0 | E24: =B15 -> 0 | F24: =B16 -> 0 | G24: =B17 -> 0
A25: Discount Factor (1/(1+WACC)^n) | C25: =1/(1+$B$13)^1 -> 0 | D25: =1/(1+$B$13)^2 -> 0 | E25: =1/(1+$B$13)^3 -> 0 | F25: =1/(1+$B$13)^4 -> 0 | G25: =1/(1+$B$13)^5 -> 0
A26: PV of FCF ($M) | C26: =C23*C25 -> 0 | D26: =D23*D25 -> 0 | E26: =E23*E25 -> 0 | F26: =F23*F25 -> 0 | G26: =G23*G25 -> 0
A28: VALUATION SUMMARY | B28: Amount ($M) | C28: Per Share
A29: Sum of PV of FCF (Years 1-5) | B29: =SUM(C26:G26) -> 0 | C29: =B29/Assumptions!B6 -> 0
A30: Terminal FCF (Year 5 FCF x (1+TG)) | B30: =G23*(1+$B$14) -> 0
A31: Terminal Value (TV / (WACC - TG)) | B31: =B30/($B$13-$B$14) -> 0 | C31: =B31/Assumptions!B6 -> 0
A32: PV of Terminal Value (TV x Y5 disc factor) | B32: =B31*G25 -> 0 | C32: =B32/Assumptions!B6 -> 0
A33: Enterprise Value | B33: =B29+B32 -> 0 | C33: =B33/Assumptions!B6 -> 0
A34: Less: Net Debt (negative = net cash added) | B34: =Assumptions!B9 -> 0
A35: Equity Value | B35: =B33-B34 -> 0 | C35: =B35/Assumptions!B6 -> 0
A36: INTRINSIC VALUE PER SHARE | B36: =B35/Assumptions!B6 -> 0 | C36: =(B36-Assumptions!B5)/Assumptions!B5 -> 0
A37: (Upside shown in column C)
A39: ENTRY PRICE (15% CAGR Target) | B39: Amount
A40: Terminal Value ($M) | B40: =B31 -> 0
A41: Terminal Value per Share | B41: =B31/Assumptions!B6 -> 0
A42: Entry Price for 15% CAGR (TV/share / 1.15^5) | B42: =B41/(1.15^5) -> 0
A43: Entry Discount from Current Price | B43: =(B42-Assumptions!B5)/Assumptions!B5 -> 0
A45: VALUE COMPOSITION NOTE
A46: PV of FCF (Y1-Y5) as % of Total IV | B46: =B29/B35 -> 0
...

Sheet Sensitivity
A1: AAPL DCF — Sensitivity Analysis (Base Case Assumptions)
A2: Intrinsic Value per Share across WACC and Terminal Growth Rate combinations
A3: Color: Green = above current price | Yellow = within 20% below | Red = more than 20% below current price
A5: Note: All values use Base Case Year 1-5 FCF growth rates. Only WACC and TG vary.
A7: WACC \ Term Growth | B7: 1.5% | C7: 2.0% | D7: 2.5% | E7: 3.0% | F7: 3.5%
A8: 7.5% | B8: 141.29 | C8: 151.46 | D8: 163.68 | E8: 178.61 | F8: 197.27
A9: 8.0% | B9: 130.47 | C9: 138.92 | D9: 148.92 | E9: 160.9 | F9: 175.56
A10: 8.5% | B10: 121.2 | C10: 128.31 | D10: 136.61 | E10: 146.42 | F10: 158.19
A11: 9.0% | B11: 113.17 | C11: 119.22 | D11: 126.21 | E11: 134.36 | F11: 143.99
A12: 9.5% | B12: 106.15 | C12: 111.35 | D12: 117.29 | E12: 124.15 | F12: 132.15
A14: Current Market Price: $295.63
A15: Base Case IV (WACC 8.5%, TG 2.5%): $136.61
A16: Market Premium to Base IV: 116.4%
A18: Green = IV > current price (undervalued)
A19: Yellow = IV within 20% below current price
A20: Red = IV more than 20% below current price
A22: BULL CASE SENSITIVITY (WACC and TG vary, Bull FCF growth rates)
A23: WACC \ Term Growth | B23: 1.5% | C23: 2.0% | D23: 2.5% | E23: 3.0% | F23: 3.5%
A24: 7.5% | B24: 158.9 | C24: 170.49 | D24: 184.39 | E24: 201.39 | F24: 222.64
A25: 8.0% | B25: 146.59 | C25: 156.22 | D25: 167.6 | E25: 181.25 | F25: 197.93
A26: 8.5% | B26: 136.05 | C26: 144.15 | D26: 153.6 | E26: 164.77 | F26: 178.17
A27: 9.0% | B27: 126.92 | C27: 133.82 | D27: 141.77 | E27: 151.05 | F27: 162.01
A28: 9.5% | B28: 118.94 | C28: 124.86 | D28: 131.63 | E28: 139.44 | F28: 148.54
A30: BEAR CASE SENSITIVITY
A31: WACC \ Term Growth | B31: 1.5% | C31: 2.0% | D31: 2.5% | E31: 3.0% | F31: 3.5%
A32: 7.5% | B32: 118.05 | C32: 126.37 | D32: 136.35 | E32: 148.55 | F32: 163.8
A33: 8.0% | B33: 109.19 | C33: 116.1 | D33: 124.27 | E33: 134.06 | F33: 146.04
A34: 8.5% | B34: 101.6 | C34: 107.41 | D34: 114.2 | E34: 122.21 | F34: 131.83
A35: 9.0% | B35: 95.02 | C35: 99.97 | D35: 105.67 | E35: 112.33 | F35: 120.2
A36: 9.5% | B36: 89.26 | C36: 93.51 | D36: 98.37 | E36: 103.97 | F36: 110.51

Sheet Historical
A1: AAPL Historical Financial Data & Growth Rates
A2: Source: Apple Inc. SEC filings (FY2020-FY2025)
A4: HISTORICAL GROWTH RATES (CAGR)
A5: Metric | B5: 3-Year CAGR (FY22-FY25) | C5: 5-Year CAGR (FY20-FY25) | D5: Notes
A6: Revenue | B6: 0.0181 | C6: 0.0868 | D6: 3yr low due to FY22-24 flatness; 5yr reflects COVID recovery
A7: EPS (Diluted) | B7: 0.0688 | C7: 0.1786 | D7: 5yr elevated by buyback EPS amplification (~40% share count reduction over decade)
A8: Free Cash Flow | B8: -0.0395 | C8: 0.0613 | D8: FCF 5yr CAGR used as primary DCF anchor; most reliable metric
A9: Shareholders Equity | B9: 0.1332 | C9: 0.0245 | D9: Unreliable — distorted by buybacks; equity swings from $50B to $74B
A11: Selected Growth Rate for DCF: | B11: 0.0613 | C11: fcf_5yr_cagr
A13: ANNUAL FINANCIALS (FY2020-FY2025, $M)
A14: Year | B14: Revenue | C14: Net Income | D14: FCF | E14: Operating CF | F14: CapEx | G14: Shareholders Equity | H14: Diluted Shares (M)
A15: FY2020 | B15: 274515 | C15: 57411 | D15: 73365 | E15: 80674 | F15: 7309 | G15: 65339 | H15: 17528
A16: FY2021 | B16: 365817 | C16: 94680 | D16: 92953 | E16: 104038 | F16: 11085 | G16: 63090 | H16: 16864
A17: FY2022 | B17: 394328 | C17: 99803 | D17: 111443 | E17: 122151 | F17: 10708 | G17: 50672 | H17: 16326
A18: FY2023 | B18: 383285 | C18: 96995 | D18: 99584 | E18: 110543 | F18: 10959 | G18: 62146 | H18: 15812
A19: FY2024 | B19: 391035 | C19: 93736 | D19: 108807 | E19: 118254 | F19: 9447 | G19: 56950 | H19: 15408
A20: FY2025 | B20: 416161 | C20: 112010 | D20: 98767 | E20: 111482 | F20: 12715 | G20: 73733 | H20: 15004
A22: HISTORICAL VALUATION MULTIPLES (FY2016-FY2025)
A23: Fiscal Year | B23: Price (Sept) | C23: Mkt Cap ($B) | D23: P/E | E23: EV/EBITDA | F23: P/S
A24: FY2016 | B24: 25.88 | C24: 542 | D24: 11.9 | E24: 7.8 | F24: 2.51
A25: FY2017 | B25: 35.9 | C25: 749.2 | D25: 15.5 | E25: 10.1 | F25: 3.27
A26: FY2018 | B26: 53.37 | C26: 1057.9 | D26: 17.8 | E26: 12.6 | F26: 3.98
A27: FY2019 | B27: 53.78 | C27: 993.4 | D27: 18 | E27: 12.4 | F27: 3.82
A28: FY2020 | B28: 112.33 | C28: 1968.9 | D28: 34.3 | E28: 25.7 | F28: 7.17
A29: FY2021 | B29: 138.13 | C29: 2329.4 | D29: 24.6 | E29: 19.3 | F29: 6.37
A30: FY2022 | B30: 135.67 | C30: 2214.9 | D30: 22.2 | E30: 17.4 | F30: 5.62
A31: FY2023 | B31: 169.07 | C31: 2673.3 | D31: 27.6 | E31: 21.2 | F31: 6.97
A32: FY2024 | B32: 231.27 | C32: 3563.4 | D32: 38 | E32: 26.8 | F32: 9.11
A33: FY2025 | B33: 253.91 | C33: 3809.7 | D33: 34 | E33: 25.9 | F33: 9.15
A35: 10yr Average P/E: | B35: 24.4
A36: 10yr Average EV/EBITDA: | B36: 17.9
A37: Base IV Implied P/E: | B37: 18 | C37: Below 10yr avg — no sanity trip
A38: Base IV Implied EV/EBITDA: | B38: 13.5 | C38: Below 10yr avg — no sanity trip
A40: Market Price Implied P/E ($295.63): | B40: 38.9 | C40: Above 10yr avg — market pricing in premium growth
A41: Market Price Implied EV/EBITDA: | B41: 29.6 | C41: Above 10yr avg — at high end of recent range

Sheet Summary
A1: AAPL DCF — Scenario Summary & Probability-Weighted Valuation
A2: Valuation Date: 2026-06-12 | Current Price: $295.63 | FY2025 FCF Base: $98,767M
A4: SCENARIO COMPARISON
A5: Metric | B5: BASE CASE | C5: BULL CASE | D5: BEAR CASE | E5: PROBABILITY-WEIGHTED
A6: WACC | B6: 8.5% | C6: 8.0% | D6: 9.0% | E6: N/A
A7: Terminal Growth Rate | B7: 2.5% | C7: 3.0% | D7: 2.0% | E7: N/A
A8: Y1 FCF Growth | B8: 8.0% | C8: 12.0% | D8: 3.0% | E8: N/A
A9: Y5 FCF Growth | B9: 4.0% | C9: 6.0% | D9: 1.0% | E9: N/A
A10: Probability Weight | B10: 40% | C10: 30% | D10: 30% | E10: 100%
A11: Intrinsic Value / Share | B11: $136.61 | C11: $185.47 | D11: $99.97 | E11: $139.01
A12: Upside / Downside | B12: -53.8% | C12: -37.3% | D12: -66.2% | E12: -53.0%
A13: Entry Price (15% CAGR) | B13: $76.21 | C13: $107.70 | D13: $53.12 | E13: N/A
A14: Enterprise Value ($M) | B14: $1,970,397 | C14: $2,690,025 | D14: $1,430,765 | E14: N/A
A15: Sum PV of FCF ($M) | B15: $469,524 | C15: $518,714 | D15: $408,293 | E15: N/A
A16: PV of Terminal Value ($M) | B16: $1,500,873 | C16: $2,171,311 | D16: $1,022,472 | E16: N/A
A18: SANITY CHECK SUMMARY
A19: Sanity Check Performed: | B19: YES
A20: P/E Trip (>2x 10yr avg of 24.4x)? | B20: NO — Implied P/E 18.0x is BELOW avg
A21: EV/EBITDA Trip (>1.5x 10yr avg of 17.9x)? | B21: NO — Implied EV/EBITDA 13.5x is BELOW avg
A22: P/B Trip? | B22: SKIPPED — Apple P/B analytically useless (buyback-distorted equity)
A23: Auto-Fix Applied? | B23: NO — DCF is internally consistent
A25: Base IV $136.61 is 54% BELOW current market price $295.63. This is not a modeling error — the DCF conservatively anchors to 5yr FCF growth of 4-8%. The market is pricing Apple at 38.9x P/E vs 10yr avg 24.4x, reflecting AI supercycle optimism, Services quality premium, and buyback EPS optionality beyond the DCF horizon.
