Workbook

Sheet DCF Model
A1: HGH.NZ Book-Value / ROE Valuation Model (Base Case)
A2: Gray cells are INPUTS - adjust to see valuation change. This is a BANK model (book value x ROE, discounted at Cost of Equity), NOT an FCF DCF.
A4: KEY INPUTS
A5: Current Stock Price | B5: 1.205
A6: Shares Outstanding, current (M) | B6: 940.559
A7: Book Value of Equity, current (M) | B7: 1289
A8: Book Value per Share, current | B8: =B7/B6 -> 0
A9: Implied P/B at current price | B9: =B5/B8 -> 0
A11: TSB Deal: New Equity Raised FY27 (M) | B11: 250
A12: TSB Deal: New Shares Issued FY27 (M) | B12: 200
A13: Ongoing Annual Share Growth (post-FY27) | B13: 0.003
A15: Cost of Equity (CoE) | B15: 0.131
A16: Exit Price-to-Book Multiple (Year 5) | B16: 0.95
A18: ROE & PAYOUT ASSUMPTIONS (Base Case)
B19: FY27 | C19: FY28 | D19: FY29 | E19: FY30 | F19: FY31
A20: Underlying ROE (on avg. equity) | B20: 0.07 | C20: 0.065 | D20: 0.078 | E20: 0.085 | F20: 0.09
A21: Dividend Payout Ratio | B21: 0.55 | C21: 0.5 | D21: 0.55 | E21: 0.55 | F21: 0.55
A23: PROJECTIONS
B24: FY27 | C24: FY28 | D24: FY29 | E24: FY30 | F24: FY31
A25: Shares Outstanding (M) | B25: =B6+B12 -> 0 | C25: =B25*(1+$B$13) -> 0 | D25: =C25*(1+$B$13) -> 0 | E25: =D25*(1+$B$13) -> 0 | F25: =E25*(1+$B$13) -> 0
A26: Beginning Equity, post-raise (M) | B26: =B7+B11 -> 0 | C26: =B30 -> 0 | D26: =C30 -> 0 | E26: =D30 -> 0 | F26: =E30 -> 0
A27: Average Equity for ROE calc (M) | B27: =(B7+B26)/2 -> 0 | C27: =(B30+C26)/2 -> 0 | D27: =(C30+D26)/2 -> 0 | E27: =(D30+E26)/2 -> 0 | F27: =(E30+F26)/2 -> 0
A28: Net Income (M) | B28: =B27*B20 -> 0 | C28: =C27*C20 -> 0 | D28: =D27*D20 -> 0 | E28: =E27*E20 -> 0 | F28: =F27*F20 -> 0
A29: Dividends Paid (M) | B29: =B28*B21 -> 0 | C29: =C28*C21 -> 0 | D29: =D28*D21 -> 0 | E29: =E28*E21 -> 0 | F29: =F28*F21 -> 0
A30: Ending Equity (M) | B30: =B26+B28-B29 -> 0 | C30: =C26+C28-C29 -> 0 | D30: =D26+D28-D29 -> 0 | E30: =E26+E28-E29 -> 0 | F30: =F26+F28-F29 -> 0
A31: Book Value per Share | B31: =B30/B25 -> 0 | C31: =C30/C25 -> 0 | D31: =D30/D25 -> 0 | E31: =E30/E25 -> 0 | F31: =F30/F25 -> 0
A32: Dividends per Share | B32: =B29/B25 -> 0 | C32: =C29/C25 -> 0 | D32: =D29/D25 -> 0 | E32: =E29/E25 -> 0 | F32: =F29/F25 -> 0
A33: Discount Factor (@ CoE) | B33: =1/(1+$B$15)^1 -> 0 | C33: =1/(1+$B$15)^2 -> 0 | D33: =1/(1+$B$15)^3 -> 0 | E33: =1/(1+$B$15)^4 -> 0 | F33: =1/(1+$B$15)^5 -> 0
A34: PV of Dividends per Share | B34: =B32*B33 -> 0 | C34: =C32*C33 -> 0 | D34: =D32*D33 -> 0 | E34: =E32*E33 -> 0 | F34: =F32*F33 -> 0
A36: VALUATION
A37: Sum of PV of Dividends | B37: =SUM(B34:F34) -> 0
A38: Exit Book Value per Share (Year 5) | B38: =F31 -> 0
A39: Exit Price per Share (Year 5, at Exit P/B) | B39: =B38*B16 -> 0
A40: PV of Exit Value | B40: =B39*F33 -> 0
A41: INTRINSIC VALUE / SHARE | B41: =B37+B40 -> 0
A43: Upside to Intrinsic Value | B43: =(B41-B5)/B5 -> 0
A45: ENTRY PRICE (15% IRR Target)
A46: Hurdle Rate | B46: 0.15
A47: PV of Yrs 1-5 Dividends @ Hurdle | B47: =NPV(B46,B32:F32) -> 0
A48: PV of Exit Value @ Hurdle | B48: =B39/(1+B46)^5 -> 0
...

Sheet Sensitivity
A1: Sensitivity Analysis
A2: Intrinsic Value by Cost of Equity & Exit P/B Multiple (Base-Case ROE/Payout/Share path)
A4: CoE \ Exit P/B | B4: 0.65 | C4: 0.8 | D4: 0.95 | E4: 1.1 | F4: 1.25
A5: 0.111 | B5: ='DCF Model'!$B$32/(1+0.111)^1+'DCF Model'!$C$32/(1+0.111)^2+'DCF Model'!$D$32/(1+0.111)^3+'DCF Model'!$E$32/(1+0.111)^4+'DCF Model'!$F$32/(1+0.111)^5+'DCF Model'!$B$38*0.65/(1+0.111)^5 -> 0 | C5: ='DCF Model'!$B$32/(1+0.111)^1+'DCF Model'!$C$32/(1+0.111)^2+'DCF Model'!$D$32/(1+0.111)^3+'DCF Model'!$E$32/(1+0.111)^4+'DCF Model'!$F$32/(1+0.111)^5+'DCF Model'!$B$38*0.8/(1+0.111)^5 -> 0 | D5: ='DCF Model'!$B$32/(1+0.111)^1+'DCF Model'!$C$32/(1+0.111)^2+'DCF Model'!$D$32/(1+0.111)^3+'DCF Model'!$E$32/(1+0.111)^4+'DCF Model'!$F$32/(1+0.111)^5+'DCF Model'!$B$38*0.95/(1+0.111)^5 -> 0 | E5: ='DCF Model'!$B$32/(1+0.111)^1+'DCF Model'!$C$32/(1+0.111)^2+'DCF Model'!$D$32/(1+0.111)^3+'DCF Model'!$E$32/(1+0.111)^4+'DCF Model'!$F$32/(1+0.111)^5+'DCF Model'!$B$38*1.1/(1+0.111)^5 -> 0 | F5: ='DCF Model'!$B$32/(1+0.111)^1+'DCF Model'!$C$32/(1+0.111)^2+'DCF Model'!$D$32/(1+0.111)^3+'DCF Model'!$E$32/(1+0.111)^4+'DCF Model'!$F$32/(1+0.111)^5+'DCF Model'!$B$38*1.25/(1+0.111)^5 -> 0
A6: 0.121 | B6: ='DCF Model'!$B$32/(1+0.121)^1+'DCF Model'!$C$32/(1+0.121)^2+'DCF Model'!$D$32/(1+0.121)^3+'DCF Model'!$E$32/(1+0.121)^4+'DCF Model'!$F$32/(1+0.121)^5+'DCF Model'!$B$38*0.65/(1+0.121)^5 -> 0 | C6: ='DCF Model'!$B$32/(1+0.121)^1+'DCF Model'!$C$32/(1+0.121)^2+'DCF Model'!$D$32/(1+0.121)^3+'DCF Model'!$E$32/(1+0.121)^4+'DCF Model'!$F$32/(1+0.121)^5+'DCF Model'!$B$38*0.8/(1+0.121)^5 -> 0 | D6: ='DCF Model'!$B$32/(1+0.121)^1+'DCF Model'!$C$32/(1+0.121)^2+'DCF Model'!$D$32/(1+0.121)^3+'DCF Model'!$E$32/(1+0.121)^4+'DCF Model'!$F$32/(1+0.121)^5+'DCF Model'!$B$38*0.95/(1+0.121)^5 -> 0 | E6: ='DCF Model'!$B$32/(1+0.121)^1+'DCF Model'!$C$32/(1+0.121)^2+'DCF Model'!$D$32/(1+0.121)^3+'DCF Model'!$E$32/(1+0.121)^4+'DCF Model'!$F$32/(1+0.121)^5+'DCF Model'!$B$38*1.1/(1+0.121)^5 -> 0 | F6: ='DCF Model'!$B$32/(1+0.121)^1+'DCF Model'!$C$32/(1+0.121)^2+'DCF Model'!$D$32/(1+0.121)^3+'DCF Model'!$E$32/(1+0.121)^4+'DCF Model'!$F$32/(1+0.121)^5+'DCF Model'!$B$38*1.25/(1+0.121)^5 -> 0
A7: 0.131 | B7: ='DCF Model'!$B$32/(1+0.131)^1+'DCF Model'!$C$32/(1+0.131)^2+'DCF Model'!$D$32/(1+0.131)^3+'DCF Model'!$E$32/(1+0.131)^4+'DCF Model'!$F$32/(1+0.131)^5+'DCF Model'!$B$38*0.65/(1+0.131)^5 -> 0 | C7: ='DCF Model'!$B$32/(1+0.131)^1+'DCF Model'!$C$32/(1+0.131)^2+'DCF Model'!$D$32/(1+0.131)^3+'DCF Model'!$E$32/(1+0.131)^4+'DCF Model'!$F$32/(1+0.131)^5+'DCF Model'!$B$38*0.8/(1+0.131)^5 -> 0 | D7: ='DCF Model'!$B$32/(1+0.131)^1+'DCF Model'!$C$32/(1+0.131)^2+'DCF Model'!$D$32/(1+0.131)^3+'DCF Model'!$E$32/(1+0.131)^4+'DCF Model'!$F$32/(1+0.131)^5+'DCF Model'!$B$38*0.95/(1+0.131)^5 -> 0 | E7: ='DCF Model'!$B$32/(1+0.131)^1+'DCF Model'!$C$32/(1+0.131)^2+'DCF Model'!$D$32/(1+0.131)^3+'DCF Model'!$E$32/(1+0.131)^4+'DCF Model'!$F$32/(1+0.131)^5+'DCF Model'!$B$38*1.1/(1+0.131)^5 -> 0 | F7: ='DCF Model'!$B$32/(1+0.131)^1+'DCF Model'!$C$32/(1+0.131)^2+'DCF Model'!$D$32/(1+0.131)^3+'DCF Model'!$E$32/(1+0.131)^4+'DCF Model'!$F$32/(1+0.131)^5+'DCF Model'!$B$38*1.25/(1+0.131)^5 -> 0
A8: 0.141 | B8: ='DCF Model'!$B$32/(1+0.141)^1+'DCF Model'!$C$32/(1+0.141)^2+'DCF Model'!$D$32/(1+0.141)^3+'DCF Model'!$E$32/(1+0.141)^4+'DCF Model'!$F$32/(1+0.141)^5+'DCF Model'!$B$38*0.65/(1+0.141)^5 -> 0 | C8: ='DCF Model'!$B$32/(1+0.141)^1+'DCF Model'!$C$32/(1+0.141)^2+'DCF Model'!$D$32/(1+0.141)^3+'DCF Model'!$E$32/(1+0.141)^4+'DCF Model'!$F$32/(1+0.141)^5+'DCF Model'!$B$38*0.8/(1+0.141)^5 -> 0 | D8: ='DCF Model'!$B$32/(1+0.141)^1+'DCF Model'!$C$32/(1+0.141)^2+'DCF Model'!$D$32/(1+0.141)^3+'DCF Model'!$E$32/(1+0.141)^4+'DCF Model'!$F$32/(1+0.141)^5+'DCF Model'!$B$38*0.95/(1+0.141)^5 -> 0 | E8: ='DCF Model'!$B$32/(1+0.141)^1+'DCF Model'!$C$32/(1+0.141)^2+'DCF Model'!$D$32/(1+0.141)^3+'DCF Model'!$E$32/(1+0.141)^4+'DCF Model'!$F$32/(1+0.141)^5+'DCF Model'!$B$38*1.1/(1+0.141)^5 -> 0 | F8: ='DCF Model'!$B$32/(1+0.141)^1+'DCF Model'!$C$32/(1+0.141)^2+'DCF Model'!$D$32/(1+0.141)^3+'DCF Model'!$E$32/(1+0.141)^4+'DCF Model'!$F$32/(1+0.141)^5+'DCF Model'!$B$38*1.25/(1+0.141)^5 -> 0
A9: 0.151 | B9: ='DCF Model'!$B$32/(1+0.151)^1+'DCF Model'!$C$32/(1+0.151)^2+'DCF Model'!$D$32/(1+0.151)^3+'DCF Model'!$E$32/(1+0.151)^4+'DCF Model'!$F$32/(1+0.151)^5+'DCF Model'!$B$38*0.65/(1+0.151)^5 -> 0 | C9: ='DCF Model'!$B$32/(1+0.151)^1+'DCF Model'!$C$32/(1+0.151)^2+'DCF Model'!$D$32/(1+0.151)^3+'DCF Model'!$E$32/(1+0.151)^4+'DCF Model'!$F$32/(1+0.151)^5+'DCF Model'!$B$38*0.8/(1+0.151)^5 -> 0 | D9: ='DCF Model'!$B$32/(1+0.151)^1+'DCF Model'!$C$32/(1+0.151)^2+'DCF Model'!$D$32/(1+0.151)^3+'DCF Model'!$E$32/(1+0.151)^4+'DCF Model'!$F$32/(1+0.151)^5+'DCF Model'!$B$38*0.95/(1+0.151)^5 -> 0 | E9: ='DCF Model'!$B$32/(1+0.151)^1+'DCF Model'!$C$32/(1+0.151)^2+'DCF Model'!$D$32/(1+0.151)^3+'DCF Model'!$E$32/(1+0.151)^4+'DCF Model'!$F$32/(1+0.151)^5+'DCF Model'!$B$38*1.1/(1+0.151)^5 -> 0 | F9: ='DCF Model'!$B$32/(1+0.151)^1+'DCF Model'!$C$32/(1+0.151)^2+'DCF Model'!$D$32/(1+0.151)^3+'DCF Model'!$E$32/(1+0.151)^4+'DCF Model'!$F$32/(1+0.151)^5+'DCF Model'!$B$38*1.25/(1+0.151)^5 -> 0

Sheet Scenarios
A1: Scenario Comparison
B3: Base | C3: Bull | D3: Bear
A4: Cost of Equity | B4: 0.131 | C4: 0.121 | D4: 0.145
A5: Exit P/B Multiple | B5: 0.95 | C5: 1.1 | D5: 0.7
A6: Intrinsic Value / Share | B6: 1.0154 | C6: 1.2929 | D6: 0.6636
A7: Upside / Downside | B7: -0.157 | C7: 0.073 | D7: -0.449
A8: Year-5 ROE | B8: 0.09 | C8: 0.11 | D8: 0.065
A10: Probability-Weighted IV | B10: 0.9792
A11: Probability-Weighted Upside | B11: -0.187
A12: Weights (Bull/Base/Bear) | B12: 0.25/0.45/0.3

Sheet Bank Metrics Quality
A1: Reported vs Underlying NPAT and ROE Reconciliation
A2: Why this model does NOT use reported Operating Cash Flow as a valuation input
A4: Period | B4: FY2021 | C4: FY2022 | D4: FY2023 | E4: FY2024 | F4: FY2025 | G4: H1-2025 | H4: H1-2026
A5: Reported NPAT (M) | B5: 87.026 | C5: 95.125 | D5: 95.868 | E5: 74.549 | F5: 38.8 | G5: 3.612 | H5: 48.8
A6: Underlying NPAT (M) | E6: 102.7 | F6: 46.9 | G6: 10.7 | H6: 46.1
A7: ROE Reported (%) | E7: 0.066 | F7: 0.032 | G7: 0.006 | H7: 0.077
A8: ROE Underlying (%) | E8: 0.098 | F8: 0.042 | G8: 0.019 | H8: 0.073
A9: Operating Cash Flow (M) | B9: -339.478 | C9: -262.314 | D9: 42.689 | E9: 928.353 | G9: 236.579
A11: Memo: OCF is NOT free cash flow for a bank
A12: FY2024 OCF +$928.4m reflects deposit inflows outpacing loan growth that year.
A13: FY2021 OCF -$339.5m reflects the mirror-image (loan growth outpacing deposits).
A14: Neither number has any relationship to distributable value to shareholders -- this is why the model is built on ROE x book value, not FCF.
A16: Memo: FY2025 was a reset year, FY2024 was not "normal" either
A17: FY2024 reported NPAT $74.5m benefited from a period before AU-ADI integration costs and impairment cycle fully hit.
A18: FY2025 reported NPAT $38.8m (underlying $46.9m) reflects Motor/Business Finance impairments + AU integration costs -- a trough, not a run rate.
A19: 1H2026 underlying NPAT $46.1m (ROE 7.3%) shows a sharp partial recovery -- treated as the START of a recovery, not yet a new steady state.

Sheet Historical
A1: Historical Valuation Multiples
A3: Fiscal Year End (30-Jun) | B3: June Close Price | C3: BVPS | D3: P/B
A4: FY2021 | B4: 2.05 | C4: 1.3 | D4: 1.58
A5: FY2022 | B5: 2.08 | C5: 1.371 | D5: 1.52
A6: FY2023 | B6: 1.8 | C6: 1.453 | D6: 1.24
A7: FY2024 | B7: 1.07 | C7: 1.33 | D7: 0.8
A8: FY2025 | B8: 0.81 | C8: 1.296 | D8: 0.62
A10: Current (11-Aug-2026) | B10: 1.205 | C10: 1.3705 | D10: 0.879
A15: Historical Growth Rates
A16: Metric | B16: 3-Year CAGR | C16: 5-Year CAGR
A18: Revenue | B18: 0.0479 | C18: 0.0672
A19: Shareholders Equity | B19: 0.1466 | C19: 0.1173
A20: NPAT | B20: -0.2584 | C20: -0.1162
A21: EPS | B21: -0.3652
A22: Growth Divergence Warning:
A23: SEVERE divergence and the central fact of this valuation: equity 3yr CAGR is +14.66% (capital-raise-driven) while NPAT 3yr CAGR is -25.84% and EPS 3yr CAGR is -36.52% over the SAME period (FY2022-FY2025). A rapidly growing book value is not translating into proportionate profit or per-share earnings growth -- the opposite: per-share earnings power has been destroyed by dilutive raises funding a business earning sub-cost-of-equity returns. This divergence is exactly why the equity/book-value CAGR must NOT be used as a forward earnings-growth proxy here; the model instead derives forward growth from the sustainable-growth formula on projected ROE, and 1H2026's recovery to 7.3% underlying ROE is treated as the start of a partial, not complete, recovery.

Sheet Model_Info
A1: Model Provenance & Methodology Notes
A4: Ticker | B4: HGH.NZ (Heartland Group Holdings Limited)
A5: Model built by | B5: Claude agent (DCF valuation skill), per repo CLAUDE.md workflow
A6: Valuation date | B6: 2026-08-11
A7: Share price date/source | B7: NZ$1.205 from Yahoo Finance HGH.NZ chart API, fetched 2026-08-11
A8: Data vintage | B8: H1-2026 (six months to 31-Dec-2025) interim result is the latest reported book value ($1,289.0m equity). FY2025 (30-Jun-2025) is the latest confirmed period-end share count (940.559m). FY2026 full-year results are due 20-Aug-2026, AFTER this model was built -- refresh after that release.
A9: Model type | B9: Book-value / ROE compounding model discounted at Cost of Equity, NOT a free-cash-flow DCF. See valuation_philosophy in the JSON for the full rationale (bank; OCF is not FCF; no net-debt bridge; deposits are not debt).
A10: Key transaction modelled | B10: TSB Bank acquisition (~NZ$620m, announced 2-Jun-2026, targeted completion Dec-2026): ~$250m new equity (~200m new shares at $1.25) is added to the share count and book value at the start of FY27 in every scenario. Guided $34m annual synergies are haircut to ~60-70% and phased in later than guidance in the base case, reflecting the precedent of Heartland's April-2024 Australian ADI acquisition, which was followed by two years of underlying ROE below 8%.
A11: Cost of equity build-up | B11: 13.1% base case: NZ risk-free ~4.5% + equity risk premium ~6.0% x beta 1.1 (CAPM base 11.1%) + 1.0pp small-cap/illiquidity premium + 1.0pp dual-regulator/integration-execution premium. Bull 12.1%, Bear 14.5%.
A12: Central finding | B12: Underlying ROE (7.3% at 1H2026) sits well below the 13.1% cost of equity. Justified P/B = (ROE-g)/(CoE-g) computed at ~0.50x using a steady-state ~8.5% ROE, versus the current traded ~0.88x P/B. Base case intrinsic value NZ$1.0154 (-15.7% vs current NZ$1.205) is a DELIBERATE, honest conclusion that the market is pricing in more TSB-merger optimism than the base case assumes -- not a modelling error.
A13: What to refresh after FY2026 results (20-Aug-2026) | B13: 1) Actual FY2026 reported/underlying NPAT and ROE vs the >=$85m / >=7% guidance floors. 2) Actual FY2026 period-end equity and share count. 3) Any update to TSB deal terms, timing, or synergy guidance. 4) Re-run the June-2026 fiscal-year-end P/B historical data point once FY2026 book value is confirmed.
A14: Cell colour conventions | B14: Gray-shaded cells (light blue-gray, #dfe6e9) on the DCF Model sheet are INPUTS -- safe to edit and the model recalculates. White cells contain FORMULAS -- do not hardcode over them. Green cells (#00b894) are headline OUTPUTS (intrinsic value, entry price).
A15: Known limitations | B15: Share count for FY2018-FY2020 is not available in the parsed Metrics.csv, so the historical P/B table starts at FY2021. TSB deal completion is modelled as a single lump-sum event at the start of FY27 for simplicity; the actual raise/completion could occur mid-year or later if regulatory/trustee approvals slip beyond the guided December-2026 timeline.
A18: STALE DATA WARNING | B18: All figures in this workbook go stale. Re-check against the latest filings and live share price before relying on this model for a live investment decision, especially after the FY2026 results (20-Aug-2026) and any TSB deal completion/condition updates.
