Workbook

Sheet Base Case
A1: 9988.HK DCF Model - Base Case
A2: All cash flows in RMB millions unless noted. Gray cells are INPUTS. Net cash (positive) is ADDED to enterprise value.
A4: KEY INPUTS
A5: Current Stock Price (HKD) | B5: 110
A6: Shares Outstanding (HK ordinary, M) | B6: 19235
A7: Cash & Equivalents (RMB M) | B7: 131530
A8: Short-Term Investments, unrestricted (RMB M) | B8: 155236
A9: Other Treasury Investments, unrestricted (RMB M) | B9: 234058
A10: Total Debt (RMB M) | B10: 259996
A11: Net Debt / (Net Cash) (RMB M) | B11: =B10-B7-B8-B9
A12: Base Year Normalized FCF (RMB M) | B12: 120000
A13: CNY -> HKD FX Rate | B13: 1.1597
A15: WACC | B15: 0.115
A16: Terminal Growth Rate | B16: 0.03
A17: Exit EV/EBITDA Multiple (cap) | B17: 7
A18: Normalized EBITDA basis (RMB M, avg FY23-25) | B18: 189901
A20: GROWTH ASSUMPTIONS | B20: Year 1 | C20: Year 2 | D20: Year 3 | E20: Year 4 | F20: Year 5
A21: FCF Growth Rate | B21: 0.22 | C21: 0.18 | D21: 0.14 | E21: 0.1 | F21: 0.07
A22: EBITDA Growth Rate (60% of FCF growth) | B22: =B21*0.6 | C22: =C21*0.6 | D22: =D21*0.6 | E22: =E21*0.6 | F22: =F21*0.6
A24: PROJECTIONS (RMB Millions)
C25: Year 1 | D25: Year 2 | E25: Year 3 | F25: Year 4 | G25: Year 5
A26: Free Cash Flow | B26: =B12 | C26: =B26*(1+B21) | D26: =C26*(1+C21) | E26: =D26*(1+D21) | F26: =E26*(1+E21) | G26: =F26*(1+F21)
A27: Discount Factor (WACC) | C27: =1/(1+$B$15)^1 | D27: =1/(1+$B$15)^2 | E27: =1/(1+$B$15)^3 | F27: =1/(1+$B$15)^4 | G27: =1/(1+$B$15)^5
A28: PV of FCF | C28: =C26*C27 | D28: =D26*D27 | E28: =E26*E27 | F28: =F26*F27 | G28: =G26*G27
A29: Normalized EBITDA | B29: =B18 | C29: =B29*(1+B22) | D29: =C29*(1+C22) | E29: =D29*(1+D22) | F29: =E29*(1+E22) | G29: =F29*(1+F22)
A31: VALUATION (RMB Millions)
A32: Sum of PV of FCF | B32: =SUM(C28:G28)
A33: Terminal FCF (Year 5 * (1+g)) | B33: =G26*(1+$B$16)
A34: Terminal Value - Gordon Growth | B34: =B33/($B$15-$B$16)
A35: Terminal Value - Exit Multiple (Y5 EBITDA x multiple) | B35: =G29*$B$17
A36: Terminal Value Used (MIN of the two) | B36: =MIN(B34,B35)
A37: PV of Terminal Value | B37: =B36*G27
A38: Enterprise Value | B38: =B32+B37
A39: Add: Net Cash (subtract if Net Debt positive) | B39: =-B11
A40: Equity Value (RMB M) | B40: =B38+B39
A41: Intrinsic Value / Share (RMB) | B41: =B40/B6
A42: INTRINSIC VALUE / SHARE (HKD) | B42: =B41*B13
A44: ENTRY PRICE (15% IRR Target)
A45: PV of Yrs 1-5 FCF @15% (RMB M) | B45: =NPV(0.15,C26:G26)
A46: PV of Terminal Value @15% (RMB M) | B46: =B34/(1.15^5)
...

Sheet Bull Case
A1: 9988.HK DCF Model - Bull Case
A2: All cash flows in RMB millions unless noted. Gray cells are INPUTS. Net cash (positive) is ADDED to enterprise value.
A4: KEY INPUTS
A5: Current Stock Price (HKD) | B5: 110
A6: Shares Outstanding (HK ordinary, M) | B6: 19235
A7: Cash & Equivalents (RMB M) | B7: 131530
A8: Short-Term Investments, unrestricted (RMB M) | B8: 155236
A9: Other Treasury Investments, unrestricted (RMB M) | B9: 234058
A10: Total Debt (RMB M) | B10: 259996
A11: Net Debt / (Net Cash) (RMB M) | B11: =B10-B7-B8-B9
A12: Base Year Normalized FCF (RMB M) | B12: 138000
A13: CNY -> HKD FX Rate | B13: 1.1597
A15: WACC | B15: 0.105
A16: Terminal Growth Rate | B16: 0.035
A17: Exit EV/EBITDA Multiple (cap) | B17: 9.5
A18: Normalized EBITDA basis (RMB M, avg FY23-25) | B18: 189901
A20: GROWTH ASSUMPTIONS | B20: Year 1 | C20: Year 2 | D20: Year 3 | E20: Year 4 | F20: Year 5
A21: FCF Growth Rate | B21: 0.28 | C21: 0.23 | D21: 0.18 | E21: 0.14 | F21: 0.1
A22: EBITDA Growth Rate (60% of FCF growth) | B22: =B21*0.6 | C22: =C21*0.6 | D22: =D21*0.6 | E22: =E21*0.6 | F22: =F21*0.6
A24: PROJECTIONS (RMB Millions)
C25: Year 1 | D25: Year 2 | E25: Year 3 | F25: Year 4 | G25: Year 5
A26: Free Cash Flow | B26: =B12 | C26: =B26*(1+B21) | D26: =C26*(1+C21) | E26: =D26*(1+D21) | F26: =E26*(1+E21) | G26: =F26*(1+F21)
A27: Discount Factor (WACC) | C27: =1/(1+$B$15)^1 | D27: =1/(1+$B$15)^2 | E27: =1/(1+$B$15)^3 | F27: =1/(1+$B$15)^4 | G27: =1/(1+$B$15)^5
A28: PV of FCF | C28: =C26*C27 | D28: =D26*D27 | E28: =E26*E27 | F28: =F26*F27 | G28: =G26*G27
A29: Normalized EBITDA | B29: =B18 | C29: =B29*(1+B22) | D29: =C29*(1+C22) | E29: =D29*(1+D22) | F29: =E29*(1+E22) | G29: =F29*(1+F22)
A31: VALUATION (RMB Millions)
A32: Sum of PV of FCF | B32: =SUM(C28:G28)
A33: Terminal FCF (Year 5 * (1+g)) | B33: =G26*(1+$B$16)
A34: Terminal Value - Gordon Growth | B34: =B33/($B$15-$B$16)
A35: Terminal Value - Exit Multiple (Y5 EBITDA x multiple) | B35: =G29*$B$17
A36: Terminal Value Used (MIN of the two) | B36: =MIN(B34,B35)
A37: PV of Terminal Value | B37: =B36*G27
A38: Enterprise Value | B38: =B32+B37
A39: Add: Net Cash (subtract if Net Debt positive) | B39: =-B11
A40: Equity Value (RMB M) | B40: =B38+B39
A41: Intrinsic Value / Share (RMB) | B41: =B40/B6
A42: INTRINSIC VALUE / SHARE (HKD) | B42: =B41*B13
A44: ENTRY PRICE (15% IRR Target)
A45: PV of Yrs 1-5 FCF @15% (RMB M) | B45: =NPV(0.15,C26:G26)
A46: PV of Terminal Value @15% (RMB M) | B46: =B34/(1.15^5)
...

Sheet Bear Case
A1: 9988.HK DCF Model - Bear Case
A2: All cash flows in RMB millions unless noted. Gray cells are INPUTS. Net cash (positive) is ADDED to enterprise value.
A4: KEY INPUTS
A5: Current Stock Price (HKD) | B5: 110
A6: Shares Outstanding (HK ordinary, M) | B6: 19235
A7: Cash & Equivalents (RMB M) | B7: 131530
A8: Short-Term Investments, unrestricted (RMB M) | B8: 155236
A9: Other Treasury Investments, unrestricted (RMB M) | B9: 234058
A10: Total Debt (RMB M) | B10: 259996
A11: Net Debt / (Net Cash) (RMB M) | B11: =B10-B7-B8-B9
A12: Base Year Normalized FCF (RMB M) | B12: 68000
A13: CNY -> HKD FX Rate | B13: 1.1597
A15: WACC | B15: 0.13
A16: Terminal Growth Rate | B16: 0.025
A17: Exit EV/EBITDA Multiple (cap) | B17: 4.5
A18: Normalized EBITDA basis (RMB M, avg FY23-25) | B18: 189901
A20: GROWTH ASSUMPTIONS | B20: Year 1 | C20: Year 2 | D20: Year 3 | E20: Year 4 | F20: Year 5
A21: FCF Growth Rate | B21: 0.06 | C21: 0.05 | D21: 0.04 | E21: 0.03 | F21: 0.02
A22: EBITDA Growth Rate (60% of FCF growth) | B22: =B21*0.6 | C22: =C21*0.6 | D22: =D21*0.6 | E22: =E21*0.6 | F22: =F21*0.6
A24: PROJECTIONS (RMB Millions)
C25: Year 1 | D25: Year 2 | E25: Year 3 | F25: Year 4 | G25: Year 5
A26: Free Cash Flow | B26: =B12 | C26: =B26*(1+B21) | D26: =C26*(1+C21) | E26: =D26*(1+D21) | F26: =E26*(1+E21) | G26: =F26*(1+F21)
A27: Discount Factor (WACC) | C27: =1/(1+$B$15)^1 | D27: =1/(1+$B$15)^2 | E27: =1/(1+$B$15)^3 | F27: =1/(1+$B$15)^4 | G27: =1/(1+$B$15)^5
A28: PV of FCF | C28: =C26*C27 | D28: =D26*D27 | E28: =E26*E27 | F28: =F26*F27 | G28: =G26*G27
A29: Normalized EBITDA | B29: =B18 | C29: =B29*(1+B22) | D29: =C29*(1+C22) | E29: =D29*(1+D22) | F29: =E29*(1+E22) | G29: =F29*(1+F22)
A31: VALUATION (RMB Millions)
A32: Sum of PV of FCF | B32: =SUM(C28:G28)
A33: Terminal FCF (Year 5 * (1+g)) | B33: =G26*(1+$B$16)
A34: Terminal Value - Gordon Growth | B34: =B33/($B$15-$B$16)
A35: Terminal Value - Exit Multiple (Y5 EBITDA x multiple) | B35: =G29*$B$17
A36: Terminal Value Used (MIN of the two) | B36: =MIN(B34,B35)
A37: PV of Terminal Value | B37: =B36*G27
A38: Enterprise Value | B38: =B32+B37
A39: Add: Net Cash (subtract if Net Debt positive) | B39: =-B11
A40: Equity Value (RMB M) | B40: =B38+B39
A41: Intrinsic Value / Share (RMB) | B41: =B40/B6
A42: INTRINSIC VALUE / SHARE (HKD) | B42: =B41*B13
A44: ENTRY PRICE (15% IRR Target)
A45: PV of Yrs 1-5 FCF @15% (RMB M) | B45: =NPV(0.15,C26:G26)
A46: PV of Terminal Value @15% (RMB M) | B46: =B34/(1.15^5)
...

Sheet Summary
A1: 9988.HK DCF Summary (HKD per HK Ordinary Share)
A2: Alibaba Group Holding Limited - Hong Kong Primary Listing (1 ADS = 8 ordinary shares). REVISED 2026-07-26: net-cash basis, re-synced to corrected BABA scenario set.
A4: Current Price (HKD) | B4: ='Base Case'!B5
B6: Bear | C6: Base | D6: Bull
A7: Intrinsic Value / Share | B7: ='Bear Case'!B42 | C7: ='Base Case'!B42 | D7: ='Bull Case'!B42
A8: Upside vs Current | B8: ='Bear Case'!B52 | C8: ='Base Case'!B52 | D8: ='Bull Case'!B52
A9: Entry Price (15% IRR) | B9: ='Bear Case'!B49 | C9: ='Base Case'!B49 | D9: ='Bull Case'!B49
A10: WACC | B10: ='Bear Case'!B15 | C10: ='Base Case'!B15 | D10: ='Bull Case'!B15
A11: Terminal Value % of EV | B11: ='Bear Case'!B55 | C11: ='Base Case'!B55 | D11: ='Bull Case'!B55
A13: PROBABILITY WEIGHTED VALUE
A14: Weight | B14: 0.25 | C14: 0.5 | D14: 0.25
A15: Weighted Intrinsic Value (HKD) | B15: =B7*B14+C7*C14+D7*D14
A16: Upside from Current | B16: =(B15-B4)/B4
A18: FX Rates Used
A19: USD/CNY | B19: 6.7617
A20: USD/HKD | B20: 7.8414
A21: CNY/HKD (derived) | B21: =B20/B19
A23: Net Cash Position (RMB M) | B23: =-'Base Case'!B11
A24: Shares Outstanding (HK ordinary, M) | B24: ='Base Case'!B6

Sheet Sensitivity
A1: Sensitivity Analysis - Base Case
A2: Intrinsic Value (HKD/share) by WACC & Terminal Growth
A3: Static values from validated model (exit-multiple cap binding across the full tested range; 7.0x cap, RMB 260,828M net cash)
A5: WACC \ Term G | B5: 0.02 | C5: 0.025 | D5: 0.03 | E5: 0.035 | F5: 0.04
A6: 0.095 | B6: 135.93 | C6: 135.93 | D6: 135.93 | E6: 135.93 | F6: 135.93
A7: 0.105 | B7: 131.34 | C7: 131.34 | D7: 131.34 | E7: 131.34 | F7: 131.34
A8: 0.115 | B8: 126.98 | C8: 126.98 | D8: 126.98 | E8: 126.98 | F8: 126.98
A9: 0.125 | B9: 122.84 | C9: 122.84 | D9: 122.84 | E9: 122.84 | F9: 122.84
A10: 0.135 | B10: 118.9 | C10: 118.9 | D10: 118.9 | E10: 118.9 | F10: 118.9

Sheet Historical
A1: Historical Growth Rates
A3: Metric | B3: 3-Year CAGR | C3: 5-Year CAGR
A4: Revenue | B4: 0.0562 | C4: 0.0737
A5: EPS | B5: 0.1684 | C5: -0.0524
A6: Equity (Book Value) | B6: 0.0234 | C6: 0.025
A7: FCF | B7: N/A (neg. FY26) | C7: N/A (neg. FY26)
A9: Selected Growth Rate: | B9: 0.025
A10: Source: | B10: equity_5yr_cagr
A11: Divergence Warning: | B11: Equity 5yr CAGR (2.5%) is far below Revenue 5yr CAGR (7.4%) and EPS 3yr CAGR (16.8%). Divergence is explained by: (1) massive share buybacks reducing equity per share denominator effects and reinvestment mix, (2) FY2026 investment cycle compressing retained earnings, (3) a corrected FY2017 equity base (278,799 RMB M, down from a previously overstated 566,578) that raises the LONGER-horizon (9yr, FY2017-FY2026) equity CAGR to 16.0% -- but this window is dominated by the initial low base and is not representative of steady-state compounding. Per the trough-FCF framework, equity CAGR is not used as the primary growth anchor -- FCF recovery trajectory is modeled explicitly by scenario. FCF CAGR is flagged N/A due to negative terminal year. (Identical to BABA_DCF.json -- company-level fundamentals, listing-venue-agnostic.)
A13: Historical FY-End Multiples (9988.HK, March close) — EV/EBITDA net-cash corrected 2026-07-26
A14: FY | B14: P/E | C14: P/B | D14: EV/EBITDA | E14: P/S
A16: FY2020 (excl-hypergrowth) | B16: 24.62 | C16: 4.86 | D16: 21.8 | E16: 8.55
A17: FY2021 (excl-hypergrowth) | B17: 27.15 | C17: 4.35 | D17: 19.07 | E17: 5.55
A18: FY2022 | B18: 30.39 | C18: 1.98 | D18: 9.94 | E18: 2.33
A19: FY2023 | B19: 25.55 | C19: 1.87 | D19: 8.26 | E19: 2.12
A20: FY2024 | B20: 16.71 | C20: 1.35 | D20: 4.62 | E20: 1.37
A21: FY2025 | B21: 17.89 | C21: 2.3 | D21: 9.64 | E21: 2.25
A22: FY2026 (trough-EBITDA outlier) | B22: 19.66 | C22: 1.96 | D22: 16.02 | E22: 1.97
A24: Note: EV/EBITDA series corrected 2026-07-26 to net full unrestricted
A25: investment portfolio (cash + ST investments + other treasury), not cash alone.
A26: FY2017-18 excluded above (ST-investment data unavailable, outside calibration window).
