Workbook

Sheet Model_Info
A1: MKR.NZ (Manuka Resources Ltd) - DCF Model
A3: Version | B3: 1.0 - fresh build (no prior DCF existed for this ticker)
A4: Built by | B4: dcf-analyst agent (Claude Sonnet 5), 2026-08-20, at user request
A5: Supersedes | B5: Nothing - first DCF for MKR.NZ
A7: DATA VINTAGE
A8: Price (quote, MKR.NZ) | B8: NZ$0.095, Yahoo Finance regularMarketTime 2026-08-19T23:41:14Z
A9: Price (ASX primary, MKR.AX) | B9: A$0.082, Yahoo Finance, 2026-08-20 (cross-check only, not used as current_price)
A10: FX AUD/NZD | B10: 1.1958, Yahoo Finance AUDNZD=X spot, 2026-08-20
A11: FX AUD/USD | B11: 0.7115, Yahoo Finance AUDUSD=X spot, 2026-08-20 (used to convert the USD-denominated Nebari facility)
A12: Balance sheet | B12: 31-Dec-2025 (H1FY2026 interim report, ASX/NZX, released 16-Mar-2026) for the raw borrowings/cash lines; net debt ANCHOR then rolled forward for the Nebari facility's second tranche (drawn 26-Jun-2026, post-interim) - see Actuals tab and inputs.net_debt_methodology in the JSON for the full derivation
A13: Share count | B13: 1,404,559,716 shares on issue at 31-Dec-2025 (H1FY2026 note 15) PLUS 73,400,000 shares issued on post-period option exercise (H1FY2026 note 20(b), subsequent events) = 1,477,959,716 fully diluted issued count used throughout. NOT included: 209.6m remaining unlisted options (~8c wtd avg strike, roughly at-the-money) or 36.4m Nebari lender warrants (A$0.2004 strike, ~144% out-of-the-money) - both are dilution risk noted but not modelled into the base share count.
A14: Guidance | B14: 30-Jan-2026 ASX release: updated 10-year Cobar Basin mine plan (avg EBITDA A$127m p.a., NPV8 A$805m, IRR ~1,092%, C1 cost A$34.4/oz Ag incl. Au credits, restart capex A$26.6m). H1FY2026 interim report (16-Mar-2026): first gold revenue targeted mid-Jul-2026, first silver targeted Sep-2026 quarter.
A16: METHODOLOGY CHOICES
A17: Model chosen | B17: Owner-FCF DCF (component build), scenario-weighted - per .claude/skills/dcf-methods/SKILL.md routing table row 'Operating company, non-US or cyclical' + section 7 adaptations. NOT a distressed/receivership asset waterfall (company is a funded, going, restarting operation, not in receivership) and NOT a pure NAV/asset play (Taranaki VTM assigned zero value, not driving the valuation).
A18: Why not historical-CAGR extrapolation | B18: Both revenue and FCF CAGRs are undefined/meaningless: FY2025 and H1FY2026 revenue is zero (both mines on care & maintenance). Forward build instead uses a PHYSICAL PRODUCTION RAMP anchored to management's own 10-year mine plan, heavily haircut for execution/going-concern risk.
A19: Mature EBITDA haircuts vs management guidance (A$127m/yr average) | B19: Base = 40% (A$50.8m), Bull = 65% (A$82.6m), Bear = 15% (A$19.1m). Haircut reflects: repeated history of slipped restarts (2022 Wonawinta trial ended early, Mt Boppy halted Q1 2024), one prior upward capex revision (A$18.9m->A$26.6m), 39% Inferred-Resource content in the 10.9Mt mine plan (only 6.9Mt/63% Reserve-backed), and near-record gold/silver prices baked into management's own economics that may not persist.
A20: Taranaki VTM (TTR) | B20: Assigned ZERO value in every scenario. Fast-track marine consent application WITHDRAWN 19-Feb-2026 after a draft decline (4-Feb-2026) - the SECOND failed NZ marine-consent attempt for this project (after a 2021 Supreme Court-driven refusal). No alternative approval pathway disclosed.
A21: WACC = 19% (AUD) | B21: Stack: ~4.0% AUD risk-free + ~5.5% small-cap ERP + ~3.0% micro-cap illiquidity + ~2.5% single-asset/single-region concentration + ~4.0% going-concern/financial-distress premium. This DOUBLE-CHARGES risk relative to section 7(f) 'charge risk once' by design: solvency risk (survival) is charged in WACC + probability weights; execution/commodity risk (scale once surviving) is charged in the EBITDA/margin/capex haircuts. Documented exception, not an oversight - see Assumptions tab.
A22: Terminal value | B22: MAX(0, MIN(Gordon, 6x terminal FCF)). Low 6x cap (vs the usual 20x) because this is a reserve-depleting single-asset miner (10.9Mt mine plan, only 63% Reserve-backed), not a perpetual compounder.
A23: SBC | B23: Verified structurally nil at this pre-revenue restart scale. Kept explicit at 0% (section 7(e)) rather than deleted; house/street band collapses to a point, band_position reported as null, not 0%.
A24: NCI / leases | B24: Not applicable - 100% ownership of all three assets (no NCI); no material IFRS16 lease book at this scale.
A25: Net debt anchor | B25: US$30m Nebari facility fully drawn (completed 26-Jun-2026) @ AUDUSD 0.7115 = A$42.16m, LESS the most recent disclosed cash figure of A$11.1m ('at time of writing', H1FY2026 report dated 16-Mar-2026) = A$31.06m. This is a DOCUMENTED ESTIMATE (no FY2026 annual or later quarterly filed yet at the valuation date), deliberately more conservative than the stale 31-Dec-2025 net debt of A$21.49m, which pre-dates the full Nebari drawdown.
A26: Entry price > intrinsic value (unusual) | B26: WACC (19%) EXCEEDS the 15% hurdle rate used for entry price. When WACC > hurdle, the house's own risk-adjusted fair value is HARSHER than what a 15%-hurdle investor requires, so entry price (discounted at the lower 15%) comes out ABOVE intrinsic value. Same relationship documented for CDI.NZ in the user's MEMORY.md (17% WACC > 15% hurdle).
A28: SCENARIO DRIVER JUDGMENT | B28: All scenario drivers (mature EBITDA %, ramp years, margins, tax ramps, capex schedules, probability weights) are the agent's judgment calls made 2026-08-20 at the user's explicit instruction to haircut management's numbers heavily and reflect execution risk. They are NOT sourced from any third-party analyst estimate.
A30: REFRESH TRIGGERS | B30: Refresh this model when: (1) the FY2026 annual report or any subsequent quarterly is filed - replace the net_debt estimate with the actual filed balance sheet; (2) first gold/silver revenue is actually recognised - compare actual ramp to the modelled ramp; (3) any Taranaki VTM regulatory development occurs (new consenting pathway announced or ruled out); (4) a material equity raise or further dilution event occurs - refresh the share count; (5) gold/silver prices move materially from current near-record levels - the mature EBITDA assumption embeds today's elevated prices.
A32: CELL COLOUR LEGEND
A33: Blue fill | B33: Hardcoded input (actuals, or a documented estimate/anchor)
A34: Yellow fill | B34: Key driver / lever - the four hardcoded rows per DCF tab (growth/margin proxy, EBITDA margin, SBC%, tax rate)
A35: Black text, white fill | B35: Formula - flows from drivers, do not hardcode
A36: Green text | B36: Cross-sheet link
A38: STALE-DATA WARNING | B38: All figures in this workbook go stale. The share count, net debt, and mine-plan economics in particular should be treated as approximate beyond a few months from the valuation date given how fast this capital structure and operational status have been changing.

Sheet Actuals
A1: MKR.NZ - Actuals & Current Position (all AUD millions unless noted)
A3: Fiscal year end | B3: 30 June
A4: Reporting currency | B4: AUD
A5: Quote currency (MKR.NZ) | B5: NZD
A7: Period | B7: FY2020 | C7: FY2021 | D7: FY2022 | E7: FY2023 | F7: FY2024 | G7: FY2025 | H7: H1-2026
A8: Revenue | B8: 9.261798 | C8: 43.752567 | D8: 53.271499 | E8: 9.899903 | F8: 15.195323 | G8: 0 | H8: 0
A9: Net income (loss) | B9: -4.552843 | C9: -2.895244 | D9: 5.28142 | E9: -26.342019 | F9: -18.234635 | G9: -16.876465 | H9: -12.875283
A10: Shareholders' equity | B10: 36.427215 | C10: 35.245377 | D10: 13.573765 | E10: 19.941974 | F10: 17.010151 | G10: 2.295736 | H10: 22.990165
A11: Free cash flow (reported) | B11: -12.975469 | C11: -7.662507 | D11: -0.527428 | E11: -15.785631 | F11: -8.652198 | G11: -5.463057 | H11: -8.533104
A12: Shares outstanding (period-end, CSV - STALE, see note row 20) | B12: 249.35371 | C12: 269.35371 | D12: 286.02038 | E12: 562.52006 | F12: 779.76767 | G12: 1065.3849 | H12: 1075.9913
A13: Cash & equivalents | B13: 1.50904 | C13: 1.018035 | D13: 1.160615 | E13: 0.265833 | F13: 2.12535 | G13: 0.968645 | H13: 2.439885
A14: Total debt | B14: 1.50904 | C14: 1.018035 | D14: 13.111178 | E14: 24.779748 | F14: 28.389352 | G14: 40.376654 | H14: 23.933377
A16: Source: research/MKR.NZ/Reports/MKR.NZ_Metrics.csv (core_metrics, AUD millions)
A18: CURRENT POSITION (post-H1FY2026, reconciled)
A19: Shares on issue at 31-Dec-2025 (H1FY26 note 15) | B19: 1404.5597
A20: + post-period option exercises (note 20(b)) | B20: 73.4
A21: Fully diluted shares used in DCF (m) | B21: =B19+B20
A23: Nebari facility (US$m, fully drawn 26-Jun-2026) | B23: 30
A24: AUD/USD spot (2026-08-20) | B24: 0.7115
A25: Nebari facility in AUD (A$m) | B25: =B23/B24
A26: Cash 'at time of writing' 16-Mar-2026 (H1FY26 report, A$m) | B26: 11.1
A27: Net debt anchor used in DCF (A$m) | B27: =B25-B26
A29: Current price MKR.NZ (NZD) | B29: 0.095
A30: AUD/NZD spot (2026-08-20) | B30: 1.1958
A31: Current price MKR.AX (AUD, cross-check) | B31: 0.082
A32: Current market cap (A$m) | B32: =B21*0.082

Sheet Assumptions
A1: Global Assumptions
A3: WACC (AUD) | B3: 0.19 | C3: Going-concern-loaded stack - see Model_Info
A4: Terminal cap multiple (x terminal FCF) | B4: 6 | C4: Low cap: reserve-depleting single-asset miner, not a perpetual compounder
A5: D&A % of revenue (mature) | C5: Set per-scenario on each DCF tab, row 12 driver-linked
A6: Fully diluted shares (m) | B6: =Actuals!B21
A7: Net debt (A$m) | B7: =Actuals!B27
A8: AUD/NZD FX rate | B8: =Actuals!B30
A9: Current price (NZD) | B9: =Actuals!B29
A10: Hurdle rate (entry price) | B10: 0.15 | C10: House standard 15% IRR hurdle
A12: SCENARIO: terminal growth & probability weight
A13: Scenario | B13: Terminal growth | C13: Probability weight
A14: Bear | B14: 0.01 | C14: 0.35
A15: Base | B15: 0.015 | C15: 0.45
A16: Bull | B16: 0.02 | C16: 0.2
A17: Sum of weights (check) | C17: =SUM(C14:C16)
A19: SCENARIO NARRATIVES
A20: Base | B20: Mature run-rate EBITDA = 40% of management's own 10-year average (A$50.8m of A$127m/yr). 3-year production ramp FY27-29. Reflects a restart that broadly succeeds but at materially lower throughput/recovery/prices than management's mine-plan case, with modest reserve-life taper from year 8 as the 39%-Inferred resource base is only partially converted.
A21: Bull | B21: Mature run-rate EBITDA = 65% of guidance (A$82.6m). Faster 2-year ramp (on-time, on-budget restart, desliming circuit performs as designed first time). Sustained near-record gold/silver prices through the ramp. Still well below management's own number - the bull case requires several independent things to go right simultaneously (execution + resource conversion + prices), which is why it is NOT modelled at management's guided A$127m.
A22: Bear | B22: Mature run-rate EBITDA = 15% of guidance (A$19.1m) - restart struggles, desliming circuit underperforms at scale (unproven), cost overruns consistent with the company's own A$18.9m->A$26.6m capex revision pattern, and gold/silver prices mean-revert from near-record levels. Equity value is FLOORED AT ZERO once net debt is applied (limited liability) - this represents effective going-concern failure / severe dilution, not merely a weaker version of the base case.

Sheet DCF_Bear
A1: MKR.NZ - Bear case DCF (A$ millions)
A3: Year | B3: FY2026A | C3: FY2027E | D3: FY2028E | E3: FY2029E | F3: FY2030E | G3: FY2031E | H3: FY2032E | I3: FY2033E | J3: FY2034E | K3: FY2035E | L3: FY2036E
A4: Year index (t) | B4: 0 | C4: 1 | D4: 2 | E4: 3 | F4: 4 | G4: 5 | H4: 6 | I4: 7 | J4: 8 | K4: 9 | L4: 10
A5: Mature run-rate EBITDA (A$m) [driver] | B5: 19.05
A6: Ramp years [driver] | B6: 4
A7: EBITDA margin (mature) [driver] | B7: 0.3
A8: Taper start year [driver] | B8: 7
A9: Taper-end EBITDA fraction [driver] | B9: 0.35
A11: Adjusted EBITDA (A$m) | B11: 0 | C11: =IF(C$4<=$B$6,$B$5*C$4/$B$6,IF(C$4<$B$8,$B$5,$B$5*(1-(1-$B$9)*(C$4-$B$8+1)/(10-$B$8+1)))) | D11: =IF(D$4<=$B$6,$B$5*D$4/$B$6,IF(D$4<$B$8,$B$5,$B$5*(1-(1-$B$9)*(D$4-$B$8+1)/(10-$B$8+1)))) | E11: =IF(E$4<=$B$6,$B$5*E$4/$B$6,IF(E$4<$B$8,$B$5,$B$5*(1-(1-$B$9)*(E$4-$B$8+1)/(10-$B$8+1)))) | F11: =IF(F$4<=$B$6,$B$5*F$4/$B$6,IF(F$4<$B$8,$B$5,$B$5*(1-(1-$B$9)*(F$4-$B$8+1)/(10-$B$8+1)))) | G11: =IF(G$4<=$B$6,$B$5*G$4/$B$6,IF(G$4<$B$8,$B$5,$B$5*(1-(1-$B$9)*(G$4-$B$8+1)/(10-$B$8+1)))) | H11: =IF(H$4<=$B$6,$B$5*H$4/$B$6,IF(H$4<$B$8,$B$5,$B$5*(1-(1-$B$9)*(H$4-$B$8+1)/(10-$B$8+1)))) | I11: =IF(I$4<=$B$6,$B$5*I$4/$B$6,IF(I$4<$B$8,$B$5,$B$5*(1-(1-$B$9)*(I$4-$B$8+1)/(10-$B$8+1)))) | J11: =IF(J$4<=$B$6,$B$5*J$4/$B$6,IF(J$4<$B$8,$B$5,$B$5*(1-(1-$B$9)*(J$4-$B$8+1)/(10-$B$8+1)))) | ... L11: =IF(L$4<=$B$6,$B$5*L$4/$B$6,IF(L$4<$B$8,$B$5,$B$5*(1-(1-$B$9)*(L$4-$B$8+1)/(10-$B$8+1))))
A12: Revenue (implied, A$m) | B12: 0 | C12: =IF($B$7=0,0,C11/$B$7) | D12: =IF($B$7=0,0,D11/$B$7) | E12: =IF($B$7=0,0,E11/$B$7) | F12: =IF($B$7=0,0,F11/$B$7) | G12: =IF($B$7=0,0,G11/$B$7) | H12: =IF($B$7=0,0,H11/$B$7) | I12: =IF($B$7=0,0,I11/$B$7) | J12: =IF($B$7=0,0,J11/$B$7) | ... L12: =IF($B$7=0,0,L11/$B$7)
A13: SBC % of revenue [driver] | B13: 0 | C13: 0 | D13: 0 | E13: 0 | F13: 0 | G13: 0 | H13: 0 | I13: 0 | J13: 0 | K13: 0 | L13: 0
A14: SBC ($m) | B14: =-B12*B13 | C14: =-C12*C13 | D14: =-D12*D13 | E14: =-E12*E13 | F14: =-F12*F13 | G14: =-G12*G13 | H14: =-H12*H13 | I14: =-I12*I13 | ... L14: =-L12*L13
A15: Owner EBITDA ($m) | B15: =B11+B14 | C15: =C11+C14 | D15: =D11+D14 | E15: =E11+E14 | F15: =F11+F14 | G15: =G11+G14 | H15: =H11+H14 | I15: =I11+I14 | ... L15: =L11+L14
A16: D&A % of revenue [driver] | B16: 0.12 | C16: =$B$16 | D16: =$B$16 | E16: =$B$16 | F16: =$B$16 | G16: =$B$16 | H16: =$B$16 | I16: =$B$16 | J16: =$B$16 | ... L16: =$B$16
A17: D&A ($m) | B17: =-B12*B16 | C17: =-C12*C16 | D17: =-D12*D16 | E17: =-E12*E16 | F17: =-F12*F16 | G17: =-G12*G16 | H17: =-H12*H16 | I17: =-I12*I16 | ... L17: =-L12*L16
A18: EBIT, SBC expensed ($m) | B18: =B15+B17 | C18: =C15+C17 | D18: =D15+D17 | E18: =E15+E17 | F18: =F15+F17 | G18: =G15+G17 | H18: =H15+H17 | I18: =I15+I17 | ... L18: =L15+L17
A19: Cash tax rate [driver] | B19: 0 | C19: 0 | D19: 0 | E19: 0 | F19: 0 | G19: 0 | H19: 0 | I19: 0 | J19: 0 | K19: 0 | L19: 0
A20: NOPAT ($m) | B20: =B18*(1-B19) | C20: =C18*(1-C19) | D20: =D18*(1-D19) | E20: =E18*(1-E19) | F20: =F18*(1-F19) | G20: =G18*(1-G19) | H20: =H18*(1-H19) | I20: =I18*(1-I19) | ... L20: =L18*(1-L19)
A21: add back D&A ($m) | B21: =-B17 | C21: =-C17 | D21: =-D17 | E21: =-E17 | F21: =-F17 | G21: =-G17 | H21: =-H17 | I21: =-I17 | ... L21: =-L17
A22: Capex % revenue (mature) [driver] | B22: 0.16
A23: Restart capex override, yr1 (A$m) [driver] | B23: 22
A24: Restart capex override, yr2 (A$m) [driver] | B24: 12
A25: less capex ($m) | B25: =-B12*$B$22 | C25: =-$B$23 | D25: =-$B$24 | E25: =-E12*$B$22 | F25: =-F12*$B$22 | G25: =-G12*$B$22 | H25: =-H12*$B$22 | I25: =-I12*$B$22 | J25: =-J12*$B$22 | K25: =-K12*$B$22 | L25: =-L12*$B$22
A26: WC capture rate [driver] | B26: 0.18
A27: add/(less) working capital ($m) | B27: 0 | C27: =-$B$26*MAX(0,C12-B12) | D27: =-$B$26*MAX(0,D12-C12) | E27: =-$B$26*MAX(0,E12-D12) | F27: =-$B$26*MAX(0,F12-E12) | G27: =-$B$26*MAX(0,G12-F12) | H27: =-$B$26*MAX(0,H12-G12) | I27: =-$B$26*MAX(0,I12-H12) | J27: =-$B$26*MAX(0,J12-I12) | ... L27: =-$B$26*MAX(0,L12-K12)
A28: Unlevered owner FCF ($m) | B28: =B20+B21+B25+B27 | C28: =C20+C21+C25+C27 | D28: =D20+D21+D25+D27 | E28: =E20+E21+E25+E27 | F28: =F20+F21+F25+F27 | G28: =G20+G21+G25+G27 | H28: =H20+H21+H25+H27 | I28: =I20+I21+I25+I27 | ... L28: =L20+L21+L25+L27
A29: Discount factor | B29: =1/(1+Assumptions!$B$3)^B$4 | C29: =1/(1+Assumptions!$B$3)^C$4 | D29: =1/(1+Assumptions!$B$3)^D$4 | E29: =1/(1+Assumptions!$B$3)^E$4 | F29: =1/(1+Assumptions!$B$3)^F$4 | G29: =1/(1+Assumptions!$B$3)^G$4 | H29: =1/(1+Assumptions!$B$3)^H$4 | I29: =1/(1+Assumptions!$B$3)^I$4 | ... L29: =1/(1+Assumptions!$B$3)^L$4
A30: PV of FCF ($m) | B30: =B28*B29 | C30: =C28*C29 | D30: =D28*D29 | E30: =E28*E29 | F30: =F28*F29 | G30: =G28*G29 | H30: =H28*H29 | I30: =I28*I29 | ... L30: =L28*L29
A32: Memo: implied owner-FCF margin | B32: =IF(B12=0,"n/a",B28/B12) | C32: =IF(C12=0,"n/a",C28/C12) | D32: =IF(D12=0,"n/a",D28/D12) | E32: =IF(E12=0,"n/a",E28/E12) | F32: =IF(F12=0,"n/a",F28/F12) | G32: =IF(G12=0,"n/a",G28/G12) | H32: =IF(H12=0,"n/a",H28/H12) | I32: =IF(I12=0,"n/a",I28/I12) | ... L32: =IF(L12=0,"n/a",L28/L12)
A35: VALUATION
A36: Sum of PV of FCF (yr1-10) | B36: =SUM(C30:L30)
A37: Terminal growth (link) | B37: =Assumptions!B14
A38: Terminal FCF (yr10 * (1+g)) | B38: =L28*(1+B37)
A39: Gordon TV | B39: =IF(Assumptions!$B$3>B37,B38/(Assumptions!$B$3-B37),"n/a")
A40: Cap TV (=cap x yr10 FCF) | B40: =Assumptions!$B$4*L28
A41: TV used = MAX(0,MIN(Gordon,cap)) | B41: =MAX(0,MIN(IF(ISNUMBER(B39),B39,B40),B40))
A42: Implied exit multiple (TV/yr10 FCF) | B42: =IF(L28=0,"n/a",B41/L28)
A43: PV of TV | B43: =B41*L29
A44: Enterprise value | B44: =B36+B43
A45: less: net debt (link) | B45: =-Assumptions!$B$7
...

Sheet DCF_Base
A1: MKR.NZ - Base case DCF (A$ millions)
A3: Year | B3: FY2026A | C3: FY2027E | D3: FY2028E | E3: FY2029E | F3: FY2030E | G3: FY2031E | H3: FY2032E | I3: FY2033E | J3: FY2034E | K3: FY2035E | L3: FY2036E
A4: Year index (t) | B4: 0 | C4: 1 | D4: 2 | E4: 3 | F4: 4 | G4: 5 | H4: 6 | I4: 7 | J4: 8 | K4: 9 | L4: 10
A5: Mature run-rate EBITDA (A$m) [driver] | B5: 50.8
A6: Ramp years [driver] | B6: 3
A7: EBITDA margin (mature) [driver] | B7: 0.42
A8: Taper start year [driver] | B8: 8
A9: Taper-end EBITDA fraction [driver] | B9: 0.55
A11: Adjusted EBITDA (A$m) | B11: 0 | C11: =IF(C$4<=$B$6,$B$5*C$4/$B$6,IF(C$4<$B$8,$B$5,$B$5*(1-(1-$B$9)*(C$4-$B$8+1)/(10-$B$8+1)))) | D11: =IF(D$4<=$B$6,$B$5*D$4/$B$6,IF(D$4<$B$8,$B$5,$B$5*(1-(1-$B$9)*(D$4-$B$8+1)/(10-$B$8+1)))) | E11: =IF(E$4<=$B$6,$B$5*E$4/$B$6,IF(E$4<$B$8,$B$5,$B$5*(1-(1-$B$9)*(E$4-$B$8+1)/(10-$B$8+1)))) | F11: =IF(F$4<=$B$6,$B$5*F$4/$B$6,IF(F$4<$B$8,$B$5,$B$5*(1-(1-$B$9)*(F$4-$B$8+1)/(10-$B$8+1)))) | G11: =IF(G$4<=$B$6,$B$5*G$4/$B$6,IF(G$4<$B$8,$B$5,$B$5*(1-(1-$B$9)*(G$4-$B$8+1)/(10-$B$8+1)))) | H11: =IF(H$4<=$B$6,$B$5*H$4/$B$6,IF(H$4<$B$8,$B$5,$B$5*(1-(1-$B$9)*(H$4-$B$8+1)/(10-$B$8+1)))) | I11: =IF(I$4<=$B$6,$B$5*I$4/$B$6,IF(I$4<$B$8,$B$5,$B$5*(1-(1-$B$9)*(I$4-$B$8+1)/(10-$B$8+1)))) | J11: =IF(J$4<=$B$6,$B$5*J$4/$B$6,IF(J$4<$B$8,$B$5,$B$5*(1-(1-$B$9)*(J$4-$B$8+1)/(10-$B$8+1)))) | ... L11: =IF(L$4<=$B$6,$B$5*L$4/$B$6,IF(L$4<$B$8,$B$5,$B$5*(1-(1-$B$9)*(L$4-$B$8+1)/(10-$B$8+1))))
A12: Revenue (implied, A$m) | B12: 0 | C12: =IF($B$7=0,0,C11/$B$7) | D12: =IF($B$7=0,0,D11/$B$7) | E12: =IF($B$7=0,0,E11/$B$7) | F12: =IF($B$7=0,0,F11/$B$7) | G12: =IF($B$7=0,0,G11/$B$7) | H12: =IF($B$7=0,0,H11/$B$7) | I12: =IF($B$7=0,0,I11/$B$7) | J12: =IF($B$7=0,0,J11/$B$7) | ... L12: =IF($B$7=0,0,L11/$B$7)
A13: SBC % of revenue [driver] | B13: 0 | C13: 0 | D13: 0 | E13: 0 | F13: 0 | G13: 0 | H13: 0 | I13: 0 | J13: 0 | K13: 0 | L13: 0
A14: SBC ($m) | B14: =-B12*B13 | C14: =-C12*C13 | D14: =-D12*D13 | E14: =-E12*E13 | F14: =-F12*F13 | G14: =-G12*G13 | H14: =-H12*H13 | I14: =-I12*I13 | ... L14: =-L12*L13
A15: Owner EBITDA ($m) | B15: =B11+B14 | C15: =C11+C14 | D15: =D11+D14 | E15: =E11+E14 | F15: =F11+F14 | G15: =G11+G14 | H15: =H11+H14 | I15: =I11+I14 | ... L15: =L11+L14
A16: D&A % of revenue [driver] | B16: 0.1 | C16: =$B$16 | D16: =$B$16 | E16: =$B$16 | F16: =$B$16 | G16: =$B$16 | H16: =$B$16 | I16: =$B$16 | J16: =$B$16 | ... L16: =$B$16
A17: D&A ($m) | B17: =-B12*B16 | C17: =-C12*C16 | D17: =-D12*D16 | E17: =-E12*E16 | F17: =-F12*F16 | G17: =-G12*G16 | H17: =-H12*H16 | I17: =-I12*I16 | ... L17: =-L12*L16
A18: EBIT, SBC expensed ($m) | B18: =B15+B17 | C18: =C15+C17 | D18: =D15+D17 | E18: =E15+E17 | F18: =F15+F17 | G18: =G15+G17 | H18: =H15+H17 | I18: =I15+I17 | ... L18: =L15+L17
A19: Cash tax rate [driver] | B19: 0 | C19: 0 | D19: 0 | E19: 0.05 | F19: 0.15 | G19: 0.25 | H19: 0.28 | I19: 0.28 | J19: 0.28 | K19: 0.28 | L19: 0.28
A20: NOPAT ($m) | B20: =B18*(1-B19) | C20: =C18*(1-C19) | D20: =D18*(1-D19) | E20: =E18*(1-E19) | F20: =F18*(1-F19) | G20: =G18*(1-G19) | H20: =H18*(1-H19) | I20: =I18*(1-I19) | ... L20: =L18*(1-L19)
A21: add back D&A ($m) | B21: =-B17 | C21: =-C17 | D21: =-D17 | E21: =-E17 | F21: =-F17 | G21: =-G17 | H21: =-H17 | I21: =-I17 | ... L21: =-L17
A22: Capex % revenue (mature) [driver] | B22: 0.12
A23: Restart capex override, yr1 (A$m) [driver] | B23: 20
A24: Restart capex override, yr2 (A$m) [driver] | B24: 8
A25: less capex ($m) | B25: =-B12*$B$22 | C25: =-$B$23 | D25: =-$B$24 | E25: =-E12*$B$22 | F25: =-F12*$B$22 | G25: =-G12*$B$22 | H25: =-H12*$B$22 | I25: =-I12*$B$22 | J25: =-J12*$B$22 | K25: =-K12*$B$22 | L25: =-L12*$B$22
A26: WC capture rate [driver] | B26: 0.15
A27: add/(less) working capital ($m) | B27: 0 | C27: =-$B$26*MAX(0,C12-B12) | D27: =-$B$26*MAX(0,D12-C12) | E27: =-$B$26*MAX(0,E12-D12) | F27: =-$B$26*MAX(0,F12-E12) | G27: =-$B$26*MAX(0,G12-F12) | H27: =-$B$26*MAX(0,H12-G12) | I27: =-$B$26*MAX(0,I12-H12) | J27: =-$B$26*MAX(0,J12-I12) | ... L27: =-$B$26*MAX(0,L12-K12)
A28: Unlevered owner FCF ($m) | B28: =B20+B21+B25+B27 | C28: =C20+C21+C25+C27 | D28: =D20+D21+D25+D27 | E28: =E20+E21+E25+E27 | F28: =F20+F21+F25+F27 | G28: =G20+G21+G25+G27 | H28: =H20+H21+H25+H27 | I28: =I20+I21+I25+I27 | ... L28: =L20+L21+L25+L27
A29: Discount factor | B29: =1/(1+Assumptions!$B$3)^B$4 | C29: =1/(1+Assumptions!$B$3)^C$4 | D29: =1/(1+Assumptions!$B$3)^D$4 | E29: =1/(1+Assumptions!$B$3)^E$4 | F29: =1/(1+Assumptions!$B$3)^F$4 | G29: =1/(1+Assumptions!$B$3)^G$4 | H29: =1/(1+Assumptions!$B$3)^H$4 | I29: =1/(1+Assumptions!$B$3)^I$4 | ... L29: =1/(1+Assumptions!$B$3)^L$4
A30: PV of FCF ($m) | B30: =B28*B29 | C30: =C28*C29 | D30: =D28*D29 | E30: =E28*E29 | F30: =F28*F29 | G30: =G28*G29 | H30: =H28*H29 | I30: =I28*I29 | ... L30: =L28*L29
A32: Memo: implied owner-FCF margin | B32: =IF(B12=0,"n/a",B28/B12) | C32: =IF(C12=0,"n/a",C28/C12) | D32: =IF(D12=0,"n/a",D28/D12) | E32: =IF(E12=0,"n/a",E28/E12) | F32: =IF(F12=0,"n/a",F28/F12) | G32: =IF(G12=0,"n/a",G28/G12) | H32: =IF(H12=0,"n/a",H28/H12) | I32: =IF(I12=0,"n/a",I28/I12) | ... L32: =IF(L12=0,"n/a",L28/L12)
A35: VALUATION
A36: Sum of PV of FCF (yr1-10) | B36: =SUM(C30:L30)
A37: Terminal growth (link) | B37: =Assumptions!B15
A38: Terminal FCF (yr10 * (1+g)) | B38: =L28*(1+B37)
A39: Gordon TV | B39: =IF(Assumptions!$B$3>B37,B38/(Assumptions!$B$3-B37),"n/a")
A40: Cap TV (=cap x yr10 FCF) | B40: =Assumptions!$B$4*L28
A41: TV used = MAX(0,MIN(Gordon,cap)) | B41: =MAX(0,MIN(IF(ISNUMBER(B39),B39,B40),B40))
A42: Implied exit multiple (TV/yr10 FCF) | B42: =IF(L28=0,"n/a",B41/L28)
A43: PV of TV | B43: =B41*L29
A44: Enterprise value | B44: =B36+B43
A45: less: net debt (link) | B45: =-Assumptions!$B$7
...

Sheet DCF_Bull
A1: MKR.NZ - Bull case DCF (A$ millions)
A3: Year | B3: FY2026A | C3: FY2027E | D3: FY2028E | E3: FY2029E | F3: FY2030E | G3: FY2031E | H3: FY2032E | I3: FY2033E | J3: FY2034E | K3: FY2035E | L3: FY2036E
A4: Year index (t) | B4: 0 | C4: 1 | D4: 2 | E4: 3 | F4: 4 | G4: 5 | H4: 6 | I4: 7 | J4: 8 | K4: 9 | L4: 10
A5: Mature run-rate EBITDA (A$m) [driver] | B5: 82.55
A6: Ramp years [driver] | B6: 2
A7: EBITDA margin (mature) [driver] | B7: 0.48
A8: Taper start year [driver] | B8: 9
A9: Taper-end EBITDA fraction [driver] | B9: 0.7
A11: Adjusted EBITDA (A$m) | B11: 0 | C11: =IF(C$4<=$B$6,$B$5*C$4/$B$6,IF(C$4<$B$8,$B$5,$B$5*(1-(1-$B$9)*(C$4-$B$8+1)/(10-$B$8+1)))) | D11: =IF(D$4<=$B$6,$B$5*D$4/$B$6,IF(D$4<$B$8,$B$5,$B$5*(1-(1-$B$9)*(D$4-$B$8+1)/(10-$B$8+1)))) | E11: =IF(E$4<=$B$6,$B$5*E$4/$B$6,IF(E$4<$B$8,$B$5,$B$5*(1-(1-$B$9)*(E$4-$B$8+1)/(10-$B$8+1)))) | F11: =IF(F$4<=$B$6,$B$5*F$4/$B$6,IF(F$4<$B$8,$B$5,$B$5*(1-(1-$B$9)*(F$4-$B$8+1)/(10-$B$8+1)))) | G11: =IF(G$4<=$B$6,$B$5*G$4/$B$6,IF(G$4<$B$8,$B$5,$B$5*(1-(1-$B$9)*(G$4-$B$8+1)/(10-$B$8+1)))) | H11: =IF(H$4<=$B$6,$B$5*H$4/$B$6,IF(H$4<$B$8,$B$5,$B$5*(1-(1-$B$9)*(H$4-$B$8+1)/(10-$B$8+1)))) | I11: =IF(I$4<=$B$6,$B$5*I$4/$B$6,IF(I$4<$B$8,$B$5,$B$5*(1-(1-$B$9)*(I$4-$B$8+1)/(10-$B$8+1)))) | J11: =IF(J$4<=$B$6,$B$5*J$4/$B$6,IF(J$4<$B$8,$B$5,$B$5*(1-(1-$B$9)*(J$4-$B$8+1)/(10-$B$8+1)))) | ... L11: =IF(L$4<=$B$6,$B$5*L$4/$B$6,IF(L$4<$B$8,$B$5,$B$5*(1-(1-$B$9)*(L$4-$B$8+1)/(10-$B$8+1))))
A12: Revenue (implied, A$m) | B12: 0 | C12: =IF($B$7=0,0,C11/$B$7) | D12: =IF($B$7=0,0,D11/$B$7) | E12: =IF($B$7=0,0,E11/$B$7) | F12: =IF($B$7=0,0,F11/$B$7) | G12: =IF($B$7=0,0,G11/$B$7) | H12: =IF($B$7=0,0,H11/$B$7) | I12: =IF($B$7=0,0,I11/$B$7) | J12: =IF($B$7=0,0,J11/$B$7) | ... L12: =IF($B$7=0,0,L11/$B$7)
A13: SBC % of revenue [driver] | B13: 0 | C13: 0 | D13: 0 | E13: 0 | F13: 0 | G13: 0 | H13: 0 | I13: 0 | J13: 0 | K13: 0 | L13: 0
A14: SBC ($m) | B14: =-B12*B13 | C14: =-C12*C13 | D14: =-D12*D13 | E14: =-E12*E13 | F14: =-F12*F13 | G14: =-G12*G13 | H14: =-H12*H13 | I14: =-I12*I13 | ... L14: =-L12*L13
A15: Owner EBITDA ($m) | B15: =B11+B14 | C15: =C11+C14 | D15: =D11+D14 | E15: =E11+E14 | F15: =F11+F14 | G15: =G11+G14 | H15: =H11+H14 | I15: =I11+I14 | ... L15: =L11+L14
A16: D&A % of revenue [driver] | B16: 0.09 | C16: =$B$16 | D16: =$B$16 | E16: =$B$16 | F16: =$B$16 | G16: =$B$16 | H16: =$B$16 | I16: =$B$16 | J16: =$B$16 | ... L16: =$B$16
A17: D&A ($m) | B17: =-B12*B16 | C17: =-C12*C16 | D17: =-D12*D16 | E17: =-E12*E16 | F17: =-F12*F16 | G17: =-G12*G16 | H17: =-H12*H16 | I17: =-I12*I16 | ... L17: =-L12*L16
A18: EBIT, SBC expensed ($m) | B18: =B15+B17 | C18: =C15+C17 | D18: =D15+D17 | E18: =E15+E17 | F18: =F15+F17 | G18: =G15+G17 | H18: =H15+H17 | I18: =I15+I17 | ... L18: =L15+L17
A19: Cash tax rate [driver] | B19: 0 | C19: 0 | D19: 0 | E19: 0.1 | F19: 0.22 | G19: 0.28 | H19: 0.28 | I19: 0.28 | J19: 0.28 | K19: 0.28 | L19: 0.28
A20: NOPAT ($m) | B20: =B18*(1-B19) | C20: =C18*(1-C19) | D20: =D18*(1-D19) | E20: =E18*(1-E19) | F20: =F18*(1-F19) | G20: =G18*(1-G19) | H20: =H18*(1-H19) | I20: =I18*(1-I19) | ... L20: =L18*(1-L19)
A21: add back D&A ($m) | B21: =-B17 | C21: =-C17 | D21: =-D17 | E21: =-E17 | F21: =-F17 | G21: =-G17 | H21: =-H17 | I21: =-I17 | ... L21: =-L17
A22: Capex % revenue (mature) [driver] | B22: 0.1
A23: Restart capex override, yr1 (A$m) [driver] | B23: 18
A24: Restart capex override, yr2 (A$m) [driver] | B24: 8.6
A25: less capex ($m) | B25: =-B12*$B$22 | C25: =-$B$23 | D25: =-$B$24 | E25: =-E12*$B$22 | F25: =-F12*$B$22 | G25: =-G12*$B$22 | H25: =-H12*$B$22 | I25: =-I12*$B$22 | J25: =-J12*$B$22 | K25: =-K12*$B$22 | L25: =-L12*$B$22
A26: WC capture rate [driver] | B26: 0.12
A27: add/(less) working capital ($m) | B27: 0 | C27: =-$B$26*MAX(0,C12-B12) | D27: =-$B$26*MAX(0,D12-C12) | E27: =-$B$26*MAX(0,E12-D12) | F27: =-$B$26*MAX(0,F12-E12) | G27: =-$B$26*MAX(0,G12-F12) | H27: =-$B$26*MAX(0,H12-G12) | I27: =-$B$26*MAX(0,I12-H12) | J27: =-$B$26*MAX(0,J12-I12) | ... L27: =-$B$26*MAX(0,L12-K12)
A28: Unlevered owner FCF ($m) | B28: =B20+B21+B25+B27 | C28: =C20+C21+C25+C27 | D28: =D20+D21+D25+D27 | E28: =E20+E21+E25+E27 | F28: =F20+F21+F25+F27 | G28: =G20+G21+G25+G27 | H28: =H20+H21+H25+H27 | I28: =I20+I21+I25+I27 | ... L28: =L20+L21+L25+L27
A29: Discount factor | B29: =1/(1+Assumptions!$B$3)^B$4 | C29: =1/(1+Assumptions!$B$3)^C$4 | D29: =1/(1+Assumptions!$B$3)^D$4 | E29: =1/(1+Assumptions!$B$3)^E$4 | F29: =1/(1+Assumptions!$B$3)^F$4 | G29: =1/(1+Assumptions!$B$3)^G$4 | H29: =1/(1+Assumptions!$B$3)^H$4 | I29: =1/(1+Assumptions!$B$3)^I$4 | ... L29: =1/(1+Assumptions!$B$3)^L$4
A30: PV of FCF ($m) | B30: =B28*B29 | C30: =C28*C29 | D30: =D28*D29 | E30: =E28*E29 | F30: =F28*F29 | G30: =G28*G29 | H30: =H28*H29 | I30: =I28*I29 | ... L30: =L28*L29
A32: Memo: implied owner-FCF margin | B32: =IF(B12=0,"n/a",B28/B12) | C32: =IF(C12=0,"n/a",C28/C12) | D32: =IF(D12=0,"n/a",D28/D12) | E32: =IF(E12=0,"n/a",E28/E12) | F32: =IF(F12=0,"n/a",F28/F12) | G32: =IF(G12=0,"n/a",G28/G12) | H32: =IF(H12=0,"n/a",H28/H12) | I32: =IF(I12=0,"n/a",I28/I12) | ... L32: =IF(L12=0,"n/a",L28/L12)
A35: VALUATION
A36: Sum of PV of FCF (yr1-10) | B36: =SUM(C30:L30)
A37: Terminal growth (link) | B37: =Assumptions!B16
A38: Terminal FCF (yr10 * (1+g)) | B38: =L28*(1+B37)
A39: Gordon TV | B39: =IF(Assumptions!$B$3>B37,B38/(Assumptions!$B$3-B37),"n/a")
A40: Cap TV (=cap x yr10 FCF) | B40: =Assumptions!$B$4*L28
A41: TV used = MAX(0,MIN(Gordon,cap)) | B41: =MAX(0,MIN(IF(ISNUMBER(B39),B39,B40),B40))
A42: Implied exit multiple (TV/yr10 FCF) | B42: =IF(L28=0,"n/a",B41/L28)
A43: PV of TV | B43: =B41*L29
A44: Enterprise value | B44: =B36+B43
A45: less: net debt (link) | B45: =-Assumptions!$B$7
...

Sheet FCF_Quality
A1: FCF Quality Reconciliation - Historical (A$m)
A3: Note: MKR.NZ is pre-revenue in FY2025/H1-2026 (both mines on care & maintenance). Reported FCF is deeply
A4: negative every year shown; SBC and interest income are both verified nil, so owner FCF = reported FCF for this ticker.
A6: Period | B6: FY2020 | C6: FY2021 | D6: FY2022 | E6: FY2023 | F6: FY2024 | G6: FY2025 | H6: H1-2026
A7: Free cash flow (company definition) | B7: -12.975469 | C7: -7.662507 | D7: -0.527428 | E7: -15.785631 | F7: -8.652198 | G7: -5.463057 | H7: -8.533104
A8: less: SBC incl. equity-award taxes | B8: 0 | C8: 0 | D8: 0 | E8: 0 | F8: 0 | G8: 0 | H8: 0
A9: less: interest income | B9: 0 | C9: 0 | D9: 0 | E9: 0 | F9: 0 | G9: 0 | H9: 0
A10: Owner FCF | B10: =B7-B8-B9 | C10: =C7-C8-C9 | D10: =D7-D8-D9 | E10: =E7-E8-E9 | F10: =F7-F8-F9 | G10: =G7-G8-G9 | H10: =H7-H8-H9
A12: Memo: cash tax rate
A13: Effectively n/a - company has recorded net losses every year shown; no cash tax paid.

Sheet Valuation
A1: MKR.NZ - Valuation Summary
A3: Scenario | B3: Value/share (NZ$) | C3: Upside vs price | D3: Probability
A4: Bear | B4: =DCF_Bear!B49 | C4: =B4/Assumptions!$B$9-1 | D4: =Assumptions!C14
A5: Base | B5: =DCF_Base!B49 | C5: =B5/Assumptions!$B$9-1 | D5: =Assumptions!C15
A6: Bull | B6: =DCF_Bull!B49 | C6: =B6/Assumptions!$B$9-1 | D6: =Assumptions!C16
A8: Probability-weighted value/share (NZ$) | B8: =SUMPRODUCT(B4:B6,D4:D6)
A9: Margin of safety | B9: =1-Assumptions!$B$9/B8
A11: ENTRY PRICE (15% hurdle)
A12: NOTE: WACC (19%) > hurdle (15%) here, so entry price sits ABOVE intrinsic value - see Model_Info.
A13: Scenario | B13: Entry price (NZ$)
A14: Bear | B14: 0 | C14: hardcoded from JSON entry_price block (closed-form 15%-hurdle calc); see JSON for full derivation
A15: Base | B15: 0.0659 | C15: hardcoded from JSON entry_price block (closed-form 15%-hurdle calc); see JSON for full derivation
A16: Bull | B16: 0.1938 | C16: hardcoded from JSON entry_price block (closed-form 15%-hurdle calc); see JSON for full derivation
A17: Weighted entry price (NZ$) | B17: =SUMPRODUCT(B14:B16,D4:D6)
A19: REQUIRED-RETURN TABLE (base case, NZ$)
A20: Required return % | B20: 9% | C20: 10% | D20: 11% | E20: 12% | F20: 15% | G20: 19%
A21: Value/share (NZ$) | B21: 0.1032 | C21: 0.0959 | D21: 0.0891 | E21: 0.0828 | F21: 0.0665 | G21: 0.0491
A23: SENSITIVITY: WACC x terminal growth (base case, NZ$)
A24: WACC \ g | B24: 0.5% | C24: 1.0% | D24: 1.5% | E24: 2.0% | F24: 2.5%
A25: 15% | B25: 0.0665 | C25: 0.0665 | D25: 0.0665 | E25: 0.0665 | F25: 0.0665
A26: 17% | B26: 0.0574 | C26: 0.0574 | D26: 0.0574 | E26: 0.0574 | F26: 0.0574
A27: 19% | B27: 0.0484 | C27: 0.0488 | D27: 0.0491 | E27: 0.0495 | F27: 0.0495
A28: 21% | B28: 0.0408 | C28: 0.041 | D28: 0.0413 | E28: 0.0416 | F28: 0.0418
A29: 23% | B29: 0.0344 | C29: 0.0345 | D29: 0.0347 | E29: 0.0349 | F29: 0.0351
