Workbook

Sheet DCF Model
A1: SEK.NZ (Seeka Limited) DCF Valuation Model - BASE CASE
A2: Gray cells are INPUTS - adjust to see valuation change. Mid-cycle component build (EBITDA->SBC->D&A->tax->capex->WC), NOT FY2025 peak-FCF extrapolation.
A4: KEY INPUTS
A5: Current Stock Price (NZD) | B5: 4.95
A6: Shares Outstanding Today (M) | B6: 44.03
A7: Cash & Equivalents (NZ$M) | B7: 19.361
A8: Total Bank Debt (NZ$M) | B8: 119.62
A9: Net Debt (NZ$M) | B9: =B8-B7 -> 0
A10: Annual Share Growth (DRP dilution) | B10: 0.0175
A12: WACC | B12: 0.155
A13: Terminal Growth Rate | B13: 0.02
A14: Terminal EV/EBITDA Cap Multiple | B14: 5.5
A15: D&A (% of revenue) | B15: 0.07
A16: Working Capital Capture (% of revenue GROWTH) | B16: 0.12
A18: Mid-Cycle Starting Revenue (NZ$M, Yr0 base) | B18: 400
A20: ANNUAL ASSUMPTIONS
B21: FY2027E | C21: FY2028E | D21: FY2029E | E21: FY2030E | F21: FY2031E
A22: Revenue Growth % | B22: 0.01 | C22: 0.03 | D22: 0.035 | E22: 0.035 | F22: 0.03
A23: EBITDA Margin % | B23: 0.165 | C23: 0.17 | D23: 0.175 | E23: 0.18 | F23: 0.183
A24: Capex % of Revenue | B24: 0.059 | C24: 0.057 | D24: 0.055 | E24: 0.052 | F24: 0.05
A25: Cash Tax Rate % | B25: 0.1 | C25: 0.14 | D25: 0.17 | E25: 0.19 | F25: 0.21
A27: PROJECTIONS (Component Build)
B28: FY2027E | C28: FY2028E | D28: FY2029E | E28: FY2030E | F28: FY2031E
A29: Revenue | B29: =$B$18*(1+B22) -> 0 | C29: =B29*(1+C22) -> 0 | D29: =C29*(1+D22) -> 0 | E29: =D29*(1+E22) -> 0 | F29: =E29*(1+F22) -> 0
A30: Adj. EBITDA | B30: =B29*B23 -> 0 | C30: =C29*C23 -> 0 | D30: =D29*D23 -> 0 | E30: =E29*E23 -> 0 | F30: =F29*F23 -> 0
A31: D&A | B31: =B29*$B$15 -> 0 | C31: =C29*$B$15 -> 0 | D31: =D29*$B$15 -> 0 | E31: =E29*$B$15 -> 0 | F31: =F29*$B$15 -> 0
A32: EBIT | B32: =B30-B31 -> 0 | C32: =C30-C31 -> 0 | D32: =D30-D31 -> 0 | E32: =E30-E31 -> 0 | F32: =F30-F31 -> 0
A33: NOPAT (EBIT x (1-tax)) | B33: =B32*(1-B25) -> 0 | C33: =C32*(1-C25) -> 0 | D33: =D32*(1-D25) -> 0 | E33: =E32*(1-E25) -> 0 | F33: =F32*(1-F25) -> 0
A34: Capex | B34: =B29*B24 -> 0 | C34: =C29*C24 -> 0 | D34: =D29*D24 -> 0 | E34: =E29*E24 -> 0 | F34: =F29*F24 -> 0
A35: Working Capital (capture x change in revenue) | B35: =$B$16*(B29-$B$18) -> 0 | C35: =$B$16*(C29-B29) -> 0 | D35: =$B$16*(D29-C29) -> 0 | E35: =$B$16*(E29-D29) -> 0 | F35: =$B$16*(F29-E29) -> 0
A36: Owner FCF (NOPAT+D&A-Capex-WC) | B36: =B33+B31-B34-B35 -> 0 | C36: =C33+C31-C34-C35 -> 0 | D36: =D33+D31-D34-D35 -> 0 | E36: =E33+E31-E34-E35 -> 0 | F36: =F33+F31-F34-F35 -> 0
A37: Owner FCF Margin % | B37: =B36/B29 -> 0 | C37: =C36/C29 -> 0 | D37: =D36/D29 -> 0 | E37: =E36/E29 -> 0 | F37: =F36/F29 -> 0
A38: Shares Outstanding (M) | B38: =$B$6*(1+$B$10) -> 0 | C38: =B38*(1+$B$10) -> 0 | D38: =C38*(1+$B$10) -> 0 | E38: =D38*(1+$B$10) -> 0 | F38: =E38*(1+$B$10) -> 0
A39: Discount Factor | B39: =1/(1+$B$12)^1 -> 0 | C39: =1/(1+$B$12)^2 -> 0 | D39: =1/(1+$B$12)^3 -> 0 | E39: =1/(1+$B$12)^4 -> 0 | F39: =1/(1+$B$12)^5 -> 0
A40: PV of Owner FCF | B40: =B36*B39 -> 0 | C40: =C36*C39 -> 0 | D40: =D36*D39 -> 0 | E40: =E36*E39 -> 0 | F40: =F36*F39 -> 0
A42: VALUATION
A43: Sum of PV of FCF (Yr1-5) | B43: =SUM(B40:F40) -> 0
A44: Terminal FCF (Yr5 FCF x (1+g)) | B44: =F36*(1+$B$13) -> 0
A45: Terminal Value (Gordon) | B45: =B44/($B$12-$B$13) -> 0
A46: Terminal Value (EV/EBITDA Cap) | B46: =$B$14*F30 -> 0
...

Sheet Sensitivity
A1: Sensitivity Analysis - Base Case Intrinsic Value
A2: WACC (rows) x Terminal Growth (columns); terminal value = MIN(Gordon, 5.5x terminal EBITDA cap)
A4: WACC \ Term G | B4: 0.01 | C4: 0.015 | D4: 0.02 | E4: 0.025 | F4: 0.03
A5: 0.135 | B5: =(SUMPRODUCT('DCF Model'!$B$36:$F$36,1/(1+0.135)^{1,2,3,4,5})+MIN((('DCF Model'!$F$36*(1+0.01))/(0.135-0.01)),'DCF Model'!$B$14*'DCF Model'!$F$30)/(1+0.135)^5-'DCF Model'!$B$9)/'DCF Model'!$F$38 -> 0 | C5: =(SUMPRODUCT('DCF Model'!$B$36:$F$36,1/(1+0.135)^{1,2,3,4,5})+MIN((('DCF Model'!$F$36*(1+0.015))/(0.135-0.015)),'DCF Model'!$B$14*'DCF Model'!$F$30)/(1+0.135)^5-'DCF Model'!$B$9)/'DCF Model'!$F$38 -> 0 | D5: =(SUMPRODUCT('DCF Model'!$B$36:$F$36,1/(1+0.135)^{1,2,3,4,5})+MIN((('DCF Model'!$F$36*(1+0.02))/(0.135-0.02)),'DCF Model'!$B$14*'DCF Model'!$F$30)/(1+0.135)^5-'DCF Model'!$B$9)/'DCF Model'!$F$38 -> 0 | E5: =(SUMPRODUCT('DCF Model'!$B$36:$F$36,1/(1+0.135)^{1,2,3,4,5})+MIN((('DCF Model'!$F$36*(1+0.025))/(0.135-0.025)),'DCF Model'!$B$14*'DCF Model'!$F$30)/(1+0.135)^5-'DCF Model'!$B$9)/'DCF Model'!$F$38 -> 0 | F5: =(SUMPRODUCT('DCF Model'!$B$36:$F$36,1/(1+0.135)^{1,2,3,4,5})+MIN((('DCF Model'!$F$36*(1+0.03))/(0.135-0.03)),'DCF Model'!$B$14*'DCF Model'!$F$30)/(1+0.135)^5-'DCF Model'!$B$9)/'DCF Model'!$F$38 -> 0
A6: 0.145 | B6: =(SUMPRODUCT('DCF Model'!$B$36:$F$36,1/(1+0.145)^{1,2,3,4,5})+MIN((('DCF Model'!$F$36*(1+0.01))/(0.145-0.01)),'DCF Model'!$B$14*'DCF Model'!$F$30)/(1+0.145)^5-'DCF Model'!$B$9)/'DCF Model'!$F$38 -> 0 | C6: =(SUMPRODUCT('DCF Model'!$B$36:$F$36,1/(1+0.145)^{1,2,3,4,5})+MIN((('DCF Model'!$F$36*(1+0.015))/(0.145-0.015)),'DCF Model'!$B$14*'DCF Model'!$F$30)/(1+0.145)^5-'DCF Model'!$B$9)/'DCF Model'!$F$38 -> 0 | D6: =(SUMPRODUCT('DCF Model'!$B$36:$F$36,1/(1+0.145)^{1,2,3,4,5})+MIN((('DCF Model'!$F$36*(1+0.02))/(0.145-0.02)),'DCF Model'!$B$14*'DCF Model'!$F$30)/(1+0.145)^5-'DCF Model'!$B$9)/'DCF Model'!$F$38 -> 0 | E6: =(SUMPRODUCT('DCF Model'!$B$36:$F$36,1/(1+0.145)^{1,2,3,4,5})+MIN((('DCF Model'!$F$36*(1+0.025))/(0.145-0.025)),'DCF Model'!$B$14*'DCF Model'!$F$30)/(1+0.145)^5-'DCF Model'!$B$9)/'DCF Model'!$F$38 -> 0 | F6: =(SUMPRODUCT('DCF Model'!$B$36:$F$36,1/(1+0.145)^{1,2,3,4,5})+MIN((('DCF Model'!$F$36*(1+0.03))/(0.145-0.03)),'DCF Model'!$B$14*'DCF Model'!$F$30)/(1+0.145)^5-'DCF Model'!$B$9)/'DCF Model'!$F$38 -> 0
A7: 0.155 | B7: =(SUMPRODUCT('DCF Model'!$B$36:$F$36,1/(1+0.155)^{1,2,3,4,5})+MIN((('DCF Model'!$F$36*(1+0.01))/(0.155-0.01)),'DCF Model'!$B$14*'DCF Model'!$F$30)/(1+0.155)^5-'DCF Model'!$B$9)/'DCF Model'!$F$38 -> 0 | C7: =(SUMPRODUCT('DCF Model'!$B$36:$F$36,1/(1+0.155)^{1,2,3,4,5})+MIN((('DCF Model'!$F$36*(1+0.015))/(0.155-0.015)),'DCF Model'!$B$14*'DCF Model'!$F$30)/(1+0.155)^5-'DCF Model'!$B$9)/'DCF Model'!$F$38 -> 0 | D7: =(SUMPRODUCT('DCF Model'!$B$36:$F$36,1/(1+0.155)^{1,2,3,4,5})+MIN((('DCF Model'!$F$36*(1+0.02))/(0.155-0.02)),'DCF Model'!$B$14*'DCF Model'!$F$30)/(1+0.155)^5-'DCF Model'!$B$9)/'DCF Model'!$F$38 -> 0 | E7: =(SUMPRODUCT('DCF Model'!$B$36:$F$36,1/(1+0.155)^{1,2,3,4,5})+MIN((('DCF Model'!$F$36*(1+0.025))/(0.155-0.025)),'DCF Model'!$B$14*'DCF Model'!$F$30)/(1+0.155)^5-'DCF Model'!$B$9)/'DCF Model'!$F$38 -> 0 | F7: =(SUMPRODUCT('DCF Model'!$B$36:$F$36,1/(1+0.155)^{1,2,3,4,5})+MIN((('DCF Model'!$F$36*(1+0.03))/(0.155-0.03)),'DCF Model'!$B$14*'DCF Model'!$F$30)/(1+0.155)^5-'DCF Model'!$B$9)/'DCF Model'!$F$38 -> 0
A8: 0.165 | B8: =(SUMPRODUCT('DCF Model'!$B$36:$F$36,1/(1+0.165)^{1,2,3,4,5})+MIN((('DCF Model'!$F$36*(1+0.01))/(0.165-0.01)),'DCF Model'!$B$14*'DCF Model'!$F$30)/(1+0.165)^5-'DCF Model'!$B$9)/'DCF Model'!$F$38 -> 0 | C8: =(SUMPRODUCT('DCF Model'!$B$36:$F$36,1/(1+0.165)^{1,2,3,4,5})+MIN((('DCF Model'!$F$36*(1+0.015))/(0.165-0.015)),'DCF Model'!$B$14*'DCF Model'!$F$30)/(1+0.165)^5-'DCF Model'!$B$9)/'DCF Model'!$F$38 -> 0 | D8: =(SUMPRODUCT('DCF Model'!$B$36:$F$36,1/(1+0.165)^{1,2,3,4,5})+MIN((('DCF Model'!$F$36*(1+0.02))/(0.165-0.02)),'DCF Model'!$B$14*'DCF Model'!$F$30)/(1+0.165)^5-'DCF Model'!$B$9)/'DCF Model'!$F$38 -> 0 | E8: =(SUMPRODUCT('DCF Model'!$B$36:$F$36,1/(1+0.165)^{1,2,3,4,5})+MIN((('DCF Model'!$F$36*(1+0.025))/(0.165-0.025)),'DCF Model'!$B$14*'DCF Model'!$F$30)/(1+0.165)^5-'DCF Model'!$B$9)/'DCF Model'!$F$38 -> 0 | F8: =(SUMPRODUCT('DCF Model'!$B$36:$F$36,1/(1+0.165)^{1,2,3,4,5})+MIN((('DCF Model'!$F$36*(1+0.03))/(0.165-0.03)),'DCF Model'!$B$14*'DCF Model'!$F$30)/(1+0.165)^5-'DCF Model'!$B$9)/'DCF Model'!$F$38 -> 0
A9: 0.175 | B9: =(SUMPRODUCT('DCF Model'!$B$36:$F$36,1/(1+0.175)^{1,2,3,4,5})+MIN((('DCF Model'!$F$36*(1+0.01))/(0.175-0.01)),'DCF Model'!$B$14*'DCF Model'!$F$30)/(1+0.175)^5-'DCF Model'!$B$9)/'DCF Model'!$F$38 -> 0 | C9: =(SUMPRODUCT('DCF Model'!$B$36:$F$36,1/(1+0.175)^{1,2,3,4,5})+MIN((('DCF Model'!$F$36*(1+0.015))/(0.175-0.015)),'DCF Model'!$B$14*'DCF Model'!$F$30)/(1+0.175)^5-'DCF Model'!$B$9)/'DCF Model'!$F$38 -> 0 | D9: =(SUMPRODUCT('DCF Model'!$B$36:$F$36,1/(1+0.175)^{1,2,3,4,5})+MIN((('DCF Model'!$F$36*(1+0.02))/(0.175-0.02)),'DCF Model'!$B$14*'DCF Model'!$F$30)/(1+0.175)^5-'DCF Model'!$B$9)/'DCF Model'!$F$38 -> 0 | E9: =(SUMPRODUCT('DCF Model'!$B$36:$F$36,1/(1+0.175)^{1,2,3,4,5})+MIN((('DCF Model'!$F$36*(1+0.025))/(0.175-0.025)),'DCF Model'!$B$14*'DCF Model'!$F$30)/(1+0.175)^5-'DCF Model'!$B$9)/'DCF Model'!$F$38 -> 0 | F9: =(SUMPRODUCT('DCF Model'!$B$36:$F$36,1/(1+0.175)^{1,2,3,4,5})+MIN((('DCF Model'!$F$36*(1+0.03))/(0.175-0.03)),'DCF Model'!$B$14*'DCF Model'!$F$30)/(1+0.175)^5-'DCF Model'!$B$9)/'DCF Model'!$F$38 -> 0

Sheet Historical
A1: Historical Growth Rates & Multiples
A3: Metric | B3: 3-Year CAGR | C3: 5-Year CAGR
A4: Revenue | B4: 0.0806 | C4: 0.1182
A5: EPS (distorted - see note) | B5: 0.681 | C5: 0.0789
A6: Equity/Book Value | B6: 0.0324 | C6: 0.1108
A7: EBITDA | B7: 0.2766 | C7: 0.1742
A9: Growth Divergence Warning:
A10: EPS and FCF CAGRs are NOT meaningful for this ticker: FY2023 was a loss-making trough (EPS -$0.34, FCF -$20.1m) and FY2020-2022 FCF alternates sign, making CAGR math undefined or explosive (e.g. EPS 3yr CAGR 68% purely reflects recovery off a near-zero FY2022 base of $0.16). Revenue CAGR (8-12%) and Equity CAGR (3-11%) are usable but even these span a trough-to-peak window. Growth for the DCF was NOT selected via CAGR extrapolation; base-case revenue growth (1-3.5%/yr) reflects modest post-moderation volume growth off a mid-cycle starting revenue of $400m, informed by Zespri's 5-year industry plan (+10% trays to 2030) rather than any single historical CAGR.
A12: FY-End EV/EBITDA History (SBC-adj)
A13: FY | B13: EV/EBITDA
A15: FY2016 | B15: 5.6
A16: FY2017 | B16: 7.9
A17: FY2018 | B17: 6.3
A18: FY2019 | B18: 7.5
A19: FY2020 | B19: 5
A20: FY2021 | B20: 4.9
A21: FY2022 | B21: 6.2
A22: FY2023 | B22: 10.9
A23: FY2024 | B23: 3.7
A24: FY2025 | B24: 3.1
A25: Note:
A26: FY-end (31 December close) EV/EBITDA computed on SBC-adjusted (i.e. effectively unadjusted, since SBC is negligible for this ticker) trailing EBITDA. These will NOT match Yahoo/screener GAAP multiples exactly due to differing EBITDA/net-debt definitions and timing. FY2023 is a trough-EBITDA outlier (10.9x) excluded from the 'average'/'max' figures used for scenario multiple caps.

Sheet FCF Quality
A1: FCF Quality: Reported vs Owner FCF Reconciliation
A2: SBC is negligible for this ticker (never exceeding 0.05% of revenue), so reported and owner FCF are virtually identical. The material historical distortion is NOT SBC -- it is cyclicality: FY2015-2023 FCF is mostly negative from orchard/post-harvest EXPANSION capex (packhouse build-out, orchard acquisition), not distress, and must not be used as a 'normal' base. Interest income is not stripped because Seeka is a net-debt company throughout.
A4: Period | B4: FY2015 | C4: FY2016 | D4: FY2017 | E4: FY2018 | F4: FY2019 | G4: FY2020 | H4: FY2021 | I4: FY2022 | J4: FY2023 | K4: FY2024 | L4: FY2025
A5: Revenue (NZ$M) | B5: 142.112 | C5: 191.317 | D5: 186.814 | E5: 203.713 | F5: 236.868 | G5: 251.457 | H5: 309.569 | I5: 348.387 | J5: 300.92 | K5: 411.412 | L5: 439.611
A6: Reported FCF (NZ$M) | B6: -14.663 | C6: -20.55 | D6: -10.3 | E6: -25.114 | F6: -19.986 | G6: 6.081 | H6: 12.094 | I6: -21.736 | J6: -20.065 | K6: 47.741 | L6: 53.301
A7: less: SBC (NZ$M) | B7: 0 | C7: 0 | D7: 0.133 | E7: 0.062 | F7: -0.044 | G7: 0.153 | H7: 0.153 | I7: 0.038 | J7: 0 | K7: 0.049 | L7: 0.073
A8: Owner FCF (NZ$M) | B8: -14.66 | C8: -20.55 | D8: -10.43 | E8: -25.18 | F8: -19.94 | G8: 5.93 | H8: 11.94 | I8: -21.77 | J8: -20.07 | K8: 47.69 | L8: 53.23
A9: Reported FCF Margin % | B9: -0.103 | C9: -0.107 | D9: -0.055 | E9: -0.123 | F9: -0.084 | G9: 0.024 | H9: 0.039 | I9: -0.062 | J9: -0.067 | K9: 0.116 | L9: 0.121
A10: Owner FCF Margin % | B10: -0.103 | C10: -0.107 | D10: -0.056 | E10: -0.124 | F10: -0.084 | G10: 0.024 | H10: 0.039 | I10: -0.062 | J10: -0.067 | K10: 0.116 | L10: 0.121
A11: Cash Tax Paid (NZ$M, memo) | B11: 1.2 | C11: 0.97 | D11: 4.17 | E11: 4.92 | F11: 2.29 | G11: 2.37 | H11: 7.66 | I11: 9.13 | J11: -1.86 | K11: 0.02 | L11: 4.73
A13: Memo: FY2015-2023 negative FCF reflects orchard/post-harvest EXPANSION capex
A14: (packhouse build-out, orchard acquisition), NOT distress - do not use as a "normal" base.

Sheet Model_Info
A1: Model Provenance & Methodology Notes
A4: Built by | B4: Claude dcf-analyst agent, per /Users/swilliams/Stocks/Research/.claude/agents/dcf-analyst.md
A5: Data vintage | B5: Share price NZ$4.95 fetched live from Yahoo Finance chart API on 2026-08-01. FY2025 annual result released 2026-02-27 (year ended 31-Dec-2025). FY2026 first guidance issued 17/18-Jun-2026 (NPBT $38-42m). H1-2026 result release advised 27-Jul-2026 but NOT YET PUBLISHED as of the valuation date (2026-08-01) - net debt, dividend, and volume figures used are the FY2025 year-end/guidance-vintage figures, not H1-2026 actuals.
A6: Methodology - core choice | B6: MID-CYCLE component-build DCF, deliberately NOT extrapolating FY2025 record-year FCF/EBITDA. This ticker is the repo's canonical peak-FCF sanity-check case (see "warning" field in the JSON) after a prior run produced IV $22.75 by flat-lining peak margins.
A7: Mid-cycle EBITDA selection | B7: Year-1 base-case EBITDA ~$66.7m on $404m revenue (16.5% margin), chosen between the FY2022-2025 straight 4-year average ($61.0m) and a guidance-informed blend including FY2026E ($69.7m), reflecting structurally higher SunGold mix without assuming the FY2025 record repeats.
A8: SBC treatment | B8: SBC is genuinely negligible for Seeka (0-$0.15m/yr, never >0.05% of revenue, verified against duckdb kpis EquityAwardTaxes=0 every year). The SBC adjustment step is applied mechanically but is immaterial - the real trap here is peak-vs-trough cyclicality, not stock compensation.
A9: Net debt / interest income | B9: Seeka is a NET DEBT company (net debt $100.3m at Dec-2025, not net cash) so interest income is NOT stripped from FCF - the interest-income double-count trap in the agent instructions applies only to net-cash companies.
A10: WACC build | B10: 15.5% base = ~11-12% NZ small-cap base + Zespri single-marketer concentration premium (1.5-2.0%) + weather/cyclone cyclicality premium (1.0-1.5%) + NZX illiquidity/small-cap premium (1.5-2.0%). Bull 14.0%, Bear 17.5%. See "wacc_rationale" block in the JSON for full detail.
A11: Terminal value | B11: MIN(Gordon growth, EV/EBITDA cap). Gordon growth structurally binds in all three scenarios at this WACC/FCF-conversion combination (SEK converts ~50-55% of EBITDA to owner FCF, and at a mid-teens WACC even a 2.5% terminal growth rate produces a Gordon value below the EV/EBITDA cap) - this is a legitimate mechanical outcome for a mid-teens-WACC cyclical, not a modeling error. EV/EBITDA caps (bear 3.5x/base 5.5x/bull 7.9x) are calibrated to Seeka's own FY-end trading history (10-year range 3.1x-7.9x ex the FY2023 trough-EBITDA outlier of 10.9x).
A12: Horizon | B12: 5-year explicit projection - appropriate because base-case owner-FCF margin is roughly stable across the window (9.5%->10.6%), not still steeply ramping, reflecting a mature business past its packhouse capacity build-out.
A13: Sanity checks | B13: Base IV ($4.54) implies a BELOW-average P/E (5.97x vs 13.0x avg) and EV/EBITDA (3.13x vs 5.58x avg) against FY2025 PEAK earnings - expected for a cyclical valued at mid-cycle vs a record year, and well within the hard 2x/1.5x ceilings. Against MID-CYCLE (5yr average) earnings, implied P/E (16.6x) and EV/EBITDA (4.50x) both sit close to or within historical average ranges, cross-confirming the valuation.
A14: What to refresh after next earnings/data | B14: H1-2026 result (expected mid-to-late Aug 2026): update net debt, dividend declaration, H1 tray volumes and revenue/EBITDA run-rate. FY2026 full-year result (expected Feb-2027): rebuild mid-cycle EBITDA anchor once the FY2026 actual NPBT (guided $38-42m) is confirmed; reassess whether mid-cycle margin assumptions (16.5%->18.3%) remain appropriate. Re-fetch live share price from Yahoo before reusing this model - it decays with market moves for a stock this volatile.
A15: Cell colour conventions | B15: GRAY cells = editable inputs. WHITE cells with borders = formula outputs (change automatically). GREEN highlighted cells = headline valuation outputs (Intrinsic Value/Share, Entry Price).
A16: Caveat | B16: All figures will go stale. This is a snapshot as of 2026-08-01 using the FY2025 annual result and Jun-2026 guidance update as the latest data points; re-verify net debt, dividend, and volume assumptions against the H1-2026 result once published before relying on this model for a live decision.
