Workbook

Sheet Model_Info
A1: VSL.NZ owner-FCF DCF model
A2: Version | B2: v2 2026-09-20. Supersedes v1 2026-09-20, which was built directly from the FY26 annual report before the financial parser populated the FY2025/FY2026 rows in core_metrics / VSL.NZ_Metrics.csv. v2 re-anchors on the DB; every FY0 anchor ties to v1 to the thousand, so driver paths are carried unchanged and the Reconciliation tab shows the NZ$0.6m net-bank-debt refinement as the only value change.
A3: Built by | B3: dcf-analyst agent (Claude Fable 5.1) on 2026-09-20 at the research-stock orchestrator's request.
A4: Data vintage | B4: Price NZ$6.35 NZX regular close 2026-09-18T04:59:55Z (Yahoo; latest close as at Sunday 20-Sep-2026). Balance sheet 30-Jun-2026 (core_metrics FY2026 from the FY26 annual report, NZX ann. 478454, 24-Aug-2026): bank loans 258.587 less cash 30.701 = net bank debt 227.9 (company KPI rounds to 227.3), lease liabilities 372.8, NCI book 9.3. Shares 146,529,960 at 30-Jun-2026 (post Oct-2025 raise). FY27 guidance: D&A 67-70, interest 38-41, capex 30-35; no revenue/EBITDA guidance; trading update at Oct-2026 AGM.
A5: Model | B5: Component owner-FCF DCF, 10-year explicit horizon FY2027-FY2036, Gordon/cap terminal value, end-of-year discounting, WACC 10.5% NZD in all scenarios.
A6: Leases | B6: Treatment B: full lease cash (principal + interest, FY26 53.5 = 4.62% of revenue) charged in the flows as a % of revenue; lease liabilities EXCLUDED from the bridge; D&A ex right-of-use for tax. Never add lease liabilities to net debt in this workbook.
A7: NCI | B7: Roofing Industries minority charged once, in the bridge (NZ$15m estimate vs 9.3m book). Flows are whole-company.
A8: Working capital | B8: NWC is 32.6% of revenue; wc_capture is NEGATIVE (base -27%): growth consumes cash.
A9: SBC | B9: Expensed in the flows at 0.35% of revenue; share count held flat. Street memo adds SBC back.
A10: EBITDA basis | B10: Adjusted EBITDA before significant items (FY26 130.3; core_metrics ebitda 128.2 is statutory after 1.0 acquisition costs and 1.1 disposal loss). FY25 adjusted 112.1 vs statutory 109.0.
A11: Drivers | B11: Scenario driver paths are the dcf-analyst agent's judgment as of 2026-09-20 (v1), carried unchanged into v2 because the DB rows corroborate rather than change the FY25/FY26 picture. Blue cells are inputs; yellow fill = key lever; black = formula; green = cross-sheet link.
A12: Refresh after | B12: Oct-2026 AGM trading update; 1H FY27 result (Feb-2027): net bank debt, lease liabilities, covenant headroom, margin. Figures in this file go stale; the live cells are authoritative over the JSON snapshot.
A13: Sheets | B13: Reconciliation (v1 -> v2 bridge), Actuals (hardcoded history from core_metrics), Assumptions (globals + per-scenario), DCF_Bear/Base/Bull (identical layout), FCF_Quality (reported to owner FCF), Valuation (summary, entry price, required-return table, sensitivity).

Sheet Reconciliation
A1: Reconciliation v1 -> v2 (NZ$ per share). Prior values hardcoded; live values link to the model; bridge figures are approximate, live cells are authoritative.
A3: Scenario | B3: v1 (2026-09-20, price 6.35) | C3: v2 live | D3: Change
A4: Bear | B4: -0.01 | C4: =DCF_Bear!$B$43 | D4: =C4-B4
A5: Base | B5: 2.45 | C5: =DCF_Base!$B$43 | D5: =C5-B5
A6: Bull | B6: 4.16 | C6: =DCF_Bull!$B$43 | D6: =C6-B6
A7: Weighted | B7: 2.27 | C7: =Valuation!$B$8 | D7: =C7-B7
A9: Bridge (approximate)
A10: Prior weighted IV (v1), unrounded 2.2666, reported 2.27 | B10: 2.267
A11: Anchor refresh: net bank debt 227.3 (company KPI) -> 227.9 (DB balance sheet: bank loans 258.587 - cash 30.701); +0.6m bridge | B11: -0.004
A12: Anchor refresh: price, shares, lease liabilities, NCI, FY27 guidance -- unchanged | B12: 0
A13: Driver changes: none (all paths carried; see assumptions_unchanged_note) | B13: 0
A14: Methodology change: none (same engine, same lease/NCI/WC treatment) | B14: 0
A15: Price move: none (same 18-Sep-2026 close) | B15: 0
A16: Residual (rounding of the v1 unrounded figure) | B16: 0
A17: New weighted IV (v2), unrounded | B17: 2.262
A19: Unchanged assertions | B19: Deliberately unchanged, with what would move each: WACC 10.5% (leverage < ~2.0x sustained); lease treatment B and lease_cost_pct 4.4/4.2/4.8 (rent re-basing or network change); NCI 15m in the bridge (a full year of Roofing NCI NPAT); wc_capture -27/-24/-30 (inventory-turn improvement showing in 1H FY27 NWC/revenue); growth and margin paths (Oct-2026 AGM update, 1H FY27 result); weights 25/50/25 (covenant headroom and pricing discipline evidence).

Sheet Actuals
A1: NZ$m | B1: FY2021 | C1: FY2022 | D1: FY2023 | E1: FY2024 | F1: FY2025 | G1: FY2026 | H1: Source
A2: Revenue | B2: 731.546 | C2: 972.667 | D2: 1244.837 | E2: 1064.326 | F2: 948.153 | G2: 1158.807 | H2: core_metrics revenue (NZ$000s / 1000)
A3: Adjusted EBITDA (post IFRS-16) | B3: 95.896 | C3: 224.443 | D3: 208.7 | E3: 147.566 | F3: 112.086 | G3: 130.323 | H3: Company adjusted EBITDA before significant items (FY26 AR segment note); FY22-24 core_metrics ebitda
A4: Operating cash flow | B4: 105.454 | C4: 12.146 | D4: 145.404 | E4: 168.711 | F4: 104.954 | G4: 73.004 | H4: core_metrics operating_cash_flow
A5: Capex | B5: 5.661 | C5: 12.209 | D5: 22.952 | E5: 26.688 | F5: 21.32 | G5: 26.606 | H5: core_metrics capex (positive = outflow)
A6: Lease principal paid | B6: 12.153 | C6: 12.866 | D6: 21.372 | E6: 23.656 | F6: 26.743 | G6: 30.989 | H6: Cash flow statements, financing (FY26 AR line 4737)
A7: Lease interest paid | B7: 11.392 | C7: 11.499 | D7: 16.363 | E7: 16.982 | F7: 17.965 | G7: 22.532 | H7: Cash flow statements, operating (FY26 AR line 4205)
A8: Bank interest paid | B8: 13.699 | C8: 15.748 | D8: 21.234 | E8: 17.51 | F8: 23.867 | G8: 16.01 | H8: Cash flow statements, operating (FY21 = expense)
A9: Interest received | B9: 0.013 | C9: 0.004 | D9: 0.051 | E9: 0.263 | F9: 0.174 | G9: 1.548 | H9: kpis InterestIncome
A10: Tax paid | B10: 18.398 | C10: 40.334 | D10: 69.391 | E10: 20.322 | F10: 7.49 | G10: 9.187 | H10: kpis CashTaxesPaid
A11: SBC expense | B11: 0 | C11: 2.683 | D11: 1.243 | E11: 2.03 | F11: 3.502 | G11: 4.366 | H11: core_metrics stock_based_comp
A12: NPAT attributable | B12: 64.832 | C12: 123.984 | D12: 87.899 | E12: 39.985 | F12: 15.728 | G12: 20.658 | H12: core_metrics net_income
A13: Shareholders' equity | B13: 154.117 | C13: 185.265 | D13: 185.918 | E13: 172.056 | F13: 169.653 | G13: 308.537 | H13: core_metrics shareholders_equity (FY26 incl. NCI 9.3)
A14: Net bank debt | B14: 69.8 | C14: 186.9 | D14: 339.7 | E14: 276 | F14: 232.4 | G14: 227.9 | H14: total_debt less cash_and_equivalents (FY26: 258.587 - 30.701); company KPI FY26 227.3
A15: Lease liabilities | E15: 290.3 | F15: 295.3 | G15: 372.8 | H15: kpis LeaseLiabilities / balance sheets
A16: Shares on issue (m) | B16: 131.409 | C16: 131.409 | D16: 131.409 | E16: 131.409 | F16: 131.695 | G16: 146.53 | H16: core_metrics shares_outstanding; raise Oct-2025
A17: Dividends paid | B17: 48 | C17: 104.137 | D17: 85.173 | E17: 57.423 | F17: 19.361 | G17: 8.787 | H17: kpis DividendsPaid
A19: Guidance FY2027
A20: D&A NZ$67-70m; interest expense NZ$38-41m; capex NZ$30-35m (NZ$14-17m growth). No revenue or EBITDA guidance. Trading update at Oct-2026 AGM.
A21: Balance sheet 30-Jun-2026: receivables 182.2, inventories 384.3, payables 189.2 (NWC 377.3 = 32.6% of revenue); gross bank loans 258.6, facilities 405.5; NCI 9.3; no buyback programme. H1 FY2026 CSV row is presentation-rounded with NULL balance-sheet cells and is not used.

Sheet Assumptions
A2: Current price (NZ$) | B2: 6.35 | C2: 2026-09-18T04:59:55Z NZX regular close (Fri 18-Sep-2026); latest regular close as at valuation date 2026-09-20 (Sunday)
A3: Price timestamp | B3: 2026-09-18T04:59:55Z NZX regular close (Fri 18-Sep-2026); latest regular close as at valuation date 2026-09-20 (Sunday) | C3: Yahoo regularMarketTime
A4: Diluted shares (m) | B4: 146.52996 | C4: 146,529,960 ordinary shares on issue at 30-Jun-2026 (core_metrics FY2026 shares_outstanding; FY26 AR). Diluted EPS equals basic ($0.14) so PSRs are immaterial. Count is post the Oct-2025 NZ$93.8m net equity raise (131.7m -> 146.5m; kpis EquityRaised FY2026 93,824). Held FLAT: SBC is expensed in the flows; no buyback programme.
A5: Net bank debt (NZ$m) | B5: 227.9 | C5: 30-Jun-2026; bank loans 258.587 less cash 30.701 (core_metrics). Company KPI 227.3. Lease liabilities are NOT here (treatment B).
A6: NCI deduction (NZ$m) | B6: 15 | C6: Roofing Industries minority, ~10x annualised NCI NPAT; book 9.3
A7: Lease liabilities memo (NZ$m) | B7: 372.8 | C7: Memo only; charged through the flows, never in the bridge
A8: D&A ex-ROU % revenue | B8: 2.1 | C8: FY26 22.9 = 1.98%; FY27 guidance implies ~2.1%
A9: Cash tax rate | B9: 29 | C9: Blended NZ 28% / AU 30%; FY26 cash tax 29% of PBT
A10: Hurdle rate | B10: 15 | C10: Entry-price IRR; TV rebuilt at this rate
A11: FY2026A revenue (NZ$m) | B11: 1158.807 | C11: core_metrics FY2026 revenue
A13: Per scenario | B13: Bear | C13: Base | D13: Bull
A14: WACC % | B14: 10.5 | C14: 10.5 | D14: 10.5
A15: Terminal growth % | B15: 2 | C15: 2.5 | D15: 3
A16: Terminal cap (x FCF10) | B16: 12 | C16: 13 | D16: 13
A17: Lease cash % revenue | B17: 4.8 | C17: 4.4 | D17: 4.2
A18: WC capture % of revenue change | B18: -30 | C18: -27 | D18: -24
A19: Probability weight | B19: 0.25 | C19: 0.5 | D19: 0.25
A20: Weights sum (must be 1) | B20: =SUM(B19:D19)
A22: Narratives
A23: Bear | B23: The 'aggressive and unsustainable' competitor pricing management called out in FY25 persists; Australian rates stay restrictive, NZ recovery stalls on the November 2026 election and construction remains flat; rollforming margins normalise after a strong first nine months. Revenue +3% FY27 then flat for two years; EBITDA margin slips to 10.2% before a slow recovery to 11%. Semi-fixed leases rise to 4.8% of revenue; working capital stays heavy (30%). With NZ$227m of bank debt and NZ$373m of leases against ~NZ$60m of pre-IFRS-16 EBITDA, this path revisits the covenant discussion that only ended 30-Jun-2026; the equity value falls below NZ$1/share. Terminal growth 2.0%, cap 12x.
A24: Base | B24: FY27 revenue +7.5%: ~3.5pp from annualising Roofing Industries (NZ$135m for nine months of FY26; pro-forma full year NZ$1,199.6m) plus ~4% underlying, carrying the 2H FY26 momentum (underlying revenue +16.4% YoY in 2H) into an NZ recovery and a flat-to-firming Australia. Growth fades to 2.5% by FY35. Adjusted EBITDA margin recovers from the FY26 trough of 11.2% to a 14.0% mid-cycle by FY32 (segment margins ~16% less ~2% corporate; FY24 segments ran 14.6-16.8%, FY23 18-20%) -- above FY25-26 but below the FY23-24 13.9-16.8% that still carried Ullrich integration and pre-price-war margins, and well below the FY22 23% boom. Lease cash 4.4% of revenue flat (FY26 4.62%; the 82-site network is semi-fixed so the ratio drifts down as revenue grows, but rent inflation and hybrid-site additions keep it near 4.4% on average), D&A ex-ROU 2.1% (FY27 guidance), capex 2.6% fading to 2.4% (FY27 NZ$30-35m), working capital absorbing 27c of every revenue dollar added (NWC is 32.6% of revenue; management targets inventory turns). Owner FCF margin builds from ~1% (FY27 working-capital drag on 7.5% growth) to ~4%; the business earns roughly its cost of capital, so most of the equity value sits in the terminal margin assumption.
A25: Bull | B25: Australia's rate cycle turns, Brisbane 2032 and resource-sector maintenance spend lift Queensland (23% of group revenue) and engineering steels, NZ recovers post-election, competitor pricing rationalises after network consolidation and possible safeguard measures. Rollforming synergies and hybrid sites lift group margin toward 15.5% by FY32 (segment margins back to ~17%, corporate cost leverage). Revenue +10% FY27 fading to 3%; lease cost dilutes to 4.2%; working-capital intensity eases to 24%. Terminal growth 3.0%.
A27: WACC rationale | B27: NZD-built: NZ 10yr government bond ~4.5% (Sep-2026) + beta 1.2 x ERP 5.0% = cost of equity ~10.5%; pre-tax cost of bank debt ~6.5% (BKBM + margin, FY26 bank interest NZ$16.0m on ~NZ$250m average drawn), 4.6% after 29% tax; capital weights ~80/20 on NZ$930m market cap vs NZ$227m net bank debt (lease liabilities are in the flows, not the capital structure) gives ~9.3%. House WACC 10.5% = 9.3% + ~1.2pp financing-stress premium: net bank debt / pre-IFRS-16 EBITDA 2.96x, covenant relaxation only expired 30-Jun-2026 after two extensions, NZ$405.5m facilities 64% drawn, and a further NZ$372.8m of lease commitments ranking alongside. Risk is charged ONCE: financing stress in the discount rate; cyclicality, competitor pricing and Roofing execution in the scenario paths and the 25% bear weight. WACC is identical in all three scenarios. RE-VALIDATED 2026-09-20 v2 against the DB FY2025/FY2026 rows: net bank debt fell 276.0 (FY24) -> 232.3 (FY25) -> 227.9 (FY26) but the FY26 step was equity-funded, not organic -- the NZ$93.8m raise covered the NZ$87.0m net Roofing outflow while levered owner FCF (9.5) barely covered the dividend (8.8). Leverage is still 2.96x pre-IFRS-16 EBITDA with NZ$372.8m of leases alongside, so the ~1.2pp premium stays. What would remove it: net bank debt / pre-IFRS-16 EBITDA sustained below ~2.0x (roughly NZ$70m of organic debt paydown or EBITDA above NZ$115m pre-IFRS-16) with the Oct-2025 amended facility running without further relaxation.
A28: Unchanged drivers | B28: All three scenario driver paths (growth, EBITDA margin, SBC%, lease cost %, D&A %, capex %, wc_capture, tax, WACC, terminal growth, cap) are carried from v1 unchanged. The DB FY2025/FY2026 rows are the same figures v1 read off the FY26 annual report, so they are corroboration, not new evidence. What would move them: (1) the Oct-2026 AGM trading update on FY27 volumes and margin -> FY27 growth and margin; (2) 1H FY27 net bank debt and leverage -> WACC premium and bear weight; (3) evidence that Roofing rollforming margins are above or below the group's -> margin path; (4) a change in the 82-site network or a rent re-basing -> lease_cost_pct.

Sheet DCF_Bear
A1: Bear scenario -- owner FCF, lease treatment B (NZ$m)
A3: Year | B3: FY2026A | C3: FY2027E | D3: FY2028E | E3: FY2029E | F3: FY2030E | G3: FY2031E | H3: FY2032E | I3: FY2033E | J3: FY2034E | K3: FY2035E | L3: FY2036E
A4: Year index | B4: 0 | C4: 1 | D4: 2 | E4: 3 | F4: 4 | G4: 5 | H4: 6 | I4: 7 | J4: 8 | K4: 9 | L4: 10
A5: Revenue growth % | C5: 3 | D5: 1 | E5: 0 | F5: 1 | G5: 2 | H5: 2 | I5: 2 | J5: 2 | K5: 2 | L5: 2
A6: Revenue | B6: 1158.807 | C6: =B6*(1+C5/100) | D6: =C6*(1+D5/100) | E6: =D6*(1+E5/100) | F6: =E6*(1+F5/100) | G6: =F6*(1+G5/100) | H6: =G6*(1+H5/100) | I6: =H6*(1+I5/100) | J6: =I6*(1+J5/100) | ... L6: =K6*(1+L5/100)
A7: Adj EBITDA margin % | B7: 11.25 | C7: 10.8 | D7: 10.5 | E7: 10.2 | F7: 10.2 | G7: 10.5 | H7: 10.8 | I7: 11 | J7: 11 | K7: 11 | L7: 11
A8: Adjusted EBITDA (post IFRS-16) | B8: =B6*B7/100 | C8: =C6*C7/100 | D8: =D6*D7/100 | E8: =E6*E7/100 | F8: =F6*F7/100 | G8: =G6*G7/100 | H8: =H6*H7/100 | I8: =I6*I7/100 | ... L8: =L6*L7/100
A9: SBC % revenue | B9: 0.38 | C9: 0.35 | D9: 0.35 | E9: 0.35 | F9: 0.35 | G9: 0.35 | H9: 0.35 | I9: 0.35 | J9: 0.35 | K9: 0.35 | L9: 0.35
A10: SBC (negative) | B10: =-B6*B9/100 | C10: =-C6*C9/100 | D10: =-D6*D9/100 | E10: =-E6*E9/100 | F10: =-F6*F9/100 | G10: =-G6*G9/100 | H10: =-H6*H9/100 | I10: =-I6*I9/100 | ... L10: =-L6*L9/100
A11: Lease cash % revenue | B11: 4.62 | C11: =Assumptions!$B$17 | D11: =Assumptions!$B$17 | E11: =Assumptions!$B$17 | F11: =Assumptions!$B$17 | G11: =Assumptions!$B$17 | H11: =Assumptions!$B$17 | I11: =Assumptions!$B$17 | J11: =Assumptions!$B$17 | ... L11: =Assumptions!$B$17
A12: Lease cash (negative) | B12: =-B6*B11/100 | C12: =-C6*C11/100 | D12: =-D6*D11/100 | E12: =-E6*E11/100 | F12: =-F6*F11/100 | G12: =-G6*G11/100 | H12: =-H6*H11/100 | I12: =-I6*I11/100 | ... L12: =-L6*L11/100
A13: Owner EBITDA (pre IFRS-16, post SBC) | B13: =B8+B10+B12 | C13: =C8+C10+C12 | D13: =D8+D10+D12 | E13: =E8+E10+E12 | F13: =F8+F10+F12 | G13: =G8+G10+G12 | H13: =H8+H10+H12 | I13: =I8+I10+I12 | ... L13: =L8+L10+L12
A14: D&A ex-ROU (negative) | B14: -22.889 | C14: =-C6*Assumptions!$B$8/100 | D14: =-D6*Assumptions!$B$8/100 | E14: =-E6*Assumptions!$B$8/100 | F14: =-F6*Assumptions!$B$8/100 | G14: =-G6*Assumptions!$B$8/100 | H14: =-H6*Assumptions!$B$8/100 | I14: =-I6*Assumptions!$B$8/100 | J14: =-J6*Assumptions!$B$8/100 | ... L14: =-L6*Assumptions!$B$8/100
A15: EBIT | B15: =B13+B14 | C15: =C13+C14 | D15: =D13+D14 | E15: =E13+E14 | F15: =F13+F14 | G15: =G13+G14 | H15: =H13+H14 | I15: =I13+I14 | ... L15: =L13+L14
A16: Cash tax rate % | B16: 29 | C16: 29 | D16: 29 | E16: 29 | F16: 29 | G16: 29 | H16: 29 | I16: 29 | J16: 29 | K16: 29 | L16: 29
A17: Cash tax (negative) | B17: =-MAX(0,B15)*B16/100 | C17: =-MAX(0,C15)*C16/100 | D17: =-MAX(0,D15)*D16/100 | E17: =-MAX(0,E15)*E16/100 | F17: =-MAX(0,F15)*F16/100 | G17: =-MAX(0,G15)*G16/100 | H17: =-MAX(0,H15)*H16/100 | I17: =-MAX(0,I15)*I16/100 | ... L17: =-MAX(0,L15)*L16/100
A18: NOPAT | B18: =B15+B17 | C18: =C15+C17 | D18: =D15+D17 | E18: =E15+E17 | F18: =F15+F17 | G18: =G15+G17 | H18: =H15+H17 | I18: =I15+I17 | ... L18: =L15+L17
A19: add back D&A | B19: =-B14 | C19: =-C14 | D19: =-D14 | E19: =-E14 | F19: =-F14 | G19: =-G14 | H19: =-H14 | I19: =-I14 | ... L19: =-L14
A20: Capex % revenue | C20: 2.5 | D20: 2.3 | E20: 2.3 | F20: 2.3 | G20: 2.3 | H20: 2.3 | I20: 2.3 | J20: 2.3 | K20: 2.3 | L20: 2.3
A21: Capex (negative) | B21: -26.606 | C21: =-C6*C20/100 | D21: =-D6*D20/100 | E21: =-E6*E20/100 | F21: =-F6*F20/100 | G21: =-G6*G20/100 | H21: =-H6*H20/100 | I21: =-I6*I20/100 | J21: =-J6*J20/100 | ... L21: =-L6*L20/100
A22: Working capital (negative = consumed) | B22: -11.136 | C22: =Assumptions!$B$18/100*(C6-B6) | D22: =Assumptions!$B$18/100*(D6-C6) | E22: =Assumptions!$B$18/100*(E6-D6) | F22: =Assumptions!$B$18/100*(F6-E6) | G22: =Assumptions!$B$18/100*(G6-F6) | H22: =Assumptions!$B$18/100*(H6-G6) | I22: =Assumptions!$B$18/100*(I6-H6) | J22: =Assumptions!$B$18/100*(J6-I6) | ... L22: =Assumptions!$B$18/100*(L6-K6)
A23: Unlevered owner FCF | B23: =B18+B19+B21+B22 | C23: =C18+C19+C21+C22 | D23: =D18+D19+D21+D22 | E23: =E18+E19+E21+E22 | F23: =F18+F19+F21+F22 | G23: =G18+G19+G21+G22 | H23: =H18+H19+H21+H22 | I23: =I18+I19+I21+I22 | ... L23: =L18+L19+L21+L22
A24: Discount factor | C24: =1/(1+Assumptions!$B$14/100)^C4 | D24: =1/(1+Assumptions!$B$14/100)^D4 | E24: =1/(1+Assumptions!$B$14/100)^E4 | F24: =1/(1+Assumptions!$B$14/100)^F4 | G24: =1/(1+Assumptions!$B$14/100)^G4 | H24: =1/(1+Assumptions!$B$14/100)^H4 | I24: =1/(1+Assumptions!$B$14/100)^I4 | J24: =1/(1+Assumptions!$B$14/100)^J4 | ... L24: =1/(1+Assumptions!$B$14/100)^L4
A25: PV of FCF | C25: =C23*C24 | D25: =D23*D24 | E25: =E23*E24 | F25: =F23*F24 | G25: =G23*G24 | H25: =H23*H24 | I25: =I23*I24 | J25: =J23*J24 | ... L25: =L23*L24
A27: Memo: FCF before SBC | C27: =C23-C10 | D27: =D23-D10 | E27: =E23-E10 | F27: =F23-F10 | G27: =G23-G10 | H27: =H23-H10 | I27: =I23-I10 | J27: =J23-J10 | ... L27: =L23-L10
A28: Memo: owner FCF margin | B28: =B23/B6 | C28: =C23/C6 | D28: =D23/D6 | E28: =E23/E6 | F28: =F23/F6 | G28: =G23/G6 | H28: =H23/H6 | I28: =I23/I6 | ... L28: =L23/L6
A30: Sum of PV (FY27-FY36) | B30: =SUM(C25:L25)
A31: Terminal growth % | B31: =Assumptions!$B$15
A32: Terminal FCF = FCF10 x (1+g) | B32: =L23*(1+B31/100)
A33: Gordon TV | B33: =B32/(Assumptions!$B$14/100-B31/100)
A34: Cap TV = cap x FCF10 | B34: =Assumptions!$B$16*L23
A35: TV used = MAX(0, MIN(Gordon, cap)) | B35: =MAX(0,MIN(B33,B34))
A36: Implied exit multiple (TV / FCF10) | B36: =IF(L23<>0,B35/L23,0)
A37: PV of TV | B37: =B35*L24
A38: Enterprise value (ex leases) | B38: =B30+B37
A39: less net bank debt | B39: =-Assumptions!$B$5
A40: less NCI | B40: =-Assumptions!$B$6
A41: Equity value | B41: =B38+B39+B40
A42: Diluted shares (m) | B42: =Assumptions!$B$4
A43: VALUE PER SHARE (NZ$) | B43: =B41/B42
...

Sheet DCF_Base
A1: Base scenario -- owner FCF, lease treatment B (NZ$m)
A3: Year | B3: FY2026A | C3: FY2027E | D3: FY2028E | E3: FY2029E | F3: FY2030E | G3: FY2031E | H3: FY2032E | I3: FY2033E | J3: FY2034E | K3: FY2035E | L3: FY2036E
A4: Year index | B4: 0 | C4: 1 | D4: 2 | E4: 3 | F4: 4 | G4: 5 | H4: 6 | I4: 7 | J4: 8 | K4: 9 | L4: 10
A5: Revenue growth % | C5: 7.5 | D5: 5.5 | E5: 5 | F5: 4.5 | G5: 4 | H5: 3.5 | I5: 3 | J5: 3 | K5: 2.5 | L5: 2.5
A6: Revenue | B6: 1158.807 | C6: =B6*(1+C5/100) | D6: =C6*(1+D5/100) | E6: =D6*(1+E5/100) | F6: =E6*(1+F5/100) | G6: =F6*(1+G5/100) | H6: =G6*(1+H5/100) | I6: =H6*(1+I5/100) | J6: =I6*(1+J5/100) | ... L6: =K6*(1+L5/100)
A7: Adj EBITDA margin % | B7: 11.25 | C7: 11.6 | D7: 12.1 | E7: 12.6 | F7: 13.1 | G7: 13.5 | H7: 14 | I7: 14 | J7: 14 | K7: 14 | L7: 14
A8: Adjusted EBITDA (post IFRS-16) | B8: =B6*B7/100 | C8: =C6*C7/100 | D8: =D6*D7/100 | E8: =E6*E7/100 | F8: =F6*F7/100 | G8: =G6*G7/100 | H8: =H6*H7/100 | I8: =I6*I7/100 | ... L8: =L6*L7/100
A9: SBC % revenue | B9: 0.38 | C9: 0.35 | D9: 0.35 | E9: 0.35 | F9: 0.35 | G9: 0.35 | H9: 0.35 | I9: 0.35 | J9: 0.35 | K9: 0.35 | L9: 0.35
A10: SBC (negative) | B10: =-B6*B9/100 | C10: =-C6*C9/100 | D10: =-D6*D9/100 | E10: =-E6*E9/100 | F10: =-F6*F9/100 | G10: =-G6*G9/100 | H10: =-H6*H9/100 | I10: =-I6*I9/100 | ... L10: =-L6*L9/100
A11: Lease cash % revenue | B11: 4.62 | C11: =Assumptions!$C$17 | D11: =Assumptions!$C$17 | E11: =Assumptions!$C$17 | F11: =Assumptions!$C$17 | G11: =Assumptions!$C$17 | H11: =Assumptions!$C$17 | I11: =Assumptions!$C$17 | J11: =Assumptions!$C$17 | ... L11: =Assumptions!$C$17
A12: Lease cash (negative) | B12: =-B6*B11/100 | C12: =-C6*C11/100 | D12: =-D6*D11/100 | E12: =-E6*E11/100 | F12: =-F6*F11/100 | G12: =-G6*G11/100 | H12: =-H6*H11/100 | I12: =-I6*I11/100 | ... L12: =-L6*L11/100
A13: Owner EBITDA (pre IFRS-16, post SBC) | B13: =B8+B10+B12 | C13: =C8+C10+C12 | D13: =D8+D10+D12 | E13: =E8+E10+E12 | F13: =F8+F10+F12 | G13: =G8+G10+G12 | H13: =H8+H10+H12 | I13: =I8+I10+I12 | ... L13: =L8+L10+L12
A14: D&A ex-ROU (negative) | B14: -22.889 | C14: =-C6*Assumptions!$B$8/100 | D14: =-D6*Assumptions!$B$8/100 | E14: =-E6*Assumptions!$B$8/100 | F14: =-F6*Assumptions!$B$8/100 | G14: =-G6*Assumptions!$B$8/100 | H14: =-H6*Assumptions!$B$8/100 | I14: =-I6*Assumptions!$B$8/100 | J14: =-J6*Assumptions!$B$8/100 | ... L14: =-L6*Assumptions!$B$8/100
A15: EBIT | B15: =B13+B14 | C15: =C13+C14 | D15: =D13+D14 | E15: =E13+E14 | F15: =F13+F14 | G15: =G13+G14 | H15: =H13+H14 | I15: =I13+I14 | ... L15: =L13+L14
A16: Cash tax rate % | B16: 29 | C16: 29 | D16: 29 | E16: 29 | F16: 29 | G16: 29 | H16: 29 | I16: 29 | J16: 29 | K16: 29 | L16: 29
A17: Cash tax (negative) | B17: =-MAX(0,B15)*B16/100 | C17: =-MAX(0,C15)*C16/100 | D17: =-MAX(0,D15)*D16/100 | E17: =-MAX(0,E15)*E16/100 | F17: =-MAX(0,F15)*F16/100 | G17: =-MAX(0,G15)*G16/100 | H17: =-MAX(0,H15)*H16/100 | I17: =-MAX(0,I15)*I16/100 | ... L17: =-MAX(0,L15)*L16/100
A18: NOPAT | B18: =B15+B17 | C18: =C15+C17 | D18: =D15+D17 | E18: =E15+E17 | F18: =F15+F17 | G18: =G15+G17 | H18: =H15+H17 | I18: =I15+I17 | ... L18: =L15+L17
A19: add back D&A | B19: =-B14 | C19: =-C14 | D19: =-D14 | E19: =-E14 | F19: =-F14 | G19: =-G14 | H19: =-H14 | I19: =-I14 | ... L19: =-L14
A20: Capex % revenue | C20: 2.6 | D20: 2.5 | E20: 2.4 | F20: 2.4 | G20: 2.4 | H20: 2.4 | I20: 2.4 | J20: 2.4 | K20: 2.4 | L20: 2.4
A21: Capex (negative) | B21: -26.606 | C21: =-C6*C20/100 | D21: =-D6*D20/100 | E21: =-E6*E20/100 | F21: =-F6*F20/100 | G21: =-G6*G20/100 | H21: =-H6*H20/100 | I21: =-I6*I20/100 | J21: =-J6*J20/100 | ... L21: =-L6*L20/100
A22: Working capital (negative = consumed) | B22: -11.136 | C22: =Assumptions!$C$18/100*(C6-B6) | D22: =Assumptions!$C$18/100*(D6-C6) | E22: =Assumptions!$C$18/100*(E6-D6) | F22: =Assumptions!$C$18/100*(F6-E6) | G22: =Assumptions!$C$18/100*(G6-F6) | H22: =Assumptions!$C$18/100*(H6-G6) | I22: =Assumptions!$C$18/100*(I6-H6) | J22: =Assumptions!$C$18/100*(J6-I6) | ... L22: =Assumptions!$C$18/100*(L6-K6)
A23: Unlevered owner FCF | B23: =B18+B19+B21+B22 | C23: =C18+C19+C21+C22 | D23: =D18+D19+D21+D22 | E23: =E18+E19+E21+E22 | F23: =F18+F19+F21+F22 | G23: =G18+G19+G21+G22 | H23: =H18+H19+H21+H22 | I23: =I18+I19+I21+I22 | ... L23: =L18+L19+L21+L22
A24: Discount factor | C24: =1/(1+Assumptions!$C$14/100)^C4 | D24: =1/(1+Assumptions!$C$14/100)^D4 | E24: =1/(1+Assumptions!$C$14/100)^E4 | F24: =1/(1+Assumptions!$C$14/100)^F4 | G24: =1/(1+Assumptions!$C$14/100)^G4 | H24: =1/(1+Assumptions!$C$14/100)^H4 | I24: =1/(1+Assumptions!$C$14/100)^I4 | J24: =1/(1+Assumptions!$C$14/100)^J4 | ... L24: =1/(1+Assumptions!$C$14/100)^L4
A25: PV of FCF | C25: =C23*C24 | D25: =D23*D24 | E25: =E23*E24 | F25: =F23*F24 | G25: =G23*G24 | H25: =H23*H24 | I25: =I23*I24 | J25: =J23*J24 | ... L25: =L23*L24
A27: Memo: FCF before SBC | C27: =C23-C10 | D27: =D23-D10 | E27: =E23-E10 | F27: =F23-F10 | G27: =G23-G10 | H27: =H23-H10 | I27: =I23-I10 | J27: =J23-J10 | ... L27: =L23-L10
A28: Memo: owner FCF margin | B28: =B23/B6 | C28: =C23/C6 | D28: =D23/D6 | E28: =E23/E6 | F28: =F23/F6 | G28: =G23/G6 | H28: =H23/H6 | I28: =I23/I6 | ... L28: =L23/L6
A30: Sum of PV (FY27-FY36) | B30: =SUM(C25:L25)
A31: Terminal growth % | B31: =Assumptions!$C$15
A32: Terminal FCF = FCF10 x (1+g) | B32: =L23*(1+B31/100)
A33: Gordon TV | B33: =B32/(Assumptions!$C$14/100-B31/100)
A34: Cap TV = cap x FCF10 | B34: =Assumptions!$C$16*L23
A35: TV used = MAX(0, MIN(Gordon, cap)) | B35: =MAX(0,MIN(B33,B34))
A36: Implied exit multiple (TV / FCF10) | B36: =IF(L23<>0,B35/L23,0)
A37: PV of TV | B37: =B35*L24
A38: Enterprise value (ex leases) | B38: =B30+B37
A39: less net bank debt | B39: =-Assumptions!$B$5
A40: less NCI | B40: =-Assumptions!$B$6
A41: Equity value | B41: =B38+B39+B40
A42: Diluted shares (m) | B42: =Assumptions!$B$4
A43: VALUE PER SHARE (NZ$) | B43: =B41/B42
...

Sheet DCF_Bull
A1: Bull scenario -- owner FCF, lease treatment B (NZ$m)
A3: Year | B3: FY2026A | C3: FY2027E | D3: FY2028E | E3: FY2029E | F3: FY2030E | G3: FY2031E | H3: FY2032E | I3: FY2033E | J3: FY2034E | K3: FY2035E | L3: FY2036E
A4: Year index | B4: 0 | C4: 1 | D4: 2 | E4: 3 | F4: 4 | G4: 5 | H4: 6 | I4: 7 | J4: 8 | K4: 9 | L4: 10
A5: Revenue growth % | C5: 10 | D5: 8 | E5: 7 | F5: 6 | G5: 5 | H5: 4 | I5: 3.5 | J5: 3 | K5: 3 | L5: 3
A6: Revenue | B6: 1158.807 | C6: =B6*(1+C5/100) | D6: =C6*(1+D5/100) | E6: =D6*(1+E5/100) | F6: =E6*(1+F5/100) | G6: =F6*(1+G5/100) | H6: =G6*(1+H5/100) | I6: =H6*(1+I5/100) | J6: =I6*(1+J5/100) | ... L6: =K6*(1+L5/100)
A7: Adj EBITDA margin % | B7: 11.25 | C7: 12 | D7: 12.8 | E7: 13.5 | F7: 14.2 | G7: 14.8 | H7: 15.2 | I7: 15.5 | J7: 15.5 | K7: 15.5 | L7: 15.5
A8: Adjusted EBITDA (post IFRS-16) | B8: =B6*B7/100 | C8: =C6*C7/100 | D8: =D6*D7/100 | E8: =E6*E7/100 | F8: =F6*F7/100 | G8: =G6*G7/100 | H8: =H6*H7/100 | I8: =I6*I7/100 | ... L8: =L6*L7/100
A9: SBC % revenue | B9: 0.38 | C9: 0.35 | D9: 0.35 | E9: 0.35 | F9: 0.35 | G9: 0.35 | H9: 0.35 | I9: 0.35 | J9: 0.35 | K9: 0.35 | L9: 0.35
A10: SBC (negative) | B10: =-B6*B9/100 | C10: =-C6*C9/100 | D10: =-D6*D9/100 | E10: =-E6*E9/100 | F10: =-F6*F9/100 | G10: =-G6*G9/100 | H10: =-H6*H9/100 | I10: =-I6*I9/100 | ... L10: =-L6*L9/100
A11: Lease cash % revenue | B11: 4.62 | C11: =Assumptions!$D$17 | D11: =Assumptions!$D$17 | E11: =Assumptions!$D$17 | F11: =Assumptions!$D$17 | G11: =Assumptions!$D$17 | H11: =Assumptions!$D$17 | I11: =Assumptions!$D$17 | J11: =Assumptions!$D$17 | ... L11: =Assumptions!$D$17
A12: Lease cash (negative) | B12: =-B6*B11/100 | C12: =-C6*C11/100 | D12: =-D6*D11/100 | E12: =-E6*E11/100 | F12: =-F6*F11/100 | G12: =-G6*G11/100 | H12: =-H6*H11/100 | I12: =-I6*I11/100 | ... L12: =-L6*L11/100
A13: Owner EBITDA (pre IFRS-16, post SBC) | B13: =B8+B10+B12 | C13: =C8+C10+C12 | D13: =D8+D10+D12 | E13: =E8+E10+E12 | F13: =F8+F10+F12 | G13: =G8+G10+G12 | H13: =H8+H10+H12 | I13: =I8+I10+I12 | ... L13: =L8+L10+L12
A14: D&A ex-ROU (negative) | B14: -22.889 | C14: =-C6*Assumptions!$B$8/100 | D14: =-D6*Assumptions!$B$8/100 | E14: =-E6*Assumptions!$B$8/100 | F14: =-F6*Assumptions!$B$8/100 | G14: =-G6*Assumptions!$B$8/100 | H14: =-H6*Assumptions!$B$8/100 | I14: =-I6*Assumptions!$B$8/100 | J14: =-J6*Assumptions!$B$8/100 | ... L14: =-L6*Assumptions!$B$8/100
A15: EBIT | B15: =B13+B14 | C15: =C13+C14 | D15: =D13+D14 | E15: =E13+E14 | F15: =F13+F14 | G15: =G13+G14 | H15: =H13+H14 | I15: =I13+I14 | ... L15: =L13+L14
A16: Cash tax rate % | B16: 29 | C16: 29 | D16: 29 | E16: 29 | F16: 29 | G16: 29 | H16: 29 | I16: 29 | J16: 29 | K16: 29 | L16: 29
A17: Cash tax (negative) | B17: =-MAX(0,B15)*B16/100 | C17: =-MAX(0,C15)*C16/100 | D17: =-MAX(0,D15)*D16/100 | E17: =-MAX(0,E15)*E16/100 | F17: =-MAX(0,F15)*F16/100 | G17: =-MAX(0,G15)*G16/100 | H17: =-MAX(0,H15)*H16/100 | I17: =-MAX(0,I15)*I16/100 | ... L17: =-MAX(0,L15)*L16/100
A18: NOPAT | B18: =B15+B17 | C18: =C15+C17 | D18: =D15+D17 | E18: =E15+E17 | F18: =F15+F17 | G18: =G15+G17 | H18: =H15+H17 | I18: =I15+I17 | ... L18: =L15+L17
A19: add back D&A | B19: =-B14 | C19: =-C14 | D19: =-D14 | E19: =-E14 | F19: =-F14 | G19: =-G14 | H19: =-H14 | I19: =-I14 | ... L19: =-L14
A20: Capex % revenue | C20: 2.6 | D20: 2.5 | E20: 2.4 | F20: 2.4 | G20: 2.4 | H20: 2.4 | I20: 2.4 | J20: 2.4 | K20: 2.4 | L20: 2.4
A21: Capex (negative) | B21: -26.606 | C21: =-C6*C20/100 | D21: =-D6*D20/100 | E21: =-E6*E20/100 | F21: =-F6*F20/100 | G21: =-G6*G20/100 | H21: =-H6*H20/100 | I21: =-I6*I20/100 | J21: =-J6*J20/100 | ... L21: =-L6*L20/100
A22: Working capital (negative = consumed) | B22: -11.136 | C22: =Assumptions!$D$18/100*(C6-B6) | D22: =Assumptions!$D$18/100*(D6-C6) | E22: =Assumptions!$D$18/100*(E6-D6) | F22: =Assumptions!$D$18/100*(F6-E6) | G22: =Assumptions!$D$18/100*(G6-F6) | H22: =Assumptions!$D$18/100*(H6-G6) | I22: =Assumptions!$D$18/100*(I6-H6) | J22: =Assumptions!$D$18/100*(J6-I6) | ... L22: =Assumptions!$D$18/100*(L6-K6)
A23: Unlevered owner FCF | B23: =B18+B19+B21+B22 | C23: =C18+C19+C21+C22 | D23: =D18+D19+D21+D22 | E23: =E18+E19+E21+E22 | F23: =F18+F19+F21+F22 | G23: =G18+G19+G21+G22 | H23: =H18+H19+H21+H22 | I23: =I18+I19+I21+I22 | ... L23: =L18+L19+L21+L22
A24: Discount factor | C24: =1/(1+Assumptions!$D$14/100)^C4 | D24: =1/(1+Assumptions!$D$14/100)^D4 | E24: =1/(1+Assumptions!$D$14/100)^E4 | F24: =1/(1+Assumptions!$D$14/100)^F4 | G24: =1/(1+Assumptions!$D$14/100)^G4 | H24: =1/(1+Assumptions!$D$14/100)^H4 | I24: =1/(1+Assumptions!$D$14/100)^I4 | J24: =1/(1+Assumptions!$D$14/100)^J4 | ... L24: =1/(1+Assumptions!$D$14/100)^L4
A25: PV of FCF | C25: =C23*C24 | D25: =D23*D24 | E25: =E23*E24 | F25: =F23*F24 | G25: =G23*G24 | H25: =H23*H24 | I25: =I23*I24 | J25: =J23*J24 | ... L25: =L23*L24
A27: Memo: FCF before SBC | C27: =C23-C10 | D27: =D23-D10 | E27: =E23-E10 | F27: =F23-F10 | G27: =G23-G10 | H27: =H23-H10 | I27: =I23-I10 | J27: =J23-J10 | ... L27: =L23-L10
A28: Memo: owner FCF margin | B28: =B23/B6 | C28: =C23/C6 | D28: =D23/D6 | E28: =E23/E6 | F28: =F23/F6 | G28: =G23/G6 | H28: =H23/H6 | I28: =I23/I6 | ... L28: =L23/L6
A30: Sum of PV (FY27-FY36) | B30: =SUM(C25:L25)
A31: Terminal growth % | B31: =Assumptions!$D$15
A32: Terminal FCF = FCF10 x (1+g) | B32: =L23*(1+B31/100)
A33: Gordon TV | B33: =B32/(Assumptions!$D$14/100-B31/100)
A34: Cap TV = cap x FCF10 | B34: =Assumptions!$D$16*L23
A35: TV used = MAX(0, MIN(Gordon, cap)) | B35: =MAX(0,MIN(B33,B34))
A36: Implied exit multiple (TV / FCF10) | B36: =IF(L23<>0,B35/L23,0)
A37: PV of TV | B37: =B35*L24
A38: Enterprise value (ex leases) | B38: =B30+B37
A39: less net bank debt | B39: =-Assumptions!$B$5
A40: less NCI | B40: =-Assumptions!$B$6
A41: Equity value | B41: =B38+B39+B40
A42: Diluted shares (m) | B42: =Assumptions!$B$4
A43: VALUE PER SHARE (NZ$) | B43: =B41/B42
...

Sheet FCF_Quality
A1: Reported FCF reconciled to unlevered owner FCF (NZ$m, lease treatment B)
A2: Line | B2: FY2021 | C2: FY2022 | D2: FY2023 | E2: FY2024 | F2: FY2025 | G2: FY2026
A3: Operating cash flow | B3: =Actuals!B4 | C3: =Actuals!C4 | D3: =Actuals!D4 | E3: =Actuals!E4 | F3: =Actuals!F4 | G3: =Actuals!G4
A4: less capex | B4: =-Actuals!B5 | C4: =-Actuals!C5 | D4: =-Actuals!D5 | E4: =-Actuals!E5 | F4: =-Actuals!F5 | G4: =-Actuals!G5
A5: Reported FCF (company style, post-interest) | B5: =B3+B4 | C5: =C3+C4 | D5: =D3+D4 | E5: =E3+E4 | F5: =F3+F4 | G5: =G3+G4
A6: less SBC | B6: =-Actuals!B11 | C6: =-Actuals!C11 | D6: =-Actuals!D11 | E6: =-Actuals!E11 | F6: =-Actuals!F11 | G6: =-Actuals!G11
A7: less interest received | B7: =-Actuals!B9 | C7: =-Actuals!C9 | D7: =-Actuals!D9 | E7: =-Actuals!E9 | F7: =-Actuals!F9 | G7: =-Actuals!G9
A8: less lease principal | B8: =-Actuals!B6 | C8: =-Actuals!C6 | D8: =-Actuals!D6 | E8: =-Actuals!E6 | F8: =-Actuals!F6 | G8: =-Actuals!G6
A9: Owner FCF (levered) | B9: =B5+B6+B7+B8 | C9: =C5+C6+C7+C8 | D9: =D5+D6+D7+D8 | E9: =E5+E6+E7+E8 | F9: =F5+F6+F7+F8 | G9: =G5+G6+G7+G8
A10: add back bank interest x (1 - tax) | B10: =Actuals!B8*(1-Assumptions!$B$9/100) | C10: =Actuals!C8*(1-Assumptions!$B$9/100) | D10: =Actuals!D8*(1-Assumptions!$B$9/100) | E10: =Actuals!E8*(1-Assumptions!$B$9/100) | F10: =Actuals!F8*(1-Assumptions!$B$9/100) | G10: =Actuals!G8*(1-Assumptions!$B$9/100)
A11: Owner FCF (unlevered) | B11: =B9+B10 | C11: =C9+C10 | D11: =D9+D10 | E11: =E9+E10 | F11: =F9+F10 | G11: =G9+G10
A12: Reported FCF margin | B12: =B5/Actuals!B2 | C12: =C5/Actuals!C2 | D12: =D5/Actuals!D2 | E12: =E5/Actuals!E2 | F12: =F5/Actuals!F2 | G12: =G5/Actuals!G2
A13: Owner FCF margin (unlevered) | B13: =B11/Actuals!B2 | C13: =C11/Actuals!C2 | D13: =D11/Actuals!D2 | E13: =E11/Actuals!E2 | F13: =F11/Actuals!F2 | G13: =G11/Actuals!G2
A14: Memo: lease cash (principal + interest) | B14: =Actuals!B6+Actuals!B7 | C14: =Actuals!C6+Actuals!C7 | D14: =Actuals!D6+Actuals!D7 | E14: =Actuals!E6+Actuals!E7 | F14: =Actuals!F6+Actuals!F7 | G14: =Actuals!G6+Actuals!G7
A15: Memo: lease cash % revenue | B15: =B14/Actuals!B2 | C15: =C14/Actuals!C2 | D15: =D14/Actuals!D2 | E15: =E14/Actuals!E2 | F15: =F14/Actuals!F2 | G15: =G14/Actuals!G2
A16: Memo: cash tax paid / NPAT (flag) | B16: =IF(Actuals!B12<>0,Actuals!B10/Actuals!B12,0) | C16: =IF(Actuals!C12<>0,Actuals!C10/Actuals!C12,0) | D16: =IF(Actuals!D12<>0,Actuals!D10/Actuals!D12,0) | E16: =IF(Actuals!E12<>0,Actuals!E10/Actuals!E12,0) | F16: =IF(Actuals!F12<>0,Actuals!F10/Actuals!F12,0) | G16: =IF(Actuals!G12<>0,Actuals!G10/Actuals!G12,0)
A18: Working-capital note: FY23-FY25 owner FCF was flattered by NZ$60m+ of inventory/receivable release after the FY22 build; FY26 absorbed NZ$11.1m. The DCF is built from components, not this series.

Sheet Valuation
A1: Valuation summary (NZ$ per share)
A3: Scenario | B3: Value per share | C3: Upside vs price | D3: Probability | E3: Street value per share | F3: Entry price @ hurdle
A4: Bear | B4: =DCF_Bear!$B$43 | C4: =B4/Assumptions!$B$2-1 | D4: =Assumptions!$B$19 | E4: =DCF_Bear!$B$48 | F4: =(SUMPRODUCT(DCF_Bear!$C$23:$L$23/(1+Assumptions!$B$10/100)^DCF_Bear!$C$4:$L$4)+MAX(0,MIN(DCF_Bear!$L$23*(1+Assumptions!$B$15/100)/(Assumptions!$B$10/100-Assumptions!$B$15/100),Assumptions!$B$16*DCF_Bear!$L$23))/(1+Assumptions!$B$10/100)^10-Assumptions!$B$5-Assumptions!$B$6)/Assumptions!$B$4
A5: Base | B5: =DCF_Base!$B$43 | C5: =B5/Assumptions!$B$2-1 | D5: =Assumptions!$C$19 | E5: =DCF_Base!$B$48 | F5: =(SUMPRODUCT(DCF_Base!$C$23:$L$23/(1+Assumptions!$B$10/100)^DCF_Base!$C$4:$L$4)+MAX(0,MIN(DCF_Base!$L$23*(1+Assumptions!$C$15/100)/(Assumptions!$B$10/100-Assumptions!$C$15/100),Assumptions!$C$16*DCF_Base!$L$23))/(1+Assumptions!$B$10/100)^10-Assumptions!$B$5-Assumptions!$B$6)/Assumptions!$B$4
A6: Bull | B6: =DCF_Bull!$B$43 | C6: =B6/Assumptions!$B$2-1 | D6: =Assumptions!$D$19 | E6: =DCF_Bull!$B$48 | F6: =(SUMPRODUCT(DCF_Bull!$C$23:$L$23/(1+Assumptions!$B$10/100)^DCF_Bull!$C$4:$L$4)+MAX(0,MIN(DCF_Bull!$L$23*(1+Assumptions!$D$15/100)/(Assumptions!$B$10/100-Assumptions!$D$15/100),Assumptions!$D$16*DCF_Bull!$L$23))/(1+Assumptions!$B$10/100)^10-Assumptions!$B$5-Assumptions!$B$6)/Assumptions!$B$4
A8: Probability-weighted value | B8: =SUMPRODUCT(B4:B6,D4:D6)
A9: Margin of safety (1 - price / weighted) | B9: =1-Assumptions!$B$2/B8
A10: Street weighted value | B10: =SUMPRODUCT(E4:E6,D4:D6)
A11: Band position (price - house) / (street - house) | B11: =IF(ABS(B10-B8)<0.000001,"n/a",(Assumptions!$B$2-B8)/(B10-B8))
A12: Weighted entry price @ hurdle (buy-below) | B12: =SUMPRODUCT(F4:F6,D4:D6)
A13: Current price | B13: =Assumptions!$B$2
A15: Required-return table (base case; TV rebuilt at each rate)
A16: Required return % | B16: 9 | C16: 10 | D16: 10.5 | E16: 11 | F16: 12 | G16: 15
A17: Value per share | B17: =(SUMPRODUCT(DCF_Base!$C$23:$L$23/(1+B$16/100)^DCF_Base!$C$4:$L$4)+MAX(0,MIN(DCF_Base!$L$23*(1+Assumptions!$C$15/100)/(B$16/100-Assumptions!$C$15/100),Assumptions!$C$16*DCF_Base!$L$23))/(1+B$16/100)^10-Assumptions!$B$5-Assumptions!$B$6)/Assumptions!$B$4 | C17: =(SUMPRODUCT(DCF_Base!$C$23:$L$23/(1+C$16/100)^DCF_Base!$C$4:$L$4)+MAX(0,MIN(DCF_Base!$L$23*(1+Assumptions!$C$15/100)/(C$16/100-Assumptions!$C$15/100),Assumptions!$C$16*DCF_Base!$L$23))/(1+C$16/100)^10-Assumptions!$B$5-Assumptions!$B$6)/Assumptions!$B$4 | D17: =(SUMPRODUCT(DCF_Base!$C$23:$L$23/(1+D$16/100)^DCF_Base!$C$4:$L$4)+MAX(0,MIN(DCF_Base!$L$23*(1+Assumptions!$C$15/100)/(D$16/100-Assumptions!$C$15/100),Assumptions!$C$16*DCF_Base!$L$23))/(1+D$16/100)^10-Assumptions!$B$5-Assumptions!$B$6)/Assumptions!$B$4 | E17: =(SUMPRODUCT(DCF_Base!$C$23:$L$23/(1+E$16/100)^DCF_Base!$C$4:$L$4)+MAX(0,MIN(DCF_Base!$L$23*(1+Assumptions!$C$15/100)/(E$16/100-Assumptions!$C$15/100),Assumptions!$C$16*DCF_Base!$L$23))/(1+E$16/100)^10-Assumptions!$B$5-Assumptions!$B$6)/Assumptions!$B$4 | F17: =(SUMPRODUCT(DCF_Base!$C$23:$L$23/(1+F$16/100)^DCF_Base!$C$4:$L$4)+MAX(0,MIN(DCF_Base!$L$23*(1+Assumptions!$C$15/100)/(F$16/100-Assumptions!$C$15/100),Assumptions!$C$16*DCF_Base!$L$23))/(1+F$16/100)^10-Assumptions!$B$5-Assumptions!$B$6)/Assumptions!$B$4 | G17: =(SUMPRODUCT(DCF_Base!$C$23:$L$23/(1+G$16/100)^DCF_Base!$C$4:$L$4)+MAX(0,MIN(DCF_Base!$L$23*(1+Assumptions!$C$15/100)/(G$16/100-Assumptions!$C$15/100),Assumptions!$C$16*DCF_Base!$L$23))/(1+G$16/100)^10-Assumptions!$B$5-Assumptions!$B$6)/Assumptions!$B$4
A19: Sensitivity: base value per share, WACC (rows) x terminal growth (columns), cap 13x applied
B20: 1.5 | C20: 2 | D20: 2.5 | E20: 3 | F20: 3.5
A21: 8.5 | B21: =IF($A21>B$20,(SUMPRODUCT(DCF_Base!$C$23:$L$23/(1+$A21/100)^DCF_Base!$C$4:$L$4)+MAX(0,MIN(DCF_Base!$L$23*(1+B$20/100)/($A21/100-B$20/100),Assumptions!$C$16*DCF_Base!$L$23))/(1+$A21/100)^10-Assumptions!$B$5-Assumptions!$B$6)/Assumptions!$B$4,"n/a") | C21: =IF($A21>C$20,(SUMPRODUCT(DCF_Base!$C$23:$L$23/(1+$A21/100)^DCF_Base!$C$4:$L$4)+MAX(0,MIN(DCF_Base!$L$23*(1+C$20/100)/($A21/100-C$20/100),Assumptions!$C$16*DCF_Base!$L$23))/(1+$A21/100)^10-Assumptions!$B$5-Assumptions!$B$6)/Assumptions!$B$4,"n/a") | D21: =IF($A21>D$20,(SUMPRODUCT(DCF_Base!$C$23:$L$23/(1+$A21/100)^DCF_Base!$C$4:$L$4)+MAX(0,MIN(DCF_Base!$L$23*(1+D$20/100)/($A21/100-D$20/100),Assumptions!$C$16*DCF_Base!$L$23))/(1+$A21/100)^10-Assumptions!$B$5-Assumptions!$B$6)/Assumptions!$B$4,"n/a") | E21: =IF($A21>E$20,(SUMPRODUCT(DCF_Base!$C$23:$L$23/(1+$A21/100)^DCF_Base!$C$4:$L$4)+MAX(0,MIN(DCF_Base!$L$23*(1+E$20/100)/($A21/100-E$20/100),Assumptions!$C$16*DCF_Base!$L$23))/(1+$A21/100)^10-Assumptions!$B$5-Assumptions!$B$6)/Assumptions!$B$4,"n/a") | F21: =IF($A21>F$20,(SUMPRODUCT(DCF_Base!$C$23:$L$23/(1+$A21/100)^DCF_Base!$C$4:$L$4)+MAX(0,MIN(DCF_Base!$L$23*(1+F$20/100)/($A21/100-F$20/100),Assumptions!$C$16*DCF_Base!$L$23))/(1+$A21/100)^10-Assumptions!$B$5-Assumptions!$B$6)/Assumptions!$B$4,"n/a")
A22: 9.5 | B22: =IF($A22>B$20,(SUMPRODUCT(DCF_Base!$C$23:$L$23/(1+$A22/100)^DCF_Base!$C$4:$L$4)+MAX(0,MIN(DCF_Base!$L$23*(1+B$20/100)/($A22/100-B$20/100),Assumptions!$C$16*DCF_Base!$L$23))/(1+$A22/100)^10-Assumptions!$B$5-Assumptions!$B$6)/Assumptions!$B$4,"n/a") | C22: =IF($A22>C$20,(SUMPRODUCT(DCF_Base!$C$23:$L$23/(1+$A22/100)^DCF_Base!$C$4:$L$4)+MAX(0,MIN(DCF_Base!$L$23*(1+C$20/100)/($A22/100-C$20/100),Assumptions!$C$16*DCF_Base!$L$23))/(1+$A22/100)^10-Assumptions!$B$5-Assumptions!$B$6)/Assumptions!$B$4,"n/a") | D22: =IF($A22>D$20,(SUMPRODUCT(DCF_Base!$C$23:$L$23/(1+$A22/100)^DCF_Base!$C$4:$L$4)+MAX(0,MIN(DCF_Base!$L$23*(1+D$20/100)/($A22/100-D$20/100),Assumptions!$C$16*DCF_Base!$L$23))/(1+$A22/100)^10-Assumptions!$B$5-Assumptions!$B$6)/Assumptions!$B$4,"n/a") | E22: =IF($A22>E$20,(SUMPRODUCT(DCF_Base!$C$23:$L$23/(1+$A22/100)^DCF_Base!$C$4:$L$4)+MAX(0,MIN(DCF_Base!$L$23*(1+E$20/100)/($A22/100-E$20/100),Assumptions!$C$16*DCF_Base!$L$23))/(1+$A22/100)^10-Assumptions!$B$5-Assumptions!$B$6)/Assumptions!$B$4,"n/a") | F22: =IF($A22>F$20,(SUMPRODUCT(DCF_Base!$C$23:$L$23/(1+$A22/100)^DCF_Base!$C$4:$L$4)+MAX(0,MIN(DCF_Base!$L$23*(1+F$20/100)/($A22/100-F$20/100),Assumptions!$C$16*DCF_Base!$L$23))/(1+$A22/100)^10-Assumptions!$B$5-Assumptions!$B$6)/Assumptions!$B$4,"n/a")
A23: 10.5 | B23: =IF($A23>B$20,(SUMPRODUCT(DCF_Base!$C$23:$L$23/(1+$A23/100)^DCF_Base!$C$4:$L$4)+MAX(0,MIN(DCF_Base!$L$23*(1+B$20/100)/($A23/100-B$20/100),Assumptions!$C$16*DCF_Base!$L$23))/(1+$A23/100)^10-Assumptions!$B$5-Assumptions!$B$6)/Assumptions!$B$4,"n/a") | C23: =IF($A23>C$20,(SUMPRODUCT(DCF_Base!$C$23:$L$23/(1+$A23/100)^DCF_Base!$C$4:$L$4)+MAX(0,MIN(DCF_Base!$L$23*(1+C$20/100)/($A23/100-C$20/100),Assumptions!$C$16*DCF_Base!$L$23))/(1+$A23/100)^10-Assumptions!$B$5-Assumptions!$B$6)/Assumptions!$B$4,"n/a") | D23: =IF($A23>D$20,(SUMPRODUCT(DCF_Base!$C$23:$L$23/(1+$A23/100)^DCF_Base!$C$4:$L$4)+MAX(0,MIN(DCF_Base!$L$23*(1+D$20/100)/($A23/100-D$20/100),Assumptions!$C$16*DCF_Base!$L$23))/(1+$A23/100)^10-Assumptions!$B$5-Assumptions!$B$6)/Assumptions!$B$4,"n/a") | E23: =IF($A23>E$20,(SUMPRODUCT(DCF_Base!$C$23:$L$23/(1+$A23/100)^DCF_Base!$C$4:$L$4)+MAX(0,MIN(DCF_Base!$L$23*(1+E$20/100)/($A23/100-E$20/100),Assumptions!$C$16*DCF_Base!$L$23))/(1+$A23/100)^10-Assumptions!$B$5-Assumptions!$B$6)/Assumptions!$B$4,"n/a") | F23: =IF($A23>F$20,(SUMPRODUCT(DCF_Base!$C$23:$L$23/(1+$A23/100)^DCF_Base!$C$4:$L$4)+MAX(0,MIN(DCF_Base!$L$23*(1+F$20/100)/($A23/100-F$20/100),Assumptions!$C$16*DCF_Base!$L$23))/(1+$A23/100)^10-Assumptions!$B$5-Assumptions!$B$6)/Assumptions!$B$4,"n/a")
A24: 11.5 | B24: =IF($A24>B$20,(SUMPRODUCT(DCF_Base!$C$23:$L$23/(1+$A24/100)^DCF_Base!$C$4:$L$4)+MAX(0,MIN(DCF_Base!$L$23*(1+B$20/100)/($A24/100-B$20/100),Assumptions!$C$16*DCF_Base!$L$23))/(1+$A24/100)^10-Assumptions!$B$5-Assumptions!$B$6)/Assumptions!$B$4,"n/a") | C24: =IF($A24>C$20,(SUMPRODUCT(DCF_Base!$C$23:$L$23/(1+$A24/100)^DCF_Base!$C$4:$L$4)+MAX(0,MIN(DCF_Base!$L$23*(1+C$20/100)/($A24/100-C$20/100),Assumptions!$C$16*DCF_Base!$L$23))/(1+$A24/100)^10-Assumptions!$B$5-Assumptions!$B$6)/Assumptions!$B$4,"n/a") | D24: =IF($A24>D$20,(SUMPRODUCT(DCF_Base!$C$23:$L$23/(1+$A24/100)^DCF_Base!$C$4:$L$4)+MAX(0,MIN(DCF_Base!$L$23*(1+D$20/100)/($A24/100-D$20/100),Assumptions!$C$16*DCF_Base!$L$23))/(1+$A24/100)^10-Assumptions!$B$5-Assumptions!$B$6)/Assumptions!$B$4,"n/a") | E24: =IF($A24>E$20,(SUMPRODUCT(DCF_Base!$C$23:$L$23/(1+$A24/100)^DCF_Base!$C$4:$L$4)+MAX(0,MIN(DCF_Base!$L$23*(1+E$20/100)/($A24/100-E$20/100),Assumptions!$C$16*DCF_Base!$L$23))/(1+$A24/100)^10-Assumptions!$B$5-Assumptions!$B$6)/Assumptions!$B$4,"n/a") | F24: =IF($A24>F$20,(SUMPRODUCT(DCF_Base!$C$23:$L$23/(1+$A24/100)^DCF_Base!$C$4:$L$4)+MAX(0,MIN(DCF_Base!$L$23*(1+F$20/100)/($A24/100-F$20/100),Assumptions!$C$16*DCF_Base!$L$23))/(1+$A24/100)^10-Assumptions!$B$5-Assumptions!$B$6)/Assumptions!$B$4,"n/a")
A25: 12.5 | B25: =IF($A25>B$20,(SUMPRODUCT(DCF_Base!$C$23:$L$23/(1+$A25/100)^DCF_Base!$C$4:$L$4)+MAX(0,MIN(DCF_Base!$L$23*(1+B$20/100)/($A25/100-B$20/100),Assumptions!$C$16*DCF_Base!$L$23))/(1+$A25/100)^10-Assumptions!$B$5-Assumptions!$B$6)/Assumptions!$B$4,"n/a") | C25: =IF($A25>C$20,(SUMPRODUCT(DCF_Base!$C$23:$L$23/(1+$A25/100)^DCF_Base!$C$4:$L$4)+MAX(0,MIN(DCF_Base!$L$23*(1+C$20/100)/($A25/100-C$20/100),Assumptions!$C$16*DCF_Base!$L$23))/(1+$A25/100)^10-Assumptions!$B$5-Assumptions!$B$6)/Assumptions!$B$4,"n/a") | D25: =IF($A25>D$20,(SUMPRODUCT(DCF_Base!$C$23:$L$23/(1+$A25/100)^DCF_Base!$C$4:$L$4)+MAX(0,MIN(DCF_Base!$L$23*(1+D$20/100)/($A25/100-D$20/100),Assumptions!$C$16*DCF_Base!$L$23))/(1+$A25/100)^10-Assumptions!$B$5-Assumptions!$B$6)/Assumptions!$B$4,"n/a") | E25: =IF($A25>E$20,(SUMPRODUCT(DCF_Base!$C$23:$L$23/(1+$A25/100)^DCF_Base!$C$4:$L$4)+MAX(0,MIN(DCF_Base!$L$23*(1+E$20/100)/($A25/100-E$20/100),Assumptions!$C$16*DCF_Base!$L$23))/(1+$A25/100)^10-Assumptions!$B$5-Assumptions!$B$6)/Assumptions!$B$4,"n/a") | F25: =IF($A25>F$20,(SUMPRODUCT(DCF_Base!$C$23:$L$23/(1+$A25/100)^DCF_Base!$C$4:$L$4)+MAX(0,MIN(DCF_Base!$L$23*(1+F$20/100)/($A25/100-F$20/100),Assumptions!$C$16*DCF_Base!$L$23))/(1+$A25/100)^10-Assumptions!$B$5-Assumptions!$B$6)/Assumptions!$B$4,"n/a")
A27: Market-implied memo: EV ex-lease / pre-IFRS-16 EBITDA FY26 | B27: =(Assumptions!$B$2*Assumptions!$B$4+Assumptions!$B$5+Assumptions!$B$6)/(Actuals!G3-Actuals!G6-Actuals!G7)
A28: Market-implied memo: P/E on FY26 adjusted NPAT 21.7 | B28: =Assumptions!$B$2/(21.7/Assumptions!$B$4)
