Workbook

Sheet Model_Info
A1: Metro Performance Glass (MPG.NZ) owner-FCF DCF -- workbook v2, 2026-09-15
A2: Supersedes the 2026-08-20 v1 workbook (base IV $2.50, weighted $2.87), whose flows deducted lease principal only, booked working capital as an inflow on growth and took a tax credit on negative EBIT.
A3: Built by Claude Fable 5.1 (interactive session, at the user's request) from MPG.NZ_DCF.json; the JSON and this workbook implement the same component model and must agree to within rounding.
A4: Data vintage: price NZ$0.83 Yahoo regular close 2026-09-15T01:38Z; balance sheet 31-Mar-2026 (FY2026 annual report, approved 27-May-2026); shares 24,591,464 post 40:1 consolidation (6-Mar-2026); no FY2027 numeric guidance ('no substantive market growth').
A5: Units: NZD thousands throughout except per-share values (NZD) and percentages.
A6: Lease treatment (B): full IFRS-16 lease cash (principal 8,042 + interest 4,546 = 12,588 in FY2026, 6.05% of revenue) is an operating cost in the flows; lease liabilities (69,532) are EXCLUDED from net debt (26,975 = bank debt 35,241 less cash 8,266).
A7: Working capital: net working capital is 14.1% of revenue (receivables + inventory + other current assets - payables - deferred income), so WC capture is NEGATIVE: growth consumes cash.
A8: Cash tax: on max(0, EBIT) where EBIT is after the lease and after D&A EX right-of-use depreciation (3.5% of revenue); rate ramps 0% -> 28% over FY2030-34 as the recognised tax losses (~$26m) run off.
A9: Terminal value: Gordon at WACC / terminal growth, capped at 5.5x year-10 pre-IFRS-16 EBITDA (the stock's own normal-year EV/EBITDA ceiling, expressed as an FCF multiple on each DCF tab), floored at zero.
A10: Scenario drivers (growth, margin, WACC, terminal growth, weights) are the 2026-08-20 dcf-analyst's judgment, kept unchanged; the 2026-09-15 rebuild changed only the flow mechanics, the lease cost, the terminal-cap basis and the sanity check.
A11: Refresh after the FY2027 interim (Nov-2026): FY0 actuals on each DCF tab, Assumptions price/timestamp/net debt/shares, and the Actuals tab. Figures go stale.
A12: Cell colours: blue = hardcoded input, yellow fill = key lever, black = formula, green = cross-sheet link. Sheet names contain no spaces.
A13: Row map on each DCF tab: 5 growth (driver), 6 revenue, 7 EBITDA margin (driver), 8 adj EBITDA, 9 SBC % (driver), 10 SBC, 11 lease % (driver), 12 lease cash, 13 owner EBITDA, 14 D&A, 15 EBIT, 16 cash tax rate (driver), 17 NOPAT, 18 add D&A, 19 capex, 20 WC, 21 owner FCF, 22 discount factor, 23 PV; valuation block rows 28-41; street memo 43-45.

Sheet Actuals
A1: Period | B1: FY2021 | C1: FY2022 | D1: FY2023 | E1: FY2024 | F1: FY2025 | G1: FY2026 | H1: Source
A2: Revenue | B2: 232274 | C2: 236063 | D2: 263520 | E2: 239280 | F2: 213922 | G2: 208163 | H2: Consolidated statement of comprehensive income, each annual report
A3: EBITDA before significant items | B3: 37500 | C3: 24600 | D3: 30744 | E3: 25104 | F3: 16897 | G3: 18241 | H3: Non-GAAP reconciliation page / segment note
A4: Lease principal paid | B4: 5789 | C4: 6940 | D4: 6873 | E4: 7561 | F4: 7542 | G4: 8042 | H4: Cash-flow statement, financing
A5: Interest paid on leases | B5: 3064 | C5: 3139 | D5: 4847 | E5: 4691 | F5: 4955 | G5: 4546 | H5: Cash-flow statement, operating
A6: Pre-IFRS-16 EBITDA (BSI less lease cash) | B6: 28647 | C6: 14521 | D6: 19024 | E6: 12852 | F6: 4400 | G6: 5653 | H6: Derived
A7: Operating cash flow | B7: 28847 | C7: 13254 | D7: 5130 | E7: 18916 | F7: 2072 | G7: 15675 | H7: Cash-flow statement
A8: Capex (PP&E + intangibles) | B8: 5793 | C8: 10399 | D8: 6734 | E8: 3984 | F8: 3009 | G8: 2849 | H8: Cash-flow statement, investing
A9: D&A | B9: 20304 | C9: 18687 | D9: 18960 | E9: 17920 | F9: 17534 | G9: 17356 | H9: OCF reconciliation
A10: Net debt (bank, ex leases) | B10: 47989 | C10: 52255 | D10: 60070 | E10: 53029 | F10: 60494 | G10: 26975 | H10: Net-debt table beneath the cash-flow statement
A11: Lease liabilities | C11: 81280 | D11: 77884 | E11: 78393 | F11: 76565 | G11: 69532 | H11: Balance sheet, current + non-current
A12: Shareholders' equity | B12: 85401 | C12: 85529 | D12: 75467 | E12: 48991 | F12: 35582 | G12: 59958 | H12: Balance sheet
A13: Shares on issue ('000, as filed) | B13: 185378 | C13: 185378 | D13: 185378 | E13: 185378 | F13: 185378 | G13: 24591 | H13: FY2026 is post 40:1 consolidation; earlier years pre-consolidation
A14: FY-end price (raw Yahoo close, NZD) | B14: 0.317 | C14: 0.235 | D14: 0.124 | E14: 0.0857 | F14: 0.0486 | G14: 1 | H14: Yahoo monthly closes; pre-Mar-2026 quotes are pre-consolidation

Sheet Assumptions
A1: Price (NZD) | B1: 0.83 | C1: Yahoo regular close 2026-09-15T01:38Z
A2: Price timestamp | B2: 2026-09-15T01:38:09Z regular NZX close (Yahoo regularMarketPrice via dcf_context)
A3: Diluted shares ('000) | B3: 24591.464 | C3: 24,591,464 post-consolidation; basic = diluted (loss year)
A4: Net debt ('000, bank only) | B4: 26975 | C4: 35,241 borrowings less 8,266 cash; leases excluded (treatment B)
A5: Net cash ('000) | B5: =-B4 | C5: Formula
A6: D&A % of revenue (ex ROU depreciation) | B6: 0.035 | C6: FY2026 D&A 17,356 less ROU depreciation 9,297 = 3.9%; 3.5% as the PP&E base shrinks toward capex
A7: Capex % of revenue | B7: 0.025 | C7: FY2022-26 average 2.3%; FY2026 1.4% is under-investment
A8: WC capture (% of revenue change; negative = investment) | B8: -0.14 | C8: Net working capital 29,318 = 14.1% of FY2026 revenue
A9: FY2026 lease cash ('000) | B9: 12588 | C9: Principal 8,042 + interest 4,546; the lease % rows on each DCF tab escalate this at 2%/yr
A10: Hurdle rate (entry price) | B10: 0.15 | C10: House 15% IRR
A11: FY2026 revenue ('000) | B11: 208163 | C11: FY0 anchor
A12: FY2026 EBITDA before significant items ('000) | B12: 18241 | C12: 18,241 (8.76% margin)
A14: Scenario | B14: Bear | C14: Base | D14: Bull
A15: WACC | B15: 0.15 | C15: 0.135 | D15: 0.125
A16: Terminal growth | B16: 0.015 | C16: 0.025 | D16: 0.03
A17: Terminal cap (x year-10 owner FCF) | B17: 20 | C17: 14.9 | D17: 11
A18: Probability weight | B18: 0.2 | C18: 0.5 | D18: 0.3
A19: Weights check (must be 100%) | B19: =SUM(B18:D18)
A21: Scenario narratives
A22: Bear | B22: Bear case: the construction downturn deepens rather than stabilises -- NZ consent momentum turns into a further multi-year decline and Victoria stays subdued longer than AGG's cost base can absorb. The premises bill ($12.6m, escalating) is fixed while revenue falls, so the pre-IFRS-16 EBITDA margin sits near 1-2% and owner FCF is negative for the first three years; the equity is worth less than zero against $27m of bank debt (the covenant path -- renegotiated Sept-2025, facility to Sept-2028 -- is the binding constraint, not the model). WACC 15.0% carries a solvency-tail premium specific to this path. Terminal cap 5.5x pre-IFRS-16 EV/EBITDA (does not bind: Gordon at 15%/1.5% is lower).
A23: Base | B23: Base case: FY27 essentially flat (management's 'no substantive market growth' guidance) as the $4m FY26 cost-out delivers its full-year benefit; EBITDA margin (before significant items, post-IFRS-16) recovers from 8.76% toward 11% -- about 5% after the $12.6m premises bill, an FY2023-24 level and well below the FY2018/FY2021 peaks -- reflecting the Commerce Commission's finding that NZ glass processing remains structurally oversupplied. Modest volume recovery from FY28 as NZ/AU consents stabilise and Building Code / NatHERS lift the double-glazing mix. Cash tax shielded by the recognised tax losses until FY2030, then ramps to the 28% statutory rate. Owner FCF builds from ~$0.6m (FY26 underlying) to ~$2.7m FY27 and ~$5m by FY31: this is a business that earns roughly its cost of capital on an ex-lease EV of ~$47m, so most of the equity value sits in the bull case, not the base.
A24: Bull | B24: Bull case: the failed Viridian takeover and persistent NZ oversupply keep consolidation optionality alive -- a rationalisation of processing capacity (Metro or a competitor exiting) restores pricing power faster than base assumes; AGG's import-model transition stabilises early and Australia's 1.2-million-homes target flows into volumes; Building Code / NatHERS drive mix-shift to Low-E / laminated / frameless product. Margin reaches 13.5% post-IFRS-16 (about 8% pre-IFRS-16, an FY2023 level, still short of FY2021's 12%). Terminal value is capped at 5.5x pre-IFRS-16 EV/EBITDA, the upper-middle of the stock's own normal-year trading range, so no re-rating beyond history is assumed even here. Amari (51%) or a strategic buying the minority at a premium is the realistic exit path.

Sheet DCF_Bear
A1: Bear case -- owner-FCF DCF, NZD thousands
A3: Year | B3: FY2026A | C3: FY2027E | D3: FY2028E | E3: FY2029E | F3: FY2030E | G3: FY2031E | H3: FY2032E | I3: FY2033E | J3: FY2034E | K3: FY2035E | L3: FY2036E
A4: Index | B4: 0 | C4: 1 | D4: 2 | E4: 3 | F4: 4 | G4: 5 | H4: 6 | I4: 7 | J4: 8 | K4: 9 | L4: 10
A5: Revenue growth YoY | C5: -0.03 | D5: -0.02 | E5: 0 | F5: 0.01 | G5: 0.015 | H5: 0.015 | I5: 0.02 | J5: 0.02 | K5: 0.02 | L5: 0.02
A6: Revenue | B6: =Assumptions!$B$11 | C6: =B6*(1+C5) | D6: =C6*(1+D5) | E6: =D6*(1+E5) | F6: =E6*(1+F5) | G6: =F6*(1+G5) | H6: =G6*(1+H5) | I6: =H6*(1+I5) | J6: =I6*(1+J5) | ... L6: =K6*(1+L5)
A7: Adj EBITDA margin (before significant items) | B7: =Assumptions!$B$12/B6 | C7: 0.075 | D7: 0.07 | E7: 0.075 | F7: 0.08 | G7: 0.085 | H7: 0.085 | I7: 0.085 | J7: 0.085 | K7: 0.085 | L7: 0.085
A8: Adjusted EBITDA | B8: =B6*B7 | C8: =C6*C7 | D8: =D6*D7 | E8: =E6*E7 | F8: =F6*F7 | G8: =G6*G7 | H8: =H6*H7 | I8: =I6*I7 | ... L8: =L6*L7
A9: SBC % of revenue | B9: 0 | C9: 0 | D9: 0 | E9: 0 | F9: 0 | G9: 0 | H9: 0 | I9: 0 | J9: 0 | K9: 0 | L9: 0
A10: SBC | B10: =-B6*B9 | C10: =-C6*C9 | D10: =-D6*D9 | E10: =-E6*E9 | F10: =-F6*F9 | G10: =-G6*G9 | H10: =-H6*H9 | I10: =-I6*I9 | ... L10: =-L6*L9
A11: Lease cash % of revenue (principal + interest) | B11: =Assumptions!$B$9/B6 | C11: 0.0636 | D11: 0.0662 | E11: 0.0675 | F11: 0.0682 | G11: 0.0685 | H11: 0.0688 | I11: 0.0688 | J11: 0.0688 | K11: 0.0688 | L11: 0.0688
A12: Lease cash | B12: =-B6*B11 | C12: =-C6*C11 | D12: =-D6*D11 | E12: =-E6*E11 | F12: =-F6*F11 | G12: =-G6*G11 | H12: =-H6*H11 | I12: =-I6*I11 | ... L12: =-L6*L11
A13: Owner EBITDA (pre-IFRS-16, after SBC) | B13: =B8+B10+B12 | C13: =C8+C10+C12 | D13: =D8+D10+D12 | E13: =E8+E10+E12 | F13: =F8+F10+F12 | G13: =G8+G10+G12 | H13: =H8+H10+H12 | I13: =I8+I10+I12 | ... L13: =L8+L10+L12
A14: D&A (ex ROU depreciation) | C14: =-C6*Assumptions!$B$6 | D14: =-D6*Assumptions!$B$6 | E14: =-E6*Assumptions!$B$6 | F14: =-F6*Assumptions!$B$6 | G14: =-G6*Assumptions!$B$6 | H14: =-H6*Assumptions!$B$6 | I14: =-I6*Assumptions!$B$6 | J14: =-J6*Assumptions!$B$6 | ... L14: =-L6*Assumptions!$B$6
A15: EBIT | C15: =C13+C14 | D15: =D13+D14 | E15: =E13+E14 | F15: =F13+F14 | G15: =G13+G14 | H15: =H13+H14 | I15: =I13+I14 | J15: =J13+J14 | ... L15: =L13+L14
A16: Cash tax rate | C16: 0 | D16: 0 | E16: 0 | F16: 0.05 | G16: 0.1 | H16: 0.15 | I16: 0.2 | J16: 0.28 | K16: 0.28 | L16: 0.28
A17: NOPAT (tax on positive EBIT only) | C17: =C15-MAX(0,C15)*C16 | D17: =D15-MAX(0,D15)*D16 | E17: =E15-MAX(0,E15)*E16 | F17: =F15-MAX(0,F15)*F16 | G17: =G15-MAX(0,G15)*G16 | H17: =H15-MAX(0,H15)*H16 | I17: =I15-MAX(0,I15)*I16 | J17: =J15-MAX(0,J15)*J16 | ... L17: =L15-MAX(0,L15)*L16
A18: add back D&A | C18: =-C14 | D18: =-D14 | E18: =-E14 | F18: =-F14 | G18: =-G14 | H18: =-H14 | I18: =-I14 | J18: =-J14 | ... L18: =-L14
A19: less capex | C19: =-C6*Assumptions!$B$7 | D19: =-D6*Assumptions!$B$7 | E19: =-E6*Assumptions!$B$7 | F19: =-F6*Assumptions!$B$7 | G19: =-G6*Assumptions!$B$7 | H19: =-H6*Assumptions!$B$7 | I19: =-I6*Assumptions!$B$7 | J19: =-J6*Assumptions!$B$7 | ... L19: =-L6*Assumptions!$B$7
A20: add working capital | C20: =Assumptions!$B$8*(C6-B6) | D20: =Assumptions!$B$8*(D6-C6) | E20: =Assumptions!$B$8*(E6-D6) | F20: =Assumptions!$B$8*(F6-E6) | G20: =Assumptions!$B$8*(G6-F6) | H20: =Assumptions!$B$8*(H6-G6) | I20: =Assumptions!$B$8*(I6-H6) | J20: =Assumptions!$B$8*(J6-I6) | ... L20: =Assumptions!$B$8*(L6-K6)
A21: Unlevered owner FCF | C21: =C17+C18+C19+C20 | D21: =D17+D18+D19+D20 | E21: =E17+E18+E19+E20 | F21: =F17+F18+F19+F20 | G21: =G17+G18+G19+G20 | H21: =H17+H18+H19+H20 | I21: =I17+I18+I19+I20 | J21: =J17+J18+J19+J20 | ... L21: =L17+L18+L19+L20
A22: Discount factor | B22: 1 | C22: =1/(1+Assumptions!$B$15)^C4 | D22: =1/(1+Assumptions!$B$15)^D4 | E22: =1/(1+Assumptions!$B$15)^E4 | F22: =1/(1+Assumptions!$B$15)^F4 | G22: =1/(1+Assumptions!$B$15)^G4 | H22: =1/(1+Assumptions!$B$15)^H4 | I22: =1/(1+Assumptions!$B$15)^I4 | J22: =1/(1+Assumptions!$B$15)^J4 | ... L22: =1/(1+Assumptions!$B$15)^L4
A23: PV of FCF | C23: =C21*C22 | D23: =D21*D22 | E23: =E21*E22 | F23: =F21*F22 | G23: =G21*G22 | H23: =H21*H22 | I23: =I21*I22 | J23: =J21*J22 | ... L23: =L21*L22
A25: Memo: FCF before SBC | C25: =C21-C10 | D25: =D21-D10 | E25: =E21-E10 | F25: =F21-F10 | G25: =G21-G10 | H25: =H21-H10 | I25: =I21-I10 | J25: =J21-J10 | ... L25: =L21-L10
A26: Memo: owner-FCF margin | C26: =C21/C6 | D26: =D21/D6 | E26: =E21/E6 | F26: =F21/F6 | G26: =G21/G6 | H26: =H21/H6 | I26: =I21/I6 | J26: =J21/J6 | ... L26: =L21/L6
A28: Sum of PV of FCF | B28: =SUM(C23:L23)
A29: Terminal growth | B29: =Assumptions!$B$16
A30: Terminal FCF (year 10 x (1+g)) | B30: =L21*(1+B29)
A31: Gordon terminal value | B31: =IF(Assumptions!$B$15>B29, B30/(Assumptions!$B$15-B29), B32)
A32: Cap terminal value (cap x year-10 FCF) | B32: =Assumptions!$B$17*L21
A33: Terminal value used = MAX(0, MIN(Gordon, cap)) | B33: =MAX(0,MIN(B31,B32))
A34: Implied exit multiple (x FCF) | B34: =IF(L21>0,B33/L21,"n/a")
A35: PV of terminal value | B35: =B33*L22
A36: Enterprise value | B36: =B28+B35
A37: add net cash (bank debt only; leases in the flows) | B37: =Assumptions!$B$5
A38: Equity value | B38: =B36+B37
A39: Diluted shares ('000) | B39: =Assumptions!$B$3
A40: Value per share (NZD) | B40: =B38/B39
A41: Upside vs price | B41: =B40/Assumptions!$B$1-1
A43: Street memo: PV of explicit-period SBC | B43: =SUMPRODUCT(-C10:L10/(1+Assumptions!$B$15)^C4:L4)
A44: Street memo: PV of terminal SBC | B44: =IF(Assumptions!$B$15>B29,-L10*(1+B29)/(Assumptions!$B$15-B29),0)*L22
...

Sheet DCF_Base
A1: Base case -- owner-FCF DCF, NZD thousands
A3: Year | B3: FY2026A | C3: FY2027E | D3: FY2028E | E3: FY2029E | F3: FY2030E | G3: FY2031E | H3: FY2032E | I3: FY2033E | J3: FY2034E | K3: FY2035E | L3: FY2036E
A4: Index | B4: 0 | C4: 1 | D4: 2 | E4: 3 | F4: 4 | G4: 5 | H4: 6 | I4: 7 | J4: 8 | K4: 9 | L4: 10
A5: Revenue growth YoY | C5: 0.005 | D5: 0.02 | E5: 0.03 | F5: 0.035 | G5: 0.035 | H5: 0.03 | I5: 0.03 | J5: 0.028 | K5: 0.025 | L5: 0.025
A6: Revenue | B6: =Assumptions!$B$11 | C6: =B6*(1+C5) | D6: =C6*(1+D5) | E6: =D6*(1+E5) | F6: =E6*(1+F5) | G6: =F6*(1+G5) | H6: =G6*(1+H5) | I6: =H6*(1+I5) | J6: =I6*(1+J5) | ... L6: =K6*(1+L5)
A7: Adj EBITDA margin (before significant items) | B7: =Assumptions!$B$12/B6 | C7: 0.098 | D7: 0.105 | E7: 0.108 | F7: 0.11 | G7: 0.11 | H7: 0.11 | I7: 0.11 | J7: 0.11 | K7: 0.11 | L7: 0.11
A8: Adjusted EBITDA | B8: =B6*B7 | C8: =C6*C7 | D8: =D6*D7 | E8: =E6*E7 | F8: =F6*F7 | G8: =G6*G7 | H8: =H6*H7 | I8: =I6*I7 | ... L8: =L6*L7
A9: SBC % of revenue | B9: 0 | C9: 0 | D9: 0 | E9: 0 | F9: 0 | G9: 0 | H9: 0 | I9: 0 | J9: 0 | K9: 0 | L9: 0
A10: SBC | B10: =-B6*B9 | C10: =-C6*C9 | D10: =-D6*D9 | E10: =-E6*E9 | F10: =-F6*F9 | G10: =-G6*G9 | H10: =-H6*H9 | I10: =-I6*I9 | ... L10: =-L6*L9
A11: Lease cash % of revenue (principal + interest) | B11: =Assumptions!$B$9/B6 | C11: 0.0614 | D11: 0.0614 | E11: 0.0608 | F11: 0.0599 | G11: 0.059 | H11: 0.0585 | I11: 0.0579 | J11: 0.0574 | K11: 0.0572 | L11: 0.0569
A12: Lease cash | B12: =-B6*B11 | C12: =-C6*C11 | D12: =-D6*D11 | E12: =-E6*E11 | F12: =-F6*F11 | G12: =-G6*G11 | H12: =-H6*H11 | I12: =-I6*I11 | ... L12: =-L6*L11
A13: Owner EBITDA (pre-IFRS-16, after SBC) | B13: =B8+B10+B12 | C13: =C8+C10+C12 | D13: =D8+D10+D12 | E13: =E8+E10+E12 | F13: =F8+F10+F12 | G13: =G8+G10+G12 | H13: =H8+H10+H12 | I13: =I8+I10+I12 | ... L13: =L8+L10+L12
A14: D&A (ex ROU depreciation) | C14: =-C6*Assumptions!$B$6 | D14: =-D6*Assumptions!$B$6 | E14: =-E6*Assumptions!$B$6 | F14: =-F6*Assumptions!$B$6 | G14: =-G6*Assumptions!$B$6 | H14: =-H6*Assumptions!$B$6 | I14: =-I6*Assumptions!$B$6 | J14: =-J6*Assumptions!$B$6 | ... L14: =-L6*Assumptions!$B$6
A15: EBIT | C15: =C13+C14 | D15: =D13+D14 | E15: =E13+E14 | F15: =F13+F14 | G15: =G13+G14 | H15: =H13+H14 | I15: =I13+I14 | J15: =J13+J14 | ... L15: =L13+L14
A16: Cash tax rate | C16: 0 | D16: 0 | E16: 0 | F16: 0.05 | G16: 0.1 | H16: 0.15 | I16: 0.2 | J16: 0.28 | K16: 0.28 | L16: 0.28
A17: NOPAT (tax on positive EBIT only) | C17: =C15-MAX(0,C15)*C16 | D17: =D15-MAX(0,D15)*D16 | E17: =E15-MAX(0,E15)*E16 | F17: =F15-MAX(0,F15)*F16 | G17: =G15-MAX(0,G15)*G16 | H17: =H15-MAX(0,H15)*H16 | I17: =I15-MAX(0,I15)*I16 | J17: =J15-MAX(0,J15)*J16 | ... L17: =L15-MAX(0,L15)*L16
A18: add back D&A | C18: =-C14 | D18: =-D14 | E18: =-E14 | F18: =-F14 | G18: =-G14 | H18: =-H14 | I18: =-I14 | J18: =-J14 | ... L18: =-L14
A19: less capex | C19: =-C6*Assumptions!$B$7 | D19: =-D6*Assumptions!$B$7 | E19: =-E6*Assumptions!$B$7 | F19: =-F6*Assumptions!$B$7 | G19: =-G6*Assumptions!$B$7 | H19: =-H6*Assumptions!$B$7 | I19: =-I6*Assumptions!$B$7 | J19: =-J6*Assumptions!$B$7 | ... L19: =-L6*Assumptions!$B$7
A20: add working capital | C20: =Assumptions!$B$8*(C6-B6) | D20: =Assumptions!$B$8*(D6-C6) | E20: =Assumptions!$B$8*(E6-D6) | F20: =Assumptions!$B$8*(F6-E6) | G20: =Assumptions!$B$8*(G6-F6) | H20: =Assumptions!$B$8*(H6-G6) | I20: =Assumptions!$B$8*(I6-H6) | J20: =Assumptions!$B$8*(J6-I6) | ... L20: =Assumptions!$B$8*(L6-K6)
A21: Unlevered owner FCF | C21: =C17+C18+C19+C20 | D21: =D17+D18+D19+D20 | E21: =E17+E18+E19+E20 | F21: =F17+F18+F19+F20 | G21: =G17+G18+G19+G20 | H21: =H17+H18+H19+H20 | I21: =I17+I18+I19+I20 | J21: =J17+J18+J19+J20 | ... L21: =L17+L18+L19+L20
A22: Discount factor | B22: 1 | C22: =1/(1+Assumptions!$C$15)^C4 | D22: =1/(1+Assumptions!$C$15)^D4 | E22: =1/(1+Assumptions!$C$15)^E4 | F22: =1/(1+Assumptions!$C$15)^F4 | G22: =1/(1+Assumptions!$C$15)^G4 | H22: =1/(1+Assumptions!$C$15)^H4 | I22: =1/(1+Assumptions!$C$15)^I4 | J22: =1/(1+Assumptions!$C$15)^J4 | ... L22: =1/(1+Assumptions!$C$15)^L4
A23: PV of FCF | C23: =C21*C22 | D23: =D21*D22 | E23: =E21*E22 | F23: =F21*F22 | G23: =G21*G22 | H23: =H21*H22 | I23: =I21*I22 | J23: =J21*J22 | ... L23: =L21*L22
A25: Memo: FCF before SBC | C25: =C21-C10 | D25: =D21-D10 | E25: =E21-E10 | F25: =F21-F10 | G25: =G21-G10 | H25: =H21-H10 | I25: =I21-I10 | J25: =J21-J10 | ... L25: =L21-L10
A26: Memo: owner-FCF margin | C26: =C21/C6 | D26: =D21/D6 | E26: =E21/E6 | F26: =F21/F6 | G26: =G21/G6 | H26: =H21/H6 | I26: =I21/I6 | J26: =J21/J6 | ... L26: =L21/L6
A28: Sum of PV of FCF | B28: =SUM(C23:L23)
A29: Terminal growth | B29: =Assumptions!$C$16
A30: Terminal FCF (year 10 x (1+g)) | B30: =L21*(1+B29)
A31: Gordon terminal value | B31: =IF(Assumptions!$C$15>B29, B30/(Assumptions!$C$15-B29), B32)
A32: Cap terminal value (cap x year-10 FCF) | B32: =Assumptions!$C$17*L21
A33: Terminal value used = MAX(0, MIN(Gordon, cap)) | B33: =MAX(0,MIN(B31,B32))
A34: Implied exit multiple (x FCF) | B34: =IF(L21>0,B33/L21,"n/a")
A35: PV of terminal value | B35: =B33*L22
A36: Enterprise value | B36: =B28+B35
A37: add net cash (bank debt only; leases in the flows) | B37: =Assumptions!$B$5
A38: Equity value | B38: =B36+B37
A39: Diluted shares ('000) | B39: =Assumptions!$B$3
A40: Value per share (NZD) | B40: =B38/B39
A41: Upside vs price | B41: =B40/Assumptions!$B$1-1
A43: Street memo: PV of explicit-period SBC | B43: =SUMPRODUCT(-C10:L10/(1+Assumptions!$C$15)^C4:L4)
A44: Street memo: PV of terminal SBC | B44: =IF(Assumptions!$C$15>B29,-L10*(1+B29)/(Assumptions!$C$15-B29),0)*L22
...

Sheet DCF_Bull
A1: Bull case -- owner-FCF DCF, NZD thousands
A3: Year | B3: FY2026A | C3: FY2027E | D3: FY2028E | E3: FY2029E | F3: FY2030E | G3: FY2031E | H3: FY2032E | I3: FY2033E | J3: FY2034E | K3: FY2035E | L3: FY2036E
A4: Index | B4: 0 | C4: 1 | D4: 2 | E4: 3 | F4: 4 | G4: 5 | H4: 6 | I4: 7 | J4: 8 | K4: 9 | L4: 10
A5: Revenue growth YoY | C5: 0.03 | D5: 0.05 | E5: 0.06 | F5: 0.06 | G5: 0.055 | H5: 0.05 | I5: 0.045 | J5: 0.04 | K5: 0.035 | L5: 0.03
A6: Revenue | B6: =Assumptions!$B$11 | C6: =B6*(1+C5) | D6: =C6*(1+D5) | E6: =D6*(1+E5) | F6: =E6*(1+F5) | G6: =F6*(1+G5) | H6: =G6*(1+H5) | I6: =H6*(1+I5) | J6: =I6*(1+J5) | ... L6: =K6*(1+L5)
A7: Adj EBITDA margin (before significant items) | B7: =Assumptions!$B$12/B6 | C7: 0.105 | D7: 0.12 | E7: 0.13 | F7: 0.135 | G7: 0.135 | H7: 0.135 | I7: 0.135 | J7: 0.135 | K7: 0.135 | L7: 0.135
A8: Adjusted EBITDA | B8: =B6*B7 | C8: =C6*C7 | D8: =D6*D7 | E8: =E6*E7 | F8: =F6*F7 | G8: =G6*G7 | H8: =H6*H7 | I8: =I6*I7 | ... L8: =L6*L7
A9: SBC % of revenue | B9: 0 | C9: 0 | D9: 0 | E9: 0 | F9: 0 | G9: 0 | H9: 0 | I9: 0 | J9: 0 | K9: 0 | L9: 0
A10: SBC | B10: =-B6*B9 | C10: =-C6*C9 | D10: =-D6*D9 | E10: =-E6*E9 | F10: =-F6*F9 | G10: =-G6*G9 | H10: =-H6*H9 | I10: =-I6*I9 | ... L10: =-L6*L9
A11: Lease cash % of revenue (principal + interest) | B11: =Assumptions!$B$9/B6 | C11: 0.0599 | D11: 0.0582 | E11: 0.056 | F11: 0.0539 | G11: 0.0521 | H11: 0.0506 | I11: 0.0494 | J11: 0.0484 | K11: 0.0477 | L11: 0.0473
A12: Lease cash | B12: =-B6*B11 | C12: =-C6*C11 | D12: =-D6*D11 | E12: =-E6*E11 | F12: =-F6*F11 | G12: =-G6*G11 | H12: =-H6*H11 | I12: =-I6*I11 | ... L12: =-L6*L11
A13: Owner EBITDA (pre-IFRS-16, after SBC) | B13: =B8+B10+B12 | C13: =C8+C10+C12 | D13: =D8+D10+D12 | E13: =E8+E10+E12 | F13: =F8+F10+F12 | G13: =G8+G10+G12 | H13: =H8+H10+H12 | I13: =I8+I10+I12 | ... L13: =L8+L10+L12
A14: D&A (ex ROU depreciation) | C14: =-C6*Assumptions!$B$6 | D14: =-D6*Assumptions!$B$6 | E14: =-E6*Assumptions!$B$6 | F14: =-F6*Assumptions!$B$6 | G14: =-G6*Assumptions!$B$6 | H14: =-H6*Assumptions!$B$6 | I14: =-I6*Assumptions!$B$6 | J14: =-J6*Assumptions!$B$6 | ... L14: =-L6*Assumptions!$B$6
A15: EBIT | C15: =C13+C14 | D15: =D13+D14 | E15: =E13+E14 | F15: =F13+F14 | G15: =G13+G14 | H15: =H13+H14 | I15: =I13+I14 | J15: =J13+J14 | ... L15: =L13+L14
A16: Cash tax rate | C16: 0 | D16: 0 | E16: 0 | F16: 0.05 | G16: 0.1 | H16: 0.15 | I16: 0.2 | J16: 0.28 | K16: 0.28 | L16: 0.28
A17: NOPAT (tax on positive EBIT only) | C17: =C15-MAX(0,C15)*C16 | D17: =D15-MAX(0,D15)*D16 | E17: =E15-MAX(0,E15)*E16 | F17: =F15-MAX(0,F15)*F16 | G17: =G15-MAX(0,G15)*G16 | H17: =H15-MAX(0,H15)*H16 | I17: =I15-MAX(0,I15)*I16 | J17: =J15-MAX(0,J15)*J16 | ... L17: =L15-MAX(0,L15)*L16
A18: add back D&A | C18: =-C14 | D18: =-D14 | E18: =-E14 | F18: =-F14 | G18: =-G14 | H18: =-H14 | I18: =-I14 | J18: =-J14 | ... L18: =-L14
A19: less capex | C19: =-C6*Assumptions!$B$7 | D19: =-D6*Assumptions!$B$7 | E19: =-E6*Assumptions!$B$7 | F19: =-F6*Assumptions!$B$7 | G19: =-G6*Assumptions!$B$7 | H19: =-H6*Assumptions!$B$7 | I19: =-I6*Assumptions!$B$7 | J19: =-J6*Assumptions!$B$7 | ... L19: =-L6*Assumptions!$B$7
A20: add working capital | C20: =Assumptions!$B$8*(C6-B6) | D20: =Assumptions!$B$8*(D6-C6) | E20: =Assumptions!$B$8*(E6-D6) | F20: =Assumptions!$B$8*(F6-E6) | G20: =Assumptions!$B$8*(G6-F6) | H20: =Assumptions!$B$8*(H6-G6) | I20: =Assumptions!$B$8*(I6-H6) | J20: =Assumptions!$B$8*(J6-I6) | ... L20: =Assumptions!$B$8*(L6-K6)
A21: Unlevered owner FCF | C21: =C17+C18+C19+C20 | D21: =D17+D18+D19+D20 | E21: =E17+E18+E19+E20 | F21: =F17+F18+F19+F20 | G21: =G17+G18+G19+G20 | H21: =H17+H18+H19+H20 | I21: =I17+I18+I19+I20 | J21: =J17+J18+J19+J20 | ... L21: =L17+L18+L19+L20
A22: Discount factor | B22: 1 | C22: =1/(1+Assumptions!$D$15)^C4 | D22: =1/(1+Assumptions!$D$15)^D4 | E22: =1/(1+Assumptions!$D$15)^E4 | F22: =1/(1+Assumptions!$D$15)^F4 | G22: =1/(1+Assumptions!$D$15)^G4 | H22: =1/(1+Assumptions!$D$15)^H4 | I22: =1/(1+Assumptions!$D$15)^I4 | J22: =1/(1+Assumptions!$D$15)^J4 | ... L22: =1/(1+Assumptions!$D$15)^L4
A23: PV of FCF | C23: =C21*C22 | D23: =D21*D22 | E23: =E21*E22 | F23: =F21*F22 | G23: =G21*G22 | H23: =H21*H22 | I23: =I21*I22 | J23: =J21*J22 | ... L23: =L21*L22
A25: Memo: FCF before SBC | C25: =C21-C10 | D25: =D21-D10 | E25: =E21-E10 | F25: =F21-F10 | G25: =G21-G10 | H25: =H21-H10 | I25: =I21-I10 | J25: =J21-J10 | ... L25: =L21-L10
A26: Memo: owner-FCF margin | C26: =C21/C6 | D26: =D21/D6 | E26: =E21/E6 | F26: =F21/F6 | G26: =G21/G6 | H26: =H21/H6 | I26: =I21/I6 | J26: =J21/J6 | ... L26: =L21/L6
A28: Sum of PV of FCF | B28: =SUM(C23:L23)
A29: Terminal growth | B29: =Assumptions!$D$16
A30: Terminal FCF (year 10 x (1+g)) | B30: =L21*(1+B29)
A31: Gordon terminal value | B31: =IF(Assumptions!$D$15>B29, B30/(Assumptions!$D$15-B29), B32)
A32: Cap terminal value (cap x year-10 FCF) | B32: =Assumptions!$D$17*L21
A33: Terminal value used = MAX(0, MIN(Gordon, cap)) | B33: =MAX(0,MIN(B31,B32))
A34: Implied exit multiple (x FCF) | B34: =IF(L21>0,B33/L21,"n/a")
A35: PV of terminal value | B35: =B33*L22
A36: Enterprise value | B36: =B28+B35
A37: add net cash (bank debt only; leases in the flows) | B37: =Assumptions!$B$5
A38: Equity value | B38: =B36+B37
A39: Diluted shares ('000) | B39: =Assumptions!$B$3
A40: Value per share (NZD) | B40: =B38/B39
A41: Upside vs price | B41: =B40/Assumptions!$B$1-1
A43: Street memo: PV of explicit-period SBC | B43: =SUMPRODUCT(-C10:L10/(1+Assumptions!$D$15)^C4:L4)
A44: Street memo: PV of terminal SBC | B44: =IF(Assumptions!$D$15>B29,-L10*(1+B29)/(Assumptions!$D$15-B29),0)*L22
...

Sheet FCF_Quality
A1: Reported FCF reconciled to owner FCF (EV basis), NZD thousands
B2: FY2025 | C2: FY2026 | D2: Note
A3: Operating cash flow (reported) | B3: 2072 | C3: 15675 | D3: Cash-flow statement; after bank interest and lease interest
A4: less capex | B4: -3009 | C4: -2849 | D4: PP&E + intangibles
A5: Free cash flow (company-style) = | B5: =B3+B4 | C5: =C3+C4
A6: less lease principal | B6: -7542 | C6: -8042 | D6: Financing activities; treatment B moves it into the flows
A7: add back bank interest paid | B7: 6051 | C7: 4010 | D7: An equity charge, not an EV charge; net debt is deducted once in the bridge
A8: less interest income | B8: -46 | C8: -49 | D8: Non-operating
A9: less working-capital swing | B9: 4743 | C9: -8194 | D9: OCF reconciliation: FY2026 payables +6,550, inventory +2,477 -- a one-off release
A10: Owner FCF, EV basis, ex WC = | B10: =B5+B6+B7+B8+B9 | C10: =C5+C6+C7+C8+C9 | D10: FY2026 551 is inputs.last_fcf
A11: Reported FCF margin | B11: =B5/213922 | C11: =C5/208163
A12: Owner FCF margin | B12: =B10/213922 | C12: =C10/208163
A13: Memo: WC swing as % of reported FCF | B13: ="n/a" | C13: =-C9/C5 | D13: 64% of FY2026 headline FCF is working-capital timing
A14: Memo: cash tax paid | B14: -180 | C14: -78 | D14: Tax losses shield; note 6.1

Sheet Valuation
A1: Valuation summary (NZD per share)
A3: Scenario | B3: Value per share | C3: Upside vs price | D3: Probability | E3: Street value per share | F3: Entry price @ hurdle
A4: Bear | B4: =DCF_Bear!$B$40 | C4: =B4/Assumptions!$B$1-1 | D4: =Assumptions!$B$18 | E4: =DCF_Bear!$B$45 | F4: =(SUMPRODUCT(DCF_Bear!$C$21:$L$21/(1+Assumptions!$B$10)^DCF_Bear!$C$4:$L$4)+MAX(0,MIN(IF(Assumptions!$B$10>Assumptions!$B$16,DCF_Bear!$L$21*(1+Assumptions!$B$16)/(Assumptions!$B$10-Assumptions!$B$16),Assumptions!$B$17*DCF_Bear!$L$21),Assumptions!$B$17*DCF_Bear!$L$21))/(1+Assumptions!$B$10)^10+Assumptions!$B$5)/Assumptions!$B$3
A5: Base | B5: =DCF_Base!$B$40 | C5: =B5/Assumptions!$B$1-1 | D5: =Assumptions!$C$18 | E5: =DCF_Base!$B$45 | F5: =(SUMPRODUCT(DCF_Base!$C$21:$L$21/(1+Assumptions!$B$10)^DCF_Base!$C$4:$L$4)+MAX(0,MIN(IF(Assumptions!$B$10>Assumptions!$C$16,DCF_Base!$L$21*(1+Assumptions!$C$16)/(Assumptions!$B$10-Assumptions!$C$16),Assumptions!$C$17*DCF_Base!$L$21),Assumptions!$C$17*DCF_Base!$L$21))/(1+Assumptions!$B$10)^10+Assumptions!$B$5)/Assumptions!$B$3
A6: Bull | B6: =DCF_Bull!$B$40 | C6: =B6/Assumptions!$B$1-1 | D6: =Assumptions!$D$18 | E6: =DCF_Bull!$B$45 | F6: =(SUMPRODUCT(DCF_Bull!$C$21:$L$21/(1+Assumptions!$B$10)^DCF_Bull!$C$4:$L$4)+MAX(0,MIN(IF(Assumptions!$B$10>Assumptions!$D$16,DCF_Bull!$L$21*(1+Assumptions!$D$16)/(Assumptions!$B$10-Assumptions!$D$16),Assumptions!$D$17*DCF_Bull!$L$21),Assumptions!$D$17*DCF_Bull!$L$21))/(1+Assumptions!$B$10)^10+Assumptions!$B$5)/Assumptions!$B$3
A8: Probability-weighted value | B8: =SUMPRODUCT(B4:B6,D4:D6)
A9: Margin of safety vs price | B9: =1-Assumptions!$B$1/B8
A10: Street weighted value | B10: =SUMPRODUCT(E4:E6,D4:D6)
A11: Weighted entry price @ hurdle | B11: =SUMPRODUCT(F4:F6,D4:D6)
A12: Band position (house = street in an SBC-zero market) | B12: n/a -- SBC is zero, so house and street coincide
A14: Required-return table (base case)
A15: Required return | B15: 0.09 | C15: 0.1 | D15: 0.11 | E15: 0.12 | F15: 0.135 | G15: 0.15
A16: Value per share | B16: =(SUMPRODUCT(DCF_Base!$C$21:$L$21/(1+B15)^DCF_Base!$C$4:$L$4)+MAX(0,MIN(IF(B15>Assumptions!$C$16,DCF_Base!$L$21*(1+Assumptions!$C$16)/(B15-Assumptions!$C$16),Assumptions!$C$17*DCF_Base!$L$21),Assumptions!$C$17*DCF_Base!$L$21))/(1+B15)^10+Assumptions!$B$5)/Assumptions!$B$3 | C16: =(SUMPRODUCT(DCF_Base!$C$21:$L$21/(1+C15)^DCF_Base!$C$4:$L$4)+MAX(0,MIN(IF(C15>Assumptions!$C$16,DCF_Base!$L$21*(1+Assumptions!$C$16)/(C15-Assumptions!$C$16),Assumptions!$C$17*DCF_Base!$L$21),Assumptions!$C$17*DCF_Base!$L$21))/(1+C15)^10+Assumptions!$B$5)/Assumptions!$B$3 | D16: =(SUMPRODUCT(DCF_Base!$C$21:$L$21/(1+D15)^DCF_Base!$C$4:$L$4)+MAX(0,MIN(IF(D15>Assumptions!$C$16,DCF_Base!$L$21*(1+Assumptions!$C$16)/(D15-Assumptions!$C$16),Assumptions!$C$17*DCF_Base!$L$21),Assumptions!$C$17*DCF_Base!$L$21))/(1+D15)^10+Assumptions!$B$5)/Assumptions!$B$3 | E16: =(SUMPRODUCT(DCF_Base!$C$21:$L$21/(1+E15)^DCF_Base!$C$4:$L$4)+MAX(0,MIN(IF(E15>Assumptions!$C$16,DCF_Base!$L$21*(1+Assumptions!$C$16)/(E15-Assumptions!$C$16),Assumptions!$C$17*DCF_Base!$L$21),Assumptions!$C$17*DCF_Base!$L$21))/(1+E15)^10+Assumptions!$B$5)/Assumptions!$B$3 | F16: =(SUMPRODUCT(DCF_Base!$C$21:$L$21/(1+F15)^DCF_Base!$C$4:$L$4)+MAX(0,MIN(IF(F15>Assumptions!$C$16,DCF_Base!$L$21*(1+Assumptions!$C$16)/(F15-Assumptions!$C$16),Assumptions!$C$17*DCF_Base!$L$21),Assumptions!$C$17*DCF_Base!$L$21))/(1+F15)^10+Assumptions!$B$5)/Assumptions!$B$3 | G16: =(SUMPRODUCT(DCF_Base!$C$21:$L$21/(1+G15)^DCF_Base!$C$4:$L$4)+MAX(0,MIN(IF(G15>Assumptions!$C$16,DCF_Base!$L$21*(1+Assumptions!$C$16)/(G15-Assumptions!$C$16),Assumptions!$C$17*DCF_Base!$L$21),Assumptions!$C$17*DCF_Base!$L$21))/(1+G15)^10+Assumptions!$B$5)/Assumptions!$B$3
A18: Sensitivity: base-case value per share, WACC (rows) x terminal growth (columns)
B19: 0.015 | C19: 0.02 | D19: 0.025 | E19: 0.03 | F19: 0.035
A20: 0.115 | B20: =IF($A20>B$19,(SUMPRODUCT(DCF_Base!$C$21:$L$21/(1+$A20)^DCF_Base!$C$4:$L$4)+MAX(0,MIN(DCF_Base!$L$21*(1+B$19)/($A20-B$19),Assumptions!$C$17*DCF_Base!$L$21))/(1+$A20)^10+Assumptions!$B$5)/Assumptions!$B$3,"n/a") | C20: =IF($A20>C$19,(SUMPRODUCT(DCF_Base!$C$21:$L$21/(1+$A20)^DCF_Base!$C$4:$L$4)+MAX(0,MIN(DCF_Base!$L$21*(1+C$19)/($A20-C$19),Assumptions!$C$17*DCF_Base!$L$21))/(1+$A20)^10+Assumptions!$B$5)/Assumptions!$B$3,"n/a") | D20: =IF($A20>D$19,(SUMPRODUCT(DCF_Base!$C$21:$L$21/(1+$A20)^DCF_Base!$C$4:$L$4)+MAX(0,MIN(DCF_Base!$L$21*(1+D$19)/($A20-D$19),Assumptions!$C$17*DCF_Base!$L$21))/(1+$A20)^10+Assumptions!$B$5)/Assumptions!$B$3,"n/a") | E20: =IF($A20>E$19,(SUMPRODUCT(DCF_Base!$C$21:$L$21/(1+$A20)^DCF_Base!$C$4:$L$4)+MAX(0,MIN(DCF_Base!$L$21*(1+E$19)/($A20-E$19),Assumptions!$C$17*DCF_Base!$L$21))/(1+$A20)^10+Assumptions!$B$5)/Assumptions!$B$3,"n/a") | F20: =IF($A20>F$19,(SUMPRODUCT(DCF_Base!$C$21:$L$21/(1+$A20)^DCF_Base!$C$4:$L$4)+MAX(0,MIN(DCF_Base!$L$21*(1+F$19)/($A20-F$19),Assumptions!$C$17*DCF_Base!$L$21))/(1+$A20)^10+Assumptions!$B$5)/Assumptions!$B$3,"n/a")
A21: 0.125 | B21: =IF($A21>B$19,(SUMPRODUCT(DCF_Base!$C$21:$L$21/(1+$A21)^DCF_Base!$C$4:$L$4)+MAX(0,MIN(DCF_Base!$L$21*(1+B$19)/($A21-B$19),Assumptions!$C$17*DCF_Base!$L$21))/(1+$A21)^10+Assumptions!$B$5)/Assumptions!$B$3,"n/a") | C21: =IF($A21>C$19,(SUMPRODUCT(DCF_Base!$C$21:$L$21/(1+$A21)^DCF_Base!$C$4:$L$4)+MAX(0,MIN(DCF_Base!$L$21*(1+C$19)/($A21-C$19),Assumptions!$C$17*DCF_Base!$L$21))/(1+$A21)^10+Assumptions!$B$5)/Assumptions!$B$3,"n/a") | D21: =IF($A21>D$19,(SUMPRODUCT(DCF_Base!$C$21:$L$21/(1+$A21)^DCF_Base!$C$4:$L$4)+MAX(0,MIN(DCF_Base!$L$21*(1+D$19)/($A21-D$19),Assumptions!$C$17*DCF_Base!$L$21))/(1+$A21)^10+Assumptions!$B$5)/Assumptions!$B$3,"n/a") | E21: =IF($A21>E$19,(SUMPRODUCT(DCF_Base!$C$21:$L$21/(1+$A21)^DCF_Base!$C$4:$L$4)+MAX(0,MIN(DCF_Base!$L$21*(1+E$19)/($A21-E$19),Assumptions!$C$17*DCF_Base!$L$21))/(1+$A21)^10+Assumptions!$B$5)/Assumptions!$B$3,"n/a") | F21: =IF($A21>F$19,(SUMPRODUCT(DCF_Base!$C$21:$L$21/(1+$A21)^DCF_Base!$C$4:$L$4)+MAX(0,MIN(DCF_Base!$L$21*(1+F$19)/($A21-F$19),Assumptions!$C$17*DCF_Base!$L$21))/(1+$A21)^10+Assumptions!$B$5)/Assumptions!$B$3,"n/a")
A22: 0.135 | B22: =IF($A22>B$19,(SUMPRODUCT(DCF_Base!$C$21:$L$21/(1+$A22)^DCF_Base!$C$4:$L$4)+MAX(0,MIN(DCF_Base!$L$21*(1+B$19)/($A22-B$19),Assumptions!$C$17*DCF_Base!$L$21))/(1+$A22)^10+Assumptions!$B$5)/Assumptions!$B$3,"n/a") | C22: =IF($A22>C$19,(SUMPRODUCT(DCF_Base!$C$21:$L$21/(1+$A22)^DCF_Base!$C$4:$L$4)+MAX(0,MIN(DCF_Base!$L$21*(1+C$19)/($A22-C$19),Assumptions!$C$17*DCF_Base!$L$21))/(1+$A22)^10+Assumptions!$B$5)/Assumptions!$B$3,"n/a") | D22: =IF($A22>D$19,(SUMPRODUCT(DCF_Base!$C$21:$L$21/(1+$A22)^DCF_Base!$C$4:$L$4)+MAX(0,MIN(DCF_Base!$L$21*(1+D$19)/($A22-D$19),Assumptions!$C$17*DCF_Base!$L$21))/(1+$A22)^10+Assumptions!$B$5)/Assumptions!$B$3,"n/a") | E22: =IF($A22>E$19,(SUMPRODUCT(DCF_Base!$C$21:$L$21/(1+$A22)^DCF_Base!$C$4:$L$4)+MAX(0,MIN(DCF_Base!$L$21*(1+E$19)/($A22-E$19),Assumptions!$C$17*DCF_Base!$L$21))/(1+$A22)^10+Assumptions!$B$5)/Assumptions!$B$3,"n/a") | F22: =IF($A22>F$19,(SUMPRODUCT(DCF_Base!$C$21:$L$21/(1+$A22)^DCF_Base!$C$4:$L$4)+MAX(0,MIN(DCF_Base!$L$21*(1+F$19)/($A22-F$19),Assumptions!$C$17*DCF_Base!$L$21))/(1+$A22)^10+Assumptions!$B$5)/Assumptions!$B$3,"n/a")
A23: 0.145 | B23: =IF($A23>B$19,(SUMPRODUCT(DCF_Base!$C$21:$L$21/(1+$A23)^DCF_Base!$C$4:$L$4)+MAX(0,MIN(DCF_Base!$L$21*(1+B$19)/($A23-B$19),Assumptions!$C$17*DCF_Base!$L$21))/(1+$A23)^10+Assumptions!$B$5)/Assumptions!$B$3,"n/a") | C23: =IF($A23>C$19,(SUMPRODUCT(DCF_Base!$C$21:$L$21/(1+$A23)^DCF_Base!$C$4:$L$4)+MAX(0,MIN(DCF_Base!$L$21*(1+C$19)/($A23-C$19),Assumptions!$C$17*DCF_Base!$L$21))/(1+$A23)^10+Assumptions!$B$5)/Assumptions!$B$3,"n/a") | D23: =IF($A23>D$19,(SUMPRODUCT(DCF_Base!$C$21:$L$21/(1+$A23)^DCF_Base!$C$4:$L$4)+MAX(0,MIN(DCF_Base!$L$21*(1+D$19)/($A23-D$19),Assumptions!$C$17*DCF_Base!$L$21))/(1+$A23)^10+Assumptions!$B$5)/Assumptions!$B$3,"n/a") | E23: =IF($A23>E$19,(SUMPRODUCT(DCF_Base!$C$21:$L$21/(1+$A23)^DCF_Base!$C$4:$L$4)+MAX(0,MIN(DCF_Base!$L$21*(1+E$19)/($A23-E$19),Assumptions!$C$17*DCF_Base!$L$21))/(1+$A23)^10+Assumptions!$B$5)/Assumptions!$B$3,"n/a") | F23: =IF($A23>F$19,(SUMPRODUCT(DCF_Base!$C$21:$L$21/(1+$A23)^DCF_Base!$C$4:$L$4)+MAX(0,MIN(DCF_Base!$L$21*(1+F$19)/($A23-F$19),Assumptions!$C$17*DCF_Base!$L$21))/(1+$A23)^10+Assumptions!$B$5)/Assumptions!$B$3,"n/a")
A24: 0.155 | B24: =IF($A24>B$19,(SUMPRODUCT(DCF_Base!$C$21:$L$21/(1+$A24)^DCF_Base!$C$4:$L$4)+MAX(0,MIN(DCF_Base!$L$21*(1+B$19)/($A24-B$19),Assumptions!$C$17*DCF_Base!$L$21))/(1+$A24)^10+Assumptions!$B$5)/Assumptions!$B$3,"n/a") | C24: =IF($A24>C$19,(SUMPRODUCT(DCF_Base!$C$21:$L$21/(1+$A24)^DCF_Base!$C$4:$L$4)+MAX(0,MIN(DCF_Base!$L$21*(1+C$19)/($A24-C$19),Assumptions!$C$17*DCF_Base!$L$21))/(1+$A24)^10+Assumptions!$B$5)/Assumptions!$B$3,"n/a") | D24: =IF($A24>D$19,(SUMPRODUCT(DCF_Base!$C$21:$L$21/(1+$A24)^DCF_Base!$C$4:$L$4)+MAX(0,MIN(DCF_Base!$L$21*(1+D$19)/($A24-D$19),Assumptions!$C$17*DCF_Base!$L$21))/(1+$A24)^10+Assumptions!$B$5)/Assumptions!$B$3,"n/a") | E24: =IF($A24>E$19,(SUMPRODUCT(DCF_Base!$C$21:$L$21/(1+$A24)^DCF_Base!$C$4:$L$4)+MAX(0,MIN(DCF_Base!$L$21*(1+E$19)/($A24-E$19),Assumptions!$C$17*DCF_Base!$L$21))/(1+$A24)^10+Assumptions!$B$5)/Assumptions!$B$3,"n/a") | F24: =IF($A24>F$19,(SUMPRODUCT(DCF_Base!$C$21:$L$21/(1+$A24)^DCF_Base!$C$4:$L$4)+MAX(0,MIN(DCF_Base!$L$21*(1+F$19)/($A24-F$19),Assumptions!$C$17*DCF_Base!$L$21))/(1+$A24)^10+Assumptions!$B$5)/Assumptions!$B$3,"n/a")
A26: Sanity (lease-consistent): market at $0.83 = 8.4x FY2026 pre-IFRS-16 EBITDA / 6.4x lease-inclusive / 0.34x book; base terminal 3.4x pre-IFRS-16 EBITDA vs 3.7-6.6x normal-year history.
