Workbook

Sheet Model_Info
A1: WasteCo Group Limited (NZX: WCO) -- owner-FCF DCF model
A2: Version | B2: 1.0 -- fresh build 2026-09-20 (no prior DCF for this ticker). Supersedes nothing.
A3: Built by | B3: dcf-analyst agent (Claude Fable 5.1), 2026-09-20, at the request of the research-stock orchestrator for Stephen Williams.
A4: Model | B4: Owner-FCF DCF on the enterprise, component build, 10-year horizon, leases as operating cost (treatment B), convertible notes at face in net debt, equity as the residual. Distress bear (terminal value on the zero floor) weighted 45%.
A5: Why this model | B5: Operating going concern with $70m revenue and positive OCF, so forward flows are the right thing to discount; but going-concern material uncertainty, second covenant breach, all core bank facilities maturing 30-May-2027 and net assets of $3.2m against $58m of debt+leases make the equity a subordinated residual. Neither a pure asset waterfall (AFC.NZ) nor a vanilla three-growth DCF fits; the hybrid is deliberate. See WCO.NZ_DCF.json model_note.
A6: Units | B6: NZ$000 throughout; shares in thousands; per-share values in NZD. Currency of flows NZD; quote currency NZD.
A7: Price | B7: NZ$0.007 -- Yahoo regularMarketPrice 2026-09-18T01:48:47Z (Friday regular session). Equals the live placement/SPP issue price; anchored by the raise until allotment 30-Sep / 7-Oct-2026. Goes stale.
A8: Balance sheet | B8: 31-Mar-2026 audited (FY2026 annual report, released 29-May-2026) PLUS announced pro-forma items: $700k convertible notes 17-Aug-2026 (convert on the raise), $2.0m placement (2-Sep-2026, minimum, not underwritten, closes 25-Sep), $0.75m SPP (11-Sep-2026, closes 30-Sep), and $8m of the $10-12m asset-sale target. Six months stale in the wrong direction; refresh at allotment and at the H1 FY2027 result.
A9: Share count | B9: 1,098,372.765k on issue + 285,714k placement + 107,143k SPP + 12,001k note conversion = 1,503,231k pro-forma. Held flat (SBC expensed in flows). Out of the money and excluded: 24.4m options at $0.030; $2m notes convertible at $0.007 (285,714k); $15m Empire notes at $0.02 (750,000k).
A10: Guidance | B10: 2-Sep-2026 fact sheet: FY27 operating EBITDA 'the same or similar' to FY26 ($5.85m); loss reduced by $2.5-4m; ~$5m annualised cost-out; FY28 full-year $5-6m cost reduction, revenue and EBITDA 'to grow significantly'.
A11: Lease treatment | B11: B: principal (3,090) + interest (1,334) = 6.3% of revenue charged in the flows; lease liabilities (17,988) excluded from net debt; tax EBIT uses D&A ex right-of-use depreciation (9.55% of FY26 revenue, gliding to 6.5%).
A12: WACC | B12: 11% NZD-built (rf 4.4% + 5.5% ERP x 1.1 + ~3% small-cap = ~13.5% CoE; Kd ~9% pre-tax, no shield while loss-making; 50/50). Same in all scenarios -- going-concern risk is charged once, in the bear weight.
A13: Terminal value | B13: max(0, min(Gordon, cap x FCF_10)). Caps: bear 10x, base 12x, bull 14x (fleet-heavy sub-scale service business, below the house 20x).
... A18: Warning | B18: Figures go stale. The JSON and this workbook were built from one engine; if they disagree after edits, the workbook formulas are live and the JSON is a snapshot.

Sheet Actuals
A1: NZ$000 | B1: FY2023 | C1: FY2024 | D1: FY2025 | E1: FY2026 | F1: Source
A2: Revenue | B2: 34392 | C2: 48233 | D2: 56409 | E2: 70217 | F2: Annual reports, statement of profit or loss
A3: Operating EBITDA (segment total, post-IFRS-16) | B3: 5586 | C3: 3369 | D3: 4640 | E3: 5851 | F3: Segment note; FY26 note 5 (before H&S reset 1,750, restructuring 1,345, acquisition 27)
A4: Net loss | B4: -1991 | C4: -4135 | D4: -9854 | E4: -12354 | F4: Statement of profit or loss
A5: Net cash from operating activities (pre debt interest) | B5: 3587 | C5: 1197 | D5: 4469 | E5: 5557 | F5: Cash flow statement (interest on borrowings sits in financing)
A6: Payments for PP&E + intangibles | B6: 8548 | C6: 3595 | D6: 1050 | E6: 1878 | F6: Cash flow statement
A7: Principal repayment of lease liabilities | B7: 725 | C7: 1323 | D7: 1700 | E7: 3090 | F7: Cash flow statement, financing
A8: Interest paid on lease liabilities | B8: 413 | C8: 799 | D8: 1037 | E8: 1334 | F8: Cash flow statement, financing
A9: Interest paid on borrowings + convertible notes | B9: 1573 | C9: 2264 | D9: 3160 | E9: 3088 | F9: Cash flow statement, financing (FY26: 1,938 + 1,150)
A10: Share-based payment expense | B10: 405 | C10: 275 | D10: 0 | E10: 76 | F10: Non-cash reconciliation / note 20 (FY25 net reversal -60 shown as 0)
A11: Depreciation & amortisation (total) | B11: 4054 | C11: 6192 | D11: 8169 | E11: 9749 | F11: Note 7
A12: of which right-of-use depreciation | B12: 837 | C12: 1550 | D12: 2019 | E12: 3040 | F12: Note 15.1
A13: Shareholders' equity | B13: 9889 | C13: 16387 | D13: 15298 | E13: 3201 | F13: Statement of financial position
A14: Borrowings (carrying, ex-lease) | B14: 27851 | C14: 45413 | D14: 40950 | E14: 40096 | F14: FY25/FY26 note 24.3; FY23/FY24 total debt per Metrics.csv incl. leases
A15: Lease liabilities | D15: 15980 | E15: 17988 | F15: Note 15.2
A16: Cash at bank | B16: 873 | C16: 1751 | D16: 5854 | E16: 1159 | F16: Statement of financial position
A17: Shares on issue (000) | B17: 504000 | C17: 800946 | D17: 1098373 | E17: 1098373 | F17: Note 19 (FY25 250,000k placement at $0.02)
A19: Balance sheet snapshot 31-Mar-2026 and pro-forma bridge (NZ$000)
A20: Borrowings at carrying value | B20: 40096
A21: Convertible notes: uplift to face ($17m - 13,046) | B21: 3954
A22: less cash | B22: -1159
A23: less $700k notes cash (17-Aug-2026; note converts) | B23: -700
A24: less placement $2.0m minimum (2-Sep-2026) | B24: -2000
A25: less SPP $0.75m (11-Sep-2026) | B25: -750
A26: less asset-sale proceeds credited ($10-12m target, haircut) | B26: -8000
A27: Total: net debt used in bridge | B27: =SUM(B20:B26)
A29: Guidance (2-Sep-2026 fact sheet)
A30: FY27 operating EBITDA 'the same or similar to FY2026'; net loss reduced $2.5-4m; ~$5m annualised cost-out; $10-12m asset sales; FY28 full-year $5-6m cost reduction, revenue/EBITDA 'grow significantly'.
A31: Buybacks: none in any period. Dividends: none.

Sheet Assumptions
A1: Globals
A2: Current price (NZD) | B2: 0.007 | C2: Yahoo 2026-09-18T01:48:47Z; equals placement price
A3: Diluted shares (000), pro-forma | B3: 1503230.6 | C3: 1,098,373 + 285,714 + 107,143 + 12,001; see Model_Info
A4: Net debt used in bridge (NZ$000) | B4: =Actuals!$B$27 | C4: Actuals bridge: pro-forma net borrowings less $8m asset sales; leases excluded (treatment B)
A5: Lease cost % of revenue | B5: 6.3 | C5: FY26 lease cash 4,424 / 70,217
A6: SBC % of revenue | B6: 0.1 | C6: FY26 expense 76 / 70,217 = 0.11%
A7: WC capture % of revenue change | B7: -5 | C7: receivables-led growth consumes cash
A8: Hurdle rate | B8: 0.15 | C8: entry-price IRR; TV rebuilt at the hurdle
A9: FY0 revenue (NZ$000) | B9: 70217 | C9: FY2026
A12: Scenario parameters
B13: Bear | C13: Base | D13: Bull
A14: WACC % | B14: 11 | C14: 11 | D14: 11
A15: Terminal growth % | B15: 2 | C15: 2.5 | D15: 2.5
A16: Terminal cap (x FCF_10) | B16: 10 | C16: 12 | D16: 14
A17: Probability weight | B17: 0.45 | C17: 0.35 | D17: 0.2
A18: Weights sum (must be 1.0) | B18: =SUM(B17:D17)
A20: Scenario narratives
A21: BEAR | B21: Turnaround stalls and the balance sheet resolves against equity. The $5m cost-out slips, the divested divisions take revenue with them (-3% FY27, flat FY28), operating EBITDA margin drifts 7.5-10% and never covers the 6.3% lease charge plus 3.5-4.5% fleet capex, so owner FCF is negative every year and the terminal value sits on the zero floor. In May 2027 the $21.8m of Kiwibank core facilities are not rolled on acceptable terms; the outcome is either enforcement under the first-ranking GSA or a rescue recapitalisation (Empire converting its $15m secured notes / a debt-for-equity swap at or below $0.007) that leaves existing holders with a sliver. The WorkSafe prosecution and the second fatality weigh on council re-tenders. Asset sales realise less than $8m in a forced process (not varied in the bridge; worth ~-$0.003/share on top).
A22: BASE | B22: Turnaround partly delivers and the lender keeps rolling. FY27 operating EBITDA flat on FY26 (8.3%) per the fact-sheet guidance, then roughly $3m of the targeted $5m annualised cost-out sticks from FY28 (11%), rising to a 14% mature margin by FY32 -- below WasteCo's own FY23 16.2% and well below the landfill-owning majors. Revenue grows 1.5% FY27 (divestments net of the Ashburton start), 3.5% FY28 (full Ashburton year), fading to 2.5%. Fleet renewal keeps costing 6.3% of revenue in leases plus capex ramping 4% -> 4.5%, so owner FCF matures at only ~2.7% of revenue. The placement and SPP complete at the announced minimums, the $700k note converts, $8m of the $10-12m asset-sale target is realised and applied to debt, and Kiwibank refinances in May 2027. Even so, EV of ~$18.5m does not cover $31.4m of pro-forma net borrowings: the equity is a residual claim below zero on a DCF basis.
A23: BULL | B23: Management's plan lands close to its own numbers. Full $5-6m cost reduction from FY28, 5% revenue growth FY28-FY30 (Ashburton, M&Q expansion, national tenders unlocked by Civic), EBITDA margin 13% FY28 rising to 17% by FY31 and held (above the FY23 16.2% peak). Fleet cost unchanged (6.3% leases + 4-4.5% capex), 28% tax once losses are used. Terminal value binds on Gordon at 2.5% (12.1x FCF), inside the 14x cap. EV of ~$39.7m clears pro-forma net borrowings by ~$8m -- about $0.0055/share, i.e. the placement price. The $2m note (conversion price $0.007) would convert at this value; the $15m Empire notes ($0.02) would not. A trade sale at 8x FY28E EBITDA (memo) is the only path materially above the current price.

Sheet DCF_Bear
A1: BEAR scenario -- owner FCF, NZ$000
A3: Year | B3: 2026A | C3: 2027E | D3: 2028E | E3: 2029E | F3: 2030E | G3: 2031E | H3: 2032E | I3: 2033E | J3: 2034E | K3: 2035E | L3: 2036E
A4: Index | B4: 0 | C4: 1 | D4: 2 | E4: 3 | F4: 4 | G4: 5 | H4: 6 | I4: 7 | J4: 8 | K4: 9 | L4: 10
A5: Revenue growth % | C5: -3 | D5: 0 | E5: 1 | F5: 1.5 | G5: 2 | H5: 2 | I5: 2 | J5: 2 | K5: 2 | L5: 2
A6: Revenue | B6: =Assumptions!$B$9 | C6: =B6*(1+C5/100) | D6: =C6*(1+D5/100) | E6: =D6*(1+E5/100) | F6: =E6*(1+F5/100) | G6: =F6*(1+G5/100) | H6: =G6*(1+H5/100) | I6: =H6*(1+I5/100) | J6: =I6*(1+J5/100) | ... L6: =K6*(1+L5/100)
A7: Adj EBITDA margin % | C7: 7.5 | D7: 8.5 | E7: 9 | F7: 9.5 | G7: 10 | H7: 10 | I7: 10 | J7: 10 | K7: 10 | L7: 10
A8: Adjusted EBITDA (post-IFRS-16) | C8: =C6*C7/100 | D8: =D6*D7/100 | E8: =E6*E7/100 | F8: =F6*F7/100 | G8: =G6*G7/100 | H8: =H6*H7/100 | I8: =I6*I7/100 | J8: =J6*J7/100 | ... L8: =L6*L7/100
A9: SBC % of revenue | C9: 0.1 | D9: 0.1 | E9: 0.1 | F9: 0.1 | G9: 0.1 | H9: 0.1 | I9: 0.1 | J9: 0.1 | K9: 0.1 | L9: 0.1
A10: SBC $ (neg) | C10: =-C6*C9/100 | D10: =-D6*D9/100 | E10: =-E6*E9/100 | F10: =-F6*F9/100 | G10: =-G6*G9/100 | H10: =-H6*H9/100 | I10: =-I6*I9/100 | J10: =-J6*J9/100 | ... L10: =-L6*L9/100
A11: Lease cost % of revenue | C11: =Assumptions!$B$5 | D11: =Assumptions!$B$5 | E11: =Assumptions!$B$5 | F11: =Assumptions!$B$5 | G11: =Assumptions!$B$5 | H11: =Assumptions!$B$5 | I11: =Assumptions!$B$5 | J11: =Assumptions!$B$5 | ... L11: =Assumptions!$B$5
A12: Lease cash $ (neg) | C12: =-C6*C11/100 | D12: =-D6*D11/100 | E12: =-E6*E11/100 | F12: =-F6*F11/100 | G12: =-G6*G11/100 | H12: =-H6*H11/100 | I12: =-I6*I11/100 | J12: =-J6*J11/100 | ... L12: =-L6*L11/100
A13: Owner EBITDA (after SBC and leases) | C13: =C8+C10+C12 | D13: =D8+D10+D12 | E13: =E8+E10+E12 | F13: =F8+F10+F12 | G13: =G8+G10+G12 | H13: =H8+H10+H12 | I13: =I8+I10+I12 | J13: =J8+J10+J12 | ... L13: =L8+L10+L12
A14: D&A ex-ROU % of revenue | C14: 9.5 | D14: 9 | E14: 8.5 | F14: 8 | G14: 7.5 | H14: 7 | I14: 6.5 | J14: 6.5 | K14: 6.5 | L14: 6.5
A15: D&A $ (neg) | C15: =-C6*C14/100 | D15: =-D6*D14/100 | E15: =-E6*E14/100 | F15: =-F6*F14/100 | G15: =-G6*G14/100 | H15: =-H6*H14/100 | I15: =-I6*I14/100 | J15: =-J6*J14/100 | ... L15: =-L6*L14/100
A16: EBIT (SBC and leases expensed) | C16: =C13+C15 | D16: =D13+D15 | E16: =E13+E15 | F16: =F13+F15 | G16: =G13+G15 | H16: =H13+H15 | I16: =I13+I15 | J16: =J13+J15 | ... L16: =L13+L15
A17: Cash tax rate % | C17: 0 | D17: 0 | E17: 0 | F17: 0 | G17: 0 | H17: 0 | I17: 14 | J17: 28 | K17: 28 | L17: 28
A18: Cash tax $ (neg; on max(0,EBIT)) | C18: =-MAX(0,C16)*C17/100 | D18: =-MAX(0,D16)*D17/100 | E18: =-MAX(0,E16)*E17/100 | F18: =-MAX(0,F16)*F17/100 | G18: =-MAX(0,G16)*G17/100 | H18: =-MAX(0,H16)*H17/100 | I18: =-MAX(0,I16)*I17/100 | J18: =-MAX(0,J16)*J17/100 | ... L18: =-MAX(0,L16)*L17/100
A19: NOPAT | C19: =C16+C18 | D19: =D16+D18 | E19: =E16+E18 | F19: =F16+F18 | G19: =G16+G18 | H19: =H16+H18 | I19: =I16+I18 | J19: =J16+J18 | ... L19: =L16+L18
A20: add back D&A | C20: =-C15 | D20: =-D15 | E20: =-E15 | F20: =-F15 | G20: =-G15 | H20: =-H15 | I20: =-I15 | J20: =-J15 | ... L20: =-L15
A21: Capex % of revenue | C21: 3.5 | D21: 3.5 | E21: 4 | F21: 4.5 | G21: 4.5 | H21: 4.5 | I21: 4.5 | J21: 4.5 | K21: 4.5 | L21: 4.5
A22: Capex $ (neg) | C22: =-C6*C21/100 | D22: =-D6*D21/100 | E22: =-E6*E21/100 | F22: =-F6*F21/100 | G22: =-G6*G21/100 | H22: =-H6*H21/100 | I22: =-I6*I21/100 | J22: =-J6*J21/100 | ... L22: =-L6*L21/100
A23: Working capital (capture x revenue change) | C23: =Assumptions!$B$7/100*(C6-B6) | D23: =Assumptions!$B$7/100*(D6-C6) | E23: =Assumptions!$B$7/100*(E6-D6) | F23: =Assumptions!$B$7/100*(F6-E6) | G23: =Assumptions!$B$7/100*(G6-F6) | H23: =Assumptions!$B$7/100*(H6-G6) | I23: =Assumptions!$B$7/100*(I6-H6) | J23: =Assumptions!$B$7/100*(J6-I6) | ... L23: =Assumptions!$B$7/100*(L6-K6)
A24: Unlevered owner FCF | C24: =C19+C20+C22+C23 | D24: =D19+D20+D22+D23 | E24: =E19+E20+E22+E23 | F24: =F19+F20+F22+F23 | G24: =G19+G20+G22+G23 | H24: =H19+H20+H22+H23 | I24: =I19+I20+I22+I23 | J24: =J19+J20+J22+J23 | ... L24: =L19+L20+L22+L23
A25: Discount factor | C25: =1/(1+$B$32/100)^C4 | D25: =1/(1+$B$32/100)^D4 | E25: =1/(1+$B$32/100)^E4 | F25: =1/(1+$B$32/100)^F4 | G25: =1/(1+$B$32/100)^G4 | H25: =1/(1+$B$32/100)^H4 | I25: =1/(1+$B$32/100)^I4 | J25: =1/(1+$B$32/100)^J4 | ... L25: =1/(1+$B$32/100)^L4
A26: PV of FCF | C26: =C24*C25 | D26: =D24*D25 | E26: =E24*E25 | F26: =F24*F25 | G26: =G24*G25 | H26: =H24*H25 | I26: =I24*I25 | J26: =J24*J25 | ... L26: =L24*L25
A28: Memo: FCF before SBC (company-style) | C28: =C24-C10 | D28: =D24-D10 | E28: =E24-E10 | F28: =F24-F10 | G28: =G24-G10 | H28: =H24-H10 | I28: =I24-I10 | J28: =J24-J10 | ... L28: =L24-L10
A29: Memo: owner FCF margin % | C29: =C24/C6*100 | D29: =D24/D6*100 | E29: =E24/E6*100 | F29: =F24/F6*100 | G29: =G24/G6*100 | H29: =H24/H6*100 | I29: =I24/I6*100 | J29: =J24/J6*100 | ... L29: =L24/L6*100
A31: Sum of PV of FCF | B31: =SUM(C26:L26)
A32: WACC % | B32: =Assumptions!B14
A33: Terminal growth % | B33: =Assumptions!B15
A34: Terminal-year FCF x (1+g) | B34: =L24*(1+B33/100)
A35: Gordon TV | B35: =IF(B32>B33,B34/((B32-B33)/100),0)
A36: Cap multiple (x FCF_10) | B36: =Assumptions!B16
A37: Cap TV | B37: =B36*L24
A38: TV used = MAX(0, MIN(Gordon, cap)) | B38: =MAX(0,MIN(B35,B37))
A39: Implied exit multiple (TV / FCF_10) | B39: =IF(L24>0,B38/L24,"n/a")
A40: PV of TV | B40: =B38*L25
A41: Enterprise value | B41: =B31+B40
A42: less net debt (bridge) | B42: =-Assumptions!$B$4
A43: Equity value | B43: =B41+B42
...

Sheet DCF_Base
A1: BASE scenario -- owner FCF, NZ$000
A3: Year | B3: 2026A | C3: 2027E | D3: 2028E | E3: 2029E | F3: 2030E | G3: 2031E | H3: 2032E | I3: 2033E | J3: 2034E | K3: 2035E | L3: 2036E
A4: Index | B4: 0 | C4: 1 | D4: 2 | E4: 3 | F4: 4 | G4: 5 | H4: 6 | I4: 7 | J4: 8 | K4: 9 | L4: 10
A5: Revenue growth % | C5: 1.5 | D5: 3.5 | E5: 3 | F5: 3 | G5: 3 | H5: 2.5 | I5: 2.5 | J5: 2.5 | K5: 2.5 | L5: 2.5
A6: Revenue | B6: =Assumptions!$B$9 | C6: =B6*(1+C5/100) | D6: =C6*(1+D5/100) | E6: =D6*(1+E5/100) | F6: =E6*(1+F5/100) | G6: =F6*(1+G5/100) | H6: =G6*(1+H5/100) | I6: =H6*(1+I5/100) | J6: =I6*(1+J5/100) | ... L6: =K6*(1+L5/100)
A7: Adj EBITDA margin % | C7: 8.3 | D7: 11 | E7: 12.5 | F7: 13 | G7: 13.5 | H7: 14 | I7: 14 | J7: 14 | K7: 14 | L7: 14
A8: Adjusted EBITDA (post-IFRS-16) | C8: =C6*C7/100 | D8: =D6*D7/100 | E8: =E6*E7/100 | F8: =F6*F7/100 | G8: =G6*G7/100 | H8: =H6*H7/100 | I8: =I6*I7/100 | J8: =J6*J7/100 | ... L8: =L6*L7/100
A9: SBC % of revenue | C9: 0.1 | D9: 0.1 | E9: 0.1 | F9: 0.1 | G9: 0.1 | H9: 0.1 | I9: 0.1 | J9: 0.1 | K9: 0.1 | L9: 0.1
A10: SBC $ (neg) | C10: =-C6*C9/100 | D10: =-D6*D9/100 | E10: =-E6*E9/100 | F10: =-F6*F9/100 | G10: =-G6*G9/100 | H10: =-H6*H9/100 | I10: =-I6*I9/100 | J10: =-J6*J9/100 | ... L10: =-L6*L9/100
A11: Lease cost % of revenue | C11: =Assumptions!$B$5 | D11: =Assumptions!$B$5 | E11: =Assumptions!$B$5 | F11: =Assumptions!$B$5 | G11: =Assumptions!$B$5 | H11: =Assumptions!$B$5 | I11: =Assumptions!$B$5 | J11: =Assumptions!$B$5 | ... L11: =Assumptions!$B$5
A12: Lease cash $ (neg) | C12: =-C6*C11/100 | D12: =-D6*D11/100 | E12: =-E6*E11/100 | F12: =-F6*F11/100 | G12: =-G6*G11/100 | H12: =-H6*H11/100 | I12: =-I6*I11/100 | J12: =-J6*J11/100 | ... L12: =-L6*L11/100
A13: Owner EBITDA (after SBC and leases) | C13: =C8+C10+C12 | D13: =D8+D10+D12 | E13: =E8+E10+E12 | F13: =F8+F10+F12 | G13: =G8+G10+G12 | H13: =H8+H10+H12 | I13: =I8+I10+I12 | J13: =J8+J10+J12 | ... L13: =L8+L10+L12
A14: D&A ex-ROU % of revenue | C14: 9.5 | D14: 9 | E14: 8.5 | F14: 8 | G14: 7.5 | H14: 7 | I14: 6.5 | J14: 6.5 | K14: 6.5 | L14: 6.5
A15: D&A $ (neg) | C15: =-C6*C14/100 | D15: =-D6*D14/100 | E15: =-E6*E14/100 | F15: =-F6*F14/100 | G15: =-G6*G14/100 | H15: =-H6*H14/100 | I15: =-I6*I14/100 | J15: =-J6*J14/100 | ... L15: =-L6*L14/100
A16: EBIT (SBC and leases expensed) | C16: =C13+C15 | D16: =D13+D15 | E16: =E13+E15 | F16: =F13+F15 | G16: =G13+G15 | H16: =H13+H15 | I16: =I13+I15 | J16: =J13+J15 | ... L16: =L13+L15
A17: Cash tax rate % | C17: 0 | D17: 0 | E17: 0 | F17: 0 | G17: 0 | H17: 0 | I17: 14 | J17: 28 | K17: 28 | L17: 28
A18: Cash tax $ (neg; on max(0,EBIT)) | C18: =-MAX(0,C16)*C17/100 | D18: =-MAX(0,D16)*D17/100 | E18: =-MAX(0,E16)*E17/100 | F18: =-MAX(0,F16)*F17/100 | G18: =-MAX(0,G16)*G17/100 | H18: =-MAX(0,H16)*H17/100 | I18: =-MAX(0,I16)*I17/100 | J18: =-MAX(0,J16)*J17/100 | ... L18: =-MAX(0,L16)*L17/100
A19: NOPAT | C19: =C16+C18 | D19: =D16+D18 | E19: =E16+E18 | F19: =F16+F18 | G19: =G16+G18 | H19: =H16+H18 | I19: =I16+I18 | J19: =J16+J18 | ... L19: =L16+L18
A20: add back D&A | C20: =-C15 | D20: =-D15 | E20: =-E15 | F20: =-F15 | G20: =-G15 | H20: =-H15 | I20: =-I15 | J20: =-J15 | ... L20: =-L15
A21: Capex % of revenue | C21: 4 | D21: 3.5 | E21: 3.5 | F21: 4 | G21: 4.5 | H21: 4.5 | I21: 4.5 | J21: 4.5 | K21: 4.5 | L21: 4.5
A22: Capex $ (neg) | C22: =-C6*C21/100 | D22: =-D6*D21/100 | E22: =-E6*E21/100 | F22: =-F6*F21/100 | G22: =-G6*G21/100 | H22: =-H6*H21/100 | I22: =-I6*I21/100 | J22: =-J6*J21/100 | ... L22: =-L6*L21/100
A23: Working capital (capture x revenue change) | C23: =Assumptions!$B$7/100*(C6-B6) | D23: =Assumptions!$B$7/100*(D6-C6) | E23: =Assumptions!$B$7/100*(E6-D6) | F23: =Assumptions!$B$7/100*(F6-E6) | G23: =Assumptions!$B$7/100*(G6-F6) | H23: =Assumptions!$B$7/100*(H6-G6) | I23: =Assumptions!$B$7/100*(I6-H6) | J23: =Assumptions!$B$7/100*(J6-I6) | ... L23: =Assumptions!$B$7/100*(L6-K6)
A24: Unlevered owner FCF | C24: =C19+C20+C22+C23 | D24: =D19+D20+D22+D23 | E24: =E19+E20+E22+E23 | F24: =F19+F20+F22+F23 | G24: =G19+G20+G22+G23 | H24: =H19+H20+H22+H23 | I24: =I19+I20+I22+I23 | J24: =J19+J20+J22+J23 | ... L24: =L19+L20+L22+L23
A25: Discount factor | C25: =1/(1+$B$32/100)^C4 | D25: =1/(1+$B$32/100)^D4 | E25: =1/(1+$B$32/100)^E4 | F25: =1/(1+$B$32/100)^F4 | G25: =1/(1+$B$32/100)^G4 | H25: =1/(1+$B$32/100)^H4 | I25: =1/(1+$B$32/100)^I4 | J25: =1/(1+$B$32/100)^J4 | ... L25: =1/(1+$B$32/100)^L4
A26: PV of FCF | C26: =C24*C25 | D26: =D24*D25 | E26: =E24*E25 | F26: =F24*F25 | G26: =G24*G25 | H26: =H24*H25 | I26: =I24*I25 | J26: =J24*J25 | ... L26: =L24*L25
A28: Memo: FCF before SBC (company-style) | C28: =C24-C10 | D28: =D24-D10 | E28: =E24-E10 | F28: =F24-F10 | G28: =G24-G10 | H28: =H24-H10 | I28: =I24-I10 | J28: =J24-J10 | ... L28: =L24-L10
A29: Memo: owner FCF margin % | C29: =C24/C6*100 | D29: =D24/D6*100 | E29: =E24/E6*100 | F29: =F24/F6*100 | G29: =G24/G6*100 | H29: =H24/H6*100 | I29: =I24/I6*100 | J29: =J24/J6*100 | ... L29: =L24/L6*100
A31: Sum of PV of FCF | B31: =SUM(C26:L26)
A32: WACC % | B32: =Assumptions!C14
A33: Terminal growth % | B33: =Assumptions!C15
A34: Terminal-year FCF x (1+g) | B34: =L24*(1+B33/100)
A35: Gordon TV | B35: =IF(B32>B33,B34/((B32-B33)/100),0)
A36: Cap multiple (x FCF_10) | B36: =Assumptions!C16
A37: Cap TV | B37: =B36*L24
A38: TV used = MAX(0, MIN(Gordon, cap)) | B38: =MAX(0,MIN(B35,B37))
A39: Implied exit multiple (TV / FCF_10) | B39: =IF(L24>0,B38/L24,"n/a")
A40: PV of TV | B40: =B38*L25
A41: Enterprise value | B41: =B31+B40
A42: less net debt (bridge) | B42: =-Assumptions!$B$4
A43: Equity value | B43: =B41+B42
...

Sheet DCF_Bull
A1: BULL scenario -- owner FCF, NZ$000
A3: Year | B3: 2026A | C3: 2027E | D3: 2028E | E3: 2029E | F3: 2030E | G3: 2031E | H3: 2032E | I3: 2033E | J3: 2034E | K3: 2035E | L3: 2036E
A4: Index | B4: 0 | C4: 1 | D4: 2 | E4: 3 | F4: 4 | G4: 5 | H4: 6 | I4: 7 | J4: 8 | K4: 9 | L4: 10
A5: Revenue growth % | C5: 1.5 | D5: 5 | E5: 5 | F5: 5 | G5: 4 | H5: 4 | I5: 3 | J5: 3 | K5: 3 | L5: 3
A6: Revenue | B6: =Assumptions!$B$9 | C6: =B6*(1+C5/100) | D6: =C6*(1+D5/100) | E6: =D6*(1+E5/100) | F6: =E6*(1+F5/100) | G6: =F6*(1+G5/100) | H6: =G6*(1+H5/100) | I6: =H6*(1+I5/100) | J6: =I6*(1+J5/100) | ... L6: =K6*(1+L5/100)
A7: Adj EBITDA margin % | C7: 8.8 | D7: 13 | E7: 15 | F7: 16 | G7: 17 | H7: 17 | I7: 17 | J7: 17 | K7: 17 | L7: 17
A8: Adjusted EBITDA (post-IFRS-16) | C8: =C6*C7/100 | D8: =D6*D7/100 | E8: =E6*E7/100 | F8: =F6*F7/100 | G8: =G6*G7/100 | H8: =H6*H7/100 | I8: =I6*I7/100 | J8: =J6*J7/100 | ... L8: =L6*L7/100
A9: SBC % of revenue | C9: 0.1 | D9: 0.1 | E9: 0.1 | F9: 0.1 | G9: 0.1 | H9: 0.1 | I9: 0.1 | J9: 0.1 | K9: 0.1 | L9: 0.1
A10: SBC $ (neg) | C10: =-C6*C9/100 | D10: =-D6*D9/100 | E10: =-E6*E9/100 | F10: =-F6*F9/100 | G10: =-G6*G9/100 | H10: =-H6*H9/100 | I10: =-I6*I9/100 | J10: =-J6*J9/100 | ... L10: =-L6*L9/100
A11: Lease cost % of revenue | C11: =Assumptions!$B$5 | D11: =Assumptions!$B$5 | E11: =Assumptions!$B$5 | F11: =Assumptions!$B$5 | G11: =Assumptions!$B$5 | H11: =Assumptions!$B$5 | I11: =Assumptions!$B$5 | J11: =Assumptions!$B$5 | ... L11: =Assumptions!$B$5
A12: Lease cash $ (neg) | C12: =-C6*C11/100 | D12: =-D6*D11/100 | E12: =-E6*E11/100 | F12: =-F6*F11/100 | G12: =-G6*G11/100 | H12: =-H6*H11/100 | I12: =-I6*I11/100 | J12: =-J6*J11/100 | ... L12: =-L6*L11/100
A13: Owner EBITDA (after SBC and leases) | C13: =C8+C10+C12 | D13: =D8+D10+D12 | E13: =E8+E10+E12 | F13: =F8+F10+F12 | G13: =G8+G10+G12 | H13: =H8+H10+H12 | I13: =I8+I10+I12 | J13: =J8+J10+J12 | ... L13: =L8+L10+L12
A14: D&A ex-ROU % of revenue | C14: 9.5 | D14: 9 | E14: 8.5 | F14: 8 | G14: 7.5 | H14: 7 | I14: 6.5 | J14: 6.5 | K14: 6.5 | L14: 6.5
A15: D&A $ (neg) | C15: =-C6*C14/100 | D15: =-D6*D14/100 | E15: =-E6*E14/100 | F15: =-F6*F14/100 | G15: =-G6*G14/100 | H15: =-H6*H14/100 | I15: =-I6*I14/100 | J15: =-J6*J14/100 | ... L15: =-L6*L14/100
A16: EBIT (SBC and leases expensed) | C16: =C13+C15 | D16: =D13+D15 | E16: =E13+E15 | F16: =F13+F15 | G16: =G13+G15 | H16: =H13+H15 | I16: =I13+I15 | J16: =J13+J15 | ... L16: =L13+L15
A17: Cash tax rate % | C17: 0 | D17: 0 | E17: 0 | F17: 0 | G17: 0 | H17: 0 | I17: 14 | J17: 28 | K17: 28 | L17: 28
A18: Cash tax $ (neg; on max(0,EBIT)) | C18: =-MAX(0,C16)*C17/100 | D18: =-MAX(0,D16)*D17/100 | E18: =-MAX(0,E16)*E17/100 | F18: =-MAX(0,F16)*F17/100 | G18: =-MAX(0,G16)*G17/100 | H18: =-MAX(0,H16)*H17/100 | I18: =-MAX(0,I16)*I17/100 | J18: =-MAX(0,J16)*J17/100 | ... L18: =-MAX(0,L16)*L17/100
A19: NOPAT | C19: =C16+C18 | D19: =D16+D18 | E19: =E16+E18 | F19: =F16+F18 | G19: =G16+G18 | H19: =H16+H18 | I19: =I16+I18 | J19: =J16+J18 | ... L19: =L16+L18
A20: add back D&A | C20: =-C15 | D20: =-D15 | E20: =-E15 | F20: =-F15 | G20: =-G15 | H20: =-H15 | I20: =-I15 | J20: =-J15 | ... L20: =-L15
A21: Capex % of revenue | C21: 4 | D21: 4 | E21: 4 | F21: 4.5 | G21: 4.5 | H21: 4.5 | I21: 4.5 | J21: 4.5 | K21: 4.5 | L21: 4.5
A22: Capex $ (neg) | C22: =-C6*C21/100 | D22: =-D6*D21/100 | E22: =-E6*E21/100 | F22: =-F6*F21/100 | G22: =-G6*G21/100 | H22: =-H6*H21/100 | I22: =-I6*I21/100 | J22: =-J6*J21/100 | ... L22: =-L6*L21/100
A23: Working capital (capture x revenue change) | C23: =Assumptions!$B$7/100*(C6-B6) | D23: =Assumptions!$B$7/100*(D6-C6) | E23: =Assumptions!$B$7/100*(E6-D6) | F23: =Assumptions!$B$7/100*(F6-E6) | G23: =Assumptions!$B$7/100*(G6-F6) | H23: =Assumptions!$B$7/100*(H6-G6) | I23: =Assumptions!$B$7/100*(I6-H6) | J23: =Assumptions!$B$7/100*(J6-I6) | ... L23: =Assumptions!$B$7/100*(L6-K6)
A24: Unlevered owner FCF | C24: =C19+C20+C22+C23 | D24: =D19+D20+D22+D23 | E24: =E19+E20+E22+E23 | F24: =F19+F20+F22+F23 | G24: =G19+G20+G22+G23 | H24: =H19+H20+H22+H23 | I24: =I19+I20+I22+I23 | J24: =J19+J20+J22+J23 | ... L24: =L19+L20+L22+L23
A25: Discount factor | C25: =1/(1+$B$32/100)^C4 | D25: =1/(1+$B$32/100)^D4 | E25: =1/(1+$B$32/100)^E4 | F25: =1/(1+$B$32/100)^F4 | G25: =1/(1+$B$32/100)^G4 | H25: =1/(1+$B$32/100)^H4 | I25: =1/(1+$B$32/100)^I4 | J25: =1/(1+$B$32/100)^J4 | ... L25: =1/(1+$B$32/100)^L4
A26: PV of FCF | C26: =C24*C25 | D26: =D24*D25 | E26: =E24*E25 | F26: =F24*F25 | G26: =G24*G25 | H26: =H24*H25 | I26: =I24*I25 | J26: =J24*J25 | ... L26: =L24*L25
A28: Memo: FCF before SBC (company-style) | C28: =C24-C10 | D28: =D24-D10 | E28: =E24-E10 | F28: =F24-F10 | G28: =G24-G10 | H28: =H24-H10 | I28: =I24-I10 | J28: =J24-J10 | ... L28: =L24-L10
A29: Memo: owner FCF margin % | C29: =C24/C6*100 | D29: =D24/D6*100 | E29: =E24/E6*100 | F29: =F24/F6*100 | G29: =G24/G6*100 | H29: =H24/H6*100 | I29: =I24/I6*100 | J29: =J24/J6*100 | ... L29: =L24/L6*100
A31: Sum of PV of FCF | B31: =SUM(C26:L26)
A32: WACC % | B32: =Assumptions!D14
A33: Terminal growth % | B33: =Assumptions!D15
A34: Terminal-year FCF x (1+g) | B34: =L24*(1+B33/100)
A35: Gordon TV | B35: =IF(B32>B33,B34/((B32-B33)/100),0)
A36: Cap multiple (x FCF_10) | B36: =Assumptions!D16
A37: Cap TV | B37: =B36*L24
A38: TV used = MAX(0, MIN(Gordon, cap)) | B38: =MAX(0,MIN(B35,B37))
A39: Implied exit multiple (TV / FCF_10) | B39: =IF(L24>0,B38/L24,"n/a")
A40: PV of TV | B40: =B38*L25
A41: Enterprise value | B41: =B31+B40
A42: less net debt (bridge) | B42: =-Assumptions!$B$4
A43: Equity value | B43: =B41+B42
...

Sheet FCF_Quality
A1: Reported FCF reconciled to owner FCF (NZ$000)
B2: FY2023 | C2: FY2024 | D2: FY2025 | E2: FY2026
A3: Revenue | B3: =Actuals!B2 | C3: =Actuals!C2 | D3: =Actuals!D2 | E3: =Actuals!E2
A4: Net cash from operating activities | B4: =Actuals!B5 | C4: =Actuals!C5 | D4: =Actuals!D5 | E4: =Actuals!E5
A5: less capex (PP&E + intangibles) | B5: =-Actuals!B6 | C5: =-Actuals!C6 | D5: =-Actuals!D6 | E5: =-Actuals!E6
A6: Equals: free cash flow (company-style, post-IFRS-16) | B6: =B4+B5 | C6: =C4+C5 | D6: =D4+D5 | E6: =E4+E5
A7: less lease principal | B7: =-Actuals!B7 | C7: =-Actuals!C7 | D7: =-Actuals!D7 | E7: =-Actuals!E7
A8: less lease interest | B8: =-Actuals!B8 | C8: =-Actuals!C8 | D8: =-Actuals!D8 | E8: =-Actuals!E8
A9: less SBC expense | B9: =-Actuals!B10 | C9: =-Actuals!C10 | D9: =-Actuals!D10 | E9: =-Actuals!E10
A10: less interest income (nil -- not net cash) | B10: 0 | C10: 0 | D10: 0 | E10: 0
A11: Equals: owner FCF (pre debt interest) | B11: =SUM(B6:B10) | C11: =SUM(C6:C10) | D11: =SUM(D6:D10) | E11: =SUM(E6:E10)
A12: Reported FCF margin % | B12: =B6/B3*100 | C12: =C6/C3*100 | D12: =D6/D3*100 | E12: =E6/E3*100
A13: Owner FCF margin % | B13: =B11/B3*100 | C13: =C11/C3*100 | D13: =D11/D3*100 | E13: =E11/E3*100
A14: Memo: interest paid on borrowings + notes | B14: =Actuals!B9 | C14: =Actuals!C9 | D14: =Actuals!D9 | E14: =Actuals!E9
A15: Memo: owner FCF after debt interest (equity FCF) | B15: =B11-B14 | C15: =C11-C14 | D15: =D11-D14 | E15: =E11-E14
A16: Memo: lease cash % of revenue | B16: =(Actuals!B7+Actuals!B8)/B3*100 | C16: =(Actuals!C7+Actuals!C8)/C3*100 | D16: =(Actuals!D7+Actuals!D8)/D3*100 | E16: =(Actuals!E7+Actuals!E8)/E3*100
A17: Memo: capex % of revenue vs D&A ex-ROU % | B17: =Actuals!B6/B3*100 | C17: =Actuals!C6/C3*100 | D17: =Actuals!D6/D3*100 | E17: =Actuals!E6/E3*100
A18: Memo: D&A ex-ROU % of revenue | B18: =(Actuals!B11-Actuals!B12)/B3*100 | C18: =(Actuals!C11-Actuals!C12)/C3*100 | D18: =(Actuals!D11-Actuals!D12)/D3*100 | E18: =(Actuals!E11-Actuals!E12)/E3*100
A19: Memo: cash tax | B19: 139 paid | C19: n/a | D19: 21 refund | E19: 13 paid -- abnormal (losses); model ramps 0% -> 28% from FY33

Sheet Valuation
A1: Valuation summary (NZD per share)
A2: Scenario | B2: Value/share | C2: Upside % | D2: Weight | E2: Street value/share | F2: TV bound | G2: Entry price @ hurdle
A3: Bear | B3: =DCF_Bear!$B$45 | C3: =(B3/Assumptions!$B$2-1)*100 | D3: =Assumptions!B17 | E3: =DCF_Bear!$B$50 | F3: =IF(DCF_Bear!$B$38=0,"floor",IF(DCF_Bear!$B$35<=DCF_Bear!$B$37,"gordon","cap")) | G3: =IF((Assumptions!$B$8*100)>Assumptions!B15,(SUMPRODUCT(DCF_Bear!$C$24:$L$24/(1+(Assumptions!$B$8*100)/100)^DCF_Bear!$C$4:$L$4)+MAX(0,MIN(DCF_Bear!$L$24*(1+Assumptions!B15/100)/(((Assumptions!$B$8*100)-Assumptions!B15)/100),Assumptions!B16*DCF_Bear!$L$24))/(1+(Assumptions!$B$8*100)/100)^10-Assumptions!$B$4)/Assumptions!$B$3,"n/a")
A4: Base | B4: =DCF_Base!$B$45 | C4: =(B4/Assumptions!$B$2-1)*100 | D4: =Assumptions!C17 | E4: =DCF_Base!$B$50 | F4: =IF(DCF_Base!$B$38=0,"floor",IF(DCF_Base!$B$35<=DCF_Base!$B$37,"gordon","cap")) | G4: =IF((Assumptions!$B$8*100)>Assumptions!C15,(SUMPRODUCT(DCF_Base!$C$24:$L$24/(1+(Assumptions!$B$8*100)/100)^DCF_Base!$C$4:$L$4)+MAX(0,MIN(DCF_Base!$L$24*(1+Assumptions!C15/100)/(((Assumptions!$B$8*100)-Assumptions!C15)/100),Assumptions!C16*DCF_Base!$L$24))/(1+(Assumptions!$B$8*100)/100)^10-Assumptions!$B$4)/Assumptions!$B$3,"n/a")
A5: Bull | B5: =DCF_Bull!$B$45 | C5: =(B5/Assumptions!$B$2-1)*100 | D5: =Assumptions!D17 | E5: =DCF_Bull!$B$50 | F5: =IF(DCF_Bull!$B$38=0,"floor",IF(DCF_Bull!$B$35<=DCF_Bull!$B$37,"gordon","cap")) | G5: =IF((Assumptions!$B$8*100)>Assumptions!D15,(SUMPRODUCT(DCF_Bull!$C$24:$L$24/(1+(Assumptions!$B$8*100)/100)^DCF_Bull!$C$4:$L$4)+MAX(0,MIN(DCF_Bull!$L$24*(1+Assumptions!D15/100)/(((Assumptions!$B$8*100)-Assumptions!D15)/100),Assumptions!D16*DCF_Bull!$L$24))/(1+(Assumptions!$B$8*100)/100)^10-Assumptions!$B$4)/Assumptions!$B$3,"n/a")
A7: Probability-weighted value/share | B7: =SUMPRODUCT(B3:B5,D3:D5)
A8: Probability-weighted, floored at 0 per scenario | B8: {=SUMPRODUCT(IF(B3:B5>0,B3:B5,0),D3:D5)}
A9: Margin of safety (1 - price/weighted) | B9: =IF(B7>0,1-Assumptions!$B$2/B7,"n/a (weighted <= 0)")
A10: Street weighted value/share | B10: =SUMPRODUCT(E3:E5,D3:D5)
A11: Band position (price - house)/(street - house) | B11: n/a -- SBC ~0.1% of revenue, band collapsed
A12: Weighted 15%-hurdle entry price | B12: =SUMPRODUCT(G3:G5,D3:D5)
A13: Current price | B13: =Assumptions!$B$2
A15: Required-return table (base case; TV rebuilt at each rate)
A16: Required return % | B16: 9 | C16: 10 | D16: 11 | E16: 12 | F16: 15 | G16: =Assumptions!C14 | H16: <- model WACC
A17: Value/share | B17: =IF(B16>Assumptions!C15,(SUMPRODUCT(DCF_Base!$C$24:$L$24/(1+B16/100)^DCF_Base!$C$4:$L$4)+MAX(0,MIN(DCF_Base!$L$24*(1+Assumptions!C15/100)/((B16-Assumptions!C15)/100),Assumptions!C16*DCF_Base!$L$24))/(1+B16/100)^10-Assumptions!$B$4)/Assumptions!$B$3,"n/a") | C17: =IF(C16>Assumptions!C15,(SUMPRODUCT(DCF_Base!$C$24:$L$24/(1+C16/100)^DCF_Base!$C$4:$L$4)+MAX(0,MIN(DCF_Base!$L$24*(1+Assumptions!C15/100)/((C16-Assumptions!C15)/100),Assumptions!C16*DCF_Base!$L$24))/(1+C16/100)^10-Assumptions!$B$4)/Assumptions!$B$3,"n/a") | D17: =IF(D16>Assumptions!C15,(SUMPRODUCT(DCF_Base!$C$24:$L$24/(1+D16/100)^DCF_Base!$C$4:$L$4)+MAX(0,MIN(DCF_Base!$L$24*(1+Assumptions!C15/100)/((D16-Assumptions!C15)/100),Assumptions!C16*DCF_Base!$L$24))/(1+D16/100)^10-Assumptions!$B$4)/Assumptions!$B$3,"n/a") | E17: =IF(E16>Assumptions!C15,(SUMPRODUCT(DCF_Base!$C$24:$L$24/(1+E16/100)^DCF_Base!$C$4:$L$4)+MAX(0,MIN(DCF_Base!$L$24*(1+Assumptions!C15/100)/((E16-Assumptions!C15)/100),Assumptions!C16*DCF_Base!$L$24))/(1+E16/100)^10-Assumptions!$B$4)/Assumptions!$B$3,"n/a") | F17: =IF(F16>Assumptions!C15,(SUMPRODUCT(DCF_Base!$C$24:$L$24/(1+F16/100)^DCF_Base!$C$4:$L$4)+MAX(0,MIN(DCF_Base!$L$24*(1+Assumptions!C15/100)/((F16-Assumptions!C15)/100),Assumptions!C16*DCF_Base!$L$24))/(1+F16/100)^10-Assumptions!$B$4)/Assumptions!$B$3,"n/a") | G17: =IF(G16>Assumptions!C15,(SUMPRODUCT(DCF_Base!$C$24:$L$24/(1+G16/100)^DCF_Base!$C$4:$L$4)+MAX(0,MIN(DCF_Base!$L$24*(1+Assumptions!C15/100)/((G16-Assumptions!C15)/100),Assumptions!C16*DCF_Base!$L$24))/(1+G16/100)^10-Assumptions!$B$4)/Assumptions!$B$3,"n/a")
A19: Sensitivity: WACC (rows) x terminal growth (cols), base case, NZD/share
B20: 1.5 | C20: 2 | D20: 2.5 | E20: 3 | F20: 3.5
A21: 9 | B21: =IF($A21>B$20,(SUMPRODUCT(DCF_Base!$C$24:$L$24/(1+$A21/100)^DCF_Base!$C$4:$L$4)+MAX(0,MIN(DCF_Base!$L$24*(1+B$20/100)/(($A21-B$20)/100),Assumptions!$C$16*DCF_Base!$L$24))/(1+$A21/100)^10-Assumptions!$B$4)/Assumptions!$B$3,"n/a") | C21: =IF($A21>C$20,(SUMPRODUCT(DCF_Base!$C$24:$L$24/(1+$A21/100)^DCF_Base!$C$4:$L$4)+MAX(0,MIN(DCF_Base!$L$24*(1+C$20/100)/(($A21-C$20)/100),Assumptions!$C$16*DCF_Base!$L$24))/(1+$A21/100)^10-Assumptions!$B$4)/Assumptions!$B$3,"n/a") | D21: =IF($A21>D$20,(SUMPRODUCT(DCF_Base!$C$24:$L$24/(1+$A21/100)^DCF_Base!$C$4:$L$4)+MAX(0,MIN(DCF_Base!$L$24*(1+D$20/100)/(($A21-D$20)/100),Assumptions!$C$16*DCF_Base!$L$24))/(1+$A21/100)^10-Assumptions!$B$4)/Assumptions!$B$3,"n/a") | E21: =IF($A21>E$20,(SUMPRODUCT(DCF_Base!$C$24:$L$24/(1+$A21/100)^DCF_Base!$C$4:$L$4)+MAX(0,MIN(DCF_Base!$L$24*(1+E$20/100)/(($A21-E$20)/100),Assumptions!$C$16*DCF_Base!$L$24))/(1+$A21/100)^10-Assumptions!$B$4)/Assumptions!$B$3,"n/a") | F21: =IF($A21>F$20,(SUMPRODUCT(DCF_Base!$C$24:$L$24/(1+$A21/100)^DCF_Base!$C$4:$L$4)+MAX(0,MIN(DCF_Base!$L$24*(1+F$20/100)/(($A21-F$20)/100),Assumptions!$C$16*DCF_Base!$L$24))/(1+$A21/100)^10-Assumptions!$B$4)/Assumptions!$B$3,"n/a")
A22: 10 | B22: =IF($A22>B$20,(SUMPRODUCT(DCF_Base!$C$24:$L$24/(1+$A22/100)^DCF_Base!$C$4:$L$4)+MAX(0,MIN(DCF_Base!$L$24*(1+B$20/100)/(($A22-B$20)/100),Assumptions!$C$16*DCF_Base!$L$24))/(1+$A22/100)^10-Assumptions!$B$4)/Assumptions!$B$3,"n/a") | C22: =IF($A22>C$20,(SUMPRODUCT(DCF_Base!$C$24:$L$24/(1+$A22/100)^DCF_Base!$C$4:$L$4)+MAX(0,MIN(DCF_Base!$L$24*(1+C$20/100)/(($A22-C$20)/100),Assumptions!$C$16*DCF_Base!$L$24))/(1+$A22/100)^10-Assumptions!$B$4)/Assumptions!$B$3,"n/a") | D22: =IF($A22>D$20,(SUMPRODUCT(DCF_Base!$C$24:$L$24/(1+$A22/100)^DCF_Base!$C$4:$L$4)+MAX(0,MIN(DCF_Base!$L$24*(1+D$20/100)/(($A22-D$20)/100),Assumptions!$C$16*DCF_Base!$L$24))/(1+$A22/100)^10-Assumptions!$B$4)/Assumptions!$B$3,"n/a") | E22: =IF($A22>E$20,(SUMPRODUCT(DCF_Base!$C$24:$L$24/(1+$A22/100)^DCF_Base!$C$4:$L$4)+MAX(0,MIN(DCF_Base!$L$24*(1+E$20/100)/(($A22-E$20)/100),Assumptions!$C$16*DCF_Base!$L$24))/(1+$A22/100)^10-Assumptions!$B$4)/Assumptions!$B$3,"n/a") | F22: =IF($A22>F$20,(SUMPRODUCT(DCF_Base!$C$24:$L$24/(1+$A22/100)^DCF_Base!$C$4:$L$4)+MAX(0,MIN(DCF_Base!$L$24*(1+F$20/100)/(($A22-F$20)/100),Assumptions!$C$16*DCF_Base!$L$24))/(1+$A22/100)^10-Assumptions!$B$4)/Assumptions!$B$3,"n/a")
A23: 11 | B23: =IF($A23>B$20,(SUMPRODUCT(DCF_Base!$C$24:$L$24/(1+$A23/100)^DCF_Base!$C$4:$L$4)+MAX(0,MIN(DCF_Base!$L$24*(1+B$20/100)/(($A23-B$20)/100),Assumptions!$C$16*DCF_Base!$L$24))/(1+$A23/100)^10-Assumptions!$B$4)/Assumptions!$B$3,"n/a") | C23: =IF($A23>C$20,(SUMPRODUCT(DCF_Base!$C$24:$L$24/(1+$A23/100)^DCF_Base!$C$4:$L$4)+MAX(0,MIN(DCF_Base!$L$24*(1+C$20/100)/(($A23-C$20)/100),Assumptions!$C$16*DCF_Base!$L$24))/(1+$A23/100)^10-Assumptions!$B$4)/Assumptions!$B$3,"n/a") | D23: =IF($A23>D$20,(SUMPRODUCT(DCF_Base!$C$24:$L$24/(1+$A23/100)^DCF_Base!$C$4:$L$4)+MAX(0,MIN(DCF_Base!$L$24*(1+D$20/100)/(($A23-D$20)/100),Assumptions!$C$16*DCF_Base!$L$24))/(1+$A23/100)^10-Assumptions!$B$4)/Assumptions!$B$3,"n/a") | E23: =IF($A23>E$20,(SUMPRODUCT(DCF_Base!$C$24:$L$24/(1+$A23/100)^DCF_Base!$C$4:$L$4)+MAX(0,MIN(DCF_Base!$L$24*(1+E$20/100)/(($A23-E$20)/100),Assumptions!$C$16*DCF_Base!$L$24))/(1+$A23/100)^10-Assumptions!$B$4)/Assumptions!$B$3,"n/a") | F23: =IF($A23>F$20,(SUMPRODUCT(DCF_Base!$C$24:$L$24/(1+$A23/100)^DCF_Base!$C$4:$L$4)+MAX(0,MIN(DCF_Base!$L$24*(1+F$20/100)/(($A23-F$20)/100),Assumptions!$C$16*DCF_Base!$L$24))/(1+$A23/100)^10-Assumptions!$B$4)/Assumptions!$B$3,"n/a")
A24: 12 | B24: =IF($A24>B$20,(SUMPRODUCT(DCF_Base!$C$24:$L$24/(1+$A24/100)^DCF_Base!$C$4:$L$4)+MAX(0,MIN(DCF_Base!$L$24*(1+B$20/100)/(($A24-B$20)/100),Assumptions!$C$16*DCF_Base!$L$24))/(1+$A24/100)^10-Assumptions!$B$4)/Assumptions!$B$3,"n/a") | C24: =IF($A24>C$20,(SUMPRODUCT(DCF_Base!$C$24:$L$24/(1+$A24/100)^DCF_Base!$C$4:$L$4)+MAX(0,MIN(DCF_Base!$L$24*(1+C$20/100)/(($A24-C$20)/100),Assumptions!$C$16*DCF_Base!$L$24))/(1+$A24/100)^10-Assumptions!$B$4)/Assumptions!$B$3,"n/a") | D24: =IF($A24>D$20,(SUMPRODUCT(DCF_Base!$C$24:$L$24/(1+$A24/100)^DCF_Base!$C$4:$L$4)+MAX(0,MIN(DCF_Base!$L$24*(1+D$20/100)/(($A24-D$20)/100),Assumptions!$C$16*DCF_Base!$L$24))/(1+$A24/100)^10-Assumptions!$B$4)/Assumptions!$B$3,"n/a") | E24: =IF($A24>E$20,(SUMPRODUCT(DCF_Base!$C$24:$L$24/(1+$A24/100)^DCF_Base!$C$4:$L$4)+MAX(0,MIN(DCF_Base!$L$24*(1+E$20/100)/(($A24-E$20)/100),Assumptions!$C$16*DCF_Base!$L$24))/(1+$A24/100)^10-Assumptions!$B$4)/Assumptions!$B$3,"n/a") | F24: =IF($A24>F$20,(SUMPRODUCT(DCF_Base!$C$24:$L$24/(1+$A24/100)^DCF_Base!$C$4:$L$4)+MAX(0,MIN(DCF_Base!$L$24*(1+F$20/100)/(($A24-F$20)/100),Assumptions!$C$16*DCF_Base!$L$24))/(1+$A24/100)^10-Assumptions!$B$4)/Assumptions!$B$3,"n/a")
A25: 13 | B25: =IF($A25>B$20,(SUMPRODUCT(DCF_Base!$C$24:$L$24/(1+$A25/100)^DCF_Base!$C$4:$L$4)+MAX(0,MIN(DCF_Base!$L$24*(1+B$20/100)/(($A25-B$20)/100),Assumptions!$C$16*DCF_Base!$L$24))/(1+$A25/100)^10-Assumptions!$B$4)/Assumptions!$B$3,"n/a") | C25: =IF($A25>C$20,(SUMPRODUCT(DCF_Base!$C$24:$L$24/(1+$A25/100)^DCF_Base!$C$4:$L$4)+MAX(0,MIN(DCF_Base!$L$24*(1+C$20/100)/(($A25-C$20)/100),Assumptions!$C$16*DCF_Base!$L$24))/(1+$A25/100)^10-Assumptions!$B$4)/Assumptions!$B$3,"n/a") | D25: =IF($A25>D$20,(SUMPRODUCT(DCF_Base!$C$24:$L$24/(1+$A25/100)^DCF_Base!$C$4:$L$4)+MAX(0,MIN(DCF_Base!$L$24*(1+D$20/100)/(($A25-D$20)/100),Assumptions!$C$16*DCF_Base!$L$24))/(1+$A25/100)^10-Assumptions!$B$4)/Assumptions!$B$3,"n/a") | E25: =IF($A25>E$20,(SUMPRODUCT(DCF_Base!$C$24:$L$24/(1+$A25/100)^DCF_Base!$C$4:$L$4)+MAX(0,MIN(DCF_Base!$L$24*(1+E$20/100)/(($A25-E$20)/100),Assumptions!$C$16*DCF_Base!$L$24))/(1+$A25/100)^10-Assumptions!$B$4)/Assumptions!$B$3,"n/a") | F25: =IF($A25>F$20,(SUMPRODUCT(DCF_Base!$C$24:$L$24/(1+$A25/100)^DCF_Base!$C$4:$L$4)+MAX(0,MIN(DCF_Base!$L$24*(1+F$20/100)/(($A25-F$20)/100),Assumptions!$C$16*DCF_Base!$L$24))/(1+$A25/100)^10-Assumptions!$B$4)/Assumptions!$B$3,"n/a")
A27: Memo: trade-sale reference -- 8x FY28E operating EBITDA (lease-inclusive) less lease liabilities scaled with revenue, less net debt bridge
A28: Bear | B28: =(8*DCF_Bear!$D$8-17988*DCF_Bear!$D$6/Assumptions!$B$9-Assumptions!$B$4)/Assumptions!$B$3
A29: Base | B29: =(8*DCF_Base!$D$8-17988*DCF_Base!$D$6/Assumptions!$B$9-Assumptions!$B$4)/Assumptions!$B$3
A30: Bull | B30: =(8*DCF_Bull!$D$8-17988*DCF_Bull!$D$6/Assumptions!$B$9-Assumptions!$B$4)/Assumptions!$B$3
A31: Weighted (floored) | B31: {=SUMPRODUCT(IF(B28:B30>0,B28:B30,0),D3:D5)}
